Workbook

Sheet DPRD PROVINSI
C8: Kecamatan | D8: PESANGGARAN
C9: Kabupaten | D9: BANYUWANGI
C10: Provinsi | D10: JAWA TIMUR
A12: I | B12: DATA PEMILIH DAN PENGGUNAAN HAK PILIH | E12: JUMLAH AKHIR
A13: A | B13: DATA PEMILIH
B14: Jumlah Pemilih dalam Daftar Pemilih Tetap (DPT) | D14: LK | E14: =KANDANGAN!AG14+PESANGGARAN!AZ14+SARONGAN!X14+SUMBERAGUNG!AX14+SUMBERMULYO!AB14 -> 21542
D15: PR | E15: =KANDANGAN!AG15+PESANGGARAN!AZ15+SARONGAN!X15+SUMBERAGUNG!AX15+SUMBERMULYO!AB15 -> 21455
D16: JML | E16: =SUM(E14:E15) -> 42997
A18: B | B18: PENGGUNA HAK PILIH
B19: 1. | C19: Jumlah pengguna hak pilih dalam Daftar Pemilih Tetap (DPT) | D19: LK | E19: =KANDANGAN!AG19+PESANGGARAN!AZ19+SARONGAN!X19+SUMBERAGUNG!AX19+SUMBERMULYO!AB19 -> 16156
D20: PR | E20: =KANDANGAN!AG20+PESANGGARAN!AZ20+SARONGAN!X20+SUMBERAGUNG!AX20+SUMBERMULYO!AB20 -> 16668
D21: JML | E21: =SUM(E19:E20) -> 32824
B22: 2. | C22: Jumlah pengguna hak pilih dalam Daftar Pemilih Tambahan (DPTb) | D22: LK | E22: =KANDANGAN!AG22+PESANGGARAN!AZ22+SARONGAN!X22+SUMBERAGUNG!AX22+SUMBERMULYO!AB22 -> 33
D23: PR | E23: =KANDANGAN!AG23+PESANGGARAN!AZ23+SARONGAN!X23+SUMBERAGUNG!AX23+SUMBERMULYO!AB23 -> 19
D24: JML | E24: =SUM(E22:E23) -> 52
B25: 3. | C25: Jumlah pengguna hak pilih dalam Daftar Pemilih Khusus (DPK) | D25: LK | E25: =KANDANGAN!AG25+PESANGGARAN!AZ25+SARONGAN!X25+SUMBERAGUNG!AX25+SUMBERMULYO!AB25 -> 291
D26: PR | E26: =KANDANGAN!AG26+PESANGGARAN!AZ26+SARONGAN!X26+SUMBERAGUNG!AX26+SUMBERMULYO!AB26 -> 311
D27: JML | E27: =SUM(E25:E26) -> 602
B28: 4. | C28: Jumlah Pengguna Hak Pilih (B.1+B.2+B.3) | D28: LK | E28: =E19+E22+E25 -> 16480
D29: PR | E29: =E20+E23+E26 -> 16998
D30: JML | E30: =SUM(E28:E29) -> 33478
A32: II | B32: DATA PENGGUNAAN SURAT SUARA
A33: 1 | B33: Jumlah surat suara yang diterima, termasuk surat suara cadangan 2,5% dari DPT | E33: =KANDANGAN!AG33+PESANGGARAN!AZ33+SARONGAN!X33+SUMBERAGUNG!AX33+SUMBERMULYO!AB33 -> 43944
A34: 2 | B34: Jumlah surat suara yang digunakan | E34: =KANDANGAN!AG34+PESANGGARAN!AZ34+SARONGAN!X34+SUMBERAGUNG!AX34+SUMBERMULYO!AB34 -> 33312
A35: 3 | B35: Jumlah surat suara dikembalikan oleh pemilih (karena rusak atau keliru coblos) | E35: =KANDANGAN!AG35+PESANGGARAN!AZ35+SARONGAN!X35+SUMBERAGUNG!AX35+SUMBERMULYO!AB35 -> 55
A36: 4 | B36: Jumlah surat suara yang tidak digunakan/tidak terpakai, termasuk sisa surat suara cadangan | E36: =E33-(E34+E35) -> 10577
A38: III | B38: DATA PEMILIH DISABILITAS
B39: Jumlah seluruh Pemilih disabilitas yang menggunakan hak pilih | D39: LK | E39: =KANDANGAN!AG39+PESANGGARAN!AZ39+SARONGAN!X39+SUMBERAGUNG!AX39+SUMBERMULYO!AB39 -> 24
D40: PR | E40: =KANDANGAN!AG40+PESANGGARAN!AZ40+SARONGAN!X40+SUMBERAGUNG!AX40+SUMBERMULYO!AB40 -> 19
D41: JML | E41: =SUM(E39:E40) -> 43
A43: IV | B43: DATA RINCIAN PEROLEHAN SUARA PASANGAN CALON BUPATI DAN WAKIL BUPATI
A44: NOMOR DAN NAMA CALON
A45: A.1 | B45: 1. | C45: Partai Kebangkitan Bangsa | E45: =KANDANGAN!AG45+PESANGGARAN!AZ45+SARONGAN!X45+SUMBERAGUNG!AX45+SUMBERMULYO!AB45 -> 1235
A46: A.2 | C46: 1. Dra. Hj. MA`MULAH HARUN, M.Pd.I. | E46: =KANDANGAN!AG46+PESANGGARAN!AZ46+SARONGAN!X46+SUMBERAGUNG!AX46+SUMBERMULYO!AB46 -> 2863
C47: 2. UBAIDILLAH, S.Fil.I. | E47: =KANDANGAN!AG47+PESANGGARAN!AZ47+SARONGAN!X47+SUMBERAGUNG!AX47+SUMBERMULYO!AB47 -> 458
C48: 3. Ir. H. YOYOK MULYADI, M.Si. | E48: =KANDANGAN!AG48+PESANGGARAN!AZ48+SARONGAN!X48+SUMBERAGUNG!AX48+SUMBERMULYO!AB48 -> 129
C49: 4. KHOIRUL ANWAR, S.Fil.I. | E49: =KANDANGAN!AG49+PESANGGARAN!AZ49+SARONGAN!X49+SUMBERAGUNG!AX49+SUMBERMULYO!AB49 -> 226
C50: 5. ARIF WIJAKSANA | E50: =KANDANGAN!AG50+PESANGGARAN!AZ50+SARONGAN!X50+SUMBERAGUNG!AX50+SUMBERMULYO!AB50 -> 221
C51: 6. Dr. SITI YUMNAH | E51: =KANDANGAN!AG51+PESANGGARAN!AZ51+SARONGAN!X51+SUMBERAGUNG!AX51+SUMBERMULYO!AB51 -> 93
C52: 7. MOHAMMAD ZAINI, M.Pd.I. | E52: =KANDANGAN!AG52+PESANGGARAN!AZ52+SARONGAN!X52+SUMBERAGUNG!AX52+SUMBERMULYO!AB52 -> 322
...

Sheet PESANGGARAN
C2: Kecamatan | D2: PESANGGARAN
C3: Kabupaten | D3: BANYUWANGI
C4: Provinsi | D4: JAWA TIMUR
C9: Kelurahan | D9: PESANGGARAN
A12: I | B12: DATA PEMILIH DAN PENGGUNAAN HAK PILIH | AZ12: JUMLAH AKHIR
A13: A | B13: DATA PEMILIH | E13: TPS 001 | F13: TPS 002 | G13: TPS 003 | H13: TPS 004 | I13: TPS 005 | J13: TPS 006 | K13: TPS 007 | L13: TPS 008 | M13: TPS 009 | N13: TPS 010 | O13: TPS 011 | P13: TPS 012 | Q13: TPS 013 | R13: TPS 014 | S13: TPS 015 | T13: TPS 016 | U13: TPS 017 | V13: TPS 018 | W13: TPS 019 | X13: TPS 020 | Y13: TPS 021 | Z13: TPS 022 | AA13: TPS 023 | AB13: TPS 024 | AC13: TPS 025 | AD13: TPS 026 | AE13: TPS 027 | AF13: TPS 028 | AG13: TPS 029 | AH13: TPS 030 | AI13: TPS 031 | AJ13: TPS 032 | AK13: TPS 033 | AL13: TPS 034 | AM13: TPS 035 | AN13: TPS 036 | AO13: TPS 037 | AP13: TPS 038 | AQ13: TPS 039 | AR13: TPS 040 | AS13: TPS 041 | AT13: TPS 042 | AU13: TPS 043 | AV13: TPS 044 | AW13: TPS 045 | AX13: TPS 046 | AY13: TPS 047
B14: Jumlah Pemilih dalam Daftar Pemilih Tetap (DPT) | D14: LK | E14: 138 | F14: 150 | G14: 141 | H14: 129 | I14: 146 | J14: 133 | K14: 83 | L14: 145 | M14: 142 | N14: 150 | O14: 147 | P14: 129 | Q14: 149 | R14: 134 | S14: 132 | T14: 136 | U14: 145 | V14: 131 | W14: 152 | X14: 155 | Y14: 115 | Z14: 109 | AA14: 205 | AB14: 127 | AC14: 144 | AD14: 128 | AE14: 118 | AF14: 129 | AG14: 118 | AH14: 144 | AI14: 112 | AJ14: 141 | AK14: 144 | AL14: 148 | AM14: 144 | AN14: 135 | AO14: 120 | AP14: 144 | AQ14: 142 | AR14: 146 | AS14: 130 | AT14: 132 | AU14: 128 | AV14: 134 | AW14: 146 | AX14: 146 | AY14: 125 | AZ14: =SUM(E14:AY14) -> 6421
D15: PR | E15: 141 | F15: 138 | G15: 130 | H15: 152 | I15: 151 | J15: 161 | K15: 83 | L15: 136 | M15: 135 | N15: 144 | O15: 142 | P15: 152 | Q15: 141 | R15: 132 | S15: 128 | T15: 157 | U15: 134 | V15: 126 | W15: 145 | X15: 140 | Y15: 107 | Z15: 113 | AA15: 94 | AB15: 130 | AC15: 149 | AD15: 144 | AE15: 126 | AF15: 111 | AG15: 126 | AH15: 136 | AI15: 109 | AJ15: 148 | AK15: 148 | AL15: 138 | AM15: 134 | AN15: 115 | AO15: 119 | AP15: 147 | AQ15: 153 | AR15: 142 | AS15: 148 | AT15: 160 | AU15: 157 | AV15: 160 | AW15: 146 | AX15: 144 | AY15: 145 | AZ15: =SUM(E15:AY15) -> 6417
D16: JML | E16: =SUM(E14:E15) -> 279 | F16: =SUM(F14:F15) -> 288 | G16: =SUM(G14:G15) -> 271 | H16: =SUM(H14:H15) -> 281 | I16: =SUM(I14:I15) -> 297 | J16: =SUM(J14:J15) -> 294 | K16: =SUM(K14:K15) -> 166 | L16: =SUM(L14:L15) -> 281 | ... AY16: =SUM(AY14:AY15) -> 270 | AZ16: =SUM(E16:AY16) -> 12838
A18: B | B18: PENGGUNA HAK PILIH
B19: 1. | C19: Jumlah pengguna hak pilih dalam Daftar Pemilih Tetap (DPT) | D19: LK | E19: 104 | F19: 115 | G19: 100 | H19: 90 | I19: 103 | J19: 97 | K19: 59 | L19: 108 | M19: 97 | N19: 106 | O19: 117 | P19: 90 | Q19: 113 | R19: 100 | S19: 109 | T19: 102 | U19: 105 | V19: 99 | W19: 119 | X19: 119 | Y19: 86 | Z19: 92 | AA19: 87 | AB19: 90 | AC19: 108 | AD19: 98 | AE19: 93 | AF19: 118 | AG19: 90 | AH19: 130 | AI19: 90 | AJ19: 106 | AK19: 107 | AL19: 114 | AM19: 114 | AN19: 103 | AO19: 96 | AP19: 108 | AQ19: 106 | AR19: 110 | AS19: 85 | AT19: 97 | AU19: 100 | AV19: 90 | AW19: 94 | AX19: 90 | AY19: 100 | AZ19: =SUM(E19:AY19) -> 4754
D20: PR | E20: 112 | F20: 119 | G20: 102 | H20: 111 | I20: 115 | J20: 122 | K20: 63 | L20: 110 | M20: 95 | N20: 116 | O20: 124 | P20: 107 | Q20: 111 | R20: 100 | S20: 103 | T20: 111 | U20: 97 | V20: 101 | W20: 113 | X20: 112 | Y20: 78 | Z20: 98 | AA20: 70 | AB20: 107 | AC20: 102 | AD20: 108 | AE20: 215 | AF20: 82 | AG20: 87 | AH20: 209 | AI20: 89 | AJ20: 107 | AK20: 110 | AL20: 100 | AM20: 103 | AN20: 92 | AO20: 92 | AP20: 118 | AQ20: 119 | AR20: 112 | AS20: 106 | AT20: 120 | AU20: 114 | AV20: 110 | AW20: 100 | AX20: 101 | AY20: 108 | AZ20: =SUM(E20:AY20) -> 5101
D21: JML | E21: =SUM(E19:E20) -> 216 | F21: =SUM(F19:F20) -> 234 | G21: =SUM(G19:G20) -> 202 | H21: =SUM(H19:H20) -> 201 | I21: =SUM(I19:I20) -> 218 | J21: =SUM(J19:J20) -> 219 | K21: =SUM(K19:K20) -> 122 | L21: =SUM(L19:L20) -> 218 | ... AY21: =SUM(AY19:AY20) -> 208 | AZ21: =SUM(E21:AY21) -> 9855
B22: 2. | C22: Jumlah pengguna hak pilih dalam Daftar Pemilih Tambahan (DPTb) | D22: LK | E22: 0 | F22: 0 | G22: 0 | H22: 0 | I22: 0 | J22: 0 | K22: 0 | L22: 0 | M22: 0 | N22: 0 | O22: 0 | P22: 1 | Q22: 0 | R22: 0 | S22: 0 | T22: 0 | U22: 0 | V22: 0 | W22: 0 | X22: 0 | Y22: 0 | Z22: 0 | AA22: 0 | AB22: 0 | AC22: 0 | AD22: 0 | AE22: 0 | AF22: 0 | AG22: 0 | AH22: 0 | AI22: 0 | AJ22: 2 | AK22: 0 | AL22: 0 | AM22: 0 | AN22: 0 | AO22: 0 | AP22: 0 | AQ22: 0 | AR22: 0 | AS22: 0 | AT22: 0 | AU22: 0 | AV22: 1 | AW22: 0 | AX22: 0 | AY22: 0 | AZ22: =SUM(E22:AY22) -> 4
D23: PR | E23: 0 | F23: 0 | G23: 0 | H23: 0 | I23: 0 | J23: 0 | K23: 0 | L23: 0 | M23: 0 | N23: 0 | O23: 0 | P23: 0 | Q23: 0 | R23: 0 | S23: 0 | T23: 0 | U23: 0 | V23: 0 | W23: 0 | X23: 0 | Y23: 0 | Z23: 0 | AA23: 0 | AB23: 0 | AC23: 0 | AD23: 1 | AE23: 0 | AF23: 0 | AG23: 0 | AH23: 0 | AI23: 0 | AJ23: 0 | AK23: 0 | AL23: 0 | AM23: 0 | AN23: 0 | AO23: 0 | AP23: 1 | AQ23: 0 | AR23: 1 | AS23: 0 | AT23: 0 | AU23: 0 | AV23: 0 | AW23: 0 | AX23: 0 | AY23: 0 | AZ23: =SUM(E23:AY23) -> 3
D24: JML | E24: =SUM(E22:E23) -> 0 | F24: =SUM(F22:F23) -> 0 | G24: =SUM(G22:G23) -> 0 | H24: =SUM(H22:H23) -> 0 | I24: =SUM(I22:I23) -> 0 | J24: =SUM(J22:J23) -> 0 | K24: =SUM(K22:K23) -> 0 | L24: =SUM(L22:L23) -> 0 | ... AY24: =SUM(AY22:AY23) -> 0 | AZ24: =SUM(E24:AY24) -> 7
B25: 3. | C25: Jumlah pengguna hak pilih dalam Daftar Pemilih Khusus (DPK) | D25: LK | E25: 3 | F25: 0 | G25: 1 | H25: 0 | I25: 1 | J25: 1 | K25: 0 | L25: 5 | M25: 2 | N25: 2 | O25: 0 | P25: 1 | Q25: 3 | R25: 0 | S25: 1 | T25: 2 | U25: 2 | V25: 2 | W25: 0 | X25: 3 | Y25: 0 | Z25: 1 | AA25: 0 | AB25: 1 | AC25: 1 | AD25: 0 | AE25: 0 | AF25: 0 | AG25: 0 | AH25: 4 | AI25: 0 | AJ25: 2 | AK25: 0 | AL25: 1 | AM25: 1 | AN25: 0 | AO25: 0 | AP25: 3 | AQ25: 2 | AR25: 1 | AS25: 5 | AT25: 4 | AU25: 3 | AV25: 3 | AW25: 1 | AX25: 1 | AY25: 3 | AZ25: =SUM(E25:AY25) -> 66
D26: PR | E26: 1 | F26: 0 | G26: 1 | H26: 4 | I26: 1 | J26: 1 | K26: 0 | L26: 2 | M26: 4 | N26: 1 | O26: 0 | P26: 1 | Q26: 3 | R26: 1 | S26: 0 | T26: 1 | U26: 3 | V26: 1 | W26: 0 | X26: 2 | Y26: 0 | Z26: 0 | AA26: 1 | AB26: 1 | AC26: 0 | AD26: 2 | AE26: 0 | AF26: 3 | AG26: 0 | AH26: 2 | AI26: 1 | AJ26: 0 | AK26: 0 | AL26: 2 | AM26: 0 | AN26: 0 | AO26: 0 | AP26: 2 | AQ26: 1 | AR26: 1 | AS26: 6 | AT26: 5 | AU26: 5 | AV26: 5 | AW26: 5 | AX26: 1 | AY26: 1 | AZ26: =SUM(E26:AY26) -> 71
D27: JML | E27: =SUM(E25:E26) -> 4 | F27: =SUM(F25:F26) -> 0 | G27: =SUM(G25:G26) -> 2 | H27: =SUM(H25:H26) -> 4 | I27: =SUM(I25:I26) -> 2 | J27: =SUM(J25:J26) -> 2 | K27: =SUM(K25:K26) -> 0 | L27: =SUM(L25:L26) -> 7 | ... AY27: =SUM(AY25:AY26) -> 4 | AZ27: =SUM(E27:AY27) -> 137
B28: 4. | C28: Jumlah Pengguna Hak Pilih (B.1+B.2+B.3) | D28: LK | E28: =SUM(E19,E22,E25) -> 107 | F28: =SUM(F19,F22,F25) -> 115 | G28: =SUM(G19,G22,G25) -> 101 | H28: =SUM(H19,H22,H25) -> 90 | I28: =SUM(I19,I22,I25) -> 104 | J28: =SUM(J19,J22,J25) -> 98 | K28: =SUM(K19,K22,K25) -> 59 | L28: =SUM(L19,L22,L25) -> 113 | ... AY28: =SUM(AY19,AY22,AY25) -> 103 | AZ28: =SUM(E28:AY28) -> 4824
D29: PR | E29: =SUM(E20,E23,E26) -> 113 | F29: =SUM(F20,F23,F26) -> 119 | G29: =SUM(G20,G23,G26) -> 103 | H29: =SUM(H20,H23,H26) -> 115 | I29: =SUM(I20,I23,I26) -> 116 | J29: =SUM(J20,J23,J26) -> 123 | K29: =SUM(K20,K23,K26) -> 63 | L29: =SUM(L20,L23,L26) -> 112 | ... AY29: =SUM(AY20,AY23,AY26) -> 109 | AZ29: =SUM(E29:AY29) -> 5175
D30: JML | E30: =SUM(E28:E29) -> 220 | F30: =SUM(F28:F29) -> 234 | G30: =SUM(G28:G29) -> 204 | H30: =SUM(H28:H29) -> 205 | I30: =SUM(I28:I29) -> 220 | J30: =SUM(J28:J29) -> 221 | K30: =SUM(K28:K29) -> 122 | L30: =SUM(L28:L29) -> 225 | ... AY30: =SUM(AY28:AY29) -> 212 | AZ30: =SUM(E30:AY30) -> 9999
A32: II | B32: DATA PENGGUNAAN SURAT SUARA
A33: 1 | B33: Jumlah surat suara yang diterima, termasuk surat suara cadangan 2,5% dari DPT | E33: 285 | F33: 294 | G33: 277 | H33: 287 | I33: 303 | J33: 300 | K33: 170 | L33: 285 | M33: 283 | N33: 300 | O33: 295 | P33: 287 | Q33: 296 | R33: 272 | S33: 276 | T33: 59 | U33: 245 | V33: 253 | W33: 303 | X33: 301 | Y33: 297 | Z33: 297 | AA33: 263 | AB33: 253 | AC33: 299 | AD33: 279 | AE33: 269 | AF33: 265 | AG33: 265 | AH33: 285 | AI33: 226 | AJ33: 295 | AK33: 298 | AL33: 292 | AM33: 284 | AN33: 255 | AO33: 244 | AP33: 298 | AQ33: 301 | AR33: 294 | AS33: 284 | AT33: 298 | AU33: 291 | AV33: 300 | AW33: 298 | AX33: 296 | AY33: 276 | AZ33: =SUM(E33:AY33) -> 12973
A34: 2 | B34: Jumlah surat suara yang digunakan | E34: 220 | F34: 234 | G34: 204 | H34: 205 | I34: 220 | J34: 221 | K34: 122 | L34: 225 | M34: 198 | N34: 225 | O34: 241 | P34: 200 | Q34: 230 | R34: 201 | S34: 213 | T34: 216 | U34: 207 | V34: 203 | W34: 232 | X34: 236 | Y34: 164 | Z34: 191 | AA34: 158 | AB34: 200 | AC34: 222 | AD34: 209 | AE34: 198 | AF34: 200 | AG34: 179 | AH34: 285 | AI34: 180 | AJ34: 217 | AK34: 217 | AL34: 217 | AM34: 218 | AN34: 195 | AO34: 188 | AP34: 232 | AQ34: 228 | AR34: 225 | AS34: 202 | AT34: 226 | AU34: 222 | AV34: 209 | AW34: 200 | AX34: 193 | AY34: 212 | AZ34: =SUM(E34:AY34) -> 9840
A35: 3 | B35: Jumlah surat suara dikembalikan oleh pemilih (karena rusak atau keliru coblos) | E35: 0 | F35: 0 | G35: 1 | H35: 0 | I35: 0 | J35: 0 | K35: 0 | L35: 1 | M35: 0 | N35: 0 | O35: 0 | P35: 0 | Q35: 0 | R35: 0 | S35: 0 | T35: 0 | U35: 0 | V35: 0 | W35: 0 | X35: 4 | Y35: 0 | Z35: 0 | AA35: 0 | AB35: 0 | AC35: 0 | AD35: 1 | AE35: 0 | AF35: 1 | AG35: 0 | AH35: 0 | AI35: 0 | AJ35: 0 | AK35: 3 | AL35: 0 | AM35: 0 | AN35: 0 | AO35: 0 | AP35: 0 | AQ35: 0 | AR35: 0 | AS35: 0 | AT35: 0 | AU35: 0 | AV35: 0 | AW35: 0 | AX35: 0 | AY35: 4 | AZ35: =SUM(E35:AY35) -> 15
A36: 4 | B36: Jumlah surat suara yang tidak digunakan/tidak terpakai, termasuk sisa surat suara cadangan | E36: =E33-(E34+E35) -> 65 | F36: =F33-(F34+F35) -> 60 | G36: =G33-(G34+G35) -> 72 | H36: =H33-(H34+H35) -> 82 | I36: =I33-(I34+I35) -> 83 | J36: =J33-(J34+J35) -> 79 | K36: =K33-(K34+K35) -> 48 | L36: =L33-(L34+L35) -> 59 | ... AY36: =AY33-(AY34+AY35) -> 60 | AZ36: =SUM(E36:AY36) -> 3118
A38: III | B38: DATA PEMILIH DISABILITAS
B39: Jumlah seluruh Pemilih disabilitas yang menggunakan hak pilih | D39: LK | E39: 0 | F39: 0 | G39: 0 | H39: 0 | I39: 0 | J39: 0 | K39: 0 | L39: 0 | M39: 0 | N39: 0 | O39: 0 | P39: 0 | Q39: 0 | R39: 0 | S39: 0 | T39: 0 | U39: 1 | V39: 1 | W39: 0 | X39: 0 | Y39: 0 | Z39: 2 | AA39: 0 | AB39: 1 | AC39: 0 | AD39: 0 | AE39: 0 | AF39: 0 | AG39: 0 | AH39: 0 | AI39: 0 | AJ39: 0 | AK39: 0 | AL39: 0 | AM39: 0 | AN39: 0 | AO39: 0 | AP39: 0 | AQ39: 1 | AR39: 0 | AS39: 1 | AT39: 0 | AU39: 0 | AV39: 0 | AW39: 0 | AX39: 0 | AY39: 0 | AZ39: =SUM(E39:AY39) -> 7
D40: PR | E40: 0 | F40: 0 | G40: 0 | H40: 0 | I40: 0 | J40: 0 | K40: 0 | L40: 0 | M40: 0 | N40: 0 | O40: 0 | P40: 0 | Q40: 0 | R40: 0 | S40: 1 | T40: 0 | U40: 0 | V40: 0 | W40: 0 | X40: 0 | Y40: 0 | Z40: 1 | AA40: 0 | AB40: 1 | AC40: 0 | AD40: 0 | AE40: 0 | AF40: 0 | AG40: 0 | AH40: 0 | AI40: 0 | AJ40: 0 | AK40: 0 | AL40: 0 | AM40: 0 | AN40: 0 | AO40: 0 | AP40: 0 | AQ40: 0 | AR40: 0 | AS40: 0 | AT40: 0 | AU40: 0 | AV40: 0 | AW40: 0 | AX40: 0 | AY40: 0 | AZ40: =SUM(E40:AY40) -> 3
D41: JML | E41: =SUM(E39:E40) -> 0 | F41: =SUM(F39:F40) -> 0 | G41: =SUM(G39:G40) -> 0 | H41: =SUM(H39:H40) -> 0 | I41: =SUM(I39:I40) -> 0 | J41: =SUM(J39:J40) -> 0 | K41: =SUM(K39:K40) -> 0 | L41: =SUM(L39:L40) -> 0 | ... AY41: =SUM(AY39:AY40) -> 0 | AZ41: =SUM(E41:AY41) -> 10
A43: IV | B43: DATA RINCIAN PEROLEHAN SUARA PASANGAN CALON BUPATI DAN WAKIL BUPATI
A44: NOMOR DAN NAMA CALON
A45: A.1 | B45: 1. | C45: Partai Kebangkitan Bangsa | E45: 15 | F45: 7 | G45: 12 | H45: 6 | I45: 15 | J45: 13 | K45: 11 | L45: 9 | M45: 3 | N45: 4 | O45: 10 | P45: 10 | Q45: 7 | R45: 13 | S45: 7 | T45: 6 | U45: 7 | V45: 10 | W45: 8 | X45: 12 | Y45: 1 | Z45: 2 | AA45: 4 | AB45: 3 | AC45: 8 | AD45: 17 | AE45: 7 | AF45: 0 | AG45: 7 | AH45: 10 | AI45: 6 | AJ45: 4 | AK45: 5 | AL45: 13 | AM45: 4 | AN45: 5 | AO45: 4 | AP45: 7 | AQ45: 8 | AR45: 10 | AS45: 8 | AT45: 10 | AU45: 11 | AV45: 3 | AW45: 9 | AX45: 5 | AY45: 8 | AZ45: =SUM(E45:AY45) -> 364
A46: A.2 | C46: 1. Dra. Hj. MA`MULAH HARUN, M.Pd.I. | E46: 10 | F46: 20 | G46: 10 | H46: 20 | I46: 16 | J46: 18 | K46: 5 | L46: 13 | M46: 11 | N46: 15 | O46: 6 | P46: 31 | Q46: 11 | R46: 19 | S46: 4 | T46: 24 | U46: 19 | V46: 3 | W46: 10 | X46: 6 | Y46: 2 | Z46: 5 | AA46: 1 | AB46: 6 | AC46: 7 | AD46: 14 | AE46: 2 | AF46: 1 | AG46: 8 | AH46: 19 | AI46: 19 | AJ46: 15 | AK46: 37 | AL46: 27 | AM46: 5 | AN46: 3 | AO46: 31 | AP46: 31 | AQ46: 14 | AR46: 36 | AS46: 16 | AT46: 8 | AU46: 9 | AV46: 8 | AW46: 15 | AX46: 3 | AY46: 12 | AZ46: =SUM(E46:AY46) -> 625
C47: 2. UBAIDILLAH, S.Fil.I. | E47: 6 | F47: 1 | G47: 3 | H47: 1 | I47: 3 | J47: 24 | K47: 31 | L47: 1 | M47: 9 | N47: 2 | O47: 2 | P47: 2 | Q47: 1 | R47: 2 | S47: 1 | T47: 2 | U47: 8 | V47: 1 | W47: 1 | X47: 0 | Y47: 1 | Z47: 1 | AA47: 0 | AB47: 0 | AC47: 2 | AD47: 5 | AE47: 3 | AF47: 0 | AG47: 2 | AH47: 44 | AI47: 9 | AJ47: 4 | AK47: 3 | AL47: 2 | AM47: 2 | AN47: 0 | AO47: 4 | AP47: 5 | AQ47: 1 | AR47: 3 | AS47: 2 | AT47: 4 | AU47: 0 | AV47: 0 | AW47: 1 | AX47: 1 | AY47: 2 | AZ47: =SUM(E47:AY47) -> 202
C48: 3. Ir. H. YOYOK MULYADI, M.Si. | E48: 1 | F48: 1 | G48: 2 | H48: 1 | I48: 3 | J48: 1 | K48: 1 | L48: 1 | M48: 0 | N48: 1 | O48: 0 | P48: 1 | Q48: 1 | R48: 3 | S48: 0 | T48: 0 | U48: 1 | V48: 1 | W48: 1 | X48: 1 | Y48: 0 | Z48: 0 | AA48: 0 | AB48: 0 | AC48: 0 | AD48: 2 | AE48: 1 | AF48: 0 | AG48: 1 | AH48: 0 | AI48: 0 | AJ48: 0 | AK48: 0 | AL48: 0 | AM48: 1 | AN48: 0 | AO48: 2 | AP48: 1 | AQ48: 0 | AR48: 2 | AS48: 0 | AT48: 0 | AU48: 1 | AV48: 1 | AW48: 1 | AX48: 1 | AY48: 0 | AZ48: =SUM(E48:AY48) -> 35
C49: 4. KHOIRUL ANWAR, S.Fil.I. | E49: 0 | F49: 2 | G49: 2 | H49: 2 | I49: 1 | J49: 1 | K49: 0 | L49: 1 | M49: 0 | N49: 5 | O49: 0 | P49: 0 | Q49: 1 | R49: 2 | S49: 1 | T49: 1 | U49: 3 | V49: 1 | W49: 1 | X49: 0 | Y49: 0 | Z49: 1 | AA49: 1 | AB49: 1 | AC49: 0 | AD49: 1 | AE49: 1 | AF49: 1 | AG49: 1 | AH49: 2 | AI49: 1 | AJ49: 1 | AK49: 1 | AL49: 1 | AM49: 1 | AN49: 0 | AO49: 2 | AP49: 1 | AQ49: 2 | AR49: 4 | AS49: 1 | AT49: 1 | AU49: 1 | AV49: 2 | AW49: 1 | AX49: 1 | AY49: 0 | AZ49: =SUM(E49:AY49) -> 54
C50: 5. ARIF WIJAKSANA | E50: 0 | F50: 1 | G50: 1 | H50: 0 | I50: 2 | J50: 2 | K50: 0 | L50: 4 | M50: 0 | N50: 1 | O50: 0 | P50: 2 | Q50: 3 | R50: 2 | S50: 2 | T50: 0 | U50: 0 | V50: 1 | W50: 0 | X50: 0 | Y50: 2 | Z50: 2 | AA50: 1 | AB50: 6 | AC50: 0 | AD50: 1 | AE50: 0 | AF50: 0 | AG50: 0 | AH50: 0 | AI50: 1 | AJ50: 2 | AK50: 1 | AL50: 3 | AM50: 2 | AN50: 0 | AO50: 5 | AP50: 2 | AQ50: 0 | AR50: 0 | AS50: 1 | AT50: 0 | AU50: 0 | AV50: 0 | AW50: 3 | AX50: 0 | AY50: 0 | AZ50: =SUM(E50:AY50) -> 53
C51: 6. Dr. SITI YUMNAH | E51: 1 | F51: 5 | G51: 2 | H51: 3 | I51: 0 | J51: 0 | K51: 0 | L51: 0 | M51: 0 | N51: 0 | O51: 2 | P51: 0 | Q51: 0 | R51: 0 | S51: 0 | T51: 1 | U51: 0 | V51: 0 | W51: 1 | X51: 0 | Y51: 1 | Z51: 0 | AA51: 0 | AB51: 0 | AC51: 2 | AD51: 1 | AE51: 3 | AF51: 2 | AG51: 0 | AH51: 1 | AI51: 0 | AJ51: 0 | AK51: 1 | AL51: 2 | AM51: 1 | AN51: 1 | AO51: 0 | AP51: 0 | AQ51: 1 | AR51: 1 | AS51: 1 | AT51: 0 | AU51: 1 | AV51: 0 | AW51: 1 | AX51: 1 | AY51: 0 | AZ51: =SUM(E51:AY51) -> 36
...

Sheet SARONGAN
C2: Kecamatan | D2: PESANGGARAN
C3: Kabupaten | D3: BANYUWANGI
C4: Provinsi | D4: JAWA TIMUR
C9: Kelurahan | D9: SARONGAN
A12: I | B12: DATA PEMILIH DAN PENGGUNAAN HAK PILIH | X12: JUMLAH AKHIR
A13: A | B13: DATA PEMILIH | E13: TPS 001 | F13: TPS 002 | G13: TPS 003 | H13: TPS 004 | I13: TPS 005 | J13: TPS 006 | K13: TPS 007 | L13: TPS 008 | M13: TPS 009 | N13: TPS 010 | O13: TPS 011 | P13: TPS 012 | Q13: TPS 013 | R13: TPS 014 | S13: TPS 015 | T13: TPS 016 | U13: TPS 017 | V13: TPS 018 | W13: TPS 019
B14: Jumlah Pemilih dalam Daftar Pemilih Tetap (DPT) | D14: LK | E14: 105 | F14: 100 | G14: 119 | H14: 147 | I14: 139 | J14: 145 | K14: 140 | L14: 144 | M14: 152 | N14: 145 | O14: 140 | P14: 139 | Q14: 144 | R14: 119 | S14: 121 | T14: 142 | U14: 98 | V14: 103 | W14: 107 | X14: =SUM(E14:W14) -> 2449
D15: PR | E15: 98 | F15: 99 | G15: 114 | H15: 147 | I15: 133 | J15: 147 | K15: 147 | L15: 148 | M15: 141 | N15: 144 | O15: 146 | P15: 140 | Q15: 150 | R15: 132 | S15: 127 | T15: 140 | U15: 89 | V15: 107 | W15: 107 | X15: =SUM(E15:W15) -> 2456
D16: JML | E16: =SUM(E14:E15) -> 203 | F16: =SUM(F14:F15) -> 199 | G16: =SUM(G14:G15) -> 233 | H16: =SUM(H14:H15) -> 294 | I16: =SUM(I14:I15) -> 272 | J16: =SUM(J14:J15) -> 292 | K16: =SUM(K14:K15) -> 287 | L16: =SUM(L14:L15) -> 292 | ... W16: =SUM(W14:W15) -> 214 | X16: =SUM(E16:W16) -> 4905
A18: B | B18: PENGGUNA HAK PILIH
B19: 1. | C19: Jumlah pengguna hak pilih dalam Daftar Pemilih Tetap (DPT) | D19: LK | E19: 89 | F19: 74 | G19: 100 | H19: 110 | I19: 112 | J19: 105 | K19: 119 | L19: 102 | M19: 115 | N19: 108 | O19: 105 | P19: 95 | Q19: 117 | R19: 92 | S19: 90 | T19: 88 | U19: 72 | V19: 81 | W19: 80 | X19: =SUM(E19:W19) -> 1854
D20: PR | E20: 75 | F20: 76 | G20: 101 | H20: 117 | I20: 102 | J20: 105 | K20: 115 | L20: 115 | M20: 104 | N20: 112 | O20: 121 | P20: 106 | Q20: 122 | R20: 99 | S20: 99 | T20: 104 | U20: 73 | V20: 87 | W20: 72 | X20: =SUM(E20:W20) -> 1905
D21: JML | E21: =SUM(E19:E20) -> 164 | F21: =SUM(F19:F20) -> 150 | G21: =SUM(G19:G20) -> 201 | H21: =SUM(H19:H20) -> 227 | I21: =SUM(I19:I20) -> 214 | J21: =SUM(J19:J20) -> 210 | K21: =SUM(K19:K20) -> 234 | L21: =SUM(L19:L20) -> 217 | ... W21: =SUM(W19:W20) -> 152 | X21: =SUM(E21:W21) -> 3759
B22: 2. | C22: Jumlah pengguna hak pilih dalam Daftar Pemilih Tambahan (DPTb) | D22: LK | E22: 0 | F22: 0 | G22: 0 | H22: 0 | I22: 0 | J22: 0 | K22: 0 | L22: 0 | M22: 0 | N22: 0 | O22: 0 | P22: 0 | Q22: 0 | R22: 0 | S22: 0 | T22: 0 | U22: 0 | V22: 0 | W22: 3 | X22: =SUM(E22:W22) -> 3
D23: PR | E23: 0 | F23: 0 | G23: 0 | H23: 0 | I23: 0 | J23: 0 | K23: 0 | L23: 0 | M23: 0 | N23: 0 | O23: 0 | P23: 2 | Q23: 0 | R23: 0 | S23: 0 | T23: 0 | U23: 0 | V23: 0 | W23: 4 | X23: =SUM(E23:W23) -> 6
D24: JML | E24: =SUM(E22:E23) -> 0 | F24: =SUM(F22:F23) -> 0 | G24: =SUM(G22:G23) -> 0 | H24: =SUM(H22:H23) -> 0 | I24: =SUM(I22:I23) -> 0 | J24: =SUM(J22:J23) -> 0 | K24: =SUM(K22:K23) -> 0 | L24: =SUM(L22:L23) -> 0 | ... W24: =SUM(W22:W23) -> 7 | X24: =SUM(E24:W24) -> 9
B25: 3. | C25: Jumlah pengguna hak pilih dalam Daftar Pemilih Khusus (DPK) | D25: LK | E25: 1 | F25: 1 | G25: 0 | H25: 12 | I25: 0 | J25: 1 | K25: 1 | L25: 4 | M25: 3 | N25: 0 | O25: 2 | P25: 1 | Q25: 1 | R25: 5 | S25: 0 | T25: 0 | U25: 2 | V25: 3 | W25: 0 | X25: =SUM(E25:W25) -> 37
D26: PR | E26: 1 | F26: 1 | G26: 0 | H26: 4 | I26: 5 | J26: 0 | K26: 3 | L26: 2 | M26: 2 | N26: 2 | O26: 0 | P26: 4 | Q26: 2 | R26: 4 | S26: 1 | T26: 0 | U26: 3 | V26: 5 | W26: 0 | X26: =SUM(E26:W26) -> 39
D27: JML | E27: =SUM(E25:E26) -> 2 | F27: =SUM(F25:F26) -> 2 | G27: =SUM(G25:G26) -> 0 | H27: =SUM(H25:H26) -> 16 | I27: =SUM(I25:I26) -> 5 | J27: =SUM(J25:J26) -> 1 | K27: =SUM(K25:K26) -> 4 | L27: =SUM(L25:L26) -> 6 | ... W27: =SUM(W25:W26) -> 0 | X27: =SUM(E27:W27) -> 76
B28: 4. | C28: Jumlah Pengguna Hak Pilih (B.1+B.2+B.3) | D28: LK | E28: =SUM(E19,E22,E25) -> 90 | F28: =SUM(F19,F22,F25) -> 75 | G28: =SUM(G19,G22,G25) -> 100 | H28: =SUM(H19,H22,H25) -> 122 | I28: =SUM(I19,I22,I25) -> 112 | J28: =SUM(J19,J22,J25) -> 106 | K28: =SUM(K19,K22,K25) -> 120 | L28: =SUM(L19,L22,L25) -> 106 | M28: =SUM(M19,M22,M25) -> 118 | N28: 108 | O28: =SUM(O19,O22,O25) -> 107 | P28: =SUM(P19,P22,P25) -> 96 | Q28: =SUM(Q19,Q22,Q25) -> 118 | R28: =SUM(R19,R22,R25) -> 97 | S28: =SUM(S19,S22,S25) -> 90 | T28: =SUM(T19,T22,T25) -> 88 | U28: =SUM(U19,U22,U25) -> 74 | V28: =SUM(V19,V22,V25) -> 84 | W28: =SUM(W19,W22,W25) -> 83 | X28: =SUM(E28:W28) -> 1894
D29: PR | E29: =SUM(E20,E23,E26) -> 76 | F29: =SUM(F20,F23,F26) -> 77 | G29: =SUM(G20,G23,G26) -> 101 | H29: =SUM(H20,H23,H26) -> 121 | I29: =SUM(I20,I23,I26) -> 107 | J29: =SUM(J20,J23,J26) -> 105 | K29: =SUM(K20,K23,K26) -> 118 | L29: =SUM(L20,L23,L26) -> 117 | ... W29: =SUM(W20,W23,W26) -> 76 | X29: =SUM(E29:W29) -> 1950
D30: JML | E30: =SUM(E28:E29) -> 166 | F30: =SUM(F28:F29) -> 152 | G30: =SUM(G28:G29) -> 201 | H30: =SUM(H28:H29) -> 243 | I30: =SUM(I28:I29) -> 219 | J30: =SUM(J28:J29) -> 211 | K30: =SUM(K28:K29) -> 238 | L30: =SUM(L28:L29) -> 223 | ... W30: =SUM(W28:W29) -> 159 | X30: =SUM(E30:W30) -> 3844
A32: II | B32: DATA PENGGUNAAN SURAT SUARA
A33: 1 | B33: Jumlah surat suara yang diterima, termasuk surat suara cadangan 2,5% dari DPT | E33: 208 | F33: 203 | G33: 240 | H33: 301 | I33: 278 | J33: 296 | K33: 293 | L33: 299 | M33: 299 | N33: 295 | O33: 292 | P33: 285 | Q33: 300 | R33: 257 | S33: 253 | T33: 288 | U33: 191 | V33: 215 | W33: 219 | X33: =SUM(E33:W33) -> 5012
A34: 2 | B34: Jumlah surat suara yang digunakan | E34: 166 | F34: 152 | G34: 201 | H34: 243 | I34: 219 | J34: 211 | K34: 238 | L34: 223 | M34: 224 | N34: 222 | O34: 228 | P34: 208 | Q34: 242 | R34: 200 | S34: 190 | T34: 192 | U34: 150 | V34: 176 | W34: 159 | X34: =SUM(E34:W34) -> 3844
A35: 3 | B35: Jumlah surat suara dikembalikan oleh pemilih (karena rusak atau keliru coblos) | E35: 0 | F35: 0 | G35: 0 | H35: 2 | I35: 0 | J35: 0 | K35: 1 | L35: 0 | M35: 0 | N35: 0 | O35: 0 | P35: 0 | Q35: 0 | R35: 0 | S35: 0 | T35: 0 | U35: 0 | V35: 0 | W35: 0 | X35: =SUM(E35:W35) -> 3
A36: 4 | B36: Jumlah surat suara yang tidak digunakan/tidak terpakai, termasuk sisa surat suara cadangan | E36: =E33-(E34+E35) -> 42 | F36: =F33-(F34+F35) -> 51 | G36: =G33-(G34+G35) -> 39 | H36: =H33-(H34+H35) -> 56 | I36: =I33-(I34+I35) -> 59 | J36: =J33-(J34+J35) -> 85 | K36: =K33-(K34+K35) -> 54 | L36: =L33-(L34+L35) -> 76 | ... W36: =W33-(W34+W35) -> 60 | X36: =SUM(E36:W36) -> 1165
A38: III | B38: DATA PEMILIH DISABILITAS
B39: Jumlah seluruh Pemilih disabilitas yang menggunakan hak pilih | D39: LK | E39: 0 | F39: 0 | G39: 0 | H39: 2 | I39: 0 | J39: 0 | K39: 0 | L39: 0 | M39: 0 | N39: 0 | O39: 0 | P39: 0 | Q39: 0 | R39: 0 | S39: 0 | T39: 0 | U39: 0 | V39: 0 | W39: 0 | X39: =SUM(E39:W39) -> 2
D40: PR | E40: 0 | F40: 0 | G40: 0 | H40: 0 | I40: 1 | J40: 0 | K40: 0 | L40: 0 | M40: 0 | N40: 1 | O40: 0 | P40: 0 | Q40: 0 | R40: 1 | S40: 1 | T40: 0 | U40: 0 | V40: 0 | W40: 0 | X40: =SUM(E40:W40) -> 4
D41: JML | E41: =SUM(E39:E40) -> 0 | F41: =SUM(F39:F40) -> 0 | G41: =SUM(G39:G40) -> 0 | H41: =SUM(H39:H40) -> 2 | I41: =SUM(I39:I40) -> 1 | J41: =SUM(J39:J40) -> 0 | K41: =SUM(K39:K40) -> 0 | L41: =SUM(L39:L40) -> 0 | ... W41: =SUM(W39:W40) -> 0 | X41: =SUM(E41:W41) -> 6
A43: IV | B43: DATA RINCIAN PEROLEHAN SUARA PASANGAN CALON BUPATI DAN WAKIL BUPATI
A44: NOMOR DAN NAMA CALON
A45: A.1 | B45: 1. | C45: Partai Kebangkitan Bangsa | E45: 11 | F45: 6 | G45: 10 | H45: 10 | I45: 5 | J45: 4 | K45: 5 | L45: 6 | M45: 11 | N45: 6 | O45: 4 | P45: 4 | Q45: 13 | R45: 6 | S45: 4 | T45: 4 | U45: 9 | V45: 3 | W45: 4 | X45: =SUM(E45:W45) -> 125
A46: A.2 | C46: 1. Dra. Hj. MA`MULAH HARUN, M.Pd.I. | E46: 17 | F46: 9 | G46: 15 | H46: 34 | I46: 21 | J46: 26 | K46: 54 | L46: 43 | M46: 39 | N46: 27 | O46: 56 | P46: 36 | Q46: 13 | R46: 19 | S46: 26 | T46: 15 | U46: 9 | V46: 13 | W46: 14 | X46: =SUM(E46:W46) -> 486
C47: 2. UBAIDILLAH, S.Fil.I. | E47: 9 | F47: 3 | G47: 7 | H47: 0 | I47: 0 | J47: 2 | K47: 3 | L47: 1 | M47: 1 | N47: 4 | O47: 1 | P47: 4 | Q47: 0 | R47: 2 | S47: 2 | T47: 3 | U47: 2 | V47: 2 | W47: 3 | X47: =SUM(E47:W47) -> 49
C48: 3. Ir. H. YOYOK MULYADI, M.Si. | E48: 0 | F48: 2 | G48: 0 | H48: 1 | I48: 0 | J48: 1 | K48: 1 | L48: 0 | M48: 0 | N48: 1 | O48: 1 | P48: 0 | Q48: 0 | R48: 0 | S48: 0 | T48: 0 | U48: 0 | V48: 3 | W48: 0 | X48: =SUM(E48:W48) -> 10
C49: 4. KHOIRUL ANWAR, S.Fil.I. | E49: 1 | F49: 4 | G49: 1 | H49: 3 | I49: 0 | J49: 0 | K49: 1 | L49: 1 | M49: 2 | N49: 5 | O49: 2 | P49: 3 | Q49: 2 | R49: 0 | S49: 0 | T49: 2 | U49: 2 | V49: 2 | W49: 0 | X49: =SUM(E49:W49) -> 31
C50: 5. ARIF WIJAKSANA | E50: 0 | F50: 0 | G50: 1 | H50: 1 | I50: 0 | J50: 1 | K50: 2 | L50: 0 | M50: 2 | N50: 1 | O50: 2 | P50: 0 | Q50: 1 | R50: 2 | S50: 0 | T50: 2 | U50: 0 | V50: 1 | W50: 0 | X50: =SUM(E50:W50) -> 16
C51: 6. Dr. SITI YUMNAH | E51: 0 | F51: 0 | G51: 1 | H51: 1 | I51: 1 | J51: 0 | K51: 0 | L51: 1 | M51: 1 | N51: 0 | O51: 0 | P51: 1 | Q51: 0 | R51: 0 | S51: 0 | T51: 0 | U51: 0 | V51: 0 | W51: 0 | X51: =SUM(E51:W51) -> 6
...

Sheet SUMBERAGUNG
C2: Kecamatan | D2: PESANGGARAN
C3: Kabupaten | D3: BANYUWANGI
C4: Provinsi | D4: JAWA TIMUR
C9: Kelurahan | D9: SUMBERAGUNG
A12: I | B12: DATA PEMILIH DAN PENGGUNAAN HAK PILIH | AX12: JUMLAH AKHIR
A13: A | B13: DATA PEMILIH | E13: TPS 001 | F13: TPS 002 | G13: TPS 003 | H13: TPS 004 | I13: TPS 005 | J13: TPS 006 | K13: TPS 007 | L13: TPS 008 | M13: TPS 009 | N13: TPS 010 | O13: TPS 011 | P13: TPS 012 | Q13: TPS 013 | R13: TPS 014 | S13: TPS 015 | T13: TPS 016 | U13: TPS 017 | V13: TPS 018 | W13: TPS 019 | X13: TPS 020 | Y13: TPS 021 | Z13: TPS 022 | AA13: TPS 023 | AB13: TPS 024 | AC13: TPS 025 | AD13: TPS 026 | AE13: TPS 027 | AF13: TPS 028 | AG13: TPS 029 | AH13: TPS 030 | AI13: TPS 031 | AJ13: TPS 032 | AK13: TPS 033 | AL13: TPS 034 | AM13: TPS 035 | AN13: TPS 036 | AO13: TPS 037 | AP13: TPS 038 | AQ13: TPS 039 | AR13: TPS 040 | AS13: TPS 041 | AT13: TPS 042 | AU13: TPS 043 | AV13: TPS 044 | AW13: TPS 045
B14: Jumlah Pemilih dalam Daftar Pemilih Tetap (DPT) | D14: LK | E14: 137 | F14: 149 | G14: 147 | H14: 151 | I14: 145 | J14: 148 | K14: 145 | L14: 133 | M14: 129 | N14: 139 | O14: 143 | P14: 143 | Q14: 142 | R14: 131 | S14: 109 | T14: 97 | U14: 120 | V14: 123 | W14: 133 | X14: 134 | Y14: 129 | Z14: 149 | AA14: 134 | AB14: 141 | AC14: 132 | AD14: 150 | AE14: 129 | AF14: 96 | AG14: 138 | AH14: 125 | AI14: 142 | AJ14: 149 | AK14: 153 | AL14: 140 | AM14: 153 | AN14: 140 | AO14: 135 | AP14: 128 | AQ14: 149 | AR14: 114 | AS14: 114 | AT14: 120 | AU14: 127 | AV14: 140 | AW14: 144 | AX14: =SUM(E14:AW14) -> 6069
D15: PR | E15: 153 | F15: 143 | G15: 149 | H15: 144 | I15: 150 | J15: 147 | K15: 142 | L15: 146 | M15: 125 | N15: 157 | O15: 144 | P15: 145 | Q15: 146 | R15: 137 | S15: 108 | T15: 90 | U15: 102 | V15: 117 | W15: 126 | X15: 118 | Y15: 131 | Z15: 137 | AA15: 127 | AB15: 121 | AC15: 149 | AD15: 138 | AE15: 125 | AF15: 91 | AG15: 142 | AH15: 123 | AI15: 145 | AJ15: 144 | AK15: 144 | AL15: 145 | AM15: 134 | AN15: 143 | AO15: 149 | AP15: 111 | AQ15: 141 | AR15: 117 | AS15: 110 | AT15: 102 | AU15: 127 | AV15: 139 | AW15: 133 | AX15: =SUM(E15:AW15) -> 5957
D16: JML | E16: =SUM(E14:E15) -> 290 | F16: =SUM(F14:F15) -> 292 | G16: =SUM(G14:G15) -> 296 | H16: =SUM(H14:H15) -> 295 | I16: =SUM(I14:I15) -> 295 | J16: =SUM(J14:J15) -> 295 | K16: =SUM(K14:K15) -> 287 | L16: =SUM(L14:L15) -> 279 | ... AX16: =SUM(AX14:AX15) -> 12026
A18: B | B18: PENGGUNA HAK PILIH
B19: 1. | C19: Jumlah pengguna hak pilih dalam Daftar Pemilih Tetap (DPT) | D19: LK | E19: 111 | F19: 114 | G19: 117 | H19: 120 | I19: 107 | J19: 112 | K19: 111 | L19: 93 | M19: 91 | N19: 106 | O19: 108 | P19: 97 | Q19: 109 | R19: 108 | S19: 82 | T19: 73 | U19: 96 | V19: 89 | W19: 102 | X19: 112 | Y19: 104 | Z19: 112 | AA19: 106 | AB19: 114 | AC19: 104 | AD19: 120 | AE19: 92 | AF19: 87 | AG19: 109 | AH19: 98 | AI19: 108 | AJ19: 108 | AK19: 119 | AL19: 101 | AM19: 99 | AN19: 109 | AO19: 114 | AP19: 91 | AQ19: 105 | AR19: 77 | AS19: 75 | AT19: 87 | AU19: 84 | AV19: 110 | AW19: 106 | AX19: =SUM(E19:AW19) -> 4597
D20: PR | E20: 112 | F20: 118 | G20: 116 | H20: 118 | I20: 115 | J20: 114 | K20: 108 | L20: 109 | M20: 92 | N20: 142 | O20: 114 | P20: 107 | Q20: 108 | R20: 114 | S20: 81 | T20: 73 | U20: 89 | V20: 72 | W20: 101 | X20: 96 | Y20: 106 | Z20: 109 | AA20: 88 | AB20: 96 | AC20: 120 | AD20: 108 | AE20: 102 | AF20: 76 | AG20: 108 | AH20: 100 | AI20: 111 | AJ20: 113 | AK20: 115 | AL20: 114 | AM20: 95 | AN20: 114 | AO20: 117 | AP20: 84 | AQ20: 117 | AR20: 88 | AS20: 81 | AT20: 80 | AU20: 92 | AV20: 110 | AW20: 91 | AX20: =SUM(E20:AW20) -> 4634
D21: JML | E21: =SUM(E19:E20) -> 223 | F21: =SUM(F19:F20) -> 232 | G21: =SUM(G19:G20) -> 233 | H21: =SUM(H19:H20) -> 238 | I21: =SUM(I19:I20) -> 222 | J21: =SUM(J19:J20) -> 226 | K21: =SUM(K19:K20) -> 219 | L21: =SUM(L19:L20) -> 202 | ... AW21: =SUM(AW19:AW20) -> 197 | AX21: =SUM(E21:AW21) -> 9231
B22: 2. | C22: Jumlah pengguna hak pilih dalam Daftar Pemilih Tambahan (DPTb) | D22: LK | E22: 0 | F22: 0 | G22: 0 | H22: 0 | I22: 0 | J22: 0 | K22: 0 | L22: 0 | M22: 0 | N22: 0 | O22: 0 | P22: 0 | Q22: 0 | R22: 0 | S22: 0 | T22: 0 | U22: 0 | V22: 0 | W22: 0 | X22: 0 | Y22: 2 | Z22: 0 | AA22: 0 | AB22: 0 | AC22: 0 | AD22: 0 | AE22: 0 | AF22: 0 | AG22: 0 | AH22: 0 | AI22: 0 | AJ22: 10 | AK22: 0 | AL22: 0 | AM22: 0 | AN22: 0 | AO22: 0 | AP22: 0 | AQ22: 0 | AR22: 0 | AS22: 0 | AT22: 0 | AU22: 0 | AV22: 0 | AW22: 0 | AX22: =SUM(E22:AW22) -> 12
D23: PR | E23: 0 | F23: 0 | G23: 0 | H23: 0 | I23: 0 | J23: 0 | K23: 0 | L23: 0 | M23: 0 | N23: 0 | O23: 0 | P23: 0 | Q23: 0 | R23: 0 | S23: 0 | T23: 0 | U23: 0 | V23: 0 | W23: 0 | X23: 0 | Y23: 2 | Z23: 0 | AA23: 0 | AB23: 0 | AC23: 0 | AD23: 0 | AE23: 0 | AF23: 0 | AG23: 0 | AH23: 0 | AI23: 0 | AJ23: 0 | AK23: 0 | AL23: 0 | AM23: 0 | AN23: 0 | AO23: 0 | AP23: 0 | AQ23: 0 | AR23: 0 | AS23: 0 | AT23: 0 | AU23: 0 | AV23: 0 | AW23: 0 | AX23: =SUM(E23:AW23) -> 2
D24: JML | E24: =SUM(E22:E23) -> 0 | F24: =SUM(F22:F23) -> 0 | G24: =SUM(G22:G23) -> 0 | H24: =SUM(H22:H23) -> 0 | I24: =SUM(I22:I23) -> 0 | J24: =SUM(J22:J23) -> 0 | K24: =SUM(K22:K23) -> 0 | L24: =SUM(L22:L23) -> 0 | ... AW24: =SUM(AW22:AW23) -> 0 | AX24: =SUM(E24:AW24) -> 14
B25: 3. | C25: Jumlah pengguna hak pilih dalam Daftar Pemilih Khusus (DPK) | D25: LK | E25: 1 | F25: 3 | G25: 3 | H25: 2 | I25: 5 | J25: 1 | K25: 0 | L25: 1 | M25: 0 | N25: 3 | O25: 0 | P25: 1 | Q25: 4 | R25: 0 | S25: 0 | T25: 2 | U25: 1 | V25: 0 | W25: 4 | X25: 1 | Y25: 1 | Z25: 1 | AA25: 0 | AB25: 3 | AC25: 0 | AD25: 0 | AE25: 1 | AF25: 0 | AG25: 6 | AH25: 0 | AI25: 3 | AJ25: 3 | AK25: 1 | AL25: 3 | AM25: 4 | AN25: 5 | AO25: 3 | AP25: 3 | AQ25: 1 | AR25: 11 | AS25: 0 | AT25: 9 | AU25: 0 | AV25: 0 | AW25: 2 | AX25: =SUM(E25:AW25) -> 92
D26: PR | E26: 2 | F26: 0 | G26: 0 | H26: 4 | I26: 3 | J26: 1 | K26: 0 | L26: 1 | M26: 0 | N26: 0 | O26: 2 | P26: 3 | Q26: 4 | R26: 3 | S26: 1 | T26: 2 | U26: 1 | V26: 0 | W26: 5 | X26: 3 | Y26: 1 | Z26: 4 | AA26: 0 | AB26: 3 | AC26: 1 | AD26: 0 | AE26: 0 | AF26: 0 | AG26: 2 | AH26: 0 | AI26: 0 | AJ26: 1 | AK26: 0 | AL26: 0 | AM26: 6 | AN26: 1 | AO26: 2 | AP26: 4 | AQ26: 0 | AR26: 8 | AS26: 1 | AT26: 9 | AU26: 0 | AV26: 1 | AW26: 2 | AX26: =SUM(E26:AW26) -> 81
D27: JML | E27: =SUM(E25:E26) -> 3 | F27: =SUM(F25:F26) -> 3 | G27: =SUM(G25:G26) -> 3 | H27: =SUM(H25:H26) -> 6 | I27: =SUM(I25:I26) -> 8 | J27: =SUM(J25:J26) -> 2 | K27: =SUM(K25:K26) -> 0 | L27: =SUM(L25:L26) -> 2 | ... AW27: =SUM(AW25:AW26) -> 4 | AX27: =SUM(E27:AW27) -> 173
B28: 4. | C28: Jumlah Pengguna Hak Pilih (B.1+B.2+B.3) | D28: LK | E28: =SUM(E19,E22,E25) -> 112 | F28: =SUM(F19,F22,F25) -> 117 | G28: =SUM(G19,G22,G25) -> 120 | H28: =SUM(H19,H22,H25) -> 122 | I28: =SUM(I19,I22,I25) -> 112 | J28: =SUM(J19,J22,J25) -> 113 | K28: =SUM(K19,K22,K25) -> 111 | L28: =SUM(L19,L22,L25) -> 94 | ... AW28: =SUM(AW19,AW22,AW25) -> 108 | AX28: =SUM(E28:AW28) -> 4701
D29: PR | E29: =SUM(E20,E23,E26) -> 114 | F29: =SUM(F20,F23,F26) -> 118 | G29: =SUM(G20,G23,G26) -> 116 | H29: =SUM(H20,H23,H26) -> 122 | I29: =SUM(I20,I23,I26) -> 118 | J29: =SUM(J20,J23,J26) -> 115 | K29: =SUM(K20,K23,K26) -> 108 | L29: =SUM(L20,L23,L26) -> 110 | ... AW29: =SUM(AW20,AW23,AW26) -> 93 | AX29: =SUM(E29:AW29) -> 4717
D30: JML | E30: =SUM(E28:E29) -> 226 | F30: =SUM(F28:F29) -> 235 | G30: =SUM(G28:G29) -> 236 | H30: =SUM(H28:H29) -> 244 | I30: =SUM(I28:I29) -> 230 | J30: =SUM(J28:J29) -> 228 | K30: =SUM(K28:K29) -> 219 | L30: =SUM(L28:L29) -> 204 | ... AW30: =SUM(AW28:AW29) -> 201 | AX30: =SUM(E30:AW30) -> 9418
A32: II | B32: DATA PENGGUNAAN SURAT SUARA
A33: 1 | B33: Jumlah surat suara yang diterima, termasuk surat suara cadangan 2,5% dari DPT | E33: 296 | F33: 298 | G33: 302 | H33: 304 | I33: 304 | J33: 301 | K33: 293 | L33: 283 | M33: 256 | N33: 302 | O33: 293 | P33: 294 | Q33: 294 | R33: 274 | S33: 222 | T33: 191 | U33: 226 | V33: 245 | W33: 265 | X33: 258 | Y33: 266 | Z33: 292 | AA33: 267 | AB33: 268 | AC33: 287 | AD33: 294 | AE33: 258 | AF33: 191 | AG33: 286 | AH33: 253 | AI33: 294 | AJ33: 299 | AK33: 303 | AL33: 291 | AM33: 293 | AN33: 290 | AO33: 289 | AP33: 244 | AQ33: 297 | AR33: 237 | AS33: 239 | AT33: 227 | AU33: 260 | AV33: 285 | AW33: 283 | AX33: =SUM(E33:AW33) -> 12294
A34: 2 | B34: Jumlah surat suara yang digunakan | E34: 226 | F34: 235 | G34: 236 | H34: 244 | I34: 230 | J34: 228 | K34: 219 | L34: 204 | M34: 183 | N34: 251 | O34: 225 | P34: 204 | Q34: 223 | R34: 225 | S34: 164 | T34: 150 | U34: 187 | V34: 161 | W34: 212 | X34: 212 | Y34: 214 | Z34: 226 | AA34: 194 | AB34: 216 | AC34: 225 | AD34: 228 | AE34: 195 | AF34: 163 | AG34: 225 | AH34: 198 | AI34: 222 | AJ34: 235 | AK34: 235 | AL34: 218 | AM34: 204 | AN34: 229 | AO34: 236 | AP34: 182 | AQ34: 223 | AR34: 184 | AS34: 157 | AT34: 185 | AU34: 176 | AV34: 221 | AW34: 201 | AX34: =SUM(E34:AW34) -> 9411
A35: 3 | B35: Jumlah surat suara dikembalikan oleh pemilih (karena rusak atau keliru coblos) | E35: 0 | F35: 2 | G35: 2 | H35: 4 | I35: 0 | J35: 0 | K35: 0 | L35: 0 | M35: 0 | N35: 1 | O35: 0 | P35: 0 | Q35: 0 | R35: 1 | S35: 2 | T35: 0 | U35: 1 | V35: 0 | W35: 0 | X35: 0 | Y35: 0 | Z35: 0 | AA35: 0 | AB35: 2 | AC35: 0 | AD35: 7 | AE35: 0 | AF35: 0 | AG35: 0 | AH35: 0 | AI35: 0 | AJ35: 0 | AK35: 0 | AL35: 0 | AM35: 0 | AN35: 0 | AO35: 0 | AP35: 0 | AQ35: 0 | AR35: 0 | AS35: 0 | AT35: 1 | AU35: 0 | AV35: 0 | AW35: 0 | AX35: =SUM(E35:AW35) -> 23
A36: 4 | B36: Jumlah surat suara yang tidak digunakan/tidak terpakai, termasuk sisa surat suara cadangan | E36: =E33-(E34+E35) -> 70 | F36: =F33-(F34+F35) -> 61 | G36: =G33-(G34+G35) -> 64 | H36: =H33-(H34+H35) -> 56 | I36: =I33-(I34+I35) -> 74 | J36: =J33-(J34+J35) -> 73 | K36: =K33-(K34+K35) -> 74 | L36: =L33-(L34+L35) -> 79 | ... AW36: =AW33-(AW34+AW35) -> 82 | AX36: =SUM(E36:AW36) -> 2860
A38: III | B38: DATA PEMILIH DISABILITAS
B39: Jumlah seluruh Pemilih disabilitas yang menggunakan hak pilih | D39: LK | E39: 0 | F39: 0 | G39: 0 | H39: 0 | I39: 0 | J39: 0 | K39: 0 | L39: 0 | M39: 0 | N39: 0 | O39: 1 | P39: 0 | Q39: 0 | R39: 0 | S39: 0 | T39: 0 | U39: 0 | V39: 0 | W39: 0 | X39: 0 | Y39: 0 | Z39: 0 | AA39: 0 | AB39: 0 | AC39: 0 | AD39: 0 | AE39: 0 | AF39: 2 | AG39: 0 | AH39: 1 | AI39: 1 | AJ39: 0 | AK39: 0 | AL39: 0 | AM39: 0 | AN39: 0 | AO39: 0 | AP39: 0 | AQ39: 0 | AR39: 1 | AS39: 0 | AT39: 0 | AU39: 0 | AV39: 0 | AW39: 0 | AX39: =SUM(E39:AW39) -> 6
D40: PR | E40: 0 | F40: 0 | G40: 0 | H40: 0 | I40: 0 | J40: 2 | K40: 0 | L40: 0 | M40: 0 | N40: 0 | O40: 0 | P40: 1 | Q40: 0 | R40: 0 | S40: 0 | T40: 0 | U40: 0 | V40: 0 | W40: 0 | X40: 0 | Y40: 0 | Z40: 0 | AA40: 0 | AB40: 0 | AC40: 0 | AD40: 0 | AE40: 0 | AF40: 0 | AG40: 0 | AH40: 0 | AI40: 0 | AJ40: 0 | AK40: 0 | AL40: 0 | AM40: 0 | AN40: 0 | AO40: 0 | AP40: 0 | AQ40: 0 | AR40: 1 | AS40: 0 | AT40: 0 | AU40: 0 | AV40: 0 | AW40: 0 | AX40: =SUM(E40:AW40) -> 4
D41: JML | E41: =SUM(E39:E40) -> 0 | F41: =SUM(F39:F40) -> 0 | G41: =SUM(G39:G40) -> 0 | H41: =SUM(H39:H40) -> 0 | I41: =SUM(I39:I40) -> 0 | J41: =SUM(J39:J40) -> 2 | K41: =SUM(K39:K40) -> 0 | L41: =SUM(L39:L40) -> 0 | ... AW41: =SUM(AW39:AW40) -> 0 | AX41: =SUM(E41:AW41) -> 10
A43: IV | B43: DATA RINCIAN PEROLEHAN SUARA PASANGAN CALON BUPATI DAN WAKIL BUPATI
A44: NOMOR DAN NAMA CALON
A45: A.1 | B45: 1. | C45: Partai Kebangkitan Bangsa | E45: 7 | F45: 9 | G45: 12 | H45: 9 | I45: 7 | J45: 8 | K45: 13 | L45: 11 | M45: 10 | N45: 14 | O45: 6 | P45: 5 | Q45: 6 | R45: 4 | S45: 4 | T45: 7 | U45: 10 | V45: 4 | W45: 2 | X45: 3 | Y45: 2 | Z45: 8 | AA45: 2 | AB45: 8 | AC45: 13 | AD45: 2 | AE45: 12 | AF45: 6 | AG45: 12 | AH45: 7 | AI45: 8 | AJ45: 11 | AK45: 11 | AL45: 5 | AM45: 6 | AN45: 3 | AO45: 6 | AP45: 3 | AQ45: 4 | AR45: 5 | AS45: 5 | AT45: 4 | AU45: 10 | AV45: 10 | AW45: 8 | AX45: =SUM(E45:AW45) -> 322
A46: A.2 | C46: 1. Dra. Hj. MA`MULAH HARUN, M.Pd.I. | E46: 10 | F46: 21 | G46: 29 | H46: 9 | I46: 8 | J46: 10 | K46: 20 | L46: 27 | M46: 23 | N46: 34 | O46: 13 | P46: 14 | Q46: 23 | R46: 30 | S46: 7 | T46: 20 | U46: 10 | V46: 12 | W46: 6 | X46: 14 | Y46: 2 | Z46: 15 | AA46: 15 | AB46: 17 | AC46: 31 | AD46: 7 | AE46: 8 | AF46: 11 | AG46: 15 | AH46: 17 | AI46: 14 | AJ46: 12 | AK46: 1 | AL46: 5 | AM46: 3 | AN46: 3 | AO46: 3 | AP46: 4 | AQ46: 18 | AR46: 6 | AS46: 6 | AT46: 5 | AU46: 49 | AV46: 40 | AW46: 30 | AX46: =SUM(E46:AW46) -> 677
C47: 2. UBAIDILLAH, S.Fil.I. | E47: 3 | F47: 2 | G47: 1 | H47: 4 | I47: 2 | J47: 3 | K47: 2 | L47: 3 | M47: 7 | N47: 7 | O47: 3 | P47: 2 | Q47: 3 | R47: 5 | S47: 0 | T47: 3 | U47: 1 | V47: 0 | W47: 3 | X47: 1 | Y47: 2 | Z47: 3 | AA47: 0 | AB47: 1 | AC47: 4 | AD47: 2 | AE47: 0 | AF47: 0 | AG47: 3 | AH47: 1 | AI47: 1 | AJ47: 1 | AK47: 3 | AL47: 0 | AM47: 3 | AN47: 2 | AO47: 1 | AP47: 1 | AQ47: 1 | AR47: 3 | AS47: 3 | AT47: 0 | AU47: 1 | AV47: 0 | AW47: 0 | AX47: =SUM(E47:AW47) -> 91
C48: 3. Ir. H. YOYOK MULYADI, M.Si. | E48: 0 | F48: 3 | G48: 0 | H48: 1 | I48: 0 | J48: 1 | K48: 1 | L48: 0 | M48: 1 | N48: 3 | O48: 2 | P48: 0 | Q48: 0 | R48: 2 | S48: 3 | T48: 0 | U48: 3 | V48: 1 | W48: 1 | X48: 0 | Y48: 0 | Z48: 3 | AA48: 2 | AB48: 0 | AC48: 0 | AD48: 0 | AE48: 1 | AF48: 1 | AG48: 1 | AH48: 2 | AI48: 1 | AJ48: 0 | AK48: 0 | AL48: 1 | AM48: 1 | AN48: 0 | AO48: 0 | AP48: 0 | AQ48: 1 | AR48: 1 | AS48: 3 | AT48: 0 | AU48: 0 | AV48: 0 | AW48: 0 | AX48: =SUM(E48:AW48) -> 40
C49: 4. KHOIRUL ANWAR, S.Fil.I. | E49: 2 | F49: 4 | G49: 1 | H49: 1 | I49: 0 | J49: 1 | K49: 2 | L49: 2 | M49: 1 | N49: 3 | O49: 1 | P49: 2 | Q49: 3 | R49: 4 | S49: 1 | T49: 1 | U49: 2 | V49: 0 | W49: 1 | X49: 1 | Y49: 0 | Z49: 2 | AA49: 4 | AB49: 0 | AC49: 4 | AD49: 1 | AE49: 1 | AF49: 0 | AG49: 3 | AH49: 1 | AI49: 0 | AJ49: 1 | AK49: 2 | AL49: 0 | AM49: 0 | AN49: 0 | AO49: 2 | AP49: 0 | AQ49: 1 | AR49: 2 | AS49: 3 | AT49: 0 | AU49: 2 | AV49: 1 | AW49: 1 | AX49: =SUM(E49:AW49) -> 64
C50: 5. ARIF WIJAKSANA | E50: 1 | F50: 1 | G50: 4 | H50: 0 | I50: 2 | J50: 1 | K50: 2 | L50: 1 | M50: 1 | N50: 3 | O50: 1 | P50: 0 | Q50: 2 | R50: 0 | S50: 2 | T50: 0 | U50: 0 | V50: 0 | W50: 3 | X50: 0 | Y50: 0 | Z50: 0 | AA50: 1 | AB50: 0 | AC50: 2 | AD50: 1 | AE50: 0 | AF50: 0 | AG50: 0 | AH50: 2 | AI50: 0 | AJ50: 0 | AK50: 0 | AL50: 1 | AM50: 2 | AN50: 0 | AO50: 0 | AP50: 0 | AQ50: 0 | AR50: 0 | AS50: 2 | AT50: 0 | AU50: 2 | AV50: 0 | AW50: 1 | AX50: =SUM(E50:AW50) -> 38
C51: 6. Dr. SITI YUMNAH | E51: 1 | F51: 1 | G51: 1 | H51: 1 | I51: 0 | J51: 1 | K51: 0 | L51: 1 | M51: 2 | N51: 1 | O51: 0 | P51: 1 | Q51: 0 | R51: 2 | S51: 0 | T51: 0 | U51: 0 | V51: 1 | W51: 1 | X51: 0 | Y51: 0 | Z51: 0 | AA51: 1 | AB51: 1 | AC51: 0 | AD51: 0 | AE51: 0 | AF51: 1 | AG51: 1 | AH51: 0 | AI51: 0 | AJ51: 0 | AK51: 0 | AL51: 0 | AM51: 0 | AN51: 0 | AO51: 1 | AP51: 0 | AQ51: 0 | AR51: 1 | AS51: 0 | AT51: 0 | AU51: 1 | AV51: 0 | AW51: 0 | AX51: =SUM(E51:AW51) -> 21
...

Sheet KANDANGAN
C2: Kecamatan | D2: PESANGGARAN
C3: Kabupaten | D3: BANYUWANGI
C4: Provinsi | D4: JAWA TIMUR
C9: Kelurahan | D9: KANDANGAN
A12: I | B12: DATA PEMILIH DAN PENGGUNAAN HAK PILIH | AG12: JUMLAH AKHIR
A13: A | B13: DATA PEMILIH | E13: TPS 001 | F13: TPS 002 | G13: TPS 003 | H13: TPS 004 | I13: TPS 005 | J13: TPS 006 | K13: TPS 007 | L13: TPS 008 | M13: TPS 009 | N13: TPS 010 | O13: TPS 011 | P13: TPS 012 | Q13: TPS 013 | R13: TPS 014 | S13: TPS 015 | T13: TPS 016 | U13: TPS 017 | V13: TPS 018 | W13: TPS 019 | X13: TPS 020 | Y13: TPS 021 | Z13: TPS 022 | AA13: TPS 023 | AB13: TPS 024 | AC13: TPS 025 | AD13: TPS 026 | AE13: TPS 027 | AF13: TPS 028
B14: Jumlah Pemilih dalam Daftar Pemilih Tetap (DPT) | D14: LK | E14: 118 | F14: 98 | G14: 113 | H14: 103 | I14: 144 | J14: 150 | K14: 117 | L14: 103 | M14: 112 | N14: 125 | O14: 107 | P14: 141 | Q14: 145 | R14: 131 | S14: 94 | T14: 136 | U14: 115 | V14: 138 | W14: 154 | X14: 136 | Y14: 147 | Z14: 137 | AA14: 84 | AB14: 140 | AC14: 126 | AD14: 113 | AE14: 114 | AF14: 127 | AG14: =SUM(E14:AF14) -> 3468
D15: PR | E15: 138 | F15: 89 | G15: 118 | H15: 121 | I15: 129 | J15: 141 | K15: 102 | L15: 90 | M15: 124 | N15: 123 | O15: 115 | P15: 142 | Q15: 142 | R15: 131 | S15: 115 | T15: 147 | U15: 128 | V15: 136 | W15: 129 | X15: 140 | Y15: 148 | Z15: 130 | AA15: 105 | AB15: 139 | AC15: 119 | AD15: 119 | AE15: 108 | AF15: 119 | AG15: =SUM(E15:AF15) -> 3487
D16: JML | E16: =SUM(E14:E15) -> 256 | F16: =SUM(F14:F15) -> 187 | G16: =SUM(G14:G15) -> 231 | H16: =SUM(H14:H15) -> 224 | I16: =SUM(I14:I15) -> 273 | J16: =SUM(J14:J15) -> 291 | K16: =SUM(K14:K15) -> 219 | L16: =SUM(L14:L15) -> 193 | ... AF16: =SUM(AF14:AF15) -> 246 | AG16: =SUM(E16:AF16) -> 6955
A18: B | B18: PENGGUNA HAK PILIH
B19: 1. | C19: Jumlah pengguna hak pilih dalam Daftar Pemilih Tetap (DPT) | D19: LK | E19: 95 | F19: 82 | G19: 83 | H19: 84 | I19: 118 | J19: 121 | K19: 81 | L19: 76 | M19: 89 | N19: 88 | O19: 71 | P19: 89 | Q19: 93 | R19: 81 | S19: 60 | T19: 95 | U19: 81 | V19: 93 | W19: 110 | X19: 88 | Y19: 101 | Z19: 89 | AA19: 65 | AB19: 106 | AC19: 87 | AD19: 83 | AE19: 94 | AF19: 93 | AG19: =SUM(E19:AF19) -> 2496
D20: PR | E20: 109 | F20: 82 | G20: 91 | H20: 92 | I20: 103 | J20: 109 | K20: 80 | L20: 70 | M20: 97 | N20: 87 | O20: 80 | P20: 101 | Q20: 91 | R20: 90 | S20: 83 | T20: 92 | U20: 97 | V20: 97 | W20: 94 | X20: 95 | Y20: 104 | Z20: 85 | AA20: 79 | AB20: 104 | AC20: 84 | AD20: 91 | AE20: 91 | AF20: 93 | AG20: =SUM(E20:AF20) -> 2571
D21: JML | E21: =SUM(E19:E20) -> 204 | F21: =SUM(F19:F20) -> 164 | G21: =SUM(G19:G20) -> 174 | H21: =SUM(H19:H20) -> 176 | I21: =SUM(I19:I20) -> 221 | J21: =SUM(J19:J20) -> 230 | K21: =SUM(K19:K20) -> 161 | L21: =SUM(L19:L20) -> 146 | ... AF21: =SUM(AF19:AF20) -> 186 | AG21: =SUM(E21:AF21) -> 5067
B22: 2. | C22: Jumlah pengguna hak pilih dalam Daftar Pemilih Tambahan (DPTb) | D22: LK | E22: 0 | F22: 0 | G22: 0 | H22: 0 | I22: 0 | J22: 0 | K22: 0 | L22: 0 | M22: 0 | N22: 0 | O22: 0 | P22: 0 | Q22: 0 | R22: 0 | S22: 0 | T22: 0 | U22: 0 | V22: 0 | W22: 0 | X22: 0 | Y22: 0 | Z22: 0 | AA22: 0 | AB22: 8 | AC22: 0 | AD22: 0 | AE22: 0 | AF22: 0 | AG22: =SUM(E22:AF22) -> 8
D23: PR | E23: 0 | F23: 0 | G23: 0 | H23: 0 | I23: 0 | J23: 0 | K23: 0 | L23: 0 | M23: 0 | N23: 0 | O23: 0 | P23: 0 | Q23: 0 | R23: 0 | S23: 0 | T23: 0 | U23: 0 | V23: 0 | W23: 0 | X23: 0 | Y23: 0 | Z23: 0 | AA23: 0 | AB23: 3 | AC23: 0 | AD23: 0 | AE23: 0 | AF23: 0 | AG23: =SUM(E23:AF23) -> 3
D24: JML | E24: =SUM(E22:E23) -> 0 | F24: =SUM(F22:F23) -> 0 | G24: =SUM(G22:G23) -> 0 | H24: =SUM(H22:H23) -> 0 | I24: =SUM(I22:I23) -> 0 | J24: =SUM(J22:J23) -> 0 | K24: =SUM(K22:K23) -> 0 | L24: =SUM(L22:L23) -> 0 | ... AF24: =SUM(AF22:AF23) -> 0 | AG24: =SUM(E24:AF24) -> 11
B25: 3. | C25: Jumlah pengguna hak pilih dalam Daftar Pemilih Khusus (DPK) | D25: LK | E25: 0 | F25: 0 | G25: 0 | H25: 1 | I25: 2 | J25: 2 | K25: 0 | L25: 0 | M25: 1 | N25: 0 | O25: 0 | P25: 2 | Q25: 1 | R25: 0 | S25: 4 | T25: 12 | U25: 7 | V25: 2 | W25: 3 | X25: 1 | Y25: 0 | Z25: 9 | AA25: 8 | AB25: 3 | AC25: 8 | AD25: 0 | AE25: 0 | AF25: 2 | AG25: =SUM(E25:AF25) -> 68
D26: PR | E26: 0 | F26: 0 | G26: 0 | H26: 2 | I26: 0 | J26: 4 | K26: 4 | L26: 1 | M26: 2 | N26: 0 | O26: 0 | P26: 2 | Q26: 2 | R26: 2 | S26: 3 | T26: 9 | U26: 9 | V26: 2 | W26: 3 | X26: 3 | Y26: 2 | Z26: 8 | AA26: 8 | AB26: 2 | AC26: 10 | AD26: 0 | AE26: 0 | AF26: 5 | AG26: =SUM(E26:AF26) -> 83
D27: JML | E27: =SUM(E25:E26) -> 0 | F27: =SUM(F25:F26) -> 0 | G27: =SUM(G25:G26) -> 0 | H27: =SUM(H25:H26) -> 3 | I27: =SUM(I25:I26) -> 2 | J27: =SUM(J25:J26) -> 6 | K27: =SUM(K25:K26) -> 4 | L27: =SUM(L25:L26) -> 1 | ... AF27: =SUM(AF25:AF26) -> 7 | AG27: =SUM(E27:AF27) -> 151
B28: 4. | C28: Jumlah Pengguna Hak Pilih (B.1+B.2+B.3) | D28: LK | E28: =SUM(E19,E22,E25) -> 95 | F28: =SUM(F19,F22,F25) -> 82 | G28: =SUM(G19,G22,G25) -> 83 | H28: =SUM(H19,H22,H25) -> 85 | I28: =SUM(I19,I22,I25) -> 120 | J28: =SUM(J19,J22,J25) -> 123 | K28: =SUM(K19,K22,K25) -> 81 | L28: =SUM(L19,L22,L25) -> 76 | ... AF28: =SUM(AF19,AF22,AF25) -> 95 | AG28: =SUM(E28:AF28) -> 2572
D29: PR | E29: =SUM(E20,E23,E26) -> 109 | F29: =SUM(F20,F23,F26) -> 82 | G29: =SUM(G20,G23,G26) -> 91 | H29: =SUM(H20,H23,H26) -> 94 | I29: =SUM(I20,I23,I26) -> 103 | J29: =SUM(J20,J23,J26) -> 113 | K29: =SUM(K20,K23,K26) -> 84 | L29: =SUM(L20,L23,L26) -> 71 | ... AF29: =SUM(AF20,AF23,AF26) -> 98 | AG29: =SUM(E29:AF29) -> 2657
D30: JML | E30: =SUM(E28:E29) -> 204 | F30: =SUM(F28:F29) -> 164 | G30: =SUM(G28:G29) -> 174 | H30: =SUM(H28:H29) -> 179 | I30: =SUM(I28:I29) -> 223 | J30: =SUM(J28:J29) -> 236 | K30: =SUM(K28:K29) -> 165 | L30: =SUM(L28:L29) -> 147 | ... AF30: =SUM(AF28:AF29) -> 193 | AG30: =SUM(E30:AF30) -> 5229
A32: II | B32: DATA PENGGUNAAN SURAT SUARA
A33: 1 | B33: Jumlah surat suara yang diterima, termasuk surat suara cadangan 2,5% dari DPT | E33: 262 | F33: 191 | G33: 236 | H33: 230 | I33: 279 | J33: 287 | K33: 224 | L33: 197 | M33: 241 | N33: 253 | O33: 227 | P33: 289 | Q33: 293 | R33: 268 | S33: 214 | T33: 289 | U33: 249 | V33: 280 | W33: 280 | X33: 282 | Y33: 291 | Z33: 273 | AA33: 153 | AB33: 285 | AC33: 251 | AD33: 291 | AE33: 287 | AF33: 248 | AG33: =SUM(E33:AF33) -> 7150
A34: 2 | B34: Jumlah surat suara yang digunakan | E34: 204 | F34: 164 | G34: 174 | H34: 179 | I34: 223 | J34: 236 | K34: 165 | L34: 147 | M34: 189 | N34: 175 | O34: 151 | P34: 194 | Q34: 187 | R34: 173 | S34: 150 | T34: 208 | U34: 194 | V34: 194 | W34: 210 | X34: 187 | Y34: 207 | Z34: 191 | AA34: 160 | AB34: 226 | AC34: 189 | AD34: 174 | AE34: 185 | AF34: 193 | AG34: =SUM(E34:AF34) -> 5229
A35: 3 | B35: Jumlah surat suara dikembalikan oleh pemilih (karena rusak atau keliru coblos) | E35: 0 | F35: 1 | G35: 2 | H35: 1 | I35: 0 | J35: 0 | K35: 0 | L35: 0 | M35: 0 | N35: 0 | O35: 0 | P35: 0 | Q35: 0 | R35: 0 | S35: 0 | T35: 0 | U35: 5 | V35: 0 | W35: 0 | X35: 0 | Y35: 0 | Z35: 0 | AA35: 2 | AB35: 0 | AC35: 1 | AD35: 0 | AE35: 0 | AF35: 0 | AG35: =SUM(E35:AF35) -> 12
A36: 4 | B36: Jumlah surat suara yang tidak digunakan/tidak terpakai, termasuk sisa surat suara cadangan | E36: =E33-(E34+E35) -> 58 | F36: =F33-(F34+F35) -> 26 | G36: =G33-(G34+G35) -> 60 | H36: =H33-(H34+H35) -> 50 | I36: =I33-(I34+I35) -> 56 | J36: =J33-(J34+J35) -> 51 | K36: =K33-(K34+K35) -> 59 | L36: =L33-(L34+L35) -> 50 | ... AF36: =AF33-(AF34+AF35) -> 55 | AG36: =SUM(E36:AF36) -> 1909
A38: III | B38: DATA PEMILIH DISABILITAS
B39: Jumlah seluruh Pemilih disabilitas yang menggunakan hak pilih | D39: LK | E39: 0 | F39: 0 | G39: 0 | H39: 0 | I39: 0 | J39: 0 | K39: 0 | L39: 0 | M39: 0 | N39: 0 | O39: 0 | P39: 0 | Q39: 0 | R39: 0 | S39: 0 | T39: 0 | U39: 0 | V39: 0 | W39: 0 | X39: 0 | Y39: 0 | Z39: 0 | AA39: 0 | AB39: 0 | AC39: 0 | AD39: 0 | AE39: 0 | AF39: 3 | AG39: =SUM(E39:AF39) -> 3
D40: PR | E40: 0 | F40: 0 | G40: 0 | H40: 0 | I40: 0 | J40: 0 | K40: 0 | L40: 0 | M40: 0 | N40: 0 | O40: 0 | P40: 0 | Q40: 0 | R40: 0 | S40: 0 | T40: 0 | U40: 0 | V40: 0 | W40: 0 | X40: 0 | Y40: 0 | Z40: 0 | AA40: 0 | AB40: 0 | AC40: 0 | AD40: 0 | AE40: 0 | AF40: 4 | AG40: =SUM(E40:AF40) -> 4
D41: JML | E41: =SUM(E39:E40) -> 0 | F41: =SUM(F39:F40) -> 0 | G41: =SUM(G39:G40) -> 0 | H41: =SUM(H39:H40) -> 0 | I41: =SUM(I39:I40) -> 0 | J41: =SUM(J39:J40) -> 0 | K41: =SUM(K39:K40) -> 0 | L41: =SUM(L39:L40) -> 0 | ... AF41: =SUM(AF39:AF40) -> 7 | AG41: =SUM(E41:AF41) -> 7
A43: IV | B43: DATA RINCIAN PEROLEHAN SUARA PASANGAN CALON BUPATI DAN WAKIL BUPATI
A44: NOMOR DAN NAMA CALON
A45: A.1 | B45: 1. | C45: Partai Kebangkitan Bangsa | E45: 9 | F45: 2 | G45: 6 | H45: 13 | I45: 12 | J45: 20 | K45: 5 | L45: 9 | M45: 14 | N45: 4 | O45: 4 | P45: 8 | Q45: 4 | R45: 5 | S45: 6 | T45: 6 | U45: 12 | V45: 6 | W45: 7 | X45: 6 | Y45: 7 | Z45: 3 | AA45: 8 | AB45: 1 | AC45: 11 | AD45: 4 | AE45: 1 | AF45: 4 | AG45: =SUM(E45:AF45) -> 197
A46: A.2 | C46: 1. Dra. Hj. MA`MULAH HARUN, M.Pd.I. | E46: 34 | F46: 20 | G46: 27 | H46: 35 | I46: 12 | J46: 44 | K46: 28 | L46: 7 | M46: 20 | N46: 15 | O46: 26 | P46: 14 | Q46: 25 | R46: 25 | S46: 18 | T46: 10 | U46: 20 | V46: 13 | W46: 12 | X46: 11 | Y46: 8 | Z46: 2 | AA46: 17 | AB46: 5 | AC46: 6 | AD46: 15 | AE46: 2 | AF46: 27 | AG46: =SUM(E46:AF46) -> 498
C47: 2. UBAIDILLAH, S.Fil.I. | E47: 0 | F47: 4 | G47: 3 | H47: 3 | I47: 1 | J47: 1 | K47: 1 | L47: 0 | M47: 0 | N47: 3 | O47: 1 | P47: 2 | Q47: 1 | R47: 2 | S47: 1 | T47: 1 | U47: 3 | V47: 1 | W47: 1 | X47: 4 | Y47: 1 | Z47: 0 | AA47: 2 | AB47: 1 | AC47: 0 | AD47: 6 | AE47: 0 | AF47: 3 | AG47: =SUM(E47:AF47) -> 46
C48: 3. Ir. H. YOYOK MULYADI, M.Si. | E48: 1 | F48: 0 | G48: 0 | H48: 1 | I48: 1 | J48: 1 | K48: 0 | L48: 0 | M48: 1 | N48: 1 | O48: 1 | P48: 1 | Q48: 0 | R48: 1 | S48: 3 | T48: 1 | U48: 0 | V48: 0 | W48: 0 | X48: 1 | Y48: 0 | Z48: 0 | AA48: 0 | AB48: 1 | AC48: 0 | AD48: 1 | AE48: 0 | AF48: 1 | AG48: =SUM(E48:AF48) -> 17
C49: 4. KHOIRUL ANWAR, S.Fil.I. | E49: 0 | F49: 2 | G49: 1 | H49: 1 | I49: 0 | J49: 4 | K49: 0 | L49: 2 | M49: 0 | N49: 2 | O49: 0 | P49: 1 | Q49: 2 | R49: 0 | S49: 0 | T49: 2 | U49: 0 | V49: 2 | W49: 2 | X49: 2 | Y49: 2 | Z49: 1 | AA49: 3 | AB49: 0 | AC49: 2 | AD49: 10 | AE49: 0 | AF49: 1 | AG49: =SUM(E49:AF49) -> 42
C50: 5. ARIF WIJAKSANA | E50: 0 | F50: 2 | G50: 0 | H50: 1 | I50: 0 | J50: 3 | K50: 0 | L50: 0 | M50: 1 | N50: 0 | O50: 0 | P50: 1 | Q50: 1 | R50: 0 | S50: 0 | T50: 0 | U50: 1 | V50: 0 | W50: 1 | X50: 0 | Y50: 1 | Z50: 0 | AA50: 0 | AB50: 0 | AC50: 0 | AD50: 0 | AE50: 0 | AF50: 1 | AG50: =SUM(E50:AF50) -> 13
C51: 6. Dr. SITI YUMNAH | E51: 0 | F51: 0 | G51: 0 | H51: 0 | I51: 0 | J51: 2 | K51: 1 | L51: 1 | M51: 1 | N51: 1 | O51: 2 | P51: 1 | Q51: 0 | R51: 1 | S51: 0 | T51: 1 | U51: 2 | V51: 0 | W51: 0 | X51: 0 | Y51: 0 | Z51: 0 | AA51: 0 | AB51: 0 | AC51: 0 | AD51: 1 | AE51: 0 | AF51: 1 | AG51: =SUM(E51:AF51) -> 15
...

Sheet SUMBERMULYO
C2: Kecamatan | D2: PESANGGARAN
C3: Kabupaten | D3: BANYUWANGI
C4: Provinsi | D4: JAWA TIMUR
C9: Kelurahan | D9: SUMBERMULYO
A12: I | B12: DATA PEMILIH DAN PENGGUNAAN HAK PILIH | AB12: JUMLAH AKHIR
A13: A | B13: DATA PEMILIH | E13: TPS 001 | F13: TPS 002 | G13: TPS 003 | H13: TPS 004 | I13: TPS 005 | J13: TPS 006 | K13: TPS 007 | L13: TPS 008 | M13: TPS 009 | N13: TPS 010 | O13: TPS 011 | P13: TPS 012 | Q13: TPS 013 | R13: TPS 014 | S13: TPS 015 | T13: TPS 016 | U13: TPS 017 | V13: TPS 018 | W13: TPS 019 | X13: TPS 020 | Y13: TPS 021 | Z13: TPS 022 | AA13: TPS 023
B14: Jumlah Pemilih dalam Daftar Pemilih Tetap (DPT) | D14: LK | E14: 156 | F14: 144 | G14: 150 | H14: 150 | I14: 137 | J14: 140 | K14: 138 | L14: 129 | M14: 106 | N14: 154 | O14: 124 | P14: 126 | Q14: 96 | R14: 146 | S14: 148 | T14: 144 | U14: 151 | V14: 120 | W14: 133 | X14: 123 | Y14: 143 | Z14: 132 | AA14: 145 | AB14: =SUM(E14:AA14) -> 3135
D15: PR | E15: 141 | F15: 148 | G15: 146 | H15: 148 | I15: 142 | J15: 149 | K15: 137 | L15: 127 | M15: 113 | N15: 136 | O15: 143 | P15: 120 | Q15: 94 | R15: 143 | S15: 144 | T15: 152 | U15: 144 | V15: 127 | W15: 131 | X15: 137 | Y15: 135 | Z15: 131 | AA15: 150 | AB15: =SUM(E15:AA15) -> 3138
D16: JML | E16: =SUM(E14:E15) -> 297 | F16: =SUM(F14:F15) -> 292 | G16: =SUM(G14:G15) -> 296 | H16: =SUM(H14:H15) -> 298 | I16: =SUM(I14:I15) -> 279 | J16: =SUM(J14:J15) -> 289 | K16: =SUM(K14:K15) -> 275 | L16: =SUM(L14:L15) -> 256 | ... AA16: =SUM(AA14:AA15) -> 295 | AB16: =SUM(E16:AA16) -> 6273
A18: B | B18: PENGGUNA HAK PILIH
B19: 1. | C19: Jumlah pengguna hak pilih dalam Daftar Pemilih Tetap (DPT) | D19: LK | E19: 125 | F19: 118 | G19: 119 | H19: 104 | I19: 100 | J19: 104 | K19: 92 | L19: 94 | M19: 81 | N19: 120 | O19: 96 | P19: 103 | Q19: 70 | R19: 118 | S19: 119 | T19: 110 | U19: 122 | V19: 88 | W19: 111 | X19: 104 | Y19: 122 | Z19: 113 | AA19: 122 | AB19: =SUM(E19:AA19) -> 2455
D20: PR | E20: 115 | F20: 116 | G20: 110 | H20: 107 | I20: 110 | J20: 109 | K20: 103 | L20: 100 | M20: 92 | N20: 102 | O20: 109 | P20: 100 | Q20: 70 | R20: 112 | S20: 112 | T20: 105 | U20: 123 | V20: 99 | W20: 106 | X20: 118 | Y20: 117 | Z20: 108 | AA20: 114 | AB20: =SUM(E20:AA20) -> 2457
D21: JML | E21: =SUM(E19:E20) -> 240 | F21: =SUM(F19:F20) -> 234 | G21: =SUM(G19:G20) -> 229 | H21: =SUM(H19:H20) -> 211 | I21: =SUM(I19:I20) -> 210 | J21: =SUM(J19:J20) -> 213 | K21: =SUM(K19:K20) -> 195 | L21: =SUM(L19:L20) -> 194 | ... AA21: =SUM(AA19:AA20) -> 236 | AB21: =SUM(E21:AA21) -> 4912
B22: 2. | C22: Jumlah pengguna hak pilih dalam Daftar Pemilih Tambahan (DPTb) | D22: LK | E22: 0 | F22: 0 | G22: 0 | H22: 0 | I22: 0 | J22: 0 | K22: 3 | L22: 0 | M22: 0 | N22: 1 | O22: 0 | P22: 0 | Q22: 0 | R22: 0 | S22: 0 | T22: 1 | U22: 0 | V22: 1 | W22: 0 | X22: 0 | Y22: 0 | Z22: 0 | AA22: 0 | AB22: =SUM(E22:AA22) -> 6
D23: PR | E23: 0 | F23: 0 | G23: 0 | H23: 0 | I23: 0 | J23: 0 | K23: 2 | L23: 1 | M23: 2 | N23: 0 | O23: 0 | P23: 0 | Q23: 0 | R23: 0 | S23: 0 | T23: 0 | U23: 0 | V23: 0 | W23: 0 | X23: 0 | Y23: 0 | Z23: 0 | AA23: 0 | AB23: =SUM(E23:AA23) -> 5
D24: JML | E24: =SUM(E22:E23) -> 0 | F24: =SUM(F22:F23) -> 0 | G24: =SUM(G22:G23) -> 0 | H24: =SUM(H22:H23) -> 0 | I24: =SUM(I22:I23) -> 0 | J24: =SUM(J22:J23) -> 0 | K24: =SUM(K22:K23) -> 5 | L24: =SUM(L22:L23) -> 1 | ... AA24: =SUM(AA22:AA23) -> 0 | AB24: =SUM(E24:AA24) -> 11
B25: 3. | C25: Jumlah pengguna hak pilih dalam Daftar Pemilih Khusus (DPK) | D25: LK | E25: 2 | F25: 1 | G25: 4 | H25: 11 | I25: 2 | J25: 1 | K25: 0 | L25: 2 | M25: 1 | N25: 2 | O25: 0 | P25: 0 | Q25: 0 | R25: 1 | S25: 0 | T25: 0 | U25: 0 | V25: 0 | W25: 1 | X25: 0 | Y25: 0 | Z25: 0 | AA25: 0 | AB25: =SUM(E25:AA25) -> 28
D26: PR | E26: 2 | F26: 1 | G26: 3 | H26: 8 | I26: 2 | J26: 3 | K26: 1 | L26: 1 | M26: 1 | N26: 3 | O26: 0 | P26: 1 | Q26: 0 | R26: 1 | S26: 1 | T26: 1 | U26: 4 | V26: 1 | W26: 0 | X26: 2 | Y26: 1 | Z26: 0 | AA26: 0 | AB26: =SUM(E26:AA26) -> 37
D27: JML | E27: =SUM(E25:E26) -> 4 | F27: =SUM(F25:F26) -> 2 | G27: =SUM(G25:G26) -> 7 | H27: =SUM(H25:H26) -> 19 | I27: =SUM(I25:I26) -> 4 | J27: =SUM(J25:J26) -> 4 | K27: =SUM(K25:K26) -> 1 | L27: =SUM(L25:L26) -> 3 | ... AA27: =SUM(AA25:AA26) -> 0 | AB27: =SUM(E27:AA27) -> 65
B28: 4. | C28: Jumlah Pengguna Hak Pilih (B.1+B.2+B.3) | D28: LK | E28: =SUM(E19,E22,E25) -> 127 | F28: =SUM(F19,F22,F25) -> 119 | G28: =SUM(G19,G22,G25) -> 123 | H28: =SUM(H19,H22,H25) -> 115 | I28: =SUM(I19,I22,I25) -> 102 | J28: =SUM(J19,J22,J25) -> 105 | K28: =SUM(K19,K22,K25) -> 95 | L28: =SUM(L19,L22,L25) -> 96 | ... AA28: =SUM(AA19,AA22,AA25) -> 122 | AB28: =SUM(E28:AA28) -> 2489
D29: PR | E29: =SUM(E20,E23,E26) -> 117 | F29: =SUM(F20,F23,F26) -> 117 | G29: =SUM(G20,G23,G26) -> 113 | H29: =SUM(H20,H23,H26) -> 115 | I29: =SUM(I20,I23,I26) -> 112 | J29: =SUM(J20,J23,J26) -> 112 | K29: =SUM(K20,K23,K26) -> 106 | L29: =SUM(L20,L23,L26) -> 102 | ... AA29: =SUM(AA20,AA23,AA26) -> 114 | AB29: =SUM(E29:AA29) -> 2499
D30: JML | E30: =SUM(E28:E29) -> 244 | F30: =SUM(F28:F29) -> 236 | G30: =SUM(G28:G29) -> 236 | H30: =SUM(H28:H29) -> 230 | I30: =SUM(I28:I29) -> 214 | J30: =SUM(J28:J29) -> 217 | K30: =SUM(K28:K29) -> 201 | L30: =SUM(L28:L29) -> 198 | ... AA30: =SUM(AA28:AA29) -> 236 | AB30: =SUM(E30:AA30) -> 4988
A32: II | B32: DATA PENGGUNAAN SURAT SUARA
A33: 1 | B33: Jumlah surat suara yang diterima, termasuk surat suara cadangan 2,5% dari DPT | E33: 304 | F33: 298 | G33: 301 | H33: 304 | I33: 285 | J33: 295 | K33: 300 | L33: 252 | M33: 224 | N33: 296 | O33: 273 | P33: 251 | Q33: 295 | R33: 295 | S33: 298 | T33: 302 | U33: 301 | V33: 252 | W33: 270 | X33: 266 | Y33: 284 | Z33: 268 | AA33: 301 | AB33: =SUM(E33:AA33) -> 6515
A34: 2 | B34: Jumlah surat suara yang digunakan | E34: 244 | F34: 236 | G34: 236 | H34: 230 | I34: 214 | J34: 217 | K34: 201 | L34: 198 | M34: 177 | N34: 228 | O34: 205 | P34: 204 | Q34: 140 | R34: 232 | S34: 232 | T34: 217 | U34: 249 | V34: 189 | W34: 218 | X34: 224 | Y34: 240 | Z34: 221 | AA34: 236 | AB34: =SUM(E34:AA34) -> 4988
A35: 3 | B35: Jumlah surat suara dikembalikan oleh pemilih (karena rusak atau keliru coblos) | E35: 0 | F35: 1 | G35: 0 | H35: 0 | I35: 0 | J35: 0 | K35: 0 | L35: 0 | M35: 0 | N35: 0 | O35: 1 | P35: 0 | Q35: 0 | R35: 0 | S35: 0 | T35: 0 | U35: 0 | V35: 0 | W35: 0 | X35: 0 | Y35: 0 | Z35: 0 | AA35: 0 | AB35: =SUM(E35:AA35) -> 2
A36: 4 | B36: Jumlah surat suara yang tidak digunakan/tidak terpakai, termasuk sisa surat suara cadangan | E36: =E33-(E34+E35) -> 60 | F36: =F33-(F34+F35) -> 61 | G36: =G33-(G34+G35) -> 65 | H36: =H33-(H34+H35) -> 74 | I36: =I33-(I34+I35) -> 71 | J36: =J33-(J34+J35) -> 78 | K36: =K33-(K34+K35) -> 99 | L36: =L33-(L34+L35) -> 54 | ... AA36: =AA33-(AA34+AA35) -> 65 | AB36: =SUM(E36:AA36) -> 1525
