Workbook

Sheet DPRD PROVINSI
C8: Kecamatan | D8: KALIPURO
C9: Kabupaten | D9: BANYUWANGI
C10: Provinsi | D10: JAWA TIMUR
A12: I | B12: DATA PEMILIH DAN PENGGUNAAN HAK PILIH | E12: JUMLAH AKHIR
A13: A | B13: DATA PEMILIH
B14: Jumlah Pemilih dalam Daftar Pemilih Tetap (DPT) | D14: LK | E14: =BULUSAN!AC14+BULUSARI!R14+GOMBENGSARI!AC14+KALIPURO!AR14+KELIR!W14+KETAPANG!BE14+KLATAK!AV14+PESUCEN!R14+TELEMUNG!T14 -> 31987
D15: PR | E15: =BULUSAN!AC15+BULUSARI!R15+GOMBENGSARI!AC15+KALIPURO!AR15+KELIR!W15+KETAPANG!BE15+KLATAK!AV15+PESUCEN!R15+TELEMUNG!T15 -> 33057
D16: JML | E16: =SUM(E14:E15) -> 65044
A18: B | B18: PENGGUNA HAK PILIH
B19: 1. | C19: Jumlah pengguna hak pilih dalam Daftar Pemilih Tetap (DPT) | D19: LK | E19: =BULUSAN!AC19+BULUSARI!R19+GOMBENGSARI!AC19+KALIPURO!AR19+KELIR!W19+KETAPANG!BE19+KLATAK!AV19+PESUCEN!R19+TELEMUNG!T19 -> 24074
D20: PR | E20: =BULUSAN!AC20+BULUSARI!R20+GOMBENGSARI!AC20+KALIPURO!AR20+KELIR!W20+KETAPANG!BE20+KLATAK!AV20+PESUCEN!R20+TELEMUNG!T20 -> 26769
D21: JML | E21: =SUM(E19:E20) -> 50843
B22: 2. | C22: Jumlah pengguna hak pilih dalam Daftar Pemilih Tambahan (DPTb) | D22: LK | E22: =BULUSAN!AC22+BULUSARI!R22+GOMBENGSARI!AC22+KALIPURO!AR22+KELIR!W22+KETAPANG!BE22+KLATAK!AV22+PESUCEN!R22+TELEMUNG!T22 -> 114
D23: PR | E23: =BULUSAN!AC23+BULUSARI!R23+GOMBENGSARI!AC23+KALIPURO!AR23+KELIR!W23+KETAPANG!BE23+KLATAK!AV23+PESUCEN!R23+TELEMUNG!T23 -> 97
D24: JML | E24: =SUM(E22:E23) -> 211
B25: 3. | C25: Jumlah pengguna hak pilih dalam Daftar Pemilih Khusus (DPK) | D25: LK | E25: =BULUSAN!AC25+BULUSARI!R25+GOMBENGSARI!AC25+KALIPURO!AR25+KELIR!W25+KETAPANG!BE25+KLATAK!AV25+PESUCEN!R25+TELEMUNG!T25 -> 361
D26: PR | E26: =BULUSAN!AC26+BULUSARI!R26+GOMBENGSARI!AC26+KALIPURO!AR26+KELIR!W26+KETAPANG!BE26+KLATAK!AV26+PESUCEN!R26+TELEMUNG!T26 -> 428
D27: JML | E27: =SUM(E25:E26) -> 789
B28: 4. | C28: Jumlah Pengguna Hak Pilih (B.1+B.2+B.3) | D28: LK | E28: =E19+E22+E25 -> 24549
D29: PR | E29: =E20+E23+E26 -> 27294
D30: JML | E30: =SUM(E28:E29) -> 51843
A32: II | B32: DATA PENGGUNAAN SURAT SUARA
A33: 1 | B33: Jumlah surat suara yang diterima, termasuk surat suara cadangan 2,5% dari DPT | E33: =BULUSAN!AC33+BULUSARI!R33+GOMBENGSARI!AC33+KALIPURO!AR33+KELIR!W33+KETAPANG!BE33+KLATAK!AV33+PESUCEN!R33+TELEMUNG!T33 -> 66196
A34: 2 | B34: Jumlah surat suara yang digunakan | E34: =BULUSAN!AC34+BULUSARI!R34+GOMBENGSARI!AC34+KALIPURO!AR34+KELIR!W34+KETAPANG!BE34+KLATAK!AV34+PESUCEN!R34+TELEMUNG!T34 -> 51843
A35: 3 | B35: Jumlah surat suara dikembalikan oleh pemilih (karena rusak atau keliru coblos) | E35: =BULUSAN!AC35+BULUSARI!R35+GOMBENGSARI!AC35+KALIPURO!AR35+KELIR!W35+KETAPANG!BE35+KLATAK!AV35+PESUCEN!R35+TELEMUNG!T35 -> 81
A36: 4 | B36: Jumlah surat suara yang tidak digunakan/tidak terpakai, termasuk sisa surat suara cadangan | E36: =E33-(E34+E35) -> 14272
A38: III | B38: DATA PEMILIH DISABILITAS
B39: Jumlah seluruh Pemilih disabilitas yang menggunakan hak pilih | D39: LK | E39: =BULUSAN!AC39+BULUSARI!R39+GOMBENGSARI!AC39+KALIPURO!AR39+KELIR!W39+KETAPANG!BE39+KLATAK!AV39+PESUCEN!R39+TELEMUNG!T39 -> 62
D40: PR | E40: =BULUSAN!AC40+BULUSARI!R40+GOMBENGSARI!AC40+KALIPURO!AR40+KELIR!W40+KETAPANG!BE40+KLATAK!AV40+PESUCEN!R40+TELEMUNG!T40 -> 85
D41: JML | E41: =SUM(E39:E40) -> 147
A43: IV | B43: DATA RINCIAN PEROLEHAN SUARA PASANGAN CALON BUPATI DAN WAKIL BUPATI
A44: NOMOR DAN NAMA CALON
A45: A.1 | B45: 1. | C45: Partai Kebangkitan Bangsa | E45: =BULUSAN!AC45+BULUSARI!R45+GOMBENGSARI!AC45+KALIPURO!AR45+KELIR!W45+KETAPANG!BE45+KLATAK!AV45+PESUCEN!R45+TELEMUNG!T45 -> 2171
A46: A.2 | C46: 1. Dra. Hj. MA`MULAH HARUN, M.Pd.I. | E46: =BULUSAN!AC46+BULUSARI!R46+GOMBENGSARI!AC46+KALIPURO!AR46+KELIR!W46+KETAPANG!BE46+KLATAK!AV46+PESUCEN!R46+TELEMUNG!T46 -> 4760
C47: 2. UBAIDILLAH, S.Fil.I. | E47: =BULUSAN!AC47+BULUSARI!R47+GOMBENGSARI!AC47+KALIPURO!AR47+KELIR!W47+KETAPANG!BE47+KLATAK!AV47+PESUCEN!R47+TELEMUNG!T47 -> 1143
C48: 3. Ir. H. YOYOK MULYADI, M.Si. | E48: =BULUSAN!AC48+BULUSARI!R48+GOMBENGSARI!AC48+KALIPURO!AR48+KELIR!W48+KETAPANG!BE48+KLATAK!AV48+PESUCEN!R48+TELEMUNG!T48 -> 357
C49: 4. KHOIRUL ANWAR, S.Fil.I. | E49: =BULUSAN!AC49+BULUSARI!R49+GOMBENGSARI!AC49+KALIPURO!AR49+KELIR!W49+KETAPANG!BE49+KLATAK!AV49+PESUCEN!R49+TELEMUNG!T49 -> 259
C50: 5. ARIF WIJAKSANA | E50: =BULUSAN!AC50+BULUSARI!R50+GOMBENGSARI!AC50+KALIPURO!AR50+KELIR!W50+KETAPANG!BE50+KLATAK!AV50+PESUCEN!R50+TELEMUNG!T50 -> 129
C51: 6. Dr. SITI YUMNAH | E51: =BULUSAN!AC51+BULUSARI!R51+GOMBENGSARI!AC51+KALIPURO!AR51+KELIR!W51+KETAPANG!BE51+KLATAK!AV51+PESUCEN!R51+TELEMUNG!T51 -> 106
C52: 7. MOHAMMAD ZAINI, M.Pd.I. | E52: =BULUSAN!AC52+BULUSARI!R52+GOMBENGSARI!AC52+KALIPURO!AR52+KELIR!W52+KETAPANG!BE52+KLATAK!AV52+PESUCEN!R52+TELEMUNG!T52 -> 84
...

Sheet BULUSAN
C2: Kecamatan | D2: KALIPURO
C3: Kabupaten | D3: BANYUWANGI
C4: Provinsi | D4: JAWA TIMUR
C9: Kelurahan | D9: BULUSAN
A12: I | B12: DATA PEMILIH DAN PENGGUNAAN HAK PILIH | AC12: JUMLAH AKHIR
A13: A | B13: DATA PEMILIH | E13: TPS 001 | F13: TPS 002 | G13: TPS 003 | H13: TPS 004 | I13: TPS 005 | J13: TPS 006 | K13: TPS 007 | L13: TPS 008 | M13: TPS 009 | N13: TPS 010 | O13: TPS 011 | P13: TPS 012 | Q13: TPS 013 | R13: TPS 014 | S13: TPS 015 | T13: TPS 016 | U13: TPS 017 | V13: TPS 018 | W13: TPS 019 | X13: TPS 020 | Y13: TPS 021 | Z13: TPS 022 | AA13: TPS 023 | AB13: TPS 024
B14: Jumlah Pemilih dalam Daftar Pemilih Tetap (DPT) | D14: LK | E14: 148 | F14: 140 | G14: 133 | H14: 145 | I14: 130 | J14: 136 | K14: 147 | L14: 130 | M14: 139 | N14: 140 | O14: 129 | P14: 109 | Q14: 148 | R14: 138 | S14: 139 | T14: 143 | U14: 140 | V14: 131 | W14: 132 | X14: 144 | Y14: 104 | Z14: 86 | AA14: 146 | AB14: 116 | AC14: =SUM(E14:AB14) -> 3193
D15: PR | E15: 146 | F15: 139 | G15: 139 | H15: 150 | I15: 136 | J15: 144 | K15: 133 | L15: 153 | M15: 145 | N15: 134 | O15: 144 | P15: 118 | Q15: 140 | R15: 146 | S15: 139 | T15: 142 | U15: 137 | V15: 134 | W15: 149 | X15: 148 | Y15: 122 | Z15: 110 | AA15: 142 | AB15: 124 | AC15: =SUM(E15:AB15) -> 3314
D16: JML | E16: =SUM(E14:E15) -> 294 | F16: =SUM(F14:F15) -> 279 | G16: =SUM(G14:G15) -> 272 | H16: =SUM(H14:H15) -> 295 | I16: =SUM(I14:I15) -> 266 | J16: =SUM(J14:J15) -> 280 | K16: =SUM(K14:K15) -> 280 | L16: =SUM(L14:L15) -> 283 | ... AB16: =SUM(AB14:AB15) -> 240 | AC16: =SUM(E16:AB16) -> 6507
A18: B | B18: PENGGUNA HAK PILIH
B19: 1. | C19: Jumlah pengguna hak pilih dalam Daftar Pemilih Tetap (DPT) | D19: LK | E19: 101 | F19: 102 | G19: 101 | H19: 122 | I19: 82 | J19: 102 | K19: 111 | L19: 98 | M19: 95 | N19: 102 | O19: 88 | P19: 68 | Q19: 92 | R19: 92 | S19: 86 | T19: 117 | U19: 122 | V19: 108 | W19: 106 | X19: 104 | Y19: 89 | Z19: 65 | AA19: 92 | AB19: 94 | AC19: =SUM(E19:AB19) -> 2339
D20: PR | E20: 117 | F20: 115 | G20: 119 | H20: 125 | I20: 107 | J20: 119 | K20: 107 | L20: 121 | M20: 119 | N20: 111 | O20: 116 | P20: 100 | Q20: 97 | R20: 109 | S20: 111 | T20: 121 | U20: 121 | V20: 121 | W20: 118 | X20: 116 | Y20: 101 | Z20: 91 | AA20: 110 | AB20: 108 | AC20: =SUM(E20:AB20) -> 2700
D21: JML | E21: =SUM(E19:E20) -> 218 | F21: =SUM(F19:F20) -> 217 | G21: =SUM(G19:G20) -> 220 | H21: =SUM(H19:H20) -> 247 | I21: =SUM(I19:I20) -> 189 | J21: =SUM(J19:J20) -> 221 | K21: =SUM(K19:K20) -> 218 | L21: =SUM(L19:L20) -> 219 | ... AB21: =SUM(AB19:AB20) -> 202 | AC21: =SUM(E21:AB21) -> 5039
B22: 2. | C22: Jumlah pengguna hak pilih dalam Daftar Pemilih Tambahan (DPTb) | D22: LK | E22: 1 | F22: 0 | G22: 1 | H22: 1 | I22: 0 | J22: 0 | K22: 0 | L22: 0 | M22: 1 | N22: 0 | O22: 0 | P22: 0 | Q22: 1 | R22: 1 | S22: 0 | T22: 0 | U22: 0 | V22: 0 | W22: 1 | X22: 0 | Y22: 0 | Z22: 0 | AA22: 0 | AB22: 0 | AC22: =SUM(E22:AB22) -> 7
D23: PR | E23: 1 | F23: 1 | G23: 0 | H23: 0 | I23: 0 | J23: 1 | K23: 1 | L23: 1 | M23: 0 | N23: 0 | O23: 0 | P23: 1 | Q23: 0 | R23: 0 | S23: 1 | T23: 2 | U23: 1 | V23: 1 | W23: 0 | X23: 1 | Y23: 1 | Z23: 1 | AA23: 1 | AB23: 1 | AC23: =SUM(E23:AB23) -> 16
D24: JML | E24: =SUM(E22:E23) -> 2 | F24: =SUM(F22:F23) -> 1 | G24: =SUM(G22:G23) -> 1 | H24: =SUM(H22:H23) -> 1 | I24: =SUM(I22:I23) -> 0 | J24: =SUM(J22:J23) -> 1 | K24: =SUM(K22:K23) -> 1 | L24: 1 | M24: 1 | N24: =SUM(N22:N23) -> 0 | O24: =SUM(O22:O23) -> 0 | P24: =SUM(P22:P23) -> 1 | Q24: =SUM(Q22:Q23) -> 1 | R24: =SUM(R22:R23) -> 1 | S24: =SUM(S22:S23) -> 1 | T24: =SUM(T22:T23) -> 2 | U24: =SUM(U22:U23) -> 1 | ... AB24: =SUM(AB22:AB23) -> 1 | AC24: =SUM(E24:AB24) -> 23
B25: 3. | C25: Jumlah pengguna hak pilih dalam Daftar Pemilih Khusus (DPK) | D25: LK | E25: 2 | F25: 1 | G25: 0 | H25: 0 | I25: 0 | J25: 0 | K25: 2 | L25: 4 | M25: 0 | N25: 0 | O25: 0 | P25: 3 | Q25: 1 | R25: 0 | S25: 1 | T25: 0 | U25: 3 | V25: 1 | W25: 0 | X25: 1 | Y25: 0 | Z25: 5 | AA25: 0 | AB25: 3 | AC25: =SUM(E25:AB25) -> 27
D26: PR | E26: 4 | F26: 3 | G26: 0 | H26: 0 | I26: 1 | J26: 1 | K26: 0 | L26: 4 | M26: 0 | N26: 1 | O26: 1 | P26: 4 | Q26: 1 | R26: 0 | S26: 2 | T26: 0 | U26: 1 | V26: 1 | W26: 0 | X26: 3 | Y26: 0 | Z26: 1 | AA26: 0 | AB26: 4 | AC26: =SUM(E26:AB26) -> 32
D27: JML | E27: =SUM(E25:E26) -> 6 | F27: =SUM(F25:F26) -> 4 | G27: =SUM(G25:G26) -> 0 | H27: =SUM(H25:H26) -> 0 | I27: =SUM(I25:I26) -> 1 | J27: =SUM(J25:J26) -> 1 | K27: =SUM(K25:K26) -> 2 | L27: =SUM(L25:L26) -> 8 | ... AB27: =SUM(AB25:AB26) -> 7 | AC27: =SUM(E27:AB27) -> 59
B28: 4. | C28: Jumlah Pengguna Hak Pilih (B.1+B.2+B.3) | D28: LK | E28: =SUM(E19,E22,E25) -> 104 | F28: =SUM(F19,F22,F25) -> 103 | G28: =SUM(G19,G22,G25) -> 102 | H28: =SUM(H19,H22,H25) -> 123 | I28: =SUM(I19,I22,I25) -> 82 | J28: =SUM(J19,J22,J25) -> 102 | K28: =SUM(K19,K22,K25) -> 113 | L28: =SUM(L19,L22,L25) -> 102 | ... AB28: =SUM(AB19,AB22,AB25) -> 97 | AC28: =SUM(E28:AB28) -> 2373
D29: PR | E29: =SUM(E20,E23,E26) -> 122 | F29: =SUM(F20,F23,F26) -> 119 | G29: =SUM(G20,G23,G26) -> 119 | H29: =SUM(H20,H23,H26) -> 125 | I29: =SUM(I20,I23,I26) -> 108 | J29: =SUM(J20,J23,J26) -> 121 | K29: =SUM(K20,K23,K26) -> 108 | L29: =SUM(L20,L23,L26) -> 126 | ... AB29: =SUM(AB20,AB23,AB26) -> 113 | AC29: =SUM(E29:AB29) -> 2748
D30: JML | E30: =SUM(E28:E29) -> 226 | F30: =SUM(F28:F29) -> 222 | G30: =SUM(G28:G29) -> 221 | H30: =SUM(H28:H29) -> 248 | I30: =SUM(I28:I29) -> 190 | J30: =SUM(J28:J29) -> 223 | K30: =SUM(K28:K29) -> 221 | L30: =SUM(L28:L29) -> 228 | ... AB30: =SUM(AB28:AB29) -> 210 | AC30: =SUM(E30:AB30) -> 5121
A32: II | B32: DATA PENGGUNAAN SURAT SUARA
A33: 1 | B33: Jumlah surat suara yang diterima, termasuk surat suara cadangan 2,5% dari DPT | E33: 300 | F33: 286 | G33: 278 | H33: 301 | I33: 272 | J33: 286 | K33: 286 | L33: 289 | M33: 271 | N33: 280 | O33: 279 | P33: 232 | Q33: 295 | R33: 290 | S33: 284 | T33: 291 | U33: 283 | V33: 270 | W33: 287 | X33: 298 | Y33: 231 | Z33: 200 | AA33: 294 | AB33: 245 | AC33: =SUM(E33:AB33) -> 6628
A34: 2 | B34: Jumlah surat suara yang digunakan | E34: 226 | F34: 222 | G34: 221 | H34: 248 | I34: 190 | J34: 223 | K34: 221 | L34: 228 | M34: 215 | N34: 214 | O34: 205 | P34: 176 | Q34: 192 | R34: 202 | S34: 201 | T34: 240 | U34: 248 | V34: 232 | W34: 225 | X34: 225 | Y34: 191 | Z34: 163 | AA34: 203 | AB34: 210 | AC34: =SUM(E34:AB34) -> 5121
A35: 3 | B35: Jumlah surat suara dikembalikan oleh pemilih (karena rusak atau keliru coblos) | E35: 0 | F35: 0 | G35: 2 | H35: 0 | I35: 0 | J35: 0 | K35: 1 | L35: 0 | M35: 0 | N35: 0 | O35: 0 | P35: 1 | Q35: 0 | R35: 0 | S35: 0 | T35: 2 | U35: 2 | V35: 0 | W35: 0 | X35: 0 | Y35: 0 | Z35: 17 | AA35: 1 | AB35: 0 | AC35: =SUM(E35:AB35) -> 26
A36: 4 | B36: Jumlah surat suara yang tidak digunakan/tidak terpakai, termasuk sisa surat suara cadangan | E36: =E33-(E34+E35) -> 74 | F36: =F33-(F34+F35) -> 64 | G36: =G33-(G34+G35) -> 55 | H36: =H33-(H34+H35) -> 53 | I36: =I33-(I34+I35) -> 82 | J36: =J33-(J34+J35) -> 63 | K36: =K33-(K34+K35) -> 64 | L36: =L33-(L34+L35) -> 61 | ... AB36: =AB33-(AB34+AB35) -> 35 | AC36: =SUM(E36:AB36) -> 1481
A38: III | B38: DATA PEMILIH DISABILITAS
B39: Jumlah seluruh Pemilih disabilitas yang menggunakan hak pilih | D39: LK | I39: 1 | K39: 3 | AC39: =SUM(E39:AB39) -> 4
D40: PR | K40: 6 | AC40: =SUM(E40:AB40) -> 6
D41: JML | E41: =SUM(E39:E40) -> 0 | F41: =SUM(F39:F40) -> 0 | G41: =SUM(G39:G40) -> 0 | H41: =SUM(H39:H40) -> 0 | I41: =SUM(I39:I40) -> 1 | J41: =SUM(J39:J40) -> 0 | K41: =SUM(K39:K40) -> 9 | L41: =SUM(L39:L40) -> 0 | ... AB41: =SUM(AB39:AB40) -> 0 | AC41: =SUM(E41:AB41) -> 10
A43: IV | B43: DATA RINCIAN PEROLEHAN SUARA PASANGAN CALON BUPATI DAN WAKIL BUPATI
A44: NOMOR DAN NAMA CALON
A45: A.1 | B45: 1. | C45: Partai Kebangkitan Bangsa | E45: 6 | F45: 15 | G45: 10 | H45: 12 | I45: 5 | J45: 13 | K45: 11 | L45: 22 | M45: 4 | N45: 7 | O45: 8 | P45: 2 | Q45: 6 | R45: 4 | S45: 2 | T45: 7 | U45: 17 | V45: 14 | W45: 14 | X45: 5 | Y45: 7 | Z45: 13 | AA45: 15 | AB45: 11 | AC45: =SUM(E45:AB45) -> 230
A46: A.2 | C46: 1. Dra. Hj. MA`MULAH HARUN, M.Pd.I. | E46: 24 | F46: 31 | G46: 27 | H46: 18 | I46: 38 | J46: 10 | K46: 37 | L46: 36 | M46: 28 | N46: 23 | O46: 13 | P46: 10 | Q46: 16 | R46: 26 | S46: 4 | T46: 42 | U46: 36 | V46: 23 | W46: 30 | X46: 52 | Y46: 6 | Z46: 11 | AA46: 28 | AB46: 14 | AC46: =SUM(E46:AB46) -> 583
C47: 2. UBAIDILLAH, S.Fil.I. | E47: 1 | F47: 5 | G47: 14 | H47: 2 | I47: 1 | J47: 3 | K47: 2 | L47: 5 | M47: 10 | N47: 0 | O47: 6 | P47: 14 | Q47: 50 | R47: 0 | S47: 1 | T47: 5 | U47: 30 | V47: 9 | W47: 1 | X47: 3 | Y47: 6 | Z47: 4 | AA47: 1 | AB47: 6 | AC47: =SUM(E47:AB47) -> 179
C48: 3. Ir. H. YOYOK MULYADI, M.Si. | E48: 1 | F48: 7 | G48: 0 | H48: 1 | I48: 1 | J48: 3 | K48: 0 | L48: 2 | M48: 2 | N48: 1 | O48: 1 | P48: 2 | Q48: 3 | R48: 3 | S48: 1 | T48: 12 | U48: 15 | V48: 3 | W48: 2 | X48: 6 | Y48: 1 | Z48: 0 | AA48: 1 | AB48: 2 | AC48: =SUM(E48:AB48) -> 70
C49: 4. KHOIRUL ANWAR, S.Fil.I. | E49: 1 | F49: 3 | G49: 2 | H49: 1 | I49: 3 | J49: 3 | K49: 7 | L49: 8 | M49: 2 | N49: 0 | O49: 3 | P49: 1 | Q49: 0 | R49: 0 | S49: 0 | T49: 3 | U49: 3 | V49: 3 | W49: 4 | X49: 3 | Y49: 27 | Z49: 3 | AA49: 1 | AB49: 7 | AC49: =SUM(E49:AB49) -> 88
C50: 5. ARIF WIJAKSANA | E50: 0 | F50: 0 | G50: 1 | H50: 0 | I50: 3 | J50: 3 | K50: 1 | L50: 1 | M50: 4 | N50: 2 | O50: 0 | P50: 1 | Q50: 1 | R50: 0 | S50: 1 | T50: 1 | U50: 2 | V50: 0 | W50: 1 | X50: 1 | Y50: 0 | Z50: 0 | AA50: 0 | AB50: 0 | AC50: =SUM(E50:AB50) -> 23
C51: 6. Dr. SITI YUMNAH | E51: 0 | F51: 1 | G51: 2 | H51: 1 | I51: 1 | J51: 0 | K51: 1 | L51: 3 | M51: 0 | N51: 1 | O51: 0 | P51: 0 | Q51: 1 | R51: 1 | S51: 0 | T51: 0 | U51: 2 | V51: 1 | W51: 0 | X51: 0 | Y51: 1 | Z51: 0 | AA51: 0 | AB51: 0 | AC51: =SUM(E51:AB51) -> 16
...

Sheet BULUSARI
C2: Kecamatan | D2: KALIPURO
C3: Kabupaten | D3: BANYUWANGI
C4: Provinsi | D4: JAWA TIMUR
C9: Kelurahan | D9: BULUSARI
A12: I | B12: DATA PEMILIH DAN PENGGUNAAN HAK PILIH | R12: JUMLAH AKHIR
A13: A | B13: DATA PEMILIH | E13: TPS 001 | F13: TPS 002 | G13: TPS 003 | H13: TPS 004 | I13: TPS 005 | J13: TPS 006 | K13: TPS 007 | L13: TPS 008 | M13: TPS 009 | N13: TPS 010 | O13: TPS 011 | P13: TPS 012 | Q13: TPS 013
B14: Jumlah Pemilih dalam Daftar Pemilih Tetap (DPT) | D14: LK | E14: 135 | F14: 127 | G14: 141 | H14: 142 | I14: 122 | J14: 103 | K14: 120 | L14: 109 | M14: 129 | N14: 137 | O14: 111 | P14: 114 | Q14: 141 | R14: =SUM(E14:Q14) -> 1631
D15: PR | E15: 135 | F15: 125 | G15: 117 | H15: 141 | I15: 117 | J15: 108 | K15: 118 | L15: 128 | M15: 136 | N15: 122 | O15: 110 | P15: 112 | Q15: 128 | R15: =SUM(E15:Q15) -> 1597
D16: JML | E16: =SUM(E14:E15) -> 270 | F16: =SUM(F14:F15) -> 252 | G16: =SUM(G14:G15) -> 258 | H16: =SUM(H14:H15) -> 283 | I16: =SUM(I14:I15) -> 239 | J16: =SUM(J14:J15) -> 211 | K16: =SUM(K14:K15) -> 238 | L16: =SUM(L14:L15) -> 237 | ... Q16: =SUM(Q14:Q15) -> 269 | R16: =SUM(E16:Q16) -> 3228
A18: B | B18: PENGGUNA HAK PILIH
B19: 1. | C19: Jumlah pengguna hak pilih dalam Daftar Pemilih Tetap (DPT) | D19: LK | E19: 114 | F19: 89 | G19: 119 | H19: 120 | I19: 109 | J19: 98 | K19: 93 | L19: 99 | M19: 101 | N19: 115 | O19: 93 | P19: 93 | Q19: 101 | R19: =SUM(E19:Q19) -> 1344
D20: PR | E20: 120 | F20: 120 | G20: 97 | H20: 127 | I20: 112 | J20: 95 | K20: 102 | L20: 117 | M20: 116 | N20: 109 | O20: 100 | P20: 100 | Q20: 113 | R20: =SUM(E20:Q20) -> 1428
D21: JML | E21: =SUM(E19:E20) -> 234 | F21: =SUM(F19:F20) -> 209 | G21: =SUM(G19:G20) -> 216 | H21: =SUM(H19:H20) -> 247 | I21: =SUM(I19:I20) -> 221 | J21: =SUM(J19:J20) -> 193 | K21: =SUM(K19:K20) -> 195 | L21: =SUM(L19:L20) -> 216 | ... Q21: =SUM(Q19:Q20) -> 214 | R21: =SUM(E21:Q21) -> 2772
B22: 2. | C22: Jumlah pengguna hak pilih dalam Daftar Pemilih Tambahan (DPTb) | D22: LK | E22: 3 | F22: 0 | G22: 0 | H22: 2 | I22: 0 | J22: 0 | K22: 0 | L22: 0 | M22: 0 | N22: 0 | O22: 1 | P22: 0 | Q22: 1 | R22: =SUM(E22:Q22) -> 7
D23: PR | E23: 0 | F23: 3 | G23: 0 | H23: 0 | I23: 1 | J23: 1 | K23: 0 | L23: 1 | M23: 0 | N23: 0 | O23: 0 | P23: 0 | Q23: 0 | R23: =SUM(E23:Q23) -> 6
D24: JML | E24: =SUM(E22:E23) -> 3 | F24: =SUM(F22:F23) -> 3 | G24: =SUM(G22:G23) -> 0 | H24: =SUM(H22:H23) -> 2 | I24: =SUM(I22:I23) -> 1 | J24: =SUM(J22:J23) -> 1 | K24: =SUM(K22:K23) -> 0 | L24: =SUM(L22:L23) -> 1 | ... Q24: =SUM(Q22:Q23) -> 1 | R24: =SUM(E24:Q24) -> 13
B25: 3. | C25: Jumlah pengguna hak pilih dalam Daftar Pemilih Khusus (DPK) | D25: LK | E25: 0 | F25: 1 | G25: 0 | H25: 0 | I25: 1 | J25: 3 | K25: 1 | L25: 0 | M25: 0 | N25: 5 | O25: 2 | P25: 0 | Q25: 2 | R25: =SUM(E25:Q25) -> 15
D26: PR | E26: 0 | F26: 2 | G26: 0 | H26: 0 | I26: 3 | J26: 4 | K26: 2 | L26: 0 | M26: 0 | N26: 5 | O26: 0 | P26: 1 | Q26: 1 | R26: =SUM(E26:Q26) -> 18
D27: JML | E27: =SUM(E25:E26) -> 0 | F27: =SUM(F25:F26) -> 3 | G27: =SUM(G25:G26) -> 0 | H27: =SUM(H25:H26) -> 0 | I27: =SUM(I25:I26) -> 4 | J27: =SUM(J25:J26) -> 7 | K27: =SUM(K25:K26) -> 3 | L27: =SUM(L25:L26) -> 0 | ... Q27: =SUM(Q25:Q26) -> 3 | R27: =SUM(E27:Q27) -> 33
B28: 4. | C28: Jumlah Pengguna Hak Pilih (B.1+B.2+B.3) | D28: LK | E28: =SUM(E19,E22,E25) -> 117 | F28: =SUM(F19,F22,F25) -> 90 | G28: =SUM(G19,G22,G25) -> 119 | H28: =SUM(H19,H22,H25) -> 122 | I28: =SUM(I19,I22,I25) -> 110 | J28: =SUM(J19,J22,J25) -> 101 | K28: =SUM(K19,K22,K25) -> 94 | L28: =SUM(L19,L22,L25) -> 99 | ... Q28: =SUM(Q19,Q22,Q25) -> 104 | R28: =SUM(E28:Q28) -> 1366
D29: PR | E29: =SUM(E20,E23,E26) -> 120 | F29: =SUM(F20,F23,F26) -> 125 | G29: =SUM(G20,G23,G26) -> 97 | H29: =SUM(H20,H23,H26) -> 127 | I29: =SUM(I20,I23,I26) -> 116 | J29: =SUM(J20,J23,J26) -> 100 | K29: =SUM(K20,K23,K26) -> 104 | L29: =SUM(L20,L23,L26) -> 118 | ... Q29: =SUM(Q20,Q23,Q26) -> 114 | R29: =SUM(E29:Q29) -> 1452
D30: JML | E30: =SUM(E28:E29) -> 237 | F30: =SUM(F28:F29) -> 215 | G30: =SUM(G28:G29) -> 216 | H30: =SUM(H28:H29) -> 249 | I30: =SUM(I28:I29) -> 226 | J30: =SUM(J28:J29) -> 201 | K30: =SUM(K28:K29) -> 198 | L30: =SUM(L28:L29) -> 217 | ... Q30: =SUM(Q28:Q29) -> 218 | R30: =SUM(E30:Q30) -> 2818
A32: II | B32: DATA PENGGUNAAN SURAT SUARA
A33: 1 | B33: Jumlah surat suara yang diterima, termasuk surat suara cadangan 2,5% dari DPT | E33: 276 | F33: 259 | G33: 264 | H33: 290 | I33: 245 | J33: 216 | K33: 243 | L33: 243 | M33: 271 | N33: 262 | O33: 226 | P33: 232 | Q33: 275 | R33: =SUM(E33:Q33) -> 3302
A34: 2 | B34: Jumlah surat suara yang digunakan | E34: 237 | F34: 215 | G34: 216 | H34: 249 | I34: 226 | J34: 201 | K34: 198 | L34: 217 | M34: 217 | N34: 234 | O34: 196 | P34: 194 | Q34: 218 | R34: =SUM(E34:Q34) -> 2818
A35: 3 | B35: Jumlah surat suara dikembalikan oleh pemilih (karena rusak atau keliru coblos) | F35: 1 | O35: 1 | R35: =SUM(E35:Q35) -> 2
A36: 4 | B36: Jumlah surat suara yang tidak digunakan/tidak terpakai, termasuk sisa surat suara cadangan | E36: =E33-(E34+E35) -> 39 | F36: =F33-(F34+F35) -> 43 | G36: =G33-(G34+G35) -> 48 | H36: =H33-(H34+H35) -> 41 | I36: =I33-(I34+I35) -> 19 | J36: =J33-(J34+J35) -> 15 | K36: =K33-(K34+K35) -> 45 | L36: =L33-(L34+L35) -> 26 | ... Q36: =Q33-(Q34+Q35) -> 57 | R36: =SUM(E36:Q36) -> 482
A38: III | B38: DATA PEMILIH DISABILITAS
B39: Jumlah seluruh Pemilih disabilitas yang menggunakan hak pilih | D39: LK | F39: 1 | R39: =SUM(E39:Q39) -> 1
D40: PR | R40: =SUM(E40:Q40) -> 0
D41: JML | E41: =SUM(E39:E40) -> 0 | F41: =SUM(F39:F40) -> 1 | G41: =SUM(G39:G40) -> 0 | H41: =SUM(H39:H40) -> 0 | I41: =SUM(I39:I40) -> 0 | J41: =SUM(J39:J40) -> 0 | K41: =SUM(K39:K40) -> 0 | L41: =SUM(L39:L40) -> 0 | ... Q41: =SUM(Q39:Q40) -> 0 | R41: =SUM(E41:Q41) -> 1
A43: IV | B43: DATA RINCIAN PEROLEHAN SUARA PASANGAN CALON BUPATI DAN WAKIL BUPATI
A44: NOMOR DAN NAMA CALON
A45: A.1 | B45: 1. | C45: Partai Kebangkitan Bangsa | E45: 9 | F45: 7 | G45: 8 | H45: 11 | I45: 5 | J45: 6 | K45: 5 | L45: 7 | M45: 13 | N45: 5 | O45: 6 | P45: 7 | Q45: 4 | R45: =SUM(E45:Q45) -> 93
A46: A.2 | C46: 1. Dra. Hj. MA`MULAH HARUN, M.Pd.I. | E46: 15 | F46: 18 | G46: 19 | H46: 12 | I46: 31 | J46: 18 | K46: 29 | L46: 43 | M46: 38 | N46: 9 | O46: 38 | P46: 17 | Q46: 28 | R46: =SUM(E46:Q46) -> 315
C47: 2. UBAIDILLAH, S.Fil.I. | E47: 8 | F47: 1 | G47: 0 | H47: 0 | I47: 2 | J47: 3 | K47: 1 | L47: 0 | M47: 1 | N47: 1 | O47: 1 | P47: 0 | Q47: 0 | R47: =SUM(E47:Q47) -> 18
C48: 3. Ir. H. YOYOK MULYADI, M.Si. | E48: 5 | F48: 0 | G48: 0 | H48: 0 | I48: 0 | J48: 4 | K48: 1 | L48: 0 | M48: 1 | N48: 0 | O48: 0 | P48: 0 | Q48: 0 | R48: =SUM(E48:Q48) -> 11
C49: 4. KHOIRUL ANWAR, S.Fil.I. | E49: 0 | F49: 0 | G49: 0 | H49: 0 | I49: 0 | J49: 0 | K49: 0 | L49: 1 | M49: 0 | N49: 0 | O49: 1 | P49: 0 | Q49: 0 | R49: =SUM(E49:Q49) -> 2
C50: 5. ARIF WIJAKSANA | E50: 1 | F50: 0 | G50: 0 | H50: 0 | I50: 0 | J50: 0 | K50: 2 | L50: 0 | M50: 0 | N50: 0 | O50: 0 | P50: 0 | Q50: 0 | R50: =SUM(E50:Q50) -> 3
C51: 6. Dr. SITI YUMNAH | E51: 0 | F51: 0 | G51: 0 | H51: 0 | I51: 0 | J51: 0 | K51: 0 | L51: 0 | M51: 0 | N51: 0 | O51: 0 | P51: 0 | Q51: 0 | R51: =SUM(E51:Q51) -> 0
...

Sheet GOMBENGSARI
C2: Kecamatan | D2: KALIPURO
C3: Kabupaten | D3: BANYUWANGI
C4: Provinsi | D4: JAWA TIMUR
C9: Kelurahan | D9: GOMBENGSARI
A12: I | B12: DATA PEMILIH DAN PENGGUNAAN HAK PILIH | AC12: JUMLAH AKHIR
A13: A | B13: DATA PEMILIH | E13: TPS 001 | F13: TPS 002 | G13: TPS 003 | H13: TPS 004 | I13: TPS 005 | J13: TPS 006 | K13: TPS 007 | L13: TPS 008 | M13: TPS 009 | N13: TPS 010 | O13: TPS 011 | P13: TPS 012 | Q13: TPS 013 | R13: TPS 014 | S13: TPS 015 | T13: TPS 016 | U13: TPS 017 | V13: TPS 018 | W13: TPS 019 | X13: TPS 020 | Y13: TPS 021 | Z13: TPS 022 | AA13: TPS 023 | AB13: TPS 024
B14: Jumlah Pemilih dalam Daftar Pemilih Tetap (DPT) | D14: LK | E14: 88 | F14: 112 | G14: 144 | H14: 112 | I14: 130 | J14: 147 | K14: 145 | L14: 148 | M14: 125 | N14: 122 | O14: 120 | P14: 148 | Q14: 148 | R14: 139 | S14: 100 | T14: 141 | U14: 139 | V14: 139 | W14: 139 | X14: 137 | Y14: 122 | Z14: 109 | AA14: 124 | AB14: 127 | AC14: =SUM(E14:AB14) -> 3105
D15: PR | E15: 84 | F15: 119 | G15: 147 | H15: 118 | I15: 144 | J15: 150 | K15: 150 | L15: 143 | M15: 136 | N15: 125 | O15: 132 | P15: 146 | Q15: 140 | R15: 146 | S15: 100 | T15: 143 | U15: 142 | V15: 139 | W15: 145 | X15: 130 | Y15: 130 | Z15: 108 | AA15: 132 | AB15: 123 | AC15: =SUM(E15:AB15) -> 3172
D16: JML | E16: =SUM(E14:E15) -> 172 | F16: =SUM(F14:F15) -> 231 | G16: =SUM(G14:G15) -> 291 | H16: =SUM(H14:H15) -> 230 | I16: =SUM(I14:I15) -> 274 | J16: =SUM(J14:J15) -> 297 | K16: =SUM(K14:K15) -> 295 | L16: =SUM(L14:L15) -> 291 | ... AB16: =SUM(AB14:AB15) -> 250 | AC16: =SUM(E16:AB16) -> 6277
A18: B | B18: PENGGUNA HAK PILIH
B19: 1. | C19: Jumlah pengguna hak pilih dalam Daftar Pemilih Tetap (DPT) | D19: LK | E19: 63 | F19: 88 | G19: 101 | H19: 80 | I19: 104 | J19: 117 | K19: 117 | L19: 124 | M19: 96 | N19: 98 | O19: 106 | P19: 124 | Q19: 111 | R19: 115 | S19: 94 | T19: 121 | U19: 120 | V19: 123 | W19: 112 | X19: 114 | Y19: 105 | Z19: 87 | AA19: 99 | AB19: 97 | AC19: =SUM(E19:AB19) -> 2516
D20: PR | E20: 73 | F20: 104 | G20: 118 | H20: 97 | I20: 133 | J20: 129 | K20: 128 | L20: 127 | M20: 107 | N20: 106 | O20: 122 | P20: 125 | Q20: 116 | R20: 123 | S20: 94 | T20: 122 | U20: 121 | V20: 120 | W20: 122 | X20: 108 | Y20: 107 | Z20: 89 | AA20: 118 | AB20: 96 | AC20: =SUM(E20:AB20) -> 2705
D21: JML | E21: =SUM(E19:E20) -> 136 | F21: =SUM(F19:F20) -> 192 | G21: =SUM(G19:G20) -> 219 | H21: =SUM(H19:H20) -> 177 | I21: =SUM(I19:I20) -> 237 | J21: =SUM(J19:J20) -> 246 | K21: =SUM(K19:K20) -> 245 | L21: =SUM(L19:L20) -> 251 | ... AB21: =SUM(AB19:AB20) -> 193 | AC21: =SUM(E21:AB21) -> 5221
B22: 2. | C22: Jumlah pengguna hak pilih dalam Daftar Pemilih Tambahan (DPTb) | D22: LK | E22: 0 | F22: 0 | G22: 0 | H22: 0 | I22: 0 | J22: 0 | K22: 0 | L22: 0 | M22: 1 | N22: 0 | O22: 0 | P22: 0 | Q22: 1 | R22: 0 | S22: 0 | T22: 1 | U22: 0 | V22: 0 | W22: 0 | X22: 0 | Y22: 0 | Z22: 0 | AA22: 1 | AB22: 0 | AC22: =SUM(E22:AB22) -> 4
D23: PR | E23: 1 | F23: 0 | G23: 1 | H23: 0 | I23: 1 | J23: 0 | K23: 1 | L23: 0 | M23: 0 | N23: 0 | O23: 0 | P23: 0 | Q23: 2 | R23: 0 | S23: 1 | T23: 0 | U23: 0 | V23: 0 | W23: 1 | X23: 0 | Y23: 0 | Z23: 0 | AA23: 1 | AB23: 1 | AC23: =SUM(E23:AB23) -> 10
D24: JML | E24: =SUM(E22:E23) -> 1 | F24: =SUM(F22:F23) -> 0 | G24: =SUM(G22:G23) -> 1 | H24: =SUM(H22:H23) -> 0 | I24: =SUM(I22:I23) -> 1 | J24: =SUM(J22:J23) -> 0 | K24: =SUM(K22:K23) -> 1 | L24: =SUM(L22:L23) -> 0 | ... AB24: =SUM(AB22:AB23) -> 1 | AC24: =SUM(E24:AB24) -> 14
B25: 3. | C25: Jumlah pengguna hak pilih dalam Daftar Pemilih Khusus (DPK) | D25: LK | E25: 0 | F25: 1 | G25: 0 | H25: 0 | I25: 1 | J25: 0 | K25: 1 | L25: 1 | M25: 0 | N25: 0 | O25: 0 | P25: 0 | Q25: 0 | R25: 0 | S25: 0 | T25: 0 | U25: 0 | V25: 3 | W25: 1 | X25: 3 | Y25: 3 | Z25: 0 | AA25: 0 | AB25: 1 | AC25: =SUM(E25:AB25) -> 15
D26: PR | E26: 1 | F26: 3 | G26: 1 | H26: 1 | I26: 0 | J26: 0 | K26: 2 | L26: 1 | M26: 1 | N26: 0 | O26: 0 | P26: 0 | Q26: 0 | R26: 0 | S26: 0 | T26: 0 | U26: 1 | V26: 0 | W26: 1 | X26: 2 | Y26: 2 | Z26: 0 | AA26: 0 | AB26: 1 | AC26: =SUM(E26:AB26) -> 17
D27: JML | E27: =SUM(E25:E26) -> 1 | F27: =SUM(F25:F26) -> 4 | G27: =SUM(G25:G26) -> 1 | H27: =SUM(H25:H26) -> 1 | I27: =SUM(I25:I26) -> 1 | J27: =SUM(J25:J26) -> 0 | K27: =SUM(K25:K26) -> 3 | L27: =SUM(L25:L26) -> 2 | ... AB27: =SUM(AB25:AB26) -> 2 | AC27: =SUM(E27:AB27) -> 32
B28: 4. | C28: Jumlah Pengguna Hak Pilih (B.1+B.2+B.3) | D28: LK | E28: =SUM(E19,E22,E25) -> 63 | F28: =SUM(F19,F22,F25) -> 89 | G28: =SUM(G19,G22,G25) -> 101 | H28: =SUM(H19,H22,H25) -> 80 | I28: =SUM(I19,I22,I25) -> 105 | J28: =SUM(J19,J22,J25) -> 117 | K28: =SUM(K19,K22,K25) -> 118 | L28: =SUM(L19,L22,L25) -> 125 | ... AB28: =SUM(AB19,AB22,AB25) -> 98 | AC28: =SUM(E28:AB28) -> 2535
D29: PR | E29: =SUM(E20,E23,E26) -> 75 | F29: =SUM(F20,F23,F26) -> 107 | G29: =SUM(G20,G23,G26) -> 120 | H29: =SUM(H20,H23,H26) -> 98 | I29: =SUM(I20,I23,I26) -> 134 | J29: =SUM(J20,J23,J26) -> 129 | K29: =SUM(K20,K23,K26) -> 131 | L29: =SUM(L20,L23,L26) -> 128 | ... AB29: =SUM(AB20,AB23,AB26) -> 98 | AC29: =SUM(E29:AB29) -> 2732
D30: JML | E30: =SUM(E28:E29) -> 138 | F30: =SUM(F28:F29) -> 196 | G30: =SUM(G28:G29) -> 221 | H30: =SUM(H28:H29) -> 178 | I30: =SUM(I28:I29) -> 239 | J30: =SUM(J28:J29) -> 246 | K30: =SUM(K28:K29) -> 249 | L30: =SUM(L28:L29) -> 253 | ... AB30: =SUM(AB28:AB29) -> 196 | AC30: =SUM(E30:AB30) -> 5267
A32: II | B32: DATA PENGGUNAAN SURAT SUARA
A33: 1 | B33: Jumlah surat suara yang diterima, termasuk surat suara cadangan 2,5% dari DPT | E33: 175 | F33: 237 | G33: 294 | H33: 235 | I33: 279 | J33: 303 | K33: 301 | L33: 297 | M33: 266 | N33: 252 | O33: 257 | P33: 301 | Q33: 294 | R33: 291 | S33: 204 | T33: 290 | U33: 287 | V33: 284 | W33: 290 | X33: 270 | Y33: 257 | Z33: 221 | AA33: 261 | AB33: 255 | AC33: =SUM(E33:AB33) -> 6401
A34: 2 | B34: Jumlah surat suara yang digunakan | E34: 138 | F34: 196 | G34: 221 | H34: 178 | I34: 239 | J34: 246 | K34: 249 | L34: 253 | M34: 205 | N34: 204 | O34: 228 | P34: 249 | Q34: 230 | R34: 238 | S34: 189 | T34: 244 | U34: 242 | V34: 246 | W34: 237 | X34: 227 | Y34: 217 | Z34: 176 | AA34: 219 | AB34: 196 | AC34: =SUM(E34:AB34) -> 5267
A35: 3 | B35: Jumlah surat suara dikembalikan oleh pemilih (karena rusak atau keliru coblos) | I35: 1 | K35: 8 | T35: 3 | W35: 1 | X35: 2 | Y35: 1 | AC35: =SUM(E35:AB35) -> 16
A36: 4 | B36: Jumlah surat suara yang tidak digunakan/tidak terpakai, termasuk sisa surat suara cadangan | E36: =E33-(E34+E35) -> 37 | F36: =F33-(F34+F35) -> 41 | G36: =G33-(G34+G35) -> 73 | H36: =H33-(H34+H35) -> 57 | I36: =I33-(I34+I35) -> 39 | J36: =J33-(J34+J35) -> 57 | K36: =K33-(K34+K35) -> 44 | L36: =L33-(L34+L35) -> 44 | ... AB36: =AB33-(AB34+AB35) -> 59 | AC36: =SUM(E36:AB36) -> 1118
A38: III | B38: DATA PEMILIH DISABILITAS
B39: Jumlah seluruh Pemilih disabilitas yang menggunakan hak pilih | D39: LK | J39: 1 | W39: 1 | AA39: 2 | AB39: 1 | AC39: =SUM(E39:AB39) -> 5
D40: PR | E40: 1 | M40: 1 | AA40: 2 | AC40: =SUM(E40:AB40) -> 4
D41: JML | E41: =SUM(E39:E40) -> 1 | F41: =SUM(F39:F40) -> 0 | G41: =SUM(G39:G40) -> 0 | H41: =SUM(H39:H40) -> 0 | I41: =SUM(I39:I40) -> 0 | J41: =SUM(J39:J40) -> 1 | K41: =SUM(K39:K40) -> 0 | L41: =SUM(L39:L40) -> 0 | ... AB41: =SUM(AB39:AB40) -> 1 | AC41: =SUM(E41:AB41) -> 9
A43: IV | B43: DATA RINCIAN PEROLEHAN SUARA PASANGAN CALON BUPATI DAN WAKIL BUPATI
A44: NOMOR DAN NAMA CALON
A45: A.1 | B45: 1. | C45: Partai Kebangkitan Bangsa | E45: 6 | F45: 10 | G45: 9 | H45: 2 | I45: 19 | J45: 8 | K45: 11 | L45: 7 | M45: 11 | N45: 26 | O45: 11 | P45: 5 | Q45: 8 | R45: 5 | S45: 11 | T45: 9 | U45: 6 | V45: 24 | W45: 20 | X45: 19 | Y45: 14 | Z45: 1 | AA45: 9 | AB45: 4 | AC45: =SUM(E45:AB45) -> 255
A46: A.2 | C46: 1. Dra. Hj. MA`MULAH HARUN, M.Pd.I. | E46: 14 | F46: 16 | G46: 18 | H46: 8 | I46: 30 | J46: 19 | K46: 60 | L46: 16 | M46: 56 | N46: 48 | O46: 30 | P46: 3 | Q46: 5 | R46: 3 | S46: 6 | T46: 24 | U46: 17 | V46: 51 | W46: 26 | X46: 14 | Y46: 23 | Z46: 2 | AA46: 13 | AB46: 8 | AC46: =SUM(E46:AB46) -> 510
C47: 2. UBAIDILLAH, S.Fil.I. | E47: 0 | F47: 0 | G47: 0 | H47: 0 | I47: 2 | J47: 2 | K47: 1 | L47: 0 | M47: 3 | N47: 2 | O47: 0 | P47: 0 | Q47: 0 | R47: 0 | S47: 1 | T47: 3 | U47: 0 | V47: 2 | W47: 9 | X47: 1 | Y47: 7 | Z47: 0 | AA47: 5 | AB47: 2 | AC47: =SUM(E47:AB47) -> 40
C48: 3. Ir. H. YOYOK MULYADI, M.Si. | E48: 1 | F48: 0 | G48: 1 | H48: 1 | I48: 0 | J48: 2 | K48: 0 | L48: 0 | M48: 0 | N48: 3 | O48: 1 | P48: 0 | Q48: 0 | R48: 0 | S48: 0 | T48: 0 | U48: 0 | V48: 0 | W48: 1 | X48: 0 | Y48: 3 | Z48: 0 | AA48: 1 | AB48: 0 | AC48: =SUM(E48:AB48) -> 14
C49: 4. KHOIRUL ANWAR, S.Fil.I. | E49: 0 | F49: 0 | G49: 2 | H49: 0 | I49: 0 | J49: 2 | K49: 1 | L49: 0 | M49: 0 | N49: 2 | O49: 0 | P49: 0 | Q49: 2 | R49: 0 | S49: 0 | T49: 0 | U49: 1 | V49: 0 | W49: 2 | X49: 1 | Y49: 0 | Z49: 0 | AA49: 3 | AB49: 0 | AC49: =SUM(E49:AB49) -> 16
C50: 5. ARIF WIJAKSANA | E50: 0 | F50: 1 | G50: 1 | H50: 0 | I50: 1 | J50: 0 | K50: 0 | L50: 0 | M50: 0 | N50: 0 | O50: 0 | P50: 0 | Q50: 0 | R50: 0 | S50: 0 | T50: 1 | U50: 1 | V50: 2 | W50: 2 | X50: 1 | Y50: 0 | Z50: 1 | AA50: 2 | AB50: 0 | AC50: =SUM(E50:AB50) -> 13
C51: 6. Dr. SITI YUMNAH | E51: 1 | F51: 1 | G51: 0 | H51: 0 | I51: 0 | J51: 1 | K51: 1 | L51: 0 | M51: 0 | N51: 0 | O51: 0 | P51: 0 | Q51: 0 | R51: 0 | S51: 0 | T51: 0 | U51: 0 | V51: 2 | W51: 2 | X51: 2 | Y51: 0 | Z51: 0 | AA51: 3 | AB51: 0 | AC51: =SUM(E51:AB51) -> 13
...

Sheet KALIPURO
C2: Kecamatan | D2: KALIPURO
C3: Kabupaten | D3: BANYUWANGI
C4: Provinsi | D4: JAWA TIMUR
C9: Kelurahan | D9: KALIPURO
A12: I | B12: DATA PEMILIH DAN PENGGUNAAN HAK PILIH | AR12: JUMLAH AKHIR
A13: A | B13: DATA PEMILIH | E13: TPS 001 | F13: TPS 002 | G13: TPS 003 | H13: TPS 004 | I13: TPS 005 | J13: TPS 006 | K13: TPS 007 | L13: TPS 008 | M13: TPS 009 | N13: TPS 010 | O13: TPS 011 | P13: TPS 012 | Q13: TPS 013 | R13: TPS 014 | S13: TPS 015 | T13: TPS 016 | U13: TPS 017 | V13: TPS 018 | W13: TPS 019 | X13: TPS 020 | Y13: TPS 021 | Z13: TPS 022 | AA13: TPS 023 | AB13: TPS 024 | AC13: TPS 025 | AD13: TPS 026 | AE13: TPS 027 | AF13: TPS 028 | AG13: TPS 029 | AH13: TPS 030 | AI13: TPS 031 | AJ13: TPS 032 | AK13: TPS 033 | AL13: TPS 034 | AM13: TPS 035 | AN13: TPS 036 | AO13: TPS 037 | AP13: TPS 038 | AQ13: TPS 039
B14: Jumlah Pemilih dalam Daftar Pemilih Tetap (DPT) | D14: LK | E14: 137 | F14: 141 | G14: 136 | H14: 135 | I14: 156 | J14: 147 | K14: 145 | L14: 147 | M14: 140 | N14: 141 | O14: 145 | P14: 134 | Q14: 148 | R14: 147 | S14: 139 | T14: 147 | U14: 138 | V14: 143 | W14: 133 | X14: 141 | Y14: 122 | Z14: 145 | AA14: 126 | AB14: 144 | AC14: 145 | AD14: 155 | AE14: 155 | AF14: 149 | AG14: 145 | AH14: 141 | AI14: 143 | AJ14: 135 | AK14: 145 | AL14: 147 | AM14: 132 | AN14: 147 | AO14: 136 | AP14: 150 | AQ14: 134 | AR14: =SUM(E14:AQ14) -> 5536
D15: PR | E15: 157 | F15: 146 | G15: 131 | H15: 154 | I15: 140 | J15: 146 | K15: 148 | L15: 151 | M15: 135 | N15: 158 | O15: 154 | P15: 124 | Q15: 150 | R15: 149 | S15: 156 | T15: 151 | U15: 158 | V15: 153 | W15: 158 | X15: 157 | Y15: 143 | Z15: 142 | AA15: 156 | AB15: 154 | AC15: 149 | AD15: 143 | AE15: 144 | AF15: 143 | AG15: 142 | AH15: 137 | AI15: 150 | AJ15: 157 | AK15: 149 | AL15: 147 | AM15: 123 | AN15: 147 | AO15: 143 | AP15: 147 | AQ15: 149 | AR15: =SUM(E15:AQ15) -> 5741
D16: JML | E16: =SUM(E14:E15) -> 294 | F16: =SUM(F14:F15) -> 287 | G16: =SUM(G14:G15) -> 267 | H16: =SUM(H14:H15) -> 289 | I16: =SUM(I14:I15) -> 296 | J16: =SUM(J14:J15) -> 293 | K16: =SUM(K14:K15) -> 293 | L16: =SUM(L14:L15) -> 298 | ... AQ16: =SUM(AQ14:AQ15) -> 283 | AR16: =SUM(E16:AQ16) -> 11277
A18: B | B18: PENGGUNA HAK PILIH
B19: 1. | C19: Jumlah pengguna hak pilih dalam Daftar Pemilih Tetap (DPT) | D19: LK | E19: 107 | F19: 105 | G19: 71 | H19: 91 | I19: 100 | J19: 84 | K19: 104 | L19: 108 | M19: 106 | N19: 101 | O19: 104 | P19: 103 | Q19: 113 | R19: 108 | S19: 105 | T19: 122 | U19: 89 | V19: 122 | W19: 95 | X19: 96 | Y19: 98 | Z19: 104 | AA19: 94 | AB19: 132 | AC19: 109 | AD19: 138 | AE19: 116 | AF19: 131 | AG19: 109 | AH19: 107 | AI19: 114 | AJ19: 110 | AK19: 111 | AL19: 127 | AM19: 107 | AN19: 123 | AO19: 101 | AP19: 131 | AQ19: 101 | AR19: =SUM(E19:AQ19) -> 4197
D20: PR | E20: 128 | F20: 117 | G20: 90 | H20: 101 | I20: 104 | J20: 99 | K20: 108 | L20: 126 | M20: 102 | N20: 116 | O20: 132 | P20: 109 | Q20: 122 | R20: 125 | S20: 120 | T20: 130 | U20: 111 | V20: 116 | W20: 125 | X20: 126 | Y20: 102 | Z20: 107 | AA20: 121 | AB20: 124 | AC20: 127 | AD20: 127 | AE20: 117 | AF20: 134 | AG20: 114 | AH20: 103 | AI20: 120 | AJ20: 123 | AK20: 109 | AL20: 126 | AM20: 107 | AN20: 116 | AO20: 96 | AP20: 122 | AQ20: 99 | AR20: =SUM(E20:AQ20) -> 4501
D21: JML | E21: =SUM(E19:E20) -> 235 | F21: =SUM(F19:F20) -> 222 | G21: =SUM(G19:G20) -> 161 | H21: =SUM(H19:H20) -> 192 | I21: =SUM(I19:I20) -> 204 | J21: =SUM(J19:J20) -> 183 | K21: =SUM(K19:K20) -> 212 | L21: =SUM(L19:L20) -> 234 | ... AQ21: =SUM(AQ19:AQ20) -> 200 | AR21: =SUM(E21:AQ21) -> 8698
B22: 2. | C22: Jumlah pengguna hak pilih dalam Daftar Pemilih Tambahan (DPTb) | D22: LK | E22: 0 | F22: 0 | G22: 3 | H22: 0 | I22: 1 | J22: 2 | K22: 0 | L22: 1 | M22: 0 | N22: 0 | O22: 0 | P22: 0 | Q22: 2 | R22: 1 | S22: 0 | T22: 1 | U22: 1 | V22: 0 | W22: 1 | X22: 0 | Y22: 0 | Z22: 1 | AA22: 0 | AB22: 1 | AC22: 0 | AD22: 0 | AE22: 0 | AF22: 0 | AG22: 0 | AH22: 0 | AI22: 0 | AJ22: 0 | AK22: 1 | AL22: 1 | AM22: 0 | AN22: 0 | AO22: 0 | AP22: 0 | AQ22: 1 | AR22: =SUM(E22:AQ22) -> 18
D23: PR | E23: 0 | F23: 1 | G23: 1 | H23: 0 | I23: 0 | J23: 0 | K23: 1 | L23: 1 | M23: 0 | N23: 0 | O23: 0 | P23: 0 | Q23: 0 | R23: 0 | S23: 1 | T23: 1 | U23: 0 | V23: 0 | W23: 0 | X23: 1 | Y23: 0 | Z23: 0 | AA23: 1 | AB23: 1 | AC23: 0 | AD23: 0 | AE23: 0 | AF23: 0 | AG23: 0 | AH23: 0 | AI23: 1 | AJ23: 0 | AK23: 0 | AL23: 0 | AM23: 1 | AN23: 0 | AO23: 0 | AP23: 0 | AQ23: 0 | AR23: =SUM(E23:AQ23) -> 11
D24: JML | E24: =SUM(E22:E23) -> 0 | F24: =SUM(F22:F23) -> 1 | G24: =SUM(G22:G23) -> 4 | H24: =SUM(H22:H23) -> 0 | I24: =SUM(I22:I23) -> 1 | J24: =SUM(J22:J23) -> 2 | K24: =SUM(K22:K23) -> 1 | L24: =SUM(L22:L23) -> 2 | ... AQ24: =SUM(AQ22:AQ23) -> 1 | AR24: =SUM(E24:AQ24) -> 29
B25: 3. | C25: Jumlah pengguna hak pilih dalam Daftar Pemilih Khusus (DPK) | D25: LK | E25: 1 | F25: 7 | G25: 1 | H25: 0 | I25: 2 | J25: 2 | K25: 4 | L25: 3 | M25: 2 | N25: 2 | O25: 2 | P25: 2 | Q25: 1 | R25: 0 | S25: 0 | T25: 3 | U25: 0 | V25: 9 | W25: 1 | X25: 7 | Y25: 1 | Z25: 1 | AA25: 0 | AB25: 2 | AC25: 1 | AD25: 3 | AE25: 3 | AF25: 0 | AG25: 2 | AH25: 6 | AI25: 4 | AJ25: 5 | AK25: 5 | AL25: 1 | AM25: 6 | AN25: 15 | AO25: 4 | AP25: 0 | AQ25: 0 | AR25: =SUM(E25:AQ25) -> 108
D26: PR | E26: 0 | F26: 0 | G26: 1 | H26: 1 | I26: 3 | J26: 8 | K26: 2 | L26: 2 | M26: 3 | N26: 1 | O26: 3 | P26: 2 | Q26: 2 | R26: 1 | S26: 5 | T26: 4 | U26: 0 | V26: 10 | W26: 0 | X26: 6 | Y26: 1 | Z26: 4 | AA26: 0 | AB26: 0 | AC26: 2 | AD26: 6 | AE26: 6 | AF26: 1 | AG26: 3 | AH26: 3 | AI26: 7 | AJ26: 6 | AK26: 8 | AL26: 2 | AM26: 5 | AN26: 15 | AO26: 4 | AP26: 0 | AQ26: 1 | AR26: =SUM(E26:AQ26) -> 128
D27: JML | E27: =SUM(E25:E26) -> 1 | F27: =SUM(F25:F26) -> 7 | G27: =SUM(G25:G26) -> 2 | H27: =SUM(H25:H26) -> 1 | I27: =SUM(I25:I26) -> 5 | J27: =SUM(J25:J26) -> 10 | K27: =SUM(K25:K26) -> 6 | L27: =SUM(L25:L26) -> 5 | ... AQ27: =SUM(AQ25:AQ26) -> 1 | AR27: =SUM(E27:AQ27) -> 236
B28: 4. | C28: Jumlah Pengguna Hak Pilih (B.1+B.2+B.3) | D28: LK | E28: =SUM(E19,E22,E25) -> 108 | F28: =SUM(F19,F22,F25) -> 112 | G28: =SUM(G19,G22,G25) -> 75 | H28: =SUM(H19,H22,H25) -> 91 | I28: =SUM(I19,I22,I25) -> 103 | J28: =SUM(J19,J22,J25) -> 88 | K28: =SUM(K19,K22,K25) -> 108 | L28: =SUM(L19,L22,L25) -> 112 | ... AQ28: =SUM(AQ19,AQ22,AQ25) -> 102 | AR28: =SUM(E28:AQ28) -> 4323
D29: PR | E29: =SUM(E20,E23,E26) -> 128 | F29: =SUM(F20,F23,F26) -> 118 | G29: =SUM(G20,G23,G26) -> 92 | H29: =SUM(H20,H23,H26) -> 102 | I29: =SUM(I20,I23,I26) -> 107 | J29: =SUM(J20,J23,J26) -> 107 | K29: =SUM(K20,K23,K26) -> 111 | L29: =SUM(L20,L23,L26) -> 129 | ... AQ29: =SUM(AQ20,AQ23,AQ26) -> 100 | AR29: =SUM(E29:AQ29) -> 4640
D30: JML | E30: =SUM(E28:E29) -> 236 | F30: =SUM(F28:F29) -> 230 | G30: =SUM(G28:G29) -> 167 | H30: =SUM(H28:H29) -> 193 | I30: =SUM(I28:I29) -> 210 | J30: =SUM(J28:J29) -> 195 | K30: =SUM(K28:K29) -> 219 | L30: =SUM(L28:L29) -> 241 | ... AQ30: =SUM(AQ28:AQ29) -> 202 | AR30: =SUM(E30:AQ30) -> 8963
A32: II | B32: DATA PENGGUNAAN SURAT SUARA
A33: 1 | B33: Jumlah surat suara yang diterima, termasuk surat suara cadangan 2,5% dari DPT | E33: 300 | F33: 303 | G33: 273 | H33: 295 | I33: 303 | J33: 299 | K33: 289 | L33: 304 | M33: 281 | N33: 305 | O33: 305 | P33: 264 | Q33: 304 | R33: 301 | S33: 301 | T33: 304 | U33: 303 | V33: 301 | W33: 297 | X33: 304 | Y33: 271 | Z33: 293 | AA33: 288 | AB33: 304 | AC33: 300 | AD33: 303 | AE33: 305 | AF33: 298 | AG33: 293 | AH33: 285 | AI33: 299 | AJ33: 299 | AK33: 300 | AL33: 300 | AM33: 272 | AN33: 301 | AO33: 285 | AP33: 303 | AQ33: 283 | AR33: =SUM(E33:AQ33) -> 11518
A34: 2 | B34: Jumlah surat suara yang digunakan | E34: 236 | F34: 230 | G34: 167 | H34: 193 | I34: 210 | J34: 195 | K34: 219 | L34: 241 | M34: 213 | N34: 220 | O34: 241 | P34: 216 | Q34: 240 | R34: 235 | S34: 231 | T34: 261 | U34: 201 | V34: 257 | W34: 222 | X34: 236 | Y34: 202 | Z34: 217 | AA34: 216 | AB34: 260 | AC34: 239 | AD34: 274 | AE34: 242 | AF34: 266 | AG34: 228 | AH34: 219 | AI34: 246 | AJ34: 244 | AK34: 234 | AL34: 257 | AM34: 226 | AN34: 269 | AO34: 205 | AP34: 253 | AQ34: 202 | AR34: =SUM(E34:AQ34) -> 8963
A35: 3 | B35: Jumlah surat suara dikembalikan oleh pemilih (karena rusak atau keliru coblos) | E35: 0 | F35: 0 | G35: 0 | H35: 1 | I35: 0 | J35: 1 | K35: 0 | L35: 0 | M35: 0 | N35: 0 | O35: 0 | P35: 2 | Q35: 0 | R35: 0 | S35: 0 | T35: 0 | U35: 0 | V35: 0 | W35: 0 | X35: 0 | Y35: 0 | Z35: 3 | AA35: 0 | AB35: 0 | AC35: 0 | AD35: 0 | AE35: 0 | AF35: 0 | AG35: 1 | AH35: 0 | AM35: 1 | AO35: 1 | AR35: =SUM(E35:AQ35) -> 10
A36: 4 | B36: Jumlah surat suara yang tidak digunakan/tidak terpakai, termasuk sisa surat suara cadangan | E36: =E33-(E34+E35) -> 64 | F36: =F33-(F34+F35) -> 73 | G36: =G33-(G34+G35) -> 106 | H36: =H33-(H34+H35) -> 101 | I36: =I33-(I34+I35) -> 93 | J36: =J33-(J34+J35) -> 103 | K36: =K33-(K34+K35) -> 70 | L36: =L33-(L34+L35) -> 63 | ... AQ36: =AQ33-(AQ34+AQ35) -> 81 | AR36: =SUM(E36:AQ36) -> 2545
A38: III | B38: DATA PEMILIH DISABILITAS
B39: Jumlah seluruh Pemilih disabilitas yang menggunakan hak pilih | D39: LK | E39: 1 | F39: 1 | G39: 0 | H39: 0 | I39: 0 | J39: 0 | K39: 0 | L39: 0 | M39: 1 | N39: 0 | O39: 0 | P39: 0 | Q39: 0 | R39: 0 | S39: 2 | T39: 1 | U39: 0 | V39: 0 | W39: 2 | X39: 0 | Y39: 0 | Z39: 0 | AA39: 0 | AB39: 0 | AC39: 3 | AD39: 3 | AE39: 0 | AF39: 0 | AG39: 0 | AH39: 1 | AR39: =SUM(E39:AQ39) -> 15
D40: PR | E40: 2 | F40: 0 | G40: 0 | H40: 0 | I40: 0 | J40: 0 | K40: 0 | L40: 0 | M40: 0 | N40: 0 | O40: 0 | P40: 0 | Q40: 0 | R40: 0 | S40: 3 | T40: 0 | U40: 2 | V40: 0 | W40: 1 | X40: 0 | Y40: 0 | Z40: 0 | AA40: 0 | AB40: 0 | AC40: 4 | AD40: 1 | AE40: 0 | AF40: 0 | AG40: 1 | AH40: 0 | AR40: =SUM(E40:AQ40) -> 14
D41: JML | E41: =SUM(E39:E40) -> 3 | F41: =SUM(F39:F40) -> 1 | G41: =SUM(G39:G40) -> 0 | H41: =SUM(H39:H40) -> 0 | I41: =SUM(I39:I40) -> 0 | J41: =SUM(J39:J40) -> 0 | K41: =SUM(K39:K40) -> 0 | L41: =SUM(L39:L40) -> 0 | ... AQ41: =SUM(AQ39:AQ40) -> 0 | AR41: =SUM(E41:AQ41) -> 29
A43: IV | B43: DATA RINCIAN PEROLEHAN SUARA PASANGAN CALON BUPATI DAN WAKIL BUPATI
A44: NOMOR DAN NAMA CALON
A45: A.1 | B45: 1. | C45: Partai Kebangkitan Bangsa | E45: 4 | F45: 8 | G45: 3 | H45: 6 | I45: 6 | J45: 5 | K45: 9 | L45: 11 | M45: 5 | N45: 10 | O45: 6 | P45: 11 | Q45: 11 | R45: 5 | S45: 6 | T45: 11 | U45: 3 | V45: 18 | W45: 5 | X45: 7 | Y45: 7 | Z45: 5 | AA45: 24 | AB45: 20 | AC45: 9 | AD45: 9 | AE45: 5 | AF45: 14 | AG45: 17 | AH45: 16 | AI45: 22 | AJ45: 9 | AK45: 11 | AL45: 31 | AM45: 11 | AN45: 24 | AO45: 15 | AP45: 16 | AQ45: 0 | AR45: =SUM(E45:AQ45) -> 415
A46: A.2 | C46: 1. Dra. Hj. MA`MULAH HARUN, M.Pd.I. | E46: 8 | F46: 11 | G46: 9 | H46: 18 | I46: 10 | J46: 14 | K46: 46 | L46: 62 | M46: 41 | N46: 36 | O46: 33 | P46: 40 | Q46: 37 | R46: 13 | S46: 22 | T46: 32 | U46: 12 | V46: 13 | W46: 16 | X46: 13 | Y46: 23 | Z46: 52 | AA46: 37 | AB46: 41 | AC46: 30 | AD46: 11 | AE46: 16 | AF46: 30 | AG46: 35 | AH46: 47 | AI46: 45 | AJ46: 39 | AK46: 29 | AL46: 40 | AM46: 25 | AN46: 69 | AO46: 35 | AP46: 43 | AQ46: 3 | AR46: =SUM(E46:AQ46) -> 1136
C47: 2. UBAIDILLAH, S.Fil.I. | E47: 3 | F47: 2 | G47: 1 | H47: 1 | I47: 2 | J47: 1 | K47: 3 | L47: 0 | M47: 7 | N47: 1 | O47: 9 | P47: 1 | Q47: 2 | R47: 1 | S47: 2 | T47: 0 | U47: 2 | V47: 3 | W47: 2 | X47: 2 | Y47: 0 | Z47: 28 | AA47: 1 | AB47: 2 | AC47: 21 | AD47: 3 | AE47: 5 | AF47: 1 | AG47: 22 | AH47: 3 | AI47: 6 | AJ47: 1 | AK47: 3 | AL47: 4 | AM47: 1 | AN47: 5 | AO47: 18 | AP47: 3 | AQ47: 0 | AR47: =SUM(E47:AQ47) -> 172
C48: 3. Ir. H. YOYOK MULYADI, M.Si. | E48: 0 | F48: 0 | G48: 3 | H48: 0 | I48: 0 | J48: 0 | K48: 1 | L48: 1 | M48: 1 | N48: 0 | O48: 0 | P48: 0 | Q48: 0 | R48: 1 | S48: 1 | T48: 0 | U48: 1 | V48: 1 | W48: 0 | X48: 0 | Y48: 0 | Z48: 0 | AA48: 2 | AB48: 2 | AC48: 0 | AD48: 0 | AE48: 4 | AF48: 1 | AG48: 2 | AH48: 0 | AI48: 0 | AJ48: 0 | AK48: 0 | AL48: 4 | AM48: 1 | AN48: 0 | AO48: 8 | AP48: 2 | AQ48: 0 | AR48: =SUM(E48:AQ48) -> 36
C49: 4. KHOIRUL ANWAR, S.Fil.I. | E49: 0 | F49: 1 | G49: 0 | H49: 0 | I49: 0 | J49: 1 | K49: 1 | L49: 0 | M49: 0 | N49: 1 | O49: 0 | P49: 1 | Q49: 0 | R49: 0 | S49: 0 | T49: 1 | U49: 2 | V49: 1 | W49: 2 | X49: 2 | Y49: 1 | Z49: 0 | AA49: 0 | AB49: 1 | AC49: 1 | AD49: 0 | AE49: 1 | AF49: 0 | AG49: 1 | AH49: 0 | AI49: 1 | AJ49: 0 | AK49: 0 | AL49: 0 | AM49: 2 | AN49: 1 | AO49: 1 | AP49: 1 | AQ49: 0 | AR49: =SUM(E49:AQ49) -> 24
C50: 5. ARIF WIJAKSANA | E50: 0 | F50: 0 | G50: 1 | H50: 0 | I50: 0 | J50: 0 | K50: 0 | L50: 1 | M50: 2 | N50: 1 | O50: 0 | P50: 0 | Q50: 0 | R50: 1 | S50: 0 | T50: 1 | U50: 0 | V50: 0 | W50: 1 | X50: 0 | Y50: 0 | Z50: 1 | AA50: 1 | AB50: 1 | AC50: 0 | AD50: 0 | AE50: 0 | AF50: 0 | AG50: 1 | AH50: 0 | AI50: 0 | AJ50: 0 | AK50: 1 | AL50: 0 | AM50: 0 | AN50: 1 | AO50: 3 | AP50: 7 | AQ50: 0 | AR50: =SUM(E50:AQ50) -> 24
C51: 6. Dr. SITI YUMNAH | E51: 0 | F51: 0 | G51: 0 | H51: 0 | I51: 0 | J51: 0 | K51: 2 | L51: 0 | M51: 0 | N51: 0 | O51: 0 | P51: 0 | Q51: 1 | R51: 1 | S51: 0 | T51: 0 | U51: 1 | V51: 0 | W51: 0 | X51: 0 | Y51: 1 | Z51: 0 | AA51: 0 | AB51: 0 | AC51: 1 | AD51: 0 | AE51: 1 | AF51: 0 | AG51: 0 | AH51: 1 | AI51: 0 | AJ51: 1 | AK51: 0 | AL51: 0 | AM51: 0 | AN51: 1 | AO51: 0 | AP51: 1 | AQ51: 1 | AR51: =SUM(E51:AQ51) -> 13
...

Sheet KELIR
C2: Kecamatan | D2: KALIPURO
C3: Kabupaten | D3: BANYUWANGI
C4: Provinsi | D4: JAWA TIMUR
C9: Kelurahan | D9: KELIR
A12: I | B12: DATA PEMILIH DAN PENGGUNAAN HAK PILIH | W12: JUMLAH AKHIR
A13: A | B13: DATA PEMILIH | E13: TPS 001 | F13: TPS 002 | G13: TPS 003 | H13: TPS 004 | I13: TPS 005 | J13: TPS 006 | K13: TPS 007 | L13: TPS 008 | M13: TPS 009 | N13: TPS 010 | O13: TPS 011 | P13: TPS 012 | Q13: TPS 013 | R13: TPS 014 | S13: TPS 015 | T13: TPS 016 | U13: TPS 017 | V13: TPS 018
B14: Jumlah Pemilih dalam Daftar Pemilih Tetap (DPT) | D14: LK | E14: 124 | F14: 130 | G14: 115 | H14: 131 | I14: 128 | J14: 128 | K14: 73 | L14: 128 | M14: 117 | N14: 117 | O14: 93 | P14: 139 | Q14: 152 | R14: 142 | S14: 132 | T14: 122 | U14: 115 | V14: 117 | W14: =SUM(E14:V14) -> 2203
D15: PR | E15: 141 | F15: 140 | G15: 124 | H15: 131 | I15: 131 | J15: 141 | K15: 85 | L15: 136 | M15: 113 | N15: 133 | O15: 83 | P15: 148 | Q15: 136 | R15: 134 | S15: 139 | T15: 136 | U15: 122 | V15: 125 | W15: =SUM(E15:V15) -> 2298
D16: JML | E16: =SUM(E14:E15) -> 265 | F16: =SUM(F14:F15) -> 270 | G16: =SUM(G14:G15) -> 239 | H16: =SUM(H14:H15) -> 262 | I16: =SUM(I14:I15) -> 259 | J16: =SUM(J14:J15) -> 269 | K16: =SUM(K14:K15) -> 158 | L16: =SUM(L14:L15) -> 264 | ... V16: =SUM(V14:V15) -> 242 | W16: =SUM(E16:V16) -> 4501
A18: B | B18: PENGGUNA HAK PILIH
B19: 1. | C19: Jumlah pengguna hak pilih dalam Daftar Pemilih Tetap (DPT) | D19: LK | E19: 106 | F19: 108 | G19: 96 | H19: 104 | I19: 100 | J19: 106 | K19: 52 | L19: 112 | M19: 92 | N19: 96 | O19: 72 | P19: 108 | Q19: 117 | R19: 108 | S19: 109 | T19: 104 | U19: 100 | V19: 82 | W19: =SUM(E19:V19) -> 1772
D20: PR | E20: 119 | F20: 120 | G20: 108 | H20: 108 | I20: 106 | J20: 119 | K20: 70 | L20: 115 | M20: 101 | N20: 121 | O20: 63 | P20: 130 | Q20: 111 | R20: 119 | S20: 118 | T20: 117 | U20: 103 | V20: 93 | W20: =SUM(E20:V20) -> 1941
D21: JML | E21: =SUM(E19:E20) -> 225 | F21: =SUM(F19:F20) -> 228 | G21: =SUM(G19:G20) -> 204 | H21: =SUM(H19:H20) -> 212 | I21: =SUM(I19:I20) -> 206 | J21: =SUM(J19:J20) -> 225 | K21: =SUM(K19:K20) -> 122 | L21: =SUM(L19:L20) -> 227 | ... V21: =SUM(V19:V20) -> 175 | W21: =SUM(E21:V21) -> 3713
B22: 2. | C22: Jumlah pengguna hak pilih dalam Daftar Pemilih Tambahan (DPTb) | D22: LK | E22: 0 | F22: 0 | G22: 1 | H22: 0 | I22: 1 | J22: 0 | K22: 1 | L22: 1 | M22: 0 | N22: 0 | O22: 1 | P22: 0 | Q22: 0 | R22: 0 | S22: 1 | T22: 0 | U22: 1 | V22: 0 | W22: =SUM(E22:V22) -> 7
D23: PR | E23: 0 | F23: 1 | G23: 0 | H23: 1 | I23: 0 | J23: 1 | K23: 0 | L23: 0 | M23: 0 | N23: 2 | O23: 0 | P23: 1 | Q23: 0 | R23: 1 | S23: 0 | T23: 1 | U23: 2 | V23: 0 | W23: =SUM(E23:V23) -> 10
D24: JML | E24: =SUM(E22:E23) -> 0 | F24: =SUM(F22:F23) -> 1 | G24: =SUM(G22:G23) -> 1 | H24: =SUM(H22:H23) -> 1 | I24: =SUM(I22:I23) -> 1 | J24: =SUM(J22:J23) -> 1 | K24: =SUM(K22:K23) -> 1 | L24: =SUM(L22:L23) -> 1 | ... V24: =SUM(V22:V23) -> 0 | W24: =SUM(E24:V24) -> 17
B25: 3. | C25: Jumlah pengguna hak pilih dalam Daftar Pemilih Khusus (DPK) | D25: LK | E25: 1 | F25: 1 | G25: 1 | H25: 1 | I25: 0 | J25: 2 | K25: 4 | L25: 0 | M25: 0 | N25: 1 | O25: 2 | P25: 4 | Q25: 0 | R25: 0 | S25: 0 | T25: 0 | U25: 1 | V25: 7 | W25: =SUM(E25:V25) -> 25
D26: PR | E26: 2 | F26: 2 | G26: 1 | H26: 1 | I26: 1 | J26: 1 | K26: 3 | L26: 0 | M26: 0 | N26: 1 | O26: 2 | P26: 7 | Q26: 1 | R26: 0 | S26: 1 | T26: 2 | U26: 3 | V26: 6 | W26: =SUM(E26:V26) -> 34
D27: JML | E27: =SUM(E25:E26) -> 3 | F27: =SUM(F25:F26) -> 3 | G27: =SUM(G25:G26) -> 2 | H27: =SUM(H25:H26) -> 2 | I27: =SUM(I25:I26) -> 1 | J27: =SUM(J25:J26) -> 3 | K27: =SUM(K25:K26) -> 7 | L27: =SUM(L25:L26) -> 0 | ... V27: =SUM(V25:V26) -> 13 | W27: =SUM(E27:V27) -> 59
B28: 4. | C28: Jumlah Pengguna Hak Pilih (B.1+B.2+B.3) | D28: LK | E28: =SUM(E19,E22,E25) -> 107 | F28: =SUM(F19,F22,F25) -> 109 | G28: =SUM(G19,G22,G25) -> 98 | H28: =SUM(H19,H22,H25) -> 105 | I28: =SUM(I19,I22,I25) -> 101 | J28: =SUM(J19,J22,J25) -> 108 | K28: =SUM(K19,K22,K25) -> 57 | L28: =SUM(L19,L22,L25) -> 113 | ... V28: =SUM(V19,V22,V25) -> 89 | W28: =SUM(E28:V28) -> 1804
D29: PR | E29: =SUM(E20,E23,E26) -> 121 | F29: =SUM(F20,F23,F26) -> 123 | G29: =SUM(G20,G23,G26) -> 109 | H29: =SUM(H20,H23,H26) -> 110 | I29: =SUM(I20,I23,I26) -> 107 | J29: =SUM(J20,J23,J26) -> 121 | K29: =SUM(K20,K23,K26) -> 73 | L29: =SUM(L20,L23,L26) -> 115 | ... V29: =SUM(V20,V23,V26) -> 99 | W29: =SUM(E29:V29) -> 1985
D30: JML | E30: =SUM(E28:E29) -> 228 | F30: =SUM(F28:F29) -> 232 | G30: =SUM(G28:G29) -> 207 | H30: =SUM(H28:H29) -> 215 | I30: =SUM(I28:I29) -> 208 | J30: =SUM(J28:J29) -> 229 | K30: =SUM(K28:K29) -> 130 | L30: =SUM(L28:L29) -> 228 | ... V30: =SUM(V28:V29) -> 188 | W30: =SUM(E30:V30) -> 3789
A32: II | B32: DATA PENGGUNAAN SURAT SUARA
A33: 1 | B33: Jumlah surat suara yang diterima, termasuk surat suara cadangan 2,5% dari DPT | E33: 271 | F33: 276 | G33: 244 | H33: 268 | I33: 264 | J33: 275 | K33: 162 | L33: 270 | M33: 235 | N33: 255 | O33: 180 | P33: 293 | Q33: 294 | R33: 284 | S33: 277 | T33: 264 | U33: 242 | V33: 247 | W33: =SUM(E33:V33) -> 4601
A34: 2 | B34: Jumlah surat suara yang digunakan | E34: 228 | F34: 232 | G34: 207 | H34: 215 | I34: 208 | J34: 229 | K34: 130 | L34: 228 | M34: 193 | N34: 221 | O34: 140 | P34: 250 | Q34: 229 | R34: 228 | S34: 229 | T34: 224 | U34: 210 | V34: 188 | W34: =SUM(E34:V34) -> 3789
A35: 3 | B35: Jumlah surat suara dikembalikan oleh pemilih (karena rusak atau keliru coblos) | O35: 1 | U35: 2 | W35: =SUM(E35:V35) -> 3
A36: 4 | B36: Jumlah surat suara yang tidak digunakan/tidak terpakai, termasuk sisa surat suara cadangan | E36: =E33-(E34+E35) -> 43 | F36: =F33-(F34+F35) -> 44 | G36: =G33-(G34+G35) -> 37 | H36: =H33-(H34+H35) -> 53 | I36: =I33-(I34+I35) -> 56 | J36: =J33-(J34+J35) -> 46 | K36: =K33-(K34+K35) -> 32 | L36: =L33-(L34+L35) -> 42 | ... V36: =V33-(V34+V35) -> 59 | W36: =SUM(E36:V36) -> 809
A38: III | B38: DATA PEMILIH DISABILITAS
B39: Jumlah seluruh Pemilih disabilitas yang menggunakan hak pilih | D39: LK | O39: 1 | W39: =SUM(E39:V39) -> 1
D40: PR | V40: 1 | W40: =SUM(E40:V40) -> 1
D41: JML | E41: =SUM(E39:E40) -> 0 | F41: =SUM(F39:F40) -> 0 | G41: =SUM(G39:G40) -> 0 | H41: =SUM(H39:H40) -> 0 | I41: =SUM(I39:I40) -> 0 | J41: =SUM(J39:J40) -> 0 | K41: =SUM(K39:K40) -> 0 | L41: =SUM(L39:L40) -> 0 | ... V41: =SUM(V39:V40) -> 1 | W41: =SUM(E41:V41) -> 2
A43: IV | B43: DATA RINCIAN PEROLEHAN SUARA PASANGAN CALON BUPATI DAN WAKIL BUPATI
A44: NOMOR DAN NAMA CALON
A45: A.1 | B45: 1. | C45: Partai Kebangkitan Bangsa | E45: 14 | F45: 12 | G45: 11 | H45: 9 | I45: 7 | J45: 11 | K45: 8 | L45: 8 | M45: 18 | N45: 13 | O45: 8 | P45: 16 | Q45: 16 | R45: 15 | S45: 11 | T45: 9 | U45: 9 | V45: 3 | W45: =SUM(E45:V45) -> 198
A46: A.2 | C46: 1. Dra. Hj. MA`MULAH HARUN, M.Pd.I. | E46: 33 | F46: 48 | G46: 40 | H46: 21 | I46: 32 | J46: 7 | K46: 8 | L46: 22 | M46: 26 | N46: 53 | O46: 32 | P46: 54 | Q46: 62 | R46: 23 | S46: 40 | T46: 13 | U46: 25 | V46: 10 | W46: =SUM(E46:V46) -> 549
C47: 2. UBAIDILLAH, S.Fil.I. | E47: 3 | F47: 2 | G47: 4 | H47: 15 | I47: 1 | J47: 2 | K47: 2 | L47: 6 | M47: 2 | N47: 2 | O47: 1 | P47: 2 | Q47: 2 | R47: 2 | S47: 4 | T47: 3 | U47: 4 | V47: 0 | W47: =SUM(E47:V47) -> 57
C48: 3. Ir. H. YOYOK MULYADI, M.Si. | E48: 0 | F48: 0 | G48: 0 | H48: 0 | I48: 1 | J48: 2 | K48: 0 | L48: 1 | M48: 1 | N48: 0 | O48: 1 | P48: 0 | Q48: 0 | R48: 0 | S48: 0 | T48: 0 | U48: 0 | V48: 0 | W48: =SUM(E48:V48) -> 6
C49: 4. KHOIRUL ANWAR, S.Fil.I. | E49: 0 | F49: 4 | G49: 0 | H49: 0 | I49: 1 | J49: 0 | K49: 0 | L49: 3 | M49: 0 | N49: 1 | O49: 0 | P49: 1 | Q49: 0 | R49: 1 | S49: 1 | T49: 1 | U49: 1 | V49: 0 | W49: =SUM(E49:V49) -> 14
C50: 5. ARIF WIJAKSANA | E50: 3 | F50: 0 | G50: 0 | H50: 4 | I50: 8 | J50: 1 | K50: 0 | L50: 0 | M50: 0 | N50: 0 | O50: 0 | P50: 0 | Q50: 1 | R50: 0 | S50: 0 | T50: 0 | U50: 0 | V50: 0 | W50: =SUM(E50:V50) -> 17
C51: 6. Dr. SITI YUMNAH | E51: 0 | F51: 0 | G51: 0 | H51: 0 | I51: 0 | J51: 0 | K51: 0 | L51: 0 | M51: 0 | N51: 0 | O51: 1 | P51: 1 | Q51: 0 | R51: 0 | S51: 4 | T51: 0 | U51: 0 | V51: 0 | W51: =SUM(E51:V51) -> 6
...

Sheet KETAPANG
C2: Kecamatan | D2: KALIPURO
C3: Kabupaten | D3: BANYUWANGI
C4: Provinsi | D4: JAWA TIMUR
C9: Kelurahan | D9: KETAPANG
A12: I | B12: DATA PEMILIH DAN PENGGUNAAN HAK PILIH | BE12: JUMLAH AKHIR
A13: A | B13: DATA PEMILIH | E13: TPS 001 | F13: TPS 002 | G13: TPS 003 | H13: TPS 004 | I13: TPS 005 | J13: TPS 006 | K13: TPS 007 | L13: TPS 008 | M13: TPS 009 | N13: TPS 010 | O13: TPS 011 | P13: TPS 012 | Q13: TPS 013 | R13: TPS 014 | S13: TPS 015 | T13: TPS 016 | U13: TPS 017 | V13: TPS 018 | W13: TPS 019 | X13: TPS 020 | Y13: TPS 021 | Z13: TPS 022 | AA13: TPS 023 | AB13: TPS 024 | AC13: TPS 025 | AD13: TPS 026 | AE13: TPS 027 | AF13: TPS 028 | AG13: TPS 029 | AH13: TPS 030 | AI13: TPS 031 | AJ13: TPS 032 | AK13: TPS 033 | AL13: TPS 034 | AM13: TPS 035 | AN13: TPS 036 | AO13: TPS 037 | AP13: TPS 038 | AQ13: TPS 039 | AR13: TPS 040 | AS13: TPS 041 | AT13: TPS 042 | AU13: TPS 043 | AV13: TPS 044 | AW13: TPS 045 | AX13: TPS 046 | AY13: TPS 047 | AZ13: TPS 048 | BA13: TPS 049 | BB13: TPS 050 | BC13: TPS 051 | BD13: TPS 052
B14: Jumlah Pemilih dalam Daftar Pemilih Tetap (DPT) | D14: LK | E14: 138 | F14: 139 | G14: 141 | H14: 142 | I14: 141 | J14: 101 | K14: 124 | L14: 133 | M14: 108 | N14: 93 | O14: 138 | P14: 122 | Q14: 138 | R14: 144 | S14: 140 | T14: 125 | U14: 124 | V14: 128 | W14: 112 | X14: 95 | Y14: 140 | Z14: 128 | AA14: 139 | AB14: 146 | AC14: 149 | AD14: 140 | AE14: 107 | AF14: 142 | AG14: 142 | AH14: 141 | AI14: 133 | AJ14: 135 | AK14: 132 | AL14: 146 | AM14: 127 | AN14: 148 | AO14: 143 | AP14: 131 | AQ14: 98 | AR14: 143 | AS14: 135 | AT14: 136 | AU14: 137 | AV14: 139 | AW14: 123 | AX14: 125 | AY14: 91 | AZ14: 137 | BA14: 121 | BB14: 125 | BC14: 121 | BD14: 116 | BE14: =SUM(E14:BD14) -> 6742
D15: PR | E15: 128 | F15: 132 | G15: 148 | H15: 139 | I15: 142 | J15: 125 | K15: 155 | L15: 131 | M15: 107 | N15: 94 | O15: 156 | P15: 129 | Q15: 148 | R15: 139 | S15: 136 | T15: 132 | U15: 139 | V15: 141 | W15: 123 | X15: 100 | Y15: 142 | Z15: 146 | AA15: 146 | AB15: 154 | AC15: 150 | AD15: 157 | AE15: 105 | AF15: 153 | AG15: 145 | AH15: 147 | AI15: 140 | AJ15: 155 | AK15: 124 | AL15: 150 | AM15: 142 | AN15: 148 | AO15: 154 | AP15: 135 | AQ15: 120 | AR15: 147 | AS15: 149 | AT15: 134 | AU15: 133 | AV15: 133 | AW15: 129 | AX15: 137 | AY15: 102 | AZ15: 147 | BA15: 126 | BB15: 126 | BC15: 134 | BD15: 104 | BE15: =SUM(E15:BD15) -> 7058
D16: JML | E16: =SUM(E14:E15) -> 266 | F16: =SUM(F14:F15) -> 271 | G16: =SUM(G14:G15) -> 289 | H16: =SUM(H14:H15) -> 281 | I16: =SUM(I14:I15) -> 283 | J16: =SUM(J14:J15) -> 226 | K16: =SUM(K14:K15) -> 279 | L16: =SUM(L14:L15) -> 264 | ... BD16: =SUM(BD14:BD15) -> 220 | BE16: =SUM(E16:BD16) -> 13800
A18: B | B18: PENGGUNA HAK PILIH
B19: 1. | C19: Jumlah pengguna hak pilih dalam Daftar Pemilih Tetap (DPT) | D19: LK | E19: 98 | F19: 98 | G19: 96 | H19: 100 | I19: 100 | J19: 70 | K19: 81 | L19: 85 | M19: 75 | N19: 71 | O19: 77 | P19: 74 | Q19: 94 | R19: 97 | S19: 83 | T19: 91 | U19: 72 | V19: 92 | W19: 68 | X19: 78 | Y19: 104 | Z19: 99 | AA19: 129 | AB19: 116 | AC19: 114 | AD19: 110 | AE19: 90 | AF19: 118 | AG19: 102 | AH19: 120 | AI19: 105 | AJ19: 100 | AK19: 97 | AL19: 96 | AM19: 90 | AN19: 101 | AO19: 97 | AP19: 96 | AQ19: 67 | AR19: 97 | AS19: 95 | AT19: 100 | AU19: 103 | AV19: 110 | AW19: 104 | AX19: 83 | AY19: 65 | AZ19: 103 | BA19: 94 | BB19: 92 | BC19: 94 | BD19: 77 | BE19: =SUM(E19:BD19) -> 4868
D20: PR | E20: 100 | F20: 97 | G20: 117 | H20: 112 | I20: 118 | J20: 97 | K20: 115 | L20: 106 | M20: 84 | N20: 76 | O20: 98 | P20: 92 | Q20: 117 | R20: 108 | S20: 107 | T20: 106 | U20: 100 | V20: 110 | W20: 90 | X20: 88 | Y20: 113 | Z20: 119 | AA20: 137 | AB20: 127 | AC20: 151 | AD20: 152 | AE20: 97 | AF20: 118 | AG20: 121 | AH20: 127 | AI20: 114 | AJ20: 120 | AK20: 104 | AL20: 117 | AM20: 105 | AN20: 118 | AO20: 118 | AP20: 104 | AQ20: 94 | AR20: 114 | AS20: 122 | AT20: 104 | AU20: 101 | AV20: 110 | AW20: 106 | AX20: 116 | AY20: 84 | AZ20: 114 | BA20: 97 | BB20: 83 | BC20: 102 | BD20: 83 | BE20: =SUM(E20:BD20) -> 5630
D21: JML | E21: =SUM(E19:E20) -> 198 | F21: =SUM(F19:F20) -> 195 | G21: =SUM(G19:G20) -> 213 | H21: =SUM(H19:H20) -> 212 | I21: =SUM(I19:I20) -> 218 | J21: =SUM(J19:J20) -> 167 | K21: =SUM(K19:K20) -> 196 | L21: =SUM(L19:L20) -> 191 | ... BD21: =SUM(BD19:BD20) -> 160 | BE21: =SUM(E21:BD21) -> 10498
B22: 2. | C22: Jumlah pengguna hak pilih dalam Daftar Pemilih Tambahan (DPTb) | D22: LK | E22: 0 | F22: 1 | G22: 1 | H22: 0 | I22: 0 | J22: 0 | K22: 1 | L22: 2 | M22: 0 | N22: 2 | O22: 0 | P22: 0 | Q22: 1 | R22: 0 | S22: 0 | T22: 1 | U22: 1 | V22: 0 | W22: 1 | X22: 1 | Y22: 0 | Z22: 0 | AA22: 1 | AB22: 2 | AC22: 1 | AD22: 1 | AE22: 0 | AF22: 0 | AG22: 0 | AH22: 0 | AI22: 1 | AJ22: 0 | AK22: 0 | AL22: 0 | AM22: 1 | AN22: 0 | AO22: 0 | AP22: 1 | AQ22: 0 | AR22: 0 | AS22: 1 | AT22: 1 | AU22: 1 | AV22: 0 | AW22: 1 | AX22: 0 | AY22: 1 | AZ22: 1 | BA22: 2 | BB22: 0 | BC22: 1 | BD22: 0 | BE22: =SUM(E22:BD22) -> 29
D23: PR | E23: 0 | F23: 0 | G23: 0 | H23: 1 | I23: 1 | J23: 1 | K23: 0 | L23: 0 | M23: 1 | N23: 1 | O23: 0 | P23: 0 | Q23: 0 | R23: 1 | S23: 0 | T23: 0 | U23: 0 | V23: 1 | W23: 2 | X23: 0 | Y23: 1 | Z23: 0 | AA23: 0 | AB23: 0 | AC23: 0 | AD23: 0 | AE23: 1 | AF23: 0 | AG23: 0 | AH23: 1 | AI23: 0 | AJ23: 1 | AK23: 2 | AL23: 0 | AM23: 0 | AN23: 0 | AO23: 1 | AP23: 0 | AQ23: 0 | AR23: 1 | AS23: 0 | AT23: 0 | AU23: 0 | AV23: 0 | AW23: 0 | AX23: 0 | AY23: 0 | AZ23: 0 | BA23: 0 | BB23: 0 | BC23: 0 | BD23: 0 | BE23: =SUM(E23:BD23) -> 17
D24: JML | E24: =SUM(E22:E23) -> 0 | F24: =SUM(F22:F23) -> 1 | G24: =SUM(G22:G23) -> 1 | H24: =SUM(H22:H23) -> 1 | I24: =SUM(I22:I23) -> 1 | J24: =SUM(J22:J23) -> 1 | K24: =SUM(K22:K23) -> 1 | L24: =SUM(L22:L23) -> 2 | ... BD24: =SUM(BD22:BD23) -> 0 | BE24: =SUM(E24:BD24) -> 46
B25: 3. | C25: Jumlah pengguna hak pilih dalam Daftar Pemilih Khusus (DPK) | D25: LK | E25: 1 | F25: 0 | G25: 0 | H25: 0 | I25: 0 | J25: 1 | K25: 1 | L25: 0 | M25: 0 | N25: 0 | O25: 0 | P25: 4 | Q25: 7 | R25: 2 | S25: 1 | T25: 0 | U25: 2 | V25: 1 | W25: 3 | X25: 2 | Y25: 1 | Z25: 2 | AA25: 0 | AB25: 3 | AC25: 1 | AD25: 7 | AE25: 2 | AF25: 0 | AG25: 0 | AH25: 1 | AI25: 1 | AJ25: 3 | AK25: 0 | AL25: 2 | AM25: 0 | AN25: 0 | AO25: 2 | AP25: 1 | AQ25: 1 | AR25: 2 | AS25: 0 | AT25: 0 | AU25: 0 | AV25: 1 | AW25: 0 | AX25: 1 | AY25: 1 | AZ25: 1 | BA25: 1 | BB25: 0 | BC25: 1 | BD25: 1 | BE25: =SUM(E25:BD25) -> 61
D26: PR | E26: 2 | F26: 0 | G26: 2 | H26: 0 | I26: 0 | J26: 2 | K26: 2 | L26: 0 | M26: 0 | N26: 2 | O26: 2 | P26: 3 | Q26: 3 | R26: 2 | S26: 1 | T26: 0 | U26: 0 | V26: 2 | W26: 1 | X26: 4 | Y26: 2 | Z26: 0 | AA26: 1 | AB26: 2 | AC26: 2 | AD26: 6 | AE26: 0 | AF26: 0 | AG26: 0 | AH26: 4 | AI26: 7 | AJ26: 1 | AK26: 1 | AL26: 3 | AM26: 0 | AN26: 0 | AO26: 4 | AP26: 0 | AQ26: 1 | AR26: 5 | AS26: 1 | AT26: 0 | AU26: 0 | AV26: 4 | AW26: 0 | AX26: 1 | AY26: 0 | AZ26: 0 | BA26: 1 | BB26: 0 | BC26: 2 | BD26: 1 | BE26: =SUM(E26:BD26) -> 77
D27: JML | E27: =SUM(E25:E26) -> 3 | F27: =SUM(F25:F26) -> 0 | G27: =SUM(G25:G26) -> 2 | H27: =SUM(H25:H26) -> 0 | I27: =SUM(I25:I26) -> 0 | J27: =SUM(J25:J26) -> 3 | K27: =SUM(K25:K26) -> 3 | L27: =SUM(L25:L26) -> 0 | ... BD27: =SUM(BD25:BD26) -> 2 | BE27: =SUM(E27:BD27) -> 138
B28: 4. | C28: Jumlah Pengguna Hak Pilih (B.1+B.2+B.3) | D28: LK | E28: =SUM(E19,E22,E25) -> 99 | F28: =SUM(F19,F22,F25) -> 99 | G28: =SUM(G19,G22,G25) -> 97 | H28: =SUM(H19,H22,H25) -> 100 | I28: =SUM(I19,I22,I25) -> 100 | J28: =SUM(J19,J22,J25) -> 71 | K28: =SUM(K19,K22,K25) -> 83 | L28: =SUM(L19,L22,L25) -> 87 | ... BD28: =SUM(BD19,BD22,BD25) -> 78 | BE28: =SUM(E28:BD28) -> 4958
D29: PR | E29: =SUM(E20,E23,E26) -> 102 | F29: =SUM(F20,F23,F26) -> 97 | G29: =SUM(G20,G23,G26) -> 119 | H29: =SUM(H20,H23,H26) -> 113 | I29: =SUM(I20,I23,I26) -> 119 | J29: =SUM(J20,J23,J26) -> 100 | K29: =SUM(K20,K23,K26) -> 117 | L29: =SUM(L20,L23,L26) -> 106 | ... BD29: =SUM(BD20,BD23,BD26) -> 84 | BE29: =SUM(E29:BD29) -> 5724
