Workbook

Sheet DPRD PROVINSI
C8: Kecamatan | D8: BANYUWANGI
C9: Kabupaten | D9: BANYUWANGI
C10: Provinsi | D10: JAWA TIMUR
A12: I | B12: DATA PEMILIH DAN PENGGUNAAN HAK PILIH | E12: JUMLAH AKHIR
A13: A | B13: DATA PEMILIH
B14: Jumlah Pemilih dalam Daftar Pemilih Tetap (DPT) | D14: LK | E14: =KAMPUNGMANDAR!P14+KAMPUNGMELAYU!M14+KARANGREJO!AI14+KEBALENAN!AH14+KEPATIHAN!S14+KERTOSARI!AB14+LATENG!AD14+PAKIS!T14+PANDEREJO!R14+PENGANJURAN!T14+PENGANTIGAN!X14+SINGONEGARAN!U14+SINGOTRUNAN!AE14+SOBO!AB14+SUMBERREJO!U14+TAMANBARU!Z14+TEMENGGUNGAN!L14+TUKANGKAYU!AD14 -> 43119
D15: PR | E15: =KAMPUNGMANDAR!P15+KAMPUNGMELAYU!M15+KARANGREJO!AI15+KEBALENAN!AH15+KEPATIHAN!S15+KERTOSARI!AB15+LATENG!AD15+PAKIS!T15+PANDEREJO!R15+PENGANJURAN!T15+PENGANTIGAN!X15+SINGONEGARAN!U15+SINGOTRUNAN!AE15+SOBO!AB15+SUMBERREJO!U15+TAMANBARU!Z15+TEMENGGUNGAN!L15+TUKANGKAYU!AD15 -> 45907
D16: JML | E16: =SUM(E14:E15) -> 89026
A18: B | B18: PENGGUNA HAK PILIH
B19: 1. | C19: Jumlah pengguna hak pilih dalam Daftar Pemilih Tetap (DPT) | D19: LK | E19: =KAMPUNGMANDAR!P19+KAMPUNGMELAYU!M19+KARANGREJO!AI19+KEBALENAN!AH19+KEPATIHAN!S19+KERTOSARI!AB19+LATENG!AD19+PAKIS!T19+PANDEREJO!R19+PENGANJURAN!T19+PENGANTIGAN!X19+SINGONEGARAN!U19+SINGOTRUNAN!AE19+SOBO!AB19+SUMBERREJO!U19+TAMANBARU!Z19+TEMENGGUNGAN!L19+TUKANGKAYU!AD19 -> 31082
D20: PR | E20: =KAMPUNGMANDAR!P20+KAMPUNGMELAYU!M20+KARANGREJO!AI20+KEBALENAN!AH20+KEPATIHAN!S20+KERTOSARI!AB20+LATENG!AD20+PAKIS!T20+PANDEREJO!R20+PENGANJURAN!T20+PENGANTIGAN!X20+SINGONEGARAN!U20+SINGOTRUNAN!AE20+SOBO!AB20+SUMBERREJO!U20+TAMANBARU!Z20+TEMENGGUNGAN!L20+TUKANGKAYU!AD20 -> 36199
D21: JML | E21: =SUM(E19:E20) -> 67281
B22: 2. | C22: Jumlah pengguna hak pilih dalam Daftar Pemilih Tambahan (DPTb) | D22: LK | E22: =KAMPUNGMANDAR!P22+KAMPUNGMELAYU!M22+KARANGREJO!AI22+KEBALENAN!AH22+KEPATIHAN!S22+KERTOSARI!AB22+LATENG!AD22+PAKIS!T22+PANDEREJO!R22+PENGANJURAN!T22+PENGANTIGAN!X22+SINGONEGARAN!U22+SINGOTRUNAN!AE22+SOBO!AB22+SUMBERREJO!U22+TAMANBARU!Z22+TEMENGGUNGAN!L22+TUKANGKAYU!AD22 -> 77
D23: PR | E23: =KAMPUNGMANDAR!P23+KAMPUNGMELAYU!M23+KARANGREJO!AI23+KEBALENAN!AH23+KEPATIHAN!S23+KERTOSARI!AB23+LATENG!AD23+PAKIS!T23+PANDEREJO!R23+PENGANJURAN!T23+PENGANTIGAN!X23+SINGONEGARAN!U23+SINGOTRUNAN!AE23+SOBO!AB23+SUMBERREJO!U23+TAMANBARU!Z23+TEMENGGUNGAN!L23+TUKANGKAYU!AD23 -> 75
D24: JML | E24: =SUM(E22:E23) -> 152
B25: 3. | C25: Jumlah pengguna hak pilih dalam Daftar Pemilih Khusus (DPK) | D25: LK | E25: =KAMPUNGMANDAR!P25+KAMPUNGMELAYU!M25+KARANGREJO!AI25+KEBALENAN!AH25+KEPATIHAN!S25+KERTOSARI!AB25+LATENG!AD25+PAKIS!T25+PANDEREJO!R25+PENGANJURAN!T25+PENGANTIGAN!X25+SINGONEGARAN!U25+SINGOTRUNAN!AE25+SOBO!AB25+SUMBERREJO!U25+TAMANBARU!Z25+TEMENGGUNGAN!L25+TUKANGKAYU!AD25 -> 538
D26: PR | E26: =KAMPUNGMANDAR!P26+KAMPUNGMELAYU!M26+KARANGREJO!AI26+KEBALENAN!AH26+KEPATIHAN!S26+KERTOSARI!AB26+LATENG!AD26+PAKIS!T26+PANDEREJO!R26+PENGANJURAN!T26+PENGANTIGAN!X26+SINGONEGARAN!U26+SINGOTRUNAN!AE26+SOBO!AB26+SUMBERREJO!U26+TAMANBARU!Z26+TEMENGGUNGAN!L26+TUKANGKAYU!AD26 -> 705
D27: JML | E27: =SUM(E25:E26) -> 1243
B28: 4. | C28: Jumlah Pengguna Hak Pilih (B.1+B.2+B.3) | D28: LK | E28: =E19+E22+E25 -> 31697
D29: PR | E29: =E20+E23+E26 -> 36979
D30: JML | E30: =SUM(E28:E29) -> 68676
A32: II | B32: DATA PENGGUNAAN SURAT SUARA
A33: 1 | B33: Jumlah surat suara yang diterima, termasuk surat suara cadangan 2,5% dari DPT | E33: =KAMPUNGMANDAR!P33+KAMPUNGMELAYU!M33+KARANGREJO!AI33+KEBALENAN!AH33+KEPATIHAN!S33+KERTOSARI!AB33+LATENG!AD33+PAKIS!T33+PANDEREJO!R33+PENGANJURAN!T33+PENGANTIGAN!X33+SINGONEGARAN!U33+SINGOTRUNAN!AE33+SOBO!AB33+SUMBERREJO!U33+TAMANBARU!Z33+TEMENGGUNGAN!L33+TUKANGKAYU!AD33 -> 90704
A34: 2 | B34: Jumlah surat suara yang digunakan | E34: =KAMPUNGMANDAR!P34+KAMPUNGMELAYU!M34+KARANGREJO!AI34+KEBALENAN!AH34+KEPATIHAN!S34+KERTOSARI!AB34+LATENG!AD34+PAKIS!T34+PANDEREJO!R34+PENGANJURAN!T34+PENGANTIGAN!X34+SINGONEGARAN!U34+SINGOTRUNAN!AE34+SOBO!AB34+SUMBERREJO!U34+TAMANBARU!Z34+TEMENGGUNGAN!L34+TUKANGKAYU!AD34 -> 68676
A35: 3 | B35: Jumlah surat suara dikembalikan oleh pemilih (karena rusak atau keliru coblos) | E35: =KAMPUNGMANDAR!P35+KAMPUNGMELAYU!M35+KARANGREJO!AI35+KEBALENAN!AH35+KEPATIHAN!S35+KERTOSARI!AB35+LATENG!AD35+PAKIS!T35+PANDEREJO!R35+PENGANJURAN!T35+PENGANTIGAN!X35+SINGONEGARAN!U35+SINGOTRUNAN!AE35+SOBO!AB35+SUMBERREJO!U35+TAMANBARU!Z35+TEMENGGUNGAN!L35+TUKANGKAYU!AD35 -> 101
A36: 4 | B36: Jumlah surat suara yang tidak digunakan/tidak terpakai, termasuk sisa surat suara cadangan | E36: =E33-(E34+E35) -> 21927
A38: III | B38: DATA PEMILIH DISABILITAS
B39: Jumlah seluruh Pemilih disabilitas yang menggunakan hak pilih | D39: LK | E39: =KAMPUNGMANDAR!P39+KAMPUNGMELAYU!M39+KARANGREJO!AI39+KEBALENAN!AH39+KEPATIHAN!S39+KERTOSARI!AB39+LATENG!AD39+PAKIS!T39+PANDEREJO!R39+PENGANJURAN!T39+PENGANTIGAN!X39+SINGONEGARAN!U39+SINGOTRUNAN!AE39+SOBO!AB39+SUMBERREJO!U39+TAMANBARU!Z39+TEMENGGUNGAN!L39+TUKANGKAYU!AD39 -> 90
D40: PR | E40: =KAMPUNGMANDAR!P40+KAMPUNGMELAYU!M40+KARANGREJO!AI40+KEBALENAN!AH40+KEPATIHAN!S40+KERTOSARI!AB40+LATENG!AD40+PAKIS!T40+PANDEREJO!R40+PENGANJURAN!T40+PENGANTIGAN!X40+SINGONEGARAN!U40+SINGOTRUNAN!AE40+SOBO!AB40+SUMBERREJO!U40+TAMANBARU!Z40+TEMENGGUNGAN!L40+TUKANGKAYU!AD40 -> 78
D41: JML | E41: =SUM(E39:E40) -> 168
A43: IV | B43: DATA RINCIAN PEROLEHAN SUARA PASANGAN CALON BUPATI DAN WAKIL BUPATI
A44: NOMOR DAN NAMA CALON
A45: A.1 | B45: 1. | C45: Partai Kebangkitan Bangsa | E45: =KAMPUNGMANDAR!P45+KAMPUNGMELAYU!M45+KARANGREJO!AI45+KEBALENAN!AH45+KEPATIHAN!S45+KERTOSARI!AB45+LATENG!AD45+PAKIS!T45+PANDEREJO!R45+PENGANJURAN!T45+PENGANTIGAN!X45+SINGONEGARAN!U45+SINGOTRUNAN!AE45+SOBO!AB45+SUMBERREJO!U45+TAMANBARU!Z45+TEMENGGUNGAN!L45+TUKANGKAYU!AD45 -> 1853
A46: A.2 | C46: 1. Dra. Hj. MA`MULAH HARUN, M.Pd.I. | E46: =KAMPUNGMANDAR!P46+KAMPUNGMELAYU!M46+KARANGREJO!AI46+KEBALENAN!AH46+KEPATIHAN!S46+KERTOSARI!AB46+LATENG!AD46+PAKIS!T46+PANDEREJO!R46+PENGANJURAN!T46+PENGANTIGAN!X46+SINGONEGARAN!U46+SINGOTRUNAN!AE46+SOBO!AB46+SUMBERREJO!U46+TAMANBARU!Z46+TEMENGGUNGAN!L46+TUKANGKAYU!AD46 -> 4640
C47: 2. UBAIDILLAH, S.Fil.I. | E47: =KAMPUNGMANDAR!P47+KAMPUNGMELAYU!M47+KARANGREJO!AI47+KEBALENAN!AH47+KEPATIHAN!S47+KERTOSARI!AB47+LATENG!AD47+PAKIS!T47+PANDEREJO!R47+PENGANJURAN!T47+PENGANTIGAN!X47+SINGONEGARAN!U47+SINGOTRUNAN!AE47+SOBO!AB47+SUMBERREJO!U47+TAMANBARU!Z47+TEMENGGUNGAN!L47+TUKANGKAYU!AD47 -> 333
C48: 3. Ir. H. YOYOK MULYADI, M.Si. | E48: =KAMPUNGMANDAR!P48+KAMPUNGMELAYU!M48+KARANGREJO!AI48+KEBALENAN!AH48+KEPATIHAN!S48+KERTOSARI!AB48+LATENG!AD48+PAKIS!T48+PANDEREJO!R48+PENGANJURAN!T48+PENGANTIGAN!X48+SINGONEGARAN!U48+SINGOTRUNAN!AE48+SOBO!AB48+SUMBERREJO!U48+TAMANBARU!Z48+TEMENGGUNGAN!L48+TUKANGKAYU!AD48 -> 180
C49: 4. KHOIRUL ANWAR, S.Fil.I. | E49: =KAMPUNGMANDAR!P49+KAMPUNGMELAYU!M49+KARANGREJO!AI49+KEBALENAN!AH49+KEPATIHAN!S49+KERTOSARI!AB49+LATENG!AD49+PAKIS!T49+PANDEREJO!R49+PENGANJURAN!T49+PENGANTIGAN!X49+SINGONEGARAN!U49+SINGOTRUNAN!AE49+SOBO!AB49+SUMBERREJO!U49+TAMANBARU!Z49+TEMENGGUNGAN!L49+TUKANGKAYU!AD49 -> 240
C50: 5. ARIF WIJAKSANA | E50: =KAMPUNGMANDAR!P50+KAMPUNGMELAYU!M50+KARANGREJO!AI50+KEBALENAN!AH50+KEPATIHAN!S50+KERTOSARI!AB50+LATENG!AD50+PAKIS!T50+PANDEREJO!R50+PENGANJURAN!T50+PENGANTIGAN!X50+SINGONEGARAN!U50+SINGOTRUNAN!AE50+SOBO!AB50+SUMBERREJO!U50+TAMANBARU!Z50+TEMENGGUNGAN!L50+TUKANGKAYU!AD50 -> 119
C51: 6. Dr. SITI YUMNAH | E51: =KAMPUNGMANDAR!P51+KAMPUNGMELAYU!M51+KARANGREJO!AI51+KEBALENAN!AH51+KEPATIHAN!S51+KERTOSARI!AB51+LATENG!AD51+PAKIS!T51+PANDEREJO!R51+PENGANJURAN!T51+PENGANTIGAN!X51+SINGONEGARAN!U51+SINGOTRUNAN!AE51+SOBO!AB51+SUMBERREJO!U51+TAMANBARU!Z51+TEMENGGUNGAN!L51+TUKANGKAYU!AD51 -> 127
C52: 7. MOHAMMAD ZAINI, M.Pd.I. | E52: =KAMPUNGMANDAR!P52+KAMPUNGMELAYU!M52+KARANGREJO!AI52+KEBALENAN!AH52+KEPATIHAN!S52+KERTOSARI!AB52+LATENG!AD52+PAKIS!T52+PANDEREJO!R52+PENGANJURAN!T52+PENGANTIGAN!X52+SINGONEGARAN!U52+SINGOTRUNAN!AE52+SOBO!AB52+SUMBERREJO!U52+TAMANBARU!Z52+TEMENGGUNGAN!L52+TUKANGKAYU!AD52 -> 97
...

Sheet PAKIS
C2: Kecamatan | D2: BANYUWANGI
C3: Kabupaten | D3: BANYUWANGI
C4: Provinsi | D4: JAWA TIMUR
C9: Kelurahan | D9: PAKIS
A12: I | B12: DATA PEMILIH DAN PENGGUNAAN HAK PILIH | T12: JUMLAH AKHIR
A13: A | B13: DATA PEMILIH | E13: TPS 001 | F13: TPS 002 | G13: TPS 003 | H13: TPS 004 | I13: TPS 005 | J13: TPS 006 | K13: TPS 007 | L13: TPS 008 | M13: TPS 009 | N13: TPS 010 | O13: TPS 011 | P13: TPS 012 | Q13: TPS 013 | R13: TPS 014 | S13: TPS 015
B14: Jumlah Pemilih dalam Daftar Pemilih Tetap (DPT) | D14: LK | E14: 129 | F14: 123 | G14: 107 | H14: 122 | I14: 121 | J14: 131 | K14: 124 | L14: 137 | M14: 122 | N14: 115 | O14: 134 | P14: 127 | Q14: 116 | R14: 131 | S14: 125 | T14: =SUM(E14:S14) -> 1864
D15: PR | E15: 134 | F15: 135 | G15: 138 | H15: 132 | I15: 137 | J15: 128 | K15: 129 | L15: 125 | M15: 128 | N15: 130 | O15: 119 | P15: 127 | Q15: 133 | R15: 124 | S15: 129 | T15: =SUM(E15:S15) -> 1948
D16: JML | E16: =SUM(E14:E15) -> 263 | F16: =SUM(F14:F15) -> 258 | G16: =SUM(G14:G15) -> 245 | H16: =SUM(H14:H15) -> 254 | I16: =SUM(I14:I15) -> 258 | J16: =SUM(J14:J15) -> 259 | K16: =SUM(K14:K15) -> 253 | L16: =SUM(L14:L15) -> 262 | ... S16: =SUM(S14:S15) -> 254 | T16: =SUM(E16:S16) -> 3812
A18: B | B18: PENGGUNA HAK PILIH
B19: 1. | C19: Jumlah pengguna hak pilih dalam Daftar Pemilih Tetap (DPT) | D19: LK | E19: 98 | F19: 96 | G19: 85 | H19: 95 | I19: 87 | J19: 101 | K19: 92 | L19: 109 | M19: 97 | N19: 88 | O19: 93 | P19: 80 | Q19: 83 | R19: 105 | S19: 92 | T19: =SUM(E19:S19) -> 1401
D20: PR | E20: 106 | F20: 108 | G20: 105 | H20: 104 | I20: 115 | J20: 101 | K20: 116 | L20: 109 | M20: 115 | N20: 113 | O20: 96 | P20: 96 | Q20: 106 | R20: 111 | S20: 101 | T20: =SUM(E20:S20) -> 1602
D21: JML | E21: =SUM(E19:E20) -> 204 | F21: =SUM(F19:F20) -> 204 | G21: =SUM(G19:G20) -> 190 | H21: =SUM(H19:H20) -> 199 | I21: =SUM(I19:I20) -> 202 | J21: =SUM(J19:J20) -> 202 | K21: =SUM(K19:K20) -> 208 | L21: =SUM(L19:L20) -> 218 | ... S21: =SUM(S19:S20) -> 193 | T21: =SUM(E21:S21) -> 3003
B22: 2. | C22: Jumlah pengguna hak pilih dalam Daftar Pemilih Tambahan (DPTb) | D22: LK | I22: 1 | T22: =SUM(E22:S22) -> 1
D23: PR | M23: 3 | T23: =SUM(E23:S23) -> 3
D24: JML | E24: =SUM(E22:E23) -> 0 | F24: =SUM(F22:F23) -> 0 | G24: =SUM(G22:G23) -> 0 | H24: =SUM(H22:H23) -> 0 | I24: =SUM(I22:I23) -> 1 | J24: =SUM(J22:J23) -> 0 | K24: =SUM(K22:K23) -> 0 | L24: =SUM(L22:L23) -> 0 | ... S24: =SUM(S22:S23) -> 0 | T24: =SUM(E24:S24) -> 4
B25: 3. | C25: Jumlah pengguna hak pilih dalam Daftar Pemilih Khusus (DPK) | D25: LK | E25: 2 | G25: 2 | H25: 2 | K25: 3 | L25: 2 | M25: 2 | O25: 2 | P25: 3 | Q25: 2 | S25: 2 | T25: =SUM(E25:S25) -> 22
D26: PR | E26: 2 | H26: 2 | I26: 5 | J26: 1 | K26: 1 | M26: 1 | O26: 9 | P26: 3 | S26: 3 | T26: =SUM(E26:S26) -> 27
D27: JML | E27: =SUM(E25:E26) -> 4 | F27: =SUM(F25:F26) -> 0 | G27: =SUM(G25:G26) -> 2 | H27: =SUM(H25:H26) -> 4 | I27: =SUM(I25:I26) -> 5 | J27: =SUM(J25:J26) -> 1 | K27: =SUM(K25:K26) -> 4 | L27: =SUM(L25:L26) -> 2 | ... S27: =SUM(S25:S26) -> 5 | T27: =SUM(E27:S27) -> 49
B28: 4. | C28: Jumlah Pengguna Hak Pilih (B.1+B.2+B.3) | D28: LK | E28: =SUM(E19,E22,E25) -> 100 | F28: =SUM(F19,F22,F25) -> 96 | G28: =SUM(G19,G22,G25) -> 87 | H28: =SUM(H19,H22,H25) -> 97 | I28: =SUM(I19,I22,I25) -> 88 | J28: =SUM(J19,J22,J25) -> 101 | K28: =SUM(K19,K22,K25) -> 95 | L28: =SUM(L19,L22,L25) -> 111 | ... S28: =SUM(S19,S22,S25) -> 94 | T28: =SUM(E28:S28) -> 1424
D29: PR | E29: =SUM(E20,E23,E26) -> 108 | F29: =SUM(F20,F23,F26) -> 108 | G29: =SUM(G20,G23,G26) -> 105 | H29: =SUM(H20,H23,H26) -> 106 | I29: =SUM(I20,I23,I26) -> 120 | J29: =SUM(J20,J23,J26) -> 102 | K29: =SUM(K20,K23,K26) -> 117 | L29: =SUM(L20,L23,L26) -> 109 | ... S29: =SUM(S20,S23,S26) -> 104 | T29: =SUM(E29:S29) -> 1632
D30: JML | E30: =SUM(E28:E29) -> 208 | F30: =SUM(F28:F29) -> 204 | G30: =SUM(G28:G29) -> 192 | H30: =SUM(H28:H29) -> 203 | I30: =SUM(I28:I29) -> 208 | J30: =SUM(J28:J29) -> 203 | K30: =SUM(K28:K29) -> 212 | L30: =SUM(L28:L29) -> 220 | ... S30: =SUM(S28:S29) -> 198 | T30: =SUM(E30:S30) -> 3056
A32: II | B32: DATA PENGGUNAAN SURAT SUARA
A33: 1 | B33: Jumlah surat suara yang diterima, termasuk surat suara cadangan 2,5% dari DPT | E33: 269 | F33: 266 | G33: 250 | H33: 260 | I33: 264 | J33: 265 | K33: 259 | L33: 268 | M33: 256 | N33: 250 | O33: 259 | P33: 260 | Q33: 254 | R33: 261 | S33: 260 | T33: =SUM(E33:S33) -> 3901
A34: 2 | B34: Jumlah surat suara yang digunakan | E34: 208 | F34: 204 | G34: 192 | H34: 203 | I34: 208 | J34: 203 | K34: 212 | L34: 220 | M34: 218 | N34: 201 | O34: 200 | P34: 182 | Q34: 191 | R34: 216 | S34: 198 | T34: =SUM(E34:S34) -> 3056
A35: 3 | B35: Jumlah surat suara dikembalikan oleh pemilih (karena rusak atau keliru coblos) | E35: 0 | F35: 1 | G35: 0 | H35: 0 | I35: 0 | J35: 0 | K35: 1 | L35: 0 | M35: 0 | N35: 0 | O35: 1 | P35: 1 | Q35: 0 | R35: 0 | S35: 1 | T35: =SUM(E35:S35) -> 5
A36: 4 | B36: Jumlah surat suara yang tidak digunakan/tidak terpakai, termasuk sisa surat suara cadangan | E36: =E33-(E34+E35) -> 61 | F36: =F33-(F34+F35) -> 61 | G36: =G33-(G34+G35) -> 58 | H36: =H33-(H34+H35) -> 57 | I36: =I33-(I34+I35) -> 56 | J36: =J33-(J34+J35) -> 62 | K36: =K33-(K34+K35) -> 46 | L36: =L33-(L34+L35) -> 48 | ... S36: =S33-(S34+S35) -> 61 | T36: =SUM(E36:S36) -> 840
A38: III | B38: DATA PEMILIH DISABILITAS
B39: Jumlah seluruh Pemilih disabilitas yang menggunakan hak pilih | D39: LK | E39: 2 | F39: 0 | G39: 1 | H39: 0 | I39: 0 | J39: 0 | K39: 0 | L39: 0 | M39: 0 | N39: 0 | O39: 0 | P39: 0 | Q39: 0 | R39: 0 | S39: 4 | T39: =SUM(E39:S39) -> 7
D40: PR | E40: 0 | F40: 0 | G40: 3 | H40: 0 | I40: 0 | J40: 0 | K40: 0 | L40: 0 | M40: 0 | N40: 0 | O40: 0 | P40: 0 | Q40: 0 | R40: 0 | S40: 3 | T40: =SUM(E40:S40) -> 6
D41: JML | E41: =SUM(E39:E40) -> 2 | F41: =SUM(F39:F40) -> 0 | G41: =SUM(G39:G40) -> 4 | H41: =SUM(H39:H40) -> 0 | I41: =SUM(I39:I40) -> 0 | J41: =SUM(J39:J40) -> 0 | K41: =SUM(K39:K40) -> 0 | L41: =SUM(L39:L40) -> 0 | ... S41: =SUM(S39:S40) -> 7 | T41: =SUM(E41:S41) -> 13
A43: IV | B43: DATA RINCIAN PEROLEHAN SUARA PASANGAN CALON BUPATI DAN WAKIL BUPATI
A44: NOMOR DAN NAMA CALON
A45: A.1 | B45: 1. | C45: Partai Kebangkitan Bangsa | E45: 13 | F45: 6 | G45: 8 | H45: 4 | I45: 5 | J45: 10 | K45: 8 | L45: 6 | M45: 7 | N45: 6 | O45: 4 | P45: 8 | Q45: 4 | R45: 3 | S45: 6 | T45: =SUM(E45:S45) -> 98
A46: A.2 | C46: 1. Dra. Hj. MA`MULAH HARUN, M.Pd.I. | E46: 9 | F46: 22 | G46: 35 | H46: 16 | I46: 10 | J46: 6 | K46: 4 | L46: 8 | M46: 8 | N46: 7 | O46: 5 | P46: 13 | Q46: 10 | R46: 9 | S46: 16 | T46: =SUM(E46:S46) -> 178
C47: 2. UBAIDILLAH, S.Fil.I. | E47: 1 | F47: 1 | G47: 1 | H47: 3 | I47: 0 | J47: 2 | K47: 1 | L47: 0 | M47: 1 | N47: 0 | O47: 2 | P47: 8 | Q47: 5 | R47: 1 | S47: 1 | T47: =SUM(E47:S47) -> 27
C48: 3. Ir. H. YOYOK MULYADI, M.Si. | E48: 0 | F48: 0 | G48: 0 | H48: 0 | I48: 2 | J48: 0 | K48: 0 | L48: 1 | M48: 0 | N48: 0 | O48: 1 | P48: 1 | Q48: 1 | R48: 1 | S48: 0 | T48: =SUM(E48:S48) -> 7
C49: 4. KHOIRUL ANWAR, S.Fil.I. | E49: 2 | F49: 0 | G49: 0 | H49: 1 | I49: 0 | J49: 0 | K49: 0 | L49: 2 | M49: 0 | N49: 1 | O49: 0 | P49: 1 | Q49: 1 | R49: 0 | S49: 0 | T49: =SUM(E49:S49) -> 8
C50: 5. ARIF WIJAKSANA | E50: 0 | F50: 0 | G50: 0 | H50: 0 | I50: 0 | J50: 1 | K50: 0 | L50: 0 | M50: 1 | N50: 1 | O50: 0 | P50: 0 | Q50: 0 | R50: 0 | S50: 0 | T50: =SUM(E50:S50) -> 3
C51: 6. Dr. SITI YUMNAH | E51: 0 | F51: 0 | G51: 0 | H51: 1 | I51: 0 | J51: 0 | K51: 2 | L51: 0 | M51: 1 | N51: 2 | O51: 2 | P51: 4 | Q51: 1 | R51: 0 | S51: 0 | T51: =SUM(E51:S51) -> 13
...

Sheet SOBO
C2: Kecamatan | D2: BANYUWANGI
C3: Kabupaten | D3: BANYUWANGI
C4: Provinsi | D4: JAWA TIMUR
C9: Kelurahan | D9: SOBO
A12: I | B12: DATA PEMILIH DAN PENGGUNAAN HAK PILIH | AB12: JUMLAH AKHIR
A13: A | B13: DATA PEMILIH | E13: TPS 001 | F13: TPS 002 | G13: TPS 003 | H13: TPS 004 | I13: TPS 005 | J13: TPS 006 | K13: TPS 007 | L13: TPS 008 | M13: TPS 009 | N13: TPS 010 | O13: TPS 011 | P13: TPS 012 | Q13: TPS 013 | R13: TPS 014 | S13: TPS 015 | T13: TPS 016 | U13: TPS 017 | V13: TPS 018 | W13: TPS 019 | X13: TPS 020 | Y13: TPS 021 | Z13: TPS 022 | AA13: TPS 023
B14: Jumlah Pemilih dalam Daftar Pemilih Tetap (DPT) | D14: LK | E14: 144 | F14: 127 | G14: 126 | H14: 136 | I14: 127 | J14: 137 | K14: 143 | L14: 135 | M14: 139 | N14: 141 | O14: 125 | P14: 134 | Q14: 148 | R14: 127 | S14: 138 | T14: 131 | U14: 123 | V14: 132 | W14: 142 | X14: 140 | Y14: 142 | Z14: 142 | AA14: 131 | AB14: =SUM(E14:AA14) -> 3110
D15: PR | E15: 146 | F15: 159 | G15: 162 | H15: 147 | I15: 147 | J15: 145 | K15: 142 | L15: 146 | M15: 156 | N15: 149 | O15: 162 | P15: 164 | Q15: 142 | R15: 147 | S15: 156 | T15: 147 | U15: 155 | V15: 149 | W15: 147 | X15: 147 | Y15: 144 | Z15: 152 | AA15: 152 | AB15: =SUM(E15:AA15) -> 3463
D16: JML | E16: =SUM(E14:E15) -> 290 | F16: =SUM(F14:F15) -> 286 | G16: =SUM(G14:G15) -> 288 | H16: =SUM(H14:H15) -> 283 | I16: =SUM(I14:I15) -> 274 | J16: =SUM(J14:J15) -> 282 | K16: =SUM(K14:K15) -> 285 | L16: =SUM(L14:L15) -> 281 | ... AA16: =SUM(AA14:AA15) -> 283 | AB16: =SUM(E16:AA16) -> 6573
A18: B | B18: PENGGUNA HAK PILIH
B19: 1. | C19: Jumlah pengguna hak pilih dalam Daftar Pemilih Tetap (DPT) | D19: LK | E19: 102 | F19: 93 | G19: 89 | H19: 85 | I19: 87 | J19: 102 | K19: 109 | L19: 108 | M19: 97 | N19: 100 | O19: 90 | P19: 104 | Q19: 116 | R19: 95 | S19: 95 | T19: 84 | U19: 99 | V19: 91 | W19: 104 | X19: 101 | Y19: 91 | Z19: 95 | AA19: 87 | AB19: =SUM(E19:AA19) -> 2224
D20: PR | E20: 104 | F20: 132 | G20: 117 | H20: 104 | I20: 100 | J20: 117 | K20: 105 | L20: 121 | M20: 129 | N20: 118 | O20: 129 | P20: 119 | Q20: 110 | R20: 115 | S20: 123 | T20: 112 | U20: 129 | V20: 120 | W20: 128 | X20: 122 | Y20: 107 | Z20: 123 | AA20: 124 | AB20: =SUM(E20:AA20) -> 2708
D21: JML | E21: =SUM(E19:E20) -> 206 | F21: =SUM(F19:F20) -> 225 | G21: =SUM(G19:G20) -> 206 | H21: =SUM(H19:H20) -> 189 | I21: =SUM(I19:I20) -> 187 | J21: =SUM(J19:J20) -> 219 | K21: =SUM(K19:K20) -> 214 | L21: =SUM(L19:L20) -> 229 | ... AA21: =SUM(AA19:AA20) -> 211 | AB21: =SUM(E21:AA21) -> 4932
B22: 2. | C22: Jumlah pengguna hak pilih dalam Daftar Pemilih Tambahan (DPTb) | D22: LK | E22: 1 | F22: 0 | G22: 0 | H22: 0 | I22: 0 | J22: 0 | K22: 0 | L22: 1 | M22: 0 | N22: 0 | O22: 0 | P22: 0 | Q22: 1 | R22: 0 | S22: 0 | T22: 0 | U22: 0 | V22: 0 | W22: 0 | X22: 0 | Y22: 2 | Z22: 0 | AA22: 0 | AB22: =SUM(E22:AA22) -> 5
D23: PR | E23: 0 | F23: 0 | G23: 0 | H23: 0 | I23: 0 | J23: 0 | K23: 0 | L23: 2 | M23: 0 | N23: 0 | O23: 0 | P23: 0 | Q23: 1 | R23: 0 | S23: 0 | T23: 0 | U23: 0 | V23: 0 | W23: 0 | X23: 0 | Y23: 2 | Z23: 0 | AA23: 0 | AB23: =SUM(E23:AA23) -> 5
D24: JML | E24: =SUM(E22:E23) -> 1 | F24: =SUM(F22:F23) -> 0 | G24: =SUM(G22:G23) -> 0 | H24: =SUM(H22:H23) -> 0 | I24: =SUM(I22:I23) -> 0 | J24: =SUM(J22:J23) -> 0 | K24: =SUM(K22:K23) -> 0 | L24: =SUM(L22:L23) -> 3 | ... AA24: =SUM(AA22:AA23) -> 0 | AB24: =SUM(E24:AA24) -> 10
B25: 3. | C25: Jumlah pengguna hak pilih dalam Daftar Pemilih Khusus (DPK) | D25: LK | E25: 0 | F25: 0 | G25: 0 | H25: 0 | I25: 0 | J25: 1 | K25: 1 | L25: 0 | M25: 0 | N25: 3 | O25: 2 | P25: 2 | Q25: 5 | R25: 1 | S25: 1 | T25: 2 | U25: 0 | V25: 3 | W25: 1 | X25: 1 | Y25: 2 | Z25: 1 | AA25: 2 | AB25: =SUM(E25:AA25) -> 28
D26: PR | E26: 1 | F26: 3 | G26: 0 | H26: 1 | I26: 1 | J26: 2 | K26: 2 | L26: 0 | M26: 0 | N26: 4 | O26: 1 | P26: 2 | Q26: 9 | R26: 0 | S26: 5 | T26: 3 | U26: 1 | V26: 3 | W26: 0 | X26: 0 | Y26: 2 | Z26: 0 | AA26: 0 | AB26: =SUM(E26:AA26) -> 40
D27: JML | E27: =SUM(E25:E26) -> 1 | F27: =SUM(F25:F26) -> 3 | G27: =SUM(G25:G26) -> 0 | H27: =SUM(H25:H26) -> 1 | I27: =SUM(I25:I26) -> 1 | J27: =SUM(J25:J26) -> 3 | K27: =SUM(K25:K26) -> 3 | L27: =SUM(L25:L26) -> 0 | ... AA27: =SUM(AA25:AA26) -> 2 | AB27: =SUM(E27:AA27) -> 68
B28: 4. | C28: Jumlah Pengguna Hak Pilih (B.1+B.2+B.3) | D28: LK | E28: =SUM(E19,E22,E25) -> 103 | F28: =SUM(F19,F22,F25) -> 93 | G28: =SUM(G19,G22,G25) -> 89 | H28: =SUM(H19,H22,H25) -> 85 | I28: =SUM(I19,I22,I25) -> 87 | J28: =SUM(J19,J22,J25) -> 103 | K28: =SUM(K19,K22,K25) -> 110 | L28: =SUM(L19,L22,L25) -> 109 | ... AA28: =SUM(AA19,AA22,AA25) -> 89 | AB28: =SUM(E28:AA28) -> 2257
D29: PR | E29: =SUM(E20,E23,E26) -> 105 | F29: =SUM(F20,F23,F26) -> 135 | G29: =SUM(G20,G23,G26) -> 117 | H29: =SUM(H20,H23,H26) -> 105 | I29: =SUM(I20,I23,I26) -> 101 | J29: =SUM(J20,J23,J26) -> 119 | K29: =SUM(K20,K23,K26) -> 107 | L29: =SUM(L20,L23,L26) -> 123 | ... AA29: =SUM(AA20,AA23,AA26) -> 124 | AB29: =SUM(E29:AA29) -> 2753
D30: JML | E30: =SUM(E28:E29) -> 208 | F30: =SUM(F28:F29) -> 228 | G30: =SUM(G28:G29) -> 206 | H30: =SUM(H28:H29) -> 190 | I30: =SUM(I28:I29) -> 188 | J30: =SUM(J28:J29) -> 222 | K30: =SUM(K28:K29) -> 217 | L30: =SUM(L28:L29) -> 232 | ... AA30: =SUM(AA28:AA29) -> 213 | AB30: =SUM(E30:AA30) -> 5010
A32: II | B32: DATA PENGGUNAAN SURAT SUARA
A33: 1 | B33: Jumlah surat suara yang diterima, termasuk surat suara cadangan 2,5% dari DPT | E33: 296 | F33: 262 | G33: 294 | H33: 289 | I33: 270 | J33: 289 | K33: 291 | L33: 287 | M33: 301 | N33: 296 | O33: 273 | P33: 304 | Q33: 296 | R33: 280 | S33: 300 | T33: 284 | U33: 284 | V33: 287 | W33: 295 | X33: 293 | Y33: 292 | Z33: 300 | AA33: 279 | AB33: =SUM(E33:AA33) -> 6642
A34: 2 | B34: Jumlah surat suara yang digunakan | E34: 208 | F34: 228 | G34: 206 | H34: 190 | I34: 188 | J34: 222 | K34: 217 | L34: 232 | M34: 226 | N34: 225 | O34: 222 | P34: 227 | Q34: 242 | R34: 211 | S34: 224 | T34: 201 | U34: 229 | V34: 217 | W34: 233 | X34: 224 | Y34: 206 | Z34: 219 | AA34: 213 | AB34: =SUM(E34:AA34) -> 5010
A35: 3 | B35: Jumlah surat suara dikembalikan oleh pemilih (karena rusak atau keliru coblos) | E35: 1 | F35: 0 | G35: 0 | H35: 0 | I35: 0 | J35: 0 | K35: 0 | L35: 0 | M35: 0 | N35: 0 | O35: 0 | P35: 0 | Q35: 0 | R35: 0 | S35: 2 | T35: 0 | U35: 0 | V35: 0 | W35: 0 | X35: 0 | Y35: 0 | Z35: 0 | AA35: 0 | AB35: =SUM(E35:AA35) -> 3
A36: 4 | B36: Jumlah surat suara yang tidak digunakan/tidak terpakai, termasuk sisa surat suara cadangan | E36: =E33-(E34+E35) -> 87 | F36: =F33-(F34+F35) -> 34 | G36: =G33-(G34+G35) -> 88 | H36: =H33-(H34+H35) -> 99 | I36: =I33-(I34+I35) -> 82 | J36: =J33-(J34+J35) -> 67 | K36: =K33-(K34+K35) -> 74 | L36: =L33-(L34+L35) -> 55 | ... AA36: =AA33-(AA34+AA35) -> 66 | AB36: =SUM(E36:AA36) -> 1629
A38: III | B38: DATA PEMILIH DISABILITAS
B39: Jumlah seluruh Pemilih disabilitas yang menggunakan hak pilih | D39: LK | E39: 2 | W39: 1 | AB39: =SUM(E39:AA39) -> 3
D40: PR | E40: 1 | Z40: 1 | AB40: =SUM(E40:AA40) -> 2
D41: JML | E41: =SUM(E39:E40) -> 3 | F41: =SUM(F39:F40) -> 0 | G41: =SUM(G39:G40) -> 0 | H41: =SUM(H39:H40) -> 0 | I41: =SUM(I39:I40) -> 0 | J41: =SUM(J39:J40) -> 0 | K41: =SUM(K39:K40) -> 0 | L41: =SUM(L39:L40) -> 0 | ... AA41: =SUM(AA39:AA40) -> 0 | AB41: =SUM(E41:AA41) -> 5
A43: IV | B43: DATA RINCIAN PEROLEHAN SUARA PASANGAN CALON BUPATI DAN WAKIL BUPATI
A44: NOMOR DAN NAMA CALON
A45: A.1 | B45: 1. | C45: Partai Kebangkitan Bangsa | E45: 8 | F45: 9 | G45: 11 | H45: 7 | I45: 12 | J45: 4 | K45: 3 | L45: 3 | M45: 8 | N45: 2 | O45: 1 | P45: 6 | Q45: 7 | R45: 3 | S45: 11 | T45: 3 | U45: 10 | V45: 1 | W45: 6 | X45: 8 | Y45: 6 | Z45: 6 | AA45: 5 | AB45: =SUM(E45:AA45) -> 140
A46: A.2 | C46: 1. Dra. Hj. MA`MULAH HARUN, M.Pd.I. | E46: 12 | F46: 17 | G46: 19 | H46: 28 | I46: 8 | J46: 10 | K46: 8 | L46: 3 | M46: 11 | N46: 17 | O46: 4 | P46: 12 | Q46: 6 | R46: 14 | S46: 17 | T46: 8 | U46: 23 | V46: 6 | W46: 21 | X46: 15 | Y46: 7 | Z46: 15 | AA46: 19 | AB46: =SUM(E46:AA46) -> 300
C47: 2. UBAIDILLAH, S.Fil.I. | E47: 1 | F47: 0 | G47: 0 | H47: 0 | I47: 2 | J47: 2 | K47: 0 | L47: 0 | M47: 0 | N47: 2 | O47: 0 | P47: 3 | Q47: 3 | R47: 2 | S47: 0 | T47: 3 | U47: 2 | V47: 0 | W47: 1 | X47: 1 | Y47: 2 | Z47: 1 | AA47: 1 | AB47: =SUM(E47:AA47) -> 26
C48: 3. Ir. H. YOYOK MULYADI, M.Si. | E48: 0 | F48: 0 | G48: 1 | H48: 0 | I48: 0 | J48: 1 | K48: 0 | L48: 0 | M48: 0 | N48: 1 | O48: 1 | P48: 0 | Q48: 0 | R48: 0 | S48: 3 | T48: 0 | U48: 1 | V48: 0 | W48: 2 | X48: 0 | Y48: 1 | Z48: 0 | AA48: 2 | AB48: =SUM(E48:AA48) -> 13
C49: 4. KHOIRUL ANWAR, S.Fil.I. | E49: 0 | F49: 1 | G49: 0 | H49: 1 | I49: 0 | J49: 0 | K49: 0 | L49: 0 | M49: 1 | N49: 1 | O49: 0 | P49: 1 | Q49: 1 | R49: 0 | S49: 0 | T49: 0 | U49: 1 | V49: 0 | W49: 0 | X49: 0 | Y49: 1 | Z49: 3 | AA49: 0 | AB49: =SUM(E49:AA49) -> 11
C50: 5. ARIF WIJAKSANA | E50: 0 | F50: 0 | G50: 0 | H50: 0 | I50: 0 | J50: 0 | K50: 0 | L50: 0 | M50: 0 | N50: 0 | O50: 0 | P50: 0 | Q50: 0 | R50: 0 | S50: 0 | T50: 0 | U50: 1 | V50: 1 | W50: 1 | X50: 0 | Y50: 1 | Z50: 0 | AA50: 0 | AB50: =SUM(E50:AA50) -> 4
C51: 6. Dr. SITI YUMNAH | E51: 0 | F51: 1 | G51: 0 | H51: 0 | I51: 2 | J51: 1 | K51: 1 | L51: 0 | M51: 1 | N51: 0 | O51: 0 | P51: 0 | Q51: 0 | R51: 1 | S51: 0 | T51: 0 | U51: 1 | V51: 1 | W51: 0 | X51: 0 | Y51: 1 | Z51: 0 | AA51: 0 | AB51: =SUM(E51:AA51) -> 10
...

Sheet KEBALENAN
C2: Kecamatan | D2: BANYUWANGI
C3: Kabupaten | D3: BANYUWANGI
C4: Provinsi | D4: JAWA TIMUR
C9: Kelurahan | D9: KEBALENAN
A12: I | B12: DATA PEMILIH DAN PENGGUNAAN HAK PILIH | AH12: JUMLAH AKHIR
A13: A | B13: DATA PEMILIH | E13: TPS 001 | F13: TPS 002 | G13: TPS 003 | H13: TPS 004 | I13: TPS 005 | J13: TPS 006 | K13: TPS 007 | L13: TPS 008 | M13: TPS 009 | N13: TPS 010 | O13: TPS 011 | P13: TPS 012 | Q13: TPS 013 | R13: TPS 014 | S13: TPS 015 | T13: TPS 016 | U13: TPS 017 | V13: TPS 018 | W13: TPS 019 | X13: TPS 020 | Y13: TPS 021 | Z13: TPS 022 | AA13: TPS 023 | AB13: TPS 024 | AC13: TPS 025 | AD13: TPS 026 | AE13: TPS 027 | AF13: TPS 028 | AG13: TPS 029
B14: Jumlah Pemilih dalam Daftar Pemilih Tetap (DPT) | D14: LK | E14: 135 | F14: 150 | G14: 140 | H14: 130 | I14: 145 | J14: 139 | K14: 138 | L14: 138 | M14: 146 | N14: 141 | O14: 134 | P14: 136 | Q14: 135 | R14: 127 | S14: 124 | T14: 127 | U14: 138 | V14: 147 | W14: 129 | X14: 120 | Y14: 130 | Z14: 135 | AA14: 136 | AB14: 125 | AC14: 136 | AD14: 135 | AE14: 82 | AF14: 74 | AG14: 148 | AH14: =SUM(E14:AG14) -> 3820
D15: PR | E15: 155 | F15: 142 | G15: 154 | H15: 159 | I15: 146 | J15: 140 | K15: 149 | L15: 154 | M15: 144 | N15: 155 | O15: 162 | P15: 143 | Q15: 129 | R15: 147 | S15: 144 | T15: 143 | U15: 153 | V15: 146 | W15: 146 | X15: 150 | Y15: 153 | Z15: 149 | AA15: 154 | AB15: 152 | AC15: 160 | AD15: 148 | AE15: 96 | AF15: 83 | AG15: 150 | AH15: =SUM(E15:AG15) -> 4206
D16: JML | E16: =SUM(E14:E15) -> 290 | F16: =SUM(F14:F15) -> 292 | G16: =SUM(G14:G15) -> 294 | H16: =SUM(H14:H15) -> 289 | I16: =SUM(I14:I15) -> 291 | J16: =SUM(J14:J15) -> 279 | K16: =SUM(K14:K15) -> 287 | L16: =SUM(L14:L15) -> 292 | ... AG16: =SUM(AG14:AG15) -> 298 | AH16: =SUM(E16:AG16) -> 8026
A18: B | B18: PENGGUNA HAK PILIH
B19: 1. | C19: Jumlah pengguna hak pilih dalam Daftar Pemilih Tetap (DPT) | D19: LK | E19: 94 | F19: 111 | G19: 95 | H19: 95 | I19: 112 | J19: 109 | K19: 103 | L19: 99 | M19: 113 | N19: 91 | O19: 101 | P19: 92 | Q19: 97 | R19: 92 | S19: 89 | T19: 92 | U19: 96 | V19: 118 | W19: 100 | X19: 88 | Y19: 93 | Z19: 94 | AA19: 101 | AB19: 87 | AC19: 102 | AD19: 96 | AE19: 56 | AF19: 53 | AG19: 123 | AH19: =SUM(E19:AG19) -> 2792
D20: PR | E20: 121 | F20: 112 | G20: 112 | H20: 127 | I20: 127 | J20: 104 | K20: 116 | L20: 126 | M20: 120 | N20: 111 | O20: 122 | P20: 116 | Q20: 112 | R20: 111 | S20: 117 | T20: 107 | U20: 124 | V20: 128 | W20: 120 | X20: 123 | Y20: 127 | Z20: 118 | AA20: 121 | AB20: 113 | AC20: 128 | AD20: 126 | AE20: 70 | AF20: 67 | AG20: 128 | AH20: =SUM(E20:AG20) -> 3354
D21: JML | E21: =SUM(E19:E20) -> 215 | F21: =SUM(F19:F20) -> 223 | G21: =SUM(G19:G20) -> 207 | H21: =SUM(H19:H20) -> 222 | I21: =SUM(I19:I20) -> 239 | J21: =SUM(J19:J20) -> 213 | K21: =SUM(K19:K20) -> 219 | L21: =SUM(L19:L20) -> 225 | ... AG21: =SUM(AG19:AG20) -> 251 | AH21: =SUM(E21:AG21) -> 6146
B22: 2. | C22: Jumlah pengguna hak pilih dalam Daftar Pemilih Tambahan (DPTb) | D22: LK | E22: 0 | F22: 0 | G22: 0 | H22: 0 | I22: 0 | J22: 0 | K22: 0 | L22: 0 | M22: 1 | N22: 0 | O22: 0 | P22: 0 | Q22: 0 | R22: 0 | S22: 1 | T22: 7 | U22: 2 | V22: 0 | W22: 0 | X22: 0 | Y22: 0 | Z22: 0 | AA22: 0 | AB22: 1 | AC22: 0 | AD22: 11 | AE22: 8 | AF22: 0 | AG22: 0 | AH22: =SUM(E22:AG22) -> 31
D23: PR | E23: 2 | F23: 0 | G23: 0 | H23: 0 | I23: 0 | J23: 0 | K23: 0 | L23: 1 | M23: 0 | N23: 0 | O23: 0 | P23: 0 | Q23: 0 | R23: 0 | S23: 2 | T23: 1 | U23: 3 | V23: 0 | W23: 0 | X23: 0 | Y23: 2 | Z23: 1 | AA23: 0 | AB23: 1 | AC23: 0 | AD23: 1 | AE23: 0 | AF23: 0 | AG23: 0 | AH23: =SUM(E23:AG23) -> 14
D24: JML | E24: =SUM(E22:E23) -> 2 | F24: =SUM(F22:F23) -> 0 | G24: =SUM(G22:G23) -> 0 | H24: =SUM(H22:H23) -> 0 | I24: =SUM(I22:I23) -> 0 | J24: =SUM(J22:J23) -> 0 | K24: =SUM(K22:K23) -> 0 | L24: =SUM(L22:L23) -> 1 | ... AG24: =SUM(AG22:AG23) -> 0 | AH24: =SUM(E24:AG24) -> 45
B25: 3. | C25: Jumlah pengguna hak pilih dalam Daftar Pemilih Khusus (DPK) | D25: LK | E25: 1 | F25: 0 | G25: 2 | H25: 1 | I25: 0 | J25: 0 | K25: 3 | L25: 2 | M25: 1 | N25: 1 | O25: 1 | P25: 0 | Q25: 4 | R25: 4 | S25: 4 | T25: 0 | U25: 0 | V25: 1 | W25: 0 | X25: 0 | Y25: 1 | Z25: 1 | AA25: 0 | AB25: 0 | AC25: 2 | AD25: 1 | AE25: 2 | AF25: 2 | AG25: 0 | AH25: =SUM(E25:AG25) -> 34
D26: PR | E26: 0 | F26: 3 | G26: 2 | H26: 2 | I26: 0 | J26: 1 | K26: 4 | L26: 1 | M26: 5 | N26: 1 | O26: 1 | P26: 1 | Q26: 2 | R26: 2 | S26: 5 | T26: 2 | U26: 0 | V26: 1 | W26: 2 | X26: 4 | Y26: 2 | Z26: 1 | AA26: 0 | AB26: 0 | AC26: 0 | AD26: 2 | AE26: 3 | AF26: 5 | AG26: 0 | AH26: =SUM(E26:AG26) -> 52
D27: JML | E27: =SUM(E25:E26) -> 1 | F27: =SUM(F25:F26) -> 3 | G27: =SUM(G25:G26) -> 4 | H27: =SUM(H25:H26) -> 3 | I27: =SUM(I25:I26) -> 0 | J27: =SUM(J25:J26) -> 1 | K27: =SUM(K25:K26) -> 7 | L27: =SUM(L25:L26) -> 3 | ... AG27: =SUM(AG25:AG26) -> 0 | AH27: =SUM(E27:AG27) -> 86
B28: 4. | C28: Jumlah Pengguna Hak Pilih (B.1+B.2+B.3) | D28: LK | E28: =SUM(E19,E22,E25) -> 95 | F28: =SUM(F19,F22,F25) -> 111 | G28: =SUM(G19,G22,G25) -> 97 | H28: =SUM(H19,H22,H25) -> 96 | I28: =SUM(I19,I22,I25) -> 112 | J28: =SUM(J19,J22,J25) -> 109 | K28: =SUM(K19,K22,K25) -> 106 | L28: =SUM(L19,L22,L25) -> 101 | ... AG28: =SUM(AG19,AG22,AG25) -> 123 | AH28: =SUM(E28:AG28) -> 2857
D29: PR | E29: =SUM(E20,E23,E26) -> 123 | F29: =SUM(F20,F23,F26) -> 115 | G29: =SUM(G20,G23,G26) -> 114 | H29: =SUM(H20,H23,H26) -> 129 | I29: =SUM(I20,I23,I26) -> 127 | J29: =SUM(J20,J23,J26) -> 105 | K29: =SUM(K20,K23,K26) -> 120 | L29: =SUM(L20,L23,L26) -> 128 | ... AG29: =SUM(AG20,AG23,AG26) -> 128 | AH29: =SUM(E29:AG29) -> 3420
D30: JML | E30: =SUM(E28:E29) -> 218 | F30: =SUM(F28:F29) -> 226 | G30: =SUM(G28:G29) -> 211 | H30: =SUM(H28:H29) -> 225 | I30: =SUM(I28:I29) -> 239 | J30: =SUM(J28:J29) -> 214 | K30: =SUM(K28:K29) -> 226 | L30: =SUM(L28:L29) -> 229 | ... AG30: =SUM(AG28:AG29) -> 251 | AH30: =SUM(E30:AG30) -> 6277
A32: II | B32: DATA PENGGUNAAN SURAT SUARA
A33: 1 | B33: Jumlah surat suara yang diterima, termasuk surat suara cadangan 2,5% dari DPT | E33: 296 | F33: 279 | G33: 300 | H33: 295 | I33: 297 | J33: 285 | K33: 288 | L33: 288 | M33: 270 | N33: 296 | O33: 302 | P33: 270 | Q33: 270 | R33: 280 | S33: 275 | T33: 276 | U33: 297 | V33: 299 | W33: 281 | X33: 275 | Y33: 289 | Z33: 280 | AA33: 283 | AB33: 283 | AC33: 302 | AD33: 290 | AE33: 240 | AF33: 168 | AG33: 306 | AH33: =SUM(E33:AG33) -> 8160
A34: 2 | B34: Jumlah surat suara yang digunakan | E34: 218 | F34: 226 | G34: 211 | H34: 225 | I34: 239 | J34: 214 | K34: 226 | L34: 229 | M34: 240 | N34: 204 | O34: 225 | P34: 209 | Q34: 215 | R34: 209 | S34: 218 | T34: 209 | U34: 225 | V34: 248 | W34: 222 | X34: 215 | Y34: 225 | Z34: 215 | AA34: 222 | AB34: 202 | AC34: 232 | AD34: 237 | AE34: 139 | AF34: 127 | AG34: 251 | AH34: =SUM(E34:AG34) -> 6277
A35: 3 | B35: Jumlah surat suara dikembalikan oleh pemilih (karena rusak atau keliru coblos) | E35: 0 | F35: 0 | G35: 0 | H35: 0 | I35: 0 | J35: 0 | K35: 1 | L35: 0 | M35: 0 | N35: 0 | O35: 0 | P35: 0 | Q35: 0 | R35: 2 | S35: 0 | U35: 1 | V35: 1 | Z35: 2 | AA35: 1 | AF35: 1 | AH35: =SUM(E35:AG35) -> 9
A36: 4 | B36: Jumlah surat suara yang tidak digunakan/tidak terpakai, termasuk sisa surat suara cadangan | E36: =E33-(E34+E35) -> 78 | F36: =F33-(F34+F35) -> 53 | G36: =G33-(G34+G35) -> 89 | H36: =H33-(H34+H35) -> 70 | I36: =I33-(I34+I35) -> 58 | J36: =J33-(J34+J35) -> 71 | K36: =K33-(K34+K35) -> 61 | L36: =L33-(L34+L35) -> 59 | ... AG36: =AG33-(AG34+AG35) -> 55 | AH36: =SUM(E36:AG36) -> 1874
A38: III | B38: DATA PEMILIH DISABILITAS
B39: Jumlah seluruh Pemilih disabilitas yang menggunakan hak pilih | D39: LK | O39: 1 | R39: 2 | X39: 1 | AC39: 1 | AE39: 1 | AH39: =SUM(E39:AG39) -> 6
D40: PR | L40: 1 | R40: 1 | U40: 1 | X40: 1 | Z40: 1 | AH40: =SUM(E40:AG40) -> 5
D41: JML | E41: =SUM(E39:E40) -> 0 | F41: =SUM(F39:F40) -> 0 | G41: =SUM(G39:G40) -> 0 | H41: =SUM(H39:H40) -> 0 | I41: =SUM(I39:I40) -> 0 | J41: =SUM(J39:J40) -> 0 | K41: =SUM(K39:K40) -> 0 | L41: =SUM(L39:L40) -> 1 | ... AG41: =SUM(AG39:AG40) -> 0 | AH41: =SUM(E41:AG41) -> 11
A43: IV | B43: DATA RINCIAN PEROLEHAN SUARA PASANGAN CALON BUPATI DAN WAKIL BUPATI
A44: NOMOR DAN NAMA CALON
A45: A.1 | B45: 1. | C45: Partai Kebangkitan Bangsa | E45: 12 | F45: 8 | G45: 6 | H45: 13 | I45: 11 | J45: 5 | K45: 4 | L45: 5 | M45: 7 | N45: 2 | O45: 2 | P45: 3 | Q45: 6 | R45: 4 | S45: 1 | T45: 4 | U45: 5 | V45: 10 | W45: 4 | X45: 6 | Y45: 3 | Z45: 1 | AA45: 2 | AB45: 1 | AC45: 2 | AD45: 2 | AE45: 1 | AF45: 4 | AG45: 2 | AH45: =SUM(E45:AG45) -> 136
A46: A.2 | C46: 1. Dra. Hj. MA`MULAH HARUN, M.Pd.I. | E46: 14 | F46: 22 | G46: 12 | H46: 21 | I46: 23 | J46: 15 | K46: 21 | L46: 17 | M46: 21 | N46: 19 | O46: 21 | P46: 8 | Q46: 12 | R46: 13 | S46: 4 | T46: 8 | U46: 19 | V46: 19 | W46: 10 | X46: 11 | Y46: 10 | Z46: 12 | AA46: 16 | AB46: 6 | AC46: 14 | AD46: 14 | AE46: 6 | AF46: 7 | AG46: 7 | AH46: =SUM(E46:AG46) -> 402
C47: 2. UBAIDILLAH, S.Fil.I. | E47: 0 | F47: 0 | G47: 0 | H47: 4 | I47: 3 | J47: 3 | K47: 2 | L47: 1 | M47: 0 | N47: 0 | O47: 1 | P47: 0 | Q47: 2 | R47: 2 | S47: 0 | T47: 0 | U47: 3 | V47: 0 | W47: 0 | X47: 0 | Y47: 0 | Z47: 0 | AA47: 2 | AB47: 0 | AC47: 2 | AD47: 1 | AE47: 2 | AF47: 2 | AG47: 1 | AH47: =SUM(E47:AG47) -> 31
C48: 3. Ir. H. YOYOK MULYADI, M.Si. | E48: 1 | F48: 0 | G48: 0 | H48: 0 | I48: 0 | J48: 0 | K48: 0 | L48: 0 | M48: 4 | N48: 1 | O48: 1 | P48: 0 | Q48: 1 | R48: 1 | S48: 1 | T48: 0 | U48: 0 | V48: 0 | W48: 3 | X48: 0 | Y48: 0 | Z48: 1 | AA48: 0 | AB48: 2 | AC48: 3 | AD48: 3 | AE48: 0 | AF48: 0 | AG48: 0 | AH48: =SUM(E48:AG48) -> 22
C49: 4. KHOIRUL ANWAR, S.Fil.I. | E49: 1 | F49: 1 | G49: 1 | H49: 1 | I49: 0 | J49: 0 | K49: 1 | L49: 1 | M49: 1 | N49: 1 | O49: 2 | P49: 0 | Q49: 0 | R49: 1 | S49: 1 | T49: 1 | U49: 1 | V49: 0 | W49: 0 | X49: 1 | Y49: 1 | Z49: 0 | AA49: 0 | AB49: 0 | AC49: 0 | AD49: 0 | AE49: 0 | AF49: 0 | AG49: 0 | AH49: =SUM(E49:AG49) -> 16
C50: 5. ARIF WIJAKSANA | E50: 2 | F50: 0 | G50: 0 | H50: 0 | I50: 0 | J50: 2 | K50: 0 | L50: 0 | M50: 1 | N50: 1 | O50: 0 | P50: 0 | Q50: 2 | R50: 0 | S50: 0 | T50: 1 | U50: 0 | V50: 1 | W50: 3 | X50: 0 | Y50: 0 | Z50: 0 | AA50: 0 | AB50: 0 | AC50: 0 | AD50: 0 | AE50: 1 | AF50: 0 | AG50: 1 | AH50: =SUM(E50:AG50) -> 15
C51: 6. Dr. SITI YUMNAH | E51: 0 | F51: 0 | G51: 0 | H51: 1 | I51: 0 | J51: 0 | K51: 0 | L51: 1 | M51: 1 | N51: 1 | O51: 0 | P51: 0 | Q51: 0 | R51: 0 | S51: 0 | T51: 1 | U51: 1 | V51: 0 | W51: 1 | X51: 0 | Y51: 0 | Z51: 0 | AA51: 1 | AB51: 1 | AC51: 2 | AD51: 0 | AE51: 0 | AF51: 0 | AG51: 0 | AH51: =SUM(E51:AG51) -> 11
...

Sheet PENGANJURAN
C2: Kecamatan | D2: BANYUWANGI
C3: Kabupaten | D3: BANYUWANGI
C4: Provinsi | D4: JAWA TIMUR
C9: Kelurahan | D9: PENGANJURAN
A12: I | B12: DATA PEMILIH DAN PENGGUNAAN HAK PILIH | T12: JUMLAH AKHIR
A13: A | B13: DATA PEMILIH | E13: TPS 001 | F13: TPS 002 | G13: TPS 003 | H13: TPS 004 | I13: TPS 005 | J13: TPS 006 | K13: TPS 007 | L13: TPS 008 | M13: TPS 009 | N13: TPS 010 | O13: TPS 011 | P13: TPS 012 | Q13: TPS 013 | R13: TPS 014 | S13: TPS 015
B14: Jumlah Pemilih dalam Daftar Pemilih Tetap (DPT) | D14: LK | E14: 136 | F14: 149 | G14: 144 | H14: 143 | I14: 141 | J14: 130 | K14: 140 | L14: 131 | M14: 129 | N14: 143 | O14: 148 | P14: 122 | Q14: 140 | R14: 140 | S14: 129 | T14: =SUM(E14:S14) -> 2065
D15: PR | E15: 157 | F15: 146 | G15: 131 | H15: 153 | I15: 147 | J15: 159 | K15: 147 | L15: 150 | M15: 159 | N15: 156 | O15: 140 | P15: 145 | Q15: 154 | R15: 140 | S15: 161 | T15: =SUM(E15:S15) -> 2245
D16: JML | E16: =SUM(E14:E15) -> 293 | F16: =SUM(F14:F15) -> 295 | G16: =SUM(G14:G15) -> 275 | H16: =SUM(H14:H15) -> 296 | I16: =SUM(I14:I15) -> 288 | J16: =SUM(J14:J15) -> 289 | K16: =SUM(K14:K15) -> 287 | L16: =SUM(L14:L15) -> 281 | ... S16: =SUM(S14:S15) -> 290 | T16: =SUM(E16:S16) -> 4310
A18: B | B18: PENGGUNA HAK PILIH
B19: 1. | C19: Jumlah pengguna hak pilih dalam Daftar Pemilih Tetap (DPT) | D19: LK | E19: 96 | F19: 105 | G19: 100 | H19: 106 | I19: 95 | J19: 93 | K19: 106 | L19: 83 | M19: 98 | N19: 90 | O19: 110 | P19: 89 | Q19: 105 | R19: 92 | S19: 90 | T19: =SUM(E19:S19) -> 1458
D20: PR | E20: 118 | F20: 114 | G20: 101 | H20: 131 | I20: 109 | J20: 126 | K20: 115 | L20: 114 | M20: 121 | N20: 115 | O20: 112 | P20: 116 | Q20: 126 | R20: 113 | S20: 123 | T20: =SUM(E20:S20) -> 1754
D21: JML | E21: =SUM(E19:E20) -> 214 | F21: =SUM(F19:F20) -> 219 | G21: =SUM(G19:G20) -> 201 | H21: =SUM(H19:H20) -> 237 | I21: =SUM(I19:I20) -> 204 | J21: =SUM(J19:J20) -> 219 | K21: =SUM(K19:K20) -> 221 | L21: =SUM(L19:L20) -> 197 | ... S21: =SUM(S19:S20) -> 213 | T21: =SUM(E21:S21) -> 3212
B22: 2. | C22: Jumlah pengguna hak pilih dalam Daftar Pemilih Tambahan (DPTb) | D22: LK | E22: 0 | F22: 0 | G22: 0 | H22: 0 | I22: 1 | J22: 0 | K22: 0 | L22: 0 | M22: 0 | N22: 1 | O22: 0 | P22: 0 | Q22: 0 | R22: 0 | S22: 1 | T22: =SUM(E22:S22) -> 3
D23: PR | E23: 0 | F23: 0 | G23: 0 | H23: 0 | I23: 1 | J23: 0 | K23: 0 | L23: 0 | M23: 0 | N23: 0 | O23: 0 | P23: 0 | Q23: 0 | R23: 0 | S23: 0 | T23: =SUM(E23:S23) -> 1
D24: JML | E24: =SUM(E22:E23) -> 0 | F24: =SUM(F22:F23) -> 0 | G24: =SUM(G22:G23) -> 0 | H24: =SUM(H22:H23) -> 0 | I24: =SUM(I22:I23) -> 2 | J24: =SUM(J22:J23) -> 0 | K24: =SUM(K22:K23) -> 0 | L24: =SUM(L22:L23) -> 0 | ... S24: =SUM(S22:S23) -> 1 | T24: =SUM(E24:S24) -> 4
B25: 3. | C25: Jumlah pengguna hak pilih dalam Daftar Pemilih Khusus (DPK) | D25: LK | E25: 3 | F25: 0 | G25: 1 | H25: 0 | I25: 1 | J25: 0 | K25: 0 | L25: 1 | M25: 1 | N25: 1 | O25: 4 | P25: 0 | Q25: 1 | R25: 3 | S25: 2 | T25: =SUM(E25:S25) -> 18
D26: PR | E26: 2 | F26: 1 | G26: 1 | H26: 0 | I26: 3 | J26: 2 | K26: 1 | L26: 1 | M26: 1 | N26: 0 | O26: 6 | P26: 4 | Q26: 1 | R26: 2 | S26: 2 | T26: =SUM(E26:S26) -> 27
D27: JML | E27: =SUM(E25:E26) -> 5 | F27: =SUM(F25:F26) -> 1 | G27: =SUM(G25:G26) -> 2 | H27: =SUM(H25:H26) -> 0 | I27: =SUM(I25:I26) -> 4 | J27: =SUM(J25:J26) -> 2 | K27: =SUM(K25:K26) -> 1 | L27: =SUM(L25:L26) -> 2 | ... S27: =SUM(S25:S26) -> 4 | T27: =SUM(E27:S27) -> 45
B28: 4. | C28: Jumlah Pengguna Hak Pilih (B.1+B.2+B.3) | D28: LK | E28: =SUM(E19,E22,E25) -> 99 | F28: =SUM(F19,F22,F25) -> 105 | G28: =SUM(G19,G22,G25) -> 101 | H28: =SUM(H19,H22,H25) -> 106 | I28: =SUM(I19,I22,I25) -> 97 | J28: =SUM(J19,J22,J25) -> 93 | K28: =SUM(K19,K22,K25) -> 106 | L28: =SUM(L19,L22,L25) -> 84 | ... S28: =SUM(S19,S22,S25) -> 93 | T28: =SUM(E28:S28) -> 1479
D29: PR | E29: =SUM(E20,E23,E26) -> 120 | F29: =SUM(F20,F23,F26) -> 115 | G29: =SUM(G20,G23,G26) -> 102 | H29: =SUM(H20,H23,H26) -> 131 | I29: =SUM(I20,I23,I26) -> 113 | J29: =SUM(J20,J23,J26) -> 128 | K29: =SUM(K20,K23,K26) -> 116 | L29: =SUM(L20,L23,L26) -> 115 | ... S29: =SUM(S20,S23,S26) -> 125 | T29: =SUM(E29:S29) -> 1782
D30: JML | E30: =SUM(E28:E29) -> 219 | F30: =SUM(F28:F29) -> 220 | G30: =SUM(G28:G29) -> 203 | H30: =SUM(H28:H29) -> 237 | I30: =SUM(I28:I29) -> 210 | J30: =SUM(J28:J29) -> 221 | K30: =SUM(K28:K29) -> 222 | L30: =SUM(L28:L29) -> 199 | ... S30: =SUM(S28:S29) -> 218 | T30: =SUM(E30:S30) -> 3261
A32: II | B32: DATA PENGGUNAAN SURAT SUARA
A33: 1 | B33: Jumlah surat suara yang diterima, termasuk surat suara cadangan 2,5% dari DPT | E33: 299 | F33: 301 | G33: 281 | H33: 302 | I33: 294 | J33: 290 | K33: 293 | L33: 288 | M33: 294 | N33: 305 | O33: 294 | P33: 270 | Q33: 290 | R33: 286 | S33: 296 | T33: =SUM(E33:S33) -> 4383
A34: 2 | B34: Jumlah surat suara yang digunakan | E34: 219 | F34: 220 | G34: 203 | H34: 237 | I34: 210 | J34: 221 | K34: 222 | L34: 199 | M34: 221 | N34: 207 | O34: 232 | P34: 209 | Q34: 233 | R34: 210 | S34: 218 | T34: =SUM(E34:S34) -> 3261
A35: 3 | B35: Jumlah surat suara dikembalikan oleh pemilih (karena rusak atau keliru coblos) | E35: 1 | F35: 0 | G35: 0 | H35: 0 | I35: 2 | J35: 0 | K35: 0 | L35: 0 | M35: 0 | N35: 0 | O35: 0 | P35: 0 | Q35: 0 | R35: 0 | S35: 0 | T35: =SUM(E35:S35) -> 3
A36: 4 | B36: Jumlah surat suara yang tidak digunakan/tidak terpakai, termasuk sisa surat suara cadangan | E36: =E33-(E34+E35) -> 79 | F36: =F33-(F34+F35) -> 81 | G36: =G33-(G34+G35) -> 78 | H36: =H33-(H34+H35) -> 65 | I36: =I33-(I34+I35) -> 82 | J36: =J33-(J34+J35) -> 69 | K36: =K33-(K34+K35) -> 71 | L36: =L33-(L34+L35) -> 89 | ... S36: =S33-(S34+S35) -> 78 | T36: =SUM(E36:S36) -> 1119
A38: III | B38: DATA PEMILIH DISABILITAS
B39: Jumlah seluruh Pemilih disabilitas yang menggunakan hak pilih | D39: LK | E39: 0 | F39: 0 | G39: 0 | H39: 0 | I39: 0 | J39: 0 | K39: 0 | L39: 0 | M39: 1 | N39: 0 | O39: 0 | P39: 0 | Q39: 0 | R39: 0 | S39: 0 | T39: =SUM(E39:S39) -> 1
D40: PR | E40: 0 | F40: 0 | G40: 0 | H40: 0 | I40: 0 | J40: 0 | K40: 0 | L40: 0 | M40: 0 | N40: 0 | O40: 0 | P40: 0 | Q40: 0 | R40: 0 | S40: 0 | T40: =SUM(E40:S40) -> 0
D41: JML | E41: =SUM(E39:E40) -> 0 | F41: =SUM(F39:F40) -> 0 | G41: =SUM(G39:G40) -> 0 | H41: =SUM(H39:H40) -> 0 | I41: =SUM(I39:I40) -> 0 | J41: =SUM(J39:J40) -> 0 | K41: =SUM(K39:K40) -> 0 | L41: =SUM(L39:L40) -> 0 | ... S41: =SUM(S39:S40) -> 0 | T41: =SUM(E41:S41) -> 1
A43: IV | B43: DATA RINCIAN PEROLEHAN SUARA PASANGAN CALON BUPATI DAN WAKIL BUPATI
A44: NOMOR DAN NAMA CALON
A45: A.1 | B45: 1. | C45: Partai Kebangkitan Bangsa | E45: 9 | F45: 8 | G45: 5 | H45: 6 | I45: 3 | J45: 9 | K45: 5 | L45: 4 | M45: 6 | N45: 4 | O45: 5 | P45: 1 | Q45: 5 | R45: 9 | S45: 2 | T45: =SUM(E45:S45) -> 81
A46: A.2 | C46: 1. Dra. Hj. MA`MULAH HARUN, M.Pd.I. | E46: 10 | F46: 14 | G46: 12 | H46: 9 | I46: 6 | J46: 22 | K46: 7 | L46: 14 | M46: 8 | N46: 3 | O46: 21 | P46: 9 | Q46: 11 | R46: 32 | S46: 10 | T46: =SUM(E46:S46) -> 188
C47: 2. UBAIDILLAH, S.Fil.I. | E47: 2 | F47: 1 | G47: 1 | H47: 0 | I47: 0 | J47: 0 | K47: 0 | L47: 2 | M47: 1 | N47: 0 | O47: 2 | P47: 0 | Q47: 2 | R47: 1 | S47: 1 | T47: =SUM(E47:S47) -> 13
C48: 3. Ir. H. YOYOK MULYADI, M.Si. | E48: 1 | F48: 1 | G48: 0 | H48: 1 | I48: 0 | J48: 0 | K48: 2 | L48: 0 | M48: 0 | N48: 0 | O48: 1 | P48: 0 | Q48: 1 | R48: 1 | S48: 0 | T48: =SUM(E48:S48) -> 8
C49: 4. KHOIRUL ANWAR, S.Fil.I. | E49: 1 | F49: 1 | G49: 0 | H49: 2 | I49: 0 | J49: 0 | K49: 0 | L49: 0 | M49: 3 | N49: 0 | O49: 0 | P49: 0 | Q49: 1 | R49: 0 | S49: 1 | T49: =SUM(E49:S49) -> 9
C50: 5. ARIF WIJAKSANA | E50: 0 | F50: 0 | G50: 1 | H50: 0 | I50: 1 | J50: 1 | K50: 0 | L50: 0 | M50: 0 | N50: 0 | O50: 0 | P50: 0 | Q50: 0 | R50: 1 | S50: 1 | T50: =SUM(E50:S50) -> 5
C51: 6. Dr. SITI YUMNAH | E51: 1 | F51: 0 | G51: 0 | H51: 0 | I51: 1 | J51: 1 | K51: 0 | L51: 0 | M51: 0 | N51: 0 | O51: 0 | P51: 0 | Q51: 0 | R51: 0 | S51: 1 | T51: =SUM(E51:S51) -> 4
...

Sheet TUKANGKAYU
C2: Kecamatan | D2: BANYUWANGI
C3: Kabupaten | D3: BANYUWANGI
C4: Provinsi | D4: JAWA TIMUR
C9: Kelurahan | D9: TUKANGKAYU
A12: I | B12: DATA PEMILIH DAN PENGGUNAAN HAK PILIH | AD12: JUMLAH AKHIR
A13: A | B13: DATA PEMILIH | E13: TPS 001 | F13: TPS 002 | G13: TPS 003 | H13: TPS 004 | I13: TPS 005 | J13: TPS 006 | K13: TPS 007 | L13: TPS 008 | M13: TPS 009 | N13: TPS 010 | O13: TPS 011 | P13: TPS 012 | Q13: TPS 013 | R13: TPS 014 | S13: TPS 015 | T13: TPS 016 | U13: TPS 017 | V13: TPS 018 | W13: TPS 019 | X13: TPS 020 | Y13: TPS 021 | Z13: TPS 022 | AA13: TPS 023 | AB13: TPS 024 | AC13: TPS 025
B14: Jumlah Pemilih dalam Daftar Pemilih Tetap (DPT) | D14: LK | E14: 136 | F14: 143 | G14: 115 | H14: 142 | I14: 126 | J14: 133 | K14: 129 | L14: 113 | M14: 130 | N14: 111 | O14: 120 | P14: 120 | Q14: 132 | R14: 129 | S14: 134 | T14: 136 | U14: 132 | V14: 133 | W14: 124 | X14: 135 | Y14: 127 | Z14: 142 | AA14: 120 | AB14: 148 | AC14: 126 | AD14: =SUM(E14:AC14) -> 3236
D15: PR | E15: 151 | F15: 147 | G15: 121 | H15: 138 | I15: 142 | J15: 138 | K15: 125 | L15: 127 | M15: 137 | N15: 125 | O15: 128 | P15: 147 | Q15: 129 | R15: 140 | S15: 149 | T15: 143 | U15: 148 | V15: 143 | W15: 144 | X15: 145 | Y15: 133 | Z15: 153 | AA15: 126 | AB15: 129 | AC15: 139 | AD15: =SUM(E15:AC15) -> 3447
D16: JML | E16: =SUM(E14:E15) -> 287 | F16: =SUM(F14:F15) -> 290 | G16: =SUM(G14:G15) -> 236 | H16: =SUM(H14:H15) -> 280 | I16: =SUM(I14:I15) -> 268 | J16: =SUM(J14:J15) -> 271 | K16: =SUM(K14:K15) -> 254 | L16: =SUM(L14:L15) -> 240 | ... AC16: =SUM(AC14:AC15) -> 265 | AD16: =SUM(E16:AC16) -> 6683
A18: B | B18: PENGGUNA HAK PILIH
B19: 1. | C19: Jumlah pengguna hak pilih dalam Daftar Pemilih Tetap (DPT) | D19: LK | E19: 108 | F19: 93 | G19: 78 | H19: 105 | I19: 97 | J19: 105 | K19: 107 | L19: 80 | M19: 95 | N19: 71 | O19: 95 | P19: 93 | Q19: 97 | R19: 100 | S19: 93 | T19: 106 | U19: 96 | V19: 98 | W19: 87 | X19: 94 | Y19: 86 | Z19: 100 | AA19: 86 | AB19: 111 | AC19: 94 | AD19: =SUM(E19:AC19) -> 2375
D20: PR | E20: 125 | F20: 118 | G20: 96 | H20: 113 | I20: 112 | J20: 116 | K20: 112 | L20: 102 | M20: 109 | N20: 94 | O20: 102 | P20: 109 | Q20: 107 | R20: 115 | S20: 107 | T20: 123 | U20: 121 | V20: 115 | W20: 108 | X20: 112 | Y20: 102 | Z20: 123 | AA20: 97 | AB20: 109 | AC20: 108 | AD20: =SUM(E20:AC20) -> 2755
D21: JML | E21: =SUM(E19:E20) -> 233 | F21: =SUM(F19:F20) -> 211 | G21: =SUM(G19:G20) -> 174 | H21: =SUM(H19:H20) -> 218 | I21: =SUM(I19:I20) -> 209 | J21: =SUM(J19:J20) -> 221 | K21: =SUM(K19:K20) -> 219 | L21: =SUM(L19:L20) -> 182 | ... AC21: =SUM(AC19:AC20) -> 202 | AD21: =SUM(E21:AC21) -> 5130
B22: 2. | C22: Jumlah pengguna hak pilih dalam Daftar Pemilih Tambahan (DPTb) | D22: LK | E22: 0 | F22: 0 | G22: 1 | H22: 0 | I22: 1 | J22: 0 | K22: 0 | L22: 0 | M22: 0 | N22: 1 | O22: 0 | P22: 0 | Q22: 0 | R22: 0 | S22: 0 | T22: 0 | U22: 0 | V22: 0 | W22: 0 | X22: 0 | Y22: 0 | Z22: 0 | AA22: 0 | AB22: 0 | AC22: 0 | AD22: =SUM(E22:AC22) -> 3
D23: PR | E23: 0 | F23: 0 | G23: 0 | H23: 0 | I23: 1 | J23: 0 | K23: 0 | L23: 0 | M23: 0 | N23: 0 | O23: 0 | P23: 0 | Q23: 0 | R23: 0 | S23: 0 | T23: 0 | U23: 0 | V23: 0 | W23: 0 | X23: 0 | Y23: 0 | Z23: 0 | AA23: 1 | AB23: 0 | AC23: 0 | AD23: =SUM(E23:AC23) -> 2
D24: JML | E24: =SUM(E22:E23) -> 0 | F24: =SUM(F22:F23) -> 0 | G24: =SUM(G22:G23) -> 1 | H24: =SUM(H22:H23) -> 0 | I24: =SUM(I22:I23) -> 2 | J24: =SUM(J22:J23) -> 0 | K24: =SUM(K22:K23) -> 0 | L24: =SUM(L22:L23) -> 0 | ... AC24: =SUM(AC22:AC23) -> 0 | AD24: =SUM(E24:AC24) -> 5
B25: 3. | C25: Jumlah pengguna hak pilih dalam Daftar Pemilih Khusus (DPK) | D25: LK | E25: 1 | F25: 2 | G25: 6 | H25: 1 | I25: 3 | J25: 0 | K25: 2 | L25: 0 | M25: 2 | N25: 0 | O25: 2 | P25: 6 | Q25: 1 | R25: 0 | S25: 0 | T25: 2 | U25: 3 | V25: 1 | W25: 4 | X25: 1 | Y25: 1 | Z25: 8 | AA25: 2 | AB25: 3 | AC25: 2 | AD25: =SUM(E25:AC25) -> 53
D26: PR | E26: 5 | F26: 3 | G26: 4 | H26: 0 | I26: 1 | J26: 1 | K26: 2 | L26: 2 | M26: 1 | N26: 0 | O26: 3 | P26: 4 | Q26: 2 | R26: 1 | S26: 2 | T26: 2 | U26: 7 | V26: 1 | W26: 6 | X26: 3 | Y26: 1 | Z26: 10 | AA26: 3 | AB26: 1 | AC26: 1 | AD26: =SUM(E26:AC26) -> 66
D27: JML | E27: =SUM(E25:E26) -> 6 | F27: =SUM(F25:F26) -> 5 | G27: =SUM(G25:G26) -> 10 | H27: =SUM(H25:H26) -> 1 | I27: =SUM(I25:I26) -> 4 | J27: =SUM(J25:J26) -> 1 | K27: =SUM(K25:K26) -> 4 | L27: =SUM(L25:L26) -> 2 | ... AC27: =SUM(AC25:AC26) -> 3 | AD27: =SUM(E27:AC27) -> 119
B28: 4. | C28: Jumlah Pengguna Hak Pilih (B.1+B.2+B.3) | D28: LK | E28: =SUM(E19,E22,E25) -> 109 | F28: =SUM(F19,F22,F25) -> 95 | G28: =SUM(G19,G22,G25) -> 85 | H28: =SUM(H19,H22,H25) -> 106 | I28: =SUM(I19,I22,I25) -> 101 | J28: =SUM(J19,J22,J25) -> 105 | K28: =SUM(K19,K22,K25) -> 109 | L28: =SUM(L19,L22,L25) -> 80 | ... AC28: =SUM(AC19,AC22,AC25) -> 96 | AD28: =SUM(E28:AC28) -> 2431
D29: PR | E29: =SUM(E20,E23,E26) -> 130 | F29: =SUM(F20,F23,F26) -> 121 | G29: =SUM(G20,G23,G26) -> 100 | H29: =SUM(H20,H23,H26) -> 113 | I29: =SUM(I20,I23,I26) -> 114 | J29: =SUM(J20,J23,J26) -> 117 | K29: =SUM(K20,K23,K26) -> 114 | L29: =SUM(L20,L23,L26) -> 104 | ... AC29: =SUM(AC20,AC23,AC26) -> 109 | AD29: =SUM(E29:AC29) -> 2823
D30: JML | E30: =SUM(E28:E29) -> 239 | F30: =SUM(F28:F29) -> 216 | G30: =SUM(G28:G29) -> 185 | H30: =SUM(H28:H29) -> 219 | I30: =SUM(I28:I29) -> 215 | J30: =SUM(J28:J29) -> 222 | K30: =SUM(K28:K29) -> 223 | L30: =SUM(L28:L29) -> 184 | ... AC30: =SUM(AC28:AC29) -> 205 | AD30: =SUM(E30:AC30) -> 5254
A32: II | B32: DATA PENGGUNAAN SURAT SUARA
A33: 1 | B33: Jumlah surat suara yang diterima, termasuk surat suara cadangan 2,5% dari DPT | E33: 293 | F33: 296 | G33: 241 | H33: 286 | I33: 274 | J33: 277 | K33: 240 | L33: 245 | M33: 273 | N33: 241 | O33: 253 | P33: 273 | Q33: 267 | R33: 254 | S33: 279 | T33: 285 | U33: 296 | V33: 282 | W33: 264 | X33: 286 | Y33: 266 | Z33: 301 | AA33: 251 | AB33: 283 | AC33: 271 | AD33: =SUM(E33:AC33) -> 6777
A34: 2 | B34: Jumlah surat suara yang digunakan | E34: 239 | F34: 216 | G34: 185 | H34: 219 | I34: 215 | J34: 222 | K34: 223 | L34: 184 | M34: 207 | N34: 166 | O34: 202 | P34: 212 | Q34: 207 | R34: 216 | S34: 202 | T34: 233 | U34: 227 | V34: 215 | W34: 205 | X34: 210 | Y34: 190 | Z34: 241 | AA34: 189 | AB34: 224 | AC34: 205 | AD34: =SUM(E34:AC34) -> 5254
A35: 3 | B35: Jumlah surat suara dikembalikan oleh pemilih (karena rusak atau keliru coblos) | E35: 0 | F35: 0 | G35: 0 | H35: 0 | I35: 1 | J35: 1 | K35: 0 | L35: 0 | M35: 2 | N35: 0 | O35: 0 | P35: 0 | Q35: 0 | R35: 1 | S35: 0 | T35: 0 | U35: 1 | V35: 1 | W35: 0 | X35: 1 | Y35: 0 | Z35: 0 | AA35: 0 | AB35: 6 | AC35: 1 | AD35: =SUM(E35:AC35) -> 15
A36: 4 | B36: Jumlah surat suara yang tidak digunakan/tidak terpakai, termasuk sisa surat suara cadangan | E36: =E33-(E34+E35) -> 54 | F36: =F33-(F34+F35) -> 80 | G36: =G33-(G34+G35) -> 56 | H36: =H33-(H34+H35) -> 67 | I36: =I33-(I34+I35) -> 58 | J36: =J33-(J34+J35) -> 54 | K36: =K33-(K34+K35) -> 17 | L36: =L33-(L34+L35) -> 61 | ... AC36: =AC33-(AC34+AC35) -> 65 | AD36: =SUM(E36:AC36) -> 1508
A38: III | B38: DATA PEMILIH DISABILITAS
B39: Jumlah seluruh Pemilih disabilitas yang menggunakan hak pilih | D39: LK | E39: 0 | F39: 0 | G39: 1 | H39: 1 | I39: 0 | J39: 1 | K39: 0 | L39: 0 | M39: 3 | N39: 0 | O39: 0 | P39: 1 | Q39: 5 | R39: 0 | S39: 0 | T39: 0 | U39: 0 | V39: 1 | W39: 1 | X39: 0 | Y39: 0 | Z39: 0 | AA39: 0 | AB39: 0 | AC39: 0 | AD39: =SUM(E39:AC39) -> 14
D40: PR | E40: 0 | F40: 0 | G40: 0 | H40: 0 | I40: 0 | J40: 0 | K40: 0 | L40: 0 | M40: 4 | N40: 0 | O40: 0 | P40: 1 | Q40: 2 | R40: 1 | S40: 0 | T40: 0 | U40: 0 | V40: 0 | W40: 4 | X40: 0 | Y40: 0 | Z40: 0 | AA40: 0 | AB40: 0 | AC40: 0 | AD40: =SUM(E40:AC40) -> 12
D41: JML | E41: =SUM(E39:E40) -> 0 | F41: =SUM(F39:F40) -> 0 | G41: =SUM(G39:G40) -> 1 | H41: =SUM(H39:H40) -> 1 | I41: =SUM(I39:I40) -> 0 | J41: =SUM(J39:J40) -> 1 | K41: =SUM(K39:K40) -> 0 | L41: =SUM(L39:L40) -> 0 | ... AC41: =SUM(AC39:AC40) -> 0 | AD41: =SUM(E41:AC41) -> 26
A43: IV | B43: DATA RINCIAN PEROLEHAN SUARA PASANGAN CALON BUPATI DAN WAKIL BUPATI
A44: NOMOR DAN NAMA CALON
A45: A.1 | B45: 1. | C45: Partai Kebangkitan Bangsa | E45: 8 | F45: 5 | G45: 10 | H45: 8 | I45: 7 | J45: 7 | K45: 7 | L45: 12 | M45: 11 | N45: 10 | O45: 3 | P45: 6 | Q45: 8 | R45: 3 | S45: 3 | T45: 5 | U45: 5 | V45: 5 | W45: 7 | X45: 5 | Y45: 5 | Z45: 7 | AA45: 5 | AB45: 6 | AC45: 4 | AD45: =SUM(E45:AC45) -> 162
A46: A.2 | C46: 1. Dra. Hj. MA`MULAH HARUN, M.Pd.I. | E46: 25 | F46: 18 | G46: 55 | H46: 41 | I46: 17 | J46: 55 | K46: 42 | L46: 46 | M46: 52 | N46: 50 | O46: 8 | P46: 18 | Q46: 15 | R46: 6 | S46: 13 | T46: 13 | U46: 37 | V46: 24 | W46: 13 | X46: 8 | Y46: 8 | Z46: 14 | AA46: 4 | AB46: 8 | AC46: 16 | AD46: =SUM(E46:AC46) -> 606
C47: 2. UBAIDILLAH, S.Fil.I. | E47: 1 | F47: 1 | G47: 0 | H47: 0 | I47: 0 | J47: 1 | K47: 0 | L47: 1 | M47: 1 | N47: 0 | O47: 0 | P47: 1 | Q47: 1 | R47: 0 | S47: 3 | T47: 2 | U47: 2 | V47: 2 | W47: 1 | X47: 0 | Y47: 4 | Z47: 1 | AA47: 0 | AB47: 0 | AC47: 3 | AD47: =SUM(E47:AC47) -> 25
C48: 3. Ir. H. YOYOK MULYADI, M.Si. | E48: 0 | F48: 0 | G48: 1 | H48: 1 | I48: 0 | J48: 0 | K48: 0 | L48: 0 | M48: 0 | N48: 0 | O48: 0 | P48: 1 | Q48: 0 | R48: 1 | S48: 1 | T48: 0 | U48: 0 | V48: 0 | W48: 2 | X48: 0 | Y48: 0 | Z48: 2 | AA48: 1 | AB48: 0 | AC48: 1 | AD48: =SUM(E48:AC48) -> 11
C49: 4. KHOIRUL ANWAR, S.Fil.I. | E49: 3 | F49: 1 | G49: 0 | H49: 1 | I49: 2 | J49: 1 | K49: 0 | L49: 0 | M49: 0 | N49: 0 | O49: 0 | P49: 3 | Q49: 1 | R49: 0 | S49: 0 | T49: 2 | U49: 0 | V49: 1 | W49: 1 | X49: 0 | Y49: 1 | Z49: 1 | AA49: 0 | AB49: 0 | AC49: 1 | AD49: =SUM(E49:AC49) -> 19
C50: 5. ARIF WIJAKSANA | E50: 1 | F50: 0 | G50: 0 | H50: 0 | I50: 1 | J50: 0 | K50: 0 | L50: 0 | M50: 1 | N50: 1 | O50: 0 | P50: 0 | Q50: 1 | R50: 0 | S50: 0 | T50: 0 | U50: 0 | V50: 0 | W50: 1 | X50: 1 | Y50: 0 | Z50: 0 | AA50: 3 | AB50: 0 | AC50: 1 | AD50: =SUM(E50:AC50) -> 11
C51: 6. Dr. SITI YUMNAH | E51: 0 | F51: 1 | G51: 0 | H51: 0 | I51: 1 | J51: 0 | K51: 0 | L51: 0 | M51: 2 | N51: 0 | O51: 0 | P51: 1 | Q51: 0 | R51: 1 | S51: 0 | T51: 0 | U51: 0 | V51: 2 | W51: 0 | X51: 0 | Y51: 0 | Z51: 0 | AA51: 1 | AB51: 0 | AC51: 1 | AD51: =SUM(E51:AC51) -> 10
...

Sheet KERTOSARI
C2: Kecamatan | D2: BANYUWANGI
C3: Kabupaten | D3: BANYUWANGI
C4: Provinsi | D4: JAWA TIMUR
C9: Kelurahan | D9: KERTOSARI
A12: I | B12: DATA PEMILIH DAN PENGGUNAAN HAK PILIH | AB12: JUMLAH AKHIR
A13: A | B13: DATA PEMILIH | E13: TPS 001 | F13: TPS 002 | G13: TPS 003 | H13: TPS 004 | I13: TPS 005 | J13: TPS 006 | K13: TPS 007 | L13: TPS 008 | M13: TPS 009 | N13: TPS 010 | O13: TPS 011 | P13: TPS 012 | Q13: TPS 013 | R13: TPS 014 | S13: TPS 015 | T13: TPS 016 | U13: TPS 017 | V13: TPS 018 | W13: TPS 019 | X13: TPS 020 | Y13: TPS 021 | Z13: TPS 022 | AA13: TPS 023
B14: Jumlah Pemilih dalam Daftar Pemilih Tetap (DPT) | D14: LK | E14: 135 | F14: 141 | G14: 138 | H14: 132 | I14: 126 | J14: 129 | K14: 113 | L14: 147 | M14: 142 | N14: 130 | O14: 120 | P14: 129 | Q14: 140 | R14: 142 | S14: 142 | T14: 142 | U14: 144 | V14: 125 | W14: 141 | X14: 135 | Y14: 138 | Z14: 130 | AA14: 101 | AB14: =SUM(E14:AA14) -> 3062
D15: PR | E15: 146 | F15: 143 | G15: 145 | H15: 150 | I15: 142 | J15: 132 | K15: 117 | L15: 131 | M15: 136 | N15: 137 | O15: 134 | P15: 138 | Q15: 140 | R15: 148 | S15: 146 | T15: 144 | U15: 134 | V15: 115 | W15: 142 | X15: 124 | Y15: 136 | Z15: 140 | AA15: 106 | AB15: =SUM(E15:AA15) -> 3126
D16: JML | E16: =SUM(E14:E15) -> 281 | F16: =SUM(F14:F15) -> 284 | G16: =SUM(G14:G15) -> 283 | H16: =SUM(H14:H15) -> 282 | I16: =SUM(I14:I15) -> 268 | J16: =SUM(J14:J15) -> 261 | K16: =SUM(K14:K15) -> 230 | L16: =SUM(L14:L15) -> 278 | ... AA16: =SUM(AA14:AA15) -> 207 | AB16: =SUM(E16:AA16) -> 6188
A18: B | B18: PENGGUNA HAK PILIH
B19: 1. | C19: Jumlah pengguna hak pilih dalam Daftar Pemilih Tetap (DPT) | D19: LK | E19: 95 | F19: 118 | G19: 103 | H19: 100 | I19: 97 | J19: 96 | K19: 90 | L19: 86 | M19: 85 | N19: 98 | O19: 80 | P19: 79 | Q19: 96 | R19: 105 | S19: 97 | T19: 97 | U19: 99 | V19: 105 | W19: 97 | X19: 91 | Y19: 95 | Z19: 94 | AA19: 67 | AB19: =SUM(E19:AA19) -> 2170
D20: PR | E20: 117 | F20: 122 | G20: 106 | H20: 122 | I20: 114 | J20: 113 | K20: 93 | L20: 124 | M20: 96 | N20: 102 | O20: 98 | P20: 108 | Q20: 114 | R20: 122 | S20: 116 | T20: 108 | U20: 98 | V20: 96 | W20: 117 | X20: 96 | Y20: 106 | Z20: 103 | AA20: 80 | AB20: =SUM(E20:AA20) -> 2471
D21: JML | E21: =SUM(E19:E20) -> 212 | F21: =SUM(F19:F20) -> 240 | G21: =SUM(G19:G20) -> 209 | H21: =SUM(H19:H20) -> 222 | I21: =SUM(I19:I20) -> 211 | J21: =SUM(J19:J20) -> 209 | K21: =SUM(K19:K20) -> 183 | L21: =SUM(L19:L20) -> 210 | ... AA21: =SUM(AA19:AA20) -> 147 | AB21: =SUM(E21:AA21) -> 4641
B22: 2. | C22: Jumlah pengguna hak pilih dalam Daftar Pemilih Tambahan (DPTb) | D22: LK | E22: 0 | F22: 0 | G22: 0 | H22: 0 | I22: 0 | J22: 0 | K22: 0 | L22: 0 | M22: 2 | N22: 0 | O22: 0 | P22: 1 | Q22: 0 | R22: 0 | S22: 0 | T22: 0 | U22: 0 | V22: 0 | W22: 0 | X22: 0 | Y22: 0 | Z22: 0 | AA22: 0 | AB22: =SUM(E22:AA22) -> 3
D23: PR | E23: 0 | F23: 0 | G23: 0 | H23: 0 | I23: 2 | J23: 0 | K23: 0 | L23: 0 | M23: 6 | N23: 0 | O23: 0 | P23: 1 | Q23: 0 | R23: 0 | S23: 0 | T23: 0 | U23: 0 | V23: 0 | W23: 0 | X23: 0 | Y23: 0 | Z23: 0 | AA23: 0 | AB23: =SUM(E23:AA23) -> 9
D24: JML | E24: =SUM(E22:E23) -> 0 | F24: =SUM(F22:F23) -> 0 | G24: =SUM(G22:G23) -> 0 | H24: =SUM(H22:H23) -> 0 | I24: =SUM(I22:I23) -> 2 | J24: =SUM(J22:J23) -> 0 | K24: =SUM(K22:K23) -> 0 | L24: =SUM(L22:L23) -> 0 | ... AA24: =SUM(AA22:AA23) -> 0 | AB24: =SUM(E24:AA24) -> 12
B25: 3. | C25: Jumlah pengguna hak pilih dalam Daftar Pemilih Khusus (DPK) | D25: LK | E25: 1 | F25: 0 | G25: 0 | H25: 1 | I25: 1 | J25: 1 | K25: 0 | L25: 2 | M25: 0 | N25: 2 | O25: 6 | P25: 0 | Q25: 0 | R25: 7 | S25: 1 | T25: 1 | U25: 3 | V25: 3 | W25: 0 | X25: 3 | Y25: 0 | Z25: 4 | AA25: 0 | AB25: =SUM(E25:AA25) -> 36
D26: PR | E26: 0 | F26: 1 | G26: 1 | H26: 1 | I26: 0 | J26: 2 | K26: 0 | L26: 2 | M26: 0 | N26: 2 | O26: 3 | P26: 0 | Q26: 0 | R26: 6 | S26: 3 | T26: 1 | U26: 4 | V26: 6 | W26: 0 | X26: 2 | Y26: 0 | Z26: 5 | AA26: 1 | AB26: =SUM(E26:AA26) -> 40
D27: JML | E27: =SUM(E25:E26) -> 1 | F27: =SUM(F25:F26) -> 1 | G27: =SUM(G25:G26) -> 1 | H27: =SUM(H25:H26) -> 2 | I27: =SUM(I25:I26) -> 1 | J27: =SUM(J25:J26) -> 3 | K27: =SUM(K25:K26) -> 0 | L27: =SUM(L25:L26) -> 4 | ... AA27: =SUM(AA25:AA26) -> 1 | AB27: =SUM(E27:AA27) -> 76
B28: 4. | C28: Jumlah Pengguna Hak Pilih (B.1+B.2+B.3) | D28: LK | E28: =SUM(E19,E22,E25) -> 96 | F28: =SUM(F19,F22,F25) -> 118 | G28: =SUM(G19,G22,G25) -> 103 | H28: =SUM(H19,H22,H25) -> 101 | I28: =SUM(I19,I22,I25) -> 98 | J28: =SUM(J19,J22,J25) -> 97 | K28: =SUM(K19,K22,K25) -> 90 | L28: =SUM(L19,L22,L25) -> 88 | ... AA28: =SUM(AA19,AA22,AA25) -> 67 | AB28: =SUM(E28:AA28) -> 2209
D29: PR | E29: =SUM(E20,E23,E26) -> 117 | F29: =SUM(F20,F23,F26) -> 123 | G29: =SUM(G20,G23,G26) -> 107 | H29: =SUM(H20,H23,H26) -> 123 | I29: =SUM(I20,I23,I26) -> 116 | J29: =SUM(J20,J23,J26) -> 115 | K29: =SUM(K20,K23,K26) -> 93 | L29: =SUM(L20,L23,L26) -> 126 | ... AA29: =SUM(AA20,AA23,AA26) -> 81 | AB29: =SUM(E29:AA29) -> 2520
D30: JML | E30: =SUM(E28:E29) -> 213 | F30: =SUM(F28:F29) -> 241 | G30: =SUM(G28:G29) -> 210 | H30: =SUM(H28:H29) -> 224 | I30: =SUM(I28:I29) -> 214 | J30: =SUM(J28:J29) -> 212 | K30: =SUM(K28:K29) -> 183 | L30: =SUM(L28:L29) -> 214 | ... AA30: =SUM(AA28:AA29) -> 148 | AB30: =SUM(E30:AA30) -> 4729
A32: II | B32: DATA PENGGUNAAN SURAT SUARA
A33: 1 | B33: Jumlah surat suara yang diterima, termasuk surat suara cadangan 2,5% dari DPT | E33: 287 | F33: 290 | G33: 289 | H33: 299 | I33: 274 | J33: 267 | K33: 235 | L33: 284 | M33: 284 | N33: 273 | O33: 260 | P33: 273 | Q33: 286 | R33: 296 | S33: 294 | T33: 293 | U33: 284 | V33: 245 | W33: 289 | X33: 265 | Y33: 280 | Z33: 276 | AA33: 212 | AB33: =SUM(E33:AA33) -> 6335
A34: 2 | B34: Jumlah surat suara yang digunakan | E34: 213 | F34: 241 | G34: 210 | H34: 224 | I34: 214 | J34: 212 | K34: 183 | L34: 214 | M34: 189 | N34: 204 | O34: 187 | P34: 189 | Q34: 210 | R34: 240 | S34: 217 | T34: 207 | U34: 204 | V34: 210 | W34: 214 | X34: 192 | Y34: 201 | Z34: 206 | AA34: 148 | AB34: =SUM(E34:AA34) -> 4729
A35: 3 | B35: Jumlah surat suara dikembalikan oleh pemilih (karena rusak atau keliru coblos) | E35: 1 | F35: 2 | G35: 0 | H35: 0 | I35: 0 | J35: 0 | K35: 0 | L35: 0 | M35: 1 | N35: 0 | O35: 0 | P35: 0 | Q35: 0 | R35: 0 | S35: 0 | T35: 0 | U35: 0 | V35: 0 | W35: 0 | X35: 0 | Y35: 1 | Z35: 0 | AA35: 0 | AB35: =SUM(E35:AA35) -> 5
A36: 4 | B36: Jumlah surat suara yang tidak digunakan/tidak terpakai, termasuk sisa surat suara cadangan | E36: =E33-(E34+E35) -> 73 | F36: =F33-(F34+F35) -> 47 | G36: =G33-(G34+G35) -> 79 | H36: =H33-(H34+H35) -> 75 | I36: =I33-(I34+I35) -> 60 | J36: =J33-(J34+J35) -> 55 | K36: =K33-(K34+K35) -> 52 | L36: =L33-(L34+L35) -> 70 | ... AA36: =AA33-(AA34+AA35) -> 64 | AB36: =SUM(E36:AA36) -> 1601
A38: III | B38: DATA PEMILIH DISABILITAS
B39: Jumlah seluruh Pemilih disabilitas yang menggunakan hak pilih | D39: LK | E39: 0 | F39: 0 | G39: 0 | H39: 0 | I39: 0 | J39: 0 | K39: 0 | L39: 0 | M39: 0 | N39: 0 | O39: 0 | P39: 0 | Q39: 1 | R39: 0 | S39: 0 | T39: 0 | U39: 0 | V39: 2 | W39: 0 | X39: 0 | Y39: 0 | Z39: 0 | AA39: 0 | AB39: =SUM(E39:AA39) -> 3
