Workbook

Sheet DPRD PROVINSI
C8: Kecamatan | D8: SRONO
C9: Kabupaten | D9: BANYUWANGI
C10: Provinsi | D10: JAWA TIMUR
A12: I | B12: DATA PEMILIH DAN PENGGUNAAN HAK PILIH | E12: JUMLAH AKHIR
A13: A | B13: DATA PEMILIH
B14: Jumlah Pemilih dalam Daftar Pemilih Tetap (DPT) | D14: LK | E14: =BAGOREJO!AM14+KEBAMAN!AW14+KEPUNDUNGAN!W14+'PARIJATAH KULON'!Y14+'PARIJATAH WETAN'!AC14+REJOAGUNG!AF14+SUKOMAJU!AC14+SUKONATAR!T14+SUMBERSARI!AH14+WONOSOBO!AS14 -> 37696
D15: PR | E15: =BAGOREJO!AM15+KEBAMAN!AW15+KEPUNDUNGAN!W15+'PARIJATAH KULON'!Y15+'PARIJATAH WETAN'!AC15+REJOAGUNG!AF15+SUKOMAJU!AC15+SUKONATAR!T15+SUMBERSARI!AH15+WONOSOBO!AS15 -> 37805
D16: JML | E16: =SUM(E14:E15) -> 75501
A18: B | B18: PENGGUNA HAK PILIH
B19: 1. | C19: Jumlah pengguna hak pilih dalam Daftar Pemilih Tetap (DPT) | D19: LK | E19: =BAGOREJO!AM19+KEBAMAN!AW19+KEPUNDUNGAN!W19+'PARIJATAH KULON'!Y19+'PARIJATAH WETAN'!AC19+REJOAGUNG!AF19+SUKOMAJU!AC19+SUKONATAR!T19+SUMBERSARI!AH19+WONOSOBO!AS19 -> 27900
D20: PR | E20: =BAGOREJO!AM20+KEBAMAN!AW20+KEPUNDUNGAN!W20+'PARIJATAH KULON'!Y20+'PARIJATAH WETAN'!AC20+REJOAGUNG!AF20+SUKOMAJU!AC20+SUKONATAR!T20+SUMBERSARI!AH20+WONOSOBO!AS20 -> 30140
D21: JML | E21: =SUM(E19:E20) -> 58040
B22: 2. | C22: Jumlah pengguna hak pilih dalam Daftar Pemilih Tambahan (DPTb) | D22: LK | E22: =BAGOREJO!AM22+KEBAMAN!AW22+KEPUNDUNGAN!W22+'PARIJATAH KULON'!Y22+'PARIJATAH WETAN'!AC22+REJOAGUNG!AF22+SUKOMAJU!AC22+SUKONATAR!T22+SUMBERSARI!AH22+WONOSOBO!AS22 -> 22
D23: PR | E23: =BAGOREJO!AM23+KEBAMAN!AW23+KEPUNDUNGAN!W23+'PARIJATAH KULON'!Y23+'PARIJATAH WETAN'!AC23+REJOAGUNG!AF23+SUKOMAJU!AC23+SUKONATAR!T23+SUMBERSARI!AH23+WONOSOBO!AS23 -> 23
D24: JML | E24: =SUM(E22:E23) -> 45
B25: 3. | C25: Jumlah pengguna hak pilih dalam Daftar Pemilih Khusus (DPK) | D25: LK | E25: =BAGOREJO!AM25+KEBAMAN!AW25+KEPUNDUNGAN!W25+'PARIJATAH KULON'!Y25+'PARIJATAH WETAN'!AC25+REJOAGUNG!AF25+SUKOMAJU!AC25+SUKONATAR!T25+SUMBERSARI!AH25+WONOSOBO!AS25 -> 407
D26: PR | E26: =BAGOREJO!AM26+KEBAMAN!AW26+KEPUNDUNGAN!W26+'PARIJATAH KULON'!Y26+'PARIJATAH WETAN'!AC26+REJOAGUNG!AF26+SUKOMAJU!AC26+SUKONATAR!T26+SUMBERSARI!AH26+WONOSOBO!AS26 -> 513
D27: JML | E27: =SUM(E25:E26) -> 920
B28: 4. | C28: Jumlah Pengguna Hak Pilih (B.1+B.2+B.3) | D28: LK | E28: =E19+E22+E25 -> 28329
D29: PR | E29: =E20+E23+E26 -> 30676
D30: JML | E30: =SUM(E28:E29) -> 59005
A32: II | B32: DATA PENGGUNAAN SURAT SUARA
A33: 1 | B33: Jumlah surat suara yang diterima, termasuk surat suara cadangan 2,5% dari DPT | E33: =BAGOREJO!AM33+KEBAMAN!AW33+KEPUNDUNGAN!W33+'PARIJATAH KULON'!Y33+'PARIJATAH WETAN'!AC33+REJOAGUNG!AF33+SUKOMAJU!AC33+SUKONATAR!T33+SUMBERSARI!AH33+WONOSOBO!AS33 -> 76907
A34: 2 | B34: Jumlah surat suara yang digunakan | E34: =BAGOREJO!AM34+KEBAMAN!AW34+KEPUNDUNGAN!W34+'PARIJATAH KULON'!Y34+'PARIJATAH WETAN'!AC34+REJOAGUNG!AF34+SUKOMAJU!AC34+SUKONATAR!T34+SUMBERSARI!AH34+WONOSOBO!AS34 -> 59005
A35: 3 | B35: Jumlah surat suara dikembalikan oleh pemilih (karena rusak atau keliru coblos) | E35: =BAGOREJO!AM35+KEBAMAN!AW35+KEPUNDUNGAN!W35+'PARIJATAH KULON'!Y35+'PARIJATAH WETAN'!AC35+REJOAGUNG!AF35+SUKOMAJU!AC35+SUKONATAR!T35+SUMBERSARI!AH35+WONOSOBO!AS35 -> 84
A36: 4 | B36: Jumlah surat suara yang tidak digunakan/tidak terpakai, termasuk sisa surat suara cadangan | E36: =E33-(E34+E35) -> 17818
A38: III | B38: DATA PEMILIH DISABILITAS
B39: Jumlah seluruh Pemilih disabilitas yang menggunakan hak pilih | D39: LK | E39: =BAGOREJO!AM39+KEBAMAN!AW39+KEPUNDUNGAN!W39+'PARIJATAH KULON'!Y39+'PARIJATAH WETAN'!AC39+REJOAGUNG!AF39+SUKOMAJU!AC39+SUKONATAR!T39+SUMBERSARI!AH39+WONOSOBO!AS39 -> 34
D40: PR | E40: =BAGOREJO!AM40+KEBAMAN!AW40+KEPUNDUNGAN!W40+'PARIJATAH KULON'!Y40+'PARIJATAH WETAN'!AC40+REJOAGUNG!AF40+SUKOMAJU!AC40+SUKONATAR!T40+SUMBERSARI!AH40+WONOSOBO!AS40 -> 31
D41: JML | E41: =SUM(E39:E40) -> 65
A43: IV | B43: DATA RINCIAN PEROLEHAN SUARA PASANGAN CALON BUPATI DAN WAKIL BUPATI
A44: NOMOR DAN NAMA CALON
A45: A.1 | B45: 1. | C45: Partai Kebangkitan Bangsa | E45: =BAGOREJO!AM45+KEBAMAN!AW45+KEPUNDUNGAN!W45+'PARIJATAH KULON'!Y45+'PARIJATAH WETAN'!AC45+REJOAGUNG!AF45+SUKOMAJU!AC45+SUKONATAR!T45+SUMBERSARI!AH45+WONOSOBO!AS45 -> 2050
A46: A.2 | C46: 1. Dra. Hj. MA`MULAH HARUN, M.Pd.I. | E46: =BAGOREJO!AM46+KEBAMAN!AW46+KEPUNDUNGAN!W46+'PARIJATAH KULON'!Y46+'PARIJATAH WETAN'!AC46+REJOAGUNG!AF46+SUKOMAJU!AC46+SUKONATAR!T46+SUMBERSARI!AH46+WONOSOBO!AS46 -> 3273
C47: 2. UBAIDILLAH, S.Fil.I. | E47: =BAGOREJO!AM47+KEBAMAN!AW47+KEPUNDUNGAN!W47+'PARIJATAH KULON'!Y47+'PARIJATAH WETAN'!AC47+REJOAGUNG!AF47+SUKOMAJU!AC47+SUKONATAR!T47+SUMBERSARI!AH47+WONOSOBO!AS47 -> 624
C48: 3. Ir. H. YOYOK MULYADI, M.Si. | E48: =BAGOREJO!AM48+KEBAMAN!AW48+KEPUNDUNGAN!W48+'PARIJATAH KULON'!Y48+'PARIJATAH WETAN'!AC48+REJOAGUNG!AF48+SUKOMAJU!AC48+SUKONATAR!T48+SUMBERSARI!AH48+WONOSOBO!AS48 -> 195
C49: 4. KHOIRUL ANWAR, S.Fil.I. | E49: =BAGOREJO!AM49+KEBAMAN!AW49+KEPUNDUNGAN!W49+'PARIJATAH KULON'!Y49+'PARIJATAH WETAN'!AC49+REJOAGUNG!AF49+SUKOMAJU!AC49+SUKONATAR!T49+SUMBERSARI!AH49+WONOSOBO!AS49 -> 358
C50: 5. ARIF WIJAKSANA | E50: =BAGOREJO!AM50+KEBAMAN!AW50+KEPUNDUNGAN!W50+'PARIJATAH KULON'!Y50+'PARIJATAH WETAN'!AC50+REJOAGUNG!AF50+SUKOMAJU!AC50+SUKONATAR!T50+SUMBERSARI!AH50+WONOSOBO!AS50 -> 333
C51: 6. Dr. SITI YUMNAH | E51: =BAGOREJO!AM51+KEBAMAN!AW51+KEPUNDUNGAN!W51+'PARIJATAH KULON'!Y51+'PARIJATAH WETAN'!AC51+REJOAGUNG!AF51+SUKOMAJU!AC51+SUKONATAR!T51+SUMBERSARI!AH51+WONOSOBO!AS51 -> 113
C52: 7. MOHAMMAD ZAINI, M.Pd.I. | E52: =BAGOREJO!AM52+KEBAMAN!AW52+KEPUNDUNGAN!W52+'PARIJATAH KULON'!Y52+'PARIJATAH WETAN'!AC52+REJOAGUNG!AF52+SUKOMAJU!AC52+SUKONATAR!T52+SUMBERSARI!AH52+WONOSOBO!AS52 -> 92
...

Sheet BAGOREJO
C2: Kecamatan | D2: SRONO
C3: Kabupaten | D3: BANYUWANGI
C4: Provinsi | D4: JAWA TIMUR
C9: Kelurahan | D9: BAGOREJO
A12: I | B12: DATA PEMILIH DAN PENGGUNAAN HAK PILIH | AM12: JUMLAH AKHIR
A13: A | B13: DATA PEMILIH | E13: TPS 001 | F13: TPS 002 | G13: TPS 003 | H13: TPS 004 | I13: TPS 005 | J13: TPS 006 | K13: TPS 007 | L13: TPS 008 | M13: TPS 009 | N13: TPS 010 | O13: TPS 011 | P13: TPS 012 | Q13: TPS 013 | R13: TPS 014 | S13: TPS 015 | T13: TPS 016 | U13: TPS 017 | V13: TPS 018 | W13: TPS 019 | X13: TPS 020 | Y13: TPS 021 | Z13: TPS 022 | AA13: TPS 023 | AB13: TPS 024 | AC13: TPS 025 | AD13: TPS 026 | AE13: TPS 027 | AF13: TPS 028 | AG13: TPS 029 | AH13: TPS 030 | AI13: TPS 031 | AJ13: TPS 032 | AK13: TPS 033 | AL13: TPS 034
B14: Jumlah Pemilih dalam Daftar Pemilih Tetap (DPT) | D14: LK | E14: 156 | F14: 142 | G14: 136 | H14: 143 | I14: 141 | J14: 140 | K14: 150 | L14: 142 | M14: 134 | N14: 148 | O14: 150 | P14: 132 | Q14: 132 | R14: 141 | S14: 148 | T14: 144 | U14: 148 | V14: 141 | W14: 144 | X14: 137 | Y14: 153 | Z14: 149 | AA14: 139 | AB14: 127 | AC14: 138 | AD14: 133 | AE14: 137 | AF14: 142 | AG14: 149 | AH14: 142 | AI14: 153 | AJ14: 134 | AK14: 142 | AL14: 125 | AM14: =SUM(E14:AL14) -> 4812
D15: PR | E15: 132 | F15: 147 | G15: 147 | H15: 138 | I15: 140 | J15: 139 | K15: 142 | L15: 143 | M15: 149 | N15: 139 | O15: 130 | P15: 147 | Q15: 140 | R15: 143 | S15: 137 | T15: 144 | U15: 137 | V15: 150 | W15: 144 | X15: 138 | Y15: 129 | Z15: 132 | AA15: 145 | AB15: 149 | AC15: 149 | AD15: 153 | AE15: 147 | AF15: 146 | AG15: 146 | AH15: 140 | AI15: 130 | AJ15: 142 | AK15: 133 | AL15: 145 | AM15: =SUM(E15:AL15) -> 4812
D16: JML | E16: =SUM(E14:E15) -> 288 | F16: =SUM(F14:F15) -> 289 | G16: =SUM(G14:G15) -> 283 | H16: =SUM(H14:H15) -> 281 | I16: =SUM(I14:I15) -> 281 | J16: =SUM(J14:J15) -> 279 | K16: =SUM(K14:K15) -> 292 | L16: =SUM(L14:L15) -> 285 | ... AL16: =SUM(AL14:AL15) -> 270 | AM16: =SUM(E16:AL16) -> 9624
A18: B | B18: PENGGUNA HAK PILIH
B19: 1. | C19: Jumlah pengguna hak pilih dalam Daftar Pemilih Tetap (DPT) | D19: LK | E19: 103 | F19: 94 | G19: 98 | H19: 91 | I19: 102 | J19: 101 | K19: 90 | L19: 90 | M19: 98 | N19: 106 | O19: 109 | P19: 90 | Q19: 93 | R19: 100 | S19: 102 | T19: 104 | U19: 108 | V19: 107 | W19: 99 | X19: 114 | Y19: 113 | Z19: 120 | AA19: 115 | AB19: 87 | AC19: 100 | AD19: 102 | AE19: 108 | AF19: 103 | AG19: 110 | AH19: 98 | AI19: 109 | AJ19: 93 | AK19: 101 | AL19: 97 | AM19: =SUM(E19:AL19) -> 3455
D20: PR | E20: 103 | F20: 113 | G20: 119 | H20: 93 | I20: 111 | J20: 114 | K20: 109 | L20: 120 | M20: 129 | N20: 111 | O20: 107 | P20: 112 | Q20: 101 | R20: 112 | S20: 103 | T20: 120 | U20: 101 | V20: 120 | W20: 115 | X20: 109 | Y20: 102 | Z20: 117 | AA20: 108 | AB20: 111 | AC20: 114 | AD20: 122 | AE20: 126 | AF20: 114 | AG20: 115 | AH20: 108 | AI20: 103 | AJ20: 109 | AK20: 102 | AL20: 102 | AM20: =SUM(E20:AL20) -> 3775
D21: JML | E21: =SUM(E19:E20) -> 206 | F21: =SUM(F19:F20) -> 207 | G21: =SUM(G19:G20) -> 217 | H21: =SUM(H19:H20) -> 184 | I21: =SUM(I19:I20) -> 213 | J21: =SUM(J19:J20) -> 215 | K21: =SUM(K19:K20) -> 199 | L21: =SUM(L19:L20) -> 210 | ... AL21: =SUM(AL19:AL20) -> 199 | AM21: =SUM(E21:AL21) -> 7230
B22: 2. | C22: Jumlah pengguna hak pilih dalam Daftar Pemilih Tambahan (DPTb) | D22: LK | E22: 0 | F22: 0 | G22: 0 | H22: 0 | I22: 0 | J22: 1 | K22: 0 | L22: 0 | M22: 0 | N22: 1 | O22: 0 | P22: 0 | Q22: 0 | R22: 0 | S22: 0 | T22: 0 | U22: 0 | V22: 0 | W22: 0 | X22: 0 | Y22: 0 | Z22: 0 | AA22: 0 | AB22: 0 | AC22: 0 | AD22: 0 | AE22: 0 | AF22: 0 | AG22: 0 | AH22: 0 | AI22: 0 | AJ22: 0 | AK22: 0 | AL22: 0 | AM22: =SUM(E22:AL22) -> 2
D23: PR | E23: 0 | F23: 0 | G23: 0 | H23: 0 | I23: 1 | J23: 2 | K23: 0 | L23: 0 | M23: 0 | N23: 0 | O23: 0 | P23: 0 | Q23: 0 | R23: 0 | S23: 0 | T23: 0 | U23: 0 | V23: 0 | W23: 0 | X23: 0 | Y23: 0 | Z23: 0 | AA23: 0 | AB23: 0 | AC23: 0 | AD23: 0 | AE23: 0 | AF23: 0 | AG23: 0 | AH23: 0 | AI23: 0 | AJ23: 0 | AK23: 0 | AL23: 0 | AM23: =SUM(E23:AL23) -> 3
D24: JML | E24: =SUM(E22:E23) -> 0 | F24: =SUM(F22:F23) -> 0 | G24: =SUM(G22:G23) -> 0 | H24: =SUM(H22:H23) -> 0 | I24: =SUM(I22:I23) -> 1 | J24: =SUM(J22:J23) -> 3 | K24: =SUM(K22:K23) -> 0 | L24: =SUM(L22:L23) -> 0 | ... AL24: =SUM(AL22:AL23) -> 0 | AM24: =SUM(E24:AL24) -> 5
B25: 3. | C25: Jumlah pengguna hak pilih dalam Daftar Pemilih Khusus (DPK) | D25: LK | E25: 1 | F25: 4 | G25: 1 | H25: 0 | I25: 1 | J25: 4 | K25: 3 | L25: 1 | M25: 1 | N25: 1 | O25: 0 | P25: 1 | Q25: 1 | R25: 1 | S25: 3 | T25: 1 | U25: 1 | V25: 3 | W25: 0 | X25: 2 | Y25: 4 | Z25: 0 | AA25: 0 | AB25: 2 | AC25: 2 | AD25: 0 | AE25: 1 | AF25: 0 | AG25: 0 | AH25: 1 | AI25: 0 | AJ25: 0 | AK25: 0 | AL25: 0 | AM25: =SUM(E25:AL25) -> 40
D26: PR | E26: 1 | F26: 6 | G26: 1 | H26: 0 | I26: 3 | J26: 0 | K26: 3 | L26: 0 | M26: 1 | N26: 1 | O26: 2 | P26: 2 | Q26: 2 | R26: 1 | S26: 5 | T26: 2 | U26: 2 | V26: 2 | W26: 1 | X26: 3 | Y26: 3 | Z26: 2 | AA26: 2 | AB26: 5 | AC26: 1 | AD26: 0 | AE26: 1 | AF26: 0 | AG26: 1 | AH26: 2 | AI26: 2 | AJ26: 0 | AK26: 0 | AL26: 1 | AM26: =SUM(E26:AL26) -> 58
D27: JML | E27: =SUM(E25:E26) -> 2 | F27: =SUM(F25:F26) -> 10 | G27: =SUM(G25:G26) -> 2 | H27: =SUM(H25:H26) -> 0 | I27: =SUM(I25:I26) -> 4 | J27: =SUM(J25:J26) -> 4 | K27: =SUM(K25:K26) -> 6 | L27: =SUM(L25:L26) -> 1 | ... AL27: =SUM(AL25:AL26) -> 1 | AM27: =SUM(E27:AL27) -> 98
B28: 4. | C28: Jumlah Pengguna Hak Pilih (B.1+B.2+B.3) | D28: LK | E28: =SUM(E19,E22,E25) -> 104 | F28: =SUM(F19,F22,F25) -> 98 | G28: =SUM(G19,G22,G25) -> 99 | H28: =SUM(H19,H22,H25) -> 91 | I28: =SUM(I19,I22,I25) -> 103 | J28: =SUM(J19,J22,J25) -> 106 | K28: =SUM(K19,K22,K25) -> 93 | L28: =SUM(L19,L22,L25) -> 91 | ... AL28: =SUM(AL19,AL22,AL25) -> 97 | AM28: =SUM(E28:AL28) -> 3497
D29: PR | E29: =SUM(E20,E23,E26) -> 104 | F29: =SUM(F20,F23,F26) -> 119 | G29: =SUM(G20,G23,G26) -> 120 | H29: =SUM(H20,H23,H26) -> 93 | I29: =SUM(I20,I23,I26) -> 115 | J29: =SUM(J20,J23,J26) -> 116 | K29: =SUM(K20,K23,K26) -> 112 | L29: =SUM(L20,L23,L26) -> 120 | ... AL29: =SUM(AL20,AL23,AL26) -> 103 | AM29: =SUM(E29:AL29) -> 3836
D30: JML | E30: =SUM(E28:E29) -> 208 | F30: =SUM(F28:F29) -> 217 | G30: =SUM(G28:G29) -> 219 | H30: =SUM(H28:H29) -> 184 | I30: =SUM(I28:I29) -> 218 | J30: =SUM(J28:J29) -> 222 | K30: =SUM(K28:K29) -> 205 | L30: =SUM(L28:L29) -> 211 | ... AL30: =SUM(AL28:AL29) -> 200 | AM30: =SUM(E30:AL30) -> 7333
A32: II | B32: DATA PENGGUNAAN SURAT SUARA
A33: 1 | B33: Jumlah surat suara yang diterima, termasuk surat suara cadangan 2,5% dari DPT | E33: 294 | F33: 295 | G33: 289 | H33: 288 | I33: 290 | J33: 285 | K33: 297 | L33: 291 | M33: 289 | N33: 293 | O33: 286 | P33: 285 | Q33: 278 | R33: 290 | S33: 291 | T33: 288 | U33: 291 | V33: 295 | W33: 294 | X33: 282 | Y33: 288 | Z33: 287 | AA33: 291 | AB33: 281 | AC33: 293 | AD33: 292 | AE33: 290 | AF33: 294 | AG33: 301 | AH33: 288 | AI33: 282 | AJ33: 282 | AK33: 282 | AL33: 276 | AM33: =SUM(E33:AL33) -> 9818
A34: 2 | B34: Jumlah surat suara yang digunakan | E34: 208 | F34: 217 | G34: 219 | H34: 184 | I34: 218 | J34: 222 | K34: 205 | L34: 211 | M34: 229 | N34: 220 | O34: 218 | P34: 205 | Q34: 197 | R34: 214 | S34: 213 | T34: 227 | U34: 212 | V34: 232 | W34: 215 | X34: 228 | Y34: 222 | Z34: 239 | AA34: 225 | AB34: 205 | AC34: 217 | AD34: 224 | AE34: 236 | AF34: 217 | AG34: 226 | AH34: 209 | AI34: 214 | AJ34: 202 | AK34: 203 | AL34: 200 | AM34: =SUM(E34:AL34) -> 7333
A35: 3 | B35: Jumlah surat suara dikembalikan oleh pemilih (karena rusak atau keliru coblos) | E35: 0 | F35: 0 | G35: 0 | H35: 0 | I35: 2 | J35: 1 | K35: 0 | L35: 0 | M35: 1 | N35: 0 | O35: 0 | P35: 0 | Q35: 0 | R35: 0 | S35: 0 | T35: 0 | U35: 0 | V35: 0 | W35: 0 | X35: 0 | Y35: 0 | Z35: 0 | AA35: 0 | AB35: 0 | AC35: 0 | AD35: 1 | AE35: 0 | AF35: 0 | AG35: 1 | AH35: 0 | AI35: 0 | AJ35: 0 | AK35: 1 | AL35: 0 | AM35: =SUM(E35:AL35) -> 7
A36: 4 | B36: Jumlah surat suara yang tidak digunakan/tidak terpakai, termasuk sisa surat suara cadangan | E36: =E33-(E34+E35) -> 86 | F36: =F33-(F34+F35) -> 78 | G36: =G33-(G34+G35) -> 70 | H36: =H33-(H34+H35) -> 104 | I36: =I33-(I34+I35) -> 70 | J36: =J33-(J34+J35) -> 62 | K36: =K33-(K34+K35) -> 92 | L36: =L33-(L34+L35) -> 80 | ... AL36: =AL33-(AL34+AL35) -> 76 | AM36: =SUM(E36:AL36) -> 2478
A38: III | B38: DATA PEMILIH DISABILITAS
B39: Jumlah seluruh Pemilih disabilitas yang menggunakan hak pilih | D39: LK | AM39: =SUM(E39:AL39) -> 0
D40: PR | AM40: =SUM(E40:AL40) -> 0
D41: JML | E41: =SUM(E39:E40) -> 0 | F41: =SUM(F39:F40) -> 0 | G41: =SUM(G39:G40) -> 0 | H41: =SUM(H39:H40) -> 0 | I41: =SUM(I39:I40) -> 0 | J41: =SUM(J39:J40) -> 0 | K41: =SUM(K39:K40) -> 0 | L41: =SUM(L39:L40) -> 0 | ... AL41: =SUM(AL39:AL40) -> 0 | AM41: =SUM(E41:AL41) -> 0
A43: IV | B43: DATA RINCIAN PEROLEHAN SUARA PASANGAN CALON BUPATI DAN WAKIL BUPATI
A44: NOMOR DAN NAMA CALON
A45: A.1 | B45: 1. | C45: Partai Kebangkitan Bangsa | E45: 17 | F45: 4 | G45: 26 | H45: 11 | I45: 10 | J45: 33 | K45: 9 | L45: 2 | M45: 12 | N45: 17 | O45: 23 | P45: 12 | Q45: 9 | R45: 10 | S45: 11 | T45: 10 | U45: 9 | V45: 8 | W45: 20 | X45: 8 | Y45: 5 | Z45: 11 | AA45: 11 | AB45: 3 | AC45: 8 | AD45: 9 | AE45: 16 | AF45: 18 | AG45: 22 | AH45: 14 | AI45: 3 | AJ45: 12 | AK45: 14 | AL45: 4 | AM45: =SUM(E45:AL45) -> 411
A46: A.2 | C46: 1. Dra. Hj. MA`MULAH HARUN, M.Pd.I. | E46: 27 | F46: 18 | G46: 17 | H46: 18 | I46: 9 | J46: 36 | K46: 13 | L46: 14 | M46: 10 | N46: 38 | O46: 31 | P46: 11 | Q46: 12 | R46: 16 | S46: 11 | T46: 13 | U46: 9 | V46: 14 | W46: 10 | X46: 8 | Y46: 5 | Z46: 10 | AA46: 10 | AB46: 5 | AC46: 8 | AD46: 13 | AE46: 12 | AF46: 26 | AG46: 18 | AH46: 5 | AI46: 1 | AJ46: 5 | AK46: 10 | AL46: 2 | AM46: =SUM(E46:AL46) -> 465
C47: 2. UBAIDILLAH, S.Fil.I. | E47: 2 | F47: 3 | G47: 2 | H47: 1 | I47: 3 | J47: 5 | K47: 1 | L47: 6 | M47: 2 | N47: 4 | O47: 4 | P47: 7 | Q47: 1 | R47: 3 | S47: 2 | T47: 1 | U47: 2 | V47: 1 | W47: 2 | X47: 0 | Y47: 2 | Z47: 1 | AA47: 0 | AB47: 0 | AC47: 0 | AD47: 0 | AE47: 1 | AF47: 3 | AG47: 4 | AH47: 2 | AI47: 2 | AJ47: 0 | AK47: 1 | AL47: 1 | AM47: =SUM(E47:AL47) -> 69
C48: 3. Ir. H. YOYOK MULYADI, M.Si. | E48: 0 | F48: 0 | G48: 1 | H48: 1 | I48: 0 | J48: 1 | K48: 1 | L48: 1 | M48: 0 | N48: 1 | O48: 1 | P48: 0 | Q48: 0 | R48: 0 | S48: 0 | T48: 1 | U48: 2 | V48: 1 | W48: 0 | X48: 1 | Y48: 0 | Z48: 0 | AA48: 0 | AB48: 0 | AC48: 0 | AD48: 0 | AE48: 1 | AF48: 1 | AG48: 2 | AH48: 1 | AI48: 0 | AJ48: 2 | AK48: 0 | AL48: 0 | AM48: =SUM(E48:AL48) -> 19
C49: 4. KHOIRUL ANWAR, S.Fil.I. | E49: 3 | F49: 1 | G49: 1 | H49: 0 | I49: 4 | J49: 3 | K49: 2 | L49: 0 | M49: 3 | N49: 1 | O49: 2 | P49: 1 | Q49: 0 | R49: 2 | S49: 2 | T49: 2 | U49: 3 | V49: 3 | W49: 3 | X49: 0 | Y49: 0 | Z49: 0 | AA49: 1 | AB49: 1 | AC49: 0 | AD49: 1 | AE49: 1 | AF49: 0 | AG49: 2 | AH49: 2 | AI49: 0 | AJ49: 1 | AK49: 1 | AL49: 1 | AM49: =SUM(E49:AL49) -> 47
C50: 5. ARIF WIJAKSANA | E50: 0 | F50: 1 | G50: 1 | H50: 0 | I50: 0 | J50: 1 | K50: 1 | L50: 0 | M50: 1 | N50: 4 | O50: 4 | P50: 7 | Q50: 0 | R50: 0 | S50: 0 | T50: 0 | U50: 3 | V50: 0 | W50: 1 | X50: 0 | Y50: 0 | Z50: 2 | AA50: 1 | AB50: 1 | AC50: 0 | AD50: 0 | AE50: 0 | AF50: 1 | AG50: 3 | AH50: 0 | AI50: 0 | AJ50: 0 | AK50: 0 | AL50: 1 | AM50: =SUM(E50:AL50) -> 33
C51: 6. Dr. SITI YUMNAH | E51: 0 | F51: 0 | G51: 0 | H51: 0 | I51: 0 | J51: 2 | K51: 0 | L51: 0 | M51: 0 | N51: 0 | O51: 0 | P51: 0 | Q51: 0 | R51: 0 | S51: 1 | T51: 0 | U51: 1 | V51: 0 | W51: 0 | X51: 0 | Y51: 1 | Z51: 0 | AA51: 0 | AB51: 0 | AC51: 0 | AD51: 0 | AE51: 0 | AF51: 0 | AG51: 0 | AH51: 0 | AI51: 0 | AJ51: 2 | AK51: 0 | AL51: 2 | AM51: =SUM(E51:AL51) -> 9
...

Sheet WONOSOBO
C2: Kecamatan | D2: SRONO
C3: Kabupaten | D3: BANYUWANGI
C4: Provinsi | D4: JAWA TIMUR
C9: Kelurahan | D9: WONOSOBO
A12: I | B12: DATA PEMILIH DAN PENGGUNAAN HAK PILIH | AS12: JUMLAH AKHIR
A13: A | B13: DATA PEMILIH | E13: TPS 001 | F13: TPS 002 | G13: TPS 003 | H13: TPS 004 | I13: TPS 005 | J13: TPS 006 | K13: TPS 007 | L13: TPS 008 | M13: TPS 009 | N13: TPS 010 | O13: TPS 011 | P13: TPS 012 | Q13: TPS 013 | R13: TPS 014 | S13: TPS 015 | T13: TPS 016 | U13: TPS 017 | V13: TPS 018 | W13: TPS 019 | X13: TPS 020 | Y13: TPS 021 | Z13: TPS 022 | AA13: TPS 023 | AB13: TPS 024 | AC13: TPS 025 | AD13: TPS 026 | AE13: TPS 027 | AF13: TPS 028 | AG13: TPS 029 | AH13: TPS 030 | AI13: TPS 031 | AJ13: TPS 032 | AK13: TPS 033 | AL13: TPS 034 | AM13: TPS 035 | AN13: TPS 036 | AO13: TPS 037 | AP13: TPS 038 | AQ13: TPS 039 | AR13: TPS 040
B14: Jumlah Pemilih dalam Daftar Pemilih Tetap (DPT) | D14: LK | E14: 133 | F14: 143 | G14: 134 | H14: 136 | I14: 129 | J14: 132 | K14: 130 | L14: 132 | M14: 142 | N14: 143 | O14: 149 | P14: 136 | Q14: 145 | R14: 149 | S14: 140 | T14: 136 | U14: 143 | V14: 142 | W14: 126 | X14: 134 | Y14: 144 | Z14: 123 | AA14: 136 | AB14: 131 | AC14: 129 | AD14: 142 | AE14: 135 | AF14: 135 | AG14: 134 | AH14: 144 | AI14: 140 | AJ14: 140 | AK14: 146 | AL14: 124 | AM14: 142 | AN14: 144 | AO14: 138 | AP14: 150 | AQ14: 153 | AR14: 145 | AS14: =SUM(E14:AR14) -> 5529
D15: PR | E15: 134 | F15: 134 | G15: 129 | H15: 127 | I15: 143 | J15: 135 | K15: 123 | L15: 127 | M15: 140 | N15: 147 | O15: 139 | P15: 122 | Q15: 131 | R15: 146 | S15: 150 | T15: 132 | U15: 139 | V15: 137 | W15: 118 | X15: 140 | Y15: 136 | Z15: 143 | AA15: 137 | AB15: 128 | AC15: 128 | AD15: 137 | AE15: 133 | AF15: 126 | AG15: 130 | AH15: 139 | AI15: 144 | AJ15: 144 | AK15: 146 | AL15: 118 | AM15: 145 | AN15: 137 | AO15: 137 | AP15: 147 | AQ15: 142 | AR15: 145 | AS15: =SUM(E15:AR15) -> 5435
D16: JML | E16: =SUM(E14:E15) -> 267 | F16: =SUM(F14:F15) -> 277 | G16: =SUM(G14:G15) -> 263 | H16: =SUM(H14:H15) -> 263 | I16: =SUM(I14:I15) -> 272 | J16: =SUM(J14:J15) -> 267 | K16: =SUM(K14:K15) -> 253 | L16: =SUM(L14:L15) -> 259 | ... AR16: =SUM(AR14:AR15) -> 290 | AS16: =SUM(E16:AR16) -> 10964
A18: B | B18: PENGGUNA HAK PILIH
B19: 1. | C19: Jumlah pengguna hak pilih dalam Daftar Pemilih Tetap (DPT) | D19: LK | E19: 98 | F19: 108 | G19: 94 | H19: 81 | I19: 92 | J19: 87 | K19: 99 | L19: 98 | M19: 112 | N19: 85 | O19: 99 | P19: 98 | Q19: 83 | R19: 100 | S19: 107 | T19: 96 | U19: 111 | V19: 99 | W19: 97 | X19: 92 | Y19: 105 | Z19: 100 | AA19: 109 | AB19: 99 | AC19: 105 | AD19: 94 | AE19: 103 | AF19: 103 | AG19: 99 | AH19: 107 | AI19: 113 | AJ19: 113 | AK19: 116 | AL19: 105 | AM19: 112 | AN19: 106 | AO19: 111 | AP19: 128 | AQ19: 119 | AR19: 103 | AS19: =SUM(E19:AR19) -> 4086
D20: PR | E20: 113 | F20: 111 | G20: 99 | H20: 90 | I20: 107 | J20: 105 | K20: 98 | L20: 97 | M20: 99 | N20: 101 | O20: 110 | P20: 82 | Q20: 89 | R20: 103 | S20: 124 | T20: 109 | U20: 107 | V20: 109 | W20: 86 | X20: 101 | Y20: 92 | Z20: 113 | AA20: 117 | AB20: 102 | AC20: 107 | AD20: 101 | AE20: 109 | AF20: 105 | AG20: 102 | AH20: 116 | AI20: 121 | AJ20: 126 | AK20: 119 | AL20: 100 | AM20: 114 | AN20: 115 | AO20: 110 | AP20: 123 | AQ20: 121 | AR20: 111 | AS20: =SUM(E20:AR20) -> 4264
D21: JML | E21: =SUM(E19:E20) -> 211 | F21: =SUM(F19:F20) -> 219 | G21: =SUM(G19:G20) -> 193 | H21: =SUM(H19:H20) -> 171 | I21: =SUM(I19:I20) -> 199 | J21: =SUM(J19:J20) -> 192 | K21: =SUM(K19:K20) -> 197 | L21: =SUM(L19:L20) -> 195 | ... AR21: =SUM(AR19:AR20) -> 214 | AS21: =SUM(E21:AR21) -> 8350
B22: 2. | C22: Jumlah pengguna hak pilih dalam Daftar Pemilih Tambahan (DPTb) | D22: LK | E22: 0 | F22: 0 | G22: 0 | H22: 0 | I22: 0 | J22: 0 | K22: 0 | L22: 0 | M22: 0 | N22: 1 | O22: 0 | P22: 0 | Q22: 0 | R22: 0 | S22: 0 | T22: 0 | U22: 1 | V22: 1 | W22: 0 | X22: 0 | Y22: 0 | Z22: 0 | AA22: 0 | AB22: 0 | AC22: 0 | AD22: 0 | AE22: 0 | AF22: 1 | AG22: 0 | AH22: 0 | AI22: 0 | AJ22: 0 | AK22: 0 | AL22: 0 | AM22: 0 | AN22: 0 | AO22: 0 | AP22: 0 | AQ22: 0 | AR22: 1 | AS22: =SUM(E22:AR22) -> 5
D23: PR | E23: 0 | F23: 0 | G23: 0 | H23: 0 | I23: 0 | J23: 0 | K23: 0 | L23: 0 | M23: 0 | N23: 1 | O23: 0 | P23: 0 | Q23: 0 | R23: 0 | S23: 0 | T23: 0 | U23: 1 | V23: 0 | W23: 0 | X23: 0 | Y23: 0 | Z23: 0 | AA23: 0 | AB23: 0 | AC23: 0 | AD23: 0 | AE23: 0 | AF23: 1 | AG23: 0 | AH23: 0 | AI23: 0 | AJ23: 0 | AK23: 0 | AL23: 0 | AM23: 0 | AN23: 0 | AO23: 0 | AP23: 0 | AQ23: 0 | AR23: 0 | AS23: =SUM(E23:AR23) -> 3
D24: JML | E24: =SUM(E22:E23) -> 0 | F24: =SUM(F22:F23) -> 0 | G24: =SUM(G22:G23) -> 0 | H24: =SUM(H22:H23) -> 0 | I24: =SUM(I22:I23) -> 0 | J24: =SUM(J22:J23) -> 0 | K24: =SUM(K22:K23) -> 0 | L24: =SUM(L22:L23) -> 0 | ... AR24: =SUM(AR22:AR23) -> 1 | AS24: =SUM(E24:AR24) -> 8
B25: 3. | C25: Jumlah pengguna hak pilih dalam Daftar Pemilih Khusus (DPK) | D25: LK | E25: 1 | F25: 0 | G25: 2 | H25: 2 | I25: 0 | J25: 0 | K25: 0 | L25: 0 | M25: 0 | N25: 0 | O25: 0 | P25: 0 | Q25: 1 | R25: 2 | S25: 2 | T25: 3 | U25: 3 | V25: 3 | W25: 0 | X25: 0 | Y25: 0 | Z25: 0 | AA25: 0 | AB25: 6 | AC25: 3 | AD25: 1 | AE25: 0 | AF25: 3 | AG25: 0 | AH25: 2 | AI25: 1 | AJ25: 3 | AK25: 2 | AL25: 1 | AM25: 4 | AN25: 0 | AO25: 0 | AP25: 0 | AQ25: 3 | AR25: 0 | AS25: =SUM(E25:AR25) -> 48
D26: PR | E26: 1 | F26: 0 | G26: 5 | H26: 2 | I26: 0 | J26: 1 | K26: 1 | L26: 0 | M26: 0 | N26: 0 | O26: 0 | P26: 0 | Q26: 9 | R26: 0 | S26: 1 | T26: 0 | U26: 5 | V26: 1 | W26: 0 | X26: 1 | Y26: 0 | Z26: 0 | AA26: 1 | AB26: 6 | AC26: 2 | AD26: 1 | AE26: 0 | AF26: 1 | AG26: 0 | AH26: 1 | AI26: 1 | AJ26: 1 | AK26: 2 | AL26: 3 | AM26: 1 | AN26: 0 | AO26: 0 | AP26: 0 | AQ26: 3 | AR26: 0 | AS26: =SUM(E26:AR26) -> 50
D27: JML | E27: =SUM(E25:E26) -> 2 | F27: =SUM(F25:F26) -> 0 | G27: =SUM(G25:G26) -> 7 | H27: =SUM(H25:H26) -> 4 | I27: =SUM(I25:I26) -> 0 | J27: =SUM(J25:J26) -> 1 | K27: =SUM(K25:K26) -> 1 | L27: =SUM(L25:L26) -> 0 | ... AR27: =SUM(AR25:AR26) -> 0 | AS27: =SUM(E27:AR27) -> 98
B28: 4. | C28: Jumlah Pengguna Hak Pilih (B.1+B.2+B.3) | D28: LK | E28: =SUM(E19,E22,E25) -> 99 | F28: =SUM(F19,F22,F25) -> 108 | G28: =SUM(G19,G22,G25) -> 96 | H28: =SUM(H19,H22,H25) -> 83 | I28: =SUM(I19,I22,I25) -> 92 | J28: =SUM(J19,J22,J25) -> 87 | K28: =SUM(K19,K22,K25) -> 99 | L28: =SUM(L19,L22,L25) -> 98 | ... AR28: =SUM(AR19,AR22,AR25) -> 104 | AS28: =SUM(E28:AR28) -> 4139
D29: PR | E29: =SUM(E20,E23,E26) -> 114 | F29: =SUM(F20,F23,F26) -> 111 | G29: =SUM(G20,G23,G26) -> 104 | H29: =SUM(H20,H23,H26) -> 92 | I29: =SUM(I20,I23,I26) -> 107 | J29: =SUM(J20,J23,J26) -> 106 | K29: =SUM(K20,K23,K26) -> 99 | L29: =SUM(L20,L23,L26) -> 97 | ... AR29: =SUM(AR20,AR23,AR26) -> 111 | AS29: =SUM(E29:AR29) -> 4317
D30: JML | E30: =SUM(E28:E29) -> 213 | F30: =SUM(F28:F29) -> 219 | G30: =SUM(G28:G29) -> 200 | H30: =SUM(H28:H29) -> 175 | I30: =SUM(I28:I29) -> 199 | J30: =SUM(J28:J29) -> 193 | K30: =SUM(K28:K29) -> 198 | L30: =SUM(L28:L29) -> 195 | ... AR30: =SUM(AR28:AR29) -> 215 | AS30: =SUM(E30:AR30) -> 8456
A32: II | B32: DATA PENGGUNAAN SURAT SUARA
A33: 1 | B33: Jumlah surat suara yang diterima, termasuk surat suara cadangan 2,5% dari DPT | E33: 274 | F33: 283 | G33: 268 | H33: 269 | I33: 277 | J33: 274 | K33: 259 | L33: 265 | M33: 288 | N33: 296 | O33: 294 | P33: 264 | Q33: 282 | R33: 282 | S33: 296 | T33: 274 | U33: 288 | V33: 285 | W33: 249 | X33: 280 | Y33: 286 | Z33: 272 | AA33: 278 | AB33: 265 | AC33: 264 | AD33: 285 | AE33: 274 | AF33: 267 | AG33: 270 | AH33: 289 | AI33: 290 | AJ33: 290 | AK33: 298 | AL33: 247 | AM33: 293 | AN33: 287 | AO33: 281 | AP33: 302 | AQ33: 301 | AR33: 286 | AS33: =SUM(E33:AR33) -> 11172
A34: 2 | B34: Jumlah surat suara yang digunakan | E34: 213 | F34: 219 | G34: 200 | H34: 175 | I34: 199 | J34: 193 | K34: 198 | L34: 195 | M34: 211 | N34: 188 | O34: 209 | P34: 180 | Q34: 182 | R34: 205 | S34: 234 | T34: 208 | U34: 228 | V34: 213 | W34: 183 | X34: 194 | Y34: 197 | Z34: 213 | AA34: 227 | AB34: 213 | AC34: 217 | AD34: 197 | AE34: 212 | AF34: 214 | AG34: 201 | AH34: 226 | AI34: 236 | AJ34: 243 | AK34: 239 | AL34: 209 | AM34: 231 | AN34: 221 | AO34: 221 | AP34: 251 | AQ34: 246 | AR34: 215 | AS34: =SUM(E34:AR34) -> 8456
A35: 3 | B35: Jumlah surat suara dikembalikan oleh pemilih (karena rusak atau keliru coblos) | E35: 0 | F35: 0 | G35: 0 | H35: 0 | I35: 0 | J35: 0 | K35: 0 | L35: 0 | M35: 0 | N35: 0 | O35: 0 | P35: 0 | Q35: 0 | R35: 0 | S35: 0 | T35: 0 | U35: 0 | V35: 0 | W35: 2 | X35: 0 | Y35: 0 | Z35: 3 | AA35: 0 | AB35: 1 | AC35: 0 | AD35: 0 | AE35: 0 | AF35: 0 | AG35: 0 | AH35: 0 | AI35: 1 | AJ35: 0 | AK35: 0 | AL35: 0 | AM35: 0 | AN35: 0 | AO35: 0 | AP35: 0 | AQ35: 0 | AR35: 0 | AS35: =SUM(E35:AR35) -> 7
A36: 4 | B36: Jumlah surat suara yang tidak digunakan/tidak terpakai, termasuk sisa surat suara cadangan | E36: =E33-(E34+E35) -> 61 | F36: =F33-(F34+F35) -> 64 | G36: =G33-(G34+G35) -> 68 | H36: =H33-(H34+H35) -> 94 | I36: =I33-(I34+I35) -> 78 | J36: =J33-(J34+J35) -> 81 | K36: =K33-(K34+K35) -> 61 | L36: =L33-(L34+L35) -> 70 | ... AR36: =AR33-(AR34+AR35) -> 71 | AS36: =SUM(E36:AR36) -> 2709
A38: III | B38: DATA PEMILIH DISABILITAS
B39: Jumlah seluruh Pemilih disabilitas yang menggunakan hak pilih | D39: LK | E39: 0 | F39: 0 | G39: 0 | H39: 0 | I39: 0 | J39: 0 | K39: 0 | L39: 0 | M39: 0 | N39: 0 | O39: 0 | P39: 0 | Q39: 0 | R39: 0 | S39: 0 | T39: 0 | U39: 2 | V39: 0 | W39: 0 | X39: 0 | Y39: 0 | Z39: 1 | AA39: 0 | AB39: 0 | AC39: 0 | AD39: 0 | AE39: 0 | AF39: 2 | AG39: 0 | AH39: 0 | AI39: 0 | AJ39: 1 | AK39: 0 | AL39: 0 | AM39: 1 | AN39: 0 | AO39: 0 | AP39: 0 | AQ39: 0 | AR39: 0 | AS39: =SUM(E39:AR39) -> 7
D40: PR | E40: 0 | F40: 0 | G40: 0 | H40: 0 | I40: 1 | J40: 0 | K40: 0 | L40: 0 | M40: 0 | N40: 0 | O40: 0 | P40: 0 | Q40: 0 | R40: 0 | S40: 0 | T40: 1 | U40: 1 | V40: 1 | W40: 0 | X40: 0 | Y40: 0 | Z40: 1 | AA40: 0 | AB40: 0 | AC40: 0 | AD40: 0 | AE40: 0 | AF40: 3 | AG40: 0 | AH40: 0 | AI40: 0 | AJ40: 1 | AK40: 0 | AL40: 0 | AM40: 0 | AN40: 0 | AO40: 0 | AP40: 0 | AQ40: 0 | AR40: 0 | AS40: =SUM(E40:AR40) -> 9
D41: JML | E41: =SUM(E39:E40) -> 0 | F41: =SUM(F39:F40) -> 0 | G41: =SUM(G39:G40) -> 0 | H41: =SUM(H39:H40) -> 0 | I41: =SUM(I39:I40) -> 1 | J41: =SUM(J39:J40) -> 0 | K41: =SUM(K39:K40) -> 0 | L41: =SUM(L39:L40) -> 0 | ... AR41: =SUM(AR39:AR40) -> 0 | AS41: =SUM(E41:AR41) -> 16
A43: IV | B43: DATA RINCIAN PEROLEHAN SUARA PASANGAN CALON BUPATI DAN WAKIL BUPATI
A44: NOMOR DAN NAMA CALON
A45: A.1 | B45: 1. | C45: Partai Kebangkitan Bangsa | E45: 1 | F45: 0 | G45: 4 | H45: 2 | I45: 3 | J45: 6 | K45: 2 | L45: 9 | M45: 5 | N45: 6 | O45: 6 | P45: 9 | Q45: 5 | R45: 3 | S45: 6 | T45: 6 | U45: 5 | V45: 2 | W45: 5 | X45: 2 | Y45: 4 | Z45: 3 | AA45: 10 | AB45: 8 | AC45: 2 | AD45: 7 | AE45: 3 | AF45: 5 | AG45: 7 | AH45: 4 | AI45: 8 | AJ45: 6 | AK45: 10 | AL45: 8 | AM45: 16 | AN45: 4 | AO45: 1 | AP45: 1 | AQ45: 4 | AR45: 6 | AS45: =SUM(E45:AR45) -> 204
A46: A.2 | C46: 1. Dra. Hj. MA`MULAH HARUN, M.Pd.I. | E46: 3 | F46: 3 | G46: 3 | H46: 7 | I46: 6 | J46: 11 | K46: 0 | L46: 7 | M46: 8 | N46: 4 | O46: 17 | P46: 14 | Q46: 10 | R46: 5 | S46: 1 | T46: 7 | U46: 6 | V46: 5 | W46: 6 | X46: 6 | Y46: 12 | Z46: 6 | AA46: 15 | AB46: 6 | AC46: 6 | AD46: 6 | AE46: 2 | AF46: 9 | AG46: 4 | AH46: 4 | AI46: 7 | AJ46: 10 | AK46: 4 | AL46: 4 | AM46: 6 | AN46: 15 | AO46: 14 | AP46: 6 | AQ46: 2 | AR46: 3 | AS46: =SUM(E46:AR46) -> 270
C47: 2. UBAIDILLAH, S.Fil.I. | E47: 1 | F47: 1 | G47: 1 | H47: 1 | I47: 0 | J47: 1 | K47: 0 | L47: 2 | M47: 1 | N47: 1 | O47: 3 | P47: 1 | Q47: 0 | R47: 2 | S47: 2 | T47: 0 | U47: 1 | V47: 1 | W47: 2 | X47: 5 | Y47: 2 | Z47: 2 | AA47: 2 | AB47: 0 | AC47: 0 | AD47: 2 | AE47: 1 | AF47: 2 | AG47: 1 | AH47: 3 | AI47: 1 | AJ47: 4 | AK47: 1 | AL47: 0 | AM47: 0 | AN47: 5 | AO47: 4 | AP47: 2 | AQ47: 0 | AR47: 1 | AS47: =SUM(E47:AR47) -> 59
C48: 3. Ir. H. YOYOK MULYADI, M.Si. | E48: 1 | F48: 1 | G48: 2 | H48: 0 | I48: 0 | J48: 0 | K48: 1 | L48: 1 | M48: 3 | N48: 1 | O48: 2 | P48: 1 | Q48: 0 | R48: 1 | S48: 1 | T48: 1 | U48: 0 | V48: 1 | W48: 0 | X48: 0 | Y48: 2 | Z48: 1 | AA48: 0 | AB48: 1 | AC48: 2 | AD48: 1 | AE48: 0 | AF48: 0 | AG48: 0 | AH48: 0 | AI48: 2 | AJ48: 3 | AK48: 0 | AL48: 0 | AM48: 0 | AN48: 1 | AO48: 0 | AP48: 1 | AQ48: 0 | AR48: 1 | AS48: =SUM(E48:AR48) -> 32
C49: 4. KHOIRUL ANWAR, S.Fil.I. | E49: 0 | F49: 0 | G49: 1 | H49: 1 | I49: 4 | J49: 1 | K49: 1 | L49: 1 | M49: 2 | N49: 0 | O49: 5 | P49: 0 | Q49: 1 | R49: 1 | S49: 1 | T49: 3 | U49: 1 | V49: 6 | W49: 1 | X49: 0 | Y49: 1 | Z49: 2 | AA49: 2 | AB49: 1 | AC49: 0 | AD49: 2 | AE49: 0 | AF49: 1 | AG49: 0 | AH49: 1 | AI49: 5 | AJ49: 4 | AK49: 3 | AL49: 0 | AM49: 0 | AN49: 1 | AO49: 0 | AP49: 2 | AQ49: 0 | AR49: 0 | AS49: =SUM(E49:AR49) -> 55
C50: 5. ARIF WIJAKSANA | E50: 1 | F50: 0 | G50: 0 | H50: 0 | I50: 2 | J50: 2 | K50: 0 | L50: 0 | M50: 0 | N50: 0 | O50: 2 | P50: 1 | Q50: 0 | R50: 0 | S50: 1 | T50: 0 | U50: 0 | V50: 1 | W50: 0 | X50: 0 | Y50: 1 | Z50: 0 | AA50: 0 | AB50: 0 | AC50: 1 | AD50: 0 | AE50: 0 | AF50: 0 | AG50: 0 | AH50: 1 | AI50: 1 | AJ50: 0 | AK50: 1 | AL50: 0 | AM50: 1 | AN50: 1 | AO50: 0 | AP50: 0 | AQ50: 0 | AR50: 0 | AS50: =SUM(E50:AR50) -> 17
C51: 6. Dr. SITI YUMNAH | E51: 0 | F51: 0 | G51: 1 | H51: 0 | I51: 1 | J51: 0 | K51: 0 | L51: 0 | M51: 0 | N51: 1 | O51: 0 | P51: 0 | Q51: 1 | R51: 0 | S51: 0 | T51: 0 | U51: 1 | V51: 0 | W51: 1 | X51: 0 | Y51: 0 | Z51: 0 | AA51: 0 | AB51: 1 | AC51: 1 | AD51: 0 | AE51: 0 | AF51: 0 | AG51: 1 | AH51: 0 | AI51: 0 | AJ51: 0 | AK51: 0 | AL51: 2 | AM51: 2 | AN51: 0 | AO51: 0 | AP51: 2 | AQ51: 0 | AR51: 0 | AS51: =SUM(E51:AR51) -> 15
...

Sheet SUKONATAR
C2: Kecamatan | D2: SRONO
C3: Kabupaten | D3: BANYUWANGI
C4: Provinsi | D4: JAWA TIMUR
C9: Kelurahan | D9: SUKONATAR
A12: I | B12: DATA PEMILIH DAN PENGGUNAAN HAK PILIH | T12: JUMLAH AKHIR
A13: A | B13: DATA PEMILIH | E13: TPS 001 | F13: TPS 002 | G13: TPS 003 | H13: TPS 004 | I13: TPS 005 | J13: TPS 006 | K13: TPS 007 | L13: TPS 008 | M13: TPS 009 | N13: TPS 010 | O13: TPS 011 | P13: TPS 012 | Q13: TPS 013 | R13: TPS 014 | S13: TPS 015
B14: Jumlah Pemilih dalam Daftar Pemilih Tetap (DPT) | D14: LK | E14: 142 | F14: 143 | G14: 145 | H14: 130 | I14: 120 | J14: 146 | K14: 134 | L14: 155 | M14: 125 | N14: 127 | O14: 119 | P14: 145 | Q14: 128 | R14: 139 | S14: 136 | T14: =SUM(E14:S14) -> 2034
D15: PR | E15: 138 | F15: 138 | G15: 141 | H15: 118 | I15: 145 | J15: 140 | K15: 132 | L15: 130 | M15: 148 | N15: 124 | O15: 124 | P15: 141 | Q15: 145 | R15: 143 | S15: 137 | T15: =SUM(E15:S15) -> 2044
D16: JML | E16: =SUM(E14:E15) -> 280 | F16: =SUM(F14:F15) -> 281 | G16: =SUM(G14:G15) -> 286 | H16: =SUM(H14:H15) -> 248 | I16: =SUM(I14:I15) -> 265 | J16: =SUM(J14:J15) -> 286 | K16: =SUM(K14:K15) -> 266 | L16: =SUM(L14:L15) -> 285 | ... S16: =SUM(S14:S15) -> 273 | T16: =SUM(E16:S16) -> 4078
A18: B | B18: PENGGUNA HAK PILIH
B19: 1. | C19: Jumlah pengguna hak pilih dalam Daftar Pemilih Tetap (DPT) | D19: LK | E19: 103 | F19: 97 | G19: 92 | H19: 90 | I19: 88 | J19: 116 | K19: 109 | L19: 109 | M19: 94 | N19: 90 | O19: 90 | P19: 114 | Q19: 102 | R19: 105 | S19: 94 | T19: =SUM(E19:S19) -> 1493
D20: PR | E20: 118 | F20: 111 | G20: 110 | H20: 80 | I20: 117 | J20: 112 | K20: 107 | L20: 106 | M20: 113 | N20: 102 | O20: 94 | P20: 122 | Q20: 125 | R20: 118 | S20: 107 | T20: =SUM(E20:S20) -> 1642
D21: JML | E21: =SUM(E19:E20) -> 221 | F21: =SUM(F19:F20) -> 208 | G21: =SUM(G19:G20) -> 202 | H21: =SUM(H19:H20) -> 170 | I21: =SUM(I19:I20) -> 205 | J21: =SUM(J19:J20) -> 228 | K21: =SUM(K19:K20) -> 216 | L21: =SUM(L19:L20) -> 215 | ... S21: =SUM(S19:S20) -> 201 | T21: =SUM(E21:S21) -> 3135
B22: 2. | C22: Jumlah pengguna hak pilih dalam Daftar Pemilih Tambahan (DPTb) | D22: LK | E22: 0 | F22: 0 | G22: 0 | H22: 0 | I22: 0 | J22: 0 | K22: 0 | L22: 0 | M22: 0 | N22: 0 | O22: 0 | P22: 0 | Q22: 0 | R22: 1 | S22: 0 | T22: =SUM(E22:S22) -> 1
D23: PR | E23: 0 | F23: 0 | G23: 0 | H23: 0 | I23: 0 | J23: 0 | K23: 0 | L23: 0 | M23: 0 | N23: 0 | O23: 0 | P23: 0 | Q23: 0 | R23: 1 | S23: 0 | T23: =SUM(E23:S23) -> 1
D24: JML | E24: =SUM(E22:E23) -> 0 | F24: =SUM(F22:F23) -> 0 | G24: =SUM(G22:G23) -> 0 | H24: =SUM(H22:H23) -> 0 | I24: =SUM(I22:I23) -> 0 | J24: =SUM(J22:J23) -> 0 | K24: =SUM(K22:K23) -> 0 | L24: =SUM(L22:L23) -> 0 | ... S24: =SUM(S22:S23) -> 0 | T24: =SUM(E24:S24) -> 2
B25: 3. | C25: Jumlah pengguna hak pilih dalam Daftar Pemilih Khusus (DPK) | D25: LK | E25: 2 | F25: 0 | G25: 1 | H25: 0 | I25: 0 | J25: 0 | K25: 1 | L25: 0 | M25: 2 | N25: 0 | O25: 0 | P25: 0 | Q25: 0 | R25: 0 | S25: 0 | T25: =SUM(E25:S25) -> 6
D26: PR | E26: 3 | F26: 0 | G26: 1 | H26: 1 | I26: 0 | J26: 0 | K26: 1 | L26: 0 | M26: 2 | N26: 0 | O26: 0 | P26: 0 | Q26: 0 | R26: 0 | S26: 1 | T26: =SUM(E26:S26) -> 9
D27: JML | E27: =SUM(E25:E26) -> 5 | F27: =SUM(F25:F26) -> 0 | G27: =SUM(G25:G26) -> 2 | H27: =SUM(H25:H26) -> 1 | I27: =SUM(I25:I26) -> 0 | J27: =SUM(J25:J26) -> 0 | K27: =SUM(K25:K26) -> 2 | L27: =SUM(L25:L26) -> 0 | ... S27: =SUM(S25:S26) -> 1 | T27: =SUM(E27:S27) -> 15
B28: 4. | C28: Jumlah Pengguna Hak Pilih (B.1+B.2+B.3) | D28: LK | E28: =SUM(E19,E22,E25) -> 105 | F28: =SUM(F19,F22,F25) -> 97 | G28: =SUM(G19,G22,G25) -> 93 | H28: =SUM(H19,H22,H25) -> 90 | I28: =SUM(I19,I22,I25) -> 88 | J28: =SUM(J19,J22,J25) -> 116 | K28: =SUM(K19,K22,K25) -> 110 | L28: =SUM(L19,L22,L25) -> 109 | ... S28: =SUM(S19,S22,S25) -> 94 | T28: =SUM(E28:S28) -> 1500
D29: PR | E29: =SUM(E20,E23,E26) -> 121 | F29: =SUM(F20,F23,F26) -> 111 | G29: =SUM(G20,G23,G26) -> 111 | H29: =SUM(H20,H23,H26) -> 81 | I29: =SUM(I20,I23,I26) -> 117 | J29: =SUM(J20,J23,J26) -> 112 | K29: =SUM(K20,K23,K26) -> 108 | L29: =SUM(L20,L23,L26) -> 106 | ... S29: =SUM(S20,S23,S26) -> 108 | T29: =SUM(E29:S29) -> 1652
D30: JML | E30: =SUM(E28:E29) -> 226 | F30: =SUM(F28:F29) -> 208 | G30: =SUM(G28:G29) -> 204 | H30: =SUM(H28:H29) -> 171 | I30: =SUM(I28:I29) -> 205 | J30: =SUM(J28:J29) -> 228 | K30: =SUM(K28:K29) -> 218 | L30: =SUM(L28:L29) -> 215 | ... S30: =SUM(S28:S29) -> 202 | T30: =SUM(E30:S30) -> 3152
A32: II | B32: DATA PENGGUNAAN SURAT SUARA
A33: 1 | B33: Jumlah surat suara yang diterima, termasuk surat suara cadangan 2,5% dari DPT | E33: 286 | F33: 287 | G33: 292 | H33: 253 | I33: 271 | J33: 282 | K33: 272 | L33: 292 | M33: 284 | N33: 255 | O33: 248 | P33: 292 | Q33: 279 | R33: 286 | S33: 279 | T33: =SUM(E33:S33) -> 4158
A34: 2 | B34: Jumlah surat suara yang digunakan | E34: 226 | F34: 208 | G34: 204 | H34: 171 | I34: 205 | J34: 228 | K34: 218 | L34: 215 | M34: 211 | N34: 192 | O34: 184 | P34: 236 | Q34: 227 | R34: 225 | S34: 202 | T34: =SUM(E34:S34) -> 3152
A35: 3 | B35: Jumlah surat suara dikembalikan oleh pemilih (karena rusak atau keliru coblos) | E35: 0 | F35: 2 | G35: 0 | H35: 0 | I35: 0 | J35: 0 | K35: 0 | L35: 1 | M35: 1 | N35: 0 | O35: 0 | P35: 1 | Q35: 0 | R35: 0 | S35: 0 | T35: =SUM(E35:S35) -> 5
A36: 4 | B36: Jumlah surat suara yang tidak digunakan/tidak terpakai, termasuk sisa surat suara cadangan | E36: =E33-(E34+E35) -> 60 | F36: =F33-(F34+F35) -> 77 | G36: =G33-(G34+G35) -> 88 | H36: =H33-(H34+H35) -> 82 | I36: =I33-(I34+I35) -> 66 | J36: =J33-(J34+J35) -> 54 | K36: =K33-(K34+K35) -> 54 | L36: =L33-(L34+L35) -> 76 | ... S36: =S33-(S34+S35) -> 77 | T36: =SUM(E36:S36) -> 1001
A38: III | B38: DATA PEMILIH DISABILITAS
B39: Jumlah seluruh Pemilih disabilitas yang menggunakan hak pilih | D39: LK | E39: 0 | F39: 0 | G39: 0 | H39: 0 | I39: 0 | J39: 0 | K39: 0 | L39: 0 | M39: 0 | N39: 2 | O39: 0 | P39: 0 | Q39: 0 | R39: 0 | S39: 0 | T39: =SUM(E39:S39) -> 2
D40: PR | E40: 0 | F40: 0 | G40: 0 | H40: 0 | I40: 0 | J40: 0 | K40: 0 | L40: 0 | M40: 0 | N40: 2 | O40: 0 | P40: 0 | Q40: 0 | R40: 0 | S40: 0 | T40: =SUM(E40:S40) -> 2
D41: JML | E41: =SUM(E39:E40) -> 0 | F41: =SUM(F39:F40) -> 0 | G41: =SUM(G39:G40) -> 0 | H41: =SUM(H39:H40) -> 0 | I41: =SUM(I39:I40) -> 0 | J41: =SUM(J39:J40) -> 0 | K41: =SUM(K39:K40) -> 0 | L41: =SUM(L39:L40) -> 0 | ... S41: =SUM(S39:S40) -> 0 | T41: =SUM(E41:S41) -> 4
A43: IV | B43: DATA RINCIAN PEROLEHAN SUARA PASANGAN CALON BUPATI DAN WAKIL BUPATI
A44: NOMOR DAN NAMA CALON
A45: A.1 | B45: 1. | C45: Partai Kebangkitan Bangsa | E45: 13 | F45: 7 | G45: 3 | H45: 3 | I45: 2 | J45: 4 | K45: 6 | L45: 2 | M45: 9 | N45: 14 | O45: 9 | P45: 17 | Q45: 10 | R45: 11 | S45: 7 | T45: =SUM(E45:S45) -> 117
A46: A.2 | C46: 1. Dra. Hj. MA`MULAH HARUN, M.Pd.I. | E46: 11 | F46: 10 | G46: 3 | H46: 3 | I46: 7 | J46: 5 | K46: 7 | L46: 11 | M46: 12 | N46: 25 | O46: 36 | P46: 57 | Q46: 28 | R46: 35 | S46: 11 | T46: =SUM(E46:S46) -> 261
C47: 2. UBAIDILLAH, S.Fil.I. | E47: 4 | F47: 4 | G47: 2 | H47: 1 | I47: 1 | J47: 0 | K47: 1 | L47: 1 | M47: 6 | N47: 0 | O47: 1 | P47: 1 | Q47: 3 | R47: 4 | S47: 2 | T47: =SUM(E47:S47) -> 31
C48: 3. Ir. H. YOYOK MULYADI, M.Si. | E48: 0 | F48: 1 | G48: 2 | H48: 0 | I48: 1 | J48: 0 | K48: 0 | L48: 0 | M48: 1 | N48: 0 | O48: 3 | P48: 1 | Q48: 1 | R48: 0 | S48: 0 | T48: =SUM(E48:S48) -> 10
C49: 4. KHOIRUL ANWAR, S.Fil.I. | E49: 3 | F49: 2 | G49: 2 | H49: 1 | I49: 1 | J49: 1 | K49: 2 | L49: 4 | M49: 2 | N49: 2 | O49: 0 | P49: 1 | Q49: 0 | R49: 2 | S49: 1 | T49: =SUM(E49:S49) -> 24
C50: 5. ARIF WIJAKSANA | E50: 3 | F50: 10 | G50: 2 | H50: 0 | I50: 0 | J50: 1 | K50: 1 | L50: 0 | M50: 0 | N50: 5 | O50: 4 | P50: 11 | Q50: 1 | R50: 1 | S50: 1 | T50: =SUM(E50:S50) -> 40
C51: 6. Dr. SITI YUMNAH | E51: 0 | F51: 0 | G51: 0 | H51: 0 | I51: 0 | J51: 1 | K51: 1 | L51: 2 | M51: 1 | N51: 0 | O51: 1 | P51: 1 | Q51: 0 | R51: 1 | S51: 1 | T51: =SUM(E51:S51) -> 9
...

Sheet KEBAMAN
C2: Kecamatan | D2: SRONO
C3: Kabupaten | D3: BANYUWANGI
C4: Provinsi | D4: JAWA TIMUR
C9: Kelurahan | D9: KEBAMAN
A12: I | B12: DATA PEMILIH DAN PENGGUNAAN HAK PILIH | AW12: JUMLAH AKHIR
A13: A | B13: DATA PEMILIH | E13: TPS 001 | F13: TPS 002 | G13: TPS 003 | H13: TPS 004 | I13: TPS 005 | J13: TPS 006 | K13: TPS 007 | L13: TPS 008 | M13: TPS 009 | N13: TPS 010 | O13: TPS 011 | P13: TPS 012 | Q13: TPS 013 | R13: TPS 014 | S13: TPS 015 | T13: TPS 016 | U13: TPS 017 | V13: TPS 018 | W13: TPS 019 | X13: TPS 020 | Y13: TPS 021 | Z13: TPS 022 | AA13: TPS 023 | AB13: TPS 024 | AC13: TPS 025 | AD13: TPS 026 | AE13: TPS 027 | AF13: TPS 028 | AG13: TPS 029 | AH13: TPS 030 | AI13: TPS 031 | AJ13: TPS 032 | AK13: TPS 033 | AL13: TPS 034 | AM13: TPS 035 | AN13: TPS 036 | AO13: TPS 037 | AP13: TPS 038 | AQ13: TPS 039 | AR13: TPS 040 | AS13: TPS 041 | AT13: TPS 042 | AU13: TPS 043 | AV13: TPS 044
B14: Jumlah Pemilih dalam Daftar Pemilih Tetap (DPT) | D14: LK | E14: 122 | F14: 134 | G14: 140 | H14: 123 | I14: 120 | J14: 138 | K14: 136 | L14: 141 | M14: 141 | N14: 117 | O14: 136 | P14: 133 | Q14: 136 | R14: 138 | S14: 134 | T14: 129 | U14: 148 | V14: 127 | W14: 122 | X14: 135 | Y14: 108 | Z14: 124 | AA14: 109 | AB14: 133 | AC14: 129 | AD14: 135 | AE14: 141 | AF14: 127 | AG14: 123 | AH14: 146 | AI14: 111 | AJ14: 117 | AK14: 128 | AL14: 131 | AM14: 138 | AN14: 128 | AO14: 142 | AP14: 140 | AQ14: 141 | AR14: 130 | AS14: 127 | AT14: 131 | AU14: 147 | AV14: 147 | AW14: =SUM(E14:AV14) -> 5783
D15: PR | E15: 129 | F15: 138 | G15: 133 | H15: 132 | I15: 152 | J15: 135 | K15: 129 | L15: 137 | M15: 138 | N15: 144 | O15: 134 | P15: 132 | Q15: 129 | R15: 149 | S15: 131 | T15: 134 | U15: 139 | V15: 141 | W15: 133 | X15: 141 | Y15: 129 | Z15: 133 | AA15: 131 | AB15: 139 | AC15: 138 | AD15: 140 | AE15: 123 | AF15: 145 | AG15: 133 | AH15: 140 | AI15: 102 | AJ15: 131 | AK15: 141 | AL15: 148 | AM15: 136 | AN15: 137 | AO15: 145 | AP15: 147 | AQ15: 138 | AR15: 143 | AS15: 133 | AT15: 133 | AU15: 139 | AV15: 127 | AW15: =SUM(E15:AV15) -> 5981
D16: JML | E16: =SUM(E14:E15) -> 251 | F16: =SUM(F14:F15) -> 272 | G16: =SUM(G14:G15) -> 273 | H16: =SUM(H14:H15) -> 255 | I16: =SUM(I14:I15) -> 272 | J16: =SUM(J14:J15) -> 273 | K16: =SUM(K14:K15) -> 265 | L16: =SUM(L14:L15) -> 278 | ... AV16: =SUM(AV14:AV15) -> 274 | AW16: =SUM(E16:AV16) -> 11764
A18: B | B18: PENGGUNA HAK PILIH
B19: 1. | C19: Jumlah pengguna hak pilih dalam Daftar Pemilih Tetap (DPT) | D19: LK | E19: 87 | F19: 95 | G19: 99 | H19: 89 | I19: 83 | J19: 106 | K19: 95 | L19: 96 | M19: 92 | N19: 87 | O19: 92 | P19: 104 | Q19: 93 | R19: 102 | S19: 96 | T19: 85 | U19: 110 | V19: 104 | W19: 97 | X19: 95 | Y19: 80 | Z19: 97 | AA19: 71 | AB19: 93 | AC19: 104 | AD19: 82 | AE19: 89 | AF19: 90 | AG19: 89 | AH19: 98 | AI19: 83 | AJ19: 87 | AK19: 88 | AL19: 96 | AM19: 91 | AN19: 99 | AO19: 111 | AP19: 108 | AQ19: 114 | AR19: 93 | AS19: 93 | AT19: 110 | AU19: 96 | AV19: 105 | AW19: =SUM(E19:AV19) -> 4174
D20: PR | E20: 105 | F20: 117 | G20: 113 | H20: 112 | I20: 110 | J20: 110 | K20: 99 | L20: 116 | M20: 104 | N20: 105 | O20: 101 | P20: 107 | Q20: 108 | R20: 133 | S20: 102 | T20: 102 | U20: 118 | V20: 121 | W20: 113 | X20: 112 | Y20: 100 | Z20: 103 | AA20: 105 | AB20: 107 | AC20: 113 | AD20: 106 | AE20: 104 | AF20: 116 | AG20: 104 | AH20: 112 | AI20: 81 | AJ20: 98 | AK20: 103 | AL20: 116 | AM20: 111 | AN20: 106 | AO20: 118 | AP20: 111 | AQ20: 107 | AR20: 115 | AS20: 107 | AT20: 101 | AU20: 108 | AV20: 99 | AW20: =SUM(E20:AV20) -> 4759
D21: JML | E21: =SUM(E19:E20) -> 192 | F21: =SUM(F19:F20) -> 212 | G21: =SUM(G19:G20) -> 212 | H21: =SUM(H19:H20) -> 201 | I21: =SUM(I19:I20) -> 193 | J21: =SUM(J19:J20) -> 216 | K21: =SUM(K19:K20) -> 194 | L21: =SUM(L19:L20) -> 212 | ... AV21: =SUM(AV19:AV20) -> 204 | AW21: =SUM(E21:AV21) -> 8933
B22: 2. | C22: Jumlah pengguna hak pilih dalam Daftar Pemilih Tambahan (DPTb) | D22: LK | E22: 0 | F22: 0 | G22: 0 | H22: 0 | I22: 0 | J22: 0 | K22: 0 | L22: 0 | M22: 0 | N22: 0 | O22: 0 | P22: 0 | Q22: 0 | R22: 0 | S22: 0 | T22: 0 | U22: 0 | V22: 0 | W22: 0 | X22: 0 | Y22: 0 | Z22: 0 | AA22: 0 | AB22: 0 | AC22: 1 | AD22: 0 | AE22: 0 | AF22: 0 | AG22: 0 | AH22: 0 | AI22: 0 | AJ22: 0 | AK22: 0 | AL22: 0 | AM22: 0 | AN22: 0 | AO22: 0 | AP22: 0 | AQ22: 0 | AR22: 0 | AS22: 0 | AT22: 0 | AU22: 1 | AV22: 0 | AW22: =SUM(E22:AV22) -> 2
D23: PR | E23: 0 | F23: 0 | G23: 0 | H23: 0 | I23: 0 | J23: 1 | K23: 0 | L23: 0 | M23: 0 | N23: 0 | O23: 0 | P23: 0 | Q23: 0 | R23: 0 | S23: 0 | T23: 0 | U23: 0 | V23: 0 | W23: 0 | X23: 0 | Y23: 0 | Z23: 0 | AA23: 0 | AB23: 0 | AC23: 2 | AD23: 0 | AE23: 0 | AF23: 0 | AG23: 0 | AH23: 0 | AI23: 0 | AJ23: 0 | AK23: 0 | AL23: 0 | AM23: 0 | AN23: 0 | AO23: 0 | AP23: 0 | AQ23: 0 | AR23: 0 | AS23: 0 | AT23: 0 | AU23: 0 | AV23: 0 | AW23: =SUM(E23:AV23) -> 3
D24: JML | E24: =SUM(E22:E23) -> 0 | F24: =SUM(F22:F23) -> 0 | G24: =SUM(G22:G23) -> 0 | H24: =SUM(H22:H23) -> 0 | I24: =SUM(I22:I23) -> 0 | J24: =SUM(J22:J23) -> 1 | K24: =SUM(K22:K23) -> 0 | L24: =SUM(L22:L23) -> 0 | ... AV24: =SUM(AV22:AV23) -> 0 | AW24: =SUM(E24:AV24) -> 5
B25: 3. | C25: Jumlah pengguna hak pilih dalam Daftar Pemilih Khusus (DPK) | D25: LK | E25: 0 | F25: 2 | G25: 0 | H25: 3 | I25: 3 | J25: 1 | K25: 1 | L25: 1 | M25: 1 | N25: 2 | O25: 3 | P25: 0 | Q25: 1 | R25: 1 | S25: 5 | T25: 1 | U25: 2 | V25: 0 | W25: 4 | X25: 4 | Y25: 3 | Z25: 5 | AA25: 4 | AB25: 0 | AC25: 2 | AD25: 3 | AE25: 4 | AF25: 2 | AG25: 7 | AH25: 5 | AI25: 1 | AJ25: 3 | AK25: 0 | AL25: 3 | AM25: 6 | AN25: 3 | AO25: 3 | AP25: 1 | AQ25: 1 | AR25: 1 | AS25: 0 | AT25: 2 | AU25: 0 | AV25: 8 | AW25: =SUM(E25:AV25) -> 102
D26: PR | E26: 0 | F26: 2 | G26: 1 | H26: 4 | I26: 2 | J26: 0 | K26: 1 | L26: 1 | M26: 0 | N26: 5 | O26: 5 | P26: 0 | Q26: 4 | R26: 4 | S26: 3 | T26: 2 | U26: 2 | V26: 3 | W26: 2 | X26: 3 | Y26: 0 | Z26: 3 | AA26: 6 | AB26: 2 | AC26: 1 | AD26: 2 | AE26: 10 | AF26: 3 | AG26: 5 | AH26: 5 | AI26: 1 | AJ26: 4 | AK26: 0 | AL26: 9 | AM26: 3 | AN26: 5 | AO26: 1 | AP26: 2 | AQ26: 3 | AR26: 1 | AS26: 0 | AT26: 2 | AU26: 1 | AV26: 20 | AW26: =SUM(E26:AV26) -> 133
D27: JML | E27: =SUM(E25:E26) -> 0 | F27: =SUM(F25:F26) -> 4 | G27: =SUM(G25:G26) -> 1 | H27: =SUM(H25:H26) -> 7 | I27: =SUM(I25:I26) -> 5 | J27: =SUM(J25:J26) -> 1 | K27: =SUM(K25:K26) -> 2 | L27: =SUM(L25:L26) -> 2 | ... AV27: =SUM(AV25:AV26) -> 28 | AW27: =SUM(E27:AV27) -> 235
B28: 4. | C28: Jumlah Pengguna Hak Pilih (B.1+B.2+B.3) | D28: LK | E28: =SUM(E19,E22,E25) -> 87 | F28: =SUM(F19,F22,F25) -> 97 | G28: =SUM(G19,G22,G25) -> 99 | H28: =SUM(H19,H22,H25) -> 92 | I28: =SUM(I19,I22,I25) -> 86 | J28: =SUM(J19,J22,J25) -> 107 | K28: =SUM(K19,K22,K25) -> 96 | L28: =SUM(L19,L22,L25) -> 97 | ... AV28: =SUM(AV19,AV22,AV25) -> 113 | AW28: =SUM(E28:AV28) -> 4278
D29: PR | E29: =SUM(E20,E23,E26) -> 105 | F29: =SUM(F20,F23,F26) -> 119 | G29: =SUM(G20,G23,G26) -> 114 | H29: =SUM(H20,H23,H26) -> 116 | I29: =SUM(I20,I23,I26) -> 112 | J29: =SUM(J20,J23,J26) -> 111 | K29: =SUM(K20,K23,K26) -> 100 | L29: =SUM(L20,L23,L26) -> 117 | ... AV29: =SUM(AV20,AV23,AV26) -> 119 | AW29: =SUM(E29:AV29) -> 4895
D30: JML | E30: =SUM(E28:E29) -> 192 | F30: =SUM(F28:F29) -> 216 | G30: =SUM(G28:G29) -> 213 | H30: =SUM(H28:H29) -> 208 | I30: =SUM(I28:I29) -> 198 | J30: =SUM(J28:J29) -> 218 | K30: =SUM(K28:K29) -> 196 | L30: =SUM(L28:L29) -> 214 | ... AV30: =SUM(AV28:AV29) -> 232 | AW30: =SUM(E30:AV30) -> 9173
A32: II | B32: DATA PENGGUNAAN SURAT SUARA
A33: 1 | B33: Jumlah surat suara yang diterima, termasuk surat suara cadangan 2,5% dari DPT | E33: 256 | F33: 278 | G33: 279 | H33: 261 | I33: 278 | J33: 281 | K33: 271 | L33: 285 | M33: 284 | N33: 267 | O33: 276 | P33: 271 | Q33: 271 | R33: 293 | S33: 271 | T33: 249 | U33: 293 | V33: 274 | W33: 261 | X33: 282 | Y33: 241 | Z33: 243 | AA33: 245 | AB33: 278 | AC33: 263 | AD33: 256 | AE33: 255 | AF33: 278 | AG33: 272 | AH33: 292 | AI33: 218 | AJ33: 243 | AK33: 275 | AL33: 285 | AM33: 280 | AN33: 272 | AO33: 293 | AP33: 292 | AQ33: 283 | AR33: 279 | AS33: 261 | AT33: 271 | AU33: 280 | AV33: 292 | AW33: =SUM(E33:AV33) -> 11928
A34: 2 | B34: Jumlah surat suara yang digunakan | E34: 192 | F34: 216 | G34: 213 | H34: 208 | I34: 198 | J34: 218 | K34: 196 | L34: 214 | M34: 197 | N34: 199 | O34: 201 | P34: 211 | Q34: 206 | R34: 240 | S34: 206 | T34: 190 | U34: 232 | V34: 228 | W34: 216 | X34: 214 | Y34: 183 | Z34: 208 | AA34: 186 | AB34: 202 | AC34: 220 | AD34: 196 | AE34: 207 | AF34: 211 | AG34: 205 | AH34: 220 | AI34: 166 | AJ34: 192 | AK34: 191 | AL34: 224 | AM34: 211 | AN34: 213 | AO34: 233 | AP34: 222 | AQ34: 225 | AR34: 210 | AS34: 200 | AT34: 215 | AU34: 206 | AV34: 232 | AW34: =SUM(E34:AV34) -> 9173
A35: 3 | B35: Jumlah surat suara dikembalikan oleh pemilih (karena rusak atau keliru coblos) | E35: 0 | F35: 1 | G35: 0 | H35: 0 | I35: 0 | J35: 0 | K35: 2 | L35: 0 | M35: 0 | N35: 0 | O35: 0 | P35: 0 | Q35: 3 | R35: 0 | S35: 2 | T35: 1 | U35: 0 | V35: 0 | W35: 0 | X35: 0 | Y35: 0 | Z35: 0 | AA35: 0 | AB35: 1 | AC35: 0 | AD35: 0 | AE35: 0 | AF35: 0 | AG35: 0 | AH35: 0 | AI35: 0 | AJ35: 1 | AK35: 0 | AL35: 1 | AM35: 0 | AN35: 0 | AO35: 0 | AP35: 0 | AQ35: 3 | AR35: 0 | AS35: 1 | AT35: 1 | AU35: 1 | AV35: 0 | AW35: =SUM(E35:AV35) -> 18
A36: 4 | B36: Jumlah surat suara yang tidak digunakan/tidak terpakai, termasuk sisa surat suara cadangan | E36: =E33-(E34+E35) -> 64 | F36: =F33-(F34+F35) -> 61 | G36: =G33-(G34+G35) -> 66 | H36: =H33-(H34+H35) -> 53 | I36: =I33-(I34+I35) -> 80 | J36: =J33-(J34+J35) -> 63 | K36: =K33-(K34+K35) -> 73 | L36: =L33-(L34+L35) -> 71 | ... AV36: =AV33-(AV34+AV35) -> 60 | AW36: =SUM(E36:AV36) -> 2737
A38: III | B38: DATA PEMILIH DISABILITAS
B39: Jumlah seluruh Pemilih disabilitas yang menggunakan hak pilih | D39: LK | P39: 2 | AH39: 3 | AW39: =SUM(E39:AV39) -> 5
D40: PR | P40: 2 | AH40: 3 | AW40: =SUM(E40:AV40) -> 5
D41: JML | E41: =SUM(E39:E40) -> 0 | F41: =SUM(F39:F40) -> 0 | G41: =SUM(G39:G40) -> 0 | H41: =SUM(H39:H40) -> 0 | I41: =SUM(I39:I40) -> 0 | J41: =SUM(J39:J40) -> 0 | K41: =SUM(K39:K40) -> 0 | L41: =SUM(L39:L40) -> 0 | ... AV41: =SUM(AV39:AV40) -> 0 | AW41: =SUM(E41:AV41) -> 10
A43: IV | B43: DATA RINCIAN PEROLEHAN SUARA PASANGAN CALON BUPATI DAN WAKIL BUPATI
A44: NOMOR DAN NAMA CALON
A45: A.1 | B45: 1. | C45: Partai Kebangkitan Bangsa | E45: 1 | F45: 4 | G45: 5 | H45: 13 | I45: 20 | J45: 20 | K45: 4 | L45: 7 | M45: 6 | N45: 7 | O45: 3 | P45: 3 | Q45: 5 | R45: 3 | S45: 6 | T45: 2 | U45: 10 | V45: 15 | W45: 11 | X45: 1 | Y45: 10 | Z45: 7 | AA45: 10 | AB45: 2 | AC45: 6 | AD45: 4 | AE45: 1 | AF45: 3 | AG45: 5 | AH45: 2 | AI45: 3 | AJ45: 2 | AK45: 7 | AL45: 5 | AM45: 4 | AN45: 1 | AO45: 4 | AP45: 6 | AQ45: 5 | AR45: 0 | AS45: 4 | AT45: 5 | AU45: 2 | AV45: 0 | AW45: =SUM(E45:AV45) -> 244
A46: A.2 | C46: 1. Dra. Hj. MA`MULAH HARUN, M.Pd.I. | E46: 7 | F46: 5 | G46: 21 | H46: 6 | I46: 34 | J46: 23 | K46: 9 | L46: 20 | M46: 5 | N46: 5 | O46: 1 | P46: 7 | Q46: 2 | R46: 11 | S46: 14 | T46: 5 | U46: 37 | V46: 41 | W46: 14 | X46: 6 | Y46: 7 | Z46: 16 | AA46: 3 | AB46: 2 | AC46: 21 | AD46: 4 | AE46: 6 | AF46: 3 | AG46: 10 | AH46: 12 | AI46: 5 | AJ46: 4 | AK46: 2 | AL46: 8 | AM46: 8 | AN46: 5 | AO46: 7 | AP46: 3 | AQ46: 18 | AR46: 5 | AS46: 1 | AT46: 3 | AU46: 2 | AV46: 9 | AW46: =SUM(E46:AV46) -> 437
C47: 2. UBAIDILLAH, S.Fil.I. | E47: 3 | F47: 1 | G47: 1 | H47: 2 | I47: 1 | J47: 4 | K47: 1 | L47: 2 | M47: 1 | N47: 0 | O47: 1 | P47: 0 | Q47: 0 | R47: 1 | S47: 2 | T47: 2 | U47: 2 | V47: 7 | W47: 3 | X47: 1 | Y47: 0 | Z47: 2 | AA47: 1 | AB47: 0 | AC47: 0 | AD47: 1 | AE47: 3 | AF47: 0 | AG47: 2 | AH47: 2 | AI47: 1 | AJ47: 0 | AK47: 0 | AL47: 5 | AM47: 4 | AN47: 1 | AO47: 1 | AP47: 0 | AQ47: 2 | AR47: 0 | AS47: 1 | AT47: 0 | AU47: 1 | AV47: 2 | AW47: =SUM(E47:AV47) -> 64
C48: 3. Ir. H. YOYOK MULYADI, M.Si. | E48: 0 | F48: 0 | G48: 0 | H48: 0 | I48: 0 | J48: 1 | K48: 0 | L48: 0 | M48: 0 | N48: 1 | O48: 0 | P48: 1 | Q48: 0 | R48: 0 | S48: 1 | T48: 1 | U48: 0 | V48: 1 | W48: 0 | X48: 2 | Y48: 0 | Z48: 0 | AA48: 0 | AB48: 0 | AC48: 1 | AD48: 0 | AE48: 1 | AF48: 0 | AG48: 0 | AH48: 1 | AI48: 1 | AJ48: 1 | AK48: 0 | AL48: 0 | AM48: 1 | AN48: 0 | AO48: 0 | AP48: 0 | AQ48: 1 | AR48: 1 | AS48: 0 | AT48: 0 | AU48: 0 | AV48: 0 | AW48: =SUM(E48:AV48) -> 16
C49: 4. KHOIRUL ANWAR, S.Fil.I. | E49: 1 | F49: 1 | G49: 0 | H49: 0 | I49: 2 | J49: 0 | K49: 1 | L49: 2 | M49: 1 | N49: 2 | O49: 0 | P49: 1 | Q49: 0 | R49: 0 | S49: 1 | T49: 6 | U49: 8 | V49: 2 | W49: 1 | X49: 1 | Y49: 1 | Z49: 2 | AA49: 1 | AB49: 0 | AC49: 0 | AD49: 0 | AE49: 1 | AF49: 0 | AG49: 2 | AH49: 1 | AI49: 3 | AJ49: 0 | AK49: 0 | AL49: 0 | AM49: 1 | AN49: 2 | AO49: 1 | AP49: 0 | AQ49: 0 | AR49: 0 | AS49: 2 | AT49: 0 | AU49: 0 | AV49: 2 | AW49: =SUM(E49:AV49) -> 49
C50: 5. ARIF WIJAKSANA | E50: 2 | F50: 0 | G50: 1 | H50: 3 | I50: 0 | J50: 3 | K50: 2 | L50: 0 | M50: 0 | N50: 0 | O50: 0 | P50: 1 | Q50: 1 | R50: 0 | S50: 0 | T50: 0 | U50: 4 | V50: 5 | W50: 1 | X50: 1 | Y50: 1 | Z50: 0 | AA50: 0 | AB50: 0 | AC50: 0 | AD50: 1 | AE50: 0 | AF50: 0 | AG50: 1 | AH50: 2 | AI50: 1 | AJ50: 0 | AK50: 0 | AL50: 2 | AM50: 0 | AN50: 0 | AO50: 1 | AP50: 0 | AQ50: 2 | AR50: 2 | AS50: 1 | AT50: 0 | AU50: 0 | AV50: 3 | AW50: =SUM(E50:AV50) -> 41
C51: 6. Dr. SITI YUMNAH | E51: 0 | F51: 0 | G51: 0 | H51: 1 | I51: 0 | J51: 1 | K51: 0 | L51: 1 | M51: 0 | N51: 0 | O51: 0 | P51: 0 | Q51: 0 | R51: 0 | S51: 0 | T51: 0 | U51: 3 | V51: 1 | W51: 1 | X51: 1 | Y51: 0 | Z51: 1 | AA51: 0 | AB51: 0 | AC51: 0 | AD51: 1 | AE51: 0 | AF51: 0 | AG51: 0 | AH51: 0 | AI51: 0 | AJ51: 0 | AK51: 0 | AL51: 0 | AM51: 0 | AN51: 0 | AO51: 0 | AP51: 0 | AQ51: 2 | AR51: 1 | AS51: 0 | AT51: 0 | AU51: 0 | AV51: 0 | AW51: =SUM(E51:AV51) -> 14
...

Sheet SUMBERSARI
C2: Kecamatan | D2: SRONO
C3: Kabupaten | D3: BANYUWANGI
C4: Provinsi | D4: JAWA TIMUR
C9: Kelurahan | D9: SUMBERSARI
A12: I | B12: DATA PEMILIH DAN PENGGUNAAN HAK PILIH | AH12: JUMLAH AKHIR
A13: A | B13: DATA PEMILIH | E13: TPS 001 | F13: TPS 002 | G13: TPS 003 | H13: TPS 004 | I13: TPS 005 | J13: TPS 006 | K13: TPS 007 | L13: TPS 008 | M13: TPS 009 | N13: TPS 010 | O13: TPS 011 | P13: TPS 012 | Q13: TPS 013 | R13: TPS 014 | S13: TPS 015 | T13: TPS 016 | U13: TPS 017 | V13: TPS 018 | W13: TPS 019 | X13: TPS 020 | Y13: TPS 021 | Z13: TPS 022 | AA13: TPS 023 | AB13: TPS 024 | AC13: TPS 025 | AD13: TPS 026 | AE13: TPS 027 | AF13: TPS 028 | AG13: TPS 029
B14: Jumlah Pemilih dalam Daftar Pemilih Tetap (DPT) | D14: LK | E14: 147 | F14: 147 | G14: 148 | H14: 148 | I14: 133 | J14: 145 | K14: 143 | L14: 127 | M14: 135 | N14: 137 | O14: 145 | P14: 148 | Q14: 151 | R14: 147 | S14: 151 | T14: 141 | U14: 129 | V14: 143 | W14: 141 | X14: 134 | Y14: 144 | Z14: 147 | AA14: 131 | AB14: 140 | AC14: 146 | AD14: 137 | AE14: 137 | AF14: 117 | AG14: 71 | AH14: =SUM(E14:AG14) -> 4010
D15: PR | E15: 132 | F15: 131 | G15: 143 | H15: 148 | I15: 146 | J15: 137 | K15: 138 | L15: 130 | M15: 149 | N15: 137 | O15: 153 | P15: 149 | Q15: 139 | R15: 150 | S15: 139 | T15: 152 | U15: 145 | V15: 127 | W15: 132 | X15: 139 | Y15: 148 | Z15: 135 | AA15: 141 | AB15: 136 | AC15: 140 | AD15: 133 | AE15: 139 | AF15: 94 | AG15: 75 | AH15: =SUM(E15:AG15) -> 3957
D16: JML | E16: =SUM(E14:E15) -> 279 | F16: =SUM(F14:F15) -> 278 | G16: =SUM(G14:G15) -> 291 | H16: =SUM(H14:H15) -> 296 | I16: =SUM(I14:I15) -> 279 | J16: =SUM(J14:J15) -> 282 | K16: =SUM(K14:K15) -> 281 | L16: =SUM(L14:L15) -> 257 | ... AG16: =SUM(AG14:AG15) -> 146 | AH16: =SUM(E16:AG16) -> 7967
A18: B | B18: PENGGUNA HAK PILIH
B19: 1. | C19: Jumlah pengguna hak pilih dalam Daftar Pemilih Tetap (DPT) | D19: LK | E19: 115 | F19: 109 | G19: 124 | H19: 112 | I19: 102 | J19: 101 | K19: 107 | L19: 87 | M19: 104 | N19: 101 | O19: 104 | P19: 95 | Q19: 95 | R19: 113 | S19: 103 | T19: 107 | U19: 94 | V19: 110 | W19: 113 | X19: 102 | Y19: 107 | Z19: 108 | AA19: 96 | AB19: 104 | AC19: 113 | AD19: 101 | AE19: 102 | AF19: 88 | AG19: 53 | AH19: =SUM(E19:AG19) -> 2970
D20: PR | E20: 109 | F20: 104 | G20: 120 | H20: 123 | I20: 116 | J20: 106 | K20: 109 | L20: 106 | M20: 121 | N20: 108 | O20: 122 | P20: 122 | Q20: 106 | R20: 130 | S20: 106 | T20: 117 | U20: 122 | V20: 108 | W20: 111 | X20: 112 | Y20: 124 | Z20: 102 | AA20: 104 | AB20: 113 | AC20: 115 | AD20: 105 | AE20: 117 | AF20: 71 | AG20: 60 | AH20: =SUM(E20:AG20) -> 3189
D21: JML | E21: =SUM(E19:E20) -> 224 | F21: =SUM(F19:F20) -> 213 | G21: =SUM(G19:G20) -> 244 | H21: =SUM(H19:H20) -> 235 | I21: =SUM(I19:I20) -> 218 | J21: =SUM(J19:J20) -> 207 | K21: =SUM(K19:K20) -> 216 | L21: =SUM(L19:L20) -> 193 | ... AG21: =SUM(AG19:AG20) -> 113 | AH21: =SUM(E21:AG21) -> 6159
B22: 2. | C22: Jumlah pengguna hak pilih dalam Daftar Pemilih Tambahan (DPTb) | D22: LK | E22: 0 | F22: 0 | G22: 0 | H22: 0 | I22: 0 | J22: 0 | K22: 0 | L22: 0 | M22: 0 | N22: 0 | O22: 0 | P22: 0 | Q22: 0 | R22: 0 | S22: 0 | T22: 0 | U22: 0 | V22: 0 | W22: 0 | X22: 0 | Y22: 0 | Z22: 1 | AA22: 0 | AB22: 0 | AC22: 0 | AD22: 0 | AE22: 0 | AF22: 0 | AG22: 0 | AH22: =SUM(E22:AG22) -> 1
D23: PR | E23: 0 | F23: 0 | G23: 0 | H23: 0 | I23: 0 | J23: 0 | K23: 0 | L23: 0 | M23: 0 | N23: 0 | O23: 1 | P23: 0 | Q23: 3 | R23: 0 | S23: 0 | T23: 0 | U23: 0 | V23: 0 | W23: 0 | X23: 0 | Y23: 0 | Z23: 0 | AA23: 0 | AB23: 0 | AC23: 0 | AD23: 0 | AE23: 0 | AF23: 0 | AG23: 0 | AH23: =SUM(E23:AG23) -> 4
D24: JML | E24: =SUM(E22:E23) -> 0 | F24: =SUM(F22:F23) -> 0 | G24: =SUM(G22:G23) -> 0 | H24: =SUM(H22:H23) -> 0 | I24: =SUM(I22:I23) -> 0 | J24: =SUM(J22:J23) -> 0 | K24: =SUM(K22:K23) -> 0 | L24: =SUM(L22:L23) -> 0 | ... AG24: =SUM(AG22:AG23) -> 0 | AH24: =SUM(E24:AG24) -> 5
B25: 3. | C25: Jumlah pengguna hak pilih dalam Daftar Pemilih Khusus (DPK) | D25: LK | E25: 1 | F25: 1 | G25: 0 | H25: 5 | I25: 0 | J25: 5 | K25: 1 | L25: 2 | M25: 0 | N25: 1 | O25: 0 | P25: 0 | Q25: 1 | R25: 0 | S25: 1 | T25: 5 | U25: 6 | V25: 1 | W25: 0 | X25: 2 | Y25: 0 | Z25: 1 | AA25: 1 | AB25: 2 | AC25: 0 | AD25: 2 | AE25: 2 | AF25: 2 | AG25: 0 | AH25: =SUM(E25:AG25) -> 42
D26: PR | E26: 4 | F26: 1 | G26: 3 | H26: 1 | I26: 1 | J26: 2 | K26: 0 | L26: 1 | M26: 3 | N26: 2 | O26: 0 | P26: 0 | Q26: 8 | R26: 0 | S26: 5 | T26: 7 | U26: 2 | V26: 5 | W26: 2 | X26: 5 | Y26: 0 | Z26: 3 | AA26: 5 | AB26: 3 | AC26: 0 | AD26: 4 | AE26: 3 | AF26: 1 | AG26: 0 | AH26: =SUM(E26:AG26) -> 71
D27: JML | E27: =SUM(E25:E26) -> 5 | F27: =SUM(F25:F26) -> 2 | G27: =SUM(G25:G26) -> 3 | H27: =SUM(H25:H26) -> 6 | I27: =SUM(I25:I26) -> 1 | J27: =SUM(J25:J26) -> 7 | K27: =SUM(K25:K26) -> 1 | L27: =SUM(L25:L26) -> 3 | ... AG27: =SUM(AG25:AG26) -> 0 | AH27: =SUM(E27:AG27) -> 113
B28: 4. | C28: Jumlah Pengguna Hak Pilih (B.1+B.2+B.3) | D28: LK | E28: =SUM(E19,E22,E25) -> 116 | F28: =SUM(F19,F22,F25) -> 110 | G28: =SUM(G19,G22,G25) -> 124 | H28: =SUM(H19,H22,H25) -> 117 | I28: =SUM(I19,I22,I25) -> 102 | J28: =SUM(J19,J22,J25) -> 106 | K28: =SUM(K19,K22,K25) -> 108 | L28: =SUM(L19,L22,L25) -> 89 | ... AG28: =SUM(AG19,AG22,AG25) -> 53 | AH28: =SUM(E28:AG28) -> 3013
D29: PR | E29: =SUM(E20,E23,E26) -> 113 | F29: =SUM(F20,F23,F26) -> 105 | G29: =SUM(G20,G23,G26) -> 123 | H29: =SUM(H20,H23,H26) -> 124 | I29: =SUM(I20,I23,I26) -> 117 | J29: =SUM(J20,J23,J26) -> 108 | K29: =SUM(K20,K23,K26) -> 109 | L29: =SUM(L20,L23,L26) -> 107 | ... AG29: =SUM(AG20,AG23,AG26) -> 60 | AH29: =SUM(E29:AG29) -> 3264
D30: JML | E30: =SUM(E28:E29) -> 229 | F30: =SUM(F28:F29) -> 215 | G30: =SUM(G28:G29) -> 247 | H30: =SUM(H28:H29) -> 241 | I30: =SUM(I28:I29) -> 219 | J30: =SUM(J28:J29) -> 214 | K30: =SUM(K28:K29) -> 217 | L30: =SUM(L28:L29) -> 196 | ... AG30: =SUM(AG28:AG29) -> 113 | AH30: =SUM(E30:AG30) -> 6277
A32: II | B32: DATA PENGGUNAAN SURAT SUARA
A33: 1 | B33: Jumlah surat suara yang diterima, termasuk surat suara cadangan 2,5% dari DPT | E33: 285 | F33: 284 | G33: 297 | H33: 302 | I33: 285 | J33: 288 | K33: 287 | L33: 263 | M33: 290 | N33: 280 | O33: 304 | P33: 303 | Q33: 296 | R33: 303 | S33: 296 | T33: 299 | U33: 280 | V33: 276 | W33: 279 | X33: 279 | Y33: 298 | Z33: 288 | AA33: 278 | AB33: 282 | AC33: 293 | AD33: 276 | AE33: 282 | AF33: 215 | AG33: 149 | AH33: =SUM(E33:AG33) -> 8137
A34: 2 | B34: Jumlah surat suara yang digunakan | E34: 229 | F34: 215 | G34: 247 | H34: 241 | I34: 219 | J34: 214 | K34: 217 | L34: 196 | M34: 228 | N34: 212 | O34: 227 | P34: 217 | Q34: 213 | R34: 243 | S34: 215 | T34: 236 | U34: 224 | V34: 224 | W34: 226 | X34: 221 | Y34: 231 | Z34: 215 | AA34: 206 | AB34: 222 | AC34: 228 | AD34: 212 | AE34: 224 | AF34: 162 | AG34: 113 | AH34: =SUM(E34:AG34) -> 6277
A35: 3 | B35: Jumlah surat suara dikembalikan oleh pemilih (karena rusak atau keliru coblos) | E35: 1 | F35: 0 | G35: 0 | H35: 0 | I35: 0 | J35: 0 | K35: 0 | L35: 0 | M35: 0 | N35: 0 | O35: 0 | P35: 0 | Q35: 4 | R35: 0 | S35: 0 | T35: 0 | U35: 1 | V35: 0 | W35: 0 | X35: 1 | Y35: 0 | Z35: 0 | AA35: 0 | AB35: 0 | AC35: 1 | AD35: 0 | AE35: 0 | AF35: 0 | AG35: 0 | AH35: =SUM(E35:AG35) -> 8
A36: 4 | B36: Jumlah surat suara yang tidak digunakan/tidak terpakai, termasuk sisa surat suara cadangan | E36: =E33-(E34+E35) -> 55 | F36: =F33-(F34+F35) -> 69 | G36: =G33-(G34+G35) -> 50 | H36: =H33-(H34+H35) -> 61 | I36: =I33-(I34+I35) -> 66 | J36: =J33-(J34+J35) -> 74 | K36: =K33-(K34+K35) -> 70 | L36: =L33-(L34+L35) -> 67 | ... AG36: =AG33-(AG34+AG35) -> 36 | AH36: =SUM(E36:AG36) -> 1852
A38: III | B38: DATA PEMILIH DISABILITAS
B39: Jumlah seluruh Pemilih disabilitas yang menggunakan hak pilih | D39: LK | E39: 0 | F39: 0 | G39: 0 | H39: 0 | I39: 0 | J39: 1 | K39: 0 | L39: 0 | M39: 0 | N39: 1 | O39: 0 | P39: 0 | Q39: 1 | R39: 0 | S39: 0 | T39: 0 | U39: 0 | V39: 0 | W39: 0 | X39: 0 | Y39: 4 | Z39: 0 | AA39: 0 | AB39: 0 | AC39: 0 | AD39: 0 | AE39: 0 | AF39: 0 | AG39: 0 | AH39: =SUM(E39:AG39) -> 7
