Workbook

Sheet DPRD PROVINSI
C8: Kecamatan | D8: TEGALSARI
C9: Kabupaten | D9: BANYUWANGI
C10: Provinsi | D10: JAWA TIMUR
A12: I | B12: DATA PEMILIH DAN PENGGUNAAN HAK PILIH | E12: JUMLAH AKHIR
A13: A | B13: DATA PEMILIH
B14: Jumlah Pemilih dalam Daftar Pemilih Tetap (DPT) | D14: LK | E14: =DASRI!AA14+KARANGDORO!AV14+KARANGMULYO!W14+TAMANSARI!AA14+TEGALREJO!AB14+TEGALSARI!AU14 -> 21381
D15: PR | E15: =DASRI!AA15+KARANGDORO!AV15+KARANGMULYO!W15+TAMANSARI!AA15+TEGALREJO!AB15+TEGALSARI!AU15 -> 21258
D16: JML | E16: =SUM(E14:E15) -> 42639
A18: B | B18: PENGGUNA HAK PILIH
B19: 1. | C19: Jumlah pengguna hak pilih dalam Daftar Pemilih Tetap (DPT) | D19: LK | E19: =DASRI!AA19+KARANGDORO!AV19+KARANGMULYO!W19+TAMANSARI!AA19+TEGALREJO!AB19+TEGALSARI!AU19 -> 14890
D20: PR | E20: =DASRI!AA20+KARANGDORO!AV20+KARANGMULYO!W20+TAMANSARI!AA20+TEGALREJO!AB20+TEGALSARI!AU20 -> 15697
D21: JML | E21: =SUM(E19:E20) -> 30587
B22: 2. | C22: Jumlah pengguna hak pilih dalam Daftar Pemilih Tambahan (DPTb) | D22: LK | E22: =DASRI!AA22+KARANGDORO!AV22+KARANGMULYO!W22+TAMANSARI!AA22+TEGALREJO!AB22+TEGALSARI!AU22 -> 24
D23: PR | E23: =DASRI!AA23+KARANGDORO!AV23+KARANGMULYO!W23+TAMANSARI!AA23+TEGALREJO!AB23+TEGALSARI!AU23 -> 33
D24: JML | E24: =SUM(E22:E23) -> 57
B25: 3. | C25: Jumlah pengguna hak pilih dalam Daftar Pemilih Khusus (DPK) | D25: LK | E25: =DASRI!AA25+KARANGDORO!AV25+KARANGMULYO!W25+TAMANSARI!AA25+TEGALREJO!AB25+TEGALSARI!AU25 -> 224
D26: PR | E26: =DASRI!AA26+KARANGDORO!AV26+KARANGMULYO!W26+TAMANSARI!AA26+TEGALREJO!AB26+TEGALSARI!AU26 -> 266
D27: JML | E27: =SUM(E25:E26) -> 490
B28: 4. | C28: Jumlah Pengguna Hak Pilih (B.1+B.2+B.3) | D28: LK | E28: =E19+E22+E25 -> 15138
D29: PR | E29: =E20+E23+E26 -> 15996
D30: JML | E30: =SUM(E28:E29) -> 31134
A32: II | B32: DATA PENGGUNAAN SURAT SUARA
A33: 1 | B33: Jumlah surat suara yang diterima, termasuk surat suara cadangan 2,5% dari DPT | E33: =DASRI!AA33+KARANGDORO!AV33+KARANGMULYO!W33+TAMANSARI!AA33+TEGALREJO!AB33+TEGALSARI!AU33 -> 43597
A34: 2 | B34: Jumlah surat suara yang digunakan | E34: =DASRI!AA34+KARANGDORO!AV34+KARANGMULYO!W34+TAMANSARI!AA34+TEGALREJO!AB34+TEGALSARI!AU34 -> 31134
A35: 3 | B35: Jumlah surat suara dikembalikan oleh pemilih (karena rusak atau keliru coblos) | E35: =DASRI!AA35+KARANGDORO!AV35+KARANGMULYO!W35+TAMANSARI!AA35+TEGALREJO!AB35+TEGALSARI!AU35 -> 61
A36: 4 | B36: Jumlah surat suara yang tidak digunakan/tidak terpakai, termasuk sisa surat suara cadangan | E36: =E33-(E34+E35) -> 12402
A38: III | B38: DATA PEMILIH DISABILITAS
B39: Jumlah seluruh Pemilih disabilitas yang menggunakan hak pilih | D39: LK | E39: =DASRI!AA39+KARANGDORO!AV39+KARANGMULYO!W39+TAMANSARI!AA39+TEGALREJO!AB39+TEGALSARI!AU39 -> 17
D40: PR | E40: =DASRI!AA40+KARANGDORO!AV40+KARANGMULYO!W40+TAMANSARI!AA40+TEGALREJO!AB40+TEGALSARI!AU40 -> 17
D41: JML | E41: =SUM(E39:E40) -> 34
A43: IV | B43: DATA RINCIAN PEROLEHAN SUARA PASANGAN CALON BUPATI DAN WAKIL BUPATI
A44: NOMOR DAN NAMA CALON
A45: A.1 | B45: 1. | C45: Partai Kebangkitan Bangsa | E45: =DASRI!AA45+KARANGDORO!AV45+KARANGMULYO!W45+TAMANSARI!AA45+TEGALREJO!AB45+TEGALSARI!AU45 -> 1114
A46: A.2 | C46: 1. Dra. Hj. MA`MULAH HARUN, M.Pd.I. | E46: =DASRI!AA46+KARANGDORO!AV46+KARANGMULYO!W46+TAMANSARI!AA46+TEGALREJO!AB46+TEGALSARI!AU46 -> 2645
C47: 2. UBAIDILLAH, S.Fil.I. | E47: =DASRI!AA47+KARANGDORO!AV47+KARANGMULYO!W47+TAMANSARI!AA47+TEGALREJO!AB47+TEGALSARI!AU47 -> 1251
C48: 3. Ir. H. YOYOK MULYADI, M.Si. | E48: =DASRI!AA48+KARANGDORO!AV48+KARANGMULYO!W48+TAMANSARI!AA48+TEGALREJO!AB48+TEGALSARI!AU48 -> 110
C49: 4. KHOIRUL ANWAR, S.Fil.I. | E49: =DASRI!AA49+KARANGDORO!AV49+KARANGMULYO!W49+TAMANSARI!AA49+TEGALREJO!AB49+TEGALSARI!AU49 -> 183
C50: 5. ARIF WIJAKSANA | E50: =DASRI!AA50+KARANGDORO!AV50+KARANGMULYO!W50+TAMANSARI!AA50+TEGALREJO!AB50+TEGALSARI!AU50 -> 225
C51: 6. Dr. SITI YUMNAH | E51: =DASRI!AA51+KARANGDORO!AV51+KARANGMULYO!W51+TAMANSARI!AA51+TEGALREJO!AB51+TEGALSARI!AU51 -> 136
C52: 7. MOHAMMAD ZAINI, M.Pd.I. | E52: =DASRI!AA52+KARANGDORO!AV52+KARANGMULYO!W52+TAMANSARI!AA52+TEGALREJO!AB52+TEGALSARI!AU52 -> 71
...

Sheet DASRI
C2: Kecamatan | D2: TEGALSARI
C3: Kabupaten | D3: BANYUWANGI
C4: Provinsi | D4: JAWA TIMUR
C9: Kelurahan | D9: DASRI
A12: I | B12: DATA PEMILIH DAN PENGGUNAAN HAK PILIH | AA12: JUMLAH AKHIR
A13: A | B13: DATA PEMILIH | E13: TPS 001 | F13: TPS 002 | G13: TPS 003 | H13: TPS 004 | I13: TPS 005 | J13: TPS 006 | K13: TPS 007 | L13: TPS 008 | M13: TPS 009 | N13: TPS 010 | O13: TPS 011 | P13: TPS 012 | Q13: TPS 013 | R13: TPS 014 | S13: TPS 015 | T13: TPS 016 | U13: TPS 017 | V13: TPS 018 | W13: TPS 019 | X13: TPS 020 | Y13: TPS 021 | Z13: TPS 022
B14: Jumlah Pemilih dalam Daftar Pemilih Tetap (DPT) | D14: LK | E14: 128 | F14: 110 | G14: 133 | H14: 138 | I14: 130 | J14: 102 | K14: 122 | L14: 149 | M14: 146 | N14: 155 | O14: 163 | P14: 131 | Q14: 123 | R14: 136 | S14: 137 | T14: 119 | U14: 117 | V14: 124 | W14: 135 | X14: 121 | Y14: 129 | Z14: 148 | AA14: =SUM(E14:Z14) -> 2896
D15: PR | E15: 117 | F15: 123 | G15: 120 | H15: 135 | I15: 136 | J15: 105 | K15: 127 | L15: 145 | M15: 152 | N15: 144 | O15: 137 | P15: 119 | Q15: 122 | R15: 140 | S15: 113 | T15: 124 | U15: 110 | V15: 127 | W15: 132 | X15: 130 | Y15: 113 | Z15: 131 | AA15: =SUM(E15:Z15) -> 2802
D16: JML | E16: =SUM(E14:E15) -> 245 | F16: =SUM(F14:F15) -> 233 | G16: =SUM(G14:G15) -> 253 | H16: =SUM(H14:H15) -> 273 | I16: =SUM(I14:I15) -> 266 | J16: =SUM(J14:J15) -> 207 | K16: =SUM(K14:K15) -> 249 | L16: =SUM(L14:L15) -> 294 | ... Z16: =SUM(Z14:Z15) -> 279 | AA16: =SUM(E16:Z16) -> 5698
A18: B | B18: PENGGUNA HAK PILIH
B19: 1. | C19: Jumlah pengguna hak pilih dalam Daftar Pemilih Tetap (DPT) | D19: LK | E19: 97 | F19: 85 | G19: 92 | H19: 99 | I19: 94 | J19: 73 | K19: 88 | L19: 104 | M19: 101 | N19: 109 | O19: 114 | P19: 86 | Q19: 79 | R19: 109 | S19: 77 | T19: 87 | U19: 81 | V19: 95 | W19: 96 | X19: 81 | Y19: 85 | Z19: 108 | AA19: =SUM(E19:Z19) -> 2040
D20: PR | E20: 89 | F20: 89 | G20: 88 | H20: 109 | I20: 98 | J20: 78 | K20: 98 | L20: 108 | M20: 109 | N20: 109 | O20: 110 | P20: 77 | Q20: 86 | R20: 104 | S20: 74 | T20: 84 | U20: 81 | V20: 92 | W20: 92 | X20: 105 | Y20: 80 | Z20: 104 | AA20: =SUM(E20:Z20) -> 2064
D21: JML | E21: =SUM(E19:E20) -> 186 | F21: =SUM(F19:F20) -> 174 | G21: =SUM(G19:G20) -> 180 | H21: =SUM(H19:H20) -> 208 | I21: =SUM(I19:I20) -> 192 | J21: =SUM(J19:J20) -> 151 | K21: =SUM(K19:K20) -> 186 | L21: =SUM(L19:L20) -> 212 | ... Z21: =SUM(Z19:Z20) -> 212 | AA21: =SUM(E21:Z21) -> 4104
B22: 2. | C22: Jumlah pengguna hak pilih dalam Daftar Pemilih Tambahan (DPTb) | D22: LK | E22: 0 | F22: 0 | G22: 0 | H22: 0 | I22: 1 | J22: 0 | K22: 0 | L22: 0 | M22: 0 | N22: 0 | O22: 0 | P22: 1 | Q22: 0 | R22: 0 | S22: 0 | T22: 0 | U22: 0 | V22: 0 | W22: 0 | X22: 0 | Y22: 0 | Z22: 0 | AA22: =SUM(E22:Z22) -> 2
D23: PR | E23: 0 | F23: 0 | G23: 0 | H23: 0 | I23: 0 | J23: 0 | K23: 0 | L23: 0 | M23: 0 | N23: 0 | O23: 0 | P23: 0 | Q23: 0 | R23: 0 | S23: 0 | T23: 0 | U23: 0 | V23: 0 | W23: 0 | X23: 0 | Y23: 0 | Z23: 0 | AA23: =SUM(E23:Z23) -> 0
D24: JML | E24: =SUM(E22:E23) -> 0 | F24: =SUM(F22:F23) -> 0 | G24: =SUM(G22:G23) -> 0 | H24: =SUM(H22:H23) -> 0 | I24: =SUM(I22:I23) -> 1 | J24: =SUM(J22:J23) -> 0 | K24: =SUM(K22:K23) -> 0 | L24: =SUM(L22:L23) -> 0 | ... Z24: =SUM(Z22:Z23) -> 0 | AA24: =SUM(E24:Z24) -> 2
B25: 3. | C25: Jumlah pengguna hak pilih dalam Daftar Pemilih Khusus (DPK) | D25: LK | E25: 1 | F25: 2 | G25: 0 | H25: 1 | I25: 2 | J25: 5 | K25: 4 | L25: 0 | M25: 1 | N25: 2 | O25: 0 | P25: 0 | Q25: 2 | R25: 2 | S25: 1 | T25: 3 | U25: 2 | V25: 4 | W25: 1 | X25: 2 | Y25: 0 | Z25: 2 | AA25: =SUM(E25:Z25) -> 37
D26: PR | E26: 2 | F26: 1 | G26: 4 | H26: 0 | I26: 4 | J26: 5 | K26: 1 | L26: 1 | M26: 2 | N26: 3 | O26: 1 | P26: 1 | Q26: 1 | R26: 2 | S26: 4 | T26: 4 | U26: 3 | V26: 3 | W26: 2 | X26: 0 | Y26: 1 | Z26: 0 | AA26: =SUM(E26:Z26) -> 45
D27: JML | E27: =SUM(E25:E26) -> 3 | F27: =SUM(F25:F26) -> 3 | G27: =SUM(G25:G26) -> 4 | H27: =SUM(H25:H26) -> 1 | I27: =SUM(I25:I26) -> 6 | J27: =SUM(J25:J26) -> 10 | K27: =SUM(K25:K26) -> 5 | L27: =SUM(L25:L26) -> 1 | ... Z27: =SUM(Z25:Z26) -> 2 | AA27: =SUM(E27:Z27) -> 82
B28: 4. | C28: Jumlah Pengguna Hak Pilih (B.1+B.2+B.3) | D28: LK | E28: =SUM(E19,E22,E25) -> 98 | F28: =SUM(F19,F22,F25) -> 87 | G28: =SUM(G19,G22,G25) -> 92 | H28: =SUM(H19,H22,H25) -> 100 | I28: =SUM(I19,I22,I25) -> 97 | J28: =SUM(J19,J22,J25) -> 78 | K28: =SUM(K19,K22,K25) -> 92 | L28: =SUM(L19,L22,L25) -> 104 | ... Z28: =SUM(Z19,Z22,Z25) -> 110 | AA28: =SUM(E28:Z28) -> 2079
D29: PR | E29: =SUM(E20,E23,E26) -> 91 | F29: =SUM(F20,F23,F26) -> 90 | G29: =SUM(G20,G23,G26) -> 92 | H29: =SUM(H20,H23,H26) -> 109 | I29: =SUM(I20,I23,I26) -> 102 | J29: =SUM(J20,J23,J26) -> 83 | K29: =SUM(K20,K23,K26) -> 99 | L29: =SUM(L20,L23,L26) -> 109 | ... Z29: =SUM(Z20,Z23,Z26) -> 104 | AA29: =SUM(E29:Z29) -> 2109
D30: JML | E30: =SUM(E28:E29) -> 189 | F30: =SUM(F28:F29) -> 177 | G30: =SUM(G28:G29) -> 184 | H30: =SUM(H28:H29) -> 209 | I30: =SUM(I28:I29) -> 199 | J30: =SUM(J28:J29) -> 161 | K30: =SUM(K28:K29) -> 191 | L30: =SUM(L28:L29) -> 213 | ... Z30: =SUM(Z28:Z29) -> 214 | AA30: =SUM(E30:Z30) -> 4188
A32: II | B32: DATA PENGGUNAAN SURAT SUARA
A33: 1 | B33: Jumlah surat suara yang diterima, termasuk surat suara cadangan 2,5% dari DPT | E33: 250 | F33: 238 | G33: 259 | H33: 279 | I33: 272 | J33: 214 | K33: 254 | L33: 300 | M33: 304 | N33: 305 | O33: 316 | P33: 255 | Q33: 251 | R33: 281 | S33: 255 | T33: 248 | U33: 232 | V33: 257 | W33: 273 | X33: 257 | Y33: 247 | Z33: 285 | AA33: =SUM(E33:Z33) -> 5832
A34: 2 | B34: Jumlah surat suara yang digunakan | E34: 189 | F34: 177 | G34: 184 | H34: 209 | I34: 199 | J34: 161 | K34: 191 | L34: 213 | M34: 213 | N34: 223 | O34: 225 | P34: 165 | Q34: 168 | R34: 217 | S34: 156 | T34: 178 | U34: 167 | V34: 194 | W34: 191 | X34: 188 | Y34: 166 | Z34: 214 | AA34: =SUM(E34:Z34) -> 4188
A35: 3 | B35: Jumlah surat suara dikembalikan oleh pemilih (karena rusak atau keliru coblos) | E35: 0 | F35: 0 | G35: 0 | H35: 2 | I35: 0 | J35: 0 | K35: 1 | L35: 0 | M35: 0 | N35: 0 | O35: 0 | P35: 0 | Q35: 0 | R35: 0 | S35: 0 | T35: 0 | U35: 0 | V35: 0 | W35: 2 | X35: 0 | Y35: 0 | Z35: 1 | AA35: =SUM(E35:Z35) -> 6
A36: 4 | B36: Jumlah surat suara yang tidak digunakan/tidak terpakai, termasuk sisa surat suara cadangan | E36: =E33-(E34+E35) -> 61 | F36: =F33-(F34+F35) -> 61 | G36: =G33-(G34+G35) -> 75 | H36: =H33-(H34+H35) -> 68 | I36: =I33-(I34+I35) -> 73 | J36: =J33-(J34+J35) -> 53 | K36: =K33-(K34+K35) -> 62 | L36: =L33-(L34+L35) -> 87 | ... Z36: =Z33-(Z34+Z35) -> 70 | AA36: =SUM(E36:Z36) -> 1638
A38: III | B38: DATA PEMILIH DISABILITAS
B39: Jumlah seluruh Pemilih disabilitas yang menggunakan hak pilih | D39: LK | E39: 0 | F39: 0 | G39: 0 | H39: 0 | I39: 0 | J39: 0 | K39: 0 | L39: 0 | M39: 0 | N39: 0 | O39: 0 | P39: 0 | Q39: 0 | R39: 0 | S39: 0 | T39: 0 | U39: 1 | V39: 0 | W39: 0 | X39: 0 | Y39: 0 | Z39: 0 | AA39: =SUM(E39:Z39) -> 1
D40: PR | E40: 0 | F40: 0 | G40: 0 | H40: 0 | I40: 0 | J40: 0 | K40: 0 | L40: 0 | M40: 0 | N40: 0 | O40: 0 | P40: 0 | Q40: 0 | R40: 0 | S40: 0 | T40: 0 | U40: 1 | V40: 0 | W40: 0 | X40: 0 | Y40: 0 | Z40: 0 | AA40: =SUM(E40:Z40) -> 1
D41: JML | E41: =SUM(E39:E40) -> 0 | F41: =SUM(F39:F40) -> 0 | G41: =SUM(G39:G40) -> 0 | H41: =SUM(H39:H40) -> 0 | I41: =SUM(I39:I40) -> 0 | J41: =SUM(J39:J40) -> 0 | K41: =SUM(K39:K40) -> 0 | L41: =SUM(L39:L40) -> 0 | ... Z41: =SUM(Z39:Z40) -> 0 | AA41: =SUM(E41:Z41) -> 2
A43: IV | B43: DATA RINCIAN PEROLEHAN SUARA PASANGAN CALON BUPATI DAN WAKIL BUPATI
A44: NOMOR DAN NAMA CALON
A45: A.1 | B45: 1. | C45: Partai Kebangkitan Bangsa | E45: 4 | F45: 0 | G45: 5 | H45: 3 | I45: 8 | J45: 2 | K45: 1 | L45: 5 | M45: 4 | N45: 3 | O45: 2 | P45: 4 | Q45: 5 | R45: 9 | S45: 5 | T45: 5 | U45: 6 | V45: 7 | W45: 5 | X45: 6 | Y45: 6 | Z45: 4 | AA45: =SUM(E45:Z45) -> 99
A46: A.2 | C46: 1. Dra. Hj. MA`MULAH HARUN, M.Pd.I. | E46: 12 | F46: 6 | G46: 7 | H46: 13 | I46: 7 | J46: 1 | K46: 5 | L46: 13 | M46: 10 | N46: 0 | O46: 10 | P46: 3 | Q46: 4 | R46: 33 | S46: 4 | T46: 19 | U46: 23 | V46: 12 | W46: 22 | X46: 8 | Y46: 9 | Z46: 9 | AA46: =SUM(E46:Z46) -> 230
C47: 2. UBAIDILLAH, S.Fil.I. | E47: 2 | F47: 1 | G47: 2 | H47: 2 | I47: 0 | J47: 0 | K47: 0 | L47: 2 | M47: 2 | N47: 2 | O47: 1 | P47: 0 | Q47: 0 | R47: 0 | S47: 0 | T47: 5 | U47: 3 | V47: 2 | W47: 0 | X47: 0 | Y47: 0 | Z47: 6 | AA47: =SUM(E47:Z47) -> 30
C48: 3. Ir. H. YOYOK MULYADI, M.Si. | E48: 0 | F48: 2 | G48: 0 | H48: 0 | I48: 0 | J48: 0 | K48: 0 | L48: 1 | M48: 1 | N48: 1 | O48: 0 | P48: 2 | Q48: 0 | R48: 0 | S48: 0 | T48: 4 | U48: 1 | V48: 0 | W48: 0 | X48: 0 | Y48: 1 | Z48: 2 | AA48: =SUM(E48:Z48) -> 15
C49: 4. KHOIRUL ANWAR, S.Fil.I. | E49: 1 | F49: 2 | G49: 1 | H49: 0 | I49: 4 | J49: 1 | K49: 1 | L49: 0 | M49: 1 | N49: 1 | O49: 1 | P49: 0 | Q49: 1 | R49: 1 | S49: 2 | T49: 3 | U49: 0 | V49: 3 | W49: 2 | X49: 1 | Y49: 3 | Z49: 2 | AA49: =SUM(E49:Z49) -> 31
C50: 5. ARIF WIJAKSANA | E50: 0 | F50: 0 | G50: 0 | H50: 0 | I50: 1 | J50: 0 | K50: 0 | L50: 0 | M50: 0 | N50: 0 | O50: 0 | P50: 0 | Q50: 0 | R50: 1 | S50: 0 | T50: 2 | U50: 0 | V50: 0 | W50: 0 | X50: 0 | Y50: 0 | Z50: 0 | AA50: =SUM(E50:Z50) -> 4
C51: 6. Dr. SITI YUMNAH | E51: 0 | F51: 1 | G51: 0 | H51: 0 | I51: 0 | J51: 0 | K51: 0 | L51: 0 | M51: 1 | N51: 1 | O51: 0 | P51: 1 | Q51: 1 | R51: 0 | S51: 0 | T51: 1 | U51: 2 | V51: 2 | W51: 3 | X51: 1 | Y51: 0 | Z51: 0 | AA51: =SUM(E51:Z51) -> 14
...

Sheet KARANGDORO
C2: Kecamatan | D2: TEGALSARI
C3: Kabupaten | D3: BANYUWANGI
C4: Provinsi | D4: JAWA TIMUR
C9: Kelurahan | D9: KARANGDORO
A12: I | B12: DATA PEMILIH DAN PENGGUNAAN HAK PILIH | AV12: JUMLAH AKHIR
A13: A | B13: DATA PEMILIH | E13: TPS 001 | F13: TPS 002 | G13: TPS 003 | H13: TPS 004 | I13: TPS 005 | J13: TPS 006 | K13: TPS 007 | L13: TPS 008 | M13: TPS 009 | N13: TPS 010 | O13: TPS 011 | P13: TPS 012 | Q13: TPS 013 | R13: TPS 014 | S13: TPS 015 | T13: TPS 016 | U13: TPS 017 | V13: TPS 018 | W13: TPS 019 | X13: TPS 020 | Y13: TPS 021 | Z13: TPS 022 | AA13: TPS 023 | AB13: TPS 024 | AC13: TPS 025 | AD13: TPS 026 | AE13: TPS 027 | AF13: TPS 028 | AG13: TPS 029 | AH13: TPS 030 | AI13: TPS 031 | AJ13: TPS 032 | AK13: TPS 033 | AL13: TPS 034 | AM13: TPS 035 | AN13: TPS 901 | AO13: TPS 902 | AP13: TPS 903 | AQ13: TPS 904 | AR13: TPS 905 | AS13: TPS 906 | AT13: TPS 907 | AU13: TPS 908
B14: Jumlah Pemilih dalam Daftar Pemilih Tetap (DPT) | D14: LK | E14: 157 | F14: 141 | G14: 125 | H14: 133 | I14: 139 | J14: 119 | K14: 131 | L14: 139 | M14: 132 | N14: 140 | O14: 139 | P14: 114 | Q14: 108 | R14: 135 | S14: 126 | T14: 140 | U14: 141 | V14: 136 | W14: 135 | X14: 144 | Y14: 135 | Z14: 152 | AA14: 151 | AB14: 143 | AC14: 120 | AD14: 119 | AE14: 119 | AF14: 106 | AG14: 105 | AH14: 112 | AI14: 114 | AJ14: 116 | AK14: 123 | AL14: 141 | AM14: 136 | AN14: 0 | AO14: 0 | AP14: 0 | AQ14: 0 | AR14: 300 | AS14: 298 | AT14: 298 | AU14: 65 | AV14: =SUM(E14:AU14) -> 5527
D15: PR | E15: 142 | F15: 155 | G15: 139 | H15: 136 | I15: 132 | J15: 119 | K15: 127 | L15: 142 | M15: 132 | N15: 128 | O15: 124 | P15: 121 | Q15: 116 | R15: 125 | S15: 116 | T15: 122 | U15: 140 | V15: 140 | W15: 120 | X15: 135 | Y15: 132 | Z15: 143 | AA15: 145 | AB15: 151 | AC15: 114 | AD15: 111 | AE15: 103 | AF15: 125 | AG15: 106 | AH15: 84 | AI15: 119 | AJ15: 101 | AK15: 123 | AL15: 147 | AM15: 158 | AN15: 300 | AO15: 292 | AP15: 297 | AQ15: 187 | AR15: 0 | AS15: 0 | AT15: 0 | AU15: 0 | AV15: =SUM(E15:AU15) -> 5549
D16: JML | E16: =SUM(E14:E15) -> 299 | F16: =SUM(F14:F15) -> 296 | G16: =SUM(G14:G15) -> 264 | H16: =SUM(H14:H15) -> 269 | I16: =SUM(I14:I15) -> 271 | J16: =SUM(J14:J15) -> 238 | K16: =SUM(K14:K15) -> 258 | L16: =SUM(L14:L15) -> 281 | ... AU16: =SUM(AU14:AU15) -> 65 | AV16: =SUM(E16:AU16) -> 11076
A18: B | B18: PENGGUNA HAK PILIH
B19: 1. | C19: Jumlah pengguna hak pilih dalam Daftar Pemilih Tetap (DPT) | D19: LK | E19: 113 | F19: 108 | G19: 93 | H19: 93 | I19: 106 | J19: 95 | K19: 96 | L19: 108 | M19: 91 | N19: 103 | O19: 109 | P19: 75 | Q19: 68 | R19: 97 | S19: 71 | T19: 114 | U19: 103 | V19: 101 | W19: 105 | X19: 108 | Y19: 92 | Z19: 104 | AA19: 117 | AB19: 101 | AC19: 87 | AD19: 79 | AE19: 91 | AF19: 77 | AG19: 77 | AH19: 81 | AI19: 91 | AJ19: 79 | AK19: 84 | AL19: 119 | AM19: 98 | AN19: 0 | AO19: 0 | AP19: 0 | AQ19: 0 | AR19: 1 | AS19: 0 | AT19: 2 | AU19: 0 | AV19: =SUM(E19:AU19) -> 3337
D20: PR | E20: 114 | F20: 124 | G20: 101 | H20: 108 | I20: 99 | J20: 98 | K20: 97 | L20: 120 | M20: 91 | N20: 99 | O20: 96 | P20: 85 | Q20: 83 | R20: 100 | S20: 75 | T20: 104 | U20: 102 | V20: 106 | W20: 104 | X20: 113 | Y20: 109 | Z20: 101 | AA20: 116 | AB20: 118 | AC20: 91 | AD20: 78 | AE20: 75 | AF20: 95 | AG20: 87 | AH20: 61 | AI20: 97 | AJ20: 82 | AK20: 88 | AL20: 124 | AM20: 107 | AN20: 0 | AO20: 0 | AP20: 3 | AQ20: 1 | AR20: 0 | AS20: 0 | AT20: 0 | AU20: 0 | AV20: =SUM(E20:AU20) -> 3452
D21: JML | E21: =SUM(E19:E20) -> 227 | F21: =SUM(F19:F20) -> 232 | G21: =SUM(G19:G20) -> 194 | H21: =SUM(H19:H20) -> 201 | I21: =SUM(I19:I20) -> 205 | J21: =SUM(J19:J20) -> 193 | K21: =SUM(K19:K20) -> 193 | L21: =SUM(L19:L20) -> 228 | ... AU21: =SUM(AU19:AU20) -> 0 | AV21: =SUM(E21:AU21) -> 6789
B22: 2. | C22: Jumlah pengguna hak pilih dalam Daftar Pemilih Tambahan (DPTb) | D22: LK | E22: 0 | F22: 1 | G22: 0 | H22: 3 | I22: 1 | J22: 2 | K22: 1 | L22: 0 | M22: 0 | N22: 0 | O22: 0 | P22: 0 | Q22: 0 | R22: 1 | S22: 0 | T22: 1 | U22: 1 | V22: 0 | W22: 0 | X22: 0 | Y22: 0 | Z22: 0 | AA22: 0 | AB22: 1 | AC22: 0 | AD22: 0 | AE22: 0 | AF22: 0 | AG22: 0 | AH22: 0 | AI22: 0 | AJ22: 0 | AK22: 0 | AL22: 0 | AM22: 0 | AN22: 0 | AO22: 0 | AP22: 0 | AQ22: 0 | AR22: 0 | AS22: 0 | AT22: 0 | AU22: 0 | AV22: =SUM(E22:AU22) -> 12
D23: PR | E23: 0 | F23: 3 | G23: 0 | H23: 0 | I23: 0 | J23: 0 | K23: 0 | L23: 0 | M23: 0 | N23: 0 | O23: 0 | P23: 0 | Q23: 0 | R23: 3 | S23: 5 | T23: 8 | U23: 2 | V23: 1 | W23: 0 | X23: 0 | Y23: 0 | Z23: 0 | AA23: 0 | AB23: 0 | AC23: 0 | AD23: 0 | AE23: 0 | AF23: 0 | AG23: 0 | AH23: 0 | AI23: 0 | AJ23: 0 | AK23: 0 | AL23: 0 | AM23: 0 | AN23: 0 | AO23: 0 | AP23: 0 | AQ23: 0 | AR23: 0 | AS23: 0 | AT23: 0 | AU23: 0 | AV23: =SUM(E23:AU23) -> 22
D24: JML | E24: =SUM(E22:E23) -> 0 | F24: =SUM(F22:F23) -> 4 | G24: =SUM(G22:G23) -> 0 | H24: =SUM(H22:H23) -> 3 | I24: =SUM(I22:I23) -> 1 | J24: =SUM(J22:J23) -> 2 | K24: =SUM(K22:K23) -> 1 | L24: =SUM(L22:L23) -> 0 | ... AU24: =SUM(AU22:AU23) -> 0 | AV24: =SUM(E24:AU24) -> 34
B25: 3. | C25: Jumlah pengguna hak pilih dalam Daftar Pemilih Khusus (DPK) | D25: LK | E25: 2 | F25: 3 | G25: 4 | H25: 3 | I25: 2 | J25: 3 | K25: 2 | L25: 2 | M25: 20 | N25: 11 | O25: 1 | P25: 1 | Q25: 1 | R25: 2 | S25: 5 | T25: 2 | U25: 2 | V25: 0 | W25: 0 | X25: 0 | Y25: 1 | Z25: 0 | AA25: 0 | AB25: 0 | AC25: 1 | AD25: 1 | AE25: 0 | AF25: 0 | AG25: 0 | AH25: 1 | AI25: 0 | AJ25: 0 | AK25: 0 | AL25: 3 | AM25: 3 | AN25: 0 | AO25: 0 | AP25: 0 | AQ25: 0 | AR25: 0 | AS25: 0 | AT25: 0 | AU25: 0 | AV25: =SUM(E25:AU25) -> 76
D26: PR | E26: 0 | F26: 3 | G26: 6 | H26: 6 | I26: 4 | J26: 3 | K26: 3 | L26: 2 | M26: 1 | N26: 0 | O26: 4 | P26: 0 | Q26: 2 | R26: 3 | S26: 5 | T26: 0 | U26: 2 | V26: 0 | W26: 1 | X26: 0 | Y26: 3 | Z26: 0 | AA26: 2 | AB26: 0 | AC26: 1 | AD26: 1 | AE26: 4 | AF26: 1 | AG26: 2 | AH26: 3 | AI26: 0 | AJ26: 0 | AK26: 1 | AL26: 0 | AM26: 5 | AN26: 0 | AO26: 0 | AP26: 0 | AQ26: 0 | AR26: 0 | AS26: 0 | AT26: 0 | AU26: 0 | AV26: =SUM(E26:AU26) -> 68
D27: JML | E27: =SUM(E25:E26) -> 2 | F27: =SUM(F25:F26) -> 6 | G27: =SUM(G25:G26) -> 10 | H27: =SUM(H25:H26) -> 9 | I27: =SUM(I25:I26) -> 6 | J27: =SUM(J25:J26) -> 6 | K27: =SUM(K25:K26) -> 5 | L27: =SUM(L25:L26) -> 4 | ... AU27: =SUM(AU25:AU26) -> 0 | AV27: =SUM(E27:AU27) -> 144
B28: 4. | C28: Jumlah Pengguna Hak Pilih (B.1+B.2+B.3) | D28: LK | E28: =SUM(E19,E22,E25) -> 115 | F28: =SUM(F19,F22,F25) -> 112 | G28: =SUM(G19,G22,G25) -> 97 | H28: =SUM(H19,H22,H25) -> 99 | I28: =SUM(I19,I22,I25) -> 109 | J28: =SUM(J19,J22,J25) -> 100 | K28: =SUM(K19,K22,K25) -> 99 | L28: =SUM(L19,L22,L25) -> 110 | ... AU28: =SUM(AU19,AU22,AU25) -> 0 | AV28: =SUM(E28:AU28) -> 3425
D29: PR | E29: =SUM(E20,E23,E26) -> 114 | F29: =SUM(F20,F23,F26) -> 130 | G29: =SUM(G20,G23,G26) -> 107 | H29: =SUM(H20,H23,H26) -> 114 | I29: =SUM(I20,I23,I26) -> 103 | J29: =SUM(J20,J23,J26) -> 101 | K29: =SUM(K20,K23,K26) -> 100 | L29: =SUM(L20,L23,L26) -> 122 | ... AU29: =SUM(AU20,AU23,AU26) -> 0 | AV29: =SUM(E29:AU29) -> 3542
D30: JML | E30: =SUM(E28:E29) -> 229 | F30: =SUM(F28:F29) -> 242 | G30: =SUM(G28:G29) -> 204 | H30: =SUM(H28:H29) -> 213 | I30: =SUM(I28:I29) -> 212 | J30: =SUM(J28:J29) -> 201 | K30: =SUM(K28:K29) -> 199 | L30: =SUM(L28:L29) -> 232 | ... AU30: =SUM(AU28:AU29) -> 0 | AV30: =SUM(E30:AU30) -> 6967
A32: II | B32: DATA PENGGUNAAN SURAT SUARA
A33: 1 | B33: Jumlah surat suara yang diterima, termasuk surat suara cadangan 2,5% dari DPT | E33: 305 | F33: 303 | G33: 270 | H33: 275 | I33: 279 | J33: 243 | K33: 264 | L33: 287 | M33: 269 | N33: 274 | O33: 269 | P33: 245 | Q33: 229 | R33: 266 | S33: 247 | T33: 268 | U33: 287 | V33: 280 | W33: 260 | X33: 285 | Y33: 263 | Z33: 301 | AA33: 302 | AB33: 311 | AC33: 240 | AD33: 236 | AE33: 227 | AF33: 236 | AG33: 216 | AH33: 201 | AI33: 238 | AJ33: 222 | AK33: 251 | AL33: 294 | AM33: 300 | AN33: 306 | AO33: 299 | AP33: 303 | AQ33: 191 | AR33: 307 | AS33: 304 | AT33: 305 | AU33: 67 | AV33: =SUM(E33:AU33) -> 11325
A34: 2 | B34: Jumlah surat suara yang digunakan | E34: 229 | F34: 242 | G34: 204 | H34: 213 | I34: 212 | J34: 201 | K34: 199 | L34: 232 | M34: 203 | N34: 213 | O34: 210 | P34: 161 | Q34: 154 | R34: 206 | S34: 161 | T34: 229 | U34: 212 | V34: 208 | W34: 210 | X34: 221 | Y34: 205 | Z34: 205 | AA34: 235 | AB34: 220 | AC34: 180 | AD34: 159 | AE34: 170 | AF34: 173 | AG34: 166 | AH34: 146 | AI34: 188 | AJ34: 161 | AK34: 173 | AL34: 246 | AM34: 213 | AN34: 0 | AO34: 0 | AP34: 3 | AQ34: 1 | AR34: 1 | AS34: 0 | AT34: 2 | AU34: 0 | AV34: =SUM(E34:AU34) -> 6967
A35: 3 | B35: Jumlah surat suara dikembalikan oleh pemilih (karena rusak atau keliru coblos) | E35: 0 | F35: 0 | G35: 0 | H35: 0 | I35: 14 | J35: 0 | K35: 1 | L35: 0 | M35: 5 | N35: 0 | O35: 0 | P35: 0 | Q35: 0 | R35: 0 | S35: 0 | T35: 0 | U35: 0 | V35: 0 | W35: 0 | X35: 0 | Y35: 0 | Z35: 0 | AA35: 0 | AB35: 0 | AC35: 0 | AD35: 0 | AE35: 0 | AF35: 0 | AG35: 0 | AH35: 0 | AI35: 1 | AJ35: 0 | AK35: 1 | AL35: 2 | AM35: 0 | AN35: 0 | AO35: 0 | AP35: 0 | AQ35: 0 | AR35: 0 | AS35: 0 | AT35: 0 | AU35: 0 | AV35: =SUM(E35:AU35) -> 24
A36: 4 | B36: Jumlah surat suara yang tidak digunakan/tidak terpakai, termasuk sisa surat suara cadangan | E36: =E33-(E34+E35) -> 76 | F36: =F33-(F34+F35) -> 61 | G36: =G33-(G34+G35) -> 66 | H36: =H33-(H34+H35) -> 62 | I36: =I33-(I34+I35) -> 53 | J36: =J33-(J34+J35) -> 42 | K36: =K33-(K34+K35) -> 64 | L36: =L33-(L34+L35) -> 55 | ... AU36: =AU33-(AU34+AU35) -> 67 | AV36: =SUM(E36:AU36) -> 4334
A38: III | B38: DATA PEMILIH DISABILITAS
B39: Jumlah seluruh Pemilih disabilitas yang menggunakan hak pilih | D39: LK | E39: 1 | F39: 0 | G39: 1 | H39: 0 | I39: 0 | J39: 0 | K39: 0 | L39: 1 | M39: 0 | N39: 0 | O39: 0 | P39: 0 | Q39: 0 | R39: 0 | S39: 0 | T39: 0 | U39: 0 | V39: 0 | W39: 0 | X39: 0 | Y39: 0 | Z39: 0 | AA39: 0 | AB39: 0 | AC39: 0 | AD39: 0 | AE39: 0 | AF39: 0 | AG39: 1 | AH39: 0 | AI39: 0 | AJ39: 1 | AK39: 0 | AL39: 0 | AM39: 0 | AN39: 0 | AO39: 0 | AP39: 0 | AQ39: 0 | AR39: 0 | AS39: 0 | AT39: 0 | AU39: 0 | AV39: =SUM(E39:AU39) -> 5
D40: PR | E40: 0 | F40: 0 | G40: 4 | H40: 0 | I40: 0 | J40: 0 | K40: 0 | L40: 1 | M40: 0 | N40: 0 | O40: 0 | P40: 0 | Q40: 0 | R40: 0 | S40: 0 | T40: 0 | U40: 0 | V40: 0 | W40: 0 | X40: 0 | Y40: 0 | Z40: 0 | AA40: 0 | AB40: 0 | AC40: 0 | AD40: 0 | AE40: 0 | AF40: 0 | AG40: 2 | AH40: 0 | AI40: 0 | AJ40: 0 | AK40: 0 | AL40: 0 | AM40: 1 | AN40: 0 | AO40: 0 | AP40: 0 | AQ40: 0 | AR40: 0 | AS40: 0 | AT40: 0 | AU40: 0 | AV40: =SUM(E40:AU40) -> 8
D41: JML | E41: =SUM(E39:E40) -> 1 | F41: =SUM(F39:F40) -> 0 | G41: =SUM(G39:G40) -> 5 | H41: =SUM(H39:H40) -> 0 | I41: =SUM(I39:I40) -> 0 | J41: =SUM(J39:J40) -> 0 | K41: =SUM(K39:K40) -> 0 | L41: =SUM(L39:L40) -> 2 | ... AU41: =SUM(AU39:AU40) -> 0 | AV41: =SUM(E41:AU41) -> 13
A43: IV | B43: DATA RINCIAN PEROLEHAN SUARA PASANGAN CALON BUPATI DAN WAKIL BUPATI
A44: NOMOR DAN NAMA CALON
A45: A.1 | B45: 1. | C45: Partai Kebangkitan Bangsa | E45: 5 | F45: 4 | G45: 2 | H45: 4 | I45: 6 | J45: 6 | K45: 0 | L45: 5 | M45: 6 | N45: 2 | O45: 4 | P45: 15 | Q45: 6 | R45: 18 | S45: 5 | T45: 25 | U45: 13 | V45: 30 | W45: 31 | X45: 17 | Y45: 31 | Z45: 17 | AA45: 14 | AB45: 8 | AC45: 5 | AD45: 5 | AE45: 6 | AF45: 8 | AG45: 1 | AH45: 4 | AI45: 2 | AJ45: 4 | AK45: 13 | AL45: 7 | AM45: 8 | AN45: 0 | AO45: 0 | AP45: 0 | AQ45: 0 | AR45: 0 | AS45: 0 | AT45: 1 | AU45: 0 | AV45: =SUM(E45:AU45) -> 338
A46: A.2 | C46: 1. Dra. Hj. MA`MULAH HARUN, M.Pd.I. | E46: 12 | F46: 5 | G46: 3 | H46: 12 | I46: 12 | J46: 8 | K46: 4 | L46: 20 | M46: 11 | N46: 12 | O46: 25 | P46: 14 | Q46: 11 | R46: 80 | S46: 19 | T46: 79 | U46: 26 | V46: 85 | W46: 116 | X46: 118 | Y46: 75 | Z46: 44 | AA46: 37 | AB46: 28 | AC46: 5 | AD46: 12 | AE46: 18 | AF46: 11 | AG46: 5 | AH46: 9 | AI46: 4 | AJ46: 2 | AK46: 9 | AL46: 17 | AM46: 14 | AN46: 0 | AO46: 0 | AP46: 2 | AQ46: 1 | AR46: 0 | AS46: 0 | AT46: 0 | AU46: 0 | AV46: =SUM(E46:AU46) -> 965
C47: 2. UBAIDILLAH, S.Fil.I. | E47: 1 | F47: 4 | G47: 2 | H47: 0 | I47: 0 | J47: 1 | K47: 0 | L47: 1 | M47: 4 | N47: 4 | O47: 3 | P47: 2 | Q47: 1 | R47: 8 | S47: 4 | T47: 1 | U47: 3 | V47: 2 | W47: 11 | X47: 3 | Y47: 2 | Z47: 2 | AA47: 5 | AB47: 2 | AC47: 0 | AD47: 0 | AE47: 2 | AF47: 2 | AG47: 2 | AH47: 0 | AI47: 0 | AJ47: 4 | AK47: 2 | AL47: 1 | AM47: 9 | AN47: 0 | AO47: 0 | AP47: 0 | AQ47: 0 | AR47: 0 | AS47: 0 | AT47: 0 | AU47: 0 | AV47: =SUM(E47:AU47) -> 88
C48: 3. Ir. H. YOYOK MULYADI, M.Si. | E48: 0 | F48: 0 | G48: 1 | H48: 2 | I48: 3 | J48: 2 | K48: 2 | L48: 0 | M48: 2 | N48: 1 | O48: 1 | P48: 1 | Q48: 0 | R48: 1 | S48: 0 | T48: 1 | U48: 1 | V48: 2 | W48: 1 | X48: 0 | Y48: 1 | Z48: 0 | AA48: 3 | AB48: 1 | AC48: 1 | AD48: 0 | AE48: 0 | AF48: 1 | AG48: 0 | AH48: 0 | AI48: 0 | AJ48: 0 | AK48: 0 | AL48: 1 | AM48: 0 | AN48: 0 | AO48: 0 | AP48: 0 | AQ48: 0 | AR48: 0 | AS48: 0 | AT48: 0 | AU48: 0 | AV48: =SUM(E48:AU48) -> 29
C49: 4. KHOIRUL ANWAR, S.Fil.I. | E49: 0 | F49: 0 | G49: 0 | H49: 0 | I49: 2 | J49: 1 | K49: 2 | L49: 2 | M49: 0 | N49: 2 | O49: 0 | P49: 0 | Q49: 0 | R49: 0 | S49: 1 | T49: 2 | U49: 1 | V49: 1 | W49: 1 | X49: 1 | Y49: 3 | Z49: 0 | AA49: 1 | AB49: 0 | AC49: 1 | AD49: 2 | AE49: 4 | AF49: 1 | AG49: 1 | AH49: 0 | AI49: 0 | AJ49: 1 | AK49: 1 | AL49: 2 | AM49: 1 | AN49: 0 | AO49: 0 | AP49: 0 | AQ49: 0 | AR49: 0 | AS49: 0 | AT49: 0 | AU49: 0 | AV49: =SUM(E49:AU49) -> 34
C50: 5. ARIF WIJAKSANA | E50: 0 | F50: 3 | G50: 1 | H50: 2 | I50: 1 | J50: 0 | K50: 2 | L50: 2 | M50: 0 | N50: 0 | O50: 2 | P50: 1 | Q50: 0 | R50: 3 | S50: 0 | T50: 0 | U50: 0 | V50: 3 | W50: 4 | X50: 5 | Y50: 1 | Z50: 1 | AA50: 1 | AB50: 1 | AC50: 0 | AD50: 0 | AE50: 1 | AF50: 0 | AG50: 0 | AH50: 1 | AI50: 0 | AJ50: 0 | AK50: 1 | AL50: 0 | AM50: 0 | AN50: 0 | AO50: 0 | AP50: 0 | AQ50: 0 | AR50: 0 | AS50: 0 | AT50: 1 | AU50: 0 | AV50: =SUM(E50:AU50) -> 37
C51: 6. Dr. SITI YUMNAH | E51: 1 | F51: 0 | G51: 1 | H51: 1 | I51: 3 | K51: 0 | L51: 0 | M51: 1 | N51: 1 | O51: 0 | P51: 0 | Q51: 0 | R51: 0 | S51: 0 | T51: 0 | U51: 0 | V51: 0 | W51: 1 | X51: 1 | Y51: 0 | Z51: 2 | AA51: 3 | AB51: 0 | AC51: 0 | AD51: 0 | AE51: 0 | AF51: 1 | AG51: 0 | AH51: 0 | AI51: 0 | AJ51: 0 | AK51: 1 | AL51: 0 | AM51: 2 | AN51: 0 | AO51: 0 | AP51: 1 | AQ51: 0 | AR51: 0 | AS51: 0 | AT51: 0 | AU51: 0 | AV51: =SUM(E51:AU51) -> 20
...

Sheet KARANGMULYO
C2: Kecamatan | D2: TEGALSARI
C3: Kabupaten | D3: BANYUWANGI
C4: Provinsi | D4: JAWA TIMUR
C9: Kelurahan | D9: KARANGMULYO
A12: I | B12: DATA PEMILIH DAN PENGGUNAAN HAK PILIH | W12: JUMLAH AKHIR
A13: A | B13: DATA PEMILIH | E13: TPS 001 | F13: TPS 002 | G13: TPS 003 | H13: TPS 004 | I13: TPS 005 | J13: TPS 006 | K13: TPS 007 | L13: TPS 008 | M13: TPS 009 | N13: TPS 010 | O13: TPS 011 | P13: TPS 012 | Q13: TPS 013 | R13: TPS 014 | S13: TPS 015 | T13: TPS 016 | U13: TPS 017 | V13: TPS 018
B14: Jumlah Pemilih dalam Daftar Pemilih Tetap (DPT) | D14: LK | E14: 134 | F14: 122 | G14: 127 | H14: 124 | I14: 130 | J14: 113 | K14: 133 | L14: 118 | M14: 138 | N14: 145 | O14: 127 | P14: 128 | Q14: 135 | R14: 117 | S14: 107 | T14: 118 | U14: 120 | V14: 134 | W14: =SUM(E14:V14) -> 2270
D15: PR | E15: 122 | F15: 131 | G15: 128 | H15: 136 | I15: 120 | J15: 127 | K15: 117 | L15: 125 | M15: 132 | N15: 131 | O15: 147 | P15: 128 | Q15: 125 | R15: 125 | S15: 99 | T15: 132 | U15: 117 | V15: 134 | W15: =SUM(E15:V15) -> 2276
D16: JML | E16: =SUM(E14:E15) -> 256 | F16: =SUM(F14:F15) -> 253 | G16: =SUM(G14:G15) -> 255 | H16: =SUM(H14:H15) -> 260 | I16: =SUM(I14:I15) -> 250 | J16: =SUM(J14:J15) -> 240 | K16: =SUM(K14:K15) -> 250 | L16: =SUM(L14:L15) -> 243 | ... V16: =SUM(V14:V15) -> 268 | W16: =SUM(E16:V16) -> 4546
A18: B | B18: PENGGUNA HAK PILIH
B19: 1. | C19: Jumlah pengguna hak pilih dalam Daftar Pemilih Tetap (DPT) | D19: LK | E19: 93 | F19: 88 | G19: 91 | H19: 86 | I19: 101 | J19: 82 | K19: 106 | L19: 89 | M19: 105 | N19: 110 | O19: 96 | P19: 85 | Q19: 103 | R19: 78 | S19: 73 | T19: 86 | U19: 95 | V19: 102 | W19: =SUM(E19:V19) -> 1669
D20: PR | E20: 88 | F20: 105 | G20: 99 | H20: 99 | I20: 93 | J20: 94 | K20: 94 | L20: 104 | M20: 105 | N20: 100 | O20: 111 | P20: 99 | Q20: 98 | R20: 97 | S20: 71 | T20: 100 | U20: 102 | V20: 99 | W20: =SUM(E20:V20) -> 1758
D21: JML | E21: =SUM(E19:E20) -> 181 | F21: =SUM(F19:F20) -> 193 | G21: =SUM(G19:G20) -> 190 | H21: =SUM(H19:H20) -> 185 | I21: =SUM(I19:I20) -> 194 | J21: =SUM(J19:J20) -> 176 | K21: =SUM(K19:K20) -> 200 | L21: =SUM(L19:L20) -> 193 | ... V21: =SUM(V19:V20) -> 201 | W21: =SUM(E21:V21) -> 3427
B22: 2. | C22: Jumlah pengguna hak pilih dalam Daftar Pemilih Tambahan (DPTb) | D22: LK | E22: 0 | F22: 0 | G22: 1 | H22: 0 | I22: 0 | J22: 0 | K22: 0 | L22: 0 | M22: 0 | N22: 0 | O22: 0 | P22: 0 | Q22: 0 | R22: 0 | S22: 0 | T22: 0 | U22: 1 | V22: 0 | W22: =SUM(E22:V22) -> 2
D23: PR | E23: 0 | F23: 0 | G23: 0 | H23: 0 | I23: 0 | J23: 0 | K23: 0 | L23: 0 | M23: 0 | N23: 0 | O23: 0 | P23: 0 | Q23: 0 | R23: 0 | S23: 0 | T23: 0 | U23: 0 | V23: 0 | W23: =SUM(E23:V23) -> 0
D24: JML | E24: =SUM(E22:E23) -> 0 | F24: =SUM(F22:F23) -> 0 | G24: =SUM(G22:G23) -> 1 | H24: =SUM(H22:H23) -> 0 | I24: =SUM(I22:I23) -> 0 | J24: =SUM(J22:J23) -> 0 | K24: =SUM(K22:K23) -> 0 | L24: =SUM(L22:L23) -> 0 | ... V24: =SUM(V22:V23) -> 0 | W24: =SUM(E24:V24) -> 2
B25: 3. | C25: Jumlah pengguna hak pilih dalam Daftar Pemilih Khusus (DPK) | D25: LK | E25: 1 | F25: 0 | G25: 0 | H25: 1 | I25: 0 | J25: 2 | K25: 0 | L25: 0 | M25: 0 | N25: 0 | O25: 3 | P25: 1 | Q25: 2 | R25: 1 | S25: 0 | T25: 1 | U25: 2 | V25: 0 | W25: =SUM(E25:V25) -> 14
D26: PR | E26: 2 | F26: 0 | G26: 0 | H26: 1 | I26: 0 | J26: 0 | K26: 0 | L26: 0 | M26: 1 | N26: 2 | O26: 1 | P26: 1 | Q26: 2 | R26: 2 | S26: 0 | T26: 6 | U26: 1 | V26: 1 | W26: =SUM(E26:V26) -> 20
D27: JML | E27: =SUM(E25:E26) -> 3 | F27: =SUM(F25:F26) -> 0 | G27: =SUM(G25:G26) -> 0 | H27: =SUM(H25:H26) -> 2 | I27: =SUM(I25:I26) -> 0 | J27: =SUM(J25:J26) -> 2 | K27: =SUM(K25:K26) -> 0 | L27: =SUM(L25:L26) -> 0 | ... V27: =SUM(V25:V26) -> 1 | W27: =SUM(E27:V27) -> 34
B28: 4. | C28: Jumlah Pengguna Hak Pilih (B.1+B.2+B.3) | D28: LK | E28: =SUM(E19,E22,E25) -> 94 | F28: =SUM(F19,F22,F25) -> 88 | G28: =SUM(G19,G22,G25) -> 92 | H28: =SUM(H19,H22,H25) -> 87 | I28: =SUM(I19,I22,I25) -> 101 | J28: =SUM(J19,J22,J25) -> 84 | K28: =SUM(K19,K22,K25) -> 106 | L28: =SUM(L19,L22,L25) -> 89 | ... V28: =SUM(V19,V22,V25) -> 102 | W28: =SUM(E28:V28) -> 1685
D29: PR | E29: =SUM(E20,E23,E26) -> 90 | F29: =SUM(F20,F23,F26) -> 105 | G29: =SUM(G20,G23,G26) -> 99 | H29: =SUM(H20,H23,H26) -> 100 | I29: =SUM(I20,I23,I26) -> 93 | J29: =SUM(J20,J23,J26) -> 94 | K29: =SUM(K20,K23,K26) -> 94 | L29: =SUM(L20,L23,L26) -> 104 | ... V29: =SUM(V20,V23,V26) -> 100 | W29: =SUM(E29:V29) -> 1778
D30: JML | E30: =SUM(E28:E29) -> 184 | F30: =SUM(F28:F29) -> 193 | G30: =SUM(G28:G29) -> 191 | H30: =SUM(H28:H29) -> 187 | I30: =SUM(I28:I29) -> 194 | J30: =SUM(J28:J29) -> 178 | K30: =SUM(K28:K29) -> 200 | L30: =SUM(L28:L29) -> 193 | ... V30: =SUM(V28:V29) -> 202 | W30: =SUM(E30:V30) -> 3463
A32: II | B32: DATA PENGGUNAAN SURAT SUARA
A33: 1 | B33: Jumlah surat suara yang diterima, termasuk surat suara cadangan 2,5% dari DPT | E33: 262 | F33: 259 | G33: 261 | H33: 266 | I33: 255 | J33: 245 | K33: 255 | L33: 248 | M33: 276 | N33: 282 | O33: 280 | P33: 262 | Q33: 266 | R33: 247 | S33: 211 | T33: 255 | U33: 242 | V33: 274 | W33: =SUM(E33:V33) -> 4646
A34: 2 | B34: Jumlah surat suara yang digunakan | E34: 184 | F34: 193 | G34: 191 | H34: 187 | I34: 194 | J34: 178 | K34: 200 | L34: 193 | M34: 211 | N34: 212 | O34: 211 | P34: 186 | Q34: 205 | R34: 178 | S34: 144 | T34: 193 | U34: 201 | V34: 202 | W34: =SUM(E34:V34) -> 3463
A35: 3 | B35: Jumlah surat suara dikembalikan oleh pemilih (karena rusak atau keliru coblos) | E35: 0 | F35: 0 | G35: 0 | H35: 0 | I35: 0 | J35: 0 | K35: 0 | L35: 0 | M35: 1 | N35: 0 | O35: 1 | P35: 0 | Q35: 0 | R35: 0 | S35: 0 | T35: 2 | U35: 1 | V35: 0 | W35: =SUM(E35:V35) -> 5
A36: 4 | B36: Jumlah surat suara yang tidak digunakan/tidak terpakai, termasuk sisa surat suara cadangan | E36: =E33-(E34+E35) -> 78 | F36: =F33-(F34+F35) -> 66 | G36: =G33-(G34+G35) -> 70 | H36: =H33-(H34+H35) -> 79 | I36: =I33-(I34+I35) -> 61 | J36: =J33-(J34+J35) -> 67 | K36: =K33-(K34+K35) -> 55 | L36: =L33-(L34+L35) -> 55 | ... V36: =V33-(V34+V35) -> 72 | W36: =SUM(E36:V36) -> 1178
A38: III | B38: DATA PEMILIH DISABILITAS
B39: Jumlah seluruh Pemilih disabilitas yang menggunakan hak pilih | D39: LK | E39: 0 | F39: 0 | G39: 0 | H39: 0 | I39: 0 | J39: 0 | K39: 0 | L39: 0 | M39: 0 | N39: 1 | O39: 0 | P39: 0 | Q39: 0 | R39: 0 | S39: 0 | T39: 0 | U39: 0 | V39: 0 | W39: =SUM(E39:V39) -> 1
D40: PR | E40: 0 | F40: 0 | G40: 0 | H40: 0 | I40: 0 | J40: 0 | K40: 0 | L40: 0 | M40: 0 | N40: 0 | O40: 0 | P40: 0 | Q40: 0 | R40: 0 | S40: 0 | T40: 0 | U40: 0 | V40: 0 | W40: =SUM(E40:V40) -> 0
D41: JML | E41: =SUM(E39:E40) -> 0 | F41: =SUM(F39:F40) -> 0 | G41: =SUM(G39:G40) -> 0 | H41: =SUM(H39:H40) -> 0 | I41: =SUM(I39:I40) -> 0 | J41: =SUM(J39:J40) -> 0 | K41: =SUM(K39:K40) -> 0 | L41: =SUM(L39:L40) -> 0 | ... V41: =SUM(V39:V40) -> 0 | W41: =SUM(E41:V41) -> 1
A43: IV | B43: DATA RINCIAN PEROLEHAN SUARA PASANGAN CALON BUPATI DAN WAKIL BUPATI
A44: NOMOR DAN NAMA CALON
A45: A.1 | B45: 1. | C45: Partai Kebangkitan Bangsa | E45: 1 | F45: 8 | G45: 4 | H45: 8 | I45: 4 | J45: 1 | K45: 9 | L45: 6 | M45: 14 | N45: 4 | O45: 5 | P45: 13 | Q45: 8 | R45: 6 | S45: 3 | T45: 7 | U45: 5 | V45: 11 | W45: =SUM(E45:V45) -> 117
A46: A.2 | C46: 1. Dra. Hj. MA`MULAH HARUN, M.Pd.I. | E46: 26 | F46: 15 | G46: 17 | H46: 23 | I46: 13 | J46: 10 | K46: 11 | L46: 5 | M46: 22 | N46: 18 | O46: 7 | P46: 29 | Q46: 21 | R46: 8 | S46: 8 | T46: 7 | U46: 16 | V46: 34 | W46: =SUM(E46:V46) -> 290
C47: 2. UBAIDILLAH, S.Fil.I. | E47: 0 | F47: 1 | G47: 3 | H47: 1 | I47: 1 | J47: 0 | K47: 1 | L47: 0 | M47: 3 | N47: 5 | O47: 0 | P47: 4 | Q47: 1 | R47: 2 | S47: 0 | T47: 2 | U47: 2 | V47: 2 | W47: =SUM(E47:V47) -> 28
C48: 3. Ir. H. YOYOK MULYADI, M.Si. | E48: 0 | F48: 2 | G48: 2 | H48: 1 | I48: 0 | J48: 1 | K48: 0 | L48: 0 | M48: 1 | N48: 0 | O48: 0 | P48: 2 | Q48: 1 | R48: 0 | S48: 1 | T48: 1 | U48: 0 | V48: 0 | W48: =SUM(E48:V48) -> 12
C49: 4. KHOIRUL ANWAR, S.Fil.I. | E49: 1 | F49: 2 | G49: 1 | H49: 1 | I49: 1 | J49: 1 | K49: 3 | L49: 1 | M49: 2 | N49: 0 | O49: 1 | P49: 2 | Q49: 0 | R49: 2 | S49: 0 | T49: 0 | U49: 3 | V49: 2 | W49: =SUM(E49:V49) -> 23
C50: 5. ARIF WIJAKSANA | E50: 0 | F50: 0 | G50: 0 | H50: 1 | I50: 0 | J50: 1 | K50: 0 | L50: 1 | M50: 1 | N50: 2 | O50: 0 | P50: 0 | Q50: 1 | R50: 0 | S50: 1 | T50: 0 | U50: 1 | V50: 2 | W50: =SUM(E50:V50) -> 11
C51: 6. Dr. SITI YUMNAH | E51: 0 | F51: 1 | G51: 2 | H51: 1 | I51: 0 | J51: 0 | K51: 0 | L51: 0 | M51: 1 | N51: 0 | O51: 0 | P51: 0 | Q51: 0 | R51: 0 | S51: 0 | T51: 2 | U51: 2 | V51: 1 | W51: =SUM(E51:V51) -> 10
...

Sheet TAMANSARI
C2: Kecamatan | D2: TEGALSARI
C3: Kabupaten | D3: BANYUWANGI
C4: Provinsi | D4: JAWA TIMUR
C9: Kelurahan | D9: TAMANSARI
A12: I | B12: DATA PEMILIH DAN PENGGUNAAN HAK PILIH | AA12: JUMLAH AKHIR
A13: A | B13: DATA PEMILIH | E13: TPS 001 | F13: TPS 002 | G13: TPS 003 | H13: TPS 004 | I13: TPS 005 | J13: TPS 006 | K13: TPS 007 | L13: TPS 008 | M13: TPS 009 | N13: TPS 010 | O13: TPS 011 | P13: TPS 012 | Q13: TPS 013 | R13: TPS 014 | S13: TPS 015 | T13: TPS 016 | U13: TPS 017 | V13: TPS 018 | W13: TPS 019 | X13: TPS 020 | Y13: TPS 021 | Z13: TPS 022
B14: Jumlah Pemilih dalam Daftar Pemilih Tetap (DPT) | D14: LK | E14: 113 | F14: 120 | G14: 114 | H14: 127 | I14: 126 | J14: 116 | K14: 116 | L14: 149 | M14: 147 | N14: 134 | O14: 133 | P14: 129 | Q14: 114 | R14: 127 | S14: 136 | T14: 104 | U14: 133 | V14: 107 | W14: 102 | X14: 123 | Y14: 106 | Z14: 134 | AA14: =SUM(E14:Z14) -> 2710
D15: PR | E15: 108 | F15: 110 | G15: 111 | H15: 117 | I15: 123 | J15: 125 | K15: 137 | L15: 144 | M15: 143 | N15: 132 | O15: 152 | P15: 121 | Q15: 127 | R15: 128 | S15: 123 | T15: 110 | U15: 133 | V15: 104 | W15: 106 | X15: 115 | Y15: 112 | Z15: 141 | AA15: =SUM(E15:Z15) -> 2722
D16: JML | E16: =SUM(E14:E15) -> 221 | F16: =SUM(F14:F15) -> 230 | G16: =SUM(G14:G15) -> 225 | H16: =SUM(H14:H15) -> 244 | I16: =SUM(I14:I15) -> 249 | J16: =SUM(J14:J15) -> 241 | K16: =SUM(K14:K15) -> 253 | L16: =SUM(L14:L15) -> 293 | ... Z16: =SUM(Z14:Z15) -> 275 | AA16: =SUM(E16:Z16) -> 5432
A18: B | B18: PENGGUNA HAK PILIH
B19: 1. | C19: Jumlah pengguna hak pilih dalam Daftar Pemilih Tetap (DPT) | D19: LK | E19: 80 | F19: 83 | G19: 79 | H19: 103 | I19: 90 | J19: 76 | K19: 86 | L19: 115 | M19: 104 | N19: 107 | O19: 89 | P19: 90 | Q19: 96 | R19: 91 | S19: 103 | T19: 78 | U19: 93 | V19: 73 | W19: 68 | X19: 95 | Y19: 79 | Z19: 106 | AA19: =SUM(E19:Z19) -> 1984
D20: PR | E20: 93 | F20: 99 | G20: 91 | H20: 98 | I20: 91 | J20: 98 | K20: 95 | L20: 117 | M20: 104 | N20: 90 | O20: 115 | P20: 95 | Q20: 96 | R20: 99 | S20: 99 | T20: 87 | U20: 100 | V20: 87 | W20: 92 | X20: 90 | Y20: 83 | Z20: 112 | AA20: =SUM(E20:Z20) -> 2131
D21: JML | E21: =SUM(E19:E20) -> 173 | F21: =SUM(F19:F20) -> 182 | G21: =SUM(G19:G20) -> 170 | H21: =SUM(H19:H20) -> 201 | I21: =SUM(I19:I20) -> 181 | J21: =SUM(J19:J20) -> 174 | K21: =SUM(K19:K20) -> 181 | L21: =SUM(L19:L20) -> 232 | ... Z21: =SUM(Z19:Z20) -> 218 | AA21: =SUM(E21:Z21) -> 4115
B22: 2. | C22: Jumlah pengguna hak pilih dalam Daftar Pemilih Tambahan (DPTb) | D22: LK | E22: 0 | F22: 0 | G22: 0 | H22: 0 | I22: 0 | J22: 1 | K22: 0 | L22: 0 | M22: 0 | N22: 0 | O22: 0 | P22: 0 | Q22: 0 | R22: 0 | S22: 1 | T22: 0 | U22: 0 | V22: 0 | W22: 0 | X22: 0 | Y22: 0 | Z22: 0 | AA22: =SUM(E22:Z22) -> 2
D23: PR | E23: 0 | F23: 0 | G23: 0 | H23: 0 | I23: 0 | J23: 0 | K23: 0 | L23: 0 | M23: 0 | N23: 0 | O23: 0 | P23: 0 | Q23: 0 | R23: 0 | S23: 3 | T23: 0 | U23: 0 | V23: 0 | W23: 0 | X23: 0 | Y23: 0 | Z23: 0 | AA23: =SUM(E23:Z23) -> 3
D24: JML | E24: =SUM(E22:E23) -> 0 | F24: =SUM(F22:F23) -> 0 | G24: =SUM(G22:G23) -> 0 | H24: =SUM(H22:H23) -> 0 | I24: =SUM(I22:I23) -> 0 | J24: =SUM(J22:J23) -> 1 | K24: =SUM(K22:K23) -> 0 | L24: =SUM(L22:L23) -> 0 | ... Z24: =SUM(Z22:Z23) -> 0 | AA24: =SUM(E24:Z24) -> 5
B25: 3. | C25: Jumlah pengguna hak pilih dalam Daftar Pemilih Khusus (DPK) | D25: LK | E25: 3 | F25: 0 | G25: 0 | H25: 0 | I25: 0 | J25: 3 | K25: 1 | L25: 1 | M25: 1 | N25: 9 | O25: 4 | P25: 0 | Q25: 0 | R25: 1 | S25: 0 | T25: 1 | U25: 0 | V25: 3 | W25: 2 | X25: 6 | Y25: 3 | Z25: 0 | AA25: =SUM(E25:Z25) -> 38
D26: PR | E26: 1 | F26: 0 | G26: 0 | H26: 0 | I26: 0 | J26: 3 | K26: 2 | L26: 0 | M26: 1 | N26: 6 | O26: 2 | P26: 1 | Q26: 0 | R26: 4 | S26: 1 | T26: 1 | U26: 0 | V26: 4 | W26: 2 | X26: 5 | Y26: 4 | Z26: 0 | AA26: =SUM(E26:Z26) -> 37
D27: JML | E27: =SUM(E25:E26) -> 4 | F27: =SUM(F25:F26) -> 0 | G27: =SUM(G25:G26) -> 0 | H27: =SUM(H25:H26) -> 0 | I27: =SUM(I25:I26) -> 0 | J27: =SUM(J25:J26) -> 6 | K27: =SUM(K25:K26) -> 3 | L27: =SUM(L25:L26) -> 1 | ... Z27: =SUM(Z25:Z26) -> 0 | AA27: =SUM(E27:Z27) -> 75
B28: 4. | C28: Jumlah Pengguna Hak Pilih (B.1+B.2+B.3) | D28: LK | E28: =SUM(E19,E22,E25) -> 83 | F28: =SUM(F19,F22,F25) -> 83 | G28: =SUM(G19,G22,G25) -> 79 | H28: =SUM(H19,H22,H25) -> 103 | I28: =SUM(I19,I22,I25) -> 90 | J28: =SUM(J19,J22,J25) -> 80 | K28: =SUM(K19,K22,K25) -> 87 | L28: =SUM(L19,L22,L25) -> 116 | ... Z28: =SUM(Z19,Z22,Z25) -> 106 | AA28: =SUM(E28:Z28) -> 2024
D29: PR | E29: =SUM(E20,E23,E26) -> 94 | F29: =SUM(F20,F23,F26) -> 99 | G29: =SUM(G20,G23,G26) -> 91 | H29: =SUM(H20,H23,H26) -> 98 | I29: =SUM(I20,I23,I26) -> 91 | J29: =SUM(J20,J23,J26) -> 101 | K29: =SUM(K20,K23,K26) -> 97 | L29: =SUM(L20,L23,L26) -> 117 | ... Z29: =SUM(Z20,Z23,Z26) -> 112 | AA29: =SUM(E29:Z29) -> 2171
D30: JML | E30: =SUM(E28:E29) -> 177 | F30: =SUM(F28:F29) -> 182 | G30: =SUM(G28:G29) -> 170 | H30: =SUM(H28:H29) -> 201 | I30: =SUM(I28:I29) -> 181 | J30: =SUM(J28:J29) -> 181 | K30: =SUM(K28:K29) -> 184 | L30: =SUM(L28:L29) -> 233 | ... Z30: =SUM(Z28:Z29) -> 218 | AA30: =SUM(E30:Z30) -> 4195
A32: II | B32: DATA PENGGUNAAN SURAT SUARA
A33: 1 | B33: Jumlah surat suara yang diterima, termasuk surat suara cadangan 2,5% dari DPT | E33: 226 | F33: 235 | G33: 230 | H33: 249 | I33: 254 | J33: 246 | K33: 259 | L33: 299 | M33: 296 | N33: 273 | O33: 291 | P33: 255 | Q33: 246 | R33: 261 | S33: 265 | T33: 219 | U33: 272 | V33: 216 | W33: 213 | X33: 243 | Y33: 223 | Z33: 281 | AA33: =SUM(E33:Z33) -> 5552
A34: 2 | B34: Jumlah surat suara yang digunakan | E34: 177 | F34: 182 | G34: 170 | H34: 201 | I34: 181 | J34: 181 | K34: 184 | L34: 233 | M34: 210 | N34: 212 | O34: 210 | P34: 186 | Q34: 192 | R34: 195 | S34: 207 | T34: 167 | U34: 193 | V34: 167 | W34: 164 | X34: 196 | Y34: 169 | Z34: 218 | AA34: =SUM(E34:Z34) -> 4195
A35: 3 | B35: Jumlah surat suara dikembalikan oleh pemilih (karena rusak atau keliru coblos) | E35: 0 | F35: 0 | G35: 0 | H35: 0 | I35: 0 | J35: 0 | K35: 0 | L35: 0 | M35: 2 | N35: 0 | O35: 0 | P35: 3 | Q35: 0 | R35: 1 | S35: 0 | T35: 1 | U35: 0 | V35: 0 | W35: 2 | X35: 0 | Y35: 0 | Z35: 0 | AA35: =SUM(E35:Z35) -> 9
A36: 4 | B36: Jumlah surat suara yang tidak digunakan/tidak terpakai, termasuk sisa surat suara cadangan | E36: =E33-(E34+E35) -> 49 | F36: =F33-(F34+F35) -> 53 | G36: =G33-(G34+G35) -> 60 | H36: =H33-(H34+H35) -> 48 | I36: =I33-(I34+I35) -> 73 | J36: =J33-(J34+J35) -> 65 | K36: =K33-(K34+K35) -> 75 | L36: =L33-(L34+L35) -> 66 | ... Z36: =Z33-(Z34+Z35) -> 63 | AA36: =SUM(E36:Z36) -> 1348
A38: III | B38: DATA PEMILIH DISABILITAS
B39: Jumlah seluruh Pemilih disabilitas yang menggunakan hak pilih | D39: LK | E39: 0 | F39: 0 | G39: 0 | H39: 0 | I39: 0 | J39: 0 | K39: 0 | L39: 0 | M39: 0 | N39: 0 | O39: 0 | P39: 0 | Q39: 0 | R39: 0 | S39: 0 | T39: 0 | U39: 0 | V39: 0 | W39: 0 | X39: 0 | Y39: 0 | Z39: 0 | AA39: =SUM(E39:Z39) -> 0
D40: PR | E40: 0 | F40: 0 | G40: 0 | H40: 0 | I40: 0 | J40: 0 | K40: 0 | L40: 0 | M40: 0 | N40: 0 | O40: 0 | P40: 0 | Q40: 0 | R40: 0 | S40: 1 | T40: 0 | U40: 0 | V40: 0 | W40: 0 | X40: 0 | Y40: 0 | Z40: 0 | AA40: =SUM(E40:Z40) -> 1
D41: JML | E41: =SUM(E39:E40) -> 0 | F41: =SUM(F39:F40) -> 0 | G41: =SUM(G39:G40) -> 0 | H41: =SUM(H39:H40) -> 0 | I41: =SUM(I39:I40) -> 0 | J41: =SUM(J39:J40) -> 0 | K41: =SUM(K39:K40) -> 0 | L41: =SUM(L39:L40) -> 0 | ... Z41: =SUM(Z39:Z40) -> 0 | AA41: =SUM(E41:Z41) -> 1
A43: IV | B43: DATA RINCIAN PEROLEHAN SUARA PASANGAN CALON BUPATI DAN WAKIL BUPATI
A44: NOMOR DAN NAMA CALON
A45: A.1 | B45: 1. | C45: Partai Kebangkitan Bangsa | E45: 3 | F45: 9 | G45: 6 | H45: 12 | I45: 8 | J45: 8 | K45: 2 | L45: 4 | M45: 8 | N45: 7 | O45: 5 | P45: 3 | Q45: 4 | R45: 3 | S45: 1 | T45: 5 | U45: 1 | V45: 3 | W45: 7 | X45: 10 | Y45: 15 | Z45: 11 | AA45: =SUM(E45:Z45) -> 135
A46: A.2 | C46: 1. Dra. Hj. MA`MULAH HARUN, M.Pd.I. | E46: 5 | F46: 9 | G46: 6 | H46: 51 | I46: 25 | J46: 12 | K46: 15 | L46: 16 | M46: 2 | N46: 2 | O46: 9 | P46: 7 | Q46: 5 | R46: 0 | S46: 10 | T46: 9 | U46: 2 | V46: 23 | W46: 30 | X46: 26 | Y46: 39 | Z46: 25 | AA46: =SUM(E46:Z46) -> 328
C47: 2. UBAIDILLAH, S.Fil.I. | E47: 0 | F47: 1 | G47: 1 | H47: 1 | I47: 2 | J47: 0 | K47: 3 | L47: 0 | M47: 0 | N47: 0 | O47: 1 | P47: 2 | Q47: 1 | R47: 0 | S47: 0 | T47: 1 | U47: 0 | V47: 0 | W47: 2 | X47: 1 | Y47: 2 | Z47: 2 | AA47: =SUM(E47:Z47) -> 20
C48: 3. Ir. H. YOYOK MULYADI, M.Si. | E48: 0 | F48: 0 | G48: 0 | H48: 1 | I48: 0 | J48: 0 | K48: 0 | L48: 3 | M48: 0 | N48: 0 | O48: 0 | P48: 0 | Q48: 0 | R48: 0 | S48: 0 | T48: 0 | U48: 1 | V48: 1 | W48: 1 | X48: 0 | Y48: 1 | Z48: 1 | AA48: =SUM(E48:Z48) -> 9
C49: 4. KHOIRUL ANWAR, S.Fil.I. | E49: 8 | F49: 0 | G49: 0 | H49: 3 | I49: 2 | J49: 0 | K49: 2 | L49: 3 | M49: 0 | N49: 1 | O49: 1 | P49: 1 | Q49: 0 | R49: 0 | S49: 1 | T49: 0 | U49: 0 | V49: 2 | W49: 1 | X49: 0 | Y49: 2 | Z49: 0 | AA49: =SUM(E49:Z49) -> 27
C50: 5. ARIF WIJAKSANA | E50: 0 | F50: 0 | G50: 1 | H50: 1 | I50: 1 | J50: 0 | K50: 0 | L50: 1 | M50: 0 | N50: 0 | O50: 0 | P50: 0 | Q50: 1 | R50: 0 | S50: 1 | T50: 0 | U50: 0 | V50: 0 | W50: 0 | X50: 0 | Y50: 1 | Z50: 0 | AA50: =SUM(E50:Z50) -> 7
C51: 6. Dr. SITI YUMNAH | E51: 0 | F51: 0 | G51: 0 | H51: 3 | I51: 1 | J51: 0 | K51: 0 | L51: 1 | M51: 1 | N51: 3 | O51: 0 | P51: 1 | Q51: 1 | R51: 1 | S51: 0 | T51: 1 | U51: 1 | V51: 0 | W51: 2 | X51: 2 | Y51: 0 | Z51: 1 | AA51: =SUM(E51:Z51) -> 19
...

Sheet TEGALREJO
C2: Kecamatan | D2: TEGALSARI
C3: Kabupaten | D3: BANYUWANGI
C4: Provinsi | D4: JAWA TIMUR
C9: Kelurahan | D9: TEGALREJO
A12: I | B12: DATA PEMILIH DAN PENGGUNAAN HAK PILIH | AB12: JUMLAH AKHIR
A13: A | B13: DATA PEMILIH | E13: TPS 001 | F13: TPS 002 | G13: TPS 003 | H13: TPS 004 | I13: TPS 005 | J13: TPS 006 | K13: TPS 007 | L13: TPS 008 | M13: TPS 009 | N13: TPS 010 | O13: TPS 011 | P13: TPS 012 | Q13: TPS 013 | R13: TPS 014 | S13: TPS 015 | T13: TPS 016 | U13: TPS 017 | V13: TPS 018 | W13: TPS 019 | X13: TPS 020 | Y13: TPS 021 | Z13: TPS 022 | AA13: TPS 023
B14: Jumlah Pemilih dalam Daftar Pemilih Tetap (DPT) | D14: LK | E14: 148 | F14: 99 | G14: 143 | H14: 144 | I14: 134 | J14: 127 | K14: 136 | L14: 92 | M14: 117 | N14: 105 | O14: 104 | P14: 133 | Q14: 136 | R14: 137 | S14: 107 | T14: 121 | U14: 104 | V14: 112 | W14: 124 | X14: 111 | Y14: 148 | Z14: 124 | AA14: 113 | AB14: =SUM(E14:AA14) -> 2819
D15: PR | E15: 148 | F15: 95 | G15: 151 | H15: 148 | I15: 137 | J15: 125 | K15: 141 | L15: 101 | M15: 105 | N15: 108 | O15: 102 | P15: 115 | Q15: 145 | R15: 146 | S15: 105 | T15: 134 | U15: 93 | V15: 117 | W15: 131 | X15: 106 | Y15: 138 | Z15: 114 | AA15: 92 | AB15: =SUM(E15:AA15) -> 2797
D16: JML | E16: =SUM(E14:E15) -> 296 | F16: =SUM(F14:F15) -> 194 | G16: =SUM(G14:G15) -> 294 | H16: =SUM(H14:H15) -> 292 | I16: =SUM(I14:I15) -> 271 | J16: =SUM(J14:J15) -> 252 | K16: =SUM(K14:K15) -> 277 | L16: =SUM(L14:L15) -> 193 | ... AA16: =SUM(AA14:AA15) -> 205 | AB16: =SUM(E16:AA16) -> 5616
A18: B | B18: PENGGUNA HAK PILIH
B19: 1. | C19: Jumlah pengguna hak pilih dalam Daftar Pemilih Tetap (DPT) | D19: LK | E19: 109 | F19: 81 | G19: 113 | H19: 92 | I19: 105 | J19: 93 | K19: 96 | L19: 58 | M19: 83 | N19: 75 | O19: 76 | P19: 97 | Q19: 109 | R19: 99 | S19: 76 | T19: 89 | U19: 70 | V19: 78 | W19: 90 | X19: 78 | Y19: 108 | Z19: 93 | AA19: 79 | AB19: =SUM(E19:AA19) -> 2047
D20: PR | E20: 111 | F20: 80 | G20: 129 | H20: 117 | I20: 94 | J20: 97 | K20: 98 | L20: 80 | M20: 82 | N20: 83 | O20: 85 | P20: 93 | Q20: 114 | R20: 121 | S20: 85 | T20: 93 | U20: 74 | V20: 87 | W20: 83 | X20: 80 | Y20: 108 | Z20: 81 | AA20: 69 | AB20: =SUM(E20:AA20) -> 2144
D21: JML | E21: =SUM(E19:E20) -> 220 | F21: =SUM(F19:F20) -> 161 | G21: =SUM(G19:G20) -> 242 | H21: =SUM(H19:H20) -> 209 | I21: =SUM(I19:I20) -> 199 | J21: =SUM(J19:J20) -> 190 | K21: =SUM(K19:K20) -> 194 | L21: =SUM(L19:L20) -> 138 | ... AA21: =SUM(AA19:AA20) -> 148 | AB21: =SUM(E21:AA21) -> 4191
B22: 2. | C22: Jumlah pengguna hak pilih dalam Daftar Pemilih Tambahan (DPTb) | D22: LK | E22: 0 | F22: 0 | G22: 1 | H22: 0 | I22: 0 | J22: 0 | K22: 0 | L22: 0 | M22: 0 | N22: 0 | O22: 0 | P22: 0 | Q22: 0 | R22: 0 | S22: 0 | T22: 0 | U22: 0 | V22: 0 | W22: 0 | X22: 0 | Y22: 0 | Z22: 0 | AA22: 1 | AB22: =SUM(E22:AA22) -> 2
D23: PR | E23: 0 | F23: 0 | G23: 1 | H23: 0 | I23: 0 | J23: 0 | K23: 1 | L23: 0 | M23: 0 | N23: 0 | O23: 0 | P23: 0 | Q23: 0 | R23: 0 | S23: 0 | T23: 0 | U23: 0 | V23: 0 | W23: 0 | X23: 0 | Y23: 0 | Z23: 0 | AA23: 1 | AB23: =SUM(E23:AA23) -> 3
D24: JML | E24: =SUM(E22:E23) -> 0 | F24: =SUM(F22:F23) -> 0 | G24: =SUM(G22:G23) -> 2 | H24: =SUM(H22:H23) -> 0 | I24: =SUM(I22:I23) -> 0 | J24: =SUM(J22:J23) -> 0 | K24: =SUM(K22:K23) -> 1 | L24: =SUM(L22:L23) -> 0 | ... AA24: =SUM(AA22:AA23) -> 2 | AB24: =SUM(E24:AA24) -> 5
B25: 3. | C25: Jumlah pengguna hak pilih dalam Daftar Pemilih Khusus (DPK) | D25: LK | E25: 0 | F25: 2 | G25: 3 | H25: 2 | I25: 1 | J25: 0 | K25: 0 | L25: 0 | M25: 1 | N25: 0 | O25: 1 | P25: 1 | Q25: 1 | R25: 0 | S25: 0 | T25: 0 | U25: 0 | V25: 2 | W25: 0 | X25: 1 | Y25: 1 | Z25: 2 | AA25: 2 | AB25: =SUM(E25:AA25) -> 20
D26: PR | E26: 4 | F26: 1 | G26: 0 | H26: 1 | I26: 1 | J26: 0 | K26: 1 | L26: 1 | M26: 7 | N26: 0 | O26: 1 | P26: 3 | Q26: 2 | R26: 2 | S26: 1 | T26: 2 | U26: 1 | V26: 1 | W26: 1 | X26: 0 | Y26: 5 | Z26: 2 | AA26: 5 | AB26: =SUM(E26:AA26) -> 42
D27: JML | E27: =SUM(E25:E26) -> 4 | F27: =SUM(F25:F26) -> 3 | G27: =SUM(G25:G26) -> 3 | H27: =SUM(H25:H26) -> 3 | I27: =SUM(I25:I26) -> 2 | J27: =SUM(J25:J26) -> 0 | K27: =SUM(K25:K26) -> 1 | L27: =SUM(L25:L26) -> 1 | ... AA27: =SUM(AA25:AA26) -> 7 | AB27: =SUM(E27:AA27) -> 62
B28: 4. | C28: Jumlah Pengguna Hak Pilih (B.1+B.2+B.3) | D28: LK | E28: =SUM(E19,E22,E25) -> 109 | F28: =SUM(F19,F22,F25) -> 83 | G28: =SUM(G19,G22,G25) -> 117 | H28: =SUM(H19,H22,H25) -> 94 | I28: =SUM(I19,I22,I25) -> 106 | J28: =SUM(J19,J22,J25) -> 93 | K28: =SUM(K19,K22,K25) -> 96 | L28: =SUM(L19,L22,L25) -> 58 | ... AA28: =SUM(AA19,AA22,AA25) -> 82 | AB28: =SUM(E28:AA28) -> 2069
D29: PR | E29: =SUM(E20,E23,E26) -> 115 | F29: =SUM(F20,F23,F26) -> 81 | G29: =SUM(G20,G23,G26) -> 130 | H29: =SUM(H20,H23,H26) -> 118 | I29: =SUM(I20,I23,I26) -> 95 | J29: =SUM(J20,J23,J26) -> 97 | K29: =SUM(K20,K23,K26) -> 100 | L29: =SUM(L20,L23,L26) -> 81 | ... AA29: =SUM(AA20,AA23,AA26) -> 75 | AB29: =SUM(E29:AA29) -> 2189
D30: JML | E30: =SUM(E28:E29) -> 224 | F30: =SUM(F28:F29) -> 164 | G30: =SUM(G28:G29) -> 247 | H30: =SUM(H28:H29) -> 212 | I30: =SUM(I28:I29) -> 201 | J30: =SUM(J28:J29) -> 190 | K30: =SUM(K28:K29) -> 196 | L30: =SUM(L28:L29) -> 139 | ... AA30: =SUM(AA28:AA29) -> 157 | AB30: =SUM(E30:AA30) -> 4258
A32: II | B32: DATA PENGGUNAAN SURAT SUARA
A33: 1 | B33: Jumlah surat suara yang diterima, termasuk surat suara cadangan 2,5% dari DPT | E33: 302 | F33: 198 | G33: 300 | H33: 298 | I33: 277 | J33: 258 | K33: 283 | L33: 198 | M33: 227 | N33: 218 | O33: 211 | P33: 253 | Q33: 287 | R33: 289 | S33: 217 | T33: 261 | U33: 201 | V33: 234 | W33: 261 | X33: 222 | Y33: 292 | Z33: 243 | AA33: 210 | AB33: =SUM(E33:AA33) -> 5740
A34: 2 | B34: Jumlah surat suara yang digunakan | E34: 224 | F34: 164 | G34: 247 | H34: 212 | I34: 201 | J34: 190 | K34: 196 | L34: 139 | M34: 173 | N34: 158 | O34: 163 | P34: 194 | Q34: 226 | R34: 222 | S34: 162 | T34: 184 | U34: 145 | V34: 168 | W34: 174 | X34: 159 | Y34: 222 | Z34: 178 | AA34: 157 | AB34: =SUM(E34:AA34) -> 4258
A35: 3 | B35: Jumlah surat suara dikembalikan oleh pemilih (karena rusak atau keliru coblos) | E35: 0 | F35: 0 | G35: 0 | H35: 0 | I35: 0 | J35: 0 | K35: 0 | L35: 0 | M35: 0 | N35: 0 | O35: 0 | P35: 1 | Q35: 0 | R35: 0 | S35: 0 | T35: 0 | U35: 0 | V35: 0 | W35: 1 | X35: 1 | Y35: 1 | Z35: 1 | AA35: 1 | AB35: =SUM(E35:AA35) -> 6
A36: 4 | B36: Jumlah surat suara yang tidak digunakan/tidak terpakai, termasuk sisa surat suara cadangan | E36: =E33-(E34+E35) -> 78 | F36: =F33-(F34+F35) -> 34 | G36: =G33-(G34+G35) -> 53 | H36: =H33-(H34+H35) -> 86 | I36: =I33-(I34+I35) -> 76 | J36: =J33-(J34+J35) -> 68 | K36: =K33-(K34+K35) -> 87 | L36: =L33-(L34+L35) -> 59 | ... AA36: =AA33-(AA34+AA35) -> 52 | AB36: =SUM(E36:AA36) -> 1476
A38: III | B38: DATA PEMILIH DISABILITAS
B39: Jumlah seluruh Pemilih disabilitas yang menggunakan hak pilih | D39: LK | E39: 0 | F39: 0 | G39: 0 | H39: 0 | I39: 0 | J39: 0 | K39: 0 | L39: 1 | M39: 0 | N39: 1 | O39: 0 | P39: 0 | Q39: 0 | R39: 0 | S39: 0 | T39: 0 | U39: 2 | V39: 0 | W39: 0 | X39: 1 | Y39: 1 | Z39: 0 | AA39: 0 | AB39: =SUM(E39:AA39) -> 6
D40: PR | E40: 1 | F40: 0 | G40: 0 | H40: 0 | I40: 0 | J40: 0 | K40: 0 | L40: 0 | M40: 1 | N40: 0 | O40: 0 | P40: 0 | Q40: 0 | R40: 0 | S40: 0 | T40: 0 | U40: 0 | V40: 0 | W40: 0 | X40: 1 | Y40: 1 | Z40: 0 | AA40: 0 | AB40: =SUM(E40:AA40) -> 4
D41: JML | E41: =SUM(E39:E40) -> 1 | F41: =SUM(F39:F40) -> 0 | G41: =SUM(G39:G40) -> 0 | H41: =SUM(H39:H40) -> 0 | I41: =SUM(I39:I40) -> 0 | J41: =SUM(J39:J40) -> 0 | K41: =SUM(K39:K40) -> 0 | L41: =SUM(L39:L40) -> 1 | ... AA41: =SUM(AA39:AA40) -> 0 | AB41: =SUM(E41:AA41) -> 10
A43: IV | B43: DATA RINCIAN PEROLEHAN SUARA PASANGAN CALON BUPATI DAN WAKIL BUPATI
A44: NOMOR DAN NAMA CALON
A45: A.1 | B45: 1. | C45: Partai Kebangkitan Bangsa | E45: 11 | F45: 8 | G45: 7 | H45: 5 | I45: 9 | J45: 8 | K45: 7 | L45: 4 | M45: 20 | N45: 5 | O45: 4 | P45: 2 | Q45: 8 | R45: 16 | S45: 1 | T45: 5 | U45: 2 | V45: 1 | W45: 5 | X45: 5 | Y45: 6 | Z45: 2 | AA45: 7 | AB45: =SUM(E45:AA45) -> 148
A46: A.2 | C46: 1. Dra. Hj. MA`MULAH HARUN, M.Pd.I. | E46: 15 | F46: 23 | G46: 27 | H46: 4 | I46: 11 | J46: 12 | K46: 9 | L46: 4 | M46: 18 | N46: 6 | O46: 2 | P46: 3 | Q46: 12 | R46: 7 | S46: 4 | T46: 8 | U46: 3 | V46: 14 | W46: 6 | X46: 3 | Y46: 6 | Z46: 5 | AA46: 3 | AB46: =SUM(E46:AA46) -> 205
C47: 2. UBAIDILLAH, S.Fil.I. | E47: 61 | F47: 37 | G47: 37 | H47: 105 | I47: 51 | J47: 22 | K47: 43 | L47: 9 | M47: 18 | N47: 11 | O47: 78 | P47: 58 | Q47: 49 | R47: 62 | S47: 11 | T47: 40 | U47: 33 | V47: 22 | W47: 10 | X47: 40 | Y47: 33 | Z47: 26 | AA47: 22 | AB47: =SUM(E47:AA47) -> 878
C48: 3. Ir. H. YOYOK MULYADI, M.Si. | E48: 2 | F48: 1 | G48: 1 | H48: 1 | I48: 1 | J48: 1 | K48: 0 | L48: 0 | M48: 1 | N48: 0 | O48: 0 | P48: 0 | Q48: 0 | R48: 1 | S48: 0 | T48: 0 | U48: 0 | V48: 0 | W48: 2 | X48: 0 | Y48: 1 | Z48: 0 | AA48: 0 | AB48: =SUM(E48:AA48) -> 12
C49: 4. KHOIRUL ANWAR, S.Fil.I. | E49: 3 | F49: 2 | G49: 0 | H49: 1 | I49: 1 | J49: 1 | K49: 1 | L49: 0 | M49: 2 | N49: 0 | O49: 1 | P49: 0 | Q49: 0 | R49: 0 | S49: 0 | T49: 0 | U49: 1 | V49: 2 | W49: 1 | X49: 2 | Y49: 1 | Z49: 1 | AA49: 0 | AB49: =SUM(E49:AA49) -> 20
C50: 5. ARIF WIJAKSANA | E50: 1 | F50: 1 | G50: 3 | H50: 0 | I50: 0 | J50: 1 | K50: 0 | L50: 1 | M50: 2 | N50: 1 | O50: 0 | P50: 0 | Q50: 1 | R50: 0 | S50: 0 | T50: 1 | U50: 0 | V50: 1 | W50: 0 | X50: 0 | Y50: 0 | Z50: 1 | AA50: 1 | AB50: =SUM(E50:AA50) -> 15
C51: 6. Dr. SITI YUMNAH | E51: 1 | F51: 1 | G51: 1 | H51: 0 | I51: 1 | J51: 1 | K51: 1 | L51: 1 | M51: 3 | N51: 2 | O51: 1 | P51: 5 | Q51: 4 | R51: 1 | S51: 1 | T51: 1 | U51: 1 | V51: 1 | W51: 1 | X51: 0 | Y51: 0 | Z51: 2 | AA51: 0 | AB51: =SUM(E51:AA51) -> 30
...

Sheet TEGALSARI
C2: Kecamatan | D2: TEGALSARI
C3: Kabupaten | D3: BANYUWANGI
C4: Provinsi | D4: JAWA TIMUR
C9: Kelurahan | D9: TEGALSARI
A12: I | B12: DATA PEMILIH DAN PENGGUNAAN HAK PILIH | AU12: JUMLAH AKHIR
A13: A | B13: DATA PEMILIH | E13: TPS 001 | F13: TPS 002 | G13: TPS 003 | H13: TPS 004 | I13: TPS 005 | J13: TPS 006 | K13: TPS 007 | L13: TPS 008 | M13: TPS 009 | N13: TPS 010 | O13: TPS 011 | P13: TPS 012 | Q13: TPS 013 | R13: TPS 014 | S13: TPS 015 | T13: TPS 016 | U13: TPS 017 | V13: TPS 018 | W13: TPS 019 | X13: TPS 020 | Y13: TPS 021 | Z13: TPS 022 | AA13: TPS 023 | AB13: TPS 024 | AC13: TPS 025 | AD13: TPS 026 | AE13: TPS 027 | AF13: TPS 028 | AG13: TPS 029 | AH13: TPS 030 | AI13: TPS 031 | AJ13: TPS 032 | AK13: TPS 033 | AL13: TPS 034 | AM13: TPS 035 | AN13: TPS 036 | AO13: TPS 037 | AP13: TPS 038 | AQ13: TPS 039 | AR13: TPS 040 | AS13: TPS 041 | AT13: TPS 042
B14: Jumlah Pemilih dalam Daftar Pemilih Tetap (DPT) | D14: LK | E14: 132 | F14: 123 | G14: 122 | H14: 122 | I14: 126 | J14: 124 | K14: 92 | L14: 89 | M14: 131 | N14: 135 | O14: 144 | P14: 99 | Q14: 110 | R14: 102 | S14: 125 | T14: 143 | U14: 102 | V14: 122 | W14: 140 | X14: 127 | Y14: 120 | Z14: 108 | AA14: 145 | AB14: 126 | AC14: 126 | AD14: 142 | AE14: 128 | AF14: 128 | AG14: 139 | AH14: 107 | AI14: 113 | AJ14: 110 | AK14: 123 | AL14: 121 | AM14: 123 | AN14: 123 | AO14: 121 | AP14: 134 | AQ14: 132 | AR14: 137 | AS14: 151 | AT14: 92 | AU14: =SUM(E14:AT14) -> 5159
D15: PR | E15: 123 | F15: 137 | G15: 99 | H15: 127 | I15: 118 | J15: 128 | K15: 89 | L15: 85 | M15: 131 | N15: 127 | O15: 144 | P15: 96 | Q15: 117 | R15: 112 | S15: 126 | T15: 130 | U15: 104 | V15: 127 | W15: 146 | X15: 134 | Y15: 130 | Z15: 112 | AA15: 143 | AB15: 131 | AC15: 134 | AD15: 140 | AE15: 112 | AF15: 134 | AG15: 136 | AH15: 94 | AI15: 116 | AJ15: 104 | AK15: 138 | AL15: 117 | AM15: 115 | AN15: 109 | AO15: 123 | AP15: 129 | AQ15: 134 | AR15: 131 | AS15: 134 | AT15: 96 | AU15: =SUM(E15:AT15) -> 5112
D16: JML | E16: =SUM(E14:E15) -> 255 | F16: =SUM(F14:F15) -> 260 | G16: =SUM(G14:G15) -> 221 | H16: =SUM(H14:H15) -> 249 | I16: =SUM(I14:I15) -> 244 | J16: =SUM(J14:J15) -> 252 | K16: =SUM(K14:K15) -> 181 | L16: =SUM(L14:L15) -> 174 | ... AT16: =SUM(AT14:AT15) -> 188 | AU16: =SUM(E16:AT16) -> 10271
A18: B | B18: PENGGUNA HAK PILIH
B19: 1. | C19: Jumlah pengguna hak pilih dalam Daftar Pemilih Tetap (DPT) | D19: LK | E19: 105 | F19: 91 | G19: 85 | H19: 103 | I19: 107 | J19: 102 | K19: 61 | L19: 67 | M19: 103 | N19: 113 | O19: 110 | P19: 83 | Q19: 79 | R19: 72 | S19: 76 | T19: 99 | U19: 74 | V19: 83 | W19: 105 | X19: 84 | Y19: 83 | Z19: 72 | AA19: 108 | AB19: 100 | AC19: 95 | AD19: 87 | AE19: 95 | AF19: 99 | AG19: 97 | AH19: 83 | AI19: 91 | AJ19: 81 | AK19: 99 | AL19: 90 | AM19: 88 | AN19: 96 | AO19: 86 | AP19: 91 | AQ19: 110 | AR19: 99 | AS19: 102 | AT19: 59 | AU19: =SUM(E19:AT19) -> 3813
D20: PR | E20: 98 | F20: 113 | G20: 76 | H20: 115 | I20: 100 | J20: 106 | K20: 74 | L20: 72 | M20: 108 | N20: 112 | O20: 107 | P20: 84 | Q20: 97 | R20: 110 | S20: 103 | T20: 103 | U20: 79 | V20: 86 | W20: 107 | X20: 99 | Y20: 97 | Z20: 81 | AA20: 114 | AB20: 112 | AC20: 116 | AD20: 111 | AE20: 95 | AF20: 109 | AG20: 109 | AH20: 78 | AI20: 99 | AJ20: 87 | AK20: 101 | AL20: 100 | AM20: 95 | AN20: 88 | AO20: 98 | AP20: 105 | AQ20: 123 | AR20: 105 | AS20: 107 | AT20: 69 | AU20: =SUM(E20:AT20) -> 4148
D21: JML | E21: =SUM(E19:E20) -> 203 | F21: =SUM(F19:F20) -> 204 | G21: =SUM(G19:G20) -> 161 | H21: =SUM(H19:H20) -> 218 | I21: =SUM(I19:I20) -> 207 | J21: =SUM(J19:J20) -> 208 | K21: =SUM(K19:K20) -> 135 | L21: =SUM(L19:L20) -> 139 | ... AT21: =SUM(AT19:AT20) -> 128 | AU21: =SUM(E21:AT21) -> 7961
B22: 2. | C22: Jumlah pengguna hak pilih dalam Daftar Pemilih Tambahan (DPTb) | D22: LK | E22: 0 | F22: 0 | G22: 0 | H22: 0 | I22: 0 | J22: 1 | K22: 0 | L22: 0 | M22: 0 | N22: 1 | O22: 0 | P22: 0 | Q22: 0 | R22: 0 | S22: 0 | T22: 0 | U22: 0 | V22: 0 | W22: 0 | X22: 0 | Y22: 0 | Z22: 0 | AA22: 0 | AB22: 0 | AC22: 0 | AD22: 0 | AE22: 0 | AF22: 0 | AG22: 1 | AH22: 0 | AI22: 0 | AJ22: 0 | AK22: 0 | AL22: 0 | AM22: 0 | AN22: 0 | AO22: 0 | AP22: 0 | AQ22: 0 | AR22: 1 | AS22: 0 | AT22: 0 | AU22: =SUM(E22:AT22) -> 4
D23: PR | E23: 2 | F23: 0 | G23: 0 | H23: 0 | I23: 0 | J23: 0 | K23: 0 | L23: 0 | M23: 0 | N23: 0 | O23: 0 | P23: 0 | Q23: 0 | R23: 0 | S23: 0 | T23: 0 | U23: 0 | V23: 1 | W23: 0 | X23: 0 | Y23: 0 | Z23: 1 | AA23: 0 | AB23: 0 | AC23: 0 | AD23: 0 | AE23: 0 | AF23: 0 | AG23: 0 | AH23: 0 | AI23: 0 | AJ23: 0 | AK23: 0 | AL23: 0 | AM23: 1 | AN23: 0 | AO23: 0 | AP23: 0 | AQ23: 0 | AR23: 0 | AS23: 0 | AT23: 0 | AU23: =SUM(E23:AT23) -> 5
D24: JML | E24: =SUM(E22:E23) -> 2 | F24: =SUM(F22:F23) -> 0 | G24: =SUM(G22:G23) -> 0 | H24: =SUM(H22:H23) -> 0 | I24: =SUM(I22:I23) -> 0 | J24: =SUM(J22:J23) -> 1 | K24: =SUM(K22:K23) -> 0 | L24: =SUM(L22:L23) -> 0 | ... AT24: =SUM(AT22:AT23) -> 0 | AU24: =SUM(E24:AT24) -> 9
