Workbook

Sheet DPRD PROVINSI
C8: Kecamatan | D8: GIRI
C9: Kabupaten | D9: BANYUWANGI
C10: Provinsi | D10: JAWA TIMUR
A12: I | B12: DATA PEMILIH DAN PENGGUNAAN HAK PILIH | E12: JUMLAH AKHIR
A13: A | B13: DATA PEMILIH
B14: Jumlah Pemilih dalam Daftar Pemilih Tetap (DPT) | D14: LK | E14: =BOYOLANGU!U14+GIRI!V14+GROGOL!V14+JAMBESARI!O14+MOJOPANGGUNG!V14+PENATABAN!V14 -> 12715
D15: PR | E15: =BOYOLANGU!U15+GIRI!V15+GROGOL!V15+JAMBESARI!O15+MOJOPANGGUNG!V15+PENATABAN!V15 -> 12285
D16: JML | E16: =SUM(E14:E15) -> 25000
A18: B | B18: PENGGUNA HAK PILIH
B19: 1. | C19: Jumlah pengguna hak pilih dalam Daftar Pemilih Tetap (DPT) | D19: LK | E19: =BOYOLANGU!U19+GIRI!V19+GROGOL!V19+JAMBESARI!O19+MOJOPANGGUNG!V19+PENATABAN!V19 -> 9670
D20: PR | E20: =BOYOLANGU!U20+GIRI!V20+GROGOL!V20+JAMBESARI!O20+MOJOPANGGUNG!V20+PENATABAN!V20 -> 10223
D21: JML | E21: =SUM(E19:E20) -> 19893
B22: 2. | C22: Jumlah pengguna hak pilih dalam Daftar Pemilih Tambahan (DPTb) | D22: LK | E22: =BOYOLANGU!U22+GIRI!V22+GROGOL!V22+JAMBESARI!O22+MOJOPANGGUNG!V22+PENATABAN!V22 -> 324
D23: PR | E23: =BOYOLANGU!U23+GIRI!V23+GROGOL!V23+JAMBESARI!O23+MOJOPANGGUNG!V23+PENATABAN!V23 -> 32
D24: JML | E24: =SUM(E22:E23) -> 356
B25: 3. | C25: Jumlah pengguna hak pilih dalam Daftar Pemilih Khusus (DPK) | D25: LK | E25: =BOYOLANGU!U25+GIRI!V25+GROGOL!V25+JAMBESARI!O25+MOJOPANGGUNG!V25+PENATABAN!V25 -> 52
D26: PR | E26: =BOYOLANGU!U26+GIRI!V26+GROGOL!V26+JAMBESARI!O26+MOJOPANGGUNG!V26+PENATABAN!V26 -> 95
D27: JML | E27: =SUM(E25:E26) -> 147
B28: 4. | C28: Jumlah Pengguna Hak Pilih (B.1+B.2+B.3) | D28: LK | E28: =E19+E22+E25 -> 10046
D29: PR | E29: =E20+E23+E26 -> 10350
D30: JML | E30: =SUM(E28:E29) -> 20396
A32: II | B32: DATA PENGGUNAAN SURAT SUARA
A33: 1 | B33: Jumlah surat suara yang diterima, termasuk surat suara cadangan 2,5% dari DPT | E33: =BOYOLANGU!U33+GIRI!V33+GROGOL!V33+JAMBESARI!O33+MOJOPANGGUNG!V33+PENATABAN!V33 -> 25519
A34: 2 | B34: Jumlah surat suara yang digunakan | E34: =BOYOLANGU!U34+GIRI!V34+GROGOL!V34+JAMBESARI!O34+MOJOPANGGUNG!V34+PENATABAN!V34 -> 20396
A35: 3 | B35: Jumlah surat suara dikembalikan oleh pemilih (karena rusak atau keliru coblos) | E35: =BOYOLANGU!U35+GIRI!V35+GROGOL!V35+JAMBESARI!O35+MOJOPANGGUNG!V35+PENATABAN!V35 -> 43
A36: 4 | B36: Jumlah surat suara yang tidak digunakan/tidak terpakai, termasuk sisa surat suara cadangan | E36: =E33-(E34+E35) -> 5080
A38: III | B38: DATA PEMILIH DISABILITAS
B39: Jumlah seluruh Pemilih disabilitas yang menggunakan hak pilih | D39: LK | E39: =BOYOLANGU!U39+GIRI!V39+GROGOL!V39+JAMBESARI!O39+MOJOPANGGUNG!V39+PENATABAN!V39 -> 28
D40: PR | E40: =BOYOLANGU!U40+GIRI!V40+GROGOL!V40+JAMBESARI!O40+MOJOPANGGUNG!V40+PENATABAN!V40 -> 20
D41: JML | E41: =SUM(E39:E40) -> 48
A43: IV | B43: DATA RINCIAN PEROLEHAN SUARA PASANGAN CALON BUPATI DAN WAKIL BUPATI
A44: NOMOR DAN NAMA CALON
A45: A.1 | B45: 1. | C45: Partai Kebangkitan Bangsa | E45: =BOYOLANGU!U45+GIRI!V45+GROGOL!V45+JAMBESARI!O45+MOJOPANGGUNG!V45+PENATABAN!V45 -> 1094
A46: A.2 | C46: 1. Dra. Hj. MA`MULAH HARUN, M.Pd.I. | E46: =BOYOLANGU!U46+GIRI!V46+GROGOL!V46+JAMBESARI!O46+MOJOPANGGUNG!V46+PENATABAN!V46 -> 3015
C47: 2. UBAIDILLAH, S.Fil.I. | E47: =BOYOLANGU!U47+GIRI!V47+GROGOL!V47+JAMBESARI!O47+MOJOPANGGUNG!V47+PENATABAN!V47 -> 148
C48: 3. Ir. H. YOYOK MULYADI, M.Si. | E48: =BOYOLANGU!U48+GIRI!V48+GROGOL!V48+JAMBESARI!O48+MOJOPANGGUNG!V48+PENATABAN!V48 -> 54
C49: 4. KHOIRUL ANWAR, S.Fil.I. | E49: =BOYOLANGU!U49+GIRI!V49+GROGOL!V49+JAMBESARI!O49+MOJOPANGGUNG!V49+PENATABAN!V49 -> 62
C50: 5. ARIF WIJAKSANA | E50: =BOYOLANGU!U50+GIRI!V50+GROGOL!V50+JAMBESARI!O50+MOJOPANGGUNG!V50+PENATABAN!V50 -> 47
C51: 6. Dr. SITI YUMNAH | E51: =BOYOLANGU!U51+GIRI!V51+GROGOL!V51+JAMBESARI!O51+MOJOPANGGUNG!V51+PENATABAN!V51 -> 40
C52: 7. MOHAMMAD ZAINI, M.Pd.I. | E52: =BOYOLANGU!U52+GIRI!V52+GROGOL!V52+JAMBESARI!O52+MOJOPANGGUNG!V52+PENATABAN!V52 -> 31
...

Sheet BOYOLANGU
C2: Kecamatan | D2: GIRI
C3: Kabupaten | D3: BANYUWANGI
C4: Provinsi | D4: JAWA TIMUR
C9: Kelurahan | D9: BOYOLANGU
A12: I | B12: DATA PEMILIH DAN PENGGUNAAN HAK PILIH | U12: JUMLAH AKHIR
A13: A | B13: DATA PEMILIH | E13: TPS 001 | F13: TPS 002 | G13: TPS 003 | H13: TPS 004 | I13: TPS 005 | J13: TPS 006 | K13: TPS 007 | L13: TPS 008 | M13: TPS 009 | N13: TPS 010 | O13: TPS 011 | P13: TPS 012 | Q13: TPS 013 | R13: TPS 014 | S13: TPS 015 | T13: TPS 016
B14: Jumlah Pemilih dalam Daftar Pemilih Tetap (DPT) | D14: LK | E14: 137 | F14: 142 | G14: 142 | H14: 141 | I14: 150 | J14: 155 | K14: 146 | L14: 155 | M14: 152 | N14: 139 | O14: 110 | P14: 125 | Q14: 110 | R14: 108 | S14: 70 | T14: 139 | U14: =SUM(E14:T14) -> 2121
D15: PR | E15: 158 | F15: 154 | G15: 155 | H15: 156 | I15: 146 | J15: 142 | K15: 152 | L15: 143 | M15: 145 | N15: 159 | O15: 111 | P15: 133 | Q15: 117 | R15: 117 | S15: 78 | T15: 128 | U15: =SUM(E15:T15) -> 2194
D16: JML | E16: =SUM(E14:E15) -> 295 | F16: =SUM(F14:F15) -> 296 | G16: =SUM(G14:G15) -> 297 | H16: =SUM(H14:H15) -> 297 | I16: =SUM(I14:I15) -> 296 | J16: =SUM(J14:J15) -> 297 | K16: =SUM(K14:K15) -> 298 | L16: =SUM(L14:L15) -> 298 | ... T16: =SUM(T14:T15) -> 267 | U16: =SUM(E16:T16) -> 4315
A18: B | B18: PENGGUNA HAK PILIH
B19: 1. | C19: Jumlah pengguna hak pilih dalam Daftar Pemilih Tetap (DPT) | D19: LK | E19: 89 | F19: 113 | G19: 117 | H19: 118 | I19: 115 | J19: 121 | K19: 107 | L19: 115 | M19: 129 | N19: 105 | O19: 88 | P19: 101 | Q19: 99 | R19: 90 | S19: 51 | T19: 106 | U19: =SUM(E19:T19) -> 1664
D20: PR | E20: 117 | F20: 120 | G20: 134 | H20: 136 | I20: 114 | J20: 123 | K20: 135 | L20: 121 | M20: 131 | N20: 128 | O20: 103 | P20: 112 | Q20: 110 | R20: 100 | S20: 68 | T20: 109 | U20: =SUM(E20:T20) -> 1861
D21: JML | E21: =SUM(E19:E20) -> 206 | F21: =SUM(F19:F20) -> 233 | G21: =SUM(G19:G20) -> 251 | H21: =SUM(H19:H20) -> 254 | I21: =SUM(I19:I20) -> 229 | J21: =SUM(J19:J20) -> 244 | K21: =SUM(K19:K20) -> 242 | L21: =SUM(L19:L20) -> 236 | ... T21: =SUM(T19:T20) -> 215 | U21: =SUM(E21:T21) -> 3525
B22: 2. | C22: Jumlah pengguna hak pilih dalam Daftar Pemilih Tambahan (DPTb) | D22: LK | U22: =SUM(E22:T22) -> 0
D23: PR | E23: 1 | U23: =SUM(E23:T23) -> 1
D24: JML | E24: =SUM(E22:E23) -> 1 | F24: =SUM(F22:F23) -> 0 | G24: =SUM(G22:G23) -> 0 | H24: =SUM(H22:H23) -> 0 | I24: =SUM(I22:I23) -> 0 | J24: =SUM(J22:J23) -> 0 | K24: =SUM(K22:K23) -> 0 | L24: =SUM(L22:L23) -> 0 | ... T24: =SUM(T22:T23) -> 0 | U24: =SUM(E24:T24) -> 1
B25: 3. | C25: Jumlah pengguna hak pilih dalam Daftar Pemilih Khusus (DPK) | D25: LK | E25: 3 | F25: 2 | H25: 2 | N25: 1 | S25: 1 | U25: =SUM(E25:T25) -> 9
D26: PR | E26: 5 | H26: 1 | I26: 1 | L26: 1 | N26: 1 | R26: 1 | U26: =SUM(E26:T26) -> 10
D27: JML | E27: =SUM(E25:E26) -> 8 | F27: =SUM(F25:F26) -> 2 | G27: =SUM(G25:G26) -> 0 | H27: =SUM(H25:H26) -> 3 | I27: =SUM(I25:I26) -> 1 | J27: =SUM(J25:J26) -> 0 | K27: =SUM(K25:K26) -> 0 | L27: =SUM(L25:L26) -> 1 | ... T27: =SUM(T25:T26) -> 0 | U27: =SUM(E27:T27) -> 19
B28: 4. | C28: Jumlah Pengguna Hak Pilih (B.1+B.2+B.3) | D28: LK | E28: =SUM(E19,E22,E25) -> 92 | F28: =SUM(F19,F22,F25) -> 115 | G28: =SUM(G19,G22,G25) -> 117 | H28: =SUM(H19,H22,H25) -> 120 | I28: =SUM(I19,I22,I25) -> 115 | J28: =SUM(J19,J22,J25) -> 121 | K28: =SUM(K19,K22,K25) -> 107 | L28: =SUM(L19,L22,L25) -> 115 | ... T28: =SUM(T19,T22,T25) -> 106 | U28: =SUM(E28:T28) -> 1673
D29: PR | E29: =SUM(E20,E23,E26) -> 123 | F29: =SUM(F20,F23,F26) -> 120 | G29: =SUM(G20,G23,G26) -> 134 | H29: =SUM(H20,H23,H26) -> 137 | I29: =SUM(I20,I23,I26) -> 115 | J29: =SUM(J20,J23,J26) -> 123 | K29: =SUM(K20,K23,K26) -> 135 | L29: =SUM(L20,L23,L26) -> 122 | ... T29: =SUM(T20,T23,T26) -> 109 | U29: =SUM(E29:T29) -> 1872
D30: JML | E30: =SUM(E28:E29) -> 215 | F30: =SUM(F28:F29) -> 235 | G30: =SUM(G28:G29) -> 251 | H30: =SUM(H28:H29) -> 257 | I30: =SUM(I28:I29) -> 230 | J30: =SUM(J28:J29) -> 244 | K30: =SUM(K28:K29) -> 242 | L30: =SUM(L28:L29) -> 237 | ... T30: =SUM(T28:T29) -> 215 | U30: =SUM(E30:T30) -> 3545
A32: II | B32: DATA PENGGUNAAN SURAT SUARA
A33: 1 | B33: Jumlah surat suara yang diterima, termasuk surat suara cadangan 2,5% dari DPT | E33: 301 | F33: 302 | G33: 303 | H33: 303 | I33: 302 | J33: 303 | K33: 303 | L33: 304 | M33: 303 | N33: 304 | O33: 226 | P33: 264 | Q33: 322 | R33: 230 | S33: 141 | T33: 273 | U33: =SUM(E33:T33) -> 4484
A34: 2 | B34: Jumlah surat suara yang digunakan | E34: 215 | F34: 235 | G34: 251 | H34: 257 | I34: 230 | J34: 244 | K34: 242 | L34: 237 | M34: 260 | N34: 235 | O34: 191 | P34: 213 | Q34: 209 | R34: 191 | S34: 120 | T34: 215 | U34: =SUM(E34:T34) -> 3545
A35: 3 | B35: Jumlah surat suara dikembalikan oleh pemilih (karena rusak atau keliru coblos) | J35: 2 | U35: =SUM(E35:T35) -> 2
A36: 4 | B36: Jumlah surat suara yang tidak digunakan/tidak terpakai, termasuk sisa surat suara cadangan | E36: =E33-(E34+E35) -> 86 | F36: =F33-(F34+F35) -> 67 | G36: =G33-(G34+G35) -> 52 | H36: =H33-(H34+H35) -> 46 | I36: =I33-(I34+I35) -> 72 | J36: =J33-(J34+J35) -> 57 | K36: =K33-(K34+K35) -> 61 | L36: =L33-(L34+L35) -> 67 | ... T36: =T33-(T34+T35) -> 58 | U36: =SUM(E36:T36) -> 937
A38: III | B38: DATA PEMILIH DISABILITAS
B39: Jumlah seluruh Pemilih disabilitas yang menggunakan hak pilih | D39: LK | F39: 1 | I39: 1 | Q39: 2 | U39: =SUM(E39:T39) -> 4
D40: PR | M40: 1 | U40: =SUM(E40:T40) -> 1
D41: JML | E41: =SUM(E39:E40) -> 0 | F41: =SUM(F39:F40) -> 1 | G41: =SUM(G39:G40) -> 0 | H41: =SUM(H39:H40) -> 0 | I41: =SUM(I39:I40) -> 1 | J41: =SUM(J39:J40) -> 0 | K41: =SUM(K39:K40) -> 0 | L41: =SUM(L39:L40) -> 0 | ... T41: =SUM(T39:T40) -> 0 | U41: =SUM(E41:T41) -> 5
A43: IV | B43: DATA RINCIAN PEROLEHAN SUARA PASANGAN CALON BUPATI DAN WAKIL BUPATI
A44: NOMOR DAN NAMA CALON
A45: A.1 | B45: 1. | C45: Partai Kebangkitan Bangsa | E45: 7 | F45: 8 | G45: 12 | H45: 17 | I45: 7 | J45: 8 | K45: 17 | L45: 6 | M45: 10 | N45: 10 | O45: 16 | P45: 11 | Q45: 8 | R45: 5 | S45: 6 | T45: 4 | U45: =SUM(E45:T45) -> 152
A46: A.2 | C46: 1. Dra. Hj. MA`MULAH HARUN, M.Pd.I. | E46: 6 | F46: 6 | G46: 33 | H46: 63 | I46: 24 | J46: 24 | K46: 17 | L46: 17 | M46: 46 | N46: 9 | O46: 27 | P46: 37 | Q46: 30 | R46: 7 | S46: 9 | T46: 28 | U46: =SUM(E46:T46) -> 383
C47: 2. UBAIDILLAH, S.Fil.I. | E47: 1 | F47: 1 | G47: 2 | H47: 2 | I47: 0 | J47: 1 | K47: 1 | L47: 2 | M47: 1 | N47: 2 | O47: 2 | P47: 3 | Q47: 3 | R47: 2 | S47: 0 | U47: =SUM(E47:T47) -> 23
C48: 3. Ir. H. YOYOK MULYADI, M.Si. | E48: 0 | F48: 0 | G48: 0 | H48: 0 | I48: 0 | J48: 1 | K48: 1 | L48: 0 | M48: 1 | N48: 1 | O48: 0 | P48: 0 | Q48: 0 | R48: 0 | S48: 2 | U48: =SUM(E48:T48) -> 6
C49: 4. KHOIRUL ANWAR, S.Fil.I. | E49: 0 | F49: 1 | G49: 2 | H49: 2 | I49: 1 | J49: 0 | K49: 0 | L49: 3 | M49: 0 | N49: 0 | O49: 2 | P49: 0 | Q49: 1 | R49: 2 | S49: 1 | T49: 2 | U49: =SUM(E49:T49) -> 17
C50: 5. ARIF WIJAKSANA | E50: 0 | F50: 0 | G50: 1 | H50: 0 | I50: 1 | J50: 1 | K50: 0 | L50: 12 | M50: 1 | N50: 0 | O50: 0 | P50: 0 | Q50: 1 | R50: 0 | S50: 0 | U50: =SUM(E50:T50) -> 17
C51: 6. Dr. SITI YUMNAH | E51: 1 | F51: 0 | G51: 1 | H51: 3 | I51: 0 | J51: 1 | K51: 0 | L51: 1 | M51: 1 | N51: 1 | O51: 0 | P51: 0 | Q51: 0 | R51: 0 | S51: 0 | U51: =SUM(E51:T51) -> 9
...

Sheet GIRI
C2: Kecamatan | D2: GIRI
C3: Kabupaten | D3: BANYUWANGI
C4: Provinsi | D4: JAWA TIMUR
C9: Kelurahan | D9: GIRI
A12: I | B12: DATA PEMILIH DAN PENGGUNAAN HAK PILIH | V12: JUMLAH AKHIR
A13: A | B13: DATA PEMILIH | E13: TPS 001 | F13: TPS 002 | G13: TPS 003 | H13: TPS 004 | I13: TPS 005 | J13: TPS 006 | K13: TPS 007 | L13: TPS 008 | M13: TPS 009 | N13: TPS 010 | O13: TPS 011 | P13: TPS 012 | Q13: TPS 013 | R13: TPS 014 | S13: TPS 015 | T13: TPS 016 | U13: TPS 017
B14: Jumlah Pemilih dalam Daftar Pemilih Tetap (DPT) | D14: LK | E14: 140 | F14: 148 | G14: 141 | H14: 141 | I14: 140 | J14: 132 | K14: 121 | L14: 134 | M14: 142 | N14: 112 | O14: 135 | P14: 125 | Q14: 110 | R14: 128 | S14: 139 | T14: 134 | U14: 141 | V14: =SUM(E14:U14) -> 2263
D15: PR | E15: 148 | F15: 140 | G15: 148 | H15: 145 | I15: 148 | J15: 147 | K15: 124 | L15: 143 | M15: 135 | N15: 122 | O15: 151 | P15: 147 | Q15: 111 | R15: 137 | S15: 138 | T15: 135 | U15: 143 | V15: =SUM(E15:U15) -> 2362
D16: JML | E16: =SUM(E14:E15) -> 288 | F16: =SUM(F14:F15) -> 288 | G16: =SUM(G14:G15) -> 289 | H16: =SUM(H14:H15) -> 286 | I16: =SUM(I14:I15) -> 288 | J16: =SUM(J14:J15) -> 279 | K16: =SUM(K14:K15) -> 245 | L16: =SUM(L14:L15) -> 277 | ... U16: =SUM(U14:U15) -> 284 | V16: =SUM(E16:U16) -> 4625
A18: B | B18: PENGGUNA HAK PILIH
B19: 1. | C19: Jumlah pengguna hak pilih dalam Daftar Pemilih Tetap (DPT) | D19: LK | E19: 92 | F19: 99 | G19: 107 | H19: 107 | I19: 90 | J19: 96 | K19: 99 | L19: 101 | M19: 114 | N19: 76 | O19: 98 | P19: 95 | Q19: 84 | R19: 94 | S19: 110 | T19: 93 | U19: 119 | V19: =SUM(E19:U19) -> 1674
D20: PR | E20: 118 | F20: 105 | G20: 129 | H20: 117 | I20: 116 | J20: 122 | K20: 103 | L20: 128 | M20: 108 | N20: 84 | O20: 123 | P20: 122 | Q20: 91 | R20: 104 | S20: 104 | T20: 107 | U20: 124 | V20: =SUM(E20:U20) -> 1905
D21: JML | E21: =SUM(E19:E20) -> 210 | F21: =SUM(F19:F20) -> 204 | G21: =SUM(G19:G20) -> 236 | H21: =SUM(H19:H20) -> 224 | I21: =SUM(I19:I20) -> 206 | J21: =SUM(J19:J20) -> 218 | K21: =SUM(K19:K20) -> 202 | L21: =SUM(L19:L20) -> 229 | ... U21: =SUM(U19:U20) -> 243 | V21: =SUM(E21:U21) -> 3579
B22: 2. | C22: Jumlah pengguna hak pilih dalam Daftar Pemilih Tambahan (DPTb) | D22: LK | G22: 2 | N22: 1 | V22: =SUM(E22:U22) -> 3
D23: PR | G23: 3 | K23: 1 | N23: 1 | S23: 1 | V23: =SUM(E23:U23) -> 6
D24: JML | E24: =SUM(E22:E23) -> 0 | F24: =SUM(F22:F23) -> 0 | G24: =SUM(G22:G23) -> 5 | H24: =SUM(H22:H23) -> 0 | I24: =SUM(I22:I23) -> 0 | J24: =SUM(J22:J23) -> 0 | K24: =SUM(K22:K23) -> 1 | L24: =SUM(L22:L23) -> 0 | ... U24: =SUM(U22:U23) -> 0 | V24: =SUM(E24:U24) -> 9
B25: 3. | C25: Jumlah pengguna hak pilih dalam Daftar Pemilih Khusus (DPK) | D25: LK | F25: 2 | G25: 3 | H25: 3 | L25: 1 | Q25: 2 | R25: 3 | V25: =SUM(E25:U25) -> 14
D26: PR | E26: 2 | F26: 4 | G26: 3 | H26: 3 | K26: 1 | P26: 3 | Q26: 2 | R26: 6 | S26: 1 | T26: 2 | U26: 1 | V26: =SUM(E26:U26) -> 28
D27: JML | E27: =SUM(E25:E26) -> 2 | F27: =SUM(F25:F26) -> 6 | G27: =SUM(G25:G26) -> 6 | H27: =SUM(H25:H26) -> 6 | I27: =SUM(I25:I26) -> 0 | J27: =SUM(J25:J26) -> 0 | K27: =SUM(K25:K26) -> 1 | L27: =SUM(L25:L26) -> 1 | ... U27: =SUM(U25:U26) -> 1 | V27: =SUM(E27:U27) -> 42
B28: 4. | C28: Jumlah Pengguna Hak Pilih (B.1+B.2+B.3) | D28: LK | E28: =SUM(E19,E22,E25) -> 92 | F28: =SUM(F19,F22,F25) -> 101 | G28: =SUM(G19,G22,G25) -> 112 | H28: =SUM(H19,H22,H25) -> 110 | I28: =SUM(I19,I22,I25) -> 90 | J28: =SUM(J19,J22,J25) -> 96 | K28: =SUM(K19,K22,K25) -> 99 | L28: =SUM(L19,L22,L25) -> 102 | ... U28: =SUM(U19,U22,U25) -> 119 | V28: =SUM(E28:U28) -> 1691
D29: PR | E29: =SUM(E20,E23,E26) -> 120 | F29: =SUM(F20,F23,F26) -> 109 | G29: =SUM(G20,G23,G26) -> 135 | H29: =SUM(H20,H23,H26) -> 120 | I29: =SUM(I20,I23,I26) -> 116 | J29: =SUM(J20,J23,J26) -> 122 | K29: =SUM(K20,K23,K26) -> 105 | L29: =SUM(L20,L23,L26) -> 128 | ... U29: =SUM(U20,U23,U26) -> 125 | V29: =SUM(E29:U29) -> 1939
D30: JML | E30: =SUM(E28:E29) -> 212 | F30: =SUM(F28:F29) -> 210 | G30: =SUM(G28:G29) -> 247 | H30: =SUM(H28:H29) -> 230 | I30: =SUM(I28:I29) -> 206 | J30: =SUM(J28:J29) -> 218 | K30: =SUM(K28:K29) -> 204 | L30: =SUM(L28:L29) -> 230 | ... U30: =SUM(U28:U29) -> 244 | V30: =SUM(E30:U30) -> 3630
A32: II | B32: DATA PENGGUNAAN SURAT SUARA
A33: 1 | B33: Jumlah surat suara yang diterima, termasuk surat suara cadangan 2,5% dari DPT | E33: 284 | F33: 294 | G33: 295 | H33: 293 | I33: 294 | J33: 283 | K33: 248 | L33: 281 | M33: 282 | N33: 237 | O33: 290 | P33: 278 | Q33: 224 | R33: 269 | S33: 281 | T33: 273 | U33: 288 | V33: =SUM(E33:U33) -> 4694
A34: 2 | B34: Jumlah surat suara yang digunakan | E34: 212 | F34: 210 | G34: 247 | H34: 230 | I34: 206 | J34: 218 | K34: 204 | L34: 230 | M34: 222 | N34: 162 | O34: 221 | P34: 220 | Q34: 179 | R34: 207 | S34: 216 | T34: 202 | U34: 244 | V34: =SUM(E34:U34) -> 3630
A35: 3 | B35: Jumlah surat suara dikembalikan oleh pemilih (karena rusak atau keliru coblos) | L35: 1 | V35: =SUM(E35:U35) -> 1
A36: 4 | B36: Jumlah surat suara yang tidak digunakan/tidak terpakai, termasuk sisa surat suara cadangan | E36: =E33-(E34+E35) -> 72 | F36: =F33-(F34+F35) -> 84 | G36: =G33-(G34+G35) -> 48 | H36: =H33-(H34+H35) -> 63 | I36: =I33-(I34+I35) -> 88 | J36: =J33-(J34+J35) -> 65 | K36: =K33-(K34+K35) -> 44 | L36: =L33-(L34+L35) -> 50 | ... N36: =N33-(N34+N35) -> 75 | O36: 69 | P36: =P33-(P34+P35) -> 58 | Q36: =Q33-(Q34+Q35) -> 45 | R36: =R33-(R34+R35) -> 62 | S36: =S33-(S34+S35) -> 65 | T36: =T33-(T34+T35) -> 71 | U36: =U33-(U34+U35) -> 44 | V36: =SUM(E36:U36) -> 1063
A38: III | B38: DATA PEMILIH DISABILITAS
B39: Jumlah seluruh Pemilih disabilitas yang menggunakan hak pilih | D39: LK | E39: 2 | S39: 1 | V39: =SUM(E39:U39) -> 3
D40: PR | E40: 2 | J40: 1 | S40: 1 | V40: =SUM(E40:U40) -> 4
D41: JML | E41: =SUM(E39:E40) -> 4 | F41: =SUM(F39:F40) -> 0 | G41: =SUM(G39:G40) -> 0 | H41: =SUM(H39:H40) -> 0 | I41: =SUM(I39:I40) -> 0 | J41: =SUM(J39:J40) -> 1 | K41: =SUM(K39:K40) -> 0 | L41: =SUM(L39:L40) -> 0 | ... U41: =SUM(U39:U40) -> 0 | V41: =SUM(E41:U41) -> 7
A43: IV | B43: DATA RINCIAN PEROLEHAN SUARA PASANGAN CALON BUPATI DAN WAKIL BUPATI
A44: NOMOR DAN NAMA CALON
A45: A.1 | B45: 1. | C45: Partai Kebangkitan Bangsa | E45: 6 | F45: 4 | G45: 4 | H45: 4 | I45: 6 | J45: 14 | K45: 10 | L45: 14 | M45: 11 | N45: 7 | O45: 5 | P45: 3 | Q45: 7 | R45: 18 | S45: 22 | T45: 16 | U45: 17 | V45: =SUM(E45:U45) -> 168
A46: A.2 | C46: 1. Dra. Hj. MA`MULAH HARUN, M.Pd.I. | E46: 6 | F46: 16 | G46: 11 | H46: 3 | I46: 8 | J46: 26 | K46: 42 | L46: 32 | M46: 19 | N46: 26 | O46: 16 | P46: 13 | Q46: 40 | R46: 61 | S46: 31 | T46: 12 | U46: 31 | V46: =SUM(E46:U46) -> 393
C47: 2. UBAIDILLAH, S.Fil.I. | E47: 2 | F47: 4 | G47: 1 | H47: 0 | I47: 1 | J47: 4 | K47: 2 | L47: 1 | M47: 1 | N47: 2 | O47: 1 | P47: 0 | Q47: 1 | R47: 0 | S47: 1 | T47: 2 | U47: 4 | V47: =SUM(E47:U47) -> 27
C48: 3. Ir. H. YOYOK MULYADI, M.Si. | E48: 1 | F48: 0 | G48: 1 | H48: 0 | I48: 0 | J48: 0 | K48: 2 | L48: 1 | M48: 1 | N48: 1 | O48: 1 | P48: 2 | Q48: 0 | R48: 1 | S48: 0 | T48: 2 | U48: 1 | V48: =SUM(E48:U48) -> 14
C49: 4. KHOIRUL ANWAR, S.Fil.I. | E49: 0 | F49: 1 | G49: 0 | H49: 0 | I49: 0 | J49: 0 | K49: 1 | L49: 1 | M49: 1 | N49: 1 | O49: 1 | P49: 0 | Q49: 0 | R49: 0 | S49: 0 | T49: 1 | U49: 0 | V49: =SUM(E49:U49) -> 7
C50: 5. ARIF WIJAKSANA | E50: 0 | F50: 1 | G50: 1 | H50: 1 | I50: 1 | J50: 0 | K50: 0 | L50: 0 | M50: 0 | N50: 0 | O50: 0 | P50: 0 | Q50: 0 | R50: 0 | S50: 0 | T50: 0 | U50: 1 | V50: =SUM(E50:U50) -> 5
C51: 6. Dr. SITI YUMNAH | E51: 0 | F51: 1 | G51: 2 | H51: 1 | I51: 0 | J51: 1 | K51: 1 | L51: 1 | M51: 4 | N51: 1 | O51: 0 | P51: 1 | Q51: 0 | R51: 1 | S51: 0 | T51: 1 | U51: 0 | V51: =SUM(E51:U51) -> 15
...

Sheet GROGOL
C2: Kecamatan | D2: GIRI
C3: Kabupaten | D3: BANYUWANGI
C4: Provinsi | D4: JAWA TIMUR
C9: Kelurahan | D9: GROGOL
A12: I | B12: DATA PEMILIH DAN PENGGUNAAN HAK PILIH | V12: JUMLAH AKHIR
A13: A | B13: DATA PEMILIH | E13: TPS 001 | F13: TPS 002 | G13: TPS 003 | H13: TPS 004 | I13: TPS 005 | J13: TPS 006 | K13: TPS 007 | L13: TPS 008 | M13: TPS 009 | N13: TPS 010 | O13: TPS 011 | P13: TPS 012 | Q13: TPS 013 | R13: TPS 014 | S13: TPS 015 | T13: TPS 016 | U13: TPS 017
B14: Jumlah Pemilih dalam Daftar Pemilih Tetap (DPT) | D14: LK | E14: 139 | F14: 128 | G14: 99 | H14: 119 | I14: 112 | J14: 141 | K14: 133 | L14: 137 | M14: 126 | N14: 121 | O14: 109 | P14: 113 | Q14: 144 | R14: 122 | S14: 93 | T14: 96 | U14: 116 | V14: =SUM(E14:U14) -> 2048
D15: PR | E15: 146 | F15: 135 | G15: 104 | H15: 131 | I15: 104 | J15: 148 | K15: 146 | L15: 151 | M15: 144 | N15: 123 | O15: 119 | P15: 114 | Q15: 132 | R15: 128 | S15: 108 | T15: 102 | U15: 103 | V15: =SUM(E15:U15) -> 2138
D16: JML | E16: =SUM(E14:E15) -> 285 | F16: =SUM(F14:F15) -> 263 | G16: =SUM(G14:G15) -> 203 | H16: =SUM(H14:H15) -> 250 | I16: =SUM(I14:I15) -> 216 | J16: =SUM(J14:J15) -> 289 | K16: =SUM(K14:K15) -> 279 | L16: =SUM(L14:L15) -> 288 | ... U16: =SUM(U14:U15) -> 219 | V16: =SUM(E16:U16) -> 4186
A18: B | B18: PENGGUNA HAK PILIH
B19: 1. | C19: Jumlah pengguna hak pilih dalam Daftar Pemilih Tetap (DPT) | D19: LK | E19: 113 | F19: 109 | G19: 76 | H19: 89 | I19: 99 | J19: 106 | K19: 94 | L19: 105 | M19: 99 | N19: 90 | O19: 88 | P19: 96 | Q19: 120 | R19: 95 | S19: 75 | T19: 80 | U19: 87 | V19: =SUM(E19:U19) -> 1621
D20: PR | E20: 117 | F20: 113 | G20: 83 | H20: 110 | I20: 96 | J20: 117 | K20: 127 | L20: 127 | M20: 122 | N20: 102 | O20: 99 | P20: 102 | Q20: 109 | R20: 109 | S20: 94 | T20: 85 | U20: 79 | V20: =SUM(E20:U20) -> 1791
D21: JML | E21: =SUM(E19:E20) -> 230 | F21: =SUM(F19:F20) -> 222 | G21: =SUM(G19:G20) -> 159 | H21: =SUM(H19:H20) -> 199 | I21: =SUM(I19:I20) -> 195 | J21: =SUM(J19:J20) -> 223 | K21: =SUM(K19:K20) -> 221 | L21: =SUM(L19:L20) -> 232 | ... U21: =SUM(U19:U20) -> 166 | V21: =SUM(E21:U21) -> 3412
B22: 2. | C22: Jumlah pengguna hak pilih dalam Daftar Pemilih Tambahan (DPTb) | D22: LK | E22: 1 | F22: 0 | G22: 0 | H22: 0 | I22: 0 | J22: 0 | K22: 0 | L22: 0 | M22: 0 | N22: 0 | O22: 0 | P22: 0 | Q22: 1 | R22: 0 | S22: 0 | V22: =SUM(E22:U22) -> 2
D23: PR | E23: 1 | F23: 0 | G23: 0 | H23: 0 | I23: 0 | J23: 0 | K23: 0 | L23: 0 | M23: 0 | N23: 0 | O23: 1 | P23: 0 | Q23: 1 | R23: 0 | S23: 0 | V23: =SUM(E23:U23) -> 3
D24: JML | E24: =SUM(E22:E23) -> 2 | F24: =SUM(F22:F23) -> 0 | G24: =SUM(G22:G23) -> 0 | H24: =SUM(H22:H23) -> 0 | I24: =SUM(I22:I23) -> 0 | J24: =SUM(J22:J23) -> 0 | K24: =SUM(K22:K23) -> 0 | L24: =SUM(L22:L23) -> 0 | ... U24: =SUM(U22:U23) -> 0 | V24: =SUM(E24:U24) -> 5
B25: 3. | C25: Jumlah pengguna hak pilih dalam Daftar Pemilih Khusus (DPK) | D25: LK | E25: 0 | F25: 0 | G25: 0 | H25: 1 | I25: 1 | J25: 0 | K25: 0 | L25: 0 | M25: 0 | N25: 0 | O25: 0 | P25: 0 | Q25: 1 | R25: 0 | S25: 0 | V25: =SUM(E25:U25) -> 3
D26: PR | E26: 1 | F26: 1 | G26: 0 | H26: 1 | I26: 1 | J26: 0 | K26: 0 | L26: 0 | M26: 1 | N26: 3 | O26: 1 | P26: 2 | Q26: 0 | R26: 0 | S26: 1 | T26: 2 | V26: =SUM(E26:U26) -> 14
D27: JML | E27: =SUM(E25:E26) -> 1 | F27: =SUM(F25:F26) -> 1 | G27: =SUM(G25:G26) -> 0 | H27: =SUM(H25:H26) -> 2 | I27: =SUM(I25:I26) -> 2 | J27: =SUM(J25:J26) -> 0 | K27: =SUM(K25:K26) -> 0 | L27: =SUM(L25:L26) -> 0 | ... U27: =SUM(U25:U26) -> 0 | V27: =SUM(E27:U27) -> 17
B28: 4. | C28: Jumlah Pengguna Hak Pilih (B.1+B.2+B.3) | D28: LK | E28: =SUM(E19,E22,E25) -> 114 | F28: =SUM(F19,F22,F25) -> 109 | G28: =SUM(G19,G22,G25) -> 76 | H28: =SUM(H19,H22,H25) -> 90 | I28: =SUM(I19,I22,I25) -> 100 | J28: =SUM(J19,J22,J25) -> 106 | K28: =SUM(K19,K22,K25) -> 94 | L28: =SUM(L19,L22,L25) -> 105 | ... U28: =SUM(U19,U22,U25) -> 87 | V28: =SUM(E28:U28) -> 1626
D29: PR | E29: =SUM(E20,E23,E26) -> 119 | F29: =SUM(F20,F23,F26) -> 114 | G29: =SUM(G20,G23,G26) -> 83 | H29: =SUM(H20,H23,H26) -> 111 | I29: =SUM(I20,I23,I26) -> 97 | J29: =SUM(J20,J23,J26) -> 117 | K29: =SUM(K20,K23,K26) -> 127 | L29: =SUM(L20,L23,L26) -> 127 | ... U29: =SUM(U20,U23,U26) -> 79 | V29: =SUM(E29:U29) -> 1808
D30: JML | E30: =SUM(E28:E29) -> 233 | F30: =SUM(F28:F29) -> 223 | G30: =SUM(G28:G29) -> 159 | H30: =SUM(H28:H29) -> 201 | I30: =SUM(I28:I29) -> 197 | J30: =SUM(J28:J29) -> 223 | K30: =SUM(K28:K29) -> 221 | L30: =SUM(L28:L29) -> 232 | ... U30: =SUM(U28:U29) -> 166 | V30: =SUM(E30:U30) -> 3434
A32: II | B32: DATA PENGGUNAAN SURAT SUARA
A33: 1 | B33: Jumlah surat suara yang diterima, termasuk surat suara cadangan 2,5% dari DPT | E33: 289 | F33: 267 | G33: 206 | H33: 253 | I33: 218 | J33: 293 | K33: 283 | L33: 292 | M33: 274 | N33: 247 | O33: 231 | P33: 229 | Q33: 280 | R33: 253 | S33: 204 | T33: 200 | U33: 222 | V33: =SUM(E33:U33) -> 4241
A34: 2 | B34: Jumlah surat suara yang digunakan | E34: 233 | F34: 223 | G34: 159 | H34: 201 | I34: 197 | J34: 223 | K34: 221 | L34: 232 | M34: 222 | N34: 195 | O34: 189 | P34: 200 | Q34: 232 | R34: 204 | S34: 170 | T34: 167 | U34: 166 | V34: =SUM(E34:U34) -> 3434
A35: 3 | B35: Jumlah surat suara dikembalikan oleh pemilih (karena rusak atau keliru coblos) | I35: 1 | V35: =SUM(E35:U35) -> 1
A36: 4 | B36: Jumlah surat suara yang tidak digunakan/tidak terpakai, termasuk sisa surat suara cadangan | E36: =E33-(E34+E35) -> 56 | F36: =F33-(F34+F35) -> 44 | G36: =G33-(G34+G35) -> 47 | H36: =H33-(H34+H35) -> 52 | I36: =I33-(I34+I35) -> 20 | J36: =J33-(J34+J35) -> 70 | K36: =K33-(K34+K35) -> 62 | L36: =L33-(L34+L35) -> 60 | ... U36: =U33-(U34+U35) -> 56 | V36: =SUM(E36:U36) -> 806
A38: III | B38: DATA PEMILIH DISABILITAS
B39: Jumlah seluruh Pemilih disabilitas yang menggunakan hak pilih | D39: LK | I39: 3 | V39: =SUM(E39:U39) -> 3
D40: PR | I40: 1 | V40: =SUM(E40:U40) -> 1
D41: JML | E41: =SUM(E39:E40) -> 0 | F41: =SUM(F39:F40) -> 0 | G41: =SUM(G39:G40) -> 0 | H41: =SUM(H39:H40) -> 0 | I41: =SUM(I39:I40) -> 4 | J41: =SUM(J39:J40) -> 0 | K41: =SUM(K39:K40) -> 0 | L41: =SUM(L39:L40) -> 0 | ... U41: =SUM(U39:U40) -> 0 | V41: =SUM(E41:U41) -> 4
A43: IV | B43: DATA RINCIAN PEROLEHAN SUARA PASANGAN CALON BUPATI DAN WAKIL BUPATI
A44: NOMOR DAN NAMA CALON
A45: A.1 | B45: 1. | C45: Partai Kebangkitan Bangsa | E45: 10 | F45: 7 | G45: 11 | H45: 14 | I45: 26 | J45: 19 | K45: 23 | L45: 17 | M45: 16 | N45: 19 | O45: 21 | P45: 22 | Q45: 23 | R45: 21 | S45: 12 | T45: 14 | U45: 11 | V45: =SUM(E45:U45) -> 286
A46: A.2 | C46: 1. Dra. Hj. MA`MULAH HARUN, M.Pd.I. | E46: 60 | F46: 38 | G46: 30 | H46: 47 | I46: 76 | J46: 69 | K46: 78 | L46: 61 | M46: 45 | N46: 44 | O46: 74 | P46: 70 | Q46: 61 | R46: 24 | S46: 25 | T46: 47 | U46: 60 | V46: =SUM(E46:U46) -> 909
C47: 2. UBAIDILLAH, S.Fil.I. | E47: 2 | F47: 1 | G47: 4 | H47: 1 | I47: 5 | J47: 2 | K47: 0 | L47: 2 | M47: 1 | N47: 1 | O47: 5 | P47: 1 | Q47: 4 | R47: 1 | S47: 1 | V47: =SUM(E47:U47) -> 31
C48: 3. Ir. H. YOYOK MULYADI, M.Si. | E48: 0 | F48: 0 | G48: 0 | H48: 0 | I48: 0 | J48: 0 | K48: 2 | L48: 1 | M48: 2 | N48: 0 | O48: 0 | P48: 2 | Q48: 0 | R48: 1 | S48: 1 | V48: =SUM(E48:U48) -> 9
C49: 4. KHOIRUL ANWAR, S.Fil.I. | E49: 0 | F49: 1 | G49: 0 | H49: 0 | I49: 3 | J49: 1 | K49: 1 | L49: 2 | M49: 2 | N49: 0 | O49: 3 | P49: 1 | Q49: 1 | R49: 0 | S49: 0 | U49: 1 | V49: =SUM(E49:U49) -> 16
C50: 5. ARIF WIJAKSANA | E50: 0 | F50: 0 | G50: 2 | H50: 1 | I50: 0 | J50: 0 | K50: 0 | L50: 0 | M50: 0 | N50: 1 | O50: 0 | P50: 1 | Q50: 0 | R50: 0 | S50: 0 | U50: 2 | V50: =SUM(E50:U50) -> 7
C51: 6. Dr. SITI YUMNAH | E51: 0 | F51: 0 | G51: 1 | H51: 0 | I51: 1 | J51: 0 | K51: 0 | L51: 0 | M51: 1 | N51: 0 | O51: 0 | P51: 0 | Q51: 0 | R51: 0 | S51: 0 | U51: 1 | V51: =SUM(E51:U51) -> 4
...

Sheet JAMBESARI
C2: Kecamatan | D2: GIRI
C3: Kabupaten | D3: BANYUWANGI
C4: Provinsi | D4: JAWA TIMUR
C9: Kelurahan | D9: JAMBESARI
A12: I | B12: DATA PEMILIH DAN PENGGUNAAN HAK PILIH | O12: JUMLAH AKHIR
A13: A | B13: DATA PEMILIH | E13: TPS 001 | F13: TPS 002 | G13: TPS 003 | H13: TPS 004 | I13: TPS 005 | J13: TPS 006 | K13: TPS 007 | L13: TPS 008 | M13: TPS 009 | N13: TPS 010
B14: Jumlah Pemilih dalam Daftar Pemilih Tetap (DPT) | D14: LK | E14: 151 | F14: 137 | G14: 145 | H14: 145 | I14: 147 | J14: 141 | K14: 124 | L14: 133 | M14: 123 | N14: 90 | O14: =SUM(E14:N14) -> 1336
D15: PR | E15: 144 | F15: 156 | G15: 151 | H15: 150 | I15: 145 | J15: 145 | K15: 136 | L15: 127 | M15: 125 | N15: 96 | O15: =SUM(E15:N15) -> 1375
D16: JML | E16: =SUM(E14:E15) -> 295 | F16: =SUM(F14:F15) -> 293 | G16: =SUM(G14:G15) -> 296 | H16: =SUM(H14:H15) -> 295 | I16: =SUM(I14:I15) -> 292 | J16: =SUM(J14:J15) -> 286 | K16: =SUM(K14:K15) -> 260 | L16: =SUM(L14:L15) -> 260 | ... N16: =SUM(N14:N15) -> 186 | O16: =SUM(E16:N16) -> 2711
A18: B | B18: PENGGUNA HAK PILIH
B19: 1. | C19: Jumlah pengguna hak pilih dalam Daftar Pemilih Tetap (DPT) | D19: LK | E19: 122 | F19: 119 | G19: 129 | H19: 118 | I19: 122 | J19: 114 | K19: 103 | L19: 114 | M19: 101 | N19: 76 | O19: =SUM(E19:N19) -> 1118
D20: PR | E20: 126 | F20: 131 | G20: 138 | H20: 134 | I20: 117 | J20: 128 | K20: 118 | L20: 115 | M20: 110 | N20: 86 | O20: =SUM(E20:N20) -> 1203
D21: JML | E21: =SUM(E19:E20) -> 248 | F21: =SUM(F19:F20) -> 250 | G21: =SUM(G19:G20) -> 267 | H21: =SUM(H19:H20) -> 252 | I21: =SUM(I19:I20) -> 239 | J21: =SUM(J19:J20) -> 242 | K21: =SUM(K19:K20) -> 221 | L21: =SUM(L19:L20) -> 229 | ... N21: =SUM(N19:N20) -> 162 | O21: =SUM(E21:N21) -> 2321
B22: 2. | C22: Jumlah pengguna hak pilih dalam Daftar Pemilih Tambahan (DPTb) | D22: LK | E22: 0 | F22: 0 | G22: 0 | H22: 0 | I22: 0 | J22: 0 | K22: 0 | L22: 1 | M22: 0 | N22: 0 | O22: =SUM(E22:N22) -> 1
D23: PR | E23: 0 | F23: 0 | G23: 0 | H23: 0 | I23: 0 | J23: 0 | K23: 0 | L23: 1 | M23: 0 | N23: 0 | O23: =SUM(E23:N23) -> 1
D24: JML | E24: =SUM(E22:E23) -> 0 | F24: =SUM(F22:F23) -> 0 | G24: =SUM(G22:G23) -> 0 | H24: =SUM(H22:H23) -> 0 | I24: =SUM(I22:I23) -> 0 | J24: =SUM(J22:J23) -> 0 | K24: =SUM(K22:K23) -> 0 | L24: =SUM(L22:L23) -> 2 | ... N24: =SUM(N22:N23) -> 0 | O24: =SUM(E24:N24) -> 2
B25: 3. | C25: Jumlah pengguna hak pilih dalam Daftar Pemilih Khusus (DPK) | D25: LK | E25: 0 | F25: 0 | G25: 1 | H25: 0 | I25: 0 | J25: 0 | K25: 0 | L25: 1 | M25: 0 | N25: 0 | O25: =SUM(E25:N25) -> 2
D26: PR | E26: 0 | F26: 2 | G26: 0 | H26: 0 | I26: 0 | J26: 1 | K26: 0 | L26: 2 | M26: 1 | N26: 0 | O26: =SUM(E26:N26) -> 6
D27: JML | E27: =SUM(E25:E26) -> 0 | F27: =SUM(F25:F26) -> 2 | G27: =SUM(G25:G26) -> 1 | H27: =SUM(H25:H26) -> 0 | I27: =SUM(I25:I26) -> 0 | J27: =SUM(J25:J26) -> 1 | K27: =SUM(K25:K26) -> 0 | L27: =SUM(L25:L26) -> 3 | ... N27: =SUM(N25:N26) -> 0 | O27: =SUM(E27:N27) -> 8
B28: 4. | C28: Jumlah Pengguna Hak Pilih (B.1+B.2+B.3) | D28: LK | E28: =SUM(E19,E22,E25) -> 122 | F28: =SUM(F19,F22,F25) -> 119 | G28: =SUM(G19,G22,G25) -> 130 | H28: =SUM(H19,H22,H25) -> 118 | I28: =SUM(I19,I22,I25) -> 122 | J28: =SUM(J19,J22,J25) -> 114 | K28: =SUM(K19,K22,K25) -> 103 | L28: =SUM(L19,L22,L25) -> 116 | ... N28: =SUM(N19,N22,N25) -> 76 | O28: =SUM(E28:N28) -> 1121
D29: PR | E29: =SUM(E20,E23,E26) -> 126 | F29: =SUM(F20,F23,F26) -> 133 | G29: =SUM(G20,G23,G26) -> 138 | H29: =SUM(H20,H23,H26) -> 134 | I29: =SUM(I20,I23,I26) -> 117 | J29: =SUM(J20,J23,J26) -> 129 | K29: =SUM(K20,K23,K26) -> 118 | L29: =SUM(L20,L23,L26) -> 118 | ... N29: =SUM(N20,N23,N26) -> 86 | O29: =SUM(E29:N29) -> 1210
D30: JML | E30: =SUM(E28:E29) -> 248 | F30: =SUM(F28:F29) -> 252 | G30: =SUM(G28:G29) -> 268 | H30: =SUM(H28:H29) -> 252 | I30: =SUM(I28:I29) -> 239 | J30: =SUM(J28:J29) -> 243 | K30: =SUM(K28:K29) -> 221 | L30: =SUM(L28:L29) -> 234 | ... N30: =SUM(N28:N29) -> 162 | O30: =SUM(E30:N30) -> 2331
A32: II | B32: DATA PENGGUNAAN SURAT SUARA
A33: 1 | B33: Jumlah surat suara yang diterima, termasuk surat suara cadangan 2,5% dari DPT | E33: 301 | F33: 299 | G33: 302 | H33: 302 | I33: 298 | J33: 292 | K33: 266 | L33: 267 | M33: 253 | N33: 190 | O33: =SUM(E33:N33) -> 2770
A34: 2 | B34: Jumlah surat suara yang digunakan | E34: 248 | F34: 252 | G34: 268 | H34: 252 | I34: 239 | J34: 243 | K34: 221 | L34: 234 | M34: 212 | N34: 162 | O34: =SUM(E34:N34) -> 2331
A35: 3 | B35: Jumlah surat suara dikembalikan oleh pemilih (karena rusak atau keliru coblos) | J35: 1 | M35: 31 | O35: =SUM(E35:N35) -> 32
A36: 4 | B36: Jumlah surat suara yang tidak digunakan/tidak terpakai, termasuk sisa surat suara cadangan | E36: =E33-(E34+E35) -> 53 | F36: =F33-(F34+F35) -> 47 | G36: =G33-(G34+G35) -> 34 | H36: =H33-(H34+H35) -> 50 | I36: =I33-(I34+I35) -> 59 | J36: =J33-(J34+J35) -> 48 | K36: =K33-(K34+K35) -> 45 | L36: =L33-(L34+L35) -> 33 | ... N36: =N33-(N34+N35) -> 28 | O36: =SUM(E36:N36) -> 407
A38: III | B38: DATA PEMILIH DISABILITAS
B39: Jumlah seluruh Pemilih disabilitas yang menggunakan hak pilih | D39: LK | E39: 2 | F39: 1 | O39: =SUM(E39:N39) -> 3
D40: PR | I40: 1 | J40: 1 | O40: =SUM(E40:N40) -> 2
D41: JML | E41: =SUM(E39:E40) -> 2 | F41: =SUM(F39:F40) -> 1 | G41: =SUM(G39:G40) -> 0 | H41: =SUM(H39:H40) -> 0 | I41: =SUM(I39:I40) -> 1 | J41: =SUM(J39:J40) -> 1 | K41: =SUM(K39:K40) -> 0 | L41: =SUM(L39:L40) -> 0 | ... N41: =SUM(N39:N40) -> 0 | O41: =SUM(E41:N41) -> 5
A43: IV | B43: DATA RINCIAN PEROLEHAN SUARA PASANGAN CALON BUPATI DAN WAKIL BUPATI
A44: NOMOR DAN NAMA CALON
A45: A.1 | B45: 1. | C45: Partai Kebangkitan Bangsa | E45: 9 | F45: 15 | G45: 12 | H45: 17 | I45: 26 | J45: 38 | K45: 33 | L45: 31 | M45: 31 | N45: 19 | O45: =SUM(E45:N45) -> 231
A46: A.2 | C46: 1. Dra. Hj. MA`MULAH HARUN, M.Pd.I. | E46: 23 | F46: 34 | G46: 62 | H46: 44 | I46: 71 | J46: 78 | K46: 74 | L46: 94 | M46: 76 | N46: 53 | O46: =SUM(E46:N46) -> 609
C47: 2. UBAIDILLAH, S.Fil.I. | E47: 5 | F47: 2 | G47: 5 | H47: 3 | I47: 4 | J47: 4 | K47: 1 | L47: 2 | M47: 3 | N47: 0 | O47: =SUM(E47:N47) -> 29
C48: 3. Ir. H. YOYOK MULYADI, M.Si. | E48: 1 | F48: 0 | G48: 0 | H48: 1 | I48: 1 | J48: 0 | K48: 1 | L48: 2 | M48: 1 | N48: 0 | O48: =SUM(E48:N48) -> 7
C49: 4. KHOIRUL ANWAR, S.Fil.I. | E49: 0 | F49: 1 | G49: 0 | H49: 0 | I49: 1 | J49: 1 | K49: 0 | L49: 0 | M49: 1 | N49: 1 | O49: =SUM(E49:N49) -> 5
C50: 5. ARIF WIJAKSANA | E50: 1 | F50: 1 | G50: 0 | H50: 0 | I50: 2 | J50: 0 | K50: 0 | L50: 0 | M50: 0 | N50: 1 | O50: =SUM(E50:N50) -> 5
C51: 6. Dr. SITI YUMNAH | E51: 1 | F51: 0 | G51: 0 | H51: 0 | I51: 0 | J51: 0 | K51: 0 | L51: 1 | M51: 0 | N51: 0 | O51: =SUM(E51:N51) -> 2
...

Sheet MOJOPANGGUNG
C2: Kecamatan | D2: GIRI
C3: Kabupaten | D3: BANYUWANGI
C4: Provinsi | D4: JAWA TIMUR
C9: Kelurahan | D9: MOJOPANGGUNG
A12: I | B12: DATA PEMILIH DAN PENGGUNAAN HAK PILIH | V12: JUMLAH AKHIR
A13: A | B13: DATA PEMILIH | E13: TPS 001 | F13: TPS 002 | G13: TPS 003 | H13: TPS 004 | I13: TPS 005 | J13: TPS 006 | K13: TPS 007 | L13: TPS 008 | M13: TPS 009 | N13: TPS 010 | O13: TPS 011 | P13: TPS 012 | Q13: TPS 013 | R13: TPS 014 | S13: TPS 015 | T13: TPS 016 | U13: TPS 017
B14: Jumlah Pemilih dalam Daftar Pemilih Tetap (DPT) | D14: LK | E14: 137 | F14: 134 | G14: 136 | H14: 139 | I14: 135 | J14: 127 | K14: 116 | L14: 120 | M14: 127 | N14: 141 | O14: 123 | P14: 119 | Q14: 129 | R14: 137 | S14: 155 | T14: 140 | U14: 135 | V14: =SUM(E14:U14) -> 2250
D15: PR | E15: 142 | F15: 134 | G15: 136 | H15: 141 | I15: 157 | J15: 150 | K15: 139 | L15: 139 | M15: 123 | N15: 133 | O15: 118 | P15: 121 | Q15: 152 | R15: 162 | S15: 140 | T15: 143 | U15: 147 | V15: =SUM(E15:U15) -> 2377
D16: JML | E16: =SUM(E14:E15) -> 279 | F16: =SUM(F14:F15) -> 268 | G16: =SUM(G14:G15) -> 272 | H16: =SUM(H14:H15) -> 280 | I16: =SUM(I14:I15) -> 292 | J16: =SUM(J14:J15) -> 277 | K16: =SUM(K14:K15) -> 255 | L16: =SUM(L14:L15) -> 259 | ... U16: =SUM(U14:U15) -> 282 | V16: =SUM(E16:U16) -> 4627
A18: B | B18: PENGGUNA HAK PILIH
B19: 1. | C19: Jumlah pengguna hak pilih dalam Daftar Pemilih Tetap (DPT) | D19: LK | E19: 95 | F19: 96 | G19: 107 | H19: 105 | I19: 93 | J19: 96 | K19: 83 | L19: 93 | M19: 98 | N19: 117 | O19: 89 | P19: 96 | Q19: 106 | R19: 97 | S19: 123 | T19: 100 | U19: 97 | V19: =SUM(E19:U19) -> 1691
D20: PR | E20: 112 | F20: 102 | G20: 109 | H20: 115 | I20: 121 | J20: 124 | K20: 109 | L20: 112 | M20: 104 | N20: 120 | O20: 91 | P20: 112 | Q20: 128 | R20: 127 | S20: 114 | T20: 117 | U20: 120 | V20: =SUM(E20:U20) -> 1937
D21: JML | E21: =SUM(E19:E20) -> 207 | F21: =SUM(F19:F20) -> 198 | G21: =SUM(G19:G20) -> 216 | H21: =SUM(H19:H20) -> 220 | I21: =SUM(I19:I20) -> 214 | J21: =SUM(J19:J20) -> 220 | K21: =SUM(K19:K20) -> 192 | L21: =SUM(L19:L20) -> 205 | ... U21: =SUM(U19:U20) -> 217 | V21: =SUM(E21:U21) -> 3628
B22: 2. | C22: Jumlah pengguna hak pilih dalam Daftar Pemilih Tambahan (DPTb) | D22: LK | F22: 1 | H22: 2 | I22: 1 | K22: 2 | T22: 1 | V22: =SUM(E22:U22) -> 7
D23: PR | F23: 1 | K23: 1 | V23: =SUM(E23:U23) -> 2
D24: JML | E24: =SUM(E22:E23) -> 0 | F24: =SUM(F22:F23) -> 2 | G24: =SUM(G22:G23) -> 0 | H24: =SUM(H22:H23) -> 2 | I24: =SUM(I22:I23) -> 1 | J24: =SUM(J22:J23) -> 0 | K24: =SUM(K22:K23) -> 3 | L24: =SUM(L22:L23) -> 0 | ... U24: =SUM(U22:U23) -> 0 | V24: =SUM(E24:U24) -> 9
B25: 3. | C25: Jumlah pengguna hak pilih dalam Daftar Pemilih Khusus (DPK) | D25: LK | F25: 2 | I25: 2 | P25: 1 | R25: 1 | S25: 2 | T25: 1 | U25: 2 | V25: =SUM(E25:U25) -> 11
D26: PR | F26: 2 | H26: 1 | I26: 3 | J26: 1 | K26: 2 | M26: 1 | S26: 1 | T26: 5 | U26: 1 | V26: =SUM(E26:U26) -> 17
D27: JML | E27: =SUM(E25:E26) -> 0 | F27: =SUM(F25:F26) -> 4 | G27: =SUM(G25:G26) -> 0 | H27: =SUM(H25:H26) -> 1 | I27: =SUM(I25:I26) -> 5 | J27: =SUM(J25:J26) -> 1 | K27: =SUM(K25:K26) -> 2 | L27: =SUM(L25:L26) -> 0 | ... U27: =SUM(U25:U26) -> 3 | V27: =SUM(E27:U27) -> 28
B28: 4. | C28: Jumlah Pengguna Hak Pilih (B.1+B.2+B.3) | D28: LK | E28: =SUM(E19,E22,E25) -> 95 | F28: =SUM(F19,F22,F25) -> 99 | G28: =SUM(G19,G22,G25) -> 107 | H28: =SUM(H19,H22,H25) -> 107 | I28: =SUM(I19,I22,I25) -> 96 | J28: =SUM(J19,J22,J25) -> 96 | K28: =SUM(K19,K22,K25) -> 85 | L28: =SUM(L19,L22,L25) -> 93 | ... U28: =SUM(U19,U22,U25) -> 99 | V28: =SUM(E28:U28) -> 1709
D29: PR | E29: =SUM(E20,E23,E26) -> 112 | F29: =SUM(F20,F23,F26) -> 105 | G29: =SUM(G20,G23,G26) -> 109 | H29: =SUM(H20,H23,H26) -> 116 | I29: =SUM(I20,I23,I26) -> 124 | J29: =SUM(J20,J23,J26) -> 125 | K29: =SUM(K20,K23,K26) -> 112 | L29: =SUM(L20,L23,L26) -> 112 | ... U29: =SUM(U20,U23,U26) -> 121 | V29: =SUM(E29:U29) -> 1956
D30: JML | E30: =SUM(E28:E29) -> 207 | F30: =SUM(F28:F29) -> 204 | G30: =SUM(G28:G29) -> 216 | H30: =SUM(H28:H29) -> 223 | I30: =SUM(I28:I29) -> 220 | J30: =SUM(J28:J29) -> 221 | K30: =SUM(K28:K29) -> 197 | L30: =SUM(L28:L29) -> 205 | ... U30: =SUM(U28:U29) -> 220 | V30: =SUM(E30:U30) -> 3665
A32: II | B32: DATA PENGGUNAAN SURAT SUARA
A33: 1 | B33: Jumlah surat suara yang diterima, termasuk surat suara cadangan 2,5% dari DPT | E33: 282 | F33: 273 | G33: 279 | H33: 287 | I33: 296 | J33: 282 | K33: 260 | L33: 264 | M33: 255 | N33: 281 | O33: 245 | P33: 244 | Q33: 287 | R33: 307 | S33: 300 | T33: 289 | U33: 288 | V33: =SUM(E33:U33) -> 4719
A34: 2 | B34: Jumlah surat suara yang digunakan | E34: 207 | F34: 204 | G34: 216 | H34: 223 | I34: 220 | J34: 221 | K34: 197 | L34: 205 | M34: 203 | N34: 237 | O34: 180 | P34: 209 | Q34: 234 | R34: 225 | S34: 240 | T34: 224 | U34: 220 | V34: =SUM(E34:U34) -> 3665
A35: 3 | B35: Jumlah surat suara dikembalikan oleh pemilih (karena rusak atau keliru coblos) | L35: 1 | O35: 2 | P35: 1 | S35: 1 | U35: 1 | V35: =SUM(E35:U35) -> 6
A36: 4 | B36: Jumlah surat suara yang tidak digunakan/tidak terpakai, termasuk sisa surat suara cadangan | E36: =E33-(E34+E35) -> 75 | F36: =F33-(F34+F35) -> 69 | G36: =G33-(G34+G35) -> 63 | H36: =H33-(H34+H35) -> 64 | I36: =I33-(I34+I35) -> 76 | J36: =J33-(J34+J35) -> 61 | K36: =K33-(K34+K35) -> 63 | L36: =L33-(L34+L35) -> 58 | ... U36: =U33-(U34+U35) -> 67 | V36: =SUM(E36:U36) -> 1048
A38: III | B38: DATA PEMILIH DISABILITAS
B39: Jumlah seluruh Pemilih disabilitas yang menggunakan hak pilih | D39: LK | G39: 1 | H39: 1 | I39: 1 | L39: 1 | N39: 1 | O39: 4 | R39: 1 | U39: 1 | V39: =SUM(E39:U39) -> 11
D40: PR | L40: 5 | N40: 1 | O40: 3 | V40: =SUM(E40:U40) -> 9
D41: JML | E41: =SUM(E39:E40) -> 0 | F41: =SUM(F39:F40) -> 0 | G41: =SUM(G39:G40) -> 1 | H41: =SUM(H39:H40) -> 1 | I41: =SUM(I39:I40) -> 1 | J41: =SUM(J39:J40) -> 0 | K41: =SUM(K39:K40) -> 0 | L41: =SUM(L39:L40) -> 6 | ... U41: =SUM(U39:U40) -> 1 | V41: =SUM(E41:U41) -> 20
A43: IV | B43: DATA RINCIAN PEROLEHAN SUARA PASANGAN CALON BUPATI DAN WAKIL BUPATI
A44: NOMOR DAN NAMA CALON
A45: A.1 | B45: 1. | C45: Partai Kebangkitan Bangsa | E45: 9 | F45: 2 | G45: 7 | H45: 9 | I45: 3 | J45: 8 | K45: 0 | L45: 10 | M45: 11 | N45: 10 | O45: 5 | P45: 9 | Q45: 3 | R45: 7 | S45: 11 | T45: 4 | U45: 1 | V45: =SUM(E45:U45) -> 109
A46: A.2 | C46: 1. Dra. Hj. MA`MULAH HARUN, M.Pd.I. | E46: 13 | F46: 8 | G46: 9 | H46: 14 | I46: 8 | J46: 9 | K46: 6 | L46: 8 | M46: 24 | N46: 28 | O46: 18 | P46: 13 | Q46: 3 | R46: 14 | S46: 10 | T46: 7 | U46: 11 | V46: =SUM(E46:U46) -> 203
C47: 2. UBAIDILLAH, S.Fil.I. | E47: 1 | F47: 4 | G47: 1 | H47: 0 | I47: 1 | J47: 0 | K47: 0 | L47: 0 | M47: 2 | N47: 0 | O47: 1 | P47: 3 | Q47: 1 | R47: 2 | S47: 0 | T47: 1 | U47: 1 | V47: =SUM(E47:U47) -> 18
C48: 3. Ir. H. YOYOK MULYADI, M.Si. | E48: 0 | F48: 0 | G48: 2 | H48: 0 | I48: 0 | J48: 2 | K48: 1 | L48: 1 | M48: 0 | N48: 2 | O48: 0 | P48: 0 | Q48: 0 | R48: 1 | S48: 0 | T48: 1 | U48: 2 | V48: =SUM(E48:U48) -> 12
C49: 4. KHOIRUL ANWAR, S.Fil.I. | E49: 0 | F49: 0 | G49: 0 | H49: 0 | I49: 0 | J49: 0 | K49: 0 | L49: 0 | M49: 1 | N49: 0 | O49: 1 | P49: 1 | Q49: 0 | R49: 0 | S49: 0 | U49: 1 | V49: =SUM(E49:U49) -> 4
C50: 5. ARIF WIJAKSANA | E50: 0 | F50: 0 | G50: 0 | H50: 2 | I50: 1 | J50: 1 | K50: 1 | L50: 0 | M50: 0 | N50: 0 | O50: 0 | P50: 2 | Q50: 0 | R50: 0 | S50: 0 | V50: =SUM(E50:U50) -> 7
C51: 6. Dr. SITI YUMNAH | E51: 0 | F51: 0 | G51: 0 | H51: 1 | I51: 0 | J51: 1 | K51: 0 | L51: 0 | M51: 0 | N51: 1 | O51: 0 | P51: 0 | Q51: 0 | R51: 0 | S51: 1 | V51: =SUM(E51:U51) -> 4
...

Sheet PENATABAN
C2: Kecamatan | D2: GIRI
C3: Kabupaten | D3: BANYUWANGI
C4: Provinsi | D4: JAWA TIMUR
C9: Kelurahan | D9: PENATABAN
A12: I | B12: DATA PEMILIH DAN PENGGUNAAN HAK PILIH | V12: JUMLAH AKHIR
A13: A | B13: DATA PEMILIH | E13: TPS 001 | F13: TPS 002 | G13: TPS 003 | H13: TPS 004 | I13: TPS 005 | J13: TPS 006 | K13: TPS 007 | L13: TPS 008 | M13: TPS 009 | N13: TPS 010 | O13: TPS 011 | P13: TPS 012 | Q13: TPS 013 | R13: TPS 901 | S13: TPS 902 | T13: TPS 903 | U13: TPS 904
B14: Jumlah Pemilih dalam Daftar Pemilih Tetap (DPT) | D14: LK | E14: 142 | F14: 145 | G14: 140 | H14: 144 | I14: 144 | J14: 147 | K14: 145 | L14: 159 | M14: 142 | N14: 129 | O14: 143 | P14: 115 | Q14: 77 | R14: 249 | S14: 252 | T14: 235 | U14: 189 | V14: =SUM(E14:U14) -> 2697
D15: PR | E15: 147 | F15: 150 | G15: 151 | H15: 141 | I15: 147 | J15: 138 | K15: 140 | L15: 134 | M15: 131 | N15: 137 | O15: 154 | P15: 134 | Q15: 97 | R15: 9 | S15: 7 | T15: 14 | U15: 8 | V15: =SUM(E15:U15) -> 1839
D16: JML | E16: =SUM(E14:E15) -> 289 | F16: =SUM(F14:F15) -> 295 | G16: =SUM(G14:G15) -> 291 | H16: =SUM(H14:H15) -> 285 | I16: =SUM(I14:I15) -> 291 | J16: =SUM(J14:J15) -> 285 | K16: =SUM(K14:K15) -> 285 | L16: =SUM(L14:L15) -> 293 | ... U16: =SUM(U14:U15) -> 197 | V16: =SUM(E16:U16) -> 4536
A18: B | B18: PENGGUNA HAK PILIH
B19: 1. | C19: Jumlah pengguna hak pilih dalam Daftar Pemilih Tetap (DPT) | D19: LK | E19: 114 | F19: 114 | G19: 108 | H19: 107 | I19: 111 | J19: 111 | K19: 124 | L19: 116 | M19: 122 | N19: 107 | O19: 117 | P19: 92 | Q19: 63 | R19: 151 | S19: 174 | T19: 126 | U19: 45 | V19: =SUM(E19:U19) -> 1902
D20: PR | E20: 124 | F20: 114 | G20: 128 | H20: 115 | I20: 125 | J20: 116 | K20: 123 | L20: 110 | M20: 121 | N20: 115 | O20: 126 | P20: 102 | Q20: 85 | R20: 6 | S20: 6 | T20: 5 | U20: 5 | V20: =SUM(E20:U20) -> 1526
D21: JML | E21: =SUM(E19:E20) -> 238 | F21: =SUM(F19:F20) -> 228 | G21: =SUM(G19:G20) -> 236 | H21: =SUM(H19:H20) -> 222 | I21: =SUM(I19:I20) -> 236 | J21: =SUM(J19:J20) -> 227 | K21: =SUM(K19:K20) -> 247 | L21: =SUM(L19:L20) -> 226 | ... U21: =SUM(U19:U20) -> 50 | V21: =SUM(E21:U21) -> 3428
B22: 2. | C22: Jumlah pengguna hak pilih dalam Daftar Pemilih Tambahan (DPTb) | D22: LK | E22: 0 | F22: 2 | G22: 0 | H22: 0 | I22: 0 | J22: 0 | K22: 1 | L22: 0 | M22: 0 | N22: 0 | O22: 0 | P22: 0 | Q22: 1 | R22: 80 | S22: 75 | T22: 83 | U22: 69 | V22: =SUM(E22:U22) -> 311
D23: PR | E23: 1 | F23: 0 | G23: 1 | H23: 0 | I23: 0 | J23: 0 | K23: 0 | L23: 0 | M23: 0 | N23: 0 | O23: 0 | P23: 0 | Q23: 1 | R23: 2 | S23: 2 | T23: 8 | U23: 4 | V23: =SUM(E23:U23) -> 19
D24: JML | E24: =SUM(E22:E23) -> 1 | F24: =SUM(F22:F23) -> 2 | G24: =SUM(G22:G23) -> 1 | H24: =SUM(H22:H23) -> 0 | I24: =SUM(I22:I23) -> 0 | J24: =SUM(J22:J23) -> 0 | K24: =SUM(K22:K23) -> 1 | L24: =SUM(L22:L23) -> 0 | ... U24: =SUM(U22:U23) -> 73 | V24: =SUM(E24:U24) -> 330
B25: 3. | C25: Jumlah pengguna hak pilih dalam Daftar Pemilih Khusus (DPK) | D25: LK | E25: 0 | F25: 1 | G25: 2 | H25: 1 | I25: 0 | J25: 3 | K25: 2 | L25: 3 | M25: 1 | N25: 0 | O25: 0 | P25: 0 | Q25: 0 | R25: 0 | S25: 0 | V25: =SUM(E25:U25) -> 13
D26: PR | E26: 0 | F26: 0 | G26: 4 | H26: 1 | I26: 2 | J26: 1 | K26: 1 | L26: 3 | M26: 1 | N26: 0 | O26: 3 | P26: 3 | Q26: 1 | R26: 0 | S26: 0 | V26: =SUM(E26:U26) -> 20
D27: JML | E27: =SUM(E25:E26) -> 0 | F27: =SUM(F25:F26) -> 1 | G27: =SUM(G25:G26) -> 6 | H27: =SUM(H25:H26) -> 2 | I27: =SUM(I25:I26) -> 2 | J27: =SUM(J25:J26) -> 4 | K27: =SUM(K25:K26) -> 3 | L27: =SUM(L25:L26) -> 6 | ... U27: =SUM(U25:U26) -> 0 | V27: =SUM(E27:U27) -> 33
B28: 4. | C28: Jumlah Pengguna Hak Pilih (B.1+B.2+B.3) | D28: LK | E28: =SUM(E19,E22,E25) -> 114 | F28: =SUM(F19,F22,F25) -> 117 | G28: =SUM(G19,G22,G25) -> 110 | H28: =SUM(H19,H22,H25) -> 108 | I28: =SUM(I19,I22,I25) -> 111 | J28: =SUM(J19,J22,J25) -> 114 | K28: =SUM(K19,K22,K25) -> 127 | L28: =SUM(L19,L22,L25) -> 119 | ... U28: =SUM(U19,U22,U25) -> 114 | V28: =SUM(E28:U28) -> 2226
D29: PR | E29: =SUM(E20,E23,E26) -> 125 | F29: =SUM(F20,F23,F26) -> 114 | G29: =SUM(G20,G23,G26) -> 133 | H29: =SUM(H20,H23,H26) -> 116 | I29: =SUM(I20,I23,I26) -> 127 | J29: =SUM(J20,J23,J26) -> 117 | K29: =SUM(K20,K23,K26) -> 124 | L29: =SUM(L20,L23,L26) -> 113 | ... U29: =SUM(U20,U23,U26) -> 9 | V29: =SUM(E29:U29) -> 1565
D30: JML | E30: =SUM(E28:E29) -> 239 | F30: =SUM(F28:F29) -> 231 | G30: =SUM(G28:G29) -> 243 | H30: =SUM(H28:H29) -> 224 | I30: =SUM(I28:I29) -> 238 | J30: =SUM(J28:J29) -> 231 | K30: =SUM(K28:K29) -> 251 | L30: =SUM(L28:L29) -> 232 | ... U30: =SUM(U28:U29) -> 123 | V30: =SUM(E30:U30) -> 3791
A32: II | B32: DATA PENGGUNAAN SURAT SUARA
A33: 1 | B33: Jumlah surat suara yang diterima, termasuk surat suara cadangan 2,5% dari DPT | E33: 293 | F33: 299 | G33: 295 | H33: 290 | I33: 295 | J33: 289 | K33: 290 | L33: 297 | M33: 277 | N33: 270 | O33: 301 | P33: 252 | Q33: 179 | R33: 264 | S33: 265 | T33: 254 | U33: 201 | V33: =SUM(E33:U33) -> 4611
A34: 2 | B34: Jumlah surat suara yang digunakan | E34: 239 | F34: 231 | G34: 243 | H34: 224 | I34: 238 | J34: 231 | K34: 251 | L34: 232 | M34: 245 | N34: 222 | O34: 246 | P34: 197 | Q34: 151 | R34: 239 | S34: 257 | T34: 222 | U34: 123 | V34: =SUM(E34:U34) -> 3791
A35: 3 | B35: Jumlah surat suara dikembalikan oleh pemilih (karena rusak atau keliru coblos) | I35: 1 | V35: =SUM(E35:U35) -> 1
A36: 4 | B36: Jumlah surat suara yang tidak digunakan/tidak terpakai, termasuk sisa surat suara cadangan | E36: =E33-(E34+E35) -> 54 | F36: =F33-(F34+F35) -> 68 | G36: =G33-(G34+G35) -> 52 | H36: =H33-(H34+H35) -> 66 | I36: =I33-(I34+I35) -> 56 | J36: =J33-(J34+J35) -> 58 | K36: =K33-(K34+K35) -> 39 | L36: =L33-(L34+L35) -> 65 | ... U36: =U33-(U34+U35) -> 78 | V36: =SUM(E36:U36) -> 819
A38: III | B38: DATA PEMILIH DISABILITAS
B39: Jumlah seluruh Pemilih disabilitas yang menggunakan hak pilih | D39: LK | P39: 2 | S39: 2 | V39: =SUM(E39:U39) -> 4
D40: PR | P40: 3 | V40: =SUM(E40:U40) -> 3
D41: JML | E41: =SUM(E39:E40) -> 0 | F41: =SUM(F39:F40) -> 0 | G41: =SUM(G39:G40) -> 0 | H41: =SUM(H39:H40) -> 0 | I41: =SUM(I39:I40) -> 0 | J41: =SUM(J39:J40) -> 0 | K41: =SUM(K39:K40) -> 0 | L41: =SUM(L39:L40) -> 0 | ... U41: =SUM(U39:U40) -> 0 | V41: =SUM(E41:U41) -> 7
A43: IV | B43: DATA RINCIAN PEROLEHAN SUARA PASANGAN CALON BUPATI DAN WAKIL BUPATI
A44: NOMOR DAN NAMA CALON
A45: A.1 | B45: 1. | C45: Partai Kebangkitan Bangsa | E45: 9 | F45: 12 | G45: 16 | H45: 12 | I45: 13 | J45: 5 | K45: 14 | L45: 11 | M45: 12 | N45: 14 | O45: 14 | P45: 4 | Q45: 5 | R45: 1 | S45: 1 | T45: 4 | U45: 1 | V45: =SUM(E45:U45) -> 148
A46: A.2 | C46: 1. Dra. Hj. MA`MULAH HARUN, M.Pd.I. | E46: 55 | F46: 40 | G46: 38 | H46: 29 | I46: 42 | J46: 37 | K46: 54 | L46: 52 | M46: 72 | N46: 42 | O46: 26 | P46: 7 | Q46: 17 | R46: 2 | S46: 1 | T46: 4 | V46: =SUM(E46:U46) -> 518
C47: 2. UBAIDILLAH, S.Fil.I. | E47: 1 | F47: 3 | G47: 1 | H47: 0 | I47: 0 | J47: 5 | K47: 1 | L47: 2 | M47: 3 | N47: 0 | O47: 2 | P47: 0 | Q47: 0 | R47: 1 | S47: 1 | V47: =SUM(E47:U47) -> 20
C48: 3. Ir. H. YOYOK MULYADI, M.Si. | E48: 0 | F48: 0 | G48: 1 | H48: 1 | I48: 1 | J48: 1 | K48: 0 | L48: 0 | M48: 1 | N48: 1 | O48: 0 | P48: 0 | Q48: 0 | R48: 0 | S48: 0 | V48: =SUM(E48:U48) -> 6
C49: 4. KHOIRUL ANWAR, S.Fil.I. | E49: 1 | F49: 3 | G49: 2 | H49: 0 | I49: 0 | J49: 1 | K49: 1 | L49: 2 | M49: 1 | N49: 1 | O49: 0 | P49: 0 | Q49: 0 | R49: 0 | S49: 1 | V49: =SUM(E49:U49) -> 13
C50: 5. ARIF WIJAKSANA | E50: 3 | F50: 0 | G50: 1 | H50: 0 | I50: 0 | J50: 0 | K50: 0 | L50: 1 | M50: 0 | N50: 0 | O50: 0 | P50: 0 | Q50: 1 | R50: 0 | S50: 0 | V50: =SUM(E50:U50) -> 6
C51: 6. Dr. SITI YUMNAH | E51: 2 | F51: 0 | G51: 1 | H51: 0 | I51: 0 | J51: 0 | K51: 0 | L51: 0 | M51: 1 | N51: 1 | O51: 0 | P51: 1 | Q51: 0 | R51: 0 | S51: 0 | V51: =SUM(E51:U51) -> 6
...
