Workbook

Sheet DPRD PROVINSI
C8: Kecamatan | D8: SINGOJURUH
C9: Kabupaten | D9: BANYUWANGI
C10: Provinsi | D10: JAWA TIMUR
A12: I | B12: DATA PEMILIH DAN PENGGUNAAN HAK PILIH | E12: JUMLAH AKHIR
A13: A | B13: DATA PEMILIH
B14: Jumlah Pemilih dalam Daftar Pemilih Tetap (DPT) | D14: LK | E14: =ALASMALANG!V14+'BENELAN KIDUL'!S14+CANTUK!T14+GAMBOR!N14+GUMIRIH!S14+KEMIRI!U14+LEMAHBANGKULON!Q14+PADANG!Q14+SINGOJURUH!AC14+SINGOLATREN!T14+SUMBERBARU!S14 -> 16137
D15: PR | E15: =ALASMALANG!V15+'BENELAN KIDUL'!S15+CANTUK!T15+GAMBOR!N15+GUMIRIH!S15+KEMIRI!U15+LEMAHBANGKULON!Q15+PADANG!Q15+SINGOJURUH!AC15+SINGOLATREN!T15+SUMBERBARU!S15 -> 16446
D16: JML | E16: =SUM(E14:E15) -> 32583
A18: B | B18: PENGGUNA HAK PILIH
B19: 1. | C19: Jumlah pengguna hak pilih dalam Daftar Pemilih Tetap (DPT) | D19: LK | E19: =ALASMALANG!V19+'BENELAN KIDUL'!S19+CANTUK!T19+GAMBOR!N19+GUMIRIH!S19+KEMIRI!U19+LEMAHBANGKULON!Q19+PADANG!Q19+SINGOJURUH!AC19+SINGOLATREN!T19+SUMBERBARU!S19 -> 12222
D20: PR | E20: =ALASMALANG!V20+'BENELAN KIDUL'!S20+CANTUK!T20+GAMBOR!N20+GUMIRIH!S20+KEMIRI!U20+LEMAHBANGKULON!Q20+PADANG!Q20+SINGOJURUH!AC20+SINGOLATREN!T20+SUMBERBARU!S20 -> 13252
D21: JML | E21: =SUM(E19:E20) -> 25474
B22: 2. | C22: Jumlah pengguna hak pilih dalam Daftar Pemilih Tambahan (DPTb) | D22: LK | E22: =ALASMALANG!V22+'BENELAN KIDUL'!S22+CANTUK!T22+GAMBOR!N22+GUMIRIH!S22+KEMIRI!U22+LEMAHBANGKULON!Q22+PADANG!Q22+SINGOJURUH!AC22+SINGOLATREN!T22+SUMBERBARU!S22 -> 40
D23: PR | E23: =ALASMALANG!V23+'BENELAN KIDUL'!S23+CANTUK!T23+GAMBOR!N23+GUMIRIH!S23+KEMIRI!U23+LEMAHBANGKULON!Q23+PADANG!Q23+SINGOJURUH!AC23+SINGOLATREN!T23+SUMBERBARU!S23 -> 41
D24: JML | E24: =SUM(E22:E23) -> 81
B25: 3. | C25: Jumlah pengguna hak pilih dalam Daftar Pemilih Khusus (DPK) | D25: LK | E25: =ALASMALANG!V25+'BENELAN KIDUL'!S25+CANTUK!T25+GAMBOR!N25+GUMIRIH!S25+KEMIRI!U25+LEMAHBANGKULON!Q25+PADANG!Q25+SINGOJURUH!AC25+SINGOLATREN!T25+SUMBERBARU!S25 -> 108
D26: PR | E26: =ALASMALANG!V26+'BENELAN KIDUL'!S26+CANTUK!T26+GAMBOR!N26+GUMIRIH!S26+KEMIRI!U26+LEMAHBANGKULON!Q26+PADANG!Q26+SINGOJURUH!AC26+SINGOLATREN!T26+SUMBERBARU!S26 -> 128
D27: JML | E27: =SUM(E25:E26) -> 236
B28: 4. | C28: Jumlah Pengguna Hak Pilih (B.1+B.2+B.3) | D28: LK | E28: =E19+E22+E25 -> 12370
D29: PR | E29: =E20+E23+E26 -> 13421
D30: JML | E30: =SUM(E28:E29) -> 25791
A32: II | B32: DATA PENGGUNAAN SURAT SUARA
A33: 1 | B33: Jumlah surat suara yang diterima, termasuk surat suara cadangan 2,5% dari DPT | E33: =ALASMALANG!V33+'BENELAN KIDUL'!S33+CANTUK!T33+GAMBOR!N33+GUMIRIH!S33+KEMIRI!U33+LEMAHBANGKULON!Q33+PADANG!Q33+SINGOJURUH!AC33+SINGOLATREN!T33+SUMBERBARU!S33 -> 32903
A34: 2 | B34: Jumlah surat suara yang digunakan | E34: =ALASMALANG!V34+'BENELAN KIDUL'!S34+CANTUK!T34+GAMBOR!N34+GUMIRIH!S34+KEMIRI!U34+LEMAHBANGKULON!Q34+PADANG!Q34+SINGOJURUH!AC34+SINGOLATREN!T34+SUMBERBARU!S34 -> 25791
A35: 3 | B35: Jumlah surat suara dikembalikan oleh pemilih (karena rusak atau keliru coblos) | E35: =ALASMALANG!V35+'BENELAN KIDUL'!S35+CANTUK!T35+GAMBOR!N35+GUMIRIH!S35+KEMIRI!U35+LEMAHBANGKULON!Q35+PADANG!Q35+SINGOJURUH!AC35+SINGOLATREN!T35+SUMBERBARU!S35 -> 62
A36: 4 | B36: Jumlah surat suara yang tidak digunakan/tidak terpakai, termasuk sisa surat suara cadangan | E36: =E33-(E34+E35) -> 7050
A38: III | B38: DATA PEMILIH DISABILITAS
B39: Jumlah seluruh Pemilih disabilitas yang menggunakan hak pilih | D39: LK | E39: =ALASMALANG!V39+'BENELAN KIDUL'!S39+CANTUK!T39+GAMBOR!N39+GUMIRIH!S39+KEMIRI!U39+LEMAHBANGKULON!Q39+PADANG!Q39+SINGOJURUH!AC39+SINGOLATREN!T39+SUMBERBARU!S39 -> 24
D40: PR | E40: =ALASMALANG!V40+'BENELAN KIDUL'!S40+CANTUK!T40+GAMBOR!N40+GUMIRIH!S40+KEMIRI!U40+LEMAHBANGKULON!Q40+PADANG!Q40+SINGOJURUH!AC40+SINGOLATREN!T40+SUMBERBARU!S40 -> 50
D41: JML | E41: =SUM(E39:E40) -> 74
A43: IV | B43: DATA RINCIAN PEROLEHAN SUARA PASANGAN CALON BUPATI DAN WAKIL BUPATI
A44: NOMOR DAN NAMA CALON
A45: A.1 | B45: 1. | C45: Partai Kebangkitan Bangsa | E45: =ALASMALANG!V45+'BENELAN KIDUL'!S45+CANTUK!T45+GAMBOR!N45+GUMIRIH!S45+KEMIRI!U45+LEMAHBANGKULON!Q45+PADANG!Q45+SINGOJURUH!AC45+SINGOLATREN!T45+SUMBERBARU!S45 -> 998
A46: A.2 | C46: 1. Dra. Hj. MA`MULAH HARUN, M.Pd.I. | E46: =ALASMALANG!V46+'BENELAN KIDUL'!S46+CANTUK!T46+GAMBOR!N46+GUMIRIH!S46+KEMIRI!U46+LEMAHBANGKULON!Q46+PADANG!Q46+SINGOJURUH!AC46+SINGOLATREN!T46+SUMBERBARU!S46 -> 1872
C47: 2. UBAIDILLAH, S.Fil.I. | E47: =ALASMALANG!V47+'BENELAN KIDUL'!S47+CANTUK!T47+GAMBOR!N47+GUMIRIH!S47+KEMIRI!U47+LEMAHBANGKULON!Q47+PADANG!Q47+SINGOJURUH!AC47+SINGOLATREN!T47+SUMBERBARU!S47 -> 451
C48: 3. Ir. H. YOYOK MULYADI, M.Si. | E48: =ALASMALANG!V48+'BENELAN KIDUL'!S48+CANTUK!T48+GAMBOR!N48+GUMIRIH!S48+KEMIRI!U48+LEMAHBANGKULON!Q48+PADANG!Q48+SINGOJURUH!AC48+SINGOLATREN!T48+SUMBERBARU!S48 -> 120
C49: 4. KHOIRUL ANWAR, S.Fil.I. | E49: =ALASMALANG!V49+'BENELAN KIDUL'!S49+CANTUK!T49+GAMBOR!N49+GUMIRIH!S49+KEMIRI!U49+LEMAHBANGKULON!Q49+PADANG!Q49+SINGOJURUH!AC49+SINGOLATREN!T49+SUMBERBARU!S49 -> 163
C50: 5. ARIF WIJAKSANA | E50: =ALASMALANG!V50+'BENELAN KIDUL'!S50+CANTUK!T50+GAMBOR!N50+GUMIRIH!S50+KEMIRI!U50+LEMAHBANGKULON!Q50+PADANG!Q50+SINGOJURUH!AC50+SINGOLATREN!T50+SUMBERBARU!S50 -> 67
C51: 6. Dr. SITI YUMNAH | E51: =ALASMALANG!V51+'BENELAN KIDUL'!S51+CANTUK!T51+GAMBOR!N51+GUMIRIH!S51+KEMIRI!U51+LEMAHBANGKULON!Q51+PADANG!Q51+SINGOJURUH!AC51+SINGOLATREN!T51+SUMBERBARU!S51 -> 42
C52: 7. MOHAMMAD ZAINI, M.Pd.I. | E52: =ALASMALANG!V52+'BENELAN KIDUL'!S52+CANTUK!T52+GAMBOR!N52+GUMIRIH!S52+KEMIRI!U52+LEMAHBANGKULON!Q52+PADANG!Q52+SINGOJURUH!AC52+SINGOLATREN!T52+SUMBERBARU!S52 -> 30
...

Sheet ALASMALANG
C2: Kecamatan | D2: SINGOJURUH
C3: Kabupaten | D3: BANYUWANGI
C4: Provinsi | D4: JAWA TIMUR
C9: Kelurahan | D9: ALASMALANG
A12: I | B12: DATA PEMILIH DAN PENGGUNAAN HAK PILIH | V12: JUMLAH AKHIR
A13: A | B13: DATA PEMILIH | E13: TPS 001 | F13: TPS 002 | G13: TPS 003 | H13: TPS 004 | I13: TPS 005 | J13: TPS 006 | K13: TPS 007 | L13: TPS 008 | M13: TPS 009 | N13: TPS 010 | O13: TPS 011 | P13: TPS 012 | Q13: TPS 013 | R13: TPS 014 | S13: TPS 015 | T13: TPS 016 | U13: TPS 017
B14: Jumlah Pemilih dalam Daftar Pemilih Tetap (DPT) | D14: LK | E14: 124 | F14: 110 | G14: 95 | H14: 116 | I14: 101 | J14: 88 | K14: 79 | L14: 121 | M14: 101 | N14: 107 | O14: 99 | P14: 103 | Q14: 128 | R14: 83 | S14: 104 | T14: 93 | U14: 127 | V14: =SUM(E14:U14) -> 1779
D15: PR | E15: 128 | F15: 102 | G15: 92 | H15: 125 | I15: 117 | J15: 94 | K15: 93 | L15: 124 | M15: 94 | N15: 117 | O15: 90 | P15: 108 | Q15: 126 | R15: 85 | S15: 113 | T15: 113 | U15: 110 | V15: =SUM(E15:U15) -> 1831
D16: JML | E16: =SUM(E14:E15) -> 252 | F16: =SUM(F14:F15) -> 212 | G16: =SUM(G14:G15) -> 187 | H16: =SUM(H14:H15) -> 241 | I16: =SUM(I14:I15) -> 218 | J16: =SUM(J14:J15) -> 182 | K16: =SUM(K14:K15) -> 172 | L16: =SUM(L14:L15) -> 245 | ... U16: =SUM(U14:U15) -> 237 | V16: =SUM(E16:U16) -> 3610
A18: B | B18: PENGGUNA HAK PILIH
B19: 1. | C19: Jumlah pengguna hak pilih dalam Daftar Pemilih Tetap (DPT) | D19: LK | E19: 114 | F19: 90 | G19: 71 | H19: 89 | I19: 80 | J19: 65 | K19: 63 | L19: 92 | M19: 82 | N19: 86 | O19: 81 | P19: 83 | Q19: 81 | R19: 66 | S19: 81 | T19: 82 | U19: 107 | V19: =SUM(E19:U19) -> 1413
D20: PR | E20: 94 | F20: 90 | G20: 81 | H20: 95 | I20: 102 | J20: 77 | K20: 74 | L20: 100 | M20: 79 | N20: 95 | O20: 74 | P20: 86 | Q20: 96 | R20: 74 | S20: 95 | T20: 102 | U20: 104 | V20: =SUM(E20:U20) -> 1518
D21: JML | E21: =SUM(E19:E20) -> 208 | F21: =SUM(F19:F20) -> 180 | G21: =SUM(G19:G20) -> 152 | H21: =SUM(H19:H20) -> 184 | I21: =SUM(I19:I20) -> 182 | J21: =SUM(J19:J20) -> 142 | K21: =SUM(K19:K20) -> 137 | L21: =SUM(L19:L20) -> 192 | ... U21: =SUM(U19:U20) -> 211 | V21: =SUM(E21:U21) -> 2931
B22: 2. | C22: Jumlah pengguna hak pilih dalam Daftar Pemilih Tambahan (DPTb) | D22: LK | T22: 0 | U22: 0 | V22: =SUM(E22:U22) -> 0
D23: PR | T23: 0 | U23: 1 | V23: =SUM(E23:U23) -> 1
D24: JML | E24: =SUM(E22:E23) -> 0 | F24: =SUM(F22:F23) -> 0 | G24: =SUM(G22:G23) -> 0 | H24: =SUM(H22:H23) -> 0 | I24: =SUM(I22:I23) -> 0 | J24: =SUM(J22:J23) -> 0 | K24: =SUM(K22:K23) -> 0 | L24: =SUM(L22:L23) -> 0 | ... U24: =SUM(U22:U23) -> 1 | V24: =SUM(E24:U24) -> 1
B25: 3. | C25: Jumlah pengguna hak pilih dalam Daftar Pemilih Khusus (DPK) | D25: LK | E25: 5 | F25: 6 | G25: 1 | H25: 0 | I25: 0 | J25: 1 | K25: 0 | L25: 1 | M25: 0 | N25: 4 | O25: 1 | P25: 2 | Q25: 3 | R25: 0 | S25: 3 | T25: 2 | U25: 0 | V25: =SUM(E25:U25) -> 29
D26: PR | E26: 3 | F26: 6 | G26: 2 | H26: 0 | I26: 0 | J26: 2 | K26: 0 | L26: 2 | M26: 0 | N26: 1 | O26: 1 | P26: 1 | Q26: 1 | R26: 1 | S26: 1 | T26: 3 | U26: 0 | V26: =SUM(E26:U26) -> 24
D27: JML | E27: =SUM(E25:E26) -> 8 | F27: =SUM(F25:F26) -> 12 | G27: =SUM(G25:G26) -> 3 | H27: =SUM(H25:H26) -> 0 | I27: =SUM(I25:I26) -> 0 | J27: =SUM(J25:J26) -> 3 | K27: =SUM(K25:K26) -> 0 | L27: =SUM(L25:L26) -> 3 | ... U27: =SUM(U25:U26) -> 0 | V27: =SUM(E27:U27) -> 53
B28: 4. | C28: Jumlah Pengguna Hak Pilih (B.1+B.2+B.3) | D28: LK | E28: =SUM(E19,E22,E25) -> 119 | F28: =SUM(F19,F22,F25) -> 96 | G28: =SUM(G19,G22,G25) -> 72 | H28: =SUM(H19,H22,H25) -> 89 | I28: =SUM(I19,I22,I25) -> 80 | J28: =SUM(J19,J22,J25) -> 66 | K28: =SUM(K19,K22,K25) -> 63 | L28: =SUM(L19,L22,L25) -> 93 | ... U28: =SUM(U19,U22,U25) -> 107 | V28: =SUM(E28:U28) -> 1442
D29: PR | E29: =SUM(E20,E23,E26) -> 97 | F29: =SUM(F20,F23,F26) -> 96 | G29: =SUM(G20,G23,G26) -> 83 | H29: =SUM(H20,H23,H26) -> 95 | I29: =SUM(I20,I23,I26) -> 102 | J29: =SUM(J20,J23,J26) -> 79 | K29: =SUM(K20,K23,K26) -> 74 | L29: =SUM(L20,L23,L26) -> 102 | ... U29: =SUM(U20,U23,U26) -> 105 | V29: =SUM(E29:U29) -> 1543
D30: JML | E30: =SUM(E28:E29) -> 216 | F30: =SUM(F28:F29) -> 192 | G30: =SUM(G28:G29) -> 155 | H30: =SUM(H28:H29) -> 184 | I30: =SUM(I28:I29) -> 182 | J30: =SUM(J28:J29) -> 145 | K30: =SUM(K28:K29) -> 137 | L30: =SUM(L28:L29) -> 195 | ... U30: =SUM(U28:U29) -> 212 | V30: =SUM(E30:U30) -> 2985
A32: II | B32: DATA PENGGUNAAN SURAT SUARA
A33: 1 | B33: Jumlah surat suara yang diterima, termasuk surat suara cadangan 2,5% dari DPT | E33: 256 | F33: 215 | G33: 291 | H33: 243 | I33: 220 | J33: 184 | K33: 173 | L33: 247 | M33: 198 | N33: 229 | O33: 190 | P33: 210 | Q33: 257 | R33: 169 | S33: 216 | T33: 209 | U33: 239 | V33: =SUM(E33:U33) -> 3746
A34: 2 | B34: Jumlah surat suara yang digunakan | E34: 216 | F34: 192 | G34: 155 | H34: 184 | I34: 182 | J34: 145 | K34: 137 | L34: 195 | M34: 161 | N34: 186 | O34: 157 | P34: 172 | Q34: 181 | R34: 141 | S34: 180 | T34: 189 | U34: 212 | V34: =SUM(E34:U34) -> 2985
A35: 3 | B35: Jumlah surat suara dikembalikan oleh pemilih (karena rusak atau keliru coblos) | E35: 0 | F35: 0 | G35: 0 | H35: 0 | I35: 2 | J35: 0 | K35: 0 | L35: 4 | M35: 2 | N35: 1 | O35: 0 | P35: 0 | Q35: 2 | R35: 0 | S35: 1 | T35: 0 | U35: 1 | V35: =SUM(E35:U35) -> 13
A36: 4 | B36: Jumlah surat suara yang tidak digunakan/tidak terpakai, termasuk sisa surat suara cadangan | E36: =E33-(E34+E35) -> 40 | F36: =F33-(F34+F35) -> 23 | G36: =G33-(G34+G35) -> 136 | H36: =H33-(H34+H35) -> 59 | I36: =I33-(I34+I35) -> 36 | J36: =J33-(J34+J35) -> 39 | K36: =K33-(K34+K35) -> 36 | L36: =L33-(L34+L35) -> 48 | ... U36: =U33-(U34+U35) -> 26 | V36: =SUM(E36:U36) -> 748
A38: III | B38: DATA PEMILIH DISABILITAS
B39: Jumlah seluruh Pemilih disabilitas yang menggunakan hak pilih | D39: LK | R39: 1 | V39: =SUM(E39:U39) -> 1
D40: PR | V40: =SUM(E40:U40) -> 0
D41: JML | E41: =SUM(E39:E40) -> 0 | F41: =SUM(F39:F40) -> 0 | G41: =SUM(G39:G40) -> 0 | H41: =SUM(H39:H40) -> 0 | I41: =SUM(I39:I40) -> 0 | J41: =SUM(J39:J40) -> 0 | K41: =SUM(K39:K40) -> 0 | L41: =SUM(L39:L40) -> 0 | ... U41: =SUM(U39:U40) -> 0 | V41: =SUM(E41:U41) -> 1
A43: IV | B43: DATA RINCIAN PEROLEHAN SUARA PASANGAN CALON BUPATI DAN WAKIL BUPATI
A44: NOMOR DAN NAMA CALON
A45: A.1 | B45: 1. | C45: Partai Kebangkitan Bangsa | E45: 7 | F45: 3 | G45: 8 | H45: 5 | I45: 7 | J45: 3 | K45: 6 | L45: 6 | M45: 3 | N45: 4 | O45: 3 | P45: 1 | Q45: 3 | R45: 6 | S45: 8 | T45: 6 | U45: 12 | V45: =SUM(E45:U45) -> 91
A46: A.2 | C46: 1. Dra. Hj. MA`MULAH HARUN, M.Pd.I. | E46: 17 | F46: 19 | G46: 12 | H46: 12 | I46: 25 | J46: 8 | K46: 17 | L46: 16 | M46: 3 | N46: 4 | O46: 7 | P46: 7 | Q46: 9 | R46: 7 | S46: 17 | T46: 18 | U46: 34 | V46: =SUM(E46:U46) -> 232
C47: 2. UBAIDILLAH, S.Fil.I. | E47: 4 | F47: 3 | G47: 2 | H47: 4 | I47: 7 | J47: 0 | K47: 1 | L47: 3 | M47: 0 | N47: 5 | O47: 3 | P47: 1 | Q47: 3 | R47: 3 | S47: 8 | T47: 5 | U47: 5 | V47: =SUM(E47:U47) -> 57
C48: 3. Ir. H. YOYOK MULYADI, M.Si. | E48: 0 | F48: 1 | G48: 1 | H48: 0 | I48: 0 | J48: 1 | K48: 0 | L48: 0 | M48: 0 | N48: 0 | O48: 0 | P48: 0 | Q48: 0 | R48: 1 | S48: 0 | T48: 2 | U48: 0 | V48: =SUM(E48:U48) -> 6
C49: 4. KHOIRUL ANWAR, S.Fil.I. | E49: 1 | F49: 1 | G49: 2 | H49: 2 | I49: 1 | J49: 0 | K49: 0 | L49: 1 | M49: 0 | N49: 1 | O49: 1 | P49: 2 | Q49: 2 | R49: 2 | S49: 5 | T49: 2 | U49: 18 | V49: =SUM(E49:U49) -> 41
C50: 5. ARIF WIJAKSANA | E50: 0 | F50: 2 | G50: 2 | H50: 2 | I50: 0 | J50: 0 | K50: 0 | L50: 0 | M50: 1 | N50: 0 | O50: 0 | P50: 0 | Q50: 0 | R50: 0 | S50: 0 | T50: 1 | U50: 0 | V50: =SUM(E50:U50) -> 8
C51: 6. Dr. SITI YUMNAH | E51: 0 | F51: 1 | G51: 0 | H51: 1 | I51: 0 | J51: 0 | K51: 0 | L51: 0 | M51: 0 | N51: 0 | O51: 0 | P51: 0 | Q51: 0 | R51: 0 | S51: 0 | T51: 1 | U51: 0 | V51: =SUM(E51:U51) -> 3
...

Sheet BENELAN KIDUL
C2: Kecamatan | D2: SINGOJURUH
C3: Kabupaten | D3: BANYUWANGI
C4: Provinsi | D4: JAWA TIMUR
C9: Kelurahan | D9: BENELAN KIDUL
A12: I | B12: DATA PEMILIH DAN PENGGUNAAN HAK PILIH | S12: JUMLAH AKHIR
A13: A | B13: DATA PEMILIH | E13: TPS 001 | F13: TPS 002 | G13: TPS 003 | H13: TPS 004 | I13: TPS 005 | J13: TPS 006 | K13: TPS 007 | L13: TPS 008 | M13: TPS 009 | N13: TPS 010 | O13: TPS 011 | P13: TPS 012 | Q13: TPS 013 | R13: TPS 014
B14: Jumlah Pemilih dalam Daftar Pemilih Tetap (DPT) | D14: LK | E14: 138 | F14: 130 | G14: 130 | H14: 146 | I14: 139 | J14: 137 | K14: 149 | L14: 133 | M14: 123 | N14: 136 | O14: 128 | P14: 107 | Q14: 127 | R14: 117 | S14: =SUM(E14:R14) -> 1840
D15: PR | E15: 126 | F15: 119 | G15: 135 | H15: 133 | I15: 129 | J15: 144 | K15: 133 | L15: 134 | M15: 115 | N15: 125 | O15: 139 | P15: 101 | Q15: 123 | R15: 112 | S15: =SUM(E15:R15) -> 1768
D16: JML | E16: =SUM(E14:E15) -> 264 | F16: =SUM(F14:F15) -> 249 | G16: =SUM(G14:G15) -> 265 | H16: =SUM(H14:H15) -> 279 | I16: =SUM(I14:I15) -> 268 | J16: =SUM(J14:J15) -> 281 | K16: =SUM(K14:K15) -> 282 | L16: =SUM(L14:L15) -> 267 | ... R16: =SUM(R14:R15) -> 229 | S16: =SUM(E16:R16) -> 3608
A18: B | B18: PENGGUNA HAK PILIH
B19: 1. | C19: Jumlah pengguna hak pilih dalam Daftar Pemilih Tetap (DPT) | D19: LK | E19: 111 | F19: 107 | G19: 102 | H19: 112 | I19: 110 | J19: 105 | K19: 117 | L19: 102 | M19: 86 | N19: 101 | O19: 93 | P19: 82 | Q19: 97 | R19: 96 | S19: =SUM(E19:R19) -> 1421
D20: PR | E20: 108 | F20: 99 | G20: 113 | H20: 114 | I20: 106 | J20: 117 | K20: 115 | L20: 108 | M20: 93 | N20: 83 | O20: 108 | P20: 78 | Q20: 107 | R20: 98 | S20: =SUM(E20:R20) -> 1447
D21: JML | E21: =SUM(E19:E20) -> 219 | F21: =SUM(F19:F20) -> 206 | G21: =SUM(G19:G20) -> 215 | H21: =SUM(H19:H20) -> 226 | I21: =SUM(I19:I20) -> 216 | J21: =SUM(J19:J20) -> 222 | K21: =SUM(K19:K20) -> 232 | L21: =SUM(L19:L20) -> 210 | ... R21: =SUM(R19:R20) -> 194 | S21: =SUM(E21:R21) -> 2868
B22: 2. | C22: Jumlah pengguna hak pilih dalam Daftar Pemilih Tambahan (DPTb) | D22: LK | E22: 0 | F22: 1 | G22: 0 | H22: 2 | I22: 1 | J22: 0 | K22: 0 | L22: 0 | M22: 1 | N22: 0 | O22: 0 | P22: 0 | Q22: 0 | R22: 0 | S22: =SUM(E22:R22) -> 5
D23: PR | E23: 0 | F23: 1 | G23: 0 | H23: 1 | I23: 2 | J23: 0 | K23: 0 | L23: 0 | M23: 1 | N23: 0 | O23: 0 | P23: 0 | Q23: 0 | R23: 0 | S23: =SUM(E23:R23) -> 5
D24: JML | E24: =SUM(E22:E23) -> 0 | F24: =SUM(F22:F23) -> 2 | G24: =SUM(G22:G23) -> 0 | H24: =SUM(H22:H23) -> 3 | I24: =SUM(I22:I23) -> 3 | J24: =SUM(J22:J23) -> 0 | K24: =SUM(K22:K23) -> 0 | L24: =SUM(L22:L23) -> 0 | ... R24: =SUM(R22:R23) -> 0 | S24: =SUM(E24:R24) -> 10
B25: 3. | C25: Jumlah pengguna hak pilih dalam Daftar Pemilih Khusus (DPK) | D25: LK | F25: 4 | G25: 1 | H25: 0 | I25: 0 | J25: 0 | K25: 0 | L25: 0 | M25: 2 | N25: 0 | O25: 3 | P25: 0 | Q25: 0 | R25: 0 | S25: =SUM(E25:R25) -> 10
D26: PR | E26: 0 | F26: 6 | G26: 1 | H26: 0 | I26: 0 | J26: 2 | K26: 0 | L26: 0 | M26: 3 | N26: 0 | O26: 2 | P26: 0 | Q26: 0 | R26: 0 | S26: =SUM(E26:R26) -> 14
D27: JML | E27: =SUM(E25:E26) -> 0 | F27: =SUM(F25:F26) -> 10 | G27: =SUM(G25:G26) -> 2 | H27: =SUM(H25:H26) -> 0 | I27: =SUM(I25:I26) -> 0 | J27: =SUM(J25:J26) -> 2 | K27: =SUM(K25:K26) -> 0 | L27: =SUM(L25:L26) -> 0 | ... R27: =SUM(R25:R26) -> 0 | S27: =SUM(E27:R27) -> 24
B28: 4. | C28: Jumlah Pengguna Hak Pilih (B.1+B.2+B.3) | D28: LK | E28: =SUM(E19,E22,E25) -> 111 | F28: =SUM(F19,F22,F25) -> 112 | G28: =SUM(G19,G22,G25) -> 103 | H28: =SUM(H19,H22,H25) -> 114 | I28: =SUM(I19,I22,I25) -> 111 | J28: =SUM(J19,J22,J25) -> 105 | K28: =SUM(K19,K22,K25) -> 117 | L28: =SUM(L19,L22,L25) -> 102 | ... R28: =SUM(R19,R22,R25) -> 96 | S28: =SUM(E28:R28) -> 1436
D29: PR | E29: =SUM(E20,E23,E26) -> 108 | F29: =SUM(F20,F23,F26) -> 106 | G29: =SUM(G20,G23,G26) -> 114 | H29: =SUM(H20,H23,H26) -> 115 | I29: =SUM(I20,I23,I26) -> 108 | J29: =SUM(J20,J23,J26) -> 119 | K29: =SUM(K20,K23,K26) -> 115 | L29: =SUM(L20,L23,L26) -> 108 | ... R29: =SUM(R20,R23,R26) -> 98 | S29: =SUM(E29:R29) -> 1466
D30: JML | E30: =SUM(E28:E29) -> 219 | F30: =SUM(F28:F29) -> 218 | G30: =SUM(G28:G29) -> 217 | H30: =SUM(H28:H29) -> 229 | I30: =SUM(I28:I29) -> 219 | J30: =SUM(J28:J29) -> 224 | K30: =SUM(K28:K29) -> 232 | L30: =SUM(L28:L29) -> 210 | ... R30: =SUM(R28:R29) -> 194 | S30: =SUM(E30:R30) -> 2902
A32: II | B32: DATA PENGGUNAAN SURAT SUARA
A33: 1 | B33: Jumlah surat suara yang diterima, termasuk surat suara cadangan 2,5% dari DPT | E33: 267 | F33: 253 | G33: 271 | H33: 282 | I33: 273 | J33: 287 | K33: 285 | L33: 270 | M33: 240 | N33: 264 | O33: 271 | P33: 210 | Q33: 253 | R33: 231 | S33: =SUM(E33:R33) -> 3657
A34: 2 | B34: Jumlah surat suara yang digunakan | E34: 219 | F34: 218 | G34: 217 | H34: 229 | I34: 219 | J34: 224 | K34: 232 | L34: 210 | M34: 186 | N34: 184 | O34: 206 | P34: 160 | Q34: 204 | R34: 194 | S34: =SUM(E34:R34) -> 2902
A35: 3 | B35: Jumlah surat suara dikembalikan oleh pemilih (karena rusak atau keliru coblos) | E35: 0 | F35: 0 | G35: 4 | H35: 1 | I35: 2 | J35: 0 | K35: 2 | L35: 0 | M35: 0 | N35: 0 | O35: 1 | P35: 0 | Q35: 0 | R35: 0 | S35: =SUM(E35:R35) -> 10
A36: 4 | B36: Jumlah surat suara yang tidak digunakan/tidak terpakai, termasuk sisa surat suara cadangan | E36: =E33-(E34+E35) -> 48 | F36: =F33-(F34+F35) -> 35 | G36: =G33-(G34+G35) -> 50 | H36: =H33-(H34+H35) -> 52 | I36: =I33-(I34+I35) -> 52 | J36: =J33-(J34+J35) -> 63 | K36: =K33-(K34+K35) -> 51 | L36: =L33-(L34+L35) -> 60 | ... R36: =R33-(R34+R35) -> 37 | S36: =SUM(E36:R36) -> 745
A38: III | B38: DATA PEMILIH DISABILITAS
B39: Jumlah seluruh Pemilih disabilitas yang menggunakan hak pilih | D39: LK | E39: 0 | F39: 1 | G39: 0 | H39: 2 | I39: 0 | J39: 0 | K39: 0 | L39: 0 | M39: 0 | N39: 2 | O39: 0 | P39: 0 | Q39: 0 | R39: 0 | S39: =SUM(E39:R39) -> 5
D40: PR | E40: 0 | F40: 3 | G40: 0 | H40: 4 | I40: 0 | J40: 4 | K40: 0 | L40: 0 | M40: 0 | N40: 2 | O40: 0 | P40: 0 | Q40: 0 | R40: 0 | S40: =SUM(E40:R40) -> 13
D41: JML | E41: =SUM(E39:E40) -> 0 | F41: =SUM(F39:F40) -> 4 | G41: =SUM(G39:G40) -> 0 | H41: =SUM(H39:H40) -> 6 | I41: =SUM(I39:I40) -> 0 | J41: =SUM(J39:J40) -> 4 | K41: =SUM(K39:K40) -> 0 | L41: =SUM(L39:L40) -> 0 | ... R41: =SUM(R39:R40) -> 0 | S41: =SUM(E41:R41) -> 18
A43: IV | B43: DATA RINCIAN PEROLEHAN SUARA PASANGAN CALON BUPATI DAN WAKIL BUPATI
A44: NOMOR DAN NAMA CALON
A45: A.1 | B45: 1. | C45: Partai Kebangkitan Bangsa | E45: 6 | F45: 17 | G45: 7 | H45: 0 | I45: 6 | J45: 12 | K45: 11 | L45: 17 | M45: 14 | N45: 12 | O45: 4 | P45: 2 | Q45: 9 | R45: 7 | S45: =SUM(E45:R45) -> 124
A46: A.2 | C46: 1. Dra. Hj. MA`MULAH HARUN, M.Pd.I. | E46: 16 | F46: 36 | G46: 15 | H46: 8 | I46: 6 | J46: 24 | K46: 23 | L46: 12 | M46: 29 | N46: 11 | O46: 13 | P46: 5 | Q46: 14 | R46: 3 | S46: =SUM(E46:R46) -> 215
C47: 2. UBAIDILLAH, S.Fil.I. | E47: 0 | F47: 1 | G47: 1 | H47: 2 | I47: 4 | J47: 7 | K47: 8 | L47: 6 | M47: 3 | N47: 11 | O47: 3 | P47: 4 | Q47: 4 | R47: 5 | S47: =SUM(E47:R47) -> 59
C48: 3. Ir. H. YOYOK MULYADI, M.Si. | E48: 0 | F48: 0 | G48: 0 | H48: 0 | I48: 2 | J48: 3 | K48: 4 | L48: 1 | M48: 2 | N48: 2 | O48: 1 | P48: 2 | Q48: 1 | R48: 2 | S48: =SUM(E48:R48) -> 20
C49: 4. KHOIRUL ANWAR, S.Fil.I. | E49: 0 | F49: 0 | G49: 1 | H49: 0 | I49: 0 | J49: 1 | K49: 1 | L49: 1 | M49: 0 | N49: 1 | O49: 0 | P49: 1 | Q49: 0 | R49: 0 | S49: =SUM(E49:R49) -> 6
C50: 5. ARIF WIJAKSANA | E50: 1 | F50: 0 | G50: 0 | H50: 0 | I50: 2 | J50: 2 | K50: 1 | L50: 0 | M50: 0 | N50: 1 | O50: 0 | P50: 1 | Q50: 0 | R50: 0 | S50: =SUM(E50:R50) -> 8
C51: 6. Dr. SITI YUMNAH | E51: 0 | F51: 3 | G51: 0 | H51: 0 | I51: 0 | J51: 1 | K51: 2 | L51: 1 | M51: 0 | N51: 0 | O51: 0 | P51: 1 | Q51: 1 | R51: 0 | S51: =SUM(E51:R51) -> 9
...

Sheet CANTUK
C2: Kecamatan | D2: SINGOJURUH
C3: Kabupaten | D3: BANYUWANGI
C4: Provinsi | D4: JAWA TIMUR
C9: Kelurahan | D9: CANTUK
A12: I | B12: DATA PEMILIH DAN PENGGUNAAN HAK PILIH | T12: JUMLAH AKHIR
A13: A | B13: DATA PEMILIH | E13: TPS 001 | F13: TPS 002 | G13: TPS 003 | H13: TPS 004 | I13: TPS 005 | J13: TPS 006 | K13: TPS 007 | L13: TPS 008 | M13: TPS 009 | N13: TPS 010 | O13: TPS 011 | P13: TPS 012 | Q13: TPS 013 | R13: TPS 014 | S13: TPS 015
B14: Jumlah Pemilih dalam Daftar Pemilih Tetap (DPT) | D14: LK | E14: 135 | F14: 130 | G14: 131 | H14: 142 | I14: 130 | J14: 128 | K14: 127 | L14: 118 | M14: 126 | N14: 132 | O14: 97 | P14: 102 | Q14: 121 | R14: 118 | S14: 124 | T14: =SUM(E14:S14) -> 1861
D15: PR | E15: 136 | F15: 128 | G15: 126 | H15: 128 | I15: 129 | J15: 134 | K15: 121 | L15: 131 | M15: 129 | N15: 152 | O15: 107 | P15: 111 | Q15: 124 | R15: 125 | S15: 117 | T15: =SUM(E15:S15) -> 1898
D16: JML | E16: =SUM(E14:E15) -> 271 | F16: =SUM(F14:F15) -> 258 | G16: =SUM(G14:G15) -> 257 | H16: =SUM(H14:H15) -> 270 | I16: =SUM(I14:I15) -> 259 | J16: =SUM(J14:J15) -> 262 | K16: =SUM(K14:K15) -> 248 | L16: =SUM(L14:L15) -> 249 | ... S16: =SUM(S14:S15) -> 241 | T16: =SUM(E16:S16) -> 3759
A18: B | B18: PENGGUNA HAK PILIH
B19: 1. | C19: Jumlah pengguna hak pilih dalam Daftar Pemilih Tetap (DPT) | D19: LK | E19: 92 | F19: 99 | G19: 93 | H19: 104 | I19: 99 | J19: 101 | K19: 98 | L19: 92 | M19: 82 | N19: 87 | O19: 64 | P19: 71 | Q19: 91 | R19: 90 | S19: 104 | T19: =SUM(E19:S19) -> 1367
D20: PR | E20: 110 | F20: 102 | G20: 97 | H20: 104 | I20: 108 | J20: 111 | K20: 96 | L20: 108 | M20: 89 | N20: 109 | O20: 89 | P20: 84 | Q20: 108 | R20: 104 | S20: 98 | T20: =SUM(E20:S20) -> 1517
D21: JML | E21: =SUM(E19:E20) -> 202 | F21: =SUM(F19:F20) -> 201 | G21: =SUM(G19:G20) -> 190 | H21: =SUM(H19:H20) -> 208 | I21: =SUM(I19:I20) -> 207 | J21: =SUM(J19:J20) -> 212 | K21: =SUM(K19:K20) -> 194 | L21: =SUM(L19:L20) -> 200 | ... S21: =SUM(S19:S20) -> 202 | T21: =SUM(E21:S21) -> 2884
B22: 2. | C22: Jumlah pengguna hak pilih dalam Daftar Pemilih Tambahan (DPTb) | D22: LK | E22: 0 | F22: 0 | G22: 1 | H22: 0 | I22: 0 | J22: 0 | K22: 0 | L22: 0 | M22: 0 | N22: 0 | O22: 2 | P22: 0 | Q22: 1 | R22: 1 | S22: 2 | T22: =SUM(E22:S22) -> 7
D23: PR | E23: 1 | F23: 0 | G23: 0 | H23: 1 | I23: 0 | J23: 0 | K23: 0 | L23: 2 | M23: 1 | N23: 0 | O23: 0 | P23: 1 | Q23: 1 | R23: 1 | S23: 2 | T23: =SUM(E23:S23) -> 10
D24: JML | E24: =SUM(E22:E23) -> 1 | F24: =SUM(F22:F23) -> 0 | G24: =SUM(G22:G23) -> 1 | H24: =SUM(H22:H23) -> 1 | I24: =SUM(I22:I23) -> 0 | J24: =SUM(J22:J23) -> 0 | K24: =SUM(K22:K23) -> 0 | L24: =SUM(L22:L23) -> 2 | ... S24: =SUM(S22:S23) -> 4 | T24: =SUM(E24:S24) -> 17
B25: 3. | C25: Jumlah pengguna hak pilih dalam Daftar Pemilih Khusus (DPK) | D25: LK | E25: 1 | F25: 0 | G25: 0 | H25: 0 | I25: 1 | J25: 0 | K25: 0 | L25: 0 | M25: 1 | N25: 2 | O25: 2 | P25: 0 | Q25: 1 | R25: 1 | S25: 0 | T25: =SUM(E25:S25) -> 9
D26: PR | E26: 2 | F26: 0 | G26: 0 | H26: 0 | I26: 1 | J26: 0 | K26: 2 | L26: 1 | M26: 0 | N26: 1 | O26: 1 | P26: 1 | Q26: 0 | R26: 0 | S26: 0 | T26: =SUM(E26:S26) -> 9
D27: JML | E27: =SUM(E25:E26) -> 3 | F27: =SUM(F25:F26) -> 0 | G27: =SUM(G25:G26) -> 0 | H27: =SUM(H25:H26) -> 0 | I27: =SUM(I25:I26) -> 2 | J27: =SUM(J25:J26) -> 0 | K27: =SUM(K25:K26) -> 2 | L27: =SUM(L25:L26) -> 1 | ... S27: =SUM(S25:S26) -> 0 | T27: =SUM(E27:S27) -> 18
B28: 4. | C28: Jumlah Pengguna Hak Pilih (B.1+B.2+B.3) | D28: LK | E28: =SUM(E19,E22,E25) -> 93 | F28: =SUM(F19,F22,F25) -> 99 | G28: =SUM(G19,G22,G25) -> 94 | H28: =SUM(H19,H22,H25) -> 104 | I28: =SUM(I19,I22,I25) -> 100 | J28: =SUM(J19,J22,J25) -> 101 | K28: =SUM(K19,K22,K25) -> 98 | L28: =SUM(L19,L22,L25) -> 92 | ... S28: =SUM(S19,S22,S25) -> 106 | T28: =SUM(E28:S28) -> 1383
D29: PR | E29: =SUM(E20,E23,E26) -> 113 | F29: =SUM(F20,F23,F26) -> 102 | G29: =SUM(G20,G23,G26) -> 97 | H29: =SUM(H20,H23,H26) -> 105 | I29: =SUM(I20,I23,I26) -> 109 | J29: =SUM(J20,J23,J26) -> 111 | K29: =SUM(K20,K23,K26) -> 98 | L29: =SUM(L20,L23,L26) -> 111 | ... S29: =SUM(S20,S23,S26) -> 100 | T29: =SUM(E29:S29) -> 1536
D30: JML | E30: =SUM(E28:E29) -> 206 | F30: =SUM(F28:F29) -> 201 | G30: =SUM(G28:G29) -> 191 | H30: =SUM(H28:H29) -> 209 | I30: =SUM(I28:I29) -> 209 | J30: =SUM(J28:J29) -> 212 | K30: =SUM(K28:K29) -> 196 | L30: =SUM(L28:L29) -> 203 | ... S30: =SUM(S28:S29) -> 206 | T30: =SUM(E30:S30) -> 2919
A32: II | B32: DATA PENGGUNAAN SURAT SUARA
A33: 1 | B33: Jumlah surat suara yang diterima, termasuk surat suara cadangan 2,5% dari DPT | E33: 275 | F33: 261 | G33: 260 | H33: 273 | I33: 255 | J33: 265 | K33: 250 | L33: 251 | M33: 257 | N33: 287 | O33: 206 | P33: 216 | Q33: 247 | R33: 246 | S33: 243 | T33: =SUM(E33:S33) -> 3792
A34: 2 | B34: Jumlah surat suara yang digunakan | E34: 206 | F34: 201 | G34: 191 | H34: 209 | I34: 209 | J34: 212 | K34: 196 | L34: 203 | M34: 173 | N34: 199 | O34: 158 | P34: 157 | Q34: 202 | R34: 197 | S34: 206 | T34: =SUM(E34:S34) -> 2919
A35: 3 | B35: Jumlah surat suara dikembalikan oleh pemilih (karena rusak atau keliru coblos) | E35: 4 | F35: 0 | G35: 1 | H35: 0 | I35: 0 | J35: 1 | K35: 0 | L35: 0 | M35: 0 | N35: 1 | O35: 0 | P35: 1 | Q35: 0 | R35: 1 | S35: 0 | T35: =SUM(E35:S35) -> 9
A36: 4 | B36: Jumlah surat suara yang tidak digunakan/tidak terpakai, termasuk sisa surat suara cadangan | E36: =E33-(E34+E35) -> 65 | F36: =F33-(F34+F35) -> 60 | G36: =G33-(G34+G35) -> 68 | H36: =H33-(H34+H35) -> 64 | I36: =I33-(I34+I35) -> 46 | J36: =J33-(J34+J35) -> 52 | K36: =K33-(K34+K35) -> 54 | L36: =L33-(L34+L35) -> 48 | ... S36: =S33-(S34+S35) -> 37 | T36: =SUM(E36:S36) -> 864
A38: III | B38: DATA PEMILIH DISABILITAS
B39: Jumlah seluruh Pemilih disabilitas yang menggunakan hak pilih | D39: LK | P39: 1 | S39: 1 | T39: =SUM(E39:S39) -> 2
D40: PR | P40: 1 | Q40: 1 | T40: =SUM(E40:S40) -> 2
D41: JML | E41: =SUM(E39:E40) -> 0 | F41: =SUM(F39:F40) -> 0 | G41: =SUM(G39:G40) -> 0 | H41: =SUM(H39:H40) -> 0 | I41: =SUM(I39:I40) -> 0 | J41: =SUM(J39:J40) -> 0 | K41: =SUM(K39:K40) -> 0 | L41: =SUM(L39:L40) -> 0 | ... S41: =SUM(S39:S40) -> 1 | T41: =SUM(E41:S41) -> 4
A43: IV | B43: DATA RINCIAN PEROLEHAN SUARA PASANGAN CALON BUPATI DAN WAKIL BUPATI
A44: NOMOR DAN NAMA CALON
A45: A.1 | B45: 1. | C45: Partai Kebangkitan Bangsa | E45: 14 | F45: 4 | G45: 7 | H45: 3 | I45: 7 | J45: 7 | K45: 8 | L45: 11 | M45: 6 | N45: 4 | O45: 9 | P45: 15 | Q45: 3 | R45: 9 | S45: 7 | T45: =SUM(E45:S45) -> 114
A46: A.2 | C46: 1. Dra. Hj. MA`MULAH HARUN, M.Pd.I. | E46: 2 | F46: 4 | G46: 8 | H46: 5 | I46: 9 | J46: 17 | K46: 8 | L46: 8 | M46: 4 | N46: 9 | O46: 7 | P46: 17 | Q46: 14 | R46: 37 | S46: 16 | T46: =SUM(E46:S46) -> 165
C47: 2. UBAIDILLAH, S.Fil.I. | E47: 0 | F47: 1 | G47: 2 | H47: 1 | I47: 2 | J47: 4 | K47: 1 | L47: 1 | M47: 1 | N47: 1 | O47: 1 | P47: 1 | Q47: 4 | R47: 1 | S47: 3 | T47: =SUM(E47:S47) -> 24
C48: 3. Ir. H. YOYOK MULYADI, M.Si. | E48: 5 | F48: 0 | G48: 0 | H48: 1 | I48: 2 | J48: 1 | K48: 2 | L48: 1 | M48: 0 | N48: 0 | O48: 1 | P48: 2 | Q48: 1 | R48: 0 | S48: 1 | T48: =SUM(E48:S48) -> 17
C49: 4. KHOIRUL ANWAR, S.Fil.I. | E49: 0 | F49: 4 | G49: 0 | H49: 1 | I49: 0 | J49: 2 | K49: 1 | L49: 0 | M49: 0 | N49: 1 | O49: 4 | P49: 1 | Q49: 5 | R49: 7 | S49: 4 | T49: =SUM(E49:S49) -> 30
C50: 5. ARIF WIJAKSANA | E50: 1 | F50: 1 | G50: 0 | H50: 0 | I50: 0 | J50: 0 | K50: 0 | L50: 0 | M50: 0 | N50: 1 | O50: 1 | P50: 0 | Q50: 0 | R50: 0 | S50: 0 | T50: =SUM(E50:S50) -> 4
C51: 6. Dr. SITI YUMNAH | E51: 0 | F51: 0 | G51: 0 | H51: 0 | I51: 0 | J51: 1 | K51: 0 | L51: 0 | M51: 0 | N51: 0 | O51: 0 | P51: 0 | Q51: 0 | R51: 1 | S51: 1 | T51: =SUM(E51:S51) -> 3
...

Sheet GAMBOR
C2: Kecamatan | D2: SINGOJURUH
C3: Kabupaten | D3: BANYUWANGI
C4: Provinsi | D4: JAWA TIMUR
C9: Kelurahan | D9: GAMBOR
A12: I | B12: DATA PEMILIH DAN PENGGUNAAN HAK PILIH | N12: JUMLAH AKHIR
A13: A | B13: DATA PEMILIH | E13: TPS 001 | F13: TPS 002 | G13: TPS 003 | H13: TPS 004 | I13: TPS 005 | J13: TPS 006 | K13: TPS 007 | L13: TPS 008 | M13: TPS 009
B14: Jumlah Pemilih dalam Daftar Pemilih Tetap (DPT) | D14: LK | E14: 125 | F14: 146 | G14: 125 | H14: 119 | I14: 115 | J14: 132 | K14: 150 | L14: 127 | M14: 112 | N14: =SUM(E14:M14) -> 1151
D15: PR | E15: 125 | F15: 131 | G15: 134 | H15: 117 | I15: 120 | J15: 120 | K15: 132 | L15: 128 | M15: 122 | N15: =SUM(E15:M15) -> 1129
D16: JML | E16: =SUM(E14:E15) -> 250 | F16: =SUM(F14:F15) -> 277 | G16: =SUM(G14:G15) -> 259 | H16: =SUM(H14:H15) -> 236 | I16: =SUM(I14:I15) -> 235 | J16: =SUM(J14:J15) -> 252 | K16: =SUM(K14:K15) -> 282 | L16: =SUM(L14:L15) -> 255 | M16: =SUM(M14:M15) -> 234 | N16: =SUM(E16:M16) -> 2280
A18: B | B18: PENGGUNA HAK PILIH
B19: 1. | C19: Jumlah pengguna hak pilih dalam Daftar Pemilih Tetap (DPT) | D19: LK | E19: 91 | F19: 124 | G19: 88 | H19: 88 | I19: 94 | J19: 106 | K19: 115 | L19: 83 | M19: 96 | N19: =SUM(E19:M19) -> 885
D20: PR | E20: 97 | F20: 115 | G20: 95 | H20: 91 | I20: 102 | J20: 92 | K20: 105 | L20: 101 | M20: 100 | N20: =SUM(E20:M20) -> 898
D21: JML | E21: =SUM(E19:E20) -> 188 | F21: =SUM(F19:F20) -> 239 | G21: =SUM(G19:G20) -> 183 | H21: =SUM(H19:H20) -> 179 | I21: =SUM(I19:I20) -> 196 | J21: =SUM(J19:J20) -> 198 | K21: =SUM(K19:K20) -> 220 | L21: =SUM(L19:L20) -> 184 | M21: =SUM(M19:M20) -> 196 | N21: =SUM(E21:M21) -> 1783
B22: 2. | C22: Jumlah pengguna hak pilih dalam Daftar Pemilih Tambahan (DPTb) | D22: LK | E22: 0 | F22: 0 | G22: 0 | H22: 0 | I22: 0 | J22: 0 | K22: 1 | L22: 0 | M22: 0 | N22: =SUM(E22:M22) -> 1
D23: PR | N23: =SUM(E23:M23) -> 0
D24: JML | E24: =SUM(E22:E23) -> 0 | F24: =SUM(F22:F23) -> 0 | G24: =SUM(G22:G23) -> 0 | H24: =SUM(H22:H23) -> 0 | I24: =SUM(I22:I23) -> 0 | J24: =SUM(J22:J23) -> 0 | K24: =SUM(K22:K23) -> 1 | L24: =SUM(L22:L23) -> 0 | M24: =SUM(M22:M23) -> 0 | N24: =SUM(E24:M24) -> 1
B25: 3. | C25: Jumlah pengguna hak pilih dalam Daftar Pemilih Khusus (DPK) | D25: LK | E25: 0 | F25: 0 | G25: 4 | H25: 1 | I25: 1 | J25: 0 | K25: 1 | L25: 1 | M25: 1 | N25: =SUM(E25:M25) -> 9
D26: PR | E26: 3 | F26: 1 | G26: 1 | H26: 3 | I26: 2 | J26: 0 | K26: 1 | L26: 3 | M26: 1 | N26: =SUM(E26:M26) -> 15
D27: JML | E27: =SUM(E25:E26) -> 3 | F27: =SUM(F25:F26) -> 1 | G27: =SUM(G25:G26) -> 5 | H27: =SUM(H25:H26) -> 4 | I27: =SUM(I25:I26) -> 3 | J27: =SUM(J25:J26) -> 0 | K27: =SUM(K25:K26) -> 2 | L27: =SUM(L25:L26) -> 4 | M27: =SUM(M25:M26) -> 2 | N27: =SUM(E27:M27) -> 24
B28: 4. | C28: Jumlah Pengguna Hak Pilih (B.1+B.2+B.3) | D28: LK | E28: =SUM(E19,E22,E25) -> 91 | F28: =SUM(F19,F22,F25) -> 124 | G28: =SUM(G19,G22,G25) -> 92 | H28: =SUM(H19,H22,H25) -> 89 | I28: =SUM(I19,I22,I25) -> 95 | J28: =SUM(J19,J22,J25) -> 106 | K28: =SUM(K19,K22,K25) -> 117 | L28: =SUM(L19,L22,L25) -> 84 | M28: =SUM(M19,M22,M25) -> 97 | N28: =SUM(E28:M28) -> 895
D29: PR | E29: =SUM(E20,E23,E26) -> 100 | F29: =SUM(F20,F23,F26) -> 116 | G29: =SUM(G20,G23,G26) -> 96 | H29: =SUM(H20,H23,H26) -> 94 | I29: =SUM(I20,I23,I26) -> 104 | J29: =SUM(J20,J23,J26) -> 92 | K29: =SUM(K20,K23,K26) -> 106 | L29: =SUM(L20,L23,L26) -> 104 | M29: =SUM(M20,M23,M26) -> 101 | N29: =SUM(E29:M29) -> 913
D30: JML | E30: =SUM(E28:E29) -> 191 | F30: =SUM(F28:F29) -> 240 | G30: =SUM(G28:G29) -> 188 | H30: =SUM(H28:H29) -> 183 | I30: =SUM(I28:I29) -> 199 | J30: =SUM(J28:J29) -> 198 | K30: =SUM(K28:K29) -> 223 | L30: =SUM(L28:L29) -> 188 | M30: =SUM(M28:M29) -> 198 | N30: =SUM(E30:M30) -> 1808
A32: II | B32: DATA PENGGUNAAN SURAT SUARA
A33: 1 | B33: Jumlah surat suara yang diterima, termasuk surat suara cadangan 2,5% dari DPT | E33: 255 | F33: 250 | G33: 265 | H33: 189 | I33: 239 | J33: 256 | K33: 285 | L33: 260 | M33: 239 | N33: =SUM(E33:M33) -> 2238
A34: 2 | B34: Jumlah surat suara yang digunakan | E34: 191 | F34: 240 | G34: 188 | H34: 183 | I34: 199 | J34: 198 | K34: 223 | L34: 188 | M34: 198 | N34: =SUM(E34:M34) -> 1808
A35: 3 | B35: Jumlah surat suara dikembalikan oleh pemilih (karena rusak atau keliru coblos) | E35: 0 | F35: 1 | G35: 0 | H35: 0 | I35: 0 | J35: 0 | K35: 0 | L35: 1 | M35: 0 | N35: =SUM(E35:M35) -> 2
A36: 4 | B36: Jumlah surat suara yang tidak digunakan/tidak terpakai, termasuk sisa surat suara cadangan | E36: =E33-(E34+E35) -> 64 | F36: =F33-(F34+F35) -> 9 | G36: =G33-(G34+G35) -> 77 | H36: =H33-(H34+H35) -> 6 | I36: =I33-(I34+I35) -> 40 | J36: =J33-(J34+J35) -> 58 | K36: =K33-(K34+K35) -> 62 | L36: =L33-(L34+L35) -> 71 | M36: =M33-(M34+M35) -> 41 | N36: =SUM(E36:M36) -> 428
A38: III | B38: DATA PEMILIH DISABILITAS
B39: Jumlah seluruh Pemilih disabilitas yang menggunakan hak pilih | D39: LK | N39: =SUM(E39:M39) -> 0
D40: PR | G40: 1 | H40: 1 | J40: 1 | N40: =SUM(E40:M40) -> 3
D41: JML | E41: =SUM(E39:E40) -> 0 | F41: =SUM(F39:F40) -> 0 | G41: =SUM(G39:G40) -> 1 | H41: =SUM(H39:H40) -> 1 | I41: =SUM(I39:I40) -> 0 | J41: =SUM(J39:J40) -> 1 | K41: =SUM(K39:K40) -> 0 | L41: =SUM(L39:L40) -> 0 | M41: =SUM(M39:M40) -> 0 | N41: =SUM(E41:M41) -> 3
A43: IV | B43: DATA RINCIAN PEROLEHAN SUARA PASANGAN CALON BUPATI DAN WAKIL BUPATI
A44: NOMOR DAN NAMA CALON
A45: A.1 | B45: 1. | C45: Partai Kebangkitan Bangsa | E45: 13 | F45: 8 | G45: 5 | H45: 18 | I45: 11 | J45: 8 | K45: 10 | L45: 9 | M45: 16 | N45: =SUM(E45:M45) -> 98
A46: A.2 | C46: 1. Dra. Hj. MA`MULAH HARUN, M.Pd.I. | E46: 19 | F46: 26 | G46: 22 | H46: 10 | I46: 27 | J46: 37 | K46: 17 | L46: 13 | M46: 55 | N46: =SUM(E46:M46) -> 226
C47: 2. UBAIDILLAH, S.Fil.I. | E47: 3 | F47: 12 | G47: 2 | H47: 4 | I47: 3 | J47: 2 | K47: 3 | L47: 2 | M47: 9 | N47: =SUM(E47:M47) -> 40
C48: 3. Ir. H. YOYOK MULYADI, M.Si. | E48: 1 | F48: 2 | G48: 1 | H48: 0 | I48: 0 | J48: 2 | K48: 1 | L48: 2 | M48: 2 | N48: =SUM(E48:M48) -> 11
C49: 4. KHOIRUL ANWAR, S.Fil.I. | E49: 2 | F49: 3 | G49: 0 | H49: 1 | I49: 1 | J49: 0 | K49: 2 | L49: 1 | M49: 1 | N49: =SUM(E49:M49) -> 11
C50: 5. ARIF WIJAKSANA | E50: 1 | F50: 3 | G50: 0 | H50: 0 | I50: 1 | J50: 1 | K50: 0 | L50: 0 | M50: 1 | N50: =SUM(E50:M50) -> 7
C51: 6. Dr. SITI YUMNAH | E51: 0 | F51: 0 | G51: 0 | H51: 0 | I51: 0 | J51: 0 | K51: 1 | L51: 0 | M51: 0 | N51: =SUM(E51:M51) -> 1
...

Sheet GUMIRIH
C2: Kecamatan | D2: SINGOJURUH
C3: Kabupaten | D3: BANYUWANGI
C4: Provinsi | D4: JAWA TIMUR
C9: Kelurahan | D9: GUMIRIH
A12: I | B12: DATA PEMILIH DAN PENGGUNAAN HAK PILIH | S12: JUMLAH AKHIR
A13: A | B13: DATA PEMILIH | E13: TPS 001 | F13: TPS 002 | G13: TPS 003 | H13: TPS 004 | I13: TPS 005 | J13: TPS 006 | K13: TPS 007 | L13: TPS 008 | M13: TPS 009 | N13: TPS 010 | O13: TPS 011 | P13: TPS 012 | Q13: TPS 013 | R13: TPS 014
B14: Jumlah Pemilih dalam Daftar Pemilih Tetap (DPT) | D14: LK | E14: 118 | F14: 97 | G14: 102 | H14: 133 | I14: 136 | J14: 127 | K14: 134 | L14: 118 | M14: 141 | N14: 140 | O14: 132 | P14: 134 | Q14: 143 | R14: 94 | S14: =SUM(E14:R14) -> 1749
D15: PR | E15: 116 | F15: 103 | G15: 110 | H15: 126 | I15: 128 | J15: 130 | K15: 141 | L15: 131 | M15: 133 | N15: 124 | O15: 144 | P15: 143 | Q15: 129 | R15: 86 | S15: =SUM(E15:R15) -> 1744
D16: JML | E16: =SUM(E14:E15) -> 234 | F16: =SUM(F14:F15) -> 200 | G16: =SUM(G14:G15) -> 212 | H16: =SUM(H14:H15) -> 259 | I16: =SUM(I14:I15) -> 264 | J16: =SUM(J14:J15) -> 257 | K16: =SUM(K14:K15) -> 275 | L16: =SUM(L14:L15) -> 249 | ... R16: =SUM(R14:R15) -> 180 | S16: =SUM(E16:R16) -> 3493
A18: B | B18: PENGGUNA HAK PILIH
B19: 1. | C19: Jumlah pengguna hak pilih dalam Daftar Pemilih Tetap (DPT) | D19: LK | E19: 85 | F19: 60 | G19: 73 | H19: 92 | I19: 96 | J19: 94 | K19: 100 | L19: 77 | M19: 96 | N19: 106 | O19: 109 | P19: 96 | Q19: 95 | R19: 74 | S19: =SUM(E19:R19) -> 1253
D20: PR | E20: 88 | F20: 72 | G20: 85 | H20: 100 | I20: 108 | J20: 89 | K20: 113 | L20: 96 | M20: 101 | N20: 111 | O20: 99 | P20: 102 | Q20: 103 | R20: 65 | S20: =SUM(E20:R20) -> 1332
D21: JML | E21: =SUM(E19:E20) -> 173 | F21: =SUM(F19:F20) -> 132 | G21: =SUM(G19:G20) -> 158 | H21: =SUM(H19:H20) -> 192 | I21: =SUM(I19:I20) -> 204 | J21: =SUM(J19:J20) -> 183 | K21: =SUM(K19:K20) -> 213 | L21: =SUM(L19:L20) -> 173 | ... R21: =SUM(R19:R20) -> 139 | S21: =SUM(E21:R21) -> 2585
B22: 2. | C22: Jumlah pengguna hak pilih dalam Daftar Pemilih Tambahan (DPTb) | D22: LK | E22: 1 | F22: 0 | G22: 1 | H22: 0 | I22: 0 | J22: 0 | K22: 2 | L22: 1 | M22: 0 | N22: 0 | O22: 0 | P22: 0 | Q22: 0 | R22: 0 | S22: =SUM(E22:R22) -> 5
D23: PR | E23: 1 | F23: 0 | G23: 0 | H23: 0 | I23: 0 | J23: 0 | K23: 0 | L23: 1 | M23: 1 | N23: 0 | O23: 1 | P23: 1 | Q23: 1 | R23: 0 | S23: =SUM(E23:R23) -> 6
D24: JML | E24: =SUM(E22:E23) -> 2 | F24: =SUM(F22:F23) -> 0 | G24: =SUM(G22:G23) -> 1 | H24: =SUM(H22:H23) -> 0 | I24: =SUM(I22:I23) -> 0 | J24: =SUM(J22:J23) -> 0 | K24: =SUM(K22:K23) -> 2 | L24: =SUM(L22:L23) -> 2 | ... R24: =SUM(R22:R23) -> 0 | S24: =SUM(E24:R24) -> 11
B25: 3. | C25: Jumlah pengguna hak pilih dalam Daftar Pemilih Khusus (DPK) | D25: LK | F25: 0 | G25: 0 | H25: 0 | I25: 0 | J25: 0 | K25: 0 | L25: 3 | M25: 0 | N25: 0 | O25: 3 | P25: 0 | Q25: 0 | R25: 0 | S25: =SUM(E25:R25) -> 6
D26: PR | F26: 0 | G26: 0 | H26: 1 | I26: 0 | J26: 0 | K26: 1 | L26: 1 | M26: 3 | N26: 0 | O26: 3 | P26: 3 | Q26: 0 | R26: 0 | S26: =SUM(E26:R26) -> 12
D27: JML | E27: =SUM(E25:E26) -> 0 | F27: =SUM(F25:F26) -> 0 | G27: =SUM(G25:G26) -> 0 | H27: =SUM(H25:H26) -> 1 | I27: =SUM(I25:I26) -> 0 | J27: =SUM(J25:J26) -> 0 | K27: =SUM(K25:K26) -> 1 | L27: =SUM(L25:L26) -> 4 | ... R27: =SUM(R25:R26) -> 0 | S27: =SUM(E27:R27) -> 18
B28: 4. | C28: Jumlah Pengguna Hak Pilih (B.1+B.2+B.3) | D28: LK | E28: =SUM(E19,E22,E25) -> 86 | F28: =SUM(F19,F22,F25) -> 60 | G28: =SUM(G19,G22,G25) -> 74 | H28: =SUM(H19,H22,H25) -> 92 | I28: =SUM(I19,I22,I25) -> 96 | J28: =SUM(J19,J22,J25) -> 94 | K28: =SUM(K19,K22,K25) -> 102 | L28: =SUM(L19,L22,L25) -> 81 | ... R28: =SUM(R19,R22,R25) -> 74 | S28: =SUM(E28:R28) -> 1264
D29: PR | E29: =SUM(E20,E23,E26) -> 89 | F29: =SUM(F20,F23,F26) -> 72 | G29: =SUM(G20,G23,G26) -> 85 | H29: =SUM(H20,H23,H26) -> 101 | I29: =SUM(I20,I23,I26) -> 108 | J29: =SUM(J20,J23,J26) -> 89 | K29: =SUM(K20,K23,K26) -> 114 | L29: =SUM(L20,L23,L26) -> 98 | ... R29: =SUM(R20,R23,R26) -> 65 | S29: =SUM(E29:R29) -> 1350
D30: JML | E30: =SUM(E28:E29) -> 175 | F30: =SUM(F28:F29) -> 132 | G30: =SUM(G28:G29) -> 159 | H30: =SUM(H28:H29) -> 193 | I30: =SUM(I28:I29) -> 204 | J30: =SUM(J28:J29) -> 183 | K30: =SUM(K28:K29) -> 216 | L30: =SUM(L28:L29) -> 179 | ... R30: =SUM(R28:R29) -> 139 | S30: =SUM(E30:R30) -> 2614
A32: II | B32: DATA PENGGUNAAN SURAT SUARA
A33: 1 | B33: Jumlah surat suara yang diterima, termasuk surat suara cadangan 2,5% dari DPT | E33: 239 | F33: 204 | G33: 216 | H33: 264 | I33: 269 | J33: 262 | K33: 281 | L33: 254 | M33: 279 | N33: 269 | O33: 282 | P33: 280 | Q33: 278 | R33: 169 | S33: =SUM(E33:R33) -> 3546
A34: 2 | B34: Jumlah surat suara yang digunakan | E34: 175 | F34: 132 | G34: 159 | H34: 193 | I34: 204 | J34: 183 | K34: 216 | L34: 179 | M34: 201 | N34: 217 | O34: 215 | P34: 202 | Q34: 199 | R34: 139 | S34: =SUM(E34:R34) -> 2614
A35: 3 | B35: Jumlah surat suara dikembalikan oleh pemilih (karena rusak atau keliru coblos) | E35: 0 | F35: 0 | G35: 2 | H35: 0 | I35: 0 | J35: 0 | K35: 0 | L35: 0 | M35: 0 | N35: 0 | O35: 0 | P35: 0 | Q35: 0 | R35: 0 | S35: =SUM(E35:R35) -> 2
A36: 4 | B36: Jumlah surat suara yang tidak digunakan/tidak terpakai, termasuk sisa surat suara cadangan | E36: =E33-(E34+E35) -> 64 | F36: =F33-(F34+F35) -> 72 | G36: =G33-(G34+G35) -> 55 | H36: =H33-(H34+H35) -> 71 | I36: =I33-(I34+I35) -> 65 | J36: =J33-(J34+J35) -> 79 | K36: =K33-(K34+K35) -> 65 | L36: =L33-(L34+L35) -> 75 | ... R36: =R33-(R34+R35) -> 30 | S36: =SUM(E36:R36) -> 930
A38: III | B38: DATA PEMILIH DISABILITAS
B39: Jumlah seluruh Pemilih disabilitas yang menggunakan hak pilih | D39: LK | P39: 1 | S39: =SUM(E39:R39) -> 1
D40: PR | S40: =SUM(E40:R40) -> 0
D41: JML | E41: =SUM(E39:E40) -> 0 | F41: =SUM(F39:F40) -> 0 | G41: =SUM(G39:G40) -> 0 | H41: =SUM(H39:H40) -> 0 | I41: =SUM(I39:I40) -> 0 | J41: =SUM(J39:J40) -> 0 | K41: =SUM(K39:K40) -> 0 | L41: =SUM(L39:L40) -> 0 | ... R41: =SUM(R39:R40) -> 0 | S41: =SUM(E41:R41) -> 1
A43: IV | B43: DATA RINCIAN PEROLEHAN SUARA PASANGAN CALON BUPATI DAN WAKIL BUPATI
A44: NOMOR DAN NAMA CALON
A45: A.1 | B45: 1. | C45: Partai Kebangkitan Bangsa | E45: 12 | F45: 8 | G45: 7 | H45: 15 | I45: 1 | J45: 3 | K45: 9 | L45: 6 | M45: 2 | N45: 10 | O45: 6 | P45: 4 | Q45: 3 | R45: 17 | S45: =SUM(E45:R45) -> 103
A46: A.2 | C46: 1. Dra. Hj. MA`MULAH HARUN, M.Pd.I. | E46: 20 | F46: 8 | G46: 16 | H46: 16 | I46: 18 | J46: 3 | K46: 39 | L46: 17 | M46: 5 | N46: 7 | O46: 10 | P46: 8 | Q46: 6 | R46: 35 | S46: =SUM(E46:R46) -> 208
C47: 2. UBAIDILLAH, S.Fil.I. | E47: 3 | F47: 0 | G47: 1 | H47: 1 | I47: 2 | J47: 0 | K47: 2 | L47: 2 | M47: 1 | N47: 7 | O47: 1 | P47: 3 | Q47: 2 | R47: 2 | S47: =SUM(E47:R47) -> 27
C48: 3. Ir. H. YOYOK MULYADI, M.Si. | E48: 0 | F48: 0 | G48: 2 | H48: 1 | I48: 0 | J48: 1 | K48: 1 | L48: 1 | M48: 0 | N48: 0 | O48: 0 | P48: 1 | Q48: 0 | R48: 0 | S48: =SUM(E48:R48) -> 7
C49: 4. KHOIRUL ANWAR, S.Fil.I. | E49: 2 | F49: 0 | G49: 0 | H49: 0 | I49: 2 | J49: 0 | K49: 1 | L49: 2 | M49: 1 | N49: 2 | O49: 0 | P49: 1 | Q49: 0 | R49: 0 | S49: =SUM(E49:R49) -> 11
C50: 5. ARIF WIJAKSANA | E50: 0 | F50: 0 | G50: 1 | H50: 0 | I50: 1 | J50: 1 | K50: 0 | L50: 0 | M50: 0 | N50: 0 | O50: 0 | P50: 0 | Q50: 0 | R50: 1 | S50: =SUM(E50:R50) -> 4
C51: 6. Dr. SITI YUMNAH | E51: 0 | F51: 0 | G51: 0 | H51: 0 | I51: 0 | J51: 0 | K51: 1 | L51: 0 | M51: 0 | N51: 0 | O51: 0 | P51: 1 | Q51: 0 | R51: 0 | S51: =SUM(E51:R51) -> 2
...

Sheet KEMIRI
C2: Kecamatan | D2: SINGOJURUH
C3: Kabupaten | D3: BANYUWANGI
C4: Provinsi | D4: JAWA TIMUR
C9: Kelurahan | D9: KEMIRI
A12: I | B12: DATA PEMILIH DAN PENGGUNAAN HAK PILIH | U12: JUMLAH AKHIR
A13: A | B13: DATA PEMILIH | E13: TPS 001 | F13: TPS 002 | G13: TPS 003 | H13: TPS 004 | I13: TPS 005 | J13: TPS 006 | K13: TPS 007 | L13: TPS 008 | M13: TPS 009 | N13: TPS 010 | O13: TPS 011 | P13: TPS 012 | Q13: TPS 013 | R13: TPS 014 | S13: TPS 015 | T13: TPS 016
B14: Jumlah Pemilih dalam Daftar Pemilih Tetap (DPT) | D14: LK | U14: =SUM(E14:T14) -> 0
D15: PR | U15: =SUM(E15:T15) -> 0
D16: JML | E16: =SUM(E14:E15) -> 0 | F16: =SUM(F14:F15) -> 0 | G16: =SUM(G14:G15) -> 0 | H16: =SUM(H14:H15) -> 0 | I16: =SUM(I14:I15) -> 0 | J16: =SUM(J14:J15) -> 0 | K16: =SUM(K14:K15) -> 0 | L16: =SUM(L14:L15) -> 0 | ... T16: =SUM(T14:T15) -> 0 | U16: =SUM(E16:T16) -> 0
A18: B | B18: PENGGUNA HAK PILIH
B19: 1. | C19: Jumlah pengguna hak pilih dalam Daftar Pemilih Tetap (DPT) | D19: LK | U19: =SUM(E19:T19) -> 0
D20: PR | U20: =SUM(E20:T20) -> 0
D21: JML | E21: =SUM(E19:E20) -> 0 | F21: =SUM(F19:F20) -> 0 | G21: =SUM(G19:G20) -> 0 | H21: =SUM(H19:H20) -> 0 | I21: =SUM(I19:I20) -> 0 | J21: =SUM(J19:J20) -> 0 | K21: =SUM(K19:K20) -> 0 | L21: =SUM(L19:L20) -> 0 | ... T21: =SUM(T19:T20) -> 0 | U21: =SUM(E21:T21) -> 0
B22: 2. | C22: Jumlah pengguna hak pilih dalam Daftar Pemilih Tambahan (DPTb) | D22: LK | U22: =SUM(E22:T22) -> 0
D23: PR | U23: =SUM(E23:T23) -> 0
D24: JML | E24: =SUM(E22:E23) -> 0 | F24: =SUM(F22:F23) -> 0 | G24: =SUM(G22:G23) -> 0 | H24: =SUM(H22:H23) -> 0 | I24: =SUM(I22:I23) -> 0 | J24: =SUM(J22:J23) -> 0 | K24: =SUM(K22:K23) -> 0 | L24: =SUM(L22:L23) -> 0 | ... T24: =SUM(T22:T23) -> 0 | U24: =SUM(E24:T24) -> 0
B25: 3. | C25: Jumlah pengguna hak pilih dalam Daftar Pemilih Khusus (DPK) | D25: LK | U25: =SUM(E25:T25) -> 0
D26: PR | U26: =SUM(E26:T26) -> 0
D27: JML | E27: =SUM(E25:E26) -> 0 | F27: =SUM(F25:F26) -> 0 | G27: =SUM(G25:G26) -> 0 | H27: =SUM(H25:H26) -> 0 | I27: =SUM(I25:I26) -> 0 | J27: =SUM(J25:J26) -> 0 | K27: =SUM(K25:K26) -> 0 | L27: =SUM(L25:L26) -> 0 | ... T27: =SUM(T25:T26) -> 0 | U27: =SUM(E27:T27) -> 0
B28: 4. | C28: Jumlah Pengguna Hak Pilih (B.1+B.2+B.3) | D28: LK | E28: =SUM(E19,E22,E25) -> 0 | F28: =SUM(F19,F22,F25) -> 0 | G28: =SUM(G19,G22,G25) -> 0 | H28: =SUM(H19,H22,H25) -> 0 | I28: =SUM(I19,I22,I25) -> 0 | J28: =SUM(J19,J22,J25) -> 0 | K28: =SUM(K19,K22,K25) -> 0 | L28: =SUM(L19,L22,L25) -> 0 | ... T28: =SUM(T19,T22,T25) -> 0 | U28: =SUM(E28:T28) -> 0
D29: PR | E29: =SUM(E20,E23,E26) -> 0 | F29: =SUM(F20,F23,F26) -> 0 | G29: =SUM(G20,G23,G26) -> 0 | H29: =SUM(H20,H23,H26) -> 0 | I29: =SUM(I20,I23,I26) -> 0 | J29: =SUM(J20,J23,J26) -> 0 | K29: =SUM(K20,K23,K26) -> 0 | L29: =SUM(L20,L23,L26) -> 0 | ... T29: =SUM(T20,T23,T26) -> 0 | U29: =SUM(E29:T29) -> 0
D30: JML | E30: =SUM(E28:E29) -> 0 | F30: =SUM(F28:F29) -> 0 | G30: =SUM(G28:G29) -> 0 | H30: =SUM(H28:H29) -> 0 | I30: =SUM(I28:I29) -> 0 | J30: =SUM(J28:J29) -> 0 | K30: =SUM(K28:K29) -> 0 | L30: =SUM(L28:L29) -> 0 | ... T30: =SUM(T28:T29) -> 0 | U30: =SUM(E30:T30) -> 0
A32: II | B32: DATA PENGGUNAAN SURAT SUARA
A33: 1 | B33: Jumlah surat suara yang diterima, termasuk surat suara cadangan 2,5% dari DPT | U33: =SUM(E33:T33) -> 0
A34: 2 | B34: Jumlah surat suara yang digunakan | U34: =SUM(E34:T34) -> 0
A35: 3 | B35: Jumlah surat suara dikembalikan oleh pemilih (karena rusak atau keliru coblos) | U35: =SUM(E35:T35) -> 0
A36: 4 | B36: Jumlah surat suara yang tidak digunakan/tidak terpakai, termasuk sisa surat suara cadangan | E36: =E33-(E34+E35) -> 0 | F36: =F33-(F34+F35) -> 0 | G36: =G33-(G34+G35) -> 0 | H36: =H33-(H34+H35) -> 0 | I36: =I33-(I34+I35) -> 0 | J36: =J33-(J34+J35) -> 0 | K36: =K33-(K34+K35) -> 0 | L36: =L33-(L34+L35) -> 0 | ... T36: =T33-(T34+T35) -> 0 | U36: =SUM(E36:T36) -> 0
A38: III | B38: DATA PEMILIH DISABILITAS
B39: Jumlah seluruh Pemilih disabilitas yang menggunakan hak pilih | D39: LK | U39: =SUM(E39:T39) -> 0
D40: PR | U40: =SUM(E40:T40) -> 0
D41: JML | E41: =SUM(E39:E40) -> 0 | F41: =SUM(F39:F40) -> 0 | G41: =SUM(G39:G40) -> 0 | H41: =SUM(H39:H40) -> 0 | I41: =SUM(I39:I40) -> 0 | J41: =SUM(J39:J40) -> 0 | K41: =SUM(K39:K40) -> 0 | L41: =SUM(L39:L40) -> 0 | ... T41: =SUM(T39:T40) -> 0 | U41: =SUM(E41:T41) -> 0
A43: IV | B43: DATA RINCIAN PEROLEHAN SUARA PASANGAN CALON BUPATI DAN WAKIL BUPATI
A44: NOMOR DAN NAMA CALON
A45: A.1 | B45: 1. | C45: Partai Kebangkitan Bangsa | U45: =SUM(E45:T45) -> 0
A46: A.2 | C46: 1. Dra. Hj. MA`MULAH HARUN, M.Pd.I. | U46: =SUM(E46:T46) -> 0
C47: 2. UBAIDILLAH, S.Fil.I. | U47: =SUM(E47:T47) -> 0
C48: 3. Ir. H. YOYOK MULYADI, M.Si. | U48: =SUM(E48:T48) -> 0
C49: 4. KHOIRUL ANWAR, S.Fil.I. | U49: =SUM(E49:T49) -> 0
C50: 5. ARIF WIJAKSANA | U50: =SUM(E50:T50) -> 0
C51: 6. Dr. SITI YUMNAH | U51: =SUM(E51:T51) -> 0
...

Sheet LEMAHBANGKULON
C2: Kecamatan | D2: SINGOJURUH
C3: Kabupaten | D3: BANYUWANGI
C4: Provinsi | D4: JAWA TIMUR
C9: Kelurahan | D9: LEMAHBANGKULON
A12: I | B12: DATA PEMILIH DAN PENGGUNAAN HAK PILIH | Q12: JUMLAH AKHIR
A13: A | B13: DATA PEMILIH | E13: TPS 001 | F13: TPS 002 | G13: TPS 003 | H13: TPS 004 | I13: TPS 005 | J13: TPS 006 | K13: TPS 007 | L13: TPS 008 | M13: TPS 009 | N13: TPS 010 | O13: TPS 011 | P13: TPS 012
B14: Jumlah Pemilih dalam Daftar Pemilih Tetap (DPT) | D14: LK | E14: 124 | F14: 96 | G14: 127 | H14: 126 | I14: 121 | J14: 117 | K14: 127 | L14: 141 | M14: 108 | N14: 125 | O14: 84 | P14: 68 | Q14: =SUM(E14:P14) -> 1364
D15: PR | E15: 125 | F15: 98 | G15: 137 | H15: 122 | I15: 141 | J15: 139 | K15: 142 | L15: 138 | M15: 119 | N15: 141 | O15: 99 | P15: 83 | Q15: =SUM(E15:P15) -> 1484
D16: JML | E16: =SUM(E14:E15) -> 249 | F16: =SUM(F14:F15) -> 194 | G16: =SUM(G14:G15) -> 264 | H16: =SUM(H14:H15) -> 248 | I16: =SUM(I14:I15) -> 262 | J16: =SUM(J14:J15) -> 256 | K16: =SUM(K14:K15) -> 269 | L16: =SUM(L14:L15) -> 279 | ... P16: =SUM(P14:P15) -> 151 | Q16: =SUM(E16:P16) -> 2848
A18: B | B18: PENGGUNA HAK PILIH
B19: 1. | C19: Jumlah pengguna hak pilih dalam Daftar Pemilih Tetap (DPT) | D19: LK | E19: 85 | F19: 79 | G19: 88 | H19: 86 | I19: 93 | J19: 76 | K19: 105 | L19: 108 | M19: 75 | N19: 94 | O19: 62 | P19: 54 | Q19: =SUM(E19:P19) -> 1005
D20: PR | E20: 101 | F20: 79 | G20: 101 | H20: 94 | I20: 110 | J20: 111 | K20: 124 | L20: 105 | M20: 98 | N20: 106 | O20: 80 | P20: 62 | Q20: =SUM(E20:P20) -> 1171
D21: JML | E21: =SUM(E19:E20) -> 186 | F21: =SUM(F19:F20) -> 158 | G21: =SUM(G19:G20) -> 189 | H21: =SUM(H19:H20) -> 180 | I21: =SUM(I19:I20) -> 203 | J21: =SUM(J19:J20) -> 187 | K21: =SUM(K19:K20) -> 229 | L21: =SUM(L19:L20) -> 213 | ... P21: =SUM(P19:P20) -> 116 | Q21: =SUM(E21:P21) -> 2176
B22: 2. | C22: Jumlah pengguna hak pilih dalam Daftar Pemilih Tambahan (DPTb) | D22: LK | E22: 0 | F22: 0 | G22: 0 | H22: 0 | I22: 0 | J22: 1 | K22: 0 | L22: 1 | M22: 1 | N22: 4 | O22: 0 | P22: 1 | Q22: =SUM(E22:P22) -> 8
D23: PR | E23: 0 | F23: 1 | G23: 0 | H23: 0 | I23: 0 | J23: 1 | K23: 0 | L23: 0 | M23: 0 | N23: 3 | O23: 0 | P23: 0 | Q23: =SUM(E23:P23) -> 5
D24: JML | E24: =SUM(E22:E23) -> 0 | F24: =SUM(F22:F23) -> 1 | G24: =SUM(G22:G23) -> 0 | H24: =SUM(H22:H23) -> 0 | I24: =SUM(I22:I23) -> 0 | J24: =SUM(J22:J23) -> 2 | K24: =SUM(K22:K23) -> 0 | L24: =SUM(L22:L23) -> 1 | ... P24: =SUM(P22:P23) -> 1 | Q24: =SUM(E24:P24) -> 13
B25: 3. | C25: Jumlah pengguna hak pilih dalam Daftar Pemilih Khusus (DPK) | D25: LK | E25: 0 | F25: 2 | G25: 2 | H25: 1 | I25: 0 | J25: 1 | K25: 0 | L25: 0 | M25: 0 | N25: 0 | O25: 0 | P25: 1 | Q25: =SUM(E25:P25) -> 7
D26: PR | E26: 0 | F26: 0 | G26: 2 | H26: 0 | I26: 0 | J26: 1 | K26: 1 | L26: 0 | M26: 1 | N26: 0 | O26: 2 | P26: 1 | Q26: =SUM(E26:P26) -> 8
D27: JML | E27: =SUM(E25:E26) -> 0 | F27: =SUM(F25:F26) -> 2 | G27: =SUM(G25:G26) -> 4 | H27: =SUM(H25:H26) -> 1 | I27: =SUM(I25:I26) -> 0 | J27: =SUM(J25:J26) -> 2 | K27: =SUM(K25:K26) -> 1 | L27: =SUM(L25:L26) -> 0 | ... P27: =SUM(P25:P26) -> 2 | Q27: =SUM(E27:P27) -> 15
B28: 4. | C28: Jumlah Pengguna Hak Pilih (B.1+B.2+B.3) | D28: LK | E28: =SUM(E19,E22,E25) -> 85 | F28: =SUM(F19,F22,F25) -> 81 | G28: =SUM(G19,G22,G25) -> 90 | H28: =SUM(H19,H22,H25) -> 87 | I28: =SUM(I19,I22,I25) -> 93 | J28: =SUM(J19,J22,J25) -> 78 | K28: =SUM(K19,K22,K25) -> 105 | L28: =SUM(L19,L22,L25) -> 109 | ... P28: =SUM(P19,P22,P25) -> 56 | Q28: =SUM(E28:P28) -> 1020
D29: PR | E29: =SUM(E20,E23,E26) -> 101 | F29: =SUM(F20,F23,F26) -> 80 | G29: =SUM(G20,G23,G26) -> 103 | H29: =SUM(H20,H23,H26) -> 94 | I29: =SUM(I20,I23,I26) -> 110 | J29: =SUM(J20,J23,J26) -> 113 | K29: =SUM(K20,K23,K26) -> 125 | L29: =SUM(L20,L23,L26) -> 105 | ... P29: =SUM(P20,P23,P26) -> 63 | Q29: =SUM(E29:P29) -> 1184
D30: JML | E30: =SUM(E28:E29) -> 186 | F30: =SUM(F28:F29) -> 161 | G30: =SUM(G28:G29) -> 193 | H30: =SUM(H28:H29) -> 181 | I30: =SUM(I28:I29) -> 203 | J30: =SUM(J28:J29) -> 191 | K30: =SUM(K28:K29) -> 230 | L30: =SUM(L28:L29) -> 214 | ... P30: =SUM(P28:P29) -> 119 | Q30: =SUM(E30:P30) -> 2204
A32: II | B32: DATA PENGGUNAAN SURAT SUARA
A33: 1 | B33: Jumlah surat suara yang diterima, termasuk surat suara cadangan 2,5% dari DPT | E33: 247 | F33: 191 | G33: 263 | H33: 248 | I33: 261 | J33: 255 | K33: 265 | L33: 283 | M33: 225 | N33: 268 | O33: 180 | P33: 149 | Q33: =SUM(E33:P33) -> 2835
A34: 2 | B34: Jumlah surat suara yang digunakan | E34: 186 | F34: 161 | G34: 193 | H34: 181 | I34: 203 | J34: 191 | K34: 230 | L34: 214 | M34: 175 | N34: 207 | O34: 144 | P34: 119 | Q34: =SUM(E34:P34) -> 2204
A35: 3 | B35: Jumlah surat suara dikembalikan oleh pemilih (karena rusak atau keliru coblos) | E35: 0 | F35: 0 | G35: 0 | H35: 0 | I35: 0 | J35: 0 | K35: 0 | L35: 0 | M35: 0 | N35: 1 | O35: 0 | P35: 2 | Q35: =SUM(E35:P35) -> 3
A36: 4 | B36: Jumlah surat suara yang tidak digunakan/tidak terpakai, termasuk sisa surat suara cadangan | E36: =E33-(E34+E35) -> 61 | F36: =F33-(F34+F35) -> 30 | G36: =G33-(G34+G35) -> 70 | H36: =H33-(H34+H35) -> 67 | I36: =I33-(I34+I35) -> 58 | J36: =J33-(J34+J35) -> 64 | K36: =K33-(K34+K35) -> 35 | L36: =L33-(L34+L35) -> 69 | ... P36: =P33-(P34+P35) -> 28 | Q36: =SUM(E36:P36) -> 628
A38: III | B38: DATA PEMILIH DISABILITAS
B39: Jumlah seluruh Pemilih disabilitas yang menggunakan hak pilih | D39: LK | E39: 0 | F39: 2 | G39: 0 | H39: 0 | I39: 0 | J39: 0 | K39: 0 | L39: 0 | M39: 0 | N39: 1 | O39: 0 | P39: 0 | Q39: =SUM(E39:P39) -> 3
D40: PR | E40: 0 | F40: 0 | G40: 0 | H40: 0 | I40: 0 | J40: 4 | K40: 0 | L40: 0 | M40: 0 | N40: 4 | O40: 0 | P40: 0 | Q40: =SUM(E40:P40) -> 8
D41: JML | E41: =SUM(E39:E40) -> 0 | F41: =SUM(F39:F40) -> 2 | G41: =SUM(G39:G40) -> 0 | H41: =SUM(H39:H40) -> 0 | I41: =SUM(I39:I40) -> 0 | J41: =SUM(J39:J40) -> 4 | K41: =SUM(K39:K40) -> 0 | L41: =SUM(L39:L40) -> 0 | ... P41: =SUM(P39:P40) -> 0 | Q41: =SUM(E41:P41) -> 11
A43: IV | B43: DATA RINCIAN PEROLEHAN SUARA PASANGAN CALON BUPATI DAN WAKIL BUPATI
A44: NOMOR DAN NAMA CALON
A45: A.1 | B45: 1. | C45: Partai Kebangkitan Bangsa | E45: 7 | F45: 9 | G45: 5 | H45: 5 | I45: 9 | J45: 10 | K45: 13 | L45: 4 | M45: 9 | N45: 12 | O45: 3 | P45: 8 | Q45: =SUM(E45:P45) -> 94
A46: A.2 | C46: 1. Dra. Hj. MA`MULAH HARUN, M.Pd.I. | E46: 8 | F46: 8 | G46: 8 | H46: 6 | I46: 14 | J46: 9 | K46: 7 | L46: 10 | M46: 20 | N46: 25 | O46: 6 | P46: 8 | Q46: =SUM(E46:P46) -> 129
C47: 2. UBAIDILLAH, S.Fil.I. | E47: 6 | F47: 12 | G47: 2 | H47: 7 | I47: 2 | J47: 4 | K47: 8 | L47: 4 | M47: 0 | N47: 8 | O47: 1 | P47: 1 | Q47: =SUM(E47:P47) -> 55
C48: 3. Ir. H. YOYOK MULYADI, M.Si. | E48: 0 | F48: 1 | G48: 0 | H48: 0 | I48: 1 | J48: 0 | K48: 1 | L48: 2 | M48: 3 | N48: 0 | O48: 0 | P48: 0 | Q48: =SUM(E48:P48) -> 8
C49: 4. KHOIRUL ANWAR, S.Fil.I. | E49: 0 | F49: 1 | G49: 2 | H49: 0 | I49: 0 | J49: 2 | K49: 2 | L49: 1 | M49: 2 | N49: 2 | O49: 0 | P49: 1 | Q49: =SUM(E49:P49) -> 13
C50: 5. ARIF WIJAKSANA | E50: 0 | F50: 0 | G50: 0 | H50: 0 | I50: 0 | J50: 2 | K50: 0 | L50: 0 | M50: 0 | N50: 1 | O50: 0 | P50: 0 | Q50: =SUM(E50:P50) -> 3
C51: 6. Dr. SITI YUMNAH | E51: 0 | F51: 0 | G51: 0 | H51: 0 | I51: 0 | J51: 0 | K51: 0 | L51: 0 | M51: 0 | N51: 1 | O51: 0 | P51: 0 | Q51: =SUM(E51:P51) -> 1
...

Sheet PADANG
C2: Kecamatan | D2: SINGOJURUH
C3: Kabupaten | D3: BANYUWANGI
C4: Provinsi | D4: JAWA TIMUR
C9: Kelurahan | D9: PADANG
A12: I | B12: DATA PEMILIH DAN PENGGUNAAN HAK PILIH | Q12: JUMLAH AKHIR
A13: A | B13: DATA PEMILIH | E13: TPS 001 | F13: TPS 002 | G13: TPS 003 | H13: TPS 004 | I13: TPS 005 | J13: TPS 006 | K13: TPS 007 | L13: TPS 008 | M13: TPS 009 | N13: TPS 010 | O13: TPS 011 | P13: TPS 012
B14: Jumlah Pemilih dalam Daftar Pemilih Tetap (DPT) | D14: LK | E14: 139 | F14: 134 | G14: 138 | H14: 136 | I14: 114 | J14: 128 | K14: 115 | L14: 133 | M14: 112 | N14: 135 | O14: 124 | P14: 119 | Q14: =SUM(E14:P14) -> 1527
D15: PR | E15: 140 | F15: 129 | G15: 141 | H15: 137 | I15: 124 | J15: 138 | K15: 118 | L15: 138 | M15: 118 | N15: 146 | O15: 138 | P15: 120 | Q15: =SUM(E15:P15) -> 1587
D16: JML | E16: =SUM(E14:E15) -> 279 | F16: =SUM(F14:F15) -> 263 | G16: =SUM(G14:G15) -> 279 | H16: =SUM(H14:H15) -> 273 | I16: =SUM(I14:I15) -> 238 | J16: =SUM(J14:J15) -> 266 | K16: =SUM(K14:K15) -> 233 | L16: =SUM(L14:L15) -> 271 | ... P16: =SUM(P14:P15) -> 239 | Q16: =SUM(E16:P16) -> 3114
A18: B | B18: PENGGUNA HAK PILIH
B19: 1. | C19: Jumlah pengguna hak pilih dalam Daftar Pemilih Tetap (DPT) | D19: LK | E19: 120 | F19: 107 | G19: 100 | H19: 100 | I19: 93 | J19: 107 | K19: 90 | L19: 110 | M19: 88 | N19: 100 | O19: 88 | P19: 90 | Q19: =SUM(E19:P19) -> 1193
D20: PR | E20: 116 | F20: 115 | G20: 111 | H20: 109 | I20: 113 | J20: 120 | K20: 102 | L20: 119 | M20: 95 | N20: 107 | O20: 110 | P20: 97 | Q20: =SUM(E20:P20) -> 1314
D21: JML | E21: =SUM(E19:E20) -> 236 | F21: =SUM(F19:F20) -> 222 | G21: =SUM(G19:G20) -> 211 | H21: =SUM(H19:H20) -> 209 | I21: =SUM(I19:I20) -> 206 | J21: =SUM(J19:J20) -> 227 | K21: =SUM(K19:K20) -> 192 | L21: =SUM(L19:L20) -> 229 | ... P21: =SUM(P19:P20) -> 187 | Q21: =SUM(E21:P21) -> 2507
B22: 2. | C22: Jumlah pengguna hak pilih dalam Daftar Pemilih Tambahan (DPTb) | D22: LK | E22: 2 | F22: 0 | G22: 1 | H22: 0 | I22: 0 | J22: 1 | K22: 1 | L22: 0 | M22: 0 | N22: 0 | O22: 0 | P22: 2 | Q22: =SUM(E22:P22) -> 7
D23: PR | E23: 3 | F23: 2 | G23: 0 | H23: 1 | I23: 0 | J23: 0 | K23: 0 | L23: 0 | M23: 1 | N23: 1 | O23: 0 | Q23: =SUM(E23:P23) -> 8
D24: JML | E24: =SUM(E22:E23) -> 5 | F24: =SUM(F22:F23) -> 2 | G24: =SUM(G22:G23) -> 1 | H24: =SUM(H22:H23) -> 1 | I24: =SUM(I22:I23) -> 0 | J24: =SUM(J22:J23) -> 1 | K24: =SUM(K22:K23) -> 1 | L24: =SUM(L22:L23) -> 0 | ... P24: =SUM(P22:P23) -> 2 | Q24: =SUM(E24:P24) -> 15
B25: 3. | C25: Jumlah pengguna hak pilih dalam Daftar Pemilih Khusus (DPK) | D25: LK | E25: 0 | F25: 1 | G25: 0 | H25: 1 | I25: 2 | J25: 0 | K25: 1 | L25: 2 | M25: 0 | N25: 2 | O25: 1 | P25: 2 | Q25: =SUM(E25:P25) -> 12
D26: PR | E26: 0 | F26: 0 | G26: 0 | H26: 2 | I26: 2 | J26: 1 | K26: 3 | L26: 2 | M26: 0 | N26: 1 | O26: 3 | Q26: =SUM(E26:P26) -> 14
D27: JML | E27: =SUM(E25:E26) -> 0 | F27: =SUM(F25:F26) -> 1 | G27: =SUM(G25:G26) -> 0 | H27: =SUM(H25:H26) -> 3 | I27: =SUM(I25:I26) -> 4 | J27: =SUM(J25:J26) -> 1 | K27: =SUM(K25:K26) -> 4 | L27: =SUM(L25:L26) -> 4 | ... P27: =SUM(P25:P26) -> 2 | Q27: =SUM(E27:P27) -> 26
B28: 4. | C28: Jumlah Pengguna Hak Pilih (B.1+B.2+B.3) | D28: LK | E28: =SUM(E19,E22,E25) -> 122 | F28: =SUM(F19,F22,F25) -> 108 | G28: =SUM(G19,G22,G25) -> 101 | H28: =SUM(H19,H22,H25) -> 101 | I28: =SUM(I19,I22,I25) -> 95 | J28: =SUM(J19,J22,J25) -> 108 | K28: =SUM(K19,K22,K25) -> 92 | L28: =SUM(L19,L22,L25) -> 112 | ... P28: =SUM(P19,P22,P25) -> 94 | Q28: =SUM(E28:P28) -> 1212
D29: PR | E29: =SUM(E20,E23,E26) -> 119 | F29: =SUM(F20,F23,F26) -> 117 | G29: =SUM(G20,G23,G26) -> 111 | H29: =SUM(H20,H23,H26) -> 112 | I29: =SUM(I20,I23,I26) -> 115 | J29: =SUM(J20,J23,J26) -> 121 | K29: =SUM(K20,K23,K26) -> 105 | L29: =SUM(L20,L23,L26) -> 121 | ... P29: =SUM(P20,P23,P26) -> 97 | Q29: =SUM(E29:P29) -> 1336
D30: JML | E30: =SUM(E28:E29) -> 241 | F30: =SUM(F28:F29) -> 225 | G30: =SUM(G28:G29) -> 212 | H30: =SUM(H28:H29) -> 213 | I30: =SUM(I28:I29) -> 210 | J30: =SUM(J28:J29) -> 229 | K30: =SUM(K28:K29) -> 197 | L30: =SUM(L28:L29) -> 233 | ... P30: =SUM(P28:P29) -> 191 | Q30: =SUM(E30:P30) -> 2548
A32: II | B32: DATA PENGGUNAAN SURAT SUARA
A33: 1 | B33: Jumlah surat suara yang diterima, termasuk surat suara cadangan 2,5% dari DPT | E33: 282 | F33: 266 | G33: 282 | H33: 267 | I33: 240 | J33: 272 | K33: 225 | L33: 275 | M33: 222 | N33: 284 | O33: 266 | P33: 241 | Q33: =SUM(E33:P33) -> 3122
A34: 2 | B34: Jumlah surat suara yang digunakan | E34: 241 | F34: 225 | G34: 212 | H34: 213 | I34: 210 | J34: 229 | K34: 197 | L34: 233 | M34: 184 | N34: 211 | O34: 202 | P34: 191 | Q34: =SUM(E34:P34) -> 2548
A35: 3 | B35: Jumlah surat suara dikembalikan oleh pemilih (karena rusak atau keliru coblos) | E35: 0 | F35: 1 | G35: 2 | H35: 3 | I35: 1 | J35: 0 | K35: 0 | L35: 0 | M35: 0 | N35: 0 | O35: 0 | P35: 0 | Q35: =SUM(E35:P35) -> 7
A36: 4 | B36: Jumlah surat suara yang tidak digunakan/tidak terpakai, termasuk sisa surat suara cadangan | E36: =E33-(E34+E35) -> 41 | F36: =F33-(F34+F35) -> 40 | G36: =G33-(G34+G35) -> 68 | H36: =H33-(H34+H35) -> 51 | I36: =I33-(I34+I35) -> 29 | J36: =J33-(J34+J35) -> 43 | K36: =K33-(K34+K35) -> 28 | L36: =L33-(L34+L35) -> 42 | ... P36: =P33-(P34+P35) -> 50 | Q36: =SUM(E36:P36) -> 567
A38: III | B38: DATA PEMILIH DISABILITAS
B39: Jumlah seluruh Pemilih disabilitas yang menggunakan hak pilih | D39: LK | L39: 1 | Q39: =SUM(E39:P39) -> 1
D40: PR | J40: 1 | L40: 1 | Q40: =SUM(E40:P40) -> 2
D41: JML | E41: =SUM(E39:E40) -> 0 | F41: =SUM(F39:F40) -> 0 | G41: =SUM(G39:G40) -> 0 | H41: =SUM(H39:H40) -> 0 | I41: =SUM(I39:I40) -> 0 | J41: =SUM(J39:J40) -> 1 | K41: =SUM(K39:K40) -> 0 | L41: =SUM(L39:L40) -> 2 | ... P41: =SUM(P39:P40) -> 0 | Q41: =SUM(E41:P41) -> 3
A43: IV | B43: DATA RINCIAN PEROLEHAN SUARA PASANGAN CALON BUPATI DAN WAKIL BUPATI
A44: NOMOR DAN NAMA CALON
