Workbook

Sheet DPRD PROVINSI
C8: Kecamatan | D8: LICIN
C9: Kabupaten | D9: BANYUWANGI
C10: Provinsi | D10: JAWA TIMUR
A12: I | B12: DATA PEMILIH DAN PENGGUNAAN HAK PILIH | E12: JUMLAH AKHIR
A13: A | B13: DATA PEMILIH
B14: Jumlah Pemilih dalam Daftar Pemilih Tetap (DPT) | D14: LK | E14: =BANJAR!N14+GUMUK!M14+JELUN!M14+KLUNCING!O14+LICIN!T14+PAKEL!N14+SEGOBANG!W14+TAMANSARI!AD14 -> 11736
D15: PR | E15: =BANJAR!N15+GUMUK!M15+JELUN!M15+KLUNCING!O15+LICIN!T15+PAKEL!N15+SEGOBANG!W15+TAMANSARI!AD15 -> 11864
D16: JML | E16: =SUM(E14:E15) -> 23600
A18: B | B18: PENGGUNA HAK PILIH
B19: 1. | C19: Jumlah pengguna hak pilih dalam Daftar Pemilih Tetap (DPT) | D19: LK | E19: =BANJAR!N19+GUMUK!M19+JELUN!M19+KLUNCING!O19+LICIN!T19+PAKEL!N19+SEGOBANG!W19+TAMANSARI!AD19 -> 9042
D20: PR | E20: =BANJAR!N20+GUMUK!M20+JELUN!M20+KLUNCING!O20+LICIN!T20+PAKEL!N20+SEGOBANG!W20+TAMANSARI!AD20 -> 9713
D21: JML | E21: =SUM(E19:E20) -> 18755
B22: 2. | C22: Jumlah pengguna hak pilih dalam Daftar Pemilih Tambahan (DPTb) | D22: LK | E22: =BANJAR!N22+GUMUK!M22+JELUN!M22+KLUNCING!O22+LICIN!T22+PAKEL!N22+SEGOBANG!W22+TAMANSARI!AD22 -> 6
D23: PR | E23: =BANJAR!N23+GUMUK!M23+JELUN!M23+KLUNCING!O23+LICIN!T23+PAKEL!N23+SEGOBANG!W23+TAMANSARI!AD23 -> 5
D24: JML | E24: =SUM(E22:E23) -> 11
B25: 3. | C25: Jumlah pengguna hak pilih dalam Daftar Pemilih Khusus (DPK) | D25: LK | E25: =BANJAR!N25+GUMUK!M25+JELUN!M25+KLUNCING!O25+LICIN!T25+PAKEL!N25+SEGOBANG!W25+TAMANSARI!AD25 -> 78
D26: PR | E26: =BANJAR!N26+GUMUK!M26+JELUN!M26+KLUNCING!O26+LICIN!T26+PAKEL!N26+SEGOBANG!W26+TAMANSARI!AD26 -> 80
D27: JML | E27: =SUM(E25:E26) -> 158
B28: 4. | C28: Jumlah Pengguna Hak Pilih (B.1+B.2+B.3) | D28: LK | E28: =E19+E22+E25 -> 9126
D29: PR | E29: =E20+E23+E26 -> 9798
D30: JML | E30: =SUM(E28:E29) -> 18924
A32: II | B32: DATA PENGGUNAAN SURAT SUARA
A33: 1 | B33: Jumlah surat suara yang diterima, termasuk surat suara cadangan 2,5% dari DPT | E33: =BANJAR!N33+GUMUK!M33+JELUN!M33+KLUNCING!O33+LICIN!T33+PAKEL!N33+SEGOBANG!W33+TAMANSARI!AD33 -> 24090
A34: 2 | B34: Jumlah surat suara yang digunakan | E34: =BANJAR!N34+GUMUK!M34+JELUN!M34+KLUNCING!O34+LICIN!T34+PAKEL!N34+SEGOBANG!W34+TAMANSARI!AD34 -> 18922
A35: 3 | B35: Jumlah surat suara dikembalikan oleh pemilih (karena rusak atau keliru coblos) | E35: =BANJAR!N35+GUMUK!M35+JELUN!M35+KLUNCING!O35+LICIN!T35+PAKEL!N35+SEGOBANG!W35+TAMANSARI!AD35 -> 45
A36: 4 | B36: Jumlah surat suara yang tidak digunakan/tidak terpakai, termasuk sisa surat suara cadangan | E36: =E33-(E34+E35) -> 5123
A38: III | B38: DATA PEMILIH DISABILITAS
B39: Jumlah seluruh Pemilih disabilitas yang menggunakan hak pilih | D39: LK | E39: =BANJAR!N39+GUMUK!M39+JELUN!M39+KLUNCING!O39+LICIN!T39+PAKEL!N39+SEGOBANG!W39+TAMANSARI!AD39 -> 27
D40: PR | E40: =BANJAR!N40+GUMUK!M40+JELUN!M40+KLUNCING!O40+LICIN!T40+PAKEL!N40+SEGOBANG!W40+TAMANSARI!AD40 -> 19
D41: JML | E41: =SUM(E39:E40) -> 46
A43: IV | B43: DATA RINCIAN PEROLEHAN SUARA PASANGAN CALON BUPATI DAN WAKIL BUPATI
A44: NOMOR DAN NAMA CALON
A45: A.1 | B45: 1. | C45: Partai Kebangkitan Bangsa | E45: =BANJAR!N45+GUMUK!M45+JELUN!M45+KLUNCING!O45+LICIN!T45+PAKEL!N45+SEGOBANG!W45+TAMANSARI!AD45 -> 1005
A46: A.2 | C46: 1. Dra. Hj. MA`MULAH HARUN, M.Pd.I. | E46: =BANJAR!N46+GUMUK!M46+JELUN!M46+KLUNCING!O46+LICIN!T46+PAKEL!N46+SEGOBANG!W46+TAMANSARI!AD46 -> 1989
C47: 2. UBAIDILLAH, S.Fil.I. | E47: =BANJAR!N47+GUMUK!M47+JELUN!M47+KLUNCING!O47+LICIN!T47+PAKEL!N47+SEGOBANG!W47+TAMANSARI!AD47 -> 177
C48: 3. Ir. H. YOYOK MULYADI, M.Si. | E48: =BANJAR!N48+GUMUK!M48+JELUN!M48+KLUNCING!O48+LICIN!T48+PAKEL!N48+SEGOBANG!W48+TAMANSARI!AD48 -> 141
C49: 4. KHOIRUL ANWAR, S.Fil.I. | E49: =BANJAR!N49+GUMUK!M49+JELUN!M49+KLUNCING!O49+LICIN!T49+PAKEL!N49+SEGOBANG!W49+TAMANSARI!AD49 -> 116
C50: 5. ARIF WIJAKSANA | E50: =BANJAR!N50+GUMUK!M50+JELUN!M50+KLUNCING!O50+LICIN!T50+PAKEL!N50+SEGOBANG!W50+TAMANSARI!AD50 -> 48
C51: 6. Dr. SITI YUMNAH | E51: =BANJAR!N51+GUMUK!M51+JELUN!M51+KLUNCING!O51+LICIN!T51+PAKEL!N51+SEGOBANG!W51+TAMANSARI!AD51 -> 24
C52: 7. MOHAMMAD ZAINI, M.Pd.I. | E52: =BANJAR!N52+GUMUK!M52+JELUN!M52+KLUNCING!O52+LICIN!T52+PAKEL!N52+SEGOBANG!W52+TAMANSARI!AD52 -> 25
...

Sheet BANJAR
C2: Kecamatan | D2: LICIN
C3: Kabupaten | D3: BANYUWANGI
C4: Provinsi | D4: JAWA TIMUR
C9: Kelurahan | D9: BANJAR
A12: I | B12: DATA PEMILIH DAN PENGGUNAAN HAK PILIH | N12: JUMLAH AKHIR
A13: A | B13: DATA PEMILIH | E13: TPS 001 | F13: TPS 002 | G13: TPS 003 | H13: TPS 004 | I13: TPS 005 | J13: TPS 006 | K13: TPS 007 | L13: TPS 008 | M13: TPS 009
B14: Jumlah Pemilih dalam Daftar Pemilih Tetap (DPT) | D14: LK | E14: 123 | F14: 103 | G14: 107 | H14: 115 | I14: 81 | J14: 73 | K14: 115 | L14: 146 | M14: 132 | N14: =SUM(E14:M14) -> 995
D15: PR | E15: 120 | F15: 107 | G15: 116 | H15: 117 | I15: 83 | J15: 77 | K15: 131 | L15: 133 | M15: 128 | N15: =SUM(E15:M15) -> 1012
D16: JML | E16: =SUM(E14:E15) -> 243 | F16: =SUM(F14:F15) -> 210 | G16: =SUM(G14:G15) -> 223 | H16: =SUM(H14:H15) -> 232 | I16: =SUM(I14:I15) -> 164 | J16: =SUM(J14:J15) -> 150 | K16: =SUM(K14:K15) -> 246 | L16: =SUM(L14:L15) -> 279 | M16: =SUM(M14:M15) -> 260 | N16: =SUM(E16:M16) -> 2007
A18: B | B18: PENGGUNA HAK PILIH
B19: 1. | C19: Jumlah pengguna hak pilih dalam Daftar Pemilih Tetap (DPT) | D19: LK | E19: 82 | F19: 78 | G19: 80 | H19: 81 | I19: 55 | J19: 61 | K19: 92 | L19: 112 | M19: 111 | N19: =SUM(E19:M19) -> 752
D20: PR | E20: 96 | F20: 86 | G20: 95 | H20: 92 | I20: 71 | J20: 65 | K20: 105 | L20: 101 | M20: 111 | N20: =SUM(E20:M20) -> 822
D21: JML | E21: =SUM(E19:E20) -> 178 | F21: =SUM(F19:F20) -> 164 | G21: =SUM(G19:G20) -> 175 | H21: =SUM(H19:H20) -> 173 | I21: =SUM(I19:I20) -> 126 | J21: =SUM(J19:J20) -> 126 | K21: =SUM(K19:K20) -> 197 | L21: =SUM(L19:L20) -> 213 | M21: =SUM(M19:M20) -> 222 | N21: =SUM(E21:M21) -> 1574
B22: 2. | C22: Jumlah pengguna hak pilih dalam Daftar Pemilih Tambahan (DPTb) | D22: LK | E22: 0 | F22: 0 | G22: 0 | H22: 0 | I22: 0 | J22: 0 | K22: 0 | L22: 0 | M22: 0 | N22: =SUM(E22:M22) -> 0
D23: PR | E23: 0 | F23: 0 | G23: 0 | H23: 0 | I23: 0 | J23: 0 | K23: 0 | L23: 0 | M23: 0 | N23: =SUM(E23:M23) -> 0
D24: JML | E24: =SUM(E22:E23) -> 0 | F24: =SUM(F22:F23) -> 0 | G24: =SUM(G22:G23) -> 0 | H24: =SUM(H22:H23) -> 0 | I24: =SUM(I22:I23) -> 0 | J24: =SUM(J22:J23) -> 0 | K24: =SUM(K22:K23) -> 0 | L24: =SUM(L22:L23) -> 0 | M24: =SUM(M22:M23) -> 0 | N24: =SUM(E24:M24) -> 0
B25: 3. | C25: Jumlah pengguna hak pilih dalam Daftar Pemilih Khusus (DPK) | D25: LK | E25: 0 | F25: 0 | G25: 0 | H25: 0 | I25: 0 | J25: 0 | K25: 0 | L25: 0 | M25: 3 | N25: =SUM(E25:M25) -> 3
D26: PR | E26: 0 | F26: 0 | G26: 1 | H26: 0 | I26: 0 | J26: 0 | K26: 2 | L26: 1 | M26: 1 | N26: =SUM(E26:M26) -> 5
D27: JML | E27: =SUM(E25:E26) -> 0 | F27: =SUM(F25:F26) -> 0 | G27: =SUM(G25:G26) -> 1 | H27: =SUM(H25:H26) -> 0 | I27: =SUM(I25:I26) -> 0 | J27: =SUM(J25:J26) -> 0 | K27: =SUM(K25:K26) -> 2 | L27: =SUM(L25:L26) -> 1 | M27: =SUM(M25:M26) -> 4 | N27: =SUM(E27:M27) -> 8
B28: 4. | C28: Jumlah Pengguna Hak Pilih (B.1+B.2+B.3) | D28: LK | E28: =SUM(E19,E22,E25) -> 82 | F28: =SUM(F19,F22,F25) -> 78 | G28: =SUM(G19,G22,G25) -> 80 | H28: =SUM(H19,H22,H25) -> 81 | I28: =SUM(I19,I22,I25) -> 55 | J28: =SUM(J19,J22,J25) -> 61 | K28: =SUM(K19,K22,K25) -> 92 | L28: =SUM(L19,L22,L25) -> 112 | M28: =SUM(M19,M22,M25) -> 114 | N28: =SUM(E28:M28) -> 755
D29: PR | E29: =SUM(E20,E23,E26) -> 96 | F29: =SUM(F20,F23,F26) -> 86 | G29: =SUM(G20,G23,G26) -> 96 | H29: =SUM(H20,H23,H26) -> 92 | I29: =SUM(I20,I23,I26) -> 71 | J29: =SUM(J20,J23,J26) -> 65 | K29: =SUM(K20,K23,K26) -> 107 | L29: =SUM(L20,L23,L26) -> 102 | M29: =SUM(M20,M23,M26) -> 112 | N29: =SUM(E29:M29) -> 827
D30: JML | E30: =SUM(E28:E29) -> 178 | F30: =SUM(F28:F29) -> 164 | G30: =SUM(G28:G29) -> 176 | H30: =SUM(H28:H29) -> 173 | I30: =SUM(I28:I29) -> 126 | J30: =SUM(J28:J29) -> 126 | K30: =SUM(K28:K29) -> 199 | L30: =SUM(L28:L29) -> 214 | M30: =SUM(M28:M29) -> 226 | N30: =SUM(E30:M30) -> 1582
A32: II | B32: DATA PENGGUNAAN SURAT SUARA
A33: 1 | B33: Jumlah surat suara yang diterima, termasuk surat suara cadangan 2,5% dari DPT | E33: 254 | F33: 215 | G33: 228 | H33: 237 | I33: 168 | J33: 153 | K33: 251 | L33: 285 | M33: 267 | N33: =SUM(E33:M33) -> 2058
A34: 2 | B34: Jumlah surat suara yang digunakan | E34: 178 | F34: 164 | G34: 176 | H34: 173 | I34: 126 | J34: 126 | K34: 199 | L34: 214 | M34: 226 | N34: =SUM(E34:M34) -> 1582
A35: 3 | B35: Jumlah surat suara dikembalikan oleh pemilih (karena rusak atau keliru coblos) | E35: 0 | F35: 0 | G35: 0 | H35: 0 | I35: 0 | J35: 0 | K35: 0 | L35: 0 | M35: 0 | N35: =SUM(E35:M35) -> 0
A36: 4 | B36: Jumlah surat suara yang tidak digunakan/tidak terpakai, termasuk sisa surat suara cadangan | E36: =E33-(E34+E35) -> 76 | F36: =F33-(F34+F35) -> 51 | G36: =G33-(G34+G35) -> 52 | H36: =H33-(H34+H35) -> 64 | I36: =I33-(I34+I35) -> 42 | J36: =J33-(J34+J35) -> 27 | K36: =K33-(K34+K35) -> 52 | L36: =L33-(L34+L35) -> 71 | M36: =M33-(M34+M35) -> 41 | N36: =SUM(E36:M36) -> 476
A38: III | B38: DATA PEMILIH DISABILITAS
B39: Jumlah seluruh Pemilih disabilitas yang menggunakan hak pilih | D39: LK | E39: 1 | F39: 2 | G39: 3 | H39: 0 | I39: 0 | J39: 0 | K39: 0 | L39: 0 | M39: 1 | N39: =SUM(E39:M39) -> 7
D40: PR | E40: 0 | F40: 1 | G40: 0 | H40: 0 | I40: 1 | J40: 0 | K40: 0 | L40: 0 | M40: 0 | N40: =SUM(E40:M40) -> 2
D41: JML | E41: =SUM(E39:E40) -> 1 | F41: =SUM(F39:F40) -> 3 | G41: =SUM(G39:G40) -> 3 | H41: =SUM(H39:H40) -> 0 | I41: =SUM(I39:I40) -> 1 | J41: =SUM(J39:J40) -> 0 | K41: =SUM(K39:K40) -> 0 | L41: =SUM(L39:L40) -> 0 | M41: =SUM(M39:M40) -> 1 | N41: =SUM(E41:M41) -> 9
A43: IV | B43: DATA RINCIAN PEROLEHAN SUARA PASANGAN CALON BUPATI DAN WAKIL BUPATI
A44: NOMOR DAN NAMA CALON
A45: A.1 | B45: 1. | C45: Partai Kebangkitan Bangsa | E45: 13 | F45: 6 | G45: 5 | H45: 15 | I45: 0 | J45: 2 | K45: 22 | L45: 8 | M45: 9 | N45: =SUM(E45:M45) -> 80
A46: A.2 | C46: 1. Dra. Hj. MA`MULAH HARUN, M.Pd.I. | E46: 24 | F46: 16 | G46: 12 | H46: 12 | I46: 6 | J46: 7 | K46: 29 | L46: 21 | M46: 12 | N46: =SUM(E46:M46) -> 139
C47: 2. UBAIDILLAH, S.Fil.I. | E47: 0 | F47: 1 | G47: 0 | H47: 0 | I47: 1 | J47: 1 | K47: 2 | L47: 1 | M47: 2 | N47: =SUM(E47:M47) -> 8
C48: 3. Ir. H. YOYOK MULYADI, M.Si. | E48: 1 | F48: 0 | G48: 0 | H48: 0 | I48: 0 | J48: 0 | K48: 1 | L48: 0 | M48: 0 | N48: =SUM(E48:M48) -> 2
C49: 4. KHOIRUL ANWAR, S.Fil.I. | E49: 0 | F49: 1 | G49: 1 | H49: 2 | I49: 0 | J49: 0 | K49: 2 | L49: 3 | M49: 0 | N49: =SUM(E49:M49) -> 9
C50: 5. ARIF WIJAKSANA | E50: 1 | F50: 1 | G50: 1 | H50: 0 | I50: 0 | J50: 0 | K50: 0 | L50: 1 | M50: 3 | N50: =SUM(E50:M50) -> 7
C51: 6. Dr. SITI YUMNAH | E51: 0 | F51: 0 | G51: 0 | H51: 0 | I51: 0 | J51: 0 | K51: 0 | L51: 0 | M51: 1 | N51: =SUM(E51:M51) -> 1
...

Sheet GUMUK
C2: Kecamatan | D2: LICIN
C3: Kabupaten | D3: BANYUWANGI
C4: Provinsi | D4: JAWA TIMUR
C9: Kelurahan | D9: GUMUK
A12: I | B12: DATA PEMILIH DAN PENGGUNAAN HAK PILIH | M12: JUMLAH AKHIR
A13: A | B13: DATA PEMILIH | E13: TPS 001 | F13: TPS 002 | G13: TPS 003 | H13: TPS 004 | I13: TPS 005 | J13: 110 | K13: TPS 007 | L13: TPS 008
B14: Jumlah Pemilih dalam Daftar Pemilih Tetap (DPT) | D14: LK | E14: 129 | F14: 145 | G14: 133 | H14: 108 | I14: 127 | J14: 110 | K14: 99 | L14: 106 | M14: =SUM(E14:L14) -> 957
D15: PR | E15: 131 | F15: 129 | G15: 139 | H15: 112 | I15: 133 | J15: 115 | K15: 111 | L15: 109 | M15: =SUM(E15:L15) -> 979
D16: JML | E16: =SUM(E14:E15) -> 260 | F16: =SUM(F14:F15) -> 274 | G16: =SUM(G14:G15) -> 272 | H16: =SUM(H14:H15) -> 220 | I16: =SUM(I14:I15) -> 260 | J16: =SUM(J14:J15) -> 225 | K16: =SUM(K14:K15) -> 210 | L16: =SUM(L14:L15) -> 215 | M16: =SUM(E16:L16) -> 1936
A18: B | B18: PENGGUNA HAK PILIH
B19: 1. | C19: Jumlah pengguna hak pilih dalam Daftar Pemilih Tetap (DPT) | D19: LK | E19: 107 | F19: 113 | G19: 102 | H19: 76 | I19: 100 | J19: 99 | K19: 79 | L19: 90 | M19: =SUM(E19:L19) -> 766
D20: PR | E20: 96 | F20: 101 | G20: 113 | H20: 86 | I20: 112 | J20: 97 | K20: 89 | L20: 98 | M20: =SUM(E20:L20) -> 792
D21: JML | E21: =SUM(E19:E20) -> 203 | F21: =SUM(F19:F20) -> 214 | G21: =SUM(G19:G20) -> 215 | H21: =SUM(H19:H20) -> 162 | I21: =SUM(I19:I20) -> 212 | J21: =SUM(J19:J20) -> 196 | K21: =SUM(K19:K20) -> 168 | L21: =SUM(L19:L20) -> 188 | M21: =SUM(E21:L21) -> 1558
B22: 2. | C22: Jumlah pengguna hak pilih dalam Daftar Pemilih Tambahan (DPTb) | D22: LK | E22: 0 | F22: 2 | G22: 0 | H22: 0 | I22: 0 | J22: 1 | K22: 0 | L22: 0 | M22: =SUM(E22:L22) -> 3
D23: PR | E23: 0 | F23: 0 | G23: 0 | H23: 0 | I23: 0 | J23: 0 | K23: 0 | L23: 0 | M23: =SUM(E23:L23) -> 0
D24: JML | E24: =SUM(E22:E23) -> 0 | F24: =SUM(F22:F23) -> 2 | G24: =SUM(G22:G23) -> 0 | H24: =SUM(H22:H23) -> 0 | I24: =SUM(I22:I23) -> 0 | J24: =SUM(J22:J23) -> 1 | K24: =SUM(K22:K23) -> 0 | L24: =SUM(L22:L23) -> 0 | M24: =SUM(E24:L24) -> 3
B25: 3. | C25: Jumlah pengguna hak pilih dalam Daftar Pemilih Khusus (DPK) | D25: LK | E25: 0 | F25: 0 | G25: 0 | H25: 0 | I25: 1 | J25: 4 | K25: 1 | L25: 2 | M25: =SUM(E25:L25) -> 8
D26: PR | E26: 0 | F26: 1 | G26: 1 | H26: 0 | I26: 2 | J26: 2 | K26: 1 | L26: 0 | M26: =SUM(E26:L26) -> 7
D27: JML | E27: =SUM(E25:E26) -> 0 | F27: =SUM(F25:F26) -> 1 | G27: =SUM(G25:G26) -> 1 | H27: =SUM(H25:H26) -> 0 | I27: =SUM(I25:I26) -> 3 | J27: =SUM(J25:J26) -> 6 | K27: =SUM(K25:K26) -> 2 | L27: =SUM(L25:L26) -> 2 | M27: =SUM(E27:L27) -> 15
B28: 4. | C28: Jumlah Pengguna Hak Pilih (B.1+B.2+B.3) | D28: LK | E28: =SUM(E19,E22,E25) -> 107 | F28: =SUM(F19,F22,F25) -> 115 | G28: =SUM(G19,G22,G25) -> 102 | H28: =SUM(H19,H22,H25) -> 76 | I28: =SUM(I19,I22,I25) -> 101 | J28: =SUM(J19,J22,J25) -> 104 | K28: =SUM(K19,K22,K25) -> 80 | L28: =SUM(L19,L22,L25) -> 92 | M28: =SUM(E28:L28) -> 777
D29: PR | E29: =SUM(E20,E23,E26) -> 96 | F29: =SUM(F20,F23,F26) -> 102 | G29: =SUM(G20,G23,G26) -> 114 | H29: =SUM(H20,H23,H26) -> 86 | I29: =SUM(I20,I23,I26) -> 114 | J29: =SUM(J20,J23,J26) -> 99 | K29: =SUM(K20,K23,K26) -> 90 | L29: =SUM(L20,L23,L26) -> 98 | M29: =SUM(E29:L29) -> 799
D30: JML | E30: =SUM(E28:E29) -> 203 | F30: =SUM(F28:F29) -> 217 | G30: =SUM(G28:G29) -> 216 | H30: =SUM(H28:H29) -> 162 | I30: =SUM(I28:I29) -> 215 | J30: =SUM(J28:J29) -> 203 | K30: =SUM(K28:K29) -> 170 | L30: =SUM(L28:L29) -> 190 | M30: =SUM(E30:L30) -> 1576
A32: II | B32: DATA PENGGUNAAN SURAT SUARA
A33: 1 | B33: Jumlah surat suara yang diterima, termasuk surat suara cadangan 2,5% dari DPT | E33: 264 | F33: 280 | G33: 278 | H33: 225 | I33: 266 | J33: 228 | K33: 205 | L33: 230 | M33: =SUM(E33:L33) -> 1976
A34: 2 | B34: Jumlah surat suara yang digunakan | E34: 203 | F34: 217 | G34: 216 | H34: 162 | I34: 215 | J34: 203 | K34: 170 | L34: 190 | M34: =SUM(E34:L34) -> 1576
A35: 3 | B35: Jumlah surat suara dikembalikan oleh pemilih (karena rusak atau keliru coblos) | E35: 1 | F35: 0 | G35: 0 | H35: 0 | I35: 0 | J35: 0 | K35: 0 | L35: 0 | M35: =SUM(E35:L35) -> 1
A36: 4 | B36: Jumlah surat suara yang tidak digunakan/tidak terpakai, termasuk sisa surat suara cadangan | E36: =E33-(E34+E35) -> 60 | F36: =F33-(F34+F35) -> 63 | G36: =G33-(G34+G35) -> 62 | H36: =H33-(H34+H35) -> 63 | I36: =I33-(I34+I35) -> 51 | J36: =J33-(J34+J35) -> 25 | K36: =K33-(K34+K35) -> 35 | L36: =L33-(L34+L35) -> 40 | M36: =SUM(E36:L36) -> 399
A38: III | B38: DATA PEMILIH DISABILITAS
B39: Jumlah seluruh Pemilih disabilitas yang menggunakan hak pilih | D39: LK | E39: 0 | F39: 0 | G39: 0 | H39: 0 | I39: 2 | J39: 0 | K39: 0 | L39: 0 | M39: =SUM(E39:L39) -> 2
D40: PR | E40: 0 | F40: 0 | G40: 0 | H40: 0 | I40: 0 | J40: 0 | K40: 0 | L40: 0 | M40: =SUM(E40:L40) -> 0
D41: JML | E41: =SUM(E39:E40) -> 0 | F41: =SUM(F39:F40) -> 0 | G41: =SUM(G39:G40) -> 0 | H41: =SUM(H39:H40) -> 0 | I41: =SUM(I39:I40) -> 2 | J41: =SUM(J39:J40) -> 0 | K41: =SUM(K39:K40) -> 0 | L41: =SUM(L39:L40) -> 0 | M41: =SUM(E41:L41) -> 2
A43: IV | B43: DATA RINCIAN PEROLEHAN SUARA PASANGAN CALON BUPATI DAN WAKIL BUPATI
A44: NOMOR DAN NAMA CALON
A45: A.1 | B45: 1. | C45: Partai Kebangkitan Bangsa | E45: 5 | F45: 8 | G45: 5 | H45: 7 | I45: 6 | J45: 8 | K45: 2 | L45: 1 | M45: =SUM(E45:L45) -> 42
A46: A.2 | C46: 1. Dra. Hj. MA`MULAH HARUN, M.Pd.I. | E46: 20 | F46: 10 | G46: 17 | H46: 8 | I46: 9 | J46: 9 | K46: 7 | L46: 16 | M46: =SUM(E46:L46) -> 96
C47: 2. UBAIDILLAH, S.Fil.I. | E47: 1 | F47: 3 | G47: 2 | H47: 0 | I47: 1 | J47: 0 | K47: 0 | L47: 0 | M47: =SUM(E47:L47) -> 7
C48: 3. Ir. H. YOYOK MULYADI, M.Si. | E48: 0 | F48: 1 | G48: 0 | H48: 1 | I48: 0 | J48: 1 | K48: 0 | L48: 0 | M48: =SUM(E48:L48) -> 3
C49: 4. KHOIRUL ANWAR, S.Fil.I. | E49: 1 | F49: 0 | G49: 0 | H49: 0 | I49: 0 | J49: 0 | K49: 0 | L49: 0 | M49: =SUM(E49:L49) -> 1
C50: 5. ARIF WIJAKSANA | E50: 0 | F50: 0 | G50: 0 | H50: 0 | I50: 0 | J50: 0 | K50: 0 | L50: 1 | M50: =SUM(E50:L50) -> 1
C51: 6. Dr. SITI YUMNAH | E51: 0 | F51: 0 | G51: 0 | H51: 0 | I51: 0 | J51: 0 | K51: 0 | L51: 0 | M51: =SUM(E51:L51) -> 0
...

Sheet JELUN
C2: Kecamatan | D2: LICIN
C3: Kabupaten | D3: BANYUWANGI
C4: Provinsi | D4: JAWA TIMUR
C9: Kelurahan | D9: JELUN
A12: I | B12: DATA PEMILIH DAN PENGGUNAAN HAK PILIH | M12: JUMLAH AKHIR
A13: A | B13: DATA PEMILIH | E13: TPS 001 | F13: TPS 002 | G13: TPS 003 | H13: TPS 004 | I13: TPS 005 | J13: TPS 006 | K13: TPS 007 | L13: TPS 008
B14: Jumlah Pemilih dalam Daftar Pemilih Tetap (DPT) | D14: LK | E14: 148 | F14: 107 | G14: 123 | H14: 127 | I14: 129 | J14: 119 | K14: 115 | L14: 110 | M14: =SUM(E14:L14) -> 978
D15: PR | E15: 141 | F15: 121 | G15: 105 | H15: 132 | I15: 132 | J15: 134 | K15: 115 | L15: 106 | M15: =SUM(E15:L15) -> 986
D16: JML | E16: =SUM(E14:E15) -> 289 | F16: =SUM(F14:F15) -> 228 | G16: =SUM(G14:G15) -> 228 | H16: =SUM(H14:H15) -> 259 | I16: =SUM(I14:I15) -> 261 | J16: =SUM(J14:J15) -> 253 | K16: =SUM(K14:K15) -> 230 | L16: =SUM(L14:L15) -> 216 | M16: =SUM(E16:L16) -> 1964
A18: B | B18: PENGGUNA HAK PILIH
B19: 1. | C19: Jumlah pengguna hak pilih dalam Daftar Pemilih Tetap (DPT) | D19: LK | E19: 100 | F19: 83 | G19: 101 | H19: 95 | I19: 108 | J19: 95 | K19: 78 | L19: 84 | M19: =SUM(E19:L19) -> 744
D20: PR | E20: 118 | F20: 100 | G20: 83 | H20: 101 | I20: 114 | J20: 109 | K20: 85 | L20: 78 | M20: =SUM(E20:L20) -> 788
D21: JML | E21: =SUM(E19:E20) -> 218 | F21: =SUM(F19:F20) -> 183 | G21: =SUM(G19:G20) -> 184 | H21: =SUM(H19:H20) -> 196 | I21: =SUM(I19:I20) -> 222 | J21: =SUM(J19:J20) -> 204 | K21: =SUM(K19:K20) -> 163 | L21: =SUM(L19:L20) -> 162 | M21: =SUM(E21:L21) -> 1532
B22: 2. | C22: Jumlah pengguna hak pilih dalam Daftar Pemilih Tambahan (DPTb) | D22: LK | E22: 0 | F22: 0 | G22: 0 | H22: 0 | I22: 0 | J22: 0 | K22: 0 | L22: 0 | M22: =SUM(E22:L22) -> 0
D23: PR | E23: 1 | F23: 0 | G23: 0 | H23: 0 | I23: 0 | J23: 0 | K23: 0 | L23: 0 | M23: =SUM(E23:L23) -> 1
D24: JML | E24: =SUM(E22:E23) -> 1 | F24: =SUM(F22:F23) -> 0 | G24: =SUM(G22:G23) -> 0 | H24: =SUM(H22:H23) -> 0 | I24: =SUM(I22:I23) -> 0 | J24: =SUM(J22:J23) -> 0 | K24: =SUM(K22:K23) -> 0 | L24: =SUM(L22:L23) -> 0 | M24: =SUM(E24:L24) -> 1
B25: 3. | C25: Jumlah pengguna hak pilih dalam Daftar Pemilih Khusus (DPK) | D25: LK | E25: 0 | F25: 0 | G25: 0 | H25: 0 | I25: 1 | J25: 0 | K25: 0 | L25: 0 | M25: =SUM(E25:L25) -> 1
D26: PR | E26: 2 | F26: 0 | G26: 0 | H26: 1 | I26: 0 | J26: 0 | K26: 0 | L26: 0 | M26: =SUM(E26:L26) -> 3
D27: JML | E27: =SUM(E25:E26) -> 2 | F27: =SUM(F25:F26) -> 0 | G27: =SUM(G25:G26) -> 0 | H27: =SUM(H25:H26) -> 1 | I27: =SUM(I25:I26) -> 1 | J27: =SUM(J25:J26) -> 0 | K27: =SUM(K25:K26) -> 0 | L27: =SUM(L25:L26) -> 0 | M27: =SUM(E27:L27) -> 4
B28: 4. | C28: Jumlah Pengguna Hak Pilih (B.1+B.2+B.3) | D28: LK | E28: =SUM(E19,E22,E25) -> 100 | F28: =SUM(F19,F22,F25) -> 83 | G28: =SUM(G19,G22,G25) -> 101 | H28: =SUM(H19,H22,H25) -> 95 | I28: =SUM(I19,I22,I25) -> 109 | J28: =SUM(J19,J22,J25) -> 95 | K28: =SUM(K19,K22,K25) -> 78 | L28: =SUM(L19,L22,L25) -> 84 | M28: =SUM(E28:L28) -> 745
D29: PR | E29: =SUM(E20,E23,E26) -> 121 | F29: =SUM(F20,F23,F26) -> 100 | G29: =SUM(G20,G23,G26) -> 83 | H29: =SUM(H20,H23,H26) -> 102 | I29: =SUM(I20,I23,I26) -> 114 | J29: =SUM(J20,J23,J26) -> 109 | K29: =SUM(K20,K23,K26) -> 85 | L29: =SUM(L20,L23,L26) -> 78 | M29: =SUM(E29:L29) -> 792
D30: JML | E30: =SUM(E28:E29) -> 221 | F30: =SUM(F28:F29) -> 183 | G30: =SUM(G28:G29) -> 184 | H30: =SUM(H28:H29) -> 197 | I30: =SUM(I28:I29) -> 223 | J30: =SUM(J28:J29) -> 204 | K30: =SUM(K28:K29) -> 163 | L30: =SUM(L28:L29) -> 162 | M30: =SUM(E30:L30) -> 1537
A32: II | B32: DATA PENGGUNAAN SURAT SUARA
A33: 1 | B33: Jumlah surat suara yang diterima, termasuk surat suara cadangan 2,5% dari DPT | E33: 300 | F33: 233 | G33: 233 | H33: 265 | I33: 268 | J33: 259 | K33: 230 | L33: 221 | M33: =SUM(E33:L33) -> 2009
A34: 2 | B34: Jumlah surat suara yang digunakan | E34: 221 | F34: 183 | G34: 184 | H34: 197 | I34: 223 | J34: 204 | K34: 163 | L34: 162 | M34: =SUM(E34:L34) -> 1537
A35: 3 | B35: Jumlah surat suara dikembalikan oleh pemilih (karena rusak atau keliru coblos) | E35: 0 | F35: 0 | G35: 1 | H35: 0 | J35: 0 | K35: 0 | L35: 0 | M35: =SUM(E35:L35) -> 1
A36: 4 | B36: Jumlah surat suara yang tidak digunakan/tidak terpakai, termasuk sisa surat suara cadangan | E36: =E33-(E34+E35) -> 79 | F36: =F33-(F34+F35) -> 50 | G36: =G33-(G34+G35) -> 48 | H36: =H33-(H34+H35) -> 68 | I36: =I33-(I34+I35) -> 45 | J36: =J33-(J34+J35) -> 55 | K36: =K33-(K34+K35) -> 67 | L36: =L33-(L34+L35) -> 59 | M36: =SUM(E36:L36) -> 471
A38: III | B38: DATA PEMILIH DISABILITAS
B39: Jumlah seluruh Pemilih disabilitas yang menggunakan hak pilih | D39: LK | E39: 0 | F39: 0 | G39: 0 | H39: 0 | I39: 0 | J39: 1 | K39: 1 | L39: 0 | M39: =SUM(E39:L39) -> 2
D40: PR | E40: 0 | F40: 0 | G40: 0 | H40: 0 | I40: 0 | J40: 1 | K40: 0 | L40: 0 | M40: =SUM(E40:L40) -> 1
D41: JML | E41: =SUM(E39:E40) -> 0 | F41: =SUM(F39:F40) -> 0 | G41: =SUM(G39:G40) -> 0 | H41: =SUM(H39:H40) -> 0 | I41: =SUM(I39:I40) -> 0 | J41: =SUM(J39:J40) -> 2 | K41: =SUM(K39:K40) -> 1 | L41: =SUM(L39:L40) -> 0 | M41: =SUM(E41:L41) -> 3
A43: IV | B43: DATA RINCIAN PEROLEHAN SUARA PASANGAN CALON BUPATI DAN WAKIL BUPATI
A44: NOMOR DAN NAMA CALON
A45: A.1 | B45: 1. | C45: Partai Kebangkitan Bangsa | E45: 9 | F45: 13 | G45: 10 | H45: 5 | I45: 6 | J45: 7 | K45: 10 | L45: 12 | M45: =SUM(E45:L45) -> 72
A46: A.2 | C46: 1. Dra. Hj. MA`MULAH HARUN, M.Pd.I. | E46: 16 | F46: 28 | G46: 25 | H46: 13 | I46: 15 | J46: 8 | K46: 10 | L46: 5 | M46: =SUM(E46:L46) -> 120
C47: 2. UBAIDILLAH, S.Fil.I. | E47: 2 | F47: 1 | G47: 1 | H47: 0 | I47: 2 | J47: 1 | K47: 1 | L47: 2 | M47: =SUM(E47:L47) -> 10
C48: 3. Ir. H. YOYOK MULYADI, M.Si. | E48: 0 | F48: 1 | G48: 0 | H48: 2 | I48: 1 | J48: 1 | K48: 1 | L48: 1 | M48: =SUM(E48:L48) -> 7
C49: 4. KHOIRUL ANWAR, S.Fil.I. | E49: 0 | F49: 1 | G49: 1 | H49: 1 | I49: 0 | J49: 0 | K49: 2 | L49: 0 | M49: =SUM(E49:L49) -> 5
C50: 5. ARIF WIJAKSANA | E50: 1 | F50: 2 | G50: 0 | H50: 1 | I50: 1 | J50: 1 | K50: 0 | L50: 0 | M50: =SUM(E50:L50) -> 6
C51: 6. Dr. SITI YUMNAH | E51: 1 | F51: 0 | G51: 0 | H51: 0 | I51: 0 | J51: 0 | K51: 0 | L51: 1 | M51: =SUM(E51:L51) -> 2
...

Sheet KLUNCING
C2: Kecamatan | D2: LICIN
C3: Kabupaten | D3: BANYUWANGI
C4: Provinsi | D4: JAWA TIMUR
C9: Kelurahan | D9: KLUNCING
A12: I | B12: DATA PEMILIH DAN PENGGUNAAN HAK PILIH | O12: JUMLAH AKHIR
A13: A | B13: DATA PEMILIH | E13: TPS 001 | F13: TPS 002 | G13: TPS 003 | H13: TPS 004 | I13: TPS 005 | J13: TPS 006 | K13: TPS 007 | L13: TPS 008 | M13: TPS 009 | N13: TPS 010
B14: Jumlah Pemilih dalam Daftar Pemilih Tetap (DPT) | D14: LK | E14: 124 | F14: 106 | G14: 134 | H14: 146 | I14: 146 | J14: 132 | K14: 138 | L14: 116 | M14: 145 | N14: 148 | O14: =SUM(E14:N14) -> 1335
D15: PR | E15: 136 | F15: 108 | G15: 147 | H15: 145 | I15: 136 | J15: 134 | K15: 144 | L15: 105 | M15: 138 | N15: 128 | O15: =SUM(E15:N15) -> 1321
D16: JML | E16: =SUM(E14:E15) -> 260 | F16: =SUM(F14:F15) -> 214 | G16: =SUM(G14:G15) -> 281 | H16: =SUM(H14:H15) -> 291 | I16: =SUM(I14:I15) -> 282 | J16: =SUM(J14:J15) -> 266 | K16: =SUM(K14:K15) -> 282 | L16: =SUM(L14:L15) -> 221 | ... N16: =SUM(N14:N15) -> 276 | O16: =SUM(E16:N16) -> 2656
A18: B | B18: PENGGUNA HAK PILIH
B19: 1. | C19: Jumlah pengguna hak pilih dalam Daftar Pemilih Tetap (DPT) | D19: LK | E19: 90 | F19: 83 | G19: 120 | H19: 112 | I19: 114 | J19: 110 | K19: 111 | L19: 96 | M19: 113 | N19: 115 | O19: =SUM(E19:N19) -> 1064
D20: PR | E20: 116 | F20: 97 | G20: 126 | H20: 125 | I20: 115 | J20: 112 | K20: 130 | L20: 93 | M20: 123 | N20: 100 | O20: =SUM(E20:N20) -> 1137
D21: JML | E21: =SUM(E19:E20) -> 206 | F21: =SUM(F19:F20) -> 180 | G21: =SUM(G19:G20) -> 246 | H21: =SUM(H19:H20) -> 237 | I21: =SUM(I19:I20) -> 229 | J21: =SUM(J19:J20) -> 222 | K21: =SUM(K19:K20) -> 241 | L21: =SUM(L19:L20) -> 189 | ... N21: =SUM(N19:N20) -> 215 | O21: =SUM(E21:N21) -> 2201
B22: 2. | C22: Jumlah pengguna hak pilih dalam Daftar Pemilih Tambahan (DPTb) | D22: LK | E22: 0 | F22: 0 | G22: 0 | H22: 0 | I22: 0 | J22: 0 | K22: 0 | L22: 0 | M22: 0 | N22: 0 | O22: =SUM(E22:N22) -> 0
D23: PR | E23: 0 | F23: 0 | G23: 0 | H23: 1 | I23: 0 | J23: 0 | K23: 0 | L23: 0 | M23: 0 | N23: 0 | O23: =SUM(E23:N23) -> 1
D24: JML | E24: =SUM(E22:E23) -> 0 | F24: =SUM(F22:F23) -> 0 | G24: =SUM(G22:G23) -> 0 | H24: =SUM(H22:H23) -> 1 | I24: =SUM(I22:I23) -> 0 | J24: =SUM(J22:J23) -> 0 | K24: =SUM(K22:K23) -> 0 | L24: =SUM(L22:L23) -> 0 | ... N24: =SUM(N22:N23) -> 0 | O24: =SUM(E24:N24) -> 1
B25: 3. | C25: Jumlah pengguna hak pilih dalam Daftar Pemilih Khusus (DPK) | D25: LK | E25: 0 | F25: 0 | G25: 0 | H25: 0 | I25: 0 | J25: 3 | K25: 0 | L25: 0 | M25: 0 | N25: 0 | O25: =SUM(E25:N25) -> 3
D26: PR | E26: 0 | F26: 0 | G26: 0 | H26: 0 | I26: 0 | J26: 1 | K26: 0 | L26: 0 | M26: 0 | N26: 0 | O26: =SUM(E26:N26) -> 1
D27: JML | E27: =SUM(E25:E26) -> 0 | F27: =SUM(F25:F26) -> 0 | G27: =SUM(G25:G26) -> 0 | H27: =SUM(H25:H26) -> 0 | I27: =SUM(I25:I26) -> 0 | J27: =SUM(J25:J26) -> 4 | K27: =SUM(K25:K26) -> 0 | L27: =SUM(L25:L26) -> 0 | ... N27: =SUM(N25:N26) -> 0 | O27: =SUM(E27:N27) -> 4
B28: 4. | C28: Jumlah Pengguna Hak Pilih (B.1+B.2+B.3) | D28: LK | E28: =SUM(E19,E22,E25) -> 90 | F28: =SUM(F19,F22,F25) -> 83 | G28: =SUM(G19,G22,G25) -> 120 | H28: =SUM(H19,H22,H25) -> 112 | I28: =SUM(I19,I22,I25) -> 114 | J28: =SUM(J19,J22,J25) -> 113 | K28: =SUM(K19,K22,K25) -> 111 | L28: =SUM(L19,L22,L25) -> 96 | ... N28: =SUM(N19,N22,N25) -> 115 | O28: =SUM(E28:N28) -> 1067
D29: PR | E29: =SUM(E20,E23,E26) -> 116 | F29: =SUM(F20,F23,F26) -> 97 | G29: =SUM(G20,G23,G26) -> 126 | H29: =SUM(H20,H23,H26) -> 126 | I29: =SUM(I20,I23,I26) -> 115 | J29: =SUM(J20,J23,J26) -> 113 | K29: =SUM(K20,K23,K26) -> 130 | L29: =SUM(L20,L23,L26) -> 93 | ... N29: =SUM(N20,N23,N26) -> 100 | O29: =SUM(E29:N29) -> 1139
D30: JML | E30: =SUM(E28:E29) -> 206 | F30: =SUM(F28:F29) -> 180 | G30: =SUM(G28:G29) -> 246 | H30: =SUM(H28:H29) -> 238 | I30: =SUM(I28:I29) -> 229 | J30: =SUM(J28:J29) -> 226 | K30: =SUM(K28:K29) -> 241 | L30: =SUM(L28:L29) -> 189 | ... N30: =SUM(N28:N29) -> 215 | O30: =SUM(E30:N30) -> 2206
A32: II | B32: DATA PENGGUNAAN SURAT SUARA
A33: 1 | B33: Jumlah surat suara yang diterima, termasuk surat suara cadangan 2,5% dari DPT | E33: 265 | F33: 218 | G33: 277 | H33: 297 | I33: 288 | J33: 272 | K33: 288 | L33: 225 | M33: 289 | N33: 282 | O33: =SUM(E33:N33) -> 2701
A34: 2 | B34: Jumlah surat suara yang digunakan | E34: 206 | F34: 180 | G34: 246 | H34: 238 | I34: 229 | J34: 226 | K34: 241 | L34: 189 | M34: 236 | N34: 215 | O34: =SUM(E34:N34) -> 2206
A35: 3 | B35: Jumlah surat suara dikembalikan oleh pemilih (karena rusak atau keliru coblos) | F35: 1 | G35: 31 | H35: 0 | I35: 0 | J35: 1 | K35: 0 | L35: 0 | M35: 0 | N35: 0 | O35: =SUM(E35:N35) -> 33
A36: 4 | B36: Jumlah surat suara yang tidak digunakan/tidak terpakai, termasuk sisa surat suara cadangan | E36: =E33-(E34+E35) -> 59 | F36: =F33-(F34+F35) -> 37 | G36: =G33-(G34+G35) -> 0 | H36: =H33-(H34+H35) -> 59 | I36: =I33-(I34+I35) -> 59 | J36: =J33-(J34+J35) -> 45 | K36: =K33-(K34+K35) -> 47 | L36: =L33-(L34+L35) -> 36 | ... N36: =N33-(N34+N35) -> 67 | O36: =SUM(E36:N36) -> 462
A38: III | B38: DATA PEMILIH DISABILITAS
B39: Jumlah seluruh Pemilih disabilitas yang menggunakan hak pilih | D39: LK | E39: 0 | F39: 0 | G39: 0 | H39: 0 | I39: 0 | J39: 0 | K39: 1 | L39: 0 | M39: 0 | N39: 0 | O39: =SUM(E39:N39) -> 1
D40: PR | E40: 0 | F40: 0 | G40: 0 | H40: 0 | I40: 0 | J40: 0 | K40: 0 | L40: 0 | M40: 0 | N40: 0 | O40: =SUM(E40:N40) -> 0
D41: JML | E41: =SUM(E39:E40) -> 0 | F41: =SUM(F39:F40) -> 0 | G41: =SUM(G39:G40) -> 0 | H41: =SUM(H39:H40) -> 0 | I41: =SUM(I39:I40) -> 0 | J41: =SUM(J39:J40) -> 0 | K41: =SUM(K39:K40) -> 1 | L41: =SUM(L39:L40) -> 0 | ... N41: =SUM(N39:N40) -> 0 | O41: =SUM(E41:N41) -> 1
A43: IV | B43: DATA RINCIAN PEROLEHAN SUARA PASANGAN CALON BUPATI DAN WAKIL BUPATI
A44: NOMOR DAN NAMA CALON
A45: A.1 | B45: 1. | C45: Partai Kebangkitan Bangsa | E45: 12 | F45: 9 | G45: 16 | H45: 10 | I45: 11 | J45: 2 | K45: 3 | L45: 8 | M45: 9 | N45: 11 | O45: =SUM(E45:N45) -> 91
A46: A.2 | C46: 1. Dra. Hj. MA`MULAH HARUN, M.Pd.I. | E46: 36 | F46: 12 | G46: 33 | H46: 21 | I46: 19 | J46: 9 | K46: 2 | L46: 26 | M46: 12 | N46: 19 | O46: =SUM(E46:N46) -> 189
C47: 2. UBAIDILLAH, S.Fil.I. | E47: 3 | F47: 1 | G47: 1 | H47: 1 | I47: 2 | J47: 3 | K47: 1 | L47: 4 | M47: 0 | N47: 2 | O47: =SUM(E47:N47) -> 18
C48: 3. Ir. H. YOYOK MULYADI, M.Si. | E48: 2 | F48: 0 | G48: 2 | H48: 1 | I48: 1 | J48: 0 | K48: 2 | L48: 0 | M48: 1 | N48: 2 | O48: =SUM(E48:N48) -> 11
C49: 4. KHOIRUL ANWAR, S.Fil.I. | E49: 0 | F49: 0 | G49: 1 | H49: 0 | I49: 3 | J49: 0 | K49: 0 | L49: 1 | M49: 2 | N49: 1 | O49: =SUM(E49:N49) -> 8
C50: 5. ARIF WIJAKSANA | E50: 1 | F50: 0 | G50: 0 | H50: 1 | I50: 0 | J50: 0 | K50: 0 | L50: 0 | M50: 0 | N50: 0 | O50: =SUM(E50:N50) -> 2
C51: 6. Dr. SITI YUMNAH | E51: 0 | F51: 0 | G51: 0 | H51: 1 | I51: 1 | J51: 0 | K51: 1 | L51: 0 | M51: 0 | N51: 1 | O51: =SUM(E51:N51) -> 4
...

Sheet LICIN
C2: Kecamatan | D2: LICIN
C3: Kabupaten | D3: BANYUWANGI
C4: Provinsi | D4: JAWA TIMUR
C9: Kelurahan | D9: LICIN
A12: I | B12: DATA PEMILIH DAN PENGGUNAAN HAK PILIH | T12: JUMLAH AKHIR
A13: A | B13: DATA PEMILIH | E13: TPS 001 | F13: TPS 002 | G13: TPS 003 | H13: TPS 004 | I13: TPS 005 | J13: TPS 006 | K13: TPS 007 | L13: TPS 008 | M13: TPS 009 | N13: TPS 010 | O13: TPS 011 | P13: TPS 012 | Q13: TPS 013 | R13: TPS 014 | S13: TPS 015
B14: Jumlah Pemilih dalam Daftar Pemilih Tetap (DPT) | D14: LK | E14: 104 | F14: 118 | G14: 112 | H14: 124 | I14: 139 | J14: 110 | K14: 87 | L14: 82 | M14: 117 | N14: 84 | O14: 87 | P14: 83 | Q14: 74 | R14: 124 | S14: 99 | T14: =SUM(E14:S14) -> 1544
D15: PR | E15: 104 | F15: 135 | G15: 116 | H15: 152 | I15: 131 | J15: 131 | K15: 94 | L15: 92 | M15: 111 | N15: 88 | O15: 91 | P15: 75 | Q15: 80 | R15: 122 | S15: 90 | T15: =SUM(E15:S15) -> 1612
D16: JML | E16: =SUM(E14:E15) -> 208 | F16: =SUM(F14:F15) -> 253 | G16: =SUM(G14:G15) -> 228 | H16: =SUM(H14:H15) -> 276 | I16: =SUM(I14:I15) -> 270 | J16: =SUM(J14:J15) -> 241 | K16: =SUM(K14:K15) -> 181 | L16: =SUM(L14:L15) -> 174 | ... S16: =SUM(S14:S15) -> 189 | T16: =SUM(E16:S16) -> 3156
A18: B | B18: PENGGUNA HAK PILIH
B19: 1. | C19: Jumlah pengguna hak pilih dalam Daftar Pemilih Tetap (DPT) | D19: LK | E19: 80 | F19: 86 | G19: 85 | H19: 102 | I19: 99 | J19: 85 | K19: 64 | L19: 66 | M19: 90 | N19: 67 | O19: 62 | P19: 69 | Q19: 60 | R19: 107 | S19: 86 | T19: =SUM(E19:S19) -> 1208
D20: PR | E20: 81 | F20: 102 | G20: 89 | H20: 126 | I20: 114 | J20: 102 | K20: 76 | L20: 79 | M20: 96 | N20: 76 | O20: 60 | P20: 67 | Q20: 71 | R20: 110 | S20: 80 | T20: =SUM(E20:S20) -> 1329
D21: JML | E21: =SUM(E19:E20) -> 161 | F21: =SUM(F19:F20) -> 188 | G21: =SUM(G19:G20) -> 174 | H21: =SUM(H19:H20) -> 228 | I21: =SUM(I19:I20) -> 213 | J21: =SUM(J19:J20) -> 187 | K21: =SUM(K19:K20) -> 140 | L21: =SUM(L19:L20) -> 145 | ... S21: =SUM(S19:S20) -> 166 | T21: =SUM(E21:S21) -> 2537
B22: 2. | C22: Jumlah pengguna hak pilih dalam Daftar Pemilih Tambahan (DPTb) | D22: LK | E22: 0 | F22: 0 | G22: 0 | H22: 0 | I22: 0 | J22: 0 | K22: 0 | L22: 0 | M22: 0 | N22: 0 | O22: 1 | P22: 0 | Q22: 0 | R22: 0 | S22: 0 | T22: =SUM(E22:S22) -> 1
D23: PR | E23: 0 | F23: 0 | G23: 0 | H23: 0 | I23: 0 | J23: 0 | K23: 0 | L23: 0 | M23: 0 | N23: 0 | O23: 2 | P23: 0 | Q23: 0 | R23: 0 | S23: 0 | T23: =SUM(E23:S23) -> 2
D24: JML | E24: 0 | F24: =SUM(F22:F23) -> 0 | G24: =SUM(G22:G23) -> 0 | H24: =SUM(H22:H23) -> 0 | I24: =SUM(I22:I23) -> 0 | J24: =SUM(J22:J23) -> 0 | K24: =SUM(K22:K23) -> 0 | L24: =SUM(L22:L23) -> 0 | M24: =SUM(M22:M23) -> 0 | ... S24: =SUM(S22:S23) -> 0 | T24: =SUM(E24:S24) -> 3
B25: 3. | C25: Jumlah pengguna hak pilih dalam Daftar Pemilih Khusus (DPK) | D25: LK | E25: 0 | F25: 0 | G25: 0 | H25: 0 | I25: 0 | J25: 0 | K25: 0 | L25: 1 | M25: 0 | N25: 0 | O25: 0 | P25: 0 | Q25: 0 | R25: 0 | S25: 0 | T25: =SUM(E25:S25) -> 1
D26: PR | E26: 0 | F26: 0 | G26: 0 | H26: 0 | I26: 0 | J26: 0 | K26: 3 | L26: 1 | M26: 0 | N26: 0 | O26: 0 | P26: 2 | Q26: 0 | R26: 0 | S26: 0 | T26: =SUM(E26:S26) -> 6
D27: JML | E27: =SUM(E25:E26) -> 0 | F27: =SUM(F25:F26) -> 0 | G27: =SUM(G25:G26) -> 0 | H27: =SUM(H25:H26) -> 0 | I27: =SUM(I25:I26) -> 0 | J27: =SUM(J25:J26) -> 0 | K27: =SUM(K25:K26) -> 3 | L27: =SUM(L25:L26) -> 2 | ... S27: =SUM(S25:S26) -> 0 | T27: =SUM(E27:S27) -> 7
B28: 4. | C28: Jumlah Pengguna Hak Pilih (B.1+B.2+B.3) | D28: LK | E28: =SUM(E19,E22,E25) -> 80 | F28: =SUM(F19,F22,F25) -> 86 | G28: =SUM(G19,G22,G25) -> 85 | H28: =SUM(H19,H22,H25) -> 102 | I28: =SUM(I19,I22,I25) -> 99 | J28: =SUM(J19,J22,J25) -> 85 | K28: =SUM(K19,K22,K25) -> 64 | L28: =SUM(L19,L22,L25) -> 67 | ... S28: =SUM(S19,S22,S25) -> 86 | T28: =SUM(E28:S28) -> 1210
D29: PR | E29: =SUM(E20,E23,E26) -> 81 | F29: =SUM(F20,F23,F26) -> 102 | G29: =SUM(G20,G23,G26) -> 89 | H29: =SUM(H20,H23,H26) -> 126 | I29: =SUM(I20,I23,I26) -> 114 | J29: =SUM(J20,J23,J26) -> 102 | K29: =SUM(K20,K23,K26) -> 79 | L29: =SUM(L20,L23,L26) -> 80 | ... S29: =SUM(S20,S23,S26) -> 80 | T29: =SUM(E29:S29) -> 1337
D30: JML | E30: =SUM(E28:E29) -> 161 | F30: =SUM(F28:F29) -> 188 | G30: =SUM(G28:G29) -> 174 | H30: =SUM(H28:H29) -> 228 | I30: =SUM(I28:I29) -> 213 | J30: =SUM(J28:J29) -> 187 | K30: =SUM(K28:K29) -> 143 | L30: =SUM(L28:L29) -> 147 | ... S30: =SUM(S28:S29) -> 166 | T30: =SUM(E30:S30) -> 2547
A32: II | B32: DATA PENGGUNAAN SURAT SUARA
A33: 1 | B33: Jumlah surat suara yang diterima, termasuk surat suara cadangan 2,5% dari DPT | E33: 213 | F33: 259 | G33: 233 | H33: 282 | I33: 276 | J33: 246 | K33: 185 | L33: 178 | M33: 233 | N33: 175 | O33: 182 | P33: 162 | Q33: 158 | R33: 251 | S33: 193 | T33: =SUM(E33:S33) -> 3226
A34: 2 | B34: Jumlah surat suara yang digunakan | E34: 161 | F34: 188 | G34: 174 | H34: 228 | I34: 213 | J34: 187 | K34: 143 | L34: 147 | M34: 186 | N34: 143 | O34: 125 | P34: 138 | Q34: 131 | R34: 217 | S34: 166 | T34: =SUM(E34:S34) -> 2547
A35: 3 | B35: Jumlah surat suara dikembalikan oleh pemilih (karena rusak atau keliru coblos) | E35: 0 | F35: 0 | G35: 0 | H35: 0 | I35: 0 | J35: 0 | K35: 0 | L35: 0 | M35: 0 | N35: 0 | O35: 0 | P35: 0 | Q35: 0 | R35: 1 | S35: 0 | T35: =SUM(E35:S35) -> 1
A36: 4 | B36: Jumlah surat suara yang tidak digunakan/tidak terpakai, termasuk sisa surat suara cadangan | E36: =E33-(E34+E35) -> 52 | F36: =F33-(F34+F35) -> 71 | G36: =G33-(G34+G35) -> 59 | H36: =H33-(H34+H35) -> 54 | I36: =I33-(I34+I35) -> 63 | J36: =J33-(J34+J35) -> 59 | K36: =K33-(K34+K35) -> 42 | L36: =L33-(L34+L35) -> 31 | ... S36: =S33-(S34+S35) -> 27 | T36: =SUM(E36:S36) -> 678
A38: III | B38: DATA PEMILIH DISABILITAS
B39: Jumlah seluruh Pemilih disabilitas yang menggunakan hak pilih | D39: LK | E39: 0 | F39: 0 | G39: 0 | H39: 1 | I39: 0 | J39: 0 | K39: 0 | L39: 0 | M39: 0 | N39: 0 | O39: 0 | P39: 1 | Q39: 0 | R39: 0 | S39: 1 | T39: =SUM(E39:S39) -> 3
D40: PR | E40: 0 | F40: 0 | G40: 0 | H40: 1 | I40: 0 | J40: 0 | K40: 0 | L40: 0 | M40: 0 | N40: 0 | O40: 1 | P40: 3 | Q40: 0 | R40: 3 | S40: 0 | T40: =SUM(E40:S40) -> 8
D41: JML | E41: =SUM(E39:E40) -> 0 | F41: =SUM(F39:F40) -> 0 | G41: =SUM(G39:G40) -> 0 | H41: =SUM(H39:H40) -> 2 | I41: =SUM(I39:I40) -> 0 | J41: =SUM(J39:J40) -> 0 | K41: =SUM(K39:K40) -> 0 | L41: =SUM(L39:L40) -> 0 | ... S41: =SUM(S39:S40) -> 1 | T41: =SUM(E41:S41) -> 11
A43: IV | B43: DATA RINCIAN PEROLEHAN SUARA PASANGAN CALON BUPATI DAN WAKIL BUPATI
A44: NOMOR DAN NAMA CALON
A45: A.1 | B45: 1. | C45: Partai Kebangkitan Bangsa | E45: 10 | F45: 14 | G45: 12 | H45: 17 | I45: 16 | J45: 20 | K45: 6 | L45: 9 | M45: 9 | N45: 11 | O45: 10 | P45: 3 | Q45: 9 | R45: 7 | S45: 7 | T45: =SUM(E45:S45) -> 160
A46: A.2 | C46: 1. Dra. Hj. MA`MULAH HARUN, M.Pd.I. | E46: 17 | F46: 45 | G46: 31 | H46: 77 | I46: 42 | J46: 43 | K46: 10 | L46: 23 | M46: 23 | N46: 16 | O46: 25 | P46: 15 | Q46: 7 | R46: 23 | S46: 47 | T46: =SUM(E46:S46) -> 444
C47: 2. UBAIDILLAH, S.Fil.I. | E47: 0 | F47: 1 | G47: 1 | H47: 0 | I47: 2 | J47: 0 | K47: 0 | L47: 1 | M47: 1 | N47: 1 | O47: 0 | P47: 2 | Q47: 0 | R47: 3 | S47: 2 | T47: =SUM(E47:S47) -> 14
C48: 3. Ir. H. YOYOK MULYADI, M.Si. | E48: 0 | F48: 3 | G48: 0 | H48: 0 | I48: 0 | J48: 3 | K48: 0 | L48: 0 | M48: 3 | N48: 0 | O48: 0 | P48: 1 | Q48: 1 | R48: 1 | S48: 1 | T48: =SUM(E48:S48) -> 13
C49: 4. KHOIRUL ANWAR, S.Fil.I. | E49: 0 | F49: 2 | G49: 0 | H49: 0 | I49: 1 | J49: 0 | K49: 0 | L49: 1 | M49: 1 | N49: 0 | O49: 0 | P49: 1 | Q49: 2 | R49: 0 | S49: 0 | T49: =SUM(E49:S49) -> 8
C50: 5. ARIF WIJAKSANA | E50: 0 | F50: 0 | G50: 1 | H50: 0 | I50: 0 | J50: 2 | K50: 0 | L50: 0 | M50: 0 | N50: 1 | O50: 0 | P50: 0 | Q50: 2 | R50: 0 | S50: 1 | T50: =SUM(E50:S50) -> 7
C51: 6. Dr. SITI YUMNAH | E51: 0 | F51: 0 | G51: 0 | H51: 0 | I51: 0 | J51: 0 | K51: 0 | L51: 0 | M51: 0 | N51: 0 | O51: 0 | P51: 0 | Q51: 0 | R51: 2 | S51: 0 | T51: =SUM(E51:S51) -> 2
...

Sheet PAKEL
C2: Kecamatan | D2: LICIN
C3: Kabupaten | D3: BANYUWANGI
C4: Provinsi | D4: JAWA TIMUR
C9: Kelurahan | D9: PAKEL
A12: I | B12: DATA PEMILIH DAN PENGGUNAAN HAK PILIH | N12: JUMLAH AKHIR
A13: A | B13: DATA PEMILIH | E13: TPS 001 | F13: TPS 002 | G13: TPS 003 | H13: TPS 004 | I13: TPS 005 | J13: TPS 006 | K13: TPS 007 | L13: TPS 008 | M13: TPS 009
B14: Jumlah Pemilih dalam Daftar Pemilih Tetap (DPT) | D14: LK | E14: 126 | F14: 128 | G14: 135 | H14: 133 | I14: 128 | J14: 97 | K14: 97 | L14: 106 | M14: 98 | N14: =SUM(E14:M14) -> 1048
D15: PR | E15: 131 | F15: 129 | G15: 133 | H15: 142 | I15: 133 | J15: 105 | K15: 103 | L15: 96 | M15: 107 | N15: =SUM(E15:M15) -> 1079
D16: JML | E16: =SUM(E14:E15) -> 257 | F16: =SUM(F14:F15) -> 257 | G16: =SUM(G14:G15) -> 268 | H16: =SUM(H14:H15) -> 275 | I16: =SUM(I14:I15) -> 261 | J16: =SUM(J14:J15) -> 202 | K16: =SUM(K14:K15) -> 200 | L16: =SUM(L14:L15) -> 202 | M16: =SUM(M14:M15) -> 205 | N16: =SUM(E16:M16) -> 2127
A18: B | B18: PENGGUNA HAK PILIH
B19: 1. | C19: Jumlah pengguna hak pilih dalam Daftar Pemilih Tetap (DPT) | D19: LK | E19: 89 | F19: 91 | G19: 102 | H19: 91 | I19: 94 | J19: 74 | K19: 72 | L19: 76 | M19: 71 | N19: =SUM(E19:M19) -> 760
D20: PR | E20: 110 | F20: 97 | G20: 104 | H20: 111 | I20: 104 | J20: 88 | K20: 82 | L20: 76 | M20: 76 | N20: =SUM(E20:M20) -> 848
D21: JML | E21: =SUM(E19:E20) -> 199 | F21: =SUM(F19:F20) -> 188 | G21: =SUM(G19:G20) -> 206 | H21: =SUM(H19:H20) -> 202 | I21: =SUM(I19:I20) -> 198 | J21: =SUM(J19:J20) -> 162 | K21: =SUM(K19:K20) -> 154 | L21: =SUM(L19:L20) -> 152 | M21: =SUM(M19:M20) -> 147 | N21: =SUM(E21:M21) -> 1608
B22: 2. | C22: Jumlah pengguna hak pilih dalam Daftar Pemilih Tambahan (DPTb) | D22: LK | E22: 0 | F22: 0 | G22: 0 | H22: 0 | I22: 0 | J22: 0 | K22: 0 | L22: 0 | M22: 0 | N22: =SUM(E22:M22) -> 0
D23: PR | E23: 0 | F23: 0 | G23: 0 | H23: 0 | I23: 0 | J23: 0 | K23: 0 | L23: 1 | M23: 0 | N23: =SUM(E23:M23) -> 1
D24: JML | E24: =SUM(E22:E23) -> 0 | F24: =SUM(F22:F23) -> 0 | G24: =SUM(G22:G23) -> 0 | H24: =SUM(H22:H23) -> 0 | I24: =SUM(I22:I23) -> 0 | J24: =SUM(J22:J23) -> 0 | K24: =SUM(K22:K23) -> 0 | L24: =SUM(L22:L23) -> 1 | M24: =SUM(M22:M23) -> 0 | N24: =SUM(E24:M24) -> 1
B25: 3. | C25: Jumlah pengguna hak pilih dalam Daftar Pemilih Khusus (DPK) | D25: LK | E25: 0 | F25: 1 | G25: 2 | H25: 0 | I25: 1 | J25: 0 | K25: 0 | L25: 0 | M25: 0 | N25: =SUM(E25:M25) -> 4
D26: PR | E26: 0 | F26: 1 | G26: 0 | H26: 0 | I26: 0 | J26: 0 | K26: 0 | L26: 0 | M26: 0 | N26: =SUM(E26:M26) -> 1
D27: JML | E27: =SUM(E25:E26) -> 0 | F27: =SUM(F25:F26) -> 2 | G27: =SUM(G25:G26) -> 2 | H27: =SUM(H25:H26) -> 0 | I27: =SUM(I25:I26) -> 1 | J27: =SUM(J25:J26) -> 0 | K27: =SUM(K25:K26) -> 0 | L27: =SUM(L25:L26) -> 0 | M27: =SUM(M25:M26) -> 0 | N27: =SUM(E27:M27) -> 5
B28: 4. | C28: Jumlah Pengguna Hak Pilih (B.1+B.2+B.3) | D28: LK | E28: =SUM(E19,E22,E25) -> 89 | F28: =SUM(F19,F22,F25) -> 92 | G28: =SUM(G19,G22,G25) -> 104 | H28: =SUM(H19,H22,H25) -> 91 | I28: =SUM(I19,I22,I25) -> 95 | J28: =SUM(J19,J22,J25) -> 74 | K28: =SUM(K19,K22,K25) -> 72 | L28: =SUM(L19,L22,L25) -> 76 | M28: =SUM(M19,M22,M25) -> 71 | N28: =SUM(E28:M28) -> 764
D29: PR | E29: =SUM(E20,E23,E26) -> 110 | F29: =SUM(F20,F23,F26) -> 98 | G29: =SUM(G20,G23,G26) -> 104 | H29: =SUM(H20,H23,H26) -> 111 | I29: =SUM(I20,I23,I26) -> 104 | J29: =SUM(J20,J23,J26) -> 88 | K29: =SUM(K20,K23,K26) -> 82 | L29: =SUM(L20,L23,L26) -> 77 | M29: =SUM(M20,M23,M26) -> 76 | N29: =SUM(E29:M29) -> 850
D30: JML | E30: =SUM(E28:E29) -> 199 | F30: =SUM(F28:F29) -> 190 | G30: =SUM(G28:G29) -> 208 | H30: =SUM(H28:H29) -> 202 | I30: =SUM(I28:I29) -> 199 | J30: =SUM(J28:J29) -> 162 | K30: =SUM(K28:K29) -> 154 | L30: =SUM(L28:L29) -> 153 | M30: =SUM(M28:M29) -> 147 | N30: =SUM(E30:M30) -> 1614
A32: II | B32: DATA PENGGUNAAN SURAT SUARA
A33: 1 | B33: Jumlah surat suara yang diterima, termasuk surat suara cadangan 2,5% dari DPT | E33: 262 | F33: 263 | G33: 272 | H33: 291 | I33: 270 | J33: 207 | K33: 204 | L33: 207 | M33: 210 | N33: =SUM(E33:M33) -> 2186
A34: 2 | B34: Jumlah surat suara yang digunakan | E34: 199 | F34: 190 | G34: 208 | H34: 202 | I34: 199 | J34: 162 | K34: 154 | L34: 153 | M34: 147 | N34: =SUM(E34:M34) -> 1614
A35: 3 | B35: Jumlah surat suara dikembalikan oleh pemilih (karena rusak atau keliru coblos) | E35: 0 | F35: 0 | G35: 0 | H35: 2 | I35: 0 | J35: 0 | K35: 0 | L35: 1 | M35: 0 | N35: =SUM(E35:M35) -> 3
A36: 4 | B36: Jumlah surat suara yang tidak digunakan/tidak terpakai, termasuk sisa surat suara cadangan | E36: =E33-(E34+E35) -> 63 | F36: =F33-(F34+F35) -> 73 | G36: =G33-(G34+G35) -> 64 | H36: =H33-(H34+H35) -> 87 | I36: =I33-(I34+I35) -> 71 | J36: =J33-(J34+J35) -> 45 | K36: =K33-(K34+K35) -> 50 | L36: =L33-(L34+L35) -> 53 | M36: =M33-(M34+M35) -> 63 | N36: =SUM(E36:M36) -> 569
A38: III | B38: DATA PEMILIH DISABILITAS
B39: Jumlah seluruh Pemilih disabilitas yang menggunakan hak pilih | D39: LK | E39: 0 | F39: 0 | G39: 0 | H39: 0 | I39: 0 | J39: 0 | K39: 0 | L39: 0 | M39: 0 | N39: =SUM(E39:M39) -> 0
D40: PR | E40: 0 | F40: 0 | G40: 0 | H40: 0 | I40: 0 | J40: 0 | K40: 0 | L40: 0 | M40: 0 | N40: =SUM(E40:M40) -> 0
D41: JML | E41: =SUM(E39:E40) -> 0 | F41: =SUM(F39:F40) -> 0 | G41: =SUM(G39:G40) -> 0 | H41: =SUM(H39:H40) -> 0 | I41: =SUM(I39:I40) -> 0 | J41: =SUM(J39:J40) -> 0 | K41: =SUM(K39:K40) -> 0 | L41: =SUM(L39:L40) -> 0 | M41: =SUM(M39:M40) -> 0 | N41: =SUM(E41:M41) -> 0
A43: IV | B43: DATA RINCIAN PEROLEHAN SUARA PASANGAN CALON BUPATI DAN WAKIL BUPATI
A44: NOMOR DAN NAMA CALON
A45: A.1 | B45: 1. | C45: Partai Kebangkitan Bangsa | E45: 6 | F45: 14 | G45: 6 | H45: 9 | I45: 12 | J45: 4 | K45: 17 | L45: 5 | M45: 12 | N45: =SUM(E45:M45) -> 85
A46: A.2 | C46: 1. Dra. Hj. MA`MULAH HARUN, M.Pd.I. | E46: 14 | F46: 9 | G46: 15 | H46: 21 | I46: 23 | J46: 12 | K46: 15 | L46: 33 | M46: 14 | N46: =SUM(E46:M46) -> 156
C47: 2. UBAIDILLAH, S.Fil.I. | E47: 2 | F47: 1 | G47: 5 | H47: 3 | I47: 7 | J47: 4 | K47: 2 | L47: 7 | M47: 1 | N47: =SUM(E47:M47) -> 32
C48: 3. Ir. H. YOYOK MULYADI, M.Si. | E48: 1 | F48: 1 | G48: 0 | H48: 1 | I48: 0 | J48: 0 | K48: 0 | L48: 0 | M48: 2 | N48: =SUM(E48:M48) -> 5
C49: 4. KHOIRUL ANWAR, S.Fil.I. | E49: 2 | F49: 9 | G49: 10 | H49: 2 | I49: 2 | J49: 8 | K49: 7 | L49: 3 | M49: 7 | N49: =SUM(E49:M49) -> 50
C50: 5. ARIF WIJAKSANA | E50: 3 | F50: 1 | G50: 1 | H50: 2 | I50: 0 | J50: 1 | K50: 0 | L50: 0 | M50: 4 | N50: =SUM(E50:M50) -> 12
C51: 6. Dr. SITI YUMNAH | E51: 1 | F51: 0 | G51: 0 | H51: 0 | I51: 0 | J51: 0 | K51: 0 | L51: 0 | M51: 1 | N51: =SUM(E51:M51) -> 2
...

Sheet SEGOBANG
C2: Kecamatan | D2: LICIN
C3: Kabupaten | D3: BANYUWANGI
C4: Provinsi | D4: JAWA TIMUR
C9: Kelurahan | D9: SEGOBANG
A12: I | B12: DATA PEMILIH DAN PENGGUNAAN HAK PILIH | W12: JUMLAH AKHIR
A13: A | B13: DATA PEMILIH | E13: TPS 001 | F13: TPS 002 | G13: TPS 003 | H13: TPS 004 | I13: TPS 005 | J13: TPS 006 | K13: TPS 007 | L13: TPS 008 | M13: TPS 009 | N13: TPS 010 | O13: TPS 011 | P13: TPS 012 | Q13: TPS 013 | R13: TPS 014 | S13: TPS 015 | T13: TPS 016 | U13: TPS 017 | V13: TPS 018
B14: Jumlah Pemilih dalam Daftar Pemilih Tetap (DPT) | D14: LK | E14: 92 | F14: 63 | G14: 139 | H14: 138 | I14: 122 | J14: 137 | K14: 148 | L14: 125 | M14: 94 | N14: 142 | O14: 121 | P14: 119 | Q14: 128 | R14: 150 | S14: 132 | T14: 108 | U14: 132 | V14: 144 | W14: =SUM(E14:V14) -> 2234
D15: PR | E15: 84 | F15: 65 | G15: 137 | H15: 129 | I15: 118 | J15: 133 | K15: 135 | L15: 117 | M15: 105 | N15: 132 | O15: 124 | P15: 113 | Q15: 141 | R15: 135 | S15: 145 | T15: 102 | U15: 126 | V15: 143 | W15: =SUM(E15:V15) -> 2184
D16: JML | E16: =SUM(E14:E15) -> 176 | F16: =SUM(F14:F15) -> 128 | G16: =SUM(G14:G15) -> 276 | H16: =SUM(H14:H15) -> 267 | I16: =SUM(I14:I15) -> 240 | J16: =SUM(J14:J15) -> 270 | K16: =SUM(K14:K15) -> 283 | L16: =SUM(L14:L15) -> 242 | ... V16: =SUM(V14:V15) -> 287 | W16: =SUM(E16:V16) -> 4418
A18: B | B18: PENGGUNA HAK PILIH
B19: 1. | C19: Jumlah pengguna hak pilih dalam Daftar Pemilih Tetap (DPT) | D19: LK | E19: 73 | F19: 46 | G19: 100 | H19: 97 | I19: 89 | J19: 102 | K19: 97 | L19: 94 | M19: 74 | N19: 106 | O19: 90 | P19: 91 | Q19: 102 | R19: 104 | S19: 101 | T19: 80 | U19: 101 | V19: 106 | W19: =SUM(E19:V19) -> 1653
D20: PR | E20: 68 | F20: 58 | G20: 111 | H20: 111 | I20: 91 | J20: 104 | K20: 100 | L20: 97 | M20: 86 | N20: 117 | O20: 96 | P20: 90 | Q20: 115 | R20: 111 | S20: 113 | T20: 90 | U20: 108 | V20: 111 | W20: =SUM(E20:V20) -> 1777
D21: JML | E21: =SUM(E19:E20) -> 141 | F21: =SUM(F19:F20) -> 104 | G21: =SUM(G19:G20) -> 211 | H21: =SUM(H19:H20) -> 208 | I21: =SUM(I19:I20) -> 180 | J21: =SUM(J19:J20) -> 206 | K21: =SUM(K19:K20) -> 197 | L21: =SUM(L19:L20) -> 191 | ... V21: =SUM(V19:V20) -> 217 | W21: =SUM(E21:V21) -> 3430
B22: 2. | C22: Jumlah pengguna hak pilih dalam Daftar Pemilih Tambahan (DPTb) | D22: LK | E22: 0 | F22: 0 | G22: 0 | H22: 0 | I22: 0 | J22: 0 | K22: 0 | L22: 0 | M22: 0 | N22: 0 | O22: 0 | P22: 0 | Q22: 0 | R22: 0 | S22: 0 | T22: 1 | U22: 0 | V22: 0 | W22: =SUM(E22:V22) -> 1
D23: PR | E23: 0 | F23: 0 | G23: 0 | H23: 0 | I23: 0 | J23: 0 | K23: 0 | L23: 0 | M23: 0 | N23: 0 | O23: 0 | P23: 0 | Q23: 0 | R23: 0 | S23: 0 | T23: 0 | U23: 0 | V23: 0 | W23: =SUM(E23:V23) -> 0
D24: JML | E24: =SUM(E22:E23) -> 0 | F24: =SUM(F22:F23) -> 0 | G24: =SUM(G22:G23) -> 0 | H24: =SUM(H22:H23) -> 0 | I24: =SUM(I22:I23) -> 0 | J24: =SUM(J22:J23) -> 0 | K24: =SUM(K22:K23) -> 0 | L24: =SUM(L22:L23) -> 0 | ... V24: =SUM(V22:V23) -> 0 | W24: =SUM(E24:V24) -> 1
B25: 3. | C25: Jumlah pengguna hak pilih dalam Daftar Pemilih Khusus (DPK) | D25: LK | E25: 0 | F25: 0 | G25: 2 | H25: 0 | I25: 1 | J25: 0 | K25: 0 | L25: 0 | M25: 0 | N25: 2 | O25: 1 | P25: 0 | Q25: 0 | R25: 1 | S25: 3 | T25: 0 | U25: 0 | V25: 1 | W25: =SUM(E25:V25) -> 11
D26: PR | E26: 0 | F26: 0 | G26: 1 | H26: 0 | I26: 1 | J26: 0 | K26: 0 | L26: 0 | M26: 0 | N26: 1 | O26: 0 | P26: 0 | Q26: 0 | R26: 0 | S26: 1 | T26: 0 | U26: 1 | V26: 0 | W26: =SUM(E26:V26) -> 5
D27: JML | E27: =SUM(E25:E26) -> 0 | F27: =SUM(F25:F26) -> 0 | G27: =SUM(G25:G26) -> 3 | H27: =SUM(H25:H26) -> 0 | I27: =SUM(I25:I26) -> 2 | J27: =SUM(J25:J26) -> 0 | K27: =SUM(K25:K26) -> 0 | L27: =SUM(L25:L26) -> 0 | ... V27: =SUM(V25:V26) -> 1 | W27: =SUM(E27:V27) -> 16
B28: 4. | C28: Jumlah Pengguna Hak Pilih (B.1+B.2+B.3) | D28: LK | E28: =SUM(E19,E22,E25) -> 73 | F28: =SUM(F19,F22,F25) -> 46 | G28: =SUM(G19,G22,G25) -> 102 | H28: =SUM(H19,H22,H25) -> 97 | I28: =SUM(I19,I22,I25) -> 90 | J28: =SUM(J19,J22,J25) -> 102 | K28: =SUM(K19,K22,K25) -> 97 | L28: =SUM(L19,L22,L25) -> 94 | ... V28: =SUM(V19,V22,V25) -> 107 | W28: =SUM(E28:V28) -> 1665
D29: PR | E29: =SUM(E20,E23,E26) -> 68 | F29: =SUM(F20,F23,F26) -> 58 | G29: =SUM(G20,G23,G26) -> 112 | H29: =SUM(H20,H23,H26) -> 111 | I29: =SUM(I20,I23,I26) -> 92 | J29: =SUM(J20,J23,J26) -> 104 | K29: =SUM(K20,K23,K26) -> 100 | L29: =SUM(L20,L23,L26) -> 97 | ... V29: =SUM(V20,V23,V26) -> 111 | W29: =SUM(E29:V29) -> 1782
D30: JML | E30: =SUM(E28:E29) -> 141 | F30: =SUM(F28:F29) -> 104 | G30: =SUM(G28:G29) -> 214 | H30: =SUM(H28:H29) -> 208 | I30: =SUM(I28:I29) -> 182 | J30: =SUM(J28:J29) -> 206 | K30: =SUM(K28:K29) -> 197 | L30: =SUM(L28:L29) -> 191 | ... V30: =SUM(V28:V29) -> 218 | W30: =SUM(E30:V30) -> 3447
A32: II | B32: DATA PENGGUNAAN SURAT SUARA
A33: 1 | B33: Jumlah surat suara yang diterima, termasuk surat suara cadangan 2,5% dari DPT | E33: 180 | F33: 131 | G33: 282 | H33: 273 | I33: 245 | J33: 276 | K33: 289 | L33: 247 | M33: 202 | N33: 280 | O33: 250 | P33: 237 | Q33: 275 | R33: 291 | S33: 284 | T33: 216 | U33: 264 | V33: 291 | W33: =SUM(E33:V33) -> 4513
A34: 2 | B34: Jumlah surat suara yang digunakan | E34: 141 | F34: 104 | G34: 214 | H34: 208 | I34: 182 | J34: 206 | K34: 197 | L34: 191 | M34: 160 | N34: 226 | O34: 187 | P34: 181 | Q34: 217 | R34: 216 | S34: 218 | T34: 171 | U34: 210 | V34: 218 | W34: =SUM(E34:V34) -> 3447
A35: 3 | B35: Jumlah surat suara dikembalikan oleh pemilih (karena rusak atau keliru coblos) | E35: 0 | F35: 0 | G35: 0 | H35: 0 | I35: 0 | J35: 0 | K35: 1 | L35: 0 | M35: 0 | N35: 0 | O35: 0 | P35: 0 | Q35: 0 | R35: 0 | S35: 0 | T35: 0 | U35: 0 | V35: 1 | W35: =SUM(E35:V35) -> 2
A36: 4 | B36: Jumlah surat suara yang tidak digunakan/tidak terpakai, termasuk sisa surat suara cadangan | E36: =E33-(E34+E35) -> 39 | F36: =F33-(F34+F35) -> 27 | G36: =G33-(G34+G35) -> 68 | H36: =H33-(H34+H35) -> 65 | I36: =I33-(I34+I35) -> 63 | J36: =J33-(J34+J35) -> 70 | K36: =K33-(K34+K35) -> 91 | L36: =L33-(L34+L35) -> 56 | ... V36: =V33-(V34+V35) -> 72 | W36: =SUM(E36:V36) -> 1064
A38: III | B38: DATA PEMILIH DISABILITAS
B39: Jumlah seluruh Pemilih disabilitas yang menggunakan hak pilih | D39: LK | E39: 0 | F39: 1 | G39: 0 | H39: 0 | I39: 0 | J39: 0 | K39: 0 | L39: 0 | M39: 0 | N39: 1 | O39: 0 | P39: 0 | Q39: 0 | R39: 1 | S39: 1 | T39: 1 | U39: 0 | V39: 0 | W39: =SUM(E39:V39) -> 5
D40: PR | E40: 0 | F40: 2 | G40: 0 | H40: 0 | I40: 0 | J40: 0 | K40: 0 | L40: 0 | M40: 1 | N40: 0 | O40: 0 | P40: 0 | Q40: 0 | R40: 1 | S40: 0 | T40: 1 | U40: 0 | V40: 0 | W40: =SUM(E40:V40) -> 5
D41: JML | E41: =SUM(E39:E40) -> 0 | F41: =SUM(F39:F40) -> 3 | G41: =SUM(G39:G40) -> 0 | H41: =SUM(H39:H40) -> 0 | I41: =SUM(I39:I40) -> 0 | J41: =SUM(J39:J40) -> 0 | K41: =SUM(K39:K40) -> 0 | L41: =SUM(L39:L40) -> 0 | ... V41: =SUM(V39:V40) -> 0 | W41: =SUM(E41:V41) -> 10
A43: IV | B43: DATA PEROLEHAN SUARA PARTAI POLITIK DAN SUARA CALON
A44: NOMOR DAN NAMA CALON
A45: A.1 | B45: 1. | C45: Partai Kebangkitan Bangsa | E45: 4 | F45: 8 | G45: 13 | H45: 7 | I45: 9 | J45: 12 | K45: 8 | L45: 8 | M45: 8 | N45: 21 | O45: 14 | P45: 15 | Q45: 9 | R45: 12 | S45: 4 | T45: 14 | U45: 20 | V45: 11 | W45: =SUM(E45:V45) -> 197
A46: A.2 | C46: 1. Dra. Hj. MA`MULAH HARUN, M.Pd.I. | E46: 12 | F46: 25 | G46: 32 | H46: 23 | I46: 13 | J46: 14 | K46: 31 | L46: 24 | M46: 20 | N46: 37 | O46: 21 | P46: 23 | Q46: 15 | R46: 10 | S46: 28 | T46: 19 | U46: 19 | V46: 16 | W46: =SUM(E46:V46) -> 382
C47: 2. UBAIDILLAH, S.Fil.I. | E47: 0 | F47: 0 | G47: 0 | H47: 3 | I47: 0 | J47: 2 | K47: 2 | L47: 1 | M47: 1 | N47: 4 | O47: 2 | P47: 1 | Q47: 3 | R47: 2 | S47: 1 | T47: 1 | U47: 0 | V47: 1 | W47: =SUM(E47:V47) -> 24
C48: 3. Ir. H. YOYOK MULYADI, M.Si. | E48: 0 | F48: 0 | G48: 2 | H48: 1 | I48: 1 | J48: 0 | K48: 1 | L48: 0 | M48: 3 | N48: 3 | O48: 2 | P48: 1 | Q48: 1 | R48: 3 | S48: 0 | T48: 0 | U48: 3 | V48: 0 | W48: =SUM(E48:V48) -> 21
C49: 4. KHOIRUL ANWAR, S.Fil.I. | E49: 0 | F49: 0 | G49: 1 | H49: 1 | I49: 0 | J49: 0 | K49: 2 | L49: 1 | M49: 1 | N49: 1 | O49: 1 | P49: 1 | Q49: 0 | R49: 2 | S49: 0 | T49: 0 | U49: 0 | V49: 0 | W49: =SUM(E49:V49) -> 11
C50: 5. ARIF WIJAKSANA | E50: 0 | F50: 0 | G50: 0 | H50: 0 | I50: 0 | J50: 0 | K50: 1 | L50: 0 | M50: 0 | N50: 0 | O50: 0 | P50: 0 | Q50: 0 | R50: 1 | S50: 1 | T50: 0 | U50: 0 | V50: 0 | W50: =SUM(E50:V50) -> 3
C51: 6. Dr. SITI YUMNAH | E51: 0 | F51: 0 | G51: 0 | H51: 0 | I51: 0 | J51: 0 | K51: 1 | L51: 0 | M51: 1 | N51: 1 | O51: 0 | P51: 1 | Q51: 0 | R51: 0 | S51: 0 | T51: 0 | U51: 2 | V51: 0 | W51: =SUM(E51:V51) -> 6
...

Sheet TAMANSARI
C2: Kecamatan | D2: LICIN
C3: Kabupaten | D3: BANYUWANGI
C4: Provinsi | D4: JAWA TIMUR
C9: Kelurahan | D9: TAMANSARI
A12: I | B12: DATA PEMILIH DAN PENGGUNAAN HAK PILIH | AD12: JUMLAH AKHIR
A13: A | B13: DATA PEMILIH | E13: TPS 001 | F13: TPS 002 | G13: TPS 003 | H13: TPS 004 | I13: TPS 005 | J13: TPS 006 | K13: TPS 007 | L13: TPS 008 | M13: TPS 009 | N13: TPS 010 | O13: TPS 011 | P13: TPS 012 | Q13: TPS 013 | R13: TPS 014 | S13: TPS 015 | T13: TPS 016 | U13: TPS 017 | V13: TPS 018 | W13: TPS 019 | X13: TPS 020 | Y13: TPS 021 | Z13: TPS 022 | AA13: TPS 023 | AB13: TPS 024 | AC13: TPS 025
B14: Jumlah Pemilih dalam Daftar Pemilih Tetap (DPT) | D14: LK | E14: 102 | F14: 102 | G14: 105 | H14: 102 | I14: 98 | J14: 96 | K14: 86 | L14: 99 | M14: 106 | N14: 147 | O14: 106 | P14: 96 | Q14: 129 | R14: 110 | S14: 88 | T14: 88 | U14: 101 | V14: 140 | W14: 124 | X14: 130 | Y14: 92 | Z14: 115 | AA14: 121 | AB14: 73 | AC14: 89 | AD14: =SUM(E14:AC14) -> 2645
D15: PR | E15: 103 | F15: 105 | G15: 114 | H15: 104 | I15: 102 | J15: 98 | K15: 90 | L15: 102 | M15: 98 | N15: 138 | O15: 105 | P15: 108 | Q15: 124 | R15: 106 | S15: 100 | T15: 83 | U15: 92 | V15: 138 | W15: 138 | X15: 135 | Y15: 92 | Z15: 115 | AA15: 126 | AB15: 79 | AC15: 96 | AD15: =SUM(E15:AC15) -> 2691
D16: JML | E16: =SUM(E14:E15) -> 205 | F16: =SUM(F14:F15) -> 207 | G16: =SUM(G14:G15) -> 219 | H16: =SUM(H14:H15) -> 206 | I16: =SUM(I14:I15) -> 200 | J16: =SUM(J14:J15) -> 194 | K16: =SUM(K14:K15) -> 176 | L16: =SUM(L14:L15) -> 201 | ... AC16: =SUM(AC14:AC15) -> 185 | AD16: =SUM(E16:AC16) -> 5336
A18: B | B18: PENGGUNA HAK PILIH
B19: 1. | C19: Jumlah pengguna hak pilih dalam Daftar Pemilih Tetap (DPT) | D19: LK | E19: 80 | F19: 70 | G19: 73 | H19: 81 | I19: 73 | J19: 72 | K19: 62 | L19: 78 | M19: 86 | N19: 108 | O19: 85 | P19: 75 | Q19: 117 | R19: 89 | S19: 71 | T19: 77 | U19: 84 | V19: 110 | W19: 94 | X19: 101 | Y19: 74 | Z19: 92 | AA19: 104 | AB19: 71 | AC19: 68 | AD19: =SUM(E19:AC19) -> 2095
D20: PR | E20: 82 | F20: 74 | G20: 92 | H20: 85 | I20: 79 | J20: 78 | K20: 73 | L20: 91 | M20: 80 | N20: 110 | O20: 85 | P20: 88 | Q20: 113 | R20: 89 | S20: 86 | T20: 76 | U20: 83 | V20: 114 | W20: 111 | X20: 122 | Y20: 78 | Z20: 92 | AA20: 102 | AB20: 61 | AC20: 76 | AD20: =SUM(E20:AC20) -> 2220
D21: JML | E21: =SUM(E19:E20) -> 162 | F21: =SUM(F19:F20) -> 144 | G21: =SUM(G19:G20) -> 165 | H21: =SUM(H19:H20) -> 166 | I21: =SUM(I19:I20) -> 152 | J21: =SUM(J19:J20) -> 150 | K21: =SUM(K19:K20) -> 135 | L21: =SUM(L19:L20) -> 169 | ... AC21: =SUM(AC19:AC20) -> 144 | AD21: =SUM(E21:AC21) -> 4315
B22: 2. | C22: Jumlah pengguna hak pilih dalam Daftar Pemilih Tambahan (DPTb) | D22: LK | E22: 0 | F22: 0 | G22: 0 | H22: 0 | I22: 0 | J22: 0 | K22: 0 | L22: 0 | M22: 0 | N22: 0 | O22: 0 | P22: 1 | Q22: 0 | R22: 0 | S22: 0 | T22: 0 | U22: 0 | V22: 0 | W22: 0 | X22: 0 | Y22: 0 | Z22: 0 | AA22: 0 | AB22: 0 | AC22: 0 | AD22: =SUM(E22:AC22) -> 1
D23: PR | E23: 0 | F23: 0 | G23: 0 | H23: 0 | I23: 0 | J23: 0 | K23: 0 | L23: 0 | M23: 0 | N23: 0 | O23: 0 | P23: 0 | Q23: 0 | R23: 0 | S23: 0 | T23: 0 | U23: 0 | V23: 0 | W23: 0 | X23: 0 | Y23: 0 | Z23: 0 | AA23: 0 | AB23: 0 | AC23: 0 | AD23: =SUM(E23:AC23) -> 0
D24: JML | E24: =SUM(E22:E23) -> 0 | F24: =SUM(F22:F23) -> 0 | G24: =SUM(G22:G23) -> 0 | H24: =SUM(H22:H23) -> 0 | I24: =SUM(I22:I23) -> 0 | J24: =SUM(J22:J23) -> 0 | K24: =SUM(K22:K23) -> 0 | L24: =SUM(L22:L23) -> 0 | ... AC24: =SUM(AC22:AC23) -> 0 | AD24: =SUM(E24:AC24) -> 1
B25: 3. | C25: Jumlah pengguna hak pilih dalam Daftar Pemilih Khusus (DPK) | D25: LK | E25: 1 | F25: 0 | G25: 1 | H25: 0 | I25: 1 | J25: 2 | K25: 0 | L25: 0 | M25: 0 | N25: 1 | O25: 1 | P25: 11 | Q25: 0 | R25: 5 | S25: 4 | T25: 3 | U25: 3 | V25: 1 | W25: 3 | X25: 0 | Y25: 3 | Z25: 3 | AA25: 1 | AB25: 2 | AC25: 1 | AD25: =SUM(E25:AC25) -> 47
D26: PR | E26: 1 | F26: 1 | G26: 2 | H26: 0 | I26: 0 | J26: 2 | K26: 0 | L26: 2 | M26: 1 | N26: 0 | O26: 2 | P26: 11 | Q26: 0 | R26: 5 | S26: 2 | T26: 4 | U26: 4 | V26: 0 | W26: 4 | X26: 0 | Y26: 3 | Z26: 0 | AA26: 2 | AB26: 4 | AC26: 2 | AD26: =SUM(E26:AC26) -> 52
D27: JML | E27: =SUM(E25:E26) -> 2 | F27: =SUM(F25:F26) -> 1 | G27: =SUM(G25:G26) -> 3 | H27: =SUM(H25:H26) -> 0 | I27: =SUM(I25:I26) -> 1 | J27: =SUM(J25:J26) -> 4 | K27: =SUM(K25:K26) -> 0 | L27: =SUM(L25:L26) -> 2 | ... AC27: =SUM(AC25:AC26) -> 3 | AD27: =SUM(E27:AC27) -> 99
B28: 4. | C28: Jumlah Pengguna Hak Pilih (B.1+B.2+B.3) | D28: LK | E28: =SUM(E19,E22,E25) -> 81 | F28: =SUM(F19,F22,F25) -> 70 | G28: =SUM(G19,G22,G25) -> 74 | H28: =SUM(H19,H22,H25) -> 81 | I28: =SUM(I19,I22,I25) -> 74 | J28: =SUM(J19,J22,J25) -> 74 | K28: =SUM(K19,K22,K25) -> 62 | L28: =SUM(L19,L22,L25) -> 78 | ... AC28: =SUM(AC19,AC22,AC25) -> 69 | AD28: =SUM(E28:AC28) -> 2143
D29: PR | E29: =SUM(E20,E23,E26) -> 83 | F29: =SUM(F20,F23,F26) -> 75 | G29: =SUM(G20,G23,G26) -> 94 | H29: =SUM(H20,H23,H26) -> 85 | I29: =SUM(I20,I23,I26) -> 79 | J29: =SUM(J20,J23,J26) -> 80 | K29: =SUM(K20,K23,K26) -> 73 | L29: =SUM(L20,L23,L26) -> 93 | ... AC29: =SUM(AC20,AC23,AC26) -> 78 | AD29: =SUM(E29:AC29) -> 2272
D30: JML | E30: =SUM(E28:E29) -> 164 | F30: =SUM(F28:F29) -> 145 | G30: =SUM(G28:G29) -> 168 | H30: =SUM(H28:H29) -> 166 | I30: =SUM(I28:I29) -> 153 | J30: =SUM(J28:J29) -> 154 | K30: =SUM(K28:K29) -> 135 | L30: =SUM(L28:L29) -> 171 | ... AC30: =SUM(AC28:AC29) -> 147 | AD30: =SUM(E30:AC30) -> 4415
A32: II | B32: DATA PENGGUNAAN SURAT SUARA
A33: 1 | B33: Jumlah surat suara yang diterima, termasuk surat suara cadangan 2,5% dari DPT | E33: 210 | F33: 212 | G33: 224 | H33: 170 | I33: 205 | J33: 199 | K33: 181 | L33: 206 | M33: 208 | N33: 291 | O33: 216 | P33: 209 | Q33: 259 | R33: 221 | S33: 195 | T33: 176 | U33: 197 | V33: 284 | W33: 267 | X33: 270 | Y33: 188 | Z33: 235 | AA33: 252 | AB33: 156 | AC33: 190 | AD33: =SUM(E33:AC33) -> 5421
A34: 2 | B34: Jumlah surat suara yang digunakan | E34: 164 | F34: 145 | G34: 168 | H34: 166 | I34: 153 | J34: 154 | K34: 135 | L34: 171 | M34: 167 | N34: 219 | O34: 173 | P34: 186 | Q34: 230 | R34: 188 | S34: 163 | T34: 160 | U34: 172 | V34: 225 | W34: 212 | X34: 223 | Y34: 158 | Z34: 187 | AA34: 209 | AB34: 138 | AC34: 147 | AD34: =SUM(E34:AC34) -> 4413
A35: 3 | B35: Jumlah surat suara dikembalikan oleh pemilih (karena rusak atau keliru coblos) | E35: 1 | F35: 0 | G35: 0 | H35: 1 | I35: 0 | J35: 0 | K35: 0 | L35: 0 | M35: 0 | N35: 0 | O35: 0 | P35: 0 | Q35: 0 | R35: 0 | S35: 0 | T35: 0 | U35: 0 | V35: 0 | W35: 0 | X35: 0 | Y35: 0 | Z35: 2 | AA35: 0 | AB35: 0 | AC35: 0 | AD35: =SUM(E35:AC35) -> 4
A36: 4 | B36: Jumlah surat suara yang tidak digunakan/tidak terpakai, termasuk sisa surat suara cadangan | E36: =E33-(E34+E35) -> 45 | F36: =F33-(F34+F35) -> 67 | G36: =G33-(G34+G35) -> 56 | H36: =H33-(H34+H35) -> 3 | I36: =I33-(I34+I35) -> 52 | J36: =J33-(J34+J35) -> 45 | K36: =K33-(K34+K35) -> 46 | L36: =L33-(L34+L35) -> 35 | ... AC36: =AC33-(AC34+AC35) -> 43 | AD36: =SUM(E36:AC36) -> 1004
A38: III | B38: DATA PEMILIH DISABILITAS
B39: Jumlah seluruh Pemilih disabilitas yang menggunakan hak pilih | D39: LK | E39: 1 | F39: 2 | G39: 0 | H39: 0 | I39: 2 | J39: 0 | K39: 0 | L39: 0 | M39: 0 | N39: 0 | O39: 0 | P39: 1 | Q39: 0 | R39: 0 | S39: 0 | T39: 0 | U39: 0 | V39: 0 | W39: 0 | X39: 1 | Y39: 0 | Z39: 0 | AA39: 0 | AB39: 0 | AC39: 0 | AD39: =SUM(E39:AC39) -> 7
D40: PR | E40: 0 | F40: 1 | G40: 0 | H40: 0 | I40: 1 | J40: 0 | K40: 0 | L40: 0 | M40: 0 | N40: 0 | O40: 0 | P40: 0 | Q40: 0 | R40: 0 | S40: 0 | T40: 0 | U40: 0 | V40: 0 | W40: 0 | X40: 1 | Y40: 0 | Z40: 0 | AA40: 0 | AB40: 0 | AC40: 0 | AD40: =SUM(E40:AC40) -> 3
