Workbook

Sheet DPD
C8: Kecamatan | D8: BANGOREJO
C9: Kabupaten | D9: BANYUWANGI
C10: Provinsi | D10: JAWA TIMUR
A12: I | B12: DATA PEMILIH DAN PENGGUNAAN HAK PILIH | E12: JUMLAH AKHIR
A13: A | B13: DATA PEMILIH
B14: Jumlah Pemilih dalam Daftar Pemilih Tetap (DPT) | D14: LK | E14: =BENCULUK!AS14+CLURING!AL14+KALIPLOSO!Q14+PLAMPANGREJO!AE14+SARIMULYO!AA14+SEMBULUNG!AC14+SRATEN!AB14 -> 23919
D15: PR | E15: =BENCULUK!AS15+CLURING!AL15+KALIPLOSO!Q15+PLAMPANGREJO!AE15+SARIMULYO!AA15+SEMBULUNG!AC15+SRATEN!AB15 -> 24124
D16: JML | E16: =SUM(E14:E15) -> 48043
A18: B | B18: PENGGUNA HAK PILIH
B19: 1. | C19: Jumlah pengguna hak pilih dalam Daftar Pemilih Tetap (DPT) | D19: LK | E19: =BENCULUK!AS19+CLURING!AL19+KALIPLOSO!Q19+PLAMPANGREJO!AE19+SARIMULYO!AA19+SEMBULUNG!AC19+SRATEN!AB19+TAMANAGUNG!AH19+TAMPO!AB19 -> 22885
D20: PR | E20: =BENCULUK!AS20+CLURING!AL20+KALIPLOSO!Q20+PLAMPANGREJO!AE20+SARIMULYO!AA20+SEMBULUNG!AC20+SRATEN!AB20+TAMANAGUNG!AH20+TAMPO!AB20 -> 24362
D21: JML | E21: =SUM(E19:E20) -> 47247
B22: 2. | C22: Jumlah pengguna hak pilih dalam Daftar Pemilih Tambahan (DPTb) | D22: LK | E22: =BENCULUK!AS22+CLURING!AL22+KALIPLOSO!Q22+PLAMPANGREJO!AE22+SARIMULYO!AA22+SEMBULUNG!AC22+SRATEN!AB22+TAMANAGUNG!AH22+TAMPO!AB22 -> 31
D23: PR | E23: =BENCULUK!AS23+CLURING!AL23+KALIPLOSO!Q23+PLAMPANGREJO!AE23+SARIMULYO!AA23+SEMBULUNG!AC23+SRATEN!AB23+TAMANAGUNG!AH23+TAMPO!AB23 -> 30
D24: JML | E24: =SUM(E22:E23) -> 61
B25: 3. | C25: Jumlah pengguna hak pilih dalam Daftar Pemilih Khusus (DPK) | D25: LK | E25: =BENCULUK!AS25+CLURING!AL25+KALIPLOSO!Q25+PLAMPANGREJO!AE25+SARIMULYO!AA25+SEMBULUNG!AC25+SRATEN!AB25+TAMANAGUNG!AH25+TAMPO!AB25 -> 228
D26: PR | E26: =BENCULUK!AS26+CLURING!AL26+KALIPLOSO!Q26+PLAMPANGREJO!AE26+SARIMULYO!AA26+SEMBULUNG!AC26+SRATEN!AB26+TAMANAGUNG!AH26+TAMPO!AB26 -> 287
D27: JML | E27: =SUM(E25:E26) -> 515
B28: 4. | C28: Jumlah Pengguna Hak Pilih (B.1+B.2+B.3) | D28: LK | E28: =E19+E22+E25 -> 23144
D29: PR | E29: =E20+E23+E26 -> 24679
D30: JML | E30: =SUM(E28:E29) -> 47823
A32: II | B32: DATA PENGGUNAAN SURAT SUARA
A33: 1 | B33: Jumlah surat suara yang diterima, termasuk surat suara cadangan 2,5% dari DPT | E33: =BENCULUK!AS33+CLURING!AL33+KALIPLOSO!Q33+PLAMPANGREJO!AE33+SARIMULYO!AA33+SEMBULUNG!AC33+SRATEN!AB33+TAMANAGUNG!AH33+TAMPO!AB33 -> 62718
A34: 2 | B34: Jumlah surat suara yang digunakan | E34: =BENCULUK!AS34+CLURING!AL34+KALIPLOSO!Q34+PLAMPANGREJO!AE34+SARIMULYO!AA34+SEMBULUNG!AC34+SRATEN!AB34+TAMANAGUNG!AH34+TAMPO!AB34 -> 47825
A35: 3 | B35: Jumlah surat suara dikembalikan oleh pemilih (karena rusak atau keliru coblos) | E35: =BENCULUK!AS35+CLURING!AL35+KALIPLOSO!Q35+PLAMPANGREJO!AE35+SARIMULYO!AA35+SEMBULUNG!AC35+SRATEN!AB35+TAMANAGUNG!AH35+TAMPO!AB35 -> 70
A36: 4 | B36: Jumlah surat suara yang tidak digunakan/tidak terpakai, termasuk sisa surat suara cadangan | E36: =E33-(E34+E35) -> 14823
A38: III | B38: DATA PEMILIH DISABILITAS
B39: Jumlah seluruh Pemilih disabilitas yang menggunakan hak pilih | D39: LK | E39: =BENCULUK!AS39+CLURING!AL39+KALIPLOSO!Q39+PLAMPANGREJO!AE39+SARIMULYO!AA39+SEMBULUNG!AC39+SRATEN!AB39+TAMANAGUNG!AH39+TAMPO!AB39 -> 125
D40: PR | E40: =BENCULUK!AS40+CLURING!AL40+KALIPLOSO!Q40+PLAMPANGREJO!AE40+SARIMULYO!AA40+SEMBULUNG!AC40+SRATEN!AB40+TAMANAGUNG!AH40+TAMPO!AB40 -> 149
D41: JML | E41: =SUM(E39:E40) -> 274
A43: IV | B43: DATA RINCIAN PEROLEHAN SUARA PASANGAN CALON BUPATI DAN WAKIL BUPATI
A44: NOMOR DAN NAMA CALON
A45: A.2 | B45: 1. | C45: AA. AHMAD NAWARDI | E45: =BENCULUK!AS45+CLURING!AL45+KALIPLOSO!Q45+PLAMPANGREJO!AE45+SARIMULYO!AA45+SEMBULUNG!AC45+SRATEN!AB45+TAMANAGUNG!AH45+TAMPO!AB45 -> 2454
B46: 2. | C46: Ir. H. AA LA NYALLA MAHMUD MATTALITI, M.HP. | E46: =BENCULUK!AS46+CLURING!AL46+KALIPLOSO!Q46+PLAMPANGREJO!AE46+SARIMULYO!AA46+SEMBULUNG!AC46+SRATEN!AB46+TAMANAGUNG!AH46+TAMPO!AB46 -> 5011
B47: 3. | C47: ABDUL QADIR AMIR HARTONO, S.E., S.H., M.H. | E47: =BENCULUK!AS47+CLURING!AL47+KALIPLOSO!Q47+PLAMPANGREJO!AE47+SARIMULYO!AA47+SEMBULUNG!AC47+SRATEN!AB47+TAMANAGUNG!AH47+TAMPO!AB47 -> 2339
B48: 4. | C48: ADILLA AZIS, S.E. | E48: =BENCULUK!AS48+CLURING!AL48+KALIPLOSO!Q48+PLAMPANGREJO!AE48+SARIMULYO!AA48+SEMBULUNG!AC48+SRATEN!AB48+TAMANAGUNG!AH48+TAMPO!AB48 -> 3932
B49: 5. | C49: Ir. H. AGUS RAHARDJO, MSc.M. | E49: =BENCULUK!AS49+CLURING!AL49+KALIPLOSO!Q49+PLAMPANGREJO!AE49+SARIMULYO!AA49+SEMBULUNG!AC49+SRATEN!AB49+TAMANAGUNG!AH49+TAMPO!AB49 -> 3091
B50: 6. | C50: Drs. AYUB KHAN | E50: =BENCULUK!AS50+CLURING!AL50+KALIPLOSO!Q50+PLAMPANGREJO!AE50+SARIMULYO!AA50+SEMBULUNG!AC50+SRATEN!AB50+TAMANAGUNG!AH50+TAMPO!AB50 -> 2433
B51: 7. | C51: BAMBANG HARIANTO | E51: =BENCULUK!AS51+CLURING!AL51+KALIPLOSO!Q51+PLAMPANGREJO!AE51+SARIMULYO!AA51+SEMBULUNG!AC51+SRATEN!AB51+TAMANAGUNG!AH51+TAMPO!AB51 -> 472
B52: 8. | C52: CATUR RUDI UTANTO, S.Sos. | E52: =BENCULUK!AS52+CLURING!AL52+KALIPLOSO!Q52+PLAMPANGREJO!AE52+SARIMULYO!AA52+SEMBULUNG!AC52+SRATEN!AB52+TAMANAGUNG!AH52+TAMPO!AB52 -> 583
...

Sheet BENCULUK
C2: Kecamatan | D2: CLURING
C3: Kabupaten | D3: BANYUWANGI
C4: Provinsi | D4: JAWA TIMUR
C9: Kelurahan | D9: BENCULUK
A12: I | B12: DATA PEMILIH DAN PENGGUNAAN HAK PILIH | AS12: JUMLAH AKHIR
A13: A | B13: DATA PEMILIH | E13: TPS 001 | F13: TPS 002 | G13: TPS 003 | H13: TPS 004 | I13: TPS 005 | J13: TPS 006 | K13: TPS 007 | L13: TPS 008 | M13: TPS 009 | N13: TPS 010 | O13: TPS 011 | P13: TPS 012 | Q13: TPS 013 | R13: TPS 014 | S13: TPS 015 | T13: TPS 016 | U13: TPS 017 | V13: TPS 018 | W13: TPS 019 | X13: TPS 020 | Y13: TPS 021 | Z13: TPS 022 | AA13: TPS 023 | AB13: TPS 024 | AC13: TPS 025 | AD13: TPS 026 | AE13: TPS 027 | AF13: TPS 028 | AG13: TPS 029 | AH13: TPS 030 | AI13: TPS 031 | AJ13: TPS 032 | AK13: TPS 033 | AL13: TPS 034 | AM13: TPS 035 | AN13: TPS 036 | AO13: TPS 037 | AP13: TPS 038 | AQ13: TPS 039 | AR13: TPS 040
B14: Jumlah Pemilih dalam Daftar Pemilih Tetap (DPT) | D14: LK | E14: 136 | F14: 122 | G14: 131 | H14: 114 | I14: 125 | J14: 123 | K14: 119 | L14: 115 | M14: 138 | N14: 121 | O14: 126 | P14: 124 | Q14: 141 | R14: 144 | S14: 139 | T14: 124 | U14: 123 | V14: 119 | W14: 123 | X14: 134 | Y14: 129 | Z14: 139 | AA14: 138 | AB14: 118 | AC14: 140 | AD14: 136 | AE14: 153 | AF14: 141 | AG14: 133 | AH14: 131 | AI14: 135 | AJ14: 127 | AK14: 141 | AL14: 127 | AM14: 130 | AN14: 132 | AO14: 125 | AP14: 143 | AQ14: 146 | AR14: 130 | AS14: =SUM(E14:AR14) -> 5235
D15: PR | E15: 123 | F15: 131 | G15: 122 | H15: 141 | I15: 121 | J15: 120 | K15: 126 | L15: 120 | M15: 134 | N15: 138 | O15: 125 | P15: 144 | Q15: 142 | R15: 133 | S15: 141 | T15: 137 | U15: 129 | V15: 113 | W15: 146 | X15: 131 | Y15: 146 | Z15: 145 | AA15: 142 | AB15: 132 | AC15: 123 | AD15: 136 | AE15: 136 | AF15: 143 | AG15: 137 | AH15: 122 | AI15: 131 | AJ15: 123 | AK15: 125 | AL15: 130 | AM15: 135 | AN15: 133 | AO15: 132 | AP15: 147 | AQ15: 126 | AR15: 140 | AS15: =SUM(E15:AR15) -> 5301
D16: JML | E16: 259 | F16: 253 | G16: 253 | H16: 255 | I16: 246 | J16: 243 | K16: 245 | L16: 235 | M16: 272 | N16: 259 | O16: 251 | P16: 268 | Q16: 283 | R16: 277 | S16: 280 | T16: 261 | U16: 252 | V16: 232 | W16: 269 | X16: 265 | Y16: 275 | Z16: 284 | AA16: 280 | AB16: 250 | AC16: 263 | AD16: 272 | AE16: 289 | AF16: 284 | AG16: 270 | AH16: 253 | AI16: 266 | AJ16: 250 | AK16: 266 | AL16: 257 | AM16: 265 | AN16: 265 | AO16: 257 | AP16: 290 | AQ16: 272 | AR16: 270 | AS16: =SUM(E16:AR16) -> 10536
A18: B | B18: PENGGUNA HAK PILIH
B19: 1. | C19: Jumlah pengguna hak pilih dalam Daftar Pemilih Tetap (DPT) | D19: LK | E19: 106 | F19: 98 | G19: 88 | H19: 84 | I19: 89 | J19: 83 | K19: 79 | L19: 92 | M19: 94 | N19: 87 | O19: 92 | P19: 81 | Q19: 98 | R19: 91 | S19: 102 | T19: 99 | U19: 85 | V19: 77 | W19: 97 | X19: 100 | Y19: 86 | Z19: 106 | AA19: 104 | AB19: 89 | AC19: 103 | AD19: 120 | AE19: 118 | AF19: 112 | AG19: 110 | AH19: 92 | AI19: 109 | AJ19: 92 | AK19: 108 | AL19: 99 | AM19: 93 | AN19: 113 | AO19: 96 | AP19: 111 | AQ19: 92 | AR19: 90 | AS19: =SUM(E19:AR19) -> 3865
D20: PR | E20: 92 | F20: 93 | G20: 89 | H20: 114 | I20: 98 | J20: 82 | K20: 86 | L20: 87 | M20: 104 | N20: 103 | O20: 97 | P20: 92 | Q20: 99 | R20: 85 | S20: 119 | T20: 108 | U20: 103 | V20: 79 | W20: 118 | X20: 108 | Y20: 115 | Z20: 116 | AA20: 124 | AB20: 101 | AC20: 94 | AD20: 118 | AE20: 113 | AF20: 117 | AG20: 112 | AH20: 91 | AI20: 111 | AJ20: 105 | AK20: 109 | AL20: 105 | AM20: 105 | AN20: 120 | AO20: 104 | AP20: 120 | AQ20: 101 | AR20: 106 | AS20: =SUM(E20:AR20) -> 4143
D21: JML | E21: 198 | F21: 191 | G21: 177 | H21: 198 | I21: 187 | J21: 165 | K21: 165 | L21: 179 | M21: 198 | N21: 190 | O21: 189 | P21: 173 | Q21: 197 | R21: 176 | S21: 221 | T21: 207 | U21: 188 | V21: 156 | W21: 215 | X21: 208 | Y21: 201 | Z21: 222 | AA21: 228 | AB21: 190 | AC21: 197 | AD21: 238 | AE21: 231 | AF21: 229 | AG21: 222 | AH21: 183 | AI21: 220 | AJ21: 197 | AK21: 217 | AL21: 204 | AM21: 198 | AN21: 233 | AO21: 200 | AP21: 231 | AQ21: 193 | AR21: 196 | AS21: =SUM(E21:AR21) -> 8008
B22: 2. | C22: Jumlah pengguna hak pilih dalam Daftar Pemilih Tambahan (DPTb) | D22: LK | E22: 1 | F22: 0 | G22: 1 | H22: 0 | I22: 0 | J22: 0 | K22: 0 | L22: 0 | M22: 0 | N22: 0 | O22: 1 | P22: 0 | Q22: 0 | R22: 0 | S22: 0 | T22: 0 | U22: 0 | V22: 0 | W22: 0 | X22: 1 | Y22: 0 | Z22: 1 | AA22: 0 | AB22: 0 | AC22: 0 | AD22: 0 | AE22: 0 | AF22: 0 | AG22: 0 | AH22: 0 | AI22: 0 | AJ22: 0 | AK22: 0 | AL22: 0 | AM22: 0 | AN22: 0 | AO22: 0 | AP22: 0 | AQ22: 0 | AR22: 0 | AS22: =SUM(E22:AR22) -> 5
D23: PR | E23: 1 | F23: 0 | G23: 0 | H23: 0 | I23: 0 | J23: 0 | K23: 0 | L23: 0 | M23: 0 | N23: 0 | O23: 3 | P23: 0 | Q23: 0 | R23: 0 | S23: 0 | T23: 0 | U23: 0 | V23: 0 | W23: 0 | X23: 0 | Y23: 0 | Z23: 0 | AA23: 0 | AB23: 0 | AC23: 0 | AD23: 0 | AE23: 0 | AF23: 0 | AG23: 0 | AH23: 0 | AI23: 0 | AJ23: 0 | AK23: 0 | AL23: 0 | AM23: 0 | AN23: 0 | AO23: 0 | AP23: 0 | AQ23: 0 | AR23: 0 | AS23: =SUM(E23:AR23) -> 4
D24: JML | E24: 2 | F24: 0 | G24: 1 | H24: 0 | I24: 0 | J24: 0 | K24: 0 | L24: 0 | M24: 0 | N24: 0 | O24: 4 | P24: 0 | Q24: 0 | R24: 0 | S24: 0 | T24: 0 | U24: 0 | V24: 0 | W24: 0 | X24: 1 | Y24: 0 | Z24: 1 | AA24: 0 | AB24: 0 | AC24: 0 | AD24: 0 | AE24: 0 | AF24: 0 | AG24: 0 | AH24: 0 | AI24: 0 | AJ24: 0 | AK24: 0 | AL24: 0 | AM24: 0 | AN24: 0 | AO24: 0 | AP24: 0 | AQ24: 0 | AR24: 0 | AS24: =SUM(E24:AR24) -> 9
B25: 3. | C25: Jumlah pengguna hak pilih dalam Daftar Pemilih Khusus (DPK) | D25: LK | E25: 3 | F25: 0 | G25: 0 | H25: 1 | I25: 0 | J25: 1 | K25: 0 | L25: 0 | M25: 0 | N25: 0 | O25: 1 | P25: 0 | Q25: 2 | R25: 0 | S25: 0 | T25: 5 | U25: 0 | V25: 0 | W25: 0 | X25: 0 | Y25: 2 | Z25: 1 | AA25: 4 | AB25: 1 | AC25: 0 | AD25: 0 | AE25: 0 | AF25: 0 | AG25: 0 | AH25: 3 | AI25: 0 | AJ25: 0 | AK25: 0 | AL25: 1 | AM25: 1 | AN25: 1 | AO25: 0 | AP25: 1 | AQ25: 1 | AR25: 0 | AS25: =SUM(E25:AR25) -> 29
D26: PR | E26: 3 | F26: 0 | G26: 0 | H26: 1 | I26: 0 | J26: 0 | K26: 1 | L26: 0 | M26: 0 | N26: 0 | O26: 1 | P26: 1 | Q26: 3 | R26: 0 | S26: 0 | T26: 0 | U26: 0 | V26: 0 | W26: 0 | X26: 0 | Y26: 3 | Z26: 0 | AA26: 1 | AB26: 2 | AC26: 2 | AD26: 0 | AE26: 0 | AF26: 0 | AG26: 0 | AH26: 1 | AI26: 1 | AJ26: 0 | AK26: 0 | AL26: 0 | AM26: 1 | AN26: 2 | AO26: 0 | AP26: 1 | AQ26: 3 | AR26: 0 | AS26: =SUM(E26:AR26) -> 27
D27: JML | E27: 6 | F27: 0 | G27: 0 | H27: 2 | I27: 0 | J27: 1 | K27: 1 | L27: 0 | M27: 0 | N27: 0 | O27: 2 | P27: 1 | Q27: 5 | R27: 0 | S27: 0 | T27: 5 | U27: 0 | V27: 0 | W27: 0 | X27: 0 | Y27: 5 | Z27: 1 | AA27: 5 | AB27: 3 | AC27: 2 | AD27: 0 | AE27: 0 | AF27: 0 | AG27: 0 | AH27: 4 | AI27: 1 | AJ27: 0 | AK27: 0 | AL27: 1 | AM27: 2 | AN27: 3 | AO27: 0 | AP27: 2 | AQ27: 4 | AR27: 0 | AS27: =SUM(E27:AR27) -> 56
B28: 4. | C28: Jumlah Pengguna Hak Pilih (B.1+B.2+B.3) | D28: LK | E28: 110 | F28: 98 | G28: 89 | H28: 85 | I28: 89 | J28: 84 | K28: 79 | L28: 92 | M28: 94 | N28: 87 | O28: 94 | P28: 81 | Q28: 100 | R28: 91 | S28: 102 | T28: 104 | U28: 85 | V28: 77 | W28: 97 | X28: 101 | Y28: 88 | Z28: 108 | AA28: 108 | AB28: 90 | AC28: 103 | AD28: 120 | AE28: 118 | AF28: 112 | AG28: 110 | AH28: 95 | AI28: 109 | AJ28: 92 | AK28: 108 | AL28: 100 | AM28: 94 | AN28: 114 | AO28: 96 | AP28: 112 | AQ28: 93 | AR28: 90 | AS28: =SUM(E28:AR28) -> 3899
D29: PR | E29: 96 | F29: 93 | G29: 89 | H29: 115 | I29: 98 | J29: 82 | K29: 87 | L29: 87 | M29: 104 | N29: 103 | O29: 101 | P29: 93 | Q29: 102 | R29: 85 | S29: 119 | T29: 108 | U29: 103 | V29: 79 | W29: 118 | X29: 108 | Y29: 118 | Z29: 116 | AA29: 125 | AB29: 103 | AC29: 96 | AD29: 118 | AE29: 113 | AF29: 117 | AG29: 112 | AH29: 92 | AI29: 112 | AJ29: 105 | AK29: 109 | AL29: 105 | AM29: 106 | AN29: 122 | AO29: 104 | AP29: 121 | AQ29: 104 | AR29: 106 | AS29: =SUM(E29:AR29) -> 4174
D30: JML | E30: 206 | F30: 191 | G30: 178 | H30: 200 | I30: 187 | J30: 166 | K30: 166 | L30: 179 | M30: 198 | N30: 190 | O30: 195 | P30: 174 | Q30: 202 | R30: 176 | S30: 221 | T30: =SUM(T28:T29) -> 212 | U30: =SUM(U28:U29) -> 188 | V30: =SUM(V28:V29) -> 156 | W30: =SUM(W28:W29) -> 215 | X30: =SUM(X28:X29) -> 209 | Y30: =SUM(Y28:Y29) -> 206 | Z30: =SUM(Z28:Z29) -> 224 | AA30: =SUM(AA28:AA29) -> 233 | ... AR30: =SUM(AR28:AR29) -> 196 | AS30: =SUM(E30:AR30) -> 8073
A32: II | B32: DATA PENGGUNAAN SURAT SUARA
A33: 1 | B33: Jumlah surat suara yang diterima, termasuk surat suara cadangan 2,5% dari DPT | E33: 265 | F33: 259 | G33: 259 | H33: 261 | I33: 251 | J33: 248 | K33: 250 | L33: 240 | M33: 278 | N33: 265 | O33: 257 | P33: 274 | Q33: 289 | R33: 283 | S33: 286 | T33: 267 | U33: 258 | V33: 237 | W33: 277 | X33: 272 | Y33: 281 | Z33: 290 | AA33: 287 | AB33: 255 | AC33: 271 | AD33: 278 | AE33: 295 | AF33: 291 | AG33: 277 | AH33: 259 | AI33: 276 | AJ33: 255 | AK33: 272 | AL33: 265 | AM33: 271 | AN33: 271 | AO33: 253 | AP33: 296 | AQ33: 282 | AR33: 275 | AS33: =SUM(E33:AR33) -> 10776
A34: 2 | B34: Jumlah surat suara yang digunakan | E34: 206 | F34: 191 | G34: 178 | H34: 200 | I34: 187 | J34: 166 | K34: 166 | L34: 179 | M34: 198 | N34: 190 | O34: 195 | P34: 174 | Q34: 202 | R34: 176 | S34: 221 | T34: 212 | U34: 188 | V34: 156 | W34: 215 | X34: 209 | Y34: 206 | Z34: 224 | AA34: 233 | AB34: 193 | AC34: 199 | AD34: 238 | AE34: 231 | AF34: 229 | AG34: 222 | AH34: 187 | AI34: 221 | AJ34: 197 | AK34: 217 | AL34: 205 | AM34: 200 | AN34: 236 | AO34: 200 | AP34: 233 | AQ34: 197 | AR34: 196 | AS34: =SUM(E34:AR34) -> 8073
A35: 3 | B35: Jumlah surat suara dikembalikan oleh pemilih (karena rusak atau keliru coblos) | E35: 1 | F35: 0 | G35: 0 | H35: 0 | I35: 0 | J35: 0 | K35: 0 | L35: 0 | M35: 0 | N35: 0 | O35: 0 | P35: 1 | Q35: 0 | R35: 0 | S35: 0 | T35: 1 | U35: 0 | V35: 0 | W35: 0 | X35: 1 | Y35: 0 | Z35: 1 | AA35: 0 | AB35: 0 | AC35: 0 | AD35: 0 | AE35: 0 | AF35: 0 | AG35: 0 | AH35: 1 | AI35: 0 | AJ35: 0 | AK35: 0 | AL35: 0 | AM35: 0 | AN35: 0 | AO35: 0 | AP35: 0 | AQ35: 1 | AR35: 0 | AS35: =SUM(E35:AR35) -> 7
A36: 4 | B36: Jumlah surat suara yang tidak digunakan/tidak terpakai, termasuk sisa surat suara cadangan | E36: 58 | F36: 68 | G36: 81 | H36: 61 | I36: 64 | J36: 82 | K36: 84 | L36: 61 | M36: 80 | N36: 75 | O36: 62 | P36: 99 | Q36: 87 | R36: 107 | S36: 65 | T36: 54 | U36: 70 | V36: 81 | W36: 62 | X36: 62 | Y36: 75 | Z36: 65 | AA36: 54 | AB36: 62 | AC36: 72 | AD36: 40 | AE36: 64 | AF36: 62 | AG36: 55 | AH36: 71 | AI36: 55 | AJ36: 58 | AK36: 55 | AL36: 60 | AM36: 71 | AN36: 35 | AO36: 53 | AP36: 63 | AQ36: 84 | AR36: 79 | AS36: =SUM(E36:AR36) -> 2696
A38: III | B38: DATA PEMILIH DISABILITAS
B39: Jumlah seluruh Pemilih disabilitas yang menggunakan hak pilih | D39: LK | E39: 0 | F39: 1 | G39: 0 | H39: 0 | I39: 0 | J39: 0 | K39: 0 | L39: 0 | M39: 0 | N39: 0 | O39: 0 | P39: 0 | Q39: 0 | R39: 0 | S39: 0 | T39: 0 | U39: 0 | V39: 0 | W39: 0 | X39: 1 | Y39: 0 | Z39: 1 | AA39: 0 | AB39: 1 | AC39: 1 | AD39: 0 | AE39: 0 | AF39: 0 | AG39: 1 | AH39: 0 | AI39: 0 | AJ39: 0 | AK39: 0 | AL39: 1 | AM39: 0 | AN39: 3 | AO39: 0 | AP39: 0 | AQ39: 0 | AR39: 0 | AS39: =SUM(E39:AR39) -> 10
D40: PR | E40: 0 | F40: 0 | G40: 0 | H40: 0 | I40: 0 | J40: 0 | K40: 0 | L40: 0 | M40: 0 | N40: 0 | O40: 0 | P40: 1 | Q40: 0 | R40: 0 | S40: 0 | T40: 0 | U40: 0 | V40: 0 | W40: 0 | X40: 1 | Y40: 0 | Z40: 4 | AA40: 0 | AB40: 1 | AC40: 0 | AD40: 0 | AE40: 0 | AF40: 0 | AG40: 0 | AH40: 0 | AI40: 0 | AJ40: 0 | AK40: 0 | AL40: 1 | AM40: 0 | AN40: 9 | AO40: 0 | AP40: 0 | AQ40: 0 | AR40: 0 | AS40: =SUM(E40:AR40) -> 17
D41: JML | E41: 0 | F41: 1 | G41: 0 | H41: 0 | I41: 0 | J41: 0 | K41: 0 | L41: 0 | M41: 0 | N41: 0 | O41: 0 | P41: 1 | Q41: 0 | R41: 0 | S41: 0 | T41: 0 | U41: 0 | V41: 0 | W41: 0 | X41: 2 | Y41: 0 | Z41: 5 | AA41: 0 | AB41: 2 | AC41: 1 | AD41: 0 | AE41: 0 | AF41: 0 | AG41: 1 | AH41: 0 | AI41: 0 | AJ41: 0 | AK41: 0 | AL41: 2 | AM41: 0 | AN41: 12 | AO41: 0 | AP41: 0 | AQ41: 0 | AR41: 0 | AS41: =SUM(E41:AR41) -> 27
A43: IV | B43: DATA RINCIAN PEROLEHAN SUARA PASANGAN CALON BUPATI DAN WAKIL BUPATI
A44: NOMOR DAN NAMA CALON
B45: 1. | C45: AA. AHMAD NAWARDI | E45: 11 | F45: 11 | G45: 11 | H45: 14 | I45: 6 | J45: 11 | K45: 10 | L45: 5 | M45: 8 | N45: 6 | O45: 8 | P45: 14 | Q45: 18 | R45: 18 | S45: 8 | T45: 13 | U45: 9 | V45: 7 | W45: 10 | X45: 9 | Y45: 13 | Z45: 7 | AA45: 11 | AB45: 11 | AC45: 19 | AD45: 19 | AE45: 17 | AF45: 19 | AG45: 20 | AH45: 19 | AI45: 12 | AJ45: 7 | AK45: 31 | AL45: 13 | AM45: 22 | AN45: 25 | AO45: 21 | AP45: 19 | AQ45: 21 | AR45: 7 | AS45: =SUM(E45:AR45) -> 540
B46: 2. | C46: Ir. H. AA LA NYALLA MAHMUD MATTALITI, M.HP. | E46: 19 | F46: 27 | G46: 23 | H46: 26 | I46: 25 | J46: 12 | K46: 23 | L46: 23 | M46: 15 | N46: 19 | O46: 31 | P46: 21 | Q46: 28 | R46: 27 | S46: 23 | T46: 28 | U46: 24 | V46: 25 | W46: 23 | X46: 34 | Y46: 34 | Z46: 38 | AA46: 41 | AB46: 19 | AC46: 24 | AD46: 25 | AE46: 30 | AF46: 31 | AG46: 24 | AH46: 24 | AI46: 25 | AJ46: 28 | AK46: 23 | AL46: 21 | AM46: 21 | AN46: 21 | AO46: 31 | AP46: 27 | AQ46: 27 | AR46: 22 | AS46: =SUM(E46:AR46) -> 1012
B47: 3. | C47: ABDUL QADIR AMIR HARTONO, S.E., S.H., M.H. | E47: 14 | F47: 14 | G47: 11 | H47: 12 | I47: 11 | J47: 8 | K47: 12 | L47: 14 | M47: 10 | N47: 13 | O47: 3 | P47: 15 | Q47: 12 | R47: 10 | S47: 8 | T47: 17 | U47: 13 | V47: 8 | W47: 11 | X47: 7 | Y47: 14 | Z47: 14 | AA47: 16 | AB47: 10 | AC47: 15 | AD47: 12 | AE47: 17 | AF47: 8 | AG47: 26 | AH47: 18 | AI47: 18 | AJ47: 26 | AK47: 16 | AL47: 17 | AM47: 21 | AN47: 13 | AO47: 5 | AP47: 16 | AQ47: 27 | AR47: 10 | AS47: =SUM(E47:AR47) -> 542
B48: 4. | C48: ADILLA AZIS, S.E. | E48: 20 | F48: 18 | G48: 23 | H48: 22 | I48: 19 | J48: 16 | K48: 21 | L48: 27 | M48: 19 | N48: 25 | O48: 21 | P48: 17 | Q48: 14 | R48: 13 | S48: 22 | T48: 27 | U48: 24 | V48: 16 | W48: 25 | X48: 18 | Y48: 18 | Z48: 17 | AA48: 17 | AB48: 16 | AC48: 19 | AD48: 34 | AE48: 22 | AF48: 16 | AG48: 32 | AH48: 13 | AI48: 41 | AJ48: 21 | AK48: 25 | AL48: 26 | AM48: 21 | AN48: 30 | AO48: 22 | AP48: 25 | AQ48: 22 | AR48: 16 | AS48: =SUM(E48:AR48) -> 860
B49: 5. | C49: Ir. H. AGUS RAHARDJO, MSc.M. | E49: 19 | F49: 18 | G49: 28 | H49: 20 | I49: 17 | J49: 11 | K49: 12 | L49: 8 | M49: 16 | N49: 15 | O49: 21 | P49: 7 | Q49: 14 | R49: 15 | S49: 20 | T49: 15 | U49: 22 | V49: 10 | W49: 14 | X49: 27 | Y49: 22 | Z49: 22 | AA49: 21 | AB49: 20 | AC49: 11 | AD49: 16 | AE49: 18 | AF49: 23 | AG49: 11 | AH49: 16 | AI49: 16 | AJ49: 11 | AK49: 20 | AL49: 15 | AM49: 13 | AN49: 12 | AO49: 17 | AP49: 25 | AQ49: 32 | AR49: 23 | AS49: =SUM(E49:AR49) -> 693
B50: 6. | C50: Drs. AYUB KHAN | E50: 14 | F50: 8 | G50: 7 | H50: 10 | I50: 8 | J50: 9 | K50: 12 | L50: 17 | M50: 18 | N50: 10 | O50: 11 | P50: 9 | Q50: 11 | R50: 11 | S50: 15 | T50: 11 | U50: 11 | V50: 9 | W50: 11 | X50: 17 | Y50: 17 | Z50: 20 | AA50: 19 | AB50: 20 | AC50: 14 | AD50: 24 | AE50: 26 | AF50: 27 | AG50: 24 | AH50: 13 | AI50: 8 | AJ50: 22 | AK50: 7 | AL50: 11 | AM50: 10 | AN50: 9 | AO50: 10 | AP50: 17 | AQ50: 8 | AR50: 10 | AS50: =SUM(E50:AR50) -> 545
B51: 7. | C51: BAMBANG HARIANTO | E51: 3 | F51: 1 | G51: 0 | H51: 7 | I51: 2 | J51: 4 | K51: 1 | L51: 1 | M51: 1 | N51: 3 | O51: 5 | P51: 5 | Q51: 2 | R51: 2 | S51: 2 | T51: 0 | U51: 2 | V51: 3 | W51: 3 | X51: 2 | Y51: 0 | Z51: 3 | AA51: 4 | AB51: 4 | AC51: 1 | AD51: 4 | AE51: 3 | AF51: 1 | AG51: 0 | AH51: 1 | AI51: 0 | AJ51: 4 | AK51: 0 | AL51: 1 | AM51: 2 | AN51: 2 | AO51: 9 | AP51: 3 | AQ51: 1 | AR51: 3 | AS51: =SUM(E51:AR51) -> 95
...

Sheet CLURING
C2: Kecamatan | D2: CLURING
C3: Kabupaten | D3: BANYUWANGI
C4: Provinsi | D4: JAWA TIMUR
C9: Kelurahan | D9: CLURING
A12: I | B12: DATA PEMILIH DAN PENGGUNAAN HAK PILIH | AL12: JUMLAH AKHIR
A13: A | B13: DATA PEMILIH | E13: TPS 001 | F13: TPS 002 | G13: TPS 003 | H13: TPS 004 | I13: TPS 005 | J13: TPS 006 | K13: TPS 007 | L13: TPS 008 | M13: TPS 009 | N13: TPS 010 | O13: TPS 011 | P13: TPS 012 | Q13: TPS 013 | R13: TPS 014 | S13: TPS 015 | T13: TPS 016 | U13: TPS 017 | V13: TPS 018 | W13: TPS 019 | X13: TPS 020 | Y13: TPS 021 | Z13: TPS 022 | AA13: TPS 023 | AB13: TPS 024 | AC13: TPS 025 | AD13: TPS 026 | AE13: TPS 027 | AF13: TPS 028 | AG13: TPS 029 | AH13: TPS 030 | AI13: TPS 031 | AJ13: TPS 032 | AK13: TPS 033
B14: Jumlah Pemilih dalam Daftar Pemilih Tetap (DPT) | D14: LK | E14: 136 | F14: 136 | G14: 145 | H14: 148 | I14: 114 | J14: 134 | K14: 130 | L14: 136 | M14: 132 | N14: 123 | O14: 117 | P14: 133 | Q14: 130 | R14: 132 | S14: 145 | T14: 128 | U14: 136 | V14: 122 | W14: 135 | X14: 135 | Y14: 141 | Z14: 133 | AA14: 142 | AB14: 158 | AC14: 141 | AD14: 146 | AE14: 131 | AF14: 140 | AG14: 134 | AH14: 133 | AI14: 121 | AJ14: 131 | AK14: 134 | AL14: =SUM(E14:AK14) -> 4432
D15: PR | E15: 138 | F15: 128 | G15: 154 | H15: 150 | I15: 139 | J15: 132 | K15: 136 | L15: 129 | M15: 126 | N15: 136 | O15: 124 | P15: 141 | Q15: 129 | R15: 122 | S15: 141 | T15: 122 | U15: 132 | V15: 129 | W15: 134 | X15: 137 | Y15: 131 | Z15: 129 | AA15: 150 | AB15: 132 | AC15: 146 | AD15: 146 | AE15: 146 | AF15: 131 | AG15: 136 | AH15: 138 | AI15: 146 | AJ15: 140 | AK15: 132 | AL15: =SUM(E15:AK15) -> 4482
D16: JML | E16: 274 | F16: 264 | G16: 299 | H16: 298 | I16: 253 | J16: 266 | K16: 266 | L16: 265 | M16: 258 | N16: 259 | O16: 241 | P16: 274 | Q16: 259 | R16: 254 | S16: 286 | T16: 250 | U16: 268 | V16: 251 | W16: 269 | X16: 272 | Y16: 272 | Z16: 262 | AA16: 292 | AB16: 290 | AC16: 287 | AD16: 292 | AE16: 277 | AF16: 271 | AG16: 270 | AH16: 271 | AI16: 267 | AJ16: =SUM(AJ14:AJ15) -> 271 | AK16: =SUM(AK14:AK15) -> 266 | AL16: =SUM(E16:AK16) -> 8914
A18: B | B18: PENGGUNA HAK PILIH
B19: 1. | C19: Jumlah pengguna hak pilih dalam Daftar Pemilih Tetap (DPT) | D19: LK | E19: 98 | F19: 91 | G19: 115 | H19: 156 | I19: 75 | J19: 99 | K19: 86 | L19: 95 | M19: 93 | N19: 101 | O19: 68 | P19: 101 | Q19: 76 | R19: 101 | S19: 96 | T19: 92 | U19: 106 | V19: 95 | W19: 98 | X19: 102 | Y19: 104 | Z19: 102 | AA19: 107 | AB19: 109 | AC19: 107 | AD19: 104 | AE19: 112 | AF19: 111 | AG19: 108 | AH19: 104 | AI19: 100 | AJ19: 97 | AK19: 105 | AL19: =SUM(E19:AK19) -> 3314
D20: PR | E20: 102 | F20: 103 | G20: 123 | H20: 90 | I20: 92 | J20: 103 | K20: 98 | L20: 101 | M20: 98 | N20: 118 | O20: 86 | P20: 115 | Q20: 92 | R20: 98 | S20: 103 | T20: 95 | U20: 108 | V20: 108 | W20: 101 | X20: 108 | Y20: 102 | Z20: 103 | AA20: 112 | AB20: 104 | AC20: 109 | AD20: 117 | AE20: 120 | AF20: 107 | AG20: 106 | AH20: 108 | AI20: 119 | AJ20: 118 | AK20: 106 | AL20: =SUM(E20:AK20) -> 3473
D21: JML | E21: 200 | F21: 194 | G21: 238 | H21: 246 | I21: 167 | J21: 202 | K21: 184 | L21: 196 | M21: 191 | N21: 219 | O21: 154 | P21: 216 | Q21: 168 | R21: 199 | S21: 199 | T21: 187 | U21: 214 | V21: 203 | W21: 199 | X21: 210 | Y21: 206 | Z21: 205 | AA21: 219 | AB21: 213 | AC21: 216 | AD21: 221 | AE21: 232 | AF21: 218 | AG21: 214 | AH21: 212 | AI21: =SUM(AI19:AI20) -> 219 | AJ21: =SUM(AJ19:AJ20) -> 215 | AK21: =SUM(AK19:AK20) -> 211 | AL21: =SUM(E21:AK21) -> 6787
B22: 2. | C22: Jumlah pengguna hak pilih dalam Daftar Pemilih Tambahan (DPTb) | D22: LK | E22: 0 | F22: 1 | G22: 0 | H22: 0 | I22: 0 | J22: 0 | K22: 0 | L22: 0 | M22: 1 | N22: 1 | O22: 2 | P22: 0 | Q22: 0 | R22: 0 | S22: 0 | T22: 1 | U22: 0 | V22: 0 | W22: 0 | X22: 0 | Y22: 0 | Z22: 0 | AA22: 0 | AB22: 0 | AC22: 0 | AD22: 0 | AE22: 0 | AF22: 0 | AG22: 0 | AH22: 0 | AI22: 0 | AJ22: 0 | AK22: 0 | AL22: =SUM(E22:AK22) -> 6
D23: PR | E23: 0 | F23: 1 | G23: 0 | H23: 0 | I23: 0 | J23: 0 | K23: 0 | L23: 1 | M23: 0 | N23: 1 | O23: 2 | P23: 0 | Q23: 0 | R23: 0 | S23: 0 | T23: 1 | U23: 0 | V23: 0 | W23: 0 | X23: 0 | Y23: 0 | Z23: 0 | AA23: 0 | AB23: 0 | AC23: 0 | AD23: 0 | AE23: 0 | AF23: 0 | AG23: 0 | AH23: 0 | AI23: 0 | AJ23: 0 | AK23: 0 | AL23: =SUM(E23:AK23) -> 6
D24: JML | E24: 0 | F24: 2 | G24: 0 | H24: 0 | I24: 0 | J24: 0 | K24: 0 | L24: 1 | M24: 1 | N24: 2 | O24: 4 | P24: 0 | Q24: 0 | R24: 0 | S24: 0 | T24: 2 | U24: 0 | V24: 0 | W24: 0 | X24: 0 | Y24: 0 | Z24: 0 | AA24: 0 | AB24: 0 | AC24: 0 | AD24: 0 | AE24: 0 | AF24: 0 | AG24: 0 | AH24: 0 | AI24: =SUM(AI22:AI23) -> 0 | AJ24: =SUM(AJ22:AJ23) -> 0 | AK24: =SUM(AK22:AK23) -> 0 | AL24: =SUM(E24:AK24) -> 12
B25: 3. | C25: Jumlah pengguna hak pilih dalam Daftar Pemilih Khusus (DPK) | D25: LK | E25: 0 | F25: 0 | G25: 2 | H25: 3 | I25: 0 | J25: 4 | K25: 1 | L25: 1 | M25: 0 | N25: 3 | O25: 1 | P25: 2 | Q25: 1 | R25: 4 | S25: 2 | T25: 1 | U25: 0 | V25: 1 | W25: 0 | X25: 0 | Y25: 1 | Z25: 1 | AA25: 0 | AB25: 1 | AC25: 2 | AD25: 1 | AE25: 2 | AF25: 5 | AG25: 3 | AH25: 0 | AI25: 3 | AJ25: 2 | AK25: 3 | AL25: =SUM(E25:AK25) -> 50
D26: PR | E26: 2 | F26: 1 | G26: 0 | H26: 3 | I26: 1 | J26: 2 | K26: 2 | L26: 3 | M26: 1 | N26: 3 | O26: 2 | P26: 3 | Q26: 4 | R26: 1 | S26: 0 | T26: 0 | U26: 2 | V26: 1 | W26: 0 | X26: 0 | Y26: 1 | Z26: 5 | AA26: 1 | AB26: 3 | AC26: 1 | AD26: 4 | AE26: 3 | AF26: 3 | AG26: 2 | AH26: 0 | AI26: 3 | AJ26: 4 | AK26: 5 | AL26: =SUM(E26:AK26) -> 66
D27: JML | E27: 2 | F27: 1 | G27: 2 | H27: 6 | I27: 1 | J27: 6 | K27: 3 | L27: 4 | M27: 1 | N27: 6 | O27: 3 | P27: 5 | Q27: 5 | R27: 5 | S27: 2 | T27: 1 | U27: 2 | V27: 2 | W27: 0 | X27: 0 | Y27: 2 | Z27: 6 | AA27: 1 | AB27: 4 | AC27: 3 | AD27: 5 | AE27: 5 | AF27: 8 | AG27: 5 | AH27: 0 | AI27: =SUM(AI25:AI26) -> 6 | AJ27: =SUM(AJ25:AJ26) -> 6 | AK27: =SUM(AK25:AK26) -> 8 | AL27: =SUM(E27:AK27) -> 116
B28: 4. | C28: Jumlah Pengguna Hak Pilih (B.1+B.2+B.3) | D28: LK | E28: 98 | F28: 92 | G28: 117 | H28: 159 | I28: 75 | J28: 103 | K28: 87 | L28: 96 | M28: 94 | N28: 105 | O28: 71 | P28: 103 | Q28: 77 | R28: 105 | S28: 98 | T28: 94 | U28: 106 | V28: 96 | W28: 98 | X28: 102 | Y28: 105 | Z28: 103 | AA28: 107 | AB28: 110 | AC28: 109 | AD28: 105 | AE28: 114 | AF28: 116 | AG28: 111 | AH28: 104 | AI28: =SUM(AI19,AI22,AI25) -> 103 | AJ28: =SUM(AJ19,AJ22,AJ25) -> 99 | AK28: =SUM(AK19,AK22,AK25) -> 108 | AL28: =SUM(E28:AK28) -> 3370
D29: PR | E29: 104 | F29: 105 | G29: 123 | H29: 93 | I29: 93 | J29: 105 | K29: 100 | L29: 105 | M29: 99 | N29: 122 | O29: 90 | P29: 118 | Q29: 96 | R29: 99 | S29: 103 | T29: 96 | U29: 110 | V29: 109 | W29: 101 | X29: 108 | Y29: 103 | Z29: 108 | AA29: 113 | AB29: 107 | AC29: 110 | AD29: 121 | AE29: 123 | AF29: 110 | AG29: 108 | AH29: 108 | AI29: =SUM(AI20,AI23,AI26) -> 122 | AJ29: =SUM(AJ20,AJ23,AJ26) -> 122 | AK29: =SUM(AK20,AK23,AK26) -> 111 | AL29: =SUM(E29:AK29) -> 3545
D30: JML | E30: 202 | F30: 197 | G30: 240 | H30: 252 | I30: 168 | J30: 208 | K30: 187 | L30: 201 | M30: 193 | N30: 227 | O30: 161 | P30: 221 | Q30: 173 | R30: 204 | S30: 201 | T30: 190 | U30: 216 | V30: 205 | W30: 199 | X30: 210 | Y30: 208 | Z30: 211 | AA30: 220 | AB30: 217 | AC30: 219 | AD30: 226 | AE30: 237 | AF30: 226 | AG30: 219 | AH30: 212 | AI30: =SUM(AI28:AI29) -> 225 | AJ30: =SUM(AJ28:AJ29) -> 221 | AK30: =SUM(AK28:AK29) -> 219 | AL30: =SUM(E30:AK30) -> 6915
A32: II | B32: DATA PENGGUNAAN SURAT SUARA
A33: 1 | B33: Jumlah surat suara yang diterima, termasuk surat suara cadangan 2,5% dari DPT | E33: 280 | F33: 270 | G33: 305 | H33: 305 | I33: 259 | J33: 271 | K33: 272 | L33: 271 | M33: 266 | N33: 262 | O33: 246 | P33: 270 | Q33: 265 | R33: 261 | S33: 292 | T33: 255 | U33: 274 | V33: 258 | W33: 265 | X33: 278 | Y33: 278 | Z33: 270 | AA33: 298 | AB33: 296 | AC33: 293 | AD33: 298 | AE33: 283 | AF33: 278 | AG33: 277 | AH33: 277 | AI33: 263 | AJ33: 277 | AK33: 272 | AL33: =SUM(E33:AK33) -> 9085
A34: 2 | B34: Jumlah surat suara yang digunakan | E34: 202 | F34: 197 | G34: 240 | H34: 252 | I34: 168 | J34: 208 | K34: 187 | L34: 201 | M34: 193 | N34: 227 | O34: 161 | P34: 221 | Q34: 173 | R34: 204 | S34: 201 | T34: 190 | U34: 216 | V34: 205 | W34: 199 | X34: 210 | Y34: 208 | Z34: 211 | AA34: 220 | AB34: 217 | AC34: 219 | AD34: 226 | AE34: 237 | AF34: 226 | AG34: 219 | AH34: 212 | AI34: 225 | AJ34: 221 | AK34: 219 | AL34: =SUM(E34:AK34) -> 6915
A35: 3 | B35: Jumlah surat suara dikembalikan oleh pemilih (karena rusak atau keliru coblos) | E35: 1 | F35: 0 | G35: 0 | H35: 0 | I35: 0 | J35: 1 | K35: 0 | L35: 0 | M35: 3 | N35: 0 | O35: 0 | P35: 0 | Q35: 0 | R35: 0 | S35: 2 | T35: 0 | U35: 0 | V35: 0 | W35: 0 | X35: 0 | Y35: 0 | Z35: 1 | AA35: 0 | AB35: 0 | AC35: 1 | AD35: 0 | AE35: 1 | AF35: 0 | AG35: 0 | AH35: 0 | AI35: 1 | AJ35: 0 | AK35: 0 | AL35: =SUM(E35:AK35) -> 11
A36: 4 | B36: Jumlah surat suara yang tidak digunakan/tidak terpakai, termasuk sisa surat suara cadangan | E36: 77 | F36: 73 | G36: 65 | H36: 53 | I36: 91 | J36: 62 | K36: 85 | L36: 70 | M36: 70 | N36: 35 | O36: 85 | P36: 49 | Q36: 92 | R36: 57 | S36: 89 | T36: 65 | U36: 58 | V36: 53 | W36: 66 | X36: 68 | Y36: 70 | Z36: 58 | AA36: 78 | AB36: 79 | AC36: 73 | AD36: 72 | AE36: 45 | AF36: 52 | AG36: 58 | AH36: 65 | AI36: =AI33-(AI34+AI35) -> 37 | AJ36: =AJ33-(AJ34+AJ35) -> 56 | AK36: =AK33-(AK34+AK35) -> 53 | AL36: =SUM(E36:AK36) -> 2159
A38: III | B38: DATA PEMILIH DISABILITAS
B39: Jumlah seluruh Pemilih disabilitas yang menggunakan hak pilih | D39: LK | E39: 0 | F39: 0 | G39: 1 | H39: 0 | I39: 0 | J39: 2 | K39: 0 | L39: 0 | M39: 0 | N39: 0 | O39: 0 | P39: 0 | Q39: 0 | R39: 0 | S39: 0 | T39: 0 | U39: 0 | V39: 0 | W39: 0 | X39: 0 | Y39: 0 | Z39: 2 | AA39: 0 | AB39: 0 | AC39: 0 | AD39: 0 | AE39: 0 | AF39: 0 | AG39: 0 | AH39: 0 | AI39: 0 | AJ39: 0 | AK39: 0 | AL39: =SUM(E39:AK39) -> 5
D40: PR | E40: 0 | F40: 0 | G40: 1 | H40: 0 | I40: 0 | J40: 1 | K40: 0 | L40: 0 | M40: 1 | N40: 0 | O40: 0 | P40: 0 | Q40: 0 | R40: 0 | S40: 0 | T40: 0 | U40: 0 | V40: 0 | W40: 1 | X40: 0 | Y40: 0 | Z40: 1 | AA40: 0 | AB40: 0 | AC40: 0 | AD40: 0 | AE40: 0 | AF40: 1 | AG40: 0 | AH40: 0 | AI40: 0 | AJ40: 0 | AK40: 0 | AL40: =SUM(E40:AK40) -> 6
D41: JML | E41: 0 | F41: 0 | G41: 2 | H41: 0 | I41: 0 | J41: 3 | K41: 0 | L41: 0 | M41: 1 | N41: 0 | O41: 0 | P41: 0 | Q41: 0 | R41: 0 | S41: 0 | T41: 0 | U41: 0 | V41: 0 | W41: 1 | X41: 0 | Y41: 0 | Z41: 3 | AA41: 0 | AB41: 0 | AC41: 0 | AD41: 0 | AE41: 0 | AF41: 1 | AG41: 0 | AH41: 0 | AI41: =SUM(AI39:AI40) -> 0 | AJ41: =SUM(AJ39:AJ40) -> 0 | AK41: =SUM(AK39:AK40) -> 0 | AL41: =SUM(E41:AK41) -> 11
A43: IV | B43: DATA RINCIAN PEROLEHAN SUARA PASANGAN CALON BUPATI DAN WAKIL BUPATI
A44: NOMOR DAN NAMA CALON
B45: 1. | C45: AA. AHMAD NAWARDI | E45: 12 | F45: 9 | G45: 13 | H45: 18 | I45: 10 | J45: 14 | K45: 9 | L45: 23 | M45: 14 | N45: 22 | O45: 10 | P45: 23 | Q45: 18 | R45: 5 | S45: 22 | T45: 14 | U45: 10 | V45: 18 | W45: 14 | X45: 21 | Y45: 8 | Z45: 32 | AA45: 18 | AB45: 19 | AC45: 6 | AD45: 10 | AE45: 13 | AF45: 9 | AG45: 10 | AH45: 8 | AI45: 15 | AJ45: 18 | AK45: 45 | AL45: =SUM(E45:AK45) -> 510
B46: 2. | C46: Ir. H. AA LA NYALLA MAHMUD MATTALITI, M.HP. | E46: 25 | F46: 39 | G46: 33 | H46: 28 | I46: 18 | J46: 37 | K46: 24 | L46: 30 | M46: 16 | N46: 20 | O46: 14 | P46: 23 | Q46: 23 | R46: 32 | S46: 20 | T46: 38 | U46: 23 | V46: 30 | W46: 18 | X46: 18 | Y46: 23 | Z46: 19 | AA46: 32 | AB46: 30 | AC46: 26 | AD46: 35 | AE46: 34 | AF46: 21 | AG46: 25 | AH46: 30 | AI46: 38 | AJ46: 30 | AK46: 27 | AL46: =SUM(E46:AK46) -> 879
B47: 3. | C47: ABDUL QADIR AMIR HARTONO, S.E., S.H., M.H. | E47: 12 | F47: 13 | G47: 12 | H47: 19 | I47: 9 | J47: 10 | K47: 11 | L47: 11 | M47: 5 | N47: 6 | O47: 10 | P47: 14 | Q47: 7 | R47: 26 | S47: 16 | T47: 8 | U47: 16 | V47: 15 | W47: 15 | X47: 26 | Y47: 24 | Z47: 25 | AA47: 18 | AB47: 11 | AC47: 20 | AD47: 22 | AE47: 15 | AF47: 19 | AG47: 14 | AH47: 15 | AI47: 11 | AJ47: 20 | AK47: 14 | AL47: =SUM(E47:AK47) -> 489
B48: 4. | C48: ADILLA AZIS, S.E. | E48: 26 | F48: 22 | G48: 29 | H48: 26 | I48: 19 | J48: 24 | K48: 20 | L48: 21 | M48: 19 | N48: 15 | O48: 13 | P48: 24 | Q48: 19 | R48: 13 | S48: 27 | T48: 22 | U48: 23 | V48: 32 | W48: 22 | X48: 19 | Y48: 29 | Z48: 31 | AA48: 25 | AB48: 38 | AC48: 26 | AD48: 21 | AE48: 22 | AF48: 25 | AG48: 20 | AH48: 31 | AI48: 28 | AJ48: 25 | AK48: 15 | AL48: =SUM(E48:AK48) -> 771
B49: 5. | C49: Ir. H. AGUS RAHARDJO, MSc.M. | E49: 20 | F49: 25 | G49: 26 | H49: 34 | I49: 15 | J49: 24 | K49: 17 | L49: 14 | M49: 31 | N49: 69 | O49: 22 | P49: 24 | Q49: 15 | R49: 18 | S49: 15 | T49: 10 | U49: 9 | V49: 15 | W49: 17 | X49: 16 | Y49: 19 | Z49: 12 | AA49: 15 | AB49: 22 | AC49: 15 | AD49: 13 | AE49: 16 | AF49: 16 | AG49: 13 | AH49: 9 | AI49: 23 | AJ49: 17 | AK49: 13 | AL49: =SUM(E49:AK49) -> 639
B50: 6. | C50: Drs. AYUB KHAN | E50: 6 | F50: 7 | G50: 5 | H50: 14 | I50: 10 | J50: 8 | K50: 8 | L50: 7 | M50: 12 | N50: 7 | O50: 9 | P50: 10 | Q50: 10 | R50: 12 | S50: 10 | T50: 15 | U50: 7 | V50: 11 | W50: 10 | X50: 7 | Y50: 8 | Z50: 4 | AA50: 7 | AB50: 9 | AC50: 11 | AD50: 11 | AE50: 9 | AF50: 5 | AG50: 13 | AH50: 7 | AI50: 10 | AJ50: 5 | AK50: 7 | AL50: =SUM(E50:AK50) -> 291
B51: 7. | C51: BAMBANG HARIANTO | E51: 5 | F51: 3 | G51: 1 | H51: 2 | I51: 2 | J51: 2 | K51: 3 | L51: 1 | M51: 2 | N51: 3 | O51: 3 | P51: 1 | Q51: 4 | R51: 3 | S51: 0 | T51: 2 | U51: 2 | V51: 0 | W51: 2 | X51: 4 | Y51: 3 | Z51: 3 | AA51: 9 | AB51: 3 | AC51: 2 | AD51: 6 | AE51: 1 | AF51: 2 | AG51: 2 | AH51: 2 | AI51: 4 | AJ51: 4 | AK51: 7 | AL51: =SUM(E51:AK51) -> 93
...

Sheet KALIPLOSO
C2: Kecamatan | D2: CLURING
C3: Kabupaten | D3: BANYUWANGI
C4: Provinsi | D4: JAWA TIMUR
C9: Kelurahan | D9: KALIPLOSO
A12: I | B12: DATA PEMILIH DAN PENGGUNAAN HAK PILIH | Q12: JUMLAH AKHIR
A13: A | B13: DATA PEMILIH | E13: TPS 001 | F13: TPS 002 | G13: TPS 003 | H13: TPS 004 | I13: TPS 005 | J13: TPS 006 | K13: TPS 007 | L13: TPS 008 | M13: TPS 009 | N13: TPS 010 | O13: TPS 011 | P13: TPS 012
B14: Jumlah Pemilih dalam Daftar Pemilih Tetap (DPT) | D14: LK | E14: 137 | F14: 152 | G14: 135 | H14: 160 | I14: 142 | J14: 143 | K14: 128 | L14: 122 | M14: 107 | N14: 132 | O14: 142 | P14: 144 | Q14: =SUM(E14:P14) -> 1644
D15: PR | E15: 149 | F15: 144 | G15: 156 | H15: 137 | I15: 149 | J15: 143 | K15: 117 | L15: 122 | M15: 98 | N15: 124 | O15: 147 | P15: 150 | Q15: =SUM(E15:P15) -> 1636
D16: JML | E16: =SUM(E14:E15) -> 286 | F16: =SUM(F14:F15) -> 296 | G16: =SUM(G14:G15) -> 291 | H16: =SUM(H14:H15) -> 297 | I16: =SUM(I14:I15) -> 291 | J16: =SUM(J14:J15) -> 286 | K16: =SUM(K14:K15) -> 245 | L16: =SUM(L14:L15) -> 244 | ... P16: =SUM(P14:P15) -> 294 | Q16: =SUM(E16:P16) -> 3280
A18: B | B18: PENGGUNA HAK PILIH
B19: 1. | C19: Jumlah pengguna hak pilih dalam Daftar Pemilih Tetap (DPT) | D19: LK | E19: 81 | F19: 107 | G19: 100 | H19: 113 | I19: 121 | J19: 113 | K19: 103 | L19: 97 | M19: 75 | N19: 114 | O19: 116 | P19: 112 | Q19: =SUM(E19:P19) -> 1252
D20: PR | E20: 112 | F20: 117 | G20: 124 | H20: 127 | I20: 121 | J20: 117 | K20: 94 | L20: 95 | M20: 71 | N20: 87 | O20: 127 | P20: 123 | Q20: =SUM(E20:P20) -> 1315
D21: JML | E21: 193 | F21: 224 | G21: 224 | H21: 240 | I21: 242 | J21: 230 | K21: 197 | L21: 192 | M21: 146 | N21: 201 | O21: 243 | P21: 235 | Q21: =SUM(E21:P21) -> 2567
B22: 2. | C22: Jumlah pengguna hak pilih dalam Daftar Pemilih Tambahan (DPTb) | D22: LK | E22: 0 | F22: 1 | G22: 0 | H22: 0 | I22: 0 | J22: 0 | K22: 0 | L22: 0 | M22: 0 | N22: 0 | O22: 0 | P22: 0 | Q22: =SUM(E22:P22) -> 1
D23: PR | E23: 0 | F23: 2 | G23: 0 | H23: 0 | I23: 1 | J23: 0 | K23: 0 | L23: 0 | M23: 0 | N23: 0 | O23: 0 | P23: 1 | Q23: =SUM(E23:P23) -> 4
D24: JML | E24: 0 | F24: 3 | G24: 0 | H24: 0 | I24: 1 | J24: 0 | K24: 0 | L24: 0 | M24: 0 | N24: 0 | O24: 0 | P24: 1 | Q24: =SUM(E24:P24) -> 5
B25: 3. | C25: Jumlah pengguna hak pilih dalam Daftar Pemilih Khusus (DPK) | D25: LK | E25: 1 | F25: 1 | G25: 0 | H25: 0 | I25: 1 | J25: 1 | K25: 1 | L25: 0 | M25: 1 | N25: 0 | O25: 0 | P25: 0 | Q25: =SUM(E25:P25) -> 6
D26: PR | E26: 2 | F26: 1 | G26: 2 | H26: 0 | I26: 2 | J26: 3 | K26: 2 | L26: 0 | M26: 2 | N26: 0 | O26: 0 | P26: 0 | Q26: =SUM(E26:P26) -> 14
D27: JML | E27: 3 | F27: 2 | G27: 2 | H27: 0 | I27: 3 | J27: 4 | K27: 3 | L27: 0 | M27: 3 | N27: 0 | O27: 0 | P27: 0 | Q27: =SUM(E27:P27) -> 20
B28: 4. | C28: Jumlah Pengguna Hak Pilih (B.1+B.2+B.3) | D28: LK | E28: 82 | F28: 109 | G28: 100 | H28: 113 | I28: 122 | J28: 114 | K28: 104 | L28: 97 | M28: 76 | N28: 114 | O28: 116 | P28: 112 | Q28: =SUM(E28:P28) -> 1259
D29: PR | E29: 114 | F29: 120 | G29: 126 | H29: 127 | I29: 124 | J29: 120 | K29: 96 | L29: 95 | M29: 73 | N29: 87 | O29: 127 | P29: 124 | Q29: =SUM(E29:P29) -> 1333
D30: JML | E30: =SUM(E28:E29) -> 196 | F30: =SUM(F28:F29) -> 229 | G30: =SUM(G28:G29) -> 226 | H30: =SUM(H28:H29) -> 240 | I30: =SUM(I28:I29) -> 246 | J30: =SUM(J28:J29) -> 234 | K30: =SUM(K28:K29) -> 200 | L30: =SUM(L28:L29) -> 192 | ... P30: =SUM(P28:P29) -> 236 | Q30: =SUM(E30:P30) -> 2592
A32: II | B32: DATA PENGGUNAAN SURAT SUARA
A33: 1 | B33: Jumlah surat suara yang diterima, termasuk surat suara cadangan 2,5% dari DPT | E33: 303 | F33: 294 | G33: 300 | H33: 301 | I33: 290 | J33: 292 | K33: 254 | L33: 249 | M33: 211 | N33: 262 | O33: 295 | P33: 300 | Q33: =SUM(E33:P33) -> 3351
A34: 2 | B34: Jumlah surat suara yang digunakan | E34: 196 | F34: 229 | G34: 226 | H34: 240 | I34: 246 | J34: 234 | K34: 200 | L34: 192 | M34: 149 | N34: 201 | O34: 243 | P34: 236 | Q34: =SUM(E34:P34) -> 2592
A35: 3 | B35: Jumlah surat suara dikembalikan oleh pemilih (karena rusak atau keliru coblos) | E35: 0 | F35: 0 | G35: 0 | H35: 0 | I35: 0 | J35: 0 | K35: 0 | L35: 0 | M35: 1 | N35: 0 | O35: 0 | P35: 0 | Q35: =SUM(E35:P35) -> 1
A36: 4 | B36: Jumlah surat suara yang tidak digunakan/tidak terpakai, termasuk sisa surat suara cadangan | E36: 107 | F36: 65 | G36: 74 | H36: 61 | I36: 44 | J36: 58 | K36: 54 | L36: 57 | M36: 61 | N36: 61 | O36: 52 | P36: 64 | Q36: =SUM(E36:P36) -> 758
A38: III | B38: DATA PEMILIH DISABILITAS
B39: Jumlah seluruh Pemilih disabilitas yang menggunakan hak pilih | D39: LK | E39: 0 | F39: 0 | G39: 0 | H39: 0 | I39: 0 | J39: 0 | K39: 0 | L39: 0 | M39: 0 | N39: 0 | O39: 0 | P39: 0 | Q39: =SUM(E39:P39) -> 0
D40: PR | E40: 0 | F40: 0 | G40: 0 | H40: 0 | I40: 0 | J40: 0 | K40: 0 | L40: 0 | M40: 0 | N40: 0 | O40: 0 | P40: 0 | Q40: =SUM(E40:P40) -> 0
D41: JML | E41: =SUM(E39:E40) -> 0 | F41: =SUM(F39:F40) -> 0 | G41: =SUM(G39:G40) -> 0 | H41: =SUM(H39:H40) -> 0 | I41: =SUM(I39:I40) -> 0 | J41: =SUM(J39:J40) -> 0 | K41: =SUM(K39:K40) -> 0 | L41: =SUM(L39:L40) -> 0 | ... P41: =SUM(P39:P40) -> 0 | Q41: =SUM(E41:P41) -> 0
A43: IV | B43: DATA RINCIAN PEROLEHAN SUARA PASANGAN CALON BUPATI DAN WAKIL BUPATI
A44: NOMOR DAN NAMA CALON
B45: 1. | C45: AA. AHMAD NAWARDI | E45: 29 | F45: 9 | G45: 37 | H45: 20 | I45: 24 | J45: 19 | K45: 15 | L45: 20 | M45: 10 | N45: 21 | O45: 19 | P45: 16 | Q45: =SUM(E45:P45) -> 239
B46: 2. | C46: Ir. H. AA LA NYALLA MAHMUD MATTALITI, M.HP. | E46: 28 | F46: 85 | G46: 37 | H46: 41 | I46: 40 | J46: 28 | K46: 13 | L46: 23 | M46: 16 | N46: 30 | O46: 41 | P46: 22 | Q46: =SUM(E46:P46) -> 404
B47: 3. | C47: ABDUL QADIR AMIR HARTONO, S.E., S.H., M.H. | E47: 13 | F47: 9 | G47: 14 | H47: 10 | I47: 13 | J47: 12 | K47: 6 | L47: 4 | M47: 7 | N47: 18 | O47: 23 | P47: 37 | Q47: =SUM(E47:P47) -> 166
B48: 4. | C48: ADILLA AZIS, S.E. | E48: 26 | F48: 26 | G48: 25 | H48: 27 | I48: 22 | J48: 25 | K48: 18 | L48: 18 | M48: 9 | N48: 23 | O48: 29 | P48: 21 | Q48: =SUM(E48:P48) -> 269
B49: 5. | C49: Ir. H. AGUS RAHARDJO, MSc.M. | E49: 15 | F49: 17 | G49: 19 | H49: 9 | I49: 24 | J49: 23 | K49: 83 | L49: 68 | M49: 51 | N49: 17 | O49: 11 | P49: 9 | Q49: =SUM(E49:P49) -> 346
B50: 6. | C50: Drs. AYUB KHAN | E50: 11 | F50: 6 | G50: 13 | H50: 4 | I50: 12 | J50: 14 | K50: 2 | L50: 3 | M50: 3 | N50: 6 | O50: 15 | P50: 18 | Q50: =SUM(E50:P50) -> 107
B51: 7. | C51: BAMBANG HARIANTO | E51: 6 | F51: 3 | G51: 3 | H51: 3 | I51: 5 | J51: 4 | K51: 2 | L51: 4 | M51: 1 | N51: 3 | O51: 8 | P51: 3 | Q51: =SUM(E51:P51) -> 45
...

Sheet PLAMPANGREJO
C2: Kecamatan | D2: CLURING
C3: Kabupaten | D3: BANYUWANGI
C4: Provinsi | D4: JAWA TIMUR
C9: Kelurahan | D9: PLAMPANGREJO
A12: I | B12: DATA PEMILIH DAN PENGGUNAAN HAK PILIH | AE12: JUMLAH AKHIR
A13: A | B13: DATA PEMILIH | E13: TPS 001 | F13: TPS 002 | G13: TPS 003 | H13: TPS 004 | I13: TPS 005 | J13: TPS 006 | K13: TPS 007 | L13: TPS 008 | M13: TPS 009 | N13: TPS 010 | O13: TPS 011 | P13: TPS 012 | Q13: TPS 013 | R13: TPS 014 | S13: TPS 015 | T13: TPS 016 | U13: TPS 017 | V13: TPS 018 | W13: TPS 019 | X13: TPS 020 | Y13: TPS 021 | Z13: TPS 022 | AA13: TPS 023 | AB13: TPS 024 | AC13: TPS 025 | AD13: TPS 026
B14: Jumlah Pemilih dalam Daftar Pemilih Tetap (DPT) | D14: LK | E14: 128 | F14: 141 | G14: 138 | H14: 130 | I14: 137 | J14: 101 | K14: 144 | L14: 119 | M14: 133 | N14: 116 | O14: 121 | P14: 145 | Q14: 148 | R14: 147 | S14: 130 | T14: 136 | U14: 150 | V14: 157 | W14: 148 | X14: 143 | Y14: 152 | Z14: 138 | AA14: 120 | AB14: 109 | AC14: 130 | AD14: 107 | AE14: =SUM(E14:AD14) -> 3468
D15: PR | E15: 130 | F15: 137 | G15: 148 | H15: 121 | I15: 128 | J15: 105 | K15: 140 | L15: 128 | M15: 134 | N15: 125 | O15: 122 | P15: 133 | Q15: 150 | R15: 145 | S15: 134 | T15: 141 | U15: 134 | V15: 141 | W15: 143 | X15: 151 | Y15: 143 | Z15: 150 | AA15: 128 | AB15: 109 | AC15: 139 | AD15: 119 | AE15: =SUM(E15:AD15) -> 3478
D16: JML | E16: =SUM(E14:E15) -> 258 | F16: =SUM(F14:F15) -> 278 | G16: =SUM(G14:G15) -> 286 | H16: =SUM(H14:H15) -> 251 | I16: =SUM(I14:I15) -> 265 | J16: =SUM(J14:J15) -> 206 | K16: =SUM(K14:K15) -> 284 | L16: =SUM(L14:L15) -> 247 | ... AD16: =SUM(AD14:AD15) -> 226 | AE16: =SUM(E16:AD16) -> 6946
A18: B | B18: PENGGUNA HAK PILIH
B19: 1. | C19: Jumlah pengguna hak pilih dalam Daftar Pemilih Tetap (DPT) | D19: LK | E19: 100 | F19: 106 | G19: 117 | H19: 94 | I19: 103 | J19: 80 | K19: 116 | L19: 89 | M19: 90 | N19: 93 | O19: 93 | P19: 109 | Q19: 114 | R19: 118 | S19: 96 | T19: 102 | U19: 106 | V19: 125 | W19: 119 | X19: 113 | Y19: 112 | Z19: 96 | AA19: 91 | AB19: 88 | AC19: 107 | AD19: 84 | AE19: =SUM(E19:AD19) -> 2661
D20: PR | E20: 108 | F20: 106 | G20: 117 | H20: 98 | I20: 105 | J20: 85 | K20: 119 | L20: 107 | M20: 110 | N20: 98 | O20: 100 | P20: 102 | Q20: 126 | R20: 114 | S20: 106 | T20: 106 | U20: 116 | V20: 110 | W20: 113 | X20: 107 | Y20: 101 | Z20: 113 | AA20: 97 | AB20: 87 | AC20: 112 | AD20: 96 | AE20: =SUM(E20:AD20) -> 2759
D21: JML | E21: 208 | F21: 212 | G21: 234 | H21: 192 | I21: 208 | J21: 165 | K21: 235 | L21: 196 | M21: 200 | N21: 191 | O21: 193 | P21: 211 | Q21: 240 | R21: 232 | S21: 202 | T21: =SUM(T19:T20) -> 208 | U21: =SUM(U19:U20) -> 222 | V21: =SUM(V19:V20) -> 235 | W21: =SUM(W19:W20) -> 232 | X21: =SUM(X19:X20) -> 220 | Y21: =SUM(Y19:Y20) -> 213 | Z21: =SUM(Z19:Z20) -> 209 | AA21: =SUM(AA19:AA20) -> 188 | ... AD21: =SUM(AD19:AD20) -> 180 | AE21: =SUM(E21:AD21) -> 5420
B22: 2. | C22: Jumlah pengguna hak pilih dalam Daftar Pemilih Tambahan (DPTb) | D22: LK | E22: 0 | F22: 0 | G22: 0 | H22: 0 | I22: 0 | J22: 1 | K22: 1 | L22: 0 | M22: 0 | N22: 0 | O22: 0 | P22: 0 | Q22: 0 | R22: 1 | S22: 1 | T22: 0 | U22: 2 | V22: 0 | W22: 0 | X22: 0 | Y22: 0 | Z22: 0 | AA22: 0 | AB22: 0 | AC22: 0 | AD22: 0 | AE22: =SUM(E22:AD22) -> 6
D23: PR | E23: 0 | F23: 0 | G23: 0 | H23: 0 | I23: 0 | J23: 0 | K23: 1 | L23: 0 | M23: 0 | N23: 1 | O23: 1 | P23: 0 | Q23: 0 | R23: 1 | S23: 0 | T23: 0 | U23: 0 | V23: 1 | W23: 1 | X23: 0 | Y23: 0 | Z23: 0 | AA23: 0 | AB23: 0 | AC23: 0 | AD23: 0 | AE23: =SUM(E23:AD23) -> 6
D24: JML | E24: 0 | F24: 0 | G24: 0 | H24: 0 | I24: 0 | J24: 1 | K24: 2 | L24: 0 | M24: 0 | N24: 1 | O24: 1 | P24: 0 | Q24: 0 | R24: 2 | S24: 1 | T24: =SUM(T22:T23) -> 0 | U24: =SUM(U22:U23) -> 2 | V24: =SUM(V22:V23) -> 1 | W24: =SUM(W22:W23) -> 1 | X24: =SUM(X22:X23) -> 0 | Y24: =SUM(Y22:Y23) -> 0 | Z24: =SUM(Z22:Z23) -> 0 | AA24: =SUM(AA22:AA23) -> 0 | ... AD24: =SUM(AD22:AD23) -> 0 | AE24: =SUM(E24:AD24) -> 12
B25: 3. | C25: Jumlah pengguna hak pilih dalam Daftar Pemilih Khusus (DPK) | D25: LK | E25: 1 | F25: 1 | G25: 1 | H25: 0 | I25: 1 | J25: 0 | K25: 0 | L25: 0 | M25: 4 | N25: 1 | O25: 0 | P25: 1 | Q25: 0 | R25: 2 | S25: 2 | T25: 0 | U25: 0 | V25: 0 | W25: 1 | X25: 0 | Y25: 0 | Z25: 2 | AA25: 0 | AB25: 0 | AC25: 1 | AD25: 0 | AE25: =SUM(E25:AD25) -> 18
D26: PR | E26: 1 | F26: 1 | G26: 1 | H26: 0 | I26: 2 | J26: 0 | K26: 0 | L26: 0 | M26: 1 | N26: 0 | O26: 1 | P26: 0 | Q26: 0 | R26: 0 | S26: 4 | T26: 1 | U26: 0 | V26: 1 | W26: 0 | X26: 0 | Y26: 1 | Z26: 2 | AA26: 0 | AB26: 0 | AC26: 0 | AD26: 1 | AE26: =SUM(E26:AD26) -> 17
D27: JML | E27: 2 | F27: 2 | G27: 2 | H27: 0 | I27: 3 | J27: 0 | K27: 0 | L27: 0 | M27: 5 | N27: 1 | O27: 1 | P27: 1 | Q27: 0 | R27: 2 | S27: 6 | T27: =SUM(T25:T26) -> 1 | U27: =SUM(U25:U26) -> 0 | V27: =SUM(V25:V26) -> 1 | W27: =SUM(W25:W26) -> 1 | X27: =SUM(X25:X26) -> 0 | Y27: =SUM(Y25:Y26) -> 1 | Z27: =SUM(Z25:Z26) -> 4 | AA27: =SUM(AA25:AA26) -> 0 | ... AD27: =SUM(AD25:AD26) -> 1 | AE27: =SUM(E27:AD27) -> 35
B28: 4. | C28: Jumlah Pengguna Hak Pilih (B.1+B.2+B.3) | D28: LK | E28: 101 | F28: 107 | G28: 118 | H28: 94 | I28: 104 | J28: 81 | K28: 117 | L28: 89 | M28: 94 | N28: 94 | O28: 93 | P28: 110 | Q28: 114 | R28: 121 | S28: 99 | T28: =SUM(T19,T22,T25) -> 102 | U28: =SUM(U19,U22,U25) -> 108 | V28: =SUM(V19,V22,V25) -> 125 | W28: =SUM(W19,W22,W25) -> 120 | X28: =SUM(X19,X22,X25) -> 113 | Y28: =SUM(Y19,Y22,Y25) -> 112 | Z28: =SUM(Z19,Z22,Z25) -> 98 | AA28: =SUM(AA19,AA22,AA25) -> 91 | ... AD28: =SUM(AD19,AD22,AD25) -> 84 | AE28: =SUM(E28:AD28) -> 2685
D29: PR | E29: 109 | F29: 107 | G29: 118 | H29: 98 | I29: 107 | J29: 85 | K29: 120 | L29: 107 | M29: 111 | N29: 99 | O29: 102 | P29: 102 | Q29: 126 | R29: 115 | S29: 110 | T29: =SUM(T20,T23,T26) -> 107 | U29: =SUM(U20,U23,U26) -> 116 | V29: =SUM(V20,V23,V26) -> 112 | W29: =SUM(W20,W23,W26) -> 114 | X29: =SUM(X20,X23,X26) -> 107 | Y29: =SUM(Y20,Y23,Y26) -> 102 | Z29: =SUM(Z20,Z23,Z26) -> 115 | AA29: =SUM(AA20,AA23,AA26) -> 97 | ... AD29: =SUM(AD20,AD23,AD26) -> 97 | AE29: =SUM(E29:AD29) -> 2782
D30: JML | E30: =SUM(E28:E29) -> 210 | F30: =SUM(F28:F29) -> 214 | G30: =SUM(G28:G29) -> 236 | H30: =SUM(H28:H29) -> 192 | I30: =SUM(I28:I29) -> 211 | J30: =SUM(J28:J29) -> 166 | K30: =SUM(K28:K29) -> 237 | L30: =SUM(L28:L29) -> 196 | ... AD30: =SUM(AD28:AD29) -> 181 | AE30: =SUM(E30:AD30) -> 5467
A32: II | B32: DATA PENGGUNAAN SURAT SUARA
A33: 1 | B33: Jumlah surat suara yang diterima, termasuk surat suara cadangan 2,5% dari DPT | E33: 261 | F33: 284 | G33: 292 | H33: 259 | I33: 271 | J33: 211 | K33: 290 | L33: 252 | M33: 273 | N33: 246 | O33: 249 | P33: 284 | Q33: 305 | R33: 299 | S33: 270 | T33: 283 | U33: 290 | V33: 304 | W33: 297 | X33: 300 | Y33: 301 | Z33: 299 | AA33: 253 | AB33: 223 | AC33: 275 | AD33: 231 | AE33: =SUM(E33:AD33) -> 7102
A34: 2 | B34: Jumlah surat suara yang digunakan | E34: 210 | F34: 214 | G34: 236 | H34: 192 | I34: 211 | J34: 166 | K34: 237 | L34: 196 | M34: 205 | N34: 193 | O34: 195 | P34: 212 | Q34: 240 | R34: 236 | S34: 209 | T34: 209 | U34: 224 | V34: 237 | W34: 234 | X34: 220 | Y34: 214 | Z34: 213 | AA34: 188 | AB34: 175 | AC34: 220 | AD34: 181 | AE34: =SUM(E34:AD34) -> 5467
A35: 3 | B35: Jumlah surat suara dikembalikan oleh pemilih (karena rusak atau keliru coblos) | E35: 0 | F35: 0 | G35: 0 | H35: 0 | I35: 0 | J35: 0 | K35: 1 | L35: 0 | M35: 0 | N35: 2 | O35: 0 | P35: 3 | Q35: 0 | R35: 0 | S35: 0 | T35: 0 | U35: 0 | V35: 0 | W35: 0 | X35: 0 | Y35: 16 | Z35: 0 | AA35: 0 | AB35: 3 | AC35: 0 | AD35: 0 | AE35: =SUM(E35:AD35) -> 25
A36: 4 | B36: Jumlah surat suara yang tidak digunakan/tidak terpakai, termasuk sisa surat suara cadangan | E36: 51 | F36: 70 | G36: 56 | H36: 67 | I36: 60 | J36: 45 | K36: 52 | L36: 56 | M36: 68 | N36: 51 | O36: 54 | P36: 69 | Q36: 65 | R36: 63 | S36: 61 | T36: =T33-(T34+T35) -> 74 | U36: =U33-(U34+U35) -> 66 | V36: =V33-(V34+V35) -> 67 | W36: =W33-(W34+W35) -> 63 | X36: =X33-(X34+X35) -> 80 | Y36: =Y33-(Y34+Y35) -> 71 | Z36: =Z33-(Z34+Z35) -> 86 | AA36: =AA33-(AA34+AA35) -> 65 | ... AD36: =AD33-(AD34+AD35) -> 50 | AE36: =SUM(E36:AD36) -> 1610
A38: III | B38: DATA PEMILIH DISABILITAS
B39: Jumlah seluruh Pemilih disabilitas yang menggunakan hak pilih | D39: LK | E39: 1 | F39: 0 | G39: 0 | H39: 0 | I39: 0 | J39: 0 | K39: 0 | L39: 0 | M39: 0 | N39: 0 | O39: 0 | P39: 5 | Q39: 0 | R39: 0 | S39: 0 | T39: 0 | U39: 0 | V39: 0 | W39: 0 | X39: 0 | Y39: 0 | Z39: 0 | AA39: 0 | AB39: 0 | AC39: 0 | AD39: 0 | AE39: =SUM(E39:AD39) -> 6
D40: PR | E40: 0 | F40: 0 | G40: 0 | H40: 0 | I40: 0 | J40: 0 | K40: 0 | L40: 0 | M40: 0 | N40: 0 | O40: 0 | P40: 4 | Q40: 0 | R40: 0 | S40: 0 | T40: 0 | U40: 0 | V40: 0 | W40: 0 | X40: 0 | Y40: 0 | Z40: 0 | AA40: 0 | AB40: 0 | AC40: 0 | AD40: 0 | AE40: =SUM(E40:AD40) -> 4
D41: JML | E41: =SUM(E39:E40) -> 1 | F41: =SUM(F39:F40) -> 0 | G41: =SUM(G39:G40) -> 0 | H41: =SUM(H39:H40) -> 0 | I41: =SUM(I39:I40) -> 0 | J41: =SUM(J39:J40) -> 0 | K41: =SUM(K39:K40) -> 0 | L41: =SUM(L39:L40) -> 0 | ... AD41: =SUM(AD39:AD40) -> 0 | AE41: =SUM(E41:AD41) -> 10
A43: IV | B43: DATA RINCIAN PEROLEHAN SUARA PASANGAN CALON BUPATI DAN WAKIL BUPATI
A44: NOMOR DAN NAMA CALON
B45: 1. | C45: AA. AHMAD NAWARDI | E45: 19 | F45: 10 | G45: 13 | H45: 10 | I45: 12 | J45: 11 | K45: 17 | L45: 7 | M45: 24 | N45: 16 | O45: 18 | P45: 19 | Q45: 19 | R45: 23 | S45: 17 | T45: 16 | U45: 19 | V45: 14 | W45: 5 | X45: 14 | Y45: 9 | Z45: 12 | AA45: 15 | AB45: 7 | AC45: 17 | AD45: 9 | AE45: 24
B46: 2. | C46: Ir. H. AA LA NYALLA MAHMUD MATTALITI, M.HP. | E46: 31 | F46: 14 | G46: 31 | H46: 9 | I46: 18 | J46: 13 | K46: 61 | L46: 31 | M46: 27 | N46: 19 | O46: 19 | P46: 51 | Q46: 43 | R46: 26 | S46: 25 | T46: 30 | U46: 27 | V46: 34 | W46: 45 | X46: 30 | Y46: 23 | Z46: 28 | AA46: 27 | AB46: 22 | AC46: 30 | AD46: 28 | AE46: 32
B47: 3. | C47: ABDUL QADIR AMIR HARTONO, S.E., S.H., M.H. | E47: 21 | F47: 14 | G47: 15 | H47: 20 | I47: 13 | J47: 17 | K47: 12 | L47: 7 | M47: 18 | N47: 10 | O47: 11 | P47: 20 | Q47: 21 | R47: 19 | S47: 16 | T47: 16 | U47: 14 | V47: 12 | W47: 9 | X47: 7 | Y47: 23 | Z47: 15 | AA47: 9 | AB47: 17 | AC47: 18 | AD47: 8 | AE47: 15
B48: 4. | C48: ADILLA AZIS, S.E. | E48: 24 | F48: 29 | G48: 27 | H48: 23 | I48: 24 | J48: 32 | K48: 30 | L48: 21 | M48: 23 | N48: 21 | O48: 21 | P48: 19 | Q48: 34 | R48: 25 | S48: 25 | T48: 22 | U48: 27 | V48: 34 | W48: 28 | X48: 33 | Y48: 25 | Z48: 32 | AA48: 22 | AB48: 26 | AC48: 27 | AD48: 16 | AE48: 21
B49: 5. | C49: Ir. H. AGUS RAHARDJO, MSc.M. | E49: 15 | F49: 17 | G49: 18 | H49: 14 | I49: 20 | J49: 26 | K49: 22 | L49: 21 | M49: 15 | N49: 21 | O49: 17 | P49: 10 | Q49: 17 | R49: 26 | S49: 24 | T49: 18 | U49: 24 | V49: 12 | W49: 19 | X49: 10 | Y49: 14 | Z49: 11 | AA49: 16 | AB49: 5 | AC49: 11 | AD49: 39 | AE49: 31
B50: 6. | C50: Drs. AYUB KHAN | E50: 10 | F50: 10 | G50: 8 | H50: 5 | I50: 15 | J50: 4 | K50: 7 | L50: 17 | M50: 14 | N50: 11 | O50: 11 | P50: 5 | Q50: 8 | R50: 15 | S50: 9 | T50: 24 | U50: 8 | V50: 5 | W50: 11 | X50: 11 | Y50: 5 | Z50: 9 | AA50: 20 | AB50: 3 | AC50: 11 | AD50: 8 | AE50: 11
B51: 7. | C51: BAMBANG HARIANTO | E51: 3 | F51: 5 | G51: 3 | H51: 1 | I51: 3 | J51: 3 | K51: 7 | L51: 3 | M51: 0 | N51: 3 | O51: 2 | P51: 0 | Q51: 8 | R51: 3 | S51: 5 | T51: 1 | U51: 1 | V51: 4 | W51: 2 | X51: 2 | Y51: 2 | Z51: 4 | AA51: 1 | AB51: 0 | AC51: 4 | AD51: 1 | AE51: 1
...

Sheet SARIMULYO
C2: Kecamatan | D2: CLURING
C3: Kabupaten | D3: BANYUWANGI
C4: Provinsi | D4: JAWA TIMUR
C9: Kelurahan | D9: SARIMULYO
A12: I | B12: DATA PEMILIH DAN PENGGUNAAN HAK PILIH | AA12: JUMLAH AKHIR
A13: A | B13: DATA PEMILIH | E13: TPS 001 | F13: TPS 002 | G13: TPS 003 | H13: TPS 004 | I13: TPS 005 | J13: TPS 006 | K13: TPS 007 | L13: TPS 008 | M13: TPS 009 | N13: TPS 010 | O13: TPS 011 | P13: TPS 012 | Q13: TPS 013 | R13: TPS 014 | S13: TPS 015 | T13: TPS 016 | U13: TPS 017 | V13: TPS 018 | W13: TPS 019 | X13: TPS 020 | Y13: TPS 021 | Z13: TPS 022
B14: Jumlah Pemilih dalam Daftar Pemilih Tetap (DPT) | D14: LK | E14: 143 | F14: 119 | G14: 113 | H14: 127 | I14: 135 | J14: 129 | K14: 128 | L14: 102 | M14: 122 | N14: 114 | O14: 136 | P14: 113 | Q14: 124 | R14: 135 | S14: 125 | T14: 110 | U14: 115 | V14: 126 | W14: 143 | X14: 155 | Y14: 143 | Z14: 137 | AA14: =SUM(E14:Z14) -> 2794
D15: PR | E15: 125 | F15: 134 | G15: 114 | H15: 133 | I15: 137 | J15: 152 | K15: 136 | L15: 110 | M15: 120 | N15: 117 | O15: 129 | P15: 135 | Q15: 118 | R15: 137 | S15: 122 | T15: 115 | U15: 114 | V15: 139 | W15: 137 | X15: 142 | Y15: 149 | Z15: 132 | AA15: =SUM(E15:Z15) -> 2847
D16: JML | E16: =SUM(E14:E15) -> 268 | F16: =SUM(F14:F15) -> 253 | G16: =SUM(G14:G15) -> 227 | H16: =SUM(H14:H15) -> 260 | I16: =SUM(I14:I15) -> 272 | J16: =SUM(J14:J15) -> 281 | K16: =SUM(K14:K15) -> 264 | L16: =SUM(L14:L15) -> 212 | ... Z16: =SUM(Z14:Z15) -> 269 | AA16: =SUM(E16:Z16) -> 5641
A18: B | B18: PENGGUNA HAK PILIH
B19: 1. | C19: Jumlah pengguna hak pilih dalam Daftar Pemilih Tetap (DPT) | D19: LK | E19: 103 | F19: 93 | G19: 79 | H19: 82 | I19: 98 | J19: 95 | K19: 91 | L19: 71 | M19: 92 | N19: 78 | O19: 103 | P19: 94 | Q19: 96 | R19: 96 | S19: 88 | T19: 78 | U19: 94 | V19: 85 | W19: 96 | X19: 119 | Y19: 103 | Z19: 115 | AA19: =SUM(E19:Z19) -> 2049
D20: PR | E20: 104 | F20: 113 | G20: 88 | H20: 106 | I20: 104 | J20: 124 | K20: 107 | L20: 74 | M20: 101 | N20: 84 | O20: 103 | P20: 113 | Q20: 97 | R20: 111 | S20: 94 | T20: 87 | U20: 87 | V20: 118 | W20: 104 | X20: 122 | Y20: 122 | Z20: 113 | AA20: =SUM(E20:Z20) -> 2276
D21: JML | E21: 207 | F21: 206 | G21: 167 | H21: 188 | I21: 202 | J21: 219 | K21: 198 | L21: 145 | M21: 193 | N21: 162 | O21: 206 | P21: 207 | Q21: 193 | R21: 207 | S21: 182 | T21: 165 | U21: 181 | V21: 203 | W21: 200 | X21: 241 | Y21: 225 | Z21: 228 | AA21: =SUM(E21:Z21) -> 4325
B22: 2. | C22: Jumlah pengguna hak pilih dalam Daftar Pemilih Tambahan (DPTb) | D22: LK | E22: 0 | F22: 0 | G22: 0 | H22: 0 | I22: 0 | J22: 0 | K22: 1 | L22: 0 | M22: 0 | N22: 0 | O22: 0 | P22: 0 | Q22: 0 | R22: 0 | S22: 0 | T22: 0 | U22: 0 | V22: 0 | W22: 0 | X22: 0 | Y22: 0 | Z22: 0 | AA22: =SUM(E22:Z22) -> 1
D23: PR | E23: 0 | F23: 0 | G23: 0 | H23: 0 | I23: 0 | J23: 0 | K23: 0 | L23: 0 | M23: 0 | N23: 0 | O23: 0 | P23: 0 | Q23: 0 | R23: 0 | S23: 0 | T23: 0 | U23: 0 | V23: 0 | W23: 0 | X23: 0 | Y23: 0 | Z23: 0 | AA23: =SUM(E23:Z23) -> 0
D24: JML | E24: 0 | F24: 0 | G24: 0 | H24: 0 | I24: 0 | J24: 0 | K24: 1 | L24: 0 | M24: 0 | N24: 0 | O24: 0 | P24: 0 | Q24: 0 | R24: 0 | S24: 0 | T24: 0 | U24: 0 | V24: 0 | W24: 0 | X24: 0 | Y24: 0 | Z24: 0 | AA24: =SUM(E24:Z24) -> 1
B25: 3. | C25: Jumlah pengguna hak pilih dalam Daftar Pemilih Khusus (DPK) | D25: LK | E25: 3 | F25: 1 | G25: 2 | H25: 0 | I25: 2 | J25: 3 | K25: 1 | L25: 1 | M25: 1 | N25: 2 | O25: 0 | P25: 0 | Q25: 2 | R25: 3 | S25: 2 | T25: 0 | U25: 1 | V25: 2 | W25: 0 | X25: 0 | Y25: 0 | Z25: 0 | AA25: =SUM(E25:Z25) -> 26
D26: PR | E26: 2 | F26: 3 | G26: 2 | H26: 1 | I26: 2 | J26: 2 | K26: 0 | L26: 3 | M26: 4 | N26: 3 | O26: 3 | P26: 3 | Q26: 2 | R26: 3 | S26: 4 | T26: 0 | U26: 4 | V26: 2 | W26: 0 | X26: 0 | Y26: 0 | Z26: 0 | AA26: =SUM(E26:Z26) -> 43
D27: JML | E27: 5 | F27: 4 | G27: 4 | H27: 1 | I27: 4 | J27: 5 | K27: 1 | L27: 4 | M27: 5 | N27: 5 | O27: 3 | P27: 3 | Q27: 4 | R27: 6 | S27: 6 | T27: 0 | U27: 5 | V27: 4 | W27: 0 | X27: 0 | Y27: 0 | Z27: 0 | AA27: =SUM(E27:Z27) -> 69
B28: 4. | C28: Jumlah Pengguna Hak Pilih (B.1+B.2+B.3) | D28: LK | E28: 106 | F28: 94 | G28: 81 | H28: 82 | I28: 100 | J28: 98 | K28: 93 | L28: 72 | M28: 93 | N28: 80 | O28: 103 | P28: 94 | Q28: 98 | R28: 99 | S28: 90 | T28: 78 | U28: 95 | V28: 87 | W28: 98 | X28: 119 | Y28: 103 | Z28: 115 | AA28: =SUM(E28:Z28) -> 2078
D29: PR | E29: 106 | F29: 116 | G29: 90 | H29: 107 | I29: 106 | J29: 126 | K29: 107 | L29: 77 | M29: 105 | N29: 87 | O29: 106 | P29: 116 | Q29: 99 | R29: 114 | S29: 98 | T29: 87 | U29: 91 | V29: 120 | W29: 104 | X29: 122 | Y29: 122 | Z29: 113 | AA29: =SUM(E29:Z29) -> 2319
D30: JML | E30: 212 | F30: 210 | G30: 171 | H30: 189 | I30: 206 | J30: 224 | K30: 200 | L30: 149 | M30: 198 | N30: 167 | O30: 209 | P30: 210 | Q30: 197 | R30: 213 | S30: 188 | T30: =SUM(T28:T29) -> 165 | U30: =SUM(U28:U29) -> 186 | V30: =SUM(V28:V29) -> 207 | W30: =SUM(W28:W29) -> 202 | X30: =SUM(X28:X29) -> 241 | Y30: =SUM(Y28:Y29) -> 225 | Z30: =SUM(Z28:Z29) -> 228 | AA30: =SUM(E30:Z30) -> 4397
A32: II | B32: DATA PENGGUNAAN SURAT SUARA
A33: 1 | B33: Jumlah surat suara yang diterima, termasuk surat suara cadangan 2,5% dari DPT | E33: 274 | F33: 259 | G33: 232 | H33: 261 | I33: 275 | J33: 288 | K33: 291 | L33: 217 | M33: 247 | N33: 248 | O33: 272 | P33: 256 | Q33: 247 | R33: 280 | S33: 242 | T33: 230 | U33: 234 | V33: 273 | W33: 286 | X33: 304 | Y33: 298 | Z33: 275 | AA33: =SUM(E33:Z33) -> 5789
A34: 2 | B34: Jumlah surat suara yang digunakan | E34: 212 | F34: 210 | G34: 171 | H34: 189 | I34: 206 | J34: 224 | K34: 200 | L34: 149 | M34: 198 | N34: 167 | O34: 209 | P34: 210 | Q34: 197 | R34: 213 | S34: 188 | T34: 165 | U34: 186 | V34: 207 | W34: 202 | X34: 241 | Y34: 225 | Z34: 228 | AA34: =SUM(E34:Z34) -> 4397
A35: 3 | B35: Jumlah surat suara dikembalikan oleh pemilih (karena rusak atau keliru coblos) | E35: 0 | F35: 0 | G35: 0 | H35: 0 | I35: 0 | J35: 0 | K35: 0 | L35: 0 | M35: 0 | N35: 0 | O35: 0 | P35: 0 | Q35: 0 | R35: 0 | S35: 0 | T35: 0 | U35: 0 | V35: 0 | W35: 0 | X35: 0 | Y35: 0 | Z35: 0 | AA35: =SUM(E35:Z35) -> 0
A36: 4 | B36: Jumlah surat suara yang tidak digunakan/tidak terpakai, termasuk sisa surat suara cadangan | E36: 62 | F36: 49 | G36: 61 | H36: 72 | I36: 69 | J36: 64 | K36: 91 | L36: 68 | M36: 49 | N36: 81 | O36: 63 | P36: 46 | Q36: 50 | R36: 67 | S36: 54 | T36: 65 | U36: 48 | V36: 66 | W36: 84 | X36: 63 | Y36: 73 | Z36: 47 | AA36: =SUM(E36:Z36) -> 1392
A38: III | B38: DATA PEMILIH DISABILITAS
B39: Jumlah seluruh Pemilih disabilitas yang menggunakan hak pilih | D39: LK | E39: 0 | F39: 0 | G39: 0 | H39: 0 | I39: 0 | J39: 0 | K39: 0 | L39: 0 | M39: 0 | N39: 0 | O39: 0 | P39: 0 | Q39: 0 | R39: 0 | S39: 0 | T39: 0 | U39: 0 | V39: 0 | W39: 0 | X39: 0 | Y39: 0 | Z39: 0 | AA39: =SUM(E39:Z39) -> 0
D40: PR | E40: 0 | F40: 0 | G40: 0 | H40: 0 | I40: 0 | J40: 0 | K40: 0 | L40: 0 | M40: 0 | N40: 0 | O40: 0 | P40: 0 | Q40: 0 | R40: 2 | S40: 0 | T40: 0 | U40: 0 | V40: 0 | W40: 0 | X40: 0 | Y40: 0 | Z40: 0 | AA40: =SUM(E40:Z40) -> 2
D41: JML | E41: =SUM(E39:E40) -> 0 | F41: =SUM(F39:F40) -> 0 | G41: =SUM(G39:G40) -> 0 | H41: =SUM(H39:H40) -> 0 | I41: =SUM(I39:I40) -> 0 | J41: =SUM(J39:J40) -> 0 | K41: =SUM(K39:K40) -> 0 | L41: =SUM(L39:L40) -> 0 | ... Z41: =SUM(Z39:Z40) -> 0 | AA41: =SUM(E41:Z41) -> 2
A43: IV | B43: DATA RINCIAN PEROLEHAN SUARA PASANGAN CALON BUPATI DAN WAKIL BUPATI
A44: NOMOR DAN NAMA CALON
B45: 1. | C45: AA. AHMAD NAWARDI | E45: 12 | F45: 13 | G45: 20 | H45: 19 | I45: 11 | J45: 5 | K45: 8 | L45: 6 | M45: 10 | N45: 11 | O45: 10 | P45: 10 | Q45: 6 | R45: 20 | S45: 15 | T45: 5 | U45: 8 | V45: 13 | W45: 12 | X45: 15 | Y45: 23 | Z45: 14 | AA45: =SUM(E45:Z45) -> 266
B46: 2. | C46: Ir. H. AA LA NYALLA MAHMUD MATTALITI, M.HP. | E46: 30 | F46: 21 | G46: 32 | H46: 24 | I46: 35 | J46: 37 | K46: 30 | L46: 20 | M46: 22 | N46: 38 | O46: 28 | P46: 22 | Q46: 31 | R46: 29 | S46: 23 | T46: 37 | U46: 38 | V46: 49 | W46: 71 | X46: 40 | Y46: 41 | Z46: 36 | AA46: =SUM(E46:Z46) -> 734
B47: 3. | C47: ABDUL QADIR AMIR HARTONO, S.E., S.H., M.H. | E47: 15 | F47: 11 | G47: 9 | H47: 22 | I47: 9 | J47: 10 | K47: 11 | L47: 6 | M47: 14 | N47: 4 | O47: 19 | P47: 10 | Q47: 23 | R47: 19 | S47: 13 | T47: 5 | U47: 9 | V47: 11 | W47: 10 | X47: 17 | Y47: 20 | Z47: 11 | AA47: =SUM(E47:Z47) -> 278
B48: 4. | C48: ADILLA AZIS, S.E. | E48: 20 | F48: 31 | G48: 29 | H48: 33 | I48: 23 | J48: 25 | K48: 27 | L48: 20 | M48: 19 | N48: 19 | O48: 24 | P48: 22 | Q48: 22 | R48: 29 | S48: 13 | T48: 11 | U48: 14 | V48: 18 | W48: 11 | X48: 31 | Y48: 22 | Z48: 26 | AA48: =SUM(E48:Z48) -> 489
B49: 5. | C49: Ir. H. AGUS RAHARDJO, MSc.M. | E49: 11 | F49: 23 | G49: 10 | H49: 10 | I49: 10 | J49: 25 | K49: 14 | L49: 8 | M49: 17 | N49: 12 | O49: 18 | P49: 21 | Q49: 26 | R49: 11 | S49: 11 | T49: 6 | U49: 14 | V49: 11 | W49: 8 | X49: 16 | Y49: 15 | Z49: 14 | AA49: =SUM(E49:Z49) -> 311
