Workbook

Sheet DPD
C8: Kecamatan | D8: KALIPURO
C9: Kabupaten | D9: BANYUWANGI
C10: Provinsi | D10: JAWA TIMUR
A12: I | B12: DATA PEMILIH DAN PENGGUNAAN HAK PILIH | E12: JUMLAH AKHIR
A13: A | B13: DATA PEMILIH
B14: Jumlah Pemilih dalam Daftar Pemilih Tetap (DPT) | D14: LK | E14: =KETAPANG!BE14+BULUSAN!AC14+KLATAK!AV14+KALIPURO!AR14+GOMBENGSARI!AC14+KELIR!W14+PESUCEN!R14+TELEMUNG!T14+BULUSARI!R14 -> 31987
D15: PR | E15: =KETAPANG!BE15+BULUSAN!AC15+KLATAK!AV15+KALIPURO!AR15+GOMBENGSARI!AC15+KELIR!W15+PESUCEN!R15+TELEMUNG!T15+BULUSARI!R15 -> 33057
D16: JML | E16: =SUM(E14:E15) -> 65044
A18: B | B18: PENGGUNA HAK PILIH
B19: 1. | C19: Jumlah pengguna hak pilih dalam Daftar Pemilih Tetap (DPT) | D19: LK | E19: =KETAPANG!BE19+BULUSAN!AC19+KLATAK!AV19+KALIPURO!AR19+GOMBENGSARI!AC19+KELIR!W19+PESUCEN!R19+TELEMUNG!T19+BULUSARI!R19 -> 24074
D20: PR | E20: =KETAPANG!BE20+BULUSAN!AC20+KLATAK!AV20+KALIPURO!AR20+GOMBENGSARI!AC20+KELIR!W20+PESUCEN!R20+TELEMUNG!T20+BULUSARI!R20 -> 26769
D21: JML | E21: =SUM(E19:E20) -> 50843
B22: 2. | C22: Jumlah pengguna hak pilih dalam Daftar Pemilih Tambahan (DPTb) | D22: LK | E22: =KETAPANG!BE22+BULUSAN!AC22+KLATAK!AV22+KALIPURO!AR22+GOMBENGSARI!AC22+KELIR!W22+PESUCEN!R22+TELEMUNG!T22+BULUSARI!R22 -> 142
D23: PR | E23: =KETAPANG!BE23+BULUSAN!AC23+KLATAK!AV23+KALIPURO!AR23+GOMBENGSARI!AC23+KELIR!W23+PESUCEN!R23+TELEMUNG!T23+BULUSARI!R23 -> 113
D24: JML | E24: =SUM(E22:E23) -> 255
B25: 3. | C25: Jumlah pengguna hak pilih dalam Daftar Pemilih Khusus (DPK) | D25: LK | E25: =KETAPANG!BE25+BULUSAN!AC25+KLATAK!AV25+KALIPURO!AR25+GOMBENGSARI!AC25+KELIR!W25+PESUCEN!R25+TELEMUNG!T25+BULUSARI!R25 -> 351
D26: PR | E26: =KETAPANG!BE26+BULUSAN!AC26+KLATAK!AV26+KALIPURO!AR26+GOMBENGSARI!AC26+KELIR!W26+PESUCEN!R26+TELEMUNG!T26+BULUSARI!R26 -> 423
D27: JML | E27: =SUM(E25:E26) -> 774
B28: 4. | C28: Jumlah Pengguna Hak Pilih (B.1+B.2+B.3) | D28: LK | E28: =E19+E22+E25 -> 24567
D29: PR | E29: =E20+E23+E26 -> 27305
D30: JML | E30: =SUM(E28:E29) -> 51872
A32: II | B32: DATA PENGGUNAAN SURAT SUARA
A33: 1 | B33: Jumlah surat suara yang diterima, termasuk surat suara cadangan 2,5% dari DPT | E33: =KETAPANG!BE33+BULUSAN!AC33+KLATAK!AV33+KALIPURO!AR33+GOMBENGSARI!AC33+KELIR!W33+PESUCEN!R33+TELEMUNG!T33+BULUSARI!R33 -> 64880
A34: 2 | B34: Jumlah surat suara yang digunakan | E34: =KETAPANG!BE34+BULUSAN!AC34+KLATAK!AV34+KALIPURO!AR34+GOMBENGSARI!AC34+KELIR!W34+PESUCEN!R34+TELEMUNG!T34+BULUSARI!R34 -> 51872
A35: 3 | B35: Jumlah surat suara dikembalikan oleh pemilih (karena rusak atau keliru coblos) | E35: =KETAPANG!BE35+BULUSAN!AC35+KLATAK!AV35+KALIPURO!AR35+GOMBENGSARI!AC35+KELIR!W35+PESUCEN!R35+TELEMUNG!T35+BULUSARI!R35 -> 55
A36: 4 | B36: Jumlah surat suara yang tidak digunakan/tidak terpakai, termasuk sisa surat suara cadangan | E36: =E33-(E34+E35) -> 12953
A38: III | B38: DATA PEMILIH DISABILITAS
B39: Jumlah seluruh Pemilih disabilitas yang menggunakan hak pilih | D39: LK | E39: =KETAPANG!BE39+BULUSAN!AC39+KLATAK!AV39+KALIPURO!AR39+GOMBENGSARI!AC39+KELIR!W39+PESUCEN!R39+TELEMUNG!T39+BULUSARI!R39 -> 64
D40: PR | E40: =KETAPANG!BE40+BULUSAN!AC40+KLATAK!AV40+KALIPURO!AR40+GOMBENGSARI!AC40+KELIR!W40+PESUCEN!R40+TELEMUNG!T40+BULUSARI!R40 -> 85
D41: JML | E41: =SUM(E39:E40) -> 149
A43: IV | B43: DATA RINCIAN PEROLEHAN SUARA PASANGAN CALON BUPATI DAN WAKIL BUPATI
B44: NOMOR DAN NAMA CALON | E44: =KETAPANG!BE44+BULUSAN!AC44+KLATAK!AV44+KALIPURO!AR44+GOMBENGSARI!AC44+KELIR!W44+PESUCEN!R44+TELEMUNG!T44+BULUSARI!R44 -> 0
B45: 1. | C45: AA. AHMAD NAWARDI | E45: =KETAPANG!BE45+BULUSAN!AC45+KLATAK!AV45+KALIPURO!AR45+GOMBENGSARI!AC45+KELIR!W45+PESUCEN!R45+TELEMUNG!T45+BULUSARI!R45 -> 5150
B46: 2. | C46: Ir. H. AA LA NYALLA MAHMUD MATTALITI, M.HP. | E46: =KETAPANG!BE46+BULUSAN!AC46+KLATAK!AV46+KALIPURO!AR46+GOMBENGSARI!AC46+KELIR!W46+PESUCEN!R46+TELEMUNG!T46+BULUSARI!R46 -> 7942
B47: 3. | C47: ABDUL QADIR AMIR HARTONO, S.E., S.H., M.H. | E47: =KETAPANG!BE47+BULUSAN!AC47+KLATAK!AV47+KALIPURO!AR47+GOMBENGSARI!AC47+KELIR!W47+PESUCEN!R47+TELEMUNG!T47+BULUSARI!R47 -> 3316
B48: 4. | C48: ADILLA AZIS, S.E. | E48: =KETAPANG!BE48+BULUSAN!AC48+KLATAK!AV48+KALIPURO!AR48+GOMBENGSARI!AC48+KELIR!W48+PESUCEN!R48+TELEMUNG!T48+BULUSARI!R48 -> 4517
B49: 5. | C49: Ir. H. AGUS RAHARDJO, MSc.M. | E49: =KETAPANG!BE49+BULUSAN!AC49+KLATAK!AV49+KALIPURO!AR49+GOMBENGSARI!AC49+KELIR!W49+PESUCEN!R49+TELEMUNG!T49+BULUSARI!R49 -> 4440
B50: 6. | C50: Drs. AYUB KHAN | E50: =KETAPANG!BE50+BULUSAN!AC50+KLATAK!AV50+KALIPURO!AR50+GOMBENGSARI!AC50+KELIR!W50+PESUCEN!R50+TELEMUNG!T50+BULUSARI!R50 -> 3948
B51: 7. | C51: BAMBANG HARIANTO | E51: =KETAPANG!BE51+BULUSAN!AC51+KLATAK!AV51+KALIPURO!AR51+GOMBENGSARI!AC51+KELIR!W51+PESUCEN!R51+TELEMUNG!T51+BULUSARI!R51 -> 550
B52: 8. | C52: CATUR RUDI UTANTO, S.Sos. | E52: =KETAPANG!BE52+BULUSAN!AC52+KLATAK!AV52+KALIPURO!AR52+GOMBENGSARI!AC52+KELIR!W52+PESUCEN!R52+TELEMUNG!T52+BULUSARI!R52 -> 933
...

Sheet KETAPANG
C2: Kecamatan | D2: KALIPURO
C3: Kabupaten | D3: BANYUWANGI
C4: Provinsi | D4: JAWA TIMUR
C9: Kelurahan | D9: KETAPANG
A12: I | B12: DATA PEMILIH DAN PENGGUNAAN HAK PILIH | BE12: JUMLAH AKHIR
A13: A | B13: DATA PEMILIH | E13: TPS 001 | F13: TPS 002 | G13: TPS 003 | H13: TPS 004 | I13: TPS 005 | J13: TPS 006 | K13: TPS 007 | L13: TPS 008 | M13: TPS 009 | N13: TPS 010 | O13: TPS 011 | P13: TPS 012 | Q13: TPS 013 | R13: TPS 014 | S13: TPS 015 | T13: TPS 016 | U13: TPS 017 | V13: TPS 018 | W13: TPS 019 | X13: TPS 020 | Y13: TPS 021 | Z13: TPS 022 | AA13: TPS 023 | AB13: TPS 024 | AC13: TPS 025 | AD13: TPS 026 | AE13: TPS 027 | AF13: TPS 028 | AG13: TPS 029 | AH13: TPS 030 | AI13: TPS 031 | AJ13: TPS 032 | AK13: TPS 033 | AL13: TPS 034 | AM13: TPS 035 | AN13: TPS 036 | AO13: TPS 037 | AP13: TPS 038 | AQ13: TPS 039 | AR13: TPS 040 | AS13: TPS 041 | AT13: TPS 042 | AU13: TPS 043 | AV13: TPS 044 | AW13: TPS 045 | AX13: TPS 046 | AY13: TPS 047 | AZ13: TPS 048 | BA13: TPS 049 | BB13: TPS 050 | BC13: TPS 051 | BD13: TPS 052
B14: Jumlah Pemilih dalam Daftar Pemilih Tetap (DPT) | D14: LK | E14: 138 | F14: 139 | G14: 141 | H14: 142 | I14: 141 | J14: 101 | K14: 124 | L14: 133 | M14: 108 | N14: 93 | O14: 138 | P14: 122 | Q14: 138 | R14: 144 | S14: 140 | T14: 125 | U14: 124 | V14: 128 | W14: 112 | X14: 95 | Y14: 140 | Z14: 128 | AA14: 139 | AB14: 146 | AC14: 149 | AD14: 140 | AE14: 107 | AF14: 142 | AG14: 142 | AH14: 141 | AI14: 133 | AJ14: 135 | AK14: 132 | AL14: 146 | AM14: 127 | AN14: 148 | AO14: 143 | AP14: 131 | AQ14: 98 | AR14: 143 | AS14: 135 | AT14: 136 | AU14: 137 | AV14: 139 | AW14: 123 | AX14: 125 | AY14: 91 | AZ14: 137 | BA14: 121 | BB14: 125 | BC14: 121 | BD14: 116 | BE14: =SUM(E14:BD14) -> 6742
D15: PR | E15: 128 | F15: 132 | G15: 148 | H15: 139 | I15: 142 | J15: 125 | K15: 155 | L15: 131 | M15: 107 | N15: 94 | O15: 156 | P15: 129 | Q15: 148 | R15: 139 | S15: 136 | T15: 132 | U15: 139 | V15: 141 | W15: 123 | X15: 100 | Y15: 142 | Z15: 146 | AA15: 146 | AB15: 154 | AC15: 150 | AD15: 157 | AE15: 105 | AF15: 153 | AG15: 145 | AH15: 147 | AI15: 140 | AJ15: 155 | AK15: 124 | AL15: 150 | AM15: 142 | AN15: 148 | AO15: 154 | AP15: 135 | AQ15: 120 | AR15: 147 | AS15: 149 | AT15: 134 | AU15: 133 | AV15: 133 | AW15: 129 | AX15: 137 | AY15: 102 | AZ15: 147 | BA15: 126 | BB15: 126 | BC15: 134 | BD15: 104 | BE15: =SUM(E15:BD15) -> 7058
D16: JML | E16: =SUM(E14:E15) -> 266 | F16: =SUM(F14:F15) -> 271 | G16: =SUM(G14:G15) -> 289 | H16: =SUM(H14:H15) -> 281 | I16: =SUM(I14:I15) -> 283 | J16: =SUM(J14:J15) -> 226 | K16: =SUM(K14:K15) -> 279 | L16: =SUM(L14:L15) -> 264 | ... BD16: =SUM(BD14:BD15) -> 220 | BE16: =SUM(E16:BD16) -> 13800
A18: B | B18: PENGGUNA HAK PILIH
B19: 1. | C19: Jumlah pengguna hak pilih dalam Daftar Pemilih Tetap (DPT) | D19: LK | E19: 98 | F19: 98 | G19: 96 | H19: 100 | I19: 100 | J19: 70 | K19: 81 | L19: 85 | M19: 75 | N19: 71 | O19: 77 | P19: 74 | Q19: 94 | R19: 97 | S19: 83 | T19: 91 | U19: 72 | V19: 92 | W19: 68 | X19: 78 | Y19: 104 | Z19: 99 | AA19: 129 | AB19: 116 | AC19: 114 | AD19: 110 | AE19: 90 | AF19: 118 | AG19: 102 | AH19: 120 | AI19: 105 | AJ19: 100 | AK19: 97 | AL19: 96 | AM19: 90 | AN19: 101 | AO19: 97 | AP19: 96 | AQ19: 67 | AR19: 97 | AS19: 95 | AT19: 100 | AU19: 103 | AV19: 110 | AW19: 104 | AX19: 83 | AY19: 65 | AZ19: 103 | BA19: 94 | BB19: 92 | BC19: 94 | BD19: 77 | BE19: =SUM(E19:BD19) -> 4868
D20: PR | E20: 100 | F20: 97 | G20: 117 | H20: 112 | I20: 118 | J20: 97 | K20: 115 | L20: 106 | M20: 84 | N20: 76 | O20: 98 | P20: 92 | Q20: 117 | R20: 108 | S20: 107 | T20: 106 | U20: 100 | V20: 110 | W20: 90 | X20: 88 | Y20: 113 | Z20: 119 | AA20: 137 | AB20: 127 | AC20: 151 | AD20: 152 | AE20: 97 | AF20: 118 | AG20: 121 | AH20: 127 | AI20: 114 | AJ20: 120 | AK20: 104 | AL20: 117 | AM20: 105 | AN20: 118 | AO20: 118 | AP20: 104 | AQ20: 94 | AR20: 114 | AS20: 122 | AT20: 104 | AU20: 101 | AV20: 110 | AW20: 106 | AX20: 116 | AY20: 84 | AZ20: 114 | BA20: 97 | BB20: 83 | BC20: 102 | BD20: 83 | BE20: =SUM(E20:BD20) -> 5630
D21: JML | E21: =SUM(E19:E20) -> 198 | F21: =SUM(F19:F20) -> 195 | G21: =SUM(G19:G20) -> 213 | H21: =SUM(H19:H20) -> 212 | I21: =SUM(I19:I20) -> 218 | J21: =SUM(J19:J20) -> 167 | K21: =SUM(K19:K20) -> 196 | L21: =SUM(L19:L20) -> 191 | ... BD21: =SUM(BD19:BD20) -> 160 | BE21: =SUM(E21:BD21) -> 10498
B22: 2. | C22: Jumlah pengguna hak pilih dalam Daftar Pemilih Tambahan (DPTb) | D22: LK | E22: 2 | F22: 2 | G22: 1 | H22: 0 | I22: 0 | J22: 0 | K22: 1 | L22: 2 | M22: 0 | N22: 2 | O22: 2 | P22: 0 | Q22: 2 | R22: 0 | S22: 0 | T22: 1 | U22: 1 | W22: 2 | X22: 1 | AA22: 1 | AB22: 2 | AC22: 1 | AD22: 1 | AI22: 1 | AJ22: 0 | AK22: 0 | AL22: 1 | AM22: 1 | AN22: 0 | AO22: 0 | AP22: 1 | AQ22: 0 | AR22: 1 | AS22: 1 | AT22: 1 | AU22: 1 | AV22: 2 | AW22: 1 | AX22: 0 | AY22: 1 | AZ22: 3 | BA22: 3 | BB22: 0 | BC22: 1 | BD22: 3 | BE22: =SUM(E22:BD22) -> 46
D23: PR | E23: 0 | F23: 1 | G23: 0 | H23: 1 | I23: 1 | J23: 1 | K23: 0 | L23: 0 | M23: 1 | N23: 1 | O23: 1 | P23: 0 | Q23: 1 | R23: 1 | S23: 0 | V23: 1 | W23: 2 | Y23: 1 | AE23: 1 | AH23: 1 | AI23: 0 | AJ23: 1 | AK23: 2 | AL23: 1 | AM23: 0 | AN23: 0 | AO23: 1 | AP23: 0 | AQ23: 0 | AR23: 2 | AS23: 0 | AT23: 0 | AU23: 0 | AV23: 2 | AW23: 0 | AX23: 0 | AY23: 0 | AZ23: 2 | BA23: 0 | BB23: 0 | BC23: 0 | BD23: 0 | BE23: =SUM(E23:BD23) -> 26
D24: JML | E24: =SUM(E22:E23) -> 2 | F24: =SUM(F22:F23) -> 3 | G24: =SUM(G22:G23) -> 1 | H24: =SUM(H22:H23) -> 1 | I24: =SUM(I22:I23) -> 1 | J24: =SUM(J22:J23) -> 1 | K24: =SUM(K22:K23) -> 1 | L24: =SUM(L22:L23) -> 2 | ... BD24: =SUM(BD22:BD23) -> 3 | BE24: =SUM(E24:BD24) -> 72
B25: 3. | C25: Jumlah pengguna hak pilih dalam Daftar Pemilih Khusus (DPK) | D25: LK | E25: 1 | F25: 0 | G25: 0 | H25: 0 | I25: 0 | J25: 1 | K25: 1 | L25: 0 | M25: 0 | N25: 0 | O25: 0 | P25: 4 | Q25: 7 | R25: 2 | S25: 1 | U25: 2 | V25: 1 | W25: 3 | X25: 2 | Y25: 1 | Z25: 2 | AB25: 3 | AC25: 1 | AD25: 7 | AE25: 2 | AH25: 1 | AI25: 1 | AJ25: 3 | AK25: 0 | AL25: 2 | AM25: 0 | AN25: 0 | AO25: 2 | AP25: 1 | AQ25: 1 | AR25: 2 | AS25: 0 | AT25: 0 | AU25: 0 | AV25: 1 | AW25: 0 | AX25: 1 | AY25: 1 | AZ25: 0 | BA25: 1 | BB25: 0 | BC25: 1 | BD25: 1 | BE25: =SUM(E25:BD25) -> 60
D26: PR | E26: 2 | F26: 0 | G26: 2 | H26: 0 | I26: 0 | J26: 2 | K26: 2 | L26: 0 | M26: 0 | N26: 2 | O26: 2 | P26: 3 | Q26: 3 | R26: 2 | S26: 1 | V26: 2 | W26: 1 | X26: 4 | Y26: 2 | AA26: 1 | AB26: 2 | AC26: 2 | AD26: 6 | AH26: 4 | AI26: 7 | AJ26: 1 | AK26: 1 | AL26: 3 | AM26: 0 | AN26: 0 | AO26: 4 | AP26: 0 | AQ26: 1 | AR26: 5 | AS26: 1 | AT26: 0 | AU26: 0 | AV26: 4 | AW26: 0 | AX26: 1 | AY26: 0 | AZ26: 0 | BA26: 1 | BB26: 0 | BC26: 2 | BD26: 1 | BE26: =SUM(E26:BD26) -> 77
D27: JML | E27: =SUM(E25:E26) -> 3 | F27: =SUM(F25:F26) -> 0 | G27: =SUM(G25:G26) -> 2 | H27: =SUM(H25:H26) -> 0 | I27: =SUM(I25:I26) -> 0 | J27: =SUM(J25:J26) -> 3 | K27: =SUM(K25:K26) -> 3 | L27: =SUM(L25:L26) -> 0 | ... BD27: =SUM(BD25:BD26) -> 2 | BE27: =SUM(E27:BD27) -> 137
B28: 4. | C28: Jumlah Pengguna Hak Pilih (B.1+B.2+B.3) | D28: LK | E28: =SUM(E19,E22,E25) -> 101 | F28: =SUM(F19,F22,F25) -> 100 | G28: =SUM(G19,G22,G25) -> 97 | H28: =SUM(H19,H22,H25) -> 100 | I28: =SUM(I19,I22,I25) -> 100 | J28: =SUM(J19,J22,J25) -> 71 | K28: =SUM(K19,K22,K25) -> 83 | L28: =SUM(L19,L22,L25) -> 87 | ... BD28: =SUM(BD19,BD22,BD25) -> 81 | BE28: =SUM(E28:BD28) -> 4974
D29: PR | E29: =SUM(E20,E23,E26) -> 102 | F29: =SUM(F20,F23,F26) -> 98 | G29: =SUM(G20,G23,G26) -> 119 | H29: =SUM(H20,H23,H26) -> 113 | I29: =SUM(I20,I23,I26) -> 119 | J29: =SUM(J20,J23,J26) -> 100 | K29: =SUM(K20,K23,K26) -> 117 | L29: =SUM(L20,L23,L26) -> 106 | ... BD29: =SUM(BD20,BD23,BD26) -> 84 | BE29: =SUM(E29:BD29) -> 5733
D30: JML | E30: =SUM(E28:E29) -> 203 | F30: =SUM(F28:F29) -> 198 | G30: =SUM(G28:G29) -> 216 | H30: =SUM(H28:H29) -> 213 | I30: =SUM(I28:I29) -> 219 | J30: =SUM(J28:J29) -> 171 | K30: =SUM(K28:K29) -> 200 | L30: =SUM(L28:L29) -> 193 | ... BD30: =SUM(BD28:BD29) -> 165 | BE30: =SUM(E30:BD30) -> 10707
A32: II | B32: DATA PENGGUNAAN SURAT SUARA
A33: 1 | B33: Jumlah surat suara yang diterima, termasuk surat suara cadangan 2% dari DPT | E33: 261 | F33: 267 | G33: 284 | H33: 275 | I33: 276 | J33: 220 | K33: 269 | L33: 261 | M33: 209 | N33: 180 | O33: 291 | P33: 247 | Q33: 281 | R33: 278 | S33: 266 | T33: 262 | U33: 258 | V33: 265 | W33: 230 | X33: 188 | Y33: 281 | Z33: 269 | AA33: 279 | AB33: 295 | AC33: 305 | AD33: 305 | AE33: 207 | AF33: 290 | AG33: 282 | AH33: 283 | AI33: 268 | AJ33: 287 | AK33: 262 | AL33: 293 | AM33: 265 | AN33: 291 | AO33: 296 | AP33: 261 | AQ33: 212 | AR33: 286 | AS33: 279 | AT33: 276 | AU33: 264 | AV33: 267 | AW33: 247 | AX33: 211 | AY33: 183 | AZ33: 279 | BA33: 241 | BB33: 257 | BC33: 249 | BD33: 214 | BE33: =SUM(E33:BD33) -> 13552
A34: 2 | B34: Jumlah surat suara yang digunakan | E34: 203 | F34: 198 | G34: 216 | H34: 213 | I34: 219 | J34: 171 | K34: 200 | L34: 193 | M34: 160 | N34: 152 | O34: 180 | P34: 173 | Q34: 224 | R34: 210 | S34: 192 | T34: 198 | U34: 175 | V34: 206 | W34: 166 | X34: 173 | Y34: 221 | Z34: 220 | AA34: 268 | AB34: 250 | AC34: 269 | AD34: 276 | AE34: 190 | AF34: 236 | AG34: 223 | AH34: 253 | AI34: 228 | AJ34: 225 | AK34: 204 | AL34: 220 | AM34: 196 | AN34: 219 | AO34: 222 | AP34: 202 | AQ34: 163 | AR34: 221 | AS34: 219 | AT34: 205 | AU34: 205 | AV34: 229 | AW34: 211 | AX34: 201 | AY34: 151 | AZ34: 222 | BA34: 196 | BB34: 175 | BC34: 200 | BD34: 165 | BE34: =SUM(E34:BD34) -> 10707
A35: 3 | B35: Jumlah surat suara dikembalikan oleh pemilih (karena rusak atau keliru coblos) | E35: 0 | F35: 0 | G35: 0 | H35: 0 | I35: 0 | J35: 0 | K35: 1 | L35: 3 | M35: 0 | N35: 0 | O35: 0 | P35: 0 | Q35: 0 | R35: 0 | S35: 0 | T35: 0 | U35: 0 | V35: 0 | W35: 0 | X35: 0 | Y35: 0 | Z35: 0 | AA35: 0 | AB35: 0 | AC35: 0 | AD35: 0 | AE35: 0 | AF35: 0 | AG35: 0 | AH35: 0 | AI35: 1 | AJ35: 2 | AK35: 0 | AL35: 0 | AM35: 0 | AN35: 2 | AO35: 0 | AP35: 0 | AQ35: 0 | AR35: 0 | AS35: 0 | AT35: 1 | AU35: 0 | AV35: 0 | AW35: 1 | AX35: 0 | AY35: 0 | AZ35: 0 | BA35: 0 | BB35: 1 | BC35: 0 | BD35: 0 | BE35: =SUM(E35:BD35) -> 12
A36: 4 | B36: Jumlah surat suara yang tidak digunakan/tidak terpakai, termasuk sisa surat suara cadangan | E36: =E33-(E34+E35) -> 58 | F36: =F33-(F34+F35) -> 69 | G36: =G33-(G34+G35) -> 68 | H36: =H33-(H34+H35) -> 62 | I36: =I33-(I34+I35) -> 57 | J36: =J33-(J34+J35) -> 49 | K36: =K33-(K34+K35) -> 68 | L36: =L33-(L34+L35) -> 65 | ... BD36: =BD33-(BD34+BD35) -> 49 | BE36: =SUM(E36:BD36) -> 2833
A38: III | B38: DATA PEMILIH DISABILITAS
B39: Jumlah seluruh Pemilih disabilitas yang menggunakan hak pilih | D39: LK | G39: 1 | H39: 1 | K39: 1 | N39: 1 | S39: 1 | AB39: 1 | AC39: 1 | AD39: 2 | AE39: 1 | AL39: 1 | AO39: 3 | AR39: 2 | AS39: 1 | AX39: 1 | BE39: =SUM(E39:BD39) -> 18
D40: PR | F40: 1 | G40: 4 | H40: 1 | I40: 1 | K40: 1 | N40: 1 | S40: 5 | AB40: 4 | AC40: 5 | AD40: 5 | AE40: 2 | AL40: 4 | AO40: 5 | AQ40: 1 | AR40: 1 | AX40: 1 | BE40: =SUM(E40:BD40) -> 42
D41: JML | E41: =SUM(E39:E40) -> 0 | F41: =SUM(F39:F40) -> 1 | G41: =SUM(G39:G40) -> 5 | H41: =SUM(H39:H40) -> 2 | I41: =SUM(I39:I40) -> 1 | J41: =SUM(J39:J40) -> 0 | K41: =SUM(K39:K40) -> 2 | L41: =SUM(L39:L40) -> 0 | ... BD41: =SUM(BD39:BD40) -> 0 | BE41: =SUM(E41:BD41) -> 60
A43: IV | B43: DATA RINCIAN PEROLEHAN SUARA PASANGAN CALON BUPATI DAN WAKIL BUPATI
B44: NOMOR DAN NAMA CALON
B45: 1. | C45: AA. AHMAD NAWARDI | E45: 8 | F45: 11 | G45: 7 | H45: 8 | I45: 9 | J45: 6 | K45: 21 | L45: 11 | M45: 14 | N45: 12 | O45: 11 | P45: 11 | Q45: 13 | R45: 6 | S45: 8 | T45: 7 | U45: 10 | V45: 19 | W45: 6 | X45: 29 | Y45: 29 | Z45: 29 | AA45: 22 | AB45: 30 | AC45: 36 | AD45: 14 | AE45: 11 | AF45: 16 | AG45: 22 | AH45: 17 | AI45: 30 | AJ45: 15 | AK45: 16 | AL45: 19 | AM45: 11 | AN45: 13 | AO45: 28 | AP45: 17 | AQ45: 5 | AR45: 24 | AS45: 10 | AT45: 10 | AU45: 16 | AV45: 20 | AW45: 16 | AX45: 10 | AY45: 15 | AZ45: 29 | BA45: 20 | BB45: 22 | BC45: 28 | BD45: 14 | BE45: =SUM(E45:BD45) -> 841
B46: 2. | C46: Ir. H. AA LA NYALLA MAHMUD MATTALITI, M.HP. | E46: 40 | F46: 35 | G46: 22 | H46: 41 | I46: 36 | J46: 23 | K46: 35 | L46: 30 | M46: 20 | N46: 23 | O46: 40 | P46: 26 | Q46: 39 | R46: 27 | S46: 30 | T46: 29 | U46: 25 | V46: 20 | W46: 25 | X46: 25 | Y46: 25 | Z46: 34 | AA46: 31 | AB46: 19 | AC46: 35 | AD46: 12 | AE46: 27 | AF46: 44 | AG46: 27 | AH46: 33 | AI46: 39 | AJ46: 39 | AK46: 32 | AL46: 30 | AM46: 20 | AN46: 45 | AO46: 30 | AP46: 32 | AQ46: 31 | AR46: 41 | AS46: 42 | AT46: 36 | AU46: 44 | AV46: 50 | AW46: 54 | AX46: 37 | AY46: 37 | AZ46: 39 | BA46: 34 | BB46: 36 | BC46: 30 | BD46: 19 | BE46: =SUM(E46:BD46) -> 1675
B47: 3. | C47: ABDUL QADIR AMIR HARTONO, S.E., S.H., M.H. | E47: 11 | F47: 19 | G47: 12 | H47: 16 | I47: 14 | J47: 16 | K47: 12 | L47: 14 | M47: 12 | N47: 14 | O47: 13 | P47: 13 | Q47: 9 | R47: 23 | S47: 13 | T47: 17 | U47: 19 | V47: 23 | W47: 18 | X47: 23 | Y47: 16 | Z47: 20 | AA47: 20 | AB47: 26 | AC47: 14 | AD47: 3 | AE47: 16 | AF47: 13 | AG47: 14 | AH47: 17 | AI47: 16 | AJ47: 9 | AK47: 15 | AL47: 17 | AM47: 16 | AN47: 10 | AO47: 8 | AP47: 13 | AQ47: 7 | AR47: 12 | AS47: 9 | AT47: 10 | AU47: 14 | AV47: 6 | AW47: 10 | AX47: 15 | AY47: 5 | AZ47: 16 | BA47: 8 | BB47: 17 | BC47: 20 | BD47: 15 | BE47: =SUM(E47:BD47) -> 738
B48: 4. | C48: ADILLA AZIS, S.E. | E48: 14 | F48: 16 | G48: 14 | H48: 17 | I48: 16 | J48: 16 | K48: 11 | L48: 15 | M48: 18 | N48: 14 | O48: 11 | P48: 28 | Q48: 23 | R48: 21 | S48: 17 | T48: 19 | U48: 13 | V48: 14 | W48: 9 | X48: 9 | Y48: 19 | Z48: 19 | AA48: 37 | AB48: 13 | AC48: 27 | AD48: 9 | AE48: 18 | AF48: 24 | AG48: 11 | AH48: 28 | AI48: 13 | AJ48: 16 | AK48: 15 | AL48: 21 | AM48: 10 | AN48: 20 | AO48: 19 | AP48: 21 | AQ48: 7 | AR48: 11 | AS48: 13 | AT48: 25 | AU48: 15 | AV48: 14 | AW48: 13 | AX48: 18 | AY48: 10 | AZ48: 21 | BA48: 10 | BB48: 17 | BC48: 23 | BD48: 20 | BE48: =SUM(E48:BD48) -> 872
B49: 5. | C49: Ir. H. AGUS RAHARDJO, MSc.M. | E49: 27 | F49: 15 | G49: 27 | H49: 27 | I49: 29 | J49: 19 | K49: 12 | L49: 19 | M49: 17 | N49: 22 | O49: 18 | P49: 15 | Q49: 26 | R49: 26 | S49: 22 | T49: 24 | U49: 19 | V49: 16 | W49: 14 | X49: 13 | Y49: 17 | Z49: 29 | AA49: 29 | AB49: 24 | AC49: 17 | AD49: 10 | AE49: 19 | AF49: 31 | AG49: 24 | AH49: 27 | AI49: 14 | AJ49: 23 | AK49: 26 | AL49: 12 | AM49: 16 | AN49: 15 | AO49: 19 | AP49: 22 | AQ49: 15 | AR49: 26 | AS49: 19 | AT49: 19 | AU49: 14 | AV49: 10 | AW49: 13 | AX49: 20 | AY49: 11 | AZ49: 20 | BA49: 14 | BB49: 16 | BC49: 28 | BD49: 22 | BE49: =SUM(E49:BD49) -> 1028
B50: 6. | C50: Drs. AYUB KHAN | E50: 14 | F50: 12 | G50: 20 | H50: 18 | I50: 16 | J50: 8 | K50: 28 | L50: 17 | M50: 12 | N50: 11 | O50: 8 | P50: 11 | Q50: 29 | R50: 16 | S50: 15 | T50: 10 | U50: 7 | V50: 26 | W50: 14 | X50: 18 | Y50: 23 | Z50: 20 | AA50: 41 | AB50: 26 | AC50: 20 | AD50: 25 | AE50: 11 | AF50: 15 | AG50: 33 | AH50: 18 | AI50: 39 | AJ50: 12 | AK50: 13 | AL50: 19 | AM50: 11 | AN50: 14 | AO50: 14 | AP50: 9 | AQ50: 12 | AR50: 19 | AS50: 24 | AT50: 19 | AU50: 24 | AV50: 31 | AW50: 37 | AX50: 23 | AY50: 15 | AZ50: 29 | BA50: 25 | BB50: 8 | BC50: 22 | BD50: 21 | BE50: =SUM(E50:BD50) -> 982
B51: 7. | C51: BAMBANG HARIANTO | E51: 1 | F51: 4 | G51: 3 | H51: 4 | I51: 0 | J51: 2 | K51: 1 | L51: 3 | M51: 2 | N51: 2 | O51: 3 | P51: 2 | Q51: 3 | R51: 2 | S51: 2 | T51: 6 | U51: 3 | V51: 5 | W51: 3 | X51: 1 | Y51: 3 | Z51: 1 | AA51: 4 | AB51: 1 | AC51: 3 | AD51: 2 | AE51: 1 | AF51: 4 | AG51: 0 | AH51: 0 | AI51: 3 | AJ51: 4 | AK51: 8 | AL51: 4 | AM51: 7 | AN51: 1 | AO51: 3 | AP51: 2 | AQ51: 1 | AR51: 1 | AS51: 1 | AT51: 2 | AU51: 4 | AV51: 2 | AW51: 1 | AX51: 1 | AY51: 0 | AZ51: 1 | BA51: 0 | BB51: 7 | BC51: 4 | BD51: 3 | BE51: =SUM(E51:BD51) -> 131
...

Sheet BULUSAN
C2: Kecamatan | D2: KALIPURO
C3: Kabupaten | D3: BANYUWANGI
C4: Provinsi | D4: JAWA TIMUR
C9: Kelurahan | D9: BULUSAN
A12: I | B12: DATA PEMILIH DAN PENGGUNAAN HAK PILIH | AC12: JUMLAH AKHIR
A13: A | B13: DATA PEMILIH | E13: TPS 001 | F13: TPS 002 | G13: TPS 003 | H13: TPS 004 | I13: TPS 005 | J13: TPS 006 | K13: TPS 007 | L13: TPS 008 | M13: TPS 009 | N13: TPS 010 | O13: TPS 011 | P13: TPS 012 | Q13: TPS 013 | R13: TPS 014 | S13: TPS 015 | T13: TPS 016 | U13: TPS 017 | V13: TPS 018 | W13: TPS 019 | X13: TPS 020 | Y13: TPS 021 | Z13: TPS 022 | AA13: TPS 023 | AB13: TPS 024
B14: Jumlah Pemilih dalam Daftar Pemilih Tetap (DPT) | D14: LK | E14: 148 | F14: 140 | G14: 133 | H14: 145 | I14: 130 | J14: 136 | K14: 147 | L14: 130 | M14: 139 | N14: 140 | O14: 129 | P14: 109 | Q14: 148 | R14: 138 | S14: 139 | T14: 143 | U14: 140 | V14: 131 | W14: 132 | X14: 144 | Y14: 104 | Z14: 86 | AA14: 146 | AB14: 116 | AC14: =SUM(E14:AB14) -> 3193
D15: PR | E15: 146 | F15: 139 | G15: 139 | H15: 150 | I15: 136 | J15: 144 | K15: 133 | L15: 153 | M15: 145 | N15: 134 | O15: 144 | P15: 118 | Q15: 140 | R15: 146 | S15: 139 | T15: 142 | U15: 137 | V15: 134 | W15: 149 | X15: 148 | Y15: 122 | Z15: 110 | AA15: 142 | AB15: 124 | AC15: =SUM(E15:AB15) -> 3314
D16: JML | E16: =SUM(E14:E15) -> 294 | F16: =SUM(F14:F15) -> 279 | G16: =SUM(G14:G15) -> 272 | H16: =SUM(H14:H15) -> 295 | I16: =SUM(I14:I15) -> 266 | J16: =SUM(J14:J15) -> 280 | K16: =SUM(K14:K15) -> 280 | L16: =SUM(L14:L15) -> 283 | ... AB16: =SUM(AB14:AB15) -> 240 | AC16: =SUM(E16:AB16) -> 6507
A18: B | B18: PENGGUNA HAK PILIH
B19: 1. | C19: Jumlah pengguna hak pilih dalam Daftar Pemilih Tetap (DPT) | D19: LK | E19: 101 | F19: 102 | G19: 101 | H19: 122 | I19: 82 | J19: 102 | K19: 111 | L19: 98 | M19: 95 | N19: 102 | O19: 88 | P19: 68 | Q19: 92 | R19: 92 | S19: 86 | T19: 117 | U19: 122 | V19: 108 | W19: 106 | X19: 104 | Y19: 89 | Z19: 65 | AA19: 92 | AB19: 94 | AC19: =SUM(E19:AB19) -> 2339
D20: PR | E20: 117 | F20: 115 | G20: 119 | H20: 125 | I20: 107 | J20: 119 | K20: 107 | L20: 121 | M20: 119 | N20: 111 | O20: 116 | P20: 100 | Q20: 97 | R20: 109 | S20: 111 | T20: 121 | U20: 121 | V20: 121 | W20: 118 | X20: 116 | Y20: 101 | Z20: 91 | AA20: 110 | AB20: 108 | AC20: =SUM(E20:AB20) -> 2700
D21: JML | E21: =SUM(E19:E20) -> 218 | F21: =SUM(F19:F20) -> 217 | G21: =SUM(G19:G20) -> 220 | H21: =SUM(H19:H20) -> 247 | I21: =SUM(I19:I20) -> 189 | J21: =SUM(J19:J20) -> 221 | K21: =SUM(K19:K20) -> 218 | L21: =SUM(L19:L20) -> 219 | ... AB21: =SUM(AB19:AB20) -> 202 | AC21: =SUM(E21:AB21) -> 5039
B22: 2. | C22: Jumlah pengguna hak pilih dalam Daftar Pemilih Tambahan (DPTb) | D22: LK | E22: 1 | F22: 0 | G22: 1 | H22: 1 | I22: 0 | J22: 0 | K22: 0 | L22: 0 | M22: 1 | N22: 0 | O22: 0 | P22: 0 | Q22: 1 | R22: 1 | S22: 0 | T22: 0 | U22: 1 | V22: 0 | W22: 1 | X22: 0 | Y22: 0 | Z22: 0 | AA22: 0 | AB22: 0 | AC22: =SUM(E22:AB22) -> 8
D23: PR | E23: 1 | F23: 1 | G23: 0 | H23: 0 | I23: 0 | J23: 1 | K23: 1 | L23: 1 | M23: 0 | N23: 0 | O23: 0 | P23: 1 | Q23: 0 | R23: 0 | S23: 1 | T23: 2 | U23: 1 | V23: 1 | W23: 0 | X23: 1 | Y23: 1 | Z23: 1 | AA23: 1 | AB23: 1 | AC23: =SUM(E23:AB23) -> 16
D24: JML | E24: =SUM(E22:E23) -> 2 | F24: =SUM(F22:F23) -> 1 | G24: =SUM(G22:G23) -> 1 | H24: =SUM(H22:H23) -> 1 | I24: =SUM(I22:I23) -> 0 | J24: =SUM(J22:J23) -> 1 | K24: =SUM(K22:K23) -> 1 | L24: =SUM(L22:L23) -> 1 | ... AB24: =SUM(AB22:AB23) -> 1 | AC24: =SUM(E24:AB24) -> 24
B25: 3. | C25: Jumlah pengguna hak pilih dalam Daftar Pemilih Khusus (DPK) | D25: LK | E25: 2 | F25: 1 | G25: 0 | H25: 0 | I25: 0 | J25: 0 | K25: 2 | L25: 4 | M25: 0 | N25: 0 | O25: 0 | P25: 3 | Q25: 1 | R25: 0 | S25: 1 | T25: 0 | U25: 3 | V25: 1 | W25: 0 | X25: 1 | Y25: 0 | Z25: 0 | AA25: 0 | AB25: 3 | AC25: =SUM(E25:AB25) -> 22
D26: PR | E26: 4 | F26: 3 | G26: 0 | H26: 0 | I26: 1 | J26: 1 | K26: 0 | L26: 4 | M26: 0 | N26: 1 | O26: 1 | P26: 4 | Q26: 1 | R26: 0 | S26: 2 | T26: 0 | U26: 1 | V26: 1 | W26: 0 | X26: 3 | Y26: 0 | Z26: 0 | AA26: 0 | AB26: 4 | AC26: =SUM(E26:AB26) -> 31
D27: JML | E27: =SUM(E25:E26) -> 6 | F27: =SUM(F25:F26) -> 4 | G27: =SUM(G25:G26) -> 0 | H27: =SUM(H25:H26) -> 0 | I27: =SUM(I25:I26) -> 1 | J27: =SUM(J25:J26) -> 1 | K27: =SUM(K25:K26) -> 2 | L27: =SUM(L25:L26) -> 8 | ... AB27: =SUM(AB25:AB26) -> 7 | AC27: =SUM(E27:AB27) -> 53
B28: 4. | C28: Jumlah Pengguna Hak Pilih (B.1+B.2+B.3) | D28: LK | E28: =SUM(E19,E22,E25) -> 104 | F28: =SUM(F19,F22,F25) -> 103 | G28: =SUM(G19,G22,G25) -> 102 | H28: =SUM(H19,H22,H25) -> 123 | I28: =SUM(I19,I22,I25) -> 82 | J28: =SUM(J19,J22,J25) -> 102 | K28: =SUM(K19,K22,K25) -> 113 | L28: =SUM(L19,L22,L25) -> 102 | ... AB28: =SUM(AB19,AB22,AB25) -> 97 | AC28: =SUM(E28:AB28) -> 2369
D29: PR | E29: =SUM(E20,E23,E26) -> 122 | F29: =SUM(F20,F23,F26) -> 119 | G29: =SUM(G20,G23,G26) -> 119 | H29: =SUM(H20,H23,H26) -> 125 | I29: =SUM(I20,I23,I26) -> 108 | J29: =SUM(J20,J23,J26) -> 121 | K29: =SUM(K20,K23,K26) -> 108 | L29: =SUM(L20,L23,L26) -> 126 | ... AB29: =SUM(AB20,AB23,AB26) -> 113 | AC29: =SUM(E29:AB29) -> 2747
D30: JML | E30: =SUM(E28:E29) -> 226 | F30: =SUM(F28:F29) -> 222 | G30: =SUM(G28:G29) -> 221 | H30: =SUM(H28:H29) -> 248 | I30: =SUM(I28:I29) -> 190 | J30: =SUM(J28:J29) -> 223 | K30: =SUM(K28:K29) -> 221 | L30: =SUM(L28:L29) -> 228 | ... AB30: =SUM(AB28:AB29) -> 210 | AC30: =SUM(E30:AB30) -> 5116
A32: II | B32: DATA PENGGUNAAN SURAT SUARA
A33: 1 | B33: Jumlah surat suara yang diterima, termasuk surat suara cadangan 2% dari DPT | E33: 300 | F33: 286 | G33: 278 | H33: 301 | I33: 272 | J33: 286 | K33: 286 | L33: 289 | M33: 281 | N33: 280 | O33: 279 | P33: 232 | Q33: 294 | R33: 290 | S33: 284 | T33: 291 | U33: 283 | V33: 270 | W33: 286 | X33: 291 | Y33: 233 | Z33: 200 | AA33: 296 | AB33: 245 | AC33: =SUM(E33:AB33) -> 6633
A34: 2 | B34: Jumlah surat suara yang digunakan | E34: 226 | F34: 222 | G34: 221 | H34: 248 | I34: 190 | J34: 223 | K34: 221 | L34: 228 | M34: 215 | N34: 214 | O34: 205 | P34: 176 | Q34: 192 | R34: 202 | S34: 201 | T34: 240 | U34: 249 | V34: 232 | W34: 225 | X34: 225 | Y34: 191 | Z34: 157 | AA34: 203 | AB34: 210 | AC34: =SUM(E34:AB34) -> 5116
A35: 3 | B35: Jumlah surat suara dikembalikan oleh pemilih (karena rusak atau keliru coblos) | E35: 1 | F35: 1 | G35: 1 | H35: 0 | I35: 0 | J35: 0 | K35: 2 | L35: 0 | M35: 0 | N35: 0 | O35: 0 | P35: 4 | Q35: 0 | R35: 0 | S35: 0 | T35: 0 | U35: 0 | V35: 0 | W35: 0 | X35: 0 | Y35: 0 | Z35: 0 | AA35: 0 | AB35: 0 | AC35: =SUM(E35:AB35) -> 9
A36: 4 | B36: Jumlah surat suara yang tidak digunakan/tidak terpakai, termasuk sisa surat suara cadangan | E36: =E33-(E34+E35) -> 73 | F36: =F33-(F34+F35) -> 63 | G36: =G33-(G34+G35) -> 56 | H36: =H33-(H34+H35) -> 53 | I36: =I33-(I34+I35) -> 82 | J36: =J33-(J34+J35) -> 63 | K36: =K33-(K34+K35) -> 63 | L36: =L33-(L34+L35) -> 61 | ... AB36: =AB33-(AB34+AB35) -> 35 | AC36: =SUM(E36:AB36) -> 1508
A38: III | B38: DATA PEMILIH DISABILITAS
B39: Jumlah seluruh Pemilih disabilitas yang menggunakan hak pilih | D39: LK | I39: 1 | K39: 3 | AC39: =SUM(E39:AB39) -> 4
D40: PR | K40: 6 | AC40: =SUM(E40:AB40) -> 6
D41: JML | E41: =SUM(E39:E40) -> 0 | F41: =SUM(F39:F40) -> 0 | G41: =SUM(G39:G40) -> 0 | H41: =SUM(H39:H40) -> 0 | I41: =SUM(I39:I40) -> 1 | J41: =SUM(J39:J40) -> 0 | K41: =SUM(K39:K40) -> 9 | L41: =SUM(L39:L40) -> 0 | ... AB41: =SUM(AB39:AB40) -> 0 | AC41: =SUM(E41:AB41) -> 10
A43: IV | B43: DATA RINCIAN PEROLEHAN SUARA PASANGAN CALON BUPATI DAN WAKIL BUPATI
B44: NOMOR DAN NAMA CALON
B45: 1. | C45: AA. AHMAD NAWARDI | E45: 28 | F45: 36 | G45: 23 | H45: 28 | I45: 18 | J45: 12 | K45: 14 | L45: 31 | M45: 21 | N45: 18 | O45: 9 | P45: 8 | Q45: 4 | R45: 12 | S45: 14 | T45: 31 | U45: 24 | V45: 24 | W45: 23 | X45: 20 | Y45: 25 | Z45: 16 | AA45: 28 | AB45: 32 | AC45: =SUM(E45:AB45) -> 499
B46: 2. | C46: Ir. H. AA LA NYALLA MAHMUD MATTALITI, M.HP. | E46: 42 | F46: 28 | G46: 26 | H46: 37 | I46: 24 | J46: 24 | K46: 31 | L46: 31 | M46: 32 | N46: 35 | O46: 29 | P46: 19 | Q46: 44 | R46: 31 | S46: 35 | T46: 43 | U46: 30 | V46: 35 | W46: 34 | X46: 23 | Y46: 30 | Z46: 22 | AA46: 23 | AB46: 17 | AC46: =SUM(E46:AB46) -> 725
B47: 3. | C47: ABDUL QADIR AMIR HARTONO, S.E., S.H., M.H. | E47: 11 | F47: 9 | G47: 14 | H47: 12 | I47: 17 | J47: 21 | K47: 14 | L47: 16 | M47: 14 | N47: 13 | O47: 20 | P47: 16 | Q47: 12 | R47: 11 | S47: 14 | T47: 20 | U47: 18 | V47: 13 | W47: 20 | X47: 26 | Y47: 18 | Z47: 13 | AA47: 17 | AB47: 21 | AC47: =SUM(E47:AB47) -> 380
B48: 4. | C48: ADILLA AZIS, S.E. | E48: 18 | F48: 15 | G48: 16 | H48: 22 | I48: 17 | J48: 12 | K48: 20 | L48: 14 | M48: 18 | N48: 13 | O48: 14 | P48: 12 | Q48: 11 | R48: 16 | S48: 18 | T48: 25 | U48: 30 | V48: 28 | W48: 14 | X48: 32 | Y48: 10 | Z48: 11 | AA48: 8 | AB48: 17 | AC48: =SUM(E48:AB48) -> 411
B49: 5. | C49: Ir. H. AGUS RAHARDJO, MSc.M. | E49: 19 | F49: 18 | G49: 17 | H49: 26 | I49: 16 | J49: 19 | K49: 19 | L49: 18 | M49: 17 | N49: 22 | O49: 16 | P49: 12 | Q49: 23 | R49: 19 | S49: 19 | T49: 17 | U49: 20 | V49: 14 | W49: 17 | X49: 14 | Y49: 14 | Z49: 8 | AA49: 19 | AB49: 15 | AC49: =SUM(E49:AB49) -> 418
B50: 6. | C50: Drs. AYUB KHAN | E50: 19 | F50: 15 | G50: 16 | H50: 14 | I50: 7 | J50: 20 | K50: 25 | L50: 17 | M50: 14 | N50: 9 | O50: 17 | P50: 18 | Q50: 24 | R50: 19 | S50: 7 | T50: 40 | U50: 41 | V50: 38 | W50: 29 | X50: 30 | Y50: 21 | Z50: 13 | AA50: 20 | AB50: 30 | AC50: =SUM(E50:AB50) -> 503
B51: 7. | C51: BAMBANG HARIANTO | E51: 3 | F51: 3 | G51: 5 | H51: 2 | I51: 1 | J51: 4 | K51: 2 | L51: 1 | M51: 0 | N51: 0 | O51: 5 | P51: 0 | Q51: 4 | R51: 5 | S51: 5 | T51: 3 | U51: 3 | V51: 2 | W51: 3 | X51: 2 | Y51: 3 | Z51: 2 | AA51: 5 | AB51: 8 | AC51: =SUM(E51:AB51) -> 71
...

Sheet KLATAK
C2: Kecamatan | D2: KALIPURO
C3: Kabupaten | D3: BANYUWANGI
C4: Provinsi | D4: JAWA TIMUR
C9: Kelurahan | D9: KLATAK
A12: I | B12: DATA PEMILIH DAN PENGGUNAAN HAK PILIH | AV12: JUMLAH AKHIR
A13: A | B13: DATA PEMILIH | E13: TPS 001 | F13: TPS 002 | G13: TPS 003 | H13: TPS 004 | I13: TPS 005 | J13: TPS 006 | K13: TPS 007 | L13: TPS 008 | M13: TPS 009 | N13: TPS 010 | O13: TPS 011 | P13: TPS 012 | Q13: TPS 013 | R13: TPS 014 | S13: TPS 015 | T13: TPS 016 | U13: TPS 017 | V13: TPS 018 | W13: TPS 019 | X13: TPS 020 | Y13: TPS 021 | Z13: TPS 022 | AA13: TPS 023 | AB13: TPS 024 | AC13: TPS 025 | AD13: TPS 026 | AE13: TPS 027 | AF13: TPS 028 | AG13: TPS 029 | AH13: TPS 030 | AI13: TPS 031 | AJ13: TPS 032 | AK13: TPS 033 | AL13: TPS 034 | AM13: TPS 035 | AN13: TPS 036 | AO13: TPS 037 | AP13: TPS 038 | AQ13: TPS 039 | AR13: TPS 040 | AS13: TPS 041 | AT13: TPS 042 | AU13: TPS 043
B14: Jumlah Pemilih dalam Daftar Pemilih Tetap (DPT) | D14: LK | E14: 142 | F14: 137 | G14: 103 | H14: 135 | I14: 134 | J14: 137 | K14: 139 | L14: 142 | M14: 126 | N14: 153 | O14: 140 | P14: 133 | Q14: 133 | R14: 144 | S14: 133 | T14: 140 | U14: 147 | V14: 140 | W14: 152 | X14: 143 | Y14: 141 | Z14: 133 | AA14: 139 | AB14: 134 | AC14: 144 | AD14: 131 | AE14: 150 | AF14: 155 | AG14: 132 | AH14: 148 | AI14: 139 | AJ14: 148 | AK14: 137 | AL14: 106 | AM14: 131 | AN14: 128 | AO14: 123 | AP14: 134 | AQ14: 152 | AR14: 119 | AS14: 145 | AT14: 137 | AU14: 145 | AV14: =SUM(E14:AU14) -> 5904
D15: PR | E15: 141 | F15: 151 | G15: 117 | H15: 138 | I15: 161 | J15: 148 | K15: 154 | L15: 143 | M15: 163 | N15: 142 | O15: 152 | P15: 158 | Q15: 150 | R15: 138 | S15: 148 | T15: 147 | U15: 147 | V15: 148 | W15: 141 | X15: 146 | Y15: 141 | Z15: 148 | AA15: 151 | AB15: 148 | AC15: 146 | AD15: 135 | AE15: 142 | AF15: 140 | AG15: 146 | AH15: 150 | AI15: 151 | AJ15: 145 | AK15: 150 | AL15: 112 | AM15: 136 | AN15: 143 | AO15: 140 | AP15: 155 | AQ15: 143 | AR15: 123 | AS15: 144 | AT15: 158 | AU15: 146 | AV15: =SUM(E15:AU15) -> 6226
D16: JML | E16: =SUM(E14:E15) -> 283 | F16: =SUM(F14:F15) -> 288 | G16: =SUM(G14:G15) -> 220 | H16: =SUM(H14:H15) -> 273 | I16: =SUM(I14:I15) -> 295 | J16: =SUM(J14:J15) -> 285 | K16: =SUM(K14:K15) -> 293 | L16: =SUM(L14:L15) -> 285 | ... AU16: =SUM(AU14:AU15) -> 291 | AV16: =SUM(E16:AU16) -> 12130
A18: B | B18: PENGGUNA HAK PILIH
B19: 1. | C19: Jumlah pengguna hak pilih dalam Daftar Pemilih Tetap (DPT) | D19: LK | E19: 114 | F19: 77 | G19: 75 | H19: 104 | I19: 97 | J19: 101 | K19: 98 | L19: 98 | M19: 85 | N19: 108 | O19: 87 | P19: 92 | Q19: 89 | R19: 106 | S19: 83 | T19: 102 | U19: 97 | V19: 87 | W19: 112 | X19: 98 | Y19: 102 | Z19: 99 | AA19: 106 | AB19: 100 | AC19: 98 | AD19: 92 | AE19: 106 | AF19: 113 | AG19: 95 | AH19: 88 | AI19: 89 | AJ19: 110 | AK19: 105 | AL19: 68 | AM19: 85 | AN19: 93 | AO19: 83 | AP19: 89 | AQ19: 95 | AR19: 77 | AS19: 92 | AT19: 121 | AU19: 79 | AV19: =SUM(E19:AU19) -> 4095
D20: PR | E20: 126 | F20: 107 | G20: 93 | H20: 108 | I20: 124 | J20: 109 | K20: 124 | L20: 116 | M20: 122 | N20: 116 | O20: 117 | P20: 120 | Q20: 118 | R20: 99 | S20: 119 | T20: 112 | U20: 110 | V20: 108 | W20: 109 | X20: 125 | Y20: 113 | Z20: 123 | AA20: 119 | AB20: 127 | AC20: 120 | AD20: 111 | AE20: 113 | AF20: 108 | AG20: 109 | AH20: 109 | AI20: 126 | AJ20: 109 | AK20: 126 | AL20: 74 | AM20: 101 | AN20: 111 | AO20: 105 | AP20: 113 | AQ20: 109 | AR20: 94 | AS20: 110 | AT20: 87 | AU20: 100 | AV20: =SUM(E20:AU20) -> 4799
D21: JML | E21: =SUM(E19:E20) -> 240 | F21: =SUM(F19:F20) -> 184 | G21: =SUM(G19:G20) -> 168 | H21: =SUM(H19:H20) -> 212 | I21: =SUM(I19:I20) -> 221 | J21: =SUM(J19:J20) -> 210 | K21: =SUM(K19:K20) -> 222 | L21: =SUM(L19:L20) -> 214 | ... AU21: =SUM(AU19:AU20) -> 179 | AV21: =SUM(E21:AU21) -> 8894
B22: 2. | C22: Jumlah pengguna hak pilih dalam Daftar Pemilih Tambahan (DPTb) | D22: LK | E22: 0 | F22: 3 | G22: 3 | H22: 1 | I22: 0 | J22: 0 | K22: 0 | L22: 0 | M22: 1 | N22: 1 | O22: 3 | P22: 0 | Q22: 0 | R22: 1 | S22: 1 | T22: 1 | U22: 2 | V22: 0 | W22: 2 | X22: 0 | Y22: 0 | Z22: 0 | AA22: 1 | AB22: 0 | AC22: 0 | AD22: 1 | AE22: 0 | AF22: 1 | AG22: 1 | AH22: 0 | AI22: 0 | AJ22: 0 | AK22: 0 | AL22: 1 | AM22: 1 | AN22: 0 | AO22: 0 | AP22: 2 | AQ22: 2 | AR22: 1 | AS22: 1 | AT22: 1 | AU22: 1 | AV22: =SUM(E22:AU22) -> 33
D23: PR | E23: 0 | F23: 1 | G23: 2 | H23: 1 | I23: 0 | J23: 0 | K23: 0 | L23: 0 | M23: 0 | N23: 2 | O23: 1 | P23: 1 | Q23: 0 | R23: 0 | S23: 0 | T23: 1 | U23: 1 | V23: 1 | W23: 1 | X23: 2 | Y23: 0 | Z23: 1 | AA23: 0 | AB23: 0 | AC23: 1 | AD23: 0 | AE23: 1 | AF23: 2 | AG23: 0 | AH23: 1 | AI23: 0 | AJ23: 0 | AK23: 1 | AL23: 0 | AM23: 0 | AN23: 1 | AO23: 1 | AP23: 3 | AQ23: 0 | AR23: 0 | AS23: 1 | AT23: 0 | AU23: 1 | AV23: =SUM(E23:AU23) -> 28
D24: JML | E24: =SUM(E22:E23) -> 0 | F24: =SUM(F22:F23) -> 4 | G24: =SUM(G22:G23) -> 5 | H24: =SUM(H22:H23) -> 2 | I24: =SUM(I22:I23) -> 0 | J24: =SUM(J22:J23) -> 0 | K24: =SUM(K22:K23) -> 0 | L24: =SUM(L22:L23) -> 0 | ... AU24: =SUM(AU22:AU23) -> 2 | AV24: =SUM(E24:AU24) -> 61
B25: 3. | C25: Jumlah pengguna hak pilih dalam Daftar Pemilih Khusus (DPK) | D25: LK | E25: 5 | F25: 1 | G25: 2 | H25: 8 | I25: 4 | J25: 2 | K25: 3 | L25: 0 | M25: 1 | N25: 0 | O25: 0 | P25: 0 | Q25: 1 | R25: 2 | S25: 0 | T25: 0 | U25: 0 | V25: 8 | W25: 2 | X25: 2 | Y25: 1 | Z25: 1 | AA25: 0 | AB25: 0 | AC25: 0 | AD25: 5 | AE25: 1 | AF25: 3 | AG25: 0 | AH25: 7 | AI25: 0 | AJ25: 5 | AK25: 2 | AL25: 1 | AM25: 1 | AN25: 2 | AO25: 1 | AP25: 5 | AQ25: 0 | AR25: 0 | AS25: 1 | AT25: 2 | AU25: 2 | AV25: =SUM(E25:AU25) -> 81
D26: PR | E26: 6 | F26: 0 | G26: 3 | H26: 10 | I26: 1 | J26: 1 | K26: 3 | L26: 0 | M26: 2 | N26: 0 | O26: 1 | P26: 0 | Q26: 1 | R26: 1 | S26: 0 | T26: 0 | U26: 1 | V26: 9 | W26: 2 | X26: 0 | Y26: 1 | Z26: 2 | AA26: 0 | AB26: 0 | AC26: 0 | AD26: 5 | AE26: 0 | AF26: 3 | AG26: 1 | AH26: 3 | AI26: 0 | AJ26: 6 | AK26: 0 | AL26: 1 | AM26: 1 | AN26: 1 | AO26: 0 | AP26: 5 | AQ26: 1 | AR26: 0 | AS26: 2 | AT26: 2 | AU26: 2 | AV26: =SUM(E26:AU26) -> 77
D27: JML | E27: =SUM(E25:E26) -> 11 | F27: =SUM(F25:F26) -> 1 | G27: =SUM(G25:G26) -> 5 | H27: =SUM(H25:H26) -> 18 | I27: =SUM(I25:I26) -> 5 | J27: =SUM(J25:J26) -> 3 | K27: =SUM(K25:K26) -> 6 | L27: =SUM(L25:L26) -> 0 | ... AU27: =SUM(AU25:AU26) -> 4 | AV27: =SUM(E27:AU27) -> 158
B28: 4. | C28: Jumlah Pengguna Hak Pilih (B.1+B.2+B.3) | D28: LK | E28: =SUM(E19,E22,E25) -> 119 | F28: =SUM(F19,F22,F25) -> 81 | G28: =SUM(G19,G22,G25) -> 80 | H28: =SUM(H19,H22,H25) -> 113 | I28: =SUM(I19,I22,I25) -> 101 | J28: =SUM(J19,J22,J25) -> 103 | K28: =SUM(K19,K22,K25) -> 101 | L28: =SUM(L19,L22,L25) -> 98 | ... AU28: =SUM(AU19,AU22,AU25) -> 82 | AV28: =SUM(E28:AU28) -> 4209
D29: PR | E29: =SUM(E20,E23,E26) -> 132 | F29: =SUM(F20,F23,F26) -> 108 | G29: =SUM(G20,G23,G26) -> 98 | H29: =SUM(H20,H23,H26) -> 119 | I29: =SUM(I20,I23,I26) -> 125 | J29: =SUM(J20,J23,J26) -> 110 | K29: =SUM(K20,K23,K26) -> 127 | L29: =SUM(L20,L23,L26) -> 116 | ... AU29: =SUM(AU20,AU23,AU26) -> 103 | AV29: =SUM(E29:AU29) -> 4904
D30: JML | E30: =SUM(E28:E29) -> 251 | F30: =SUM(F28:F29) -> 189 | G30: =SUM(G28:G29) -> 178 | H30: =SUM(H28:H29) -> 232 | I30: =SUM(I28:I29) -> 226 | J30: =SUM(J28:J29) -> 213 | K30: =SUM(K28:K29) -> 228 | L30: =SUM(L28:L29) -> 214 | ... AU30: =SUM(AU28:AU29) -> 185 | AV30: =SUM(E30:AU30) -> 9113
A32: II | B32: DATA PENGGUNAAN SURAT SUARA
A33: 1 | B33: Jumlah surat suara yang diterima, termasuk surat suara cadangan 2% dari DPT | E33: 276 | F33: 283 | G33: 205 | H33: 265 | I33: 279 | J33: 281 | K33: 290 | L33: 280 | M33: 285 | N33: 279 | O33: 236 | P33: 287 | Q33: 278 | R33: 278 | S33: 276 | T33: 283 | U33: 289 | V33: 273 | W33: 278 | X33: 284 | Y33: 277 | Z33: 275 | AA33: 285 | AB33: 277 | AC33: 285 | AD33: 253 | AE33: 277 | AF33: 290 | AG33: 252 | AH33: 301 | AI33: 285 | AJ33: 290 | AK33: 270 | AL33: 211 | AM33: 262 | AN33: 266 | AO33: 269 | AP33: 283 | AQ33: 290 | AR33: 225 | AS33: 295 | AT33: 291 | AU33: 275 | AV33: =SUM(E33:AU33) -> 11769
A34: 2 | B34: Jumlah surat suara yang digunakan | E34: 251 | F34: 189 | G34: 178 | H34: 232 | I34: 226 | J34: 213 | K34: 228 | L34: 214 | M34: 211 | N34: 227 | O34: 209 | P34: 213 | Q34: 209 | R34: 209 | S34: 203 | T34: 216 | U34: 211 | V34: 213 | W34: 228 | X34: 227 | Y34: 217 | Z34: 226 | AA34: 226 | AB34: 227 | AC34: 219 | AD34: 214 | AE34: 221 | AF34: 230 | AG34: 206 | AH34: 208 | AI34: 215 | AJ34: 230 | AK34: 234 | AL34: 145 | AM34: 189 | AN34: 208 | AO34: 190 | AP34: 217 | AQ34: 207 | AR34: 172 | AS34: 207 | AT34: 213 | AU34: 185 | AV34: =SUM(E34:AU34) -> 9113
A35: 3 | B35: Jumlah surat suara dikembalikan oleh pemilih (karena rusak atau keliru coblos) | E35: 0 | F35: 0 | G35: 0 | H35: 0 | I35: 0 | J35: 0 | K35: 1 | L35: 0 | M35: 0 | N35: 0 | O35: 0 | P35: 0 | Q35: 0 | R35: 1 | S35: 1 | T35: 0 | U35: 0 | V35: 0 | W35: 0 | X35: 0 | Y35: 0 | Z35: 0 | AA35: 0 | AB35: 0 | AC35: 0 | AD35: 0 | AE35: 0 | AF35: 0 | AG35: 0 | AH35: 0 | AI35: 0 | AJ35: 0 | AK35: 0 | AL35: 0 | AM35: 0 | AN35: 1 | AO35: 0 | AP35: 2 | AQ35: 0 | AR35: 0 | AS35: 0 | AT35: 0 | AU35: 0 | AV35: =SUM(E35:AU35) -> 6
A36: 4 | B36: Jumlah surat suara yang tidak digunakan/tidak terpakai, termasuk sisa surat suara cadangan | E36: =E33-(E34+E35) -> 25 | F36: =F33-(F34+F35) -> 94 | G36: =G33-(G34+G35) -> 27 | H36: =H33-(H34+H35) -> 33 | I36: =I33-(I34+I35) -> 53 | J36: =J33-(J34+J35) -> 68 | K36: =K33-(K34+K35) -> 61 | L36: =L33-(L34+L35) -> 66 | ... AU36: =AU33-(AU34+AU35) -> 90 | AV36: =SUM(E36:AU36) -> 2650
A38: III | B38: DATA PEMILIH DISABILITAS
B39: Jumlah seluruh Pemilih disabilitas yang menggunakan hak pilih | D39: LK | E39: 1 | G39: 1 | J39: 2 | M39: 1 | X39: 3 | AA39: 1 | AF39: 1 | AI39: 1 | AO39: 1 | AU39: 1 | AV39: =SUM(E39:AU39) -> 13
D40: PR | E40: 1 | P40: 2 | U40: 1 | X40: 2 | AA40: 2 | AF40: 1 | AH40: 1 | AI40: 1 | AM40: 1 | AU40: 1 | AV40: =SUM(E40:AU40) -> 13
D41: JML | E41: =SUM(E39:E40) -> 2 | F41: =SUM(F39:F40) -> 0 | G41: =SUM(G39:G40) -> 1 | H41: =SUM(H39:H40) -> 0 | I41: =SUM(I39:I40) -> 0 | J41: =SUM(J39:J40) -> 2 | K41: =SUM(K39:K40) -> 0 | L41: =SUM(L39:L40) -> 0 | ... AU41: =SUM(AU39:AU40) -> 2 | AV41: =SUM(E41:AU41) -> 26
A43: IV | B43: DATA RINCIAN PEROLEHAN SUARA PASANGAN CALON BUPATI DAN WAKIL BUPATI
B44: NOMOR DAN NAMA CALON
B45: 1. | C45: AA. AHMAD NAWARDI | E45: 13 | F45: 9 | G45: 10 | H45: 13 | I45: 17 | J45: 14 | K45: 20 | L45: 16 | M45: 12 | N45: 24 | O45: 7 | P45: 5 | Q45: 7 | R45: 12 | S45: 7 | T45: 10 | U45: 3 | V45: 27 | W45: 13 | X45: 18 | Y45: 12 | Z45: 30 | AA45: 16 | AB45: 22 | AC45: 9 | AD45: 15 | AE45: 20 | AF45: 20 | AG45: 14 | AH45: 11 | AI45: 14 | AJ45: 24 | AK45: 30 | AL45: 5 | AM45: 7 | AN45: 5 | AO45: 6 | AP45: 4 | AQ45: 4 | AR45: 8 | AS45: 11 | AT45: 7 | AU45: 10 | AV45: =SUM(E45:AU45) -> 561
B46: 2. | C46: Ir. H. AA LA NYALLA MAHMUD MATTALITI, M.HP. | E46: 43 | F46: 34 | G46: 23 | H46: 39 | I46: 41 | J46: 29 | K46: 30 | L46: 25 | M46: 34 | N46: 37 | O46: 27 | P46: 23 | Q46: 34 | R46: 25 | S46: 29 | T46: 23 | U46: 30 | V46: 16 | W46: 38 | X46: 33 | Y46: 44 | Z46: 47 | AA46: 57 | AB46: 47 | AC46: 37 | AD46: 30 | AE46: 33 | AF46: 36 | AG46: 30 | AH46: 47 | AI46: 35 | AJ46: 36 | AK46: 57 | AL46: 25 | AM46: 36 | AN46: 30 | AO46: 28 | AP46: 30 | AQ46: 39 | AR46: 23 | AS46: 42 | AT46: 40 | AU46: 29 | AV46: =SUM(E46:AU46) -> 1471
B47: 3. | C47: ABDUL QADIR AMIR HARTONO, S.E., S.H., M.H. | E47: 32 | F47: 10 | G47: 14 | H47: 21 | I47: 23 | J47: 12 | K47: 17 | L47: 11 | M47: 17 | N47: 14 | O47: 8 | P47: 8 | Q47: 18 | R47: 11 | S47: 13 | T47: 11 | U47: 10 | V47: 16 | W47: 8 | X47: 17 | Y47: 16 | Z47: 8 | AA47: 11 | AB47: 12 | AC47: 17 | AD47: 13 | AE47: 12 | AF47: 29 | AG47: 13 | AH47: 8 | AI47: 19 | AJ47: 25 | AK47: 9 | AL47: 12 | AM47: 14 | AN47: 11 | AO47: 6 | AP47: 9 | AQ47: 8 | AR47: 9 | AS47: 14 | AT47: 13 | AU47: 17 | AV47: =SUM(E47:AU47) -> 596
B48: 4. | C48: ADILLA AZIS, S.E. | E48: 37 | F48: 17 | G48: 11 | H48: 24 | I48: 12 | J48: 19 | K48: 17 | L48: 22 | M48: 19 | N48: 21 | O48: 11 | P48: 14 | Q48: 22 | R48: 17 | S48: 23 | T48: 23 | U48: 21 | V48: 21 | W48: 12 | X48: 19 | Y48: 26 | Z48: 12 | AA48: 16 | AB48: 21 | AC48: 16 | AD48: 16 | AE48: 17 | AF48: 14 | AG48: 16 | AH48: 13 | AI48: 24 | AJ48: 22 | AK48: 31 | AL48: 15 | AM48: 15 | AN48: 16 | AO48: 13 | AP48: 15 | AQ48: 23 | AR48: 16 | AS48: 10 | AT48: 21 | AU48: 15 | AV48: =SUM(E48:AU48) -> 785
B49: 5. | C49: Ir. H. AGUS RAHARDJO, MSc.M. | E49: 20 | F49: 19 | G49: 27 | H49: 22 | I49: 26 | J49: 22 | K49: 15 | L49: 20 | M49: 17 | N49: 18 | O49: 28 | P49: 27 | Q49: 26 | R49: 17 | S49: 19 | T49: 24 | U49: 18 | V49: 23 | W49: 31 | X49: 18 | Y49: 16 | Z49: 23 | AA49: 32 | AB49: 29 | AC49: 21 | AD49: 28 | AE49: 17 | AF49: 17 | AG49: 27 | AH49: 17 | AI49: 27 | AJ49: 17 | AK49: 17 | AL49: 15 | AM49: 29 | AN49: 26 | AO49: 25 | AP49: 30 | AQ49: 19 | AR49: 24 | AS49: 21 | AT49: 27 | AU49: 20 | AV49: =SUM(E49:AU49) -> 961
B50: 6. | C50: Drs. AYUB KHAN | E50: 13 | F50: 10 | G50: 9 | H50: 7 | I50: 15 | J50: 11 | K50: 20 | L50: 8 | M50: 10 | N50: 11 | O50: 12 | P50: 12 | Q50: 8 | R50: 17 | S50: 10 | T50: 5 | U50: 17 | V50: 13 | W50: 21 | X50: 18 | Y50: 9 | Z50: 22 | AA50: 17 | AB50: 14 | AC50: 27 | AD50: 16 | AE50: 23 | AF50: 14 | AG50: 17 | AH50: 21 | AI50: 14 | AJ50: 21 | AK50: 10 | AL50: 8 | AM50: 8 | AN50: 16 | AO50: 7 | AP50: 13 | AQ50: 13 | AR50: 10 | AS50: 9 | AT50: 11 | AU50: 13 | AV50: =SUM(E50:AU50) -> 580
B51: 7. | C51: BAMBANG HARIANTO | E51: 1 | F51: 0 | G51: 2 | H51: 3 | I51: 2 | J51: 2 | K51: 2 | L51: 1 | M51: 3 | N51: 0 | O51: 4 | P51: 5 | Q51: 4 | R51: 3 | S51: 3 | T51: 2 | U51: 5 | V51: 1 | W51: 2 | X51: 2 | Y51: 2 | Z51: 4 | AA51: 3 | AB51: 0 | AC51: 4 | AD51: 1 | AE51: 2 | AF51: 0 | AG51: 0 | AH51: 2 | AI51: 3 | AJ51: 1 | AK51: 0 | AL51: 2 | AM51: 0 | AN51: 5 | AO51: 4 | AP51: 4 | AQ51: 2 | AR51: 0 | AS51: 4 | AT51: 1 | AU51: 1 | AV51: =SUM(E51:AU51) -> 92
...

Sheet KALIPURO
C2: Kecamatan | D2: KALIPURO
C3: Kabupaten | D3: BANYUWANGI
C4: Provinsi | D4: JAWA TIMUR
C9: Kelurahan
A12: I | B12: DATA PEMILIH DAN PENGGUNAAN HAK PILIH | AR12: JUMLAH AKHIR
A13: A | B13: DATA PEMILIH | E13: TPS 001 | F13: TPS 002 | G13: TPS 003 | H13: TPS 004 | I13: TPS 005 | J13: TPS 006 | K13: TPS 007 | L13: TPS 008 | M13: TPS 009 | N13: TPS 010 | O13: TPS 011 | P13: TPS 012 | Q13: TPS 013 | R13: TPS 014 | S13: TPS 015 | T13: TPS 016 | U13: TPS 017 | V13: TPS 018 | W13: TPS 019 | X13: TPS 020 | Y13: TPS 021 | Z13: TPS 022 | AA13: TPS 023 | AB13: TPS 024 | AC13: TPS 025 | AD13: TPS 026 | AE13: TPS 027 | AF13: TPS 028 | AG13: TPS 029 | AH13: TPS 030 | AI13: TPS 031 | AJ13: TPS 032 | AK13: TPS 033 | AL13: TPS 034 | AM13: TPS 035 | AN13: TPS 036 | AO13: TPS 037 | AP13: TPS 038 | AQ13: TPS 039
B14: Jumlah Pemilih dalam Daftar Pemilih Tetap (DPT) | D14: LK | E14: 137 | F14: 141 | G14: 136 | H14: 135 | I14: 156 | J14: 147 | K14: 145 | L14: 147 | M14: 140 | N14: 141 | O14: 145 | P14: 134 | Q14: 148 | R14: 147 | S14: 139 | T14: 147 | U14: 138 | V14: 143 | W14: 133 | X14: 141 | Y14: 122 | Z14: 145 | AA14: 126 | AB14: 144 | AC14: 145 | AD14: 155 | AE14: 155 | AF14: 149 | AG14: 145 | AH14: 141 | AI14: 143 | AJ14: 135 | AK14: 145 | AL14: 147 | AM14: 132 | AN14: 147 | AO14: 136 | AP14: 150 | AQ14: 134 | AR14: =SUM(E14:AQ14) -> 5536
D15: PR | E15: 157 | F15: 146 | G15: 131 | H15: 154 | I15: 140 | J15: 146 | K15: 148 | L15: 151 | M15: 135 | N15: 158 | O15: 154 | P15: 124 | Q15: 150 | R15: 149 | S15: 156 | T15: 151 | U15: 158 | V15: 153 | W15: 158 | X15: 157 | Y15: 143 | Z15: 142 | AA15: 156 | AB15: 154 | AC15: 149 | AD15: 143 | AE15: 144 | AF15: 143 | AG15: 142 | AH15: 137 | AI15: 150 | AJ15: 157 | AK15: 149 | AL15: 147 | AM15: 123 | AN15: 147 | AO15: 143 | AP15: 147 | AQ15: 149 | AR15: =SUM(E15:AQ15) -> 5741
D16: JML | E16: =SUM(E14:E15) -> 294 | F16: =SUM(F14:F15) -> 287 | G16: =SUM(G14:G15) -> 267 | H16: =SUM(H14:H15) -> 289 | I16: =SUM(I14:I15) -> 296 | J16: =SUM(J14:J15) -> 293 | K16: =SUM(K14:K15) -> 293 | L16: =SUM(L14:L15) -> 298 | ... AQ16: =SUM(AQ14:AQ15) -> 283 | AR16: =SUM(E16:AQ16) -> 11277
A18: B | B18: PENGGUNA HAK PILIH
B19: 1. | C19: Jumlah pengguna hak pilih dalam Daftar Pemilih Tetap (DPT) | D19: LK | E19: 107 | F19: 105 | G19: 71 | H19: 91 | I19: 100 | J19: 84 | K19: 104 | L19: 108 | M19: 106 | N19: 101 | O19: 104 | P19: 103 | Q19: 113 | R19: 108 | S19: 105 | T19: 122 | U19: 89 | V19: 122 | W19: 95 | X19: 96 | Y19: 98 | Z19: 104 | AA19: 94 | AB19: 132 | AC19: 109 | AD19: 138 | AE19: 116 | AF19: 131 | AG19: 109 | AH19: 107 | AI19: 114 | AJ19: 110 | AK19: 111 | AL19: 127 | AM19: 107 | AN19: 123 | AO19: 101 | AP19: 131 | AQ19: 101 | AR19: =SUM(E19:AQ19) -> 4197
D20: PR | E20: 128 | F20: 117 | G20: 90 | H20: 101 | I20: 104 | J20: 99 | K20: 108 | L20: 126 | M20: 102 | N20: 116 | O20: 132 | P20: 109 | Q20: 122 | R20: 125 | S20: 120 | T20: 130 | U20: 111 | V20: 116 | W20: 125 | X20: 126 | Y20: 102 | Z20: 107 | AA20: 121 | AB20: 124 | AC20: 127 | AD20: 127 | AE20: 117 | AF20: 134 | AG20: 114 | AH20: 103 | AI20: 120 | AJ20: 123 | AK20: 109 | AL20: 126 | AM20: 107 | AN20: 116 | AO20: 96 | AP20: 122 | AQ20: 99 | AR20: =SUM(E20:AQ20) -> 4501
D21: JML | E21: =SUM(E19:E20) -> 235 | F21: =SUM(F19:F20) -> 222 | G21: =SUM(G19:G20) -> 161 | H21: =SUM(H19:H20) -> 192 | I21: =SUM(I19:I20) -> 204 | J21: =SUM(J19:J20) -> 183 | K21: =SUM(K19:K20) -> 212 | L21: =SUM(L19:L20) -> 234 | ... AQ21: =SUM(AQ19:AQ20) -> 200 | AR21: =SUM(E21:AQ21) -> 8698
B22: 2. | C22: Jumlah pengguna hak pilih dalam Daftar Pemilih Tambahan (DPTb) | D22: LK | E22: 0 | F22: 0 | G22: 3 | H22: 0 | I22: 1 | J22: 2 | K22: 0 | L22: 1 | M22: 0 | N22: 0 | O22: 0 | P22: 0 | Q22: 2 | R22: 2 | S22: 0 | T22: 1 | U22: 1 | V22: 0 | W22: 1 | X22: 0 | Y22: 0 | Z22: 1 | AA22: 0 | AB22: 1 | AC22: 0 | AD22: 0 | AE22: 0 | AF22: 0 | AG22: 0 | AH22: 0 | AI22: 0 | AJ22: 0 | AK22: 1 | AL22: 1 | AM22: 0 | AN22: 0 | AO22: 0 | AP22: 0 | AQ22: 1 | AR22: =SUM(E22:AQ22) -> 19
D23: PR | E23: 0 | F23: 1 | G23: 1 | H23: 0 | I23: 0 | J23: 0 | K23: 1 | L23: 1 | M23: 0 | N23: 0 | O23: 0 | P23: 0 | Q23: 0 | R23: 1 | S23: 1 | T23: 1 | U23: 0 | V23: 1 | W23: 0 | X23: 1 | Y23: 0 | Z23: 0 | AA23: 1 | AB23: 1 | AC23: 0 | AD23: 0 | AE23: 0 | AF23: 0 | AG23: 0 | AH23: 0 | AI23: 1 | AJ23: 0 | AK23: 0 | AL23: 0 | AM23: 1 | AN23: 0 | AO23: 0 | AP23: 0 | AQ23: 0 | AR23: =SUM(E23:AQ23) -> 13
D24: JML | E24: =SUM(E22:E23) -> 0 | F24: =SUM(F22:F23) -> 1 | G24: =SUM(G22:G23) -> 4 | H24: =SUM(H22:H23) -> 0 | I24: =SUM(I22:I23) -> 1 | J24: =SUM(J22:J23) -> 2 | K24: =SUM(K22:K23) -> 1 | L24: =SUM(L22:L23) -> 2 | ... AQ24: =SUM(AQ22:AQ23) -> 1 | AR24: =SUM(E24:AQ24) -> 32
B25: 3. | C25: Jumlah pengguna hak pilih dalam Daftar Pemilih Khusus (DPK) | D25: LK | E25: 1 | F25: 7 | G25: 1 | H25: 0 | I25: 2 | J25: 2 | K25: 4 | L25: 3 | M25: 2 | N25: 2 | O25: 2 | P25: 2 | Q25: 1 | R25: 0 | S25: 0 | T25: 3 | U25: 0 | V25: 9 | W25: 1 | X25: 7 | Y25: 1 | Z25: 1 | AA25: 0 | AB25: 2 | AC25: 1 | AD25: 3 | AE25: 3 | AF25: 0 | AG25: 2 | AH25: 6 | AI25: 4 | AJ25: 5 | AK25: 5 | AL25: 1 | AM25: 6 | AN25: 15 | AO25: 4 | AP25: 0 | AQ25: 0 | AR25: =SUM(E25:AQ25) -> 108
D26: PR | E26: 0 | F26: 0 | G26: 1 | H26: 1 | I26: 3 | J26: 8 | K26: 2 | L26: 2 | M26: 3 | N26: 1 | O26: 3 | P26: 2 | Q26: 2 | R26: 1 | S26: 5 | T26: 4 | U26: 0 | V26: 10 | W26: 0 | X26: 6 | Y26: 1 | Z26: 4 | AA26: 0 | AB26: 0 | AC26: 2 | AD26: 6 | AE26: 6 | AF26: 1 | AG26: 3 | AH26: 3 | AI26: 7 | AJ26: 6 | AK26: 8 | AL26: 2 | AM26: 5 | AN26: 15 | AO26: 4 | AP26: 0 | AQ26: 1 | AR26: =SUM(E26:AQ26) -> 128
D27: JML | E27: =SUM(E25:E26) -> 1 | F27: =SUM(F25:F26) -> 7 | G27: =SUM(G25:G26) -> 2 | H27: =SUM(H25:H26) -> 1 | I27: =SUM(I25:I26) -> 5 | J27: =SUM(J25:J26) -> 10 | K27: =SUM(K25:K26) -> 6 | L27: =SUM(L25:L26) -> 5 | ... AQ27: =SUM(AQ25:AQ26) -> 1 | AR27: =SUM(E27:AQ27) -> 236
B28: 4. | C28: Jumlah Pengguna Hak Pilih (B.1+B.2+B.3) | D28: LK | E28: =SUM(E19,E22,E25) -> 108 | F28: =SUM(F19,F22,F25) -> 112 | G28: =SUM(G19,G22,G25) -> 75 | H28: =SUM(H19,H22,H25) -> 91 | I28: =SUM(I19,I22,I25) -> 103 | J28: =SUM(J19,J22,J25) -> 88 | K28: =SUM(K19,K22,K25) -> 108 | L28: =SUM(L19,L22,L25) -> 112 | ... AQ28: =SUM(AQ19,AQ22,AQ25) -> 102 | AR28: =SUM(E28:AQ28) -> 4324
D29: PR | E29: =SUM(E20,E23,E26) -> 128 | F29: =SUM(F20,F23,F26) -> 118 | G29: =SUM(G20,G23,G26) -> 92 | H29: =SUM(H20,H23,H26) -> 102 | I29: =SUM(I20,I23,I26) -> 107 | J29: =SUM(J20,J23,J26) -> 107 | K29: =SUM(K20,K23,K26) -> 111 | L29: =SUM(L20,L23,L26) -> 129 | ... AQ29: =SUM(AQ20,AQ23,AQ26) -> 100 | AR29: =SUM(E29:AQ29) -> 4642
D30: JML | E30: =SUM(E28:E29) -> 236 | F30: =SUM(F28:F29) -> 230 | G30: =SUM(G28:G29) -> 167 | H30: =SUM(H28:H29) -> 193 | I30: =SUM(I28:I29) -> 210 | J30: =SUM(J28:J29) -> 195 | K30: =SUM(K28:K29) -> 219 | L30: =SUM(L28:L29) -> 241 | ... AQ30: =SUM(AQ28:AQ29) -> 202 | AR30: =SUM(E30:AQ30) -> 8966
A32: II | B32: DATA PENGGUNAAN SURAT SUARA
A33: 1 | B33: Jumlah surat suara yang diterima, termasuk surat suara cadangan 2% dari DPT | E33: 292 | F33: 285 | G33: 266 | H33: 285 | I33: 289 | J33: 292 | K33: 290 | L33: 293 | M33: 281 | N33: 296 | O33: 288 | P33: 264 | Q33: 270 | R33: 292 | S33: 304 | T33: 294 | U33: 293 | V33: 302 | W33: 289 | X33: 293 | Y33: 262 | Z33: 285 | AA33: 279 | AB33: 294 | AC33: 283 | AD33: 293 | AE33: 296 | AF33: 291 | AG33: 274 | AH33: 274 | AI33: 328 | AJ33: 279 | AK33: 292 | AL33: 292 | AM33: 251 | AN33: 294 | AO33: 269 | AP33: 303 | AQ33: 280 | AR33: =SUM(E33:AQ33) -> 11177
A34: 2 | B34: Jumlah surat suara yang digunakan | E34: 236 | F34: 230 | G34: 167 | H34: 193 | I34: 210 | J34: 195 | K34: 219 | L34: 241 | M34: 213 | N34: 220 | O34: 241 | P34: 216 | Q34: 240 | R34: 237 | S34: 231 | T34: 261 | U34: 201 | V34: 258 | W34: 222 | X34: 236 | Y34: 202 | Z34: 217 | AA34: 216 | AB34: 260 | AC34: 239 | AD34: 274 | AE34: 242 | AF34: 266 | AG34: 228 | AH34: 219 | AI34: 246 | AJ34: 244 | AK34: 234 | AL34: 257 | AM34: 226 | AN34: 269 | AO34: 205 | AP34: 253 | AQ34: 202 | AR34: =SUM(E34:AQ34) -> 8966
A35: 3 | B35: Jumlah surat suara dikembalikan oleh pemilih (karena rusak atau keliru coblos) | E35: 0 | F35: 0 | G35: 0 | H35: 0 | I35: 2 | J35: 4 | K35: 0 | L35: 0 | M35: 0 | N35: 0 | O35: 0 | P35: 0 | Q35: 0 | R35: 0 | S35: 0 | T35: 0 | U35: 1 | V35: 0 | W35: 0 | X35: 0 | Y35: 0 | Z35: 0 | AA35: 0 | AB35: 0 | AC35: 0 | AD35: 2 | AE35: 0 | AF35: 0 | AG35: 1 | AH35: 0 | AI35: 0 | AJ35: 0 | AK35: 0 | AL35: 2 | AM35: 0 | AN35: 0 | AO35: 2 | AP35: 0 | AQ35: 0 | AR35: =SUM(E35:AQ35) -> 14
A36: 4 | B36: Jumlah surat suara yang tidak digunakan/tidak terpakai, termasuk sisa surat suara cadangan | E36: =E33-(E34+E35) -> 56 | F36: =F33-(F34+F35) -> 55 | G36: =G33-(G34+G35) -> 99 | H36: =H33-(H34+H35) -> 92 | I36: =I33-(I34+I35) -> 77 | J36: =J33-(J34+J35) -> 93 | K36: =K33-(K34+K35) -> 71 | L36: =L33-(L34+L35) -> 52 | ... AQ36: =AQ33-(AQ34+AQ35) -> 78 | AR36: =SUM(E36:AQ36) -> 2197
A38: III | B38: DATA PEMILIH DISABILITAS
B39: Jumlah seluruh Pemilih disabilitas yang menggunakan hak pilih | D39: LK | E39: 1 | F39: 1 | M39: 1 | S39: 2 | T39: 1 | W39: 2 | AC39: 3 | AD39: 3 | AH39: 1 | AQ39: 1 | AR39: =SUM(E39:AQ39) -> 16
D40: PR | E40: 2 | S40: 3 | U40: 2 | W40: 1 | AC40: 4 | AD40: 1 | AG40: 1 | AR40: =SUM(E40:AQ40) -> 14
D41: JML | E41: =SUM(E39:E40) -> 3 | F41: =SUM(F39:F40) -> 1 | G41: =SUM(G39:G40) -> 0 | H41: =SUM(H39:H40) -> 0 | I41: =SUM(I39:I40) -> 0 | J41: =SUM(J39:J40) -> 0 | K41: =SUM(K39:K40) -> 0 | L41: =SUM(L39:L40) -> 0 | ... AQ41: =SUM(AQ39:AQ40) -> 1 | AR41: =SUM(E41:AQ41) -> 30
A43: IV | B43: DATA RINCIAN PEROLEHAN SUARA PASANGAN CALON BUPATI DAN WAKIL BUPATI
B44: NOMOR DAN NAMA CALON
B45: 1. | C45: AA. AHMAD NAWARDI | E45: 5 | F45: 14 | G45: 8 | H45: 4 | I45: 11 | J45: 20 | K45: 16 | L45: 18 | M45: 18 | N45: 21 | O45: 17 | P45: 21 | Q45: 24 | R45: 27 | S45: 21 | T45: 32 | U45: 14 | V45: 53 | W45: 10 | X45: 26 | Y45: 20 | Z45: 26 | AA45: 34 | AB45: 51 | AC45: 52 | AD45: 48 | AE45: 34 | AF45: 34 | AG45: 50 | AH45: 31 | AI45: 47 | AJ45: 50 | AK45: 34 | AL45: 39 | AM45: 32 | AN45: 44 | AO45: 29 | AP45: 31 | AQ45: 7 | AR45: =SUM(E45:AQ45) -> 1073
B46: 2. | C46: Ir. H. AA LA NYALLA MAHMUD MATTALITI, M.HP. | E46: 35 | F46: 28 | G46: 21 | H46: 18 | I46: 30 | J46: 29 | K46: 32 | L46: 45 | M46: 34 | N46: 27 | O46: 44 | P46: 25 | Q46: 34 | R46: 29 | S46: 36 | T46: 24 | U46: 26 | V46: 37 | W46: 22 | X46: 39 | Y46: 23 | Z46: 23 | AA46: 31 | AB46: 24 | AC46: 33 | AD46: 37 | AE46: 54 | AF46: 22 | AG46: 26 | AH46: 25 | AI46: 38 | AJ46: 40 | AK46: 48 | AL46: 26 | AM46: 30 | AN46: 35 | AO46: 19 | AP46: 26 | AQ46: 30 | AR46: =SUM(E46:AQ46) -> 1205
B47: 3. | C47: ABDUL QADIR AMIR HARTONO, S.E., S.H., M.H. | E47: 19 | F47: 16 | G47: 6 | H47: 16 | I47: 10 | J47: 10 | K47: 17 | L47: 9 | M47: 8 | N47: 13 | O47: 11 | P47: 12 | Q47: 17 | R47: 10 | S47: 13 | T47: 13 | U47: 17 | V47: 13 | W47: 14 | X47: 9 | Y47: 21 | Z47: 12 | AA47: 8 | AB47: 8 | AC47: 21 | AD47: 18 | AE47: 16 | AF47: 17 | AG47: 9 | AH47: 14 | AI47: 17 | AJ47: 10 | AK47: 14 | AL47: 15 | AM47: 20 | AN47: 8 | AO47: 13 | AP47: 9 | AQ47: 12 | AR47: =SUM(E47:AQ47) -> 515
B48: 4. | C48: ADILLA AZIS, S.E. | E48: 29 | F48: 22 | G48: 12 | H48: 14 | I48: 16 | J48: 15 | K48: 20 | L48: 32 | M48: 37 | N48: 19 | O48: 28 | P48: 26 | Q48: 30 | R48: 26 | S48: 18 | T48: 28 | U48: 20 | V48: 20 | W48: 33 | X48: 18 | Y48: 23 | Z48: 24 | AA48: 29 | AB48: 15 | AC48: 15 | AD48: 36 | AE48: 21 | AF48: 28 | AG48: 12 | AH48: 19 | AI48: 20 | AJ48: 18 | AK48: 25 | AL48: 16 | AM48: 18 | AN48: 19 | AO48: 20 | AP48: 19 | AQ48: 27 | AR48: =SUM(E48:AQ48) -> 867
B49: 5. | C49: Ir. H. AGUS RAHARDJO, MSc.M. | E49: 22 | F49: 24 | G49: 24 | H49: 25 | I49: 23 | J49: 15 | K49: 19 | L49: 15 | M49: 12 | N49: 16 | O49: 29 | P49: 12 | Q49: 16 | R49: 31 | S49: 24 | T49: 10 | U49: 22 | V49: 14 | W49: 14 | X49: 20 | Y49: 30 | Z49: 27 | AA49: 11 | AB49: 15 | AC49: 17 | AD49: 11 | AE49: 15 | AF49: 24 | AG49: 13 | AH49: 24 | AI49: 17 | AJ49: 15 | AK49: 22 | AL49: 24 | AM49: 23 | AN49: 20 | AO49: 11 | AP49: 21 | AQ49: 7 | AR49: =SUM(E49:AQ49) -> 734
B50: 6. | C50: Drs. AYUB KHAN | E50: 18 | F50: 17 | G50: 12 | H50: 13 | I50: 8 | J50: 10 | K50: 11 | L50: 22 | M50: 11 | N50: 11 | O50: 14 | P50: 14 | Q50: 17 | R50: 14 | S50: 13 | T50: 12 | U50: 14 | V50: 27 | W50: 9 | X50: 14 | Y50: 10 | Z50: 23 | AA50: 20 | AB50: 27 | AC50: 21 | AD50: 7 | AE50: 23 | AF50: 17 | AG50: 38 | AH50: 14 | AI50: 21 | AJ50: 31 | AK50: 13 | AL50: 24 | AM50: 18 | AN50: 24 | AO50: 29 | AP50: 14 | AQ50: 9 | AR50: =SUM(E50:AQ50) -> 664
B51: 7. | C51: BAMBANG HARIANTO | E51: 3 | F51: 2 | G51: 2 | H51: 1 | I51: 1 | J51: 2 | K51: 4 | L51: 2 | M51: 1 | N51: 3 | O51: 0 | P51: 2 | Q51: 3 | R51: 4 | S51: 0 | T51: 2 | U51: 2 | V51: 5 | W51: 1 | X51: 3 | Y51: 1 | Z51: 1 | AA51: 2 | AB51: 0 | AC51: 1 | AD51: 3 | AE51: 5 | AF51: 2 | AG51: 1 | AH51: 3 | AI51: 2 | AJ51: 2 | AK51: 4 | AL51: 0 | AM51: 0 | AN51: 5 | AO51: 1 | AP51: 2 | AQ51: 2 | AR51: =SUM(E51:AQ51) -> 80
...

Sheet GOMBENGSARI
C2: Kecamatan | D2: KALIPURO
C3: Kabupaten | D3: BANYUWANGI
C4: Provinsi | D4: JAWA TIMUR
C9: Kelurahan
A12: I | B12: DATA PEMILIH DAN PENGGUNAAN HAK PILIH | AC12: JUMLAH AKHIR
A13: A | B13: DATA PEMILIH | E13: TPS 001 | F13: TPS 002 | G13: TPS 003 | H13: TPS 004 | I13: TPS 005 | J13: TPS 006 | K13: TPS 007 | L13: TPS 008 | M13: TPS 009 | N13: TPS 010 | O13: TPS 011 | P13: TPS 012 | Q13: TPS 013 | R13: TPS 014 | S13: TPS 015 | T13: TPS 016 | U13: TPS 017 | V13: TPS 018 | W13: TPS 019 | X13: TPS 020 | Y13: TPS 021 | Z13: TPS 022 | AA13: TPS 023 | AB13: TPS 024
B14: Jumlah Pemilih dalam Daftar Pemilih Tetap (DPT) | D14: LK | E14: 88 | F14: 112 | G14: 144 | H14: 112 | I14: 130 | J14: 147 | K14: 145 | L14: 148 | M14: 125 | N14: 122 | O14: 120 | P14: 148 | Q14: 148 | R14: 139 | S14: 100 | T14: 141 | U14: 139 | V14: 139 | W14: 139 | X14: 137 | Y14: 122 | Z14: 109 | AA14: 124 | AB14: 127 | AC14: =SUM(E14:AB14) -> 3105
D15: PR | E15: 84 | F15: 119 | G15: 147 | H15: 118 | I15: 144 | J15: 150 | K15: 150 | L15: 143 | M15: 136 | N15: 125 | O15: 132 | P15: 146 | Q15: 140 | R15: 146 | S15: 100 | T15: 143 | U15: 142 | V15: 139 | W15: 145 | X15: 130 | Y15: 130 | Z15: 108 | AA15: 132 | AB15: 123 | AC15: =SUM(E15:AB15) -> 3172
D16: JML | E16: =SUM(E14:E15) -> 172 | F16: =SUM(F14:F15) -> 231 | G16: =SUM(G14:G15) -> 291 | H16: =SUM(H14:H15) -> 230 | I16: =SUM(I14:I15) -> 274 | J16: =SUM(J14:J15) -> 297 | K16: =SUM(K14:K15) -> 295 | L16: =SUM(L14:L15) -> 291 | ... AB16: =SUM(AB14:AB15) -> 250 | AC16: =SUM(E16:AB16) -> 6277
A18: B | B18: PENGGUNA HAK PILIH
B19: 1. | C19: Jumlah pengguna hak pilih dalam Daftar Pemilih Tetap (DPT) | D19: LK | E19: 63 | F19: 88 | G19: 101 | H19: 80 | I19: 104 | J19: 117 | K19: 117 | L19: 124 | M19: 96 | N19: 98 | O19: 106 | P19: 124 | Q19: 111 | R19: 115 | S19: 94 | T19: 121 | U19: 120 | V19: 123 | W19: 112 | X19: 114 | Y19: 105 | Z19: 87 | AA19: 99 | AB19: 97 | AC19: =SUM(E19:AB19) -> 2516
D20: PR | E20: 73 | F20: 104 | G20: 118 | H20: 97 | I20: 133 | J20: 129 | K20: 128 | L20: 127 | M20: 107 | N20: 106 | O20: 122 | P20: 125 | Q20: 116 | R20: 123 | S20: 94 | T20: 122 | U20: 121 | V20: 120 | W20: 122 | X20: 108 | Y20: 107 | Z20: 89 | AA20: 118 | AB20: 96 | AC20: =SUM(E20:AB20) -> 2705
D21: JML | E21: =SUM(E19:E20) -> 136 | F21: =SUM(F19:F20) -> 192 | G21: =SUM(G19:G20) -> 219 | H21: =SUM(H19:H20) -> 177 | I21: =SUM(I19:I20) -> 237 | J21: =SUM(J19:J20) -> 246 | K21: =SUM(K19:K20) -> 245 | L21: =SUM(L19:L20) -> 251 | ... AB21: =SUM(AB19:AB20) -> 193 | AC21: =SUM(E21:AB21) -> 5221
B22: 2. | C22: Jumlah pengguna hak pilih dalam Daftar Pemilih Tambahan (DPTb) | D22: LK | E22: 0 | F22: 0 | G22: 0 | H22: 0 | I22: 0 | J22: 0 | K22: 0 | L22: 0 | M22: 1 | N22: 0 | O22: 0 | P22: 0 | Q22: 1 | R22: 0 | S22: 0 | T22: 1 | U22: 0 | V22: 0 | W22: 0 | X22: 0 | Y22: 0 | Z22: 0 | AA22: 1 | AB22: 0 | AC22: =SUM(E22:AB22) -> 4
D23: PR | E23: 1 | F23: 0 | G23: 1 | H23: 0 | I23: 1 | J23: 0 | K23: 1 | L23: 0 | M23: 0 | N23: 0 | O23: 0 | P23: 0 | Q23: 2 | R23: 0 | S23: 1 | T23: 0 | U23: 0 | V23: 0 | W23: 1 | X23: 0 | Y23: 0 | Z23: 0 | AA23: 1 | AB23: 1 | AC23: =SUM(E23:AB23) -> 10
