Workbook

Sheet DPD
C8: Kecamatan | D8: GIRI
C9: Kabupaten | D9: BANYUWANGI
C10: Provinsi | D10: JAWA TIMUR
A12: I | B12: DATA PEMILIH DAN PENGGUNAAN HAK PILIH | E12: JUMLAH AKHIR
A13: A | B13: DATA PEMILIH
B14: Jumlah Pemilih dalam Daftar Pemilih Tetap (DPT) | D14: LK | E14: =BOYOLANGU!U14+GIRI!V14+GROGOL!V14+JAMBESARI!O14+MOJOPANGGUNG!V14+PENATABAN!V14 -> 12715
D15: PR | E15: =BOYOLANGU!U15+GIRI!V15+GROGOL!V15+JAMBESARI!O15+MOJOPANGGUNG!V15+PENATABAN!V15 -> 12285
D16: JML | E16: =SUM(E14:E15) -> 25000
A18: B | B18: PENGGUNA HAK PILIH
B19: 1. | C19: Jumlah pengguna hak pilih dalam Daftar Pemilih Tetap (DPT) | D19: LK | E19: =BOYOLANGU!U19+GIRI!V19+GROGOL!V19+JAMBESARI!O19+MOJOPANGGUNG!V19+PENATABAN!V19 -> 9732
D20: PR | E20: =BOYOLANGU!U20+GIRI!V20+GROGOL!V20+JAMBESARI!O20+MOJOPANGGUNG!V20+PENATABAN!V20 -> 10226
D21: JML | E21: =SUM(E19:E20) -> 19958
B22: 2. | C22: Jumlah pengguna hak pilih dalam Daftar Pemilih Tambahan (DPTb) | D22: LK | E22: =BOYOLANGU!U22+GIRI!V22+GROGOL!V22+JAMBESARI!O22+MOJOPANGGUNG!V22+PENATABAN!V22 -> 338
D23: PR | E23: =BOYOLANGU!U23+GIRI!V23+GROGOL!V23+JAMBESARI!O23+MOJOPANGGUNG!V23+PENATABAN!V23 -> 56
D24: JML | E24: =SUM(E22:E23) -> 394
B25: 3. | C25: Jumlah pengguna hak pilih dalam Daftar Pemilih Khusus (DPK) | D25: LK | E25: =BOYOLANGU!U25+GIRI!V25+GROGOL!V25+JAMBESARI!O25+MOJOPANGGUNG!V25+PENATABAN!V25 -> 52
D26: PR | E26: =BOYOLANGU!U26+GIRI!V26+GROGOL!V26+JAMBESARI!O26+MOJOPANGGUNG!V26+PENATABAN!V26 -> 95
D27: JML | E27: =SUM(E25:E26) -> 147
B28: 4. | C28: Jumlah Pengguna Hak Pilih (B.1+B.2+B.3) | D28: LK | E28: =E19+E22+E25 -> 10122
D29: PR | E29: =E20+E23+E26 -> 10377
D30: JML | E30: =SUM(E28:E29) -> 20499
A32: II | B32: DATA PENGGUNAAN SURAT SUARA
A33: 1 | B33: Jumlah surat suara yang diterima, termasuk surat suara cadangan 2,5% dari DPT | E33: =BOYOLANGU!U33+GIRI!V33+GROGOL!V33+JAMBESARI!O33+MOJOPANGGUNG!V33+PENATABAN!V33 -> 25445
A34: 2 | B34: Jumlah surat suara yang digunakan | E34: =BOYOLANGU!U34+GIRI!V34+GROGOL!V34+JAMBESARI!O34+MOJOPANGGUNG!V34+PENATABAN!V34 -> 20499
A35: 3 | B35: Jumlah surat suara dikembalikan oleh pemilih (karena rusak atau keliru coblos) | E35: =BOYOLANGU!U35+GIRI!V35+GROGOL!V35+JAMBESARI!O35+MOJOPANGGUNG!V35+PENATABAN!V35 -> 48
A36: 4 | B36: Jumlah surat suara yang tidak digunakan/tidak terpakai, termasuk sisa surat suara cadangan | E36: =E33-(E34+E35) -> 4898
A38: III | B38: DATA PEMILIH DISABILITAS
B39: Jumlah seluruh Pemilih disabilitas yang menggunakan hak pilih | D39: LK | E39: =BOYOLANGU!U39+GIRI!V39+GROGOL!V39+JAMBESARI!O39+MOJOPANGGUNG!V39+PENATABAN!V39 -> 28
D40: PR | E40: =BOYOLANGU!U40+GIRI!V40+GROGOL!V40+JAMBESARI!O40+MOJOPANGGUNG!V40+PENATABAN!V40 -> 20
D41: JML | E41: =SUM(E39:E40) -> 48
A43: IV | B43: DATA RINCIAN PEROLEHAN SUARA PASANGAN CALON BUPATI DAN WAKIL BUPATI
A44: NOMOR DAN NAMA CALON
B45: 1. | C45: AA. AHMAD NAWARDI | E45: =BOYOLANGU!U45+GIRI!V45+GROGOL!V45+JAMBESARI!O45+MOJOPANGGUNG!V45+PENATABAN!V45 -> 1845
B46: 2. | C46: Ir. H. AA LA NYALLA MAHMUD MATTALITI, M.HP. | E46: =BOYOLANGU!U46+GIRI!V46+GROGOL!V46+JAMBESARI!O46+MOJOPANGGUNG!V46+PENATABAN!V46 -> 3189
B47: 3. | C47: ABDUL QADIR AMIR HARTONO, S.E., S.H., M.H. | E47: =BOYOLANGU!U47+GIRI!V47+GROGOL!V47+JAMBESARI!O47+MOJOPANGGUNG!V47+PENATABAN!V47 -> 1278
B48: 4. | C48: ADILLA AZIS, S.E. | E48: =BOYOLANGU!U48+GIRI!V48+GROGOL!V48+JAMBESARI!O48+MOJOPANGGUNG!V48+PENATABAN!V48 -> 1870
B49: 5. | C49: Ir. H. AGUS RAHARDJO, MSc.M. | E49: =BOYOLANGU!U49+GIRI!V49+GROGOL!V49+JAMBESARI!O49+MOJOPANGGUNG!V49+PENATABAN!V49 -> 1943
B50: 6. | C50: Drs. AYUB KHAN | E50: =BOYOLANGU!U50+GIRI!V50+GROGOL!V50+JAMBESARI!O50+MOJOPANGGUNG!V50+PENATABAN!V50 -> 1223
B51: 7. | C51: BAMBANG HARIANTO | E51: =BOYOLANGU!U51+GIRI!V51+GROGOL!V51+JAMBESARI!O51+MOJOPANGGUNG!V51+PENATABAN!V51 -> 215
B52: 8. | C52: CATUR RUDI UTANTO, S.Sos. | E52: =BOYOLANGU!U52+GIRI!V52+GROGOL!V52+JAMBESARI!O52+MOJOPANGGUNG!V52+PENATABAN!V52 -> 299
...

Sheet BOYOLANGU
C2: Kecamatan | D2: GIRI
C3: Kabupaten | D3: BANYUWANGI
C4: Provinsi | D4: JAWA TIMUR
C9: Kelurahan | D9: BOYOLANGU
A12: I | B12: DATA PEMILIH DAN PENGGUNAAN HAK PILIH | U12: JUMLAH AKHIR
A13: A | B13: DATA PEMILIH | E13: TPS 001 | F13: TPS 002 | G13: TPS 003 | H13: TPS 004 | I13: TPS 005 | J13: TPS 006 | K13: TPS 007 | L13: TPS 008 | M13: TPS 009 | N13: TPS 010 | O13: TPS 011 | P13: TPS 012 | Q13: TPS 013 | R13: TPS 014 | S13: TPS 015 | T13: TPS 016
B14: Jumlah Pemilih dalam Daftar Pemilih Tetap (DPT) | D14: LK | E14: 137 | F14: 142 | G14: 142 | H14: 141 | I14: 150 | J14: 155 | K14: 146 | L14: 155 | M14: 152 | N14: 139 | O14: 110 | P14: 125 | Q14: 110 | R14: 108 | S14: 70 | T14: 139 | U14: =SUM(E14:T14) -> 2121
D15: PR | E15: 158 | F15: 154 | G15: 155 | H15: 156 | I15: 146 | J15: 142 | K15: 152 | L15: 143 | M15: 145 | N15: 159 | O15: 111 | P15: 133 | Q15: 117 | R15: 117 | S15: 78 | T15: 128 | U15: =SUM(E15:T15) -> 2194
D16: JML | E16: =SUM(E14:E15) -> 295 | F16: =SUM(F14:F15) -> 296 | G16: =SUM(G14:G15) -> 297 | H16: =SUM(H14:H15) -> 297 | I16: =SUM(I14:I15) -> 296 | J16: =SUM(J14:J15) -> 297 | K16: =SUM(K14:K15) -> 298 | L16: =SUM(L14:L15) -> 298 | ... T16: =SUM(T14:T15) -> 267 | U16: =SUM(E16:T16) -> 4315
A18: B | B18: PENGGUNA HAK PILIH
B19: 1. | C19: Jumlah pengguna hak pilih dalam Daftar Pemilih Tetap (DPT) | D19: LK | E19: 89 | F19: 113 | G19: 117 | H19: 118 | I19: 115 | J19: 121 | K19: 107 | L19: 115 | M19: 129 | N19: 105 | O19: 88 | P19: 101 | Q19: 99 | R19: 90 | S19: 51 | T19: 106 | U19: =SUM(E19:T19) -> 1664
D20: PR | E20: 117 | F20: 120 | G20: 134 | H20: 136 | I20: 114 | J20: 123 | K20: 135 | L20: 121 | M20: 131 | N20: 128 | O20: 103 | P20: 112 | Q20: 110 | R20: 100 | S20: 68 | T20: 109 | U20: =SUM(E20:T20) -> 1861
D21: JML | E21: =SUM(E19:E20) -> 206 | F21: =SUM(F19:F20) -> 233 | G21: =SUM(G19:G20) -> 251 | H21: =SUM(H19:H20) -> 254 | I21: =SUM(I19:I20) -> 229 | J21: =SUM(J19:J20) -> 244 | K21: =SUM(K19:K20) -> 242 | L21: =SUM(L19:L20) -> 236 | ... T21: =SUM(T19:T20) -> 215 | U21: =SUM(E21:T21) -> 3525
B22: 2. | C22: Jumlah pengguna hak pilih dalam Daftar Pemilih Tambahan (DPTb) | D22: LK | E22: 1 | F22: 0 | G22: 0 | H22: 0 | I22: 0 | J22: 0 | K22: 0 | L22: 0 | M22: 0 | N22: 0 | O22: 0 | P22: 0 | Q22: 0 | R22: 0 | S22: 0 | U22: =SUM(E22:T22) -> 1
D23: PR | E23: 2 | F23: 0 | G23: 0 | H23: 0 | I23: 0 | J23: 0 | K23: 0 | L23: 0 | M23: 0 | N23: 0 | O23: 0 | P23: 0 | Q23: 0 | R23: 0 | S23: 0 | U23: =SUM(E23:T23) -> 2
D24: JML | E24: =SUM(E22:E23) -> 3 | F24: =SUM(F22:F23) -> 0 | G24: =SUM(G22:G23) -> 0 | H24: =SUM(H22:H23) -> 0 | I24: =SUM(I22:I23) -> 0 | J24: =SUM(J22:J23) -> 0 | K24: =SUM(K22:K23) -> 0 | L24: =SUM(L22:L23) -> 0 | ... T24: =SUM(T22:T23) -> 0 | U24: =SUM(E24:T24) -> 3
B25: 3. | C25: Jumlah pengguna hak pilih dalam Daftar Pemilih Khusus (DPK) | D25: LK | E25: 3 | F25: 2 | G25: 0 | H25: 2 | I25: 0 | J25: 0 | K25: 0 | L25: 0 | M25: 0 | N25: 1 | O25: 0 | P25: 0 | Q25: 0 | R25: 0 | S25: 1 | U25: =SUM(E25:T25) -> 9
D26: PR | E26: 5 | F26: 0 | G26: 0 | H26: 1 | I26: 1 | J26: 0 | K26: 0 | L26: 1 | M26: 0 | N26: 1 | O26: 0 | P26: 0 | Q26: 0 | R26: 1 | S26: 0 | U26: =SUM(E26:T26) -> 10
D27: JML | E27: =SUM(E25:E26) -> 8 | F27: =SUM(F25:F26) -> 2 | G27: =SUM(G25:G26) -> 0 | H27: =SUM(H25:H26) -> 3 | I27: =SUM(I25:I26) -> 1 | J27: =SUM(J25:J26) -> 0 | K27: =SUM(K25:K26) -> 0 | L27: =SUM(L25:L26) -> 1 | ... T27: =SUM(T25:T26) -> 0 | U27: =SUM(E27:T27) -> 19
B28: 4. | C28: Jumlah Pengguna Hak Pilih (B.1+B.2+B.3) | D28: LK | E28: =SUM(E19,E22,E25) -> 93 | F28: =SUM(F19,F22,F25) -> 115 | G28: =SUM(G19,G22,G25) -> 117 | H28: =SUM(H19,H22,H25) -> 120 | I28: =SUM(I19,I22,I25) -> 115 | J28: =SUM(J19,J22,J25) -> 121 | K28: =SUM(K19,K22,K25) -> 107 | L28: =SUM(L19,L22,L25) -> 115 | ... T28: =SUM(T19,T22,T25) -> 106 | U28: =SUM(E28:T28) -> 1674
D29: PR | E29: =SUM(E20,E23,E26) -> 124 | F29: =SUM(F20,F23,F26) -> 120 | G29: =SUM(G20,G23,G26) -> 134 | H29: =SUM(H20,H23,H26) -> 137 | I29: =SUM(I20,I23,I26) -> 115 | J29: =SUM(J20,J23,J26) -> 123 | K29: =SUM(K20,K23,K26) -> 135 | L29: =SUM(L20,L23,L26) -> 122 | ... T29: =SUM(T20,T23,T26) -> 109 | U29: =SUM(E29:T29) -> 1873
D30: JML | E30: =SUM(E28:E29) -> 217 | F30: =SUM(F28:F29) -> 235 | G30: =SUM(G28:G29) -> 251 | H30: =SUM(H28:H29) -> 257 | I30: =SUM(I28:I29) -> 230 | J30: =SUM(J28:J29) -> 244 | K30: =SUM(K28:K29) -> 242 | L30: =SUM(L28:L29) -> 237 | ... T30: =SUM(T28:T29) -> 215 | U30: =SUM(E30:T30) -> 3547
A32: II | B32: DATA PENGGUNAAN SURAT SUARA
A33: 1 | B33: Jumlah surat suara yang diterima, termasuk surat suara cadangan 2,5% dari DPT | E33: 301 | F33: 301 | G33: 302 | H33: 295 | I33: 302 | J33: 303 | K33: 284 | L33: 304 | M33: 303 | N33: 304 | O33: 226 | P33: 264 | Q33: 233 | R33: 230 | S33: 152 | T33: 273 | U33: =SUM(E33:T33) -> 4377
A34: 2 | B34: Jumlah surat suara yang digunakan | E34: 217 | F34: 235 | G34: 251 | H34: 257 | I34: 230 | J34: 244 | K34: 242 | L34: 237 | M34: 260 | N34: 235 | O34: 191 | P34: 213 | Q34: 209 | R34: 191 | S34: 120 | T34: 215 | U34: =SUM(E34:T34) -> 3547
A35: 3 | B35: Jumlah surat suara dikembalikan oleh pemilih (karena rusak atau keliru coblos) | E35: 1 | U35: =SUM(E35:T35) -> 1
A36: 4 | B36: Jumlah surat suara yang tidak digunakan/tidak terpakai, termasuk sisa surat suara cadangan | E36: =E33-(E34+E35) -> 83 | F36: =F33-(F34+F35) -> 66 | G36: =G33-(G34+G35) -> 51 | H36: =H33-(H34+H35) -> 38 | I36: =I33-(I34+I35) -> 72 | J36: =J33-(J34+J35) -> 59 | K36: =K33-(K34+K35) -> 42 | L36: =L33-(L34+L35) -> 67 | ... T36: =T33-(T34+T35) -> 58 | U36: =SUM(E36:T36) -> 829
A38: III | B38: DATA PEMILIH DISABILITAS
B39: Jumlah seluruh Pemilih disabilitas yang menggunakan hak pilih | D39: LK | F39: 1 | I39: 1 | Q39: 2 | U39: =SUM(E39:T39) -> 4
D40: PR | M40: 1 | U40: =SUM(E40:T40) -> 1
D41: JML | E41: =SUM(E39:E40) -> 0 | F41: =SUM(F39:F40) -> 1 | G41: =SUM(G39:G40) -> 0 | H41: =SUM(H39:H40) -> 0 | I41: =SUM(I39:I40) -> 1 | J41: =SUM(J39:J40) -> 0 | K41: =SUM(K39:K40) -> 0 | L41: =SUM(L39:L40) -> 0 | ... T41: =SUM(T39:T40) -> 0 | U41: =SUM(E41:T41) -> 5
A43: IV | B43: DATA RINCIAN PEROLEHAN SUARA PASANGAN CALON BUPATI DAN WAKIL BUPATI
A44: NOMOR DAN NAMA CALON
B45: 1. | C45: AA. AHMAD NAWARDI | E45: 9 | F45: 6 | G45: 18 | H45: 27 | I45: 16 | J45: 14 | K45: 14 | L45: 24 | M45: 28 | N45: 21 | O45: 24 | P45: 30 | Q45: 17 | R45: 12 | S45: 7 | T45: 13 | U45: =SUM(E45:T45) -> 280
B46: 2. | C46: Ir. H. AA LA NYALLA MAHMUD MATTALITI, M.HP. | E46: 34 | F46: 33 | G46: 31 | H46: 38 | I46: 27 | J46: 27 | K46: 26 | L46: 31 | M46: 29 | N46: 38 | O46: 26 | P46: 36 | Q46: 46 | R46: 45 | S46: 17 | T46: 28 | U46: =SUM(E46:T46) -> 512
B47: 3. | C47: ABDUL QADIR AMIR HARTONO, S.E., S.H., M.H. | E47: 9 | F47: 12 | G47: 15 | H47: 15 | I47: 24 | J47: 14 | K47: 19 | L47: 9 | M47: 15 | N47: 15 | O47: 13 | P47: 13 | Q47: 13 | R47: 16 | S47: 9 | T47: 18 | U47: =SUM(E47:T47) -> 229
B48: 4. | C48: ADILLA AZIS, S.E. | E48: 16 | F48: 17 | G48: 24 | H48: 19 | I48: 19 | J48: 32 | K48: 19 | L48: 33 | M48: 28 | N48: 25 | O48: 21 | P48: 18 | Q48: 24 | R48: 21 | S48: 11 | T48: 18 | U48: =SUM(E48:T48) -> 345
B49: 5. | C49: Ir. H. AGUS RAHARDJO, MSc.M. | E49: 36 | F49: 25 | G49: 22 | H49: 31 | I49: 22 | J49: 18 | K49: 24 | L49: 22 | M49: 24 | N49: 13 | O49: 11 | P49: 15 | Q49: 17 | R49: 9 | S49: 21 | T49: 20 | U49: =SUM(E49:T49) -> 330
B50: 6. | C50: Drs. AYUB KHAN | E50: 9 | F50: 11 | G50: 12 | H50: 26 | I50: 15 | J50: 10 | K50: 8 | L50: 16 | M50: 17 | N50: 13 | O50: 20 | P50: 13 | Q50: 10 | R50: 13 | S50: 6 | T50: 15 | U50: =SUM(E50:T50) -> 214
B51: 7. | C51: BAMBANG HARIANTO | E51: 3 | F51: 2 | G51: 4 | H51: 1 | I51: 2 | J51: 1 | K51: 4 | L51: 1 | M51: 2 | N51: 3 | O51: 2 | P51: 0 | Q51: 1 | R51: 1 | S51: 0 | T51: 1 | U51: =SUM(E51:T51) -> 28
...

Sheet GIRI
C2: Kecamatan | D2: GIRI
C3: Kabupaten | D3: BANYUWANGI
C4: Provinsi | D4: JAWA TIMUR
C9: Kelurahan | D9: GIRI
A12: I | B12: DATA PEMILIH DAN PENGGUNAAN HAK PILIH | V12: JUMLAH AKHIR
A13: A | B13: DATA PEMILIH | E13: TPS 001 | F13: TPS 002 | G13: TPS 003 | H13: TPS 004 | I13: TPS 005 | J13: TPS 006 | K13: TPS 007 | L13: TPS 008 | M13: TPS 009 | N13: TPS 010 | O13: TPS 011 | P13: TPS 012 | Q13: TPS 013 | R13: TPS 014 | S13: TPS 015 | T13: TPS 016 | U13: TPS 017
B14: Jumlah Pemilih dalam Daftar Pemilih Tetap (DPT) | D14: LK | E14: 140 | F14: 148 | G14: 141 | H14: 141 | I14: 140 | J14: 132 | K14: 121 | L14: 134 | M14: 142 | N14: 112 | O14: 135 | P14: 125 | Q14: 110 | R14: 128 | S14: 139 | T14: 134 | U14: 141 | V14: =SUM(E14:U14) -> 2263
D15: PR | E15: 148 | F15: 140 | G15: 148 | H15: 145 | I15: 148 | J15: 147 | K15: 124 | L15: 143 | M15: 135 | N15: 122 | O15: 151 | P15: 147 | Q15: 111 | R15: 137 | S15: 138 | T15: 135 | U15: 143 | V15: =SUM(E15:U15) -> 2362
D16: JML | E16: =SUM(E14:E15) -> 288 | F16: =SUM(F14:F15) -> 288 | G16: =SUM(G14:G15) -> 289 | H16: =SUM(H14:H15) -> 286 | I16: =SUM(I14:I15) -> 288 | J16: =SUM(J14:J15) -> 279 | K16: =SUM(K14:K15) -> 245 | L16: =SUM(L14:L15) -> 277 | ... U16: =SUM(U14:U15) -> 284 | V16: =SUM(E16:U16) -> 4625
A18: B | B18: PENGGUNA HAK PILIH
B19: 1. | C19: Jumlah pengguna hak pilih dalam Daftar Pemilih Tetap (DPT) | D19: LK | E19: 92 | F19: 99 | G19: 107 | H19: 107 | I19: 90 | J19: 96 | K19: 99 | L19: 101 | M19: 114 | N19: 76 | O19: 98 | P19: 95 | Q19: 84 | R19: 94 | S19: 110 | T19: 93 | U19: 119 | V19: =SUM(E19:U19) -> 1674
D20: PR | E20: 118 | F20: 105 | G20: 129 | H20: 117 | I20: 116 | J20: 122 | K20: 103 | L20: 128 | M20: 108 | N20: 84 | O20: 123 | P20: 122 | Q20: 91 | R20: 104 | S20: 104 | T20: 107 | U20: 124 | V20: =SUM(E20:U20) -> 1905
D21: JML | E21: =SUM(E19:E20) -> 210 | F21: =SUM(F19:F20) -> 204 | G21: =SUM(G19:G20) -> 236 | H21: =SUM(H19:H20) -> 224 | I21: =SUM(I19:I20) -> 206 | J21: =SUM(J19:J20) -> 218 | K21: =SUM(K19:K20) -> 202 | L21: =SUM(L19:L20) -> 229 | ... U21: =SUM(U19:U20) -> 243 | V21: =SUM(E21:U21) -> 3579
B22: 2. | C22: Jumlah pengguna hak pilih dalam Daftar Pemilih Tambahan (DPTb) | D22: LK | E22: 1 | F22: 2 | G22: 2 | H22: 1 | I22: 0 | J22: 0 | K22: 0 | L22: 0 | M22: 0 | N22: 1 | O22: 0 | P22: 4 | Q22: 2 | R22: 1 | S22: 0 | V22: =SUM(E22:U22) -> 14
D23: PR | E23: 0 | F23: 2 | G23: 3 | H23: 1 | I23: 0 | J23: 0 | K23: 1 | L23: 0 | M23: 0 | N23: 1 | O23: 1 | P23: 2 | Q23: 1 | R23: 3 | S23: 0 | V23: =SUM(E23:U23) -> 15
D24: JML | E24: =SUM(E22:E23) -> 1 | F24: =SUM(F22:F23) -> 4 | G24: =SUM(G22:G23) -> 5 | H24: =SUM(H22:H23) -> 2 | I24: =SUM(I22:I23) -> 0 | J24: =SUM(J22:J23) -> 0 | K24: =SUM(K22:K23) -> 1 | L24: =SUM(L22:L23) -> 0 | ... U24: =SUM(U22:U23) -> 0 | V24: =SUM(E24:U24) -> 29
B25: 3. | C25: Jumlah pengguna hak pilih dalam Daftar Pemilih Khusus (DPK) | D25: LK | E25: 0 | F25: 2 | G25: 3 | H25: 3 | I25: 0 | J25: 0 | K25: 0 | L25: 1 | M25: 0 | N25: 0 | O25: 0 | P25: 0 | Q25: 2 | R25: 3 | S25: 0 | V25: =SUM(E25:U25) -> 14
D26: PR | E26: 2 | F26: 4 | G26: 3 | H26: 3 | I26: 0 | J26: 0 | K26: 1 | L26: 0 | M26: 0 | N26: 0 | O26: 0 | P26: 3 | Q26: 2 | R26: 6 | S26: 1 | T26: 2 | U26: 1 | V26: =SUM(E26:U26) -> 28
D27: JML | E27: =SUM(E25:E26) -> 2 | F27: =SUM(F25:F26) -> 6 | G27: =SUM(G25:G26) -> 6 | H27: =SUM(H25:H26) -> 6 | I27: =SUM(I25:I26) -> 0 | J27: =SUM(J25:J26) -> 0 | K27: =SUM(K25:K26) -> 1 | L27: =SUM(L25:L26) -> 1 | ... U27: =SUM(U25:U26) -> 1 | V27: =SUM(E27:U27) -> 42
B28: 4. | C28: Jumlah Pengguna Hak Pilih (B.1+B.2+B.3) | D28: LK | E28: =SUM(E19,E22,E25) -> 93 | F28: =SUM(F19,F22,F25) -> 103 | G28: =SUM(G19,G22,G25) -> 112 | H28: =SUM(H19,H22,H25) -> 111 | I28: =SUM(I19,I22,I25) -> 90 | J28: =SUM(J19,J22,J25) -> 96 | K28: =SUM(K19,K22,K25) -> 99 | L28: =SUM(L19,L22,L25) -> 102 | ... U28: =SUM(U19,U22,U25) -> 119 | V28: =SUM(E28:U28) -> 1702
D29: PR | E29: =SUM(E20,E23,E26) -> 120 | F29: =SUM(F20,F23,F26) -> 111 | G29: =SUM(G20,G23,G26) -> 135 | H29: =SUM(H20,H23,H26) -> 121 | I29: =SUM(I20,I23,I26) -> 116 | J29: =SUM(J20,J23,J26) -> 122 | K29: =SUM(K20,K23,K26) -> 105 | L29: =SUM(L20,L23,L26) -> 128 | ... U29: =SUM(U20,U23,U26) -> 125 | V29: =SUM(E29:U29) -> 1948
D30: JML | E30: =SUM(E28:E29) -> 213 | F30: =SUM(F28:F29) -> 214 | G30: =SUM(G28:G29) -> 247 | H30: =SUM(H28:H29) -> 232 | I30: =SUM(I28:I29) -> 206 | J30: =SUM(J28:J29) -> 218 | K30: =SUM(K28:K29) -> 204 | L30: =SUM(L28:L29) -> 230 | ... U30: =SUM(U28:U29) -> 244 | V30: =SUM(E30:U30) -> 3650
A32: II | B32: DATA PENGGUNAAN SURAT SUARA
A33: 1 | B33: Jumlah surat suara yang diterima, termasuk surat suara cadangan 2,5% dari DPT | E33: 293 | F33: 293 | G33: 293 | H33: 292 | I33: 292 | J33: 285 | K33: 248 | L33: 281 | M33: 283 | N33: 239 | O33: 290 | P33: 276 | Q33: 225 | R33: 269 | S33: 281 | T33: 273 | U33: 290 | V33: =SUM(E33:U33) -> 4703
A34: 2 | B34: Jumlah surat suara yang digunakan | E34: 213 | F34: 214 | G34: 247 | H34: 232 | I34: 206 | J34: 218 | K34: 204 | L34: 230 | M34: 222 | N34: 162 | O34: 222 | P34: 226 | Q34: 182 | R34: 211 | S34: 215 | T34: 202 | U34: 244 | V34: =SUM(E34:U34) -> 3650
A35: 3 | B35: Jumlah surat suara dikembalikan oleh pemilih (karena rusak atau keliru coblos) | F35: 1 | H35: 2 | M35: 1 | N35: 1 | T35: 1 | V35: =SUM(E35:U35) -> 6
A36: 4 | B36: Jumlah surat suara yang tidak digunakan/tidak terpakai, termasuk sisa surat suara cadangan | E36: =E33-(E34+E35) -> 80 | F36: =F33-(F34+F35) -> 78 | G36: =G33-(G34+G35) -> 46 | H36: =H33-(H34+H35) -> 58 | I36: =I33-(I34+I35) -> 86 | J36: =J33-(J34+J35) -> 67 | K36: =K33-(K34+K35) -> 44 | L36: =L33-(L34+L35) -> 51 | ... U36: =U33-(U34+U35) -> 46 | V36: =SUM(E36:U36) -> 1047
A38: III | B38: DATA PEMILIH DISABILITAS
B39: Jumlah seluruh Pemilih disabilitas yang menggunakan hak pilih | D39: LK | E39: 2 | S39: 1 | V39: =SUM(E39:U39) -> 3
D40: PR | E40: 2 | J40: 1 | S40: 1 | V40: =SUM(E40:U40) -> 4
D41: JML | E41: =SUM(E39:E40) -> 4 | F41: =SUM(F39:F40) -> 0 | G41: =SUM(G39:G40) -> 0 | H41: =SUM(H39:H40) -> 0 | I41: =SUM(I39:I40) -> 0 | J41: =SUM(J39:J40) -> 1 | K41: =SUM(K39:K40) -> 0 | L41: =SUM(L39:L40) -> 0 | ... U41: =SUM(U39:U40) -> 0 | V41: =SUM(E41:U41) -> 7
A43: IV | B43: DATA RINCIAN PEROLEHAN SUARA PASANGAN CALON BUPATI DAN WAKIL BUPATI
A44: NOMOR DAN NAMA CALON
B45: 1. | C45: AA. AHMAD NAWARDI | E45: 17 | F45: 10 | G45: 8 | H45: 8 | I45: 11 | J45: 11 | K45: 20 | L45: 12 | M45: 19 | N45: 16 | O45: 11 | P45: 12 | Q45: 16 | R45: 21 | S45: 24 | T45: 20 | U45: 32 | V45: =SUM(E45:U45) -> 268
B46: 2. | C46: Ir. H. AA LA NYALLA MAHMUD MATTALITI, M.HP. | E46: 18 | F46: 36 | G46: 32 | H46: 24 | I46: 19 | J46: 35 | K46: 20 | L46: 30 | M46: 37 | N46: 20 | O46: 28 | P46: 46 | Q46: 18 | R46: 29 | S46: 39 | T46: 46 | U46: 47 | V46: =SUM(E46:U46) -> 524
B47: 3. | C47: ABDUL QADIR AMIR HARTONO, S.E., S.H., M.H. | E47: 17 | F47: 8 | G47: 12 | H47: 17 | I47: 19 | J47: 12 | K47: 10 | L47: 17 | M47: 13 | N47: 8 | O47: 14 | P47: 9 | Q47: 9 | R47: 14 | S47: 22 | T47: 21 | U47: 16 | V47: =SUM(E47:U47) -> 238
B48: 4. | C48: ADILLA AZIS, S.E. | E48: 26 | F48: 17 | G48: 19 | H48: 20 | I48: 19 | J48: 16 | K48: 16 | L48: 28 | M48: 25 | N48: 21 | O48: 25 | P48: 18 | Q48: 24 | R48: 28 | S48: 26 | T48: 24 | U48: 29 | V48: =SUM(E48:U48) -> 381
B49: 5. | C49: Ir. H. AGUS RAHARDJO, MSc.M. | E49: 32 | F49: 28 | G49: 29 | H49: 31 | I49: 24 | J49: 30 | K49: 22 | L49: 10 | M49: 25 | N49: 16 | O49: 18 | P49: 36 | Q49: 26 | R49: 12 | S49: 11 | T49: 14 | U49: 18 | V49: =SUM(E49:U49) -> 382
B50: 6. | C50: Drs. AYUB KHAN | E50: 10 | F50: 10 | G50: 18 | H50: 12 | I50: 16 | J50: 11 | K50: 15 | L50: 16 | M50: 24 | N50: 6 | O50: 6 | P50: 17 | Q50: 14 | R50: 18 | S50: 12 | T50: 8 | U50: 14 | V50: =SUM(E50:U50) -> 227
B51: 7. | C51: BAMBANG HARIANTO | E51: 4 | F51: 3 | G51: 6 | H51: 3 | I51: 1 | J51: 5 | K51: 2 | L51: 4 | M51: 5 | N51: 0 | O51: 2 | P51: 2 | Q51: 2 | R51: 1 | S51: 2 | T51: 5 | U51: 1 | V51: =SUM(E51:U51) -> 48
...

Sheet GROGOL
C2: Kecamatan | D2: GIRI
C3: Kabupaten | D3: BANYUWANGI
C4: Provinsi | D4: JAWA TIMUR
C9: Kelurahan | D9: GROGOL
A12: I | B12: DATA PEMILIH DAN PENGGUNAAN HAK PILIH | V12: JUMLAH AKHIR
A13: A | B13: DATA PEMILIH | E13: TPS 001 | F13: TPS 002 | G13: TPS 003 | H13: TPS 004 | I13: TPS 005 | J13: TPS 006 | K13: TPS 007 | L13: TPS 008 | M13: TPS 009 | N13: TPS 010 | O13: TPS 011 | P13: TPS 012 | Q13: TPS 013 | R13: TPS 014 | S13: TPS 015 | T13: TPS 016 | U13: TPS 017
B14: Jumlah Pemilih dalam Daftar Pemilih Tetap (DPT) | D14: LK | E14: 139 | F14: 128 | G14: 99 | H14: 119 | I14: 112 | J14: 141 | K14: 133 | L14: 137 | M14: 126 | N14: 121 | O14: 109 | P14: 113 | Q14: 144 | R14: 122 | S14: 93 | T14: 96 | U14: 116 | V14: =SUM(E14:U14) -> 2048
D15: PR | E15: 146 | F15: 135 | G15: 104 | H15: 131 | I15: 104 | J15: 148 | K15: 146 | L15: 151 | M15: 144 | N15: 123 | O15: 119 | P15: 114 | Q15: 132 | R15: 128 | S15: 108 | T15: 102 | U15: 103 | V15: =SUM(E15:U15) -> 2138
D16: JML | E16: =SUM(E14:E15) -> 285 | F16: =SUM(F14:F15) -> 263 | G16: =SUM(G14:G15) -> 203 | H16: =SUM(H14:H15) -> 250 | I16: =SUM(I14:I15) -> 216 | J16: =SUM(J14:J15) -> 289 | K16: =SUM(K14:K15) -> 279 | L16: =SUM(L14:L15) -> 288 | ... U16: =SUM(U14:U15) -> 219 | V16: =SUM(E16:U16) -> 4186
A18: B | B18: PENGGUNA HAK PILIH
B19: 1. | C19: Jumlah pengguna hak pilih dalam Daftar Pemilih Tetap (DPT) | D19: LK | E19: 113 | F19: 109 | G19: 76 | H19: 89 | I19: 99 | J19: 106 | K19: 94 | L19: 105 | M19: 99 | N19: 90 | O19: 88 | P19: 96 | Q19: 120 | R19: 95 | S19: 75 | T19: 80 | U19: 87 | V19: =SUM(E19:U19) -> 1621
D20: PR | E20: 117 | F20: 113 | G20: 83 | H20: 110 | I20: 96 | J20: 117 | K20: 127 | L20: 127 | M20: 122 | N20: 102 | O20: 99 | P20: 102 | Q20: 109 | R20: 109 | S20: 94 | T20: 85 | U20: 79 | V20: =SUM(E20:U20) -> 1791
D21: JML | E21: =SUM(E19:E20) -> 230 | F21: =SUM(F19:F20) -> 222 | G21: =SUM(G19:G20) -> 159 | H21: =SUM(H19:H20) -> 199 | I21: =SUM(I19:I20) -> 195 | J21: =SUM(J19:J20) -> 223 | K21: =SUM(K19:K20) -> 221 | L21: =SUM(L19:L20) -> 232 | ... U21: =SUM(U19:U20) -> 166 | V21: =SUM(E21:U21) -> 3412
B22: 2. | C22: Jumlah pengguna hak pilih dalam Daftar Pemilih Tambahan (DPTb) | D22: LK | E22: 1 | F22: 0 | G22: 0 | H22: 0 | I22: 0 | J22: 0 | K22: 0 | L22: 0 | M22: 0 | N22: 0 | O22: 0 | P22: 0 | Q22: 1 | R22: 0 | S22: 0 | V22: =SUM(E22:U22) -> 2
D23: PR | E23: 1 | F23: 0 | G23: 0 | H23: 0 | I23: 0 | J23: 0 | K23: 0 | L23: 0 | M23: 0 | N23: 0 | O23: 1 | P23: 0 | Q23: 1 | R23: 0 | S23: 0 | V23: =SUM(E23:U23) -> 3
D24: JML | E24: =SUM(E22:E23) -> 2 | F24: =SUM(F22:F23) -> 0 | G24: =SUM(G22:G23) -> 0 | H24: =SUM(H22:H23) -> 0 | I24: =SUM(I22:I23) -> 0 | J24: =SUM(J22:J23) -> 0 | K24: =SUM(K22:K23) -> 0 | L24: =SUM(L22:L23) -> 0 | ... U24: =SUM(U22:U23) -> 0 | V24: =SUM(E24:U24) -> 5
B25: 3. | C25: Jumlah pengguna hak pilih dalam Daftar Pemilih Khusus (DPK) | D25: LK | E25: 0 | F25: 0 | G25: 0 | H25: 1 | I25: 1 | J25: 0 | K25: 0 | L25: 0 | M25: 0 | N25: 0 | O25: 0 | P25: 0 | Q25: 1 | R25: 0 | S25: 0 | V25: =SUM(E25:U25) -> 3
D26: PR | E26: 1 | F26: 1 | G26: 0 | H26: 1 | I26: 1 | J26: 0 | K26: 0 | L26: 0 | M26: 1 | N26: 3 | O26: 1 | P26: 2 | Q26: 0 | R26: 0 | S26: 1 | T26: 2 | V26: =SUM(E26:U26) -> 14
D27: JML | E27: =SUM(E25:E26) -> 1 | F27: =SUM(F25:F26) -> 1 | G27: =SUM(G25:G26) -> 0 | H27: =SUM(H25:H26) -> 2 | I27: =SUM(I25:I26) -> 2 | J27: =SUM(J25:J26) -> 0 | K27: =SUM(K25:K26) -> 0 | L27: =SUM(L25:L26) -> 0 | ... U27: =SUM(U25:U26) -> 0 | V27: =SUM(E27:U27) -> 17
B28: 4. | C28: Jumlah Pengguna Hak Pilih (B.1+B.2+B.3) | D28: LK | E28: =SUM(E19,E22,E25) -> 114 | F28: =SUM(F19,F22,F25) -> 109 | G28: =SUM(G19,G22,G25) -> 76 | H28: =SUM(H19,H22,H25) -> 90 | I28: =SUM(I19,I22,I25) -> 100 | J28: =SUM(J19,J22,J25) -> 106 | K28: =SUM(K19,K22,K25) -> 94 | L28: =SUM(L19,L22,L25) -> 105 | ... U28: =SUM(U19,U22,U25) -> 87 | V28: =SUM(E28:U28) -> 1626
D29: PR | E29: =SUM(E20,E23,E26) -> 119 | F29: =SUM(F20,F23,F26) -> 114 | G29: =SUM(G20,G23,G26) -> 83 | H29: =SUM(H20,H23,H26) -> 111 | I29: =SUM(I20,I23,I26) -> 97 | J29: =SUM(J20,J23,J26) -> 117 | K29: =SUM(K20,K23,K26) -> 127 | L29: =SUM(L20,L23,L26) -> 127 | ... U29: =SUM(U20,U23,U26) -> 79 | V29: =SUM(E29:U29) -> 1808
D30: JML | E30: =SUM(E28:E29) -> 233 | F30: =SUM(F28:F29) -> 223 | G30: =SUM(G28:G29) -> 159 | H30: =SUM(H28:H29) -> 201 | I30: =SUM(I28:I29) -> 197 | J30: =SUM(J28:J29) -> 223 | K30: =SUM(K28:K29) -> 221 | L30: =SUM(L28:L29) -> 232 | ... U30: =SUM(U28:U29) -> 166 | V30: =SUM(E30:U30) -> 3434
A32: II | B32: DATA PENGGUNAAN SURAT SUARA
A33: 1 | B33: Jumlah surat suara yang diterima, termasuk surat suara cadangan 2,5% dari DPT | E33: 289 | F33: 267 | G33: 206 | H33: 253 | I33: 220 | J33: 294 | K33: 283 | L33: 292 | M33: 276 | N33: 248 | O33: 232 | P33: 232 | Q33: 280 | R33: 252 | S33: 204 | T33: 200 | U33: 222 | V33: =SUM(E33:U33) -> 4250
A34: 2 | B34: Jumlah surat suara yang digunakan | E34: 233 | F34: 223 | G34: 159 | H34: 201 | I34: 197 | J34: 223 | K34: 221 | L34: 232 | M34: 222 | N34: 195 | O34: 189 | P34: 200 | Q34: 232 | R34: 204 | S34: 170 | T34: 167 | U34: 166 | V34: =SUM(E34:U34) -> 3434
A35: 3 | B35: Jumlah surat suara dikembalikan oleh pemilih (karena rusak atau keliru coblos) | L35: 1 | V35: =SUM(E35:U35) -> 1
A36: 4 | B36: Jumlah surat suara yang tidak digunakan/tidak terpakai, termasuk sisa surat suara cadangan | E36: =E33-(E34+E35) -> 56 | F36: =F33-(F34+F35) -> 44 | G36: =G33-(G34+G35) -> 47 | H36: =H33-(H34+H35) -> 52 | I36: =I33-(I34+I35) -> 23 | J36: =J33-(J34+J35) -> 71 | K36: =K33-(K34+K35) -> 62 | L36: =L33-(L34+L35) -> 59 | ... U36: =U33-(U34+U35) -> 56 | V36: =SUM(E36:U36) -> 815
A38: III | B38: DATA PEMILIH DISABILITAS
B39: Jumlah seluruh Pemilih disabilitas yang menggunakan hak pilih | D39: LK | I39: 3 | V39: =SUM(E39:U39) -> 3
D40: PR | I40: 1 | V40: =SUM(E40:U40) -> 1
D41: JML | E41: =SUM(E39:E40) -> 0 | F41: =SUM(F39:F40) -> 0 | G41: =SUM(G39:G40) -> 0 | H41: =SUM(H39:H40) -> 0 | I41: =SUM(I39:I40) -> 4 | J41: =SUM(J39:J40) -> 0 | K41: =SUM(K39:K40) -> 0 | L41: =SUM(L39:L40) -> 0 | ... U41: =SUM(U39:U40) -> 0 | V41: =SUM(E41:U41) -> 4
A43: IV | B43: DATA RINCIAN PEROLEHAN SUARA PASANGAN CALON BUPATI DAN WAKIL BUPATI
A44: NOMOR DAN NAMA CALON
B45: 1. | C45: AA. AHMAD NAWARDI | E45: 16 | F45: 7 | G45: 19 | H45: 23 | I45: 34 | J45: 28 | K45: 43 | L45: 30 | M45: 29 | N45: 43 | O45: 31 | P45: 30 | Q45: 35 | R45: 37 | S45: 34 | T45: 35 | U45: 19 | V45: =SUM(E45:U45) -> 493
B46: 2. | C46: Ir. H. AA LA NYALLA MAHMUD MATTALITI, M.HP. | E46: 33 | F46: 32 | G46: 29 | H46: 32 | I46: 23 | J46: 41 | K46: 34 | L46: 33 | M46: 31 | N46: 30 | O46: 36 | P46: 38 | Q46: 45 | R46: 45 | S46: 55 | T46: 33 | U46: 27 | V46: =SUM(E46:U46) -> 597
B47: 3. | C47: ABDUL QADIR AMIR HARTONO, S.E., S.H., M.H. | E47: 14 | F47: 10 | G47: 3 | H47: 15 | I47: 21 | J47: 8 | K47: 13 | L47: 12 | M47: 18 | N47: 10 | O47: 13 | P47: 7 | Q47: 15 | R47: 12 | S47: 10 | T47: 12 | U47: 12 | V47: =SUM(E47:U47) -> 205
B48: 4. | C48: ADILLA AZIS, S.E. | E48: 20 | F48: 17 | G48: 23 | H48: 14 | I48: 20 | J48: 30 | K48: 26 | L48: 29 | M48: 23 | N48: 14 | O48: 18 | P48: 34 | Q48: 21 | R48: 20 | S48: 11 | T48: 18 | U48: 14 | V48: =SUM(E48:U48) -> 352
B49: 5. | C49: Ir. H. AGUS RAHARDJO, MSc.M. | E49: 25 | F49: 25 | G49: 12 | H49: 10 | I49: 13 | J49: 16 | K49: 10 | L49: 39 | M49: 14 | N49: 17 | O49: 11 | P49: 17 | Q49: 12 | R49: 6 | S49: 8 | T49: 9 | U49: 20 | V49: =SUM(E49:U49) -> 264
B50: 6. | C50: Drs. AYUB KHAN | E50: 14 | F50: 16 | G50: 11 | H50: 15 | I50: 16 | J50: 8 | K50: 13 | L50: 17 | M50: 21 | N50: 10 | O50: 21 | P50: 14 | Q50: 16 | R50: 12 | S50: 7 | T50: 7 | U50: 8 | V50: =SUM(E50:U50) -> 226
B51: 7. | C51: BAMBANG HARIANTO | E51: 1 | F51: 1 | G51: 1 | H51: 5 | I51: 1 | J51: 3 | K51: 1 | L51: 8 | M51: 3 | N51: 0 | O51: 0 | P51: 1 | Q51: 4 | R51: 2 | S51: 2 | T51: 2 | U51: 2 | V51: =SUM(E51:U51) -> 37
...

Sheet JAMBESARI
C2: Kecamatan | D2: GIRI
C3: Kabupaten | D3: BANYUWANGI
C4: Provinsi | D4: JAWA TIMUR
C9: Kelurahan | D9: JAMBESARI
A12: I | B12: DATA PEMILIH DAN PENGGUNAAN HAK PILIH | O12: JUMLAH AKHIR
A13: A | B13: DATA PEMILIH | E13: TPS 001 | F13: TPS 002 | G13: TPS 003 | H13: TPS 004 | I13: TPS 005 | J13: TPS 006 | K13: TPS 007 | L13: TPS 008 | M13: TPS 009 | N13: TPS 010
B14: Jumlah Pemilih dalam Daftar Pemilih Tetap (DPT) | D14: LK | E14: 151 | F14: 137 | G14: 145 | H14: 145 | I14: 147 | J14: 141 | K14: 124 | L14: 133 | M14: 123 | N14: 90 | O14: =SUM(E14:N14) -> 1336
D15: PR | E15: 144 | F15: 156 | G15: 151 | H15: 150 | I15: 145 | J15: 145 | K15: 136 | L15: 127 | M15: 125 | N15: 96 | O15: =SUM(E15:N15) -> 1375
D16: JML | E16: =SUM(E14:E15) -> 295 | F16: =SUM(F14:F15) -> 293 | G16: =SUM(G14:G15) -> 296 | H16: =SUM(H14:H15) -> 295 | I16: =SUM(I14:I15) -> 292 | J16: =SUM(J14:J15) -> 286 | K16: =SUM(K14:K15) -> 260 | L16: =SUM(L14:L15) -> 260 | ... N16: =SUM(N14:N15) -> 186 | O16: =SUM(E16:N16) -> 2711
A18: B | B18: PENGGUNA HAK PILIH
B19: 1. | C19: Jumlah pengguna hak pilih dalam Daftar Pemilih Tetap (DPT) | D19: LK | E19: 122 | F19: 119 | G19: 129 | H19: 118 | I19: 122 | J19: 114 | K19: 103 | L19: 114 | M19: 101 | N19: 76 | O19: =SUM(E19:N19) -> 1118
D20: PR | E20: 126 | F20: 131 | G20: 138 | H20: 134 | I20: 117 | J20: 128 | K20: 118 | L20: 115 | M20: 110 | N20: 86 | O20: =SUM(E20:N20) -> 1203
D21: JML | E21: =SUM(E19:E20) -> 248 | F21: =SUM(F19:F20) -> 250 | G21: =SUM(G19:G20) -> 267 | H21: =SUM(H19:H20) -> 252 | I21: =SUM(I19:I20) -> 239 | J21: =SUM(J19:J20) -> 242 | K21: =SUM(K19:K20) -> 221 | L21: =SUM(L19:L20) -> 229 | ... N21: =SUM(N19:N20) -> 162 | O21: =SUM(E21:N21) -> 2321
B22: 2. | C22: Jumlah pengguna hak pilih dalam Daftar Pemilih Tambahan (DPTb) | D22: LK | E22: 0 | F22: 0 | G22: 0 | H22: 0 | I22: 0 | J22: 0 | K22: 0 | L22: 1 | M22: 0 | N22: 0 | O22: =SUM(E22:N22) -> 1
D23: PR | E23: 0 | F23: 0 | G23: 0 | H23: 0 | I23: 0 | J23: 0 | K23: 0 | L23: 1 | M23: 0 | N23: 0 | O23: =SUM(E23:N23) -> 1
D24: JML | E24: =SUM(E22:E23) -> 0 | F24: =SUM(F22:F23) -> 0 | G24: =SUM(G22:G23) -> 0 | H24: =SUM(H22:H23) -> 0 | I24: =SUM(I22:I23) -> 0 | J24: =SUM(J22:J23) -> 0 | K24: =SUM(K22:K23) -> 0 | L24: =SUM(L22:L23) -> 2 | ... N24: =SUM(N22:N23) -> 0 | O24: =SUM(E24:N24) -> 2
B25: 3. | C25: Jumlah pengguna hak pilih dalam Daftar Pemilih Khusus (DPK) | D25: LK | E25: 0 | F25: 0 | G25: 1 | H25: 0 | I25: 0 | J25: 0 | K25: 0 | L25: 1 | M25: 0 | N25: 0 | O25: =SUM(E25:N25) -> 2
D26: PR | E26: 0 | F26: 2 | G26: 0 | H26: 0 | I26: 0 | J26: 1 | K26: 0 | L26: 2 | M26: 1 | N26: 0 | O26: =SUM(E26:N26) -> 6
D27: JML | E27: =SUM(E25:E26) -> 0 | F27: =SUM(F25:F26) -> 2 | G27: =SUM(G25:G26) -> 1 | H27: =SUM(H25:H26) -> 0 | I27: =SUM(I25:I26) -> 0 | J27: =SUM(J25:J26) -> 1 | K27: =SUM(K25:K26) -> 0 | L27: =SUM(L25:L26) -> 3 | ... N27: =SUM(N25:N26) -> 0 | O27: =SUM(E27:N27) -> 8
B28: 4. | C28: Jumlah Pengguna Hak Pilih (B.1+B.2+B.3) | D28: LK | E28: =SUM(E19,E22,E25) -> 122 | F28: =SUM(F19,F22,F25) -> 119 | G28: =SUM(G19,G22,G25) -> 130 | H28: =SUM(H19,H22,H25) -> 118 | I28: =SUM(I19,I22,I25) -> 122 | J28: =SUM(J19,J22,J25) -> 114 | K28: =SUM(K19,K22,K25) -> 103 | L28: =SUM(L19,L22,L25) -> 116 | ... N28: =SUM(N19,N22,N25) -> 76 | O28: =SUM(E28:N28) -> 1121
D29: PR | E29: =SUM(E20,E23,E26) -> 126 | F29: =SUM(F20,F23,F26) -> 133 | G29: =SUM(G20,G23,G26) -> 138 | H29: =SUM(H20,H23,H26) -> 134 | I29: =SUM(I20,I23,I26) -> 117 | J29: =SUM(J20,J23,J26) -> 129 | K29: =SUM(K20,K23,K26) -> 118 | L29: =SUM(L20,L23,L26) -> 118 | ... N29: =SUM(N20,N23,N26) -> 86 | O29: =SUM(E29:N29) -> 1210
D30: JML | E30: =SUM(E28:E29) -> 248 | F30: =SUM(F28:F29) -> 252 | G30: =SUM(G28:G29) -> 268 | H30: =SUM(H28:H29) -> 252 | I30: =SUM(I28:I29) -> 239 | J30: =SUM(J28:J29) -> 243 | K30: =SUM(K28:K29) -> 221 | L30: =SUM(L28:L29) -> 234 | ... N30: =SUM(N28:N29) -> 162 | O30: =SUM(E30:N30) -> 2331
A32: II | B32: DATA PENGGUNAAN SURAT SUARA
A33: 1 | B33: Jumlah surat suara yang diterima, termasuk surat suara cadangan 2,5% dari DPT | E33: 311 | F33: 299 | G33: 292 | H33: 302 | I33: 309 | J33: 295 | K33: 266 | L33: 266 | M33: 253 | N33: 190 | O33: =SUM(E33:N33) -> 2783
A34: 2 | B34: Jumlah surat suara yang digunakan | E34: 248 | F34: 252 | G34: 268 | H34: 252 | I34: 239 | J34: 243 | K34: 221 | L34: 234 | M34: 212 | N34: 162 | O34: =SUM(E34:N34) -> 2331
A35: 3 | B35: Jumlah surat suara dikembalikan oleh pemilih (karena rusak atau keliru coblos) | M35: 39 | O35: =SUM(E35:N35) -> 39
A36: 4 | B36: Jumlah surat suara yang tidak digunakan/tidak terpakai, termasuk sisa surat suara cadangan | E36: =E33-(E34+E35) -> 63 | F36: =F33-(F34+F35) -> 47 | G36: =G33-(G34+G35) -> 24 | H36: =H33-(H34+H35) -> 50 | I36: =I33-(I34+I35) -> 70 | J36: =J33-(J34+J35) -> 52 | K36: =K33-(K34+K35) -> 45 | L36: =L33-(L34+L35) -> 32 | ... N36: =N33-(N34+N35) -> 28 | O36: =SUM(E36:N36) -> 413
A38: III | B38: DATA PEMILIH DISABILITAS
B39: Jumlah seluruh Pemilih disabilitas yang menggunakan hak pilih | D39: LK | E39: 2 | F39: 1 | O39: =SUM(E39:N39) -> 3
D40: PR | I40: 1 | J40: 1 | O40: =SUM(E40:N40) -> 2
D41: JML | E41: =SUM(E39:E40) -> 2 | F41: =SUM(F39:F40) -> 1 | G41: =SUM(G39:G40) -> 0 | H41: =SUM(H39:H40) -> 0 | I41: =SUM(I39:I40) -> 1 | J41: =SUM(J39:J40) -> 1 | K41: =SUM(K39:K40) -> 0 | L41: =SUM(L39:L40) -> 0 | ... N41: =SUM(N39:N40) -> 0 | O41: =SUM(E41:N41) -> 5
A43: IV | B43: DATA RINCIAN PEROLEHAN SUARA PASANGAN CALON BUPATI DAN WAKIL BUPATI
A44: NOMOR DAN NAMA CALON
B45: 1. | C45: AA. AHMAD NAWARDI | E45: 12 | F45: 21 | G45: 35 | H45: 38 | I45: 47 | J45: 45 | K45: 30 | L45: 42 | M45: 52 | N45: 29 | O45: =SUM(E45:N45) -> 351
B46: 2. | C46: Ir. H. AA LA NYALLA MAHMUD MATTALITI, M.HP. | E46: 46 | F46: 55 | G46: 38 | H46: 38 | I46: 39 | J46: 48 | K46: 36 | L46: 33 | M46: 28 | N46: 18 | O46: =SUM(E46:N46) -> 379
B47: 3. | C47: ABDUL QADIR AMIR HARTONO, S.E., S.H., M.H. | E47: 18 | F47: 13 | G47: 15 | H47: 13 | I47: 10 | J47: 10 | K47: 10 | L47: 14 | M47: 13 | N47: 11 | O47: =SUM(E47:N47) -> 127
B48: 4. | C48: ADILLA AZIS, S.E. | E48: 19 | F48: 21 | G48: 18 | H48: 30 | I48: 20 | J48: 20 | K48: 19 | L48: 17 | M48: 22 | N48: 22 | O48: =SUM(E48:N48) -> 208
B49: 5. | C49: Ir. H. AGUS RAHARDJO, MSc.M. | E49: 13 | F49: 14 | G49: 18 | H49: 10 | I49: 14 | J49: 12 | K49: 14 | L49: 11 | M49: 8 | N49: 13 | O49: =SUM(E49:N49) -> 127
B50: 6. | C50: Drs. AYUB KHAN | E50: 21 | F50: 14 | G50: 8 | H50: 7 | I50: 11 | J50: 23 | K50: 14 | L50: 15 | M50: 8 | N50: 12 | O50: =SUM(E50:N50) -> 133
B51: 7. | C51: BAMBANG HARIANTO | E51: 3 | F51: 3 | G51: 1 | H51: 2 | I51: 3 | J51: 0 | K51: 0 | L51: 2 | M51: 2 | N51: 0 | O51: =SUM(E51:N51) -> 16
...

Sheet MOJOPANGGUNG
C2: Kecamatan | D2: GIRI
C3: Kabupaten | D3: BANYUWANGI
C4: Provinsi | D4: JAWA TIMUR
C9: Kelurahan | D9: MOJOPANGGUNG
A12: I | B12: DATA PEMILIH DAN PENGGUNAAN HAK PILIH | V12: JUMLAH AKHIR
A13: A | B13: DATA PEMILIH | E13: TPS 001 | F13: TPS 002 | G13: TPS 003 | H13: TPS 004 | I13: TPS 005 | J13: TPS 006 | K13: TPS 007 | L13: TPS 008 | M13: TPS 009 | N13: TPS 010 | O13: TPS 011 | P13: TPS 012 | Q13: TPS 013 | R13: TPS 014 | S13: TPS 015 | T13: TPS 016 | U13: TPS 017
B14: Jumlah Pemilih dalam Daftar Pemilih Tetap (DPT) | D14: LK | E14: 137 | F14: 134 | G14: 136 | H14: 139 | I14: 135 | J14: 127 | K14: 116 | L14: 120 | M14: 127 | N14: 141 | O14: 123 | P14: 119 | Q14: 129 | R14: 137 | S14: 155 | T14: 140 | U14: 135 | V14: =SUM(E14:U14) -> 2250
D15: PR | E15: 142 | F15: 134 | G15: 136 | H15: 141 | I15: 157 | J15: 150 | K15: 139 | L15: 139 | M15: 123 | N15: 133 | O15: 118 | P15: 121 | Q15: 152 | R15: 162 | S15: 140 | T15: 143 | U15: 147 | V15: =SUM(E15:U15) -> 2377
D16: JML | E16: =SUM(E14:E15) -> 279 | F16: =SUM(F14:F15) -> 268 | G16: =SUM(G14:G15) -> 272 | H16: =SUM(H14:H15) -> 280 | I16: =SUM(I14:I15) -> 292 | J16: =SUM(J14:J15) -> 277 | K16: =SUM(K14:K15) -> 255 | L16: =SUM(L14:L15) -> 259 | ... U16: =SUM(U14:U15) -> 282 | V16: =SUM(E16:U16) -> 4627
A18: B | B18: PENGGUNA HAK PILIH
B19: 1. | C19: Jumlah pengguna hak pilih dalam Daftar Pemilih Tetap (DPT) | D19: LK | E19: 95 | F19: 96 | G19: 107 | H19: 105 | I19: 93 | J19: 96 | K19: 83 | L19: 93 | M19: 98 | N19: 117 | O19: 89 | P19: 96 | Q19: 106 | R19: 97 | S19: 123 | T19: 100 | U19: 97 | V19: =SUM(E19:U19) -> 1691
D20: PR | E20: 112 | F20: 102 | G20: 109 | H20: 115 | I20: 121 | J20: 124 | K20: 109 | L20: 112 | M20: 104 | N20: 120 | O20: 91 | P20: 112 | Q20: 128 | R20: 127 | S20: 114 | T20: 117 | U20: 120 | V20: =SUM(E20:U20) -> 1937
D21: JML | E21: =SUM(E19:E20) -> 207 | F21: =SUM(F19:F20) -> 198 | G21: =SUM(G19:G20) -> 216 | H21: =SUM(H19:H20) -> 220 | I21: =SUM(I19:I20) -> 214 | J21: =SUM(J19:J20) -> 220 | K21: =SUM(K19:K20) -> 192 | L21: =SUM(L19:L20) -> 205 | ... U21: =SUM(U19:U20) -> 217 | V21: =SUM(E21:U21) -> 3628
B22: 2. | C22: Jumlah pengguna hak pilih dalam Daftar Pemilih Tambahan (DPTb) | D22: LK | E22: 0 | F22: 1 | G22: 0 | H22: 2 | I22: 1 | J22: 1 | K22: 2 | L22: 0 | M22: 0 | N22: 0 | O22: 0 | P22: 0 | Q22: 0 | R22: 1 | S22: 0 | T22: 2 | U22: 2 | V22: =SUM(E22:U22) -> 12
D23: PR | E23: 0 | F23: 1 | G23: 0 | H23: 0 | I23: 0 | J23: 0 | K23: 2 | L23: 0 | M23: 0 | N23: 0 | O23: 0 | P23: 0 | Q23: 0 | R23: 0 | S23: 0 | T23: 0 | U23: 2 | V23: =SUM(E23:U23) -> 5
D24: JML | E24: =SUM(E22:E23) -> 0 | F24: =SUM(F22:F23) -> 2 | G24: =SUM(G22:G23) -> 0 | H24: =SUM(H22:H23) -> 2 | I24: =SUM(I22:I23) -> 1 | J24: =SUM(J22:J23) -> 1 | K24: =SUM(K22:K23) -> 4 | L24: =SUM(L22:L23) -> 0 | ... U24: =SUM(U22:U23) -> 4 | V24: =SUM(E24:U24) -> 17
B25: 3. | C25: Jumlah pengguna hak pilih dalam Daftar Pemilih Khusus (DPK) | D25: LK | E25: 0 | F25: 2 | G25: 0 | H25: 0 | I25: 2 | J25: 0 | K25: 0 | L25: 0 | M25: 0 | N25: 0 | O25: 0 | P25: 1 | Q25: 0 | R25: 1 | S25: 2 | T25: 1 | U25: 2 | V25: =SUM(E25:U25) -> 11
D26: PR | E26: 0 | F26: 2 | G26: 0 | H26: 1 | I26: 3 | J26: 1 | K26: 2 | L26: 0 | M26: 1 | N26: 0 | O26: 0 | P26: 0 | Q26: 0 | R26: 0 | S26: 1 | T26: 5 | U26: 1 | V26: =SUM(E26:U26) -> 17
D27: JML | E27: =SUM(E25:E26) -> 0 | F27: =SUM(F25:F26) -> 4 | G27: =SUM(G25:G26) -> 0 | H27: =SUM(H25:H26) -> 1 | I27: =SUM(I25:I26) -> 5 | J27: =SUM(J25:J26) -> 1 | K27: =SUM(K25:K26) -> 2 | L27: =SUM(L25:L26) -> 0 | ... U27: =SUM(U25:U26) -> 3 | V27: =SUM(E27:U27) -> 28
B28: 4. | C28: Jumlah Pengguna Hak Pilih (B.1+B.2+B.3) | D28: LK | E28: =SUM(E19,E22,E25) -> 95 | F28: =SUM(F19,F22,F25) -> 99 | G28: =SUM(G19,G22,G25) -> 107 | H28: =SUM(H19,H22,H25) -> 107 | I28: =SUM(I19,I22,I25) -> 96 | J28: =SUM(J19,J22,J25) -> 97 | K28: =SUM(K19,K22,K25) -> 85 | L28: =SUM(L19,L22,L25) -> 93 | ... U28: =SUM(U19,U22,U25) -> 101 | V28: =SUM(E28:U28) -> 1714
D29: PR | E29: =SUM(E20,E23,E26) -> 112 | F29: =SUM(F20,F23,F26) -> 105 | G29: =SUM(G20,G23,G26) -> 109 | H29: =SUM(H20,H23,H26) -> 116 | I29: =SUM(I20,I23,I26) -> 124 | J29: =SUM(J20,J23,J26) -> 125 | K29: =SUM(K20,K23,K26) -> 113 | L29: =SUM(L20,L23,L26) -> 112 | ... U29: =SUM(U20,U23,U26) -> 123 | V29: =SUM(E29:U29) -> 1959
D30: JML | E30: =SUM(E28:E29) -> 207 | F30: =SUM(F28:F29) -> 204 | G30: =SUM(G28:G29) -> 216 | H30: =SUM(H28:H29) -> 223 | I30: =SUM(I28:I29) -> 220 | J30: =SUM(J28:J29) -> 222 | K30: =SUM(K28:K29) -> 198 | L30: =SUM(L28:L29) -> 205 | ... U30: =SUM(U28:U29) -> 224 | V30: =SUM(E30:U30) -> 3673
A32: II | B32: DATA PENGGUNAAN SURAT SUARA
A33: 1 | B33: Jumlah surat suara yang diterima, termasuk surat suara cadangan 2,5% dari DPT | E33: 283 | F33: 272 | G33: 276 | H33: 284 | I33: 292 | J33: 288 | K33: 269 | L33: 265 | M33: 255 | N33: 279 | O33: 244 | P33: 244 | Q33: 285 | R33: 304 | S33: 300 | T33: 289 | U33: 286 | V33: =SUM(E33:U33) -> 4715
A34: 2 | B34: Jumlah surat suara yang digunakan | E34: 207 | F34: 204 | G34: 216 | H34: 223 | I34: 220 | J34: 222 | K34: 198 | L34: 205 | M34: 203 | N34: 237 | O34: 180 | P34: 209 | Q34: 234 | R34: 226 | S34: 240 | T34: 225 | U34: 224 | V34: =SUM(E34:U34) -> 3673
A35: 3 | B35: Jumlah surat suara dikembalikan oleh pemilih (karena rusak atau keliru coblos) | S35: 1 | V35: =SUM(E35:U35) -> 1
A36: 4 | B36: Jumlah surat suara yang tidak digunakan/tidak terpakai, termasuk sisa surat suara cadangan | E36: =E33-(E34+E35) -> 76 | F36: =F33-(F34+F35) -> 68 | G36: =G33-(G34+G35) -> 60 | H36: =H33-(H34+H35) -> 61 | I36: =I33-(I34+I35) -> 72 | J36: =J33-(J34+J35) -> 66 | K36: =K33-(K34+K35) -> 71 | L36: =L33-(L34+L35) -> 60 | ... U36: =U33-(U34+U35) -> 62 | V36: =SUM(E36:U36) -> 1041
A38: III | B38: DATA PEMILIH DISABILITAS
B39: Jumlah seluruh Pemilih disabilitas yang menggunakan hak pilih | D39: LK | G39: 1 | H39: 1 | I39: 1 | L39: 1 | N39: 1 | O39: 4 | R39: 1 | U39: 1 | V39: =SUM(E39:U39) -> 11
D40: PR | L40: 5 | N40: 1 | O40: 3 | V40: =SUM(E40:U40) -> 9
D41: JML | E41: =SUM(E39:E40) -> 0 | F41: =SUM(F39:F40) -> 0 | G41: =SUM(G39:G40) -> 1 | H41: =SUM(H39:H40) -> 1 | I41: =SUM(I39:I40) -> 1 | J41: =SUM(J39:J40) -> 0 | K41: =SUM(K39:K40) -> 0 | L41: =SUM(L39:L40) -> 6 | ... U41: =SUM(U39:U40) -> 1 | V41: =SUM(E41:U41) -> 20
A43: IV | B43: DATA RINCIAN PEROLEHAN SUARA PASANGAN CALON BUPATI DAN WAKIL BUPATI
A44: NOMOR DAN NAMA CALON
B45: 1. | C45: AA. AHMAD NAWARDI | E45: 11 | F45: 6 | G45: 12 | H45: 8 | I45: 12 | J45: 9 | K45: 13 | L45: 12 | M45: 12 | N45: 13 | O45: 11 | P45: 16 | Q45: 17 | R45: 9 | S45: 8 | T45: 7 | U45: 7 | V45: =SUM(E45:U45) -> 183
B46: 2. | C46: Ir. H. AA LA NYALLA MAHMUD MATTALITI, M.HP. | E46: 26 | F46: 38 | G46: 24 | H46: 38 | I46: 16 | J46: 29 | K46: 32 | L46: 23 | M46: 32 | N46: 36 | O46: 20 | P46: 29 | Q46: 43 | R46: 43 | S46: 45 | T46: 33 | U46: 31 | V46: =SUM(E46:U46) -> 538
B47: 3. | C47: ABDUL QADIR AMIR HARTONO, S.E., S.H., M.H. | E47: 13 | F47: 13 | G47: 16 | H47: 10 | I47: 10 | J47: 21 | K47: 19 | L47: 12 | M47: 8 | N47: 16 | O47: 21 | P47: 11 | Q47: 20 | R47: 13 | S47: 21 | T47: 9 | U47: 13 | V47: =SUM(E47:U47) -> 246
B48: 4. | C48: ADILLA AZIS, S.E. | E48: 11 | F48: 15 | G48: 19 | H48: 22 | I48: 11 | J48: 19 | K48: 15 | L48: 19 | M48: 20 | N48: 16 | O48: 19 | P48: 16 | Q48: 24 | R48: 25 | S48: 14 | T48: 13 | U48: 12 | V48: =SUM(E48:U48) -> 290
B49: 5. | C49: Ir. H. AGUS RAHARDJO, MSc.M. | E49: 24 | F49: 27 | G49: 25 | H49: 25 | I49: 33 | J49: 35 | K49: 24 | L49: 28 | M49: 18 | N49: 34 | O49: 13 | P49: 25 | Q49: 22 | R49: 39 | S49: 27 | T49: 29 | U49: 21 | V49: =SUM(E49:U49) -> 449
B50: 6. | C50: Drs. AYUB KHAN | E50: 12 | F50: 8 | G50: 4 | H50: 11 | I50: 11 | J50: 12 | K50: 5 | L50: 8 | M50: 22 | N50: 9 | O50: 10 | P50: 11 | Q50: 6 | R50: 11 | S50: 14 | T50: 13 | U50: 13 | V50: =SUM(E50:U50) -> 180
B51: 7. | C51: BAMBANG HARIANTO | E51: 4 | F51: 1 | G51: 4 | H51: 4 | I51: 1 | J51: 3 | K51: 2 | L51: 3 | M51: 0 | N51: 3 | O51: 2 | P51: 0 | Q51: 2 | R51: 3 | S51: 1 | T51: 2 | U51: 10 | V51: =SUM(E51:U51) -> 45
...

Sheet PENATABAN
C2: Kecamatan | D2: GIRI
C3: Kabupaten | D3: BANYUWANGI
C4: Provinsi | D4: JAWA TIMUR
C9: Kelurahan | D9: PENATABAN
A12: I | B12: DATA PEMILIH DAN PENGGUNAAN HAK PILIH | V12: JUMLAH AKHIR
A13: A | B13: DATA PEMILIH | E13: TPS 001 | F13: TPS 002 | G13: TPS 003 | H13: TPS 004 | I13: TPS 005 | J13: TPS 006 | K13: TPS 007 | L13: TPS 008 | M13: TPS 009 | N13: TPS 010 | O13: TPS 011 | P13: TPS 012 | Q13: TPS 013 | R13: TPS 901 | S13: TPS 902 | T13: TPS 903 | U13: TPS 904
B14: Jumlah Pemilih dalam Daftar Pemilih Tetap (DPT) | D14: LK | E14: 142 | F14: 145 | G14: 140 | H14: 144 | I14: 144 | J14: 147 | K14: 145 | L14: 159 | M14: 142 | N14: 129 | O14: 143 | P14: 115 | Q14: 77 | R14: 249 | S14: 252 | T14: 235 | U14: 189 | V14: =SUM(E14:U14) -> 2697
D15: PR | E15: 147 | F15: 150 | G15: 151 | H15: 141 | I15: 147 | J15: 138 | K15: 140 | L15: 134 | M15: 131 | N15: 137 | O15: 154 | P15: 134 | Q15: 97 | R15: 9 | S15: 7 | T15: 14 | U15: 8 | V15: =SUM(E15:U15) -> 1839
D16: JML | E16: =SUM(E14:E15) -> 289 | F16: =SUM(F14:F15) -> 295 | G16: =SUM(G14:G15) -> 291 | H16: =SUM(H14:H15) -> 285 | I16: =SUM(I14:I15) -> 291 | J16: =SUM(J14:J15) -> 285 | K16: =SUM(K14:K15) -> 285 | L16: =SUM(L14:L15) -> 293 | ... U16: =SUM(U14:U15) -> 197 | V16: =SUM(E16:U16) -> 4536
A18: B | B18: PENGGUNA HAK PILIH
B19: 1. | C19: Jumlah pengguna hak pilih dalam Daftar Pemilih Tetap (DPT) | D19: LK | E19: 114 | F19: 114 | G19: 108 | H19: 107 | I19: 111 | J19: 111 | K19: 124 | L19: 116 | M19: 122 | N19: 107 | O19: 117 | P19: 92 | Q19: 63 | R19: 151 | S19: 174 | T19: 126 | U19: 107 | V19: =SUM(E19:U19) -> 1964
D20: PR | E20: 124 | F20: 114 | G20: 128 | H20: 115 | I20: 125 | J20: 116 | K20: 123 | L20: 110 | M20: 121 | N20: 115 | O20: 126 | P20: 102 | Q20: 85 | R20: 6 | S20: 6 | T20: 5 | U20: 8 | V20: =SUM(E20:U20) -> 1529
D21: JML | E21: =SUM(E19:E20) -> 238 | F21: =SUM(F19:F20) -> 228 | G21: =SUM(G19:G20) -> 236 | H21: =SUM(H19:H20) -> 222 | I21: =SUM(I19:I20) -> 236 | J21: =SUM(J19:J20) -> 227 | K21: =SUM(K19:K20) -> 247 | L21: =SUM(L19:L20) -> 226 | ... U21: =SUM(U19:U20) -> 115 | V21: =SUM(E21:U21) -> 3493
B22: 2. | C22: Jumlah pengguna hak pilih dalam Daftar Pemilih Tambahan (DPTb) | D22: LK | E22: 0 | F22: 3 | G22: 0 | H22: 0 | I22: 0 | J22: 0 | K22: 1 | L22: 0 | M22: 0 | N22: 0 | O22: 0 | P22: 4 | Q22: 1 | R22: 88 | S22: 78 | T22: 86 | U22: 47 | V22: =SUM(E22:U22) -> 308
D23: PR | E23: 1 | F23: 1 | G23: 1 | H23: 0 | I23: 0 | J23: 2 | K23: 0 | L23: 0 | M23: 0 | N23: 0 | O23: 0 | P23: 5 | Q23: 1 | R23: 2 | S23: 2 | T23: 9 | U23: 6 | V23: =SUM(E23:U23) -> 30
D24: JML | E24: =SUM(E22:E23) -> 1 | F24: =SUM(F22:F23) -> 4 | G24: =SUM(G22:G23) -> 1 | H24: =SUM(H22:H23) -> 0 | I24: =SUM(I22:I23) -> 0 | J24: =SUM(J22:J23) -> 2 | K24: =SUM(K22:K23) -> 1 | L24: =SUM(L22:L23) -> 0 | ... U24: =SUM(U22:U23) -> 53 | V24: =SUM(E24:U24) -> 338
B25: 3. | C25: Jumlah pengguna hak pilih dalam Daftar Pemilih Khusus (DPK) | D25: LK | E25: 0 | F25: 1 | G25: 2 | H25: 1 | I25: 0 | J25: 3 | K25: 2 | L25: 3 | M25: 1 | N25: 0 | O25: 0 | P25: 0 | Q25: 0 | R25: 0 | S25: 0 | V25: =SUM(E25:U25) -> 13
D26: PR | E26: 0 | F26: 0 | G26: 4 | H26: 1 | I26: 2 | J26: 1 | K26: 1 | L26: 3 | M26: 1 | N26: 0 | O26: 3 | P26: 3 | Q26: 1 | R26: 0 | S26: 0 | V26: =SUM(E26:U26) -> 20
D27: JML | E27: =SUM(E25:E26) -> 0 | F27: =SUM(F25:F26) -> 1 | G27: =SUM(G25:G26) -> 6 | H27: =SUM(H25:H26) -> 2 | I27: =SUM(I25:I26) -> 2 | J27: =SUM(J25:J26) -> 4 | K27: =SUM(K25:K26) -> 3 | L27: =SUM(L25:L26) -> 6 | ... U27: =SUM(U25:U26) -> 0 | V27: =SUM(E27:U27) -> 33
B28: 4. | C28: Jumlah Pengguna Hak Pilih (B.1+B.2+B.3) | D28: LK | E28: =SUM(E19,E22,E25) -> 114 | F28: =SUM(F19,F22,F25) -> 118 | G28: =SUM(G19,G22,G25) -> 110 | H28: =SUM(H19,H22,H25) -> 108 | I28: =SUM(I19,I22,I25) -> 111 | J28: =SUM(J19,J22,J25) -> 114 | K28: =SUM(K19,K22,K25) -> 127 | L28: =SUM(L19,L22,L25) -> 119 | ... U28: =SUM(U19,U22,U25) -> 154 | V28: =SUM(E28:U28) -> 2285
D29: PR | E29: =SUM(E20,E23,E26) -> 125 | F29: =SUM(F20,F23,F26) -> 115 | G29: =SUM(G20,G23,G26) -> 133 | H29: =SUM(H20,H23,H26) -> 116 | I29: =SUM(I20,I23,I26) -> 127 | J29: =SUM(J20,J23,J26) -> 119 | K29: =SUM(K20,K23,K26) -> 124 | L29: =SUM(L20,L23,L26) -> 113 | ... U29: =SUM(U20,U23,U26) -> 14 | V29: =SUM(E29:U29) -> 1579
D30: JML | E30: =SUM(E28:E29) -> 239 | F30: =SUM(F28:F29) -> 233 | G30: =SUM(G28:G29) -> 243 | H30: =SUM(H28:H29) -> 224 | I30: =SUM(I28:I29) -> 238 | J30: =SUM(J28:J29) -> 233 | K30: =SUM(K28:K29) -> 251 | L30: =SUM(L28:L29) -> 232 | ... U30: =SUM(U28:U29) -> 168 | V30: =SUM(E30:U30) -> 3864
A32: II | B32: DATA PENGGUNAAN SURAT SUARA
A33: 1 | B33: Jumlah surat suara yang diterima, termasuk surat suara cadangan 2,5% dari DPT | E33: 294 | F33: 301 | G33: 296 | H33: 289 | I33: 295 | J33: 289 | K33: 290 | L33: 297 | M33: 279 | N33: 270 | O33: 301 | P33: 252 | Q33: 179 | R33: 264 | S33: 266 | T33: 254 | U33: 201 | V33: =SUM(E33:U33) -> 4617
A34: 2 | B34: Jumlah surat suara yang digunakan | E34: 239 | F34: 233 | G34: 243 | H34: 224 | I34: 238 | J34: 233 | K34: 251 | L34: 232 | M34: 245 | N34: 222 | O34: 246 | P34: 206 | Q34: 151 | R34: 247 | S34: 260 | T34: 226 | U34: 168 | V34: =SUM(E34:U34) -> 3864
A35: 3 | B35: Jumlah surat suara dikembalikan oleh pemilih (karena rusak atau keliru coblos) | V35: =SUM(E35:U35) -> 0
A36: 4 | B36: Jumlah surat suara yang tidak digunakan/tidak terpakai, termasuk sisa surat suara cadangan | E36: =E33-(E34+E35) -> 55 | F36: =F33-(F34+F35) -> 68 | G36: =G33-(G34+G35) -> 53 | H36: =H33-(H34+H35) -> 65 | I36: =I33-(I34+I35) -> 57 | J36: =J33-(J34+J35) -> 56 | K36: =K33-(K34+K35) -> 39 | L36: =L33-(L34+L35) -> 65 | ... U36: =U33-(U34+U35) -> 33 | V36: =SUM(E36:U36) -> 753
A38: III | B38: DATA PEMILIH DISABILITAS
B39: Jumlah seluruh Pemilih disabilitas yang menggunakan hak pilih | D39: LK | P39: 2 | S39: 2 | V39: =SUM(E39:U39) -> 4
D40: PR | P40: 3 | V40: =SUM(E40:U40) -> 3
D41: JML | E41: =SUM(E39:E40) -> 0 | F41: =SUM(F39:F40) -> 0 | G41: =SUM(G39:G40) -> 0 | H41: =SUM(H39:H40) -> 0 | I41: =SUM(I39:I40) -> 0 | J41: =SUM(J39:J40) -> 0 | K41: =SUM(K39:K40) -> 0 | L41: =SUM(L39:L40) -> 0 | ... U41: =SUM(U39:U40) -> 0 | V41: =SUM(E41:U41) -> 7
A43: IV | B43: DATA RINCIAN PEROLEHAN SUARA PASANGAN CALON BUPATI DAN WAKIL BUPATI
A44: NOMOR DAN NAMA CALON
B45: 1. | C45: AA. AHMAD NAWARDI | E45: 21 | F45: 19 | G45: 16 | H45: 21 | I45: 23 | J45: 18 | K45: 18 | L45: 19 | M45: 31 | N45: 18 | O45: 14 | P45: 11 | Q45: 6 | R45: 6 | S45: 4 | T45: 8 | U45: 17 | V45: =SUM(E45:U45) -> 270
B46: 2. | C46: Ir. H. AA LA NYALLA MAHMUD MATTALITI, M.HP. | E46: 35 | F46: 29 | G46: 31 | H46: 36 | I46: 39 | J46: 47 | K46: 27 | L46: 50 | M46: 40 | N46: 25 | O46: 42 | P46: 27 | Q46: 21 | R46: 56 | S46: 55 | T46: 43 | U46: 36 | V46: =SUM(E46:U46) -> 639
B47: 3. | C47: ABDUL QADIR AMIR HARTONO, S.E., S.H., M.H. | E47: 6 | F47: 11 | G47: 10 | H47: 12 | I47: 16 | J47: 8 | K47: 26 | L47: 12 | M47: 19 | N47: 16 | O47: 13 | P47: 15 | Q47: 6 | R47: 15 | S47: 20 | T47: 19 | U47: 9 | V47: =SUM(E47:U47) -> 233
B48: 4. | C48: ADILLA AZIS, S.E. | E48: 29 | F48: 28 | G48: 16 | H48: 23 | I48: 16 | J48: 32 | K48: 16 | L48: 23 | M48: 23 | N48: 11 | O48: 10 | P48: 13 | Q48: 12 | R48: 13 | S48: 11 | T48: 9 | U48: 9 | V48: =SUM(E48:U48) -> 294
B49: 5. | C49: Ir. H. AGUS RAHARDJO, MSc.M. | E49: 25 | F49: 25 | G49: 21 | H49: 22 | I49: 30 | J49: 18 | K49: 17 | L49: 30 | M49: 14 | N49: 30 | O49: 33 | P49: 26 | Q49: 28 | R49: 20 | S49: 21 | T49: 17 | U49: 14 | V49: =SUM(E49:U49) -> 391
B50: 6. | C50: Drs. AYUB KHAN | E50: 13 | F50: 18 | G50: 19 | H50: 13 | I50: 17 | J50: 18 | K50: 26 | L50: 17 | M50: 17 | N50: 17 | O50: 18 | P50: 6 | Q50: 13 | R50: 9 | S50: 6 | T50: 12 | U50: 4 | V50: =SUM(E50:U50) -> 243
B51: 7. | C51: BAMBANG HARIANTO | E51: 1 | F51: 3 | G51: 3 | H51: 0 | I51: 3 | J51: 0 | K51: 2 | L51: 0 | M51: 2 | N51: 4 | O51: 4 | P51: 4 | Q51: 3 | R51: 3 | S51: 2 | T51: 3 | U51: 4 | V51: =SUM(E51:U51) -> 41
...
