Workbook

Sheet DPD
C8: Kecamatan | D8: BANGOREJO
C9: Kabupaten | D9: BANYUWANGI
C10: Provinsi | D10: JAWA TIMUR
A12: I | B12: DATA PEMILIH DAN PENGGUNAAN HAK PILIH | E12: JUMLAH AKHIR
A13: A | B13: DATA PEMILIH
B14: Jumlah Pemilih dalam Daftar Pemilih Tetap (DPT) | D14: LK | E14: =PAKIS!T14+SOBO!AB14+KEBALENAN!AH14+PENGANJURAN!T14+TUKANGKAYU!AD14+KERTOSARI!AB14+KARANGREJO!AI14+KEPATIHAN!S14+PANDEREJO!R14+SINGONEGARAN!U14+TEMENGGUNGAN!L14+KAMPUNGMELAYU!M14+KAMPUNGMANDAR!P14+LATENG!AD14+SINGOTRUNAN!AE14+PENGANTIGAN!X14+TAMANBARU!Z14+SUMBERREJO!U14 -> 43114
D15: PR | E15: =PAKIS!T15+SOBO!AB15+KEBALENAN!AH15+PENGANJURAN!T15+TUKANGKAYU!AD15+KERTOSARI!AB15+KARANGREJO!AI15+KEPATIHAN!S15+PANDEREJO!R15+SINGONEGARAN!U15+TEMENGGUNGAN!L15+KAMPUNGMELAYU!M15+KAMPUNGMANDAR!P15+LATENG!AD15+SINGOTRUNAN!AE15+PENGANTIGAN!X15+TAMANBARU!Z15+SUMBERREJO!U15 -> 45912
D16: JML | E16: =SUM(E14:E15) -> 89026
A18: B | B18: PENGGUNA HAK PILIH
B19: 1. | C19: Jumlah pengguna hak pilih dalam Daftar Pemilih Tetap (DPT) | D19: LK | E19: =PAKIS!T19+SOBO!AB19+KEBALENAN!AH19+PENGANJURAN!T19+TUKANGKAYU!AD19+KERTOSARI!AB19+KARANGREJO!AI19+KEPATIHAN!S19+PANDEREJO!R19+SINGONEGARAN!U19+TEMENGGUNGAN!L19+KAMPUNGMELAYU!M19+KAMPUNGMANDAR!P19+LATENG!AD19+SINGOTRUNAN!AE19+PENGANTIGAN!X19+TAMANBARU!Z19+SUMBERREJO!U19 -> 31081
D20: PR | E20: =PAKIS!T20+SOBO!AB20+KEBALENAN!AH20+PENGANJURAN!T20+TUKANGKAYU!AD20+KERTOSARI!AB20+KARANGREJO!AI20+KEPATIHAN!S20+PANDEREJO!R20+SINGONEGARAN!U20+TEMENGGUNGAN!L20+KAMPUNGMELAYU!M20+KAMPUNGMANDAR!P20+LATENG!AD20+SINGOTRUNAN!AE20+PENGANTIGAN!X20+TAMANBARU!Z20+SUMBERREJO!U20 -> 36200
D21: JML | E21: =SUM(E19:E20) -> 67281
B22: 2. | C22: Jumlah pengguna hak pilih dalam Daftar Pemilih Tambahan (DPTb) | D22: LK | E22: =PAKIS!T22+SOBO!AB22+KEBALENAN!AH22+PENGANJURAN!T22+TUKANGKAYU!AD22+KERTOSARI!AB22+KARANGREJO!AI22+KEPATIHAN!S22+PANDEREJO!R22+SINGONEGARAN!U22+TEMENGGUNGAN!L22+KAMPUNGMELAYU!M22+KAMPUNGMANDAR!P22+LATENG!AD22+SINGOTRUNAN!AE22+PENGANTIGAN!X22+TAMANBARU!Z22+SUMBERREJO!U22 -> 154
D23: PR | E23: =PAKIS!T23+SOBO!AB23+KEBALENAN!AH23+PENGANJURAN!T23+TUKANGKAYU!AD23+KERTOSARI!AB23+KARANGREJO!AI23+KEPATIHAN!S23+PANDEREJO!R23+SINGONEGARAN!U23+TEMENGGUNGAN!L23+KAMPUNGMELAYU!M23+KAMPUNGMANDAR!P23+LATENG!AD23+SINGOTRUNAN!AE23+PENGANTIGAN!X23+TAMANBARU!Z23+SUMBERREJO!U23 -> 146
D24: JML | E24: =SUM(E22:E23) -> 300
B25: 3. | C25: Jumlah pengguna hak pilih dalam Daftar Pemilih Khusus (DPK) | D25: LK | E25: =PAKIS!T25+SOBO!AB25+KEBALENAN!AH25+PENGANJURAN!T25+TUKANGKAYU!AD25+KERTOSARI!AB25+KARANGREJO!AI25+KEPATIHAN!S25+PANDEREJO!R25+SINGONEGARAN!U25+TEMENGGUNGAN!L25+KAMPUNGMELAYU!M25+KAMPUNGMANDAR!P25+LATENG!AD25+SINGOTRUNAN!AE25+PENGANTIGAN!X25+TAMANBARU!Z25+SUMBERREJO!U25 -> 533
D26: PR | E26: =PAKIS!T26+SOBO!AB26+KEBALENAN!AH26+PENGANJURAN!T26+TUKANGKAYU!AD26+KERTOSARI!AB26+KARANGREJO!AI26+KEPATIHAN!S26+PANDEREJO!R26+SINGONEGARAN!U26+TEMENGGUNGAN!L26+KAMPUNGMELAYU!M26+KAMPUNGMANDAR!P26+LATENG!AD26+SINGOTRUNAN!AE26+PENGANTIGAN!X26+TAMANBARU!Z26+SUMBERREJO!U26 -> 703
D27: JML | E27: =SUM(E25:E26) -> 1236
B28: 4. | C28: Jumlah Pengguna Hak Pilih (B.1+B.2+B.3) | D28: LK | E28: =E19+E22+E25 -> 31768
D29: PR | E29: =E20+E23+E26 -> 37049
D30: JML | E30: =SUM(E28:E29) -> 68817
A32: II | B32: DATA PENGGUNAAN SURAT SUARA
A33: 1 | B33: Jumlah surat suara yang diterima, termasuk surat suara cadangan 2,5% dari DPT | E33: =PAKIS!T33+SOBO!AB33+KEBALENAN!AH33+PENGANJURAN!T33+TUKANGKAYU!AD33+KERTOSARI!AB33+KARANGREJO!AI33+KEPATIHAN!S33+PANDEREJO!R33+SINGONEGARAN!U33+TEMENGGUNGAN!L33+KAMPUNGMELAYU!M33+KAMPUNGMANDAR!P33+LATENG!AD33+SINGOTRUNAN!AE33+PENGANTIGAN!X33+TAMANBARU!Z33+SUMBERREJO!U33 -> 91208
A34: 2 | B34: Jumlah surat suara yang digunakan | E34: =PAKIS!T34+SOBO!AB34+KEBALENAN!AH34+PENGANJURAN!T34+TUKANGKAYU!AD34+KERTOSARI!AB34+KARANGREJO!AI34+KEPATIHAN!S34+PANDEREJO!R34+SINGONEGARAN!U34+TEMENGGUNGAN!L34+KAMPUNGMELAYU!M34+KAMPUNGMANDAR!P34+LATENG!AD34+SINGOTRUNAN!AE34+PENGANTIGAN!X34+TAMANBARU!Z34+SUMBERREJO!U34 -> 68817
A35: 3 | B35: Jumlah surat suara dikembalikan oleh pemilih (karena rusak atau keliru coblos) | E35: =PAKIS!T35+SOBO!AB35+KEBALENAN!AH35+PENGANJURAN!T35+TUKANGKAYU!AD35+KERTOSARI!AB35+KARANGREJO!AI35+KEPATIHAN!S35+PANDEREJO!R35+SINGONEGARAN!U35+TEMENGGUNGAN!L35+KAMPUNGMELAYU!M35+KAMPUNGMANDAR!P35+LATENG!AD35+SINGOTRUNAN!AE35+PENGANTIGAN!X35+TAMANBARU!Z35+SUMBERREJO!U35 -> 135
A36: 4 | B36: Jumlah surat suara yang tidak digunakan/tidak terpakai, termasuk sisa surat suara cadangan | E36: =E33-(E34+E35) -> 22256
A38: III | B38: DATA PEMILIH DISABILITAS
B39: Jumlah seluruh Pemilih disabilitas yang menggunakan hak pilih | D39: LK | E39: =PAKIS!T39+SOBO!AB39+KEBALENAN!AH39+PENGANJURAN!T39+TUKANGKAYU!AD39+KERTOSARI!AB39+KARANGREJO!AI39+KEPATIHAN!S39+PANDEREJO!R39+SINGONEGARAN!U39+TEMENGGUNGAN!L39+KAMPUNGMELAYU!M39+KAMPUNGMANDAR!P39+LATENG!AD39+SINGOTRUNAN!AE39+PENGANTIGAN!X39+TAMANBARU!Z39+SUMBERREJO!U39 -> 88
D40: PR | E40: =PAKIS!T40+SOBO!AB40+KEBALENAN!AH40+PENGANJURAN!T40+TUKANGKAYU!AD40+KERTOSARI!AB40+KARANGREJO!AI40+KEPATIHAN!S40+PANDEREJO!R40+SINGONEGARAN!U40+TEMENGGUNGAN!L40+KAMPUNGMELAYU!M40+KAMPUNGMANDAR!P40+LATENG!AD40+SINGOTRUNAN!AE40+PENGANTIGAN!X40+TAMANBARU!Z40+SUMBERREJO!U40 -> 77
D41: JML | E41: =SUM(E39:E40) -> 165
A43: IV | B43: DATA RINCIAN PEROLEHAN SUARA PASANGAN CALON BUPATI DAN WAKIL BUPATI
A44: NOMOR DAN NAMA CALON
A45: A.2 | B45: 1. | C45: AA. AHMAD NAWARDI | E45: =PAKIS!T45+SOBO!AB45+KEBALENAN!AH45+PENGANJURAN!T45+TUKANGKAYU!AD45+KERTOSARI!AB45+KARANGREJO!AI45+KEPATIHAN!S45+PANDEREJO!R45+SINGONEGARAN!U45+TEMENGGUNGAN!L45+KAMPUNGMELAYU!M45+KAMPUNGMANDAR!P45+LATENG!AD45+SINGOTRUNAN!AE45+PENGANTIGAN!X45+TAMANBARU!Z45+SUMBERREJO!U45 -> 4038
B46: 2. | C46: Ir. H. AA LA NYALLA MAHMUD MATTALITI, M.HP. | E46: =PAKIS!T46+SOBO!AB46+KEBALENAN!AH46+PENGANJURAN!T46+TUKANGKAYU!AD46+KERTOSARI!AB46+KARANGREJO!AI46+KEPATIHAN!S46+PANDEREJO!R46+SINGONEGARAN!U46+TEMENGGUNGAN!L46+KAMPUNGMELAYU!M46+KAMPUNGMANDAR!P46+LATENG!AD46+SINGOTRUNAN!AE46+PENGANTIGAN!X46+TAMANBARU!Z46+SUMBERREJO!U46 -> 9710
B47: 3. | C47: ABDUL QADIR AMIR HARTONO, S.E., S.H., M.H. | E47: =PAKIS!T47+SOBO!AB47+KEBALENAN!AH47+PENGANJURAN!T47+TUKANGKAYU!AD47+KERTOSARI!AB47+KARANGREJO!AI47+KEPATIHAN!S47+PANDEREJO!R47+SINGONEGARAN!U47+TEMENGGUNGAN!L47+KAMPUNGMELAYU!M47+KAMPUNGMANDAR!P47+LATENG!AD47+SINGOTRUNAN!AE47+PENGANTIGAN!X47+TAMANBARU!Z47+SUMBERREJO!U47 -> 3966
B48: 4. | C48: ADILLA AZIS, S.E. | E48: =PAKIS!T48+SOBO!AB48+KEBALENAN!AH48+PENGANJURAN!T48+TUKANGKAYU!AD48+KERTOSARI!AB48+KARANGREJO!AI48+KEPATIHAN!S48+PANDEREJO!R48+SINGONEGARAN!U48+TEMENGGUNGAN!L48+KAMPUNGMELAYU!M48+KAMPUNGMANDAR!P48+LATENG!AD48+SINGOTRUNAN!AE48+PENGANTIGAN!X48+TAMANBARU!Z48+SUMBERREJO!U48 -> 6802
B49: 5. | C49: Ir. H. AGUS RAHARDJO, MSc.M. | E49: =PAKIS!T49+SOBO!AB49+KEBALENAN!AH49+PENGANJURAN!T49+TUKANGKAYU!AD49+KERTOSARI!AB49+KARANGREJO!AI49+KEPATIHAN!S49+PANDEREJO!R49+SINGONEGARAN!U49+TEMENGGUNGAN!L49+KAMPUNGMELAYU!M49+KAMPUNGMANDAR!P49+LATENG!AD49+SINGOTRUNAN!AE49+PENGANTIGAN!X49+TAMANBARU!Z49+SUMBERREJO!U49 -> 8277
B50: 6. | C50: Drs. AYUB KHAN | E50: =PAKIS!T50+SOBO!AB50+KEBALENAN!AH50+PENGANJURAN!T50+TUKANGKAYU!AD50+KERTOSARI!AB50+KARANGREJO!AI50+KEPATIHAN!S50+PANDEREJO!R50+SINGONEGARAN!U50+TEMENGGUNGAN!L50+KAMPUNGMELAYU!M50+KAMPUNGMANDAR!P50+LATENG!AD50+SINGOTRUNAN!AE50+PENGANTIGAN!X50+TAMANBARU!Z50+SUMBERREJO!U50 -> 3882
B51: 7. | C51: BAMBANG HARIANTO | E51: =PAKIS!T51+SOBO!AB51+KEBALENAN!AH51+PENGANJURAN!T51+TUKANGKAYU!AD51+KERTOSARI!AB51+KARANGREJO!AI51+KEPATIHAN!S51+PANDEREJO!R51+SINGONEGARAN!U51+TEMENGGUNGAN!L51+KAMPUNGMELAYU!M51+KAMPUNGMANDAR!P51+LATENG!AD51+SINGOTRUNAN!AE51+PENGANTIGAN!X51+TAMANBARU!Z51+SUMBERREJO!U51 -> 777
B52: 8. | C52: CATUR RUDI UTANTO, S.Sos. | E52: =PAKIS!T52+SOBO!AB52+KEBALENAN!AH52+PENGANJURAN!T52+TUKANGKAYU!AD52+KERTOSARI!AB52+KARANGREJO!AI52+KEPATIHAN!S52+PANDEREJO!R52+SINGONEGARAN!U52+TEMENGGUNGAN!L52+KAMPUNGMELAYU!M52+KAMPUNGMANDAR!P52+LATENG!AD52+SINGOTRUNAN!AE52+PENGANTIGAN!X52+TAMANBARU!Z52+SUMBERREJO!U52 -> 1339
...

Sheet PAKIS
C2: Kecamatan | D2: BANYUWANGI
C3: Kabupaten | D3: BANYUWANGI
C4: Provinsi | D4: JAWA TIMUR
C9: Kelurahan | D9: PAKIS
A12: I | B12: DATA PEMILIH DAN PENGGUNAAN HAK PILIH | T12: JUMLAH AKHIR
A13: A | B13: DATA PEMILIH | E13: TPS 001 | F13: TPS 002 | G13: TPS 003 | H13: TPS 004 | I13: TPS 005 | J13: TPS 006 | K13: TPS 007 | L13: TPS 008 | M13: TPS 009 | N13: TPS 010 | O13: TPS 011 | P13: TPS 012 | Q13: TPS 013 | R13: TPS 014 | S13: TPS 015
B14: Jumlah Pemilih dalam Daftar Pemilih Tetap (DPT) | D14: LK | E14: 129 | F14: 123 | G14: 107 | H14: 122 | I14: 121 | J14: 131 | K14: 124 | L14: 137 | M14: 122 | N14: 115 | O14: 134 | P14: 127 | Q14: 116 | R14: 131 | S14: 125 | T14: =SUM(E14:S14) -> 1864
D15: PR | E15: 134 | F15: 135 | G15: 138 | H15: 132 | I15: 137 | J15: 128 | K15: 129 | L15: 125 | M15: 128 | N15: 130 | O15: 119 | P15: 127 | Q15: 133 | R15: 124 | S15: 129 | T15: =SUM(E15:S15) -> 1948
D16: JML | E16: =SUM(E14:E15) -> 263 | F16: =SUM(F14:F15) -> 258 | G16: =SUM(G14:G15) -> 245 | H16: =SUM(H14:H15) -> 254 | I16: =SUM(I14:I15) -> 258 | J16: =SUM(J14:J15) -> 259 | K16: =SUM(K14:K15) -> 253 | L16: =SUM(L14:L15) -> 262 | ... S16: =SUM(S14:S15) -> 254 | T16: =SUM(E16:S16) -> 3812
A18: B | B18: PENGGUNA HAK PILIH
B19: 1. | C19: Jumlah pengguna hak pilih dalam Daftar Pemilih Tetap (DPT) | D19: LK | E19: 98 | F19: 96 | G19: 85 | H19: 95 | I19: 87 | J19: 101 | K19: 92 | L19: 109 | M19: 97 | N19: 88 | O19: 93 | P19: 80 | Q19: 83 | R19: 105 | S19: 92 | T19: =SUM(E19:S19) -> 1401
D20: PR | E20: 106 | F20: 108 | G20: 105 | H20: 104 | I20: 115 | J20: 101 | K20: 116 | L20: 109 | M20: 115 | N20: 113 | O20: 97 | P20: 96 | Q20: 106 | R20: 111 | S20: 101 | T20: =SUM(E20:S20) -> 1603
D21: JML | E21: =SUM(E19:E20) -> 204 | F21: =SUM(F19:F20) -> 204 | G21: =SUM(G19:G20) -> 190 | H21: =SUM(H19:H20) -> 199 | I21: =SUM(I19:I20) -> 202 | J21: =SUM(J19:J20) -> 202 | K21: =SUM(K19:K20) -> 208 | L21: =SUM(L19:L20) -> 218 | ... S21: =SUM(S19:S20) -> 193 | T21: =SUM(E21:S21) -> 3004
B22: 2. | C22: Jumlah pengguna hak pilih dalam Daftar Pemilih Tambahan (DPTb) | D22: LK | E22: 1 | F22: 0 | G22: 2 | H22: 0 | I22: 2 | J22: 0 | K22: 0 | L22: 0 | M22: 0 | N22: 0 | O22: 0 | P22: 0 | Q22: 0 | R22: 0 | S22: 2 | T22: =SUM(E22:S22) -> 7
D23: PR | E23: 1 | F23: 0 | G23: 2 | H23: 0 | I23: 0 | J23: 0 | K23: 0 | L23: 0 | M23: 3 | N23: 1 | O23: 0 | P23: 0 | Q23: 0 | R23: 0 | S23: 3 | T23: =SUM(E23:S23) -> 10
D24: JML | E24: =SUM(E22:E23) -> 2 | F24: =SUM(F22:F23) -> 0 | G24: =SUM(G22:G23) -> 4 | H24: =SUM(H22:H23) -> 0 | I24: =SUM(I22:I23) -> 2 | J24: =SUM(J22:J23) -> 0 | K24: =SUM(K22:K23) -> 0 | L24: =SUM(L22:L23) -> 0 | ... S24: =SUM(S22:S23) -> 5 | T24: =SUM(E24:S24) -> 17
B25: 3. | C25: Jumlah pengguna hak pilih dalam Daftar Pemilih Khusus (DPK) | D25: LK | E25: 2 | F25: 0 | G25: 2 | H25: 2 | I25: 0 | J25: 0 | K25: 3 | L25: 2 | M25: 2 | N25: 0 | O25: 2 | P25: 3 | Q25: 2 | R25: 0 | S25: 1 | T25: =SUM(E25:S25) -> 21
D26: PR | E26: 2 | F26: 0 | G26: 0 | H26: 2 | I26: 5 | J26: 1 | K26: 1 | L26: 0 | M26: 1 | N26: 0 | O26: 7 | P26: 3 | Q26: 0 | R26: 0 | S26: 1 | T26: =SUM(E26:S26) -> 23
D27: JML | E27: =SUM(E25:E26) -> 4 | F27: =SUM(F25:F26) -> 0 | G27: =SUM(G25:G26) -> 2 | H27: =SUM(H25:H26) -> 4 | I27: =SUM(I25:I26) -> 5 | J27: =SUM(J25:J26) -> 1 | K27: =SUM(K25:K26) -> 4 | L27: =SUM(L25:L26) -> 2 | ... S27: =SUM(S25:S26) -> 2 | T27: =SUM(E27:S27) -> 44
B28: 4. | C28: Jumlah Pengguna Hak Pilih (B.1+B.2+B.3) | D28: LK | E28: =SUM(E19,E22,E25) -> 101 | F28: =SUM(F19,F22,F25) -> 96 | G28: =SUM(G19,G22,G25) -> 89 | H28: =SUM(H19,H22,H25) -> 97 | I28: =SUM(I19,I22,I25) -> 89 | J28: =SUM(J19,J22,J25) -> 101 | K28: =SUM(K19,K22,K25) -> 95 | L28: =SUM(L19,L22,L25) -> 111 | ... S28: =SUM(S19,S22,S25) -> 95 | T28: =SUM(E28:S28) -> 1429
D29: PR | E29: =SUM(E20,E23,E26) -> 109 | F29: =SUM(F20,F23,F26) -> 108 | G29: =SUM(G20,G23,G26) -> 107 | H29: =SUM(H20,H23,H26) -> 106 | I29: =SUM(I20,I23,I26) -> 120 | J29: =SUM(J20,J23,J26) -> 102 | K29: =SUM(K20,K23,K26) -> 117 | L29: =SUM(L20,L23,L26) -> 109 | ... S29: =SUM(S20,S23,S26) -> 105 | T29: =SUM(E29:S29) -> 1636
D30: JML | E30: =SUM(E28:E29) -> 210 | F30: =SUM(F28:F29) -> 204 | G30: =SUM(G28:G29) -> 196 | H30: =SUM(H28:H29) -> 203 | I30: =SUM(I28:I29) -> 209 | J30: =SUM(J28:J29) -> 203 | K30: =SUM(K28:K29) -> 212 | L30: =SUM(L28:L29) -> 220 | ... S30: =SUM(S28:S29) -> 200 | T30: =SUM(E30:S30) -> 3065
A32: II | B32: DATA PENGGUNAAN SURAT SUARA
A33: 1 | B33: Jumlah surat suara yang diterima, termasuk surat suara cadangan 2% dari DPT | E33: 269 | F33: 263 | G33: 250 | H33: 260 | I33: 263 | J33: 265 | K33: 259 | L33: 268 | M33: 255 | N33: 250 | O33: 257 | P33: 260 | Q33: 244 | R33: 259 | S33: 260 | T33: =SUM(E33:S33) -> 3882
A34: 2 | B34: Jumlah surat suara yang digunakan | E34: 210 | F34: 204 | G34: 196 | H34: 203 | I34: 209 | J34: 203 | K34: 212 | L34: 220 | M34: 218 | N34: 202 | O34: 199 | P34: 182 | Q34: 191 | R34: 216 | S34: 200 | T34: =SUM(E34:S34) -> 3065
A35: 3 | B35: Jumlah surat suara dikembalikan oleh pemilih (karena rusak atau keliru coblos) | E35: 0 | F35: 0 | G35: 0 | H35: 0 | I35: 0 | J35: 1 | K35: 1 | L35: 0 | M35: 0 | N35: 0 | O35: 1 | P35: 0 | Q35: 0 | R35: 1 | S35: 0 | T35: =SUM(E35:S35) -> 4
A36: 4 | B36: Jumlah surat suara yang tidak digunakan/tidak terpakai, termasuk sisa surat suara cadangan | E36: =E33-(E34+E35) -> 59 | F36: =F33-(F34+F35) -> 59 | G36: =G33-(G34+G35) -> 54 | H36: =H33-(H34+H35) -> 57 | I36: =I33-(I34+I35) -> 54 | J36: =J33-(J34+J35) -> 61 | K36: =K33-(K34+K35) -> 46 | L36: =L33-(L34+L35) -> 48 | ... S36: =S33-(S34+S35) -> 60 | T36: =SUM(E36:S36) -> 813
A38: III | B38: DATA PEMILIH DISABILITAS
B39: Jumlah seluruh Pemilih disabilitas yang menggunakan hak pilih | D39: LK | E39: 2 | G39: 1 | S39: 4 | T39: =SUM(E39:S39) -> 7
D40: PR | G40: 3 | S40: 3 | T40: =SUM(E40:S40) -> 6
D41: JML | E41: =SUM(E39:E40) -> 2 | F41: =SUM(F39:F40) -> 0 | G41: =SUM(G39:G40) -> 4 | H41: =SUM(H39:H40) -> 0 | I41: =SUM(I39:I40) -> 0 | J41: =SUM(J39:J40) -> 0 | K41: =SUM(K39:K40) -> 0 | L41: =SUM(L39:L40) -> 0 | ... S41: =SUM(S39:S40) -> 7 | T41: =SUM(E41:S41) -> 13
A43: IV | B43: DATA RINCIAN PEROLEHAN SUARA PASANGAN CALON BUPATI DAN WAKIL BUPATI
A44: NOMOR DAN NAMA CALON
B45: 1. | C45: AA. AHMAD NAWARDI | E45: 17 | F45: 13 | G45: 13 | H45: 20 | I45: 19 | J45: 18 | K45: 20 | L45: 20 | M45: 22 | N45: 26 | O45: 20 | P45: 23 | Q45: 26 | R45: 12 | S45: 23 | T45: =SUM(E45:S45) -> 292
B46: 2. | C46: Ir. H. AA LA NYALLA MAHMUD MATTALITI, M.HP. | E46: 30 | F46: 34 | G46: 26 | H46: 21 | I46: 40 | J46: 41 | K46: 34 | L46: 34 | M46: 42 | N46: 33 | O46: 29 | P46: 31 | Q46: 28 | R46: 35 | S46: 22 | T46: =SUM(E46:S46) -> 480
B47: 3. | C47: ABDUL QADIR AMIR HARTONO, S.E., S.H., M.H. | E47: 15 | F47: 8 | G47: 7 | H47: 10 | I47: 7 | J47: 13 | K47: 17 | L47: 27 | M47: 12 | N47: 13 | O47: 20 | P47: 13 | Q47: 17 | R47: 12 | S47: 13 | T47: =SUM(E47:S47) -> 204
B48: 4. | C48: ADILLA AZIS, S.E. | E48: 23 | F48: 23 | G48: 26 | H48: 21 | I48: 20 | J48: 14 | K48: 13 | L48: 19 | M48: 17 | N48: 7 | O48: 18 | P48: 11 | Q48: 15 | R48: 33 | S48: 18 | T48: =SUM(E48:S48) -> 278
B49: 5. | C49: Ir. H. AGUS RAHARDJO, MSc.M. | E49: 29 | F49: 21 | G49: 22 | H49: 22 | I49: 29 | J49: 18 | K49: 43 | L49: 35 | M49: 42 | N49: 38 | O49: 34 | P49: 18 | Q49: 19 | R49: 14 | S49: 15 | T49: =SUM(E49:S49) -> 399
B50: 6. | C50: Drs. AYUB KHAN | E50: 11 | F50: 9 | G50: 16 | H50: 19 | I50: 8 | J50: 4 | K50: 11 | L50: 10 | M50: 12 | N50: 12 | O50: 17 | P50: 6 | Q50: 16 | R50: 15 | S50: 8 | T50: =SUM(E50:S50) -> 174
B51: 7. | C51: BAMBANG HARIANTO | E51: 0 | F51: 1 | G51: 0 | H51: 2 | I51: 4 | J51: 1 | K51: 3 | L51: 1 | M51: 2 | N51: 0 | O51: 2 | P51: 7 | Q51: 0 | R51: 0 | S51: 1 | T51: =SUM(E51:S51) -> 24
...

Sheet SOBO
C2: Kecamatan | D2: BANYUWANGI
C3: Kabupaten | D3: BANYUWANGI
C4: Provinsi | D4: JAWA TIMUR
C9: Kelurahan | D9: SOBO
A12: I | B12: DATA PEMILIH DAN PENGGUNAAN HAK PILIH | AB12: JUMLAH AKHIR
A13: A | B13: DATA PEMILIH | E13: TPS 001 | F13: TPS 002 | G13: TPS 003 | H13: TPS 004 | I13: TPS 005 | J13: TPS 006 | K13: TPS 007 | L13: TPS 008 | M13: TPS 009 | N13: TPS 010 | O13: TPS 011 | P13: TPS 012 | Q13: TPS 013 | R13: TPS 014 | S13: TPS 015 | T13: TPS 016 | U13: TPS 017 | V13: TPS 018 | W13: TPS 019 | X13: TPS 020 | Y13: TPS 021 | Z13: TPS 022 | AA13: TPS 023
B14: Jumlah Pemilih dalam Daftar Pemilih Tetap (DPT) | D14: LK | E14: 144 | F14: 127 | G14: 126 | H14: 136 | I14: 127 | J14: 137 | K14: 143 | L14: 135 | M14: 139 | N14: 141 | O14: 125 | P14: 134 | Q14: 148 | R14: 127 | S14: 138 | T14: 131 | U14: 123 | V14: 132 | W14: 142 | X14: 140 | Y14: 142 | Z14: 142 | AA14: 131 | AB14: =SUM(E14:AA14) -> 3110
D15: PR | E15: 146 | F15: 159 | G15: 162 | H15: 147 | I15: 147 | J15: 145 | K15: 142 | L15: 146 | M15: 156 | N15: 149 | O15: 162 | P15: 164 | Q15: 142 | R15: 147 | S15: 156 | T15: 147 | U15: 155 | V15: 149 | W15: 147 | X15: 147 | Y15: 144 | Z15: 152 | AA15: 152 | AB15: =SUM(E15:AA15) -> 3463
D16: JML | E16: =SUM(E14:E15) -> 290 | F16: =SUM(F14:F15) -> 286 | G16: =SUM(G14:G15) -> 288 | H16: =SUM(H14:H15) -> 283 | I16: =SUM(I14:I15) -> 274 | J16: =SUM(J14:J15) -> 282 | K16: =SUM(K14:K15) -> 285 | L16: =SUM(L14:L15) -> 281 | ... AA16: =SUM(AA14:AA15) -> 283 | AB16: =SUM(E16:AA16) -> 6573
A18: B | B18: PENGGUNA HAK PILIH
B19: 1. | C19: Jumlah pengguna hak pilih dalam Daftar Pemilih Tetap (DPT) | D19: LK | E19: 102 | F19: 93 | G19: 89 | H19: 85 | I19: 87 | J19: 102 | K19: 109 | L19: 108 | M19: 97 | N19: 100 | O19: 90 | P19: 104 | Q19: 116 | R19: 95 | S19: 95 | T19: 84 | U19: 99 | V19: 91 | W19: 104 | X19: 101 | Y19: 91 | Z19: 95 | AA19: 87 | AB19: =SUM(E19:AA19) -> 2224
D20: PR | E20: 104 | F20: 132 | G20: 117 | H20: 104 | I20: 100 | J20: 117 | K20: 105 | L20: 121 | M20: 129 | N20: 118 | O20: 129 | P20: 119 | Q20: 110 | R20: 115 | S20: 123 | T20: 112 | U20: 129 | V20: 120 | W20: 128 | X20: 122 | Y20: 107 | Z20: 123 | AA20: 124 | AB20: =SUM(E20:AA20) -> 2708
D21: JML | E21: =SUM(E19:E20) -> 206 | F21: =SUM(F19:F20) -> 225 | G21: =SUM(G19:G20) -> 206 | H21: =SUM(H19:H20) -> 189 | I21: =SUM(I19:I20) -> 187 | J21: =SUM(J19:J20) -> 219 | K21: =SUM(K19:K20) -> 214 | L21: =SUM(L19:L20) -> 229 | ... AA21: =SUM(AA19:AA20) -> 211 | AB21: =SUM(E21:AA21) -> 4932
B22: 2. | C22: Jumlah pengguna hak pilih dalam Daftar Pemilih Tambahan (DPTb) | D22: LK | E22: 2 | F22: 1 | G22: 0 | H22: 1 | I22: 4 | J22: 0 | K22: 0 | L22: 1 | M22: 0 | N22: 0 | O22: 3 | P22: 0 | Q22: 1 | R22: 0 | S22: 0 | T22: 0 | U22: 0 | V22: 0 | W22: 0 | X22: 0 | Y22: 2 | Z22: 0 | AA22: 0 | AB22: =SUM(E22:AA22) -> 15
D23: PR | E23: 2 | F23: 0 | G23: 0 | H23: 0 | I23: 2 | J23: 0 | K23: 0 | L23: 2 | M23: 0 | N23: 0 | O23: 2 | P23: 0 | Q23: 1 | R23: 0 | S23: 1 | T23: 0 | U23: 0 | V23: 0 | W23: 0 | X23: 0 | Y23: 2 | Z23: 0 | AA23: 0 | AB23: =SUM(E23:AA23) -> 12
D24: JML | E24: =SUM(E22:E23) -> 4 | F24: =SUM(F22:F23) -> 1 | G24: =SUM(G22:G23) -> 0 | H24: =SUM(H22:H23) -> 1 | I24: =SUM(I22:I23) -> 6 | J24: =SUM(J22:J23) -> 0 | K24: =SUM(K22:K23) -> 0 | L24: =SUM(L22:L23) -> 3 | ... AA24: =SUM(AA22:AA23) -> 0 | AB24: =SUM(E24:AA24) -> 27
B25: 3. | C25: Jumlah pengguna hak pilih dalam Daftar Pemilih Khusus (DPK) | D25: LK | E25: 0 | F25: 0 | G25: 0 | H25: 0 | I25: 0 | J25: 1 | K25: 1 | L25: 0 | M25: 0 | N25: 3 | O25: 0 | P25: 2 | Q25: 5 | R25: 1 | S25: 1 | T25: 2 | U25: 0 | V25: 3 | W25: 1 | X25: 1 | Y25: 2 | Z25: 1 | AA25: 2 | AB25: =SUM(E25:AA25) -> 26
D26: PR | E26: 1 | F26: 3 | G26: 0 | H26: 1 | I26: 1 | J26: 2 | K26: 3 | L26: 0 | M26: 0 | N26: 4 | O26: 1 | P26: 2 | Q26: 9 | R26: 0 | S26: 5 | T26: 3 | U26: 1 | V26: 3 | W26: 0 | X26: 0 | Y26: 2 | Z26: 0 | AA26: 0 | AB26: =SUM(E26:AA26) -> 41
D27: JML | E27: =SUM(E25:E26) -> 1 | F27: =SUM(F25:F26) -> 3 | G27: =SUM(G25:G26) -> 0 | H27: =SUM(H25:H26) -> 1 | I27: =SUM(I25:I26) -> 1 | J27: =SUM(J25:J26) -> 3 | K27: =SUM(K25:K26) -> 4 | L27: =SUM(L25:L26) -> 0 | ... AA27: =SUM(AA25:AA26) -> 2 | AB27: =SUM(E27:AA27) -> 67
B28: 4. | C28: Jumlah Pengguna Hak Pilih (B.1+B.2+B.3) | D28: LK | E28: =SUM(E19,E22,E25) -> 104 | F28: =SUM(F19,F22,F25) -> 94 | G28: =SUM(G19,G22,G25) -> 89 | H28: =SUM(H19,H22,H25) -> 86 | I28: =SUM(I19,I22,I25) -> 91 | J28: =SUM(J19,J22,J25) -> 103 | K28: =SUM(K19,K22,K25) -> 110 | L28: =SUM(L19,L22,L25) -> 109 | ... AA28: =SUM(AA19,AA22,AA25) -> 89 | AB28: =SUM(E28:AA28) -> 2265
D29: PR | E29: =SUM(E20,E23,E26) -> 107 | F29: =SUM(F20,F23,F26) -> 135 | G29: =SUM(G20,G23,G26) -> 117 | H29: =SUM(H20,H23,H26) -> 105 | I29: =SUM(I20,I23,I26) -> 103 | J29: =SUM(J20,J23,J26) -> 119 | K29: =SUM(K20,K23,K26) -> 108 | L29: =SUM(L20,L23,L26) -> 123 | ... AA29: =SUM(AA20,AA23,AA26) -> 124 | AB29: =SUM(E29:AA29) -> 2761
D30: JML | E30: =SUM(E28:E29) -> 211 | F30: =SUM(F28:F29) -> 229 | G30: =SUM(G28:G29) -> 206 | H30: =SUM(H28:H29) -> 191 | I30: =SUM(I28:I29) -> 194 | J30: =SUM(J28:J29) -> 222 | K30: =SUM(K28:K29) -> 218 | L30: =SUM(L28:L29) -> 232 | ... AA30: =SUM(AA28:AA29) -> 213 | AB30: =SUM(E30:AA30) -> 5026
A32: II | B32: DATA PENGGUNAAN SURAT SUARA
A33: 1 | B33: Jumlah surat suara yang diterima, termasuk surat suara cadangan 2% dari DPT | E33: 296 | F33: 295 | G33: 294 | H33: 289 | I33: 280 | J33: 286 | K33: 291 | L33: 287 | M33: 300 | N33: 296 | O33: 293 | P33: 304 | Q33: 296 | R33: 280 | S33: 300 | T33: 284 | U33: 284 | V33: 287 | W33: 293 | X33: 293 | Y33: 292 | Z33: 320 | AA33: 279 | AB33: =SUM(E33:AA33) -> 6719
A34: 2 | B34: Jumlah surat suara yang digunakan | E34: 211 | F34: 229 | G34: 206 | H34: 191 | I34: 194 | J34: 222 | K34: 218 | L34: 232 | M34: 226 | N34: 225 | O34: 225 | P34: 227 | Q34: 242 | R34: 211 | S34: 225 | T34: 201 | U34: 229 | V34: 217 | W34: 233 | X34: 224 | Y34: 206 | Z34: 219 | AA34: 213 | AB34: =SUM(E34:AA34) -> 5026
A35: 3 | B35: Jumlah surat suara dikembalikan oleh pemilih (karena rusak atau keliru coblos) | E35: 0 | F35: 0 | G35: 0 | H35: 0 | I35: 0 | J35: 0 | K35: 0 | L35: 0 | M35: 0 | N35: 0 | O35: 0 | P35: 0 | Q35: 0 | R35: 0 | S35: 2 | T35: 0 | U35: 0 | V35: 0 | W35: 0 | X35: 1 | Y35: 0 | Z35: 0 | AA35: 0 | AB35: =SUM(E35:AA35) -> 3
A36: 4 | B36: Jumlah surat suara yang tidak digunakan/tidak terpakai, termasuk sisa surat suara cadangan | E36: =E33-(E34+E35) -> 85 | F36: =F33-(F34+F35) -> 66 | G36: =G33-(G34+G35) -> 88 | H36: =H33-(H34+H35) -> 98 | I36: =I33-(I34+I35) -> 86 | J36: =J33-(J34+J35) -> 64 | K36: =K33-(K34+K35) -> 73 | L36: =L33-(L34+L35) -> 55 | ... AA36: =AA33-(AA34+AA35) -> 66 | AB36: =SUM(E36:AA36) -> 1690
A38: III | B38: DATA PEMILIH DISABILITAS
B39: Jumlah seluruh Pemilih disabilitas yang menggunakan hak pilih | D39: LK | E39: 2 | W39: 1 | AB39: =SUM(E39:AA39) -> 3
D40: PR | E40: 1 | Z40: 1 | AB40: =SUM(E40:AA40) -> 2
D41: JML | E41: =SUM(E39:E40) -> 3 | F41: =SUM(F39:F40) -> 0 | G41: =SUM(G39:G40) -> 0 | H41: =SUM(H39:H40) -> 0 | I41: =SUM(I39:I40) -> 0 | J41: =SUM(J39:J40) -> 0 | K41: =SUM(K39:K40) -> 0 | L41: =SUM(L39:L40) -> 0 | ... AA41: =SUM(AA39:AA40) -> 0 | AB41: =SUM(E41:AA41) -> 5
A43: IV | B43: DATA RINCIAN PEROLEHAN SUARA PASANGAN CALON BUPATI DAN WAKIL BUPATI
A44: NOMOR DAN NAMA CALON
B45: 1. | C45: AA. AHMAD NAWARDI | E45: 12 | F45: 12 | G45: 11 | H45: 17 | I45: 7 | J45: 31 | K45: 22 | L45: 6 | M45: 16 | N45: 18 | O45: 11 | P45: 16 | Q45: 14 | R45: 9 | S45: 6 | T45: 10 | U45: 11 | V45: 17 | W45: 6 | X45: 18 | Y45: 17 | Z45: 15 | AA45: 11 | AB45: =SUM(E45:AA45) -> 313
B46: 2. | C46: Ir. H. AA LA NYALLA MAHMUD MATTALITI, M.HP. | E46: 31 | F46: 30 | G46: 26 | H46: 41 | I46: 21 | J46: 30 | K46: 32 | L46: 23 | M46: 30 | N46: 34 | O46: 33 | P46: 25 | Q46: 36 | R46: 26 | S46: 31 | T46: 28 | U46: 35 | V46: 33 | W46: 29 | X46: 34 | Y46: 37 | Z46: 32 | AA46: 39 | AB46: =SUM(E46:AA46) -> 716
B47: 3. | C47: ABDUL QADIR AMIR HARTONO, S.E., S.H., M.H. | E47: 11 | F47: 13 | G47: 13 | H47: 14 | I47: 21 | J47: 15 | K47: 13 | L47: 4 | M47: 15 | N47: 14 | O47: 11 | P47: 12 | Q47: 14 | R47: 15 | S47: 10 | T47: 10 | U47: 17 | V47: 12 | W47: 20 | X47: 11 | Y47: 14 | Z47: 13 | AA47: 7 | AB47: =SUM(E47:AA47) -> 299
B48: 4. | C48: ADILLA AZIS, S.E. | E48: 20 | F48: 25 | G48: 19 | H48: 19 | I48: 20 | J48: 11 | K48: 14 | L48: 15 | M48: 26 | N48: 14 | O48: 20 | P48: 18 | Q48: 18 | R48: 15 | S48: 26 | T48: 23 | U48: 23 | V48: 15 | W48: 25 | X48: 15 | Y48: 13 | Z48: 28 | AA48: 23 | AB48: =SUM(E48:AA48) -> 445
B49: 5. | C49: Ir. H. AGUS RAHARDJO, MSc.M. | E49: 31 | F49: 33 | G49: 33 | H49: 19 | I49: 26 | J49: 19 | K49: 33 | L49: 14 | M49: 15 | N49: 21 | O49: 27 | P49: 20 | Q49: 18 | R49: 35 | S49: 42 | T49: 20 | U49: 19 | V49: 18 | W49: 32 | X49: 29 | Y49: 17 | Z49: 23 | AA49: 26 | AB49: =SUM(E49:AA49) -> 570
B50: 6. | C50: Drs. AYUB KHAN | E50: 14 | F50: 17 | G50: 11 | H50: 15 | I50: 8 | J50: 14 | K50: 8 | L50: 5 | M50: 21 | N50: 16 | O50: 5 | P50: 14 | Q50: 12 | R50: 10 | S50: 15 | T50: 10 | U50: 22 | V50: 11 | W50: 16 | X50: 11 | Y50: 9 | Z50: 13 | AA50: 11 | AB50: =SUM(E50:AA50) -> 288
B51: 7. | C51: BAMBANG HARIANTO | E51: 5 | F51: 1 | G51: 3 | H51: 1 | I51: 2 | J51: 2 | K51: 1 | L51: 1 | M51: 1 | N51: 2 | O51: 5 | P51: 7 | Q51: 1 | R51: 4 | S51: 4 | T51: 1 | U51: 1 | V51: 3 | W51: 4 | X51: 2 | Y51: 1 | Z51: 4 | AA51: 2 | AB51: =SUM(E51:AA51) -> 58
...

Sheet KEBALENAN
C2: Kecamatan | D2: BANYUWANGI
C3: Kabupaten | D3: BANYUWANGI
C4: Provinsi | D4: JAWA TIMUR
C9: Kelurahan | D9: KEBALENAN
A12: I | B12: DATA PEMILIH DAN PENGGUNAAN HAK PILIH | AH12: JUMLAH AKHIR
A13: A | B13: DATA PEMILIH | E13: TPS 001 | F13: TPS 002 | G13: TPS 003 | H13: TPS 004 | I13: TPS 005 | J13: TPS 006 | K13: TPS 007 | L13: TPS 008 | M13: TPS 009 | N13: TPS 010 | O13: TPS 011 | P13: TPS 012 | Q13: TPS 013 | R13: TPS 014 | S13: TPS 015 | T13: TPS 016 | U13: TPS 017 | V13: TPS 018 | W13: TPS 019 | X13: TPS 020 | Y13: TPS 021 | Z13: TPS 022 | AA13: TPS 023 | AB13: TPS 024 | AC13: TPS 025 | AD13: TPS 026 | AE13: TPS 027 | AF13: TPS 028 | AG13: TPS 029
B14: Jumlah Pemilih dalam Daftar Pemilih Tetap (DPT) | D14: LK | E14: 135 | F14: 150 | G14: 140 | H14: 130 | I14: 145 | J14: 139 | K14: 138 | L14: 138 | M14: 146 | N14: 141 | O14: 134 | P14: 136 | Q14: 135 | R14: 127 | S14: 124 | T14: 127 | U14: 138 | V14: 147 | W14: 129 | X14: 120 | Y14: 130 | Z14: 135 | AA14: 136 | AB14: 125 | AC14: 136 | AD14: 135 | AE14: 82 | AF14: 74 | AG14: 148 | AH14: =SUM(E14:AG14) -> 3820
D15: PR | E15: 155 | F15: 142 | G15: 154 | H15: 159 | I15: 146 | J15: 140 | K15: 149 | L15: 154 | M15: 144 | N15: 155 | O15: 162 | P15: 143 | Q15: 129 | R15: 147 | S15: 144 | T15: 143 | U15: 153 | V15: 146 | W15: 146 | X15: 150 | Y15: 153 | Z15: 149 | AA15: 154 | AB15: 152 | AC15: 160 | AD15: 148 | AE15: 96 | AF15: 83 | AG15: 150 | AH15: =SUM(E15:AG15) -> 4206
D16: JML | E16: =SUM(E14:E15) -> 290 | F16: =SUM(F14:F15) -> 292 | G16: =SUM(G14:G15) -> 294 | H16: =SUM(H14:H15) -> 289 | I16: =SUM(I14:I15) -> 291 | J16: =SUM(J14:J15) -> 279 | K16: =SUM(K14:K15) -> 287 | L16: =SUM(L14:L15) -> 292 | ... AG16: =SUM(AG14:AG15) -> 298 | AH16: =SUM(E16:AG16) -> 8026
A18: B | B18: PENGGUNA HAK PILIH
B19: 1. | C19: Jumlah pengguna hak pilih dalam Daftar Pemilih Tetap (DPT) | D19: LK | E19: 94 | F19: 111 | G19: 95 | H19: 95 | I19: 112 | J19: 109 | K19: 103 | L19: 99 | M19: 113 | N19: 91 | O19: 101 | P19: 92 | Q19: 97 | R19: 92 | S19: 89 | T19: 92 | U19: 96 | V19: 118 | W19: 100 | X19: 88 | Y19: 93 | Z19: 94 | AA19: 101 | AB19: 87 | AC19: 102 | AD19: 96 | AE19: 56 | AF19: 53 | AG19: 123 | AH19: =SUM(E19:AG19) -> 2792
D20: PR | E20: 121 | F20: 112 | G20: 112 | H20: 127 | I20: 127 | J20: 104 | K20: 116 | L20: 126 | M20: 120 | N20: 111 | O20: 122 | P20: 116 | Q20: 112 | R20: 111 | S20: 117 | T20: 107 | U20: 124 | V20: 128 | W20: 120 | X20: 123 | Y20: 127 | Z20: 118 | AA20: 121 | AB20: 113 | AC20: 128 | AD20: 126 | AE20: 70 | AF20: 67 | AG20: 128 | AH20: =SUM(E20:AG20) -> 3354
D21: JML | E21: =SUM(E19:E20) -> 215 | F21: =SUM(F19:F20) -> 223 | G21: =SUM(G19:G20) -> 207 | H21: =SUM(H19:H20) -> 222 | I21: =SUM(I19:I20) -> 239 | J21: =SUM(J19:J20) -> 213 | K21: =SUM(K19:K20) -> 219 | L21: =SUM(L19:L20) -> 225 | ... AG21: =SUM(AG19:AG20) -> 251 | AH21: =SUM(E21:AG21) -> 6146
B22: 2. | C22: Jumlah pengguna hak pilih dalam Daftar Pemilih Tambahan (DPTb) | D22: LK | E22: 0 | F22: 1 | G22: 2 | H22: 0 | I22: 0 | J22: 0 | K22: 1 | L22: 2 | M22: 1 | N22: 0 | O22: 0 | P22: 4 | Q22: 0 | R22: 0 | S22: 3 | T22: 9 | U22: 2 | V22: 0 | W22: 0 | X22: 0 | Y22: 0 | Z22: 1 | AA22: 0 | AB22: 1 | AC22: 0 | AD22: 11 | AE22: 8 | AF22: 0 | AG22: 0 | AH22: =SUM(E22:AG22) -> 46
D23: PR | E23: 2 | F23: 2 | G23: 0 | H23: 0 | I23: 0 | J23: 0 | K23: 1 | L23: 3 | M23: 0 | N23: 0 | O23: 0 | P23: 4 | Q23: 0 | R23: 0 | S23: 3 | T23: 3 | U23: 3 | V23: 0 | W23: 0 | X23: 0 | Y23: 2 | Z23: 3 | AA23: 1 | AB23: 2 | AC23: 0 | AD23: 1 | AE23: 0 | AF23: 0 | AG23: 0 | AH23: =SUM(E23:AG23) -> 30
D24: JML | E24: =SUM(E22:E23) -> 2 | F24: =SUM(F22:F23) -> 3 | G24: =SUM(G22:G23) -> 2 | H24: =SUM(H22:H23) -> 0 | I24: =SUM(I22:I23) -> 0 | J24: =SUM(J22:J23) -> 0 | K24: =SUM(K22:K23) -> 2 | L24: =SUM(L22:L23) -> 5 | ... AG24: =SUM(AG22:AG23) -> 0 | AH24: =SUM(E24:AG24) -> 76
B25: 3. | C25: Jumlah pengguna hak pilih dalam Daftar Pemilih Khusus (DPK) | D25: LK | E25: 1 | F25: 0 | G25: 2 | H25: 1 | I25: 0 | J25: 0 | K25: 3 | L25: 2 | M25: 1 | N25: 1 | O25: 1 | P25: 0 | Q25: 4 | R25: 4 | S25: 4 | T25: 0 | U25: 0 | V25: 1 | W25: 0 | X25: 0 | Y25: 1 | Z25: 0 | AA25: 0 | AB25: 0 | AC25: 2 | AD25: 1 | AE25: 2 | AF25: 2 | AG25: 0 | AH25: =SUM(E25:AG25) -> 33
D26: PR | E26: 0 | F26: 3 | G26: 2 | H26: 2 | I26: 0 | J26: 1 | K26: 4 | L26: 1 | M26: 5 | N26: 1 | O26: 1 | P26: 1 | Q26: 2 | R26: 2 | S26: 5 | T26: 2 | U26: 0 | V26: 1 | W26: 2 | X26: 4 | Y26: 2 | Z26: 2 | AA26: 0 | AB26: 0 | AC26: 0 | AD26: 2 | AE26: 3 | AF26: 5 | AG26: 0 | AH26: =SUM(E26:AG26) -> 53
D27: JML | E27: =SUM(E25:E26) -> 1 | F27: =SUM(F25:F26) -> 3 | G27: =SUM(G25:G26) -> 4 | H27: =SUM(H25:H26) -> 3 | I27: =SUM(I25:I26) -> 0 | J27: =SUM(J25:J26) -> 1 | K27: =SUM(K25:K26) -> 7 | L27: =SUM(L25:L26) -> 3 | ... AG27: =SUM(AG25:AG26) -> 0 | AH27: =SUM(E27:AG27) -> 86
B28: 4. | C28: Jumlah Pengguna Hak Pilih (B.1+B.2+B.3) | D28: LK | E28: =SUM(E19,E22,E25) -> 95 | F28: =SUM(F19,F22,F25) -> 112 | G28: =SUM(G19,G22,G25) -> 99 | H28: =SUM(H19,H22,H25) -> 96 | I28: =SUM(I19,I22,I25) -> 112 | J28: =SUM(J19,J22,J25) -> 109 | K28: =SUM(K19,K22,K25) -> 107 | L28: =SUM(L19,L22,L25) -> 103 | ... AG28: =SUM(AG19,AG22,AG25) -> 123 | AH28: =SUM(E28:AG28) -> 2871
D29: PR | E29: =SUM(E20,E23,E26) -> 123 | F29: =SUM(F20,F23,F26) -> 117 | G29: =SUM(G20,G23,G26) -> 114 | H29: =SUM(H20,H23,H26) -> 129 | I29: =SUM(I20,I23,I26) -> 127 | J29: =SUM(J20,J23,J26) -> 105 | K29: =SUM(K20,K23,K26) -> 121 | L29: =SUM(L20,L23,L26) -> 130 | ... AG29: =SUM(AG20,AG23,AG26) -> 128 | AH29: =SUM(E29:AG29) -> 3437
D30: JML | E30: =SUM(E28:E29) -> 218 | F30: =SUM(F28:F29) -> 229 | G30: =SUM(G28:G29) -> 213 | H30: =SUM(H28:H29) -> 225 | I30: =SUM(I28:I29) -> 239 | J30: =SUM(J28:J29) -> 214 | K30: =SUM(K28:K29) -> 228 | L30: =SUM(L28:L29) -> 233 | ... AG30: =SUM(AG28:AG29) -> 251 | AH30: =SUM(E30:AG30) -> 6308
A32: II | B32: DATA PENGGUNAAN SURAT SUARA
A33: 1 | B33: Jumlah surat suara yang diterima, termasuk surat suara cadangan 2% dari DPT | E33: 296 | F33: 318 | G33: 301 | H33: 295 | I33: 297 | J33: 286 | K33: 293 | L33: 289 | M33: 297 | N33: 303 | O33: 302 | P33: 285 | Q33: 270 | R33: 280 | S33: 275 | T33: 276 | U33: 296 | V33: 299 | W33: 282 | X33: 274 | Y33: 289 | Z33: 290 | AA33: 296 | AB33: 283 | AC33: 302 | AD33: 291 | AE33: 272 | AF33: 161 | AG33: 306 | AH33: =SUM(E33:AG33) -> 8304
A34: 2 | B34: Jumlah surat suara yang digunakan | E34: 218 | F34: 229 | G34: 213 | H34: 225 | I34: 239 | J34: 214 | K34: 228 | L34: 233 | M34: 240 | N34: 204 | O34: 225 | P34: 217 | Q34: 215 | R34: 209 | S34: 221 | T34: 213 | U34: 225 | V34: 248 | W34: 222 | X34: 215 | Y34: 225 | Z34: 218 | AA34: 223 | AB34: 203 | AC34: 232 | AD34: 237 | AE34: 139 | AF34: 127 | AG34: 251 | AH34: =SUM(E34:AG34) -> 6308
A35: 3 | B35: Jumlah surat suara dikembalikan oleh pemilih (karena rusak atau keliru coblos) | E35: 32 | F35: 0 | G35: 0 | H35: 0 | I35: 0 | J35: 0 | K35: 1 | L35: 0 | M35: 0 | N35: 0 | O35: 0 | P35: 1 | Q35: 0 | R35: 1 | S35: 0 | T35: 0 | U35: 0 | V35: 0 | W35: 0 | X35: 0 | Y35: 0 | Z35: 0 | AA35: 0 | AB35: 0 | AC35: 0 | AD35: 0 | AE35: 0 | AF35: 0 | AG35: 0 | AH35: =SUM(E35:AG35) -> 35
A36: 4 | B36: Jumlah surat suara yang tidak digunakan/tidak terpakai, termasuk sisa surat suara cadangan | E36: =E33-(E34+E35) -> 46 | F36: =F33-(F34+F35) -> 89 | G36: =G33-(G34+G35) -> 88 | H36: =H33-(H34+H35) -> 70 | I36: =I33-(I34+I35) -> 58 | J36: =J33-(J34+J35) -> 72 | K36: =K33-(K34+K35) -> 64 | L36: =L33-(L34+L35) -> 56 | ... AG36: =AG33-(AG34+AG35) -> 55 | AH36: =SUM(E36:AG36) -> 1961
A38: III | B38: DATA PEMILIH DISABILITAS
B39: Jumlah seluruh Pemilih disabilitas yang menggunakan hak pilih | D39: LK | O39: 1 | R39: 2 | X39: 1 | AC39: 1 | AE39: 1 | AH39: =SUM(E39:AG39) -> 6
D40: PR | L40: 1 | R40: 1 | U40: 1 | X40: 1 | Z40: 1 | AH40: =SUM(E40:AG40) -> 5
D41: JML | E41: =SUM(E39:E40) -> 0 | F41: =SUM(F39:F40) -> 0 | G41: =SUM(G39:G40) -> 0 | H41: =SUM(H39:H40) -> 0 | I41: =SUM(I39:I40) -> 0 | J41: =SUM(J39:J40) -> 0 | K41: =SUM(K39:K40) -> 0 | L41: =SUM(L39:L40) -> 1 | ... AG41: =SUM(AG39:AG40) -> 0 | AH41: =SUM(E41:AG41) -> 11
A43: IV | B43: DATA RINCIAN PEROLEHAN SUARA PASANGAN CALON BUPATI DAN WAKIL BUPATI
A44: NOMOR DAN NAMA CALON
B45: 1. | C45: AA. AHMAD NAWARDI | E45: 9 | F45: 18 | G45: 14 | H45: 17 | I45: 27 | J45: 16 | K45: 17 | L45: 10 | M45: 15 | N45: 13 | O45: 14 | P45: 6 | Q45: 8 | R45: 12 | S45: 8 | T45: 10 | U45: 16 | V45: 8 | W45: 17 | X45: 9 | Y45: 5 | Z45: 10 | AA45: 11 | AB45: 9 | AC45: 11 | AD45: 21 | AE45: 2 | AF45: 12 | AG45: 35 | AH45: =SUM(E45:AG45) -> 380
B46: 2. | C46: Ir. H. AA LA NYALLA MAHMUD MATTALITI, M.HP. | E46: 34 | F46: 26 | G46: 37 | H46: 39 | I46: 30 | J46: 25 | K46: 37 | L46: 30 | M46: 36 | N46: 29 | O46: 36 | P46: 27 | Q46: 25 | R46: 42 | S46: 36 | T46: 30 | U46: 26 | V46: 30 | W46: 33 | X46: 41 | Y46: 32 | Z46: 36 | AA46: 32 | AB46: 34 | AC46: 39 | AD46: 37 | AE46: 21 | AF46: 13 | AG46: 28 | AH46: =SUM(E46:AG46) -> 921
B47: 3. | C47: ABDUL QADIR AMIR HARTONO, S.E., S.H., M.H. | E47: 7 | F47: 8 | G47: 9 | H47: 21 | I47: 18 | J47: 16 | K47: 15 | L47: 12 | M47: 9 | N47: 8 | O47: 8 | P47: 13 | Q47: 14 | R47: 8 | S47: 6 | T47: 9 | U47: 35 | V47: 12 | W47: 42 | X47: 12 | Y47: 5 | Z47: 7 | AA47: 27 | AB47: 6 | AC47: 12 | AD47: 10 | AE47: 6 | AF47: 5 | AG47: 9 | AH47: =SUM(E47:AG47) -> 369
B48: 4. | C48: ADILLA AZIS, S.E. | E48: 23 | F48: 30 | G48: 16 | H48: 18 | I48: 24 | J48: 26 | K48: 23 | L48: 34 | M48: 25 | N48: 19 | O48: 14 | P48: 26 | Q48: 17 | R48: 20 | S48: 37 | T48: 25 | U48: 19 | V48: 25 | W48: 13 | X48: 15 | Y48: 22 | Z48: 13 | AA48: 24 | AB48: 30 | AC48: 37 | AD48: 33 | AE48: 18 | AF48: 19 | AG48: 37 | AH48: =SUM(E48:AG48) -> 682
B49: 5. | C49: Ir. H. AGUS RAHARDJO, MSc.M. | E49: 35 | F49: 25 | G49: 36 | H49: 17 | I49: 29 | J49: 30 | K49: 26 | L49: 36 | M49: 31 | N49: 21 | O49: 27 | P49: 25 | Q49: 29 | R49: 19 | S49: 19 | T49: 31 | U49: 29 | V49: 44 | W49: 27 | X49: 15 | Y49: 30 | Z49: 29 | AA49: 23 | AB49: 30 | AC49: 32 | AD49: 31 | AE49: 21 | AF49: 17 | AG49: 39 | AH49: =SUM(E49:AG49) -> 803
B50: 6. | C50: Drs. AYUB KHAN | E50: 8 | F50: 11 | G50: 3 | H50: 11 | I50: 12 | J50: 10 | K50: 8 | L50: 18 | M50: 15 | N50: 10 | O50: 26 | P50: 11 | Q50: 11 | R50: 10 | S50: 12 | T50: 7 | U50: 11 | V50: 7 | W50: 10 | X50: 16 | Y50: 9 | Z50: 8 | AA50: 7 | AB50: 9 | AC50: 16 | AD50: 9 | AE50: 8 | AF50: 12 | AG50: 8 | AH50: =SUM(E50:AG50) -> 313
B51: 7. | C51: BAMBANG HARIANTO | E51: 5 | F51: 3 | G51: 4 | H51: 4 | I51: 0 | J51: 3 | K51: 2 | L51: 2 | M51: 1 | N51: 1 | O51: 4 | P51: 3 | Q51: 2 | R51: 1 | S51: 0 | T51: 2 | U51: 1 | V51: 3 | W51: 2 | X51: 4 | Y51: 3 | Z51: 7 | AA51: 3 | AB51: 0 | AC51: 2 | AD51: 0 | AE51: 1 | AF51: 2 | AG51: 5 | AH51: =SUM(E51:AG51) -> 70
...

Sheet PENGANJURAN
C2: Kecamatan | D2: BANYUWANGI
C3: Kabupaten | D3: BANYUWANGI
C4: Provinsi | D4: JAWA TIMUR
C9: Kelurahan
D10: PENGANJURAN
A12: I | B12: DATA PEMILIH DAN PENGGUNAAN HAK PILIH | T12: JUMLAH AKHIR
A13: A | B13: DATA PEMILIH | E13: TPS 001 | F13: TPS 002 | G13: TPS 003 | H13: TPS 004 | I13: TPS 005 | J13: TPS 006 | K13: TPS 007 | L13: TPS 008 | M13: TPS 009 | N13: TPS 010 | O13: TPS 011 | P13: TPS 012 | Q13: TPS 013 | R13: TPS 014 | S13: TPS 015
B14: Jumlah Pemilih dalam Daftar Pemilih Tetap (DPT) | D14: LK | E14: 136 | F14: 149 | G14: 144 | H14: 143 | I14: 141 | J14: 130 | K14: 140 | L14: 131 | M14: 129 | N14: 143 | O14: 148 | P14: 122 | Q14: 140 | R14: 140 | S14: 129 | T14: =SUM(E14:S14) -> 2065
D15: PR | E15: 157 | F15: 146 | G15: 131 | H15: 153 | I15: 147 | J15: 159 | K15: 147 | L15: 150 | M15: 159 | N15: 156 | O15: 140 | P15: 145 | Q15: 154 | R15: 140 | S15: 161 | T15: =SUM(E15:S15) -> 2245
D16: JML | E16: =SUM(E14:E15) -> 293 | F16: =SUM(F14:F15) -> 295 | G16: =SUM(G14:G15) -> 275 | H16: =SUM(H14:H15) -> 296 | I16: =SUM(I14:I15) -> 288 | J16: =SUM(J14:J15) -> 289 | K16: =SUM(K14:K15) -> 287 | L16: =SUM(L14:L15) -> 281 | ... S16: =SUM(S14:S15) -> 290 | T16: =SUM(E16:S16) -> 4310
A18: B | B18: PENGGUNA HAK PILIH
B19: 1. | C19: Jumlah pengguna hak pilih dalam Daftar Pemilih Tetap (DPT) | D19: LK | E19: 96 | F19: 105 | G19: 100 | H19: 106 | I19: 95 | J19: 93 | K19: 106 | L19: 83 | M19: 98 | N19: 90 | O19: 110 | P19: 89 | Q19: 105 | R19: 92 | S19: 90 | T19: =SUM(E19:S19) -> 1458
D20: PR | E20: 118 | F20: 114 | G20: 101 | H20: 131 | I20: 109 | J20: 126 | K20: 115 | L20: 114 | M20: 121 | N20: 115 | O20: 112 | P20: 116 | Q20: 126 | R20: 113 | S20: 123 | T20: =SUM(E20:S20) -> 1754
D21: JML | E21: =SUM(E19:E20) -> 214 | F21: =SUM(F19:F20) -> 219 | G21: =SUM(G19:G20) -> 201 | H21: =SUM(H19:H20) -> 237 | I21: =SUM(I19:I20) -> 204 | J21: =SUM(J19:J20) -> 219 | K21: =SUM(K19:K20) -> 221 | L21: =SUM(L19:L20) -> 197 | ... S21: =SUM(S19:S20) -> 213 | T21: =SUM(E21:S21) -> 3212
B22: 2. | C22: Jumlah pengguna hak pilih dalam Daftar Pemilih Tambahan (DPTb) | D22: LK | E22: 0 | F22: 0 | G22: 0 | H22: 0 | I22: 3 | J22: 1 | K22: 3 | L22: 0 | M22: 0 | N22: 8 | O22: 0 | P22: 0 | Q22: 1 | R22: 1 | S22: 2 | T22: =SUM(E22:S22) -> 19
D23: PR | E23: 0 | F23: 1 | G23: 0 | H23: 0 | I23: 1 | J23: 1 | K23: 0 | L23: 0 | M23: 0 | N23: 5 | O23: 0 | P23: 1 | Q23: 1 | R23: 0 | S23: 0 | T23: =SUM(E23:S23) -> 10
D24: JML | E24: =SUM(E22:E23) -> 0 | F24: =SUM(F22:F23) -> 1 | G24: =SUM(G22:G23) -> 0 | H24: =SUM(H22:H23) -> 0 | I24: =SUM(I22:I23) -> 4 | J24: =SUM(J22:J23) -> 2 | K24: =SUM(K22:K23) -> 3 | L24: =SUM(L22:L23) -> 0 | ... S24: =SUM(S22:S23) -> 2 | T24: =SUM(E24:S24) -> 29
B25: 3. | C25: Jumlah pengguna hak pilih dalam Daftar Pemilih Khusus (DPK) | D25: LK | E25: 3 | F25: 0 | G25: 1 | H25: 0 | I25: 1 | J25: 0 | K25: 0 | L25: 1 | M25: 1 | N25: 1 | O25: 4 | P25: 0 | Q25: 1 | R25: 3 | S25: 2 | T25: =SUM(E25:S25) -> 18
D26: PR | E26: 2 | F26: 1 | G26: 1 | H26: 0 | I26: 3 | J26: 2 | K26: 1 | L26: 1 | M26: 1 | N26: 0 | O26: 6 | P26: 4 | Q26: 1 | R26: 2 | S26: 2 | T26: =SUM(E26:S26) -> 27
D27: JML | E27: =SUM(E25:E26) -> 5 | F27: =SUM(F25:F26) -> 1 | G27: =SUM(G25:G26) -> 2 | H27: =SUM(H25:H26) -> 0 | I27: =SUM(I25:I26) -> 4 | J27: =SUM(J25:J26) -> 2 | K27: =SUM(K25:K26) -> 1 | L27: =SUM(L25:L26) -> 2 | ... S27: =SUM(S25:S26) -> 4 | T27: =SUM(E27:S27) -> 45
B28: 4. | C28: Jumlah Pengguna Hak Pilih (B.1+B.2+B.3) | D28: LK | E28: =SUM(E19,E22,E25) -> 99 | F28: =SUM(F19,F22,F25) -> 105 | G28: =SUM(G19,G22,G25) -> 101 | H28: =SUM(H19,H22,H25) -> 106 | I28: =SUM(I19,I22,I25) -> 99 | J28: =SUM(J19,J22,J25) -> 94 | K28: =SUM(K19,K22,K25) -> 109 | L28: =SUM(L19,L22,L25) -> 84 | ... S28: =SUM(S19,S22,S25) -> 94 | T28: =SUM(E28:S28) -> 1495
D29: PR | E29: =SUM(E20,E23,E26) -> 120 | F29: =SUM(F20,F23,F26) -> 116 | G29: =SUM(G20,G23,G26) -> 102 | H29: =SUM(H20,H23,H26) -> 131 | I29: =SUM(I20,I23,I26) -> 113 | J29: =SUM(J20,J23,J26) -> 129 | K29: =SUM(K20,K23,K26) -> 116 | L29: =SUM(L20,L23,L26) -> 115 | ... S29: =SUM(S20,S23,S26) -> 125 | T29: =SUM(E29:S29) -> 1791
D30: JML | E30: =SUM(E28:E29) -> 219 | F30: =SUM(F28:F29) -> 221 | G30: =SUM(G28:G29) -> 203 | H30: =SUM(H28:H29) -> 237 | I30: =SUM(I28:I29) -> 212 | J30: =SUM(J28:J29) -> 223 | K30: =SUM(K28:K29) -> 225 | L30: =SUM(L28:L29) -> 199 | ... S30: =SUM(S28:S29) -> 219 | T30: =SUM(E30:S30) -> 3286
A32: II | B32: DATA PENGGUNAAN SURAT SUARA
A33: 1 | B33: Jumlah surat suara yang diterima, termasuk surat suara cadangan 2% dari DPT | E33: 299 | F33: 301 | G33: 281 | H33: 292 | I33: 294 | J33: 296 | K33: 294 | L33: 277 | M33: 292 | N33: 305 | O33: 295 | P33: 271 | Q33: 300 | R33: 286 | S33: 294 | T33: =SUM(E33:S33) -> 4377
A34: 2 | B34: Jumlah surat suara yang digunakan | E34: 219 | F34: 221 | G34: 203 | H34: 237 | I34: 212 | J34: 223 | K34: 225 | L34: 199 | M34: 221 | N34: 219 | O34: 232 | P34: 210 | Q34: 235 | R34: 211 | S34: 219 | T34: =SUM(E34:S34) -> 3286
A35: 3 | B35: Jumlah surat suara dikembalikan oleh pemilih (karena rusak atau keliru coblos) | E35: 0 | F35: 0 | G35: 0 | H35: 0 | I35: 3 | J35: 0 | K35: 0 | L35: 0 | M35: 0 | N35: 0 | O35: 0 | P35: 0 | Q35: 0 | R35: 0 | S35: 0 | T35: =SUM(E35:S35) -> 3
A36: 4 | B36: Jumlah surat suara yang tidak digunakan/tidak terpakai, termasuk sisa surat suara cadangan | E36: =E33-(E34+E35) -> 80 | F36: =F33-(F34+F35) -> 80 | G36: =G33-(G34+G35) -> 78 | H36: =H33-(H34+H35) -> 55 | I36: =I33-(I34+I35) -> 79 | J36: =J33-(J34+J35) -> 73 | K36: =K33-(K34+K35) -> 69 | L36: =L33-(L34+L35) -> 78 | ... S36: =S33-(S34+S35) -> 75 | T36: =SUM(E36:S36) -> 1088
A38: III | B38: DATA PEMILIH DISABILITAS
B39: Jumlah seluruh Pemilih disabilitas yang menggunakan hak pilih | D39: LK | M39: 1 | T39: =SUM(E39:S39) -> 1
D40: PR | T40: =SUM(E40:S40) -> 0
D41: JML | E41: =SUM(E39:E40) -> 0 | F41: =SUM(F39:F40) -> 0 | G41: =SUM(G39:G40) -> 0 | H41: =SUM(H39:H40) -> 0 | I41: =SUM(I39:I40) -> 0 | J41: =SUM(J39:J40) -> 0 | K41: =SUM(K39:K40) -> 0 | L41: =SUM(L39:L40) -> 0 | ... S41: =SUM(S39:S40) -> 0 | T41: =SUM(E41:S41) -> 1
A43: IV | B43: DATA RINCIAN PEROLEHAN SUARA PASANGAN CALON BUPATI DAN WAKIL BUPATI
A44: NOMOR DAN NAMA CALON
B45: 1. | C45: AA. AHMAD NAWARDI | E45: 7 | F45: 15 | G45: 16 | H45: 12 | I45: 5 | J45: 14 | K45: 12 | L45: 7 | M45: 9 | N45: 8 | O45: 14 | P45: 5 | Q45: 6 | R45: 13 | S45: 4 | T45: =SUM(E45:S45) -> 147
B46: 2. | C46: Ir. H. AA LA NYALLA MAHMUD MATTALITI, M.HP. | E46: 28 | F46: 18 | G46: 24 | H46: 27 | I46: 32 | J46: 32 | K46: 31 | L46: 30 | M46: 35 | N46: 32 | O46: 31 | P46: 25 | Q46: 36 | R46: 38 | S46: 29 | T46: =SUM(E46:S46) -> 448
B47: 3. | C47: ABDUL QADIR AMIR HARTONO, S.E., S.H., M.H. | E47: 17 | F47: 11 | G47: 7 | H47: 19 | I47: 14 | J47: 8 | K47: 6 | L47: 10 | M47: 12 | N47: 13 | O47: 15 | P47: 17 | Q47: 13 | R47: 13 | S47: 14 | T47: =SUM(E47:S47) -> 189
B48: 4. | C48: ADILLA AZIS, S.E. | E48: 17 | F48: 30 | G48: 15 | H48: 17 | I48: 18 | J48: 13 | K48: 17 | L48: 15 | M48: 13 | N48: 13 | O48: 17 | P48: 24 | Q48: 18 | R48: 15 | S48: 16 | T48: =SUM(E48:S48) -> 258
B49: 5. | C49: Ir. H. AGUS RAHARDJO, MSc.M. | E49: 26 | F49: 25 | G49: 15 | H49: 28 | I49: 28 | J49: 34 | K49: 25 | L49: 26 | M49: 25 | N49: 39 | O49: 23 | P49: 26 | Q49: 21 | R49: 21 | S49: 29 | T49: =SUM(E49:S49) -> 391
B50: 6. | C50: Drs. AYUB KHAN | E50: 7 | F50: 11 | G50: 8 | H50: 12 | I50: 10 | J50: 6 | K50: 7 | L50: 5 | M50: 10 | N50: 10 | O50: 23 | P50: 12 | Q50: 20 | R50: 11 | S50: 7 | T50: =SUM(E50:S50) -> 159
...

Sheet TUKANGKAYU
C2: Kecamatan | D2: BANYUWANGI
C3: Kabupaten | D3: BANYUWANGI
C4: Provinsi | D4: JAWA TIMUR
C9: Kelurahan | D9: TUKANGKAYU
A12: I | B12: DATA PEMILIH DAN PENGGUNAAN HAK PILIH | AD12: JUMLAH AKHIR
A13: A | B13: DATA PEMILIH | E13: TPS 001 | F13: TPS 002 | G13: TPS 003 | H13: TPS 004 | I13: TPS 005 | J13: TPS 006 | K13: TPS 007 | L13: TPS 008 | M13: TPS 009 | N13: TPS 010 | O13: TPS 011 | P13: TPS 012 | Q13: TPS 013 | R13: TPS 014 | S13: TPS 015 | T13: TPS 016 | U13: TPS 017 | V13: TPS 018 | W13: TPS 019 | X13: TPS 020 | Y13: TPS 021 | Z13: TPS 022 | AA13: TPS 023 | AB13: TPS 024 | AC13: TPS 025
B14: Jumlah Pemilih dalam Daftar Pemilih Tetap (DPT) | D14: LK | E14: 136 | F14: 143 | G14: 115 | H14: 142 | I14: 126 | J14: 133 | K14: 129 | L14: 113 | M14: 130 | N14: 111 | O14: 120 | P14: 120 | Q14: 132 | R14: 129 | S14: 134 | T14: 136 | U14: 132 | V14: 133 | W14: 124 | X14: 135 | Y14: 127 | Z14: 142 | AA14: 120 | AB14: 148 | AC14: 126 | AD14: =SUM(E14:AC14) -> 3236
D15: PR | E15: 151 | F15: 147 | G15: 121 | H15: 138 | I15: 142 | J15: 138 | K15: 125 | L15: 127 | M15: 137 | N15: 125 | O15: 128 | P15: 147 | Q15: 129 | R15: 140 | S15: 149 | T15: 143 | U15: 148 | V15: 143 | W15: 144 | X15: 145 | Y15: 133 | Z15: 153 | AA15: 126 | AB15: 129 | AC15: 139 | AD15: =SUM(E15:AC15) -> 3447
D16: JML | E16: =SUM(E14:E15) -> 287 | F16: =SUM(F14:F15) -> 290 | G16: =SUM(G14:G15) -> 236 | H16: =SUM(H14:H15) -> 280 | I16: =SUM(I14:I15) -> 268 | J16: =SUM(J14:J15) -> 271 | K16: =SUM(K14:K15) -> 254 | L16: =SUM(L14:L15) -> 240 | ... AC16: =SUM(AC14:AC15) -> 265 | AD16: =SUM(E16:AC16) -> 6683
A18: B | B18: PENGGUNA HAK PILIH
B19: 1. | C19: Jumlah pengguna hak pilih dalam Daftar Pemilih Tetap (DPT) | D19: LK | E19: 108 | F19: 93 | G19: 78 | H19: 105 | I19: 97 | J19: 105 | K19: 107 | L19: 80 | M19: 95 | N19: 71 | O19: 95 | P19: 93 | Q19: 97 | R19: 100 | S19: 93 | T19: 106 | U19: 96 | V19: 98 | W19: 87 | X19: 94 | Y19: 86 | Z19: 100 | AA19: 86 | AB19: 111 | AC19: 94 | AD19: =SUM(E19:AC19) -> 2375
D20: PR | E20: 125 | F20: 118 | G20: 96 | H20: 113 | I20: 112 | J20: 116 | K20: 112 | L20: 102 | M20: 109 | N20: 94 | O20: 102 | P20: 109 | Q20: 107 | R20: 115 | S20: 107 | T20: 123 | U20: 121 | V20: 115 | W20: 108 | X20: 112 | Y20: 102 | Z20: 123 | AA20: 97 | AB20: 109 | AC20: 108 | AD20: =SUM(E20:AC20) -> 2755
D21: JML | E21: =SUM(E19:E20) -> 233 | F21: =SUM(F19:F20) -> 211 | G21: =SUM(G19:G20) -> 174 | H21: =SUM(H19:H20) -> 218 | I21: =SUM(I19:I20) -> 209 | J21: =SUM(J19:J20) -> 221 | K21: =SUM(K19:K20) -> 219 | L21: =SUM(L19:L20) -> 182 | ... AC21: =SUM(AC19:AC20) -> 202 | AD21: =SUM(E21:AC21) -> 5130
B22: 2. | C22: Jumlah pengguna hak pilih dalam Daftar Pemilih Tambahan (DPTb) | D22: LK | E22: 0 | F22: 0 | G22: 1 | H22: 0 | I22: 1 | J22: 0 | K22: 0 | L22: 0 | M22: 0 | N22: 1 | O22: 0 | P22: 0 | Q22: 0 | R22: 0 | S22: 0 | T22: 0 | U22: 0 | V22: 0 | W22: 2 | X22: 0 | Y22: 1 | Z22: 0 | AA22: 0 | AB22: 0 | AC22: 0 | AD22: =SUM(E22:AC22) -> 6
D23: PR | E23: 0 | F23: 0 | G23: 0 | H23: 0 | I23: 1 | J23: 0 | K23: 0 | L23: 0 | M23: 0 | N23: 0 | O23: 0 | P23: 0 | Q23: 0 | R23: 0 | S23: 0 | T23: 2 | U23: 0 | V23: 0 | W23: 6 | X23: 0 | Y23: 1 | Z23: 1 | AA23: 1 | AB23: 0 | AC23: 0 | AD23: =SUM(E23:AC23) -> 12
D24: JML | E24: =SUM(E22:E23) -> 0 | F24: =SUM(F22:F23) -> 0 | G24: =SUM(G22:G23) -> 1 | H24: =SUM(H22:H23) -> 0 | I24: =SUM(I22:I23) -> 2 | J24: =SUM(J22:J23) -> 0 | K24: =SUM(K22:K23) -> 0 | L24: =SUM(L22:L23) -> 0 | ... AC24: =SUM(AC22:AC23) -> 0 | AD24: =SUM(E24:AC24) -> 18
B25: 3. | C25: Jumlah pengguna hak pilih dalam Daftar Pemilih Khusus (DPK) | D25: LK | E25: 1 | F25: 2 | G25: 6 | H25: 1 | I25: 3 | J25: 0 | K25: 2 | L25: 0 | M25: 2 | N25: 0 | O25: 2 | P25: 6 | Q25: 1 | R25: 0 | S25: 0 | T25: 2 | U25: 3 | V25: 1 | W25: 4 | X25: 1 | Y25: 1 | Z25: 8 | AA25: 2 | AB25: 3 | AC25: 2 | AD25: =SUM(E25:AC25) -> 53
D26: PR | E26: 5 | F26: 3 | G26: 4 | H26: 0 | I26: 1 | J26: 1 | K26: 2 | L26: 2 | M26: 1 | N26: 0 | O26: 3 | P26: 4 | Q26: 2 | R26: 1 | S26: 2 | T26: 2 | U26: 7 | V26: 1 | W26: 6 | X26: 3 | Y26: 1 | Z26: 10 | AA26: 3 | AB26: 1 | AC26: 1 | AD26: =SUM(E26:AC26) -> 66
D27: JML | E27: =SUM(E25:E26) -> 6 | F27: =SUM(F25:F26) -> 5 | G27: =SUM(G25:G26) -> 10 | H27: =SUM(H25:H26) -> 1 | I27: =SUM(I25:I26) -> 4 | J27: =SUM(J25:J26) -> 1 | K27: =SUM(K25:K26) -> 4 | L27: =SUM(L25:L26) -> 2 | ... AC27: =SUM(AC25:AC26) -> 3 | AD27: =SUM(E27:AC27) -> 119
B28: 4. | C28: Jumlah Pengguna Hak Pilih (B.1+B.2+B.3) | D28: LK | E28: =SUM(E19,E22,E25) -> 109 | F28: =SUM(F19,F22,F25) -> 95 | G28: =SUM(G19,G22,G25) -> 85 | H28: =SUM(H19,H22,H25) -> 106 | I28: =SUM(I19,I22,I25) -> 101 | J28: =SUM(J19,J22,J25) -> 105 | K28: =SUM(K19,K22,K25) -> 109 | L28: =SUM(L19,L22,L25) -> 80 | ... AC28: =SUM(AC19,AC22,AC25) -> 96 | AD28: =SUM(E28:AC28) -> 2434
D29: PR | E29: =SUM(E20,E23,E26) -> 130 | F29: =SUM(F20,F23,F26) -> 121 | G29: =SUM(G20,G23,G26) -> 100 | H29: =SUM(H20,H23,H26) -> 113 | I29: =SUM(I20,I23,I26) -> 114 | J29: =SUM(J20,J23,J26) -> 117 | K29: =SUM(K20,K23,K26) -> 114 | L29: =SUM(L20,L23,L26) -> 104 | ... AC29: =SUM(AC20,AC23,AC26) -> 109 | AD29: =SUM(E29:AC29) -> 2833
D30: JML | E30: =SUM(E28:E29) -> 239 | F30: =SUM(F28:F29) -> 216 | G30: =SUM(G28:G29) -> 185 | H30: =SUM(H28:H29) -> 219 | I30: =SUM(I28:I29) -> 215 | J30: =SUM(J28:J29) -> 222 | K30: =SUM(K28:K29) -> 223 | L30: =SUM(L28:L29) -> 184 | ... AC30: =SUM(AC28:AC29) -> 205 | AD30: =SUM(E30:AC30) -> 5267
A32: II | B32: DATA PENGGUNAAN SURAT SUARA
A33: 1 | B33: Jumlah surat suara yang diterima, termasuk surat suara cadangan 2% dari DPT | E33: 294 | F33: 296 | G33: 241 | H33: 286 | I33: 274 | J33: 277 | K33: 260 | L33: 245 | M33: 273 | N33: 241 | O33: 253 | P33: 273 | Q33: 267 | R33: 271 | S33: 289 | T33: 285 | U33: 286 | V33: 282 | W33: 274 | X33: 287 | Y33: 266 | Z33: 301 | AA33: 254 | AB33: 283 | AC33: 262 | AD33: =SUM(E33:AC33) -> 6820
A34: 2 | B34: Jumlah surat suara yang digunakan | E34: 239 | F34: 216 | G34: 185 | H34: 219 | I34: 215 | J34: 222 | K34: 223 | L34: 184 | M34: 207 | N34: 166 | O34: 202 | P34: 212 | Q34: 207 | R34: 216 | S34: 202 | T34: 235 | U34: 227 | V34: 215 | W34: 213 | X34: 210 | Y34: 192 | Z34: 242 | AA34: 189 | AB34: 224 | AC34: 205 | AD34: =SUM(E34:AC34) -> 5267
A35: 3 | B35: Jumlah surat suara dikembalikan oleh pemilih (karena rusak atau keliru coblos) | E35: 0 | F35: 0 | G35: 1 | H35: 0 | I35: 0 | J35: 1 | K35: 2 | L35: 0 | M35: 0 | N35: 0 | O35: 0 | P35: 0 | Q35: 1 | R35: 0 | S35: 0 | T35: 0 | U35: 0 | V35: 2 | W35: 0 | X35: 1 | Y35: 0 | Z35: 0 | AA35: 0 | AB35: 6 | AC35: 0 | AD35: =SUM(E35:AC35) -> 14
A36: 4 | B36: Jumlah surat suara yang tidak digunakan/tidak terpakai, termasuk sisa surat suara cadangan | E36: =E33-(E34+E35) -> 55 | F36: =F33-(F34+F35) -> 80 | G36: =G33-(G34+G35) -> 55 | H36: =H33-(H34+H35) -> 67 | I36: =I33-(I34+I35) -> 59 | J36: =J33-(J34+J35) -> 54 | K36: =K33-(K34+K35) -> 35 | L36: =L33-(L34+L35) -> 61 | ... AC36: =AC33-(AC34+AC35) -> 57 | AD36: =SUM(E36:AC36) -> 1539
A38: III | B38: DATA PEMILIH DISABILITAS
B39: Jumlah seluruh Pemilih disabilitas yang menggunakan hak pilih | D39: LK | G39: 1 | H39: 1 | J39: 1 | M39: 3 | P39: 1 | Q39: 5 | V39: 1 | W39: 1 | AD39: =SUM(E39:AC39) -> 14
D40: PR | M40: 4 | P40: 1 | Q40: 2 | R40: 1 | W40: 4 | AD40: =SUM(E40:AC40) -> 12
D41: JML | E41: =SUM(E39:E40) -> 0 | F41: =SUM(F39:F40) -> 0 | G41: =SUM(G39:G40) -> 1 | H41: =SUM(H39:H40) -> 1 | I41: =SUM(I39:I40) -> 0 | J41: =SUM(J39:J40) -> 1 | K41: =SUM(K39:K40) -> 0 | L41: =SUM(L39:L40) -> 0 | ... AC41: =SUM(AC39:AC40) -> 0 | AD41: =SUM(E41:AC41) -> 26
A43: IV | B43: DATA RINCIAN PEROLEHAN SUARA PASANGAN CALON BUPATI DAN WAKIL BUPATI
A44: NOMOR DAN NAMA CALON
B45: 1. | C45: AA. AHMAD NAWARDI | E45: 16 | F45: 8 | G45: 24 | H45: 7 | I45: 15 | J45: 12 | K45: 23 | L45: 24 | M45: 30 | N45: 32 | O45: 10 | P45: 10 | Q45: 10 | R45: 6 | S45: 6 | T45: 10 | U45: 15 | V45: 6 | W45: 7 | X45: 10 | Y45: 4 | Z45: 10 | AA45: 14 | AB45: 17 | AC45: 4 | AD45: =SUM(E45:AC45) -> 330
B46: 2. | C46: Ir. H. AA LA NYALLA MAHMUD MATTALITI, M.HP. | E46: 18 | F46: 30 | G46: 28 | H46: 36 | I46: 37 | J46: 43 | K46: 32 | L46: 24 | M46: 26 | N46: 10 | O46: 29 | P46: 24 | Q46: 33 | R46: 28 | S46: 25 | T46: 24 | U46: 21 | V46: 34 | W46: 33 | X46: 30 | Y46: 25 | Z46: 28 | AA46: 26 | AB46: 27 | AC46: 21 | AD46: =SUM(E46:AC46) -> 692
B47: 3. | C47: ABDUL QADIR AMIR HARTONO, S.E., S.H., M.H. | E47: 11 | F47: 14 | G47: 8 | H47: 8 | I47: 5 | J47: 10 | K47: 11 | L47: 5 | M47: 5 | N47: 12 | O47: 9 | P47: 11 | Q47: 15 | R47: 5 | S47: 15 | T47: 11 | U47: 11 | V47: 15 | W47: 4 | X47: 7 | Y47: 8 | Z47: 22 | AA47: 9 | AB47: 13 | AC47: 7 | AD47: =SUM(E47:AC47) -> 251
B48: 4. | C48: ADILLA AZIS, S.E. | E48: 23 | F48: 23 | G48: 15 | H48: 25 | I48: 23 | J48: 23 | K48: 25 | L48: 25 | M48: 25 | N48: 15 | O48: 10 | P48: 16 | Q48: 13 | R48: 22 | S48: 11 | T48: 25 | U48: 25 | V48: 19 | W48: 14 | X48: 11 | Y48: 16 | Z48: 24 | AA48: 17 | AB48: 24 | AC48: 18 | AD48: =SUM(E48:AC48) -> 487
B49: 5. | C49: Ir. H. AGUS RAHARDJO, MSc.M. | E49: 20 | F49: 21 | G49: 17 | H49: 24 | I49: 20 | J49: 25 | K49: 16 | L49: 19 | M49: 19 | N49: 13 | O49: 32 | P49: 36 | Q49: 33 | R49: 45 | S49: 28 | T49: 20 | U49: 36 | V49: 38 | W49: 50 | X49: 33 | Y49: 35 | Z49: 39 | AA49: 25 | AB49: 20 | AC49: 34 | AD49: =SUM(E49:AC49) -> 698
B50: 6. | C50: Drs. AYUB KHAN | E50: 14 | F50: 7 | G50: 11 | H50: 13 | I50: 8 | J50: 9 | K50: 5 | L50: 14 | M50: 8 | N50: 5 | O50: 14 | P50: 10 | Q50: 10 | R50: 3 | S50: 13 | T50: 15 | U50: 10 | V50: 14 | W50: 13 | X50: 10 | Y50: 14 | Z50: 14 | AA50: 12 | AB50: 11 | AC50: 13 | AD50: =SUM(E50:AC50) -> 270
B51: 7. | C51: BAMBANG HARIANTO | E51: 1 | F51: 6 | G51: 2 | H51: 0 | I51: 3 | J51: 5 | K51: 1 | L51: 3 | M51: 0 | N51: 2 | O51: 2 | P51: 4 | Q51: 3 | R51: 6 | S51: 3 | T51: 1 | U51: 2 | V51: 2 | W51: 5 | X51: 3 | Y51: 1 | Z51: 3 | AA51: 3 | AB51: 3 | AC51: 5 | AD51: =SUM(E51:AC51) -> 69
...

Sheet KERTOSARI
C2: Kecamatan | D2: BANYUWANGI
C3: Kabupaten | D3: BANYUWANGI
C4: Provinsi | D4: JAWA TIMUR
C9: Kelurahan | D9: KERTOSARI
A12: I | B12: DATA PEMILIH DAN PENGGUNAAN HAK PILIH | AB12: JUMLAH AKHIR
A13: A | B13: DATA PEMILIH | E13: TPS 001 | F13: TPS 002 | G13: TPS 003 | H13: TPS 004 | I13: TPS 005 | J13: TPS 006 | K13: TPS 007 | L13: TPS 008 | M13: TPS 009 | N13: TPS 010 | O13: TPS 011 | P13: TPS 012 | Q13: TPS 013 | R13: TPS 014 | S13: TPS 015 | T13: TPS 016 | U13: TPS 017 | V13: TPS 018 | W13: TPS 019 | X13: TPS 020 | Y13: TPS 021 | Z13: TPS 022 | AA13: TPS 023
B14: Jumlah Pemilih dalam Daftar Pemilih Tetap (DPT) | D14: LK | E14: 135 | F14: 141 | G14: 138 | H14: 132 | I14: 126 | J14: 129 | K14: 113 | L14: 147 | M14: 142 | N14: 130 | O14: 120 | P14: 129 | Q14: 140 | R14: 142 | S14: 142 | T14: 142 | U14: 144 | V14: 125 | W14: 141 | X14: 135 | Y14: 138 | Z14: 130 | AA14: 101 | AB14: =SUM(E14:AA14) -> 3062
D15: PR | E15: 146 | F15: 143 | G15: 145 | H15: 150 | I15: 142 | J15: 132 | K15: 117 | L15: 131 | M15: 136 | N15: 137 | O15: 134 | P15: 138 | Q15: 140 | R15: 148 | S15: 146 | T15: 144 | U15: 134 | V15: 115 | W15: 142 | X15: 124 | Y15: 136 | Z15: 140 | AA15: 106 | AB15: =SUM(E15:AA15) -> 3126
D16: JML | E16: =SUM(E14:E15) -> 281 | F16: =SUM(F14:F15) -> 284 | G16: =SUM(G14:G15) -> 283 | H16: =SUM(H14:H15) -> 282 | I16: =SUM(I14:I15) -> 268 | J16: =SUM(J14:J15) -> 261 | K16: =SUM(K14:K15) -> 230 | L16: =SUM(L14:L15) -> 278 | ... AA16: =SUM(AA14:AA15) -> 207 | AB16: =SUM(E16:AA16) -> 6188
A18: B | B18: PENGGUNA HAK PILIH
B19: 1. | C19: Jumlah pengguna hak pilih dalam Daftar Pemilih Tetap (DPT) | D19: LK | E19: 95 | F19: 118 | G19: 103 | H19: 100 | I19: 97 | J19: 96 | K19: 90 | L19: 86 | M19: 85 | N19: 98 | O19: 80 | P19: 79 | Q19: 96 | R19: 105 | S19: 97 | T19: 97 | U19: 99 | V19: 105 | W19: 97 | X19: 91 | Y19: 95 | Z19: 94 | AA19: 67 | AB19: =SUM(E19:AA19) -> 2170
D20: PR | E20: 117 | F20: 122 | G20: 106 | H20: 122 | I20: 114 | J20: 113 | K20: 93 | L20: 124 | M20: 96 | N20: 102 | O20: 98 | P20: 108 | Q20: 114 | R20: 122 | S20: 116 | T20: 108 | U20: 98 | V20: 96 | W20: 117 | X20: 96 | Y20: 106 | Z20: 103 | AA20: 80 | AB20: =SUM(E20:AA20) -> 2471
D21: JML | E21: =SUM(E19:E20) -> 212 | F21: =SUM(F19:F20) -> 240 | G21: =SUM(G19:G20) -> 209 | H21: =SUM(H19:H20) -> 222 | I21: =SUM(I19:I20) -> 211 | J21: =SUM(J19:J20) -> 209 | K21: =SUM(K19:K20) -> 183 | L21: =SUM(L19:L20) -> 210 | ... AA21: =SUM(AA19:AA20) -> 147 | AB21: =SUM(E21:AA21) -> 4641
B22: 2. | C22: Jumlah pengguna hak pilih dalam Daftar Pemilih Tambahan (DPTb) | D22: LK | E22: 0 | F22: 0 | G22: 0 | H22: 0 | I22: 0 | J22: 0 | K22: 0 | L22: 0 | M22: 2 | N22: 0 | O22: 0 | P22: 1 | Q22: 0 | R22: 1 | S22: 0 | T22: 0 | U22: 0 | V22: 1 | W22: 0 | X22: 0 | Y22: 0 | Z22: 0 | AA22: 0 | AB22: =SUM(E22:AA22) -> 5
D23: PR | E23: 0 | F23: 0 | G23: 0 | H23: 0 | I23: 2 | J23: 0 | K23: 0 | L23: 0 | M23: 6 | N23: 0 | O23: 0 | P23: 1 | Q23: 0 | R23: 0 | S23: 0 | T23: 0 | U23: 0 | V23: 1 | W23: 0 | X23: 0 | Y23: 0 | Z23: 0 | AA23: 0 | AB23: =SUM(E23:AA23) -> 10
D24: JML | E24: =SUM(E22:E23) -> 0 | F24: =SUM(F22:F23) -> 0 | G24: =SUM(G22:G23) -> 0 | H24: =SUM(H22:H23) -> 0 | I24: =SUM(I22:I23) -> 2 | J24: =SUM(J22:J23) -> 0 | K24: =SUM(K22:K23) -> 0 | L24: =SUM(L22:L23) -> 0 | ... AA24: =SUM(AA22:AA23) -> 0 | AB24: =SUM(E24:AA24) -> 15
B25: 3. | C25: Jumlah pengguna hak pilih dalam Daftar Pemilih Khusus (DPK) | D25: LK | E25: 1 | F25: 0 | G25: 0 | H25: 1 | I25: 1 | J25: 1 | K25: 0 | L25: 1 | M25: 0 | N25: 2 | O25: 6 | P25: 0 | Q25: 0 | R25: 7 | S25: 1 | T25: 1 | U25: 3 | V25: 3 | W25: 0 | X25: 3 | Y25: 0 | Z25: 4 | AA25: 0 | AB25: =SUM(E25:AA25) -> 35
D26: PR | E26: 0 | F26: 1 | G26: 1 | H26: 1 | I26: 0 | J26: 2 | K26: 0 | L26: 2 | M26: 0 | N26: 2 | O26: 3 | P26: 0 | Q26: 0 | R26: 6 | S26: 3 | T26: 1 | U26: 4 | V26: 6 | W26: 0 | X26: 2 | Y26: 0 | Z26: 5 | AA26: 1 | AB26: =SUM(E26:AA26) -> 40
D27: JML | E27: =SUM(E25:E26) -> 1 | F27: =SUM(F25:F26) -> 1 | G27: =SUM(G25:G26) -> 1 | H27: =SUM(H25:H26) -> 2 | I27: =SUM(I25:I26) -> 1 | J27: =SUM(J25:J26) -> 3 | K27: =SUM(K25:K26) -> 0 | L27: =SUM(L25:L26) -> 3 | ... AA27: =SUM(AA25:AA26) -> 1 | AB27: =SUM(E27:AA27) -> 75
B28: 4. | C28: Jumlah Pengguna Hak Pilih (B.1+B.2+B.3) | D28: LK | E28: =SUM(E19,E22,E25) -> 96 | F28: =SUM(F19,F22,F25) -> 118 | G28: =SUM(G19,G22,G25) -> 103 | H28: =SUM(H19,H22,H25) -> 101 | I28: =SUM(I19,I22,I25) -> 98 | J28: =SUM(J19,J22,J25) -> 97 | K28: =SUM(K19,K22,K25) -> 90 | L28: =SUM(L19,L22,L25) -> 87 | ... AA28: =SUM(AA19,AA22,AA25) -> 67 | AB28: =SUM(E28:AA28) -> 2210
D29: PR | E29: =SUM(E20,E23,E26) -> 117 | F29: =SUM(F20,F23,F26) -> 123 | G29: =SUM(G20,G23,G26) -> 107 | H29: =SUM(H20,H23,H26) -> 123 | I29: =SUM(I20,I23,I26) -> 116 | J29: =SUM(J20,J23,J26) -> 115 | K29: =SUM(K20,K23,K26) -> 93 | L29: =SUM(L20,L23,L26) -> 126 | ... AA29: =SUM(AA20,AA23,AA26) -> 81 | AB29: =SUM(E29:AA29) -> 2521
D30: JML | E30: =SUM(E28:E29) -> 213 | F30: =SUM(F28:F29) -> 241 | G30: =SUM(G28:G29) -> 210 | H30: =SUM(H28:H29) -> 224 | I30: =SUM(I28:I29) -> 214 | J30: =SUM(J28:J29) -> 212 | K30: =SUM(K28:K29) -> 183 | L30: =SUM(L28:L29) -> 213 | ... AA30: =SUM(AA28:AA29) -> 148 | AB30: =SUM(E30:AA30) -> 4731
A32: II | B32: DATA PENGGUNAAN SURAT SUARA
A33: 1 | B33: Jumlah surat suara yang diterima, termasuk surat suara cadangan 2% dari DPT | E33: 287 | F33: 290 | G33: 282 | H33: 288 | I33: 263 | J33: 267 | K33: 234 | L33: 284 | M33: 284 | N33: 273 | O33: 258 | P33: 273 | Q33: 286 | R33: 297 | S33: 294 | T33: 292 | U33: 285 | V33: 245 | W33: 289 | X33: 265 | Y33: 290 | Z33: 276 | AA33: 212 | AB33: =SUM(E33:AA33) -> 6314
A34: 2 | B34: Jumlah surat suara yang digunakan | E34: 213 | F34: 241 | G34: 210 | H34: 224 | I34: 214 | J34: 212 | K34: 183 | L34: 213 | M34: 189 | N34: 204 | O34: 187 | P34: 189 | Q34: 210 | R34: 241 | S34: 217 | T34: 207 | U34: 204 | V34: 212 | W34: 214 | X34: 192 | Y34: 201 | Z34: 206 | AA34: 148 | AB34: =SUM(E34:AA34) -> 4731
A35: 3 | B35: Jumlah surat suara dikembalikan oleh pemilih (karena rusak atau keliru coblos) | E35: 0 | F35: 1 | G35: 0 | H35: 0 | I35: 0 | J35: 0 | K35: 0 | L35: 0 | M35: 1 | N35: 0 | O35: 0 | P35: 0 | Q35: 0 | R35: 0 | S35: 0 | T35: 0 | U35: 0 | V35: 0 | W35: 0 | X35: 0 | Y35: 0 | Z35: 0 | AA35: 1 | AB35: =SUM(E35:AA35) -> 3
A36: 4 | B36: Jumlah surat suara yang tidak digunakan/tidak terpakai, termasuk sisa surat suara cadangan | E36: =E33-(E34+E35) -> 74 | F36: =F33-(F34+F35) -> 48 | G36: =G33-(G34+G35) -> 72 | H36: =H33-(H34+H35) -> 64 | I36: =I33-(I34+I35) -> 49 | J36: =J33-(J34+J35) -> 55 | K36: =K33-(K34+K35) -> 51 | L36: =L33-(L34+L35) -> 71 | ... AA36: =AA33-(AA34+AA35) -> 63 | AB36: =SUM(E36:AA36) -> 1580
A38: III | B38: DATA PEMILIH DISABILITAS
B39: Jumlah seluruh Pemilih disabilitas yang menggunakan hak pilih | D39: LK | Q39: 1 | V39: 2 | AB39: =SUM(E39:AA39) -> 3
