Workbook

Sheet DPD
C8: Kecamatan | D8: SRONO
C9: Kabupaten | D9: BANYUWANGI
C10: Provinsi | D10: JAWA TIMUR
A12: I | B12: DATA PEMILIH DAN PENGGUNAAN HAK PILIH | E12: JUMLAH AKHIR
A13: A | B13: DATA PEMILIH
B14: Jumlah Pemilih dalam Daftar Pemilih Tetap (DPT) | D14: LK | E14: =BAGOREJO!AM14+KEBAMAN!AW14+KEPUNDUNGAN!W14+'PARIJATAH KULON'!Y14+'PARIJATAH WETAN'!AC14+REJOAGUNG!AF14+SUKOMAJU!AC14+SUKONATAR!T14+SUMBERSARI!AH14+WONOSOBO!AS14 -> 37686
D15: PR | E15: =BAGOREJO!AM15+KEBAMAN!AW15+KEPUNDUNGAN!W15+'PARIJATAH KULON'!Y15+'PARIJATAH WETAN'!AC15+REJOAGUNG!AF15+SUKOMAJU!AC15+SUKONATAR!T15+SUMBERSARI!AH15+WONOSOBO!AS15 -> 37815
D16: JML | E16: =SUM(E14:E15) -> 75501
A18: B | B18: PENGGUNA HAK PILIH
B19: 1. | C19: Jumlah pengguna hak pilih dalam Daftar Pemilih Tetap (DPT) | D19: LK | E19: =BAGOREJO!AM19+KEBAMAN!AW19+KEPUNDUNGAN!W19+'PARIJATAH KULON'!Y19+'PARIJATAH WETAN'!AC19+REJOAGUNG!AF19+SUKOMAJU!AC19+SUKONATAR!T19+SUMBERSARI!AH19+WONOSOBO!AS19 -> 27897
D20: PR | E20: =BAGOREJO!AM20+KEBAMAN!AW20+KEPUNDUNGAN!W20+'PARIJATAH KULON'!Y20+'PARIJATAH WETAN'!AC20+REJOAGUNG!AF20+SUKOMAJU!AC20+SUKONATAR!T20+SUMBERSARI!AH20+WONOSOBO!AS20 -> 30154
D21: JML | E21: =SUM(E19:E20) -> 58051
B22: 2. | C22: Jumlah pengguna hak pilih dalam Daftar Pemilih Tambahan (DPTb) | D22: LK | E22: =BAGOREJO!AM22+KEBAMAN!AW22+KEPUNDUNGAN!W22+'PARIJATAH KULON'!Y22+'PARIJATAH WETAN'!AC22+REJOAGUNG!AF22+SUKOMAJU!AC22+SUKONATAR!T22+SUMBERSARI!AH22+WONOSOBO!AS22 -> 23
D23: PR | E23: =BAGOREJO!AM23+KEBAMAN!AW23+KEPUNDUNGAN!W23+'PARIJATAH KULON'!Y23+'PARIJATAH WETAN'!AC23+REJOAGUNG!AF23+SUKOMAJU!AC23+SUKONATAR!T23+SUMBERSARI!AH23+WONOSOBO!AS23 -> 25
D24: JML | E24: =SUM(E22:E23) -> 48
B25: 3. | C25: Jumlah pengguna hak pilih dalam Daftar Pemilih Khusus (DPK) | D25: LK | E25: =BAGOREJO!AM25+KEBAMAN!AW25+KEPUNDUNGAN!W25+'PARIJATAH KULON'!Y25+'PARIJATAH WETAN'!AC25+REJOAGUNG!AF25+SUKOMAJU!AC25+SUKONATAR!T25+SUMBERSARI!AH25+WONOSOBO!AS25 -> 405
D26: PR | E26: =BAGOREJO!AM26+KEBAMAN!AW26+KEPUNDUNGAN!W26+'PARIJATAH KULON'!Y26+'PARIJATAH WETAN'!AC26+REJOAGUNG!AF26+SUKOMAJU!AC26+SUKONATAR!T26+SUMBERSARI!AH26+WONOSOBO!AS26 -> 510
D27: JML | E27: =SUM(E25:E26) -> 915
B28: 4. | C28: Jumlah Pengguna Hak Pilih (B.1+B.2+B.3) | D28: LK | E28: =E19+E22+E25 -> 28325
D29: PR | E29: =E20+E23+E26 -> 30689
D30: JML | E30: =SUM(E28:E29) -> 59014
A32: II | B32: DATA PENGGUNAAN SURAT SUARA
A33: 1 | B33: Jumlah surat suara yang diterima, termasuk surat suara cadangan 2,5% dari DPT | E33: =BAGOREJO!AM33+KEBAMAN!AW33+KEPUNDUNGAN!W33+'PARIJATAH KULON'!Y33+'PARIJATAH WETAN'!AC33+REJOAGUNG!AF33+SUKOMAJU!AC33+SUKONATAR!T33+SUMBERSARI!AH33+WONOSOBO!AS33 -> 76923
A34: 2 | B34: Jumlah surat suara yang digunakan | E34: =BAGOREJO!AM34+KEBAMAN!AW34+KEPUNDUNGAN!W34+'PARIJATAH KULON'!Y34+'PARIJATAH WETAN'!AC34+REJOAGUNG!AF34+SUKOMAJU!AC34+SUKONATAR!T34+SUMBERSARI!AH34+WONOSOBO!AS34 -> 58997
A35: 3 | B35: Jumlah surat suara dikembalikan oleh pemilih (karena rusak atau keliru coblos) | E35: =BAGOREJO!AM35+KEBAMAN!AW35+KEPUNDUNGAN!W35+'PARIJATAH KULON'!Y35+'PARIJATAH WETAN'!AC35+REJOAGUNG!AF35+SUKOMAJU!AC35+SUKONATAR!T35+SUMBERSARI!AH35+WONOSOBO!AS35 -> 59
A36: 4 | B36: Jumlah surat suara yang tidak digunakan/tidak terpakai, termasuk sisa surat suara cadangan | E36: =E33-(E34+E35) -> 17867
A38: III | B38: DATA PEMILIH DISABILITAS
B39: Jumlah seluruh Pemilih disabilitas yang menggunakan hak pilih | D39: LK | E39: =BAGOREJO!AM39+KEBAMAN!AW39+KEPUNDUNGAN!W39+'PARIJATAH KULON'!Y39+'PARIJATAH WETAN'!AC39+REJOAGUNG!AF39+SUKOMAJU!AC39+SUKONATAR!T39+SUMBERSARI!AH39+WONOSOBO!AS39 -> 20
D40: PR | E40: =BAGOREJO!AM40+KEBAMAN!AW40+KEPUNDUNGAN!W40+'PARIJATAH KULON'!Y40+'PARIJATAH WETAN'!AC40+REJOAGUNG!AF40+SUKOMAJU!AC40+SUKONATAR!T40+SUMBERSARI!AH40+WONOSOBO!AS40 -> 23
D41: JML | E41: =SUM(E39:E40) -> 43
A43: IV | B43: DATA RINCIAN PEROLEHAN SUARA PASANGAN CALON BUPATI DAN WAKIL BUPATI
A44: NOMOR DAN NAMA CALON
B45: 1. | C45: AA. AHMAD NAWARDI | E45: =BAGOREJO!AM45+KEBAMAN!AW45+KEPUNDUNGAN!W45+'PARIJATAH KULON'!Y45+'PARIJATAH WETAN'!AC45+REJOAGUNG!AF45+SUKOMAJU!AC45+SUKONATAR!T45+SUMBERSARI!AH45+WONOSOBO!AS45 -> 4345
B46: 2. | C46: Ir. H. AA LA NYALLA MAHMUD MATTALITI, M.HP. | E46: =BAGOREJO!AM46+KEBAMAN!AW46+KEPUNDUNGAN!W46+'PARIJATAH KULON'!Y46+'PARIJATAH WETAN'!AC46+REJOAGUNG!AF46+SUKOMAJU!AC46+SUKONATAR!T46+SUMBERSARI!AH46+WONOSOBO!AS46 -> 8914
B47: 3. | C47: ABDUL QADIR AMIR HARTONO, S.E., S.H., M.H. | E47: =BAGOREJO!AM47+KEBAMAN!AW47+KEPUNDUNGAN!W47+'PARIJATAH KULON'!Y47+'PARIJATAH WETAN'!AC47+REJOAGUNG!AF47+SUKOMAJU!AC47+SUKONATAR!T47+SUMBERSARI!AH47+WONOSOBO!AS47 -> 3777
B48: 4. | C48: ADILLA AZIS, S.E. | E48: =BAGOREJO!AM48+KEBAMAN!AW48+KEPUNDUNGAN!W48+'PARIJATAH KULON'!Y48+'PARIJATAH WETAN'!AC48+REJOAGUNG!AF48+SUKOMAJU!AC48+SUKONATAR!T48+SUMBERSARI!AH48+WONOSOBO!AS48 -> 6512
B49: 5. | C49: Ir. H. AGUS RAHARDJO, MSc.M. | E49: =BAGOREJO!AM49+KEBAMAN!AW49+KEPUNDUNGAN!W49+'PARIJATAH KULON'!Y49+'PARIJATAH WETAN'!AC49+REJOAGUNG!AF49+SUKOMAJU!AC49+SUKONATAR!T49+SUMBERSARI!AH49+WONOSOBO!AS49 -> 5019
B50: 6. | C50: Drs. AYUB KHAN | E50: =BAGOREJO!AM50+KEBAMAN!AW50+KEPUNDUNGAN!W50+'PARIJATAH KULON'!Y50+'PARIJATAH WETAN'!AC50+REJOAGUNG!AF50+SUKOMAJU!AC50+SUKONATAR!T50+SUMBERSARI!AH50+WONOSOBO!AS50 -> 3117
B51: 7. | C51: BAMBANG HARIANTO | E51: =BAGOREJO!AM51+KEBAMAN!AW51+KEPUNDUNGAN!W51+'PARIJATAH KULON'!Y51+'PARIJATAH WETAN'!AC51+REJOAGUNG!AF51+SUKOMAJU!AC51+SUKONATAR!T51+SUMBERSARI!AH51+WONOSOBO!AS51 -> 785
B52: 8. | C52: CATUR RUDI UTANTO, S.Sos. | E52: =BAGOREJO!AM52+KEBAMAN!AW52+KEPUNDUNGAN!W52+'PARIJATAH KULON'!Y52+'PARIJATAH WETAN'!AC52+REJOAGUNG!AF52+SUKOMAJU!AC52+SUKONATAR!T52+SUMBERSARI!AH52+WONOSOBO!AS52 -> 1045
...

Sheet BAGOREJO
C2: Kecamatan | D2: SRONO
C3: Kabupaten | D3: BANYUWANGI
C4: Provinsi | D4: JAWA TIMUR
C9: Kelurahan | D9: BAGOREJO
A12: I | B12: DATA PEMILIH DAN PENGGUNAAN HAK PILIH | AM12: JUMLAH AKHIR
A13: A | B13: DATA PEMILIH | E13: TPS 001 | F13: TPS 002 | G13: TPS 003 | H13: TPS 004 | I13: TPS 005 | J13: TPS 006 | K13: TPS 007 | L13: TPS 008 | M13: TPS 009 | N13: TPS 010 | O13: TPS 011 | P13: TPS 012 | Q13: TPS 013 | R13: TPS 014 | S13: TPS 015 | T13: TPS 016 | U13: TPS 017 | V13: TPS 018 | W13: TPS 019 | X13: TPS 020 | Y13: TPS 021 | Z13: TPS 022 | AA13: TPS 023 | AB13: TPS 024 | AC13: TPS 025 | AD13: TPS 026 | AE13: TPS 027 | AF13: TPS 028 | AG13: TPS 029 | AH13: TPS 030 | AI13: TPS 031 | AJ13: TPS 032 | AK13: TPS 033 | AL13: TPS 034
B14: Jumlah Pemilih dalam Daftar Pemilih Tetap (DPT) | D14: LK | E14: 156 | F14: 142 | G14: 136 | H14: 143 | I14: 141 | J14: 140 | K14: 150 | L14: 142 | M14: 134 | N14: 148 | O14: 150 | P14: 132 | Q14: 132 | R14: 141 | S14: 148 | T14: 144 | U14: 148 | V14: 141 | W14: 144 | X14: 137 | Y14: 153 | Z14: 149 | AA14: 139 | AB14: 127 | AC14: 138 | AD14: 133 | AE14: 137 | AF14: 142 | AG14: 149 | AH14: 142 | AI14: 153 | AJ14: 134 | AK14: 142 | AL14: 125 | AM14: =SUM(E14:AL14) -> 4812
D15: PR | E15: 132 | F15: 147 | G15: 147 | H15: 138 | I15: 140 | J15: 139 | K15: 142 | L15: 143 | M15: 149 | N15: 139 | O15: 130 | P15: 147 | Q15: 140 | R15: 143 | S15: 137 | T15: 144 | U15: 137 | V15: 150 | W15: 144 | X15: 138 | Y15: 129 | Z15: 132 | AA15: 145 | AB15: 149 | AC15: 149 | AD15: 153 | AE15: 147 | AF15: 146 | AG15: 146 | AH15: 140 | AI15: 130 | AJ15: 142 | AK15: 133 | AL15: 145 | AM15: =SUM(E15:AL15) -> 4812
D16: JML | E16: =SUM(E14:E15) -> 288 | F16: =SUM(F14:F15) -> 289 | G16: =SUM(G14:G15) -> 283 | H16: =SUM(H14:H15) -> 281 | I16: =SUM(I14:I15) -> 281 | J16: =SUM(J14:J15) -> 279 | K16: =SUM(K14:K15) -> 292 | L16: =SUM(L14:L15) -> 285 | ... AL16: =SUM(AL14:AL15) -> 270 | AM16: =SUM(E16:AL16) -> 9624
A18: B | B18: PENGGUNA HAK PILIH
B19: 1. | C19: Jumlah pengguna hak pilih dalam Daftar Pemilih Tetap (DPT) | D19: LK | E19: 103 | F19: 94 | G19: 98 | H19: 91 | I19: 102 | J19: 101 | K19: 90 | L19: 90 | M19: 98 | N19: 106 | O19: 109 | P19: 90 | Q19: 93 | R19: 100 | S19: 102 | T19: 104 | U19: 108 | V19: 107 | W19: 99 | X19: 114 | Y19: 113 | Z19: 120 | AA19: 115 | AB19: 87 | AC19: 100 | AD19: 102 | AE19: 108 | AF19: 103 | AG19: 110 | AH19: 98 | AI19: 109 | AJ19: 93 | AK19: 101 | AL19: 97 | AM19: =SUM(E19:AL19) -> 3455
D20: PR | E20: 103 | F20: 113 | G20: 119 | H20: 93 | I20: 111 | J20: 114 | K20: 109 | L20: 120 | M20: 129 | N20: 111 | O20: 107 | P20: 112 | Q20: 101 | R20: 112 | S20: 103 | T20: 120 | U20: 101 | V20: 120 | W20: 115 | X20: 109 | Y20: 102 | Z20: 117 | AA20: 108 | AB20: 111 | AC20: 114 | AD20: 122 | AE20: 126 | AF20: 114 | AG20: 115 | AH20: 108 | AI20: 103 | AJ20: 109 | AK20: 102 | AL20: 102 | AM20: =SUM(E20:AL20) -> 3775
D21: JML | E21: =SUM(E19:E20) -> 206 | F21: =SUM(F19:F20) -> 207 | G21: =SUM(G19:G20) -> 217 | H21: =SUM(H19:H20) -> 184 | I21: =SUM(I19:I20) -> 213 | J21: =SUM(J19:J20) -> 215 | K21: =SUM(K19:K20) -> 199 | L21: =SUM(L19:L20) -> 210 | ... AL21: =SUM(AL19:AL20) -> 199 | AM21: =SUM(E21:AL21) -> 7230
B22: 2. | C22: Jumlah pengguna hak pilih dalam Daftar Pemilih Tambahan (DPTb) | D22: LK | E22: 0 | F22: 0 | G22: 0 | H22: 0 | I22: 1 | J22: 1 | K22: 0 | L22: 0 | M22: 0 | N22: 0 | O22: 0 | P22: 0 | Q22: 0 | R22: 0 | S22: 0 | T22: 0 | U22: 0 | V22: 0 | W22: 0 | X22: 0 | Y22: 0 | Z22: 0 | AA22: 0 | AB22: 0 | AC22: 0 | AD22: 0 | AE22: 0 | AF22: 0 | AG22: 0 | AH22: 0 | AI22: 0 | AJ22: 0 | AK22: 0 | AL22: 0 | AM22: =SUM(E22:AL22) -> 2
D23: PR | E23: 0 | F23: 0 | G23: 0 | H23: 0 | I23: 0 | J23: 2 | K23: 0 | L23: 0 | M23: 0 | N23: 0 | O23: 1 | P23: 0 | Q23: 0 | R23: 0 | S23: 0 | T23: 0 | U23: 0 | V23: 0 | W23: 0 | X23: 0 | Y23: 0 | Z23: 0 | AA23: 0 | AB23: 0 | AC23: 0 | AD23: 0 | AE23: 0 | AF23: 0 | AG23: 0 | AH23: 0 | AI23: 0 | AJ23: 0 | AK23: 0 | AL23: 0 | AM23: =SUM(E23:AL23) -> 3
D24: JML | E24: =SUM(E22:E23) -> 0 | F24: =SUM(F22:F23) -> 0 | G24: =SUM(G22:G23) -> 0 | H24: =SUM(H22:H23) -> 0 | I24: =SUM(I22:I23) -> 1 | J24: =SUM(J22:J23) -> 3 | K24: =SUM(K22:K23) -> 0 | L24: =SUM(L22:L23) -> 0 | ... AL24: =SUM(AL22:AL23) -> 0 | AM24: =SUM(E24:AL24) -> 5
B25: 3. | C25: Jumlah pengguna hak pilih dalam Daftar Pemilih Khusus (DPK) | D25: LK | E25: 1 | F25: 4 | G25: 1 | H25: 0 | I25: 1 | J25: 4 | K25: 3 | L25: 1 | M25: 1 | N25: 1 | O25: 0 | P25: 1 | Q25: 1 | R25: 1 | S25: 3 | T25: 1 | U25: 1 | V25: 3 | W25: 0 | X25: 2 | Y25: 4 | Z25: 0 | AA25: 2 | AB25: 2 | AC25: 2 | AD25: 0 | AE25: 1 | AF25: 0 | AG25: 0 | AH25: 0 | AI25: 0 | AJ25: 0 | AK25: 0 | AL25: 0 | AM25: =SUM(E25:AL25) -> 41
D26: PR | E26: 1 | F26: 6 | G26: 1 | H26: 0 | I26: 3 | J26: 0 | K26: 3 | L26: 0 | M26: 1 | N26: 2 | O26: 2 | P26: 2 | Q26: 2 | R26: 1 | S26: 5 | T26: 2 | U26: 2 | V26: 2 | W26: 1 | X26: 3 | Y26: 3 | Z26: 2 | AA26: 2 | AB26: 5 | AC26: 1 | AD26: 0 | AE26: 1 | AF26: 0 | AG26: 1 | AH26: 1 | AI26: 2 | AJ26: 0 | AK26: 0 | AL26: 1 | AM26: =SUM(E26:AL26) -> 58
D27: JML | E27: =SUM(E25:E26) -> 2 | F27: =SUM(F25:F26) -> 10 | G27: =SUM(G25:G26) -> 2 | H27: =SUM(H25:H26) -> 0 | I27: =SUM(I25:I26) -> 4 | J27: =SUM(J25:J26) -> 4 | K27: =SUM(K25:K26) -> 6 | L27: =SUM(L25:L26) -> 1 | ... AL27: =SUM(AL25:AL26) -> 1 | AM27: =SUM(E27:AL27) -> 99
B28: 4. | C28: Jumlah Pengguna Hak Pilih (B.1+B.2+B.3) | D28: LK | E28: =SUM(E19,E22,E25) -> 104 | F28: =SUM(F19,F22,F25) -> 98 | G28: =SUM(G19,G22,G25) -> 99 | H28: =SUM(H19,H22,H25) -> 91 | I28: =SUM(I19,I22,I25) -> 104 | J28: =SUM(J19,J22,J25) -> 106 | K28: =SUM(K19,K22,K25) -> 93 | L28: =SUM(L19,L22,L25) -> 91 | ... AL28: =SUM(AL19,AL22,AL25) -> 97 | AM28: =SUM(E28:AL28) -> 3498
D29: PR | E29: =SUM(E20,E23,E26) -> 104 | F29: =SUM(F20,F23,F26) -> 119 | G29: =SUM(G20,G23,G26) -> 120 | H29: =SUM(H20,H23,H26) -> 93 | I29: =SUM(I20,I23,I26) -> 114 | J29: =SUM(J20,J23,J26) -> 116 | K29: =SUM(K20,K23,K26) -> 112 | L29: =SUM(L20,L23,L26) -> 120 | ... AL29: =SUM(AL20,AL23,AL26) -> 103 | AM29: =SUM(E29:AL29) -> 3836
D30: JML | E30: =SUM(E28:E29) -> 208 | F30: =SUM(F28:F29) -> 217 | G30: =SUM(G28:G29) -> 219 | H30: =SUM(H28:H29) -> 184 | I30: =SUM(I28:I29) -> 218 | J30: =SUM(J28:J29) -> 222 | K30: =SUM(K28:K29) -> 205 | L30: =SUM(L28:L29) -> 211 | ... AL30: =SUM(AL28:AL29) -> 200 | AM30: =SUM(E30:AL30) -> 7334
A32: II | B32: DATA PENGGUNAAN SURAT SUARA
A33: 1 | B33: Jumlah surat suara yang diterima, termasuk surat suara cadangan 2,5% dari DPT | E33: 293 | F33: 265 | G33: 289 | H33: 287 | I33: 287 | J33: 285 | K33: 298 | L33: 291 | M33: 289 | N33: 293 | O33: 286 | P33: 285 | Q33: 278 | R33: 290 | S33: 292 | T33: 296 | U33: 291 | V33: 297 | W33: 294 | X33: 291 | Y33: 288 | Z33: 286 | AA33: 290 | AB33: 282 | AC33: 293 | AD33: 292 | AE33: 290 | AF33: 292 | AG33: 301 | AH33: 288 | AI33: 289 | AJ33: 282 | AK33: 281 | AL33: 276 | AM33: =SUM(E33:AL33) -> 9807
A34: 2 | B34: Jumlah surat suara yang digunakan | E34: 208 | F34: 217 | G34: 219 | H34: 184 | I34: 218 | J34: 222 | K34: 205 | L34: 211 | M34: 229 | N34: 220 | O34: 218 | P34: 205 | Q34: 197 | R34: 214 | S34: 213 | T34: 227 | U34: 212 | V34: 232 | W34: 215 | X34: 228 | Y34: 222 | Z34: 239 | AA34: 225 | AB34: 205 | AC34: 217 | AD34: 224 | AE34: 236 | AF34: 217 | AG34: 226 | AH34: 209 | AI34: 214 | AJ34: 202 | AK34: 203 | AL34: 200 | AM34: =SUM(E34:AL34) -> 7333
A35: 3 | B35: Jumlah surat suara dikembalikan oleh pemilih (karena rusak atau keliru coblos) | E35: 0 | F35: 0 | G35: 0 | H35: 0 | I35: 1 | J35: 0 | K35: 2 | L35: 0 | M35: 0 | N35: 0 | O35: 1 | P35: 0 | Q35: 0 | R35: 0 | S35: 0 | T35: 0 | U35: 0 | V35: 0 | W35: 1 | X35: 0 | Y35: 0 | Z35: 0 | AA35: 0 | AB35: 0 | AC35: 0 | AD35: 0 | AE35: 0 | AF35: 0 | AG35: 0 | AH35: 0 | AI35: 0 | AJ35: 0 | AK35: 0 | AL35: 0 | AM35: =SUM(E35:AL35) -> 5
A36: 4 | B36: Jumlah surat suara yang tidak digunakan/tidak terpakai, termasuk sisa surat suara cadangan | E36: =E33-(E34+E35) -> 85 | F36: =F33-(F34+F35) -> 48 | G36: =G33-(G34+G35) -> 70 | H36: =H33-(H34+H35) -> 103 | I36: =I33-(I34+I35) -> 68 | J36: =J33-(J34+J35) -> 63 | K36: =K33-(K34+K35) -> 91 | L36: =L33-(L34+L35) -> 80 | ... AL36: =AL33-(AL34+AL35) -> 76 | AM36: =SUM(E36:AL36) -> 2469
A38: III | B38: DATA PEMILIH DISABILITAS
B39: Jumlah seluruh Pemilih disabilitas yang menggunakan hak pilih | D39: LK | AM39: =SUM(E39:AL39) -> 0
D40: PR | AM40: =SUM(E40:AL40) -> 0
D41: JML | E41: =SUM(E39:E40) -> 0 | F41: =SUM(F39:F40) -> 0 | G41: =SUM(G39:G40) -> 0 | H41: =SUM(H39:H40) -> 0 | I41: =SUM(I39:I40) -> 0 | J41: =SUM(J39:J40) -> 0 | K41: =SUM(K39:K40) -> 0 | L41: =SUM(L39:L40) -> 0 | ... AL41: =SUM(AL39:AL40) -> 0 | AM41: =SUM(E41:AL41) -> 0
A43: IV | B43: DATA RINCIAN PEROLEHAN SUARA PASANGAN CALON BUPATI DAN WAKIL BUPATI
A44: NOMOR DAN NAMA CALON
B45: 1. | C45: AA. AHMAD NAWARDI | E45: 29 | F45: 22 | G45: 27 | H45: 38 | I45: 36 | J45: 29 | K45: 20 | L45: 21 | M45: 18 | N45: 20 | O45: 30 | P45: 20 | Q45: 17 | R45: 25 | S45: 17 | T45: 15 | U45: 13 | V45: 17 | W45: 25 | X45: 12 | Y45: 20 | Z45: 17 | AA45: 22 | AB45: 4 | AC45: 13 | AD45: 22 | AE45: 34 | AF45: 20 | AG45: 22 | AH45: 18 | AI45: 11 | AJ45: 10 | AK45: 11 | AL45: 7 | AM45: =SUM(E45:AL45) -> 682
B46: 2. | C46: Ir. H. AA LA NYALLA MAHMUD MATTALITI, M.HP. | E46: 30 | F46: 35 | G46: 39 | H46: 41 | I46: 48 | J46: 26 | K46: 39 | L46: 32 | M46: 35 | N46: 32 | O46: 31 | P46: 45 | Q46: 27 | R46: 25 | S46: 31 | T46: 33 | U46: 24 | V46: 41 | W46: 22 | X46: 23 | Y46: 31 | Z46: 27 | AA46: 19 | AB46: 29 | AC46: 20 | AD46: 17 | AE46: 35 | AF46: 30 | AG46: 42 | AH46: 23 | AI46: 23 | AJ46: 27 | AK46: 35 | AL46: 35 | AM46: =SUM(E46:AL46) -> 1052
B47: 3. | C47: ABDUL QADIR AMIR HARTONO, S.E., S.H., M.H. | E47: 12 | F47: 15 | G47: 13 | H47: 9 | I47: 11 | J47: 14 | K47: 17 | L47: 12 | M47: 14 | N47: 18 | O47: 11 | P47: 13 | Q47: 17 | R47: 19 | S47: 11 | T47: 17 | U47: 11 | V47: 13 | W47: 10 | X47: 15 | Y47: 20 | Z47: 12 | AA47: 18 | AB47: 11 | AC47: 10 | AD47: 14 | AE47: 12 | AF47: 18 | AG47: 10 | AH47: 11 | AI47: 13 | AJ47: 14 | AK47: 14 | AL47: 18 | AM47: =SUM(E47:AL47) -> 467
B48: 4. | C48: ADILLA AZIS, S.E. | E48: 18 | F48: 20 | G48: 21 | H48: 13 | I48: 19 | J48: 28 | K48: 15 | L48: 23 | M48: 26 | N48: 19 | O48: 16 | P48: 14 | Q48: 14 | R48: 22 | S48: 23 | T48: 20 | U48: 17 | V48: 25 | W48: 21 | X48: 26 | Y48: 25 | Z48: 23 | AA48: 28 | AB48: 25 | AC48: 18 | AD48: 17 | AE48: 16 | AF48: 13 | AG48: 10 | AH48: 19 | AI48: 13 | AJ48: 18 | AK48: 29 | AL48: 19 | AM48: =SUM(E48:AL48) -> 673
B49: 5. | C49: Ir. H. AGUS RAHARDJO, MSc.M. | E49: 18 | F49: 22 | G49: 14 | H49: 18 | I49: 27 | J49: 18 | K49: 20 | L49: 13 | M49: 16 | N49: 13 | O49: 15 | P49: 14 | Q49: 15 | R49: 19 | S49: 11 | T49: 34 | U49: 36 | V49: 17 | W49: 22 | X49: 25 | Y49: 20 | Z49: 25 | AA49: 31 | AB49: 19 | AC49: 28 | AD49: 18 | AE49: 17 | AF49: 13 | AG49: 15 | AH49: 31 | AI49: 30 | AJ49: 36 | AK49: 22 | AL49: 23 | AM49: =SUM(E49:AL49) -> 715
B50: 6. | C50: Drs. AYUB KHAN | E50: 10 | F50: 5 | G50: 16 | H50: 7 | I50: 12 | J50: 20 | K50: 17 | L50: 12 | M50: 7 | N50: 19 | O50: 10 | P50: 16 | Q50: 15 | R50: 11 | S50: 11 | T50: 8 | U50: 8 | V50: 12 | W50: 16 | X50: 12 | Y50: 11 | Z50: 10 | AA50: 10 | AB50: 18 | AC50: 8 | AD50: 9 | AE50: 10 | AF50: 13 | AG50: 11 | AH50: 10 | AI50: 7 | AJ50: 10 | AK50: 12 | AL50: 8 | AM50: =SUM(E50:AL50) -> 391
B51: 7. | C51: BAMBANG HARIANTO | E51: 2 | F51: 4 | G51: 3 | H51: 1 | I51: 2 | J51: 2 | K51: 4 | L51: 2 | M51: 3 | N51: 2 | O51: 4 | P51: 3 | Q51: 0 | R51: 0 | S51: 6 | T51: 4 | U51: 2 | V51: 1 | W51: 3 | X51: 3 | Y51: 5 | Z51: 2 | AA51: 1 | AB51: 4 | AC51: 2 | AD51: 3 | AE51: 1 | AF51: 1 | AG51: 2 | AH51: 3 | AI51: 4 | AJ51: 2 | AK51: 3 | AL51: 4 | AM51: =SUM(E51:AL51) -> 88
...

Sheet WONOSOBO
C2: Kecamatan | D2: SRONO
C3: Kabupaten | D3: BANYUWANGI
C4: Provinsi | D4: JAWA TIMUR
C9: Kelurahan | D9: WONOSOBO
A12: I | B12: DATA PEMILIH DAN PENGGUNAAN HAK PILIH | AS12: JUMLAH AKHIR
A13: A | B13: DATA PEMILIH | E13: TPS 001 | F13: TPS 002 | G13: TPS 003 | H13: TPS 004 | I13: TPS 005 | J13: TPS 006 | K13: TPS 007 | L13: TPS 008 | M13: TPS 009 | N13: TPS 010 | O13: TPS 011 | P13: TPS 012 | Q13: TPS 013 | R13: TPS 014 | S13: TPS 015 | T13: TPS 016 | U13: TPS 017 | V13: TPS 018 | W13: TPS 019 | X13: TPS 020 | Y13: TPS 021 | Z13: TPS 022 | AA13: TPS 023 | AB13: TPS 024 | AC13: TPS 025 | AD13: TPS 026 | AE13: TPS 027 | AF13: TPS 028 | AG13: TPS 029 | AH13: TPS 030 | AI13: TPS 031 | AJ13: TPS 032 | AK13: TPS 033 | AL13: TPS 034 | AM13: TPS 035 | AN13: TPS 036 | AO13: TPS 037 | AP13: TPS 038 | AQ13: TPS 039 | AR13: TPS 040
B14: Jumlah Pemilih dalam Daftar Pemilih Tetap (DPT) | D14: LK | E14: 133 | F14: 143 | G14: 134 | H14: 136 | I14: 129 | J14: 132 | K14: 130 | L14: 132 | M14: 142 | N14: 143 | O14: 149 | P14: 136 | Q14: 145 | R14: 149 | S14: 140 | T14: 136 | U14: 143 | V14: 142 | W14: 126 | X14: 134 | Y14: 144 | Z14: 123 | AA14: 136 | AB14: 131 | AC14: 129 | AD14: 142 | AE14: 135 | AF14: 135 | AG14: 134 | AH14: 144 | AI14: 140 | AJ14: 140 | AK14: 146 | AL14: 124 | AM14: 142 | AN14: 144 | AO14: 138 | AP14: 150 | AQ14: 153 | AR14: 145 | AS14: =SUM(E14:AR14) -> 5529
D15: PR | E15: 134 | F15: 134 | G15: 129 | H15: 127 | I15: 143 | J15: 135 | K15: 123 | L15: 127 | M15: 140 | N15: 147 | O15: 139 | P15: 122 | Q15: 131 | R15: 146 | S15: 150 | T15: 132 | U15: 139 | V15: 137 | W15: 118 | X15: 140 | Y15: 136 | Z15: 143 | AA15: 137 | AB15: 128 | AC15: 128 | AD15: 137 | AE15: 133 | AF15: 126 | AG15: 130 | AH15: 139 | AI15: 144 | AJ15: 144 | AK15: 146 | AL15: 118 | AM15: 145 | AN15: 137 | AO15: 137 | AP15: 147 | AQ15: 142 | AR15: 145 | AS15: =SUM(E15:AR15) -> 5435
D16: JML | E16: =SUM(E14:E15) -> 267 | F16: =SUM(F14:F15) -> 277 | G16: =SUM(G14:G15) -> 263 | H16: =SUM(H14:H15) -> 263 | I16: =SUM(I14:I15) -> 272 | J16: =SUM(J14:J15) -> 267 | K16: =SUM(K14:K15) -> 253 | L16: =SUM(L14:L15) -> 259 | ... AR16: =SUM(AR14:AR15) -> 290 | AS16: =SUM(E16:AR16) -> 10964
A18: B | B18: PENGGUNA HAK PILIH
B19: 1. | C19: Jumlah pengguna hak pilih dalam Daftar Pemilih Tetap (DPT) | D19: LK | E19: 98 | F19: 108 | G19: 94 | H19: 81 | I19: 92 | J19: 87 | K19: 99 | L19: 98 | M19: 112 | N19: 85 | O19: 99 | P19: 98 | Q19: 83 | R19: 100 | S19: 107 | T19: 96 | U19: 111 | V19: 99 | W19: 97 | X19: 92 | Y19: 105 | Z19: 100 | AA19: 109 | AB19: 99 | AC19: 105 | AD19: 94 | AE19: 103 | AF19: 103 | AG19: 99 | AH19: 107 | AI19: 113 | AJ19: 113 | AK19: 116 | AL19: 105 | AM19: 112 | AN19: 106 | AO19: 111 | AP19: 128 | AQ19: 119 | AR19: 103 | AS19: =SUM(E19:AR19) -> 4086
D20: PR | E20: 113 | F20: 111 | G20: 99 | H20: 90 | I20: 107 | J20: 105 | K20: 98 | L20: 97 | M20: 99 | N20: 101 | O20: 110 | P20: 82 | Q20: 89 | R20: 103 | S20: 124 | T20: 109 | U20: 107 | V20: 109 | W20: 86 | X20: 101 | Y20: 92 | Z20: 113 | AA20: 117 | AB20: 102 | AC20: 107 | AD20: 101 | AE20: 109 | AF20: 105 | AG20: 102 | AH20: 116 | AI20: 121 | AJ20: 126 | AK20: 119 | AL20: 100 | AM20: 114 | AN20: 115 | AO20: 110 | AP20: 123 | AQ20: 122 | AR20: 111 | AS20: =SUM(E20:AR20) -> 4265
D21: JML | E21: =SUM(E19:E20) -> 211 | F21: =SUM(F19:F20) -> 219 | G21: =SUM(G19:G20) -> 193 | H21: =SUM(H19:H20) -> 171 | I21: =SUM(I19:I20) -> 199 | J21: =SUM(J19:J20) -> 192 | K21: =SUM(K19:K20) -> 197 | L21: =SUM(L19:L20) -> 195 | ... AR21: =SUM(AR19:AR20) -> 214 | AS21: =SUM(E21:AR21) -> 8351
B22: 2. | C22: Jumlah pengguna hak pilih dalam Daftar Pemilih Tambahan (DPTb) | D22: LK | E22: 0 | F22: 0 | G22: 0 | H22: 0 | I22: 0 | J22: 0 | K22: 0 | L22: 0 | M22: 0 | N22: 1 | O22: 0 | P22: 0 | Q22: 0 | R22: 0 | S22: 0 | T22: 0 | U22: 1 | V22: 1 | W22: 0 | X22: 0 | Y22: 0 | Z22: 0 | AA22: 0 | AB22: 0 | AC22: 0 | AD22: 0 | AE22: 0 | AF22: 1 | AG22: 0 | AH22: 0 | AI22: 0 | AJ22: 0 | AK22: 0 | AL22: 0 | AM22: 0 | AN22: 0 | AO22: 0 | AP22: 0 | AQ22: 0 | AR22: 1 | AS22: =SUM(E22:AR22) -> 5
D23: PR | E23: 0 | F23: 0 | G23: 0 | H23: 0 | I23: 0 | J23: 0 | K23: 0 | L23: 0 | M23: 0 | N23: 2 | O23: 0 | P23: 0 | Q23: 0 | R23: 0 | S23: 0 | T23: 0 | U23: 1 | V23: 1 | W23: 0 | X23: 0 | Y23: 0 | Z23: 0 | AA23: 0 | AB23: 0 | AC23: 0 | AD23: 0 | AE23: 0 | AF23: 0 | AG23: 0 | AH23: 0 | AI23: 0 | AJ23: 0 | AK23: 0 | AL23: 0 | AM23: 0 | AN23: 0 | AO23: 0 | AP23: 0 | AQ23: 0 | AR23: 0 | AS23: =SUM(E23:AR23) -> 4
D24: JML | E24: =SUM(E22:E23) -> 0 | F24: =SUM(F22:F23) -> 0 | G24: =SUM(G22:G23) -> 0 | H24: =SUM(H22:H23) -> 0 | I24: =SUM(I22:I23) -> 0 | J24: =SUM(J22:J23) -> 0 | K24: =SUM(K22:K23) -> 0 | L24: =SUM(L22:L23) -> 0 | ... AR24: =SUM(AR22:AR23) -> 1 | AS24: =SUM(E24:AR24) -> 9
B25: 3. | C25: Jumlah pengguna hak pilih dalam Daftar Pemilih Khusus (DPK) | D25: LK | E25: 1 | F25: 0 | G25: 2 | H25: 2 | I25: 0 | J25: 0 | K25: 0 | L25: 0 | M25: 0 | N25: 0 | O25: 0 | P25: 0 | Q25: 1 | R25: 2 | S25: 2 | T25: 3 | U25: 3 | V25: 3 | W25: 0 | X25: 0 | Y25: 0 | Z25: 0 | AA25: 0 | AB25: 6 | AC25: 3 | AD25: 1 | AE25: 0 | AF25: 5 | AG25: 0 | AH25: 2 | AI25: 1 | AJ25: 3 | AK25: 2 | AL25: 1 | AM25: 4 | AN25: 0 | AO25: 0 | AP25: 0 | AQ25: 3 | AR25: 0 | AS25: =SUM(E25:AR25) -> 50
D26: PR | E26: 1 | F26: 0 | G26: 5 | H26: 2 | I26: 0 | J26: 1 | K26: 1 | L26: 0 | M26: 0 | N26: 0 | O26: 0 | P26: 0 | Q26: 9 | R26: 0 | S26: 1 | T26: 0 | U26: 5 | V26: 1 | W26: 0 | X26: 1 | Y26: 0 | Z26: 0 | AA26: 1 | AB26: 6 | AC26: 2 | AD26: 1 | AE26: 0 | AF26: 1 | AG26: 0 | AH26: 1 | AI26: 1 | AJ26: 1 | AK26: 2 | AL26: 3 | AM26: 1 | AN26: 0 | AO26: 0 | AP26: 0 | AQ26: 3 | AR26: 0 | AS26: =SUM(E26:AR26) -> 50
D27: JML | E27: =SUM(E25:E26) -> 2 | F27: =SUM(F25:F26) -> 0 | G27: =SUM(G25:G26) -> 7 | H27: =SUM(H25:H26) -> 4 | I27: =SUM(I25:I26) -> 0 | J27: =SUM(J25:J26) -> 1 | K27: =SUM(K25:K26) -> 1 | L27: =SUM(L25:L26) -> 0 | ... AR27: =SUM(AR25:AR26) -> 0 | AS27: =SUM(E27:AR27) -> 100
B28: 4. | C28: Jumlah Pengguna Hak Pilih (B.1+B.2+B.3) | D28: LK | E28: =SUM(E19,E22,E25) -> 99 | F28: =SUM(F19,F22,F25) -> 108 | G28: =SUM(G19,G22,G25) -> 96 | H28: =SUM(H19,H22,H25) -> 83 | I28: =SUM(I19,I22,I25) -> 92 | J28: =SUM(J19,J22,J25) -> 87 | K28: =SUM(K19,K22,K25) -> 99 | L28: =SUM(L19,L22,L25) -> 98 | ... AR28: =SUM(AR19,AR22,AR25) -> 104 | AS28: =SUM(E28:AR28) -> 4141
D29: PR | E29: =SUM(E20,E23,E26) -> 114 | F29: =SUM(F20,F23,F26) -> 111 | G29: =SUM(G20,G23,G26) -> 104 | H29: =SUM(H20,H23,H26) -> 92 | I29: =SUM(I20,I23,I26) -> 107 | J29: =SUM(J20,J23,J26) -> 106 | K29: =SUM(K20,K23,K26) -> 99 | L29: =SUM(L20,L23,L26) -> 97 | ... AR29: =SUM(AR20,AR23,AR26) -> 111 | AS29: =SUM(E29:AR29) -> 4319
D30: JML | E30: =SUM(E28:E29) -> 213 | F30: =SUM(F28:F29) -> 219 | G30: =SUM(G28:G29) -> 200 | H30: =SUM(H28:H29) -> 175 | I30: =SUM(I28:I29) -> 199 | J30: =SUM(J28:J29) -> 193 | K30: =SUM(K28:K29) -> 198 | L30: =SUM(L28:L29) -> 195 | ... AR30: =SUM(AR28:AR29) -> 215 | AS30: =SUM(E30:AR30) -> 8460
A32: II | B32: DATA PENGGUNAAN SURAT SUARA
A33: 1 | B33: Jumlah surat suara yang diterima, termasuk surat suara cadangan 2,5% dari DPT | E33: 273 | F33: 283 | G33: 269 | H33: 269 | I33: 277 | J33: 273 | K33: 259 | L33: 265 | M33: 288 | N33: 296 | O33: 294 | P33: 264 | Q33: 282 | R33: 301 | S33: 298 | T33: 274 | U33: 288 | V33: 285 | W33: 249 | X33: 280 | Y33: 287 | Z33: 263 | AA33: 277 | AB33: 263 | AC33: 263 | AD33: 285 | AE33: 274 | AF33: 288 | AG33: 270 | AH33: 289 | AI33: 290 | AJ33: 289 | AK33: 298 | AL33: 247 | AM33: 293 | AN33: 287 | AO33: 281 | AP33: 302 | AQ33: 303 | AR33: 296 | AS33: =SUM(E33:AR33) -> 11212
A34: 2 | B34: Jumlah surat suara yang digunakan | E34: 213 | F34: 219 | G34: 200 | H34: 175 | I34: 199 | J34: 193 | K34: 198 | L34: 195 | M34: 211 | N34: 189 | O34: 209 | P34: 180 | Q34: 182 | R34: 205 | S34: 234 | T34: 208 | U34: 228 | V34: 213 | W34: 183 | X34: 194 | Y34: 197 | Z34: 213 | AA34: 227 | AB34: 213 | AC34: 217 | AD34: 197 | AE34: 212 | AF34: 216 | AG34: 201 | AH34: 226 | AI34: 236 | AJ34: 243 | AK34: 239 | AL34: 209 | AM34: 231 | AN34: 221 | AO34: 221 | AP34: 251 | AQ34: 247 | AR34: 215 | AS34: =SUM(E34:AR34) -> 8460
A35: 3 | B35: Jumlah surat suara dikembalikan oleh pemilih (karena rusak atau keliru coblos) | E35: 0 | F35: 0 | G35: 0 | H35: 0 | I35: 0 | J35: 0 | K35: 0 | L35: 0 | M35: 1 | N35: 0 | O35: 0 | P35: 0 | Q35: 1 | R35: 0 | S35: 0 | T35: 0 | U35: 0 | V35: 0 | W35: 0 | X35: 0 | Y35: 0 | Z35: 0 | AA35: 1 | AB35: 0 | AC35: 0 | AD35: 0 | AE35: 0 | AF35: 0 | AG35: 3 | AH35: 0 | AI35: 0 | AJ35: 0 | AK35: 0 | AL35: 0 | AM35: 0 | AN35: 0 | AO35: 0 | AP35: 0 | AQ35: 0 | AR35: 0 | AS35: =SUM(E35:AR35) -> 6
A36: 4 | B36: Jumlah surat suara yang tidak digunakan/tidak terpakai, termasuk sisa surat suara cadangan | E36: =E33-(E34+E35) -> 60 | F36: =F33-(F34+F35) -> 64 | G36: =G33-(G34+G35) -> 69 | H36: =H33-(H34+H35) -> 94 | I36: =I33-(I34+I35) -> 78 | J36: =J33-(J34+J35) -> 80 | K36: =K33-(K34+K35) -> 61 | L36: =L33-(L34+L35) -> 70 | ... AR36: =AR33-(AR34+AR35) -> 81 | AS36: =SUM(E36:AR36) -> 2746
A38: III | B38: DATA PEMILIH DISABILITAS
B39: Jumlah seluruh Pemilih disabilitas yang menggunakan hak pilih | D39: LK | E39: 0 | F39: 0 | G39: 0 | H39: 0 | I39: 0 | J39: 0 | K39: 0 | L39: 0 | M39: 0 | N39: 0 | O39: 0 | P39: 0 | Q39: 0 | R39: 0 | S39: 0 | T39: 0 | U39: 2 | V39: 0 | W39: 0 | X39: 0 | Y39: 0 | Z39: 1 | AA39: 0 | AB39: 0 | AC39: 0 | AD39: 0 | AE39: 0 | AF39: 2 | AG39: 0 | AH39: 0 | AI39: 0 | AJ39: 1 | AK39: 0 | AL39: 0 | AM39: 1 | AN39: 0 | AO39: 0 | AP39: 0 | AQ39: 0 | AR39: 0 | AS39: =SUM(E39:AR39) -> 7
D40: PR | E40: 0 | F40: 0 | G40: 0 | H40: 0 | I40: 0 | J40: 1 | K40: 0 | L40: 0 | M40: 0 | N40: 0 | O40: 0 | P40: 0 | Q40: 0 | R40: 0 | S40: 0 | T40: 0 | U40: 1 | V40: 1 | W40: 0 | X40: 0 | Y40: 1 | Z40: 0 | AA40: 0 | AB40: 0 | AC40: 0 | AD40: 0 | AE40: 0 | AF40: 3 | AG40: 0 | AH40: 0 | AI40: 0 | AJ40: 1 | AK40: 0 | AL40: 0 | AM40: 0 | AN40: 0 | AO40: 0 | AP40: 0 | AQ40: 0 | AR40: 0 | AS40: =SUM(E40:AR40) -> 8
D41: JML | E41: =SUM(E39:E40) -> 0 | F41: =SUM(F39:F40) -> 0 | G41: =SUM(G39:G40) -> 0 | H41: =SUM(H39:H40) -> 0 | I41: =SUM(I39:I40) -> 0 | J41: =SUM(J39:J40) -> 1 | K41: =SUM(K39:K40) -> 0 | L41: =SUM(L39:L40) -> 0 | ... AR41: =SUM(AR39:AR40) -> 0 | AS41: =SUM(E41:AR41) -> 15
A43: IV | B43: DATA RINCIAN PEROLEHAN SUARA PASANGAN CALON BUPATI DAN WAKIL BUPATI
A44: NOMOR DAN NAMA CALON
B45: 1. | C45: AA. AHMAD NAWARDI | E45: 6 | F45: 12 | G45: 6 | H45: 5 | I45: 3 | J45: 5 | K45: 5 | L45: 6 | M45: 13 | N45: 10 | O45: 15 | P45: 8 | Q45: 10 | R45: 6 | S45: 15 | T45: 9 | U45: 3 | V45: 13 | W45: 7 | X45: 10 | Y45: 5 | Z45: 11 | AA45: 13 | AB45: 11 | AC45: 9 | AD45: 12 | AE45: 9 | AF45: 10 | AG45: 14 | AH45: 12 | AI45: 11 | AJ45: 15 | AK45: 21 | AL45: 17 | AM45: 21 | AN45: 10 | AO45: 12 | AP45: 12 | AQ45: 11 | AR45: 15 | AS45: =SUM(E45:AR45) -> 418
B46: 2. | C46: Ir. H. AA LA NYALLA MAHMUD MATTALITI, M.HP. | E46: 50 | F46: 53 | G46: 43 | H46: 39 | I46: 35 | J46: 41 | K46: 41 | L46: 36 | M46: 35 | N46: 21 | O46: 42 | P46: 39 | Q46: 25 | R46: 38 | S46: 52 | T46: 30 | U46: 32 | V46: 42 | W46: 43 | X46: 26 | Y46: 41 | Z46: 51 | AA46: 38 | AB46: 43 | AC46: 41 | AD46: 42 | AE46: 30 | AF46: 30 | AG46: 30 | AH46: 33 | AI46: 43 | AJ46: 34 | AK46: 34 | AL46: 29 | AM46: 33 | AN46: 35 | AO46: 19 | AP46: 38 | AQ46: 24 | AR46: 50 | AS46: =SUM(E46:AR46) -> 1481
B47: 3. | C47: ABDUL QADIR AMIR HARTONO, S.E., S.H., M.H. | E47: 9 | F47: 14 | G47: 21 | H47: 18 | I47: 8 | J47: 12 | K47: 15 | L47: 12 | M47: 16 | N47: 13 | O47: 18 | P47: 13 | Q47: 8 | R47: 19 | S47: 16 | T47: 35 | U47: 7 | V47: 12 | W47: 16 | X47: 9 | Y47: 6 | Z47: 17 | AA47: 15 | AB47: 11 | AC47: 6 | AD47: 16 | AE47: 14 | AF47: 11 | AG47: 13 | AH47: 10 | AI47: 14 | AJ47: 21 | AK47: 26 | AL47: 17 | AM47: 27 | AN47: 15 | AO47: 21 | AP47: 14 | AQ47: 18 | AR47: 6 | AS47: =SUM(E47:AR47) -> 589
B48: 4. | C48: ADILLA AZIS, S.E. | E48: 29 | F48: 40 | G48: 18 | H48: 24 | I48: 22 | J48: 34 | K48: 20 | L48: 28 | M48: 22 | N48: 15 | O48: 12 | P48: 21 | Q48: 17 | R48: 25 | S48: 29 | T48: 21 | U48: 28 | V48: 27 | W48: 25 | X48: 20 | Y48: 26 | Z48: 32 | AA48: 23 | AB48: 22 | AC48: 22 | AD48: 20 | AE48: 30 | AF48: 25 | AG48: 22 | AH48: 39 | AI48: 40 | AJ48: 43 | AK48: 26 | AL48: 24 | AM48: 27 | AN48: 25 | AO48: 31 | AP48: 40 | AQ48: 22 | AR48: 17 | AS48: =SUM(E48:AR48) -> 1033
B49: 5. | C49: Ir. H. AGUS RAHARDJO, MSc.M. | E49: 14 | F49: 17 | G49: 17 | H49: 14 | I49: 12 | J49: 15 | K49: 20 | L49: 12 | M49: 18 | N49: 19 | O49: 26 | P49: 18 | Q49: 13 | R49: 20 | S49: 23 | T49: 9 | U49: 17 | V49: 15 | W49: 14 | X49: 6 | Y49: 5 | Z49: 17 | AA49: 22 | AB49: 18 | AC49: 29 | AD49: 9 | AE49: 15 | AF49: 17 | AG49: 18 | AH49: 23 | AI49: 17 | AJ49: 24 | AK49: 18 | AL49: 18 | AM49: 24 | AN49: 14 | AO49: 24 | AP49: 13 | AQ49: 16 | AR49: 16 | AS49: =SUM(E49:AR49) -> 676
B50: 6. | C50: Drs. AYUB KHAN | E50: 10 | F50: 7 | G50: 13 | H50: 15 | I50: 13 | J50: 11 | K50: 2 | L50: 7 | M50: 10 | N50: 6 | O50: 17 | P50: 8 | Q50: 13 | R50: 6 | S50: 10 | T50: 8 | U50: 8 | V50: 8 | W50: 8 | X50: 15 | Y50: 9 | Z50: 11 | AA50: 18 | AB50: 16 | AC50: 15 | AD50: 6 | AE50: 9 | AF50: 11 | AG50: 12 | AH50: 5 | AI50: 6 | AJ50: 13 | AK50: 8 | AL50: 7 | AM50: 8 | AN50: 13 | AO50: 8 | AP50: 10 | AQ50: 12 | AR50: 3 | AS50: =SUM(E50:AR50) -> 395
B51: 7. | C51: BAMBANG HARIANTO | E51: 2 | F51: 4 | G51: 6 | H51: 2 | I51: 2 | J51: 2 | K51: 5 | L51: 2 | M51: 1 | N51: 7 | O51: 2 | P51: 3 | Q51: 6 | R51: 3 | S51: 2 | T51: 4 | U51: 5 | V51: 1 | W51: 5 | X51: 1 | Y51: 6 | Z51: 1 | AA51: 3 | AB51: 1 | AC51: 3 | AD51: 0 | AE51: 3 | AF51: 5 | AG51: 0 | AH51: 3 | AI51: 2 | AJ51: 0 | AK51: 1 | AL51: 3 | AM51: 4 | AN51: 5 | AO51: 6 | AP51: 7 | AQ51: 4 | AR51: 8 | AS51: =SUM(E51:AR51) -> 130
...

Sheet SUKONATAR
C2: Kecamatan | D2: SRONO
C3: Kabupaten | D3: BANYUWANGI
C4: Provinsi | D4: JAWA TIMUR
C9: Kelurahan | D9: SUKONATAR
A12: I | B12: DATA PEMILIH DAN PENGGUNAAN HAK PILIH | T12: JUMLAH AKHIR
A13: A | B13: DATA PEMILIH | E13: TPS 001 | F13: TPS 002 | G13: TPS 003 | H13: TPS 004 | I13: TPS 005 | J13: TPS 006 | K13: TPS 007 | L13: TPS 008 | M13: TPS 009 | N13: TPS 010 | O13: TPS 011 | P13: TPS 012 | Q13: TPS 013 | R13: TPS 014 | S13: TPS 015
B14: Jumlah Pemilih dalam Daftar Pemilih Tetap (DPT) | D14: LK | E14: 142 | F14: 143 | G14: 145 | H14: 130 | I14: 120 | J14: 146 | K14: 134 | L14: 155 | M14: 125 | N14: 127 | O14: 119 | P14: 145 | Q14: 128 | R14: 139 | S14: 136 | T14: =SUM(E14:S14) -> 2034
D15: PR | E15: 138 | F15: 138 | G15: 141 | H15: 118 | I15: 145 | J15: 140 | K15: 132 | L15: 130 | M15: 148 | N15: 124 | O15: 124 | P15: 141 | Q15: 145 | R15: 143 | S15: 137 | T15: =SUM(E15:S15) -> 2044
D16: JML | E16: =SUM(E14:E15) -> 280 | F16: =SUM(F14:F15) -> 281 | G16: =SUM(G14:G15) -> 286 | H16: =SUM(H14:H15) -> 248 | I16: =SUM(I14:I15) -> 265 | J16: =SUM(J14:J15) -> 286 | K16: =SUM(K14:K15) -> 266 | L16: =SUM(L14:L15) -> 285 | ... S16: =SUM(S14:S15) -> 273 | T16: =SUM(E16:S16) -> 4078
A18: B | B18: PENGGUNA HAK PILIH
B19: 1. | C19: Jumlah pengguna hak pilih dalam Daftar Pemilih Tetap (DPT) | D19: LK | E19: 103 | F19: 97 | G19: 92 | H19: 90 | I19: 88 | J19: 116 | K19: 109 | L19: 109 | M19: 94 | N19: 90 | O19: 90 | P19: 114 | Q19: 102 | R19: 105 | S19: 94 | T19: =SUM(E19:S19) -> 1493
D20: PR | E20: 118 | F20: 111 | G20: 110 | H20: 80 | I20: 117 | J20: 112 | K20: 107 | L20: 106 | M20: 113 | N20: 102 | O20: 94 | P20: 122 | Q20: 125 | R20: 118 | S20: 107 | T20: =SUM(E20:S20) -> 1642
D21: JML | E21: =SUM(E19:E20) -> 221 | F21: =SUM(F19:F20) -> 208 | G21: =SUM(G19:G20) -> 202 | H21: =SUM(H19:H20) -> 170 | I21: =SUM(I19:I20) -> 205 | J21: =SUM(J19:J20) -> 228 | K21: =SUM(K19:K20) -> 216 | L21: =SUM(L19:L20) -> 215 | ... S21: =SUM(S19:S20) -> 201 | T21: =SUM(E21:S21) -> 3135
B22: 2. | C22: Jumlah pengguna hak pilih dalam Daftar Pemilih Tambahan (DPTb) | D22: LK | E22: 0 | F22: 0 | G22: 0 | H22: 0 | I22: 0 | J22: 0 | K22: 0 | L22: 0 | M22: 0 | N22: 0 | O22: 0 | P22: 0 | Q22: 0 | R22: 1 | S22: 0 | T22: =SUM(E22:S22) -> 1
D23: PR | E23: 0 | F23: 0 | G23: 0 | H23: 0 | I23: 0 | J23: 0 | K23: 0 | L23: 0 | M23: 0 | N23: 0 | O23: 0 | P23: 0 | Q23: 1 | R23: 1 | S23: 0 | T23: =SUM(E23:S23) -> 2
D24: JML | E24: =SUM(E22:E23) -> 0 | F24: =SUM(F22:F23) -> 0 | G24: =SUM(G22:G23) -> 0 | H24: =SUM(H22:H23) -> 0 | I24: =SUM(I22:I23) -> 0 | J24: =SUM(J22:J23) -> 0 | K24: =SUM(K22:K23) -> 0 | L24: =SUM(L22:L23) -> 0 | ... S24: =SUM(S22:S23) -> 0 | T24: =SUM(E24:S24) -> 3
B25: 3. | C25: Jumlah pengguna hak pilih dalam Daftar Pemilih Khusus (DPK) | D25: LK | E25: 2 | F25: 0 | G25: 1 | H25: 0 | I25: 0 | J25: 0 | K25: 1 | L25: 0 | M25: 2 | N25: 0 | O25: 0 | P25: 0 | Q25: 0 | R25: 0 | S25: 1 | T25: =SUM(E25:S25) -> 7
D26: PR | E26: 3 | F26: 0 | G26: 1 | H26: 1 | I26: 0 | J26: 0 | K26: 1 | L26: 0 | M26: 2 | N26: 0 | O26: 0 | P26: 0 | Q26: 0 | R26: 1 | S26: 1 | T26: =SUM(E26:S26) -> 10
D27: JML | E27: =SUM(E25:E26) -> 5 | F27: =SUM(F25:F26) -> 0 | G27: =SUM(G25:G26) -> 2 | H27: =SUM(H25:H26) -> 1 | I27: =SUM(I25:I26) -> 0 | J27: =SUM(J25:J26) -> 0 | K27: =SUM(K25:K26) -> 2 | L27: =SUM(L25:L26) -> 0 | ... S27: =SUM(S25:S26) -> 2 | T27: =SUM(E27:S27) -> 17
B28: 4. | C28: Jumlah Pengguna Hak Pilih (B.1+B.2+B.3) | D28: LK | E28: =SUM(E19,E22,E25) -> 105 | F28: =SUM(F19,F22,F25) -> 97 | G28: =SUM(G19,G22,G25) -> 93 | H28: =SUM(H19,H22,H25) -> 90 | I28: =SUM(I19,I22,I25) -> 88 | J28: =SUM(J19,J22,J25) -> 116 | K28: =SUM(K19,K22,K25) -> 110 | L28: =SUM(L19,L22,L25) -> 109 | ... S28: =SUM(S19,S22,S25) -> 95 | T28: =SUM(E28:S28) -> 1501
D29: PR | E29: =SUM(E20,E23,E26) -> 121 | F29: =SUM(F20,F23,F26) -> 111 | G29: =SUM(G20,G23,G26) -> 111 | H29: =SUM(H20,H23,H26) -> 81 | I29: =SUM(I20,I23,I26) -> 117 | J29: =SUM(J20,J23,J26) -> 112 | K29: =SUM(K20,K23,K26) -> 108 | L29: =SUM(L20,L23,L26) -> 106 | ... S29: =SUM(S20,S23,S26) -> 108 | T29: =SUM(E29:S29) -> 1654
D30: JML | E30: =SUM(E28:E29) -> 226 | F30: =SUM(F28:F29) -> 208 | G30: =SUM(G28:G29) -> 204 | H30: =SUM(H28:H29) -> 171 | I30: =SUM(I28:I29) -> 205 | J30: =SUM(J28:J29) -> 228 | K30: =SUM(K28:K29) -> 218 | L30: =SUM(L28:L29) -> 215 | ... S30: =SUM(S28:S29) -> 203 | T30: =SUM(E30:S30) -> 3155
A32: II | B32: DATA PENGGUNAAN SURAT SUARA
A33: 1 | B33: Jumlah surat suara yang diterima, termasuk surat suara cadangan 2,5% dari DPT | E33: 286 | F33: 287 | G33: 292 | H33: 253 | I33: 271 | J33: 292 | K33: 272 | L33: 291 | M33: 284 | N33: 257 | O33: 248 | P33: 292 | Q33: 279 | R33: 288 | S33: 279 | T33: =SUM(E33:S33) -> 4171
A34: 2 | B34: Jumlah surat suara yang digunakan | E34: 226 | F34: 208 | G34: 204 | H34: 171 | I34: 205 | J34: 228 | K34: 218 | L34: 215 | M34: 211 | N34: 192 | O34: 184 | P34: 236 | Q34: 227 | R34: 225 | S34: 202 | T34: =SUM(E34:S34) -> 3152
A35: 3 | B35: Jumlah surat suara dikembalikan oleh pemilih (karena rusak atau keliru coblos) | E35: 1 | F35: 0 | G35: 0 | H35: 0 | I35: 0 | J35: 0 | K35: 0 | L35: 0 | M35: 0 | N35: 0 | O35: 0 | P35: 0 | Q35: 0 | R35: 0 | S35: 0 | T35: =SUM(E35:S35) -> 1
A36: 4 | B36: Jumlah surat suara yang tidak digunakan/tidak terpakai, termasuk sisa surat suara cadangan | E36: =E33-(E34+E35) -> 59 | F36: =F33-(F34+F35) -> 79 | G36: =G33-(G34+G35) -> 88 | H36: =H33-(H34+H35) -> 82 | I36: =I33-(I34+I35) -> 66 | J36: =J33-(J34+J35) -> 64 | K36: =K33-(K34+K35) -> 54 | L36: =L33-(L34+L35) -> 76 | ... S36: =S33-(S34+S35) -> 77 | T36: =SUM(E36:S36) -> 1018
A38: III | B38: DATA PEMILIH DISABILITAS
B39: Jumlah seluruh Pemilih disabilitas yang menggunakan hak pilih | D39: LK | E39: 0 | F39: 0 | G39: 0 | H39: 0 | I39: 0 | J39: 0 | K39: 0 | L39: 0 | M39: 0 | N39: 2 | O39: 0 | P39: 0 | Q39: 0 | R39: 0 | S39: 0 | T39: =SUM(E39:S39) -> 2
D40: PR | E40: 0 | F40: 0 | G40: 0 | H40: 0 | I40: 0 | J40: 0 | K40: 0 | L40: 0 | M40: 0 | N40: 2 | O40: 0 | P40: 0 | Q40: 0 | R40: 0 | S40: 0 | T40: =SUM(E40:S40) -> 2
D41: JML | E41: =SUM(E39:E40) -> 0 | F41: =SUM(F39:F40) -> 0 | G41: =SUM(G39:G40) -> 0 | H41: =SUM(H39:H40) -> 0 | I41: =SUM(I39:I40) -> 0 | J41: =SUM(J39:J40) -> 0 | K41: =SUM(K39:K40) -> 0 | L41: =SUM(L39:L40) -> 0 | ... S41: =SUM(S39:S40) -> 0 | T41: =SUM(E41:S41) -> 4
A43: IV | B43: DATA RINCIAN PEROLEHAN SUARA PASANGAN CALON BUPATI DAN WAKIL BUPATI
A44: NOMOR DAN NAMA CALON
B45: 1. | C45: AA. AHMAD NAWARDI | E45: 21 | F45: 8 | G45: 8 | H45: 5 | I45: 10 | J45: 13 | K45: 6 | L45: 14 | M45: 7 | N45: 17 | O45: 30 | P45: 23 | Q45: 25 | R45: 33 | S45: 15 | T45: =SUM(E45:S45) -> 235
B46: 2. | C46: Ir. H. AA LA NYALLA MAHMUD MATTALITI, M.HP. | E46: 66 | F46: 22 | G46: 42 | H46: 37 | I46: 31 | J46: 29 | K46: 40 | L46: 37 | M46: 40 | N46: 38 | O46: 42 | P46: 48 | Q46: 31 | R46: 53 | S46: 35 | T46: =SUM(E46:S46) -> 591
B47: 3. | C47: ABDUL QADIR AMIR HARTONO, S.E., S.H., M.H. | E47: 18 | F47: 12 | G47: 8 | H47: 9 | I47: 5 | J47: 6 | K47: 11 | L47: 14 | M47: 13 | N47: 10 | O47: 8 | P47: 14 | Q47: 9 | R47: 7 | S47: 10 | T47: =SUM(E47:S47) -> 154
B48: 4. | C48: ADILLA AZIS, S.E. | E48: 16 | F48: 25 | G48: 30 | H48: 16 | I48: 26 | J48: 29 | K48: 26 | L48: 17 | M48: 22 | N48: 17 | O48: 14 | P48: 17 | Q48: 22 | R48: 14 | S48: 22 | T48: =SUM(E48:S48) -> 313
B49: 5. | C49: Ir. H. AGUS RAHARDJO, MSc.M. | E49: 17 | F49: 13 | G49: 13 | H49: 12 | I49: 19 | J49: 22 | K49: 18 | L49: 18 | M49: 11 | N49: 14 | O49: 11 | P49: 13 | Q49: 13 | R49: 17 | S49: 10 | T49: =SUM(E49:S49) -> 221
B50: 6. | C50: Drs. AYUB KHAN | E50: 13 | F50: 10 | G50: 14 | H50: 10 | I50: 15 | J50: 9 | K50: 7 | L50: 9 | M50: 5 | N50: 13 | O50: 14 | P50: 14 | Q50: 16 | R50: 14 | S50: 10 | T50: =SUM(E50:S50) -> 173
B51: 7. | C51: BAMBANG HARIANTO | E51: 1 | F51: 0 | G51: 3 | H51: 3 | I51: 2 | J51: 2 | K51: 6 | L51: 3 | M51: 2 | N51: 3 | O51: 4 | P51: 2 | Q51: 6 | R51: 2 | S51: 8 | T51: =SUM(E51:S51) -> 47
...

Sheet KEBAMAN
C2: Kecamatan | D2: SRONO
C3: Kabupaten | D3: BANYUWANGI
C4: Provinsi | D4: JAWA TIMUR
C9: Kelurahan | D9: KEBAMAN
A12: I | B12: DATA PEMILIH DAN PENGGUNAAN HAK PILIH | AW12: JUMLAH AKHIR
A13: A | B13: DATA PEMILIH | E13: TPS 001 | F13: TPS 002 | G13: TPS 003 | H13: TPS 004 | I13: TPS 005 | J13: TPS 006 | K13: TPS 007 | L13: TPS 008 | M13: TPS 009 | N13: TPS 010 | O13: TPS 011 | P13: TPS 012 | Q13: TPS 013 | R13: TPS 014 | S13: TPS 015 | T13: TPS 016 | U13: TPS 017 | V13: TPS 018 | W13: TPS 019 | X13: TPS 020 | Y13: TPS 021 | Z13: TPS 022 | AA13: TPS 023 | AB13: TPS 024 | AC13: TPS 025 | AD13: TPS 026 | AE13: TPS 027 | AF13: TPS 028 | AG13: TPS 029 | AH13: TPS 030 | AI13: TPS 031 | AJ13: TPS 032 | AK13: TPS 033 | AL13: TPS 034 | AM13: TPS 035 | AN13: TPS 036 | AO13: TPS 037 | AP13: TPS 038 | AQ13: TPS 039 | AR13: TPS 040 | AS13: TPS 041 | AT13: TPS 042 | AU13: TPS 043 | AV13: TPS 044
B14: Jumlah Pemilih dalam Daftar Pemilih Tetap (DPT) | D14: LK | E14: 122 | F14: 134 | G14: 140 | H14: 123 | I14: 120 | J14: 138 | K14: 136 | L14: 141 | M14: 141 | N14: 117 | O14: 136 | P14: 133 | Q14: 126 | R14: 138 | S14: 134 | T14: 129 | U14: 148 | V14: 127 | W14: 122 | X14: 135 | Y14: 108 | Z14: 124 | AA14: 109 | AB14: 133 | AC14: 129 | AD14: 135 | AE14: 141 | AF14: 127 | AG14: 123 | AH14: 146 | AI14: 111 | AJ14: 117 | AK14: 128 | AL14: 131 | AM14: 138 | AN14: 128 | AO14: 142 | AP14: 140 | AQ14: 141 | AR14: 130 | AS14: 127 | AT14: 131 | AU14: 147 | AV14: 147 | AW14: =SUM(E14:AV14) -> 5773
D15: PR | E15: 129 | F15: 138 | G15: 133 | H15: 132 | I15: 152 | J15: 135 | K15: 129 | L15: 137 | M15: 138 | N15: 144 | O15: 134 | P15: 132 | Q15: 139 | R15: 149 | S15: 131 | T15: 134 | U15: 139 | V15: 141 | W15: 133 | X15: 141 | Y15: 129 | Z15: 133 | AA15: 131 | AB15: 139 | AC15: 138 | AD15: 140 | AE15: 123 | AF15: 145 | AG15: 133 | AH15: 140 | AI15: 102 | AJ15: 131 | AK15: 141 | AL15: 148 | AM15: 136 | AN15: 137 | AO15: 145 | AP15: 147 | AQ15: 138 | AR15: 143 | AS15: 133 | AT15: 133 | AU15: 139 | AV15: 127 | AW15: =SUM(E15:AV15) -> 5991
D16: JML | E16: =SUM(E14:E15) -> 251 | F16: =SUM(F14:F15) -> 272 | G16: =SUM(G14:G15) -> 273 | H16: =SUM(H14:H15) -> 255 | I16: =SUM(I14:I15) -> 272 | J16: =SUM(J14:J15) -> 273 | K16: =SUM(K14:K15) -> 265 | L16: =SUM(L14:L15) -> 278 | ... AV16: =SUM(AV14:AV15) -> 274 | AW16: =SUM(E16:AV16) -> 11764
A18: B | B18: PENGGUNA HAK PILIH
B19: 1. | C19: Jumlah pengguna hak pilih dalam Daftar Pemilih Tetap (DPT) | D19: LK | E19: 87 | F19: 95 | G19: 99 | H19: 89 | I19: 83 | J19: 106 | K19: 95 | L19: 96 | M19: 92 | N19: 87 | O19: 92 | P19: 104 | Q19: 93 | R19: 102 | S19: 96 | T19: 85 | U19: 110 | V19: 104 | W19: 97 | X19: 95 | Y19: 80 | Z19: 97 | AA19: 71 | AB19: 93 | AC19: 104 | AD19: 83 | AE19: 89 | AF19: 90 | AG19: 89 | AH19: 98 | AI19: 83 | AJ19: 87 | AK19: 88 | AL19: 96 | AM19: 91 | AN19: 99 | AO19: 111 | AP19: 108 | AQ19: 114 | AR19: 93 | AS19: 93 | AT19: 110 | AU19: 96 | AV19: 105 | AW19: =SUM(E19:AV19) -> 4175
D20: PR | E20: 105 | F20: 117 | G20: 113 | H20: 112 | I20: 110 | J20: 110 | K20: 99 | L20: 116 | M20: 104 | N20: 105 | O20: 101 | P20: 107 | Q20: 108 | R20: 133 | S20: 102 | T20: 102 | U20: 118 | V20: 121 | W20: 113 | X20: 112 | Y20: 100 | Z20: 103 | AA20: 105 | AB20: 107 | AC20: 113 | AD20: 106 | AE20: 116 | AF20: 116 | AG20: 104 | AH20: 112 | AI20: 81 | AJ20: 98 | AK20: 103 | AL20: 116 | AM20: 111 | AN20: 106 | AO20: 118 | AP20: 110 | AQ20: 111 | AR20: 107 | AS20: 115 | AT20: 107 | AU20: 101 | AV20: 108 | AW20: =SUM(E20:AV20) -> 4782
D21: JML | E21: =SUM(E19:E20) -> 192 | F21: =SUM(F19:F20) -> 212 | G21: =SUM(G19:G20) -> 212 | H21: =SUM(H19:H20) -> 201 | I21: =SUM(I19:I20) -> 193 | J21: =SUM(J19:J20) -> 216 | K21: =SUM(K19:K20) -> 194 | L21: =SUM(L19:L20) -> 212 | ... AV21: =SUM(AV19:AV20) -> 213 | AW21: =SUM(E21:AV21) -> 8957
B22: 2. | C22: Jumlah pengguna hak pilih dalam Daftar Pemilih Tambahan (DPTb) | D22: LK | E22: 0 | F22: 0 | G22: 0 | H22: 0 | I22: 0 | J22: 0 | K22: 0 | L22: 0 | M22: 0 | N22: 0 | O22: 0 | P22: 0 | Q22: 0 | R22: 0 | S22: 0 | T22: 0 | U22: 0 | V22: 0 | W22: 0 | X22: 0 | Y22: 0 | Z22: 0 | AA22: 0 | AB22: 0 | AC22: 1 | AD22: 0 | AE22: 0 | AF22: 0 | AG22: 0 | AH22: 0 | AI22: 0 | AJ22: 0 | AK22: 0 | AL22: 0 | AM22: 1 | AN22: 0 | AO22: 0 | AP22: 0 | AQ22: 0 | AR22: 0 | AS22: 0 | AT22: 0 | AU22: 0 | AV22: 0 | AW22: =SUM(E22:AV22) -> 2
D23: PR | E23: 0 | F23: 0 | G23: 0 | H23: 0 | I23: 0 | J23: 1 | K23: 0 | L23: 0 | M23: 0 | N23: 0 | O23: 0 | P23: 0 | Q23: 0 | R23: 0 | S23: 0 | T23: 0 | U23: 0 | V23: 0 | W23: 0 | X23: 0 | Y23: 0 | Z23: 0 | AA23: 0 | AB23: 0 | AC23: 0 | AD23: 2 | AE23: 0 | AF23: 0 | AG23: 0 | AH23: 0 | AI23: 0 | AJ23: 0 | AK23: 0 | AL23: 0 | AM23: 0 | AN23: 0 | AO23: 0 | AP23: 0 | AQ23: 0 | AR23: 0 | AS23: 0 | AT23: 0 | AU23: 0 | AV23: 0 | AW23: =SUM(E23:AV23) -> 3
D24: JML | E24: =SUM(E22:E23) -> 0 | F24: =SUM(F22:F23) -> 0 | G24: =SUM(G22:G23) -> 0 | H24: =SUM(H22:H23) -> 0 | I24: =SUM(I22:I23) -> 0 | J24: =SUM(J22:J23) -> 1 | K24: =SUM(K22:K23) -> 0 | L24: =SUM(L22:L23) -> 0 | ... AV24: =SUM(AV22:AV23) -> 0 | AW24: =SUM(E24:AV24) -> 5
B25: 3. | C25: Jumlah pengguna hak pilih dalam Daftar Pemilih Khusus (DPK) | D25: LK | E25: 0 | F25: 2 | G25: 0 | H25: 3 | I25: 3 | J25: 1 | K25: 1 | L25: 1 | M25: 1 | N25: 2 | O25: 3 | P25: 0 | Q25: 1 | R25: 1 | S25: 5 | T25: 2 | U25: 2 | V25: 0 | W25: 4 | X25: 4 | Y25: 3 | Z25: 5 | AA25: 4 | AB25: 0 | AC25: 1 | AD25: 3 | AE25: 4 | AF25: 2 | AG25: 7 | AH25: 5 | AI25: 1 | AJ25: 3 | AK25: 0 | AL25: 3 | AM25: 6 | AN25: 3 | AO25: 3 | AP25: 1 | AQ25: 1 | AR25: 1 | AS25: 0 | AT25: 2 | AU25: 1 | AV25: 8 | AW25: =SUM(E25:AV25) -> 103
D26: PR | E26: 0 | F26: 2 | G26: 1 | H26: 4 | I26: 2 | J26: 0 | K26: 1 | L26: 1 | M26: 0 | N26: 5 | O26: 4 | P26: 0 | Q26: 4 | R26: 4 | S26: 3 | T26: 1 | U26: 2 | V26: 3 | W26: 2 | X26: 3 | Y26: 0 | Z26: 3 | AA26: 6 | AB26: 2 | AC26: 3 | AD26: 2 | AE26: 10 | AF26: 3 | AG26: 5 | AH26: 5 | AI26: 1 | AJ26: 4 | AK26: 0 | AL26: 9 | AM26: 3 | AN26: 5 | AO26: 1 | AP26: 2 | AQ26: 3 | AR26: 1 | AS26: 0 | AT26: 2 | AU26: 1 | AV26: 24 | AW26: =SUM(E26:AV26) -> 137
D27: JML | E27: =SUM(E25:E26) -> 0 | F27: =SUM(F25:F26) -> 4 | G27: =SUM(G25:G26) -> 1 | H27: =SUM(H25:H26) -> 7 | I27: =SUM(I25:I26) -> 5 | J27: =SUM(J25:J26) -> 1 | K27: =SUM(K25:K26) -> 2 | L27: =SUM(L25:L26) -> 2 | ... AV27: =SUM(AV25:AV26) -> 32 | AW27: =SUM(E27:AV27) -> 240
B28: 4. | C28: Jumlah Pengguna Hak Pilih (B.1+B.2+B.3) | D28: LK | E28: =SUM(E19,E22,E25) -> 87 | F28: =SUM(F19,F22,F25) -> 97 | G28: =SUM(G19,G22,G25) -> 99 | H28: =SUM(H19,H22,H25) -> 92 | I28: =SUM(I19,I22,I25) -> 86 | J28: =SUM(J19,J22,J25) -> 107 | K28: =SUM(K19,K22,K25) -> 96 | L28: =SUM(L19,L22,L25) -> 97 | ... AV28: =SUM(AV19,AV22,AV25) -> 113 | AW28: =SUM(E28:AV28) -> 4280
D29: PR | E29: =SUM(E20,E23,E26) -> 105 | F29: =SUM(F20,F23,F26) -> 119 | G29: =SUM(G20,G23,G26) -> 114 | H29: =SUM(H20,H23,H26) -> 116 | I29: =SUM(I20,I23,I26) -> 112 | J29: =SUM(J20,J23,J26) -> 111 | K29: =SUM(K20,K23,K26) -> 100 | L29: =SUM(L20,L23,L26) -> 117 | ... AV29: =SUM(AV20,AV23,AV26) -> 132 | AW29: =SUM(E29:AV29) -> 4922
D30: JML | E30: =SUM(E28:E29) -> 192 | F30: =SUM(F28:F29) -> 216 | G30: =SUM(G28:G29) -> 213 | H30: =SUM(H28:H29) -> 208 | I30: =SUM(I28:I29) -> 198 | J30: =SUM(J28:J29) -> 218 | K30: =SUM(K28:K29) -> 196 | L30: =SUM(L28:L29) -> 214 | ... AV30: =SUM(AV28:AV29) -> 245 | AW30: =SUM(E30:AV30) -> 9202
A32: II | B32: DATA PENGGUNAAN SURAT SUARA
A33: 1 | B33: Jumlah surat suara yang diterima, termasuk surat suara cadangan 2,5% dari DPT | E33: 259 | F33: 279 | G33: 277 | H33: 261 | I33: 276 | J33: 278 | K33: 271 | L33: 284 | M33: 285 | N33: 267 | O33: 276 | P33: 271 | Q33: 271 | R33: 293 | S33: 271 | T33: 269 | U33: 293 | V33: 275 | W33: 261 | X33: 281 | Y33: 242 | Z33: 263 | AA33: 245 | AB33: 279 | AC33: 274 | AD33: 256 | AE33: 265 | AF33: 278 | AG33: 262 | AH33: 282 | AI33: 218 | AJ33: 253 | AK33: 275 | AL33: 285 | AM33: 251 | AN33: 272 | AO33: 293 | AP33: 293 | AQ33: 285 | AR33: 289 | AS33: 261 | AT33: 271 | AU33: 292 | AV33: 281 | AW33: =SUM(E33:AV33) -> 11963
A34: 2 | B34: Jumlah surat suara yang digunakan | E34: 192 | F34: 216 | G34: 213 | H34: 208 | I34: 198 | J34: 218 | K34: 196 | L34: 214 | M34: 197 | N34: 199 | O34: 201 | P34: 211 | Q34: 206 | R34: 240 | S34: 206 | T34: 190 | U34: 232 | V34: 228 | W34: 216 | X34: 214 | Y34: 183 | Z34: 208 | AA34: 186 | AB34: 202 | AC34: 220 | AD34: 196 | AE34: 207 | AF34: 211 | AG34: 205 | AH34: 220 | AI34: 166 | AJ34: 192 | AK34: 191 | AL34: 224 | AM34: 211 | AN34: 213 | AO34: 233 | AP34: 222 | AQ34: 225 | AR34: 210 | AS34: 200 | AT34: 215 | AU34: 206 | AV34: 232 | AW34: =SUM(E34:AV34) -> 9173
A35: 3 | B35: Jumlah surat suara dikembalikan oleh pemilih (karena rusak atau keliru coblos) | E35: 0 | F35: 0 | G35: 0 | H35: 0 | I35: 0 | J35: 0 | K35: 1 | L35: 0 | M35: 0 | N35: 0 | O35: 0 | P35: 0 | Q35: 3 | R35: 0 | S35: 0 | T35: 0 | U35: 1 | V35: 0 | W35: 0 | X35: 0 | Y35: 0 | Z35: 0 | AA35: 0 | AB35: 0 | AC35: 0 | AD35: 0 | AE35: 0 | AF35: 1 | AG35: 1 | AH35: 0 | AI35: 0 | AJ35: 0 | AK35: 0 | AL35: 1 | AM35: 0 | AN35: 0 | AO35: 1 | AP35: 0 | AQ35: 8 | AR35: 0 | AS35: 0 | AT35: 0 | AU35: 0 | AV35: 0 | AW35: =SUM(E35:AV35) -> 17
A36: 4 | B36: Jumlah surat suara yang tidak digunakan/tidak terpakai, termasuk sisa surat suara cadangan | E36: =E33-(E34+E35) -> 67 | F36: =F33-(F34+F35) -> 63 | G36: =G33-(G34+G35) -> 64 | H36: =H33-(H34+H35) -> 53 | I36: =I33-(I34+I35) -> 78 | J36: =J33-(J34+J35) -> 60 | K36: =K33-(K34+K35) -> 74 | L36: =L33-(L34+L35) -> 70 | ... AV36: =AV33-(AV34+AV35) -> 49 | AW36: =SUM(E36:AV36) -> 2773
A38: III | B38: DATA PEMILIH DISABILITAS
B39: Jumlah seluruh Pemilih disabilitas yang menggunakan hak pilih | D39: LK | T39: 0 | U39: 0 | V39: 0 | W39: 0 | X39: 0 | Y39: 0 | Z39: 0 | AA39: 0 | AB39: 0 | AC39: 0 | AD39: 0 | AE39: 0 | AF39: 0 | AG39: 0 | AH39: 0 | AI39: 0 | AJ39: 0 | AK39: 0 | AL39: 0 | AM39: 0 | AN39: 0 | AO39: 0 | AP39: 0 | AQ39: 0 | AR39: 0 | AS39: 0 | AT39: 0 | AU39: 0 | AV39: 0 | AW39: =SUM(E39:AV39) -> 0
D40: PR | E40: 3 | P40: 2 | T40: 0 | U40: 0 | V40: 0 | W40: 0 | X40: 0 | Y40: 0 | Z40: 0 | AA40: 0 | AB40: 0 | AC40: 0 | AD40: 0 | AE40: 0 | AF40: 0 | AG40: 3 | AH40: 0 | AI40: 0 | AJ40: 0 | AK40: 0 | AL40: 0 | AM40: 0 | AN40: 0 | AO40: 0 | AP40: 0 | AQ40: 0 | AR40: 0 | AS40: 0 | AT40: 0 | AU40: 0 | AV40: 0 | AW40: =SUM(E40:AV40) -> 8
D41: JML | E41: =SUM(E39:E40) -> 3 | F41: =SUM(F39:F40) -> 0 | G41: =SUM(G39:G40) -> 0 | H41: =SUM(H39:H40) -> 0 | I41: =SUM(I39:I40) -> 0 | J41: =SUM(J39:J40) -> 0 | K41: =SUM(K39:K40) -> 0 | L41: =SUM(L39:L40) -> 0 | ... AV41: =SUM(AV39:AV40) -> 0 | AW41: =SUM(E41:AV41) -> 8
A43: IV | B43: DATA RINCIAN PEROLEHAN SUARA PASANGAN CALON BUPATI DAN WAKIL BUPATI
A44: NOMOR DAN NAMA CALON
B45: 1. | C45: AA. AHMAD NAWARDI | E45: 10 | F45: 12 | G45: 14 | H45: 10 | I45: 29 | J45: 26 | K45: 7 | L45: 10 | M45: 11 | N45: 6 | O45: 7 | P45: 14 | Q45: 12 | R45: 6 | S45: 16 | T45: 4 | U45: 20 | V45: 19 | W45: 21 | X45: 14 | Y45: 10 | Z45: 3 | AA45: 12 | AB45: 14 | AC45: 22 | AD45: 6 | AE45: 8 | AF45: 15 | AG45: 9 | AH45: 13 | AI45: 15 | AJ45: 11 | AK45: 13 | AL45: 19 | AM45: 22 | AN45: 16 | AO45: 13 | AP45: 8 | AQ45: 25 | AR45: 15 | AS45: 13 | AT45: 10 | AU45: 5 | AV45: 13 | AW45: =SUM(E45:AV45) -> 578
B46: 2. | C46: Ir. H. AA LA NYALLA MAHMUD MATTALITI, M.HP. | E46: 36 | F46: 41 | G46: 41 | H46: 47 | I46: 34 | J46: 38 | K46: 43 | L46: 41 | M46: 59 | N46: 42 | O46: 30 | P46: 48 | Q46: 36 | R46: 41 | S46: 27 | T46: 22 | U46: 27 | V46: 34 | W46: 32 | X46: 27 | Y46: 25 | Z46: 25 | AA46: 25 | AB46: 33 | AC46: 23 | AD46: 39 | AE46: 27 | AF46: 20 | AG46: 40 | AH46: 34 | AI46: 28 | AJ46: 37 | AK46: 35 | AL46: 43 | AM46: 36 | AN46: 34 | AO46: 30 | AP46: 36 | AQ46: 19 | AR46: 32 | AS46: 25 | AT46: 37 | AU46: 28 | AV46: 37 | AW46: =SUM(E46:AV46) -> 1494
B47: 3. | C47: ABDUL QADIR AMIR HARTONO, S.E., S.H., M.H. | E47: 17 | F47: 10 | G47: 14 | H47: 15 | I47: 8 | J47: 12 | K47: 6 | L47: 13 | M47: 11 | N47: 10 | O47: 5 | P47: 13 | Q47: 6 | R47: 19 | S47: 15 | T47: 16 | U47: 10 | V47: 7 | W47: 19 | X47: 13 | Y47: 9 | Z47: 7 | AA47: 11 | AB47: 7 | AC47: 14 | AD47: 6 | AE47: 14 | AF47: 12 | AG47: 9 | AH47: 10 | AI47: 14 | AJ47: 12 | AK47: 8 | AL47: 16 | AM47: 11 | AN47: 11 | AO47: 30 | AP47: 14 | AQ47: 16 | AR47: 12 | AS47: 7 | AT47: 16 | AU47: 7 | AV47: 9 | AW47: =SUM(E47:AV47) -> 521
B48: 4. | C48: ADILLA AZIS, S.E. | E48: 23 | F48: 21 | G48: 20 | H48: 25 | I48: 18 | J48: 18 | K48: 16 | L48: 20 | M48: 18 | N48: 14 | O48: 20 | P48: 18 | Q48: 23 | R48: 22 | S48: 26 | T48: 20 | U48: 32 | V48: 22 | W48: 18 | X48: 21 | Y48: 13 | Z48: 21 | AA48: 18 | AB48: 16 | AC48: 16 | AD48: 19 | AE48: 20 | AF48: 25 | AG48: 19 | AH48: 24 | AI48: 20 | AJ48: 26 | AK48: 17 | AL48: 18 | AM48: 26 | AN48: 24 | AO48: 19 | AP48: 15 | AQ48: 18 | AR48: 19 | AS48: 27 | AT48: 17 | AU48: 16 | AV48: 32 | AW48: =SUM(E48:AV48) -> 900
B49: 5. | C49: Ir. H. AGUS RAHARDJO, MSc.M. | E49: 13 | F49: 19 | G49: 19 | H49: 25 | I49: 10 | J49: 14 | K49: 34 | L49: 14 | M49: 7 | N49: 12 | O49: 15 | P49: 20 | Q49: 11 | R49: 20 | S49: 17 | T49: 25 | U49: 19 | V49: 21 | W49: 17 | X49: 12 | Y49: 25 | Z49: 30 | AA49: 13 | AB49: 17 | AC49: 17 | AD49: 23 | AE49: 9 | AF49: 16 | AG49: 13 | AH49: 24 | AI49: 13 | AJ49: 24 | AK49: 11 | AL49: 17 | AM49: 17 | AN49: 20 | AO49: 21 | AP49: 10 | AQ49: 21 | AR49: 17 | AS49: 15 | AT49: 8 | AU49: 16 | AV49: 21 | AW49: =SUM(E49:AV49) -> 762
B50: 6. | C50: Drs. AYUB KHAN | E50: 13 | F50: 6 | G50: 12 | H50: 13 | I50: 13 | J50: 9 | K50: 13 | L50: 13 | M50: 13 | N50: 6 | O50: 9 | P50: 3 | Q50: 7 | R50: 12 | S50: 12 | T50: 8 | U50: 15 | V50: 24 | W50: 14 | X50: 12 | Y50: 14 | Z50: 13 | AA50: 11 | AB50: 19 | AC50: 19 | AD50: 8 | AE50: 9 | AF50: 14 | AG50: 9 | AH50: 10 | AI50: 6 | AJ50: 9 | AK50: 5 | AL50: 20 | AM50: 11 | AN50: 9 | AO50: 23 | AP50: 12 | AQ50: 19 | AR50: 11 | AS50: 10 | AT50: 5 | AU50: 4 | AV50: 11 | AW50: =SUM(E50:AV50) -> 508
B51: 7. | C51: BAMBANG HARIANTO | E51: 3 | F51: 2 | G51: 1 | H51: 1 | I51: 3 | J51: 1 | K51: 3 | L51: 3 | M51: 1 | N51: 5 | O51: 5 | P51: 4 | Q51: 4 | R51: 3 | S51: 1 | T51: 2 | U51: 1 | V51: 0 | W51: 2 | X51: 1 | Y51: 1 | Z51: 2 | AA51: 5 | AB51: 3 | AC51: 2 | AD51: 3 | AE51: 4 | AF51: 2 | AG51: 4 | AH51: 1 | AI51: 2 | AJ51: 4 | AK51: 1 | AL51: 2 | AM51: 0 | AN51: 3 | AO51: 7 | AP51: 6 | AQ51: 2 | AR51: 6 | AS51: 2 | AT51: 2 | AU51: 2 | AV51: 4 | AW51: =SUM(E51:AV51) -> 116
...

Sheet SUMBERSARI
C2: Kecamatan | D2: SRONO
C3: Kabupaten | D3: BANYUWANGI
C4: Provinsi | D4: JAWA TIMUR
C9: Kelurahan | D9: SUMBERSARI
A12: I | B12: DATA PEMILIH DAN PENGGUNAAN HAK PILIH | AH12: JUMLAH AKHIR
A13: A | B13: DATA PEMILIH | E13: TPS 001 | F13: TPS 002 | G13: TPS 003 | H13: TPS 004 | I13: TPS 005 | J13: TPS 006 | K13: TPS 007 | L13: TPS 008 | M13: TPS 009 | N13: TPS 010 | O13: TPS 011 | P13: TPS 012 | Q13: TPS 013 | R13: TPS 014 | S13: TPS 015 | T13: TPS 016 | U13: TPS 017 | V13: TPS 018 | W13: TPS 019 | X13: TPS 020 | Y13: TPS 021 | Z13: TPS 022 | AA13: TPS 023 | AB13: TPS 024 | AC13: TPS 025 | AD13: TPS 026 | AE13: TPS 027 | AF13: TPS 028 | AG13: TPS 029
B14: Jumlah Pemilih dalam Daftar Pemilih Tetap (DPT) | D14: LK | E14: 147 | F14: 147 | G14: 148 | H14: 148 | I14: 133 | J14: 145 | K14: 143 | L14: 127 | M14: 135 | N14: 137 | O14: 145 | P14: 148 | Q14: 151 | R14: 147 | S14: 151 | T14: 141 | U14: 129 | V14: 143 | W14: 141 | X14: 134 | Y14: 144 | Z14: 147 | AA14: 131 | AB14: 140 | AC14: 146 | AD14: 137 | AE14: 137 | AF14: 117 | AG14: 71 | AH14: =SUM(E14:AG14) -> 4010
D15: PR | E15: 132 | F15: 131 | G15: 143 | H15: 148 | I15: 146 | J15: 137 | K15: 138 | L15: 130 | M15: 149 | N15: 137 | O15: 153 | P15: 149 | Q15: 139 | R15: 150 | S15: 139 | T15: 152 | U15: 145 | V15: 127 | W15: 132 | X15: 139 | Y15: 148 | Z15: 135 | AA15: 141 | AB15: 136 | AC15: 140 | AD15: 133 | AE15: 139 | AF15: 94 | AG15: 75 | AH15: =SUM(E15:AG15) -> 3957
D16: JML | E16: =SUM(E14:E15) -> 279 | F16: =SUM(F14:F15) -> 278 | G16: =SUM(G14:G15) -> 291 | H16: =SUM(H14:H15) -> 296 | I16: =SUM(I14:I15) -> 279 | J16: =SUM(J14:J15) -> 282 | K16: =SUM(K14:K15) -> 281 | L16: =SUM(L14:L15) -> 257 | ... AG16: =SUM(AG14:AG15) -> 146 | AH16: =SUM(E16:AG16) -> 7967
A18: B | B18: PENGGUNA HAK PILIH
B19: 1. | C19: Jumlah pengguna hak pilih dalam Daftar Pemilih Tetap (DPT) | D19: LK | E19: 115 | F19: 109 | G19: 124 | H19: 112 | I19: 102 | J19: 101 | K19: 107 | L19: 87 | M19: 104 | N19: 101 | O19: 104 | P19: 95 | Q19: 95 | R19: 113 | S19: 103 | T19: 107 | U19: 94 | V19: 110 | W19: 113 | X19: 102 | Y19: 107 | Z19: 108 | AA19: 96 | AB19: 104 | AC19: 113 | AD19: 101 | AE19: 102 | AF19: 88 | AG19: 53 | AH19: =SUM(E19:AG19) -> 2970
D20: PR | E20: 109 | F20: 104 | G20: 120 | H20: 123 | I20: 116 | J20: 106 | K20: 109 | L20: 106 | M20: 121 | N20: 108 | O20: 122 | P20: 122 | Q20: 106 | R20: 130 | S20: 106 | T20: 117 | U20: 122 | V20: 108 | W20: 111 | X20: 112 | Y20: 124 | Z20: 102 | AA20: 104 | AB20: 113 | AC20: 115 | AD20: 105 | AE20: 117 | AF20: 71 | AG20: 60 | AH20: =SUM(E20:AG20) -> 3189
D21: JML | E21: =SUM(E19:E20) -> 224 | F21: =SUM(F19:F20) -> 213 | G21: =SUM(G19:G20) -> 244 | H21: =SUM(H19:H20) -> 235 | I21: =SUM(I19:I20) -> 218 | J21: =SUM(J19:J20) -> 207 | K21: =SUM(K19:K20) -> 216 | L21: =SUM(L19:L20) -> 193 | ... AG21: =SUM(AG19:AG20) -> 113 | AH21: =SUM(E21:AG21) -> 6159
B22: 2. | C22: Jumlah pengguna hak pilih dalam Daftar Pemilih Tambahan (DPTb) | D22: LK | E22: 0 | F22: 0 | G22: 0 | H22: 0 | I22: 0 | J22: 0 | K22: 0 | L22: 0 | M22: 0 | N22: 0 | O22: 0 | P22: 0 | Q22: 0 | R22: 0 | S22: 0 | T22: 0 | U22: 0 | V22: 0 | W22: 0 | X22: 0 | Y22: 0 | Z22: 1 | AA22: 0 | AB22: 0 | AC22: 0 | AD22: 0 | AE22: 0 | AF22: 0 | AG22: 0 | AH22: =SUM(E22:AG22) -> 1
D23: PR | E23: 0 | F23: 0 | G23: 0 | H23: 0 | I23: 0 | J23: 0 | K23: 0 | L23: 0 | M23: 0 | N23: 0 | O23: 1 | P23: 0 | Q23: 3 | R23: 0 | S23: 0 | T23: 0 | U23: 0 | V23: 0 | W23: 0 | X23: 0 | Y23: 0 | Z23: 0 | AA23: 0 | AB23: 0 | AC23: 0 | AD23: 0 | AE23: 0 | AF23: 0 | AG23: 0 | AH23: =SUM(E23:AG23) -> 4
D24: JML | E24: =SUM(E22:E23) -> 0 | F24: =SUM(F22:F23) -> 0 | G24: =SUM(G22:G23) -> 0 | H24: =SUM(H22:H23) -> 0 | I24: =SUM(I22:I23) -> 0 | J24: =SUM(J22:J23) -> 0 | K24: =SUM(K22:K23) -> 0 | L24: =SUM(L22:L23) -> 0 | ... AG24: =SUM(AG22:AG23) -> 0 | AH24: =SUM(E24:AG24) -> 5
B25: 3. | C25: Jumlah pengguna hak pilih dalam Daftar Pemilih Khusus (DPK) | D25: LK | E25: 1 | F25: 1 | G25: 0 | H25: 5 | I25: 0 | J25: 5 | K25: 1 | L25: 2 | M25: 0 | N25: 1 | O25: 0 | P25: 0 | Q25: 1 | R25: 0 | S25: 1 | T25: 5 | U25: 6 | V25: 1 | W25: 0 | X25: 2 | Y25: 0 | Z25: 1 | AA25: 1 | AB25: 2 | AC25: 0 | AD25: 2 | AE25: 2 | AF25: 2 | AG25: 0 | AH25: =SUM(E25:AG25) -> 42
D26: PR | E26: 4 | F26: 1 | G26: 3 | H26: 1 | I26: 1 | J26: 2 | K26: 0 | L26: 1 | M26: 3 | N26: 2 | O26: 0 | P26: 0 | Q26: 8 | R26: 0 | S26: 5 | T26: 7 | U26: 2 | V26: 5 | W26: 2 | X26: 5 | Y26: 0 | Z26: 3 | AA26: 5 | AB26: 3 | AC26: 0 | AD26: 4 | AE26: 3 | AF26: 1 | AG26: 0 | AH26: =SUM(E26:AG26) -> 71
D27: JML | E27: =SUM(E25:E26) -> 5 | F27: =SUM(F25:F26) -> 2 | G27: =SUM(G25:G26) -> 3 | H27: =SUM(H25:H26) -> 6 | I27: =SUM(I25:I26) -> 1 | J27: =SUM(J25:J26) -> 7 | K27: =SUM(K25:K26) -> 1 | L27: =SUM(L25:L26) -> 3 | ... AG27: =SUM(AG25:AG26) -> 0 | AH27: =SUM(E27:AG27) -> 113
B28: 4. | C28: Jumlah Pengguna Hak Pilih (B.1+B.2+B.3) | D28: LK | E28: =SUM(E19,E22,E25) -> 116 | F28: =SUM(F19,F22,F25) -> 110 | G28: =SUM(G19,G22,G25) -> 124 | H28: =SUM(H19,H22,H25) -> 117 | I28: =SUM(I19,I22,I25) -> 102 | J28: =SUM(J19,J22,J25) -> 106 | K28: =SUM(K19,K22,K25) -> 108 | L28: =SUM(L19,L22,L25) -> 89 | ... AG28: =SUM(AG19,AG22,AG25) -> 53 | AH28: =SUM(E28:AG28) -> 3013
D29: PR | E29: =SUM(E20,E23,E26) -> 113 | F29: =SUM(F20,F23,F26) -> 105 | G29: =SUM(G20,G23,G26) -> 123 | H29: =SUM(H20,H23,H26) -> 124 | I29: =SUM(I20,I23,I26) -> 117 | J29: =SUM(J20,J23,J26) -> 108 | K29: =SUM(K20,K23,K26) -> 109 | L29: =SUM(L20,L23,L26) -> 107 | ... V29: =SUM(V20,V23,V26) -> 113 | W29: 113 | X29: 117 | Y29: 124 | Z29: 105 | AA29: 109 | AB29: 116 | AC29: 115 | AD29: 109 | AE29: 120 | AF29: 72 | AG29: 60 | AH29: =SUM(E29:AG29) -> 3264
D30: JML | E30: =SUM(E28:E29) -> 229 | F30: =SUM(F28:F29) -> 215 | G30: =SUM(G28:G29) -> 247 | H30: =SUM(H28:H29) -> 241 | I30: =SUM(I28:I29) -> 219 | J30: =SUM(J28:J29) -> 214 | K30: =SUM(K28:K29) -> 217 | L30: =SUM(L28:L29) -> 196 | ... AG30: =SUM(AG28:AG29) -> 113 | AH30: =SUM(E30:AG30) -> 6277
A32: II | B32: DATA PENGGUNAAN SURAT SUARA
A33: 1 | B33: Jumlah surat suara yang diterima, termasuk surat suara cadangan 2,5% dari DPT | E33: 285 | F33: 284 | G33: 297 | H33: 303 | I33: 285 | J33: 288 | K33: 288 | L33: 263 | M33: 290 | N33: 280 | O33: 304 | P33: 303 | Q33: 296 | R33: 293 | S33: 286 | T33: 299 | U33: 280 | V33: 276 | W33: 279 | X33: 279 | Y33: 298 | Z33: 288 | AA33: 278 | AB33: 282 | AC33: 292 | AD33: 276 | AE33: 282 | AF33: 216 | AG33: 139 | AH33: =SUM(E33:AG33) -> 8109
