Workbook

Sheet DPD
C8: Kecamatan | D8: BLIMBINGSARI
C9: Kabupaten | D9: BANYUWANGI
C10: Provinsi | D10: JAWA TIMUR
A12: I | B12: DATA PEMILIH DAN PENGGUNAAN HAK PILIH | E12: JUMLAH AKHIR
A13: A | B13: DATA PEMILIH
B14: Jumlah Pemilih dalam Daftar Pemilih Tetap (DPT) | D14: LK | E14: =BADEAN!AB14+BLIMBINGSARI!U14+BOMO!W14+GINTANGAN!Z14+KALIGUNG!R14+KAOTAN!M14+KARANGREJO!P14+PATOMAN!T14+SUKOJATI!P14+WATUKEBO!AK14 -> 21865
D15: PR | E15: =BADEAN!AB15+BLIMBINGSARI!U15+BOMO!W15+GINTANGAN!Z15+KALIGUNG!R15+KAOTAN!M15+KARANGREJO!P15+PATOMAN!T15+SUKOJATI!P15+WATUKEBO!AK15 -> 21891
D16: JML | E16: =SUM(E14:E15) -> 43756
A18: B | B18: PENGGUNA HAK PILIH
B19: 1. | C19: Jumlah pengguna hak pilih dalam Daftar Pemilih Tetap (DPT) | D19: LK | E19: =BADEAN!AB19+BLIMBINGSARI!U19+BOMO!W19+GINTANGAN!Z19+KALIGUNG!R19+KAOTAN!M19+KARANGREJO!P19+PATOMAN!T19+SUKOJATI!P19+WATUKEBO!AK19 -> 16413
D20: PR | E20: =BADEAN!AB20+BLIMBINGSARI!U20+BOMO!W20+GINTANGAN!Z20+KALIGUNG!R20+KAOTAN!M20+KARANGREJO!P20+PATOMAN!T20+SUKOJATI!P20+WATUKEBO!AK20 -> 17835
D21: JML | E21: =SUM(E19:E20) -> 34248
B22: 2. | C22: Jumlah pengguna hak pilih dalam Daftar Pemilih Tambahan (DPTb) | D22: LK | E22: =BADEAN!AB22+BLIMBINGSARI!U22+BOMO!W22+GINTANGAN!Z22+KALIGUNG!R22+KAOTAN!M22+KARANGREJO!P22+PATOMAN!T22+SUKOJATI!P22+WATUKEBO!AK22 -> 101
D23: PR | E23: =BADEAN!AB23+BLIMBINGSARI!U23+BOMO!W23+GINTANGAN!Z23+KALIGUNG!R23+KAOTAN!M23+KARANGREJO!P23+PATOMAN!T23+SUKOJATI!P23+WATUKEBO!AK23 -> 27
D24: JML | E24: =SUM(E22:E23) -> 128
B25: 3. | C25: Jumlah pengguna hak pilih dalam Daftar Pemilih Khusus (DPK) | D25: LK | E25: =BADEAN!AB25+BLIMBINGSARI!U25+BOMO!W25+GINTANGAN!Z25+KALIGUNG!R25+KAOTAN!M25+KARANGREJO!P25+PATOMAN!T25+SUKOJATI!P25+WATUKEBO!AK25 -> 100
D26: PR | E26: =BADEAN!AB26+BLIMBINGSARI!U26+BOMO!W26+GINTANGAN!Z26+KALIGUNG!R26+KAOTAN!M26+KARANGREJO!P26+PATOMAN!T26+SUKOJATI!P26+WATUKEBO!AK26 -> 140
D27: JML | E27: =SUM(E25:E26) -> 240
B28: 4. | C28: Jumlah Pengguna Hak Pilih (B.1+B.2+B.3) | D28: LK | E28: =E19+E22+E25 -> 16614
D29: PR | E29: =E20+E23+E26 -> 18002
D30: JML | E30: =SUM(E28:E29) -> 34616
A32: II | B32: DATA PENGGUNAAN SURAT SUARA
A33: 1 | B33: Jumlah surat suara yang diterima, termasuk surat suara cadangan 2,5% dari DPT | E33: =BADEAN!AB33+BLIMBINGSARI!U33+BOMO!W33+GINTANGAN!Z33+KALIGUNG!R33+KAOTAN!M33+KARANGREJO!P33+PATOMAN!T33+SUKOJATI!P33+WATUKEBO!AK33 -> 44739
A34: 2 | B34: Jumlah surat suara yang digunakan | E34: =BADEAN!AB34+BLIMBINGSARI!U34+BOMO!W34+GINTANGAN!Z34+KALIGUNG!R34+KAOTAN!M34+KARANGREJO!P34+PATOMAN!T34+SUKOJATI!P34+WATUKEBO!AK34 -> 34616
A35: 3 | B35: Jumlah surat suara dikembalikan oleh pemilih (karena rusak atau keliru coblos) | E35: =BADEAN!AB35+BLIMBINGSARI!U35+BOMO!W35+GINTANGAN!Z35+KALIGUNG!R35+KAOTAN!M35+KARANGREJO!P35+PATOMAN!T35+SUKOJATI!P35+WATUKEBO!AK35 -> 131
A36: 4 | B36: Jumlah surat suara yang tidak digunakan/tidak terpakai, termasuk sisa surat suara cadangan | E36: =E33-(E34+E35) -> 9992
A38: III | B38: DATA PEMILIH DISABILITAS
B39: Jumlah seluruh Pemilih disabilitas yang menggunakan hak pilih | D39: LK | E39: =BADEAN!AB39+BLIMBINGSARI!U39+BOMO!W39+GINTANGAN!Z39+KALIGUNG!R39+KAOTAN!M39+KARANGREJO!P39+PATOMAN!T39+SUKOJATI!P39+WATUKEBO!AK39 -> 46
D40: PR | E40: =BADEAN!AB40+BLIMBINGSARI!U40+BOMO!W40+GINTANGAN!Z40+KALIGUNG!R40+KAOTAN!M40+KARANGREJO!P40+PATOMAN!T40+SUKOJATI!P40+WATUKEBO!AK40 -> 48
D41: JML | E41: =SUM(E39:E40) -> 94
A43: IV | B43: DATA RINCIAN PEROLEHAN SUARA PASANGAN CALON BUPATI DAN WAKIL BUPATI
A44: NOMOR DAN NAMA CALON
A45: A.2 | B45: 1. | C45: AA. AHMAD NAWARDI | E45: =BADEAN!AB45+BLIMBINGSARI!U45+BOMO!W45+GINTANGAN!Z45+KALIGUNG!R45+KAOTAN!M45+KARANGREJO!P45+PATOMAN!T45+SUKOJATI!P45+WATUKEBO!AK45 -> 2452
B46: 2. | C46: Ir. H. AA LA NYALLA MAHMUD MATTALITI, M.HP. | E46: =BADEAN!AB46+BLIMBINGSARI!U46+BOMO!W46+GINTANGAN!Z46+KALIGUNG!R46+KAOTAN!M46+KARANGREJO!P46+PATOMAN!T46+SUKOJATI!P46+WATUKEBO!AK46 -> 5449
B47: 3. | C47: ABDUL QADIR AMIR HARTONO, S.E., S.H., M.H. | E47: =BADEAN!AB47+BLIMBINGSARI!U47+BOMO!W47+GINTANGAN!Z47+KALIGUNG!R47+KAOTAN!M47+KARANGREJO!P47+PATOMAN!T47+SUKOJATI!P47+WATUKEBO!AK47 -> 2152
B48: 4. | C48: ADILLA AZIS, S.E. | E48: =BADEAN!AB48+BLIMBINGSARI!U48+BOMO!W48+GINTANGAN!Z48+KALIGUNG!R48+KAOTAN!M48+KARANGREJO!P48+PATOMAN!T48+SUKOJATI!P48+WATUKEBO!AK48 -> 4551
B49: 5. | C49: Ir. H. AGUS RAHARDJO, MSc.M. | E49: =BADEAN!AB49+BLIMBINGSARI!U49+BOMO!W49+GINTANGAN!Z49+KALIGUNG!R49+KAOTAN!M49+KARANGREJO!P49+PATOMAN!T49+SUKOJATI!P49+WATUKEBO!AK49 -> 2250
B50: 6. | C50: Drs. AYUB KHAN | E50: =BADEAN!AB50+BLIMBINGSARI!U50+BOMO!W50+GINTANGAN!Z50+KALIGUNG!R50+KAOTAN!M50+KARANGREJO!P50+PATOMAN!T50+SUKOJATI!P50+WATUKEBO!AK50 -> 2020
B51: 7. | C51: BAMBANG HARIANTO | E51: =BADEAN!AB51+BLIMBINGSARI!U51+BOMO!W51+GINTANGAN!Z51+KALIGUNG!R51+KAOTAN!M51+KARANGREJO!P51+PATOMAN!T51+SUKOJATI!P51+WATUKEBO!AK51 -> 332
B52: 8. | C52: CATUR RUDI UTANTO, S.Sos. | E52: =BADEAN!AB52+BLIMBINGSARI!U52+BOMO!W52+GINTANGAN!Z52+KALIGUNG!R52+KAOTAN!M52+KARANGREJO!P52+PATOMAN!T52+SUKOJATI!P52+WATUKEBO!AK52 -> 544
...

Sheet BADEAN
C2: Kecamatan | D2: BLIMBINGSARI
C3: Kabupaten | D3: BANYUWANGI
C4: Provinsi | D4: JAWA TIMUR
C9: Kelurahan | D9: BADEAN
A12: I | B12: DATA PEMILIH DAN PENGGUNAAN HAK PILIH | AB12: JUMLAH AKHIR
A13: A | B13: DATA PEMILIH | E13: TPS 001 | F13: TPS 002 | G13: TPS 003 | H13: TPS 004 | I13: TPS 005 | J13: TPS 006 | K13: TPS 007 | L13: TPS 008 | M13: TPS 009 | N13: TPS 010 | O13: TPS 011 | P13: TPS 012 | Q13: TPS 013 | R13: TPS 014 | S13: TPS 015 | T13: TPS 016 | U13: TPS 017 | V13: TPS 018 | W13: TPS 019 | X13: TPS 020 | Y13: TPS 021 | Z13: TPS 022 | AA13: TPS 023
B14: Jumlah Pemilih dalam Daftar Pemilih Tetap (DPT) | D14: LK | E14: 135 | F14: 117 | G14: 109 | H14: 108 | I14: 137 | J14: 145 | K14: 122 | L14: 119 | M14: 144 | N14: 134 | O14: 146 | P14: 128 | Q14: 141 | R14: 115 | S14: 85 | T14: 89 | U14: 124 | V14: 120 | W14: 134 | X14: 136 | Y14: 131 | Z14: 125 | AA14: 125 | AB14: =SUM(E14:AA14) -> 2869
D15: PR | E15: 130 | F15: 129 | G15: 141 | H15: 122 | I15: 129 | J15: 134 | K15: 132 | L15: 151 | M15: 131 | N15: 143 | O15: 129 | P15: 126 | Q15: 125 | R15: 114 | S15: 102 | T15: 101 | U15: 129 | V15: 131 | W15: 126 | X15: 122 | Y15: 124 | Z15: 116 | AA15: 114 | AB15: =SUM(E15:AA15) -> 2901
D16: JML | E16: =SUM(E14:E15) -> 265 | F16: =SUM(F14:F15) -> 246 | G16: =SUM(G14:G15) -> 250 | H16: =SUM(H14:H15) -> 230 | I16: =SUM(I14:I15) -> 266 | J16: =SUM(J14:J15) -> 279 | K16: =SUM(K14:K15) -> 254 | L16: =SUM(L14:L15) -> 270 | ... AA16: =SUM(AA14:AA15) -> 239 | AB16: =SUM(E16:AA16) -> 5770
A18: B | B18: PENGGUNA HAK PILIH
B19: 1. | C19: Jumlah pengguna hak pilih dalam Daftar Pemilih Tetap (DPT) | D19: LK | E19: 111 | F19: 99 | G19: 84 | H19: 86 | I19: 104 | J19: 102 | K19: 85 | L19: 72 | M19: 104 | N19: 93 | O19: 106 | P19: 104 | Q19: 93 | R19: 67 | S19: 64 | T19: 55 | U19: 92 | V19: 91 | W19: 100 | X19: 98 | Y19: 100 | Z19: 104 | AA19: 95 | AB19: =SUM(E19:AA19) -> 2109
D20: PR | E20: 114 | F20: 104 | G20: 115 | H20: 98 | I20: 108 | J20: 102 | K20: 120 | L20: 108 | M20: 111 | N20: 110 | O20: 102 | P20: 107 | Q20: 97 | R20: 81 | S20: 81 | T20: 71 | U20: 107 | V20: 112 | W20: 98 | X20: 104 | Y20: 92 | Z20: 101 | AA20: 94 | AB20: =SUM(E20:AA20) -> 2337
D21: JML | E21: 225 | F21: 203 | G21: 199 | H21: 184 | I21: 212 | J21: 204 | K21: 205 | L21: 180 | M21: 215 | N21: 203 | O21: 208 | P21: 211 | Q21: 190 | R21: 148 | S21: 145 | T21: 126 | U21: 199 | V21: 203 | W21: 198 | X21: 202 | Y21: 192 | Z21: 205 | AA21: 189 | AB21: =SUM(E21:AA21) -> 4446
B22: 2. | C22: Jumlah pengguna hak pilih dalam Daftar Pemilih Tambahan (DPTb) | D22: LK | E22: 0 | F22: 0 | G22: 0 | H22: 0 | I22: 0 | J22: 0 | K22: 0 | L22: 0 | M22: 0 | N22: 0 | O22: 1 | P22: 0 | Q22: 0 | R22: 0 | S22: 0 | T22: 0 | U22: 0 | V22: 0 | W22: 0 | X22: 0 | Y22: 0 | Z22: 0 | AA22: 0 | AB22: =SUM(E22:AA22) -> 1
D23: PR | E23: 0 | F23: 0 | G23: 0 | H23: 0 | I23: 0 | J23: 0 | K23: 0 | L23: 0 | M23: 0 | N23: 0 | O23: 0 | P23: 0 | Q23: 0 | R23: 0 | S23: 0 | T23: 0 | U23: 0 | V23: 0 | W23: 0 | X23: 0 | Y23: 0 | Z23: 0 | AA23: 0 | AB23: =SUM(E23:AA23) -> 0
D24: JML | E24: 0 | F24: 0 | G24: 0 | H24: 0 | I24: 0 | J24: 0 | K24: 0 | L24: 0 | M24: 0 | N24: 0 | O24: 1 | P24: 0 | Q24: 0 | R24: 0 | S24: 0 | T24: 0 | U24: 0 | V24: 0 | W24: 0 | X24: 0 | Y24: 0 | Z24: 0 | AA24: 0 | AB24: =SUM(E24:AA24) -> 1
B25: 3. | C25: Jumlah pengguna hak pilih dalam Daftar Pemilih Khusus (DPK) | D25: LK | E25: 0 | F25: 0 | G25: 4 | H25: 0 | I25: 1 | J25: 3 | K25: 1 | L25: 1 | M25: 0 | N25: 3 | O25: 1 | P25: 2 | Q25: 4 | R25: 3 | S25: 0 | T25: 6 | U25: 0 | V25: 4 | W25: 1 | X25: 0 | Y25: 3 | Z25: 3 | AA25: 1 | AB25: =SUM(E25:AA25) -> 41
D26: PR | E26: 0 | F26: 0 | G26: 2 | H26: 0 | I26: 3 | J26: 6 | K26: 0 | L26: 2 | M26: 2 | N26: 1 | O26: 3 | P26: 4 | Q26: 3 | R26: 3 | S26: 0 | T26: 6 | U26: 0 | V26: 2 | W26: 2 | X26: 0 | Y26: 1 | Z26: 0 | AA26: 0 | AB26: =SUM(E26:AA26) -> 40
D27: JML | E27: 0 | F27: 0 | G27: 6 | H27: 0 | I27: 4 | J27: 9 | K27: 1 | L27: 3 | M27: 2 | N27: 4 | O27: 4 | P27: 6 | Q27: 7 | R27: 6 | S27: 0 | T27: 12 | U27: 0 | V27: 6 | W27: 3 | X27: 0 | Y27: 4 | Z27: 3 | AA27: 1 | AB27: =SUM(E27:AA27) -> 81
B28: 4. | C28: Jumlah Pengguna Hak Pilih (B.1+B.2+B.3) | D28: LK | E28: 111 | F28: 99 | G28: 88 | H28: 86 | I28: 105 | J28: 105 | K28: 86 | L28: 73 | M28: 104 | N28: 96 | O28: 108 | P28: 106 | Q28: 97 | R28: 70 | S28: 64 | T28: 61 | U28: 92 | V28: 97 | W28: 101 | X28: 98 | Y28: 104 | Z28: 107 | AA28: 96 | AB28: =SUM(E28:AA28) -> 2154
D29: PR | E29: 114 | F29: 104 | G29: 117 | H29: 98 | I29: 111 | J29: 108 | K29: 120 | L29: 110 | M29: 113 | N29: 111 | O29: 105 | P29: 111 | Q29: 100 | R29: 84 | S29: 81 | T29: 77 | U29: 107 | V29: 114 | W29: 100 | X29: 104 | Y29: 93 | Z29: 101 | AA29: 94 | AB29: =SUM(E29:AA29) -> 2377
D30: JML | E30: =SUM(E28:E29) -> 225 | F30: =SUM(F28:F29) -> 203 | G30: =SUM(G28:G29) -> 205 | H30: =SUM(H28:H29) -> 184 | I30: =SUM(I28:I29) -> 216 | J30: =SUM(J28:J29) -> 213 | K30: =SUM(K28:K29) -> 206 | L30: =SUM(L28:L29) -> 183 | ... AA30: =SUM(AA28:AA29) -> 190 | AB30: =SUM(E30:AA30) -> 4531
A32: II | B32: DATA PENGGUNAAN SURAT SUARA
A33: 1 | B33: Jumlah surat suara yang diterima, termasuk surat suara cadangan 2,5% dari DPT | E33: 271 | F33: 251 | G33: 255 | H33: 235 | I33: 272 | J33: 285 | K33: 260 | L33: 276 | M33: 281 | N33: 283 | O33: 281 | P33: 260 | Q33: 272 | R33: 234 | S33: 191 | T33: 194 | U33: 259 | V33: 257 | W33: 266 | X33: 264 | Y33: 261 | Z33: 246 | AA33: 244 | AB33: =SUM(E33:AA33) -> 5898
A34: 2 | B34: Jumlah surat suara yang digunakan | E34: 225 | F34: 203 | G34: 205 | H34: 184 | I34: 216 | J34: 213 | K34: 206 | L34: 183 | M34: 217 | N34: 207 | O34: 213 | P34: 217 | Q34: 197 | R34: 154 | S34: 145 | T34: 138 | U34: 199 | V34: 209 | W34: 201 | X34: 202 | Y34: 196 | Z34: 208 | AA34: 190 | AB34: =SUM(E34:AA34) -> 4528
A35: 3 | B35: Jumlah surat suara dikembalikan oleh pemilih (karena rusak atau keliru coblos) | E35: 0 | F35: 1 | G35: 0 | H35: 0 | I35: 0 | J35: 6 | K35: 0 | L35: 0 | M35: 0 | N35: 0 | O35: 0 | P35: 1 | Q35: 0 | R35: 0 | S35: 0 | T35: 0 | U35: 0 | V35: 0 | W35: 0 | X35: 0 | Y35: 0 | Z35: 0 | AA35: 0 | AB35: =SUM(E35:AA35) -> 8
A36: 4 | B36: Jumlah surat suara yang tidak digunakan/tidak terpakai, termasuk sisa surat suara cadangan | E36: 46 | F36: 47 | G36: 50 | H36: 51 | I36: 56 | J36: 66 | K36: 54 | L36: 93 | M36: 64 | N36: 76 | O36: 68 | P36: 42 | Q36: 75 | R36: 80 | S36: 46 | T36: 56 | U36: 60 | V36: 48 | W36: 65 | X36: 62 | Y36: 65 | Z36: 38 | AA36: 54 | AB36: =SUM(E36:AA36) -> 1362
A38: III | B38: DATA PEMILIH DISABILITAS
B39: Jumlah seluruh Pemilih disabilitas yang menggunakan hak pilih | D39: LK | E39: 0 | F39: 0 | G39: 0 | H39: 0 | I39: 1 | J39: 0 | K39: 0 | L39: 0 | M39: 0 | N39: 0 | O39: 0 | P39: 0 | Q39: 0 | R39: 1 | S39: 0 | T39: 0 | U39: 0 | V39: 0 | W39: 0 | X39: 0 | Y39: 0 | Z39: 0 | AA39: 1 | AB39: =SUM(E39:AA39) -> 3
D40: PR | E40: 0 | F40: 0 | G40: 0 | H40: 0 | I40: 1 | J40: 0 | K40: 0 | L40: 0 | M40: 0 | N40: 0 | O40: 0 | P40: 0 | Q40: 0 | R40: 3 | S40: 0 | T40: 0 | U40: 0 | V40: 0 | W40: 0 | X40: 0 | Y40: 0 | Z40: 0 | AA40: 2 | AB40: =SUM(E40:AA40) -> 6
D41: JML | E41: =SUM(E39:E40) -> 0 | F41: =SUM(F39:F40) -> 0 | G41: =SUM(G39:G40) -> 0 | H41: =SUM(H39:H40) -> 0 | I41: =SUM(I39:I40) -> 2 | J41: =SUM(J39:J40) -> 0 | K41: =SUM(K39:K40) -> 0 | L41: =SUM(L39:L40) -> 0 | ... AA41: =SUM(AA39:AA40) -> 3 | AB41: =SUM(E41:AA41) -> 9
A43: IV | B43: DATA RINCIAN PEROLEHAN SUARA PASANGAN CALON BUPATI DAN WAKIL BUPATI
A44: NOMOR DAN NAMA CALON
B45: 1. | C45: AA. AHMAD NAWARDI | E45: 9 | F45: 19 | G45: 10 | H45: 10 | I45: 18 | J45: 17 | K45: 5 | L45: 9 | M45: 22 | N45: 13 | O45: 8 | P45: 27 | Q45: 25 | R45: 19 | S45: 11 | T45: 20 | U45: 17 | V45: 18 | W45: 18 | X45: 20 | Y45: 20 | Z45: 32 | AA45: 17 | AB45: =SUM(E45:AA45) -> 384
B46: 2. | C46: Ir. H. AA LA NYALLA MAHMUD MATTALITI, M.HP. | E46: 34 | F46: 39 | G46: 28 | H46: 37 | I46: 48 | J46: 48 | K46: 47 | L46: 44 | M46: 36 | N46: 49 | O46: 51 | P46: 48 | Q46: 41 | R46: 29 | S46: 37 | T46: 28 | U46: 53 | V46: 44 | W46: 47 | X46: 53 | Y46: 35 | Z46: 65 | AA46: 28 | AB46: =SUM(E46:AA46) -> 969
B47: 3. | C47: ABDUL QADIR AMIR HARTONO, S.E., S.H., M.H. | E47: 14 | F47: 9 | G47: 11 | H47: 6 | I47: 4 | J47: 12 | K47: 9 | L47: 17 | M47: 9 | N47: 15 | O47: 13 | P47: 15 | Q47: 13 | R47: 6 | S47: 8 | T47: 3 | U47: 10 | V47: 16 | W47: 12 | X47: 4 | Y47: 14 | Z47: 10 | AA47: 18 | AB47: =SUM(E47:AA47) -> 248
B48: 4. | C48: ADILLA AZIS, S.E. | E48: 33 | F48: 27 | G48: 42 | H48: 19 | I48: 15 | J48: 21 | K48: 25 | L48: 34 | M48: 30 | N48: 21 | O48: 55 | P48: 24 | Q48: 24 | R48: 21 | S48: 11 | T48: 14 | U48: 19 | V48: 19 | W48: 20 | X48: 23 | Y48: 36 | Z48: 14 | AA48: 13 | AB48: =SUM(E48:AA48) -> 560
B49: 5. | C49: Ir. H. AGUS RAHARDJO, MSc.M. | E49: 12 | F49: 17 | G49: 17 | H49: 14 | I49: 16 | J49: 14 | K49: 8 | L49: 10 | M49: 21 | N49: 16 | O49: 20 | P49: 9 | Q49: 11 | R49: 9 | S49: 8 | T49: 11 | U49: 12 | V49: 15 | W49: 15 | X49: 7 | Y49: 15 | Z49: 8 | AA49: 6 | AB49: =SUM(E49:AA49) -> 291
B50: 6. | C50: Drs. AYUB KHAN | E50: 25 | F50: 17 | G50: 17 | H50: 16 | I50: 10 | J50: 14 | K50: 16 | L50: 7 | M50: 14 | N50: 17 | O50: 13 | P50: 16 | Q50: 16 | R50: 12 | S50: 9 | T50: 8 | U50: 14 | V50: 18 | W50: 16 | X50: 10 | Y50: 11 | Z50: 13 | AA50: 14 | AB50: =SUM(E50:AA50) -> 323
B51: 7. | C51: BAMBANG HARIANTO | E51: 1 | F51: 2 | G51: 2 | H51: 2 | I51: 1 | J51: 1 | K51: 0 | L51: 1 | M51: 2 | N51: 1 | O51: 0 | P51: 1 | Q51: 3 | R51: 0 | S51: 2 | T51: 1 | U51: 1 | V51: 3 | W51: 3 | X51: 5 | Y51: 3 | Z51: 1 | AA51: 1 | AB51: =SUM(E51:AA51) -> 37
...

Sheet BLIMBINGSARI
C2: Kecamatan | D2: BLIMBINGSARI
C3: Kabupaten | D3: BANYUWANGI
C4: Provinsi | D4: JAWA TIMUR
C9: Kelurahan | D9: BLIMBINGSARI
A12: I | B12: DATA PEMILIH DAN PENGGUNAAN HAK PILIH | U12: JUMLAH AKHIR
A13: A | B13: DATA PEMILIH | E13: TPS 001 | F13: TPS 002 | G13: TPS 003 | H13: TPS 004 | I13: TPS 005 | J13: TPS 006 | K13: TPS 007 | L13: TPS 008 | M13: TPS 009 | N13: TPS 010 | O13: TPS 011 | P13: TPS 012 | Q13: TPS 013 | R13: TPS 014 | S13: TPS 015 | T13: TPS 016
B14: Jumlah Pemilih dalam Daftar Pemilih Tetap (DPT) | D14: LK | E14: 131 | F14: 147 | G14: 117 | H14: 106 | I14: 134 | J14: 135 | K14: 123 | L14: 110 | M14: 101 | N14: 126 | O14: 86 | P14: 122 | Q14: 144 | R14: 131 | S14: 112 | T14: 143 | U14: =SUM(E14:T14) -> 1968
D15: PR | E15: 131 | F15: 139 | G15: 132 | H15: 111 | I15: 139 | J15: 140 | K15: 143 | L15: 118 | M15: 116 | N15: 139 | O15: 95 | P15: 114 | Q15: 144 | R15: 141 | S15: 107 | T15: 145 | U15: =SUM(E15:T15) -> 2054
D16: JML | E16: =SUM(E14:E15) -> 262 | F16: =SUM(F14:F15) -> 286 | G16: =SUM(G14:G15) -> 249 | H16: =SUM(H14:H15) -> 217 | I16: =SUM(I14:I15) -> 273 | J16: =SUM(J14:J15) -> 275 | K16: =SUM(K14:K15) -> 266 | L16: =SUM(L14:L15) -> 228 | ... T16: =SUM(T14:T15) -> 288 | U16: =SUM(E16:T16) -> 4022
A18: B | B18: PENGGUNA HAK PILIH
B19: 1. | C19: Jumlah pengguna hak pilih dalam Daftar Pemilih Tetap (DPT) | D19: LK | E19: 101 | F19: 117 | G19: 86 | H19: 84 | I19: 107 | J19: 108 | K19: 94 | L19: 77 | M19: 87 | N19: 98 | O19: 62 | P19: 92 | Q19: 106 | R19: 93 | S19: 84 | T19: 114 | U19: =SUM(E19:T19) -> 1510
D20: PR | E20: 116 | F20: 122 | G20: 109 | H20: 91 | I20: 112 | J20: 110 | K20: 118 | L20: 89 | M20: 99 | N20: 115 | O20: 79 | P20: 102 | Q20: 108 | R20: 97 | S20: 90 | T20: 125 | U20: =SUM(E20:T20) -> 1682
D21: JML | E21: 217 | F21: 239 | G21: 195 | H21: 175 | I21: 219 | J21: 218 | K21: 212 | L21: 166 | M21: 186 | N21: 213 | O21: 141 | P21: 194 | Q21: 214 | R21: 190 | S21: 174 | T21: =SUM(T19:T20) -> 239 | U21: =SUM(E21:T21) -> 3192
B22: 2. | C22: Jumlah pengguna hak pilih dalam Daftar Pemilih Tambahan (DPTb) | D22: LK | E22: 1 | F22: 0 | G22: 0 | H22: 0 | I22: 0 | J22: 1 | K22: 2 | L22: 1 | M22: 2 | N22: 2 | O22: 0 | P22: 0 | Q22: 0 | R22: 0 | S22: 0 | T22: 0 | U22: =SUM(E22:T22) -> 9
D23: PR | E23: 0 | F23: 0 | G23: 0 | H23: 0 | I23: 0 | J23: 1 | K23: 1 | L23: 1 | M23: 4 | N23: 0 | O23: 0 | P23: 0 | Q23: 0 | R23: 0 | S23: 0 | T23: 0 | U23: =SUM(E23:T23) -> 7
D24: JML | E24: 1 | F24: 0 | G24: 0 | H24: 0 | I24: 0 | J24: 2 | K24: 3 | L24: 2 | M24: 6 | N24: 2 | O24: 0 | P24: 0 | Q24: 0 | R24: 0 | S24: 0 | T24: =SUM(T22:T23) -> 0 | U24: =SUM(E24:T24) -> 16
B25: 3. | C25: Jumlah pengguna hak pilih dalam Daftar Pemilih Khusus (DPK) | D25: LK | E25: 1 | F25: 1 | G25: 1 | H25: 3 | I25: 0 | J25: 0 | K25: 1 | L25: 0 | M25: 0 | N25: 2 | O25: 0 | P25: 1 | Q25: 1 | R25: 1 | S25: 4 | T25: 0 | U25: =SUM(E25:T25) -> 16
D26: PR | E26: 2 | F26: 1 | G26: 0 | H26: 1 | I26: 2 | J26: 1 | K26: 1 | L26: 1 | M26: 1 | N26: 2 | O26: 1 | P26: 1 | Q26: 0 | R26: 1 | S26: 3 | T26: 1 | U26: =SUM(E26:T26) -> 19
D27: JML | E27: 3 | F27: 2 | G27: 1 | H27: 4 | I27: 2 | J27: 1 | K27: 2 | L27: 1 | M27: 1 | N27: 4 | O27: 1 | P27: 2 | Q27: 1 | R27: 2 | S27: 7 | T27: =SUM(T25:T26) -> 1 | U27: =SUM(E27:T27) -> 35
B28: 4. | C28: Jumlah Pengguna Hak Pilih (B.1+B.2+B.3) | D28: LK | E28: 103 | F28: 118 | G28: 87 | H28: 87 | I28: 107 | J28: 109 | K28: 97 | L28: 78 | M28: 89 | N28: 102 | O28: 62 | P28: 93 | Q28: 107 | R28: 94 | S28: 88 | T28: =SUM(T19,T22,T25) -> 114 | U28: =SUM(E28:T28) -> 1535
D29: PR | E29: 118 | F29: 123 | G29: 109 | H29: 92 | I29: 114 | J29: 112 | K29: 120 | L29: 91 | M29: 104 | N29: 117 | O29: 80 | P29: 103 | Q29: 108 | R29: 98 | S29: 93 | T29: =SUM(T20,T23,T26) -> 126 | U29: =SUM(E29:T29) -> 1708
D30: JML | E30: =SUM(E28:E29) -> 221 | F30: =SUM(F28:F29) -> 241 | G30: =SUM(G28:G29) -> 196 | H30: =SUM(H28:H29) -> 179 | I30: =SUM(I28:I29) -> 221 | J30: =SUM(J28:J29) -> 221 | K30: =SUM(K28:K29) -> 217 | L30: =SUM(L28:L29) -> 169 | ... T30: =SUM(T28:T29) -> 240 | U30: =SUM(E30:T30) -> 3243
A32: II | B32: DATA PENGGUNAAN SURAT SUARA
A33: 1 | B33: Jumlah surat suara yang diterima, termasuk surat suara cadangan 2,5% dari DPT | E33: 268 | F33: 292 | G33: 254 | H33: 222 | I33: 279 | J33: 281 | K33: 272 | L33: 233 | M33: 222 | N33: 271 | O33: 186 | P33: 241 | Q33: 295 | R33: 278 | S33: 224 | T33: 294 | U33: =SUM(E33:T33) -> 4112
A34: 2 | B34: Jumlah surat suara yang digunakan | E34: 221 | F34: 241 | G34: 196 | H34: 179 | I34: 221 | J34: 221 | K34: 217 | L34: 169 | M34: 193 | N34: 219 | O34: 142 | P34: 196 | Q34: 215 | R34: 192 | S34: 181 | T34: 240 | U34: =SUM(E34:T34) -> 3243
A35: 3 | B35: Jumlah surat suara dikembalikan oleh pemilih (karena rusak atau keliru coblos) | E35: 1 | F35: 0 | G35: 0 | H35: 0 | I35: 1 | J35: 0 | K35: 0 | L35: 0 | M35: 0 | N35: 2 | O35: 1 | P35: 1 | Q35: 0 | R35: 0 | S35: 6 | T35: 0 | U35: =SUM(E35:T35) -> 12
A36: 4 | B36: Jumlah surat suara yang tidak digunakan/tidak terpakai, termasuk sisa surat suara cadangan | E36: 46 | F36: 51 | G36: 58 | H36: 43 | I36: 57 | J36: 60 | K36: 55 | L36: 64 | M36: 29 | N36: 50 | O36: 43 | P36: 44 | Q36: 80 | R36: 86 | S36: 37 | T36: =T33-(T34+T35) -> 54 | U36: =SUM(E36:T36) -> 857
A38: III | B38: DATA PEMILIH DISABILITAS
B39: Jumlah seluruh Pemilih disabilitas yang menggunakan hak pilih | D39: LK | E39: 0 | F39: 0 | G39: 0 | H39: 1 | I39: 0 | J39: 0 | K39: 0 | L39: 0 | M39: 0 | N39: 0 | O39: 2 | P39: 0 | Q39: 1 | R39: 0 | S39: 0 | T39: 0 | U39: =SUM(E39:T39) -> 4
D40: PR | E40: 0 | F40: 0 | G40: 0 | H40: 1 | I40: 0 | J40: 0 | K40: 0 | L40: 1 | M40: 1 | N40: 0 | O40: 1 | P40: 0 | Q40: 1 | R40: 0 | S40: 0 | T40: 0 | U40: =SUM(E40:T40) -> 5
D41: JML | E41: =SUM(E39:E40) -> 0 | F41: =SUM(F39:F40) -> 0 | G41: =SUM(G39:G40) -> 0 | H41: =SUM(H39:H40) -> 2 | I41: =SUM(I39:I40) -> 0 | J41: =SUM(J39:J40) -> 0 | K41: =SUM(K39:K40) -> 0 | L41: =SUM(L39:L40) -> 1 | ... T41: =SUM(T39:T40) -> 0 | U41: =SUM(E41:T41) -> 9
A43: IV | B43: DATA RINCIAN PEROLEHAN SUARA PASANGAN CALON BUPATI DAN WAKIL BUPATI
A44: NOMOR DAN NAMA CALON
B45: 1. | C45: AA. AHMAD NAWARDI | E45: 24 | F45: 18 | G45: 16 | H45: 22 | I45: 12 | J45: 14 | K45: 6 | L45: 20 | M45: 14 | N45: 15 | O45: 12 | P45: 23 | Q45: 18 | R45: 8 | S45: 8 | T45: 4 | U45: =SUM(E45:T45) -> 234
B46: 2. | C46: Ir. H. AA LA NYALLA MAHMUD MATTALITI, M.HP. | E46: 31 | F46: 39 | G46: 38 | H46: 30 | I46: 42 | J46: 38 | K46: 23 | L46: 12 | M46: 25 | N46: 32 | O46: 14 | P46: 32 | Q46: 47 | R46: 26 | S46: 15 | T46: 21 | U46: =SUM(E46:T46) -> 465
B47: 3. | C47: ABDUL QADIR AMIR HARTONO, S.E., S.H., M.H. | E47: 19 | F47: 15 | G47: 12 | H47: 16 | I47: 12 | J47: 16 | K47: 4 | L47: 5 | M47: 5 | N47: 6 | O47: 15 | P47: 13 | Q47: 14 | R47: 11 | S47: 9 | T47: 7 | U47: =SUM(E47:T47) -> 179
B48: 4. | C48: ADILLA AZIS, S.E. | E48: 26 | F48: 31 | G48: 23 | H48: 28 | I48: 22 | J48: 30 | K48: 19 | L48: 37 | M48: 39 | N48: 54 | O48: 19 | P48: 42 | Q48: 27 | R48: 17 | S48: 25 | T48: 19 | U48: =SUM(E48:T48) -> 458
B49: 5. | C49: Ir. H. AGUS RAHARDJO, MSc.M. | E49: 15 | F49: 7 | G49: 12 | H49: 8 | I49: 12 | J49: 14 | K49: 8 | L49: 7 | M49: 9 | N49: 15 | O49: 9 | P49: 5 | Q49: 8 | R49: 9 | S49: 5 | T49: 7 | U49: =SUM(E49:T49) -> 150
B50: 6. | C50: Drs. AYUB KHAN | E50: 11 | F50: 9 | G50: 10 | H50: 7 | I50: 17 | J50: 12 | K50: 10 | L50: 7 | M50: 10 | N50: 19 | O50: 13 | P50: 9 | Q50: 12 | R50: 4 | S50: 4 | T50: 12 | U50: =SUM(E50:T50) -> 166
B51: 7. | C51: BAMBANG HARIANTO | E51: 1 | F51: 2 | G51: 0 | H51: 3 | I51: 4 | J51: 1 | K51: 2 | L51: 2 | M51: 3 | N51: 0 | O51: 0 | P51: 1 | Q51: 1 | R51: 1 | S51: 1 | T51: 1 | U51: =SUM(E51:T51) -> 23
...

Sheet BOMO
C2: Kecamatan | D2: BLIMBINGSARI
C3: Kabupaten | D3: BANYUWANGI
C4: Provinsi | D4: JAWA TIMUR
C9: Kelurahan | D9: BOMO
A12: I | B12: DATA PEMILIH DAN PENGGUNAAN HAK PILIH | W12: JUMLAH AKHIR
A13: A | B13: DATA PEMILIH | E13: TPS 001 | F13: TPS 002 | G13: TPS 003 | H13: TPS 004 | I13: TPS 005 | J13: TPS 006 | K13: TPS 007 | L13: TPS 008 | M13: TPS 009 | N13: TPS 010 | O13: TPS 011 | P13: TPS 012 | Q13: TPS 013 | R13: TPS 014 | S13: TPS 015 | T13: TPS 016 | U13: TPS 017 | V13: TPS 018
B14: Jumlah Pemilih dalam Daftar Pemilih Tetap (DPT) | D14: LK | E14: 142 | F14: 123 | G14: 144 | H14: 139 | I14: 133 | J14: 151 | K14: 136 | L14: 141 | M14: 150 | N14: 113 | O14: 133 | P14: 121 | Q14: 121 | R14: 133 | S14: 130 | T14: 121 | U14: 127 | V14: 123 | W14: =SUM(E14:V14) -> 2381
D15: PR | E15: 143 | F15: 143 | G15: 150 | H15: 146 | I15: 133 | J15: 145 | K15: 138 | L15: 156 | M15: 141 | N15: 121 | O15: 140 | P15: 132 | Q15: 131 | R15: 129 | S15: 136 | T15: 122 | U15: 128 | V15: 119 | W15: =SUM(E15:V15) -> 2453
D16: JML | E16: =SUM(E14:E15) -> 285 | F16: =SUM(F14:F15) -> 266 | G16: =SUM(G14:G15) -> 294 | H16: =SUM(H14:H15) -> 285 | I16: =SUM(I14:I15) -> 266 | J16: =SUM(J14:J15) -> 296 | K16: =SUM(K14:K15) -> 274 | L16: =SUM(L14:L15) -> 297 | ... V16: =SUM(V14:V15) -> 242 | W16: =SUM(E16:V16) -> 4834
A18: B | B18: PENGGUNA HAK PILIH
B19: 1. | C19: Jumlah pengguna hak pilih dalam Daftar Pemilih Tetap (DPT) | D19: LK | E19: 117 | F19: 88 | G19: 96 | H19: 104 | I19: 96 | J19: 109 | K19: 105 | L19: 105 | M19: 113 | N19: 96 | O19: 102 | P19: 96 | Q19: 67 | R19: 89 | S19: 95 | T19: 99 | U19: 93 | V19: 83 | W19: =SUM(E19:V19) -> 1753
D20: PR | E20: 122 | F20: 111 | G20: 116 | H20: 118 | I20: 100 | J20: 109 | K20: 112 | L20: 127 | M20: 117 | N20: 99 | O20: 122 | P20: 102 | Q20: 87 | R20: 92 | S20: 106 | T20: 99 | U20: 109 | V20: 88 | W20: =SUM(E20:V20) -> 1936
D21: JML | E21: 239 | F21: 199 | G21: 212 | H21: 222 | I21: 196 | J21: 218 | K21: 217 | L21: 232 | M21: 230 | N21: 195 | O21: 224 | P21: 198 | Q21: 154 | R21: 181 | S21: 201 | T21: 198 | U21: 202 | V21: 171 | W21: =SUM(E21:V21) -> 3689
B22: 2. | C22: Jumlah pengguna hak pilih dalam Daftar Pemilih Tambahan (DPTb) | D22: LK | E22: 0 | F22: 0 | G22: 0 | H22: 0 | I22: 0 | J22: 2 | K22: 0 | L22: 0 | M22: 0 | N22: 0 | O22: 0 | P22: 0 | Q22: 0 | R22: 0 | S22: 0 | T22: 1 | U22: 3 | V22: 0 | W22: =SUM(E22:V22) -> 6
D23: PR | E23: 0 | F23: 0 | G23: 0 | H23: 0 | I23: 0 | J23: 0 | K23: 0 | L23: 0 | M23: 0 | N23: 0 | O23: 0 | P23: 0 | Q23: 0 | R23: 0 | S23: 0 | T23: 0 | U23: 1 | V23: 0 | W23: =SUM(E23:V23) -> 1
D24: JML | E24: 0 | F24: 0 | G24: 0 | H24: 0 | I24: 0 | J24: 2 | K24: 0 | L24: 0 | M24: 0 | N24: 0 | O24: 0 | P24: 0 | Q24: 0 | R24: 0 | S24: 0 | T24: 1 | U24: 4 | V24: 0 | W24: =SUM(E24:V24) -> 7
B25: 3. | C25: Jumlah pengguna hak pilih dalam Daftar Pemilih Khusus (DPK) | D25: LK | E25: 1 | F25: 0 | G25: 2 | H25: 0 | I25: 0 | J25: 0 | K25: 0 | L25: 1 | M25: 1 | N25: 0 | O25: 0 | P25: 1 | Q25: 1 | R25: 0 | S25: 0 | T25: 0 | U25: 1 | V25: 1 | W25: =SUM(E25:V25) -> 9
D26: PR | E26: 2 | F26: 0 | G26: 1 | H26: 0 | I26: 0 | J26: 0 | K26: 0 | L26: 0 | M26: 3 | N26: 0 | O26: 0 | P26: 1 | Q26: 0 | R26: 0 | S26: 1 | T26: 0 | U26: 0 | V26: 1 | W26: =SUM(E26:V26) -> 9
D27: JML | E27: 3 | F27: 0 | G27: 3 | H27: 0 | I27: 0 | J27: 0 | K27: 0 | L27: 1 | M27: 4 | N27: 0 | O27: 0 | P27: 2 | Q27: 1 | R27: 0 | S27: 1 | T27: 0 | U27: 1 | V27: 2 | W27: =SUM(E27:V27) -> 18
B28: 4. | C28: Jumlah Pengguna Hak Pilih (B.1+B.2+B.3) | D28: LK | E28: 118 | F28: 88 | G28: 98 | H28: 104 | I28: 96 | J28: 111 | K28: 105 | L28: 106 | M28: 114 | N28: 96 | O28: 102 | P28: 97 | Q28: 68 | R28: 89 | S28: 95 | T28: 100 | U28: 97 | V28: 84 | W28: =SUM(E28:V28) -> 1768
D29: PR | E29: 124 | F29: 111 | G29: 117 | H29: 118 | I29: 100 | J29: 109 | K29: 112 | L29: 127 | M29: 120 | N29: 99 | O29: 122 | P29: 103 | Q29: 87 | R29: 92 | S29: 107 | T29: 99 | U29: 110 | V29: 89 | W29: =SUM(E29:V29) -> 1946
D30: JML | E30: =SUM(E28:E29) -> 242 | F30: =SUM(F28:F29) -> 199 | G30: =SUM(G28:G29) -> 215 | H30: =SUM(H28:H29) -> 222 | I30: =SUM(I28:I29) -> 196 | J30: =SUM(J28:J29) -> 220 | K30: =SUM(K28:K29) -> 217 | L30: =SUM(L28:L29) -> 233 | ... S30: =SUM(S28:S29) -> 202 | T30: 199 | U30: 207 | V30: 173 | W30: =SUM(E30:V30) -> 3714
A32: II | B32: DATA PENGGUNAAN SURAT SUARA
A33: 1 | B33: Jumlah surat suara yang diterima, termasuk surat suara cadangan 2,5% dari DPT | E33: 291 | F33: 272 | G33: 300 | H33: 291 | I33: 272 | J33: 302 | K33: 280 | L33: 303 | M33: 297 | N33: 239 | O33: 279 | P33: 259 | Q33: 258 | R33: 268 | S33: 272 | T33: 248 | U33: 261 | V33: 248 | W33: =SUM(E33:V33) -> 4940
A34: 2 | B34: Jumlah surat suara yang digunakan | E34: 242 | F34: 199 | G34: 215 | H34: 222 | I34: 196 | J34: 220 | K34: 217 | L34: 233 | M34: 234 | N34: 195 | O34: 224 | P34: 200 | Q34: 155 | R34: 181 | S34: 202 | T34: 199 | U34: 207 | V34: 173 | W34: =SUM(E34:V34) -> 3714
A35: 3 | B35: Jumlah surat suara dikembalikan oleh pemilih (karena rusak atau keliru coblos) | E35: 0 | F35: 0 | G35: 0 | H35: 0 | I35: 0 | J35: 0 | K35: 0 | L35: 0 | M35: 0 | N35: 0 | O35: 0 | P35: 0 | Q35: 0 | R35: 0 | S35: 0 | T35: 0 | U35: 0 | V35: 0 | W35: =SUM(E35:V35) -> 0
A36: 4 | B36: Jumlah surat suara yang tidak digunakan/tidak terpakai, termasuk sisa surat suara cadangan | E36: 49 | F36: 73 | G36: 85 | H36: 69 | I36: 76 | J36: 82 | K36: 63 | L36: 70 | M36: 63 | N36: 44 | O36: 55 | P36: 59 | Q36: 103 | R36: 87 | S36: 70 | T36: =T33-(T34+T35) -> 49 | U36: =U33-(U34+U35) -> 54 | V36: =V33-(V34+V35) -> 75 | W36: =SUM(E36:V36) -> 1226
A38: III | B38: DATA PEMILIH DISABILITAS
B39: Jumlah seluruh Pemilih disabilitas yang menggunakan hak pilih | D39: LK | E39: 0 | F39: 0 | G39: 0 | H39: 0 | I39: 0 | J39: 0 | K39: 0 | L39: 0 | M39: 0 | N39: 0 | O39: 1 | P39: 1 | Q39: 0 | R39: 0 | S39: 0 | T39: 1 | U39: 0 | V39: 1 | W39: =SUM(E39:V39) -> 4
D40: PR | E40: 0 | F40: 0 | G40: 0 | H40: 0 | I40: 0 | J40: 0 | K40: 0 | L40: 0 | M40: 0 | N40: 0 | O40: 0 | P40: 0 | Q40: 0 | R40: 0 | S40: 0 | T40: 0 | U40: 0 | V40: 0 | W40: =SUM(E40:V40) -> 0
D41: JML | E41: =SUM(E39:E40) -> 0 | F41: =SUM(F39:F40) -> 0 | G41: =SUM(G39:G40) -> 0 | H41: =SUM(H39:H40) -> 0 | I41: =SUM(I39:I40) -> 0 | J41: =SUM(J39:J40) -> 0 | K41: =SUM(K39:K40) -> 0 | L41: =SUM(L39:L40) -> 0 | ... V41: =SUM(V39:V40) -> 1 | W41: =SUM(E41:V41) -> 4
A43: IV | B43: DATA RINCIAN PEROLEHAN SUARA PASANGAN CALON BUPATI DAN WAKIL BUPATI
A44: NOMOR DAN NAMA CALON
B45: 1. | C45: AA. AHMAD NAWARDI | E45: 12 | F45: 12 | G45: 13 | H45: 14 | I45: 19 | J45: 3 | K45: 15 | L45: 5 | M45: 1 | N45: 2 | O45: 18 | P45: 6 | Q45: 9 | R45: 8 | S45: 15 | T45: 3 | U45: 3 | V45: 8 | W45: =SUM(E45:V45) -> 166
B46: 2. | C46: Ir. H. AA LA NYALLA MAHMUD MATTALITI, M.HP. | E46: 47 | F46: 36 | G46: 45 | H46: 20 | I46: 29 | J46: 28 | K46: 17 | L46: 26 | M46: 25 | N46: 16 | O46: 25 | P46: 13 | Q46: 15 | R46: 18 | S46: 34 | T46: 24 | U46: 19 | V46: 10 | W46: =SUM(E46:V46) -> 447
B47: 3. | C47: ABDUL QADIR AMIR HARTONO, S.E., S.H., M.H. | E47: 17 | F47: 7 | G47: 15 | H47: 20 | I47: 19 | J47: 17 | K47: 19 | L47: 12 | M47: 17 | N47: 9 | O47: 11 | P47: 7 | Q47: 14 | R47: 19 | S47: 21 | T47: 14 | U47: 14 | V47: 11 | W47: =SUM(E47:V47) -> 263
B48: 4. | C48: ADILLA AZIS, S.E. | E48: 21 | F48: 16 | G48: 34 | H48: 29 | I48: 25 | J48: 32 | K48: 15 | L48: 27 | M48: 21 | N48: 20 | O48: 21 | P48: 19 | Q48: 27 | R48: 22 | S48: 22 | T48: 34 | U48: 28 | V48: 24 | W48: =SUM(E48:V48) -> 437
B49: 5. | C49: Ir. H. AGUS RAHARDJO, MSc.M. | E49: 6 | F49: 14 | G49: 15 | H49: 17 | I49: 21 | J49: 10 | K49: 14 | L49: 14 | M49: 10 | N49: 17 | O49: 13 | P49: 12 | Q49: 7 | R49: 16 | S49: 8 | T49: 13 | U49: 16 | V49: 4 | W49: =SUM(E49:V49) -> 227
B50: 6. | C50: Drs. AYUB KHAN | E50: 7 | F50: 5 | G50: 1 | H50: 4 | I50: 15 | J50: 19 | K50: 13 | L50: 9 | M50: 6 | N50: 7 | O50: 6 | P50: 5 | Q50: 4 | R50: 12 | S50: 5 | T50: 9 | U50: 9 | V50: 7 | W50: =SUM(E50:V50) -> 143
B51: 7. | C51: BAMBANG HARIANTO | E51: 2 | F51: 0 | G51: 0 | H51: 3 | I51: 5 | J51: 0 | K51: 0 | L51: 4 | M51: 1 | N51: 1 | O51: 4 | P51: 5 | Q51: 4 | R51: 3 | S51: 2 | T51: 7 | U51: 0 | V51: 6 | W51: =SUM(E51:V51) -> 47
...

Sheet GINTANGAN
C2: Kecamatan | D2: BLIMBINGSARI
C3: Kabupaten | D3: BANYUWANGI
C4: Provinsi | D4: JAWA TIMUR
C9: Kelurahan | D9: GINTANGAN
A12: I | B12: DATA PEMILIH DAN PENGGUNAAN HAK PILIH | Z12: JUMLAH AKHIR
A13: A | B13: DATA PEMILIH | E13: TPS 001 | F13: TPS 002 | G13: TPS 003 | H13: TPS 004 | I13: TPS 005 | J13: TPS 006 | K13: TPS 007 | L13: TPS 008 | M13: TPS 009 | N13: TPS 010 | O13: TPS 011 | P13: TPS 012 | Q13: TPS 013 | R13: TPS 014 | S13: TPS 015 | T13: TPS 016 | U13: TPS 017 | V13: TPS 018 | W13: TPS 019 | X13: TPS 020 | Y13: TPS 021
B14: Jumlah Pemilih dalam Daftar Pemilih Tetap (DPT) | D14: LK | E14: 131 | F14: 144 | G14: 132 | H14: 135 | I14: 130 | J14: 127 | K14: 139 | L14: 150 | M14: 143 | N14: 116 | O14: 128 | P14: 110 | Q14: 120 | R14: 112 | S14: 110 | T14: 139 | U14: 131 | V14: 125 | W14: 127 | X14: 126 | Y14: 133 | Z14: =SUM(E14:Y14) -> 2708
D15: PR | E15: 133 | F15: 142 | G15: 152 | H15: 150 | I15: 140 | J15: 133 | K15: 145 | L15: 139 | M15: 141 | N15: 125 | O15: 107 | P15: 133 | Q15: 124 | R15: 117 | S15: 115 | T15: 138 | U15: 144 | V15: 137 | W15: 140 | X15: 148 | Y15: 136 | Z15: =SUM(E15:Y15) -> 2839
D16: JML | E16: =SUM(E14:E15) -> 264 | F16: =SUM(F14:F15) -> 286 | G16: =SUM(G14:G15) -> 284 | H16: =SUM(H14:H15) -> 285 | I16: =SUM(I14:I15) -> 270 | J16: =SUM(J14:J15) -> 260 | K16: =SUM(K14:K15) -> 284 | L16: =SUM(L14:L15) -> 289 | ... Y16: =SUM(Y14:Y15) -> 269 | Z16: =SUM(E16:Y16) -> 5547
A18: B | B18: PENGGUNA HAK PILIH
B19: 1. | C19: Jumlah pengguna hak pilih dalam Daftar Pemilih Tetap (DPT) | D19: LK | E19: 95 | F19: 101 | G19: 106 | H19: 92 | I19: 99 | J19: 97 | K19: 96 | L19: 125 | M19: 112 | N19: 81 | O19: 88 | P19: 88 | Q19: 104 | R19: 95 | S19: 86 | T19: 98 | U19: 102 | V19: 100 | W19: 91 | X19: 105 | Y19: 90 | Z19: =SUM(E19:Y19) -> 2051
D20: PR | E20: 105 | F20: 108 | G20: 128 | H20: 117 | I20: 119 | J20: 110 | K20: 128 | L20: 116 | M20: 122 | N20: 102 | O20: 88 | P20: 111 | Q20: 106 | R20: 93 | S20: 91 | T20: 113 | U20: 113 | V20: 112 | W20: 105 | X20: 127 | Y20: 107 | Z20: =SUM(E20:Y20) -> 2321
D21: JML | E21: 200 | F21: 209 | G21: 234 | H21: 209 | I21: 218 | J21: 207 | K21: 224 | L21: 241 | M21: 234 | N21: 183 | O21: 176 | P21: 199 | Q21: 210 | R21: 188 | S21: 177 | T21: 211 | U21: 215 | V21: 212 | W21: 196 | X21: 232 | Y21: 197 | Z21: =SUM(E21:Y21) -> 4372
B22: 2. | C22: Jumlah pengguna hak pilih dalam Daftar Pemilih Tambahan (DPTb) | D22: LK | E22: 0 | F22: 0 | G22: 0 | H22: 0 | I22: 1 | J22: 0 | K22: 0 | L22: 0 | M22: 0 | N22: 0 | O22: 0 | P22: 0 | Q22: 1 | R22: 0 | S22: 0 | T22: 0 | U22: 0 | V22: 0 | W22: 0 | X22: 0 | Y22: 0 | Z22: =SUM(E22:Y22) -> 2
D23: PR | E23: 0 | F23: 0 | G23: 0 | H23: 0 | I23: 0 | J23: 1 | K23: 0 | L23: 0 | M23: 0 | N23: 0 | O23: 0 | P23: 1 | Q23: 1 | R23: 0 | S23: 0 | T23: 0 | U23: 0 | V23: 0 | W23: 0 | X23: 0 | Y23: 1 | Z23: =SUM(E23:Y23) -> 4
D24: JML | E24: 0 | F24: 0 | G24: 0 | H24: 0 | I24: 1 | J24: 1 | K24: 0 | L24: 0 | M24: 0 | N24: 0 | O24: 0 | P24: 1 | Q24: 2 | R24: 0 | S24: 0 | T24: 0 | U24: 0 | V24: 0 | W24: 0 | X24: 0 | Y24: 1 | Z24: =SUM(E24:Y24) -> 6
B25: 3. | C25: Jumlah pengguna hak pilih dalam Daftar Pemilih Khusus (DPK) | D25: LK | E25: 0 | F25: 1 | G25: 0 | H25: 0 | I25: 0 | J25: 0 | K25: 1 | L25: 0 | M25: 1 | N25: 0 | O25: 0 | P25: 0 | Q25: 1 | R25: 0 | S25: 0 | T25: 0 | U25: 0 | V25: 0 | W25: 0 | X25: 1 | Y25: 0 | Z25: =SUM(E25:Y25) -> 5
D26: PR | E26: 0 | F26: 0 | G26: 0 | H26: 1 | I26: 1 | J26: 3 | K26: 2 | L26: 2 | M26: 0 | N26: 0 | O26: 0 | P26: 0 | Q26: 1 | R26: 0 | S26: 0 | T26: 0 | U26: 0 | V26: 0 | W26: 0 | X26: 0 | Y26: 0 | Z26: =SUM(E26:Y26) -> 10
D27: JML | E27: 0 | F27: 1 | G27: 0 | H27: 1 | I27: 1 | J27: 3 | K27: 3 | L27: 2 | M27: 1 | N27: 0 | O27: 0 | P27: 0 | Q27: 2 | R27: 0 | S27: 0 | T27: 0 | U27: 0 | V27: 0 | W27: 0 | X27: 1 | Y27: 0 | Z27: =SUM(E27:Y27) -> 15
B28: 4. | C28: Jumlah Pengguna Hak Pilih (B.1+B.2+B.3) | D28: LK | E28: 95 | F28: 102 | G28: 106 | H28: 92 | I28: 100 | J28: 97 | K28: 97 | L28: 125 | M28: 113 | N28: 81 | O28: 88 | P28: 88 | Q28: 106 | R28: 95 | S28: 86 | T28: 98 | U28: 102 | V28: 100 | W28: 91 | X28: 106 | Y28: 90 | Z28: =SUM(E28:Y28) -> 2058
D29: PR | E29: 105 | F29: 108 | G29: 128 | H29: 118 | I29: 120 | J29: 114 | K29: 130 | L29: 118 | M29: 122 | N29: 102 | O29: 88 | P29: 112 | Q29: 108 | R29: 93 | S29: 91 | T29: 113 | U29: 113 | V29: 112 | W29: 105 | X29: 127 | Y29: 108 | Z29: =SUM(E29:Y29) -> 2335
D30: JML | E30: =SUM(E28:E29) -> 200 | F30: =SUM(F28:F29) -> 210 | G30: =SUM(G28:G29) -> 234 | H30: =SUM(H28:H29) -> 210 | I30: =SUM(I28:I29) -> 220 | J30: =SUM(J28:J29) -> 211 | K30: =SUM(K28:K29) -> 227 | L30: =SUM(L28:L29) -> 243 | ... Y30: =SUM(Y28:Y29) -> 198 | Z30: =SUM(E30:Y30) -> 4393
A32: II | B32: DATA PENGGUNAAN SURAT SUARA
A33: 1 | B33: Jumlah surat suara yang diterima, termasuk surat suara cadangan 2,5% dari DPT | E33: 270 | F33: 292 | G33: 290 | H33: 291 | I33: 276 | J33: 266 | K33: 290 | L33: 294 | M33: 290 | N33: 246 | O33: 240 | P33: 248 | Q33: 249 | R33: 234 | S33: 230 | T33: 283 | U33: 281 | V33: 268 | W33: 273 | X33: 280 | Y33: 275 | Z33: =SUM(E33:Y33) -> 5666
A34: 2 | B34: Jumlah surat suara yang digunakan | E34: 200 | F34: 210 | G34: 234 | H34: 210 | I34: 220 | J34: 211 | K34: 227 | L34: 243 | M34: 235 | N34: 183 | O34: 176 | P34: 200 | Q34: 214 | R34: 188 | S34: 177 | T34: 211 | U34: 215 | V34: 212 | W34: 196 | X34: 233 | Y34: 198 | Z34: =SUM(E34:Y34) -> 4393
A35: 3 | B35: Jumlah surat suara dikembalikan oleh pemilih (karena rusak atau keliru coblos) | E35: 0 | F35: 1 | G35: 0 | H35: 0 | I35: 1 | J35: 0 | K35: 2 | L35: 0 | M35: 0 | N35: 0 | O35: 0 | P35: 0 | Q35: 0 | R35: 0 | S35: 0 | T35: 0 | U35: 0 | V35: 1 | W35: 0 | X35: 0 | Y35: 0 | Z35: =SUM(E35:Y35) -> 5
A36: 4 | B36: Jumlah surat suara yang tidak digunakan/tidak terpakai, termasuk sisa surat suara cadangan | E36: 70 | F36: 81 | G36: 56 | H36: 81 | I36: 55 | J36: 55 | K36: 61 | L36: 51 | M36: 55 | N36: 63 | O36: 64 | P36: 48 | Q36: 35 | R36: 46 | S36: 53 | T36: 72 | U36: 66 | V36: 55 | W36: 77 | X36: 47 | Y36: 77 | Z36: =SUM(E36:Y36) -> 1268
A38: III | B38: DATA PEMILIH DISABILITAS
B39: Jumlah seluruh Pemilih disabilitas yang menggunakan hak pilih | D39: LK | E39: 0 | F39: 0 | G39: 1 | H39: 0 | I39: 0 | J39: 0 | K39: 0 | L39: 2 | M39: 0 | N39: 0 | O39: 0 | P39: 0 | Q39: 0 | R39: 0 | S39: 1 | T39: 0 | U39: 0 | V39: 0 | W39: 0 | X39: 0 | Y39: 0 | Z39: =SUM(E39:Y39) -> 4
D40: PR | E40: 0 | F40: 1 | G40: 0 | H40: 0 | I40: 0 | J40: 0 | K40: 2 | L40: 1 | M40: 0 | N40: 1 | O40: 0 | P40: 0 | Q40: 0 | R40: 0 | S40: 0 | T40: 0 | U40: 0 | V40: 0 | W40: 0 | X40: 1 | Y40: 0 | Z40: =SUM(E40:Y40) -> 6
D41: JML | E41: =SUM(E39:E40) -> 0 | F41: =SUM(F39:F40) -> 1 | G41: =SUM(G39:G40) -> 1 | H41: =SUM(H39:H40) -> 0 | I41: =SUM(I39:I40) -> 0 | J41: =SUM(J39:J40) -> 0 | K41: =SUM(K39:K40) -> 2 | L41: =SUM(L39:L40) -> 3 | ... Y41: =SUM(Y39:Y40) -> 0 | Z41: =SUM(E41:Y41) -> 10
A43: IV | B43: DATA RINCIAN PEROLEHAN SUARA PASANGAN CALON BUPATI DAN WAKIL BUPATI
A44: NOMOR DAN NAMA CALON
B45: 1. | C45: AA. AHMAD NAWARDI | E45: 10 | F45: 11 | G45: 10 | H45: 15 | I45: 11 | J45: 10 | K45: 16 | L45: 7 | M45: 15 | N45: 14 | O45: 12 | P45: 6 | Q45: 8 | R45: 15 | S45: 12 | T45: 15 | U45: 15 | V45: 13 | W45: 17 | X45: 17 | Y45: 16 | Z45: =SUM(E45:Y45) -> 265
B46: 2. | C46: Ir. H. AA LA NYALLA MAHMUD MATTALITI, M.HP. | E46: 22 | F46: 36 | G46: 55 | H46: 83 | I46: 78 | J46: 26 | K46: 33 | L46: 45 | M46: 58 | N46: 29 | O46: 22 | P46: 33 | Q46: 44 | R46: 38 | S46: 30 | T46: 30 | U46: 33 | V46: 29 | W46: 20 | X46: 22 | Y46: 40 | Z46: =SUM(E46:Y46) -> 806
B47: 3. | C47: ABDUL QADIR AMIR HARTONO, S.E., S.H., M.H. | E47: 12 | F47: 12 | G47: 13 | H47: 10 | I47: 16 | J47: 14 | K47: 11 | L47: 15 | M47: 8 | N47: 11 | O47: 11 | P47: 8 | Q47: 15 | R47: 15 | S47: 12 | T47: 8 | U47: 22 | V47: 15 | W47: 10 | X47: 15 | Y47: 9 | Z47: =SUM(E47:Y47) -> 262
B48: 4. | C48: ADILLA AZIS, S.E. | E48: 25 | F48: 29 | G48: 16 | H48: 26 | I48: 21 | J48: 30 | K48: 30 | L48: 54 | M48: 33 | N48: 23 | O48: 49 | P48: 64 | Q48: 26 | R48: 28 | S48: 31 | T48: 32 | U48: 44 | V48: 55 | W48: 51 | X48: 37 | Y48: 35 | Z48: =SUM(E48:Y48) -> 739
B49: 5. | C49: Ir. H. AGUS RAHARDJO, MSc.M. | E49: 9 | F49: 12 | G49: 12 | H49: 18 | I49: 15 | J49: 12 | K49: 14 | L49: 18 | M49: 13 | N49: 8 | O49: 9 | P49: 9 | Q49: 23 | R49: 14 | S49: 10 | T49: 9 | U49: 13 | V49: 16 | W49: 11 | X49: 14 | Y49: 18 | Z49: =SUM(E49:Y49) -> 277
B50: 6. | C50: Drs. AYUB KHAN | E50: 14 | F50: 11 | G50: 15 | H50: 10 | I50: 7 | J50: 10 | K50: 9 | L50: 10 | M50: 13 | N50: 13 | O50: 13 | P50: 5 | Q50: 16 | R50: 12 | S50: 7 | T50: 10 | U50: 12 | V50: 13 | W50: 11 | X50: 26 | Y50: 14 | Z50: =SUM(E50:Y50) -> 251
B51: 7. | C51: BAMBANG HARIANTO | E51: 3 | F51: 0 | G51: 1 | H51: 0 | I51: 0 | J51: 3 | K51: 3 | L51: 0 | M51: 4 | N51: 1 | O51: 1 | P51: 0 | Q51: 1 | R51: 2 | S51: 1 | T51: 8 | U51: 2 | V51: 2 | W51: 1 | X51: 0 | Y51: 3 | Z51: =SUM(E51:Y51) -> 36
...

Sheet KALIGUNG
C2: Kecamatan | D2: BLIMBINGSARI
C3: Kabupaten | D3: BANYUWANGI
C4: Provinsi | D4: JAWA TIMUR
C9: Kelurahan | D9: KALIGUNG
A12: I | B12: DATA PEMILIH DAN PENGGUNAAN HAK PILIH | R12: JUMLAH AKHIR
A13: A | B13: DATA PEMILIH | E13: TPS 001 | F13: TPS 002 | G13: TPS 003 | H13: TPS 004 | I13: TPS 005 | J13: TPS 006 | K13: TPS 007 | L13: TPS 008 | M13: TPS 009 | N13: TPS 010 | O13: TPS 011 | P13: TPS 901 | Q13: TPS 902
B14: Jumlah Pemilih dalam Daftar Pemilih Tetap (DPT) | D14: LK | E14: 116 | F14: 123 | G14: 135 | H14: 136 | I14: 146 | J14: 140 | K14: 127 | L14: 122 | M14: 134 | N14: 143 | O14: 140 | P14: 267 | Q14: 223 | R14: =SUM(E14:Q14) -> 1952
D15: PR | E15: 119 | F15: 131 | G15: 117 | H15: 138 | I15: 149 | J15: 135 | K15: 123 | L15: 140 | M15: 148 | N15: 139 | O15: 137 | P15: 0 | Q15: 0 | R15: =SUM(E15:Q15) -> 1476
D16: JML | E16: =SUM(E14:E15) -> 235 | F16: =SUM(F14:F15) -> 254 | G16: =SUM(G14:G15) -> 252 | H16: =SUM(H14:H15) -> 274 | I16: =SUM(I14:I15) -> 295 | J16: =SUM(J14:J15) -> 275 | K16: =SUM(K14:K15) -> 250 | L16: =SUM(L14:L15) -> 262 | ... Q16: =SUM(Q14:Q15) -> 223 | R16: =SUM(E16:Q16) -> 3428
A18: B | B18: PENGGUNA HAK PILIH
B19: 1. | C19: Jumlah pengguna hak pilih dalam Daftar Pemilih Tetap (DPT) | D19: LK | E19: 83 | F19: 81 | G19: 95 | H19: 103 | I19: 116 | J19: 101 | K19: 85 | L19: 89 | M19: 97 | N19: 113 | O19: 104 | P19: 125 | Q19: 97 | R19: =SUM(E19:Q19) -> 1289
D20: PR | E20: 91 | F20: 108 | G20: 95 | H20: 115 | I20: 128 | J20: 114 | K20: 100 | L20: 115 | M20: 128 | N20: 104 | O20: 105 | P20: 0 | Q20: 0 | R20: =SUM(E20:Q20) -> 1203
D21: JML | E21: =SUM(E19:E20) -> 174 | F21: =SUM(F19:F20) -> 189 | G21: =SUM(G19:G20) -> 190 | H21: =SUM(H19:H20) -> 218 | I21: =SUM(I19:I20) -> 244 | J21: =SUM(J19:J20) -> 215 | K21: =SUM(K19:K20) -> 185 | L21: =SUM(L19:L20) -> 204 | ... Q21: =SUM(Q19:Q20) -> 97 | R21: =SUM(E21:Q21) -> 2492
B22: 2. | C22: Jumlah pengguna hak pilih dalam Daftar Pemilih Tambahan (DPTb) | D22: LK | E22: 4 | F22: 5 | G22: 1 | H22: 2 | I22: 1 | J22: 1 | K22: 0 | L22: 1 | M22: 4 | N22: 1 | O22: 0 | P22: 9 | Q22: 32 | R22: =SUM(E22:Q22) -> 61
D23: PR | E23: 0 | F23: 0 | G23: 0 | H23: 0 | I23: 0 | J23: 0 | K23: 0 | L23: 1 | M23: 0 | N23: 0 | O23: 0 | P23: 0 | Q23: 0 | R23: =SUM(E23:Q23) -> 1
D24: JML | E24: =SUM(E22:E23) -> 4 | F24: =SUM(F22:F23) -> 5 | G24: =SUM(G22:G23) -> 1 | H24: =SUM(H22:H23) -> 2 | I24: =SUM(I22:I23) -> 1 | J24: =SUM(J22:J23) -> 1 | K24: =SUM(K22:K23) -> 0 | L24: =SUM(L22:L23) -> 2 | ... Q24: =SUM(Q22:Q23) -> 32 | R24: =SUM(E24:Q24) -> 62
B25: 3. | C25: Jumlah pengguna hak pilih dalam Daftar Pemilih Khusus (DPK) | D25: LK | E25: 0 | F25: 0 | G25: 1 | H25: 0 | I25: 0 | J25: 0 | K25: 0 | L25: 0 | M25: 0 | N25: 0 | O25: 1 | P25: 0 | Q25: 0 | R25: =SUM(E25:Q25) -> 2
D26: PR | E26: 1 | F26: 0 | G26: 3 | H26: 0 | I26: 0 | J26: 0 | K26: 0 | L26: 2 | M26: 0 | N26: 0 | O26: 2 | P26: 0 | Q26: 0 | R26: =SUM(E26:Q26) -> 8
D27: JML | E27: =SUM(E25:E26) -> 1 | F27: =SUM(F25:F26) -> 0 | G27: =SUM(G25:G26) -> 4 | H27: =SUM(H25:H26) -> 0 | I27: =SUM(I25:I26) -> 0 | J27: =SUM(J25:J26) -> 0 | K27: =SUM(K25:K26) -> 0 | L27: =SUM(L25:L26) -> 2 | ... Q27: =SUM(Q25:Q26) -> 0 | R27: =SUM(E27:Q27) -> 10
B28: 4. | C28: Jumlah Pengguna Hak Pilih (B.1+B.2+B.3) | D28: LK | E28: =SUM(E19,E22,E25) -> 87 | F28: =SUM(F19,F22,F25) -> 86 | G28: =SUM(G19,G22,G25) -> 97 | H28: =SUM(H19,H22,H25) -> 105 | I28: =SUM(I19,I22,I25) -> 117 | J28: =SUM(J19,J22,J25) -> 102 | K28: =SUM(K19,K22,K25) -> 85 | L28: =SUM(L19,L22,L25) -> 90 | ... Q28: =SUM(Q19,Q22,Q25) -> 129 | R28: =SUM(E28:Q28) -> 1352
D29: PR | E29: =SUM(E20,E23,E26) -> 92 | F29: =SUM(F20,F23,F26) -> 108 | G29: =SUM(G20,G23,G26) -> 98 | H29: =SUM(H20,H23,H26) -> 115 | I29: =SUM(I20,I23,I26) -> 128 | J29: =SUM(J20,J23,J26) -> 114 | K29: =SUM(K20,K23,K26) -> 100 | L29: =SUM(L20,L23,L26) -> 118 | ... Q29: =SUM(Q20,Q23,Q26) -> 0 | R29: =SUM(E29:Q29) -> 1212
D30: JML | E30: =SUM(E28:E29) -> 179 | F30: =SUM(F28:F29) -> 194 | G30: =SUM(G28:G29) -> 195 | H30: =SUM(H28:H29) -> 220 | I30: =SUM(I28:I29) -> 245 | J30: =SUM(J28:J29) -> 216 | K30: =SUM(K28:K29) -> 185 | L30: =SUM(L28:L29) -> 208 | ... Q30: =SUM(Q28:Q29) -> 129 | R30: =SUM(E30:Q30) -> 2564
A32: II | B32: DATA PENGGUNAAN SURAT SUARA
A33: 1 | B33: Jumlah surat suara yang diterima, termasuk surat suara cadangan 2,5% dari DPT | E33: 240 | F33: 260 | G33: 259 | H33: 290 | I33: 311 | J33: 283 | K33: 255 | L33: 269 | M33: 288 | N33: 288 | O33: 283 | P33: 273 | Q33: 229 | R33: =SUM(E33:Q33) -> 3528
A34: 2 | B34: Jumlah surat suara yang digunakan | E34: 179 | F34: 194 | G34: 195 | H34: 220 | I34: 245 | J34: 216 | K34: 185 | L34: 208 | M34: 229 | N34: 218 | O34: 212 | P34: 134 | Q34: 129 | R34: =SUM(E34:Q34) -> 2564
A35: 3 | B35: Jumlah surat suara dikembalikan oleh pemilih (karena rusak atau keliru coblos) | E35: 0 | F35: 0 | G35: 0 | H35: 0 | I35: 0 | J35: 1 | K35: 0 | L35: 0 | M35: 0 | N35: 2 | O35: 1 | P35: 0 | Q35: 0 | R35: =SUM(E35:Q35) -> 4
A36: 4 | B36: Jumlah surat suara yang tidak digunakan/tidak terpakai, termasuk sisa surat suara cadangan | E36: =E33-(E34+E35) -> 61 | F36: =F33-(F34+F35) -> 66 | G36: =G33-(G34+G35) -> 64 | H36: =H33-(H34+H35) -> 70 | I36: =I33-(I34+I35) -> 66 | J36: =J33-(J34+J35) -> 66 | K36: =K33-(K34+K35) -> 70 | L36: =L33-(L34+L35) -> 61 | ... Q36: =Q33-(Q34+Q35) -> 100 | R36: =SUM(E36:Q36) -> 960
A38: III | B38: DATA PEMILIH DISABILITAS
B39: Jumlah seluruh Pemilih disabilitas yang menggunakan hak pilih | D39: LK | E39: 0 | F39: 0 | G39: 0 | H39: 0 | I39: 3 | J39: 0 | K39: 0 | L39: 0 | M39: 0 | N39: 0 | O39: 0 | P39: 0 | Q39: 0 | R39: =SUM(E39:Q39) -> 3
D40: PR | E40: 0 | F40: 0 | G40: 0 | H40: 0 | I40: 0 | J40: 0 | K40: 0 | L40: 0 | M40: 0 | N40: 0 | O40: 1 | P40: 0 | Q40: 0 | R40: =SUM(E40:Q40) -> 1
D41: JML | E41: =SUM(E39:E40) -> 0 | F41: =SUM(F39:F40) -> 0 | G41: =SUM(G39:G40) -> 0 | H41: =SUM(H39:H40) -> 0 | I41: =SUM(I39:I40) -> 3 | J41: =SUM(J39:J40) -> 0 | K41: =SUM(K39:K40) -> 0 | L41: =SUM(L39:L40) -> 0 | ... Q41: =SUM(Q39:Q40) -> 0 | R41: =SUM(E41:Q41) -> 4
A43: IV | B43: DATA RINCIAN PEROLEHAN SUARA PASANGAN CALON BUPATI DAN WAKIL BUPATI
A44: NOMOR DAN NAMA CALON
B45: 1. | C45: AA. AHMAD NAWARDI | E45: 17 | F45: 11 | G45: 11 | H45: 10 | I45: 23 | J45: 11 | K45: 21 | L45: 6 | M45: 14 | N45: 15 | O45: 12 | P45: 3 | Q45: 6 | R45: =SUM(E45:Q45) -> 160
B46: 2. | C46: Ir. H. AA LA NYALLA MAHMUD MATTALITI, M.HP. | E46: 28 | F46: 25 | G46: 19 | H46: 20 | I46: 30 | J46: 23 | K46: 27 | L46: 35 | M46: 34 | N46: 35 | O46: 36 | P46: 1 | Q46: 6 | R46: =SUM(E46:Q46) -> 319
B47: 3. | C47: ABDUL QADIR AMIR HARTONO, S.E., S.H., M.H. | E47: 10 | F47: 12 | G47: 10 | H47: 14 | I47: 15 | J47: 17 | K47: 6 | L47: 9 | M47: 13 | N47: 16 | O47: 13 | P47: 4 | Q47: 7 | R47: =SUM(E47:Q47) -> 146
B48: 4. | C48: ADILLA AZIS, S.E. | E48: 17 | F48: 32 | G48: 22 | H48: 30 | I48: 38 | J48: 28 | K48: 28 | L48: 17 | M48: 32 | N48: 29 | O48: 26 | P48: 0 | Q48: 0 | R48: =SUM(E48:Q48) -> 299
B49: 5. | C49: Ir. H. AGUS RAHARDJO, MSc.M. | E49: 9 | F49: 16 | G49: 20 | H49: 11 | I49: 10 | J49: 14 | K49: 12 | L49: 16 | M49: 12 | N49: 16 | O49: 14 | P49: 8 | Q49: 17 | R49: =SUM(E49:Q49) -> 175
B50: 6. | C50: Drs. AYUB KHAN | E50: 11 | F50: 9 | G50: 12 | H50: 18 | I50: 11 | J50: 22 | K50: 12 | L50: 11 | M50: 13 | N50: 10 | O50: 13 | P50: 3 | Q50: 20 | R50: =SUM(E50:Q50) -> 165
B51: 7. | C51: BAMBANG HARIANTO | E51: 0 | F51: 2 | G51: 0 | H51: 0 | I51: 5 | J51: 3 | K51: 4 | L51: 0 | M51: 1 | N51: 2 | O51: 2 | P51: 0 | Q51: 0 | R51: =SUM(E51:Q51) -> 19
...

Sheet KAOTAN
C2: Kecamatan | D2: BLIMBINGSARI
C3: Kabupaten | D3: BANYUWANGI
C4: Provinsi | D4: JAWA TIMUR
C9: Kelurahan | D9: KAOTAN
A12: I | B12: DATA PEMILIH DAN PENGGUNAAN HAK PILIH | M12: JUMLAH AKHIR
A13: A | B13: DATA PEMILIH | E13: TPS 001 | F13: TPS 002 | G13: TPS 003 | H13: TPS 004 | I13: TPS 005 | J13: TPS 006 | K13: TPS 007 | L13: TPS 008
B14: Jumlah Pemilih dalam Daftar Pemilih Tetap (DPT) | D14: LK | E14: 143 | F14: 142 | G14: 147 | H14: 115 | I14: 127 | J14: 132 | K14: 135 | L14: 139 | M14: =SUM(E14:L14) -> 1080
D15: PR | E15: 147 | F15: 139 | G15: 121 | H15: 123 | I15: 130 | J15: 136 | K15: 141 | L15: 148 | M15: =SUM(E15:L15) -> 1085
D16: JML | E16: =SUM(E14:E15) -> 290 | F16: =SUM(F14:F15) -> 281 | G16: =SUM(G14:G15) -> 268 | H16: =SUM(H14:H15) -> 238 | I16: =SUM(I14:I15) -> 257 | J16: =SUM(J14:J15) -> 268 | K16: =SUM(K14:K15) -> 276 | L16: =SUM(L14:L15) -> 287 | M16: =SUM(E16:L16) -> 2165
A18: B | B18: PENGGUNA HAK PILIH
B19: 1. | C19: Jumlah pengguna hak pilih dalam Daftar Pemilih Tetap (DPT) | D19: LK | E19: 117 | F19: 103 | G19: 125 | H19: 102 | I19: 110 | J19: 119 | K19: 109 | L19: 115 | M19: =SUM(E19:L19) -> 900
D20: PR | E20: 123 | F20: 111 | G20: 108 | H20: 102 | I20: 117 | J20: 99 | K20: 119 | L20: 127 | M20: =SUM(E20:L20) -> 906
D21: JML | E21: =SUM(E19:E20) -> 240 | F21: =SUM(F19:F20) -> 214 | G21: =SUM(G19:G20) -> 233 | H21: =SUM(H19:H20) -> 204 | I21: =SUM(I19:I20) -> 227 | J21: =SUM(J19:J20) -> 218 | K21: =SUM(K19:K20) -> 228 | L21: =SUM(L19:L20) -> 242 | M21: =SUM(E21:L21) -> 1806
B22: 2. | C22: Jumlah pengguna hak pilih dalam Daftar Pemilih Tambahan (DPTb) | D22: LK | E22: 0 | F22: 1 | G22: 0 | H22: 0 | I22: 0 | J22: 1 | K22: 1 | L22: 2 | M22: =SUM(E22:L22) -> 5
D23: PR | E23: 0 | F23: 1 | G23: 1 | H23: 0 | I23: 0 | J23: 0 | K23: 1 | L23: 1 | M23: =SUM(E23:L23) -> 4
D24: JML | E24: =SUM(E22:E23) -> 0 | F24: =SUM(F22:F23) -> 2 | G24: =SUM(G22:G23) -> 1 | H24: =SUM(H22:H23) -> 0 | I24: =SUM(I22:I23) -> 0 | J24: =SUM(J22:J23) -> 1 | K24: =SUM(K22:K23) -> 2 | L24: =SUM(L22:L23) -> 3 | M24: =SUM(E24:L24) -> 9
B25: 3. | C25: Jumlah pengguna hak pilih dalam Daftar Pemilih Khusus (DPK) | D25: LK | E25: 0 | F25: 1 | G25: 0 | H25: 0 | I25: 0 | J25: 0 | K25: 0 | L25: 0 | M25: =SUM(E25:L25) -> 1
D26: PR | E26: 0 | F26: 2 | G26: 0 | H26: 0 | I26: 0 | J26: 2 | K26: 0 | L26: 0 | M26: =SUM(E26:L26) -> 4
D27: JML | E27: =SUM(E25:E26) -> 0 | F27: =SUM(F25:F26) -> 3 | G27: =SUM(G25:G26) -> 0 | H27: =SUM(H25:H26) -> 0 | I27: =SUM(I25:I26) -> 0 | J27: =SUM(J25:J26) -> 2 | K27: =SUM(K25:K26) -> 0 | L27: =SUM(L25:L26) -> 0 | M27: =SUM(E27:L27) -> 5
B28: 4. | C28: Jumlah Pengguna Hak Pilih (B.1+B.2+B.3) | D28: LK | E28: =SUM(E19,E22,E25) -> 117 | F28: =SUM(F19,F22,F25) -> 105 | G28: =SUM(G19,G22,G25) -> 125 | H28: =SUM(H19,H22,H25) -> 102 | I28: =SUM(I19,I22,I25) -> 110 | J28: =SUM(J19,J22,J25) -> 120 | K28: =SUM(K19,K22,K25) -> 110 | L28: =SUM(L19,L22,L25) -> 117 | M28: =SUM(E28:L28) -> 906
D29: PR | E29: =SUM(E20,E23,E26) -> 123 | F29: =SUM(F20,F23,F26) -> 114 | G29: =SUM(G20,G23,G26) -> 109 | H29: =SUM(H20,H23,H26) -> 102 | I29: =SUM(I20,I23,I26) -> 117 | J29: =SUM(J20,J23,J26) -> 101 | K29: =SUM(K20,K23,K26) -> 120 | L29: =SUM(L20,L23,L26) -> 128 | M29: =SUM(E29:L29) -> 914
D30: JML | E30: =SUM(E28:E29) -> 240 | F30: =SUM(F28:F29) -> 219 | G30: =SUM(G28:G29) -> 234 | H30: =SUM(H28:H29) -> 204 | I30: =SUM(I28:I29) -> 227 | J30: =SUM(J28:J29) -> 221 | K30: =SUM(K28:K29) -> 230 | L30: =SUM(L28:L29) -> 245 | M30: =SUM(E30:L30) -> 1820
A32: II | B32: DATA PENGGUNAAN SURAT SUARA
A33: 1 | B33: Jumlah surat suara yang diterima, termasuk surat suara cadangan 2,5% dari DPT | E33: 296 | F33: 287 | G33: 274 | H33: 243 | I33: 263 | J33: 274 | K33: 282 | L33: 293 | M33: =SUM(E33:L33) -> 2212
A34: 2 | B34: Jumlah surat suara yang digunakan | E34: 240 | F34: 219 | G34: 234 | H34: 204 | I34: 227 | J34: 221 | K34: 230 | L34: 245 | M34: =SUM(E34:L34) -> 1820
A35: 3 | B35: Jumlah surat suara dikembalikan oleh pemilih (karena rusak atau keliru coblos) | E35: 1 | F35: 1 | G35: 2 | H35: 0 | I35: 0 | J35: 1 | K35: 0 | L35: 0 | M35: =SUM(E35:L35) -> 5
A36: 4 | B36: Jumlah surat suara yang tidak digunakan/tidak terpakai, termasuk sisa surat suara cadangan | E36: =E33-(E34+E35) -> 55 | F36: =F33-(F34+F35) -> 67 | G36: =G33-(G34+G35) -> 38 | H36: =H33-(H34+H35) -> 39 | I36: =I33-(I34+I35) -> 36 | J36: =J33-(J34+J35) -> 52 | K36: =K33-(K34+K35) -> 52 | L36: =L33-(L34+L35) -> 48 | M36: =SUM(E36:L36) -> 387
A38: III | B38: DATA PEMILIH DISABILITAS
B39: Jumlah seluruh Pemilih disabilitas yang menggunakan hak pilih | D39: LK | E39: 1 | F39: 0 | G39: 0 | H39: 1 | I39: 0 | J39: 0 | K39: 0 | L39: 1 | M39: =SUM(E39:L39) -> 3
D40: PR | E40: 0 | F40: 0 | G40: 0 | H40: 3 | I40: 0 | J40: 2 | K40: 1 | L40: 4 | M40: =SUM(E40:L40) -> 10
D41: JML | E41: =SUM(E39:E40) -> 1 | F41: =SUM(F39:F40) -> 0 | G41: =SUM(G39:G40) -> 0 | H41: =SUM(H39:H40) -> 4 | I41: =SUM(I39:I40) -> 0 | J41: =SUM(J39:J40) -> 2 | K41: =SUM(K39:K40) -> 1 | L41: =SUM(L39:L40) -> 5 | M41: =SUM(E41:L41) -> 13
A43: IV | B43: DATA RINCIAN PEROLEHAN SUARA PASANGAN CALON BUPATI DAN WAKIL BUPATI
A44: NOMOR DAN NAMA CALON
B45: 1. | C45: AA. AHMAD NAWARDI | E45: 10 | F45: 17 | G45: 14 | H45: 13 | I45: 12 | J45: 15 | K45: 13 | L45: 11 | M45: =SUM(E45:L45) -> 105
B46: 2. | C46: Ir. H. AA LA NYALLA MAHMUD MATTALITI, M.HP. | E46: 35 | F46: 29 | G46: 39 | H46: 33 | I46: 17 | J46: 25 | K46: 25 | L46: 39 | M46: =SUM(E46:L46) -> 242
B47: 3. | C47: ABDUL QADIR AMIR HARTONO, S.E., S.H., M.H. | E47: 12 | F47: 15 | G47: 13 | H47: 11 | I47: 15 | J47: 16 | K47: 21 | L47: 21 | M47: =SUM(E47:L47) -> 124
B48: 4. | C48: ADILLA AZIS, S.E. | E48: 45 | F48: 34 | G48: 29 | H48: 38 | I48: 42 | J48: 32 | K48: 26 | L48: 26 | M48: =SUM(E48:L48) -> 272
B49: 5. | C49: Ir. H. AGUS RAHARDJO, MSc.M. | E49: 21 | F49: 13 | G49: 21 | H49: 15 | I49: 24 | J49: 19 | K49: 20 | L49: 12 | M49: =SUM(E49:L49) -> 145
B50: 6. | C50: Drs. AYUB KHAN | E50: 17 | F50: 14 | G50: 7 | H50: 6 | I50: 10 | J50: 16 | K50: 12 | L50: 12 | M50: =SUM(E50:L50) -> 94
B51: 7. | C51: BAMBANG HARIANTO | E51: 1 | F51: 3 | G51: 0 | H51: 1 | I51: 2 | J51: 0 | K51: 3 | L51: 1 | M51: =SUM(E51:L51) -> 11
...

Sheet KARANGREJO
C2: Kecamatan | D2: BLIMBINGSARI
C3: Kabupaten | D3: BANYUWANGI
C4: Provinsi | D4: JAWA TIMUR
C9: Kelurahan | D9: KARANGREJO
A12: I | B12: DATA PEMILIH DAN PENGGUNAAN HAK PILIH | P12: JUMLAH AKHIR
A13: A | B13: DATA PEMILIH | E13: TPS 001 | F13: TPS 002 | G13: TPS 003 | H13: TPS 004 | I13: TPS 005 | J13: TPS 006 | K13: TPS 007 | L13: TPS 008 | M13: TPS 009 | N13: TPS 010 | O13: TPS 011
B14: Jumlah Pemilih dalam Daftar Pemilih Tetap (DPT) | D14: LK | E14: 116 | F14: 118 | G14: 141 | H14: 136 | I14: 143 | J14: 130 | K14: 131 | L14: 127 | M14: 127 | N14: 121 | O14: 116 | P14: =SUM(E14:O14) -> 1406
D15: PR | E15: 112 | F15: 113 | G15: 122 | H15: 150 | I15: 134 | J15: 139 | K15: 128 | L15: 133 | M15: 124 | N15: 131 | O15: 126 | P15: =SUM(E15:O15) -> 1412
D16: JML | E16: =SUM(E14:E15) -> 228 | F16: =SUM(F14:F15) -> 231 | G16: =SUM(G14:G15) -> 263 | H16: =SUM(H14:H15) -> 286 | I16: =SUM(I14:I15) -> 277 | J16: =SUM(J14:J15) -> 269 | K16: =SUM(K14:K15) -> 259 | L16: =SUM(L14:L15) -> 260 | ... O16: =SUM(O14:O15) -> 242 | P16: =SUM(E16:O16) -> 2818
A18: B | B18: PENGGUNA HAK PILIH
B19: 1. | C19: Jumlah pengguna hak pilih dalam Daftar Pemilih Tetap (DPT) | D19: LK | E19: 79 | F19: 73 | G19: 108 | H19: 104 | I19: 113 | J19: 99 | K19: 100 | L19: 103 | M19: 85 | N19: 79 | O19: 81 | P19: =SUM(E19:O19) -> 1024
D20: PR | E20: 85 | F20: 88 | G20: 105 | H20: 120 | I20: 114 | J20: 112 | K20: 101 | L20: 116 | M20: 101 | N20: 94 | O20: 97 | P20: =SUM(E20:O20) -> 1133
D21: JML | E21: =SUM(E19:E20) -> 164 | F21: =SUM(F19:F20) -> 161 | G21: =SUM(G19:G20) -> 213 | H21: =SUM(H19:H20) -> 224 | I21: =SUM(I19:I20) -> 227 | J21: =SUM(J19:J20) -> 211 | K21: =SUM(K19:K20) -> 201 | L21: =SUM(L19:L20) -> 219 | ... O21: =SUM(O19:O20) -> 178 | P21: =SUM(E21:O21) -> 2157
B22: 2. | C22: Jumlah pengguna hak pilih dalam Daftar Pemilih Tambahan (DPTb) | D22: LK | E22: 0 | F22: 6 | G22: 0 | H22: 2 | I22: 0 | J22: 0 | K22: 0 | L22: 0 | M22: 1 | N22: 0 | O22: 0 | P22: =SUM(E22:O22) -> 9
D23: PR | E23: 0 | F23: 0 | G23: 1 | H23: 1 | I23: 0 | J23: 0 | K23: 0 | L23: 0 | M23: 0 | N23: 0 | O23: 1 | P23: =SUM(E23:O23) -> 3
D24: JML | E24: =SUM(E22:E23) -> 0 | F24: =SUM(F22:F23) -> 6 | G24: =SUM(G22:G23) -> 1 | H24: =SUM(H22:H23) -> 3 | I24: =SUM(I22:I23) -> 0 | J24: =SUM(J22:J23) -> 0 | K24: =SUM(K22:K23) -> 0 | L24: =SUM(L22:L23) -> 0 | ... O24: =SUM(O22:O23) -> 1 | P24: =SUM(E24:O24) -> 12
B25: 3. | C25: Jumlah pengguna hak pilih dalam Daftar Pemilih Khusus (DPK) | D25: LK | E25: 0 | F25: 0 | G25: 0 | H25: 1 | I25: 0 | J25: 0 | K25: 1 | L25: 1 | M25: 0 | N25: 0 | O25: 0 | P25: =SUM(E25:O25) -> 3
D26: PR | E26: 0 | F26: 0 | G26: 1 | H26: 1 | I26: 0 | J26: 0 | K26: 1 | L26: 2 | M26: 0 | N26: 1 | O26: 1 | P26: =SUM(E26:O26) -> 7
D27: JML | E27: =SUM(E25:E26) -> 0 | F27: =SUM(F25:F26) -> 0 | G27: =SUM(G25:G26) -> 1 | H27: =SUM(H25:H26) -> 2 | I27: =SUM(I25:I26) -> 0 | J27: =SUM(J25:J26) -> 0 | K27: =SUM(K25:K26) -> 2 | L27: =SUM(L25:L26) -> 3 | ... O27: =SUM(O25:O26) -> 1 | P27: =SUM(E27:O27) -> 10
B28: 4. | C28: Jumlah Pengguna Hak Pilih (B.1+B.2+B.3) | D28: LK | E28: =SUM(E19,E22,E25) -> 79 | F28: =SUM(F19,F22,F25) -> 79 | G28: =SUM(G19,G22,G25) -> 108 | H28: =SUM(H19,H22,H25) -> 107 | I28: =SUM(I19,I22,I25) -> 113 | J28: =SUM(J19,J22,J25) -> 99 | K28: =SUM(K19,K22,K25) -> 101 | L28: =SUM(L19,L22,L25) -> 104 | ... O28: =SUM(O19,O22,O25) -> 81 | P28: =SUM(E28:O28) -> 1036
D29: PR | E29: =SUM(E20,E23,E26) -> 85 | F29: =SUM(F20,F23,F26) -> 88 | G29: =SUM(G20,G23,G26) -> 107 | H29: =SUM(H20,H23,H26) -> 122 | I29: =SUM(I20,I23,I26) -> 114 | J29: =SUM(J20,J23,J26) -> 112 | K29: =SUM(K20,K23,K26) -> 102 | L29: =SUM(L20,L23,L26) -> 118 | ... O29: =SUM(O20,O23,O26) -> 99 | P29: =SUM(E29:O29) -> 1143
D30: JML | E30: =SUM(E28:E29) -> 164 | F30: =SUM(F28:F29) -> 167 | G30: =SUM(G28:G29) -> 215 | H30: =SUM(H28:H29) -> 229 | I30: =SUM(I28:I29) -> 227 | J30: =SUM(J28:J29) -> 211 | K30: =SUM(K28:K29) -> 203 | L30: =SUM(L28:L29) -> 222 | ... O30: =SUM(O28:O29) -> 180 | P30: =SUM(E30:O30) -> 2179
A32: II | B32: DATA PENGGUNAAN SURAT SUARA
A33: 1 | B33: Jumlah surat suara yang diterima, termasuk surat suara cadangan 2,5% dari DPT | E33: 233 | F33: 236 | G33: 269 | H33: 293 | I33: 283 | J33: 275 | K33: 265 | L33: 266 | M33: 257 | N33: 258 | O33: 247 | P33: =SUM(E33:O33) -> 2882
A34: 2 | B34: Jumlah surat suara yang digunakan | E34: 164 | F34: 167 | G34: 215 | H34: 229 | I34: 227 | J34: 211 | K34: 203 | L34: 222 | M34: 187 | N34: 174 | O34: 180 | P34: =SUM(E34:O34) -> 2179
A35: 3 | B35: Jumlah surat suara dikembalikan oleh pemilih (karena rusak atau keliru coblos) | E35: 16 | F35: 0 | G35: 0 | H35: 39 | I35: 0 | J35: 19 | K35: 1 | L35: 2 | M35: 3 | N35: 1 | O35: 0 | P35: =SUM(E35:O35) -> 81
A36: 4 | B36: Jumlah surat suara yang tidak digunakan/tidak terpakai, termasuk sisa surat suara cadangan | E36: =E33-(E34+E35) -> 53 | F36: =F33-(F34+F35) -> 69 | G36: =G33-(G34+G35) -> 54 | H36: =H33-(H34+H35) -> 25 | I36: =I33-(I34+I35) -> 56 | J36: =J33-(J34+J35) -> 45 | K36: =K33-(K34+K35) -> 61 | L36: =L33-(L34+L35) -> 42 | ... O36: =O33-(O34+O35) -> 67 | P36: =SUM(E36:O36) -> 622
A38: III | B38: DATA PEMILIH DISABILITAS
B39: Jumlah seluruh Pemilih disabilitas yang menggunakan hak pilih | D39: LK | E39: 0 | F39: 1 | G39: 1 | H39: 3 | I39: 0 | J39: 0 | K39: 1 | L39: 1 | M39: 0 | N39: 0 | O39: 0 | P39: =SUM(E39:O39) -> 7
D40: PR | E40: 1 | F40: 1 | G40: 0 | H40: 1 | I40: 0 | J40: 0 | K40: 1 | L40: 1 | M40: 0 | N40: 0 | O40: 0 | P40: =SUM(E40:O40) -> 5
D41: JML | E41: =SUM(E39:E40) -> 1 | F41: =SUM(F39:F40) -> 2 | G41: =SUM(G39:G40) -> 1 | H41: =SUM(H39:H40) -> 4 | I41: =SUM(I39:I40) -> 0 | J41: =SUM(J39:J40) -> 0 | K41: =SUM(K39:K40) -> 2 | L41: =SUM(L39:L40) -> 2 | ... O41: =SUM(O39:O40) -> 0 | P41: =SUM(E41:O41) -> 12
A43: IV | B43: DATA RINCIAN PEROLEHAN SUARA PASANGAN CALON BUPATI DAN WAKIL BUPATI
A44: NOMOR DAN NAMA CALON
B45: 1. | C45: AA. AHMAD NAWARDI | E45: 25 | F45: 13 | G45: 17 | H45: 8 | I45: 17 | J45: 15 | K45: 9 | L45: 19 | M45: 7 | N45: 14 | O45: 12 | P45: =SUM(E45:O45) -> 156
B46: 2. | C46: Ir. H. AA LA NYALLA MAHMUD MATTALITI, M.HP. | E46: 27 | F46: 26 | G46: 19 | H46: 38 | I46: 20 | J46: 22 | K46: 28 | L46: 43 | M46: 30 | N46: 36 | O46: 37 | P46: =SUM(E46:O46) -> 326
B47: 3. | C47: ABDUL QADIR AMIR HARTONO, S.E., S.H., M.H. | E47: 12 | F47: 12 | G47: 20 | H47: 21 | I47: 9 | J47: 17 | K47: 15 | L47: 14 | M47: 8 | N47: 19 | O47: 13 | P47: =SUM(E47:O47) -> 160
B48: 4. | C48: ADILLA AZIS, S.E. | E48: 14 | F48: 25 | G48: 28 | H48: 20 | I48: 26 | J48: 20 | K48: 18 | L48: 21 | M48: 17 | N48: 21 | O48: 24 | P48: =SUM(E48:O48) -> 234
B49: 5. | C49: Ir. H. AGUS RAHARDJO, MSc.M. | E49: 13 | F49: 10 | G49: 15 | H49: 15 | I49: 25 | J49: 15 | K49: 14 | L49: 11 | M49: 18 | N49: 11 | O49: 13 | P49: =SUM(E49:O49) -> 160
B50: 6. | C50: Drs. AYUB KHAN | E50: 11 | F50: 13 | G50: 15 | H50: 10 | I50: 9 | J50: 9 | K50: 7 | L50: 27 | M50: 9 | N50: 9 | O50: 11 | P50: =SUM(E50:O50) -> 130
