Workbook

Sheet DPD
C8: Kecamatan | D8: WONGSOREJO
C9: Kabupaten | D9: BANYUWANGI
C10: Provinsi | D10: JAWA TIMUR
A12: I | B12: DATA PEMILIH DAN PENGGUNAAN HAK PILIH | E12: JUMLAH AKHIR
A13: A | B13: DATA PEMILIH
B14: Jumlah Pemilih dalam Daftar Pemilih Tetap (DPT) | D14: LK | E14: =ALASBULUH!AG14+ALASREJO!U14+BAJULMATI!AD14+BANGSRING!W14+BENGKAK!Y14+BIMOREJO!R14+SIDODADI!U14+SIDOWANGI!P14+SUMBERANYAR!N14+SUMBERKENCONO!T14+WATUKEBO!Y14+WONGSOREJO!AM14 -> 29810
D15: PR | E15: =ALASBULUH!AG15+ALASREJO!U15+BAJULMATI!AD15+BANGSRING!W15+BENGKAK!Y15+BIMOREJO!R15+SIDODADI!U15+SIDOWANGI!P15+SUMBERANYAR!N15+SUMBERKENCONO!T15+WATUKEBO!Y15+WONGSOREJO!AM15 -> 30473
D16: JML | E16: =SUM(E14:E15) -> 60283
A18: B | B18: PENGGUNA HAK PILIH
B19: 1. | C19: Jumlah pengguna hak pilih dalam Daftar Pemilih Tetap (DPT) | D19: LK | E19: =ALASBULUH!AG19+ALASREJO!U19+BAJULMATI!AD19+BANGSRING!W19+BENGKAK!Y19+BIMOREJO!R19+SIDODADI!U19+SIDOWANGI!P19+SUMBERANYAR!N19+SUMBERKENCONO!T19+WATUKEBO!Y19+WONGSOREJO!AM19 -> 22279
D20: PR | E20: =ALASBULUH!AG20+ALASREJO!U20+BAJULMATI!AD20+BANGSRING!W20+BENGKAK!Y20+BIMOREJO!R20+SIDODADI!U20+SIDOWANGI!P20+SUMBERANYAR!N20+SUMBERKENCONO!T20+WATUKEBO!Y20+WONGSOREJO!AM20 -> 24259
D21: JML | E21: =SUM(E19:E20) -> 46538
B22: 2. | C22: Jumlah pengguna hak pilih dalam Daftar Pemilih Tambahan (DPTb) | D22: LK | E22: =ALASBULUH!AG22+ALASREJO!U22+BAJULMATI!AD22+BANGSRING!W22+BENGKAK!Y22+BIMOREJO!R22+SIDODADI!U22+SIDOWANGI!P22+SUMBERANYAR!N22+SUMBERKENCONO!T22+WATUKEBO!Y22+WONGSOREJO!AM22 -> 43
D23: PR | E23: =ALASBULUH!AG23+ALASREJO!U23+BAJULMATI!AD23+BANGSRING!W23+BENGKAK!Y23+BIMOREJO!R23+SIDODADI!U23+SIDOWANGI!P23+SUMBERANYAR!N23+SUMBERKENCONO!T23+WATUKEBO!Y23+WONGSOREJO!AM23 -> 31
D24: JML | E24: =SUM(E22:E23) -> 74
B25: 3. | C25: Jumlah pengguna hak pilih dalam Daftar Pemilih Khusus (DPK) | D25: LK | E25: =ALASBULUH!AG25+ALASREJO!U25+BAJULMATI!AD25+BANGSRING!W25+BENGKAK!Y25+BIMOREJO!R25+SIDODADI!U25+SIDOWANGI!P25+SUMBERANYAR!N25+SUMBERKENCONO!T25+WATUKEBO!Y25+WONGSOREJO!AM25 -> 162
D26: PR | E26: =ALASBULUH!AG26+ALASREJO!U26+BAJULMATI!AD26+BANGSRING!W26+BENGKAK!Y26+BIMOREJO!R26+SIDODADI!U26+SIDOWANGI!P26+SUMBERANYAR!N26+SUMBERKENCONO!T26+WATUKEBO!Y26+WONGSOREJO!AM26 -> 198
D27: JML | E27: =SUM(E25:E26) -> 360
B28: 4. | C28: Jumlah Pengguna Hak Pilih (B.1+B.2+B.3) | D28: LK | E28: =E19+E22+E25 -> 22484
D29: PR | E29: =E20+E23+E26 -> 24488
D30: JML | E30: =SUM(E28:E29) -> 46972
A32: II | B32: DATA PENGGUNAAN SURAT SUARA
A33: 1 | B33: Jumlah surat suara yang diterima, termasuk surat suara cadangan 2,5% dari DPT | E33: =ALASBULUH!AG33+ALASREJO!U33+BAJULMATI!AD33+BANGSRING!W33+BENGKAK!Y33+BIMOREJO!R33+SIDODADI!U33+SIDOWANGI!P33+SUMBERANYAR!N33+SUMBERKENCONO!T33+WATUKEBO!Y33+WONGSOREJO!AM33 -> 61525
A34: 2 | B34: Jumlah surat suara yang digunakan | E34: =ALASBULUH!AG34+ALASREJO!U34+BAJULMATI!AD34+BANGSRING!W34+BENGKAK!Y34+BIMOREJO!R34+SIDODADI!U34+SIDOWANGI!P34+SUMBERANYAR!N34+SUMBERKENCONO!T34+WATUKEBO!Y34+WONGSOREJO!AM34 -> 46972
A35: 3 | B35: Jumlah surat suara dikembalikan oleh pemilih (karena rusak atau keliru coblos) | E35: =ALASBULUH!AG35+ALASREJO!U35+BAJULMATI!AD35+BANGSRING!W35+BENGKAK!Y35+BIMOREJO!R35+SIDODADI!U35+SIDOWANGI!P35+SUMBERANYAR!N35+SUMBERKENCONO!T35+WATUKEBO!Y35+WONGSOREJO!AM35 -> 72
A36: 4 | B36: Jumlah surat suara yang tidak digunakan/tidak terpakai, termasuk sisa surat suara cadangan | E36: =E33-(E34+E35) -> 14481
A38: III | B38: DATA PEMILIH DISABILITAS
B39: Jumlah seluruh Pemilih disabilitas yang menggunakan hak pilih | D39: LK | E39: =ALASBULUH!AG39+ALASREJO!U39+BAJULMATI!AD39+BANGSRING!W39+BENGKAK!Y39+BIMOREJO!R39+SIDODADI!U39+SIDOWANGI!P39+SUMBERANYAR!N39+SUMBERKENCONO!T39+WATUKEBO!Y39+WONGSOREJO!AM39 -> 11
D40: PR | E40: =ALASBULUH!AG40+ALASREJO!U40+BAJULMATI!AD40+BANGSRING!W40+BENGKAK!Y40+BIMOREJO!R40+SIDODADI!U40+SIDOWANGI!P40+SUMBERANYAR!N40+SUMBERKENCONO!T40+WATUKEBO!Y40+WONGSOREJO!AM40 -> 27
D41: JML | E41: =SUM(E39:E40) -> 38
A43: IV | B43: DATA RINCIAN PEROLEHAN SUARA PASANGAN CALON BUPATI DAN WAKIL BUPATI
A44: NOMOR DAN NAMA CALON
B45: 1. | C45: AA. AHMAD NAWARDI | E45: =ALASBULUH!AG45+ALASREJO!U45+BAJULMATI!AD45+BANGSRING!W45+BENGKAK!Y45+BIMOREJO!R45+SIDODADI!U45+SIDOWANGI!P45+SUMBERANYAR!N45+SUMBERKENCONO!T45+WATUKEBO!Y45+WONGSOREJO!AM45 -> 4169
B46: 2. | C46: Ir. H. AA LA NYALLA MAHMUD MATTALITI, M.HP. | E46: =ALASBULUH!AG46+ALASREJO!U46+BAJULMATI!AD46+BANGSRING!W46+BENGKAK!Y46+BIMOREJO!R46+SIDODADI!U46+SIDOWANGI!P46+SUMBERANYAR!N46+SUMBERKENCONO!T46+WATUKEBO!Y46+WONGSOREJO!AM46 -> 8109
B47: 3. | C47: ABDUL QADIR AMIR HARTONO, S.E., S.H., M.H. | E47: =ALASBULUH!AG47+ALASREJO!U47+BAJULMATI!AD47+BANGSRING!W47+BENGKAK!Y47+BIMOREJO!R47+SIDODADI!U47+SIDOWANGI!P47+SUMBERANYAR!N47+SUMBERKENCONO!T47+WATUKEBO!Y47+WONGSOREJO!AM47 -> 3480
B48: 4. | C48: ADILLA AZIS, S.E. | E48: =ALASBULUH!AG48+ALASREJO!U48+BAJULMATI!AD48+BANGSRING!W48+BENGKAK!Y48+BIMOREJO!R48+SIDODADI!U48+SIDOWANGI!P48+SUMBERANYAR!N48+SUMBERKENCONO!T48+WATUKEBO!Y48+WONGSOREJO!AM48 -> 4593
B49: 5. | C49: Ir. H. AGUS RAHARDJO, MSc.M. | E49: =ALASBULUH!AG49+ALASREJO!U49+BAJULMATI!AD49+BANGSRING!W49+BENGKAK!Y49+BIMOREJO!R49+SIDODADI!U49+SIDOWANGI!P49+SUMBERANYAR!N49+SUMBERKENCONO!T49+WATUKEBO!Y49+WONGSOREJO!AM49 -> 2775
B50: 6. | C50: Drs. AYUB KHAN | E50: =ALASBULUH!AG50+ALASREJO!U50+BAJULMATI!AD50+BANGSRING!W50+BENGKAK!Y50+BIMOREJO!R50+SIDODADI!U50+SIDOWANGI!P50+SUMBERANYAR!N50+SUMBERKENCONO!T50+WATUKEBO!Y50+WONGSOREJO!AM50 -> 4783
B51: 7. | C51: BAMBANG HARIANTO | E51: =ALASBULUH!AG51+ALASREJO!U51+BAJULMATI!AD51+BANGSRING!W51+BENGKAK!Y51+BIMOREJO!R51+SIDODADI!U51+SIDOWANGI!P51+SUMBERANYAR!N51+SUMBERKENCONO!T51+WATUKEBO!Y51+WONGSOREJO!AM51 -> 452
B52: 8. | C52: CATUR RUDI UTANTO, S.Sos. | E52: =ALASBULUH!AG52+ALASREJO!U52+BAJULMATI!AD52+BANGSRING!W52+BENGKAK!Y52+BIMOREJO!R52+SIDODADI!U52+SIDOWANGI!P52+SUMBERANYAR!N52+SUMBERKENCONO!T52+WATUKEBO!Y52+WONGSOREJO!AM52 -> 514
...

Sheet BANGSRING
C2: Kecamatan | D2: WONGSOREJO
C3: Kabupaten | D3: BANYUWANGI
C4: Provinsi | D4: JAWA TIMUR
C9: Kelurahan | D9: BANGSRING
A12: I | B12: DATA PEMILIH DAN PENGGUNAAN HAK PILIH | W12: JUMLAH AKHIR
A13: A | B13: DATA PEMILIH | E13: TPS 001 | F13: TPS 002 | G13: TPS 003 | H13: TPS 004 | I13: TPS 005 | J13: TPS 006 | K13: TPS 007 | L13: TPS 008 | M13: TPS 009 | N13: TPS 010 | O13: TPS 011 | P13: TPS 012 | Q13: TPS 013 | R13: TPS 014 | S13: TPS 015 | T13: TPS 016 | U13: TPS 017 | V13: TPS 018
B14: Jumlah Pemilih dalam Daftar Pemilih Tetap (DPT) | D14: LK | E14: 142 | F14: 135 | G14: 133 | H14: 137 | I14: 142 | J14: 148 | K14: 143 | L14: 147 | M14: 143 | N14: 61 | O14: 150 | P14: 143 | Q14: 122 | R14: 136 | S14: 147 | T14: 115 | U14: 122 | V14: 126 | W14: =SUM(E14:V14) -> 2392
D15: PR | E15: 138 | F15: 131 | G15: 149 | H15: 140 | I15: 150 | J15: 149 | K15: 143 | L15: 151 | M15: 140 | N15: 64 | O15: 142 | P15: 149 | Q15: 134 | R15: 152 | S15: 146 | T15: 121 | U15: 131 | V15: 125 | W15: =SUM(E15:V15) -> 2455
D16: JML | E16: =SUM(E14:E15) -> 280 | F16: =SUM(F14:F15) -> 266 | G16: =SUM(G14:G15) -> 282 | H16: =SUM(H14:H15) -> 277 | I16: =SUM(I14:I15) -> 292 | J16: =SUM(J14:J15) -> 297 | K16: =SUM(K14:K15) -> 286 | L16: =SUM(L14:L15) -> 298 | ... V16: =SUM(V14:V15) -> 251 | W16: =SUM(E16:V16) -> 4847
A18: B | B18: PENGGUNA HAK PILIH
B19: 1. | C19: Jumlah pengguna hak pilih dalam Daftar Pemilih Tetap (DPT) | D19: LK | E19: 107 | F19: 95 | G19: 93 | H19: 91 | I19: 106 | J19: 111 | K19: 108 | L19: 107 | M19: 121 | N19: 50 | O19: 123 | P19: 121 | Q19: 95 | R19: 96 | S19: 113 | T19: 96 | U19: 98 | V19: 100 | W19: =SUM(E19:V19) -> 1831
D20: PR | E20: 112 | F20: 100 | G20: 132 | H20: 113 | I20: 120 | J20: 127 | K20: 119 | L20: 129 | M20: 118 | N20: 56 | O20: 113 | P20: 113 | Q20: 110 | R20: 116 | S20: 120 | T20: 88 | U20: 112 | V20: 106 | W20: =SUM(E20:V20) -> 2004
D21: JML | E21: =SUM(E19:E20) -> 219 | F21: =SUM(F19:F20) -> 195 | G21: =SUM(G19:G20) -> 225 | H21: =SUM(H19:H20) -> 204 | I21: =SUM(I19:I20) -> 226 | J21: =SUM(J19:J20) -> 238 | K21: =SUM(K19:K20) -> 227 | L21: =SUM(L19:L20) -> 236 | ... V21: =SUM(V19:V20) -> 206 | W21: =SUM(E21:V21) -> 3835
B22: 2. | C22: Jumlah pengguna hak pilih dalam Daftar Pemilih Tambahan (DPTb) | D22: LK | E22: 0 | F22: 0 | G22: 0 | H22: 0 | I22: 0 | J22: 0 | K22: 0 | L22: 0 | M22: 0 | N22: 0 | O22: 0 | P22: 0 | Q22: 0 | R22: 0 | S22: 0 | T22: 0 | U22: 0 | V22: 0 | W22: =SUM(E22:V22) -> 0
D23: PR | E23: 0 | F23: 0 | G23: 0 | H23: 0 | I23: 0 | J23: 0 | K23: 0 | L23: 0 | M23: 0 | N23: 0 | O23: 0 | P23: 0 | Q23: 0 | R23: 0 | S23: 3 | T23: 0 | U23: 0 | V23: 0 | W23: =SUM(E23:V23) -> 3
D24: JML | E24: =SUM(E22:E23) -> 0 | F24: =SUM(F22:F23) -> 0 | G24: =SUM(G22:G23) -> 0 | H24: =SUM(H22:H23) -> 0 | I24: =SUM(I22:I23) -> 0 | J24: =SUM(J22:J23) -> 0 | K24: =SUM(K22:K23) -> 0 | L24: =SUM(L22:L23) -> 0 | ... V24: =SUM(V22:V23) -> 0 | W24: =SUM(E24:V24) -> 3
B25: 3. | C25: Jumlah pengguna hak pilih dalam Daftar Pemilih Khusus (DPK) | D25: LK | E25: 3 | F25: 3 | G25: 0 | H25: 4 | I25: 2 | J25: 0 | K25: 3 | L25: 0 | M25: 0 | N25: 1 | O25: 0 | P25: 3 | Q25: 6 | R25: 0 | S25: 0 | T25: 1 | U25: 3 | V25: 0 | W25: =SUM(E25:V25) -> 29
D26: PR | E26: 5 | F26: 7 | G26: 1 | H26: 4 | I26: 0 | J26: 1 | K26: 3 | L26: 0 | M26: 1 | N26: 1 | O26: 0 | P26: 9 | Q26: 2 | R26: 1 | S26: 0 | T26: 2 | U26: 6 | V26: 0 | W26: =SUM(E26:V26) -> 43
D27: JML | E27: =SUM(E25:E26) -> 8 | F27: =SUM(F25:F26) -> 10 | G27: =SUM(G25:G26) -> 1 | H27: =SUM(H25:H26) -> 8 | I27: =SUM(I25:I26) -> 2 | J27: =SUM(J25:J26) -> 1 | K27: =SUM(K25:K26) -> 6 | L27: =SUM(L25:L26) -> 0 | ... V27: =SUM(V25:V26) -> 0 | W27: =SUM(E27:V27) -> 72
B28: 4. | C28: Jumlah Pengguna Hak Pilih (B.1+B.2+B.3) | D28: LK | E28: =SUM(E19,E22,E25) -> 110 | F28: =SUM(F19,F22,F25) -> 98 | G28: =SUM(G19,G22,G25) -> 93 | H28: =SUM(H19,H22,H25) -> 95 | I28: =SUM(I19,I22,I25) -> 108 | J28: =SUM(J19,J22,J25) -> 111 | K28: =SUM(K19,K22,K25) -> 111 | L28: =SUM(L19,L22,L25) -> 107 | ... V28: =SUM(V19,V22,V25) -> 100 | W28: =SUM(E28:V28) -> 1860
D29: PR | E29: =SUM(E20,E23,E26) -> 117 | F29: =SUM(F20,F23,F26) -> 107 | G29: =SUM(G20,G23,G26) -> 133 | H29: =SUM(H20,H23,H26) -> 117 | I29: =SUM(I20,I23,I26) -> 120 | J29: =SUM(J20,J23,J26) -> 128 | K29: =SUM(K20,K23,K26) -> 122 | L29: =SUM(L20,L23,L26) -> 129 | ... V29: =SUM(V20,V23,V26) -> 106 | W29: =SUM(E29:V29) -> 2050
D30: JML | E30: =SUM(E28:E29) -> 227 | F30: =SUM(F28:F29) -> 205 | G30: =SUM(G28:G29) -> 226 | H30: =SUM(H28:H29) -> 212 | I30: =SUM(I28:I29) -> 228 | J30: =SUM(J28:J29) -> 239 | K30: =SUM(K28:K29) -> 233 | L30: =SUM(L28:L29) -> 236 | ... V30: =SUM(V28:V29) -> 206 | W30: =SUM(E30:V30) -> 3910
A32: II | B32: DATA PENGGUNAAN SURAT SUARA
A33: 1 | B33: Jumlah surat suara yang diterima, termasuk surat suara cadangan 2,5% dari DPT | E33: 286 | F33: 272 | G33: 288 | H33: 280 | I33: 300 | J33: 303 | K33: 288 | L33: 304 | M33: 289 | N33: 128 | O33: 298 | P33: 298 | Q33: 262 | R33: 294 | S33: 299 | T33: 237 | U33: 263 | V33: 256 | W33: =SUM(E33:V33) -> 4945
A34: 2 | B34: Jumlah surat suara yang digunakan | E34: 227 | F34: 205 | G34: 226 | H34: 212 | I34: 228 | J34: 239 | K34: 233 | L34: 236 | M34: 240 | N34: 108 | O34: 236 | P34: 246 | Q34: 213 | R34: 213 | S34: 236 | T34: 187 | U34: 219 | V34: 206 | W34: =SUM(E34:V34) -> 3910
A35: 3 | B35: Jumlah surat suara dikembalikan oleh pemilih (karena rusak atau keliru coblos) | E35: 0 | F35: 0 | G35: 0 | H35: 0 | I35: 0 | J35: 0 | K35: 0 | L35: 0 | M35: 0 | N35: 0 | O35: 0 | P35: 0 | Q35: 0 | R35: 0 | S35: 0 | T35: 9 | U35: 0 | V35: 0 | W35: =SUM(E35:V35) -> 9
A36: 4 | B36: Jumlah surat suara yang tidak digunakan/tidak terpakai, termasuk sisa surat suara cadangan | E36: =E33-(E34+E35) -> 59 | F36: =F33-(F34+F35) -> 67 | G36: =G33-(G34+G35) -> 62 | H36: =H33-(H34+H35) -> 68 | I36: =I33-(I34+I35) -> 72 | J36: =J33-(J34+J35) -> 64 | K36: =K33-(K34+K35) -> 55 | L36: =L33-(L34+L35) -> 68 | ... V36: =V33-(V34+V35) -> 50 | W36: =SUM(E36:V36) -> 1026
A38: III | B38: DATA PEMILIH DISABILITAS
B39: Jumlah seluruh Pemilih disabilitas yang menggunakan hak pilih | D39: LK | E39: 0 | F39: 2 | G39: 1 | H39: 0 | I39: 0 | J39: 0 | K39: 0 | L39: 0 | M39: 0 | N39: 0 | O39: 0 | P39: 0 | Q39: 0 | R39: 0 | S39: 0 | T39: 0 | U39: 0 | V39: 0 | W39: =SUM(E39:V39) -> 3
D40: PR | E40: 0 | F40: 2 | G40: 0 | H40: 0 | I40: 0 | J40: 0 | K40: 0 | L40: 0 | M40: 0 | N40: 0 | O40: 0 | P40: 0 | Q40: 0 | R40: 2 | S40: 0 | T40: 0 | U40: 0 | V40: 0 | W40: =SUM(E40:V40) -> 4
D41: JML | E41: =SUM(E39:E40) -> 0 | F41: =SUM(F39:F40) -> 4 | G41: =SUM(G39:G40) -> 1 | H41: =SUM(H39:H40) -> 0 | I41: =SUM(I39:I40) -> 0 | J41: =SUM(J39:J40) -> 0 | K41: =SUM(K39:K40) -> 0 | L41: =SUM(L39:L40) -> 0 | ... V41: =SUM(V39:V40) -> 0 | W41: =SUM(E41:V41) -> 7
A43: IV | B43: DATA RINCIAN PEROLEHAN SUARA PASANGAN CALON BUPATI DAN WAKIL BUPATI
A44: NOMOR DAN NAMA CALON
B45: 1. | C45: AA. AHMAD NAWARDI | E45: 21 | F45: 25 | G45: 20 | H45: 22 | I45: 12 | J45: 21 | K45: 11 | L45: 17 | M45: 12 | N45: 5 | O45: 19 | P45: 26 | Q45: 11 | R45: 21 | S45: 24 | T45: 15 | U45: 20 | V45: 10 | W45: =SUM(E45:V45) -> 312
B46: 2. | C46: Ir. H. AA LA NYALLA MAHMUD MATTALITI, M.HP. | E46: 34 | F46: 33 | G46: 38 | H46: 36 | I46: 41 | J46: 35 | K46: 48 | L46: 43 | M46: 36 | N46: 11 | O46: 31 | P46: 36 | Q46: 41 | R46: 35 | S46: 41 | T46: 39 | U46: 29 | V46: 28 | W46: =SUM(E46:V46) -> 635
B47: 3. | C47: ABDUL QADIR AMIR HARTONO, S.E., S.H., M.H. | E47: 21 | F47: 26 | G47: 19 | H47: 15 | I47: 19 | J47: 26 | K47: 27 | L47: 11 | M47: 23 | N47: 7 | O47: 34 | P47: 33 | Q47: 23 | R47: 17 | S47: 26 | T47: 16 | U47: 22 | V47: 27 | W47: =SUM(E47:V47) -> 392
B48: 4. | C48: ADILLA AZIS, S.E. | E48: 12 | F48: 22 | G48: 21 | H48: 8 | I48: 21 | J48: 27 | K48: 23 | L48: 17 | M48: 22 | N48: 19 | O48: 18 | P48: 21 | Q48: 21 | R48: 25 | S48: 34 | T48: 15 | U48: 19 | V48: 17 | W48: =SUM(E48:V48) -> 362
B49: 5. | C49: Ir. H. AGUS RAHARDJO, MSc.M. | E49: 14 | F49: 10 | G49: 10 | H49: 12 | I49: 15 | J49: 12 | K49: 15 | L49: 23 | M49: 11 | N49: 12 | O49: 11 | P49: 6 | Q49: 9 | R49: 9 | S49: 15 | T49: 11 | U49: 10 | V49: 10 | W49: =SUM(E49:V49) -> 215
B50: 6. | C50: Drs. AYUB KHAN | E50: 47 | F50: 26 | G50: 30 | H50: 25 | I50: 16 | J50: 36 | K50: 15 | L50: 33 | M50: 24 | N50: 5 | O50: 31 | P50: 30 | Q50: 12 | R50: 21 | S50: 23 | T50: 21 | U50: 24 | V50: 15 | W50: =SUM(E50:V50) -> 434
B51: 7. | C51: BAMBANG HARIANTO | E51: 0 | F51: 4 | G51: 3 | H51: 1 | I51: 2 | J51: 0 | K51: 3 | L51: 1 | M51: 4 | N51: 6 | O51: 3 | P51: 3 | Q51: 1 | R51: 4 | S51: 0 | T51: 1 | U51: 2 | V51: 2 | W51: =SUM(E51:V51) -> 40
...

Sheet BENGKAK
C2: Kecamatan | D2: WONGSOREJO
C3: Kabupaten | D3: BANYUWANGI
C4: Provinsi | D4: JAWA TIMUR
C9: Kelurahan | D9: BENGKAK
A12: I | B12: DATA PEMILIH DAN PENGGUNAAN HAK PILIH | Y12: JUMLAH AKHIR
A13: A | B13: DATA PEMILIH | E13: TPS 001 | F13: TPS 002 | G13: TPS 003 | H13: TPS 004 | I13: TPS 005 | J13: TPS 006 | K13: TPS 007 | L13: TPS 008 | M13: TPS 009 | N13: TPS 010 | O13: TPS 011 | P13: TPS 012 | Q13: TPS 013 | R13: TPS 014 | S13: TPS 015 | T13: TPS 016 | U13: TPS 017 | V13: TPS 018 | W13: TPS 019 | X13: TPS 020
B14: Jumlah Pemilih dalam Daftar Pemilih Tetap (DPT) | D14: LK | E14: 121 | F14: 137 | G14: 150 | H14: 141 | I14: 129 | J14: 142 | K14: 142 | L14: 142 | M14: 132 | N14: 111 | O14: 121 | P14: 140 | Q14: 115 | R14: 135 | S14: 139 | T14: 110 | U14: 151 | V14: 139 | W14: 133 | X14: 132 | Y14: =SUM(E14:X14) -> 2662
D15: PR | E15: 114 | F15: 156 | G15: 148 | H15: 137 | I15: 143 | J15: 151 | K15: 148 | L15: 141 | M15: 135 | N15: 129 | O15: 129 | P15: 121 | Q15: 115 | R15: 147 | S15: 152 | T15: 132 | U15: 146 | V15: 149 | W15: 147 | X15: 144 | Y15: =SUM(E15:X15) -> 2784
D16: JML | E16: =SUM(E14:E15) -> 235 | F16: =SUM(F14:F15) -> 293 | G16: =SUM(G14:G15) -> 298 | H16: =SUM(H14:H15) -> 278 | I16: =SUM(I14:I15) -> 272 | J16: =SUM(J14:J15) -> 293 | K16: =SUM(K14:K15) -> 290 | L16: =SUM(L14:L15) -> 283 | ... X16: =SUM(X14:X15) -> 276 | Y16: =SUM(E16:X16) -> 5446
A18: B | B18: PENGGUNA HAK PILIH
B19: 1. | C19: Jumlah pengguna hak pilih dalam Daftar Pemilih Tetap (DPT) | D19: LK | E19: 98 | F19: 99 | G19: 122 | H19: 107 | I19: 94 | J19: 114 | K19: 107 | L19: 116 | M19: 97 | N19: 83 | O19: 89 | P19: 107 | Q19: 93 | R19: 96 | S19: 99 | T19: 75 | U19: 137 | V19: 107 | W19: 109 | X19: 101 | Y19: =SUM(E19:X19) -> 2050
D20: PR | E20: 102 | F20: 117 | G20: 109 | H20: 100 | I20: 110 | J20: 129 | K20: 123 | L20: 110 | M20: 112 | N20: 110 | O20: 116 | P20: 106 | Q20: 100 | R20: 118 | S20: 123 | T20: 94 | U20: 138 | V20: 124 | W20: 116 | X20: 114 | Y20: =SUM(E20:X20) -> 2271
D21: JML | E21: =SUM(E19:E20) -> 200 | F21: =SUM(F19:F20) -> 216 | G21: =SUM(G19:G20) -> 231 | H21: =SUM(H19:H20) -> 207 | I21: =SUM(I19:I20) -> 204 | J21: =SUM(J19:J20) -> 243 | K21: =SUM(K19:K20) -> 230 | L21: =SUM(L19:L20) -> 226 | ... X21: =SUM(X19:X20) -> 215 | Y21: =SUM(E21:X21) -> 4321
B22: 2. | C22: Jumlah pengguna hak pilih dalam Daftar Pemilih Tambahan (DPTb) | D22: LK | E22: 0 | F22: 0 | G22: 0 | H22: 0 | I22: 0 | J22: 0 | K22: 0 | L22: 0 | M22: 0 | N22: 0 | O22: 0 | P22: 0 | Q22: 0 | R22: 0 | S22: 0 | T22: 0 | U22: 0 | V22: 0 | W22: 0 | X22: 0 | Y22: =SUM(E22:X22) -> 0
D23: PR | E23: 0 | F23: 0 | G23: 0 | H23: 0 | I23: 0 | J23: 0 | K23: 0 | L23: 0 | M23: 0 | N23: 0 | O23: 0 | P23: 0 | Q23: 0 | R23: 0 | S23: 0 | T23: 0 | U23: 0 | V23: 0 | W23: 0 | X23: 0 | Y23: =SUM(E23:X23) -> 0
D24: JML | E24: =SUM(E22:E23) -> 0 | F24: =SUM(F22:F23) -> 0 | G24: =SUM(G22:G23) -> 0 | H24: =SUM(H22:H23) -> 0 | I24: =SUM(I22:I23) -> 0 | J24: =SUM(J22:J23) -> 0 | K24: =SUM(K22:K23) -> 0 | L24: =SUM(L22:L23) -> 0 | ... X24: =SUM(X22:X23) -> 0 | Y24: =SUM(E24:X24) -> 0
B25: 3. | C25: Jumlah pengguna hak pilih dalam Daftar Pemilih Khusus (DPK) | D25: LK | E25: 0 | F25: 0 | G25: 0 | H25: 0 | I25: 0 | J25: 0 | K25: 0 | L25: 0 | M25: 0 | N25: 0 | O25: 0 | P25: 0 | Q25: 0 | R25: 0 | S25: 0 | T25: 0 | U25: 1 | V25: 0 | W25: 0 | X25: 1 | Y25: =SUM(E25:X25) -> 2
D26: PR | E26: 0 | F26: 0 | G26: 0 | H26: 0 | I26: 0 | J26: 0 | K26: 0 | L26: 0 | M26: 0 | N26: 0 | O26: 0 | P26: 0 | Q26: 0 | R26: 0 | S26: 0 | T26: 0 | U26: 0 | V26: 0 | W26: 0 | X26: 1 | Y26: =SUM(E26:X26) -> 1
D27: JML | E27: =SUM(E25:E26) -> 0 | F27: =SUM(F25:F26) -> 0 | G27: =SUM(G25:G26) -> 0 | H27: =SUM(H25:H26) -> 0 | I27: =SUM(I25:I26) -> 0 | J27: =SUM(J25:J26) -> 0 | K27: =SUM(K25:K26) -> 0 | L27: =SUM(L25:L26) -> 0 | ... X27: =SUM(X25:X26) -> 2 | Y27: =SUM(E27:X27) -> 3
B28: 4. | C28: Jumlah Pengguna Hak Pilih (B.1+B.2+B.3) | D28: LK | E28: =SUM(E19,E22,E25) -> 98 | F28: =SUM(F19,F22,F25) -> 99 | G28: =SUM(G19,G22,G25) -> 122 | H28: =SUM(H19,H22,H25) -> 107 | I28: =SUM(I19,I22,I25) -> 94 | J28: =SUM(J19,J22,J25) -> 114 | K28: =SUM(K19,K22,K25) -> 107 | L28: =SUM(L19,L22,L25) -> 116 | ... X28: =SUM(X19,X22,X25) -> 102 | Y28: =SUM(E28:X28) -> 2052
D29: PR | E29: =SUM(E20,E23,E26) -> 102 | F29: =SUM(F20,F23,F26) -> 117 | G29: =SUM(G20,G23,G26) -> 109 | H29: =SUM(H20,H23,H26) -> 100 | I29: =SUM(I20,I23,I26) -> 110 | J29: =SUM(J20,J23,J26) -> 129 | K29: =SUM(K20,K23,K26) -> 123 | L29: =SUM(L20,L23,L26) -> 110 | ... X29: =SUM(X20,X23,X26) -> 115 | Y29: =SUM(E29:X29) -> 2272
D30: JML | E30: =SUM(E28:E29) -> 200 | F30: =SUM(F28:F29) -> 216 | G30: =SUM(G28:G29) -> 231 | H30: =SUM(H28:H29) -> 207 | I30: =SUM(I28:I29) -> 204 | J30: =SUM(J28:J29) -> 243 | K30: =SUM(K28:K29) -> 230 | L30: =SUM(L28:L29) -> 226 | ... X30: =SUM(X28:X29) -> 217 | Y30: =SUM(E30:X30) -> 4324
A32: II | B32: DATA PENGGUNAAN SURAT SUARA
A33: 1 | B33: Jumlah surat suara yang diterima, termasuk surat suara cadangan 2,5% dari DPT | E33: 240 | F33: 299 | G33: 304 | H33: 284 | I33: 277 | J33: 298 | K33: 296 | L33: 289 | M33: 273 | N33: 245 | O33: 255 | P33: 267 | Q33: 235 | R33: 287 | S33: 297 | T33: 247 | U33: 304 | V33: 294 | W33: 286 | X33: 283 | Y33: =SUM(E33:X33) -> 5560
A34: 2 | B34: Jumlah surat suara yang digunakan | E34: 200 | F34: 216 | G34: 231 | H34: 207 | I34: 204 | J34: 243 | K34: 230 | L34: 226 | M34: 209 | N34: 193 | O34: 205 | P34: 213 | Q34: 193 | R34: 214 | S34: 222 | T34: 169 | U34: 276 | V34: 231 | W34: 225 | X34: 217 | Y34: =SUM(E34:X34) -> 4324
A35: 3 | B35: Jumlah surat suara dikembalikan oleh pemilih (karena rusak atau keliru coblos) | E35: 0 | F35: 0 | G35: 0 | H35: 0 | I35: 0 | J35: 0 | K35: 0 | L35: 0 | M35: 0 | N35: 1 | O35: 0 | P35: 0 | Q35: 0 | R35: 0 | S35: 0 | T35: 0 | U35: 1 | V35: 0 | W35: 0 | X35: 0 | Y35: =SUM(E35:X35) -> 2
A36: 4 | B36: Jumlah surat suara yang tidak digunakan/tidak terpakai, termasuk sisa surat suara cadangan | E36: =E33-(E34+E35) -> 40 | F36: =F33-(F34+F35) -> 83 | G36: =G33-(G34+G35) -> 73 | H36: =H33-(H34+H35) -> 77 | I36: =I33-(I34+I35) -> 73 | J36: =J33-(J34+J35) -> 55 | K36: =K33-(K34+K35) -> 66 | L36: =L33-(L34+L35) -> 63 | ... X36: =X33-(X34+X35) -> 66 | Y36: =SUM(E36:X36) -> 1234
A38: III | B38: DATA PEMILIH DISABILITAS
B39: Jumlah seluruh Pemilih disabilitas yang menggunakan hak pilih | D39: LK | E39: 0 | F39: 0 | G39: 0 | H39: 0 | I39: 0 | J39: 0 | K39: 0 | L39: 0 | M39: 0 | N39: 0 | O39: 0 | P39: 0 | Q39: 0 | R39: 0 | S39: 0 | T39: 0 | U39: 0 | V39: 0 | W39: 0 | X39: 0 | Y39: =SUM(E39:X39) -> 0
D40: PR | E40: 0 | F40: 0 | G40: 0 | H40: 0 | I40: 0 | J40: 0 | K40: 0 | L40: 0 | M40: 0 | N40: 0 | O40: 1 | P40: 0 | Q40: 0 | R40: 0 | S40: 0 | T40: 0 | U40: 0 | V40: 0 | W40: 0 | X40: 0 | Y40: =SUM(E40:X40) -> 1
D41: JML | E41: =SUM(E39:E40) -> 0 | F41: =SUM(F39:F40) -> 0 | G41: =SUM(G39:G40) -> 0 | H41: =SUM(H39:H40) -> 0 | I41: =SUM(I39:I40) -> 0 | J41: =SUM(J39:J40) -> 0 | K41: =SUM(K39:K40) -> 0 | L41: =SUM(L39:L40) -> 0 | ... X41: =SUM(X39:X40) -> 0 | Y41: =SUM(E41:X41) -> 1
A43: IV | B43: DATA RINCIAN PEROLEHAN SUARA PASANGAN CALON BUPATI DAN WAKIL BUPATI
A44: NOMOR DAN NAMA CALON
B45: 1. | C45: AA. AHMAD NAWARDI | E45: 10 | F45: 22 | G45: 19 | H45: 6 | I45: 7 | J45: 14 | K45: 12 | L45: 17 | M45: 26 | N45: 19 | O45: 22 | P45: 12 | Q45: 14 | R45: 28 | S45: 16 | T45: 5 | U45: 21 | V45: 20 | W45: 18 | X45: 27 | Y45: =SUM(E45:X45) -> 335
B46: 2. | C46: Ir. H. AA LA NYALLA MAHMUD MATTALITI, M.HP. | E46: 51 | F46: 30 | G46: 52 | H46: 31 | I46: 30 | J46: 32 | K46: 27 | L46: 28 | M46: 38 | N46: 36 | O46: 29 | P46: 36 | Q46: 23 | R46: 44 | S46: 54 | T46: 32 | U46: 29 | V46: 23 | W46: 47 | X46: 50 | Y46: =SUM(E46:X46) -> 722
B47: 3. | C47: ABDUL QADIR AMIR HARTONO, S.E., S.H., M.H. | E47: 16 | F47: 17 | G47: 23 | H47: 22 | I47: 9 | J47: 20 | K47: 21 | L47: 16 | M47: 11 | N47: 19 | O47: 12 | P47: 19 | Q47: 20 | R47: 13 | S47: 9 | T47: 22 | U47: 22 | V47: 8 | W47: 11 | X47: 20 | Y47: =SUM(E47:X47) -> 330
B48: 4. | C48: ADILLA AZIS, S.E. | E48: 15 | F48: 23 | G48: 16 | H48: 20 | I48: 17 | J48: 34 | K48: 26 | L48: 35 | M48: 20 | N48: 13 | O48: 21 | P48: 19 | Q48: 10 | R48: 17 | S48: 15 | T48: 20 | U48: 22 | V48: 19 | W48: 21 | X48: 20 | Y48: =SUM(E48:X48) -> 403
B49: 5. | C49: Ir. H. AGUS RAHARDJO, MSc.M. | E49: 12 | F49: 14 | G49: 15 | H49: 12 | I49: 11 | J49: 17 | K49: 11 | L49: 11 | M49: 10 | N49: 11 | O49: 11 | P49: 19 | Q49: 19 | R49: 13 | S49: 18 | T49: 13 | U49: 24 | V49: 12 | W49: 17 | X49: 10 | Y49: =SUM(E49:X49) -> 280
B50: 6. | C50: Drs. AYUB KHAN | E50: 16 | F50: 16 | G50: 25 | H50: 24 | I50: 14 | J50: 14 | K50: 34 | L50: 13 | M50: 21 | N50: 22 | O50: 46 | P50: 28 | Q50: 19 | R50: 15 | S50: 20 | T50: 9 | U50: 31 | V50: 27 | W50: 13 | X50: 13 | Y50: =SUM(E50:X50) -> 420
B51: 7. | C51: BAMBANG HARIANTO | E51: 0 | F51: 4 | G51: 0 | H51: 1 | I51: 2 | J51: 2 | K51: 1 | L51: 2 | M51: 1 | N51: 0 | O51: 1 | P51: 1 | Q51: 0 | R51: 2 | S51: 2 | T51: 2 | U51: 5 | V51: 0 | W51: 3 | X51: 4 | Y51: =SUM(E51:X51) -> 33
...

Sheet ALASBULUH
C2: Kecamatan | D2: WONGSOREJO
C3: Kabupaten | D3: BANYUWANGI
C4: Provinsi | D4: JAWA TIMUR
C9: Kelurahan | D9: ALASBULUH
A12: I | B12: DATA PEMILIH DAN PENGGUNAAN HAK PILIH | AG12: JUMLAH AKHIR
A13: A | B13: DATA PEMILIH | E13: TPS 001 | F13: TPS 002 | G13: TPS 003 | H13: TPS 004 | I13: TPS 005 | J13: TPS 006 | K13: TPS 007 | L13: TPS 008 | M13: TPS 009 | N13: TPS 010 | O13: TPS 011 | P13: TPS 012 | Q13: TPS 013 | R13: TPS 014 | S13: TPS 015 | T13: TPS 016 | U13: TPS 017 | V13: TPS 018 | W13: TPS 019 | X13: TPS 020 | Y13: TPS 021 | Z13: TPS 022 | AA13: TPS 023 | AB13: TPS 024 | AC13: TPS 025 | AD13: TPS 026 | AE13: TPS 027 | AF13: TPS 028
B14: Jumlah Pemilih dalam Daftar Pemilih Tetap (DPT) | D14: LK | E14: 152 | F14: 132 | G14: 152 | H14: 172 | I14: 136 | J14: 167 | K14: 143 | L14: 151 | M14: 160 | N14: 142 | O14: 147 | P14: 140 | Q14: 116 | R14: 134 | S14: 135 | T14: 154 | U14: 129 | V14: 155 | W14: 147 | X14: 147 | Y14: 128 | Z14: 123 | AA14: 151 | AB14: 115 | AC14: 135 | AD14: 141 | AE14: 118 | AF14: 124 | AG14: =SUM(E14:AF14) -> 3946
D15: PR | E15: 145 | F15: 168 | G15: 145 | H15: 127 | I15: 163 | J15: 130 | K15: 156 | L15: 148 | M15: 139 | N15: 157 | O15: 139 | P15: 154 | Q15: 126 | R15: 151 | S15: 145 | T15: 143 | U15: 133 | V15: 142 | W15: 152 | X15: 153 | Y15: 141 | Z15: 120 | AA15: 149 | AB15: 100 | AC15: 145 | AD15: 137 | AE15: 120 | AF15: 141 | AG15: =SUM(E15:AF15) -> 3969
D16: JML | E16: =SUM(E14:E15) -> 297 | F16: =SUM(F14:F15) -> 300 | G16: =SUM(G14:G15) -> 297 | H16: =SUM(H14:H15) -> 299 | I16: =SUM(I14:I15) -> 299 | J16: =SUM(J14:J15) -> 297 | K16: =SUM(K14:K15) -> 299 | L16: =SUM(L14:L15) -> 299 | ... AF16: =SUM(AF14:AF15) -> 265 | AG16: =SUM(E16:AF16) -> 7915
A18: B | B18: PENGGUNA HAK PILIH
B19: 1. | C19: Jumlah pengguna hak pilih dalam Daftar Pemilih Tetap (DPT) | D19: LK | E19: 109 | F19: 86 | G19: 113 | H19: 126 | I19: 83 | J19: 116 | K19: 93 | L19: 97 | M19: 125 | N19: 109 | O19: 111 | P19: 118 | Q19: 85 | R19: 101 | S19: 97 | T19: 98 | U19: 99 | V19: 104 | W19: 93 | X19: 124 | Y19: 104 | Z19: 89 | AA19: 101 | AB19: 92 | AC19: 113 | AD19: 104 | AE19: 101 | AF19: 85 | AG19: =SUM(E19:AF19) -> 2876
D20: PR | E20: 106 | F20: 120 | G20: 99 | H20: 104 | I20: 137 | J20: 101 | K20: 110 | L20: 127 | M20: 122 | N20: 137 | O20: 109 | P20: 126 | Q20: 94 | R20: 115 | S20: 101 | T20: 92 | U20: 98 | V20: 98 | W20: 117 | X20: 124 | Y20: 110 | Z20: 92 | AA20: 115 | AB20: 87 | AC20: 120 | AD20: 122 | AE20: 97 | AF20: 102 | AG20: =SUM(E20:AF20) -> 3082
D21: JML | E21: =SUM(E19:E20) -> 215 | F21: =SUM(F19:F20) -> 206 | G21: =SUM(G19:G20) -> 212 | H21: =SUM(H19:H20) -> 230 | I21: =SUM(I19:I20) -> 220 | J21: =SUM(J19:J20) -> 217 | K21: =SUM(K19:K20) -> 203 | L21: =SUM(L19:L20) -> 224 | ... AF21: =SUM(AF19:AF20) -> 187 | AG21: =SUM(E21:AF21) -> 5958
B22: 2. | C22: Jumlah pengguna hak pilih dalam Daftar Pemilih Tambahan (DPTb) | D22: LK | E22: 0 | F22: 1 | G22: 0 | H22: 0 | I22: 0 | J22: 0 | K22: 1 | L22: 0 | M22: 0 | N22: 0 | O22: 0 | P22: 0 | Q22: 0 | R22: 0 | S22: 0 | T22: 0 | U22: 0 | V22: 0 | W22: 0 | X22: 0 | Y22: 0 | Z22: 0 | AA22: 0 | AB22: 0 | AC22: 0 | AD22: 0 | AE22: 1 | AF22: 0 | AG22: =SUM(E22:AF22) -> 3
D23: PR | E23: 0 | F23: 1 | G23: 0 | H23: 0 | I23: 0 | J23: 0 | K23: 0 | L23: 0 | M23: 0 | N23: 0 | O23: 0 | P23: 0 | Q23: 0 | R23: 0 | S23: 0 | T23: 0 | U23: 0 | V23: 0 | W23: 0 | X23: 0 | Y23: 0 | Z23: 0 | AA23: 0 | AB23: 0 | AC23: 0 | AD23: 0 | AE23: 0 | AF23: 0 | AG23: =SUM(E23:AF23) -> 1
D24: JML | E24: =SUM(E22:E23) -> 0 | F24: =SUM(F22:F23) -> 2 | G24: =SUM(G22:G23) -> 0 | H24: =SUM(H22:H23) -> 0 | I24: =SUM(I22:I23) -> 0 | J24: =SUM(J22:J23) -> 0 | K24: =SUM(K22:K23) -> 1 | L24: =SUM(L22:L23) -> 0 | ... AF24: =SUM(AF22:AF23) -> 0 | AG24: =SUM(E24:AF24) -> 4
B25: 3. | C25: Jumlah pengguna hak pilih dalam Daftar Pemilih Khusus (DPK) | D25: LK | E25: 0 | F25: 0 | G25: 0 | H25: 0 | I25: 0 | J25: 0 | K25: 0 | L25: 0 | M25: 0 | N25: 0 | O25: 0 | P25: 0 | Q25: 1 | R25: 0 | S25: 0 | T25: 0 | U25: 0 | V25: 0 | W25: 0 | X25: 0 | Y25: 6 | Z25: 0 | AA25: 0 | AB25: 0 | AC25: 0 | AD25: 0 | AE25: 0 | AF25: 8 | AG25: =SUM(E25:AF25) -> 15
D26: PR | E26: 0 | F26: 0 | G26: 0 | H26: 0 | I26: 0 | J26: 0 | K26: 0 | L26: 0 | M26: 0 | N26: 0 | O26: 0 | P26: 0 | Q26: 2 | R26: 0 | S26: 0 | T26: 0 | U26: 0 | V26: 0 | W26: 0 | X26: 0 | Y26: 10 | Z26: 0 | AA26: 0 | AB26: 0 | AC26: 0 | AD26: 0 | AE26: 0 | AF26: 6 | AG26: =SUM(E26:AF26) -> 18
D27: JML | E27: =SUM(E25:E26) -> 0 | F27: =SUM(F25:F26) -> 0 | G27: =SUM(G25:G26) -> 0 | H27: =SUM(H25:H26) -> 0 | I27: =SUM(I25:I26) -> 0 | J27: =SUM(J25:J26) -> 0 | K27: =SUM(K25:K26) -> 0 | L27: =SUM(L25:L26) -> 0 | ... AF27: =SUM(AF25:AF26) -> 14 | AG27: =SUM(E27:AF27) -> 33
B28: 4. | C28: Jumlah Pengguna Hak Pilih (B.1+B.2+B.3) | D28: LK | E28: =SUM(E19,E22,E25) -> 109 | F28: =SUM(F19,F22,F25) -> 87 | G28: =SUM(G19,G22,G25) -> 113 | H28: =SUM(H19,H22,H25) -> 126 | I28: =SUM(I19,I22,I25) -> 83 | J28: =SUM(J19,J22,J25) -> 116 | K28: =SUM(K19,K22,K25) -> 94 | L28: =SUM(L19,L22,L25) -> 97 | ... AF28: =SUM(AF19,AF22,AF25) -> 93 | AG28: =SUM(E28:AF28) -> 2894
D29: PR | E29: =SUM(E20,E23,E26) -> 106 | F29: =SUM(F20,F23,F26) -> 121 | G29: =SUM(G20,G23,G26) -> 99 | H29: =SUM(H20,H23,H26) -> 104 | I29: =SUM(I20,I23,I26) -> 137 | J29: =SUM(J20,J23,J26) -> 101 | K29: =SUM(K20,K23,K26) -> 110 | L29: =SUM(L20,L23,L26) -> 127 | ... AF29: =SUM(AF20,AF23,AF26) -> 108 | AG29: =SUM(E29:AF29) -> 3101
D30: JML | E30: =SUM(E28:E29) -> 215 | F30: =SUM(F28:F29) -> 208 | G30: =SUM(G28:G29) -> 212 | H30: =SUM(H28:H29) -> 230 | I30: =SUM(I28:I29) -> 220 | J30: =SUM(J28:J29) -> 217 | K30: =SUM(K28:K29) -> 204 | L30: =SUM(L28:L29) -> 224 | ... AF30: =SUM(AF28:AF29) -> 201 | AG30: =SUM(E30:AF30) -> 5995
A32: II | B32: DATA PENGGUNAAN SURAT SUARA
A33: 1 | B33: Jumlah surat suara yang diterima, termasuk surat suara cadangan 2,5% dari DPT | E33: 303 | F33: 306 | G33: 304 | H33: 305 | I33: 305 | J33: 303 | K33: 305 | L33: 305 | M33: 305 | N33: 305 | O33: 292 | P33: 300 | Q33: 247 | R33: 291 | S33: 286 | T33: 303 | U33: 268 | V33: 303 | W33: 305 | X33: 306 | Y33: 275 | Z33: 248 | AA33: 306 | AB33: 220 | AC33: 286 | AD33: 281 | AE33: 243 | AF33: 271 | AG33: =SUM(E33:AF33) -> 8077
A34: 2 | B34: Jumlah surat suara yang digunakan | E34: 215 | F34: 208 | G34: 212 | H34: 230 | I34: 220 | J34: 217 | K34: 204 | L34: 224 | M34: 247 | N34: 246 | O34: 220 | P34: 244 | Q34: 182 | R34: 216 | S34: 198 | T34: 190 | U34: 197 | V34: 202 | W34: 210 | X34: 248 | Y34: 230 | Z34: 181 | AA34: 216 | AB34: 179 | AC34: 233 | AD34: 226 | AE34: 199 | AF34: 201 | AG34: =SUM(E34:AF34) -> 5995
A35: 3 | B35: Jumlah surat suara dikembalikan oleh pemilih (karena rusak atau keliru coblos) | E35: 1 | F35: 0 | G35: 0 | H35: 0 | I35: 0 | J35: 1 | K35: 3 | L35: 0 | M35: 0 | N35: 0 | O35: 0 | P35: 0 | Q35: 0 | R35: 0 | S35: 0 | T35: 0 | U35: 0 | V35: 0 | W35: 0 | X35: 0 | Y35: 0 | Z35: 0 | AA35: 0 | AB35: 0 | AC35: 21 | AD35: 0 | AE35: 0 | AF35: 0 | AG35: =SUM(E35:AF35) -> 26
A36: 4 | B36: Jumlah surat suara yang tidak digunakan/tidak terpakai, termasuk sisa surat suara cadangan | E36: =E33-(E34+E35) -> 87 | F36: =F33-(F34+F35) -> 98 | G36: =G33-(G34+G35) -> 92 | H36: =H33-(H34+H35) -> 75 | I36: =I33-(I34+I35) -> 85 | J36: =J33-(J34+J35) -> 85 | K36: =K33-(K34+K35) -> 98 | L36: =L33-(L34+L35) -> 81 | ... AF36: =AF33-(AF34+AF35) -> 70 | AG36: =SUM(E36:AF36) -> 2056
A38: III | B38: DATA PEMILIH DISABILITAS
B39: Jumlah seluruh Pemilih disabilitas yang menggunakan hak pilih | D39: LK | E39: 0 | F39: 0 | G39: 0 | H39: 0 | I39: 0 | J39: 0 | K39: 0 | L39: 0 | M39: 0 | N39: 0 | O39: 0 | P39: 0 | Q39: 0 | R39: 0 | S39: 0 | T39: 0 | U39: 0 | V39: 0 | W39: 0 | X39: 0 | Y39: 0 | Z39: 0 | AA39: 0 | AB39: 0 | AC39: 0 | AD39: 0 | AE39: 0 | AF39: 0 | AG39: =SUM(E39:AF39) -> 0
D40: PR | E40: 0 | F40: 0 | G40: 0 | H40: 0 | I40: 0 | J40: 0 | K40: 0 | L40: 0 | M40: 0 | N40: 0 | O40: 0 | P40: 0 | Q40: 0 | R40: 0 | S40: 0 | T40: 0 | U40: 0 | V40: 0 | W40: 0 | X40: 0 | Y40: 0 | Z40: 0 | AA40: 2 | AB40: 0 | AC40: 0 | AD40: 0 | AE40: 0 | AF40: 0 | AG40: =SUM(E40:AF40) -> 2
D41: JML | E41: =SUM(E39:E40) -> 0 | F41: =SUM(F39:F40) -> 0 | G41: =SUM(G39:G40) -> 0 | H41: =SUM(H39:H40) -> 0 | I41: =SUM(I39:I40) -> 0 | J41: =SUM(J39:J40) -> 0 | K41: =SUM(K39:K40) -> 0 | L41: =SUM(L39:L40) -> 0 | ... AF41: =SUM(AF39:AF40) -> 0 | AG41: =SUM(E41:AF41) -> 2
A43: IV | B43: DATA RINCIAN PEROLEHAN SUARA PASANGAN CALON BUPATI DAN WAKIL BUPATI
A44: NOMOR DAN NAMA CALON
B45: 1. | C45: AA. AHMAD NAWARDI | E45: 33 | F45: 11 | G45: 14 | H45: 23 | I45: 22 | J45: 20 | K45: 26 | L45: 48 | M45: 40 | N45: 19 | O45: 12 | P45: 38 | Q45: 44 | R45: 28 | S45: 18 | T45: 16 | U45: 19 | V45: 33 | W45: 30 | X45: 23 | Y45: 18 | Z45: 28 | AA45: 17 | AB45: 15 | AC45: 28 | AD45: 24 | AE45: 24 | AF45: 25 | AG45: =SUM(E45:AF45) -> 696
B46: 2. | C46: Ir. H. AA LA NYALLA MAHMUD MATTALITI, M.HP. | E46: 41 | F46: 60 | G46: 44 | H46: 47 | I46: 41 | J46: 35 | K46: 32 | L46: 33 | M46: 63 | N46: 33 | O46: 37 | P46: 35 | Q46: 29 | R46: 47 | S46: 30 | T46: 27 | U46: 41 | V46: 25 | W46: 41 | X46: 36 | Y46: 52 | Z46: 38 | AA46: 37 | AB46: 20 | AC46: 41 | AD46: 33 | AE46: 44 | AF46: 37 | AG46: =SUM(E46:AF46) -> 1079
B47: 3. | C47: ABDUL QADIR AMIR HARTONO, S.E., S.H., M.H. | E47: 21 | F47: 21 | G47: 26 | H47: 22 | I47: 28 | J47: 21 | K47: 22 | L47: 23 | M47: 23 | N47: 22 | O47: 27 | P47: 26 | Q47: 17 | R47: 10 | S47: 8 | T47: 29 | U47: 32 | V47: 18 | W47: 17 | X47: 23 | Y47: 13 | Z47: 16 | AA47: 16 | AB47: 13 | AC47: 10 | AD47: 23 | AE47: 16 | AF47: 17 | AG47: =SUM(E47:AF47) -> 560
B48: 4. | C48: ADILLA AZIS, S.E. | E48: 23 | F48: 26 | G48: 19 | H48: 29 | I48: 24 | J48: 31 | K48: 13 | L48: 17 | M48: 17 | N48: 25 | O48: 21 | P48: 17 | Q48: 12 | R48: 24 | S48: 17 | T48: 16 | U48: 19 | V48: 17 | W48: 16 | X48: 26 | Y48: 22 | Z48: 13 | AA48: 12 | AB48: 10 | AC48: 13 | AD48: 27 | AE48: 19 | AF48: 20 | AG48: =SUM(E48:AF48) -> 545
B49: 5. | C49: Ir. H. AGUS RAHARDJO, MSc.M. | E49: 9 | F49: 11 | G49: 14 | H49: 20 | I49: 13 | J49: 18 | K49: 12 | L49: 14 | M49: 19 | N49: 15 | O49: 13 | P49: 28 | Q49: 6 | R49: 12 | S49: 4 | T49: 11 | U49: 11 | V49: 13 | W49: 7 | X49: 15 | Y49: 16 | Z49: 17 | AA49: 12 | AB49: 13 | AC49: 18 | AD49: 19 | AE49: 15 | AF49: 18 | AG49: =SUM(E49:AF49) -> 393
B50: 6. | C50: Drs. AYUB KHAN | E50: 22 | F50: 14 | G50: 16 | H50: 14 | I50: 28 | J50: 33 | K50: 44 | L50: 38 | M50: 20 | N50: 18 | O50: 36 | P50: 26 | Q50: 13 | R50: 12 | S50: 23 | T50: 32 | U50: 19 | V50: 29 | W50: 26 | X50: 24 | Y50: 20 | Z50: 10 | AA50: 30 | AB50: 21 | AC50: 55 | AD50: 31 | AE50: 26 | AF50: 16 | AG50: =SUM(E50:AF50) -> 696
B51: 7. | C51: BAMBANG HARIANTO | E51: 5 | F51: 2 | G51: 3 | H51: 3 | I51: 3 | J51: 3 | K51: 1 | L51: 2 | M51: 3 | N51: 1 | O51: 1 | P51: 3 | Q51: 1 | R51: 0 | S51: 2 | T51: 0 | U51: 1 | V51: 4 | W51: 0 | X51: 4 | Y51: 2 | Z51: 2 | AA51: 1 | AB51: 6 | AC51: 3 | AD51: 2 | AE51: 1 | AF51: 0 | AG51: =SUM(E51:AF51) -> 59
...

Sheet WONGSOREJO
C2: Kecamatan | D2: WONGSOREJO
C3: Kabupaten | D3: BANYUWANGI
C4: Provinsi | D4: JAWA TIMUR
C9: Kelurahan | D9: WONGSOREJO
A12: I | B12: DATA PEMILIH DAN PENGGUNAAN HAK PILIH | AM12: JUMLAH AKHIR
A13: A | B13: DATA PEMILIH | E13: TPS 001 | F13: TPS 002 | G13: TPS 003 | H13: TPS 004 | I13: TPS 005 | J13: TPS 006 | K13: TPS 007 | L13: TPS 008 | M13: TPS 009 | N13: TPS 010 | O13: TPS 011 | P13: TPS 012 | Q13: TPS 013 | R13: TPS 014 | S13: TPS 015 | T13: TPS 016 | U13: TPS 017 | V13: TPS 018 | W13: TPS 019 | X13: TPS 020 | Y13: TPS 021 | Z13: TPS 022 | AA13: TPS 023 | AB13: TPS 024 | AC13: TPS 025 | AD13: TPS 026 | AE13: TPS 027 | AF13: TPS 028 | AG13: TPS 029 | AH13: TPS 030 | AI13: TPS 031 | AJ13: TPS 032 | AK13: TPS 033 | AL13: TPS 034
B14: Jumlah Pemilih dalam Daftar Pemilih Tetap (DPT) | D14: LK | E14: 119 | F14: 124 | G14: 138 | H14: 131 | I14: 132 | J14: 132 | K14: 122 | L14: 113 | M14: 135 | N14: 124 | O14: 121 | P14: 123 | Q14: 132 | R14: 132 | S14: 144 | T14: 130 | U14: 123 | V14: 132 | W14: 120 | X14: 125 | Y14: 90 | Z14: 116 | AA14: 127 | AB14: 120 | AC14: 118 | AD14: 139 | AE14: 119 | AF14: 114 | AG14: 137 | AH14: 116 | AI14: 141 | AJ14: 117 | AK14: 101 | AL14: 106 | AM14: =SUM(E14:AL14) -> 4213
D15: PR | E15: 124 | F15: 149 | G15: 136 | H15: 131 | I15: 132 | J15: 139 | K15: 148 | L15: 115 | M15: 134 | N15: 119 | O15: 130 | P15: 131 | Q15: 138 | R15: 128 | S15: 142 | T15: 134 | U15: 125 | V15: 146 | W15: 131 | X15: 124 | Y15: 107 | Z15: 146 | AA15: 142 | AB15: 138 | AC15: 130 | AD15: 138 | AE15: 122 | AF15: 115 | AG15: 138 | AH15: 110 | AI15: 135 | AJ15: 115 | AK15: 111 | AL15: 101 | AM15: =SUM(E15:AL15) -> 4404
D16: JML | E16: =SUM(E14:E15) -> 243 | F16: =SUM(F14:F15) -> 273 | G16: =SUM(G14:G15) -> 274 | H16: =SUM(H14:H15) -> 262 | I16: =SUM(I14:I15) -> 264 | J16: =SUM(J14:J15) -> 271 | K16: =SUM(K14:K15) -> 270 | L16: =SUM(L14:L15) -> 228 | ... AL16: =SUM(AL14:AL15) -> 207 | AM16: =SUM(E16:AL16) -> 8617
A18: B | B18: PENGGUNA HAK PILIH
B19: 1. | C19: Jumlah pengguna hak pilih dalam Daftar Pemilih Tetap (DPT) | D19: LK | E19: 82 | F19: 86 | G19: 111 | H19: 92 | I19: 98 | J19: 93 | K19: 94 | L19: 90 | M19: 94 | N19: 97 | O19: 90 | P19: 97 | Q19: 109 | R19: 97 | S19: 118 | T19: 100 | U19: 89 | V19: 105 | W19: 81 | X19: 88 | Y19: 58 | Z19: 85 | AA19: 99 | AB19: 105 | AC19: 88 | AD19: 100 | AE19: 83 | AF19: 89 | AG19: 96 | AH19: 81 | AI19: 92 | AJ19: 103 | AK19: 74 | AL19: 79 | AM19: =SUM(E19:AL19) -> 3143
D20: PR | E20: 93 | F20: 102 | G20: 111 | H20: 123 | I20: 112 | J20: 118 | K20: 117 | L20: 96 | M20: 107 | N20: 100 | O20: 102 | P20: 102 | Q20: 118 | R20: 106 | S20: 121 | T20: 106 | U20: 93 | V20: 116 | W20: 94 | X20: 91 | Y20: 79 | Z20: 109 | AA20: 105 | AB20: 118 | AC20: 99 | AD20: 113 | AE20: 84 | AF20: 87 | AG20: 109 | AH20: 76 | AI20: 80 | AJ20: 100 | AK20: 83 | AL20: 73 | AM20: =SUM(E20:AL20) -> 3443
D21: JML | E21: =SUM(E19:E20) -> 175 | F21: =SUM(F19:F20) -> 188 | G21: =SUM(G19:G20) -> 222 | H21: =SUM(H19:H20) -> 215 | I21: =SUM(I19:I20) -> 210 | J21: =SUM(J19:J20) -> 211 | K21: =SUM(K19:K20) -> 211 | L21: =SUM(L19:L20) -> 186 | ... AL21: =SUM(AL19:AL20) -> 152 | AM21: =SUM(E21:AL21) -> 6586
B22: 2. | C22: Jumlah pengguna hak pilih dalam Daftar Pemilih Tambahan (DPTb) | D22: LK | E22: 0 | F22: 0 | G22: 0 | H22: 0 | I22: 0 | J22: 0 | K22: 0 | L22: 0 | M22: 0 | N22: 0 | O22: 0 | P22: 1 | Q22: 0 | R22: 0 | S22: 0 | T22: 0 | U22: 0 | V22: 0 | W22: 0 | X22: 0 | Y22: 0 | Z22: 0 | AA22: 0 | AB22: 0 | AC22: 0 | AD22: 0 | AE22: 1 | AF22: 1 | AG22: 4 | AH22: 3 | AI22: 0 | AJ22: 1 | AK22: 4 | AL22: 0 | AM22: =SUM(E22:AL22) -> 15
D23: PR | E23: 0 | F23: 0 | G23: 0 | H23: 0 | I23: 0 | J23: 0 | K23: 0 | L23: 0 | M23: 0 | N23: 1 | O23: 0 | P23: 1 | Q23: 0 | R23: 0 | S23: 0 | T23: 0 | U23: 0 | V23: 0 | W23: 0 | X23: 0 | Y23: 0 | Z23: 1 | AA23: 1 | AB23: 0 | AC23: 1 | AD23: 1 | AE23: 2 | AF23: 0 | AG23: 0 | AH23: 2 | AI23: 0 | AJ23: 0 | AK23: 1 | AL23: 0 | AM23: =SUM(E23:AL23) -> 11
D24: JML | E24: =SUM(E22:E23) -> 0 | F24: =SUM(F22:F23) -> 0 | G24: =SUM(G22:G23) -> 0 | H24: =SUM(H22:H23) -> 0 | I24: =SUM(I22:I23) -> 0 | J24: =SUM(J22:J23) -> 0 | K24: =SUM(K22:K23) -> 0 | L24: =SUM(L22:L23) -> 0 | ... AL24: =SUM(AL22:AL23) -> 0 | AM24: =SUM(E24:AL24) -> 26
B25: 3. | C25: Jumlah pengguna hak pilih dalam Daftar Pemilih Khusus (DPK) | D25: LK | E25: 1 | F25: 2 | G25: 0 | H25: 5 | I25: 0 | J25: 0 | K25: 0 | L25: 0 | M25: 0 | N25: 0 | O25: 0 | P25: 2 | Q25: 0 | R25: 0 | S25: 0 | T25: 0 | U25: 0 | V25: 1 | W25: 0 | X25: 1 | Y25: 0 | Z25: 1 | AA25: 1 | AB25: 2 | AC25: 3 | AD25: 1 | AE25: 0 | AF25: 0 | AG25: 1 | AH25: 0 | AI25: 4 | AJ25: 1 | AK25: 0 | AL25: 0 | AM25: =SUM(E25:AL25) -> 26
D26: PR | E26: 2 | F26: 1 | G26: 0 | H26: 4 | I26: 0 | J26: 3 | K26: 0 | L26: 0 | M26: 0 | N26: 0 | O26: 0 | P26: 0 | Q26: 0 | R26: 0 | S26: 0 | T26: 0 | U26: 0 | V26: 3 | W26: 0 | X26: 2 | Y26: 1 | Z26: 1 | AA26: 1 | AB26: 1 | AC26: 1 | AD26: 3 | AE26: 0 | AF26: 0 | AG26: 1 | AH26: 0 | AI26: 2 | AJ26: 1 | AK26: 0 | AL26: 0 | AM26: =SUM(E26:AL26) -> 27
D27: JML | E27: =SUM(E25:E26) -> 3 | F27: =SUM(F25:F26) -> 3 | G27: =SUM(G25:G26) -> 0 | H27: =SUM(H25:H26) -> 9 | I27: =SUM(I25:I26) -> 0 | J27: =SUM(J25:J26) -> 3 | K27: =SUM(K25:K26) -> 0 | L27: =SUM(L25:L26) -> 0 | ... AL27: =SUM(AL25:AL26) -> 0 | AM27: =SUM(E27:AL27) -> 53
B28: 4. | C28: Jumlah Pengguna Hak Pilih (B.1+B.2+B.3) | D28: LK | E28: =SUM(E19,E22,E25) -> 83 | F28: =SUM(F19,F22,F25) -> 88 | G28: =SUM(G19,G22,G25) -> 111 | H28: =SUM(H19,H22,H25) -> 97 | I28: =SUM(I19,I22,I25) -> 98 | J28: =SUM(J19,J22,J25) -> 93 | K28: =SUM(K19,K22,K25) -> 94 | L28: =SUM(L19,L22,L25) -> 90 | ... AL28: =SUM(AL19,AL22,AL25) -> 79 | AM28: =SUM(E28:AL28) -> 3184
D29: PR | E29: =SUM(E20,E23,E26) -> 95 | F29: =SUM(F20,F23,F26) -> 103 | G29: =SUM(G20,G23,G26) -> 111 | H29: =SUM(H20,H23,H26) -> 127 | I29: =SUM(I20,I23,I26) -> 112 | J29: =SUM(J20,J23,J26) -> 121 | K29: =SUM(K20,K23,K26) -> 117 | L29: =SUM(L20,L23,L26) -> 96 | ... AL29: =SUM(AL20,AL23,AL26) -> 73 | AM29: =SUM(E29:AL29) -> 3481
D30: JML | E30: =SUM(E28:E29) -> 178 | F30: =SUM(F28:F29) -> 191 | G30: =SUM(G28:G29) -> 222 | H30: =SUM(H28:H29) -> 224 | I30: =SUM(I28:I29) -> 210 | J30: =SUM(J28:J29) -> 214 | K30: =SUM(K28:K29) -> 211 | L30: =SUM(L28:L29) -> 186 | ... AL30: =SUM(AL28:AL29) -> 152 | AM30: =SUM(E30:AL30) -> 6665
A32: II | B32: DATA PENGGUNAAN SURAT SUARA
A33: 1 | B33: Jumlah surat suara yang diterima, termasuk surat suara cadangan 2,5% dari DPT | E33: 248 | F33: 279 | G33: 280 | H33: 268 | I33: 270 | J33: 277 | K33: 276 | L33: 233 | M33: 275 | N33: 248 | O33: 257 | P33: 260 | Q33: 276 | R33: 266 | S33: 292 | T33: 271 | U33: 253 | V33: 284 | W33: 257 | X33: 254 | Y33: 197 | Z33: 268 | AA33: 275 | AB33: 264 | AC33: 253 | AD33: 283 | AE33: 246 | AF33: 234 | AG33: 281 | AH33: 231 | AI33: 282 | AJ33: 237 | AK33: 217 | AL33: 212 | AM33: =SUM(E33:AL33) -> 8804
A34: 2 | B34: Jumlah surat suara yang digunakan | E34: 178 | F34: 191 | G34: 222 | H34: 224 | I34: 210 | J34: 214 | K34: 211 | L34: 186 | M34: 201 | N34: 198 | O34: 192 | P34: 203 | Q34: 227 | R34: 203 | S34: 239 | T34: 206 | U34: 182 | V34: 225 | W34: 175 | X34: 182 | Y34: 138 | Z34: 197 | AA34: 207 | AB34: 226 | AC34: 192 | AD34: 218 | AE34: 170 | AF34: 177 | AG34: 211 | AH34: 162 | AI34: 178 | AJ34: 206 | AK34: 162 | AL34: 152 | AM34: =SUM(E34:AL34) -> 6665
A35: 3 | B35: Jumlah surat suara dikembalikan oleh pemilih (karena rusak atau keliru coblos) | E35: 0 | F35: 2 | G35: 0 | H35: 0 | I35: 0 | J35: 0 | K35: 0 | L35: 0 | M35: 0 | N35: 0 | O35: 0 | P35: 0 | Q35: 0 | R35: 0 | S35: 0 | T35: 0 | U35: 1 | V35: 0 | W35: 0 | X35: 0 | Y35: 1 | Z35: 0 | AA35: 1 | AB35: 0 | AC35: 0 | AD35: 0 | AE35: 0 | AF35: 0 | AG35: 0 | AH35: 0 | AI35: 0 | AJ35: 0 | AK35: 1 | AL35: 0 | AM35: =SUM(E35:AL35) -> 6
A36: 4 | B36: Jumlah surat suara yang tidak digunakan/tidak terpakai, termasuk sisa surat suara cadangan | E36: =E33-(E34+E35) -> 70 | F36: =F33-(F34+F35) -> 86 | G36: =G33-(G34+G35) -> 58 | H36: =H33-(H34+H35) -> 44 | I36: =I33-(I34+I35) -> 60 | J36: =J33-(J34+J35) -> 63 | K36: =K33-(K34+K35) -> 65 | L36: =L33-(L34+L35) -> 47 | ... AL36: =AL33-(AL34+AL35) -> 60 | AM36: =SUM(E36:AL36) -> 2133
A38: III | B38: DATA PEMILIH DISABILITAS
B39: Jumlah seluruh Pemilih disabilitas yang menggunakan hak pilih | D39: LK | E39: 0 | F39: 0 | G39: 0 | H39: 2 | I39: 0 | J39: 0 | K39: 0 | L39: 0 | M39: 0 | N39: 0 | O39: 0 | P39: 0 | Q39: 0 | R39: 0 | S39: 0 | T39: 0 | U39: 0 | V39: 0 | W39: 0 | X39: 0 | Y39: 0 | Z39: 0 | AA39: 0 | AB39: 0 | AC39: 0 | AD39: 0 | AE39: 0 | AF39: 0 | AG39: 0 | AH39: 0 | AI39: 0 | AJ39: 0 | AK39: 0 | AL39: 0 | AM39: =SUM(E39:AL39) -> 2
D40: PR | E40: 0 | F40: 0 | G40: 0 | H40: 0 | I40: 0 | J40: 0 | K40: 0 | L40: 0 | M40: 0 | N40: 0 | O40: 0 | P40: 0 | Q40: 0 | R40: 0 | S40: 0 | T40: 0 | U40: 0 | V40: 0 | W40: 0 | X40: 0 | Y40: 0 | Z40: 0 | AA40: 1 | AB40: 0 | AC40: 0 | AD40: 0 | AE40: 0 | AF40: 0 | AG40: 1 | AH40: 0 | AI40: 0 | AJ40: 0 | AK40: 0 | AL40: 0 | AM40: =SUM(E40:AL40) -> 2
D41: JML | E41: =SUM(E39:E40) -> 0 | F41: =SUM(F39:F40) -> 0 | G41: =SUM(G39:G40) -> 0 | H41: =SUM(H39:H40) -> 2 | I41: =SUM(I39:I40) -> 0 | J41: =SUM(J39:J40) -> 0 | K41: =SUM(K39:K40) -> 0 | L41: =SUM(L39:L40) -> 0 | ... AL41: =SUM(AL39:AL40) -> 0 | AM41: =SUM(E41:AL41) -> 4
A43: IV | B43: DATA RINCIAN PEROLEHAN SUARA PASANGAN CALON BUPATI DAN WAKIL BUPATI
A44: NOMOR DAN NAMA CALON
B45: 1. | C45: AA. AHMAD NAWARDI | E45: 30 | F45: 11 | G45: 13 | H45: 32 | I45: 19 | J45: 10 | K45: 6 | L45: 19 | M45: 11 | N45: 21 | O45: 17 | P45: 20 | Q45: 17 | R45: 24 | S45: 13 | T45: 20 | U45: 10 | V45: 13 | W45: 13 | X45: 9 | Y45: 13 | Z45: 26 | AA45: 15 | AB45: 15 | AC45: 10 | AD45: 23 | AE45: 26 | AF45: 15 | AG45: 30 | AH45: 15 | AI45: 21 | AJ45: 27 | AK45: 16 | AL45: 22 | AM45: =SUM(E45:AL45) -> 602
B46: 2. | C46: Ir. H. AA LA NYALLA MAHMUD MATTALITI, M.HP. | E46: 41 | F46: 27 | G46: 26 | H46: 43 | I46: 34 | J46: 28 | K46: 30 | L46: 35 | M46: 36 | N46: 25 | O46: 32 | P46: 35 | Q46: 36 | R46: 48 | S46: 21 | T46: 27 | U46: 36 | V46: 37 | W46: 14 | X46: 32 | Y46: 18 | Z46: 49 | AA46: 32 | AB46: 27 | AC46: 39 | AD46: 34 | AE46: 37 | AF46: 39 | AG46: 38 | AH46: 41 | AI46: 51 | AJ46: 26 | AK46: 32 | AL46: 18 | AM46: =SUM(E46:AL46) -> 1124
B47: 3. | C47: ABDUL QADIR AMIR HARTONO, S.E., S.H., M.H. | E47: 14 | F47: 20 | G47: 24 | H47: 14 | I47: 14 | J47: 14 | K47: 12 | L47: 14 | M47: 10 | N47: 19 | O47: 10 | P47: 27 | Q47: 17 | R47: 20 | S47: 13 | T47: 9 | U47: 11 | V47: 15 | W47: 12 | X47: 8 | Y47: 5 | Z47: 16 | AA47: 10 | AB47: 11 | AC47: 6 | AD47: 12 | AE47: 8 | AF47: 14 | AG47: 16 | AH47: 11 | AI47: 15 | AJ47: 15 | AK47: 15 | AL47: 12 | AM47: =SUM(E47:AL47) -> 463
B48: 4. | C48: ADILLA AZIS, S.E. | E48: 13 | F48: 23 | G48: 25 | H48: 21 | I48: 15 | J48: 27 | K48: 24 | L48: 18 | M48: 15 | N48: 20 | O48: 10 | P48: 16 | Q48: 22 | R48: 18 | S48: 38 | T48: 20 | U48: 24 | V48: 30 | W48: 21 | X48: 16 | Y48: 14 | Z48: 16 | AA48: 17 | AB48: 26 | AC48: 22 | AD48: 23 | AE48: 12 | AF48: 21 | AG48: 14 | AH48: 8 | AI48: 16 | AJ48: 13 | AK48: 21 | AL48: 18 | AM48: =SUM(E48:AL48) -> 657
B49: 5. | C49: Ir. H. AGUS RAHARDJO, MSc.M. | E49: 8 | F49: 10 | G49: 14 | H49: 13 | I49: 14 | J49: 23 | K49: 20 | L49: 6 | M49: 12 | N49: 12 | O49: 11 | P49: 10 | Q49: 11 | R49: 9 | S49: 11 | T49: 9 | U49: 7 | V49: 10 | W49: 6 | X49: 10 | Y49: 6 | Z49: 7 | AA49: 15 | AB49: 20 | AC49: 11 | AD49: 20 | AE49: 5 | AF49: 8 | AG49: 13 | AH49: 7 | AI49: 16 | AJ49: 9 | AK49: 13 | AL49: 14 | AM49: =SUM(E49:AL49) -> 390
B50: 6. | C50: Drs. AYUB KHAN | E50: 19 | F50: 23 | G50: 16 | H50: 33 | I50: 21 | J50: 35 | K50: 33 | L50: 22 | M50: 14 | N50: 24 | O50: 31 | P50: 31 | Q50: 15 | R50: 24 | S50: 41 | T50: 40 | U50: 22 | V50: 23 | W50: 25 | X50: 22 | Y50: 13 | Z50: 20 | AA50: 49 | AB50: 29 | AC50: 17 | AD50: 8 | AE50: 13 | AF50: 15 | AG50: 13 | AH50: 17 | AI50: 5 | AJ50: 29 | AK50: 16 | AL50: 13 | AM50: =SUM(E50:AL50) -> 771
B51: 7. | C51: BAMBANG HARIANTO | E51: 1 | F51: 0 | G51: 2 | H51: 0 | I51: 5 | J51: 2 | K51: 0 | L51: 2 | M51: 0 | N51: 0 | O51: 0 | P51: 3 | Q51: 1 | R51: 1 | S51: 0 | T51: 0 | U51: 0 | V51: 3 | W51: 3 | X51: 3 | Y51: 1 | Z51: 2 | AA51: 1 | AB51: 0 | AC51: 0 | AD51: 2 | AE51: 1 | AF51: 0 | AG51: 1 | AH51: 3 | AI51: 2 | AJ51: 1 | AK51: 2 | AL51: 5 | AM51: =SUM(E51:AL51) -> 47
...

Sheet SUMBERKENCONO
C2: Kecamatan | D2: WONGSOREJO
C3: Kabupaten | D3: BANYUWANGI
C4: Provinsi | D4: JAWA TIMUR
C9: Kelurahan | D9: SUMBERKENCONO
A12: I | B12: DATA PEMILIH DAN PENGGUNAAN HAK PILIH | T12: JUMLAH AKHIR
A13: A | B13: DATA PEMILIH | E13: TPS 001 | F13: TPS 002 | G13: TPS 003 | H13: TPS 004 | I13: TPS 005 | J13: TPS 006 | K13: TPS 007 | L13: TPS 008 | M13: TPS 009 | N13: TPS 010 | O13: TPS 011 | P13: TPS 012 | Q13: TPS 013 | R13: TPS 014 | S13: TPS 015
B14: Jumlah Pemilih dalam Daftar Pemilih Tetap (DPT) | D14: LK | E14: 140 | F14: 147 | G14: 125 | H14: 131 | I14: 134 | J14: 149 | K14: 141 | L14: 143 | M14: 154 | N14: 131 | O14: 140 | P14: 148 | Q14: 146 | R14: 131 | S14: 141 | T14: =SUM(E14:S14) -> 2101
D15: PR | E15: 127 | F15: 140 | G15: 123 | H15: 145 | I15: 129 | J15: 145 | K15: 149 | L15: 149 | M15: 144 | N15: 150 | O15: 146 | P15: 138 | Q15: 150 | R15: 156 | S15: 152 | T15: =SUM(E15:S15) -> 2143
D16: JML | E16: =SUM(E14:E15) -> 267 | F16: =SUM(F14:F15) -> 287 | G16: =SUM(G14:G15) -> 248 | H16: =SUM(H14:H15) -> 276 | I16: =SUM(I14:I15) -> 263 | J16: =SUM(J14:J15) -> 294 | K16: =SUM(K14:K15) -> 290 | L16: =SUM(L14:L15) -> 292 | ... S16: =SUM(S14:S15) -> 293 | T16: =SUM(E16:S16) -> 4244
A18: B | B18: PENGGUNA HAK PILIH
B19: 1. | C19: Jumlah pengguna hak pilih dalam Daftar Pemilih Tetap (DPT) | D19: LK | E19: 99 | F19: 108 | G19: 94 | H19: 91 | I19: 106 | J19: 109 | K19: 118 | L19: 101 | M19: 108 | N19: 97 | O19: 104 | P19: 117 | Q19: 105 | R19: 105 | S19: 111 | T19: =SUM(E19:S19) -> 1573
D20: PR | E20: 112 | F20: 111 | G20: 98 | H20: 110 | I20: 114 | J20: 111 | K20: 125 | L20: 111 | M20: 107 | N20: 121 | O20: 118 | P20: 114 | Q20: 121 | R20: 120 | S20: 132 | T20: =SUM(E20:S20) -> 1725
D21: JML | E21: =SUM(E19:E20) -> 211 | F21: =SUM(F19:F20) -> 219 | G21: =SUM(G19:G20) -> 192 | H21: =SUM(H19:H20) -> 201 | I21: =SUM(I19:I20) -> 220 | J21: =SUM(J19:J20) -> 220 | K21: =SUM(K19:K20) -> 243 | L21: =SUM(L19:L20) -> 212 | ... S21: =SUM(S19:S20) -> 243 | T21: =SUM(E21:S21) -> 3298
B22: 2. | C22: Jumlah pengguna hak pilih dalam Daftar Pemilih Tambahan (DPTb) | D22: LK | E22: 0 | F22: 0 | G22: 3 | H22: 2 | I22: 1 | J22: 0 | K22: 0 | L22: 0 | M22: 0 | N22: 0 | O22: 0 | P22: 0 | Q22: 0 | R22: 0 | S22: 0 | T22: =SUM(E22:S22) -> 6
D23: PR | E23: 0 | F23: 0 | G23: 0 | H23: 2 | I23: 1 | J23: 0 | K23: 0 | L23: 0 | M23: 0 | N23: 0 | O23: 0 | P23: 0 | Q23: 0 | R23: 0 | S23: 0 | T23: =SUM(E23:S23) -> 3
D24: JML | E24: =SUM(E22:E23) -> 0 | F24: =SUM(F22:F23) -> 0 | G24: =SUM(G22:G23) -> 3 | H24: =SUM(H22:H23) -> 4 | I24: =SUM(I22:I23) -> 2 | J24: =SUM(J22:J23) -> 0 | K24: =SUM(K22:K23) -> 0 | L24: =SUM(L22:L23) -> 0 | ... S24: =SUM(S22:S23) -> 0 | T24: =SUM(E24:S24) -> 9
B25: 3. | C25: Jumlah pengguna hak pilih dalam Daftar Pemilih Khusus (DPK) | D25: LK | E25: 0 | F25: 0 | G25: 0 | H25: 0 | I25: 0 | J25: 0 | K25: 0 | L25: 0 | M25: 0 | N25: 0 | O25: 0 | P25: 0 | Q25: 0 | R25: 1 | S25: 2 | T25: =SUM(E25:S25) -> 3
D26: PR | E26: 0 | F26: 0 | G26: 0 | H26: 0 | I26: 0 | J26: 0 | K26: 0 | L26: 0 | M26: 2 | N26: 0 | O26: 0 | P26: 0 | Q26: 0 | R26: 0 | S26: 1 | T26: =SUM(E26:S26) -> 3
D27: JML | E27: =SUM(E25:E26) -> 0 | F27: =SUM(F25:F26) -> 0 | G27: =SUM(G25:G26) -> 0 | H27: =SUM(H25:H26) -> 0 | I27: =SUM(I25:I26) -> 0 | J27: =SUM(J25:J26) -> 0 | K27: =SUM(K25:K26) -> 0 | L27: =SUM(L25:L26) -> 0 | ... S27: =SUM(S25:S26) -> 3 | T27: =SUM(E27:S27) -> 6
B28: 4. | C28: Jumlah Pengguna Hak Pilih (B.1+B.2+B.3) | D28: LK | E28: =SUM(E19,E22,E25) -> 99 | F28: =SUM(F19,F22,F25) -> 108 | G28: =SUM(G19,G22,G25) -> 97 | H28: =SUM(H19,H22,H25) -> 93 | I28: =SUM(I19,I22,I25) -> 107 | J28: =SUM(J19,J22,J25) -> 109 | K28: =SUM(K19,K22,K25) -> 118 | L28: =SUM(L19,L22,L25) -> 101 | ... S28: =SUM(S19,S22,S25) -> 113 | T28: =SUM(E28:S28) -> 1582
D29: PR | E29: =SUM(E20,E23,E26) -> 112 | F29: =SUM(F20,F23,F26) -> 111 | G29: =SUM(G20,G23,G26) -> 98 | H29: =SUM(H20,H23,H26) -> 112 | I29: =SUM(I20,I23,I26) -> 115 | J29: =SUM(J20,J23,J26) -> 111 | K29: =SUM(K20,K23,K26) -> 125 | L29: =SUM(L20,L23,L26) -> 111 | ... S29: =SUM(S20,S23,S26) -> 133 | T29: =SUM(E29:S29) -> 1731
D30: JML | E30: =SUM(E28:E29) -> 211 | F30: =SUM(F28:F29) -> 219 | G30: =SUM(G28:G29) -> 195 | H30: =SUM(H28:H29) -> 205 | I30: =SUM(I28:I29) -> 222 | J30: =SUM(J28:J29) -> 220 | K30: =SUM(K28:K29) -> 243 | L30: =SUM(L28:L29) -> 212 | ... S30: =SUM(S28:S29) -> 246 | T30: =SUM(E30:S30) -> 3313
A32: II | B32: DATA PENGGUNAAN SURAT SUARA
A33: 1 | B33: Jumlah surat suara yang diterima, termasuk surat suara cadangan 2,5% dari DPT | E33: 273 | F33: 293 | G33: 253 | H33: 282 | I33: 269 | J33: 301 | K33: 296 | L33: 296 | M33: 304 | N33: 287 | O33: 292 | P33: 292 | Q33: 302 | R33: 293 | S33: 299 | T33: =SUM(E33:S33) -> 4332
A34: 2 | B34: Jumlah surat suara yang digunakan | E34: 211 | F34: 219 | G34: 195 | H34: 205 | I34: 222 | J34: 220 | K34: 243 | L34: 212 | M34: 217 | N34: 218 | O34: 222 | P34: 231 | Q34: 226 | R34: 226 | S34: 246 | T34: =SUM(E34:S34) -> 3313
A35: 3 | B35: Jumlah surat suara dikembalikan oleh pemilih (karena rusak atau keliru coblos) | E35: 0 | F35: 0 | G35: 0 | H35: 0 | I35: 0 | J35: 0 | K35: 0 | L35: 0 | M35: 0 | N35: 0 | O35: 0 | P35: 1 | Q35: 0 | R35: 0 | S35: 0 | T35: =SUM(E35:S35) -> 1
A36: 4 | B36: Jumlah surat suara yang tidak digunakan/tidak terpakai, termasuk sisa surat suara cadangan | E36: =E33-(E34+E35) -> 62 | F36: =F33-(F34+F35) -> 74 | G36: =G33-(G34+G35) -> 58 | H36: =H33-(H34+H35) -> 77 | I36: =I33-(I34+I35) -> 47 | J36: =J33-(J34+J35) -> 81 | K36: =K33-(K34+K35) -> 53 | L36: =L33-(L34+L35) -> 84 | ... S36: =S33-(S34+S35) -> 53 | T36: =SUM(E36:S36) -> 1018
A38: III | B38: DATA PEMILIH DISABILITAS
B39: Jumlah seluruh Pemilih disabilitas yang menggunakan hak pilih | D39: LK | E39: 0 | F39: 0 | G39: 0 | H39: 0 | I39: 0 | J39: 0 | K39: 1 | L39: 0 | M39: 0 | N39: 0 | O39: 0 | P39: 0 | Q39: 0 | R39: 0 | S39: 0 | T39: =SUM(E39:S39) -> 1
D40: PR | E40: 0 | F40: 0 | G40: 0 | H40: 0 | I40: 0 | J40: 0 | K40: 0 | L40: 0 | M40: 0 | N40: 0 | O40: 0 | P40: 0 | Q40: 0 | R40: 0 | S40: 0 | T40: =SUM(E40:S40) -> 0
D41: JML | E41: =SUM(E39:E40) -> 0 | F41: =SUM(F39:F40) -> 0 | G41: =SUM(G39:G40) -> 0 | H41: =SUM(H39:H40) -> 0 | I41: =SUM(I39:I40) -> 0 | J41: =SUM(J39:J40) -> 0 | K41: =SUM(K39:K40) -> 1 | L41: =SUM(L39:L40) -> 0 | ... S41: =SUM(S39:S40) -> 0 | T41: =SUM(E41:S41) -> 1
A43: IV | B43: DATA RINCIAN PEROLEHAN SUARA PASANGAN CALON BUPATI DAN WAKIL BUPATI
A44: NOMOR DAN NAMA CALON
B45: 1. | C45: AA. AHMAD NAWARDI | E45: 18 | F45: 17 | G45: 24 | H45: 13 | I45: 23 | J45: 15 | K45: 9 | L45: 14 | M45: 11 | N45: 18 | O45: 16 | P45: 18 | Q45: 28 | R45: 25 | S45: 14 | T45: =SUM(E45:S45) -> 263
B46: 2. | C46: Ir. H. AA LA NYALLA MAHMUD MATTALITI, M.HP. | E46: 48 | F46: 42 | G46: 34 | H46: 47 | I46: 40 | J46: 45 | K46: 32 | L46: 47 | M46: 58 | N46: 30 | O46: 57 | P46: 33 | Q46: 42 | R46: 32 | S46: 34 | T46: =SUM(E46:S46) -> 621
B47: 3. | C47: ABDUL QADIR AMIR HARTONO, S.E., S.H., M.H. | E47: 14 | F47: 9 | G47: 9 | H47: 20 | I47: 15 | J47: 12 | K47: 33 | L47: 14 | M47: 15 | N47: 17 | O47: 9 | P47: 23 | Q47: 11 | R47: 17 | S47: 17 | T47: =SUM(E47:S47) -> 235
B48: 4. | C48: ADILLA AZIS, S.E. | E48: 25 | F48: 24 | G48: 24 | H48: 9 | I48: 29 | J48: 29 | K48: 21 | L48: 18 | M48: 19 | N48: 19 | O48: 29 | P48: 19 | Q48: 30 | R48: 27 | S48: 12 | T48: =SUM(E48:S48) -> 334
B49: 5. | C49: Ir. H. AGUS RAHARDJO, MSc.M. | E49: 5 | F49: 13 | G49: 7 | H49: 13 | I49: 9 | J49: 14 | K49: 14 | L49: 14 | M49: 19 | N49: 17 | O49: 10 | P49: 10 | Q49: 7 | R49: 26 | S49: 15 | T49: =SUM(E49:S49) -> 193
B50: 6. | C50: Drs. AYUB KHAN | E50: 16 | F50: 19 | G50: 20 | H50: 7 | I50: 12 | J50: 8 | K50: 56 | L50: 17 | M50: 11 | N50: 10 | O50: 17 | P50: 22 | Q50: 25 | R50: 18 | S50: 74 | T50: =SUM(E50:S50) -> 332
B51: 7. | C51: BAMBANG HARIANTO | E51: 0 | F51: 3 | G51: 5 | H51: 5 | I51: 3 | J51: 3 | K51: 1 | L51: 2 | M51: 1 | N51: 2 | O51: 2 | P51: 6 | Q51: 7 | R51: 6 | S51: 2 | T51: =SUM(E51:S51) -> 48
...

Sheet SIDODADI
C2: Kecamatan | D2: WONGSOREJO
C3: Kabupaten | D3: BANYUWANGI
C4: Provinsi | D4: JAWA TIMUR
C9: Kelurahan | D9: SIDODADI
A12: I | B12: DATA PEMILIH DAN PENGGUNAAN HAK PILIH | U12: JUMLAH AKHIR
A13: A | B13: DATA PEMILIH | E13: TPS 001 | F13: TPS 002 | G13: TPS 003 | H13: TPS 004 | I13: TPS 005 | J13: TPS 006 | K13: TPS 007 | L13: TPS 008 | M13: TPS 009 | N13: TPS 010 | O13: TPS 011 | P13: TPS 012 | Q13: TPS 013 | R13: TPS 014 | S13: TPS 015 | T13: TPS 016
B14: Jumlah Pemilih dalam Daftar Pemilih Tetap (DPT) | D14: LK | E14: 137 | F14: 130 | G14: 151 | H14: 129 | I14: 134 | J14: 151 | K14: 141 | L14: 120 | M14: 133 | N14: 121 | O14: 141 | P14: 144 | Q14: 148 | R14: 149 | S14: 130 | T14: 94 | U14: =SUM(E14:T14) -> 2153
D15: PR | E15: 138 | F15: 132 | G15: 139 | H15: 125 | I15: 157 | J15: 135 | K15: 134 | L15: 113 | M15: 136 | N15: 126 | O15: 146 | P15: 143 | Q15: 138 | R15: 146 | S15: 122 | T15: 89 | U15: =SUM(E15:T15) -> 2119
D16: JML | E16: =SUM(E14:E15) -> 275 | F16: =SUM(F14:F15) -> 262 | G16: =SUM(G14:G15) -> 290 | H16: =SUM(H14:H15) -> 254 | I16: =SUM(I14:I15) -> 291 | J16: =SUM(J14:J15) -> 286 | K16: =SUM(K14:K15) -> 275 | L16: =SUM(L14:L15) -> 233 | ... T16: =SUM(T14:T15) -> 183 | U16: =SUM(E16:T16) -> 4272
A18: B | B18: PENGGUNA HAK PILIH
B19: 1. | C19: Jumlah pengguna hak pilih dalam Daftar Pemilih Tetap (DPT) | D19: LK | E19: 111 | F19: 98 | G19: 131 | H19: 96 | I19: 95 | J19: 122 | K19: 103 | L19: 85 | M19: 92 | N19: 85 | O19: 89 | P19: 107 | Q19: 106 | R19: 109 | S19: 93 | T19: 73 | U19: =SUM(E19:T19) -> 1595
D20: PR | E20: 114 | F20: 112 | G20: 123 | H20: 94 | I20: 115 | J20: 118 | K20: 109 | L20: 94 | M20: 104 | N20: 103 | O20: 117 | P20: 126 | Q20: 97 | R20: 120 | S20: 103 | T20: 72 | U20: =SUM(E20:T20) -> 1721
D21: JML | E21: =SUM(E19:E20) -> 225 | F21: =SUM(F19:F20) -> 210 | G21: =SUM(G19:G20) -> 254 | H21: =SUM(H19:H20) -> 190 | I21: =SUM(I19:I20) -> 210 | J21: =SUM(J19:J20) -> 240 | K21: =SUM(K19:K20) -> 212 | L21: =SUM(L19:L20) -> 179 | ... T21: =SUM(T19:T20) -> 145 | U21: =SUM(E21:T21) -> 3316
B22: 2. | C22: Jumlah pengguna hak pilih dalam Daftar Pemilih Tambahan (DPTb) | D22: LK | E22: 0 | F22: 0 | G22: 0 | H22: 0 | I22: 1 | J22: 0 | K22: 0 | L22: 0 | M22: 0 | N22: 0 | O22: 0 | P22: 0 | Q22: 0 | R22: 1 | S22: 0 | T22: 0 | U22: =SUM(E22:T22) -> 2
D23: PR | E23: 0 | F23: 0 | G23: 0 | H23: 0 | I23: 0 | J23: 0 | K23: 0 | L23: 0 | M23: 0 | N23: 0 | O23: 0 | P23: 0 | Q23: 0 | R23: 0 | S23: 1 | T23: 1 | U23: =SUM(E23:T23) -> 2
D24: JML | E24: =SUM(E22:E23) -> 0 | F24: =SUM(F22:F23) -> 0 | G24: =SUM(G22:G23) -> 0 | H24: =SUM(H22:H23) -> 0 | I24: =SUM(I22:I23) -> 1 | J24: =SUM(J22:J23) -> 0 | K24: =SUM(K22:K23) -> 0 | L24: =SUM(L22:L23) -> 0 | ... T24: =SUM(T22:T23) -> 1 | U24: =SUM(E24:T24) -> 4
B25: 3. | C25: Jumlah pengguna hak pilih dalam Daftar Pemilih Khusus (DPK) | D25: LK | E25: 0 | F25: 3 | G25: 0 | H25: 1 | I25: 1 | J25: 0 | K25: 2 | L25: 1 | M25: 0 | N25: 1 | O25: 0 | P25: 0 | Q25: 0 | R25: 0 | S25: 1 | T25: 0 | U25: =SUM(E25:T25) -> 10
D26: PR | E26: 0 | F26: 2 | G26: 0 | H26: 2 | I26: 3 | J26: 0 | K26: 3 | L26: 0 | M26: 0 | N26: 1 | O26: 0 | P26: 0 | Q26: 0 | R26: 0 | S26: 2 | T26: 0 | U26: =SUM(E26:T26) -> 13
D27: JML | E27: =SUM(E25:E26) -> 0 | F27: =SUM(F25:F26) -> 5 | G27: =SUM(G25:G26) -> 0 | H27: =SUM(H25:H26) -> 3 | I27: =SUM(I25:I26) -> 4 | J27: =SUM(J25:J26) -> 0 | K27: =SUM(K25:K26) -> 5 | L27: =SUM(L25:L26) -> 1 | ... T27: =SUM(T25:T26) -> 0 | U27: =SUM(E27:T27) -> 23
B28: 4. | C28: Jumlah Pengguna Hak Pilih (B.1+B.2+B.3) | D28: LK | E28: =SUM(E19,E22,E25) -> 111 | F28: =SUM(F19,F22,F25) -> 101 | G28: =SUM(G19,G22,G25) -> 131 | H28: =SUM(H19,H22,H25) -> 97 | I28: =SUM(I19,I22,I25) -> 97 | J28: =SUM(J19,J22,J25) -> 122 | K28: =SUM(K19,K22,K25) -> 105 | L28: =SUM(L19,L22,L25) -> 86 | ... T28: =SUM(T19,T22,T25) -> 73 | U28: =SUM(E28:T28) -> 1607
D29: PR | E29: =SUM(E20,E23,E26) -> 114 | F29: =SUM(F20,F23,F26) -> 114 | G29: =SUM(G20,G23,G26) -> 123 | H29: =SUM(H20,H23,H26) -> 96 | I29: =SUM(I20,I23,I26) -> 118 | J29: =SUM(J20,J23,J26) -> 118 | K29: =SUM(K20,K23,K26) -> 112 | L29: =SUM(L20,L23,L26) -> 94 | ... T29: =SUM(T20,T23,T26) -> 73 | U29: =SUM(E29:T29) -> 1736
D30: JML | E30: =SUM(E28:E29) -> 225 | F30: =SUM(F28:F29) -> 215 | G30: =SUM(G28:G29) -> 254 | H30: =SUM(H28:H29) -> 193 | I30: =SUM(I28:I29) -> 215 | J30: =SUM(J28:J29) -> 240 | K30: =SUM(K28:K29) -> 217 | L30: =SUM(L28:L29) -> 180 | ... T30: =SUM(T28:T29) -> 146 | U30: =SUM(E30:T30) -> 3343
A32: II | B32: DATA PENGGUNAAN SURAT SUARA
A33: 1 | B33: Jumlah surat suara yang diterima, termasuk surat suara cadangan 2,5% dari DPT | E33: 280 | F33: 267 | G33: 295 | H33: 259 | I33: 297 | J33: 291 | K33: 279 | L33: 237 | M33: 272 | N33: 252 | O33: 281 | P33: 292 | Q33: 291 | R33: 301 | S33: 257 | T33: 186 | U33: =SUM(E33:T33) -> 4337
A34: 2 | B34: Jumlah surat suara yang digunakan | E34: 225 | F34: 215 | G34: 254 | H34: 193 | I34: 215 | J34: 240 | K34: 217 | L34: 180 | M34: 196 | N34: 190 | O34: 206 | P34: 233 | Q34: 203 | R34: 230 | S34: 200 | T34: 146 | U34: =SUM(E34:T34) -> 3343
