Workbook

Sheet DPR
C8: Kecamatan | D8: SILIRAGUNG
C9: Kabupaten | D9: BANYUWANGI
C10: Provinsi | D10: JAWA TIMUR
A12: I | B12: DATA PEMILIH DAN PENGGUNAAN HAK PILIH | E12: JUMLAH AKHIR
A13: A | B13: DATA PEMILIH
B14: Jumlah Pemilih dalam Daftar Pemilih Tetap (DPT) | D14: LK | E14: =BARUREJO!AX14+BULUAGUNG!AC14+KESILIR!AJ14+SENEPOREJO!AB14+SILIRAGUNG!AB14 -> 19220
D15: PR | E15: =BARUREJO!AX15+BULUAGUNG!AC15+KESILIR!AJ15+SENEPOREJO!AB15+SILIRAGUNG!AB15 -> 18803
D16: JML | E16: =SUM(E14:E15) -> 38023
A18: B | B18: PENGGUNA HAK PILIH
B19: 1. | C19: Jumlah pengguna hak pilih dalam Daftar Pemilih Tetap (DPT) | D19: LK | E19: =BARUREJO!AX19+BULUAGUNG!AC19+KESILIR!AJ19+SENEPOREJO!AB19+SILIRAGUNG!AB19 -> 14553
D20: PR | E20: =BARUREJO!AX20+BULUAGUNG!AC20+KESILIR!AJ20+SENEPOREJO!AB20+SILIRAGUNG!AB20 -> 14882
D21: JML | E21: =SUM(E19:E20) -> 29435
B22: 2. | C22: Jumlah pengguna hak pilih dalam Daftar Pemilih Tambahan (DPTb) | D22: LK | E22: =BARUREJO!AX22+BULUAGUNG!AC22+KESILIR!AJ22+SENEPOREJO!AB22+SILIRAGUNG!AB22 -> 10
D23: PR | E23: =BARUREJO!AX23+BULUAGUNG!AC23+KESILIR!AJ23+SENEPOREJO!AB23+SILIRAGUNG!AB23 -> 3
D24: JML | E24: =SUM(E22:E23) -> 13
B25: 3. | C25: Jumlah pengguna hak pilih dalam Daftar Pemilih Khusus (DPK) | D25: LK | E25: =BARUREJO!AX25+BULUAGUNG!AC25+KESILIR!AJ25+SENEPOREJO!AB25+SILIRAGUNG!AB25 -> 272
D26: PR | E26: =BARUREJO!AX26+BULUAGUNG!AC26+KESILIR!AJ26+SENEPOREJO!AB26+SILIRAGUNG!AB26 -> 391
D27: JML | E27: =SUM(E25:E26) -> 663
B28: 4. | C28: Jumlah Pengguna Hak Pilih (B.1+B.2+B.3) | D28: LK | E28: =E19+E22+E25 -> 14835
D29: PR | E29: =E20+E23+E26 -> 15276
D30: JML | E30: =SUM(E28:E29) -> 30111
A32: II | B32: DATA PENGGUNAAN SURAT SUARA
A33: 1 | B33: Jumlah surat suara yang diterima, termasuk surat suara cadangan 2,5% dari DPT | E33: =BARUREJO!AX33+BULUAGUNG!AC33+KESILIR!AJ33+SENEPOREJO!AB33+SILIRAGUNG!AB33 -> 38901
A34: 2 | B34: Jumlah surat suara yang digunakan | E34: =BARUREJO!AX34+BULUAGUNG!AC34+KESILIR!AJ34+SENEPOREJO!AB34+SILIRAGUNG!AB34 -> 30111
A35: 3 | B35: Jumlah surat suara dikembalikan oleh pemilih (karena rusak atau keliru coblos) | E35: =BARUREJO!AX35+BULUAGUNG!AC35+KESILIR!AJ35+SENEPOREJO!AB35+SILIRAGUNG!AB35 -> 71
A36: 4 | B36: Jumlah surat suara yang tidak digunakan/tidak terpakai, termasuk sisa surat suara cadangan | E36: =E33-(E34+E35) -> 8719
A38: III | B38: DATA PEMILIH DISABILITAS
B39: Jumlah seluruh Pemilih disabilitas yang menggunakan hak pilih | D39: LK | E39: =BARUREJO!AX39+BULUAGUNG!AC39+KESILIR!AJ39+SENEPOREJO!AB39+SILIRAGUNG!AB39 -> 11
D40: PR | E40: =BARUREJO!AX40+BULUAGUNG!AC40+KESILIR!AJ40+SENEPOREJO!AB40+SILIRAGUNG!AB40 -> 22
D41: JML | E41: =SUM(E39:E40) -> 33
A43: IV | B43: DATA RINCIAN PEROLEHAN SUARA PASANGAN CALON BUPATI DAN WAKIL BUPATI
A44: NOMOR DAN NAMA CALON
A45: A.1 | B45: 1. | C45: Partai Kebangkitan Bangsa | E45: =BARUREJO!AX45+BULUAGUNG!AC45+KESILIR!AJ45+SENEPOREJO!AB45+SILIRAGUNG!AB45 -> 1041
A46: A.2 | B46: 1 | C46: 1. Dr. Hj. NIHAYATUL WAFIROH, M.A. | E46: =BARUREJO!AX46+BULUAGUNG!AC46+KESILIR!AJ46+SENEPOREJO!AB46+SILIRAGUNG!AB46 -> 3894
B47: 2 | C47: 2. H. M. NASIM KHAN | E47: =BARUREJO!AX47+BULUAGUNG!AC47+KESILIR!AJ47+SENEPOREJO!AB47+SILIRAGUNG!AB47 -> 221
B48: 3 | C48: 3. Dr. H. AKIK ZAMAN, M.Pd.I. | E48: =BARUREJO!AX48+BULUAGUNG!AC48+KESILIR!AJ48+SENEPOREJO!AB48+SILIRAGUNG!AB48 -> 104
B49: 4 | C49: 4. AHMAD RIFA'I, S.H. | E49: =BARUREJO!AX49+BULUAGUNG!AC49+KESILIR!AJ49+SENEPOREJO!AB49+SILIRAGUNG!AB49 -> 122
B50: 5 | C50: 5. Drs. H. MAHFUD M.N. | E50: =BARUREJO!AX50+BULUAGUNG!AC50+KESILIR!AJ50+SENEPOREJO!AB50+SILIRAGUNG!AB50 -> 107
B51: 6 | C51: 6. NURHAYATI, S.Pd. | E51: =BARUREJO!AX51+BULUAGUNG!AC51+KESILIR!AJ51+SENEPOREJO!AB51+SILIRAGUNG!AB51 -> 78
B52: 7 | C52: 7. MAFTUHA KISWAH | E52: =BARUREJO!AX52+BULUAGUNG!AC52+KESILIR!AJ52+SENEPOREJO!AB52+SILIRAGUNG!AB52 -> 63
...

Sheet BARUREJO
C2: Kecamatan | D2: SILIRAGUNG
C3: Kabupaten | D3: BANYUWANGI
C4: Provinsi | D4: JAWA TIMUR
C9: Kelurahan | D9: BARUREJO
A12: I | B12: DATA PEMILIH DAN PENGGUNAAN HAK PILIH | AX12: JUMLAH AKHIR
A13: A | B13: DATA PEMILIH | E13: TPS 001 | F13: TPS 002 | G13: TPS 003 | H13: TPS 004 | I13: TPS 005 | J13: TPS 006 | K13: TPS 007 | L13: TPS 008 | M13: TPS 009 | N13: TPS 010 | O13: TPS 011 | P13: TPS 012 | Q13: TPS 013 | R13: TPS 014 | S13: TPS 015 | T13: TPS 016 | U13: TPS 017 | V13: TPS 018 | W13: TPS 019 | X13: TPS 020 | Y13: TPS 021 | Z13: TPS 022 | AA13: TPS 023 | AB13: TPS 024 | AC13: TPS 025 | AD13: TPS 026 | AE13: TPS 027 | AF13: TPS 028 | AG13: TPS 029 | AH13: TPS 030 | AI13: TPS 031 | AJ13: TPS 032 | AK13: TPS 033 | AL13: TPS 034 | AM13: TPS 035 | AN13: TPS 036 | AO13: TPS 037 | AP13: TPS 038 | AQ13: TPS 039 | AR13: TPS 040 | AS13: TPS 041 | AT13: TPS 042 | AU13: TPS 043 | AV13: TPS 044 | AW13: TPS 045
B14: Jumlah Pemilih dalam Daftar Pemilih Tetap (DPT) | D14: LK | E14: 139 | F14: 140 | G14: 131 | H14: 134 | I14: 139 | J14: 143 | K14: 137 | L14: 144 | M14: 148 | N14: 142 | O14: 153 | P14: 138 | Q14: 148 | R14: 151 | S14: 122 | T14: 96 | U14: 104 | V14: 146 | W14: 135 | X14: 127 | Y14: 143 | Z14: 139 | AA14: 129 | AB14: 135 | AC14: 119 | AD14: 140 | AE14: 123 | AF14: 132 | AG14: 122 | AH14: 146 | AI14: 142 | AJ14: 153 | AK14: 119 | AL14: 102 | AM14: 84 | AN14: 152 | AO14: 142 | AP14: 154 | AQ14: 105 | AR14: 117 | AS14: 144 | AT14: 143 | AU14: 128 | AV14: 86 | AW14: 36 | AX14: =SUM(E14:AW14) -> 5852
D15: PR | E15: 128 | F15: 121 | G15: 118 | H15: 129 | I15: 140 | J15: 137 | K15: 126 | L15: 148 | M15: 135 | N15: 142 | O15: 139 | P15: 128 | Q15: 140 | R15: 129 | S15: 121 | T15: 94 | U15: 119 | V15: 130 | W15: 127 | X15: 119 | Y15: 128 | Z15: 123 | AA15: 133 | AB15: 147 | AC15: 107 | AD15: 140 | AE15: 124 | AF15: 127 | AG15: 110 | AH15: 147 | AI15: 148 | AJ15: 142 | AK15: 136 | AL15: 87 | AM15: 61 | AN15: 138 | AO15: 130 | AP15: 144 | AQ15: 94 | AR15: 127 | AS15: 153 | AT15: 143 | AU15: 141 | AV15: 71 | AW15: 39 | AX15: =SUM(E15:AW15) -> 5610
D16: JML | E16: =SUM(E14:E15) -> 267 | F16: =SUM(F14:F15) -> 261 | G16: =SUM(G14:G15) -> 249 | H16: =SUM(H14:H15) -> 263 | I16: =SUM(I14:I15) -> 279 | J16: =SUM(J14:J15) -> 280 | K16: =SUM(K14:K15) -> 263 | L16: =SUM(L14:L15) -> 292 | ... AW16: =SUM(AW14:AW15) -> 75 | AX16: =SUM(E16:AW16) -> 11462
A18: B | B18: PENGGUNA HAK PILIH
B19: 1. | C19: Jumlah pengguna hak pilih dalam Daftar Pemilih Tetap (DPT) | D19: LK | E19: 100 | F19: 112 | G19: 114 | H19: 100 | I19: 100 | J19: 99 | K19: 117 | L19: 101 | M19: 93 | N19: 93 | O19: 114 | P19: 109 | Q19: 109 | R19: 114 | S19: 92 | T19: 69 | U19: 80 | V19: 104 | W19: 109 | X19: 89 | Y19: 102 | Z19: 117 | AA19: 99 | AB19: 105 | AC19: 71 | AD19: 96 | AE19: 82 | AF19: 92 | AG19: 92 | AH19: 106 | AI19: 95 | AJ19: 98 | AK19: 95 | AL19: 79 | AM19: 48 | AN19: 102 | AO19: 103 | AP19: 100 | AQ19: 77 | AR19: 81 | AS19: 96 | AT19: 90 | AU19: 100 | AV19: 74 | AW19: 23 | AX19: =SUM(E19:AW19) -> 4241
D20: PR | E20: 93 | F20: 102 | G20: 87 | H20: 101 | I20: 100 | J20: 110 | K20: 98 | L20: 118 | M20: 113 | N20: 108 | O20: 114 | P20: 103 | Q20: 109 | R20: 98 | S20: 96 | T20: 69 | U20: 95 | V20: 106 | W20: 99 | X20: 95 | Y20: 100 | Z20: 105 | AA20: 100 | AB20: 119 | AC20: 81 | AD20: 112 | AE20: 97 | AF20: 95 | AG20: 89 | AH20: 115 | AI20: 113 | AJ20: 102 | AK20: 111 | AL20: 63 | AM20: 42 | AN20: 100 | AO20: 98 | AP20: 108 | AQ20: 72 | AR20: 97 | AS20: 103 | AT20: 100 | AU20: 109 | AV20: 58 | AW20: 28 | AX20: =SUM(E20:AW20) -> 4331
D21: JML | E21: =SUM(E19:E20) -> 193 | F21: =SUM(F19:F20) -> 214 | G21: =SUM(G19:G20) -> 201 | H21: =SUM(H19:H20) -> 201 | I21: =SUM(I19:I20) -> 200 | J21: =SUM(J19:J20) -> 209 | K21: =SUM(K19:K20) -> 215 | L21: =SUM(L19:L20) -> 219 | ... AW21: =SUM(AW19:AW20) -> 51 | AX21: =SUM(E21:AW21) -> 8572
B22: 2. | C22: Jumlah pengguna hak pilih dalam Daftar Pemilih Tambahan (DPTb) | D22: LK | E22: 0 | F22: 0 | G22: 0 | H22: 0 | I22: 0 | J22: 0 | K22: 1 | L22: 0 | M22: 1 | N22: 0 | O22: 0 | P22: 0 | Q22: 0 | R22: 0 | S22: 1 | AX22: =SUM(E22:AW22) -> 3
D23: PR | E23: 0 | F23: 0 | G23: 0 | H23: 0 | I23: 0 | J23: 0 | K23: 0 | L23: 0 | M23: 0 | N23: 0 | O23: 0 | P23: 0 | Q23: 0 | R23: 0 | S23: 0 | AX23: =SUM(E23:AW23) -> 0
D24: JML | E24: =SUM(E22:E23) -> 0 | F24: =SUM(F22:F23) -> 0 | G24: =SUM(G22:G23) -> 0 | H24: =SUM(H22:H23) -> 0 | I24: =SUM(I22:I23) -> 0 | J24: =SUM(J22:J23) -> 0 | K24: =SUM(K22:K23) -> 1 | L24: =SUM(L22:L23) -> 0 | ... AW24: =SUM(AW22:AW23) -> 0 | AX24: =SUM(E24:AW24) -> 3
B25: 3. | C25: Jumlah pengguna hak pilih dalam Daftar Pemilih Khusus (DPK) | D25: LK | E25: 4 | F25: 0 | G25: 4 | H25: 3 | I25: 1 | J25: 3 | K25: 4 | L25: 2 | M25: 3 | N25: 1 | O25: 5 | P25: 0 | Q25: 3 | R25: 4 | S25: 6 | T25: 5 | U25: 8 | V25: 3 | W25: 1 | X25: 2 | Y25: 1 | Z25: 2 | AA25: 2 | AB25: 0 | AC25: 3 | AD25: 3 | AE25: 5 | AF25: 6 | AG25: 0 | AH25: 1 | AI25: 0 | AJ25: 2 | AK25: 3 | AL25: 4 | AM25: 1 | AN25: 2 | AO25: 0 | AP25: 0 | AQ25: 1 | AR25: 1 | AS25: 1 | AT25: 4 | AU25: 3 | AV25: 0 | AW25: 0 | AX25: =SUM(E25:AW25) -> 107
D26: PR | E26: 5 | F26: 1 | G26: 7 | H26: 10 | I26: 4 | J26: 3 | K26: 2 | L26: 2 | M26: 3 | N26: 3 | O26: 5 | P26: 0 | Q26: 5 | R26: 7 | S26: 3 | T26: 6 | U26: 9 | V26: 3 | W26: 2 | X26: 2 | Y26: 1 | Z26: 3 | AA26: 2 | AB26: 4 | AC26: 5 | AD26: 1 | AE26: 4 | AF26: 5 | AG26: 2 | AH26: 6 | AI26: 0 | AJ26: 7 | AK26: 3 | AL26: 3 | AM26: 3 | AN26: 1 | AO26: 2 | AP26: 0 | AQ26: 2 | AR26: 0 | AS26: 5 | AT26: 9 | AU26: 6 | AV26: 0 | AW26: 0 | AX26: =SUM(E26:AW26) -> 156
D27: JML | E27: =SUM(E25:E26) -> 9 | F27: =SUM(F25:F26) -> 1 | G27: =SUM(G25:G26) -> 11 | H27: =SUM(H25:H26) -> 13 | I27: =SUM(I25:I26) -> 5 | J27: =SUM(J25:J26) -> 6 | K27: =SUM(K25:K26) -> 6 | L27: =SUM(L25:L26) -> 4 | ... AW27: =SUM(AW25:AW26) -> 0 | AX27: =SUM(E27:AW27) -> 263
B28: 4. | C28: Jumlah Pengguna Hak Pilih (B.1+B.2+B.3) | D28: LK | E28: =SUM(E19,E22,E25) -> 104 | F28: =SUM(F19,F22,F25) -> 112 | G28: =SUM(G19,G22,G25) -> 118 | H28: =SUM(H19,H22,H25) -> 103 | I28: =SUM(I19,I22,I25) -> 101 | J28: =SUM(J19,J22,J25) -> 102 | K28: =SUM(K19,K22,K25) -> 122 | L28: =SUM(L19,L22,L25) -> 103 | ... AW28: =SUM(AW19,AW22,AW25) -> 23 | AX28: =SUM(E28:AW28) -> 4351
D29: PR | E29: =SUM(E20,E23,E26) -> 98 | F29: =SUM(F20,F23,F26) -> 103 | G29: =SUM(G20,G23,G26) -> 94 | H29: =SUM(H20,H23,H26) -> 111 | I29: =SUM(I20,I23,I26) -> 104 | J29: =SUM(J20,J23,J26) -> 113 | K29: =SUM(K20,K23,K26) -> 100 | L29: =SUM(L20,L23,L26) -> 120 | ... AW29: =SUM(AW20,AW23,AW26) -> 28 | AX29: =SUM(E29:AW29) -> 4487
D30: JML | E30: =SUM(E28:E29) -> 202 | F30: =SUM(F28:F29) -> 215 | G30: =SUM(G28:G29) -> 212 | H30: =SUM(H28:H29) -> 214 | I30: =SUM(I28:I29) -> 205 | J30: =SUM(J28:J29) -> 215 | K30: =SUM(K28:K29) -> 222 | L30: =SUM(L28:L29) -> 223 | ... AW30: =SUM(AW28:AW29) -> 51 | AX30: =SUM(E30:AW30) -> 8838
A32: II | B32: DATA PENGGUNAAN SURAT SUARA
A33: 1 | B33: Jumlah surat suara yang diterima, termasuk surat suara cadangan 2,5% dari DPT | E33: 273 | F33: 272 | G33: 254 | H33: 269 | I33: 285 | J33: 286 | K33: 269 | L33: 299 | M33: 289 | N33: 300 | O33: 298 | P33: 273 | Q33: 295 | R33: 286 | S33: 248 | T33: 196 | U33: 228 | V33: 282 | W33: 270 | X33: 251 | Y33: 277 | Z33: 268 | AA33: 268 | AB33: 288 | AC33: 231 | AD33: 284 | AE33: 252 | AF33: 271 | AG33: 237 | AH33: 297 | AI33: 296 | AJ33: 301 | AK33: 261 | AL33: 193 | AM33: 148 | AN33: 296 | AO33: 278 | AP33: 304 | AQ33: 203 | AR33: 249 | AS33: 303 | AT33: 292 | AU33: 294 | AV33: 161 | AW33: 77 | AX33: =SUM(E33:AW33) -> 11752
A34: 2 | B34: Jumlah surat suara yang digunakan | E34: 202 | F34: 215 | G34: 212 | H34: 214 | I34: 205 | J34: 215 | K34: 222 | L34: 223 | M34: 213 | N34: 205 | O34: 238 | P34: 212 | Q34: 226 | R34: 223 | S34: 198 | T34: 149 | U34: 192 | V34: 216 | W34: 211 | X34: 188 | Y34: 204 | Z34: 227 | AA34: 203 | AB34: 228 | AC34: 160 | AD34: 212 | AE34: 188 | AF34: 198 | AG34: 183 | AH34: 228 | AI34: 208 | AJ34: 209 | AK34: 212 | AL34: 149 | AM34: 94 | AN34: 205 | AO34: 203 | AP34: 208 | AQ34: 152 | AR34: 179 | AS34: 205 | AT34: 203 | AU34: 218 | AV34: 132 | AW34: 51 | AX34: =SUM(E34:AW34) -> 8838
A35: 3 | B35: Jumlah surat suara dikembalikan oleh pemilih (karena rusak atau keliru coblos) | E35: 1 | L35: 1 | N35: 1 | P35: 19 | Q35: 1 | R35: 2 | S35: 1 | T35: 3 | V35: 1 | W35: 4 | Y35: 1 | AI35: 0 | AJ35: 0 | AK35: 1 | AL35: 1 | AM35: 0 | AN35: 1 | AO35: 0 | AP35: 0 | AQ35: 0 | AR35: 0 | AS35: 0 | AT35: 0 | AU35: 0 | AV35: 0 | AW35: 0 | AX35: =SUM(E35:AW35) -> 38
A36: 4 | B36: Jumlah surat suara yang tidak digunakan/tidak terpakai, termasuk sisa surat suara cadangan | E36: =E33-(E34+E35) -> 70 | F36: =F33-(F34+F35) -> 57 | G36: =G33-(G34+G35) -> 42 | H36: =H33-(H34+H35) -> 55 | I36: =I33-(I34+I35) -> 80 | J36: =J33-(J34+J35) -> 71 | K36: =K33-(K34+K35) -> 47 | L36: =L33-(L34+L35) -> 75 | ... AW36: =AW33-(AW34+AW35) -> 26 | AX36: =SUM(E36:AW36) -> 2876
A38: III | B38: DATA PEMILIH DISABILITAS
B39: Jumlah seluruh Pemilih disabilitas yang menggunakan hak pilih | D39: LK | T39: 0 | U39: 0 | V39: 0 | W39: 1 | X39: 0 | Y39: 0 | Z39: 0 | AA39: 0 | AB39: 0 | AC39: 0 | AD39: 0 | AE39: 0 | AF39: 0 | AG39: 0 | AH39: 0 | AX39: =SUM(E39:AW39) -> 1
D40: PR | E40: 0 | F40: 0 | G40: 0 | H40: 0 | I40: 0 | J40: 0 | K40: 0 | L40: 0 | M40: 0 | N40: 1 | O40: 0 | P40: 0 | Q40: 0 | R40: 0 | S40: 2 | T40: 1 | U40: 0 | V40: 0 | W40: 0 | X40: 0 | Y40: 0 | Z40: 0 | AA40: 0 | AB40: 0 | AC40: 0 | AD40: 0 | AE40: 0 | AF40: 0 | AG40: 0 | AH40: 0 | AI40: 0 | AJ40: 0 | AK40: 0 | AL40: 0 | AM40: 0 | AN40: 0 | AO40: 0 | AP40: 0 | AQ40: 0 | AR40: 1 | AS40: 1 | AT40: 0 | AU40: 0 | AV40: 0 | AW40: 0 | AX40: =SUM(E40:AW40) -> 6
D41: JML | E41: =SUM(E39:E40) -> 0 | F41: =SUM(F39:F40) -> 0 | G41: =SUM(G39:G40) -> 0 | H41: =SUM(H39:H40) -> 0 | I41: =SUM(I39:I40) -> 0 | J41: =SUM(J39:J40) -> 0 | K41: =SUM(K39:K40) -> 0 | L41: =SUM(L39:L40) -> 0 | ... AW41: =SUM(AW39:AW40) -> 0 | AX41: =SUM(E41:AW41) -> 7
A43: IV | B43: DATA RINCIAN PEROLEHAN SUARA PASANGAN CALON BUPATI DAN WAKIL BUPATI
A44: NOMOR DAN NAMA CALON
A45: A.1 | B45: 1. | C45: Partai Kebangkitan Bangsa | E45: 7 | F45: 15 | G45: 12 | H45: 8 | I45: 11 | J45: 14 | K45: 8 | L45: 4 | M45: 19 | N45: 22 | O45: 11 | P45: 6 | Q45: 2 | R45: 7 | S45: 14 | T45: 6 | U45: 11 | V45: 12 | W45: 8 | X45: 4 | Y45: 4 | Z45: 15 | AA45: 19 | AB45: 11 | AC45: 6 | AD45: 11 | AE45: 12 | AF45: 15 | AG45: 14 | AH45: 42 | AI45: 18 | AJ45: 12 | AK45: 11 | AL45: 3 | AM45: 0 | AN45: 17 | AO45: 5 | AP45: 4 | AQ45: 4 | AR45: 8 | AS45: 1 | AT45: 5 | AU45: 5 | AV45: 1 | AW45: 7 | AX45: =SUM(E45:AW45) -> 451
A46: A.2 | B46: 1 | C46: 1. Dr. Hj. NIHAYATUL WAFIROH, M.A. | E46: 9 | F46: 24 | G46: 7 | H46: 21 | I46: 21 | J46: 43 | K46: 40 | L46: 22 | M46: 45 | N46: 38 | O46: 77 | P46: 31 | Q46: 17 | R46: 14 | S46: 41 | T46: 10 | U46: 32 | V46: 37 | W46: 38 | X46: 25 | Y46: 10 | Z46: 22 | AA46: 28 | AB46: 23 | AC46: 66 | AD46: 90 | AE46: 57 | AF46: 89 | AG46: 93 | AH46: 111 | AI46: 58 | AJ46: 48 | AK46: 45 | AL46: 7 | AM46: 1 | AN46: 63 | AO46: 19 | AP46: 13 | AQ46: 3 | AR46: 37 | AS46: 4 | AT46: 33 | AU46: 17 | AV46: 12 | AW46: 5 | AX46: =SUM(E46:AW46) -> 1546
B47: 2 | C47: 2. H. M. NASIM KHAN | E47: 0 | F47: 0 | G47: 1 | H47: 1 | I47: 3 | J47: 9 | K47: 3 | L47: 5 | M47: 3 | N47: 0 | O47: 2 | P47: 3 | Q47: 2 | R47: 1 | S47: 1 | T47: 2 | U47: 0 | V47: 3 | W47: 1 | X47: 0 | Y47: 1 | Z47: 2 | AA47: 0 | AB47: 1 | AC47: 0 | AD47: 2 | AE47: 4 | AF47: 0 | AG47: 0 | AH47: 1 | AI47: 1 | AJ47: 3 | AK47: 3 | AL47: 0 | AM47: 0 | AN47: 4 | AO47: 4 | AP47: 1 | AQ47: 1 | AR47: 5 | AS47: 1 | AT47: 0 | AU47: 0 | AV47: 0 | AW47: 0 | AX47: =SUM(E47:AW47) -> 74
B48: 3 | C48: 3. Dr. H. AKIK ZAMAN, M.Pd.I. | E48: 0 | F48: 1 | G48: 0 | H48: 1 | I48: 0 | J48: 1 | K48: 2 | L48: 0 | M48: 2 | N48: 0 | O48: 0 | P48: 1 | Q48: 0 | R48: 0 | S48: 5 | T48: 0 | U48: 0 | V48: 1 | W48: 1 | X48: 0 | Y48: 1 | Z48: 2 | AA48: 3 | AB48: 0 | AC48: 0 | AD48: 2 | AE48: 0 | AF48: 0 | AG48: 0 | AH48: 0 | AI48: 1 | AJ48: 1 | AK48: 0 | AL48: 0 | AM48: 0 | AN48: 3 | AO48: 0 | AP48: 0 | AQ48: 0 | AR48: 1 | AS48: 0 | AT48: 0 | AU48: 0 | AV48: 0 | AW48: 3 | AX48: =SUM(E48:AW48) -> 32
B49: 4 | C49: 4. AHMAD RIFA'I, S.H. | E49: 0 | F49: 4 | G49: 1 | H49: 0 | I49: 2 | J49: 3 | K49: 1 | L49: 0 | M49: 0 | N49: 1 | O49: 1 | P49: 0 | Q49: 0 | R49: 1 | S49: 0 | T49: 0 | U49: 0 | V49: 0 | W49: 0 | X49: 0 | Y49: 0 | Z49: 0 | AA49: 1 | AB49: 0 | AC49: 2 | AD49: 2 | AE49: 0 | AF49: 1 | AG49: 1 | AH49: 0 | AI49: 1 | AJ49: 0 | AK49: 3 | AL49: 0 | AM49: 0 | AN49: 3 | AO49: 0 | AP49: 0 | AQ49: 0 | AR49: 2 | AS49: 0 | AT49: 0 | AU49: 1 | AV49: 0 | AW49: 0 | AX49: =SUM(E49:AW49) -> 31
B50: 5 | C50: 5. Drs. H. MAHFUD M.N. | E50: 2 | F50: 0 | G50: 1 | H50: 2 | I50: 0 | J50: 0 | K50: 0 | L50: 1 | M50: 0 | N50: 0 | O50: 1 | P50: 2 | Q50: 2 | R50: 1 | S50: 3 | T50: 1 | U50: 1 | V50: 0 | W50: 1 | X50: 0 | Y50: 1 | Z50: 1 | AA50: 0 | AB50: 0 | AC50: 0 | AD50: 1 | AE50: 0 | AF50: 0 | AG50: 0 | AH50: 0 | AI50: 0 | AJ50: 2 | AK50: 2 | AL50: 1 | AM50: 0 | AN50: 0 | AO50: 0 | AP50: 1 | AQ50: 0 | AR50: 0 | AS50: 0 | AT50: 0 | AU50: 2 | AV50: 0 | AW50: 0 | AX50: =SUM(E50:AW50) -> 29
B51: 6 | C51: 6. NURHAYATI, S.Pd. | E51: 0 | F51: 1 | G51: 0 | H51: 0 | I51: 0 | J51: 0 | K51: 0 | L51: 0 | M51: 0 | N51: 0 | O51: 0 | P51: 0 | Q51: 0 | R51: 1 | S51: 2 | T51: 0 | U51: 0 | V51: 0 | W51: 0 | X51: 0 | Y51: 0 | Z51: 1 | AA51: 1 | AB51: 0 | AC51: 0 | AD51: 0 | AE51: 0 | AF51: 1 | AG51: 2 | AH51: 1 | AI51: 1 | AJ51: 0 | AK51: 0 | AL51: 0 | AM51: 0 | AN51: 0 | AO51: 0 | AP51: 0 | AQ51: 0 | AR51: 1 | AS51: 0 | AT51: 1 | AU51: 0 | AV51: 0 | AW51: 0 | AX51: =SUM(E51:AW51) -> 13
...

Sheet BULUAGUNG
C2: Kecamatan | D2: SILIRAGUNG
C3: Kabupaten | D3: BANYUWANGI
C4: Provinsi | D4: JAWA TIMUR
C9: Kelurahan | D9: BULUAGUNG
A12: I | B12: DATA PEMILIH DAN PENGGUNAAN HAK PILIH | AC12: JUMLAH AKHIR
A13: A | B13: DATA PEMILIH | E13: TPS 001 | F13: TPS 002 | G13: TPS 003 | H13: TPS 004 | I13: TPS 005 | J13: TPS 006 | K13: TPS 007 | L13: TPS 008 | M13: TPS 009 | N13: TPS 010 | O13: TPS 011 | P13: TPS 012 | Q13: TPS 013 | R13: TPS 014 | S13: TPS 015 | T13: TPS 016 | U13: TPS 017 | V13: TPS 018 | W13: TPS 019 | X13: TPS 020 | Y13: TPS 021 | Z13: TPS 022 | AA13: TPS 023 | AB13: TPS 024
B14: Jumlah Pemilih dalam Daftar Pemilih Tetap (DPT) | D14: LK | E14: 136 | F14: 147 | G14: 138 | H14: 129 | I14: 138 | J14: 136 | K14: 136 | L14: 134 | M14: 130 | N14: 135 | O14: 134 | P14: 131 | Q14: 147 | R14: 140 | S14: 144 | T14: 140 | U14: 150 | V14: 143 | W14: 162 | X14: 149 | Y14: 145 | Z14: 141 | AA14: 143 | AB14: 118 | AC14: =SUM(E14:AB14) -> 3346
D15: PR | E15: 146 | F15: 143 | G15: 130 | H15: 130 | I15: 136 | J15: 126 | K15: 125 | L15: 135 | M15: 130 | N15: 137 | O15: 137 | P15: 132 | Q15: 146 | R15: 150 | S15: 143 | T15: 148 | U15: 142 | V15: 150 | W15: 134 | X15: 127 | Y15: 143 | Z15: 134 | AA15: 131 | AB15: 104 | AC15: =SUM(E15:AB15) -> 3259
D16: JML | E16: =SUM(E14:E15) -> 282 | F16: =SUM(F14:F15) -> 290 | G16: =SUM(G14:G15) -> 268 | H16: =SUM(H14:H15) -> 259 | I16: =SUM(I14:I15) -> 274 | J16: =SUM(J14:J15) -> 262 | K16: =SUM(K14:K15) -> 261 | L16: =SUM(L14:L15) -> 269 | ... AB16: =SUM(AB14:AB15) -> 222 | AC16: =SUM(E16:AB16) -> 6605
A18: B | B18: PENGGUNA HAK PILIH
B19: 1. | C19: Jumlah pengguna hak pilih dalam Daftar Pemilih Tetap (DPT) | D19: LK | E19: 106 | F19: 114 | G19: 103 | H19: 86 | I19: 102 | J19: 107 | K19: 96 | L19: 96 | M19: 95 | N19: 95 | O19: 104 | P19: 116 | Q19: 106 | R19: 105 | S19: 117 | T19: 105 | U19: 108 | V19: 107 | W19: 120 | X19: 112 | Y19: 106 | Z19: 105 | AA19: 117 | AB19: 76 | AC19: =SUM(E19:AB19) -> 2504
D20: PR | E20: 103 | F20: 108 | G20: 98 | H20: 115 | I20: 95 | J20: 95 | K20: 97 | L20: 110 | M20: 95 | N20: 108 | O20: 100 | P20: 112 | Q20: 118 | R20: 112 | S20: 114 | T20: 108 | U20: 117 | V20: 129 | W20: 106 | X20: 93 | Y20: 108 | Z20: 106 | AA20: 106 | AB20: 69 | AC20: =SUM(E20:AB20) -> 2522
D21: JML | E21: =SUM(E19:E20) -> 209 | F21: =SUM(F19:F20) -> 222 | G21: =SUM(G19:G20) -> 201 | H21: =SUM(H19:H20) -> 201 | I21: =SUM(I19:I20) -> 197 | J21: =SUM(J19:J20) -> 202 | K21: =SUM(K19:K20) -> 193 | L21: =SUM(L19:L20) -> 206 | ... AB21: =SUM(AB19:AB20) -> 145 | AC21: =SUM(E21:AB21) -> 5026
B22: 2. | C22: Jumlah pengguna hak pilih dalam Daftar Pemilih Tambahan (DPTb) | D22: LK | E22: 1 | F22: 0 | G22: 0 | H22: 1 | I22: 0 | J22: 0 | K22: 0 | L22: 0 | M22: 0 | N22: 1 | O22: 0 | P22: 0 | Q22: 0 | R22: 0 | S22: 0 | AC22: =SUM(E22:AB22) -> 3
D23: PR | E23: 0 | F23: 0 | G23: 0 | H23: 1 | I23: 0 | J23: 0 | K23: 0 | L23: 0 | M23: 0 | N23: 0 | O23: 0 | P23: 0 | Q23: 0 | R23: 0 | S23: 0 | AC23: =SUM(E23:AB23) -> 1
D24: JML | E24: =SUM(E22:E23) -> 1 | F24: =SUM(F22:F23) -> 0 | G24: =SUM(G22:G23) -> 0 | H24: =SUM(H22:H23) -> 2 | I24: =SUM(I22:I23) -> 0 | J24: =SUM(J22:J23) -> 0 | K24: =SUM(K22:K23) -> 0 | L24: =SUM(L22:L23) -> 0 | ... AB24: =SUM(AB22:AB23) -> 0 | AC24: =SUM(E24:AB24) -> 4
B25: 3. | C25: Jumlah pengguna hak pilih dalam Daftar Pemilih Khusus (DPK) | D25: LK | E25: 1 | F25: 0 | G25: 0 | H25: 1 | I25: 0 | J25: 1 | K25: 2 | L25: 3 | M25: 0 | N25: 0 | O25: 2 | P25: 1 | Q25: 4 | R25: 1 | S25: 0 | T25: 6 | U25: 2 | V25: 0 | W25: 1 | X25: 1 | Y25: 0 | Z25: 0 | AA25: 2 | AB25: 0 | AC25: =SUM(E25:AB25) -> 28
D26: PR | E26: 4 | F26: 1 | G26: 0 | H26: 0 | I26: 0 | J26: 4 | K26: 3 | L26: 1 | M26: 0 | N26: 2 | O26: 3 | P26: 1 | Q26: 4 | R26: 4 | S26: 0 | T26: 5 | U26: 3 | V26: 4 | W26: 0 | X26: 0 | Y26: 1 | Z26: 2 | AA26: 0 | AB26: 1 | AC26: =SUM(E26:AB26) -> 43
D27: JML | E27: =SUM(E25:E26) -> 5 | F27: =SUM(F25:F26) -> 1 | G27: =SUM(G25:G26) -> 0 | H27: =SUM(H25:H26) -> 1 | I27: =SUM(I25:I26) -> 0 | J27: =SUM(J25:J26) -> 5 | K27: =SUM(K25:K26) -> 5 | L27: =SUM(L25:L26) -> 4 | ... AB27: =SUM(AB25:AB26) -> 1 | AC27: =SUM(E27:AB27) -> 71
B28: 4. | C28: Jumlah Pengguna Hak Pilih (B.1+B.2+B.3) | D28: LK | E28: =SUM(E19,E22,E25) -> 108 | F28: =SUM(F19,F22,F25) -> 114 | G28: =SUM(G19,G22,G25) -> 103 | H28: =SUM(H19,H22,H25) -> 88 | I28: =SUM(I19,I22,I25) -> 102 | J28: =SUM(J19,J22,J25) -> 108 | K28: =SUM(K19,K22,K25) -> 98 | L28: =SUM(L19,L22,L25) -> 99 | ... AB28: =SUM(AB19,AB22,AB25) -> 76 | AC28: =SUM(E28:AB28) -> 2535
D29: PR | E29: =SUM(E20,E23,E26) -> 107 | F29: =SUM(F20,F23,F26) -> 109 | G29: =SUM(G20,G23,G26) -> 98 | H29: =SUM(H20,H23,H26) -> 116 | I29: =SUM(I20,I23,I26) -> 95 | J29: =SUM(J20,J23,J26) -> 99 | K29: =SUM(K20,K23,K26) -> 100 | L29: =SUM(L20,L23,L26) -> 111 | ... AB29: =SUM(AB20,AB23,AB26) -> 70 | AC29: =SUM(E29:AB29) -> 2566
D30: JML | E30: =SUM(E28:E29) -> 215 | F30: =SUM(F28:F29) -> 223 | G30: =SUM(G28:G29) -> 201 | H30: =SUM(H28:H29) -> 204 | I30: =SUM(I28:I29) -> 197 | J30: =SUM(J28:J29) -> 207 | K30: =SUM(K28:K29) -> 198 | L30: =SUM(L28:L29) -> 210 | ... AB30: =SUM(AB28:AB29) -> 146 | AC30: =SUM(E30:AB30) -> 5101
A32: II | B32: DATA PENGGUNAAN SURAT SUARA
A33: 1 | B33: Jumlah surat suara yang diterima, termasuk surat suara cadangan 2,5% dari DPT | E33: 288 | F33: 296 | G33: 274 | H33: 265 | I33: 280 | J33: 268 | K33: 277 | L33: 275 | M33: 266 | N33: 276 | O33: 277 | P33: 268 | Q33: 299 | R33: 296 | S33: 293 | T33: 294 | U33: 298 | V33: 299 | W33: 302 | X33: 282 | Y33: 294 | Z33: 281 | AA33: 281 | AB33: 227 | AC33: =SUM(E33:AB33) -> 6756
A34: 2 | B34: Jumlah surat suara yang digunakan | E34: 215 | F34: 223 | G34: 201 | H34: 204 | I34: 197 | J34: 207 | K34: 198 | L34: 210 | M34: 190 | N34: 206 | O34: 209 | P34: 230 | Q34: 232 | R34: 222 | S34: 231 | T34: 224 | U34: 230 | V34: 240 | W34: 227 | X34: 206 | Y34: 215 | Z34: 213 | AA34: 225 | AB34: 146 | AC34: =SUM(E34:AB34) -> 5101
A35: 3 | B35: Jumlah surat suara dikembalikan oleh pemilih (karena rusak atau keliru coblos) | E35: 0 | F35: 0 | G35: 0 | H35: 0 | I35: 1 | J35: 0 | K35: 0 | L35: 0 | M35: 0 | N35: 0 | O35: 0 | P35: 0 | Q35: 0 | R35: 0 | S35: 0 | AC35: =SUM(E35:AB35) -> 1
A36: 4 | B36: Jumlah surat suara yang tidak digunakan/tidak terpakai, termasuk sisa surat suara cadangan | E36: =E33-(E34+E35) -> 73 | F36: =F33-(F34+F35) -> 73 | G36: =G33-(G34+G35) -> 73 | H36: =H33-(H34+H35) -> 61 | I36: =I33-(I34+I35) -> 82 | J36: =J33-(J34+J35) -> 61 | K36: =K33-(K34+K35) -> 79 | L36: =L33-(L34+L35) -> 65 | ... AB36: =AB33-(AB34+AB35) -> 81 | AC36: =SUM(E36:AB36) -> 1654
A38: III | B38: DATA PEMILIH DISABILITAS
B39: Jumlah seluruh Pemilih disabilitas yang menggunakan hak pilih | D39: LK | H39: 1 | Y39: 1 | AC39: =SUM(E39:AB39) -> 2
D40: PR | E40: 1 | G40: 2 | H40: 3 | Y40: 1 | AA40: 1 | AC40: =SUM(E40:AB40) -> 8
D41: JML | E41: =SUM(E39:E40) -> 1 | F41: =SUM(F39:F40) -> 0 | G41: =SUM(G39:G40) -> 2 | H41: =SUM(H39:H40) -> 4 | I41: =SUM(I39:I40) -> 0 | J41: =SUM(J39:J40) -> 0 | K41: =SUM(K39:K40) -> 0 | L41: =SUM(L39:L40) -> 0 | ... AB41: =SUM(AB39:AB40) -> 0 | AC41: =SUM(E41:AB41) -> 10
A43: IV | B43: DATA RINCIAN PEROLEHAN SUARA PASANGAN CALON BUPATI DAN WAKIL BUPATI
A44: NOMOR DAN NAMA CALON
A45: A.1 | B45: 1. | C45: Partai Kebangkitan Bangsa | E45: 6 | F45: 6 | G45: 4 | H45: 13 | I45: 13 | J45: 9 | K45: 6 | L45: 7 | M45: 12 | N45: 1 | O45: 14 | P45: 8 | Q45: 2 | R45: 3 | S45: 8 | T45: 6 | U45: 17 | V45: 26 | W45: 13 | X45: 0 | Y45: 4 | Z45: 1 | AA45: 3 | AB45: 7 | AC45: =SUM(E45:AB45) -> 189
A46: A.2 | B46: 1 | C46: 1. Dr. Hj. NIHAYATUL WAFIROH, M.A. | E46: 31 | F46: 46 | G46: 33 | H46: 44 | I46: 54 | J46: 25 | K46: 24 | L46: 37 | M46: 40 | N46: 39 | O46: 33 | P46: 16 | Q46: 14 | R46: 12 | S46: 18 | T46: 31 | U46: 53 | V46: 99 | W46: 35 | X46: 1 | Y46: 5 | Z46: 0 | AA46: 1 | AB46: 28 | AC46: =SUM(E46:AB46) -> 719
B47: 2 | C47: 2. H. M. NASIM KHAN | E47: 1 | F47: 1 | G47: 3 | H47: 4 | I47: 1 | J47: 0 | K47: 5 | L47: 1 | M47: 0 | N47: 1 | O47: 1 | P47: 3 | Q47: 1 | R47: 0 | S47: 0 | T47: 0 | U47: 1 | V47: 5 | W47: 2 | X47: 0 | Y47: 0 | Z47: 0 | AA47: 1 | AB47: 0 | AC47: =SUM(E47:AB47) -> 31
B48: 3 | C48: 3. Dr. H. AKIK ZAMAN, M.Pd.I. | E48: 0 | F48: 1 | G48: 2 | H48: 0 | I48: 4 | J48: 0 | K48: 3 | L48: 0 | M48: 0 | N48: 0 | O48: 1 | P48: 0 | Q48: 0 | R48: 0 | S48: 0 | T48: 1 | U48: 0 | V48: 2 | W48: 0 | X48: 0 | Y48: 0 | Z48: 0 | AA48: 0 | AB48: 0 | AC48: =SUM(E48:AB48) -> 14
B49: 4 | C49: 4. AHMAD RIFA'I, S.H. | E49: 0 | F49: 1 | G49: 4 | H49: 0 | I49: 0 | J49: 1 | K49: 1 | L49: 3 | M49: 1 | N49: 0 | O49: 0 | P49: 0 | Q49: 1 | R49: 0 | S49: 1 | T49: 0 | U49: 1 | V49: 1 | W49: 0 | X49: 0 | Y49: 0 | Z49: 0 | AA49: 0 | AB49: 0 | AC49: =SUM(E49:AB49) -> 15
B50: 5 | C50: 5. Drs. H. MAHFUD M.N. | E50: 1 | F50: 0 | G50: 1 | H50: 0 | I50: 3 | J50: 0 | K50: 0 | L50: 1 | M50: 1 | N50: 0 | O50: 2 | P50: 0 | Q50: 1 | R50: 0 | S50: 0 | T50: 0 | U50: 0 | V50: 1 | W50: 1 | X50: 0 | Y50: 2 | Z50: 0 | AA50: 0 | AB50: 2 | AC50: =SUM(E50:AB50) -> 16
B51: 6 | C51: 6. NURHAYATI, S.Pd. | E51: 2 | F51: 0 | G51: 3 | H51: 0 | I51: 0 | J51: 0 | K51: 1 | L51: 0 | M51: 3 | N51: 0 | O51: 1 | P51: 1 | Q51: 0 | R51: 0 | S51: 0 | T51: 1 | U51: 1 | V51: 1 | W51: 1 | X51: 0 | Y51: 0 | Z51: 1 | AA51: 0 | AB51: 0 | AC51: =SUM(E51:AB51) -> 16
...

Sheet KESILIR
C2: Kecamatan | D2: SILIRAGUNG
C3: Kabupaten | D3: BANYUWANGI
C4: Provinsi | D4: JAWA TIMUR
C9: Kelurahan | D9: KESILIR
A12: I | B12: DATA PEMILIH DAN PENGGUNAAN HAK PILIH | AJ12: JUMLAH AKHIR
A13: A | B13: DATA PEMILIH | E13: TPS 001 | F13: TPS 002 | G13: TPS 003 | H13: TPS 004 | I13: TPS 005 | J13: TPS 006 | K13: TPS 007 | L13: TPS 008 | M13: TPS 009 | N13: TPS 010 | O13: TPS 011 | P13: TPS 012 | Q13: TPS 013 | R13: TPS 014 | S13: TPS 015 | T13: TPS 016 | U13: TPS 017 | V13: TPS 018 | W13: TPS 019 | X13: TPS 020 | Y13: TPS 021 | Z13: TPS 022 | AA13: TPS 023 | AB13: TPS 024 | AC13: TPS 025 | AD13: TPS 026 | AE13: TPS 027 | AF13: TPS 028 | AG13: TPS 029 | AH13: TPS 030 | AI13: TPS 031
B14: Jumlah Pemilih dalam Daftar Pemilih Tetap (DPT) | D14: LK | E14: 136 | F14: 134 | G14: 138 | H14: 149 | I14: 111 | J14: 124 | K14: 130 | L14: 121 | M14: 121 | N14: 142 | O14: 141 | P14: 134 | Q14: 120 | R14: 141 | S14: 131 | T14: 123 | U14: 125 | V14: 131 | W14: 132 | X14: 127 | Y14: 142 | Z14: 122 | AA14: 134 | AB14: 125 | AC14: 128 | AD14: 136 | AE14: 135 | AF14: 115 | AG14: 126 | AH14: 141 | AI14: 132 | AJ14: =SUM(E14:AI14) -> 4047
D15: PR | E15: 114 | F15: 111 | G15: 135 | H15: 138 | I15: 123 | J15: 131 | K15: 131 | L15: 118 | M15: 127 | N15: 126 | O15: 131 | P15: 149 | Q15: 111 | R15: 124 | S15: 130 | T15: 117 | U15: 130 | V15: 121 | W15: 122 | X15: 116 | Y15: 119 | Z15: 128 | AA15: 142 | AB15: 128 | AC15: 130 | AD15: 140 | AE15: 123 | AF15: 127 | AG15: 142 | AH15: 128 | AI15: 133 | AJ15: =SUM(E15:AI15) -> 3945
D16: JML | E16: =SUM(E14:E15) -> 250 | F16: =SUM(F14:F15) -> 245 | G16: =SUM(G14:G15) -> 273 | H16: =SUM(H14:H15) -> 287 | I16: =SUM(I14:I15) -> 234 | J16: =SUM(J14:J15) -> 255 | K16: =SUM(K14:K15) -> 261 | L16: =SUM(L14:L15) -> 239 | ... AI16: =SUM(AI14:AI15) -> 265 | AJ16: =SUM(E16:AI16) -> 7992
A18: B | B18: PENGGUNA HAK PILIH
B19: 1. | C19: Jumlah pengguna hak pilih dalam Daftar Pemilih Tetap (DPT) | D19: LK | E19: 108 | F19: 107 | G19: 111 | H19: 110 | I19: 91 | J19: 99 | K19: 109 | L19: 92 | M19: 102 | N19: 116 | O19: 107 | P19: 110 | Q19: 108 | R19: 108 | S19: 95 | T19: 93 | U19: 105 | V19: 96 | W19: 98 | X19: 98 | Y19: 108 | Z19: 98 | AA19: 111 | AB19: 94 | AC19: 110 | AD19: 101 | AE19: 115 | AF19: 102 | AG19: 108 | AH19: 115 | AI19: 110 | AJ19: =SUM(E19:AI19) -> 3235
D20: PR | E20: 94 | F20: 96 | G20: 111 | H20: 113 | I20: 100 | J20: 103 | K20: 112 | L20: 94 | M20: 93 | N20: 104 | O20: 105 | P20: 119 | Q20: 91 | R20: 103 | S20: 100 | T20: 95 | U20: 116 | V20: 101 | W20: 91 | X20: 92 | Y20: 108 | Z20: 111 | AA20: 114 | AB20: 90 | AC20: 109 | AD20: 105 | AE20: 101 | AF20: 111 | AG20: 116 | AH20: 102 | AI20: 112 | AJ20: =SUM(E20:AI20) -> 3212
D21: JML | E21: =SUM(E19:E20) -> 202 | F21: =SUM(F19:F20) -> 203 | G21: =SUM(G19:G20) -> 222 | H21: =SUM(H19:H20) -> 223 | I21: =SUM(I19:I20) -> 191 | J21: =SUM(J19:J20) -> 202 | K21: =SUM(K19:K20) -> 221 | L21: =SUM(L19:L20) -> 186 | ... AI21: =SUM(AI19:AI20) -> 222 | AJ21: =SUM(E21:AI21) -> 6447
B22: 2. | C22: Jumlah pengguna hak pilih dalam Daftar Pemilih Tambahan (DPTb) | D22: LK | Z22: 1 | AJ22: =SUM(E22:AI22) -> 1
D23: PR | AJ23: =SUM(E23:AI23) -> 0
D24: JML | E24: =SUM(E22:E23) -> 0 | F24: =SUM(F22:F23) -> 0 | G24: =SUM(G22:G23) -> 0 | H24: =SUM(H22:H23) -> 0 | I24: =SUM(I22:I23) -> 0 | J24: =SUM(J22:J23) -> 0 | K24: =SUM(K22:K23) -> 0 | L24: =SUM(L22:L23) -> 0 | ... AI24: =SUM(AI22:AI23) -> 0 | AJ24: =SUM(E24:AI24) -> 1
B25: 3. | C25: Jumlah pengguna hak pilih dalam Daftar Pemilih Khusus (DPK) | D25: LK | E25: 4 | F25: 3 | G25: 3 | H25: 1 | I25: 0 | J25: 6 | K25: 3 | L25: 3 | M25: 3 | N25: 0 | O25: 1 | P25: 0 | Q25: 0 | R25: 1 | S25: 6 | T25: 3 | U25: 1 | V25: 4 | W25: 6 | X25: 4 | Y25: 3 | Z25: 1 | AA25: 4 | AB25: 3 | AC25: 0 | AD25: 0 | AE25: 4 | AF25: 0 | AG25: 2 | AH25: 5 | AI25: 1 | AJ25: =SUM(E25:AI25) -> 75
D26: PR | E26: 5 | F26: 6 | G26: 4 | H26: 2 | I26: 0 | J26: 7 | K26: 5 | L26: 6 | M26: 5 | N26: 1 | O26: 1 | P26: 3 | Q26: 0 | R26: 1 | S26: 11 | T26: 6 | U26: 1 | V26: 3 | W26: 8 | X26: 2 | Y26: 4 | Z26: 1 | AA26: 3 | AB26: 2 | AC26: 0 | AD26: 1 | AE26: 3 | AF26: 0 | AG26: 1 | AH26: 5 | AI26: 4 | AJ26: =SUM(E26:AI26) -> 101
D27: JML | E27: =SUM(E25:E26) -> 9 | F27: =SUM(F25:F26) -> 9 | G27: =SUM(G25:G26) -> 7 | H27: =SUM(H25:H26) -> 3 | I27: =SUM(I25:I26) -> 0 | J27: =SUM(J25:J26) -> 13 | K27: =SUM(K25:K26) -> 8 | L27: =SUM(L25:L26) -> 9 | ... AI27: =SUM(AI25:AI26) -> 5 | AJ27: =SUM(E27:AI27) -> 176
B28: 4. | C28: Jumlah Pengguna Hak Pilih (B.1+B.2+B.3) | D28: LK | E28: =SUM(E19,E22,E25) -> 112 | F28: =SUM(F19,F22,F25) -> 110 | G28: =SUM(G19,G22,G25) -> 114 | H28: =SUM(H19,H22,H25) -> 111 | I28: =SUM(I19,I22,I25) -> 91 | J28: =SUM(J19,J22,J25) -> 105 | K28: =SUM(K19,K22,K25) -> 112 | L28: =SUM(L19,L22,L25) -> 95 | ... AI28: =SUM(AI19,AI22,AI25) -> 111 | AJ28: =SUM(E28:AI28) -> 3311
D29: PR | E29: =SUM(E20,E23,E26) -> 99 | F29: =SUM(F20,F23,F26) -> 102 | G29: =SUM(G20,G23,G26) -> 115 | H29: =SUM(H20,H23,H26) -> 115 | I29: =SUM(I20,I23,I26) -> 100 | J29: =SUM(J20,J23,J26) -> 110 | K29: =SUM(K20,K23,K26) -> 117 | L29: =SUM(L20,L23,L26) -> 100 | ... AI29: =SUM(AI20,AI23,AI26) -> 116 | AJ29: =SUM(E29:AI29) -> 3313
D30: JML | E30: =SUM(E28:E29) -> 211 | F30: =SUM(F28:F29) -> 212 | G30: =SUM(G28:G29) -> 229 | H30: =SUM(H28:H29) -> 226 | I30: =SUM(I28:I29) -> 191 | J30: =SUM(J28:J29) -> 215 | K30: =SUM(K28:K29) -> 229 | L30: =SUM(L28:L29) -> 195 | ... AI30: =SUM(AI28:AI29) -> 227 | AJ30: =SUM(E30:AI30) -> 6624
A32: II | B32: DATA PENGGUNAAN SURAT SUARA
A33: 1 | B33: Jumlah surat suara yang diterima, termasuk surat suara cadangan 2,5% dari DPT | E33: 255 | F33: 250 | G33: 279 | H33: 293 | I33: 239 | J33: 261 | K33: 277 | L33: 244 | M33: 253 | N33: 274 | O33: 267 | P33: 289 | Q33: 236 | R33: 271 | S33: 268 | T33: 245 | U33: 261 | V33: 258 | W33: 260 | X33: 249 | Y33: 267 | Z33: 255 | AA33: 272 | AB33: 259 | AC33: 264 | AD33: 282 | AE33: 265 | AF33: 247 | AG33: 284 | AH33: 275 | AI33: 271 | AJ33: =SUM(E33:AI33) -> 8170
A34: 2 | B34: Jumlah surat suara yang digunakan | E34: 211 | F34: 212 | G34: 229 | H34: 226 | I34: 191 | J34: 215 | K34: 229 | L34: 195 | M34: 203 | N34: 221 | O34: 214 | P34: 232 | Q34: 199 | R34: 213 | S34: 212 | T34: 197 | U34: 223 | V34: 204 | W34: 203 | X34: 196 | Y34: 223 | Z34: 212 | AA34: 232 | AB34: 189 | AC34: 219 | AD34: 207 | AE34: 223 | AF34: 213 | AG34: 227 | AH34: 227 | AI34: 227 | AJ34: =SUM(E34:AI34) -> 6624
A35: 3 | B35: Jumlah surat suara dikembalikan oleh pemilih (karena rusak atau keliru coblos) | T35: 0 | U35: 0 | V35: 3 | W35: 0 | X35: 0 | Y35: 0 | Z35: 0 | AA35: 0 | AB35: 0 | AC35: 1 | AD35: 1 | AE35: 0 | AF35: 0 | AG35: 0 | AH35: 1 | AI35: 1 | AJ35: =SUM(E35:AI35) -> 7
A36: 4 | B36: Jumlah surat suara yang tidak digunakan/tidak terpakai, termasuk sisa surat suara cadangan | E36: =E33-(E34+E35) -> 44 | F36: =F33-(F34+F35) -> 38 | G36: =G33-(G34+G35) -> 50 | H36: =H33-(H34+H35) -> 67 | I36: =I33-(I34+I35) -> 48 | J36: =J33-(J34+J35) -> 46 | K36: =K33-(K34+K35) -> 48 | L36: =L33-(L34+L35) -> 49 | ... AI36: =AI33-(AI34+AI35) -> 43 | AJ36: =SUM(E36:AI36) -> 1539
A38: III | B38: DATA PEMILIH DISABILITAS
B39: Jumlah seluruh Pemilih disabilitas yang menggunakan hak pilih | D39: LK | L39: 1 | N39: 2 | X39: 1 | AJ39: =SUM(E39:AI39) -> 4
D40: PR | AJ40: =SUM(E40:AI40) -> 0
D41: JML | E41: =SUM(E39:E40) -> 0 | F41: =SUM(F39:F40) -> 0 | G41: =SUM(G39:G40) -> 0 | H41: =SUM(H39:H40) -> 0 | I41: =SUM(I39:I40) -> 0 | J41: =SUM(J39:J40) -> 0 | K41: =SUM(K39:K40) -> 0 | L41: =SUM(L39:L40) -> 1 | ... AI41: =SUM(AI39:AI40) -> 0 | AJ41: =SUM(E41:AI41) -> 4
A43: IV | B43: DATA RINCIAN PEROLEHAN SUARA PASANGAN CALON BUPATI DAN WAKIL BUPATI
A44: NOMOR DAN NAMA CALON
A45: A.1 | B45: 1. | C45: Partai Kebangkitan Bangsa | E45: 5 | F45: 3 | G45: 5 | H45: 4 | I45: 6 | J45: 2 | K45: 6 | L45: 5 | M45: 10 | N45: 5 | O45: 5 | P45: 2 | Q45: 2 | R45: 4 | S45: 3 | T45: 5 | U45: 7 | V45: 10 | W45: 3 | X45: 2 | Y45: 4 | Z45: 11 | AA45: 1 | AB45: 5 | AC45: 4 | AD45: 1 | AE45: 5 | AF45: 1 | AG45: 7 | AH45: 7 | AI45: 3 | AJ45: =SUM(E45:AI45) -> 143
A46: A.2 | B46: 1 | C46: 1. Dr. Hj. NIHAYATUL WAFIROH, M.A. | E46: 21 | F46: 21 | G46: 25 | H46: 10 | I46: 20 | J46: 8 | K46: 30 | L46: 15 | M46: 32 | N46: 45 | O46: 19 | P46: 22 | Q46: 5 | R46: 11 | S46: 13 | T46: 15 | U46: 23 | V46: 26 | W46: 30 | X46: 7 | Y46: 25 | Z46: 34 | AA46: 15 | AB46: 14 | AC46: 15 | AD46: 4 | AE46: 16 | AF46: 9 | AG46: 24 | AH46: 12 | AI46: 19 | AJ46: =SUM(E46:AI46) -> 585
B47: 2 | C47: 2. H. M. NASIM KHAN | E47: 4 | F47: 5 | G47: 3 | H47: 4 | I47: 2 | J47: 0 | K47: 1 | L47: 0 | M47: 1 | N47: 1 | O47: 3 | P47: 2 | Q47: 0 | R47: 0 | S47: 0 | T47: 0 | U47: 6 | V47: 0 | W47: 5 | X47: 2 | Y47: 0 | Z47: 1 | AA47: 0 | AB47: 0 | AC47: 1 | AD47: 1 | AE47: 3 | AF47: 1 | AG47: 7 | AH47: 1 | AI47: 1 | AJ47: =SUM(E47:AI47) -> 55
B48: 3 | C48: 3. Dr. H. AKIK ZAMAN, M.Pd.I. | E48: 1 | F48: 6 | G48: 2 | H48: 0 | I48: 2 | J48: 0 | K48: 1 | L48: 0 | M48: 9 | N48: 1 | O48: 0 | P48: 4 | Q48: 0 | R48: 0 | S48: 0 | T48: 1 | U48: 0 | V48: 0 | W48: 0 | X48: 2 | Y48: 0 | Z48: 1 | AA48: 0 | AB48: 0 | AC48: 1 | AD48: 1 | AE48: 1 | AF48: 0 | AG48: 0 | AH48: 0 | AI48: 0 | AJ48: =SUM(E48:AI48) -> 33
B49: 4 | C49: 4. AHMAD RIFA'I, S.H. | E49: 2 | F49: 1 | G49: 3 | H49: 1 | I49: 3 | J49: 0 | K49: 3 | L49: 1 | M49: 0 | N49: 2 | O49: 1 | P49: 1 | Q49: 0 | R49: 5 | S49: 6 | T49: 2 | U49: 0 | V49: 2 | W49: 1 | X49: 1 | Y49: 0 | Z49: 1 | AA49: 1 | AB49: 0 | AC49: 0 | AD49: 0 | AE49: 0 | AF49: 1 | AG49: 0 | AH49: 2 | AI49: 1 | AJ49: =SUM(E49:AI49) -> 41
B50: 5 | C50: 5. Drs. H. MAHFUD M.N. | E50: 3 | F50: 2 | G50: 3 | H50: 2 | I50: 0 | J50: 0 | K50: 0 | L50: 0 | M50: 0 | N50: 0 | O50: 0 | P50: 1 | Q50: 0 | R50: 0 | S50: 2 | T50: 0 | U50: 1 | V50: 0 | W50: 0 | X50: 0 | Y50: 0 | Z50: 0 | AA50: 0 | AB50: 1 | AC50: 0 | AD50: 1 | AE50: 0 | AF50: 0 | AG50: 0 | AH50: 0 | AI50: 0 | AJ50: =SUM(E50:AI50) -> 16
B51: 6 | C51: 6. NURHAYATI, S.Pd. | E51: 0 | F51: 1 | G51: 3 | H51: 1 | I51: 1 | J51: 0 | K51: 0 | L51: 0 | M51: 2 | N51: 1 | O51: 0 | P51: 0 | Q51: 0 | R51: 2 | S51: 0 | T51: 0 | U51: 4 | V51: 2 | W51: 1 | X51: 0 | Y51: 1 | Z51: 2 | AA51: 0 | AB51: 0 | AC51: 0 | AD51: 2 | AE51: 0 | AF51: 0 | AG51: 0 | AH51: 0 | AI51: 1 | AJ51: =SUM(E51:AI51) -> 24
...

Sheet SENEPOREJO
C2: Kecamatan | D2: SILIRAGUNG
C3: Kabupaten | D3: BANYUWANGI
C4: Provinsi | D4: JAWA TIMUR
C9: Kelurahan | D9: SENEPOREJO
A12: I | B12: DATA PEMILIH DAN PENGGUNAAN HAK PILIH | AB12: JUMLAH AKHIR
A13: A | B13: DATA PEMILIH | E13: TPS 001 | F13: TPS 002 | G13: TPS 003 | H13: TPS 004 | I13: TPS 005 | J13: TPS 006 | K13: TPS 007 | L13: TPS 008 | M13: TPS 009 | N13: TPS 010 | O13: TPS 011 | P13: TPS 012 | Q13: TPS 013 | R13: TPS 014 | S13: TPS 015 | T13: TPS 016 | U13: TPS 017 | V13: TPS 018 | W13: TPS 019 | X13: TPS 020 | Y13: TPS 021 | Z13: TPS 022 | AA13: TPS 023
B14: Jumlah Pemilih dalam Daftar Pemilih Tetap (DPT) | D14: LK | E14: 133 | F14: 132 | G14: 142 | H14: 138 | I14: 136 | J14: 115 | K14: 118 | L14: 107 | M14: 150 | N14: 140 | O14: 90 | P14: 91 | Q14: 134 | R14: 109 | S14: 136 | T14: 100 | U14: 130 | V14: 139 | W14: 134 | X14: 135 | Y14: 123 | Z14: 149 | AA14: 143 | AB14: =SUM(E14:AA14) -> 2924
D15: PR | E15: 148 | F15: 134 | G15: 140 | H15: 136 | I15: 142 | J15: 119 | K15: 112 | L15: 104 | M15: 127 | N15: 144 | O15: 88 | P15: 85 | Q15: 119 | R15: 119 | S15: 143 | T15: 99 | U15: 146 | V15: 139 | W15: 131 | X15: 148 | Y15: 120 | Z15: 144 | AA15: 140 | AB15: =SUM(E15:AA15) -> 2927
D16: JML | E16: =SUM(E14:E15) -> 281 | F16: =SUM(F14:F15) -> 266 | G16: =SUM(G14:G15) -> 282 | H16: =SUM(H14:H15) -> 274 | I16: =SUM(I14:I15) -> 278 | J16: =SUM(J14:J15) -> 234 | K16: =SUM(K14:K15) -> 230 | L16: =SUM(L14:L15) -> 211 | ... AA16: =SUM(AA14:AA15) -> 283 | AB16: =SUM(E16:AA16) -> 5851
A18: B | B18: PENGGUNA HAK PILIH
B19: 1. | C19: Jumlah pengguna hak pilih dalam Daftar Pemilih Tetap (DPT) | D19: LK | E19: 105 | F19: 102 | G19: 111 | H19: 105 | I19: 108 | J19: 91 | K19: 95 | L19: 80 | M19: 109 | N19: 124 | O19: 77 | P19: 80 | Q19: 100 | R19: 89 | S19: 110 | T19: 79 | U19: 106 | V19: 107 | W19: 113 | X19: 111 | Y19: 100 | Z19: 103 | AA19: 116 | AB19: =SUM(E19:AA19) -> 2321
D20: PR | E20: 116 | F20: 114 | G20: 116 | H20: 105 | I20: 119 | J20: 101 | K20: 95 | L20: 87 | M20: 102 | N20: 126 | O20: 75 | P20: 75 | Q20: 93 | R20: 98 | S20: 122 | T20: 73 | U20: 125 | V20: 115 | W20: 114 | X20: 125 | Y20: 99 | Z20: 117 | AA20: 112 | AB20: =SUM(E20:AA20) -> 2424
D21: JML | E21: =SUM(E19:E20) -> 221 | F21: =SUM(F19:F20) -> 216 | G21: =SUM(G19:G20) -> 227 | H21: =SUM(H19:H20) -> 210 | I21: =SUM(I19:I20) -> 227 | J21: =SUM(J19:J20) -> 192 | K21: =SUM(K19:K20) -> 190 | L21: =SUM(L19:L20) -> 167 | ... AA21: =SUM(AA19:AA20) -> 228 | AB21: =SUM(E21:AA21) -> 4745
B22: 2. | C22: Jumlah pengguna hak pilih dalam Daftar Pemilih Tambahan (DPTb) | D22: LK | E22: 0 | F22: 0 | G22: 0 | H22: 2 | I22: 0 | J22: 0 | K22: 0 | L22: 0 | M22: 0 | N22: 0 | O22: 0 | P22: 0 | Q22: 0 | R22: 0 | S22: 0 | AB22: =SUM(E22:AA22) -> 2
D23: PR | E23: 0 | F23: 1 | G23: 0 | H23: 1 | I23: 0 | J23: 0 | K23: 0 | L23: 0 | M23: 0 | N23: 0 | O23: 0 | P23: 0 | Q23: 0 | R23: 0 | S23: 0 | AB23: =SUM(E23:AA23) -> 2
D24: JML | E24: =SUM(E22:E23) -> 0 | F24: =SUM(F22:F23) -> 1 | G24: =SUM(G22:G23) -> 0 | H24: =SUM(H22:H23) -> 3 | I24: =SUM(I22:I23) -> 0 | J24: =SUM(J22:J23) -> 0 | K24: =SUM(K22:K23) -> 0 | L24: =SUM(L22:L23) -> 0 | ... AA24: =SUM(AA22:AA23) -> 0 | AB24: =SUM(E24:AA24) -> 4
B25: 3. | C25: Jumlah pengguna hak pilih dalam Daftar Pemilih Khusus (DPK) | D25: LK | E25: 0 | F25: 0 | G25: 0 | H25: 3 | I25: 1 | J25: 2 | K25: 2 | L25: 0 | M25: 0 | N25: 0 | O25: 1 | P25: 1 | Q25: 2 | R25: 0 | S25: 0 | T25: 0 | U25: 0 | V25: 1 | W25: 0 | X25: 1 | Y25: 0 | Z25: 1 | AA25: 0 | AB25: =SUM(E25:AA25) -> 15
D26: PR | E26: 2 | F26: 0 | G26: 2 | H26: 1 | I26: 0 | J26: 0 | K26: 3 | L26: 1 | M26: 0 | N26: 0 | O26: 1 | P26: 0 | Q26: 0 | R26: 2 | S26: 0 | T26: 0 | U26: 1 | V26: 3 | W26: 0 | X26: 0 | Y26: 0 | Z26: 0 | AA26: 0 | AB26: =SUM(E26:AA26) -> 16
D27: JML | E27: =SUM(E25:E26) -> 2 | F27: =SUM(F25:F26) -> 0 | G27: =SUM(G25:G26) -> 2 | H27: =SUM(H25:H26) -> 4 | I27: =SUM(I25:I26) -> 1 | J27: =SUM(J25:J26) -> 2 | K27: =SUM(K25:K26) -> 5 | L27: =SUM(L25:L26) -> 1 | ... AA27: =SUM(AA25:AA26) -> 0 | AB27: =SUM(E27:AA27) -> 31
B28: 4. | C28: Jumlah Pengguna Hak Pilih (B.1+B.2+B.3) | D28: LK | E28: =SUM(E19,E22,E25) -> 105 | F28: =SUM(F19,F22,F25) -> 102 | G28: =SUM(G19,G22,G25) -> 111 | H28: =SUM(H19,H22,H25) -> 110 | I28: =SUM(I19,I22,I25) -> 109 | J28: =SUM(J19,J22,J25) -> 93 | K28: =SUM(K19,K22,K25) -> 97 | L28: =SUM(L19,L22,L25) -> 80 | ... AA28: =SUM(AA19,AA22,AA25) -> 116 | AB28: =SUM(E28:AA28) -> 2338
D29: PR | E29: =SUM(E20,E23,E26) -> 118 | F29: =SUM(F20,F23,F26) -> 115 | G29: =SUM(G20,G23,G26) -> 118 | H29: =SUM(H20,H23,H26) -> 107 | I29: =SUM(I20,I23,I26) -> 119 | J29: =SUM(J20,J23,J26) -> 101 | K29: =SUM(K20,K23,K26) -> 98 | L29: =SUM(L20,L23,L26) -> 88 | ... AA29: =SUM(AA20,AA23,AA26) -> 112 | AB29: =SUM(E29:AA29) -> 2442
D30: JML | E30: =SUM(E28:E29) -> 223 | F30: =SUM(F28:F29) -> 217 | G30: =SUM(G28:G29) -> 229 | H30: =SUM(H28:H29) -> 217 | I30: =SUM(I28:I29) -> 228 | J30: =SUM(J28:J29) -> 194 | K30: =SUM(K28:K29) -> 195 | L30: =SUM(L28:L29) -> 168 | ... AA30: =SUM(AA28:AA29) -> 228 | AB30: =SUM(E30:AA30) -> 4780
A32: II | B32: DATA PENGGUNAAN SURAT SUARA
A33: 1 | B33: Jumlah surat suara yang diterima, termasuk surat suara cadangan 2,5% dari DPT | E33: 287 | F33: 271 | G33: 288 | H33: 280 | I33: 285 | J33: 239 | K33: 235 | L33: 217 | M33: 283 | N33: 290 | O33: 183 | P33: 191 | Q33: 259 | R33: 233 | S33: 286 | T33: 203 | U33: 282 | V33: 284 | W33: 271 | X33: 289 | Y33: 248 | Z33: 299 | AA33: 289 | AB33: =SUM(E33:AA33) -> 5992
A34: 2 | B34: Jumlah surat suara yang digunakan | E34: 223 | F34: 217 | G34: 229 | H34: 217 | I34: 228 | J34: 194 | K34: 195 | L34: 168 | M34: 211 | N34: 250 | O34: 154 | P34: 156 | Q34: 195 | R34: 189 | S34: 232 | T34: 152 | U34: 232 | V34: 226 | W34: 227 | X34: 237 | Y34: 199 | Z34: 221 | AA34: 228 | AB34: =SUM(E34:AA34) -> 4780
A35: 3 | B35: Jumlah surat suara dikembalikan oleh pemilih (karena rusak atau keliru coblos) | E35: 0 | F35: 1 | G35: 1 | H35: 3 | I35: 1 | J35: 1 | K35: 0 | L35: 2 | M35: 0 | N35: 2 | O35: 0 | P35: 1 | Q35: 0 | R35: 0 | S35: 0 | T35: 0 | U35: 0 | V35: 2 | W35: 0 | X35: 1 | Y35: 3 | Z35: 1 | AA35: 0 | AB35: =SUM(E35:AA35) -> 19
A36: 4 | B36: Jumlah surat suara yang tidak digunakan/tidak terpakai, termasuk sisa surat suara cadangan | E36: =E33-(E34+E35) -> 64 | F36: =F33-(F34+F35) -> 53 | G36: =G33-(G34+G35) -> 58 | H36: =H33-(H34+H35) -> 60 | I36: =I33-(I34+I35) -> 56 | J36: =J33-(J34+J35) -> 44 | K36: =K33-(K34+K35) -> 40 | L36: =L33-(L34+L35) -> 47 | ... AA36: =AA33-(AA34+AA35) -> 61 | AB36: =SUM(E36:AA36) -> 1193
A38: III | B38: DATA PEMILIH DISABILITAS
B39: Jumlah seluruh Pemilih disabilitas yang menggunakan hak pilih | D39: LK | I39: 1 | S39: 1 | AB39: =SUM(E39:AA39) -> 2
D40: PR | I40: 1 | L40: 1 | T40: 1 | AB40: =SUM(E40:AA40) -> 3
D41: JML | E41: =SUM(E39:E40) -> 0 | F41: =SUM(F39:F40) -> 0 | G41: =SUM(G39:G40) -> 0 | H41: =SUM(H39:H40) -> 0 | I41: =SUM(I39:I40) -> 2 | J41: =SUM(J39:J40) -> 0 | K41: =SUM(K39:K40) -> 0 | L41: =SUM(L39:L40) -> 1 | ... AA41: =SUM(AA39:AA40) -> 0 | AB41: =SUM(E41:AA41) -> 5
A43: IV | B43: DATA RINCIAN PEROLEHAN SUARA PASANGAN CALON BUPATI DAN WAKIL BUPATI
A44: NOMOR DAN NAMA CALON
A45: A.1 | B45: 1. | C45: Partai Kebangkitan Bangsa | E45: 5 | F45: 8 | G45: 2 | H45: 8 | I45: 1 | J45: 10 | K45: 3 | L45: 4 | M45: 8 | N45: 3 | O45: 4 | P45: 3 | Q45: 8 | R45: 1 | S45: 3 | T45: 3 | U45: 1 | V45: 4 | W45: 3 | X45: 8 | Y45: 5 | Z45: 2 | AA45: 3 | AB45: =SUM(E45:AA45) -> 100
A46: A.2 | B46: 1 | C46: 1. Dr. Hj. NIHAYATUL WAFIROH, M.A. | E46: 59 | F46: 80 | G46: 30 | H46: 44 | I46: 9 | J46: 36 | K46: 24 | L46: 26 | M46: 23 | N46: 19 | O46: 22 | P46: 30 | Q46: 12 | R46: 37 | S46: 24 | T46: 12 | U46: 10 | V46: 5 | W46: 9 | X46: 12 | Y46: 5 | Z46: 10 | AA46: 14 | AB46: =SUM(E46:AA46) -> 552
B47: 2 | C47: 2. H. M. NASIM KHAN | E47: 2 | F47: 0 | G47: 0 | H47: 2 | I47: 0 | J47: 0 | K47: 2 | L47: 3 | M47: 0 | N47: 1 | O47: 3 | P47: 1 | Q47: 0 | R47: 0 | S47: 3 | T47: 0 | U47: 0 | V47: 0 | W47: 1 | X47: 0 | Y47: 2 | Z47: 0 | AA47: 2 | AB47: =SUM(E47:AA47) -> 22
B48: 3 | C48: 3. Dr. H. AKIK ZAMAN, M.Pd.I. | E48: 4 | F48: 0 | G48: 0 | H48: 0 | I48: 2 | J48: 2 | K48: 0 | L48: 0 | M48: 0 | N48: 0 | O48: 0 | P48: 0 | Q48: 0 | R48: 1 | S48: 0 | T48: 0 | U48: 0 | V48: 0 | W48: 2 | X48: 0 | Y48: 0 | Z48: 0 | AA48: 1 | AB48: =SUM(E48:AA48) -> 12
B49: 4 | C49: 4. AHMAD RIFA'I, S.H. | E49: 2 | F49: 1 | G49: 0 | H49: 0 | I49: 1 | J49: 0 | K49: 0 | L49: 0 | M49: 0 | N49: 2 | O49: 1 | P49: 0 | Q49: 0 | R49: 0 | S49: 0 | T49: 0 | U49: 2 | V49: 0 | W49: 0 | X49: 0 | Y49: 0 | Z49: 1 | AA49: 0 | AB49: =SUM(E49:AA49) -> 10
B50: 5 | C50: 5. Drs. H. MAHFUD M.N. | E50: 0 | F50: 0 | G50: 0 | H50: 1 | I50: 0 | J50: 0 | K50: 1 | L50: 1 | M50: 2 | N50: 2 | O50: 0 | P50: 0 | Q50: 1 | R50: 1 | S50: 1 | T50: 0 | U50: 1 | V50: 1 | W50: 1 | X50: 1 | Y50: 1 | Z50: 0 | AA50: 0 | AB50: =SUM(E50:AA50) -> 15
B51: 6 | C51: 6. NURHAYATI, S.Pd. | E51: 1 | F51: 1 | G51: 1 | H51: 0 | I51: 0 | J51: 0 | K51: 0 | L51: 1 | M51: 1 | N51: 0 | O51: 0 | P51: 0 | Q51: 1 | R51: 0 | S51: 1 | T51: 0 | U51: 0 | V51: 0 | W51: 0 | X51: 0 | Y51: 0 | Z51: 0 | AA51: 0 | AB51: =SUM(E51:AA51) -> 7
...

Sheet SILIRAGUNG
C2: Kecamatan | D2: SILIRAGUNG
C3: Kabupaten | D3: BANYUWANGI
C4: Provinsi | D4: JAWA TIMUR
C9: Kelurahan | D9: SILIRAGUNG
A12: I | B12: DATA PEMILIH DAN PENGGUNAAN HAK PILIH | AB12: JUMLAH AKHIR
A13: A | B13: DATA PEMILIH | E13: TPS 001 | F13: TPS 002 | G13: TPS 003 | H13: TPS 004 | I13: TPS 005 | J13: TPS 006 | K13: TPS 007 | L13: TPS 008 | M13: TPS 009 | N13: TPS 010 | O13: TPS 011 | P13: TPS 012 | Q13: TPS 013 | R13: TPS 014 | S13: TPS 015 | T13: TPS 016 | U13: TPS 017 | V13: TPS 018 | W13: TPS 019 | X13: TPS 020 | Y13: TPS 021 | Z13: TPS 022 | AA13: TPS 023
B14: Jumlah Pemilih dalam Daftar Pemilih Tetap (DPT) | D14: LK | E14: 145 | F14: 131 | G14: 134 | H14: 122 | I14: 121 | J14: 109 | K14: 127 | L14: 130 | M14: 140 | N14: 125 | O14: 136 | P14: 142 | Q14: 134 | R14: 131 | S14: 124 | T14: 148 | U14: 136 | V14: 131 | W14: 138 | X14: 139 | Y14: 139 | Z14: 133 | AA14: 136 | AB14: =SUM(E14:AA14) -> 3051
D15: PR | E15: 125 | F15: 123 | G15: 135 | H15: 131 | I15: 133 | J15: 129 | K15: 126 | L15: 137 | M15: 131 | N15: 144 | O15: 134 | P15: 126 | Q15: 133 | R15: 140 | S15: 142 | T15: 125 | U15: 143 | V15: 124 | W15: 145 | X15: 141 | Y15: 137 | Z15: 126 | AA15: 132 | AB15: =SUM(E15:AA15) -> 3062
D16: JML | E16: =SUM(E14:E15) -> 270 | F16: =SUM(F14:F15) -> 254 | G16: =SUM(G14:G15) -> 269 | H16: =SUM(H14:H15) -> 253 | I16: =SUM(I14:I15) -> 254 | J16: =SUM(J14:J15) -> 238 | K16: =SUM(K14:K15) -> 253 | L16: =SUM(L14:L15) -> 267 | ... AA16: =SUM(AA14:AA15) -> 268 | AB16: =SUM(E16:AA16) -> 6113
A18: B | B18: PENGGUNA HAK PILIH
B19: 1. | C19: Jumlah pengguna hak pilih dalam Daftar Pemilih Tetap (DPT) | D19: LK | E19: 109 | F19: 97 | G19: 104 | H19: 86 | I19: 89 | J19: 83 | K19: 89 | L19: 100 | M19: 107 | N19: 93 | O19: 91 | P19: 94 | Q19: 97 | R19: 96 | S19: 88 | T19: 113 | U19: 109 | V19: 90 | W19: 109 | X19: 110 | Y19: 104 | Z19: 94 | AA19: 100 | AB19: =SUM(E19:AA19) -> 2252
D20: PR | E20: 98 | F20: 104 | G20: 107 | H20: 98 | I20: 105 | J20: 108 | K20: 100 | L20: 108 | M20: 104 | N20: 112 | O20: 101 | P20: 87 | Q20: 99 | R20: 109 | S20: 95 | T20: 98 | U20: 120 | V20: 94 | W20: 119 | X20: 122 | Y20: 111 | Z20: 95 | AA20: 99 | AB20: =SUM(E20:AA20) -> 2393
D21: JML | E21: =SUM(E19:E20) -> 207 | F21: =SUM(F19:F20) -> 201 | G21: =SUM(G19:G20) -> 211 | H21: =SUM(H19:H20) -> 184 | I21: =SUM(I19:I20) -> 194 | J21: =SUM(J19:J20) -> 191 | K21: =SUM(K19:K20) -> 189 | L21: =SUM(L19:L20) -> 208 | ... AA21: =SUM(AA19:AA20) -> 199 | AB21: =SUM(E21:AA21) -> 4645
B22: 2. | C22: Jumlah pengguna hak pilih dalam Daftar Pemilih Tambahan (DPTb) | D22: LK | E22: 0 | F22: 0 | G22: 0 | H22: 0 | I22: 0 | J22: 0 | K22: 0 | L22: 0 | M22: 0 | N22: 0 | O22: 0 | P22: 0 | Q22: 0 | R22: 0 | S22: 1 | AB22: =SUM(E22:AA22) -> 1
D23: PR | E23: 0 | F23: 0 | G23: 0 | H23: 0 | I23: 0 | J23: 0 | K23: 0 | L23: 0 | M23: 0 | N23: 0 | O23: 0 | P23: 0 | Q23: 0 | R23: 0 | S23: 0 | AB23: =SUM(E23:AA23) -> 0
D24: JML | E24: =SUM(E22:E23) -> 0 | F24: =SUM(F22:F23) -> 0 | G24: =SUM(G22:G23) -> 0 | H24: =SUM(H22:H23) -> 0 | I24: =SUM(I22:I23) -> 0 | J24: =SUM(J22:J23) -> 0 | K24: =SUM(K22:K23) -> 0 | L24: =SUM(L22:L23) -> 0 | ... AA24: =SUM(AA22:AA23) -> 0 | AB24: =SUM(E24:AA24) -> 1
B25: 3. | C25: Jumlah pengguna hak pilih dalam Daftar Pemilih Khusus (DPK) | D25: LK | E25: 2 | F25: 2 | G25: 4 | H25: 1 | I25: 1 | J25: 6 | K25: 5 | L25: 1 | M25: 0 | N25: 1 | O25: 0 | P25: 4 | Q25: 0 | R25: 3 | S25: 2 | T25: 2 | U25: 4 | V25: 2 | W25: 0 | X25: 0 | Y25: 1 | Z25: 5 | AA25: 1 | AB25: =SUM(E25:AA25) -> 47
D26: PR | E26: 3 | F26: 6 | G26: 6 | H26: 3 | I26: 4 | J26: 4 | K26: 4 | L26: 0 | M26: 5 | N26: 5 | O26: 1 | P26: 9 | Q26: 1 | R26: 2 | S26: 1 | T26: 5 | U26: 3 | V26: 2 | W26: 2 | X26: 2 | Y26: 2 | Z26: 3 | AA26: 2 | AB26: =SUM(E26:AA26) -> 75
D27: JML | E27: =SUM(E25:E26) -> 5 | F27: =SUM(F25:F26) -> 8 | G27: =SUM(G25:G26) -> 10 | H27: =SUM(H25:H26) -> 4 | I27: =SUM(I25:I26) -> 5 | J27: =SUM(J25:J26) -> 10 | K27: =SUM(K25:K26) -> 9 | L27: =SUM(L25:L26) -> 1 | ... AA27: =SUM(AA25:AA26) -> 3 | AB27: =SUM(E27:AA27) -> 122
B28: 4. | C28: Jumlah Pengguna Hak Pilih (B.1+B.2+B.3) | D28: LK | E28: =SUM(E19,E22,E25) -> 111 | F28: =SUM(F19,F22,F25) -> 99 | G28: =SUM(G19,G22,G25) -> 108 | H28: =SUM(H19,H22,H25) -> 87 | I28: =SUM(I19,I22,I25) -> 90 | J28: =SUM(J19,J22,J25) -> 89 | K28: =SUM(K19,K22,K25) -> 94 | L28: =SUM(L19,L22,L25) -> 101 | ... AA28: =SUM(AA19,AA22,AA25) -> 101 | AB28: =SUM(E28:AA28) -> 2300
D29: PR | E29: =SUM(E20,E23,E26) -> 101 | F29: =SUM(F20,F23,F26) -> 110 | G29: =SUM(G20,G23,G26) -> 113 | H29: =SUM(H20,H23,H26) -> 101 | I29: =SUM(I20,I23,I26) -> 109 | J29: =SUM(J20,J23,J26) -> 112 | K29: =SUM(K20,K23,K26) -> 104 | L29: =SUM(L20,L23,L26) -> 108 | ... AA29: =SUM(AA20,AA23,AA26) -> 101 | AB29: =SUM(E29:AA29) -> 2468
D30: JML | E30: =SUM(E28:E29) -> 212 | F30: =SUM(F28:F29) -> 209 | G30: =SUM(G28:G29) -> 221 | H30: =SUM(H28:H29) -> 188 | I30: =SUM(I28:I29) -> 199 | J30: =SUM(J28:J29) -> 201 | K30: =SUM(K28:K29) -> 198 | L30: =SUM(L28:L29) -> 209 | ... AA30: =SUM(AA28:AA29) -> 202 | AB30: =SUM(E30:AA30) -> 4768
A32: II | B32: DATA PENGGUNAAN SURAT SUARA
A33: 1 | B33: Jumlah surat suara yang diterima, termasuk surat suara cadangan 2,5% dari DPT | E33: 266 | F33: 260 | G33: 275 | H33: 259 | I33: 260 | J33: 243 | K33: 259 | L33: 273 | M33: 276 | N33: 275 | O33: 276 | P33: 274 | Q33: 273 | R33: 277 | S33: 272 | T33: 279 | U33: 285 | V33: 261 | W33: 291 | X33: 286 | Y33: 282 | Z33: 265 | AA33: 264 | AB33: =SUM(E33:AA33) -> 6231
A34: 2 | B34: Jumlah surat suara yang digunakan | E34: 212 | F34: 209 | G34: 221 | H34: 188 | I34: 199 | J34: 201 | K34: 198 | L34: 209 | M34: 216 | N34: 211 | O34: 193 | P34: 194 | Q34: 197 | R34: 210 | S34: 187 | T34: 218 | U34: 236 | V34: 188 | W34: 230 | X34: 234 | Y34: 218 | Z34: 197 | AA34: 202 | AB34: =SUM(E34:AA34) -> 4768
A35: 3 | B35: Jumlah surat suara dikembalikan oleh pemilih (karena rusak atau keliru coblos) | E35: 0 | F35: 0 | G35: 0 | H35: 0 | I35: 0 | J35: 0 | K35: 0 | L35: 0 | M35: 0 | N35: 1 | O35: 1 | P35: 3 | Q35: 0 | R35: 0 | S35: 1 | AB35: =SUM(E35:AA35) -> 6
A36: 4 | B36: Jumlah surat suara yang tidak digunakan/tidak terpakai, termasuk sisa surat suara cadangan | E36: =E33-(E34+E35) -> 54 | F36: =F33-(F34+F35) -> 51 | G36: =G33-(G34+G35) -> 54 | H36: =H33-(H34+H35) -> 71 | I36: =I33-(I34+I35) -> 61 | J36: =J33-(J34+J35) -> 42 | K36: =K33-(K34+K35) -> 61 | L36: =L33-(L34+L35) -> 64 | ... AA36: =AA33-(AA34+AA35) -> 62 | AB36: =SUM(E36:AA36) -> 1457
A38: III | B38: DATA PEMILIH DISABILITAS
B39: Jumlah seluruh Pemilih disabilitas yang menggunakan hak pilih | D39: LK | N39: 1 | AA39: 1 | AB39: =SUM(E39:AA39) -> 2
D40: PR | J40: 1 | N40: 1 | X40: 2 | AA40: 1 | AB40: =SUM(E40:AA40) -> 5
D41: JML | E41: =SUM(E39:E40) -> 0 | F41: =SUM(F39:F40) -> 0 | G41: =SUM(G39:G40) -> 0 | H41: =SUM(H39:H40) -> 0 | I41: =SUM(I39:I40) -> 0 | J41: =SUM(J39:J40) -> 1 | K41: =SUM(K39:K40) -> 0 | L41: =SUM(L39:L40) -> 0 | ... AA41: =SUM(AA39:AA40) -> 2 | AB41: =SUM(E41:AA41) -> 7
A43: IV | B43: DATA RINCIAN PEROLEHAN SUARA PASANGAN CALON BUPATI DAN WAKIL BUPATI
A44: NOMOR DAN NAMA CALON
A45: A.1 | B45: 1. | C45: Partai Kebangkitan Bangsa | E45: 12 | F45: 9 | G45: 7 | H45: 5 | I45: 7 | J45: 14 | K45: 3 | L45: 7 | M45: 4 | N45: 3 | O45: 6 | P45: 5 | Q45: 16 | R45: 10 | S45: 6 | T45: 11 | U45: 6 | V45: 3 | W45: 1 | X45: 1 | Y45: 8 | Z45: 5 | AA45: 9 | AB45: =SUM(E45:AA45) -> 158
A46: A.2 | B46: 1 | C46: 1. Dr. Hj. NIHAYATUL WAFIROH, M.A. | E46: 42 | F46: 22 | G46: 18 | H46: 14 | I46: 8 | J46: 12 | K46: 20 | L46: 11 | M46: 5 | N46: 12 | O46: 14 | P46: 19 | Q46: 44 | R46: 40 | S46: 23 | T46: 23 | U46: 33 | V46: 23 | W46: 12 | X46: 28 | Y46: 42 | Z46: 9 | AA46: 18 | AB46: =SUM(E46:AA46) -> 492
B47: 2 | C47: 2. H. M. NASIM KHAN | E47: 3 | F47: 2 | G47: 0 | H47: 0 | I47: 1 | J47: 1 | K47: 0 | L47: 6 | M47: 2 | N47: 2 | O47: 1 | P47: 2 | Q47: 2 | R47: 1 | S47: 0 | T47: 1 | U47: 2 | V47: 0 | W47: 0 | X47: 1 | Y47: 1 | Z47: 8 | AA47: 3 | AB47: =SUM(E47:AA47) -> 39
B48: 3 | C48: 3. Dr. H. AKIK ZAMAN, M.Pd.I. | E48: 0 | F48: 0 | G48: 1 | H48: 0 | I48: 1 | J48: 1 | K48: 0 | L48: 1 | M48: 0 | N48: 0 | O48: 1 | P48: 1 | Q48: 1 | R48: 0 | S48: 1 | T48: 0 | U48: 1 | V48: 1 | W48: 0 | X48: 0 | Y48: 1 | Z48: 2 | AA48: 0 | AB48: =SUM(E48:AA48) -> 13
B49: 4 | C49: 4. AHMAD RIFA'I, S.H. | E49: 0 | F49: 0 | G49: 0 | H49: 3 | I49: 3 | J49: 4 | K49: 1 | L49: 1 | M49: 0 | N49: 0 | O49: 1 | P49: 1 | Q49: 0 | R49: 2 | S49: 1 | T49: 0 | U49: 4 | V49: 0 | W49: 0 | X49: 2 | Y49: 2 | Z49: 0 | AA49: 0 | AB49: =SUM(E49:AA49) -> 25
B50: 5 | C50: 5. Drs. H. MAHFUD M.N. | E50: 4 | F50: 1 | G50: 1 | H50: 0 | I50: 1 | J50: 1 | K50: 1 | L50: 0 | M50: 1 | N50: 2 | O50: 0 | P50: 1 | Q50: 0 | R50: 2 | S50: 1 | T50: 1 | U50: 0 | V50: 1 | W50: 1 | X50: 4 | Y50: 3 | Z50: 2 | AA50: 3 | AB50: =SUM(E50:AA50) -> 31
B51: 6 | C51: 6. NURHAYATI, S.Pd. | E51: 1 | F51: 0 | G51: 0 | H51: 2 | I51: 0 | J51: 1 | K51: 0 | L51: 0 | M51: 0 | N51: 1 | O51: 2 | P51: 2 | Q51: 0 | R51: 1 | S51: 0 | T51: 0 | U51: 0 | V51: 3 | W51: 2 | X51: 1 | Y51: 0 | Z51: 1 | AA51: 1 | AB51: =SUM(E51:AA51) -> 18
...
