Workbook

Sheet DPR
C8: Kecamatan | D8: SEMPU
C9: Kabupaten | D9: BANYUWANGI
C10: Provinsi | D10: JAWA TIMUR
A12: I | B12: DATA PEMILIH DAN PENGGUNAAN HAK PILIH | E12: JUMLAH AKHIR
A13: A | B13: DATA PEMILIH
B14: Jumlah Pemilih dalam Daftar Pemilih Tetap (DPT) | D14: LK | E14: =GENDOH!AG14+JAMBEWANGI!BR14+KARANGSARI!AX14+SEMPU!Y14+TEGALARUM!AA14+TEMUASRI!AJ14+TEMUGURUH!AL14 -> 32583
D15: PR | E15: =GENDOH!AG15+JAMBEWANGI!BR15+KARANGSARI!AX15+SEMPU!Y15+TEGALARUM!AA15+TEMUASRI!AJ15+TEMUGURUH!AL15 -> 32633
D16: JML | E16: =SUM(E14:E15) -> 65216
A18: B | B18: PENGGUNA HAK PILIH
B19: 1. | C19: Jumlah pengguna hak pilih dalam Daftar Pemilih Tetap (DPT) | D19: LK | E19: =GENDOH!AG19+JAMBEWANGI!BR19+KARANGSARI!AX19+SEMPU!Y19+TEGALARUM!AA19+TEMUASRI!AJ19+TEMUGURUH!AL19 -> 23335
D20: PR | E20: =GENDOH!AG20+JAMBEWANGI!BR20+KARANGSARI!AX20+SEMPU!Y20+TEGALARUM!AA20+TEMUASRI!AJ20+TEMUGURUH!AL20 -> 25100
D21: JML | E21: =SUM(E19:E20) -> 48435
B22: 2. | C22: Jumlah pengguna hak pilih dalam Daftar Pemilih Tambahan (DPTb) | D22: LK | E22: =GENDOH!AG22+JAMBEWANGI!BR22+KARANGSARI!AX22+SEMPU!Y22+TEGALARUM!AA22+TEMUASRI!AJ22+TEMUGURUH!AL22 -> 64
D23: PR | E23: =GENDOH!AG23+JAMBEWANGI!BR23+KARANGSARI!AX23+SEMPU!Y23+TEGALARUM!AA23+TEMUASRI!AJ23+TEMUGURUH!AL23 -> 66
D24: JML | E24: =SUM(E22:E23) -> 130
B25: 3. | C25: Jumlah pengguna hak pilih dalam Daftar Pemilih Khusus (DPK) | D25: LK | E25: =GENDOH!AG25+JAMBEWANGI!BR25+KARANGSARI!AX25+SEMPU!Y25+TEGALARUM!AA25+TEMUASRI!AJ25+TEMUGURUH!AL25 -> 208
D26: PR | E26: =GENDOH!AG26+JAMBEWANGI!BR26+KARANGSARI!AX26+SEMPU!Y26+TEGALARUM!AA26+TEMUASRI!AJ26+TEMUGURUH!AL26 -> 282
D27: JML | E27: =SUM(E25:E26) -> 490
B28: 4. | C28: Jumlah Pengguna Hak Pilih (B.1+B.2+B.3) | D28: LK | E28: =E19+E22+E25 -> 23607
D29: PR | E29: =E20+E23+E26 -> 25448
D30: JML | E30: =SUM(E28:E29) -> 49055
A32: II | B32: DATA PENGGUNAAN SURAT SUARA
A33: 1 | B33: Jumlah surat suara yang diterima, termasuk surat suara cadangan 2,5% dari DPT | E33: =GENDOH!AG33+JAMBEWANGI!BR33+KARANGSARI!AX33+SEMPU!Y33+TEGALARUM!AA33+TEMUASRI!AJ33+TEMUGURUH!AL33 -> 66778
A34: 2 | B34: Jumlah surat suara yang digunakan | E34: =GENDOH!AG34+JAMBEWANGI!BR34+KARANGSARI!AX34+SEMPU!Y34+TEGALARUM!AA34+TEMUASRI!AJ34+TEMUGURUH!AL34 -> 49055
A35: 3 | B35: Jumlah surat suara dikembalikan oleh pemilih (karena rusak atau keliru coblos) | E35: =GENDOH!AG35+JAMBEWANGI!BR35+KARANGSARI!AX35+SEMPU!Y35+TEGALARUM!AA35+TEMUASRI!AJ35+TEMUGURUH!AL35 -> 111
A36: 4 | B36: Jumlah surat suara yang tidak digunakan/tidak terpakai, termasuk sisa surat suara cadangan | E36: =E33-(E34+E35) -> 17612
A38: III | B38: DATA PEMILIH DISABILITAS
B39: Jumlah seluruh Pemilih disabilitas yang menggunakan hak pilih | D39: LK | E39: =GENDOH!AG39+JAMBEWANGI!BR39+KARANGSARI!AX39+SEMPU!Y39+TEGALARUM!AA39+TEMUASRI!AJ39+TEMUGURUH!AL39 -> 50
D40: PR | E40: =GENDOH!AG40+JAMBEWANGI!BR40+KARANGSARI!AX40+SEMPU!Y40+TEGALARUM!AA40+TEMUASRI!AJ40+TEMUGURUH!AL40 -> 82
D41: JML | E41: =SUM(E39:E40) -> 132
A43: IV | B43: DATA RINCIAN PEROLEHAN SUARA PASANGAN CALON BUPATI DAN WAKIL BUPATI
A44: NOMOR DAN NAMA CALON
A45: A.1 | B45: 1. | C45: Partai Kebangkitan Bangsa | E45: =GENDOH!AG45+JAMBEWANGI!BR45+KARANGSARI!AX45+SEMPU!Y45+TEGALARUM!AA45+TEMUASRI!AJ45+TEMUGURUH!AL45 -> 1700
A46: A.2 | B46: 1 | C46: 1. Dr. Hj. NIHAYATUL WAFIROH, M.A. | E46: =GENDOH!AG46+JAMBEWANGI!BR46+KARANGSARI!AX46+SEMPU!Y46+TEGALARUM!AA46+TEMUASRI!AJ46+TEMUGURUH!AL46 -> 4018
B47: 2 | C47: 2. H. M. NASIM KHAN | E47: =GENDOH!AG47+JAMBEWANGI!BR47+KARANGSARI!AX47+SEMPU!Y47+TEGALARUM!AA47+TEMUASRI!AJ47+TEMUGURUH!AL47 -> 540
B48: 3 | C48: 3. Dr. H. AKIK ZAMAN, M.Pd.I. | E48: =GENDOH!AG48+JAMBEWANGI!BR48+KARANGSARI!AX48+SEMPU!Y48+TEGALARUM!AA48+TEMUASRI!AJ48+TEMUGURUH!AL48 -> 133
B49: 4 | C49: 4. AHMAD RIFA'I, S.H. | E49: =GENDOH!AG49+JAMBEWANGI!BR49+KARANGSARI!AX49+SEMPU!Y49+TEGALARUM!AA49+TEMUASRI!AJ49+TEMUGURUH!AL49 -> 170
B50: 5 | C50: 5. Drs. H. MAHFUD M.N. | E50: =GENDOH!AG50+JAMBEWANGI!BR50+KARANGSARI!AX50+SEMPU!Y50+TEGALARUM!AA50+TEMUASRI!AJ50+TEMUGURUH!AL50 -> 115
B51: 6 | C51: 6. NURHAYATI, S.Pd. | E51: =GENDOH!AG51+JAMBEWANGI!BR51+KARANGSARI!AX51+SEMPU!Y51+TEGALARUM!AA51+TEMUASRI!AJ51+TEMUGURUH!AL51 -> 136
B52: 7 | C52: 7. MAFTUHA KISWAH | E52: =GENDOH!AG52+JAMBEWANGI!BR52+KARANGSARI!AX52+SEMPU!Y52+TEGALARUM!AA52+TEMUASRI!AJ52+TEMUGURUH!AL52 -> 28
...

Sheet SEMPU
C2: Kecamatan | D2: SEMPU
C3: Kabupaten | D3: BANYUWANGI
C4: Provinsi | D4: JAWA TIMUR
C9: Kelurahan | D9: SEMPU
A12: I | B12: DATA PEMILIH DAN PENGGUNAAN HAK PILIH | Y12: JUMLAH AKHIR
A13: A | B13: DATA PEMILIH | E13: TPS 001 | F13: TPS 002 | G13: TPS 003 | H13: TPS 004 | I13: TPS 005 | J13: TPS 006 | K13: TPS 007 | L13: TPS 008 | M13: TPS 009 | N13: TPS 010 | O13: TPS 011 | P13: TPS 012 | Q13: TPS 013 | R13: TPS 014 | S13: TPS 015 | T13: TPS 016 | U13: TPS 017 | V13: TPS 018 | W13: TPS 019 | X13: TPS 020
B14: Jumlah Pemilih dalam Daftar Pemilih Tetap (DPT) | D14: LK | E14: 131 | F14: 133 | G14: 87 | H14: 116 | I14: 126 | J14: 145 | K14: 80 | L14: 103 | M14: 142 | N14: 129 | O14: 151 | P14: 129 | Q14: 136 | R14: 109 | S14: 132 | T14: 141 | U14: 134 | V14: 99 | W14: 108 | X14: 79 | Y14: =SUM(E14:X14) -> 2410
D15: PR | E15: 140 | F15: 146 | G15: 106 | H15: 107 | I15: 133 | J15: 145 | K15: 104 | L15: 99 | M15: 135 | N15: 146 | O15: 135 | P15: 148 | Q15: 149 | R15: 120 | S15: 143 | T15: 142 | U15: 129 | V15: 112 | W15: 133 | X15: 71 | Y15: =SUM(E15:X15) -> 2543
D16: JML | E16: =SUM(E14:E15) -> 271 | F16: =SUM(F14:F15) -> 279 | G16: =SUM(G14:G15) -> 193 | H16: =SUM(H14:H15) -> 223 | I16: =SUM(I14:I15) -> 259 | J16: =SUM(J14:J15) -> 290 | K16: =SUM(K14:K15) -> 184 | L16: =SUM(L14:L15) -> 202 | ... X16: =SUM(X14:X15) -> 150 | Y16: =SUM(E16:X16) -> 4953
A18: B | B18: PENGGUNA HAK PILIH
B19: 1. | C19: Jumlah pengguna hak pilih dalam Daftar Pemilih Tetap (DPT) | D19: LK | E19: 108 | F19: 92 | G19: 68 | H19: 84 | I19: 96 | J19: 100 | K19: 55 | L19: 86 | M19: 112 | N19: 96 | O19: 113 | P19: 97 | Q19: 99 | R19: 85 | S19: 95 | T19: 99 | U19: 103 | V19: 76 | W19: 77 | X19: 62 | Y19: =SUM(E19:X19) -> 1803
D20: PR | E20: 106 | F20: 114 | G20: 86 | H20: 86 | I20: 101 | J20: 114 | K20: 77 | L20: 82 | M20: 112 | N20: 112 | O20: 109 | P20: 127 | Q20: 116 | R20: 91 | S20: 117 | T20: 108 | U20: 109 | V20: 92 | W20: 107 | X20: 62 | Y20: =SUM(E20:X20) -> 2028
D21: JML | E21: =SUM(E19:E20) -> 214 | F21: =SUM(F19:F20) -> 206 | G21: =SUM(G19:G20) -> 154 | H21: =SUM(H19:H20) -> 170 | I21: =SUM(I19:I20) -> 197 | J21: =SUM(J19:J20) -> 214 | K21: =SUM(K19:K20) -> 132 | L21: =SUM(L19:L20) -> 168 | ... X21: =SUM(X19:X20) -> 124 | Y21: =SUM(E21:X21) -> 3831
B22: 2. | C22: Jumlah pengguna hak pilih dalam Daftar Pemilih Tambahan (DPTb) | D22: LK | E22: 0 | F22: 0 | G22: 0 | H22: 0 | I22: 0 | J22: 0 | K22: 1 | L22: 0 | M22: 0 | N22: 0 | O22: 0 | P22: 0 | Q22: 0 | R22: 2 | S22: 0 | T22: 0 | U22: 0 | V22: 0 | W22: 0 | X22: 0 | Y22: =SUM(E22:X22) -> 3
D23: PR | E23: 0 | F23: 0 | G23: 0 | H23: 0 | I23: 0 | J23: 0 | K23: 4 | L23: 0 | M23: 0 | N23: 0 | O23: 0 | P23: 0 | Q23: 0 | R23: 1 | S23: 0 | T23: 0 | U23: 0 | V23: 0 | W23: 0 | X23: 0 | Y23: =SUM(E23:X23) -> 5
D24: JML | E24: =SUM(E22:E23) -> 0 | F24: =SUM(F22:F23) -> 0 | G24: =SUM(G22:G23) -> 0 | H24: =SUM(H22:H23) -> 0 | I24: =SUM(I22:I23) -> 0 | J24: =SUM(J22:J23) -> 0 | K24: =SUM(K22:K23) -> 5 | L24: =SUM(L22:L23) -> 0 | ... X24: =SUM(X22:X23) -> 0 | Y24: =SUM(E24:X24) -> 8
B25: 3. | C25: Jumlah pengguna hak pilih dalam Daftar Pemilih Khusus (DPK) | D25: LK | E25: 2 | F25: 1 | G25: 0 | H25: 3 | I25: 1 | J25: 1 | K25: 1 | L25: 1 | M25: 2 | N25: 0 | O25: 0 | P25: 1 | Q25: 1 | R25: 3 | S25: 2 | T25: 0 | U25: 10 | V25: 1 | W25: 0 | X25: 1 | Y25: =SUM(E25:X25) -> 31
D26: PR | E26: 1 | F26: 5 | G26: 0 | H26: 4 | I26: 1 | J26: 3 | K26: 0 | L26: 1 | M26: 4 | N26: 0 | O26: 0 | P26: 1 | Q26: 1 | R26: 1 | S26: 4 | T26: 1 | U26: 6 | V26: 5 | W26: 1 | X26: 1 | Y26: =SUM(E26:X26) -> 40
D27: JML | E27: =SUM(E25:E26) -> 3 | F27: =SUM(F25:F26) -> 6 | G27: =SUM(G25:G26) -> 0 | H27: =SUM(H25:H26) -> 7 | I27: =SUM(I25:I26) -> 2 | J27: =SUM(J25:J26) -> 4 | K27: =SUM(K25:K26) -> 1 | L27: =SUM(L25:L26) -> 2 | ... N27: =SUM(N25:N26) -> 0 | O27: 0 | P27: =SUM(P25:P26) -> 2 | Q27: =SUM(Q25:Q26) -> 2 | R27: =SUM(R25:R26) -> 4 | S27: =SUM(S25:S26) -> 6 | T27: =SUM(T25:T26) -> 1 | U27: =SUM(U25:U26) -> 16 | V27: =SUM(V25:V26) -> 6 | W27: =SUM(W25:W26) -> 1 | X27: =SUM(X25:X26) -> 2 | Y27: =SUM(E27:X27) -> 71
B28: 4. | C28: Jumlah Pengguna Hak Pilih (B.1+B.2+B.3) | D28: LK | E28: =SUM(E19,E22,E25) -> 110 | F28: =SUM(F19,F22,F25) -> 93 | G28: =SUM(G19,G22,G25) -> 68 | H28: =SUM(H19,H22,H25) -> 87 | I28: =SUM(I19,I22,I25) -> 97 | J28: =SUM(J19,J22,J25) -> 101 | K28: =SUM(K19,K22,K25) -> 57 | L28: =SUM(L19,L22,L25) -> 87 | ... X28: =SUM(X19,X22,X25) -> 63 | Y28: =SUM(E28:X28) -> 1837
D29: PR | E29: =SUM(E20,E23,E26) -> 107 | F29: =SUM(F20,F23,F26) -> 119 | G29: =SUM(G20,G23,G26) -> 86 | H29: =SUM(H20,H23,H26) -> 90 | I29: =SUM(I20,I23,I26) -> 102 | J29: =SUM(J20,J23,J26) -> 117 | K29: =SUM(K20,K23,K26) -> 81 | L29: =SUM(L20,L23,L26) -> 83 | ... X29: =SUM(X20,X23,X26) -> 63 | Y29: =SUM(E29:X29) -> 2073
D30: JML | E30: =SUM(E28:E29) -> 217 | F30: =SUM(F28:F29) -> 212 | G30: =SUM(G28:G29) -> 154 | H30: =SUM(H28:H29) -> 177 | I30: =SUM(I28:I29) -> 199 | J30: =SUM(J28:J29) -> 218 | K30: =SUM(K28:K29) -> 138 | L30: =SUM(L28:L29) -> 170 | ... X30: =SUM(X28:X29) -> 126 | Y30: =SUM(E30:X30) -> 3910
A32: II | B32: DATA PENGGUNAAN SURAT SUARA
A33: 1 | B33: Jumlah surat suara yang diterima, termasuk surat suara cadangan 2,5% dari DPT | E33: 260 | F33: 287 | G33: 197 | H33: 228 | I33: 265 | J33: 296 | K33: 187 | L33: 207 | M33: 283 | N33: 281 | O33: 292 | P33: 281 | Q33: 291 | R33: 233 | S33: 281 | T33: 289 | U33: 269 | V33: 236 | W33: 246 | X33: 153 | Y33: =SUM(E33:X33) -> 5062
A34: 2 | B34: Jumlah surat suara yang digunakan | E34: 217 | F34: 212 | G34: 154 | H34: 177 | I34: 199 | J34: 218 | K34: 138 | L34: 170 | M34: 230 | N34: 208 | O34: 222 | P34: 226 | Q34: 217 | R34: 183 | S34: 218 | T34: 208 | U34: 228 | V34: 174 | W34: 185 | X34: 126 | Y34: =SUM(E34:X34) -> 3910
A35: 3 | B35: Jumlah surat suara dikembalikan oleh pemilih (karena rusak atau keliru coblos) | E35: 0 | F35: 0 | G35: 0 | H35: 0 | I35: 0 | J35: 0 | K35: 0 | L35: 0 | M35: 0 | N35: 0 | O35: 0 | P35: 0 | Q35: 0 | R35: 0 | S35: 0 | T35: 1 | U35: 0 | V35: 0 | W35: 0 | X35: 0 | Y35: =SUM(E35:X35) -> 1
A36: 4 | B36: Jumlah surat suara yang tidak digunakan/tidak terpakai, termasuk sisa surat suara cadangan | E36: =E33-(E34+E35) -> 43 | F36: =F33-(F34+F35) -> 75 | G36: =G33-(G34+G35) -> 43 | H36: =H33-(H34+H35) -> 51 | I36: =I33-(I34+I35) -> 66 | J36: =J33-(J34+J35) -> 78 | K36: =K33-(K34+K35) -> 49 | L36: =L33-(L34+L35) -> 37 | ... X36: =X33-(X34+X35) -> 27 | Y36: =SUM(E36:X36) -> 1151
A38: III | B38: DATA PEMILIH DISABILITAS
B39: Jumlah seluruh Pemilih disabilitas yang menggunakan hak pilih | D39: LK | E39: 0 | F39: 1 | G39: 0 | H39: 1 | I39: 0 | J39: 0 | K39: 0 | L39: 0 | M39: 0 | N39: 0 | O39: 0 | P39: 1 | Q39: 0 | R39: 0 | S39: 0 | T39: 0 | U39: 0 | V39: 0 | W39: 0 | X39: 2 | Y39: =SUM(E39:X39) -> 5
D40: PR | E40: 0 | F40: 0 | G40: 0 | H40: 1 | I40: 0 | J40: 0 | K40: 0 | L40: 2 | M40: 0 | N40: 0 | O40: 0 | P40: 0 | Q40: 0 | R40: 0 | S40: 0 | T40: 0 | U40: 0 | V40: 0 | W40: 2 | X40: 0 | Y40: =SUM(E40:X40) -> 5
D41: JML | E41: =SUM(E39:E40) -> 0 | F41: =SUM(F39:F40) -> 1 | G41: =SUM(G39:G40) -> 0 | H41: =SUM(H39:H40) -> 2 | I41: =SUM(I39:I40) -> 0 | J41: =SUM(J39:J40) -> 0 | K41: =SUM(K39:K40) -> 0 | L41: =SUM(L39:L40) -> 2 | ... X41: =SUM(X39:X40) -> 2 | Y41: =SUM(E41:X41) -> 10
A43: IV | B43: DATA RINCIAN PEROLEHAN SUARA PASANGAN CALON BUPATI DAN WAKIL BUPATI
A44: NOMOR DAN NAMA CALON
A45: A.1 | B45: 1. | C45: Partai Kebangkitan Bangsa | E45: 2 | F45: 5 | G45: 2 | H45: 5 | I45: 9 | J45: 9 | K45: 3 | L45: 3 | M45: 5 | N45: 6 | O45: 2 | P45: 9 | Q45: 0 | R45: 4 | S45: 3 | T45: 6 | U45: 8 | V45: 6 | W45: 3 | X45: 6 | Y45: =SUM(E45:X45) -> 96
A46: A.2 | B46: 1 | C46: 1. Dr. Hj. NIHAYATUL WAFIROH, M.A. | E46: 15 | F46: 10 | G46: 5 | H46: 9 | I46: 17 | J46: 7 | K46: 3 | L46: 3 | M46: 20 | N46: 8 | O46: 3 | P46: 57 | Q46: 9 | R46: 15 | S46: 16 | T46: 15 | U46: 21 | V46: 7 | W46: 18 | X46: 5 | Y46: =SUM(E46:X46) -> 263
B47: 2 | C47: 2. H. M. NASIM KHAN | E47: 2 | F47: 3 | G47: 0 | H47: 0 | I47: 0 | J47: 0 | K47: 0 | L47: 1 | M47: 0 | N47: 2 | O47: 0 | P47: 1 | Q47: 23 | R47: 0 | S47: 2 | T47: 3 | U47: 2 | V47: 2 | W47: 2 | X47: 2 | Y47: =SUM(E47:X47) -> 45
B48: 3 | C48: 3. Dr. H. AKIK ZAMAN, M.Pd.I. | E48: 1 | F48: 0 | G48: 0 | H48: 0 | I48: 0 | J48: 0 | K48: 0 | L48: 0 | M48: 1 | N48: 0 | O48: 0 | P48: 1 | Q48: 3 | R48: 0 | S48: 0 | T48: 1 | U48: 2 | V48: 1 | W48: 0 | X48: 1 | Y48: =SUM(E48:X48) -> 11
B49: 4 | C49: 4. AHMAD RIFA'I, S.H. | E49: 1 | F49: 2 | G49: 1 | H49: 0 | I49: 0 | J49: 0 | K49: 0 | L49: 1 | M49: 0 | N49: 1 | O49: 0 | P49: 4 | Q49: 0 | R49: 1 | S49: 1 | T49: 1 | U49: 1 | V49: 1 | W49: 1 | X49: 0 | Y49: =SUM(E49:X49) -> 16
B50: 5 | C50: 5. Drs. H. MAHFUD M.N. | E50: 0 | F50: 0 | G50: 0 | H50: 0 | I50: 0 | J50: 0 | K50: 0 | L50: 1 | M50: 1 | N50: 0 | O50: 0 | P50: 2 | Q50: 0 | R50: 0 | S50: 0 | T50: 1 | U50: 2 | V50: 0 | W50: 1 | X50: 1 | Y50: =SUM(E50:X50) -> 9
B51: 6 | C51: 6. NURHAYATI, S.Pd. | E51: 0 | F51: 0 | G51: 0 | H51: 0 | I51: 0 | J51: 0 | K51: 0 | L51: 0 | M51: 0 | N51: 0 | O51: 0 | P51: 1 | Q51: 0 | R51: 1 | S51: 1 | T51: 0 | U51: 0 | V51: 0 | W51: 1 | X51: 0 | Y51: =SUM(E51:X51) -> 4
...

Sheet JAMBEWANGI
C2: Kecamatan | D2: SEMPU
C3: Kabupaten | D3: BANYUWANGI
C4: Provinsi | D4: JAWA TIMUR
C9: Kelurahan | D9: JAMBEWANGI
A12: I | B12: DATA PEMILIH DAN PENGGUNAAN HAK PILIH | BR12: JUMLAH AKHIR
A13: A | B13: DATA PEMILIH | E13: TPS 001 | F13: TPS 002 | G13: TPS 003 | H13: TPS 004 | I13: TPS 005 | J13: TPS 006 | K13: TPS 007 | L13: TPS 008 | M13: TPS 009 | N13: TPS 010 | O13: TPS 011 | P13: TPS 012 | Q13: TPS 013 | R13: TPS 014 | S13: TPS 015 | T13: TPS 016 | U13: TPS 017 | V13: TPS 018 | W13: TPS 019 | X13: TPS 020 | Y13: TPS 021 | Z13: TPS 022 | AA13: TPS 023 | AB13: TPS 024 | AC13: TPS 025 | AD13: TPS 026 | AE13: TPS 027 | AF13: TPS 028 | AG13: TPS 029 | AH13: TPS 030 | AI13: TPS 031 | AJ13: TPS 032 | AK13: TPS 033 | AL13: TPS 034 | AM13: TPS 035 | AN13: TPS 036 | AO13: TPS 037 | AP13: TPS 038 | AQ13: TPS 039 | AR13: TPS 040 | AS13: TPS 041 | AT13: TPS 042 | AU13: TPS 043 | AV13: TPS 044 | AW13: TPS 045 | AX13: TPS 046 | AY13: TPS 047 | AZ13: TPS 048 | BA13: TPS 049 | BB13: TPS 050 | BC13: TPS 051 | BD13: TPS 052 | BE13: TPS 053 | BF13: TPS 054 | BG13: TPS 055 | BH13: TPS 056 | BI13: TPS 057 | BJ13: TPS 058 | BK13: TPS 059 | BL13: TPS 060 | BM13: TPS 061 | BN13: TPS 062 | BO13: TPS 063 | BP13: TPS 064 | BQ13: TPS 065
B14: Jumlah Pemilih dalam Daftar Pemilih Tetap (DPT) | D14: LK | E14: 122 | F14: 121 | G14: 102 | H14: 136 | I14: 143 | J14: 138 | K14: 140 | L14: 114 | M14: 153 | N14: 150 | O14: 146 | P14: 146 | Q14: 136 | R14: 131 | S14: 140 | T14: 142 | U14: 139 | V14: 147 | W14: 140 | X14: 143 | Y14: 143 | Z14: 162 | AA14: 144 | AB14: 145 | AC14: 155 | AD14: 149 | AE14: 157 | AF14: 146 | AG14: 138 | AH14: 145 | AI14: 145 | AJ14: 144 | AK14: 143 | AL14: 133 | AM14: 122 | AN14: 160 | AO14: 153 | AP14: 139 | AQ14: 136 | AR14: 105 | AS14: 115 | AT14: 112 | AU14: 147 | AV14: 126 | AW14: 120 | AX14: 142 | AY14: 144 | AZ14: 140 | BA14: 137 | BB14: 94 | BC14: 108 | BD14: 146 | BE14: 110 | BF14: 132 | BG14: 146 | BH14: 122 | BI14: 126 | BJ14: 140 | BK14: 124 | BL14: 153 | BM14: 132 | BN14: 149 | BO14: 142 | BP14: 146 | BQ14: 133 | BR14: =SUM(E14:BQ14) -> 8879
D15: PR | E15: 118 | F15: 102 | G15: 97 | H15: 144 | I15: 136 | J15: 129 | K15: 142 | L15: 135 | M15: 137 | N15: 144 | O15: 147 | P15: 147 | Q15: 154 | R15: 143 | S15: 141 | T15: 151 | U15: 141 | V15: 132 | W15: 137 | X15: 128 | Y15: 146 | Z15: 136 | AA15: 145 | AB15: 143 | AC15: 136 | AD15: 147 | AE15: 139 | AF15: 149 | AG15: 138 | AH15: 143 | AI15: 139 | AJ15: 147 | AK15: 143 | AL15: 107 | AM15: 121 | AN15: 136 | AO15: 141 | AP15: 143 | AQ15: 142 | AR15: 122 | AS15: 133 | AT15: 103 | AU15: 126 | AV15: 120 | AW15: 132 | AX15: 149 | AY15: 143 | AZ15: 129 | BA15: 145 | BB15: 96 | BC15: 96 | BD15: 143 | BE15: 119 | BF15: 150 | BG15: 131 | BH15: 123 | BI15: 115 | BJ15: 137 | BK15: 132 | BL15: 144 | BM15: 125 | BN15: 141 | BO15: 143 | BP15: 139 | BQ15: 133 | BR15: =SUM(E15:BQ15) -> 8715
D16: JML | E16: =SUM(E14:E15) -> 240 | F16: =SUM(F14:F15) -> 223 | G16: =SUM(G14:G15) -> 199 | H16: =SUM(H14:H15) -> 280 | I16: =SUM(I14:I15) -> 279 | J16: =SUM(J14:J15) -> 267 | K16: =SUM(K14:K15) -> 282 | L16: =SUM(L14:L15) -> 249 | ... BQ16: =SUM(BQ14:BQ15) -> 266 | BR16: =SUM(E16:BQ16) -> 17594
A18: B | B18: PENGGUNA HAK PILIH
B19: 1. | C19: Jumlah pengguna hak pilih dalam Daftar Pemilih Tetap (DPT) | D19: LK | E19: 78 | F19: 85 | G19: 77 | H19: 90 | I19: 103 | J19: 117 | K19: 100 | L19: 82 | M19: 95 | N19: 106 | O19: 94 | P19: 103 | Q19: 88 | R19: 81 | S19: 97 | T19: 86 | U19: 100 | V19: 94 | W19: 84 | X19: 94 | Y19: 109 | Z19: 113 | AA19: 98 | AB19: 104 | AC19: 120 | AD19: 109 | AE19: 113 | AF19: 99 | AG19: 93 | AH19: 95 | AI19: 98 | AJ19: 111 | AK19: 107 | AL19: 104 | AM19: 95 | AN19: 120 | AO19: 118 | AP19: 98 | AQ19: 101 | AR19: 87 | AS19: 87 | AT19: 84 | AU19: 122 | AV19: 80 | AW19: 86 | AX19: 101 | AY19: 94 | AZ19: 98 | BA19: 105 | BB19: 62 | BC19: 81 | BD19: 104 | BE19: 82 | BF19: 101 | BG19: 122 | BH19: 95 | BI19: 101 | BJ19: 112 | BK19: 101 | BL19: 113 | BM19: 96 | BN19: 107 | BO19: 105 | BP19: 115 | BQ19: 109 | BR19: =SUM(E19:BQ19) -> 6409
D20: PR | E20: 93 | F20: 72 | G20: 76 | H20: 107 | I20: 104 | J20: 112 | K20: 112 | L20: 109 | M20: 110 | N20: 122 | O20: 108 | P20: 115 | Q20: 120 | R20: 118 | S20: 108 | T20: 104 | U20: 108 | V20: 96 | W20: 103 | X20: 92 | Y20: 111 | Z20: 107 | AA20: 110 | AB20: 100 | AC20: 115 | AD20: 115 | AE20: 102 | AF20: 122 | AG20: 98 | AH20: 105 | AI20: 102 | AJ20: 116 | AK20: 111 | AL20: 93 | AM20: 98 | AN20: 101 | AO20: 118 | AP20: 121 | AQ20: 110 | AR20: 105 | AS20: 110 | AT20: 83 | AU20: 111 | AV20: 98 | AW20: 102 | AX20: 115 | AY20: 106 | AZ20: 99 | BA20: 109 | BB20: 66 | BC20: 86 | BD20: 119 | BE20: 101 | BF20: 122 | BG20: 108 | BH20: 103 | BI20: 98 | BJ20: 108 | BK20: 103 | BL20: 110 | BM20: 89 | BN20: 121 | BO20: 107 | BP20: 113 | BQ20: 115 | BR20: =SUM(E20:BQ20) -> 6851
D21: JML | E21: =SUM(E19:E20) -> 171 | F21: =SUM(F19:F20) -> 157 | G21: =SUM(G19:G20) -> 153 | H21: =SUM(H19:H20) -> 197 | I21: =SUM(I19:I20) -> 207 | J21: =SUM(J19:J20) -> 229 | K21: =SUM(K19:K20) -> 212 | L21: =SUM(L19:L20) -> 191 | ... BQ21: =SUM(BQ19:BQ20) -> 224 | BR21: =SUM(E21:BQ21) -> 13260
B22: 2. | C22: Jumlah pengguna hak pilih dalam Daftar Pemilih Tambahan (DPTb) | D22: LK | E22: 0 | F22: 0 | G22: 0 | H22: 0 | I22: 0 | J22: 0 | K22: 0 | L22: 0 | M22: 1 | N22: 1 | O22: 1 | P22: 1 | Q22: 0 | R22: 0 | S22: 0 | T22: 2 | U22: 0 | V22: 0 | W22: 0 | X22: 0 | Y22: 0 | Z22: 0 | AA22: 0 | AB22: 1 | AC22: 0 | AD22: 0 | AE22: 0 | AF22: 0 | AG22: 0 | AH22: 0 | AI22: 0 | AJ22: 0 | AK22: 0 | AL22: 0 | AM22: 0 | AN22: 0 | AO22: 0 | AP22: 0 | AQ22: 0 | AR22: 0 | AS22: 0 | AT22: 0 | AU22: 0 | AV22: 0 | AW22: 0 | AX22: 0 | AY22: 0 | AZ22: 0 | BA22: 0 | BB22: 1 | BC22: 0 | BD22: 0 | BE22: 0 | BF22: 0 | BG22: 0 | BH22: 0 | BI22: 0 | BJ22: 0 | BK22: 0 | BL22: 0 | BM22: 2 | BN22: 0 | BO22: 1 | BP22: 0 | BQ22: 0 | BR22: =SUM(E22:BQ22) -> 11
D23: PR | E23: 0 | F23: 0 | G23: 0 | H23: 0 | I23: 0 | J23: 0 | K23: 0 | L23: 0 | M23: 0 | N23: 1 | O23: 0 | P23: 0 | Q23: 0 | R23: 0 | S23: 0 | T23: 1 | U23: 0 | V23: 0 | W23: 0 | X23: 0 | Y23: 0 | Z23: 0 | AA23: 1 | AB23: 0 | AC23: 0 | AD23: 0 | AE23: 0 | AF23: 0 | AG23: 0 | AH23: 0 | AI23: 0 | AJ23: 0 | AK23: 0 | AL23: 0 | AM23: 0 | AN23: 0 | AO23: 1 | AP23: 0 | AQ23: 0 | AR23: 0 | AS23: 0 | AT23: 0 | AU23: 0 | AV23: 0 | AW23: 0 | AX23: 0 | AY23: 0 | AZ23: 0 | BA23: 0 | BB23: 0 | BC23: 0 | BD23: 0 | BE23: 0 | BF23: 0 | BG23: 0 | BH23: 0 | BI23: 0 | BJ23: 0 | BK23: 0 | BL23: 0 | BM23: 1 | BN23: 0 | BO23: 0 | BP23: 0 | BQ23: 0 | BR23: =SUM(E23:BQ23) -> 5
D24: JML | E24: =SUM(E22:E23) -> 0 | F24: =SUM(F22:F23) -> 0 | G24: =SUM(G22:G23) -> 0 | H24: =SUM(H22:H23) -> 0 | I24: =SUM(I22:I23) -> 0 | J24: =SUM(J22:J23) -> 0 | K24: =SUM(K22:K23) -> 0 | L24: =SUM(L22:L23) -> 0 | ... BQ24: =SUM(BQ22:BQ23) -> 0 | BR24: =SUM(E24:BQ24) -> 16
B25: 3. | C25: Jumlah pengguna hak pilih dalam Daftar Pemilih Khusus (DPK) | D25: LK | E25: 0 | F25: 2 | G25: 0 | H25: 1 | I25: 0 | J25: 0 | K25: 5 | L25: 2 | M25: 1 | N25: 3 | O25: 0 | P25: 0 | Q25: 0 | R25: 3 | S25: 1 | T25: 0 | U25: 0 | V25: 0 | W25: 0 | X25: 3 | Y25: 0 | Z25: 0 | AA25: 0 | AB25: 0 | AC25: 0 | AD25: 0 | AE25: 0 | AF25: 0 | AG25: 0 | AH25: 0 | AI25: 0 | AJ25: 0 | AK25: 0 | AL25: 0 | AM25: 1 | AN25: 2 | AO25: 3 | AP25: 0 | AQ25: 1 | AR25: 0 | AS25: 1 | AT25: 0 | AU25: 0 | AV25: 16 | AW25: 0 | AX25: 0 | AY25: 1 | AZ25: 0 | BA25: 0 | BB25: 0 | BC25: 2 | BD25: 0 | BE25: 0 | BF25: 4 | BG25: 1 | BH25: 2 | BI25: 0 | BJ25: 0 | BK25: 0 | BL25: 0 | BM25: 0 | BN25: 0 | BO25: 0 | BP25: 0 | BQ25: 0 | BR25: =SUM(E25:BQ25) -> 55
D26: PR | E26: 0 | F26: 4 | G26: 0 | H26: 2 | I26: 0 | J26: 0 | K26: 4 | L26: 2 | M26: 2 | N26: 0 | O26: 0 | P26: 0 | Q26: 0 | R26: 1 | S26: 0 | T26: 0 | U26: 0 | V26: 0 | W26: 0 | X26: 5 | Y26: 0 | Z26: 0 | AA26: 0 | AB26: 0 | AC26: 0 | AD26: 0 | AE26: 0 | AF26: 0 | AG26: 1 | AH26: 2 | AI26: 0 | AJ26: 0 | AK26: 3 | AL26: 0 | AM26: 1 | AN26: 0 | AO26: 0 | AP26: 0 | AQ26: 1 | AR26: 0 | AS26: 2 | AT26: 0 | AU26: 0 | AV26: 17 | AW26: 0 | AX26: 0 | AY26: 1 | AZ26: 0 | BA26: 0 | BB26: 0 | BC26: 3 | BD26: 0 | BE26: 0 | BF26: 4 | BG26: 2 | BH26: 3 | BI26: 1 | BJ26: 0 | BK26: 0 | BL26: 0 | BM26: 0 | BN26: 0 | BO26: 2 | BP26: 0 | BQ26: 0 | BR26: =SUM(E26:BQ26) -> 63
D27: JML | E27: =SUM(E25:E26) -> 0 | F27: =SUM(F25:F26) -> 6 | G27: =SUM(G25:G26) -> 0 | H27: =SUM(H25:H26) -> 3 | I27: =SUM(I25:I26) -> 0 | J27: =SUM(J25:J26) -> 0 | K27: =SUM(K25:K26) -> 9 | L27: =SUM(L25:L26) -> 4 | ... BQ27: =SUM(BQ25:BQ26) -> 0 | BR27: =SUM(E27:BQ27) -> 118
B28: 4. | C28: Jumlah Pengguna Hak Pilih (B.1+B.2+B.3) | D28: LK | E28: =SUM(E19,E22,E25) -> 78 | F28: =SUM(F19,F22,F25) -> 87 | G28: =SUM(G19,G22,G25) -> 77 | H28: =SUM(H19,H22,H25) -> 91 | I28: =SUM(I19,I22,I25) -> 103 | J28: =SUM(J19,J22,J25) -> 117 | K28: =SUM(K19,K22,K25) -> 105 | L28: =SUM(L19,L22,L25) -> 84 | ... BQ28: =SUM(BQ19,BQ22,BQ25) -> 109 | BR28: =SUM(E28:BQ28) -> 6475
D29: PR | E29: =SUM(E20,E23,E26) -> 93 | F29: =SUM(F20,F23,F26) -> 76 | G29: =SUM(G20,G23,G26) -> 76 | H29: =SUM(H20,H23,H26) -> 109 | I29: =SUM(I20,I23,I26) -> 104 | J29: =SUM(J20,J23,J26) -> 112 | K29: =SUM(K20,K23,K26) -> 116 | L29: =SUM(L20,L23,L26) -> 111 | ... BQ29: =SUM(BQ20,BQ23,BQ26) -> 115 | BR29: =SUM(E29:BQ29) -> 6919
D30: JML | E30: =SUM(E28:E29) -> 171 | F30: =SUM(F28:F29) -> 163 | G30: =SUM(G28:G29) -> 153 | H30: =SUM(H28:H29) -> 200 | I30: =SUM(I28:I29) -> 207 | J30: =SUM(J28:J29) -> 229 | K30: =SUM(K28:K29) -> 221 | L30: =SUM(L28:L29) -> 195 | ... BQ30: =SUM(BQ28:BQ29) -> 224 | BR30: =SUM(E30:BQ30) -> 13394
A32: II | B32: DATA PENGGUNAAN SURAT SUARA
A33: 1 | B33: Jumlah surat suara yang diterima, termasuk surat suara cadangan 2,5% dari DPT | E33: 246 | F33: 228 | G33: 203 | H33: 286 | I33: 285 | J33: 272 | K33: 288 | L33: 254 | M33: 296 | N33: 305 | O33: 289 | P33: 299 | Q33: 287 | R33: 280 | S33: 286 | T33: 299 | U33: 276 | V33: 285 | W33: 283 | X33: 278 | Y33: 264 | Z33: 304 | AA33: 295 | AB33: 295 | AC33: 299 | AD33: 302 | AE33: 302 | AF33: 311 | AG33: 282 | AH33: 284 | AI33: 270 | AJ33: 297 | AK33: 293 | AL33: 235 | AM33: 248 | AN33: 302 | AO33: 300 | AP33: 296 | AQ33: 284 | AR33: 232 | AS33: 254 | AT33: 222 | AU33: 278 | AV33: 270 | AW33: 258 | AX33: 297 | AY33: 284 | AZ33: 274 | BA33: 289 | BB33: 194 | BC33: 209 | BD33: 304 | BE33: 234 | BF33: 288 | BG33: 283 | BH33: 250 | BI33: 246 | BJ33: 283 | BK33: 262 | BL33: 300 | BM33: 263 | BN33: 316 | BO33: 291 | BP33: 291 | BQ33: 272 | BR33: =SUM(E33:BQ33) -> 17932
A34: 2 | B34: Jumlah surat suara yang digunakan | E34: 171 | F34: 163 | G34: 153 | H34: 200 | I34: 207 | J34: 229 | K34: 221 | L34: 195 | M34: 209 | N34: 233 | O34: 203 | P34: 219 | Q34: 208 | R34: 203 | S34: 206 | T34: 193 | U34: 208 | V34: 190 | W34: 187 | X34: 194 | Y34: 220 | Z34: 220 | AA34: 209 | AB34: 205 | AC34: 235 | AD34: 224 | AE34: 215 | AF34: 221 | AG34: 192 | AH34: 202 | AI34: 200 | AJ34: 227 | AK34: 221 | AL34: 197 | AM34: 195 | AN34: 223 | AO34: 240 | AP34: 219 | AQ34: 213 | AR34: 192 | AS34: 200 | AT34: 167 | AU34: 233 | AV34: 211 | AW34: 188 | AX34: 216 | AY34: 202 | AZ34: 197 | BA34: 214 | BB34: 129 | BC34: 172 | BD34: 223 | BE34: 183 | BF34: 231 | BG34: 233 | BH34: 203 | BI34: 200 | BJ34: 220 | BK34: 204 | BL34: 223 | BM34: 188 | BN34: 228 | BO34: 215 | BP34: 228 | BQ34: 224 | BR34: =SUM(E34:BQ34) -> 13394
A35: 3 | B35: Jumlah surat suara dikembalikan oleh pemilih (karena rusak atau keliru coblos) | E35: 23 | F35: 0 | G35: 0 | H35: 0 | I35: 1 | J35: 0 | K35: 0 | L35: 0 | M35: 2 | N35: 4 | O35: 0 | P35: 0 | Q35: 0 | R35: 0 | S35: 0 | T35: 0 | U35: 1 | V35: 0 | W35: 0 | X35: 2 | Y35: 1 | Z35: 0 | AA35: 0 | AB35: 0 | AC35: 6 | AD35: 0 | AE35: 0 | AF35: 1 | AG35: 1 | AH35: 0 | AI35: 1 | AJ35: 0 | AK35: 1 | AL35: 1 | AM35: 1 | AN35: 0 | AO35: 1 | AP35: 0 | AQ35: 0 | AR35: 2 | AS35: 0 | AT35: 0 | AU35: 0 | AV35: 0 | AW35: 0 | AX35: 0 | AY35: 0 | AZ35: 0 | BA35: 0 | BB35: 0 | BC35: 14 | BD35: 0 | BE35: 0 | BF35: 1 | BG35: 0 | BH35: 1 | BI35: 0 | BJ35: 0 | BK35: 2 | BL35: 0 | BM35: 0 | BN35: 0 | BO35: 0 | BP35: 0 | BQ35: 0 | BR35: =SUM(E35:BQ35) -> 67
A36: 4 | B36: Jumlah surat suara yang tidak digunakan/tidak terpakai, termasuk sisa surat suara cadangan | E36: =E33-(E34+E35) -> 52 | F36: =F33-(F34+F35) -> 65 | G36: =G33-(G34+G35) -> 50 | H36: =H33-(H34+H35) -> 86 | I36: =I33-(I34+I35) -> 77 | J36: =J33-(J34+J35) -> 43 | K36: =K33-(K34+K35) -> 67 | L36: =L33-(L34+L35) -> 59 | ... BQ36: =BQ33-(BQ34+BQ35) -> 48 | BR36: =SUM(E36:BQ36) -> 4471
A38: III | B38: DATA PEMILIH DISABILITAS
B39: Jumlah seluruh Pemilih disabilitas yang menggunakan hak pilih | D39: LK | E39: 0 | F39: 1 | G39: 1 | H39: 0 | I39: 0 | J39: 0 | K39: 0 | L39: 0 | M39: 0 | N39: 0 | O39: 0 | P39: 0 | Q39: 0 | R39: 1 | S39: 0 | T39: 0 | U39: 2 | V39: 0 | W39: 0 | X39: 1 | Y39: 0 | Z39: 0 | AA39: 0 | AB39: 0 | AC39: 0 | AD39: 0 | AE39: 0 | AF39: 0 | AG39: 1 | AH39: 0 | AI39: 0 | AJ39: 0 | AK39: 1 | AL39: 0 | AM39: 0 | AN39: 0 | AO39: 2 | AP39: 0 | AQ39: 1 | AR39: 0 | AS39: 0 | AT39: 0 | AU39: 0 | AV39: 0 | AW39: 0 | AX39: 0 | AY39: 1 | AZ39: 0 | BA39: 0 | BB39: 0 | BC39: 0 | BD39: 1 | BE39: 0 | BF39: 0 | BG39: 0 | BH39: 1 | BI39: 1 | BJ39: 0 | BK39: 0 | BL39: 1 | BM39: 0 | BN39: 0 | BO39: 0 | BP39: 0 | BQ39: 0 | BR39: =SUM(E39:BQ39) -> 16
D40: PR | E40: 0 | F40: 1 | G40: 0 | H40: 0 | I40: 0 | J40: 2 | K40: 0 | L40: 0 | M40: 0 | N40: 0 | O40: 0 | P40: 0 | Q40: 0 | R40: 0 | S40: 1 | T40: 0 | U40: 2 | V40: 0 | W40: 0 | X40: 1 | Y40: 0 | Z40: 1 | AA40: 0 | AB40: 0 | AC40: 0 | AD40: 0 | AE40: 0 | AF40: 0 | AG40: 0 | AH40: 0 | AI40: 0 | AJ40: 0 | AK40: 0 | AL40: 0 | AM40: 0 | AN40: 0 | AO40: 0 | AP40: 0 | AQ40: 0 | AR40: 0 | AS40: 0 | AT40: 0 | AU40: 0 | AV40: 0 | AW40: 0 | AX40: 0 | AY40: 0 | AZ40: 1 | BA40: 0 | BB40: 0 | BC40: 0 | BD40: 1 | BE40: 0 | BF40: 0 | BG40: 0 | BH40: 0 | BI40: 1 | BJ40: 0 | BK40: 0 | BL40: 2 | BM40: 0 | BN40: 1 | BO40: 0 | BP40: 0 | BQ40: 0 | BR40: =SUM(E40:BQ40) -> 14
D41: JML | E41: =SUM(E39:E40) -> 0 | F41: =SUM(F39:F40) -> 2 | G41: =SUM(G39:G40) -> 1 | H41: =SUM(H39:H40) -> 0 | I41: =SUM(I39:I40) -> 0 | J41: =SUM(J39:J40) -> 2 | K41: =SUM(K39:K40) -> 0 | L41: =SUM(L39:L40) -> 0 | ... BQ41: =SUM(BQ39:BQ40) -> 0 | BR41: =SUM(E41:BQ41) -> 30
A43: IV | B43: DATA RINCIAN PEROLEHAN SUARA PASANGAN CALON BUPATI DAN WAKIL BUPATI
A44: NOMOR DAN NAMA CALON
A45: A.1 | B45: 1. | C45: Partai Kebangkitan Bangsa | E45: 2 | F45: 3 | G45: 5 | H45: 7 | I45: 5 | J45: 7 | K45: 6 | L45: 3 | M45: 7 | N45: 0 | O45: 4 | P45: 7 | Q45: 5 | R45: 3 | S45: 15 | T45: 8 | U45: 12 | V45: 8 | W45: 16 | X45: 26 | Y45: 23 | Z45: 5 | AA45: 11 | AB45: 7 | AC45: 4 | AD45: 9 | AE45: 8 | AF45: 22 | AG45: 8 | AH45: 10 | AI45: 6 | AJ45: 8 | AK45: 9 | AL45: 5 | AM45: 10 | AN45: 8 | AO45: 7 | AP45: 11 | AQ45: 5 | AR45: 6 | AS45: 6 | AT45: 4 | AU45: 2 | AV45: 15 | AW45: 7 | AX45: 11 | AY45: 14 | AZ45: 10 | BA45: 15 | BB45: 5 | BC45: 4 | BD45: 6 | BE45: 6 | BF45: 13 | BG45: 9 | BH45: 5 | BI45: 8 | BJ45: 4 | BK45: 2 | BL45: 4 | BM45: 2 | BN45: 4 | BO45: 5 | BP45: 4 | BQ45: 4 | BR45: =SUM(E45:BQ45) -> 500
A46: A.2 | B46: 1 | C46: 1. Dr. Hj. NIHAYATUL WAFIROH, M.A. | E46: 12 | F46: 15 | G46: 2 | H46: 5 | I46: 14 | J46: 25 | K46: 3 | L46: 8 | M46: 15 | N46: 16 | O46: 21 | P46: 11 | Q46: 16 | R46: 2 | S46: 27 | T46: 27 | U46: 20 | V46: 15 | W46: 35 | X46: 17 | Y46: 30 | Z46: 15 | AA46: 27 | AB46: 10 | AC46: 14 | AD46: 14 | AE46: 41 | AF46: 54 | AG46: 25 | AH46: 40 | AI46: 27 | AJ46: 24 | AK46: 20 | AL46: 8 | AM46: 5 | AN46: 12 | AO46: 16 | AP46: 31 | AQ46: 8 | AR46: 50 | AS46: 8 | AT46: 11 | AU46: 17 | AV46: 38 | AW46: 58 | AX46: 40 | AY46: 59 | AZ46: 34 | BA46: 17 | BB46: 14 | BC46: 29 | BD46: 51 | BE46: 43 | BF46: 30 | BG46: 47 | BH46: 21 | BI46: 7 | BJ46: 5 | BK46: 8 | BL46: 9 | BM46: 10 | BN46: 9 | BO46: 3 | BP46: 20 | BQ46: 18 | BR46: =SUM(E46:BQ46) -> 1383
B47: 2 | C47: 2. H. M. NASIM KHAN | E47: 0 | F47: 1 | G47: 0 | H47: 1 | I47: 1 | J47: 5 | K47: 0 | L47: 0 | M47: 0 | N47: 1 | O47: 1 | P47: 1 | Q47: 0 | R47: 2 | S47: 0 | T47: 7 | U47: 0 | V47: 4 | W47: 5 | X47: 4 | Y47: 3 | Z47: 4 | AA47: 0 | AB47: 4 | AC47: 0 | AD47: 2 | AE47: 1 | AF47: 0 | AG47: 2 | AH47: 2 | AI47: 4 | AJ47: 6 | AK47: 1 | AL47: 0 | AM47: 0 | AN47: 2 | AO47: 1 | AP47: 2 | AQ47: 2 | AR47: 9 | AS47: 3 | AT47: 0 | AU47: 0 | AV47: 3 | AW47: 1 | AX47: 0 | AY47: 2 | AZ47: 4 | BA47: 4 | BB47: 0 | BC47: 0 | BD47: 2 | BE47: 0 | BF47: 1 | BG47: 5 | BH47: 0 | BI47: 0 | BJ47: 2 | BK47: 0 | BL47: 3 | BM47: 0 | BN47: 4 | BO47: 0 | BP47: 6 | BQ47: 2 | BR47: =SUM(E47:BQ47) -> 120
B48: 3 | C48: 3. Dr. H. AKIK ZAMAN, M.Pd.I. | E48: 0 | F48: 0 | G48: 0 | H48: 0 | I48: 0 | J48: 1 | K48: 0 | L48: 0 | M48: 0 | N48: 1 | O48: 0 | P48: 2 | Q48: 0 | R48: 0 | S48: 1 | T48: 1 | U48: 0 | V48: 0 | W48: 2 | X48: 1 | Y48: 1 | Z48: 1 | AA48: 0 | AB48: 0 | AC48: 1 | AD48: 0 | AE48: 0 | AF48: 4 | AG48: 2 | AH48: 1 | AI48: 1 | AJ48: 0 | AK48: 1 | AL48: 0 | AM48: 0 | AN48: 0 | AO48: 1 | AP48: 2 | AQ48: 0 | AR48: 2 | AS48: 0 | AT48: 0 | AU48: 2 | AV48: 1 | AW48: 2 | AX48: 0 | AY48: 1 | AZ48: 1 | BA48: 3 | BB48: 0 | BC48: 1 | BD48: 0 | BE48: 0 | BF48: 1 | BG48: 4 | BH48: 0 | BI48: 0 | BJ48: 0 | BK48: 0 | BL48: 0 | BM48: 0 | BN48: 1 | BO48: 0 | BP48: 0 | BQ48: 0 | BR48: =SUM(E48:BQ48) -> 43
B49: 4 | C49: 4. AHMAD RIFA'I, S.H. | E49: 0 | F49: 0 | G49: 0 | H49: 0 | I49: 0 | J49: 0 | K49: 0 | L49: 0 | M49: 0 | N49: 2 | O49: 1 | P49: 1 | Q49: 2 | R49: 1 | S49: 7 | T49: 2 | U49: 2 | V49: 1 | W49: 0 | X49: 1 | Y49: 0 | Z49: 0 | AA49: 1 | AB49: 0 | AC49: 1 | AD49: 0 | AE49: 0 | AF49: 1 | AG49: 1 | AH49: 0 | AI49: 1 | AJ49: 2 | AK49: 3 | AL49: 1 | AM49: 1 | AN49: 0 | AO49: 4 | AP49: 1 | AQ49: 1 | AR49: 3 | AS49: 1 | AT49: 0 | AU49: 0 | AV49: 1 | AW49: 0 | AX49: 1 | AY49: 4 | AZ49: 4 | BA49: 1 | BB49: 1 | BC49: 0 | BD49: 1 | BE49: 1 | BF49: 0 | BG49: 0 | BH49: 0 | BI49: 0 | BJ49: 1 | BK49: 1 | BL49: 1 | BM49: 0 | BN49: 0 | BO49: 2 | BP49: 2 | BQ49: 0 | BR49: =SUM(E49:BQ49) -> 63
B50: 5 | C50: 5. Drs. H. MAHFUD M.N. | E50: 0 | F50: 0 | G50: 0 | H50: 1 | I50: 0 | J50: 0 | K50: 1 | L50: 0 | M50: 0 | N50: 1 | O50: 1 | P50: 0 | Q50: 0 | R50: 0 | S50: 1 | T50: 1 | U50: 2 | V50: 0 | W50: 2 | X50: 3 | Y50: 1 | Z50: 1 | AA50: 7 | AB50: 1 | AC50: 1 | AD50: 0 | AE50: 0 | AF50: 1 | AG50: 1 | AH50: 0 | AI50: 0 | AJ50: 1 | AK50: 0 | AL50: 0 | AM50: 2 | AN50: 0 | AO50: 1 | AP50: 0 | AQ50: 1 | AR50: 1 | AS50: 0 | AT50: 0 | AU50: 0 | AV50: 1 | AW50: 0 | AX50: 1 | AY50: 0 | AZ50: 4 | BA50: 1 | BB50: 0 | BC50: 0 | BD50: 1 | BE50: 0 | BF50: 0 | BG50: 0 | BH50: 0 | BI50: 0 | BJ50: 0 | BK50: 0 | BL50: 1 | BM50: 0 | BN50: 0 | BO50: 0 | BP50: 0 | BQ50: 0 | BR50: =SUM(E50:BQ50) -> 41
B51: 6 | C51: 6. NURHAYATI, S.Pd. | E51: 0 | F51: 0 | G51: 0 | H51: 1 | I51: 0 | J51: 0 | K51: 0 | L51: 0 | M51: 0 | N51: 0 | O51: 1 | P51: 0 | Q51: 1 | R51: 1 | S51: 1 | T51: 4 | U51: 1 | V51: 1 | W51: 3 | X51: 2 | Y51: 4 | Z51: 1 | AA51: 8 | AB51: 2 | AC51: 1 | AD51: 1 | AE51: 0 | AF51: 0 | AG51: 1 | AH51: 3 | AI51: 1 | AJ51: 0 | AK51: 0 | AL51: 0 | AM51: 1 | AN51: 0 | AO51: 2 | AP51: 0 | AQ51: 0 | AR51: 1 | AS51: 0 | AT51: 0 | AU51: 0 | AV51: 0 | AW51: 1 | AX51: 0 | AY51: 1 | AZ51: 1 | BA51: 0 | BB51: 0 | BC51: 2 | BD51: 1 | BE51: 0 | BF51: 2 | BG51: 1 | BH51: 2 | BI51: 1 | BJ51: 0 | BK51: 0 | BL51: 0 | BM51: 0 | BN51: 1 | BO51: 0 | BP51: 1 | BQ51: 0 | BR51: =SUM(E51:BQ51) -> 56
...

Sheet KARANGSARI
C2: Kecamatan | D2: SEMPU
C3: Kabupaten | D3: BANYUWANGI
C4: Provinsi | D4: JAWA TIMUR
C9: Kelurahan | D9: KARANGSARI
A12: I | B12: DATA PEMILIH DAN PENGGUNAAN HAK PILIH | AX12: JUMLAH AKHIR
A13: A | B13: DATA PEMILIH | E13: TPS 001 | F13: TPS 002 | G13: TPS 003 | H13: TPS 004 | I13: TPS 005 | J13: TPS 006 | K13: TPS 007 | L13: TPS 008 | M13: TPS 009 | N13: TPS 010 | O13: TPS 011 | P13: TPS 012 | Q13: TPS 013 | R13: TPS 014 | S13: TPS 015 | T13: TPS 016 | U13: TPS 017 | V13: TPS 018 | W13: TPS 019 | X13: TPS 020 | Y13: TPS 021 | Z13: TPS 022 | AA13: TPS 023 | AB13: TPS 024 | AC13: TPS 025 | AD13: TPS 026 | AE13: TPS 027 | AF13: TPS 028 | AG13: TPS 029 | AH13: TPS 030 | AI13: TPS 031 | AJ13: TPS 032 | AK13: TPS 033 | AL13: TPS 034 | AM13: TPS 035 | AN13: TPS 036 | AO13: TPS 037 | AP13: TPS 038 | AQ13: TPS 039 | AR13: TPS 040 | AS13: TPS 041 | AT13: TPS 042 | AU13: TPS 043 | AV13: TPS 044 | AW13: TPS 045
B14: Jumlah Pemilih dalam Daftar Pemilih Tetap (DPT) | D14: LK | E14: 149 | F14: 145 | G14: 119 | H14: 137 | I14: 143 | J14: 101 | K14: 146 | L14: 146 | M14: 150 | N14: 133 | O14: 124 | P14: 95 | Q14: 142 | R14: 147 | S14: 130 | T14: 108 | U14: 149 | V14: 135 | W14: 148 | X14: 149 | Y14: 157 | Z14: 143 | AA14: 163 | AB14: 143 | AC14: 111 | AD14: 116 | AE14: 138 | AF14: 121 | AG14: 136 | AH14: 148 | AI14: 98 | AJ14: 140 | AK14: 107 | AL14: 149 | AM14: 144 | AN14: 121 | AO14: 90 | AP14: 145 | AQ14: 153 | AR14: 135 | AS14: 148 | AT14: 142 | AU14: 140 | AV14: 136 | AW14: 141 | AX14: =SUM(E14:AW14) -> 6061
D15: PR | E15: 128 | F15: 151 | G15: 121 | H15: 140 | I15: 145 | J15: 101 | K15: 146 | L15: 143 | M15: 144 | N15: 128 | O15: 116 | P15: 95 | Q15: 149 | R15: 148 | S15: 138 | T15: 104 | U15: 129 | V15: 132 | W15: 144 | X15: 141 | Y15: 140 | Z15: 134 | AA15: 135 | AB15: 145 | AC15: 122 | AD15: 118 | AE15: 159 | AF15: 128 | AG15: 137 | AH15: 130 | AI15: 93 | AJ15: 136 | AK15: 114 | AL15: 144 | AM15: 148 | AN15: 126 | AO15: 98 | AP15: 143 | AQ15: 145 | AR15: 137 | AS15: 140 | AT15: 152 | AU15: 134 | AV15: 150 | AW15: 154 | AX15: =SUM(E15:AW15) -> 6005
D16: JML | E16: =SUM(E14:E15) -> 277 | F16: =SUM(F14:F15) -> 296 | G16: =SUM(G14:G15) -> 240 | H16: =SUM(H14:H15) -> 277 | I16: =SUM(I14:I15) -> 288 | J16: =SUM(J14:J15) -> 202 | K16: =SUM(K14:K15) -> 292 | L16: =SUM(L14:L15) -> 289 | ... AW16: =SUM(AW14:AW15) -> 295 | AX16: =SUM(E16:AW16) -> 12066
A18: B | B18: PENGGUNA HAK PILIH
B19: 1. | C19: Jumlah pengguna hak pilih dalam Daftar Pemilih Tetap (DPT) | D19: LK | E19: 103 | F19: 106 | G19: 89 | H19: 106 | I19: 101 | J19: 63 | K19: 78 | L19: 102 | M19: 107 | N19: 71 | O19: 85 | P19: 71 | Q19: 111 | R19: 102 | S19: 95 | T19: 77 | U19: 114 | V19: 106 | W19: 100 | X19: 108 | Y19: 105 | Z19: 92 | AA19: 107 | AB19: 94 | AC19: 80 | AD19: 96 | AE19: 93 | AF19: 93 | AG19: 105 | AH19: 115 | AI19: 82 | AJ19: 114 | AK19: 75 | AL19: 104 | AM19: 102 | AN19: 93 | AO19: 71 | AP19: 110 | AQ19: 113 | AR19: 91 | AS19: 123 | AT19: 95 | AU19: 97 | AV19: 96 | AW19: 107 | AX19: =SUM(E19:AW19) -> 4348
D20: PR | E20: 106 | F20: 123 | G20: 88 | H20: 112 | I20: 113 | J20: 73 | K20: 96 | L20: 111 | M20: 95 | N20: 93 | O20: 91 | P20: 72 | Q20: 117 | R20: 111 | S20: 97 | T20: 80 | U20: 104 | V20: 107 | W20: 109 | X20: 111 | Y20: 106 | Z20: 103 | AA20: 103 | AB20: 110 | AC20: 104 | AD20: 90 | AE20: 120 | AF20: 98 | AG20: 116 | AH20: 105 | AI20: 80 | AJ20: 109 | AK20: 94 | AL20: 90 | AM20: 106 | AN20: 101 | AO20: 81 | AP20: 118 | AQ20: 116 | AR20: 106 | AS20: 121 | AT20: 124 | AU20: 102 | AV20: 114 | AW20: 107 | AX20: =SUM(E20:AW20) -> 4633
D21: JML | E21: =SUM(E19:E20) -> 209 | F21: =SUM(F19:F20) -> 229 | G21: =SUM(G19:G20) -> 177 | H21: =SUM(H19:H20) -> 218 | I21: =SUM(I19:I20) -> 214 | J21: =SUM(J19:J20) -> 136 | K21: =SUM(K19:K20) -> 174 | L21: =SUM(L19:L20) -> 213 | ... AW21: =SUM(AW19:AW20) -> 214 | AX21: =SUM(E21:AW21) -> 8981
B22: 2. | C22: Jumlah pengguna hak pilih dalam Daftar Pemilih Tambahan (DPTb) | D22: LK | E22: 0 | F22: 0 | G22: 0 | H22: 0 | I22: 2 | J22: 1 | K22: 0 | L22: 0 | M22: 0 | N22: 0 | O22: 0 | P22: 1 | Q22: 0 | R22: 0 | S22: 0 | T22: 1 | U22: 0 | V22: 0 | W22: 0 | X22: 0 | Y22: 0 | Z22: 0 | AA22: 0 | AB22: 0 | AC22: 0 | AD22: 0 | AE22: 0 | AF22: 0 | AG22: 0 | AH22: 1 | AI22: 1 | AJ22: 0 | AK22: 0 | AL22: 0 | AM22: 1 | AN22: 1 | AO22: 0 | AP22: 1 | AQ22: 0 | AR22: 1 | AS22: 0 | AT22: 1 | AU22: 0 | AV22: 0 | AW22: 0 | AX22: =SUM(E22:AW22) -> 12
D23: PR | E23: 0 | F23: 1 | G23: 1 | H23: 1 | I23: 0 | J23: 0 | K23: 0 | L23: 1 | M23: 1 | N23: 0 | O23: 0 | P23: 0 | Q23: 0 | R23: 1 | S23: 0 | T23: 0 | U23: 0 | V23: 1 | W23: 0 | X23: 0 | Y23: 0 | Z23: 0 | AA23: 0 | AB23: 0 | AC23: 1 | AD23: 0 | AE23: 0 | AF23: 0 | AG23: 2 | AH23: 0 | AI23: 0 | AJ23: 0 | AK23: 0 | AL23: 1 | AM23: 0 | AN23: 0 | AO23: 0 | AP23: 4 | AQ23: 0 | AR23: 1 | AS23: 0 | AT23: 0 | AU23: 0 | AV23: 0 | AW23: 2 | AX23: =SUM(E23:AW23) -> 18
D24: JML | E24: =SUM(E22:E23) -> 0 | F24: =SUM(F22:F23) -> 1 | G24: =SUM(G22:G23) -> 1 | H24: =SUM(H22:H23) -> 1 | I24: =SUM(I22:I23) -> 2 | J24: =SUM(J22:J23) -> 1 | K24: =SUM(K22:K23) -> 0 | L24: =SUM(L22:L23) -> 1 | ... AW24: =SUM(AW22:AW23) -> 2 | AX24: =SUM(E24:AW24) -> 30
B25: 3. | C25: Jumlah pengguna hak pilih dalam Daftar Pemilih Khusus (DPK) | D25: LK | E25: 0 | F25: 0 | G25: 0 | H25: 0 | I25: 0 | J25: 0 | K25: 2 | L25: 4 | M25: 0 | N25: 0 | O25: 0 | P25: 2 | Q25: 0 | R25: 1 | S25: 1 | T25: 0 | U25: 6 | V25: 1 | W25: 3 | X25: 1 | Y25: 2 | Z25: 0 | AA25: 0 | AB25: 2 | AC25: 0 | AD25: 0 | AE25: 0 | AF25: 0 | AG25: 0 | AH25: 0 | AI25: 0 | AJ25: 2 | AK25: 4 | AL25: 0 | AM25: 4 | AN25: 0 | AO25: 0 | AP25: 0 | AQ25: 1 | AR25: 3 | AS25: 0 | AT25: 0 | AU25: 0 | AV25: 0 | AW25: 0 | AX25: =SUM(E25:AW25) -> 39
D26: PR | E26: 0 | F26: 0 | G26: 0 | H26: 0 | I26: 0 | J26: 0 | K26: 2 | L26: 4 | M26: 0 | N26: 0 | O26: 0 | P26: 4 | Q26: 0 | R26: 3 | S26: 3 | T26: 0 | U26: 7 | V26: 0 | W26: 2 | X26: 1 | Y26: 0 | Z26: 0 | AA26: 0 | AB26: 0 | AC26: 0 | AD26: 0 | AE26: 0 | AF26: 0 | AG26: 0 | AH26: 0 | AI26: 1 | AJ26: 3 | AK26: 0 | AL26: 2 | AM26: 3 | AN26: 2 | AO26: 0 | AP26: 0 | AQ26: 0 | AR26: 3 | AS26: 0 | AT26: 0 | AU26: 0 | AV26: 1 | AW26: 2 | AX26: =SUM(E26:AW26) -> 43
D27: JML | E27: =SUM(E25:E26) -> 0 | F27: =SUM(F25:F26) -> 0 | G27: =SUM(G25:G26) -> 0 | H27: =SUM(H25:H26) -> 0 | I27: =SUM(I25:I26) -> 0 | J27: =SUM(J25:J26) -> 0 | K27: =SUM(K25:K26) -> 4 | L27: =SUM(L25:L26) -> 8 | ... AW27: =SUM(AW25:AW26) -> 2 | AX27: =SUM(E27:AW27) -> 82
B28: 4. | C28: Jumlah Pengguna Hak Pilih (B.1+B.2+B.3) | D28: LK | E28: =SUM(E19,E22,E25) -> 103 | F28: =SUM(F19,F22,F25) -> 106 | G28: =SUM(G19,G22,G25) -> 89 | H28: =SUM(H19,H22,H25) -> 106 | I28: =SUM(I19,I22,I25) -> 103 | J28: =SUM(J19,J22,J25) -> 64 | K28: =SUM(K19,K22,K25) -> 80 | L28: =SUM(L19,L22,L25) -> 106 | ... AW28: =SUM(AW19,AW22,AW25) -> 107 | AX28: =SUM(E28:AW28) -> 4399
D29: PR | E29: =SUM(E20,E23,E26) -> 106 | F29: =SUM(F20,F23,F26) -> 124 | G29: =SUM(G20,G23,G26) -> 89 | H29: =SUM(H20,H23,H26) -> 113 | I29: =SUM(I20,I23,I26) -> 113 | J29: =SUM(J20,J23,J26) -> 73 | K29: =SUM(K20,K23,K26) -> 98 | L29: =SUM(L20,L23,L26) -> 116 | ... AW29: =SUM(AW20,AW23,AW26) -> 111 | AX29: =SUM(E29:AW29) -> 4694
D30: JML | E30: =SUM(E28:E29) -> 209 | F30: =SUM(F28:F29) -> 230 | G30: =SUM(G28:G29) -> 178 | H30: =SUM(H28:H29) -> 219 | I30: =SUM(I28:I29) -> 216 | J30: =SUM(J28:J29) -> 137 | K30: =SUM(K28:K29) -> 178 | L30: =SUM(L28:L29) -> 222 | ... AW30: =SUM(AW28:AW29) -> 218 | AX30: =SUM(E30:AW30) -> 9093
A32: II | B32: DATA PENGGUNAAN SURAT SUARA
A33: 1 | B33: Jumlah surat suara yang diterima, termasuk surat suara cadangan 2,5% dari DPT | E33: 283 | F33: 303 | G33: 245 | H33: 283 | I33: 294 | J33: 286 | K33: 287 | L33: 295 | M33: 300 | N33: 267 | O33: 245 | P33: 194 | Q33: 297 | R33: 301 | S33: 274 | T33: 217 | U33: 287 | V33: 273 | W33: 309 | X33: 316 | Y33: 303 | Z33: 283 | AA33: 304 | AB33: 294 | AC33: 238 | AD33: 249 | AE33: 323 | AF33: 253 | AG33: 279 | AH33: 284 | AI33: 195 | AJ33: 281 | AK33: 226 | AL33: 299 | AM33: 297 | AN33: 252 | AO33: 192 | AP33: 305 | AQ33: 309 | AR33: 278 | AS33: 295 | AT33: 300 | AU33: 280 | AV33: 292 | AW33: 300 | AX33: =SUM(E33:AW33) -> 12467
A34: 2 | B34: Jumlah surat suara yang digunakan | E34: 209 | F34: 230 | G34: 178 | H34: 219 | I34: 216 | J34: 137 | K34: 178 | L34: 222 | M34: 203 | N34: 164 | O34: 176 | P34: 150 | Q34: 228 | R34: 218 | S34: 196 | T34: 158 | U34: 231 | V34: 215 | W34: 214 | X34: 221 | Y34: 213 | Z34: 195 | AA34: 210 | AB34: 206 | AC34: 185 | AD34: 186 | AE34: 213 | AF34: 191 | AG34: 223 | AH34: 221 | AI34: 164 | AJ34: 228 | AK34: 173 | AL34: 197 | AM34: 216 | AN34: 197 | AO34: 152 | AP34: 233 | AQ34: 230 | AR34: 205 | AS34: 244 | AT34: 220 | AU34: 199 | AV34: 211 | AW34: 218 | AX34: =SUM(E34:AW34) -> 9093
A35: 3 | B35: Jumlah surat suara dikembalikan oleh pemilih (karena rusak atau keliru coblos) | E35: 0 | F35: 0 | G35: 0 | H35: 0 | I35: 0 | J35: 0 | K35: 1 | L35: 2 | M35: 0 | N35: 0 | O35: 0 | P35: 0 | Q35: 0 | R35: 2 | S35: 1 | T35: 0 | U35: 0 | V35: 0 | W35: 0 | X35: 0 | Y35: 0 | Z35: 0 | AA35: 0 | AB35: 0 | AC35: 0 | AD35: 0 | AE35: 1 | AF35: 0 | AG35: 0 | AH35: 0 | AI35: 0 | AJ35: 1 | AK35: 1 | AL35: 0 | AM35: 0 | AN35: 1 | AO35: 0 | AP35: 0 | AQ35: 0 | AR35: 0 | AS35: 1 | AT35: 0 | AU35: 0 | AV35: 2 | AW35: 0 | AX35: =SUM(E35:AW35) -> 13
A36: 4 | B36: Jumlah surat suara yang tidak digunakan/tidak terpakai, termasuk sisa surat suara cadangan | E36: =E33-(E34+E35) -> 74 | F36: =F33-(F34+F35) -> 73 | G36: =G33-(G34+G35) -> 67 | H36: =H33-(H34+H35) -> 64 | I36: =I33-(I34+I35) -> 78 | J36: =J33-(J34+J35) -> 149 | K36: =K33-(K34+K35) -> 108 | L36: =L33-(L34+L35) -> 71 | ... AW36: =AW33-(AW34+AW35) -> 82 | AX36: =SUM(E36:AW36) -> 3361
A38: III | B38: DATA PEMILIH DISABILITAS
B39: Jumlah seluruh Pemilih disabilitas yang menggunakan hak pilih | D39: LK | E39: 0 | F39: 0 | G39: 0 | H39: 0 | I39: 1 | J39: 0 | K39: 0 | L39: 0 | M39: 0 | N39: 0 | O39: 0 | P39: 0 | Q39: 0 | R39: 0 | S39: 0 | T39: 0 | U39: 0 | V39: 0 | W39: 0 | X39: 0 | Y39: 0 | Z39: 0 | AA39: 0 | AB39: 0 | AC39: 0 | AD39: 0 | AE39: 0 | AF39: 0 | AG39: 0 | AH39: 1 | AI39: 1 | AJ39: 0 | AK39: 0 | AL39: 0 | AM39: 0 | AN39: 0 | AO39: 0 | AP39: 0 | AQ39: 0 | AR39: 0 | AS39: 0 | AT39: 0 | AU39: 0 | AV39: 0 | AW39: 1 | AX39: =SUM(E39:AW39) -> 4
D40: PR | E40: 0 | F40: 0 | G40: 0 | H40: 0 | I40: 0 | J40: 0 | K40: 0 | L40: 0 | M40: 0 | N40: 0 | O40: 0 | P40: 0 | Q40: 0 | R40: 1 | S40: 0 | T40: 0 | U40: 0 | V40: 0 | W40: 0 | X40: 0 | Y40: 0 | Z40: 0 | AA40: 0 | AB40: 0 | AC40: 1 | AD40: 0 | AE40: 0 | AF40: 0 | AG40: 0 | AH40: 0 | AI40: 0 | AJ40: 0 | AK40: 0 | AL40: 0 | AM40: 0 | AN40: 0 | AO40: 0 | AP40: 0 | AQ40: 0 | AR40: 0 | AS40: 0 | AT40: 1 | AU40: 0 | AV40: 0 | AW40: 0 | AX40: =SUM(E40:AW40) -> 3
D41: JML | E41: =SUM(E39:E40) -> 0 | F41: =SUM(F39:F40) -> 0 | G41: =SUM(G39:G40) -> 0 | H41: =SUM(H39:H40) -> 0 | I41: =SUM(I39:I40) -> 1 | J41: =SUM(J39:J40) -> 0 | K41: =SUM(K39:K40) -> 0 | L41: =SUM(L39:L40) -> 0 | ... AW41: =SUM(AW39:AW40) -> 1 | AX41: =SUM(E41:AW41) -> 7
A43: IV | B43: DATA RINCIAN PEROLEHAN SUARA PASANGAN CALON BUPATI DAN WAKIL BUPATI
A44: NOMOR DAN NAMA CALON
A45: A.1 | B45: 1. | C45: Partai Kebangkitan Bangsa | E45: 10 | F45: 4 | G45: 0 | H45: 4 | I45: 7 | J45: 3 | K45: 1 | L45: 3 | M45: 5 | N45: 6 | O45: 7 | P45: 3 | Q45: 0 | R45: 7 | S45: 4 | T45: 4 | U45: 2 | V45: 7 | W45: 5 | X45: 9 | Y45: 4 | Z45: 4 | AA45: 6 | AB45: 7 | AC45: 3 | AD45: 6 | AE45: 8 | AF45: 4 | AG45: 9 | AH45: 9 | AI45: 8 | AJ45: 5 | AK45: 6 | AL45: 6 | AM45: 9 | AN45: 10 | AO45: 11 | AP45: 8 | AQ45: 3 | AR45: 7 | AS45: 12 | AT45: 3 | AU45: 5 | AV45: 8 | AW45: 2 | AX45: =SUM(E45:AW45) -> 254
A46: A.2 | B46: 1 | C46: 1. Dr. Hj. NIHAYATUL WAFIROH, M.A. | E46: 6 | F46: 2 | G46: 10 | H46: 6 | I46: 12 | J46: 12 | K46: 4 | L46: 11 | M46: 14 | N46: 16 | O46: 6 | P46: 6 | Q46: 18 | R46: 12 | S46: 10 | T46: 4 | U46: 11 | V46: 6 | W46: 18 | X46: 14 | Y46: 7 | Z46: 3 | AA46: 11 | AB46: 9 | AC46: 23 | AD46: 7 | AE46: 29 | AF46: 23 | AG46: 9 | AH46: 9 | AI46: 15 | AJ46: 30 | AK46: 9 | AL46: 6 | AM46: 29 | AN46: 19 | AO46: 16 | AP46: 28 | AQ46: 8 | AR46: 32 | AS46: 59 | AT46: 11 | AU46: 9 | AV46: 12 | AW46: 15 | AX46: =SUM(E46:AW46) -> 626
B47: 2 | C47: 2. H. M. NASIM KHAN | E47: 1 | F47: 0 | G47: 1 | H47: 1 | I47: 1 | J47: 0 | K47: 0 | L47: 7 | M47: 3 | N47: 4 | O47: 0 | P47: 1 | Q47: 1 | R47: 4 | S47: 0 | T47: 0 | U47: 5 | V47: 0 | W47: 0 | X47: 5 | Y47: 4 | Z47: 3 | AA47: 5 | AB47: 2 | AC47: 3 | AD47: 1 | AE47: 1 | AF47: 1 | AG47: 2 | AH47: 4 | AI47: 0 | AJ47: 1 | AK47: 1 | AL47: 0 | AM47: 11 | AN47: 2 | AO47: 2 | AP47: 2 | AQ47: 2 | AR47: 3 | AS47: 1 | AT47: 1 | AU47: 1 | AV47: 1 | AW47: 1 | AX47: =SUM(E47:AW47) -> 89
B48: 3 | C48: 3. Dr. H. AKIK ZAMAN, M.Pd.I. | E48: 0 | F48: 0 | G48: 1 | H48: 1 | I48: 0 | J48: 0 | K48: 0 | L48: 1 | M48: 0 | N48: 0 | O48: 0 | P48: 1 | Q48: 0 | R48: 0 | S48: 1 | T48: 0 | U48: 0 | V48: 0 | W48: 1 | X48: 1 | Y48: 0 | Z48: 0 | AA48: 1 | AB48: 0 | AC48: 0 | AD48: 0 | AE48: 0 | AF48: 0 | AG48: 1 | AH48: 1 | AI48: 1 | AJ48: 1 | AK48: 0 | AL48: 0 | AM48: 1 | AN48: 1 | AO48: 2 | AP48: 0 | AQ48: 0 | AR48: 0 | AS48: 1 | AT48: 1 | AU48: 0 | AV48: 0 | AW48: 0 | AX48: =SUM(E48:AW48) -> 18
B49: 4 | C49: 4. AHMAD RIFA'I, S.H. | E49: 0 | F49: 0 | G49: 0 | H49: 0 | I49: 0 | J49: 1 | K49: 0 | L49: 0 | M49: 0 | N49: 2 | O49: 0 | P49: 0 | Q49: 0 | R49: 0 | S49: 1 | T49: 0 | U49: 0 | V49: 0 | W49: 0 | X49: 6 | Y49: 0 | Z49: 1 | AA49: 2 | AB49: 2 | AC49: 0 | AD49: 1 | AE49: 1 | AF49: 2 | AG49: 1 | AH49: 1 | AI49: 0 | AJ49: 0 | AK49: 0 | AL49: 0 | AM49: 3 | AN49: 1 | AO49: 1 | AP49: 0 | AQ49: 0 | AR49: 0 | AS49: 5 | AT49: 0 | AU49: 2 | AV49: 1 | AW49: 0 | AX49: =SUM(E49:AW49) -> 34
B50: 5 | C50: 5. Drs. H. MAHFUD M.N. | E50: 0 | F50: 0 | G50: 0 | H50: 1 | I50: 1 | J50: 0 | K50: 0 | L50: 0 | M50: 0 | N50: 0 | O50: 1 | P50: 0 | Q50: 0 | R50: 0 | S50: 0 | T50: 0 | U50: 0 | V50: 0 | W50: 0 | X50: 1 | Y50: 0 | Z50: 0 | AA50: 0 | AB50: 2 | AC50: 0 | AD50: 0 | AE50: 0 | AF50: 0 | AG50: 0 | AH50: 0 | AI50: 0 | AJ50: 0 | AK50: 0 | AL50: 0 | AM50: 2 | AN50: 0 | AO50: 3 | AP50: 0 | AQ50: 1 | AR50: 0 | AS50: 2 | AT50: 0 | AU50: 1 | AV50: 1 | AW50: 0 | AX50: =SUM(E50:AW50) -> 16
B51: 6 | C51: 6. NURHAYATI, S.Pd. | E51: 0 | F51: 0 | G51: 0 | H51: 0 | I51: 0 | J51: 0 | K51: 0 | L51: 0 | M51: 1 | N51: 0 | O51: 3 | P51: 0 | Q51: 0 | R51: 2 | S51: 1 | T51: 0 | U51: 0 | V51: 0 | W51: 0 | X51: 0 | Y51: 0 | Z51: 0 | AA51: 1 | AB51: 0 | AC51: 1 | AD51: 0 | AE51: 0 | AF51: 2 | AG51: 0 | AH51: 0 | AI51: 1 | AJ51: 0 | AK51: 0 | AL51: 1 | AM51: 3 | AN51: 2 | AO51: 1 | AP51: 0 | AQ51: 0 | AR51: 1 | AS51: 2 | AT51: 0 | AU51: 0 | AV51: 1 | AW51: 1 | AX51: =SUM(E51:AW51) -> 24
...

Sheet TEMUGURUH
C2: Kecamatan | D2: SEMPU
C3: Kabupaten | D3: BANYUWANGI
C4: Provinsi | D4: JAWA TIMUR
C9: Kelurahan | D9: TEMUGURUH
A12: I | B12: DATA PEMILIH DAN PENGGUNAAN HAK PILIH | AL12: JUMLAH AKHIR
A13: A | B13: DATA PEMILIH | E13: TPS 001 | F13: TPS 002 | G13: TPS 003 | H13: TPS 004 | I13: TPS 005 | J13: TPS 006 | K13: TPS 007 | L13: TPS 008 | M13: TPS 009 | N13: TPS 010 | O13: TPS 011 | P13: TPS 012 | Q13: TPS 013 | R13: TPS 014 | S13: TPS 015 | T13: TPS 016 | U13: TPS 017 | V13: TPS 018 | W13: TPS 019 | X13: TPS 020 | Y13: TPS 021 | Z13: TPS 022 | AA13: TPS 023 | AB13: TPS 024 | AC13: TPS 025 | AD13: TPS 026 | AE13: TPS 027 | AF13: TPS 028 | AG13: TPS 029 | AH13: TPS 030 | AI13: TPS 031 | AJ13: TPS 032 | AK13: TPS 033
B14: Jumlah Pemilih dalam Daftar Pemilih Tetap (DPT) | D14: LK | E14: 149 | F14: 118 | G14: 119 | H14: 126 | I14: 112 | J14: 139 | K14: 141 | L14: 143 | M14: 110 | N14: 142 | O14: 114 | P14: 115 | Q14: 119 | R14: 146 | S14: 131 | T14: 105 | U14: 140 | V14: 152 | W14: 136 | X14: 121 | Y14: 108 | Z14: 112 | AA14: 148 | AB14: 143 | AC14: 149 | AD14: 144 | AE14: 146 | AF14: 150 | AG14: 154 | AH14: 146 | AI14: 158 | AJ14: 144 | AK14: 149 | AL14: =SUM(E14:AK14) -> 4429
D15: PR | E15: 136 | F15: 113 | G15: 123 | H15: 137 | I15: 113 | J15: 131 | K15: 142 | L15: 134 | M15: 141 | N15: 150 | O15: 121 | P15: 131 | Q15: 122 | R15: 144 | S15: 117 | T15: 95 | U15: 126 | V15: 138 | W15: 149 | X15: 115 | Y15: 94 | Z15: 117 | AA15: 135 | AB15: 152 | AC15: 150 | AD15: 146 | AE15: 151 | AF15: 145 | AG15: 143 | AH15: 130 | AI15: 137 | AJ15: 147 | AK15: 146 | AL15: =SUM(E15:AK15) -> 4371
D16: JML | E16: =SUM(E14:E15) -> 285 | F16: =SUM(F14:F15) -> 231 | G16: =SUM(G14:G15) -> 242 | H16: =SUM(H14:H15) -> 263 | I16: =SUM(I14:I15) -> 225 | J16: =SUM(J14:J15) -> 270 | K16: =SUM(K14:K15) -> 283 | L16: =SUM(L14:L15) -> 277 | ... AK16: =SUM(AK14:AK15) -> 295 | AL16: =SUM(E16:AK16) -> 8800
A18: B | B18: PENGGUNA HAK PILIH
B19: 1. | C19: Jumlah pengguna hak pilih dalam Daftar Pemilih Tetap (DPT) | D19: LK | E19: 112 | F19: 80 | G19: 88 | H19: 87 | I19: 80 | J19: 96 | K19: 104 | L19: 105 | M19: 81 | N19: 98 | O19: 77 | P19: 80 | Q19: 83 | R19: 86 | S19: 103 | T19: 71 | U19: 93 | V19: 100 | W19: 97 | X19: 68 | Y19: 67 | Z19: 79 | AA19: 105 | AB19: 90 | AC19: 99 | AD19: 146 | AE19: 112 | AF19: 90 | AG19: 118 | AH19: 100 | AI19: 106 | AJ19: 107 | AK19: 117 | AL19: =SUM(E19:AK19) -> 3125
D20: PR | E20: 98 | F20: 87 | G20: 90 | H20: 97 | I20: 81 | J20: 92 | K20: 110 | L20: 98 | M20: 104 | N20: 110 | O20: 99 | P20: 91 | Q20: 92 | R20: 96 | S20: 98 | T20: 76 | U20: 86 | V20: 94 | W20: 110 | X20: 77 | Y20: 75 | Z20: 86 | AA20: 108 | AB20: 106 | AC20: 119 | AD20: 66 | AE20: 128 | AF20: 95 | AG20: 119 | AH20: 95 | AI20: 104 | AJ20: 123 | AK20: 122 | AL20: =SUM(E20:AK20) -> 3232
D21: JML | E21: =SUM(E19:E20) -> 210 | F21: =SUM(F19:F20) -> 167 | G21: =SUM(G19:G20) -> 178 | H21: =SUM(H19:H20) -> 184 | I21: =SUM(I19:I20) -> 161 | J21: =SUM(J19:J20) -> 188 | K21: =SUM(K19:K20) -> 214 | L21: =SUM(L19:L20) -> 203 | ... AK21: =SUM(AK19:AK20) -> 239 | AL21: =SUM(E21:AK21) -> 6357
B22: 2. | C22: Jumlah pengguna hak pilih dalam Daftar Pemilih Tambahan (DPTb) | D22: LK | E22: 0 | F22: 0 | G22: 1 | H22: 0 | I22: 1 | J22: 1 | K22: 1 | L22: 0 | M22: 0 | N22: 0 | O22: 0 | P22: 0 | Q22: 0 | R22: 0 | S22: 0 | T22: 0 | U22: 0 | V22: 0 | W22: 0 | X22: 0 | Y22: 0 | Z22: 0 | AA22: 0 | AB22: 0 | AC22: 1 | AD22: 0 | AE22: 0 | AF22: 0 | AG22: 0 | AH22: 0 | AI22: 1 | AJ22: 0 | AK22: 0 | AL22: =SUM(E22:AK22) -> 6
D23: PR | E23: 0 | F23: 0 | G23: 1 | H23: 1 | I23: 0 | J23: 0 | K23: 0 | L23: 0 | M23: 0 | N23: 1 | O23: 0 | P23: 0 | Q23: 0 | R23: 0 | S23: 0 | T23: 0 | U23: 0 | V23: 0 | W23: 1 | X23: 0 | Y23: 0 | Z23: 1 | AA23: 0 | AB23: 0 | AC23: 0 | AD23: 0 | AE23: 0 | AF23: 0 | AG23: 1 | AH23: 1 | AI23: 0 | AJ23: 0 | AK23: 1 | AL23: =SUM(E23:AK23) -> 8
D24: JML | E24: =SUM(E22:E23) -> 0 | F24: =SUM(F22:F23) -> 0 | G24: =SUM(G22:G23) -> 2 | H24: =SUM(H22:H23) -> 1 | I24: =SUM(I22:I23) -> 1 | J24: =SUM(J22:J23) -> 1 | K24: =SUM(K22:K23) -> 1 | L24: =SUM(L22:L23) -> 0 | ... AK24: =SUM(AK22:AK23) -> 1 | AL24: =SUM(E24:AK24) -> 14
B25: 3. | C25: Jumlah pengguna hak pilih dalam Daftar Pemilih Khusus (DPK) | D25: LK | E25: 0 | F25: 0 | G25: 0 | H25: 1 | I25: 1 | J25: 2 | K25: 1 | L25: 2 | M25: 1 | N25: 1 | O25: 0 | P25: 1 | Q25: 1 | R25: 0 | S25: 1 | T25: 0 | U25: 0 | V25: 0 | W25: 0 | X25: 0 | Y25: 0 | Z25: 2 | AA25: 0 | AB25: 0 | AC25: 0 | AD25: 0 | AE25: 0 | AF25: 0 | AG25: 0 | AH25: 0 | AI25: 0 | AJ25: 2 | AK25: 2 | AL25: =SUM(E25:AK25) -> 18
D26: PR | E26: 0 | F26: 0 | G26: 2 | H26: 0 | I26: 2 | J26: 2 | K26: 1 | L26: 2 | M26: 3 | N26: 4 | O26: 0 | P26: 2 | Q26: 1 | R26: 0 | S26: 1 | T26: 1 | U26: 0 | V26: 0 | W26: 0 | X26: 0 | Y26: 0 | Z26: 2 | AA26: 0 | AB26: 0 | AC26: 0 | AD26: 0 | AE26: 0 | AF26: 0 | AG26: 0 | AH26: 1 | AI26: 0 | AJ26: 2 | AK26: 3 | AL26: =SUM(E26:AK26) -> 29
D27: JML | E27: =SUM(E25:E26) -> 0 | F27: =SUM(F25:F26) -> 0 | G27: =SUM(G25:G26) -> 2 | H27: =SUM(H25:H26) -> 1 | I27: =SUM(I25:I26) -> 3 | J27: =SUM(J25:J26) -> 4 | K27: =SUM(K25:K26) -> 2 | L27: =SUM(L25:L26) -> 4 | ... AK27: =SUM(AK25:AK26) -> 5 | AL27: =SUM(E27:AK27) -> 47
B28: 4. | C28: Jumlah Pengguna Hak Pilih (B.1+B.2+B.3) | D28: LK | E28: =SUM(E19,E22,E25) -> 112 | F28: =SUM(F19,F22,F25) -> 80 | G28: =SUM(G19,G22,G25) -> 89 | H28: =SUM(H19,H22,H25) -> 88 | I28: =SUM(I19,I22,I25) -> 82 | J28: =SUM(J19,J22,J25) -> 99 | K28: =SUM(K19,K22,K25) -> 106 | L28: =SUM(L19,L22,L25) -> 107 | ... AK28: =SUM(AK19,AK22,AK25) -> 119 | AL28: =SUM(E28:AK28) -> 3149
D29: PR | E29: =SUM(E20,E23,E26) -> 98 | F29: =SUM(F20,F23,F26) -> 87 | G29: =SUM(G20,G23,G26) -> 93 | H29: =SUM(H20,H23,H26) -> 98 | I29: =SUM(I20,I23,I26) -> 83 | J29: =SUM(J20,J23,J26) -> 94 | K29: =SUM(K20,K23,K26) -> 111 | L29: =SUM(L20,L23,L26) -> 100 | ... AK29: =SUM(AK20,AK23,AK26) -> 126 | AL29: =SUM(E29:AK29) -> 3269
D30: JML | E30: =SUM(E28:E29) -> 210 | F30: =SUM(F28:F29) -> 167 | G30: =SUM(G28:G29) -> 182 | H30: =SUM(H28:H29) -> 186 | I30: =SUM(I28:I29) -> 165 | J30: =SUM(J28:J29) -> 193 | K30: =SUM(K28:K29) -> 217 | L30: =SUM(L28:L29) -> 207 | ... AK30: =SUM(AK28:AK29) -> 245 | AL30: =SUM(E30:AK30) -> 6418
A32: II | B32: DATA PENGGUNAAN SURAT SUARA
A33: 1 | B33: Jumlah surat suara yang diterima, termasuk surat suara cadangan 2,5% dari DPT | E33: 291 | F33: 236 | G33: 247 | H33: 270 | I33: 229 | J33: 276 | K33: 289 | L33: 294 | M33: 247 | N33: 298 | O33: 240 | P33: 251 | Q33: 246 | R33: 296 | S33: 253 | T33: 204 | U33: 272 | V33: 294 | W33: 291 | X33: 241 | Y33: 208 | Z33: 234 | AA33: 280 | AB33: 311 | AC33: 305 | AD33: 296 | AE33: 293 | AF33: 301 | AG33: 293 | AH33: 282 | AI33: 291 | AJ33: 280 | AK33: 301 | AL33: =SUM(E33:AK33) -> 8940
A34: 2 | B34: Jumlah surat suara yang digunakan | E34: 210 | F34: 167 | G34: 182 | H34: 186 | I34: 165 | J34: 193 | K34: 217 | L34: 207 | M34: 189 | N34: 214 | O34: 176 | P34: 174 | Q34: 177 | R34: 182 | S34: 203 | T34: 148 | U34: 179 | V34: 194 | W34: 208 | X34: 145 | Y34: 142 | Z34: 170 | AA34: 213 | AB34: 196 | AC34: 219 | AD34: 212 | AE34: 240 | AF34: 185 | AG34: 238 | AH34: 197 | AI34: 211 | AJ34: 234 | AK34: 245 | AL34: =SUM(E34:AK34) -> 6418
A35: 3 | B35: Jumlah surat suara dikembalikan oleh pemilih (karena rusak atau keliru coblos) | E35: 0 | F35: 0 | G35: 0 | H35: 0 | I35: 0 | J35: 1 | K35: 1 | L35: 1 | M35: 0 | N35: 1 | O35: 0 | P35: 0 | Q35: 0 | R35: 1 | S35: 0 | T35: 0 | U35: 0 | V35: 0 | W35: 0 | X35: 0 | Y35: 0 | Z35: 1 | AA35: 0 | AB35: 0 | AC35: 0 | AD35: 0 | AE35: 0 | AF35: 1 | AG35: 0 | AH35: 0 | AI35: 2 | AJ35: 0 | AK35: 3 | AL35: =SUM(E35:AK35) -> 12
A36: 4 | B36: Jumlah surat suara yang tidak digunakan/tidak terpakai, termasuk sisa surat suara cadangan | E36: =E33-(E34+E35) -> 81 | F36: =F33-(F34+F35) -> 69 | G36: =G33-(G34+G35) -> 65 | H36: =H33-(H34+H35) -> 84 | I36: =I33-(I34+I35) -> 64 | J36: =J33-(J34+J35) -> 82 | K36: =K33-(K34+K35) -> 71 | L36: =L33-(L34+L35) -> 86 | ... AK36: =AK33-(AK34+AK35) -> 53 | AL36: =SUM(E36:AK36) -> 2510
A38: III | B38: DATA PEMILIH DISABILITAS
B39: Jumlah seluruh Pemilih disabilitas yang menggunakan hak pilih | D39: LK | E39: 0 | F39: 0 | G39: 0 | H39: 0 | I39: 0 | J39: 0 | K39: 1 | L39: 0 | M39: 1 | N39: 0 | O39: 0 | P39: 0 | Q39: 0 | R39: 0 | S39: 0 | T39: 0 | U39: 0 | V39: 0 | W39: 0 | X39: 0 | Y39: 0 | Z39: 1 | AA39: 0 | AB39: 0 | AC39: 0 | AD39: 0 | AE39: 0 | AF39: 2 | AG39: 0 | AH39: 0 | AI39: 0 | AJ39: 0 | AK39: 0 | AL39: =SUM(E39:AK39) -> 5
D40: PR | E40: 0 | F40: 0 | G40: 0 | H40: 0 | I40: 0 | J40: 0 | K40: 0 | L40: 0 | M40: 0 | N40: 0 | O40: 0 | P40: 0 | Q40: 0 | R40: 0 | S40: 0 | T40: 0 | U40: 0 | V40: 0 | W40: 0 | X40: 0 | Y40: 0 | Z40: 0 | AA40: 0 | AB40: 0 | AC40: 0 | AD40: 0 | AE40: 1 | AF40: 1 | AG40: 0 | AH40: 0 | AI40: 0 | AJ40: 0 | AK40: 0 | AL40: =SUM(E40:AK40) -> 2
D41: JML | E41: =SUM(E39:E40) -> 0 | F41: =SUM(F39:F40) -> 0 | G41: =SUM(G39:G40) -> 0 | H41: =SUM(H39:H40) -> 0 | I41: =SUM(I39:I40) -> 0 | J41: =SUM(J39:J40) -> 0 | K41: =SUM(K39:K40) -> 1 | L41: =SUM(L39:L40) -> 0 | ... AK41: =SUM(AK39:AK40) -> 0 | AL41: =SUM(E41:AK41) -> 7
A43: IV | B43: DATA RINCIAN PEROLEHAN SUARA PASANGAN CALON BUPATI DAN WAKIL BUPATI
A44: NOMOR DAN NAMA CALON
A45: A.1 | B45: 1. | C45: Partai Kebangkitan Bangsa | E45: 3 | F45: 0 | G45: 6 | H45: 10 | I45: 5 | J45: 7 | K45: 2 | L45: 14 | M45: 9 | N45: 16 | O45: 14 | P45: 21 | Q45: 6 | R45: 10 | S45: 13 | T45: 7 | U45: 8 | V45: 7 | W45: 4 | X45: 8 | Y45: 5 | Z45: 13 | AA45: 6 | AB45: 5 | AC45: 6 | AD45: 6 | AE45: 12 | AF45: 11 | AG45: 2 | AH45: 3 | AI45: 4 | AJ45: 9 | AK45: 8 | AL45: =SUM(E45:AK45) -> 260
A46: A.2 | B46: 1 | C46: 1. Dr. Hj. NIHAYATUL WAFIROH, M.A. | E46: 1 | F46: 3 | G46: 10 | H46: 15 | I46: 7 | J46: 21 | K46: 11 | L46: 24 | M46: 27 | N46: 22 | O46: 18 | P46: 21 | Q46: 38 | R46: 37 | S46: 26 | T46: 18 | U46: 17 | V46: 8 | W46: 24 | X46: 19 | Y46: 6 | Z46: 30 | AA46: 22 | AB46: 18 | AC46: 12 | AD46: 14 | AE46: 16 | AF46: 15 | AG46: 7 | AH46: 1 | AI46: 0 | AJ46: 6 | AK46: 12 | AL46: =SUM(E46:AK46) -> 526
B47: 2 | C47: 2. H. M. NASIM KHAN | E47: 2 | F47: 2 | G47: 4 | H47: 2 | I47: 6 | J47: 7 | K47: 3 | L47: 8 | M47: 9 | N47: 7 | O47: 1 | P47: 3 | Q47: 7 | R47: 3 | S47: 4 | T47: 2 | U47: 3 | V47: 3 | W47: 2 | X47: 3 | Y47: 0 | Z47: 6 | AA47: 0 | AB47: 2 | AC47: 0 | AD47: 2 | AE47: 1 | AF47: 5 | AG47: 1 | AH47: 1 | AI47: 1 | AJ47: 2 | AK47: 0 | AL47: =SUM(E47:AK47) -> 102
B48: 3 | C48: 3. Dr. H. AKIK ZAMAN, M.Pd.I. | E48: 0 | F48: 1 | G48: 1 | H48: 0 | I48: 2 | J48: 0 | K48: 1 | L48: 2 | M48: 3 | N48: 0 | O48: 1 | P48: 2 | Q48: 0 | R48: 2 | S48: 3 | T48: 0 | U48: 0 | V48: 1 | W48: 1 | X48: 0 | Y48: 0 | Z48: 0 | AA48: 0 | AB48: 0 | AC48: 0 | AD48: 0 | AE48: 0 | AF48: 0 | AG48: 0 | AH48: 0 | AI48: 0 | AJ48: 1 | AK48: 1 | AL48: =SUM(E48:AK48) -> 22
B49: 4 | C49: 4. AHMAD RIFA'I, S.H. | E49: 1 | F49: 0 | G49: 1 | H49: 0 | I49: 0 | J49: 0 | K49: 0 | L49: 0 | M49: 2 | N49: 2 | O49: 0 | P49: 0 | Q49: 2 | R49: 1 | S49: 2 | T49: 0 | U49: 0 | V49: 0 | W49: 1 | X49: 0 | Y49: 0 | Z49: 0 | AA49: 0 | AB49: 0 | AC49: 0 | AD49: 0 | AE49: 2 | AF49: 0 | AG49: 0 | AH49: 0 | AI49: 0 | AJ49: 1 | AK49: 0 | AL49: =SUM(E49:AK49) -> 15
B50: 5 | C50: 5. Drs. H. MAHFUD M.N. | E50: 0 | F50: 0 | G50: 1 | H50: 0 | I50: 0 | J50: 1 | K50: 1 | L50: 0 | M50: 0 | N50: 1 | O50: 0 | P50: 2 | Q50: 1 | R50: 2 | S50: 0 | T50: 0 | U50: 0 | V50: 0 | W50: 0 | X50: 0 | Y50: 0 | Z50: 1 | AA50: 0 | AB50: 0 | AC50: 1 | AD50: 1 | AE50: 0 | AF50: 1 | AG50: 0 | AH50: 0 | AI50: 0 | AJ50: 0 | AK50: 0 | AL50: =SUM(E50:AK50) -> 13
B51: 6 | C51: 6. NURHAYATI, S.Pd. | E51: 0 | F51: 0 | G51: 1 | H51: 0 | I51: 0 | J51: 0 | K51: 0 | L51: 2 | M51: 1 | N51: 0 | O51: 0 | P51: 0 | Q51: 1 | R51: 0 | S51: 0 | T51: 0 | U51: 1 | V51: 1 | W51: 0 | X51: 0 | Y51: 0 | Z51: 0 | AA51: 1 | AB51: 0 | AC51: 0 | AD51: 0 | AE51: 0 | AF51: 0 | AG51: 0 | AH51: 0 | AI51: 0 | AJ51: 0 | AK51: 0 | AL51: =SUM(E51:AK51) -> 8
...

Sheet GENDOH
C2: Kecamatan | D2: SEMPU
C3: Kabupaten | D3: BANYUWANGI
C4: Provinsi | D4: JAWA TIMUR
C9: Kelurahan | D9: GENDOH
A12: I | B12: DATA PEMILIH DAN PENGGUNAAN HAK PILIH | AG12: JUMLAH AKHIR
A13: A | B13: DATA PEMILIH | E13: TPS 001 | F13: TPS 002 | G13: TPS 003 | H13: TPS 004 | I13: TPS 005 | J13: TPS 006 | K13: TPS 007 | L13: TPS 008 | M13: TPS 009 | N13: TPS 010 | O13: TPS 011 | P13: TPS 012 | Q13: TPS 013 | R13: TPS 014 | S13: TPS 015 | T13: TPS 016 | U13: TPS 017 | V13: TPS 018 | W13: TPS 019 | X13: TPS 020 | Y13: TPS 021 | Z13: TPS 022 | AA13: TPS 023 | AB13: TPS 024 | AC13: TPS 025 | AD13: TPS 026 | AE13: TPS 027 | AF13: TPS 028
