Workbook

Sheet DPR RI
C8: Kecamatan | D8: BANGOREJO
C9: Kabupaten | D9: BANYUWANGI
C10: Provinsi | D10: JAWA TIMUR
A12: I | B12: DATA PEMILIH DAN PENGGUNAAN HAK PILIH | E12: JUMLAH AKHIR
A13: A | B13: DATA PEMILIH
B14: Jumlah Pemilih dalam Daftar Pemilih Tetap (DPT) | D14: LK | E14: =BANGOREJO!AG14+KEBONDALEM!AH14+RINGINTELU!Z14+SAMBIMULYO!AF14+SAMBIREJO!AF14+SUKOREJO!AB14+TEMUREJO!AU14 -> 26100
D15: PR | E15: =BANGOREJO!AG15+KEBONDALEM!AH15+RINGINTELU!Z15+SAMBIMULYO!AF15+SAMBIREJO!AF15+SUKOREJO!AB15+TEMUREJO!AU15 -> 25979
D16: JML | E16: =SUM(E14:E15) -> 52079
A18: B | B18: PENGGUNA HAK PILIH
B19: 1. | C19: Jumlah pengguna hak pilih dalam Daftar Pemilih Tetap (DPT) | D19: LK | E19: =BANGOREJO!AG19+KEBONDALEM!AH19+RINGINTELU!Z19+SAMBIMULYO!AF19+SAMBIREJO!AF19+SUKOREJO!AB19+TEMUREJO!AU19 -> 19808
D20: PR | E20: =BANGOREJO!AG20+KEBONDALEM!AH20+RINGINTELU!Z20+SAMBIMULYO!AF20+SAMBIREJO!AF20+SUKOREJO!AB20+TEMUREJO!AU20 -> 20559
D21: JML | E21: =SUM(E19:E20) -> 40367
B22: 2. | C22: Jumlah pengguna hak pilih dalam Daftar Pemilih Tambahan (DPTb) | D22: LK | E22: =BANGOREJO!AG22+KEBONDALEM!AH22+RINGINTELU!Z22+SAMBIMULYO!AF22+SAMBIREJO!AF22+SUKOREJO!AB22+TEMUREJO!AU22 -> 12
D23: PR | E23: =BANGOREJO!AG23+KEBONDALEM!AH23+RINGINTELU!Z23+SAMBIMULYO!AF23+SAMBIREJO!AF23+SUKOREJO!AB23+TEMUREJO!AU23 -> 14
D24: JML | E24: =SUM(E22:E23) -> 26
B25: 3. | C25: Jumlah pengguna hak pilih dalam Daftar Pemilih Khusus (DPK) | D25: LK | E25: =BANGOREJO!AG25+KEBONDALEM!AH25+RINGINTELU!Z25+SAMBIMULYO!AF25+SAMBIREJO!AF25+SUKOREJO!AB25+TEMUREJO!AU25 -> 186
D26: PR | E26: =BANGOREJO!AG26+KEBONDALEM!AH26+RINGINTELU!Z26+SAMBIMULYO!AF26+SAMBIREJO!AF26+SUKOREJO!AB26+TEMUREJO!AU26 -> 211
D27: JML | E27: =SUM(E25:E26) -> 397
B28: 4. | C28: Jumlah Pengguna Hak Pilih (B.1+B.2+B.3) | D28: LK | E28: =E19+E22+E25 -> 20006
D29: PR | E29: =E20+E23+E26 -> 20784
D30: JML | E30: =SUM(E28:E29) -> 40790
A32: II | B32: DATA PENGGUNAAN SURAT SUARA
A33: 1 | B33: Jumlah surat suara yang diterima, termasuk surat suara cadangan 2,5% dari DPT | E33: =BANGOREJO!AG33+KEBONDALEM!AH33+RINGINTELU!Z33+SAMBIMULYO!AF33+SAMBIREJO!AF33+SUKOREJO!AB33+TEMUREJO!AU33 -> 53172
A34: 2 | B34: Jumlah surat suara yang digunakan | E34: =BANGOREJO!AG34+KEBONDALEM!AH34+RINGINTELU!Z34+SAMBIMULYO!AF34+SAMBIREJO!AF34+SUKOREJO!AB34+TEMUREJO!AU34 -> 40790
A35: 3 | B35: Jumlah surat suara dikembalikan oleh pemilih (karena rusak atau keliru coblos) | E35: =BANGOREJO!AG35+KEBONDALEM!AH35+RINGINTELU!Z35+SAMBIMULYO!AF35+SAMBIREJO!AF35+SUKOREJO!AB35+TEMUREJO!AU35 -> 180
A36: 4 | B36: Jumlah surat suara yang tidak digunakan/tidak terpakai, termasuk sisa surat suara cadangan | E36: =E33-(E34+E35) -> 12202
A38: III | B38: DATA PEMILIH DISABILITAS
B39: Jumlah seluruh Pemilih disabilitas yang menggunakan hak pilih | D39: LK | E39: =BANGOREJO!AG39+KEBONDALEM!AH39+RINGINTELU!Z39+SAMBIMULYO!AF39+SAMBIREJO!AF39+SUKOREJO!AB39+TEMUREJO!AU39 -> 33
D40: PR | E40: =BANGOREJO!AG40+KEBONDALEM!AH40+RINGINTELU!Z40+SAMBIMULYO!AF40+SAMBIREJO!AF40+SUKOREJO!AB40+TEMUREJO!AU40 -> 38
D41: JML | E41: =SUM(E39:E40) -> 71
A43: IV | B43: DATA RINCIAN PEROLEHAN SUARA PASANGAN CALON BUPATI DAN WAKIL BUPATI
A44: NOMOR DAN NAMA CALON
A45: A.1 | B45: 1. | C45: Partai Kebangkitan Bangsa | E45: =BANGOREJO!AG45+KEBONDALEM!AH45+RINGINTELU!Z45+SAMBIMULYO!AF45+SAMBIREJO!AF45+SUKOREJO!AB45+TEMUREJO!AU45 -> 920
A46: A.2 | B46: 1 | C46: 1. Dr. Hj. NIHAYATUL WAFIROH, M.A. | E46: =BANGOREJO!AG46+KEBONDALEM!AH46+RINGINTELU!Z46+SAMBIMULYO!AF46+SAMBIREJO!AF46+SUKOREJO!AB46+TEMUREJO!AU46 -> 3445
B47: 2 | C47: 2. H. M. NASIM KHAN | E47: =BANGOREJO!AG47+KEBONDALEM!AH47+RINGINTELU!Z47+SAMBIMULYO!AF47+SAMBIREJO!AF47+SUKOREJO!AB47+TEMUREJO!AU47 -> 561
B48: 3 | C48: 3. Dr. H. AKIK ZAMAN, M.Pd.I. | E48: =BANGOREJO!AG48+KEBONDALEM!AH48+RINGINTELU!Z48+SAMBIMULYO!AF48+SAMBIREJO!AF48+SUKOREJO!AB48+TEMUREJO!AU48 -> 80
B49: 4 | C49: 4. AHMAD RIFA'I, S.H. | E49: =BANGOREJO!AG49+KEBONDALEM!AH49+RINGINTELU!Z49+SAMBIMULYO!AF49+SAMBIREJO!AF49+SUKOREJO!AB49+TEMUREJO!AU49 -> 134
B50: 5 | C50: 5. Drs. H. MAHFUD M.N. | E50: =BANGOREJO!AG50+KEBONDALEM!AH50+RINGINTELU!Z50+SAMBIMULYO!AF50+SAMBIREJO!AF50+SUKOREJO!AB50+TEMUREJO!AU50 -> 93
B51: 6 | C51: 6. NURHAYATI, S.Pd. | E51: =BANGOREJO!AG51+KEBONDALEM!AH51+RINGINTELU!Z51+SAMBIMULYO!AF51+SAMBIREJO!AF51+SUKOREJO!AB51+TEMUREJO!AU51 -> 94
B52: 7 | C52: 7. MAFTUHA KISWAH | E52: =BANGOREJO!AG52+KEBONDALEM!AH52+RINGINTELU!Z52+SAMBIMULYO!AF52+SAMBIREJO!AF52+SUKOREJO!AB52+TEMUREJO!AU52 -> 57
...

Sheet BANGOREJO
C2: Kecamatan | D2: BANGOREJO
C3: Kabupaten | D3: BANYUWANGI
C4: Provinsi | D4: JAWA TIMUR
C9: Kelurahan | D9: BANGOREJO
A12: I | B12: DATA PEMILIH DAN PENGGUNAAN HAK PILIH | AG12: JUMLAH AKHIR
A13: A | B13: DATA PEMILIH | E13: TPS 001 | F13: TPS 002 | G13: TPS 003 | H13: TPS 004 | I13: TPS 005 | J13: TPS 006 | K13: TPS 007 | L13: TPS 008 | M13: TPS 009 | N13: TPS 010 | O13: TPS 011 | P13: TPS 012 | Q13: TPS 013 | R13: TPS 014 | S13: TPS 015 | T13: TPS 016 | U13: TPS 017 | V13: TPS 018 | W13: TPS 019 | X13: TPS 020 | Y13: TPS 021 | Z13: TPS 022 | AA13: TPS 023 | AB13: TPS 024 | AC13: TPS 025 | AD13: TPS 026 | AE13: TPS 027 | AF13: TPS 028
B14: Jumlah Pemilih dalam Daftar Pemilih Tetap (DPT) | D14: LK | E14: 129 | F14: 130 | G14: 151 | H14: 139 | I14: 144 | J14: 124 | K14: 119 | L14: 140 | M14: 147 | N14: 146 | O14: 130 | P14: 144 | Q14: 144 | R14: 139 | S14: 145 | T14: 135 | U14: 123 | V14: 140 | W14: 134 | X14: 140 | Y14: 116 | Z14: 122 | AA14: 126 | AB14: 120 | AC14: 144 | AD14: 112 | AE14: 86 | AF14: 101 | AG14: =SUM(E14:AF14) -> 3670
D15: PR | E15: 136 | F15: 138 | G15: 145 | H15: 128 | I15: 145 | J15: 137 | K15: 134 | L15: 140 | M15: 151 | N15: 147 | O15: 143 | P15: 140 | Q15: 145 | R15: 147 | S15: 149 | T15: 108 | U15: 118 | V15: 157 | W15: 155 | X15: 131 | Y15: 104 | Z15: 111 | AA15: 123 | AB15: 122 | AC15: 139 | AD15: 124 | AE15: 87 | AF15: 115 | AG15: =SUM(E15:AF15) -> 3719
D16: JML | E16: =SUM(E14:E15) -> 265 | F16: =SUM(F14:F15) -> 268 | G16: =SUM(G14:G15) -> 296 | H16: =SUM(H14:H15) -> 267 | I16: =SUM(I14:I15) -> 289 | J16: =SUM(J14:J15) -> 261 | K16: =SUM(K14:K15) -> 253 | L16: =SUM(L14:L15) -> 280 | ... AF16: =SUM(AF14:AF15) -> 216 | AG16: =SUM(E16:AF16) -> 7389
A18: B | B18: PENGGUNA HAK PILIH
B19: 1. | C19: Jumlah pengguna hak pilih dalam Daftar Pemilih Tetap (DPT) | D19: LK | E19: 100 | F19: 98 | G19: 110 | H19: 122 | I19: 111 | J19: 113 | K19: 99 | L19: 115 | M19: 124 | N19: 101 | O19: 102 | P19: 108 | Q19: 115 | R19: 110 | S19: 102 | T19: 88 | U19: 79 | V19: 109 | W19: 101 | X19: 120 | Y19: 95 | Z19: 90 | AA19: 87 | AB19: 94 | AC19: 99 | AD19: 77 | AE19: 64 | AF19: 78 | AG19: =SUM(E19:AF19) -> 2811
D20: PR | E20: 120 | F20: 108 | G20: 122 | H20: 112 | I20: 112 | J20: 121 | K20: 106 | L20: 118 | M20: 127 | N20: 121 | O20: 112 | P20: 114 | Q20: 126 | R20: 119 | S20: 120 | T20: 80 | U20: 93 | V20: 129 | W20: 125 | X20: 112 | Y20: 82 | Z20: 87 | AA20: 87 | AB20: 96 | AC20: 105 | AD20: 95 | AE20: 61 | AF20: 91 | AG20: =SUM(E20:AF20) -> 3001
D21: JML | E21: =SUM(E19:E20) -> 220 | F21: =SUM(F19:F20) -> 206 | G21: =SUM(G19:G20) -> 232 | H21: =SUM(H19:H20) -> 234 | I21: =SUM(I19:I20) -> 223 | J21: =SUM(J19:J20) -> 234 | K21: =SUM(K19:K20) -> 205 | L21: =SUM(L19:L20) -> 233 | ... AF21: =SUM(AF19:AF20) -> 169 | AG21: =SUM(E21:AF21) -> 5812
B22: 2. | C22: Jumlah pengguna hak pilih dalam Daftar Pemilih Tambahan (DPTb) | D22: LK | T22: 0 | U22: 0 | V22: 0 | W22: 0 | X22: 0 | Y22: 0 | Z22: 0 | AA22: 0 | AB22: 0 | AC22: 0 | AD22: 1 | AE22: 0 | AF22: 0 | AG22: =SUM(E22:AF22) -> 1
D23: PR | T23: 0 | U23: 0 | V23: 0 | W23: 0 | X23: 0 | Y23: 0 | Z23: 0 | AA23: 0 | AB23: 0 | AC23: 0 | AD23: 1 | AE23: 0 | AF23: 0 | AG23: =SUM(E23:AF23) -> 1
D24: JML | E24: =SUM(E22:E23) -> 0 | F24: =SUM(F22:F23) -> 0 | G24: =SUM(G22:G23) -> 0 | H24: =SUM(H22:H23) -> 0 | I24: =SUM(I22:I23) -> 0 | J24: =SUM(J22:J23) -> 0 | K24: =SUM(K22:K23) -> 0 | L24: =SUM(L22:L23) -> 0 | ... AF24: =SUM(AF22:AF23) -> 0 | AG24: =SUM(E24:AF24) -> 2
B25: 3. | C25: Jumlah pengguna hak pilih dalam Daftar Pemilih Khusus (DPK) | D25: LK | E25: 2 | F25: 3 | G25: 3 | H25: 0 | I25: 0 | J25: 2 | K25: 0 | L25: 0 | M25: 1 | N25: 1 | O25: 3 | P25: 2 | Q25: 5 | R25: 1 | S25: 2 | T25: 5 | U25: 2 | V25: 2 | W25: 2 | X25: 0 | Y25: 2 | Z25: 2 | AA25: 2 | AB25: 1 | AC25: 1 | AD25: 4 | AE25: 1 | AF25: 0 | AG25: =SUM(E25:AF25) -> 49
D26: PR | E26: 2 | F26: 1 | G26: 1 | H26: 2 | I26: 0 | J26: 2 | K26: 0 | L26: 0 | M26: 3 | N26: 0 | O26: 1 | P26: 6 | Q26: 4 | R26: 0 | S26: 2 | T26: 2 | U26: 1 | V26: 2 | W26: 2 | X26: 0 | Y26: 2 | Z26: 0 | AA26: 5 | AB26: 1 | AC26: 1 | AD26: 1 | AE26: 4 | AF26: 0 | AG26: =SUM(E26:AF26) -> 45
D27: JML | E27: =SUM(E25:E26) -> 4 | F27: =SUM(F25:F26) -> 4 | G27: =SUM(G25:G26) -> 4 | H27: =SUM(H25:H26) -> 2 | I27: =SUM(I25:I26) -> 0 | J27: =SUM(J25:J26) -> 4 | K27: =SUM(K25:K26) -> 0 | L27: =SUM(L25:L26) -> 0 | ... AF27: =SUM(AF25:AF26) -> 0 | AG27: =SUM(E27:AF27) -> 94
B28: 4. | C28: Jumlah Pengguna Hak Pilih (B.1+B.2+B.3) | D28: LK | E28: =SUM(E19,E22,E25) -> 102 | F28: =SUM(F19,F22,F25) -> 101 | G28: =SUM(G19,G22,G25) -> 113 | H28: =SUM(H19,H22,H25) -> 122 | I28: =SUM(I19,I22,I25) -> 111 | J28: =SUM(J19,J22,J25) -> 115 | K28: =SUM(K19,K22,K25) -> 99 | L28: =SUM(L19,L22,L25) -> 115 | ... AF28: =SUM(AF19,AF22,AF25) -> 78 | AG28: =SUM(E28:AF28) -> 2861
D29: PR | E29: =SUM(E20,E23,E26) -> 122 | F29: =SUM(F20,F23,F26) -> 109 | G29: =SUM(G20,G23,G26) -> 123 | H29: =SUM(H20,H23,H26) -> 114 | I29: =SUM(I20,I23,I26) -> 112 | J29: =SUM(J20,J23,J26) -> 123 | K29: =SUM(K20,K23,K26) -> 106 | L29: =SUM(L20,L23,L26) -> 118 | ... AF29: =SUM(AF20,AF23,AF26) -> 91 | AG29: =SUM(E29:AF29) -> 3047
D30: JML | E30: =SUM(E28:E29) -> 224 | F30: =SUM(F28:F29) -> 210 | G30: =SUM(G28:G29) -> 236 | H30: =SUM(H28:H29) -> 236 | I30: =SUM(I28:I29) -> 223 | J30: =SUM(J28:J29) -> 238 | K30: =SUM(K28:K29) -> 205 | L30: =SUM(L28:L29) -> 233 | ... AF30: =SUM(AF28:AF29) -> 169 | AG30: =SUM(E30:AF30) -> 5908
A32: II | B32: DATA PENGGUNAAN SURAT SUARA
A33: 1 | B33: Jumlah surat suara yang diterima, termasuk surat suara cadangan 2,5% dari DPT | E33: 271 | F33: 274 | G33: 302 | H33: 273 | I33: 293 | J33: 267 | K33: 254 | L33: 284 | M33: 304 | N33: 299 | O33: 278 | P33: 290 | Q33: 295 | R33: 291 | S33: 300 | T33: 248 | U33: 246 | V33: 303 | W33: 295 | X33: 277 | Y33: 225 | Z33: 238 | AA33: 254 | AB33: 247 | AC33: 288 | AD33: 240 | AE33: 177 | AF33: 221 | AG33: =SUM(E33:AF33) -> 7534
A34: 2 | B34: Jumlah surat suara yang digunakan | E34: 224 | F34: 210 | G34: 236 | H34: 236 | I34: 223 | J34: 238 | K34: 205 | L34: 233 | M34: 255 | N34: 223 | O34: 218 | P34: 230 | Q34: 250 | R34: 230 | S34: 226 | T34: 175 | U34: 175 | V34: 242 | W34: 230 | X34: 232 | Y34: 181 | Z34: 179 | AA34: 181 | AB34: 192 | AC34: 206 | AD34: 179 | AE34: 130 | AF34: 169 | AG34: =SUM(E34:AF34) -> 5908
A35: 3 | B35: Jumlah surat suara dikembalikan oleh pemilih (karena rusak atau keliru coblos) | E35: 25 | F35: 0 | G35: 0 | H35: 3 | I35: 0 | J35: 0 | K35: 1 | L35: 0 | M35: 0 | N35: 0 | O35: 2 | P35: 0 | Q35: 0 | R35: 0 | S35: 0 | T35: 1 | U35: 1 | V35: 0 | W35: 2 | X35: 0 | Y35: 0 | Z35: 1 | AA35: 1 | AB35: 0 | AC35: 0 | AD35: 0 | AE35: 0 | AF35: 0 | AG35: =SUM(E35:AF35) -> 37
A36: 4 | B36: Jumlah surat suara yang tidak digunakan/tidak terpakai, termasuk sisa surat suara cadangan | E36: =E33-(E34+E35) -> 22 | F36: =F33-(F34+F35) -> 64 | G36: =G33-(G34+G35) -> 66 | H36: =H33-(H34+H35) -> 34 | I36: =I33-(I34+I35) -> 70 | J36: =J33-(J34+J35) -> 29 | K36: =K33-(K34+K35) -> 48 | L36: =L33-(L34+L35) -> 51 | ... AF36: =AF33-(AF34+AF35) -> 52 | AG36: =SUM(E36:AF36) -> 1589
A38: III | B38: DATA PEMILIH DISABILITAS
B39: Jumlah seluruh Pemilih disabilitas yang menggunakan hak pilih | D39: LK | T39: 0 | U39: 0 | V39: 3 | W39: 0 | X39: 0 | Y39: 0 | Z39: 0 | AA39: 0 | AB39: 1 | AC39: 0 | AD39: 0 | AE39: 0 | AF39: 0 | AG39: =SUM(E39:AF39) -> 4
D40: PR | R40: 1 | T40: 1 | U40: 0 | V40: 2 | W40: 0 | X40: 0 | Y40: 0 | Z40: 0 | AA40: 0 | AB40: 1 | AC40: 0 | AD40: 0 | AE40: 0 | AF40: 0 | AG40: =SUM(E40:AF40) -> 5
D41: JML | E41: =SUM(E39:E40) -> 0 | F41: =SUM(F39:F40) -> 0 | G41: =SUM(G39:G40) -> 0 | H41: =SUM(H39:H40) -> 0 | I41: =SUM(I39:I40) -> 0 | J41: =SUM(J39:J40) -> 0 | K41: =SUM(K39:K40) -> 0 | L41: =SUM(L39:L40) -> 0 | ... AF41: =SUM(AF39:AF40) -> 0 | AG41: =SUM(E41:AF41) -> 9
A43: IV | B43: DATA RINCIAN PEROLEHAN SUARA PASANGAN CALON BUPATI DAN WAKIL BUPATI
A44: NOMOR DAN NAMA CALON
A45: A.1 | B45: 1. | C45: Partai Kebangkitan Bangsa | E45: 13 | F45: 2 | G45: 4 | H45: 12 | I45: 2 | J45: 4 | K45: 3 | L45: 5 | M45: 0 | N45: 3 | O45: 10 | P45: 9 | Q45: 2 | R45: 6 | S45: 6 | T45: 2 | U45: 1 | V45: 3 | W45: 6 | X45: 13 | Y45: 1 | Z45: 2 | AA45: 4 | AB45: 1 | AC45: 8 | AD45: 5 | AE45: 2 | AF45: 1 | AG45: =SUM(E45:AF45) -> 130
A46: A.2 | B46: 1 | C46: 1. Dr. Hj. NIHAYATUL WAFIROH, M.A. | E46: 37 | F46: 20 | G46: 14 | H46: 29 | I46: 4 | J46: 18 | K46: 7 | L46: 14 | M46: 18 | N46: 13 | O46: 28 | P46: 27 | Q46: 7 | R46: 9 | S46: 10 | T46: 1 | U46: 7 | V46: 9 | W46: 13 | X46: 40 | Y46: 9 | Z46: 5 | AA46: 7 | AB46: 5 | AC46: 17 | AD46: 0 | AE46: 14 | AF46: 1 | AG46: =SUM(E46:AF46) -> 383
B47: 2 | C47: 2. H. M. NASIM KHAN | E47: 0 | F47: 3 | G47: 0 | H47: 2 | I47: 4 | J47: 4 | K47: 0 | L47: 4 | M47: 1 | N47: 1 | O47: 3 | P47: 9 | Q47: 7 | R47: 6 | S47: 0 | T47: 1 | U47: 0 | V47: 3 | W47: 2 | X47: 2 | Y47: 0 | Z47: 1 | AA47: 1 | AB47: 0 | AC47: 6 | AD47: 2 | AE47: 12 | AF47: 0 | AG47: =SUM(E47:AF47) -> 74
B48: 3 | C48: 3. Dr. H. AKIK ZAMAN, M.Pd.I. | E48: 1 | F48: 1 | G48: 1 | H48: 2 | I48: 0 | J48: 0 | K48: 0 | L48: 0 | M48: 0 | N48: 0 | O48: 0 | P48: 0 | Q48: 0 | R48: 0 | S48: 1 | T48: 0 | U48: 1 | V48: 0 | W48: 1 | X48: 3 | Y48: 0 | Z48: 0 | AA48: 0 | AB48: 2 | AC48: 0 | AD48: 0 | AE48: 0 | AF48: 2 | AG48: =SUM(E48:AF48) -> 15
B49: 4 | C49: 4. AHMAD RIFA'I, S.H. | E49: 1 | F49: 0 | G49: 0 | H49: 0 | I49: 0 | J49: 0 | K49: 0 | L49: 1 | M49: 1 | N49: 1 | O49: 1 | P49: 0 | Q49: 1 | R49: 1 | S49: 0 | T49: 0 | U49: 1 | V49: 0 | W49: 0 | X49: 1 | Y49: 0 | Z49: 0 | AA49: 0 | AB49: 1 | AC49: 0 | AD49: 1 | AE49: 1 | AF49: 1 | AG49: =SUM(E49:AF49) -> 13
B50: 5 | C50: 5. Drs. H. MAHFUD M.N. | E50: 0 | F50: 2 | G50: 0 | H50: 1 | I50: 0 | J50: 0 | K50: 0 | L50: 1 | M50: 1 | N50: 0 | O50: 0 | P50: 1 | Q50: 1 | R50: 0 | S50: 0 | T50: 0 | U50: 0 | V50: 0 | W50: 1 | X50: 3 | Y50: 1 | Z50: 0 | AA50: 0 | AB50: 0 | AC50: 1 | AD50: 0 | AE50: 1 | AF50: 0 | AG50: =SUM(E50:AF50) -> 14
B51: 6 | C51: 6. NURHAYATI, S.Pd. | E51: 1 | F51: 0 | G51: 2 | H51: 0 | I51: 3 | J51: 1 | K51: 0 | L51: 1 | M51: 0 | N51: 0 | O51: 3 | P51: 3 | Q51: 0 | R51: 1 | S51: 0 | T51: 1 | U51: 1 | V51: 1 | W51: 1 | X51: 2 | Y51: 1 | Z51: 1 | AA51: 0 | AB51: 0 | AC51: 0 | AD51: 0 | AE51: 0 | AF51: 0 | AG51: =SUM(E51:AF51) -> 23
...

Sheet KEBONDALEM
C2: Kecamatan | D2: BANGOREJO
C3: Kabupaten | D3: BANYUWANGI
C4: Provinsi | D4: JAWA TIMUR
C9: Kelurahan | D9: KEBONDALEM
A12: I | B12: DATA PEMILIH DAN PENGGUNAAN HAK PILIH | AH12: JUMLAH AKHIR
A13: A | B13: DATA PEMILIH | E13: TPS 001 | F13: TPS 002 | G13: TPS 003 | H13: TPS 004 | I13: TPS 005 | J13: TPS 006 | K13: TPS 007 | L13: TPS 008 | M13: TPS 009 | N13: TPS 010 | O13: TPS 011 | P13: TPS 012 | Q13: TPS 013 | R13: TPS 014 | S13: TPS 015 | T13: TPS 016 | U13: TPS 017 | V13: TPS 018 | W13: TPS 019 | X13: TPS 020 | Y13: TPS 021 | Z13: TPS 022 | AA13: TPS 023 | AB13: TPS 024 | AC13: TPS 025 | AD13: TPS 026 | AE13: TPS 027 | AF13: TPS 028 | AG13: TPS 029
B14: Jumlah Pemilih dalam Daftar Pemilih Tetap (DPT) | D14: LK | E14: 137 | F14: 124 | G14: 141 | H14: 143 | I14: 136 | J14: 145 | K14: 145 | L14: 145 | M14: 134 | N14: 123 | O14: 138 | P14: 130 | Q14: 139 | R14: 135 | S14: 136 | T14: 142 | U14: 127 | V14: 143 | W14: 134 | X14: 138 | Y14: 147 | Z14: 145 | AA14: 144 | AB14: 114 | AC14: 130 | AD14: 127 | AE14: 130 | AF14: 85 | AG14: 141 | AH14: =SUM(E14:AG14) -> 3898
D15: PR | E15: 125 | F15: 152 | G15: 151 | H15: 149 | I15: 138 | J15: 125 | K15: 154 | L15: 144 | M15: 136 | N15: 122 | O15: 138 | P15: 138 | Q15: 153 | R15: 138 | S15: 145 | T15: 151 | U15: 127 | V15: 135 | W15: 132 | X15: 137 | Y15: 129 | Z15: 150 | AA15: 145 | AB15: 123 | AC15: 138 | AD15: 142 | AE15: 145 | AF15: 100 | AG15: 128 | AH15: =SUM(E15:AG15) -> 3990
D16: JML | E16: =SUM(E14:E15) -> 262 | F16: =SUM(F14:F15) -> 276 | G16: =SUM(G14:G15) -> 292 | H16: =SUM(H14:H15) -> 292 | I16: =SUM(I14:I15) -> 274 | J16: =SUM(J14:J15) -> 270 | K16: =SUM(K14:K15) -> 299 | L16: =SUM(L14:L15) -> 289 | ... AG16: =SUM(AG14:AG15) -> 269 | AH16: =SUM(E16:AG16) -> 7888
A18: B | B18: PENGGUNA HAK PILIH
B19: 1. | C19: Jumlah pengguna hak pilih dalam Daftar Pemilih Tetap (DPT) | D19: LK | E19: 89 | F19: 90 | G19: 90 | H19: 87 | I19: 103 | J19: 110 | K19: 88 | L19: 104 | M19: 100 | N19: 87 | O19: 101 | P19: 85 | Q19: 93 | R19: 97 | S19: 96 | T19: 100 | U19: 94 | V19: 107 | W19: 109 | X19: 110 | Y19: 108 | Z19: 89 | AA19: 93 | AB19: 89 | AC19: 92 | AD19: 90 | AE19: 102 | AF19: 65 | AG19: 107 | AH19: =SUM(E19:AG19) -> 2775
D20: PR | E20: 88 | F20: 100 | G20: 109 | H20: 115 | I20: 102 | J20: 102 | K20: 95 | L20: 113 | M20: 101 | N20: 99 | O20: 104 | P20: 91 | Q20: 103 | R20: 97 | S20: 87 | T20: 102 | U20: 99 | V20: 107 | W20: 120 | X20: 110 | Y20: 99 | Z20: 110 | AA20: 110 | AB20: 103 | AC20: 106 | AD20: 96 | AE20: 115 | AF20: 77 | AG20: 102 | AH20: =SUM(E20:AG20) -> 2962
D21: JML | E21: =SUM(E19:E20) -> 177 | F21: =SUM(F19:F20) -> 190 | G21: =SUM(G19:G20) -> 199 | H21: =SUM(H19:H20) -> 202 | I21: =SUM(I19:I20) -> 205 | J21: =SUM(J19:J20) -> 212 | K21: =SUM(K19:K20) -> 183 | L21: =SUM(L19:L20) -> 217 | ... AG21: =SUM(AG19:AG20) -> 209 | AH21: =SUM(E21:AG21) -> 5737
B22: 2. | C22: Jumlah pengguna hak pilih dalam Daftar Pemilih Tambahan (DPTb) | D22: LK | T22: 0 | U22: 1 | V22: 0 | W22: 0 | X22: 0 | Y22: 0 | Z22: 0 | AA22: 0 | AB22: 0 | AC22: 0 | AD22: 0 | AE22: 0 | AF22: 0 | AG22: 0 | AH22: =SUM(E22:AG22) -> 1
D23: PR | T23: 0 | U23: 1 | V23: 0 | W23: 0 | X23: 0 | Y23: 0 | Z23: 0 | AA23: 0 | AB23: 0 | AC23: 0 | AD23: 0 | AE23: 0 | AF23: 0 | AG23: 0 | AH23: =SUM(E23:AG23) -> 1
D24: JML | E24: =SUM(E22:E23) -> 0 | F24: =SUM(F22:F23) -> 0 | G24: =SUM(G22:G23) -> 0 | H24: =SUM(H22:H23) -> 0 | I24: =SUM(I22:I23) -> 0 | J24: =SUM(J22:J23) -> 0 | K24: =SUM(K22:K23) -> 0 | L24: =SUM(L22:L23) -> 0 | ... AG24: =SUM(AG22:AG23) -> 0 | AH24: =SUM(E24:AG24) -> 2
B25: 3. | C25: Jumlah pengguna hak pilih dalam Daftar Pemilih Khusus (DPK) | D25: LK | E25: 0 | F25: 0 | G25: 3 | H25: 0 | I25: 0 | J25: 0 | K25: 0 | L25: 0 | M25: 0 | N25: 0 | O25: 0 | P25: 0 | Q25: 0 | R25: 0 | S25: 0 | T25: 2 | U25: 2 | V25: 1 | W25: 0 | X25: 0 | Y25: 0 | Z25: 0 | AA25: 0 | AB25: 0 | AC25: 4 | AD25: 0 | AE25: 0 | AF25: 1 | AG25: 0 | AH25: =SUM(E25:AG25) -> 13
D26: PR | E26: 3 | F26: 0 | G26: 5 | H26: 0 | I26: 0 | J26: 0 | K26: 0 | L26: 0 | M26: 1 | N26: 2 | O26: 0 | P26: 0 | Q26: 0 | R26: 2 | S26: 0 | T26: 3 | U26: 2 | V26: 0 | W26: 0 | X26: 0 | Y26: 0 | Z26: 0 | AA26: 0 | AB26: 0 | AC26: 1 | AD26: 0 | AE26: 0 | AF26: 1 | AG26: 0 | AH26: =SUM(E26:AG26) -> 20
D27: JML | E27: =SUM(E25:E26) -> 3 | F27: =SUM(F25:F26) -> 0 | G27: =SUM(G25:G26) -> 8 | H27: =SUM(H25:H26) -> 0 | I27: =SUM(I25:I26) -> 0 | J27: =SUM(J25:J26) -> 0 | K27: =SUM(K25:K26) -> 0 | L27: =SUM(L25:L26) -> 0 | ... AG27: =SUM(AG25:AG26) -> 0 | AH27: =SUM(E27:AG27) -> 33
B28: 4. | C28: Jumlah Pengguna Hak Pilih (B.1+B.2+B.3) | D28: LK | E28: =SUM(E19,E22,E25) -> 89 | F28: =SUM(F19,F22,F25) -> 90 | G28: =SUM(G19,G22,G25) -> 93 | H28: =SUM(H19,H22,H25) -> 87 | I28: =SUM(I19,I22,I25) -> 103 | J28: =SUM(J19,J22,J25) -> 110 | K28: =SUM(K19,K22,K25) -> 88 | L28: =SUM(L19,L22,L25) -> 104 | ... AG28: =SUM(AG19,AG22,AG25) -> 107 | AH28: =SUM(E28:AG28) -> 2789
D29: PR | E29: =SUM(E20,E23,E26) -> 91 | F29: =SUM(F20,F23,F26) -> 100 | G29: =SUM(G20,G23,G26) -> 114 | H29: =SUM(H20,H23,H26) -> 115 | I29: =SUM(I20,I23,I26) -> 102 | J29: =SUM(J20,J23,J26) -> 102 | K29: =SUM(K20,K23,K26) -> 95 | L29: =SUM(L20,L23,L26) -> 113 | ... AG29: =SUM(AG20,AG23,AG26) -> 102 | AH29: =SUM(E29:AG29) -> 2983
D30: JML | E30: =SUM(E28:E29) -> 180 | F30: =SUM(F28:F29) -> 190 | G30: =SUM(G28:G29) -> 207 | H30: =SUM(H28:H29) -> 202 | I30: =SUM(I28:I29) -> 205 | J30: =SUM(J28:J29) -> 212 | K30: =SUM(K28:K29) -> 183 | L30: =SUM(L28:L29) -> 217 | ... AG30: =SUM(AG28:AG29) -> 209 | AH30: =SUM(E30:AG30) -> 5772
A32: II | B32: DATA PENGGUNAAN SURAT SUARA
A33: 1 | B33: Jumlah surat suara yang diterima, termasuk surat suara cadangan 2,5% dari DPT | E33: 268 | F33: 282 | G33: 298 | H33: 298 | I33: 280 | J33: 276 | K33: 301 | L33: 296 | M33: 276 | N33: 250 | O33: 282 | P33: 272 | Q33: 298 | R33: 279 | S33: 287 | T33: 299 | U33: 260 | V33: 284 | W33: 272 | X33: 281 | Y33: 282 | Z33: 301 | AA33: 295 | AB33: 242 | AC33: 274 | AD33: 275 | AE33: 281 | AF33: 189 | AG33: 275 | AH33: =SUM(E33:AG33) -> 8053
A34: 2 | B34: Jumlah surat suara yang digunakan | E34: 180 | F34: 190 | G34: 207 | H34: 202 | I34: 205 | J34: 212 | K34: 183 | L34: 217 | M34: 202 | N34: 188 | O34: 205 | P34: 176 | Q34: 196 | R34: 196 | S34: 183 | T34: 207 | U34: 199 | V34: 215 | W34: 229 | X34: 220 | Y34: 207 | Z34: 199 | AA34: 203 | AB34: 192 | AC34: 203 | AD34: 186 | AE34: 217 | AF34: 144 | AG34: 209 | AH34: =SUM(E34:AG34) -> 5772
A35: 3 | B35: Jumlah surat suara dikembalikan oleh pemilih (karena rusak atau keliru coblos) | E35: 0 | F35: 0 | G35: 0 | H35: 0 | I35: 0 | J35: 0 | K35: 0 | L35: 0 | M35: 0 | N35: 0 | O35: 0 | P35: 0 | Q35: 1 | R35: 0 | S35: 0 | T35: 0 | U35: 0 | V35: 0 | W35: 0 | X35: 0 | Y35: 0 | Z35: 0 | AA35: 2 | AB35: 0 | AC35: 2 | AD35: 0 | AE35: 0 | AF35: 0 | AG35: 0 | AH35: =SUM(E35:AG35) -> 5
A36: 4 | B36: Jumlah surat suara yang tidak digunakan/tidak terpakai, termasuk sisa surat suara cadangan | E36: =E33-(E34+E35) -> 88 | F36: =F33-(F34+F35) -> 92 | G36: =G33-(G34+G35) -> 91 | H36: =H33-(H34+H35) -> 96 | I36: =I33-(I34+I35) -> 75 | J36: =J33-(J34+J35) -> 64 | K36: =K33-(K34+K35) -> 118 | L36: =L33-(L34+L35) -> 79 | ... AG36: =AG33-(AG34+AG35) -> 66 | AH36: =SUM(E36:AG36) -> 2276
A38: III | B38: DATA PEMILIH DISABILITAS
B39: Jumlah seluruh Pemilih disabilitas yang menggunakan hak pilih | D39: LK | E39: 0 | F39: 0 | G39: 0 | H39: 0 | I39: 0 | J39: 0 | K39: 3 | L39: 3 | M39: 0 | N39: 0 | O39: 0 | P39: 0 | Q39: 0 | R39: 0 | S39: 0 | T39: 0 | U39: 1 | V39: 0 | W39: 0 | X39: 0 | Y39: 0 | Z39: 0 | AA39: 0 | AB39: 0 | AC39: 2 | AD39: 0 | AE39: 0 | AF39: 0 | AG39: 1 | AH39: =SUM(E39:AG39) -> 10
D40: PR | E40: 0 | F40: 0 | G40: 0 | H40: 0 | I40: 2 | J40: 0 | K40: 3 | L40: 7 | M40: 0 | N40: 0 | O40: 0 | P40: 0 | Q40: 0 | R40: 0 | S40: 0 | T40: 0 | U40: 1 | V40: 0 | W40: 0 | X40: 0 | Y40: 0 | Z40: 0 | AA40: 0 | AB40: 0 | AC40: 0 | AD40: 0 | AE40: 0 | AF40: 0 | AG40: 1 | AH40: =SUM(E40:AG40) -> 14
D41: JML | E41: =SUM(E39:E40) -> 0 | F41: =SUM(F39:F40) -> 0 | G41: =SUM(G39:G40) -> 0 | H41: =SUM(H39:H40) -> 0 | I41: =SUM(I39:I40) -> 2 | J41: =SUM(J39:J40) -> 0 | K41: =SUM(K39:K40) -> 6 | L41: =SUM(L39:L40) -> 10 | ... AG41: =SUM(AG39:AG40) -> 2 | AH41: =SUM(E41:AG41) -> 24
A43: IV | B43: DATA RINCIAN PEROLEHAN SUARA PASANGAN CALON BUPATI DAN WAKIL BUPATI
A44: NOMOR DAN NAMA CALON
A45: A.1 | B45: 1. | C45: Partai Kebangkitan Bangsa | E45: 11 | F45: 2 | G45: 2 | H45: 6 | I45: 8 | J45: 3 | K45: 3 | L45: 4 | M45: 7 | N45: 3 | O45: 2 | P45: 1 | Q45: 2 | R45: 5 | S45: 3 | T45: 2 | U45: 3 | V45: 4 | W45: 0 | X45: 3 | Y45: 1 | Z45: 6 | AA45: 7 | AB45: 3 | AC45: 10 | AD45: 7 | AE45: 0 | AF45: 0 | AG45: 6 | AH45: =SUM(E45:AG45) -> 114
A46: A.2 | B46: 1 | C46: 1. Dr. Hj. NIHAYATUL WAFIROH, M.A. | E46: 9 | F46: 11 | G46: 5 | H46: 5 | I46: 25 | J46: 29 | K46: 5 | L46: 16 | M46: 50 | N46: 44 | O46: 6 | P46: 9 | Q46: 8 | R46: 4 | S46: 11 | T46: 18 | U46: 5 | V46: 6 | W46: 3 | X46: 7 | Y46: 4 | Z46: 5 | AA46: 1 | AB46: 14 | AC46: 45 | AD46: 11 | AE46: 2 | AF46: 0 | AG46: 12 | AH46: =SUM(E46:AG46) -> 370
B47: 2 | C47: 2. H. M. NASIM KHAN | E47: 8 | F47: 0 | G47: 0 | H47: 2 | I47: 1 | J47: 0 | K47: 1 | L47: 1 | M47: 4 | N47: 2 | O47: 0 | P47: 0 | Q47: 0 | R47: 1 | S47: 0 | T47: 1 | U47: 0 | V47: 4 | W47: 1 | X47: 0 | Y47: 0 | Z47: 0 | AA47: 0 | AB47: 0 | AC47: 1 | AD47: 1 | AE47: 2 | AF47: 0 | AG47: 1 | AH47: =SUM(E47:AG47) -> 31
B48: 3 | C48: 3. Dr. H. AKIK ZAMAN, M.Pd.I. | E48: 0 | F48: 0 | G48: 0 | H48: 0 | I48: 0 | J48: 0 | K48: 0 | L48: 0 | M48: 1 | N48: 0 | O48: 1 | P48: 0 | Q48: 0 | R48: 0 | S48: 0 | T48: 0 | U48: 0 | V48: 0 | W48: 0 | X48: 0 | Y48: 1 | Z48: 2 | AA48: 0 | AB48: 0 | AC48: 0 | AD48: 0 | AE48: 1 | AF48: 0 | AG48: 1 | AH48: =SUM(E48:AG48) -> 7
B49: 4 | C49: 4. AHMAD RIFA'I, S.H. | E49: 0 | F49: 0 | G49: 1 | H49: 1 | I49: 1 | J49: 1 | K49: 0 | L49: 1 | M49: 0 | N49: 0 | O49: 1 | P49: 0 | Q49: 1 | R49: 0 | S49: 0 | T49: 1 | U49: 0 | V49: 0 | W49: 1 | X49: 0 | Y49: 0 | Z49: 0 | AA49: 3 | AB49: 1 | AC49: 0 | AD49: 0 | AE49: 0 | AF49: 0 | AG49: 0 | AH49: =SUM(E49:AG49) -> 13
B50: 5 | C50: 5. Drs. H. MAHFUD M.N. | E50: 0 | F50: 1 | G50: 0 | H50: 0 | I50: 0 | J50: 0 | K50: 0 | L50: 0 | M50: 0 | N50: 0 | O50: 0 | P50: 1 | Q50: 0 | R50: 1 | S50: 0 | T50: 0 | U50: 0 | V50: 0 | W50: 0 | X50: 0 | Y50: 0 | Z50: 2 | AA50: 0 | AB50: 0 | AC50: 1 | AD50: 0 | AE50: 1 | AF50: 1 | AG50: 1 | AH50: =SUM(E50:AG50) -> 9
B51: 6 | C51: 6. NURHAYATI, S.Pd. | E51: 1 | F51: 0 | G51: 2 | H51: 0 | I51: 0 | J51: 0 | K51: 0 | L51: 0 | M51: 0 | N51: 0 | O51: 0 | P51: 0 | Q51: 0 | R51: 0 | S51: 0 | T51: 0 | U51: 0 | V51: 0 | W51: 0 | X51: 1 | Y51: 1 | Z51: 0 | AA51: 0 | AB51: 0 | AC51: 0 | AD51: 0 | AE51: 0 | AF51: 0 | AG51: 1 | AH51: =SUM(E51:AG51) -> 6
...

Sheet RINGINTELU
C2: Kecamatan | D2: BANGOREJO
C3: Kabupaten | D3: BANYUWANGI
C4: Provinsi | D4: JAWA TIMUR
C9: Kelurahan | D9: RINGINTELU
A12: I | B12: DATA PEMILIH DAN PENGGUNAAN HAK PILIH | Z12: JUMLAH AKHIR
A13: A | B13: DATA PEMILIH | E13: TPS 001 | F13: TPS 002 | G13: TPS 003 | H13: TPS 004 | I13: TPS 005 | J13: TPS 006 | K13: TPS 007 | L13: TPS 008 | M13: TPS 009 | N13: TPS 010 | O13: TPS 011 | P13: TPS 012 | Q13: TPS 013 | R13: TPS 014 | S13: TPS 015 | T13: TPS 016 | U13: TPS 017 | V13: TPS 018 | W13: TPS 019 | X13: TPS 020 | Y13: TPS 021
B14: Jumlah Pemilih dalam Daftar Pemilih Tetap (DPT) | D14: LK | E14: 140 | F14: 148 | G14: 109 | H14: 139 | I14: 147 | J14: 152 | K14: 104 | L14: 135 | M14: 146 | N14: 145 | O14: 142 | P14: 146 | Q14: 154 | R14: 141 | S14: 145 | T14: 97 | U14: 136 | V14: 144 | W14: 136 | X14: 134 | Y14: 135 | Z14: =SUM(E14:Y14) -> 2875
D15: PR | E15: 133 | F15: 125 | G15: 118 | H15: 152 | I15: 139 | J15: 142 | K15: 104 | L15: 141 | M15: 134 | N15: 132 | O15: 132 | P15: 137 | Q15: 135 | R15: 140 | S15: 143 | T15: 100 | U15: 143 | V15: 131 | W15: 123 | X15: 148 | Y15: 149 | Z15: =SUM(E15:Y15) -> 2801
D16: JML | E16: =SUM(E14:E15) -> 273 | F16: =SUM(F14:F15) -> 273 | G16: =SUM(G14:G15) -> 227 | H16: =SUM(H14:H15) -> 291 | I16: =SUM(I14:I15) -> 286 | J16: =SUM(J14:J15) -> 294 | K16: =SUM(K14:K15) -> 208 | L16: =SUM(L14:L15) -> 276 | ... Y16: =SUM(Y14:Y15) -> 284 | Z16: =SUM(E16:Y16) -> 5676
A18: B | B18: PENGGUNA HAK PILIH
B19: 1. | C19: Jumlah pengguna hak pilih dalam Daftar Pemilih Tetap (DPT) | D19: LK | E19: 98 | F19: 103 | G19: 75 | H19: 123 | I19: 98 | J19: 116 | K19: 70 | L19: 99 | M19: 97 | N19: 106 | O19: 101 | P19: 108 | Q19: 107 | R19: 108 | S19: 106 | T19: 68 | U19: 97 | V19: 101 | W19: 94 | X19: 91 | Y19: 97 | Z19: =SUM(E19:Y19) -> 2063
D20: PR | E20: 102 | F20: 79 | G20: 82 | H20: 108 | I20: 102 | J20: 109 | K20: 78 | L20: 107 | M20: 103 | N20: 88 | O20: 108 | P20: 120 | Q20: 102 | R20: 109 | S20: 115 | T20: 71 | U20: 101 | V20: 96 | W20: 102 | X20: 110 | Y20: 106 | Z20: =SUM(E20:Y20) -> 2098
D21: JML | E21: =SUM(E19:E20) -> 200 | F21: =SUM(F19:F20) -> 182 | G21: =SUM(G19:G20) -> 157 | H21: =SUM(H19:H20) -> 231 | I21: =SUM(I19:I20) -> 200 | J21: =SUM(J19:J20) -> 225 | K21: =SUM(K19:K20) -> 148 | L21: =SUM(L19:L20) -> 206 | ... Y21: =SUM(Y19:Y20) -> 203 | Z21: =SUM(E21:Y21) -> 4161
B22: 2. | C22: Jumlah pengguna hak pilih dalam Daftar Pemilih Tambahan (DPTb) | D22: LK | E22: 0 | F22: 0 | G22: 0 | H22: 0 | I22: 0 | J22: 0 | K22: 1 | L22: 0 | M22: 0 | N22: 0 | O22: 0 | P22: 0 | Q22: 0 | R22: 0 | S22: 0 | Z22: =SUM(E22:Y22) -> 1
D23: PR | E23: 0 | F23: 0 | G23: 0 | H23: 0 | I23: 1 | J23: 0 | K23: 0 | L23: 0 | M23: 0 | N23: 0 | O23: 0 | P23: 0 | Q23: 0 | R23: 0 | S23: 0 | Z23: =SUM(E23:Y23) -> 1
D24: JML | E24: =SUM(E22:E23) -> 0 | F24: =SUM(F22:F23) -> 0 | G24: =SUM(G22:G23) -> 0 | H24: =SUM(H22:H23) -> 0 | I24: =SUM(I22:I23) -> 1 | J24: =SUM(J22:J23) -> 0 | K24: =SUM(K22:K23) -> 1 | L24: =SUM(L22:L23) -> 0 | ... Y24: =SUM(Y22:Y23) -> 0 | Z24: =SUM(E24:Y24) -> 2
B25: 3. | C25: Jumlah pengguna hak pilih dalam Daftar Pemilih Khusus (DPK) | D25: LK | E25: 0 | F25: 0 | G25: 1 | H25: 0 | I25: 1 | J25: 1 | K25: 0 | L25: 0 | M25: 0 | N25: 0 | O25: 1 | P25: 0 | Q25: 0 | R25: 2 | S25: 1 | T25: 0 | U25: 3 | V25: 0 | W25: 1 | X25: 3 | Y25: 0 | Z25: =SUM(E25:Y25) -> 14
D26: PR | E26: 0 | F26: 0 | G26: 0 | H26: 0 | I26: 0 | J26: 3 | K26: 1 | L26: 0 | M26: 0 | N26: 1 | O26: 0 | P26: 0 | Q26: 0 | R26: 2 | S26: 1 | T26: 0 | U26: 1 | V26: 0 | W26: 0 | X26: 1 | Y26: 0 | Z26: =SUM(E26:Y26) -> 10
D27: JML | E27: =SUM(E25:E26) -> 0 | F27: =SUM(F25:F26) -> 0 | G27: =SUM(G25:G26) -> 1 | H27: =SUM(H25:H26) -> 0 | I27: =SUM(I25:I26) -> 1 | J27: =SUM(J25:J26) -> 4 | K27: =SUM(K25:K26) -> 1 | L27: =SUM(L25:L26) -> 0 | ... Y27: =SUM(Y25:Y26) -> 0 | Z27: =SUM(E27:Y27) -> 24
B28: 4. | C28: Jumlah Pengguna Hak Pilih (B.1+B.2+B.3) | D28: LK | E28: =SUM(E19,E22,E25) -> 98 | F28: =SUM(F19,F22,F25) -> 103 | G28: =SUM(G19,G22,G25) -> 76 | H28: =SUM(H19,H22,H25) -> 123 | I28: =SUM(I19,I22,I25) -> 99 | J28: =SUM(J19,J22,J25) -> 117 | K28: =SUM(K19,K22,K25) -> 71 | L28: =SUM(L19,L22,L25) -> 99 | ... Y28: =SUM(Y19,Y22,Y25) -> 97 | Z28: =SUM(E28:Y28) -> 2078
D29: PR | E29: =SUM(E20,E23,E26) -> 102 | F29: =SUM(F20,F23,F26) -> 79 | G29: =SUM(G20,G23,G26) -> 82 | H29: =SUM(H20,H23,H26) -> 108 | I29: =SUM(I20,I23,I26) -> 103 | J29: =SUM(J20,J23,J26) -> 112 | K29: =SUM(K20,K23,K26) -> 79 | L29: =SUM(L20,L23,L26) -> 107 | ... Y29: =SUM(Y20,Y23,Y26) -> 106 | Z29: =SUM(E29:Y29) -> 2109
D30: JML | E30: =SUM(E28:E29) -> 200 | F30: =SUM(F28:F29) -> 182 | G30: =SUM(G28:G29) -> 158 | H30: =SUM(H28:H29) -> 231 | I30: =SUM(I28:I29) -> 202 | J30: =SUM(J28:J29) -> 229 | K30: =SUM(K28:K29) -> 150 | L30: =SUM(L28:L29) -> 206 | ... Y30: =SUM(Y28:Y29) -> 203 | Z30: =SUM(E30:Y30) -> 4187
A32: II | B32: DATA PENGGUNAAN SURAT SUARA
A33: 1 | B33: Jumlah surat suara yang diterima, termasuk surat suara cadangan 2,5% dari DPT | E33: 279 | F33: 279 | G33: 232 | H33: 297 | I33: 272 | J33: 300 | K33: 213 | L33: 282 | M33: 286 | N33: 283 | O33: 280 | P33: 289 | Q33: 285 | R33: 287 | S33: 294 | T33: 201 | U33: 284 | V33: 281 | W33: 265 | X33: 288 | Y33: 300 | Z33: =SUM(E33:Y33) -> 5777
A34: 2 | B34: Jumlah surat suara yang digunakan | E34: 200 | F34: 182 | G34: 158 | H34: 231 | I34: 202 | J34: 229 | K34: 150 | L34: 206 | M34: 200 | N34: 195 | O34: 210 | P34: 228 | Q34: 209 | R34: 221 | S34: 223 | T34: 139 | U34: 202 | V34: 197 | W34: 197 | X34: 205 | Y34: 203 | Z34: =SUM(E34:Y34) -> 4187
A35: 3 | B35: Jumlah surat suara dikembalikan oleh pemilih (karena rusak atau keliru coblos) | E35: 0 | F35: 0 | G35: 0 | H35: 0 | I35: 0 | J35: 1 | K35: 0 | L35: 0 | M35: 0 | N35: 0 | O35: 1 | P35: 0 | Q35: 0 | R35: 0 | S35: 4 | T35: 1 | U35: 6 | V35: 1 | W35: 0 | X35: 0 | Y35: 0 | Z35: =SUM(E35:Y35) -> 14
A36: 4 | B36: Jumlah surat suara yang tidak digunakan/tidak terpakai, termasuk sisa surat suara cadangan | E36: =E33-(E34+E35) -> 79 | F36: =F33-(F34+F35) -> 97 | G36: =G33-(G34+G35) -> 74 | H36: =H33-(H34+H35) -> 66 | I36: =I33-(I34+I35) -> 70 | J36: =J33-(J34+J35) -> 70 | K36: =K33-(K34+K35) -> 63 | L36: =L33-(L34+L35) -> 76 | ... Y36: =Y33-(Y34+Y35) -> 97 | Z36: =SUM(E36:Y36) -> 1576
A38: III | B38: DATA PEMILIH DISABILITAS
B39: Jumlah seluruh Pemilih disabilitas yang menggunakan hak pilih | D39: LK | E39: 0 | F39: 0 | G39: 0 | H39: 0 | I39: 0 | J39: 0 | K39: 0 | L39: 0 | M39: 1 | N39: 0 | O39: 0 | P39: 0 | Q39: 0 | R39: 0 | S39: 0 | T39: 0 | U39: 0 | V39: 2 | W39: 0 | X39: 0 | Y39: 0 | Z39: =SUM(E39:Y39) -> 3
D40: PR | E40: 1 | F40: 0 | G40: 0 | H40: 0 | I40: 0 | J40: 1 | K40: 0 | L40: 0 | M40: 0 | N40: 0 | O40: 0 | P40: 0 | Q40: 0 | R40: 0 | S40: 0 | T40: 0 | U40: 0 | V40: 0 | W40: 0 | X40: 0 | Y40: 0 | Z40: =SUM(E40:Y40) -> 2
D41: JML | E41: =SUM(E39:E40) -> 1 | F41: =SUM(F39:F40) -> 0 | G41: =SUM(G39:G40) -> 0 | H41: =SUM(H39:H40) -> 0 | I41: =SUM(I39:I40) -> 0 | J41: =SUM(J39:J40) -> 1 | K41: =SUM(K39:K40) -> 0 | L41: =SUM(L39:L40) -> 0 | ... Y41: =SUM(Y39:Y40) -> 0 | Z41: =SUM(E41:Y41) -> 5
A43: IV | B43: DATA RINCIAN PEROLEHAN SUARA PASANGAN CALON BUPATI DAN WAKIL BUPATI
A44: NOMOR DAN NAMA CALON
A45: A.1 | B45: 1. | C45: Partai Kebangkitan Bangsa | E45: 0 | F45: 2 | G45: 3 | H45: 9 | I45: 11 | J45: 4 | K45: 5 | L45: 2 | M45: 12 | N45: 13 | O45: 18 | P45: 9 | Q45: 1 | R45: 5 | S45: 10 | T45: 1 | U45: 7 | V45: 6 | W45: 9 | X45: 4 | Y45: 4 | Z45: =SUM(E45:Y45) -> 135
A46: A.2 | B46: 1 | C46: 1. Dr. Hj. NIHAYATUL WAFIROH, M.A. | E46: 26 | F46: 6 | G46: 10 | H46: 36 | I46: 42 | J46: 37 | K46: 11 | L46: 6 | M46: 22 | N46: 20 | O46: 52 | P46: 16 | Q46: 6 | R46: 7 | S46: 28 | T46: 4 | U46: 12 | V46: 10 | W46: 6 | X46: 6 | Y46: 18 | Z46: =SUM(E46:Y46) -> 381
B47: 2 | C47: 2. H. M. NASIM KHAN | E47: 3 | F47: 3 | G47: 6 | H47: 5 | I47: 1 | J47: 3 | K47: 1 | L47: 30 | M47: 5 | N47: 13 | O47: 2 | P47: 15 | Q47: 7 | R47: 4 | S47: 0 | T47: 1 | U47: 0 | V47: 2 | W47: 3 | X47: 0 | Y47: 2 | Z47: =SUM(E47:Y47) -> 106
B48: 3 | C48: 3. Dr. H. AKIK ZAMAN, M.Pd.I. | E48: 0 | F48: 0 | G48: 0 | H48: 1 | I48: 1 | J48: 1 | K48: 2 | L48: 1 | M48: 1 | N48: 0 | O48: 2 | P48: 1 | Q48: 0 | R48: 0 | S48: 1 | T48: 1 | U48: 0 | V48: 2 | W48: 0 | X48: 0 | Y48: 0 | Z48: =SUM(E48:Y48) -> 14
B49: 4 | C49: 4. AHMAD RIFA'I, S.H. | E49: 1 | F49: 1 | G49: 2 | H49: 1 | I49: 2 | J49: 1 | K49: 0 | L49: 8 | M49: 0 | N49: 3 | O49: 2 | P49: 2 | Q49: 2 | R49: 0 | S49: 0 | T49: 0 | U49: 2 | V49: 2 | W49: 0 | X49: 0 | Y49: 1 | Z49: =SUM(E49:Y49) -> 30
B50: 5 | C50: 5. Drs. H. MAHFUD M.N. | E50: 1 | F50: 0 | G50: 0 | H50: 0 | I50: 0 | J50: 1 | K50: 0 | L50: 1 | M50: 1 | N50: 0 | O50: 3 | P50: 1 | Q50: 0 | R50: 1 | S50: 1 | T50: 0 | U50: 1 | V50: 0 | W50: 1 | X50: 0 | Y50: 0 | Z50: =SUM(E50:Y50) -> 12
B51: 6 | C51: 6. NURHAYATI, S.Pd. | E51: 0 | F51: 1 | G51: 1 | H51: 1 | I51: 1 | J51: 0 | K51: 1 | L51: 0 | M51: 0 | N51: 2 | O51: 0 | P51: 0 | Q51: 1 | R51: 1 | S51: 1 | T51: 0 | U51: 0 | V51: 0 | W51: 1 | X51: 0 | Y51: 0 | Z51: =SUM(E51:Y51) -> 11
...

Sheet SAMBIMULYO
C2: Kecamatan | D2: BANGOREJO
C3: Kabupaten | D3: BANYUWANGI
C4: Provinsi | D4: JAWA TIMUR
C9: Kelurahan | D9: SAMBIMULYO
A12: I | B12: DATA PEMILIH DAN PENGGUNAAN HAK PILIH | AF12: JUMLAH AKHIR
A13: A | B13: DATA PEMILIH | E13: TPS 001 | F13: TPS 002 | G13: TPS 003 | H13: TPS 004 | I13: TPS 005 | J13: TPS 006 | K13: TPS 007 | L13: TPS 008 | M13: TPS 009 | N13: TPS 010 | O13: TPS 011 | P13: TPS 012 | Q13: TPS 013 | R13: TPS 014 | S13: TPS 015 | T13: TPS 016 | U13: TPS 017 | V13: TPS 018 | W13: TPS 019 | X13: TPS 020 | Y13: TPS 021 | Z13: TPS 022 | AA13: TPS 023 | AB13: TPS 024 | AC13: TPS 025 | AD13: TPS 026 | AE13: TPS 027
B14: Jumlah Pemilih dalam Daftar Pemilih Tetap (DPT) | D14: LK | E14: 136 | F14: 113 | G14: 121 | H14: 116 | I14: 108 | J14: 125 | K14: 119 | L14: 137 | M14: 143 | N14: 128 | O14: 118 | P14: 149 | Q14: 142 | R14: 139 | S14: 143 | T14: 141 | U14: 137 | V14: 152 | W14: 119 | X14: 135 | Y14: 141 | Z14: 138 | AA14: 111 | AB14: 135 | AC14: 148 | AD14: 81 | AE14: 93 | AF14: =SUM(E14:AE14) -> 3468
D15: PR | E15: 138 | F15: 115 | G15: 132 | H15: 119 | I15: 112 | J15: 123 | K15: 118 | L15: 136 | M15: 141 | N15: 136 | O15: 104 | P15: 147 | Q15: 149 | R15: 155 | S15: 147 | T15: 125 | U15: 148 | V15: 145 | W15: 117 | X15: 157 | Y15: 150 | Z15: 143 | AA15: 117 | AB15: 127 | AC15: 141 | AD15: 81 | AE15: 76 | AF15: =SUM(E15:AE15) -> 3499
D16: JML | E16: =SUM(E14:E15) -> 274 | F16: =SUM(F14:F15) -> 228 | G16: =SUM(G14:G15) -> 253 | H16: =SUM(H14:H15) -> 235 | I16: =SUM(I14:I15) -> 220 | J16: =SUM(J14:J15) -> 248 | K16: =SUM(K14:K15) -> 237 | L16: =SUM(L14:L15) -> 273 | ... AE16: =SUM(AE14:AE15) -> 169 | AF16: =SUM(E16:AE16) -> 6967
A18: B | B18: PENGGUNA HAK PILIH
B19: 1. | C19: Jumlah pengguna hak pilih dalam Daftar Pemilih Tetap (DPT) | D19: LK | E19: 107 | F19: 101 | G19: 89 | H19: 85 | I19: 87 | J19: 100 | K19: 94 | L19: 101 | M19: 115 | N19: 101 | O19: 96 | P19: 119 | Q19: 105 | R19: 111 | S19: 113 | T19: 104 | U19: 101 | V19: 109 | W19: 96 | X19: 105 | Y19: 104 | Z19: 106 | AA19: 85 | AB19: 106 | AC19: 118 | AD19: 71 | AE19: 68 | AF19: =SUM(E19:AE19) -> 2697
D20: PR | E20: 109 | F20: 93 | G20: 104 | H20: 96 | I20: 91 | J20: 100 | K20: 81 | L20: 105 | M20: 111 | N20: 101 | O20: 88 | P20: 120 | Q20: 121 | R20: 136 | S20: 120 | T20: 94 | U20: 115 | V20: 112 | W20: 96 | X20: 114 | Y20: 119 | Z20: 117 | AA20: 100 | AB20: 105 | AC20: 108 | AD20: 67 | AE20: 65 | AF20: =SUM(E20:AE20) -> 2788
D21: JML | E21: =SUM(E19:E20) -> 216 | F21: =SUM(F19:F20) -> 194 | G21: =SUM(G19:G20) -> 193 | H21: =SUM(H19:H20) -> 181 | I21: =SUM(I19:I20) -> 178 | J21: =SUM(J19:J20) -> 200 | K21: =SUM(K19:K20) -> 175 | L21: =SUM(L19:L20) -> 206 | ... AE21: =SUM(AE19:AE20) -> 133 | AF21: =SUM(E21:AE21) -> 5485
B22: 2. | C22: Jumlah pengguna hak pilih dalam Daftar Pemilih Tambahan (DPTb) | D22: LK | T22: 0 | U22: 0 | V22: 0 | W22: 0 | X22: 0 | Y22: 0 | Z22: 0 | AA22: 0 | AB22: 0 | AC22: 0 | AD22: 1 | AE22: 0 | AF22: =SUM(E22:AE22) -> 1
D23: PR | T23: 0 | U23: 0 | V23: 0 | W23: 0 | X23: 0 | Y23: 0 | Z23: 0 | AA23: 0 | AB23: 0 | AC23: 0 | AD23: 0 | AE23: 0 | AF23: =SUM(E23:AE23) -> 0
D24: JML | E24: =SUM(E22:E23) -> 0 | F24: =SUM(F22:F23) -> 0 | G24: =SUM(G22:G23) -> 0 | H24: =SUM(H22:H23) -> 0 | I24: =SUM(I22:I23) -> 0 | J24: =SUM(J22:J23) -> 0 | K24: =SUM(K22:K23) -> 0 | L24: =SUM(L22:L23) -> 0 | ... AE24: =SUM(AE22:AE23) -> 0 | AF24: =SUM(E24:AE24) -> 1
B25: 3. | C25: Jumlah pengguna hak pilih dalam Daftar Pemilih Khusus (DPK) | D25: LK | E25: 0 | F25: 1 | G25: 1 | H25: 0 | I25: 3 | J25: 4 | K25: 1 | L25: 0 | M25: 1 | N25: 0 | O25: 2 | P25: 0 | Q25: 1 | R25: 3 | S25: 3 | T25: 1 | U25: 0 | V25: 0 | W25: 2 | X25: 1 | Y25: 0 | Z25: 2 | AA25: 4 | AB25: 0 | AC25: 3 | AD25: 1 | AE25: 3 | AF25: =SUM(E25:AE25) -> 37
D26: PR | E26: 0 | F26: 3 | G26: 2 | H26: 4 | I26: 3 | J26: 2 | K26: 2 | L26: 2 | M26: 3 | N26: 1 | O26: 0 | P26: 1 | Q26: 0 | R26: 2 | S26: 0 | T26: 2 | U26: 1 | V26: 0 | W26: 2 | X26: 1 | Y26: 0 | Z26: 0 | AA26: 0 | AB26: 0 | AC26: 2 | AD26: 0 | AE26: 4 | AF26: =SUM(E26:AE26) -> 37
D27: JML | E27: =SUM(E25:E26) -> 0 | F27: =SUM(F25:F26) -> 4 | G27: =SUM(G25:G26) -> 3 | H27: =SUM(H25:H26) -> 4 | I27: =SUM(I25:I26) -> 6 | J27: =SUM(J25:J26) -> 6 | K27: =SUM(K25:K26) -> 3 | L27: =SUM(L25:L26) -> 2 | ... AE27: =SUM(AE25:AE26) -> 7 | AF27: =SUM(E27:AE27) -> 74
B28: 4. | C28: Jumlah Pengguna Hak Pilih (B.1+B.2+B.3) | D28: LK | E28: =SUM(E19,E22,E25) -> 107 | F28: =SUM(F19,F22,F25) -> 102 | G28: =SUM(G19,G22,G25) -> 90 | H28: =SUM(H19,H22,H25) -> 85 | I28: =SUM(I19,I22,I25) -> 90 | J28: =SUM(J19,J22,J25) -> 104 | K28: =SUM(K19,K22,K25) -> 95 | L28: =SUM(L19,L22,L25) -> 101 | ... AE28: =SUM(AE19,AE22,AE25) -> 71 | AF28: =SUM(E28:AE28) -> 2735
D29: PR | E29: =SUM(E20,E23,E26) -> 109 | F29: =SUM(F20,F23,F26) -> 96 | G29: =SUM(G20,G23,G26) -> 106 | H29: =SUM(H20,H23,H26) -> 100 | I29: =SUM(I20,I23,I26) -> 94 | J29: =SUM(J20,J23,J26) -> 102 | K29: =SUM(K20,K23,K26) -> 83 | L29: =SUM(L20,L23,L26) -> 107 | ... AE29: =SUM(AE20,AE23,AE26) -> 69 | AF29: =SUM(E29:AE29) -> 2825
D30: JML | E30: =SUM(E28:E29) -> 216 | F30: =SUM(F28:F29) -> 198 | G30: =SUM(G28:G29) -> 196 | H30: =SUM(H28:H29) -> 185 | I30: =SUM(I28:I29) -> 184 | J30: =SUM(J28:J29) -> 206 | K30: =SUM(K28:K29) -> 178 | L30: =SUM(L28:L29) -> 208 | ... AE30: =SUM(AE28:AE29) -> 140 | AF30: =SUM(E30:AE30) -> 5560
A32: II | B32: DATA PENGGUNAAN SURAT SUARA
A33: 1 | B33: Jumlah surat suara yang diterima, termasuk surat suara cadangan 2,5% dari DPT | E33: 280 | F33: 233 | G33: 260 | H33: 240 | I33: 225 | J33: 253 | K33: 242 | L33: 279 | M33: 290 | N33: 271 | O33: 227 | P33: 302 | Q33: 297 | R33: 301 | S33: 296 | T33: 272 | U33: 292 | V33: 303 | W33: 241 | X33: 298 | Y33: 307 | Z33: 287 | AA33: 233 | AB33: 268 | AC33: 295 | AD33: 166 | AE33: 172 | AF33: =SUM(E33:AE33) -> 7130
A34: 2 | B34: Jumlah surat suara yang digunakan | E34: 216 | F34: 198 | G34: 196 | H34: 185 | I34: 184 | J34: 206 | K34: 178 | L34: 208 | M34: 230 | N34: 203 | O34: 186 | P34: 240 | Q34: 227 | R34: 252 | S34: 236 | T34: 201 | U34: 217 | V34: 221 | W34: 196 | X34: 221 | Y34: 223 | Z34: 225 | AA34: 189 | AB34: 211 | AC34: 231 | AD34: 140 | AE34: 140 | AF34: =SUM(E34:AE34) -> 5560
A35: 3 | B35: Jumlah surat suara dikembalikan oleh pemilih (karena rusak atau keliru coblos) | E35: 0 | F35: 0 | G35: 0 | H35: 0 | I35: 0 | J35: 1 | K35: 2 | L35: 0 | M35: 5 | N35: 0 | O35: 0 | P35: 6 | Q35: 0 | R35: 0 | S35: 0 | T35: 0 | U35: 0 | V35: 0 | W35: 0 | X35: 0 | Y35: 2 | Z35: 0 | AA35: 0 | AB35: 0 | AC35: 2 | AD35: 1 | AE35: 0 | AF35: =SUM(E35:AE35) -> 19
A36: 4 | B36: Jumlah surat suara yang tidak digunakan/tidak terpakai, termasuk sisa surat suara cadangan | E36: =E33-(E34+E35) -> 64 | F36: =F33-(F34+F35) -> 35 | G36: =G33-(G34+G35) -> 64 | H36: =H33-(H34+H35) -> 55 | I36: =I33-(I34+I35) -> 41 | J36: =J33-(J34+J35) -> 46 | K36: =K33-(K34+K35) -> 62 | L36: =L33-(L34+L35) -> 71 | ... AE36: =AE33-(AE34+AE35) -> 32 | AF36: =SUM(E36:AE36) -> 1551
A38: III | B38: DATA PEMILIH DISABILITAS
B39: Jumlah seluruh Pemilih disabilitas yang menggunakan hak pilih | D39: LK | E39: 0 | F39: 0 | G39: 0 | H39: 0 | I39: 0 | J39: 2 | K39: 1 | L39: 0 | M39: 0 | N39: 0 | O39: 0 | P39: 0 | Q39: 0 | R39: 0 | S39: 0 | T39: 0 | U39: 0 | V39: 0 | W39: 1 | X39: 0 | Y39: 0 | Z39: 0 | AA39: 0 | AB39: 0 | AC39: 0 | AD39: 0 | AE39: 0 | AF39: =SUM(E39:AE39) -> 4
D40: PR | E40: 0 | F40: 0 | G40: 0 | H40: 0 | I40: 0 | J40: 0 | K40: 1 | L40: 0 | M40: 0 | N40: 0 | O40: 1 | P40: 0 | Q40: 0 | R40: 0 | S40: 0 | T40: 0 | U40: 0 | V40: 0 | W40: 1 | X40: 0 | Y40: 0 | Z40: 0 | AA40: 0 | AB40: 0 | AC40: 0 | AD40: 0 | AE40: 0 | AF40: =SUM(E40:AE40) -> 3
D41: JML | E41: =SUM(E39:E40) -> 0 | F41: =SUM(F39:F40) -> 0 | G41: =SUM(G39:G40) -> 0 | H41: =SUM(H39:H40) -> 0 | I41: =SUM(I39:I40) -> 0 | J41: =SUM(J39:J40) -> 2 | K41: =SUM(K39:K40) -> 2 | L41: =SUM(L39:L40) -> 0 | ... AE41: =SUM(AE39:AE40) -> 0 | AF41: =SUM(E41:AE41) -> 7
A43: IV | B43: DATA RINCIAN PEROLEHAN SUARA PASANGAN CALON BUPATI DAN WAKIL BUPATI
A44: NOMOR DAN NAMA CALON
A45: A.1 | B45: 1. | C45: Partai Kebangkitan Bangsa | E45: 9 | F45: 5 | G45: 3 | H45: 3 | I45: 3 | J45: 6 | K45: 3 | L45: 3 | M45: 6 | N45: 6 | O45: 7 | P45: 16 | Q45: 3 | R45: 9 | S45: 7 | T45: 5 | U45: 8 | V45: 8 | W45: 6 | X45: 0 | Y45: 7 | Z45: 1 | AA45: 0 | AB45: 9 | AC45: 3 | AD45: 1 | AE45: 2 | AF45: =SUM(E45:AE45) -> 139
A46: A.2 | B46: 1 | C46: 1. Dr. Hj. NIHAYATUL WAFIROH, M.A. | E46: 41 | F46: 9 | G46: 22 | H46: 15 | I46: 8 | J46: 13 | K46: 8 | L46: 26 | M46: 24 | N46: 43 | O46: 18 | P46: 77 | Q46: 18 | R46: 49 | S46: 54 | T46: 41 | U46: 22 | V46: 18 | W46: 24 | X46: 35 | Y46: 12 | Z46: 18 | AA46: 23 | AB46: 40 | AC46: 26 | AD46: 13 | AE46: 20 | AF46: =SUM(E46:AE46) -> 717
B47: 2 | C47: 2. H. M. NASIM KHAN | E47: 2 | F47: 0 | G47: 3 | H47: 1 | I47: 0 | J47: 2 | K47: 0 | L47: 3 | M47: 0 | N47: 3 | O47: 1 | P47: 7 | Q47: 1 | R47: 9 | S47: 10 | T47: 3 | U47: 0 | V47: 2 | W47: 0 | X47: 2 | Y47: 1 | Z47: 2 | AA47: 8 | AB47: 24 | AC47: 55 | AD47: 0 | AE47: 3 | AF47: =SUM(E47:AE47) -> 142
B48: 3 | C48: 3. Dr. H. AKIK ZAMAN, M.Pd.I. | E48: 1 | F48: 0 | G48: 0 | H48: 0 | I48: 0 | J48: 1 | K48: 0 | L48: 0 | M48: 0 | N48: 1 | O48: 1 | P48: 1 | Q48: 0 | R48: 1 | S48: 1 | T48: 0 | U48: 1 | V48: 0 | W48: 0 | X48: 0 | Y48: 1 | Z48: 0 | AA48: 0 | AB48: 0 | AC48: 1 | AD48: 0 | AE48: 0 | AF48: =SUM(E48:AE48) -> 10
B49: 4 | C49: 4. AHMAD RIFA'I, S.H. | E49: 0 | F49: 0 | G49: 0 | H49: 0 | I49: 0 | J49: 2 | K49: 0 | L49: 1 | M49: 0 | N49: 3 | O49: 0 | P49: 1 | Q49: 0 | R49: 0 | S49: 0 | T49: 1 | U49: 0 | V49: 0 | W49: 0 | X49: 1 | Y49: 1 | Z49: 0 | AA49: 3 | AB49: 0 | AC49: 0 | AD49: 0 | AE49: 0 | AF49: =SUM(E49:AE49) -> 13
B50: 5 | C50: 5. Drs. H. MAHFUD M.N. | E50: 0 | F50: 1 | G50: 1 | H50: 0 | I50: 0 | J50: 0 | K50: 1 | L50: 2 | M50: 0 | N50: 1 | O50: 1 | P50: 1 | Q50: 1 | R50: 0 | S50: 4 | T50: 2 | U50: 1 | V50: 2 | W50: 0 | X50: 0 | Y50: 0 | Z50: 0 | AA50: 1 | AB50: 0 | AC50: 0 | AD50: 0 | AE50: 0 | AF50: =SUM(E50:AE50) -> 19
B51: 6 | C51: 6. NURHAYATI, S.Pd. | E51: 0 | F51: 1 | G51: 0 | H51: 1 | I51: 0 | J51: 0 | K51: 1 | L51: 3 | M51: 1 | N51: 1 | O51: 1 | P51: 0 | Q51: 0 | R51: 0 | S51: 1 | T51: 0 | U51: 1 | V51: 0 | W51: 1 | X51: 0 | Y51: 2 | Z51: 0 | AA51: 0 | AB51: 0 | AC51: 0 | AD51: 1 | AE51: 0 | AF51: =SUM(E51:AE51) -> 15
...

Sheet SAMBIREJO
C2: Kecamatan | D2: BANGOREJO
C3: Kabupaten | D3: BANYUWANGI
C4: Provinsi | D4: JAWA TIMUR
C9: Kelurahan | D9: SAMBIREJO
A12: I | B12: DATA PEMILIH DAN PENGGUNAAN HAK PILIH | AF12: JUMLAH AKHIR
A13: A | B13: DATA PEMILIH | E13: TPS 001 | F13: TPS 002 | G13: TPS 003 | H13: TPS 004 | I13: TPS 005 | J13: TPS 006 | K13: TPS 007 | L13: TPS 008 | M13: TPS 009 | N13: TPS 010 | O13: TPS 011 | P13: TPS 012 | Q13: TPS 013 | R13: TPS 014 | S13: TPS 015 | T13: TPS 016 | U13: TPS 017 | V13: TPS 018 | W13: TPS 019 | X13: TPS 020 | Y13: TPS 021 | Z13: TPS 022 | AA13: TPS 023 | AB13: TPS 024 | AC13: TPS 025 | AD13: TPS 026 | AE13: TPS 027
B14: Jumlah Pemilih dalam Daftar Pemilih Tetap (DPT) | D14: LK | E14: 154 | F14: 144 | G14: 142 | H14: 113 | I14: 124 | J14: 132 | K14: 113 | L14: 131 | M14: 131 | N14: 116 | O14: 138 | P14: 130 | Q14: 147 | R14: 152 | S14: 146 | T14: 121 | U14: 142 | V14: 144 | W14: 120 | X14: 113 | Y14: 139 | Z14: 129 | AA14: 138 | AB14: 150 | AC14: 136 | AD14: 131 | AE14: 137 | AF14: =SUM(E14:AE14) -> 3613
D15: PR | E15: 141 | F15: 136 | G15: 135 | H15: 116 | I15: 108 | J15: 134 | K15: 125 | L15: 148 | M15: 149 | N15: 115 | O15: 124 | P15: 132 | Q15: 139 | R15: 131 | S15: 138 | T15: 114 | U15: 139 | V15: 132 | W15: 118 | X15: 126 | Y15: 138 | Z15: 125 | AA15: 141 | AB15: 129 | AC15: 146 | AD15: 125 | AE15: 146 | AF15: =SUM(E15:AE15) -> 3550
D16: JML | E16: =SUM(E14:E15) -> 295 | F16: =SUM(F14:F15) -> 280 | G16: =SUM(G14:G15) -> 277 | H16: =SUM(H14:H15) -> 229 | I16: =SUM(I14:I15) -> 232 | J16: =SUM(J14:J15) -> 266 | K16: =SUM(K14:K15) -> 238 | L16: =SUM(L14:L15) -> 279 | ... AE16: =SUM(AE14:AE15) -> 283 | AF16: =SUM(E16:AE16) -> 7163
A18: B | B18: PENGGUNA HAK PILIH
B19: 1. | C19: Jumlah pengguna hak pilih dalam Daftar Pemilih Tetap (DPT) | D19: LK | E19: 130 | F19: 127 | G19: 99 | H19: 92 | I19: 98 | J19: 107 | K19: 89 | L19: 92 | M19: 94 | N19: 79 | O19: 104 | P19: 95 | Q19: 110 | R19: 105 | S19: 99 | T19: 83 | U19: 98 | V19: 102 | W19: 102 | X19: 88 | Y19: 103 | Z19: 102 | AA19: 114 | AB19: 104 | AC19: 103 | AD19: 109 | AE19: 105 | AF19: =SUM(E19:AE19) -> 2733
D20: PR | E20: 112 | F20: 109 | G20: 115 | H20: 90 | I20: 89 | J20: 108 | K20: 101 | L20: 123 | M20: 121 | N20: 91 | O20: 95 | P20: 95 | Q20: 111 | R20: 100 | S20: 101 | T20: 81 | U20: 102 | V20: 92 | W20: 97 | X20: 94 | Y20: 110 | Z20: 103 | AA20: 121 | AB20: 107 | AC20: 119 | AD20: 105 | AE20: 108 | AF20: =SUM(E20:AE20) -> 2800
D21: JML | E21: =SUM(E19:E20) -> 242 | F21: =SUM(F19:F20) -> 236 | G21: =SUM(G19:G20) -> 214 | H21: =SUM(H19:H20) -> 182 | I21: =SUM(I19:I20) -> 187 | J21: =SUM(J19:J20) -> 215 | K21: =SUM(K19:K20) -> 190 | L21: =SUM(L19:L20) -> 215 | ... AE21: =SUM(AE19:AE20) -> 213 | AF21: =SUM(E21:AE21) -> 5533
B22: 2. | C22: Jumlah pengguna hak pilih dalam Daftar Pemilih Tambahan (DPTb) | D22: LK | E22: 0 | F22: 1 | G22: 0 | H22: 0 | I22: 0 | J22: 0 | K22: 0 | L22: 0 | M22: 0 | N22: 0 | O22: 0 | P22: 0 | Q22: 0 | R22: 0 | S22: 0 | T22: 0 | U22: 0 | V22: 0 | W22: 0 | X22: 0 | Y22: 0 | Z22: 0 | AA22: 0 | AB22: 0 | AC22: 0 | AD22: 0 | AE22: 0 | AF22: =SUM(E22:AE22) -> 1
D23: PR | E23: 0 | F23: 1 | G23: 0 | H23: 0 | I23: 0 | J23: 0 | K23: 0 | L23: 0 | M23: 0 | N23: 0 | O23: 0 | P23: 0 | Q23: 0 | R23: 0 | S23: 0 | T23: 0 | U23: 0 | V23: 0 | W23: 0 | X23: 0 | Y23: 0 | Z23: 0 | AA23: 1 | AB23: 1 | AC23: 0 | AD23: 1 | AE23: 0 | AF23: =SUM(E23:AE23) -> 4
D24: JML | E24: =SUM(E22:E23) -> 0 | F24: =SUM(F22:F23) -> 2 | G24: =SUM(G22:G23) -> 0 | H24: =SUM(H22:H23) -> 0 | I24: =SUM(I22:I23) -> 0 | J24: =SUM(J22:J23) -> 0 | K24: =SUM(K22:K23) -> 0 | L24: =SUM(L22:L23) -> 0 | ... AE24: =SUM(AE22:AE23) -> 0 | AF24: =SUM(E24:AE24) -> 5
B25: 3. | C25: Jumlah pengguna hak pilih dalam Daftar Pemilih Khusus (DPK) | D25: LK | E25: 0 | F25: 2 | G25: 2 | H25: 1 | I25: 0 | J25: 0 | K25: 2 | L25: 0 | M25: 0 | N25: 1 | O25: 3 | P25: 1 | Q25: 0 | R25: 0 | S25: 1 | T25: 2 | U25: 0 | V25: 0 | W25: 0 | X25: 0 | Y25: 1 | Z25: 2 | AA25: 0 | AB25: 0 | AC25: 1 | AD25: 0 | AE25: 0 | AF25: =SUM(E25:AE25) -> 19
D26: PR | E26: 0 | F26: 3 | G26: 2 | H26: 4 | I26: 0 | J26: 0 | K26: 0 | L26: 0 | M26: 0 | N26: 1 | O26: 0 | P26: 0 | Q26: 0 | R26: 0 | S26: 1 | T26: 1 | U26: 0 | V26: 3 | W26: 1 | X26: 3 | Y26: 1 | Z26: 0 | AA26: 0 | AB26: 0 | AC26: 1 | AD26: 2 | AE26: 1 | AF26: =SUM(E26:AE26) -> 24
D27: JML | E27: =SUM(E25:E26) -> 0 | F27: =SUM(F25:F26) -> 5 | G27: =SUM(G25:G26) -> 4 | H27: =SUM(H25:H26) -> 5 | I27: =SUM(I25:I26) -> 0 | J27: =SUM(J25:J26) -> 0 | K27: =SUM(K25:K26) -> 2 | L27: =SUM(L25:L26) -> 0 | ... AE27: =SUM(AE25:AE26) -> 1 | AF27: =SUM(E27:AE27) -> 43
B28: 4. | C28: Jumlah Pengguna Hak Pilih (B.1+B.2+B.3) | D28: LK | E28: =SUM(E19,E22,E25) -> 130 | F28: =SUM(F19,F22,F25) -> 130 | G28: =SUM(G19,G22,G25) -> 101 | H28: =SUM(H19,H22,H25) -> 93 | I28: =SUM(I19,I22,I25) -> 98 | J28: =SUM(J19,J22,J25) -> 107 | K28: =SUM(K19,K22,K25) -> 91 | L28: =SUM(L19,L22,L25) -> 92 | ... AE28: =SUM(AE19,AE22,AE25) -> 105 | AF28: =SUM(E28:AE28) -> 2753
D29: PR | E29: =SUM(E20,E23,E26) -> 112 | F29: =SUM(F20,F23,F26) -> 113 | G29: =SUM(G20,G23,G26) -> 117 | H29: =SUM(H20,H23,H26) -> 94 | I29: =SUM(I20,I23,I26) -> 89 | J29: =SUM(J20,J23,J26) -> 108 | K29: =SUM(K20,K23,K26) -> 101 | L29: =SUM(L20,L23,L26) -> 123 | ... AE29: =SUM(AE20,AE23,AE26) -> 109 | AF29: =SUM(E29:AE29) -> 2828
D30: JML | E30: =SUM(E28:E29) -> 242 | F30: =SUM(F28:F29) -> 243 | G30: =SUM(G28:G29) -> 218 | H30: =SUM(H28:H29) -> 187 | I30: =SUM(I28:I29) -> 187 | J30: =SUM(J28:J29) -> 215 | K30: =SUM(K28:K29) -> 192 | L30: =SUM(L28:L29) -> 215 | ... AE30: =SUM(AE28:AE29) -> 214 | AF30: =SUM(E30:AE30) -> 5581
A32: II | B32: DATA PENGGUNAAN SURAT SUARA
A33: 1 | B33: Jumlah surat suara yang diterima, termasuk surat suara cadangan 2,5% dari DPT | E33: 300 | F33: 288 | G33: 293 | H33: 234 | I33: 235 | J33: 272 | K33: 243 | L33: 285 | M33: 286 | N33: 236 | O33: 268 | P33: 268 | Q33: 291 | R33: 289 | S33: 290 | T33: 240 | U33: 287 | V33: 276 | W33: 243 | X33: 244 | Y33: 283 | Z33: 260 | AA33: 285 | AB33: 285 | AC33: 288 | AD33: 262 | AE33: 289 | AF33: =SUM(E33:AE33) -> 7320
A34: 2 | B34: Jumlah surat suara yang digunakan | E34: 242 | F34: 243 | G34: 218 | H34: 187 | I34: 187 | J34: 215 | K34: 192 | L34: 215 | M34: 215 | N34: 172 | O34: 202 | P34: 191 | Q34: 221 | R34: 205 | S34: 202 | T34: 167 | U34: 200 | V34: 197 | W34: 200 | X34: 185 | Y34: 215 | Z34: 207 | AA34: 236 | AB34: 212 | AC34: 224 | AD34: 217 | AE34: 214 | AF34: =SUM(E34:AE34) -> 5581
A35: 3 | B35: Jumlah surat suara dikembalikan oleh pemilih (karena rusak atau keliru coblos) | E35: 3 | F35: 0 | G35: 0 | H35: 0 | I35: 0 | J35: 3 | K35: 4 | L35: 1 | M35: 0 | N35: 0 | O35: 0 | P35: 0 | Q35: 0 | R35: 0 | S35: 0 | T35: 0 | U35: 0 | V35: 0 | W35: 0 | X35: 1 | Y35: 2 | Z35: 0 | AA35: 0 | AB35: 0 | AC35: 0 | AD35: 0 | AE35: 0 | AF35: =SUM(E35:AE35) -> 14
A36: 4 | B36: Jumlah surat suara yang tidak digunakan/tidak terpakai, termasuk sisa surat suara cadangan | E36: =E33-(E34+E35) -> 55 | F36: =F33-(F34+F35) -> 45 | G36: =G33-(G34+G35) -> 75 | H36: =H33-(H34+H35) -> 47 | I36: =I33-(I34+I35) -> 48 | J36: =J33-(J34+J35) -> 54 | K36: =K33-(K34+K35) -> 47 | L36: =L33-(L34+L35) -> 69 | ... AE36: =AE33-(AE34+AE35) -> 75 | AF36: =SUM(E36:AE36) -> 1725
A38: III | B38: DATA PEMILIH DISABILITAS
B39: Jumlah seluruh Pemilih disabilitas yang menggunakan hak pilih | D39: LK | E39: 0 | F39: 1 | G39: 0 | H39: 0 | I39: 0 | J39: 0 | K39: 0 | L39: 0 | M39: 0 | N39: 0 | O39: 0 | P39: 0 | Q39: 0 | R39: 0 | S39: 0 | T39: 0 | U39: 0 | V39: 1 | W39: 0 | X39: 0 | Y39: 0 | Z39: 0 | AA39: 0 | AB39: 0 | AC39: 1 | AD39: 0 | AE39: 0 | AF39: =SUM(E39:AE39) -> 3
D40: PR | E40: 1 | F40: 0 | G40: 0 | H40: 0 | I40: 0 | J40: 0 | K40: 0 | L40: 0 | M40: 0 | N40: 0 | O40: 0 | P40: 0 | Q40: 0 | R40: 0 | S40: 0 | T40: 0 | U40: 0 | V40: 0 | W40: 0 | X40: 0 | Y40: 0 | Z40: 0 | AA40: 0 | AB40: 0 | AC40: 0 | AD40: 0 | AE40: 1 | AF40: =SUM(E40:AE40) -> 2
D41: JML | E41: =SUM(E39:E40) -> 1 | F41: =SUM(F39:F40) -> 1 | G41: =SUM(G39:G40) -> 0 | H41: =SUM(H39:H40) -> 0 | I41: =SUM(I39:I40) -> 0 | J41: =SUM(J39:J40) -> 0 | K41: =SUM(K39:K40) -> 0 | L41: =SUM(L39:L40) -> 0 | ... AE41: =SUM(AE39:AE40) -> 1 | AF41: =SUM(E41:AE41) -> 5
A43: IV | B43: DATA RINCIAN PEROLEHAN SUARA PASANGAN CALON BUPATI DAN WAKIL BUPATI
A44: NOMOR DAN NAMA CALON
A45: A.1 | B45: 1. | C45: Partai Kebangkitan Bangsa | E45: 3 | F45: 10 | G45: 19 | H45: 8 | I45: 2 | J45: 6 | K45: 6 | L45: 4 | M45: 0 | N45: 3 | O45: 1 | P45: 1 | Q45: 7 | R45: 10 | S45: 5 | T45: 8 | U45: 9 | V45: 4 | W45: 0 | X45: 10 | Y45: 8 | Z45: 5 | AA45: 3 | AB45: 2 | AC45: 5 | AD45: 1 | AE45: 3 | AF45: =SUM(E45:AE45) -> 143
A46: A.2 | B46: 1 | C46: 1. Dr. Hj. NIHAYATUL WAFIROH, M.A. | E46: 40 | F46: 24 | G46: 72 | H46: 38 | I46: 3 | J46: 17 | K46: 21 | L46: 21 | M46: 2 | N46: 16 | O46: 2 | P46: 17 | Q46: 31 | R46: 28 | S46: 16 | T46: 13 | U46: 36 | V46: 9 | W46: 19 | X46: 17 | Y46: 20 | Z46: 24 | AA46: 26 | AB46: 8 | AC46: 0 | AD46: 16 | AE46: 11 | AF46: =SUM(E46:AE46) -> 547
B47: 2 | C47: 2. H. M. NASIM KHAN | E47: 0 | F47: 0 | G47: 9 | H47: 5 | I47: 0 | J47: 2 | K47: 8 | L47: 9 | M47: 1 | N47: 2 | O47: 1 | P47: 2 | Q47: 2 | R47: 1 | S47: 0 | T47: 0 | U47: 1 | V47: 3 | W47: 0 | X47: 4 | Y47: 6 | Z47: 2 | AA47: 3 | AB47: 2 | AC47: 1 | AD47: 0 | AE47: 1 | AF47: =SUM(E47:AE47) -> 65
B48: 3 | C48: 3. Dr. H. AKIK ZAMAN, M.Pd.I. | E48: 1 | F48: 1 | G48: 1 | H48: 0 | I48: 0 | J48: 0 | K48: 1 | L48: 1 | M48: 0 | N48: 2 | O48: 0 | P48: 1 | Q48: 0 | R48: 0 | S48: 0 | T48: 0 | U48: 1 | V48: 0 | W48: 0 | X48: 0 | Y48: 0 | Z48: 2 | AA48: 1 | AB48: 0 | AC48: 0 | AD48: 2 | AE48: 0 | AF48: =SUM(E48:AE48) -> 14
B49: 4 | C49: 4. AHMAD RIFA'I, S.H. | E49: 1 | F49: 1 | G49: 0 | H49: 4 | I49: 1 | J49: 0 | K49: 1 | L49: 1 | M49: 0 | N49: 1 | O49: 0 | P49: 1 | Q49: 0 | R49: 1 | S49: 0 | T49: 1 | U49: 1 | V49: 0 | W49: 0 | X49: 2 | Y49: 2 | Z49: 1 | AA49: 0 | AB49: 2 | AC49: 0 | AD49: 2 | AE49: 2 | AF49: =SUM(E49:AE49) -> 25
B50: 5 | C50: 5. Drs. H. MAHFUD M.N. | E50: 0 | F50: 0 | G50: 0 | H50: 1 | I50: 0 | J50: 0 | K50: 0 | L50: 0 | M50: 0 | N50: 0 | O50: 0 | P50: 0 | Q50: 0 | R50: 1 | S50: 0 | T50: 1 | U50: 1 | V50: 0 | W50: 0 | X50: 1 | Y50: 0 | Z50: 0 | AA50: 0 | AB50: 0 | AC50: 0 | AD50: 0 | AE50: 1 | AF50: =SUM(E50:AE50) -> 6
B51: 6 | C51: 6. NURHAYATI, S.Pd. | E51: 2 | F51: 1 | G51: 1 | H51: 1 | I51: 0 | J51: 0 | K51: 0 | L51: 0 | M51: 0 | N51: 2 | O51: 0 | P51: 0 | Q51: 0 | R51: 2 | S51: 0 | T51: 0 | U51: 1 | V51: 0 | W51: 0 | X51: 1 | Y51: 0 | Z51: 1 | AA51: 2 | AB51: 1 | AC51: 0 | AD51: 0 | AE51: 0 | AF51: =SUM(E51:AE51) -> 15
...

Sheet SUKOREJO
C2: Kecamatan | D2: BANGOREJO
C3: Kabupaten | D3: BANYUWANGI
C4: Provinsi | D4: JAWA TIMUR
C9: Kelurahan | D9: SUKOREJO
A12: I | B12: DATA PEMILIH DAN PENGGUNAAN HAK PILIH | AB12: JUMLAH AKHIR
A13: A | B13: DATA PEMILIH | E13: TPS 001 | F13: TPS 002 | G13: TPS 003 | H13: TPS 004 | I13: TPS 005 | J13: TPS 006 | K13: TPS 007 | L13: TPS 008 | M13: TPS 009 | N13: TPS 010 | O13: TPS 011 | P13: TPS 012 | Q13: TPS 013 | R13: TPS 014 | S13: TPS 015 | T13: TPS 016 | U13: TPS 017 | V13: TPS 018 | W13: TPS 019 | X13: TPS 020 | Y13: TPS 021 | Z13: TPS 022 | AA13: TPS 023
B14: Jumlah Pemilih dalam Daftar Pemilih Tetap (DPT) | D14: LK | E14: 148 | F14: 141 | G14: 141 | H14: 107 | I14: 110 | J14: 133 | K14: 127 | L14: 115 | M14: 105 | N14: 128 | O14: 145 | P14: 157 | Q14: 141 | R14: 151 | S14: 132 | T14: 141 | U14: 153 | V14: 151 | W14: 137 | X14: 155 | Y14: 146 | Z14: 147 | AA14: 144 | AB14: =SUM(E14:AA14) -> 3155
D15: PR | E15: 131 | F15: 149 | G15: 143 | H15: 100 | I15: 107 | J15: 132 | K15: 127 | L15: 102 | M15: 112 | N15: 122 | O15: 149 | P15: 133 | Q15: 143 | R15: 135 | S15: 122 | T15: 140 | U15: 139 | V15: 139 | W15: 156 | X15: 127 | Y15: 147 | Z15: 143 | AA15: 147 | AB15: =SUM(E15:AA15) -> 3045
D16: JML | E16: =SUM(E14:E15) -> 279 | F16: =SUM(F14:F15) -> 290 | G16: =SUM(G14:G15) -> 284 | H16: =SUM(H14:H15) -> 207 | I16: =SUM(I14:I15) -> 217 | J16: =SUM(J14:J15) -> 265 | K16: =SUM(K14:K15) -> 254 | L16: =SUM(L14:L15) -> 217 | ... AA16: =SUM(AA14:AA15) -> 291 | AB16: =SUM(E16:AA16) -> 6200
A18: B | B18: PENGGUNA HAK PILIH
B19: 1. | C19: Jumlah pengguna hak pilih dalam Daftar Pemilih Tetap (DPT) | D19: LK | E19: 105 | F19: 112 | G19: 116 | H19: 90 | I19: 76 | J19: 104 | K19: 96 | L19: 88 | M19: 82 | N19: 109 | O19: 125 | P19: 109 | Q19: 102 | R19: 107 | S19: 105 | T19: 103 | U19: 115 | V19: 120 | W19: 104 | X19: 114 | Y19: 118 | Z19: 122 | AA19: 102 | AB19: =SUM(E19:AA19) -> 2424
D20: PR | E20: 107 | F20: 122 | G20: 121 | H20: 78 | I20: 78 | J20: 106 | K20: 109 | L20: 81 | M20: 84 | N20: 103 | O20: 122 | P20: 102 | Q20: 111 | R20: 110 | S20: 103 | T20: 118 | U20: 118 | V20: 122 | W20: 120 | X20: 116 | Y20: 126 | Z20: 120 | AA20: 113 | AB20: =SUM(E20:AA20) -> 2490
D21: JML | E21: =SUM(E19:E20) -> 212 | F21: =SUM(F19:F20) -> 234 | G21: =SUM(G19:G20) -> 237 | H21: =SUM(H19:H20) -> 168 | I21: =SUM(I19:I20) -> 154 | J21: =SUM(J19:J20) -> 210 | K21: =SUM(K19:K20) -> 205 | L21: =SUM(L19:L20) -> 169 | ... AA21: =SUM(AA19:AA20) -> 215 | AB21: =SUM(E21:AA21) -> 4914
B22: 2. | C22: Jumlah pengguna hak pilih dalam Daftar Pemilih Tambahan (DPTb) | D22: LK | E22: 0 | F22: 0 | G22: 0 | H22: 2 | I22: 0 | J22: 0 | K22: 0 | L22: 0 | M22: 0 | N22: 0 | O22: 0 | P22: 0 | Q22: 0 | R22: 0 | S22: 0 | T22: 0 | U22: 0 | V22: 0 | W22: 0 | X22: 0 | Y22: 0 | Z22: 0 | AA22: 0 | AB22: =SUM(E22:AA22) -> 2
D23: PR | E23: 0 | F23: 0 | G23: 0 | H23: 0 | I23: 0 | J23: 0 | K23: 0 | L23: 0 | M23: 0 | N23: 0 | O23: 0 | P23: 0 | Q23: 0 | R23: 0 | S23: 0 | T23: 0 | U23: 0 | V23: 0 | W23: 0 | X23: 0 | Y23: 0 | Z23: 0 | AA23: 0 | AB23: =SUM(E23:AA23) -> 0
D24: JML | E24: =SUM(E22:E23) -> 0 | F24: =SUM(F22:F23) -> 0 | G24: =SUM(G22:G23) -> 0 | H24: =SUM(H22:H23) -> 2 | I24: =SUM(I22:I23) -> 0 | J24: =SUM(J22:J23) -> 0 | K24: =SUM(K22:K23) -> 0 | L24: =SUM(L22:L23) -> 0 | ... AA24: =SUM(AA22:AA23) -> 0 | AB24: =SUM(E24:AA24) -> 2
B25: 3. | C25: Jumlah pengguna hak pilih dalam Daftar Pemilih Khusus (DPK) | D25: LK | E25: 0 | F25: 1 | G25: 0 | H25: 2 | I25: 0 | J25: 2 | K25: 0 | L25: 0 | M25: 0 | N25: 2 | O25: 3 | P25: 1 | Q25: 0 | R25: 0 | S25: 0 | T25: 0 | U25: 0 | V25: 0 | W25: 1 | X25: 0 | Y25: 0 | Z25: 1 | AA25: 1 | AB25: =SUM(E25:AA25) -> 14
D26: PR | E26: 0 | F26: 2 | G26: 0 | H26: 3 | I26: 3 | J26: 0 | K26: 0 | L26: 2 | M26: 0 | N26: 5 | O26: 6 | P26: 2 | Q26: 0 | R26: 1 | S26: 0 | T26: 0 | U26: 0 | V26: 0 | W26: 1 | X26: 0 | Y26: 0 | Z26: 2 | AA26: 1 | AB26: =SUM(E26:AA26) -> 28
D27: JML | E27: =SUM(E25:E26) -> 0 | F27: =SUM(F25:F26) -> 3 | G27: =SUM(G25:G26) -> 0 | H27: =SUM(H25:H26) -> 5 | I27: =SUM(I25:I26) -> 3 | J27: =SUM(J25:J26) -> 2 | K27: =SUM(K25:K26) -> 0 | L27: =SUM(L25:L26) -> 2 | ... AA27: =SUM(AA25:AA26) -> 2 | AB27: =SUM(E27:AA27) -> 42
B28: 4. | C28: Jumlah Pengguna Hak Pilih (B.1+B.2+B.3) | D28: LK | E28: =SUM(E19,E22,E25) -> 105 | F28: =SUM(F19,F22,F25) -> 113 | G28: =SUM(G19,G22,G25) -> 116 | H28: =SUM(H19,H22,H25) -> 94 | I28: =SUM(I19,I22,I25) -> 76 | J28: =SUM(J19,J22,J25) -> 106 | K28: =SUM(K19,K22,K25) -> 96 | L28: =SUM(L19,L22,L25) -> 88 | ... AA28: =SUM(AA19,AA22,AA25) -> 103 | AB28: =SUM(E28:AA28) -> 2440
