Workbook

Sheet DPR RI
C8: Kecamatan | D8: GAMBIRAN
C9: Kabupaten | D9: BANYUWANGI
C10: Provinsi | D10: JAWA TIMUR
A12: I | B12: DATA PEMILIH DAN PENGGUNAAN HAK PILIH | E12: JUMLAH AKHIR
A13: A | B13: DATA PEMILIH
B14: Jumlah Pemilih dalam Daftar Pemilih Tetap (DPT) | D14: LK | E14: =GAMBIRAN!AY14+JAJAG!BA14+PURWODADI!AC14+WRINGINAGUNG!AB14+WRINGINREJO!X14+YOSOMULYO!AP14 -> 25710
D15: PR | E15: =GAMBIRAN!AY15+JAJAG!BA15+PURWODADI!AC15+WRINGINAGUNG!AB15+WRINGINREJO!X15+YOSOMULYO!AP15 -> 26323
D16: JML | E16: =SUM(E14:E15) -> 52033
A18: B | B18: PENGGUNA HAK PILIH
B19: 1. | C19: Jumlah pengguna hak pilih dalam Daftar Pemilih Tetap (DPT) | D19: LK | E19: =GAMBIRAN!AY19+JAJAG!BA19+PURWODADI!AC19+WRINGINAGUNG!AB19+WRINGINREJO!X19+YOSOMULYO!AP19 -> 19014
D20: PR | E20: =GAMBIRAN!AY20+JAJAG!BA20+PURWODADI!AC20+WRINGINAGUNG!AB20+WRINGINREJO!X20+YOSOMULYO!AP20 -> 20748
D21: JML | E21: =SUM(E19:E20) -> 39762
B22: 2. | C22: Jumlah pengguna hak pilih dalam Daftar Pemilih Tambahan (DPTb) | D22: LK | E22: =GAMBIRAN!AY22+JAJAG!BA22+PURWODADI!AC22+WRINGINAGUNG!AB22+WRINGINREJO!X22+YOSOMULYO!AP22 -> 28
D23: PR | E23: =GAMBIRAN!AY23+JAJAG!BA23+PURWODADI!AC23+WRINGINAGUNG!AB23+WRINGINREJO!X23+YOSOMULYO!AP23 -> 24
D24: JML | E24: =SUM(E22:E23) -> 52
B25: 3. | C25: Jumlah pengguna hak pilih dalam Daftar Pemilih Khusus (DPK) | D25: LK | E25: =GAMBIRAN!AY25+JAJAG!BA25+PURWODADI!AC25+WRINGINAGUNG!AB25+WRINGINREJO!X25+YOSOMULYO!AP25 -> 200
D26: PR | E26: =GAMBIRAN!AY26+JAJAG!BA26+PURWODADI!AC26+WRINGINAGUNG!AB26+WRINGINREJO!X26+YOSOMULYO!AP26 -> 230
D27: JML | E27: =SUM(E25:E26) -> 430
B28: 4. | C28: Jumlah Pengguna Hak Pilih (B.1+B.2+B.3) | D28: LK | E28: =E19+E22+E25 -> 19242
D29: PR | E29: =E20+E23+E26 -> 21002
D30: JML | E30: =SUM(E28:E29) -> 40244
A32: II | B32: DATA PENGGUNAAN SURAT SUARA
A33: 1 | B33: Jumlah surat suara yang diterima, termasuk surat suara cadangan 2,5% dari DPT | E33: =GAMBIRAN!AY33+JAJAG!BA33+PURWODADI!AC33+WRINGINAGUNG!AB33+WRINGINREJO!X33+YOSOMULYO!AP33 -> 53221
A34: 2 | B34: Jumlah surat suara yang digunakan | E34: =GAMBIRAN!AY34+JAJAG!BA34+PURWODADI!AC34+WRINGINAGUNG!AB34+WRINGINREJO!X34+YOSOMULYO!AP34 -> 40244
A35: 3 | B35: Jumlah surat suara dikembalikan oleh pemilih (karena rusak atau keliru coblos) | E35: =GAMBIRAN!AY35+JAJAG!BA35+PURWODADI!AC35+WRINGINAGUNG!AB35+WRINGINREJO!X35+YOSOMULYO!AP35 -> 72
A36: 4 | B36: Jumlah surat suara yang tidak digunakan/tidak terpakai, termasuk sisa surat suara cadangan | E36: =E33-(E34+E35) -> 12905
A38: III | B38: DATA PEMILIH DISABILITAS
B39: Jumlah seluruh Pemilih disabilitas yang menggunakan hak pilih | D39: LK | E39: =GAMBIRAN!AY39+JAJAG!BA39+PURWODADI!AC39+WRINGINAGUNG!AB39+WRINGINREJO!X39+YOSOMULYO!AP39 -> 35
D40: PR | E40: =GAMBIRAN!AY40+JAJAG!BA40+PURWODADI!AC40+WRINGINAGUNG!AB40+WRINGINREJO!X40+YOSOMULYO!AP40 -> 43
D41: JML | E41: =SUM(E39:E40) -> 78
A43: IV | B43: DATA RINCIAN PEROLEHAN SUARA PASANGAN CALON BUPATI DAN WAKIL BUPATI
A44: NOMOR DAN NAMA CALON
A45: A.1 | B45: 1. | C45: Partai Kebangkitan Bangsa | E45: =GAMBIRAN!AY45+JAJAG!BA45+PURWODADI!AC45+WRINGINAGUNG!AB45+WRINGINREJO!X45+YOSOMULYO!AP45 -> 1123
A46: A.2 | B46: 1 | C46: 1. Dr. Hj. NIHAYATUL WAFIROH, M.A. | E46: =GAMBIRAN!AY46+JAJAG!BA46+PURWODADI!AC46+WRINGINAGUNG!AB46+WRINGINREJO!X46+YOSOMULYO!AP46 -> 3216
B47: 2 | C47: 2. H. M. NASIM KHAN | E47: =GAMBIRAN!AY47+JAJAG!BA47+PURWODADI!AC47+WRINGINAGUNG!AB47+WRINGINREJO!X47+YOSOMULYO!AP47 -> 228
B48: 3 | C48: 3. Dr. H. AKIK ZAMAN, M.Pd.I. | E48: =GAMBIRAN!AY48+JAJAG!BA48+PURWODADI!AC48+WRINGINAGUNG!AB48+WRINGINREJO!X48+YOSOMULYO!AP48 -> 154
B49: 4 | C49: 4. AHMAD RIFA'I, S.H. | E49: =GAMBIRAN!AY49+JAJAG!BA49+PURWODADI!AC49+WRINGINAGUNG!AB49+WRINGINREJO!X49+YOSOMULYO!AP49 -> 227
B50: 5 | C50: 5. Drs. H. MAHFUD M.N. | E50: =GAMBIRAN!AY50+JAJAG!BA50+PURWODADI!AC50+WRINGINAGUNG!AB50+WRINGINREJO!X50+YOSOMULYO!AP50 -> 87
B51: 6 | C51: 6. NURHAYATI, S.Pd. | E51: =GAMBIRAN!AY51+JAJAG!BA51+PURWODADI!AC51+WRINGINAGUNG!AB51+WRINGINREJO!X51+YOSOMULYO!AP51 -> 148
B52: 7 | C52: 7. MAFTUHA KISWAH | E52: =GAMBIRAN!AY52+JAJAG!BA52+PURWODADI!AC52+WRINGINAGUNG!AB52+WRINGINREJO!X52+YOSOMULYO!AP52 -> 41
...

Sheet GAMBIRAN
C2: Kecamatan | D2: GAMBIRAN
C3: Kabupaten | D3: BANYUWANGI
C4: Provinsi | D4: JAWA TIMUR
C9: Kelurahan | D9: GAMBIRAN
A12: I | B12: DATA PEMILIH DAN PENGGUNAAN HAK PILIH | AY12: JUMLAH AKHIR
A13: A | B13: DATA PEMILIH | E13: TPS 001 | F13: TPS 002 | G13: TPS 003 | H13: TPS 004 | I13: TPS 005 | J13: TPS 006 | K13: TPS 007 | L13: TPS 008 | M13: TPS 009 | N13: TPS 010 | O13: TPS 011 | P13: TPS 012 | Q13: TPS 013 | R13: TPS 014 | S13: TPS 015 | T13: TPS 016 | U13: TPS 017 | V13: TPS 018 | W13: TPS 019 | X13: TPS 020 | Y13: TPS 021 | Z13: TPS 022 | AA13: TPS 023 | AB13: TPS 024 | AC13: TPS 025 | AD13: TPS 026 | AE13: TPS 027 | AF13: TPS 028 | AG13: TPS 029 | AH13: TPS 030 | AI13: TPS 031 | AJ13: TPS 032 | AK13: TPS 033 | AL13: TPS 034 | AM13: TPS 035 | AN13: TPS 036 | AO13: TPS 037 | AP13: TPS 038 | AQ13: TPS 039 | AR13: TPS 040 | AS13: TPS 041 | AT13: TPS 042 | AU13: TPS 043 | AV13: TPS 044 | AW13: TPS 045 | AX13: TPS 046
B14: Jumlah Pemilih dalam Daftar Pemilih Tetap (DPT) | D14: LK | E14: 123 | F14: 140 | G14: 122 | H14: 121 | I14: 142 | J14: 124 | K14: 123 | L14: 132 | M14: 104 | N14: 142 | O14: 149 | P14: 134 | Q14: 113 | R14: 101 | S14: 103 | T14: 128 | U14: 135 | V14: 137 | W14: 145 | X14: 137 | Y14: 131 | Z14: 133 | AA14: 122 | AB14: 121 | AC14: 132 | AD14: 131 | AE14: 113 | AF14: 95 | AG14: 141 | AH14: 80 | AI14: 134 | AJ14: 134 | AK14: 148 | AL14: 149 | AM14: 137 | AN14: 139 | AO14: 144 | AP14: 130 | AQ14: 148 | AR14: 132 | AS14: 145 | AT14: 134 | AU14: 145 | AV14: 136 | AW14: 131 | AX14: 154 | AY14: =SUM(E14:AX14) -> 5994
D15: PR | E15: 112 | F15: 126 | G15: 132 | H15: 134 | I15: 139 | J15: 142 | K15: 109 | L15: 126 | M15: 130 | N15: 153 | O15: 140 | P15: 127 | Q15: 109 | R15: 121 | S15: 117 | T15: 151 | U15: 149 | V15: 137 | W15: 143 | X15: 140 | Y15: 145 | Z15: 135 | AA15: 120 | AB15: 102 | AC15: 145 | AD15: 133 | AE15: 116 | AF15: 109 | AG15: 130 | AH15: 71 | AI15: 134 | AJ15: 143 | AK15: 142 | AL15: 144 | AM15: 148 | AN15: 136 | AO15: 146 | AP15: 143 | AQ15: 136 | AR15: 127 | AS15: 140 | AT15: 126 | AU15: 135 | AV15: 136 | AW15: 139 | AX15: 124 | AY15: =SUM(E15:AX15) -> 6042
D16: JML | E16: =SUM(E14:E15) -> 235 | F16: =SUM(F14:F15) -> 266 | G16: =SUM(G14:G15) -> 254 | H16: =SUM(H14:H15) -> 255 | I16: =SUM(I14:I15) -> 281 | J16: =SUM(J14:J15) -> 266 | K16: =SUM(K14:K15) -> 232 | L16: =SUM(L14:L15) -> 258 | ... AX16: =SUM(AX14:AX15) -> 278 | AY16: =SUM(E16:AX16) -> 12036
A18: B | B18: PENGGUNA HAK PILIH
B19: 1. | C19: Jumlah pengguna hak pilih dalam Daftar Pemilih Tetap (DPT) | D19: LK | E19: 85 | F19: 106 | G19: 76 | H19: 77 | I19: 96 | J19: 88 | K19: 88 | L19: 94 | M19: 65 | N19: 103 | O19: 94 | P19: 99 | Q19: 82 | R19: 71 | S19: 83 | T19: 91 | U19: 102 | V19: 102 | W19: 96 | X19: 116 | Y19: 95 | Z19: 100 | AA19: 90 | AB19: 90 | AC19: 85 | AD19: 94 | AE19: 89 | AF19: 68 | AG19: 114 | AH19: 63 | AI19: 98 | AJ19: 101 | AK19: 106 | AL19: 111 | AM19: 117 | AN19: 99 | AO19: 107 | AP19: 94 | AQ19: 103 | AR19: 91 | AS19: 103 | AT19: 106 | AU19: 118 | AV19: 97 | AW19: 85 | AX19: 98 | AY19: =SUM(E19:AX19) -> 4336
D20: PR | E20: 95 | F20: 98 | G20: 95 | H20: 91 | I20: 110 | J20: 108 | K20: 79 | L20: 100 | M20: 101 | N20: 112 | O20: 90 | P20: 108 | Q20: 93 | R20: 82 | S20: 96 | T20: 107 | U20: 122 | V20: 118 | W20: 104 | X20: 115 | Y20: 120 | Z20: 104 | AA20: 103 | AB20: 89 | AC20: 110 | AD20: 109 | AE20: 99 | AF20: 92 | AG20: 109 | AH20: 59 | AI20: 104 | AJ20: 105 | AK20: 118 | AL20: 126 | AM20: 129 | AN20: 103 | AO20: 122 | AP20: 110 | AQ20: 93 | AR20: 103 | AS20: 107 | AT20: 103 | AU20: 112 | AV20: 105 | AW20: 98 | AX20: 102 | AY20: =SUM(E20:AX20) -> 4758
D21: JML | E21: =SUM(E19:E20) -> 180 | F21: =SUM(F19:F20) -> 204 | G21: =SUM(G19:G20) -> 171 | H21: =SUM(H19:H20) -> 168 | I21: =SUM(I19:I20) -> 206 | J21: =SUM(J19:J20) -> 196 | K21: =SUM(K19:K20) -> 167 | L21: =SUM(L19:L20) -> 194 | ... AX21: =SUM(AX19:AX20) -> 200 | AY21: =SUM(E21:AX21) -> 9094
B22: 2. | C22: Jumlah pengguna hak pilih dalam Daftar Pemilih Tambahan (DPTb) | D22: LK | E22: 0 | F22: 1 | G22: 0 | H22: 0 | I22: 0 | J22: 0 | K22: 0 | L22: 0 | M22: 0 | N22: 0 | O22: 3 | P22: 1 | Q22: 1 | R22: 0 | S22: 0 | AI22: 0 | AJ22: 2 | AK22: 0 | AL22: 0 | AM22: 0 | AN22: 0 | AO22: 0 | AP22: 0 | AQ22: 0 | AR22: 1 | AS22: 0 | AT22: 0 | AU22: 0 | AV22: 0 | AW22: 0 | AY22: =SUM(E22:AX22) -> 9
D23: PR | E23: 0 | F23: 0 | G23: 0 | H23: 0 | I23: 0 | J23: 0 | K23: 0 | L23: 0 | M23: 0 | N23: 0 | O23: 5 | P23: 2 | Q23: 1 | R23: 0 | S23: 0 | AI23: 0 | AJ23: 1 | AK23: 0 | AL23: 0 | AM23: 0 | AN23: 0 | AO23: 0 | AP23: 0 | AQ23: 0 | AR23: 0 | AS23: 0 | AT23: 0 | AU23: 0 | AV23: 0 | AW23: 0 | AY23: =SUM(E23:AX23) -> 9
D24: JML | E24: =SUM(E22:E23) -> 0 | F24: =SUM(F22:F23) -> 1 | G24: =SUM(G22:G23) -> 0 | H24: =SUM(H22:H23) -> 0 | I24: =SUM(I22:I23) -> 0 | J24: =SUM(J22:J23) -> 0 | K24: =SUM(K22:K23) -> 0 | L24: =SUM(L22:L23) -> 0 | ... AX24: =SUM(AX22:AX23) -> 0 | AY24: =SUM(E24:AX24) -> 18
B25: 3. | C25: Jumlah pengguna hak pilih dalam Daftar Pemilih Khusus (DPK) | D25: LK | E25: 1 | F25: 0 | G25: 0 | H25: 1 | I25: 1 | J25: 1 | K25: 0 | L25: 0 | M25: 0 | N25: 2 | O25: 0 | P25: 0 | Q25: 2 | R25: 0 | S25: 0 | T25: 1 | U25: 0 | V25: 0 | W25: 2 | X25: 0 | Y25: 0 | Z25: 0 | AA25: 0 | AB25: 1 | AC25: 1 | AD25: 0 | AE25: 1 | AF25: 0 | AG25: 0 | AH25: 0 | AI25: 0 | AJ25: 0 | AK25: 0 | AL25: 0 | AM25: 4 | AN25: 4 | AO25: 0 | AP25: 0 | AQ25: 0 | AR25: 1 | AS25: 0 | AT25: 1 | AU25: 0 | AV25: 1 | AW25: 4 | AY25: =SUM(E25:AX25) -> 29
D26: PR | E26: 1 | F26: 0 | G26: 0 | H26: 0 | I26: 1 | J26: 2 | K26: 0 | L26: 0 | M26: 0 | N26: 1 | O26: 0 | P26: 0 | Q26: 1 | R26: 0 | S26: 0 | T26: 2 | U26: 0 | V26: 0 | W26: 5 | X26: 0 | Y26: 0 | Z26: 0 | AA26: 0 | AB26: 2 | AC26: 3 | AD26: 0 | AE26: 2 | AF26: 1 | AG26: 0 | AH26: 0 | AI26: 0 | AJ26: 0 | AK26: 0 | AL26: 0 | AM26: 5 | AN26: 4 | AO26: 0 | AP26: 0 | AQ26: 0 | AR26: 2 | AS26: 0 | AT26: 0 | AU26: 0 | AV26: 2 | AW26: 4 | AY26: =SUM(E26:AX26) -> 38
D27: JML | E27: =SUM(E25:E26) -> 2 | F27: =SUM(F25:F26) -> 0 | G27: =SUM(G25:G26) -> 0 | H27: =SUM(H25:H26) -> 1 | I27: =SUM(I25:I26) -> 2 | J27: =SUM(J25:J26) -> 3 | K27: =SUM(K25:K26) -> 0 | L27: =SUM(L25:L26) -> 0 | ... AX27: =SUM(AX25:AX26) -> 0 | AY27: =SUM(E27:AX27) -> 67
B28: 4. | C28: Jumlah Pengguna Hak Pilih (B.1+B.2+B.3) | D28: LK | E28: =SUM(E19,E22,E25) -> 86 | F28: =SUM(F19,F22,F25) -> 107 | G28: =SUM(G19,G22,G25) -> 76 | H28: =SUM(H19,H22,H25) -> 78 | I28: =SUM(I19,I22,I25) -> 97 | J28: =SUM(J19,J22,J25) -> 89 | K28: =SUM(K19,K22,K25) -> 88 | L28: =SUM(L19,L22,L25) -> 94 | ... AX28: =SUM(AX19,AX22,AX25) -> 98 | AY28: =SUM(E28:AX28) -> 4374
D29: PR | E29: =SUM(E20,E23,E26) -> 96 | F29: =SUM(F20,F23,F26) -> 98 | G29: =SUM(G20,G23,G26) -> 95 | H29: =SUM(H20,H23,H26) -> 91 | I29: =SUM(I20,I23,I26) -> 111 | J29: =SUM(J20,J23,J26) -> 110 | K29: =SUM(K20,K23,K26) -> 79 | L29: =SUM(L20,L23,L26) -> 100 | ... AX29: =SUM(AX20,AX23,AX26) -> 102 | AY29: =SUM(E29:AX29) -> 4805
D30: JML | E30: =SUM(E28:E29) -> 182 | F30: =SUM(F28:F29) -> 205 | G30: =SUM(G28:G29) -> 171 | H30: =SUM(H28:H29) -> 169 | I30: =SUM(I28:I29) -> 208 | J30: =SUM(J28:J29) -> 199 | K30: =SUM(K28:K29) -> 167 | L30: =SUM(L28:L29) -> 194 | ... AX30: =SUM(AX28:AX29) -> 200 | AY30: =SUM(E30:AX30) -> 9179
A32: II | B32: DATA PENGGUNAAN SURAT SUARA
A33: 1 | B33: Jumlah surat suara yang diterima, termasuk surat suara cadangan 2,5% dari DPT | E33: 240 | F33: 272 | G33: 260 | H33: 260 | I33: 277 | J33: 271 | K33: 227 | L33: 254 | M33: 240 | N33: 301 | O33: 293 | P33: 266 | Q33: 247 | R33: 226 | S33: 224 | T33: 294 | U33: 290 | V33: 274 | W33: 295 | X33: 283 | Y33: 282 | Z33: 274 | AA33: 247 | AB33: 209 | AC33: 283 | AD33: 270 | AE33: 225 | AF33: 209 | AG33: 267 | AH33: 154 | AI33: 274 | AJ33: 285 | AK33: 276 | AL33: 299 | AM33: 282 | AN33: 281 | AO33: 296 | AP33: 279 | AQ33: 290 | AR33: 265 | AS33: 281 | AT33: 266 | AU33: 285 | AV33: 288 | AW33: 275 | AX33: 274 | AY33: =SUM(E33:AX33) -> 12210
A34: 2 | B34: Jumlah surat suara yang digunakan | E34: 182 | F34: 205 | G34: 171 | H34: 169 | I34: 208 | J34: 199 | K34: 167 | L34: 194 | M34: 166 | N34: 218 | O34: 192 | P34: 210 | Q34: 180 | R34: 153 | S34: 179 | T34: 201 | U34: 224 | V34: 220 | W34: 207 | X34: 231 | Y34: 215 | Z34: 204 | AA34: 193 | AB34: 182 | AC34: 199 | AD34: 203 | AE34: 191 | AF34: 161 | AG34: 223 | AH34: 122 | AI34: 202 | AJ34: 209 | AK34: 224 | AL34: 237 | AM34: 255 | AN34: 210 | AO34: 229 | AP34: 204 | AQ34: 196 | AR34: 198 | AS34: 210 | AT34: 210 | AU34: 230 | AV34: 205 | AW34: 191 | AX34: 200 | AY34: =SUM(E34:AX34) -> 9179
A35: 3 | B35: Jumlah surat suara dikembalikan oleh pemilih (karena rusak atau keliru coblos) | E35: 4 | F35: 0 | G35: 2 | H35: 0 | I35: 0 | J35: 0 | K35: 3 | L35: 1 | M35: 1 | N35: 1 | O35: 0 | P35: 1 | Q35: 0 | R35: 0 | S35: 0 | T35: 1 | U35: 0 | V35: 1 | W35: 3 | X35: 0 | Y35: 0 | Z35: 0 | AA35: 1 | AB35: 0 | AC35: 0 | AD35: 0 | AE35: 0 | AF35: 0 | AG35: 2 | AH35: 0 | AI35: 0 | AJ35: 1 | AK35: 0 | AL35: 0 | AM35: 0 | AN35: 1 | AO35: 0 | AP35: 0 | AQ35: 2 | AR35: 0 | AS35: 0 | AT35: 0 | AU35: 4 | AV35: 0 | AW35: 1 | AY35: =SUM(E35:AX35) -> 30
A36: 4 | B36: Jumlah surat suara yang tidak digunakan/tidak terpakai, termasuk sisa surat suara cadangan | E36: =E33-(E34+E35) -> 54 | F36: =F33-(F34+F35) -> 67 | G36: =G33-(G34+G35) -> 87 | H36: =H33-(H34+H35) -> 91 | I36: =I33-(I34+I35) -> 69 | J36: =J33-(J34+J35) -> 72 | K36: =K33-(K34+K35) -> 57 | L36: =L33-(L34+L35) -> 59 | ... AX36: =AX33-(AX34+AX35) -> 74 | AY36: =SUM(E36:AX36) -> 3001
AY37: =SUM(E37:AX37) -> 0
A38: III | B38: DATA PEMILIH DISABILITAS | AY38: =SUM(E38:AX38) -> 0
B39: Jumlah seluruh Pemilih disabilitas yang menggunakan hak pilih | D39: LK | E39: 0 | F39: 0 | G39: 1 | H39: 0 | I39: 0 | J39: 0 | K39: 1 | L39: 0 | M39: 0 | N39: 0 | O39: 0 | P39: 1 | Q39: 0 | R39: 0 | S39: 0 | T39: 0 | U39: 0 | V39: 0 | W39: 0 | X39: 0 | Y39: 0 | Z39: 0 | AA39: 1 | AB39: 0 | AC39: 1 | AD39: 0 | AE39: 0 | AF39: 0 | AG39: 0 | AH39: 0 | AI39: 0 | AJ39: 0 | AK39: 0 | AL39: 0 | AM39: 0 | AN39: 0 | AO39: 0 | AP39: 0 | AQ39: 0 | AR39: 0 | AS39: 0 | AT39: 0 | AU39: 0 | AV39: 0 | AW39: 0 | AY39: =SUM(E39:AX39) -> 5
D40: PR | E40: 0 | F40: 0 | G40: 0 | H40: 1 | I40: 0 | J40: 1 | K40: 0 | L40: 0 | M40: 0 | N40: 0 | O40: 0 | P40: 0 | Q40: 0 | R40: 0 | S40: 0 | T40: 0 | U40: 0 | V40: 0 | W40: 0 | X40: 0 | Y40: 0 | Z40: 0 | AA40: 0 | AB40: 0 | AC40: 1 | AD40: 0 | AE40: 0 | AF40: 1 | AG40: 0 | AH40: 0 | AI40: 0 | AJ40: 0 | AK40: 1 | AL40: 0 | AM40: 0 | AN40: 0 | AO40: 0 | AP40: 0 | AQ40: 0 | AR40: 0 | AS40: 0 | AT40: 0 | AU40: 0 | AV40: 0 | AW40: 0 | AY40: =SUM(E40:AX40) -> 5
D41: JML | E41: =SUM(E39:E40) -> 0 | F41: =SUM(F39:F40) -> 0 | G41: =SUM(G39:G40) -> 1 | H41: =SUM(H39:H40) -> 1 | I41: =SUM(I39:I40) -> 0 | J41: =SUM(J39:J40) -> 1 | K41: =SUM(K39:K40) -> 1 | L41: =SUM(L39:L40) -> 0 | ... AX41: =SUM(AX39:AX40) -> 0 | AY41: =SUM(E41:AX41) -> 10
AY42: =SUM(E42:AX42) -> 0
A43: IV | B43: DATA RINCIAN PEROLEHAN SUARA PASANGAN CALON BUPATI DAN WAKIL BUPATI | AY43: =SUM(E43:AX43) -> 0
A44: NOMOR DAN NAMA CALON | AY44: =SUM(E44:AX44) -> 0
A45: A.1 | B45: 1. | C45: Partai Kebangkitan Bangsa | E45: 6 | F45: 1 | G45: 2 | H45: 1 | I45: 10 | J45: 1 | K45: 2 | L45: 6 | M45: 9 | N45: 11 | O45: 5 | P45: 1 | Q45: 5 | R45: 1 | S45: 1 | T45: 4 | U45: 4 | V45: 4 | W45: 5 | X45: 4 | Y45: 5 | Z45: 6 | AA45: 3 | AB45: 4 | AC45: 7 | AD45: 1 | AE45: 10 | AF45: 4 | AG45: 14 | AH45: 1 | AI45: 0 | AJ45: 7 | AK45: 15 | AL45: 10 | AM45: 14 | AN45: 12 | AO45: 17 | AP45: 7 | AQ45: 17 | AR45: 8 | AS45: 14 | AT45: 13 | AU45: 14 | AV45: 5 | AW45: 6 | AX45: 2 | AY45: =SUM(E45:AX45) -> 299
A46: A.2 | B46: 1 | C46: 1. Dr. Hj. NIHAYATUL WAFIROH, M.A. | E46: 7 | F46: 13 | G46: 5 | H46: 4 | I46: 10 | J46: 9 | K46: 0 | L46: 10 | M46: 4 | N46: 13 | O46: 20 | P46: 14 | Q46: 7 | R46: 2 | S46: 3 | T46: 5 | U46: 4 | V46: 10 | W46: 5 | X46: 12 | Y46: 5 | Z46: 20 | AA46: 8 | AB46: 10 | AC46: 17 | AD46: 10 | AE46: 15 | AF46: 34 | AG46: 34 | AH46: 1 | AI46: 1 | AJ46: 24 | AK46: 37 | AL46: 30 | AM46: 16 | AN46: 4 | AO46: 43 | AP46: 16 | AQ46: 28 | AR46: 35 | AS46: 25 | AT46: 33 | AU46: 49 | AV46: 8 | AW46: 15 | AX46: 11 | AY46: =SUM(E46:AX46) -> 686
B47: 2 | C47: 2. H. M. NASIM KHAN | E47: 1 | F47: 1 | G47: 0 | H47: 1 | I47: 0 | J47: 2 | K47: 0 | L47: 3 | M47: 0 | N47: 2 | O47: 1 | P47: 0 | Q47: 1 | R47: 2 | S47: 0 | T47: 2 | U47: 0 | V47: 1 | W47: 4 | X47: 5 | Y47: 1 | Z47: 2 | AA47: 0 | AB47: 0 | AC47: 1 | AD47: 0 | AE47: 1 | AF47: 0 | AG47: 1 | AH47: 0 | AI47: 0 | AJ47: 1 | AK47: 1 | AL47: 0 | AM47: 3 | AN47: 2 | AO47: 0 | AP47: 0 | AQ47: 2 | AR47: 1 | AS47: 3 | AT47: 0 | AU47: 0 | AV47: 1 | AW47: 0 | AX47: 1 | AY47: =SUM(E47:AX47) -> 47
B48: 3 | C48: 3. Dr. H. AKIK ZAMAN, M.Pd.I. | E48: 0 | F48: 1 | G48: 1 | H48: 0 | I48: 0 | J48: 0 | K48: 0 | L48: 0 | M48: 0 | N48: 0 | O48: 0 | P48: 1 | Q48: 1 | R48: 1 | S48: 0 | T48: 0 | U48: 0 | V48: 0 | W48: 0 | X48: 1 | Y48: 1 | Z48: 0 | AA48: 0 | AB48: 0 | AC48: 1 | AD48: 0 | AE48: 0 | AF48: 0 | AG48: 5 | AH48: 0 | AI48: 0 | AJ48: 1 | AK48: 1 | AL48: 3 | AM48: 0 | AN48: 0 | AO48: 5 | AP48: 2 | AQ48: 0 | AR48: 3 | AS48: 6 | AT48: 2 | AU48: 4 | AV48: 4 | AW48: 2 | AX48: 1 | AY48: =SUM(E48:AX48) -> 47
B49: 4 | C49: 4. AHMAD RIFA'I, S.H. | E49: 1 | F49: 1 | G49: 0 | H49: 0 | I49: 0 | J49: 0 | K49: 0 | L49: 0 | M49: 0 | N49: 1 | O49: 2 | P49: 2 | Q49: 0 | R49: 0 | S49: 2 | T49: 0 | U49: 0 | V49: 0 | W49: 5 | X49: 0 | Y49: 0 | Z49: 3 | AA49: 2 | AB49: 0 | AC49: 1 | AD49: 0 | AE49: 1 | AF49: 1 | AG49: 1 | AH49: 0 | AI49: 0 | AJ49: 0 | AK49: 2 | AL49: 1 | AM49: 0 | AN49: 0 | AO49: 2 | AP49: 1 | AQ49: 2 | AR49: 4 | AS49: 6 | AT49: 13 | AU49: 0 | AV49: 0 | AW49: 1 | AX49: 1 | AY49: =SUM(E49:AX49) -> 56
...

Sheet JAJAG
C2: Kecamatan | D2: GAMBIRAN
C3: Kabupaten | D3: BANYUWANGI
C4: Provinsi | D4: JAWA TIMUR
C9: Kelurahan | D9: JAJAG
A12: I | B12: DATA PEMILIH DAN PENGGUNAAN HAK PILIH | BA12: JUMLAH AKHIR
A13: A | B13: DATA PEMILIH | E13: TPS 001 | F13: TPS 002 | G13: TPS 003 | H13: TPS 004 | I13: TPS 005 | J13: TPS 006 | K13: TPS 007 | L13: TPS 008 | M13: TPS 009 | N13: TPS 010 | O13: TPS 011 | P13: TPS 012 | Q13: TPS 013 | R13: TPS 014 | S13: TPS 015 | T13: TPS 016 | U13: TPS 017 | V13: TPS 018 | W13: TPS 019 | X13: TPS 020 | Y13: TPS 021 | Z13: TPS 022 | AA13: TPS 023 | AB13: TPS 024 | AC13: TPS 025 | AD13: TPS 026 | AE13: TPS 027 | AF13: TPS 028 | AG13: TPS 029 | AH13: TPS 030 | AI13: TPS 031 | AJ13: TPS 032 | AK13: TPS 033 | AL13: TPS 034 | AM13: TPS 035 | AN13: TPS 036 | AO13: TPS 037 | AP13: TPS 038 | AQ13: TPS 039 | AR13: TPS 040 | AS13: TPS 041 | AT13: TPS 042 | AU13: TPS 043 | AV13: TPS 044 | AW13: TPS 045 | AX13: TPS 046 | AY13: TPS 047 | AZ13: TPS 048
B14: Jumlah Pemilih dalam Daftar Pemilih Tetap (DPT) | D14: LK | E14: 136 | F14: 136 | G14: 104 | H14: 123 | I14: 142 | J14: 128 | K14: 118 | L14: 116 | M14: 106 | N14: 127 | O14: 131 | P14: 111 | Q14: 96 | R14: 146 | S14: 136 | T14: 148 | U14: 99 | V14: 145 | W14: 152 | X14: 139 | Y14: 143 | Z14: 77 | AA14: 149 | AB14: 131 | AC14: 128 | AD14: 129 | AE14: 117 | AF14: 141 | AG14: 136 | AH14: 146 | AI14: 70 | AJ14: 141 | AK14: 134 | AL14: 142 | AM14: 125 | AN14: 132 | AO14: 133 | AP14: 141 | AQ14: 125 | AR14: 129 | AS14: 114 | AT14: 131 | AU14: 138 | AV14: 134 | AW14: 143 | AX14: 121 | AY14: 111 | AZ14: 88 | BA14: =SUM(E14:AZ14) -> 6088
D15: PR | E15: 155 | F15: 158 | G15: 104 | H15: 155 | I15: 146 | J15: 149 | K15: 126 | L15: 128 | M15: 119 | N15: 134 | O15: 131 | P15: 123 | Q15: 114 | R15: 141 | S15: 158 | T15: 149 | U15: 113 | V15: 145 | W15: 147 | X15: 140 | Y15: 132 | Z15: 79 | AA15: 144 | AB15: 129 | AC15: 142 | AD15: 159 | AE15: 128 | AF15: 137 | AG15: 133 | AH15: 136 | AI15: 76 | AJ15: 143 | AK15: 135 | AL15: 145 | AM15: 117 | AN15: 141 | AO15: 140 | AP15: 152 | AQ15: 108 | AR15: 125 | AS15: 116 | AT15: 159 | AU15: 134 | AV15: 149 | AW15: 154 | AX15: 117 | AY15: 123 | AZ15: 99 | BA15: =SUM(E15:AZ15) -> 6387
D16: JML | E16: =SUM(E14:E15) -> 291 | F16: =SUM(F14:F15) -> 294 | G16: =SUM(G14:G15) -> 208 | H16: =SUM(H14:H15) -> 278 | I16: =SUM(I14:I15) -> 288 | J16: =SUM(J14:J15) -> 277 | K16: =SUM(K14:K15) -> 244 | L16: =SUM(L14:L15) -> 244 | ... AZ16: =SUM(AZ14:AZ15) -> 187 | BA16: =SUM(E16:AZ16) -> 12475
A18: B | B18: PENGGUNA HAK PILIH
B19: 1. | C19: Jumlah pengguna hak pilih dalam Daftar Pemilih Tetap (DPT) | D19: LK | E19: 98 | F19: 109 | G19: 87 | H19: 90 | I19: 105 | J19: 101 | K19: 86 | L19: 89 | M19: 76 | N19: 85 | O19: 98 | P19: 89 | Q19: 79 | R19: 115 | S19: 106 | T19: 113 | U19: 73 | V19: 100 | W19: 109 | X19: 106 | Y19: 103 | Z19: 58 | AA19: 110 | AB19: 98 | AC19: 92 | AD19: 88 | AE19: 97 | AF19: 109 | AG19: 103 | AH19: 100 | AI19: 43 | AJ19: 104 | AK19: 93 | AL19: 93 | AM19: 88 | AN19: 103 | AO19: 92 | AP19: 99 | AQ19: 81 | AR19: 93 | AS19: 79 | AT19: 104 | AU19: 104 | AV19: 107 | AW19: 107 | AX19: 99 | AY19: 77 | AZ19: 67 | BA19: =SUM(E19:AZ19) -> 4505
D20: PR | E20: 115 | F20: 122 | G20: 86 | H20: 120 | I20: 115 | J20: 118 | K20: 107 | L20: 98 | M20: 92 | N20: 104 | O20: 100 | P20: 97 | Q20: 94 | R20: 108 | S20: 113 | T20: 119 | U20: 87 | V20: 109 | W20: 119 | X20: 127 | Y20: 109 | Z20: 68 | AA20: 113 | AB20: 105 | AC20: 104 | AD20: 119 | AE20: 103 | AF20: 109 | AG20: 95 | AH20: 102 | AI20: 57 | AJ20: 115 | AK20: 105 | AL20: 103 | AM20: 99 | AN20: 96 | AO20: 98 | AP20: 111 | AQ20: 82 | AR20: 97 | AS20: 92 | AT20: 139 | AU20: 96 | AV20: 123 | AW20: 105 | AX20: 93 | AY20: 96 | AZ20: 77 | BA20: =SUM(E20:AZ20) -> 4961
D21: JML | E21: =SUM(E19:E20) -> 213 | F21: =SUM(F19:F20) -> 231 | G21: =SUM(G19:G20) -> 173 | H21: =SUM(H19:H20) -> 210 | I21: =SUM(I19:I20) -> 220 | J21: =SUM(J19:J20) -> 219 | K21: =SUM(K19:K20) -> 193 | L21: =SUM(L19:L20) -> 187 | ... AZ21: =SUM(AZ19:AZ20) -> 144 | BA21: =SUM(E21:AZ21) -> 9466
B22: 2. | C22: Jumlah pengguna hak pilih dalam Daftar Pemilih Tambahan (DPTb) | D22: LK | E22: 0 | F22: 7 | G22: 3 | H22: 0 | I22: 0 | J22: 0 | K22: 1 | L22: 0 | M22: 0 | N22: 0 | O22: 0 | P22: 0 | Q22: 0 | R22: 1 | S22: 0 | T22: 0 | U22: 0 | V22: 0 | W22: 0 | X22: 0 | Y22: 0 | Z22: 0 | AA22: 0 | AB22: 0 | AC22: 0 | AD22: 0 | AE22: 1 | AF22: 0 | AG22: 0 | AH22: 0 | AX22: 0 | AY22: 0 | AZ22: 1 | BA22: =SUM(E22:AZ22) -> 14
D23: PR | E23: 0 | F23: 7 | G23: 1 | H23: 0 | I23: 0 | J23: 0 | K23: 0 | L23: 0 | M23: 0 | N23: 0 | O23: 0 | P23: 0 | Q23: 0 | R23: 0 | S23: 0 | T23: 0 | U23: 0 | V23: 0 | W23: 0 | X23: 0 | Y23: 0 | Z23: 0 | AA23: 0 | AB23: 0 | AC23: 0 | AD23: 0 | AE23: 1 | AF23: 0 | AG23: 0 | AH23: 0 | AX23: 0 | AY23: 0 | AZ23: 0 | BA23: =SUM(E23:AZ23) -> 9
D24: JML | E24: =SUM(E22:E23) -> 0 | F24: =SUM(F22:F23) -> 14 | G24: =SUM(G22:G23) -> 4 | H24: =SUM(H22:H23) -> 0 | I24: =SUM(I22:I23) -> 0 | J24: =SUM(J22:J23) -> 0 | K24: =SUM(K22:K23) -> 1 | L24: =SUM(L22:L23) -> 0 | ... AZ24: =SUM(AZ22:AZ23) -> 1 | BA24: =SUM(E24:AZ24) -> 23
B25: 3. | C25: Jumlah pengguna hak pilih dalam Daftar Pemilih Khusus (DPK) | D25: LK | E25: 0 | F25: 1 | G25: 0 | H25: 0 | I25: 1 | J25: 4 | K25: 1 | L25: 3 | M25: 1 | N25: 0 | O25: 10 | P25: 0 | Q25: 2 | R25: 6 | S25: 2 | T25: 1 | U25: 0 | V25: 3 | W25: 1 | X25: 0 | Y25: 0 | Z25: 0 | AA25: 1 | AB25: 0 | AC25: 4 | AD25: 4 | AE25: 0 | AF25: 1 | AG25: 4 | AH25: 0 | AI25: 0 | AJ25: 0 | AK25: 2 | AL25: 0 | AM25: 0 | AN25: 0 | AO25: 3 | AP25: 1 | AQ25: 1 | AR25: 2 | AS25: 1 | AT25: 4 | AU25: 0 | AV25: 3 | AW25: 0 | AX25: 0 | AY25: 0 | AZ25: 0 | BA25: =SUM(E25:AZ25) -> 67
D26: PR | E26: 1 | F26: 3 | G26: 0 | H26: 0 | I26: 2 | J26: 3 | K26: 1 | L26: 2 | M26: 2 | N26: 2 | O26: 6 | P26: 0 | Q26: 0 | R26: 3 | S26: 1 | T26: 0 | U26: 0 | V26: 1 | W26: 0 | X26: 0 | Y26: 0 | Z26: 0 | AA26: 0 | AB26: 0 | AC26: 6 | AD26: 4 | AE26: 0 | AF26: 1 | AG26: 2 | AH26: 1 | AI26: 1 | AJ26: 0 | AK26: 1 | AL26: 0 | AM26: 1 | AN26: 0 | AO26: 3 | AP26: 3 | AQ26: 2 | AR26: 2 | AS26: 6 | AT26: 3 | AU26: 0 | AV26: 4 | AW26: 2 | AX26: 2 | AY26: 3 | AZ26: 0 | BA26: =SUM(E26:AZ26) -> 74
D27: JML | E27: =SUM(E25:E26) -> 1 | F27: =SUM(F25:F26) -> 4 | G27: =SUM(G25:G26) -> 0 | H27: =SUM(H25:H26) -> 0 | I27: =SUM(I25:I26) -> 3 | J27: =SUM(J25:J26) -> 7 | K27: =SUM(K25:K26) -> 2 | L27: =SUM(L25:L26) -> 5 | ... AZ27: =SUM(AZ25:AZ26) -> 0 | BA27: =SUM(E27:AZ27) -> 141
B28: 4. | C28: Jumlah Pengguna Hak Pilih (B.1+B.2+B.3) | D28: LK | E28: =SUM(E19,E22,E25) -> 98 | F28: =SUM(F19,F22,F25) -> 117 | G28: =SUM(G19,G22,G25) -> 90 | H28: =SUM(H19,H22,H25) -> 90 | I28: =SUM(I19,I22,I25) -> 106 | J28: =SUM(J19,J22,J25) -> 105 | K28: =SUM(K19,K22,K25) -> 88 | L28: =SUM(L19,L22,L25) -> 92 | ... AZ28: =SUM(AZ19,AZ22,AZ25) -> 68 | BA28: =SUM(E28:AZ28) -> 4586
D29: PR | E29: =SUM(E20,E23,E26) -> 116 | F29: =SUM(F20,F23,F26) -> 132 | G29: =SUM(G20,G23,G26) -> 87 | H29: =SUM(H20,H23,H26) -> 120 | I29: =SUM(I20,I23,I26) -> 117 | J29: =SUM(J20,J23,J26) -> 121 | K29: =SUM(K20,K23,K26) -> 108 | L29: =SUM(L20,L23,L26) -> 100 | ... AZ29: =SUM(AZ20,AZ23,AZ26) -> 77 | BA29: =SUM(E29:AZ29) -> 5044
D30: JML | E30: =SUM(E28:E29) -> 214 | F30: =SUM(F28:F29) -> 249 | G30: =SUM(G28:G29) -> 177 | H30: =SUM(H28:H29) -> 210 | I30: =SUM(I28:I29) -> 223 | J30: =SUM(J28:J29) -> 226 | K30: =SUM(K28:K29) -> 196 | L30: =SUM(L28:L29) -> 192 | ... AZ30: =SUM(AZ28:AZ29) -> 145 | BA30: =SUM(E30:AZ30) -> 9630
A32: II | B32: DATA PENGGUNAAN SURAT SUARA
A33: 1 | B33: Jumlah surat suara yang diterima, termasuk surat suara cadangan 2,5% dari DPT | E33: 295 | F33: 291 | G33: 213 | H33: 284 | I33: 304 | J33: 283 | K33: 249 | L33: 249 | M33: 300 | N33: 237 | O33: 277 | P33: 229 | Q33: 215 | R33: 303 | S33: 300 | T33: 303 | U33: 218 | V33: 296 | W33: 306 | X33: 275 | Y33: 281 | Z33: 159 | AA33: 300 | AB33: 266 | AC33: 276 | AD33: 294 | AE33: 254 | AF33: 284 | AG33: 275 | AH33: 298 | AI33: 249 | AJ33: 289 | AK33: 274 | AL33: 299 | AM33: 247 | AN33: 278 | AO33: 275 | AP33: 299 | AQ33: 238 | AR33: 260 | AS33: 235 | AT33: 297 | AU33: 278 | AV33: 289 | AW33: 303 | AX33: 243 | AY33: 239 | AZ33: 191 | BA33: =SUM(E33:AZ33) -> 12897
A34: 2 | B34: Jumlah surat suara yang digunakan | E34: 214 | F34: 249 | G34: 177 | H34: 210 | I34: 223 | J34: 226 | K34: 196 | L34: 192 | M34: 171 | N34: 191 | O34: 214 | P34: 186 | Q34: 175 | R34: 233 | S34: 222 | T34: 233 | U34: 160 | V34: 213 | W34: 229 | X34: 233 | Y34: 212 | Z34: 126 | AA34: 224 | AB34: 203 | AC34: 206 | AD34: 215 | AE34: 202 | AF34: 220 | AG34: 204 | AH34: 203 | AI34: 101 | AJ34: 219 | AK34: 201 | AL34: 196 | AM34: 188 | AN34: 199 | AO34: 196 | AP34: 214 | AQ34: 166 | AR34: 194 | AS34: 178 | AT34: 250 | AU34: 200 | AV34: 237 | AW34: 214 | AX34: 194 | AY34: 176 | AZ34: 145 | BA34: =SUM(E34:AZ34) -> 9630
A35: 3 | B35: Jumlah surat suara dikembalikan oleh pemilih (karena rusak atau keliru coblos) | E35: 0 | F35: 0 | G35: 0 | H35: 0 | I35: 0 | J35: 0 | K35: 2 | L35: 0 | M35: 0 | N35: 0 | O35: 0 | P35: 0 | Q35: 0 | R35: 1 | S35: 0 | T35: 0 | U35: 1 | V35: 1 | W35: 0 | X35: 0 | Y35: 1 | Z35: 0 | AA35: 0 | AB35: 0 | AC35: 0 | AD35: 0 | AE35: 2 | AF35: 0 | AG35: 2 | AH35: 1 | AI35: 0 | AJ35: 0 | AK35: 1 | AL35: 0 | AM35: 0 | AN35: 0 | AO35: 0 | AP35: 0 | AQ35: 0 | AR35: 0 | AS35: 0 | AT35: 0 | AU35: 0 | AV35: 0 | AW35: 1 | BA35: =SUM(E35:AZ35) -> 13
A36: 4 | B36: Jumlah surat suara yang tidak digunakan/tidak terpakai, termasuk sisa surat suara cadangan | E36: =E33-(E34+E35) -> 81 | F36: =F33-(F34+F35) -> 42 | G36: =G33-(G34+G35) -> 36 | H36: =H33-(H34+H35) -> 74 | I36: =I33-(I34+I35) -> 81 | J36: =J33-(J34+J35) -> 57 | K36: =K33-(K34+K35) -> 51 | L36: =L33-(L34+L35) -> 57 | ... AZ36: =AZ33-(AZ34+AZ35) -> 46 | BA36: =SUM(E36:AZ36) -> 3254
A38: III | B38: DATA PEMILIH DISABILITAS
B39: Jumlah seluruh Pemilih disabilitas yang menggunakan hak pilih | D39: LK | E39: 0 | F39: 0 | G39: 0 | H39: 0 | I39: 1 | J39: 0 | K39: 0 | L39: 0 | M39: 0 | N39: 0 | O39: 0 | P39: 1 | Q39: 0 | R39: 0 | S39: 0 | T39: 0 | U39: 1 | V39: 0 | W39: 0 | X39: 2 | Y39: 0 | Z39: 1 | AA39: 0 | AB39: 0 | AC39: 0 | AD39: 0 | AE39: 0 | AF39: 0 | AG39: 0 | AH39: 0 | AI39: 0 | AJ39: 0 | AK39: 0 | AL39: 0 | AM39: 0 | AN39: 0 | AO39: 0 | AP39: 1 | AQ39: 0 | AR39: 1 | AS39: 1 | AT39: 0 | AU39: 0 | AV39: 0 | AW39: 0 | AX39: 0 | AY39: 0 | AZ39: 0 | BA39: =SUM(E39:AZ39) -> 9
D40: PR | E40: 0 | F40: 0 | G40: 0 | H40: 0 | I40: 0 | J40: 0 | K40: 1 | L40: 0 | M40: 0 | N40: 0 | O40: 0 | P40: 0 | Q40: 0 | R40: 1 | S40: 0 | T40: 0 | U40: 1 | V40: 0 | W40: 0 | X40: 1 | Y40: 0 | Z40: 3 | AA40: 0 | AB40: 0 | AC40: 0 | AD40: 0 | AE40: 0 | AF40: 0 | AG40: 0 | AH40: 0 | AI40: 0 | AJ40: 0 | AK40: 0 | AL40: 0 | AM40: 0 | AN40: 0 | AO40: 2 | AP40: 1 | AQ40: 0 | AR40: 0 | AS40: 0 | AT40: 0 | AU40: 0 | AV40: 0 | AW40: 0 | AX40: 0 | AY40: 0 | AZ40: 1 | BA40: =SUM(E40:AZ40) -> 11
D41: JML | E41: =SUM(E39:E40) -> 0 | F41: =SUM(F39:F40) -> 0 | G41: =SUM(G39:G40) -> 0 | H41: =SUM(H39:H40) -> 0 | I41: =SUM(I39:I40) -> 1 | J41: =SUM(J39:J40) -> 0 | K41: =SUM(K39:K40) -> 1 | L41: =SUM(L39:L40) -> 0 | ... AZ41: =SUM(AZ39:AZ40) -> 1 | BA41: =SUM(E41:AZ41) -> 20
A43: IV | B43: DATA RINCIAN PEROLEHAN SUARA PASANGAN CALON BUPATI DAN WAKIL BUPATI
A44: NOMOR DAN NAMA CALON
A45: A.1 | B45: 1. | C45: Partai Kebangkitan Bangsa | E45: 4 | F45: 6 | G45: 0 | H45: 1 | I45: 3 | J45: 2 | K45: 3 | L45: 7 | M45: 7 | N45: 6 | O45: 2 | P45: 9 | Q45: 2 | R45: 9 | S45: 10 | T45: 8 | U45: 4 | V45: 6 | W45: 6 | X45: 3 | Y45: 4 | Z45: 5 | AA45: 7 | AB45: 5 | AC45: 4 | AD45: 11 | AE45: 1 | AF45: 4 | AG45: 8 | AH45: 7 | AI45: 1 | AJ45: 4 | AK45: 3 | AL45: 1 | AM45: 1 | AN45: 4 | AO45: 5 | AP45: 11 | AQ45: 4 | AR45: 3 | AS45: 3 | AT45: 8 | AU45: 5 | AV45: 4 | AW45: 2 | AX45: 3 | AY45: 2 | AZ45: 1 | BA45: =SUM(E45:AZ45) -> 219
A46: A.2 | B46: 1 | C46: 1. Dr. Hj. NIHAYATUL WAFIROH, M.A. | E46: 2 | F46: 16 | G46: 9 | H46: 8 | I46: 16 | J46: 12 | K46: 13 | L46: 31 | M46: 16 | N46: 15 | O46: 1 | P46: 0 | Q46: 5 | R46: 5 | S46: 29 | T46: 23 | U46: 18 | V46: 15 | W46: 4 | X46: 3 | Y46: 31 | Z46: 10 | AA46: 17 | AB46: 13 | AC46: 6 | AD46: 12 | AE46: 4 | AF46: 21 | AG46: 33 | AH46: 18 | AI46: 7 | AJ46: 9 | AK46: 6 | AL46: 10 | AM46: 3 | AN46: 9 | AO46: 10 | AP46: 12 | AQ46: 10 | AR46: 4 | AS46: 4 | AT46: 4 | AU46: 12 | AV46: 4 | AW46: 17 | AX46: 6 | AY46: 11 | AZ46: 1 | BA46: =SUM(E46:AZ46) -> 545
B47: 2 | C47: 2. H. M. NASIM KHAN | E47: 0 | F47: 0 | G47: 0 | H47: 1 | I47: 0 | J47: 4 | K47: 0 | L47: 0 | M47: 1 | N47: 0 | O47: 0 | P47: 0 | Q47: 1 | R47: 3 | S47: 0 | T47: 1 | U47: 0 | V47: 1 | W47: 3 | X47: 0 | Y47: 0 | Z47: 1 | AA47: 0 | AB47: 1 | AC47: 0 | AD47: 2 | AE47: 0 | AF47: 0 | AG47: 1 | AH47: 2 | AI47: 0 | AJ47: 2 | AK47: 1 | AL47: 1 | AM47: 0 | AN47: 0 | AO47: 0 | AP47: 0 | AQ47: 1 | AR47: 0 | AS47: 2 | AT47: 0 | AU47: 0 | AV47: 0 | AW47: 0 | AX47: 1 | AY47: 2 | AZ47: 0 | BA47: =SUM(E47:AZ47) -> 32
B48: 3 | C48: 3. Dr. H. AKIK ZAMAN, M.Pd.I. | E48: 0 | F48: 0 | G48: 1 | H48: 0 | I48: 1 | J48: 0 | K48: 1 | L48: 2 | M48: 0 | N48: 2 | O48: 1 | P48: 0 | Q48: 0 | R48: 2 | S48: 0 | T48: 0 | U48: 2 | V48: 0 | W48: 0 | X48: 0 | Y48: 0 | Z48: 0 | AA48: 0 | AB48: 0 | AC48: 0 | AD48: 0 | AE48: 0 | AF48: 1 | AG48: 1 | AH48: 0 | AI48: 0 | AJ48: 0 | AK48: 0 | AL48: 1 | AM48: 0 | AN48: 0 | AO48: 0 | AP48: 1 | AQ48: 0 | AR48: 0 | AS48: 1 | AT48: 2 | AU48: 0 | AV48: 1 | AW48: 0 | AX48: 0 | AY48: 0 | AZ48: 0 | BA48: =SUM(E48:AZ48) -> 20
B49: 4 | C49: 4. AHMAD RIFA'I, S.H. | E49: 0 | F49: 0 | G49: 2 | H49: 0 | I49: 0 | J49: 2 | K49: 0 | L49: 0 | M49: 0 | N49: 0 | O49: 1 | P49: 0 | Q49: 0 | R49: 3 | S49: 0 | T49: 0 | U49: 0 | V49: 4 | W49: 1 | X49: 0 | Y49: 0 | Z49: 0 | AA49: 0 | AB49: 1 | AC49: 1 | AD49: 1 | AE49: 0 | AF49: 1 | AG49: 0 | AH49: 0 | AI49: 0 | AJ49: 1 | AK49: 1 | AL49: 0 | AM49: 3 | AN49: 1 | AO49: 0 | AP49: 3 | AQ49: 2 | AR49: 1 | AS49: 0 | AT49: 1 | AU49: 0 | AV49: 0 | AW49: 0 | AX49: 0 | AY49: 3 | AZ49: 0 | BA49: =SUM(E49:AZ49) -> 33
B50: 5 | C50: 5. Drs. H. MAHFUD M.N. | E50: 0 | F50: 1 | G50: 1 | H50: 0 | I50: 0 | J50: 0 | K50: 0 | L50: 0 | M50: 1 | N50: 1 | O50: 0 | P50: 0 | Q50: 1 | R50: 2 | S50: 2 | T50: 0 | U50: 0 | V50: 1 | W50: 1 | X50: 0 | Y50: 1 | Z50: 0 | AA50: 1 | AB50: 1 | AC50: 0 | AD50: 0 | AE50: 1 | AF50: 0 | AG50: 0 | AH50: 0 | AI50: 0 | AJ50: 0 | AK50: 0 | AL50: 0 | AM50: 0 | AN50: 0 | AO50: 0 | AP50: 1 | AQ50: 0 | AR50: 0 | AS50: 0 | AT50: 0 | AU50: 0 | AV50: 0 | AW50: 0 | AX50: 1 | AY50: 0 | AZ50: 0 | BA50: =SUM(E50:AZ50) -> 17
B51: 6 | C51: 6. NURHAYATI, S.Pd. | E51: 1 | F51: 1 | G51: 0 | H51: 0 | I51: 0 | J51: 0 | K51: 0 | L51: 0 | M51: 0 | N51: 0 | O51: 0 | P51: 0 | Q51: 0 | R51: 0 | S51: 0 | T51: 2 | U51: 0 | V51: 0 | W51: 0 | X51: 0 | Y51: 1 | Z51: 1 | AA51: 0 | AB51: 0 | AC51: 3 | AD51: 1 | AE51: 0 | AF51: 0 | AG51: 0 | AH51: 1 | AI51: 0 | AJ51: 0 | AK51: 0 | AL51: 0 | AM51: 1 | AN51: 0 | AO51: 0 | AP51: 1 | AQ51: 0 | AR51: 0 | AS51: 0 | AT51: 0 | AU51: 1 | AV51: 0 | AW51: 0 | AX51: 3 | AY51: 0 | AZ51: 0 | BA51: =SUM(E51:AZ51) -> 17
...

Sheet PURWODADI
C2: Kecamatan | D2: GAMBIRAN
C3: Kabupaten | D3: BANYUWANGI
C4: Provinsi | D4: JAWA TIMUR
C9: Kelurahan | D9: PURWODADI
A12: I | B12: DATA PEMILIH DAN PENGGUNAAN HAK PILIH | AC12: JUMLAH AKHIR
A13: A | B13: DATA PEMILIH | E13: TPS 001 | F13: TPS 002 | G13: TPS 003 | H13: TPS 004 | I13: TPS 005 | J13: TPS 006 | K13: TPS 007 | L13: TPS 008 | M13: TPS 009 | N13: TPS 010 | O13: TPS 011 | P13: TPS 012 | Q13: TPS 013 | R13: TPS 014 | S13: TPS 015 | T13: TPS 016 | U13: TPS 017 | V13: TPS 018 | W13: TPS 019 | X13: TPS 020 | Y13: TPS 021 | Z13: TPS 022 | AA13: TPS 023 | AB13: TPS 024
B14: Jumlah Pemilih dalam Daftar Pemilih Tetap (DPT) | D14: LK | E14: 125 | F14: 98 | G14: 127 | H14: 127 | I14: 137 | J14: 137 | K14: 140 | L14: 117 | M14: 133 | N14: 133 | O14: 147 | P14: 136 | Q14: 160 | R14: 148 | S14: 110 | T14: 124 | U14: 129 | V14: 135 | W14: 108 | X14: 121 | Y14: 151 | Z14: 141 | AA14: 103 | AB14: 135 | AC14: =SUM(E14:AB14) -> 3122
D15: PR | E15: 131 | F15: 104 | G15: 131 | H15: 144 | I15: 136 | J15: 142 | K15: 142 | L15: 103 | M15: 123 | N15: 152 | O15: 141 | P15: 155 | Q15: 134 | R15: 138 | S15: 113 | T15: 152 | U15: 136 | V15: 134 | W15: 121 | X15: 115 | Y15: 133 | Z15: 141 | AA15: 140 | AB15: 135 | AC15: =SUM(E15:AB15) -> 3196
D16: JML | E16: =SUM(E14:E15) -> 256 | F16: =SUM(F14:F15) -> 202 | G16: =SUM(G14:G15) -> 258 | H16: =SUM(H14:H15) -> 271 | I16: =SUM(I14:I15) -> 273 | J16: =SUM(J14:J15) -> 279 | K16: =SUM(K14:K15) -> 282 | L16: =SUM(L14:L15) -> 220 | ... AB16: =SUM(AB14:AB15) -> 270 | AC16: =SUM(E16:AB16) -> 6318
A18: B | B18: PENGGUNA HAK PILIH
B19: 1. | C19: Jumlah pengguna hak pilih dalam Daftar Pemilih Tetap (DPT) | D19: LK | E19: 83 | F19: 76 | G19: 107 | H19: 80 | I19: 101 | J19: 100 | K19: 102 | L19: 86 | M19: 111 | N19: 104 | O19: 112 | P19: 99 | Q19: 122 | R19: 121 | S19: 85 | T19: 88 | U19: 85 | V19: 104 | W19: 83 | X19: 87 | Y19: 122 | Z19: 110 | AA19: 82 | AB19: 110 | AC19: =SUM(E19:AB19) -> 2360
D20: PR | E20: 96 | F20: 87 | G20: 110 | H20: 111 | I20: 109 | J20: 115 | K20: 111 | L20: 83 | M20: 98 | N20: 132 | O20: 116 | P20: 137 | Q20: 109 | R20: 103 | S20: 96 | T20: 112 | U20: 104 | V20: 106 | W20: 102 | X20: 92 | Y20: 107 | Z20: 115 | AA20: 119 | AB20: 122 | AC20: =SUM(E20:AB20) -> 2592
D21: JML | E21: =SUM(E19:E20) -> 179 | F21: =SUM(F19:F20) -> 163 | G21: =SUM(G19:G20) -> 217 | H21: =SUM(H19:H20) -> 191 | I21: =SUM(I19:I20) -> 210 | J21: =SUM(J19:J20) -> 215 | K21: =SUM(K19:K20) -> 213 | L21: =SUM(L19:L20) -> 169 | ... AB21: =SUM(AB19:AB20) -> 232 | AC21: =SUM(E21:AB21) -> 4952
B22: 2. | C22: Jumlah pengguna hak pilih dalam Daftar Pemilih Tambahan (DPTb) | D22: LK | E22: 0 | F22: 0 | G22: 1 | H22: 1 | I22: 0 | J22: 0 | K22: 0 | L22: 0 | M22: 0 | N22: 0 | O22: 0 | P22: 0 | Q22: 0 | R22: 0 | S22: 0 | AC22: =SUM(E22:AB22) -> 2
D23: PR | E23: 0 | F23: 0 | G23: 1 | H23: 1 | I23: 0 | J23: 0 | K23: 0 | L23: 0 | M23: 0 | N23: 0 | O23: 0 | P23: 0 | Q23: 0 | R23: 0 | S23: 0 | AC23: =SUM(E23:AB23) -> 2
D24: JML | E24: =SUM(E22:E23) -> 0 | F24: =SUM(F22:F23) -> 0 | G24: =SUM(G22:G23) -> 2 | H24: =SUM(H22:H23) -> 2 | I24: =SUM(I22:I23) -> 0 | J24: =SUM(J22:J23) -> 0 | K24: =SUM(K22:K23) -> 0 | L24: =SUM(L22:L23) -> 0 | ... AB24: =SUM(AB22:AB23) -> 0 | AC24: =SUM(E24:AB24) -> 4
B25: 3. | C25: Jumlah pengguna hak pilih dalam Daftar Pemilih Khusus (DPK) | D25: LK | E25: 1 | F25: 0 | G25: 2 | H25: 0 | I25: 0 | J25: 0 | K25: 2 | L25: 2 | M25: 0 | N25: 0 | O25: 0 | P25: 0 | Q25: 2 | R25: 0 | S25: 0 | T25: 1 | U25: 1 | V25: 0 | W25: 1 | X25: 0 | Y25: 0 | Z25: 0 | AA25: 0 | AB25: 0 | AC25: =SUM(E25:AB25) -> 12
D26: PR | E26: 1 | F26: 0 | G26: 2 | H26: 0 | I26: 0 | J26: 3 | K26: 2 | L26: 0 | M26: 1 | N26: 2 | O26: 1 | P26: 0 | Q26: 2 | R26: 1 | S26: 3 | T26: 1 | U26: 1 | V26: 0 | W26: 0 | X26: 0 | Y26: 0 | Z26: 0 | AA26: 0 | AB26: 0 | AC26: =SUM(E26:AB26) -> 20
D27: JML | E27: =SUM(E25:E26) -> 2 | F27: =SUM(F25:F26) -> 0 | G27: =SUM(G25:G26) -> 4 | H27: =SUM(H25:H26) -> 0 | I27: =SUM(I25:I26) -> 0 | J27: =SUM(J25:J26) -> 3 | K27: =SUM(K25:K26) -> 4 | L27: =SUM(L25:L26) -> 2 | ... AB27: =SUM(AB25:AB26) -> 0 | AC27: =SUM(E27:AB27) -> 32
B28: 4. | C28: Jumlah Pengguna Hak Pilih (B.1+B.2+B.3) | D28: LK | E28: =SUM(E19,E22,E25) -> 84 | F28: =SUM(F19,F22,F25) -> 76 | G28: =SUM(G19,G22,G25) -> 110 | H28: =SUM(H19,H22,H25) -> 81 | I28: =SUM(I19,I22,I25) -> 101 | J28: =SUM(J19,J22,J25) -> 100 | K28: =SUM(K19,K22,K25) -> 104 | L28: =SUM(L19,L22,L25) -> 88 | ... AB28: =SUM(AB19,AB22,AB25) -> 110 | AC28: =SUM(E28:AB28) -> 2374
D29: PR | E29: =SUM(E20,E23,E26) -> 97 | F29: =SUM(F20,F23,F26) -> 87 | G29: =SUM(G20,G23,G26) -> 113 | H29: =SUM(H20,H23,H26) -> 112 | I29: =SUM(I20,I23,I26) -> 109 | J29: =SUM(J20,J23,J26) -> 118 | K29: =SUM(K20,K23,K26) -> 113 | L29: =SUM(L20,L23,L26) -> 83 | ... AB29: =SUM(AB20,AB23,AB26) -> 122 | AC29: =SUM(E29:AB29) -> 2614
D30: JML | E30: =SUM(E28:E29) -> 181 | F30: =SUM(F28:F29) -> 163 | G30: =SUM(G28:G29) -> 223 | H30: =SUM(H28:H29) -> 193 | I30: =SUM(I28:I29) -> 210 | J30: =SUM(J28:J29) -> 218 | K30: =SUM(K28:K29) -> 217 | L30: =SUM(L28:L29) -> 171 | ... AB30: =SUM(AB28:AB29) -> 232 | AC30: =SUM(E30:AB30) -> 4988
A32: II | B32: DATA PENGGUNAAN SURAT SUARA
A33: 1 | B33: Jumlah surat suara yang diterima, termasuk surat suara cadangan 2,5% dari DPT | E33: 262 | F33: 208 | G33: 264 | H33: 277 | I33: 279 | J33: 285 | K33: 288 | L33: 226 | M33: 262 | N33: 292 | O33: 294 | P33: 297 | Q33: 300 | R33: 292 | S33: 248 | T33: 282 | U33: 272 | V33: 275 | W33: 234 | X33: 241 | Y33: 290 | Z33: 288 | AA33: 248 | AB33: 276 | AC33: =SUM(E33:AB33) -> 6480
A34: 2 | B34: Jumlah surat suara yang digunakan | E34: 181 | F34: 163 | G34: 223 | H34: 193 | I34: 210 | J34: 218 | K34: 217 | L34: 171 | M34: 210 | N34: 238 | O34: 229 | P34: 236 | Q34: 235 | R34: 225 | S34: 184 | T34: 202 | U34: 191 | V34: 210 | W34: 186 | X34: 179 | Y34: 229 | Z34: 225 | AA34: 201 | AB34: 232 | AC34: =SUM(E34:AB34) -> 4988
A35: 3 | B35: Jumlah surat suara dikembalikan oleh pemilih (karena rusak atau keliru coblos) | E35: 0 | F35: 0 | G35: 0 | H35: 0 | I35: 0 | J35: 0 | K35: 0 | L35: 2 | M35: 0 | N35: 0 | O35: 0 | P35: 0 | Q35: 0 | R35: 0 | S35: 1 | T35: 0 | U35: 0 | V35: 0 | W35: 2 | X35: 0 | Y35: 0 | Z35: 1 | AA35: 0 | AB35: 0 | AC35: =SUM(E35:AB35) -> 6
A36: 4 | B36: Jumlah surat suara yang tidak digunakan/tidak terpakai, termasuk sisa surat suara cadangan | E36: =E33-(E34+E35) -> 81 | F36: =F33-(F34+F35) -> 45 | G36: =G33-(G34+G35) -> 41 | H36: =H33-(H34+H35) -> 84 | I36: =I33-(I34+I35) -> 69 | J36: =J33-(J34+J35) -> 67 | K36: =K33-(K34+K35) -> 71 | L36: =L33-(L34+L35) -> 53 | ... AB36: =AB33-(AB34+AB35) -> 44 | AC36: =SUM(E36:AB36) -> 1486
A38: III | B38: DATA PEMILIH DISABILITAS
B39: Jumlah seluruh Pemilih disabilitas yang menggunakan hak pilih | D39: LK | E39: 1 | F39: 0 | G39: 0 | H39: 0 | I39: 0 | J39: 0 | K39: 0 | L39: 0 | M39: 0 | N39: 0 | O39: 0 | P39: 0 | Q39: 2 | R39: 0 | S39: 0 | T39: 0 | U39: 1 | V39: 0 | W39: 1 | X39: 0 | Y39: 0 | Z39: 0 | AA39: 1 | AB39: 0 | AC39: =SUM(E39:AB39) -> 6
D40: PR | E40: 0 | F40: 0 | G40: 0 | H40: 0 | I40: 0 | J40: 0 | K40: 0 | L40: 0 | M40: 1 | N40: 1 | O40: 0 | P40: 0 | Q40: 0 | R40: 0 | S40: 0 | T40: 0 | U40: 4 | V40: 0 | W40: 2 | X40: 0 | Y40: 0 | Z40: 0 | AA40: 1 | AB40: 0 | AC40: =SUM(E40:AB40) -> 9
D41: JML | E41: =SUM(E39:E40) -> 1 | F41: =SUM(F39:F40) -> 0 | G41: =SUM(G39:G40) -> 0 | H41: =SUM(H39:H40) -> 0 | I41: =SUM(I39:I40) -> 0 | J41: =SUM(J39:J40) -> 0 | K41: =SUM(K39:K40) -> 0 | L41: =SUM(L39:L40) -> 0 | ... AB41: =SUM(AB39:AB40) -> 0 | AC41: =SUM(E41:AB41) -> 15
A43: IV | B43: DATA RINCIAN PEROLEHAN SUARA PASANGAN CALON BUPATI DAN WAKIL BUPATI
A44: NOMOR DAN NAMA CALON
A45: A.1 | B45: 1. | C45: Partai Kebangkitan Bangsa | E45: 10 | F45: 3 | G45: 10 | H45: 8 | I45: 5 | J45: 6 | K45: 2 | L45: 7 | M45: 5 | N45: 10 | O45: 7 | P45: 7 | Q45: 9 | R45: 5 | S45: 5 | T45: 1 | U45: 2 | V45: 3 | W45: 11 | X45: 4 | Y45: 19 | Z45: 10 | AA45: 2 | AB45: 7 | AC45: =SUM(E45:AB45) -> 158
A46: A.2 | B46: 1 | C46: 1. Dr. Hj. NIHAYATUL WAFIROH, M.A. | E46: 17 | F46: 12 | G46: 28 | H46: 84 | I46: 16 | J46: 14 | K46: 24 | L46: 33 | M46: 13 | N46: 24 | O46: 27 | P46: 24 | Q46: 12 | R46: 17 | S46: 27 | T46: 1 | U46: 2 | V46: 13 | W46: 12 | X46: 7 | Y46: 62 | Z46: 21 | AA46: 43 | AB46: 35 | AC46: =SUM(E46:AB46) -> 568
B47: 2 | C47: 2. H. M. NASIM KHAN | E47: 3 | F47: 0 | G47: 3 | H47: 0 | I47: 3 | J47: 0 | K47: 0 | L47: 1 | M47: 1 | N47: 0 | O47: 6 | P47: 4 | Q47: 1 | R47: 0 | S47: 0 | T47: 0 | U47: 0 | V47: 0 | W47: 0 | X47: 0 | Y47: 3 | Z47: 2 | AA47: 0 | AB47: 2 | AC47: =SUM(E47:AB47) -> 29
B48: 3 | C48: 3. Dr. H. AKIK ZAMAN, M.Pd.I. | E48: 1 | F48: 1 | G48: 3 | H48: 0 | I48: 0 | J48: 1 | K48: 1 | L48: 0 | M48: 0 | N48: 0 | O48: 0 | P48: 1 | Q48: 2 | R48: 1 | S48: 0 | T48: 0 | U48: 0 | V48: 2 | W48: 2 | X48: 0 | Y48: 0 | Z48: 0 | AA48: 0 | AB48: 1 | AC48: =SUM(E48:AB48) -> 16
B49: 4 | C49: 4. AHMAD RIFA'I, S.H. | E49: 1 | F49: 0 | G49: 0 | H49: 1 | I49: 1 | J49: 0 | K49: 0 | L49: 1 | M49: 0 | N49: 0 | O49: 2 | P49: 2 | Q49: 4 | R49: 1 | S49: 6 | T49: 1 | U49: 0 | V49: 0 | W49: 2 | X49: 0 | Y49: 1 | Z49: 1 | AA49: 0 | AB49: 1 | AC49: =SUM(E49:AB49) -> 25
B50: 5 | C50: 5. Drs. H. MAHFUD M.N. | E50: 1 | F50: 0 | G50: 3 | H50: 0 | I50: 1 | J50: 1 | K50: 0 | L50: 1 | M50: 2 | N50: 1 | O50: 1 | P50: 1 | Q50: 0 | R50: 0 | S50: 2 | T50: 0 | U50: 0 | V50: 0 | W50: 0 | X50: 0 | Y50: 0 | Z50: 0 | AA50: 0 | AB50: 0 | AC50: =SUM(E50:AB50) -> 14
B51: 6 | C51: 6. NURHAYATI, S.Pd. | E51: 2 | F51: 1 | G51: 0 | H51: 1 | I51: 2 | J51: 0 | K51: 0 | L51: 0 | M51: 1 | N51: 1 | O51: 0 | P51: 0 | Q51: 0 | R51: 0 | S51: 0 | T51: 0 | U51: 0 | V51: 0 | W51: 0 | X51: 0 | Y51: 5 | Z51: 0 | AA51: 0 | AB51: 1 | AC51: =SUM(E51:AB51) -> 14
...

Sheet WRINGINAGUNG
C2: Kecamatan | D2: GAMBIRAN
C3: Kabupaten | D3: BANYUWANGI
C4: Provinsi | D4: JAWA TIMUR
C9: Kelurahan | D9: WRINGINAGUNG
A12: I | B12: DATA PEMILIH DAN PENGGUNAAN HAK PILIH | AB12: JUMLAH AKHIR
A13: A | B13: DATA PEMILIH | E13: TPS 001 | F13: TPS 002 | G13: TPS 003 | H13: TPS 004 | I13: TPS 005 | J13: TPS 006 | K13: TPS 007 | L13: TPS 008 | M13: TPS 009 | N13: TPS 010 | O13: TPS 011 | P13: TPS 012 | Q13: TPS 013 | R13: TPS 014 | S13: TPS 015 | T13: TPS 016 | U13: TPS 017 | V13: TPS 018 | W13: TPS 019 | X13: TPS 020 | Y13: TPS 021 | Z13: TPS 022 | AA13: TPS 023
B14: Jumlah Pemilih dalam Daftar Pemilih Tetap (DPT) | D14: LK | E14: 139 | F14: 131 | G14: 139 | H14: 147 | I14: 121 | J14: 145 | K14: 129 | L14: 152 | M14: 140 | N14: 130 | O14: 146 | P14: 129 | Q14: 122 | R14: 147 | S14: 147 | T14: 143 | U14: 120 | V14: 121 | W14: 113 | X14: 132 | Y14: 133 | Z14: 145 | AA14: 135 | AB14: =SUM(E14:AA14) -> 3106
D15: PR | E15: 143 | F15: 156 | G15: 137 | H15: 150 | I15: 147 | J15: 148 | K15: 125 | L15: 136 | M15: 153 | N15: 136 | O15: 137 | P15: 143 | Q15: 131 | R15: 140 | S15: 144 | T15: 133 | U15: 130 | V15: 115 | W15: 115 | X15: 138 | Y15: 129 | Z15: 142 | AA15: 145 | AB15: =SUM(E15:AA15) -> 3173
D16: JML | E16: =SUM(E14:E15) -> 282 | F16: =SUM(F14:F15) -> 287 | G16: =SUM(G14:G15) -> 276 | H16: =SUM(H14:H15) -> 297 | I16: =SUM(I14:I15) -> 268 | J16: =SUM(J14:J15) -> 293 | K16: =SUM(K14:K15) -> 254 | L16: =SUM(L14:L15) -> 288 | ... AA16: =SUM(AA14:AA15) -> 280 | AB16: =SUM(E16:AA16) -> 6279
A18: B | B18: PENGGUNA HAK PILIH
B19: 1. | C19: Jumlah pengguna hak pilih dalam Daftar Pemilih Tetap (DPT) | D19: LK | E19: 96 | F19: 104 | G19: 101 | H19: 128 | I19: 93 | J19: 103 | K19: 92 | L19: 105 | M19: 99 | N19: 86 | O19: 113 | P19: 104 | Q19: 94 | R19: 96 | S19: 110 | T19: 108 | U19: 91 | V19: 85 | W19: 78 | X19: 88 | Y19: 105 | Z19: 112 | AA19: 100 | AB19: =SUM(E19:AA19) -> 2291
D20: PR | E20: 111 | F20: 126 | G20: 110 | H20: 134 | I20: 122 | J20: 122 | K20: 94 | L20: 103 | M20: 115 | N20: 105 | O20: 108 | P20: 105 | Q20: 108 | R20: 108 | S20: 115 | T20: 110 | U20: 104 | V20: 88 | W20: 101 | X20: 114 | Y20: 114 | Z20: 118 | AA20: 107 | AB20: =SUM(E20:AA20) -> 2542
D21: JML | E21: =SUM(E19:E20) -> 207 | F21: =SUM(F19:F20) -> 230 | G21: =SUM(G19:G20) -> 211 | H21: =SUM(H19:H20) -> 262 | I21: =SUM(I19:I20) -> 215 | J21: =SUM(J19:J20) -> 225 | K21: =SUM(K19:K20) -> 186 | L21: =SUM(L19:L20) -> 208 | ... AA21: =SUM(AA19:AA20) -> 207 | AB21: =SUM(E21:AA21) -> 4833
B22: 2. | C22: Jumlah pengguna hak pilih dalam Daftar Pemilih Tambahan (DPTb) | D22: LK | E22: 0 | F22: 0 | G22: 0 | H22: 0 | I22: 0 | J22: 0 | K22: 0 | L22: 0 | M22: 0 | N22: 0 | O22: 0 | P22: 0 | Q22: 0 | R22: 0 | S22: 0 | AB22: =SUM(E22:AA22) -> 0
D23: PR | E23: 0 | F23: 3 | G23: 0 | H23: 0 | I23: 0 | J23: 0 | K23: 0 | L23: 0 | M23: 0 | N23: 0 | O23: 0 | P23: 0 | Q23: 0 | R23: 0 | S23: 0 | AB23: =SUM(E23:AA23) -> 3
D24: JML | E24: =SUM(E22:E23) -> 0 | F24: =SUM(F22:F23) -> 3 | G24: =SUM(G22:G23) -> 0 | H24: =SUM(H22:H23) -> 0 | I24: =SUM(I22:I23) -> 0 | J24: =SUM(J22:J23) -> 0 | K24: =SUM(K22:K23) -> 0 | L24: =SUM(L22:L23) -> 0 | ... AA24: =SUM(AA22:AA23) -> 0 | AB24: =SUM(E24:AA24) -> 3
B25: 3. | C25: Jumlah pengguna hak pilih dalam Daftar Pemilih Khusus (DPK) | D25: LK | E25: 0 | F25: 0 | G25: 2 | H25: 0 | I25: 5 | J25: 0 | K25: 0 | L25: 1 | M25: 1 | N25: 1 | O25: 2 | P25: 0 | Q25: 1 | R25: 1 | S25: 2 | T25: 0 | U25: 0 | V25: 1 | W25: 0 | X25: 1 | Y25: 2 | Z25: 0 | AA25: 4 | AB25: =SUM(E25:AA25) -> 24
D26: PR | E26: 0 | F26: 0 | G26: 1 | H26: 0 | I26: 6 | J26: 0 | K26: 0 | L26: 1 | M26: 0 | N26: 3 | O26: 3 | P26: 1 | Q26: 0 | R26: 0 | S26: 4 | T26: 0 | U26: 0 | V26: 1 | W26: 0 | X26: 1 | Y26: 2 | Z26: 0 | AA26: 3 | AB26: =SUM(E26:AA26) -> 26
D27: JML | E27: =SUM(E25:E26) -> 0 | F27: =SUM(F25:F26) -> 0 | G27: =SUM(G25:G26) -> 3 | H27: =SUM(H25:H26) -> 0 | I27: =SUM(I25:I26) -> 11 | J27: =SUM(J25:J26) -> 0 | K27: =SUM(K25:K26) -> 0 | L27: =SUM(L25:L26) -> 2 | ... AA27: =SUM(AA25:AA26) -> 7 | AB27: =SUM(E27:AA27) -> 50
B28: 4. | C28: Jumlah Pengguna Hak Pilih (B.1+B.2+B.3) | D28: LK | E28: =SUM(E19,E22,E25) -> 96 | F28: =SUM(F19,F22,F25) -> 104 | G28: =SUM(G19,G22,G25) -> 103 | H28: =SUM(H19,H22,H25) -> 128 | I28: =SUM(I19,I22,I25) -> 98 | J28: =SUM(J19,J22,J25) -> 103 | K28: =SUM(K19,K22,K25) -> 92 | L28: =SUM(L19,L22,L25) -> 106 | ... AA28: =SUM(AA19,AA22,AA25) -> 104 | AB28: =SUM(E28:AA28) -> 2315
D29: PR | E29: =SUM(E20,E23,E26) -> 111 | F29: =SUM(F20,F23,F26) -> 129 | G29: =SUM(G20,G23,G26) -> 111 | H29: =SUM(H20,H23,H26) -> 134 | I29: =SUM(I20,I23,I26) -> 128 | J29: =SUM(J20,J23,J26) -> 122 | K29: =SUM(K20,K23,K26) -> 94 | L29: =SUM(L20,L23,L26) -> 104 | ... AA29: =SUM(AA20,AA23,AA26) -> 110 | AB29: =SUM(E29:AA29) -> 2571
D30: JML | E30: =SUM(E28:E29) -> 207 | F30: =SUM(F28:F29) -> 233 | G30: =SUM(G28:G29) -> 214 | H30: =SUM(H28:H29) -> 262 | I30: =SUM(I28:I29) -> 226 | J30: =SUM(J28:J29) -> 225 | K30: =SUM(K28:K29) -> 186 | L30: =SUM(L28:L29) -> 210 | ... AA30: =SUM(AA28:AA29) -> 214 | AB30: =SUM(E30:AA30) -> 4886
A32: II | B32: DATA PENGGUNAAN SURAT SUARA
A33: 1 | B33: Jumlah surat suara yang diterima, termasuk surat suara cadangan 2,5% dari DPT | E33: 288 | F33: 283 | G33: 282 | H33: 303 | I33: 274 | J33: 299 | K33: 260 | L33: 294 | M33: 309 | N33: 272 | O33: 289 | P33: 278 | Q33: 259 | R33: 293 | S33: 298 | T33: 282 | U33: 255 | V33: 241 | W33: 243 | X33: 276 | Y33: 268 | Z33: 293 | AA33: 255 | AB33: =SUM(E33:AA33) -> 6394
A34: 2 | B34: Jumlah surat suara yang digunakan | E34: 207 | F34: 233 | G34: 214 | H34: 262 | I34: 226 | J34: 225 | K34: 186 | L34: 210 | M34: 215 | N34: 195 | O34: 226 | P34: 210 | Q34: 203 | R34: 205 | S34: 231 | T34: 218 | U34: 195 | V34: 175 | W34: 179 | X34: 204 | Y34: 223 | Z34: 230 | AA34: 214 | AB34: =SUM(E34:AA34) -> 4886
A35: 3 | B35: Jumlah surat suara dikembalikan oleh pemilih (karena rusak atau keliru coblos) | E35: 0 | F35: 0 | G35: 0 | H35: 0 | I35: 0 | J35: 0 | K35: 1 | L35: 0 | M35: 0 | N35: 0 | O35: 0 | P35: 0 | Q35: 0 | R35: 0 | S35: 0 | T35: 0 | U35: 2 | V35: 0 | W35: 1 | X35: 0 | Y35: 0 | Z35: 0 | AA35: 0 | AB35: =SUM(E35:AA35) -> 4
A36: 4 | B36: Jumlah surat suara yang tidak digunakan/tidak terpakai, termasuk sisa surat suara cadangan | E36: =E33-(E34+E35) -> 81 | F36: =F33-(F34+F35) -> 50 | G36: =G33-(G34+G35) -> 68 | H36: =H33-(H34+H35) -> 41 | I36: =I33-(I34+I35) -> 48 | J36: =J33-(J34+J35) -> 74 | K36: =K33-(K34+K35) -> 73 | L36: =L33-(L34+L35) -> 84 | ... AA36: =AA33-(AA34+AA35) -> 41 | AB36: =SUM(E36:AA36) -> 1504
A38: III | B38: DATA PEMILIH DISABILITAS
B39: Jumlah seluruh Pemilih disabilitas yang menggunakan hak pilih | D39: LK | Q39: 1 | T39: 0 | U39: 0 | V39: 1 | W39: 0 | X39: 0 | Y39: 0 | Z39: 0 | AA39: 1 | AB39: =SUM(E39:AA39) -> 3
D40: PR | T40: 0 | U40: 0 | V40: 1 | W40: 0 | X40: 0 | Y40: 0 | Z40: 0 | AA40: 0 | AB40: =SUM(E40:AA40) -> 1
D41: JML | E41: =SUM(E39:E40) -> 0 | F41: =SUM(F39:F40) -> 0 | G41: =SUM(G39:G40) -> 0 | H41: =SUM(H39:H40) -> 0 | I41: =SUM(I39:I40) -> 0 | J41: =SUM(J39:J40) -> 0 | K41: =SUM(K39:K40) -> 0 | L41: =SUM(L39:L40) -> 0 | ... AA41: =SUM(AA39:AA40) -> 1 | AB41: =SUM(E41:AA41) -> 4
A43: IV | B43: DATA RINCIAN PEROLEHAN SUARA PASANGAN CALON BUPATI DAN WAKIL BUPATI
A44: NOMOR DAN NAMA CALON
A45: A.1 | B45: 1. | C45: Partai Kebangkitan Bangsa | E45: 20 | F45: 2 | G45: 10 | H45: 9 | I45: 3 | J45: 7 | K45: 3 | L45: 6 | M45: 10 | N45: 10 | O45: 2 | P45: 0 | Q45: 4 | R45: 11 | S45: 5 | T45: 7 | U45: 4 | V45: 1 | W45: 3 | X45: 6 | Y45: 6 | Z45: 4 | AA45: 2 | AB45: =SUM(E45:AA45) -> 135
A46: A.2 | B46: 1 | C46: 1. Dr. Hj. NIHAYATUL WAFIROH, M.A. | E46: 41 | F46: 21 | G46: 27 | H46: 29 | I46: 16 | J46: 22 | K46: 15 | L46: 20 | M46: 15 | N46: 32 | O46: 15 | P46: 10 | Q46: 3 | R46: 28 | S46: 40 | T46: 32 | U46: 17 | V46: 6 | W46: 10 | X46: 19 | Y46: 11 | Z46: 20 | AA46: 16 | AB46: =SUM(E46:AA46) -> 465
B47: 2 | C47: 2. H. M. NASIM KHAN | E47: 0 | F47: 3 | G47: 1 | H47: 1 | I47: 0 | J47: 0 | K47: 3 | L47: 1 | M47: 4 | N47: 6 | O47: 0 | P47: 0 | Q47: 1 | R47: 3 | S47: 1 | T47: 0 | U47: 0 | V47: 1 | W47: 1 | X47: 0 | Y47: 0 | Z47: 2 | AA47: 2 | AB47: =SUM(E47:AA47) -> 30
B48: 3 | C48: 3. Dr. H. AKIK ZAMAN, M.Pd.I. | E48: 1 | F48: 0 | G48: 0 | H48: 0 | I48: 0 | J48: 4 | K48: 2 | L48: 2 | M48: 0 | N48: 1 | O48: 0 | P48: 1 | Q48: 1 | R48: 4 | S48: 0 | T48: 2 | U48: 1 | V48: 0 | W48: 2 | X48: 0 | Y48: 0 | Z48: 1 | AA48: 1 | AB48: =SUM(E48:AA48) -> 23
B49: 4 | C49: 4. AHMAD RIFA'I, S.H. | E49: 0 | F49: 0 | G49: 0 | H49: 0 | I49: 0 | J49: 0 | K49: 2 | L49: 3 | M49: 4 | N49: 2 | O49: 0 | P49: 1 | Q49: 1 | R49: 3 | S49: 2 | T49: 2 | U49: 2 | V49: 3 | W49: 1 | X49: 0 | Y49: 7 | Z49: 4 | AA49: 0 | AB49: =SUM(E49:AA49) -> 37
B50: 5 | C50: 5. Drs. H. MAHFUD M.N. | E50: 1 | F50: 0 | G50: 0 | H50: 0 | I50: 0 | J50: 1 | K50: 0 | L50: 2 | M50: 1 | N50: 2 | O50: 0 | P50: 0 | Q50: 0 | R50: 0 | S50: 0 | T50: 0 | U50: 1 | V50: 0 | W50: 0 | X50: 1 | Y50: 1 | Z50: 1 | AA50: 1 | AB50: =SUM(E50:AA50) -> 12
B51: 6 | C51: 6. NURHAYATI, S.Pd. | E51: 2 | F51: 1 | G51: 4 | H51: 3 | I51: 0 | J51: 0 | K51: 1 | L51: 2 | M51: 4 | N51: 4 | O51: 0 | P51: 0 | Q51: 0 | R51: 3 | S51: 1 | T51: 0 | U51: 0 | V51: 0 | W51: 0 | X51: 1 | Y51: 2 | Z51: 2 | AA51: 2 | AB51: =SUM(E51:AA51) -> 32
...

Sheet WRINGINREJO
C2: Kecamatan | D2: GAMBIRAN
C3: Kabupaten | D3: BANYUWANGI
C4: Provinsi | D4: JAWA TIMUR
C9: Kelurahan | D9: WRINGINREJO
A12: I | B12: DATA PEMILIH DAN PENGGUNAAN HAK PILIH | X12: JUMLAH AKHIR
A13: A | B13: DATA PEMILIH | E13: TPS 001 | F13: TPS 002 | G13: TPS 003 | H13: TPS 004 | I13: TPS 005 | J13: TPS 006 | K13: TPS 007 | L13: TPS 008 | M13: TPS 009 | N13: TPS 010 | O13: TPS 011 | P13: TPS 012 | Q13: TPS 013 | R13: TPS 014 | S13: TPS 015 | T13: TPS 016 | U13: TPS 017 | V13: TPS 018 | W13: TPS 019
B14: Jumlah Pemilih dalam Daftar Pemilih Tetap (DPT) | D14: LK | E14: 151 | F14: 137 | G14: 138 | H14: 147 | I14: 148 | J14: 147 | K14: 144 | L14: 126 | M14: 145 | N14: 153 | O14: 152 | P14: 108 | Q14: 139 | R14: 106 | S14: 135 | T14: 127 | U14: 101 | V14: 119 | W14: 119 | X14: =SUM(E14:W14) -> 2542
D15: PR | E15: 142 | F15: 156 | G15: 150 | H15: 146 | I15: 136 | J15: 150 | K15: 151 | L15: 126 | M15: 148 | N15: 143 | O15: 134 | P15: 106 | Q15: 141 | R15: 110 | S15: 135 | T15: 140 | U15: 108 | V15: 110 | W15: 124 | X15: =SUM(E15:W15) -> 2556
D16: JML | E16: =SUM(E14:E15) -> 293 | F16: =SUM(F14:F15) -> 293 | G16: =SUM(G14:G15) -> 288 | H16: =SUM(H14:H15) -> 293 | I16: =SUM(I14:I15) -> 284 | J16: =SUM(J14:J15) -> 297 | K16: =SUM(K14:K15) -> 295 | L16: =SUM(L14:L15) -> 252 | ... W16: =SUM(W14:W15) -> 243 | X16: =SUM(E16:W16) -> 5098
A18: B | B18: PENGGUNA HAK PILIH
B19: 1. | C19: Jumlah pengguna hak pilih dalam Daftar Pemilih Tetap (DPT) | D19: LK | E19: 112 | F19: 126 | G19: 106 | H19: 112 | I19: 104 | J19: 100 | K19: 104 | L19: 91 | M19: 119 | N19: 105 | O19: 108 | P19: 97 | Q19: 106 | R19: 74 | S19: 97 | T19: 98 | U19: 84 | V19: 89 | W19: 95 | X19: =SUM(E19:W19) -> 1927
D20: PR | E20: 106 | F20: 105 | G20: 126 | H20: 119 | I20: 106 | J20: 124 | K20: 119 | L20: 104 | M20: 111 | N20: 109 | O20: 95 | P20: 86 | Q20: 112 | R20: 77 | S20: 110 | T20: 107 | U20: 89 | V20: 87 | W20: 87 | X20: =SUM(E20:W20) -> 1979
D21: JML | E21: =SUM(E19:E20) -> 218 | F21: =SUM(F19:F20) -> 231 | G21: =SUM(G19:G20) -> 232 | H21: =SUM(H19:H20) -> 231 | I21: =SUM(I19:I20) -> 210 | J21: =SUM(J19:J20) -> 224 | K21: =SUM(K19:K20) -> 223 | L21: =SUM(L19:L20) -> 195 | ... W21: =SUM(W19:W20) -> 182 | X21: =SUM(E21:W21) -> 3906
B22: 2. | C22: Jumlah pengguna hak pilih dalam Daftar Pemilih Tambahan (DPTb) | D22: LK | X22: =SUM(E22:W22) -> 0
D23: PR | X23: =SUM(E23:W23) -> 0
D24: JML | E24: =SUM(E22:E23) -> 0 | F24: =SUM(F22:F23) -> 0 | G24: =SUM(G22:G23) -> 0 | H24: =SUM(H22:H23) -> 0 | I24: =SUM(I22:I23) -> 0 | J24: =SUM(J22:J23) -> 0 | K24: =SUM(K22:K23) -> 0 | L24: =SUM(L22:L23) -> 0 | ... W24: =SUM(W22:W23) -> 0 | X24: =SUM(E24:W24) -> 0
B25: 3. | C25: Jumlah pengguna hak pilih dalam Daftar Pemilih Khusus (DPK) | D25: LK | E25: 1 | F25: 0 | G25: 0 | H25: 0 | I25: 1 | J25: 2 | K25: 1 | L25: 0 | M25: 2 | N25: 1 | O25: 3 | P25: 0 | Q25: 1 | R25: 12 | S25: 2 | T25: 0 | U25: 11 | V25: 3 | W25: 1 | X25: =SUM(E25:W25) -> 41
D26: PR | E26: 1 | F26: 0 | G26: 0 | H26: 5 | I26: 0 | J26: 1 | K26: 1 | L26: 0 | M26: 1 | N26: 3 | O26: 2 | P26: 2 | Q26: 1 | R26: 12 | S26: 1 | T26: 0 | U26: 14 | V26: 2 | W26: 3 | X26: =SUM(E26:W26) -> 49
D27: JML | E27: =SUM(E25:E26) -> 2 | F27: =SUM(F25:F26) -> 0 | G27: =SUM(G25:G26) -> 0 | H27: =SUM(H25:H26) -> 5 | I27: =SUM(I25:I26) -> 1 | J27: =SUM(J25:J26) -> 3 | K27: =SUM(K25:K26) -> 2 | L27: =SUM(L25:L26) -> 0 | ... W27: =SUM(W25:W26) -> 4 | X27: =SUM(E27:W27) -> 90
B28: 4. | C28: Jumlah Pengguna Hak Pilih (B.1+B.2+B.3) | D28: LK | E28: =SUM(E19,E22,E25) -> 113 | F28: =SUM(F19,F22,F25) -> 126 | G28: =SUM(G19,G22,G25) -> 106 | H28: =SUM(H19,H22,H25) -> 112 | I28: =SUM(I19,I22,I25) -> 105 | J28: =SUM(J19,J22,J25) -> 102 | K28: =SUM(K19,K22,K25) -> 105 | L28: =SUM(L19,L22,L25) -> 91 | ... W28: =SUM(W19,W22,W25) -> 96 | X28: =SUM(E28:W28) -> 1968
D29: PR | E29: =SUM(E20,E23,E26) -> 107 | F29: =SUM(F20,F23,F26) -> 105 | G29: =SUM(G20,G23,G26) -> 126 | H29: =SUM(H20,H23,H26) -> 124 | I29: =SUM(I20,I23,I26) -> 106 | J29: =SUM(J20,J23,J26) -> 125 | K29: =SUM(K20,K23,K26) -> 120 | L29: =SUM(L20,L23,L26) -> 104 | ... W29: =SUM(W20,W23,W26) -> 90 | X29: =SUM(E29:W29) -> 2028
D30: JML | E30: =SUM(E28:E29) -> 220 | F30: =SUM(F28:F29) -> 231 | G30: =SUM(G28:G29) -> 232 | H30: =SUM(H28:H29) -> 236 | I30: =SUM(I28:I29) -> 211 | J30: =SUM(J28:J29) -> 227 | K30: =SUM(K28:K29) -> 225 | L30: =SUM(L28:L29) -> 195 | ... W30: =SUM(W28:W29) -> 186 | X30: =SUM(E30:W30) -> 3996
A32: II | B32: DATA PENGGUNAAN SURAT SUARA
A33: 1 | B33: Jumlah surat suara yang diterima, termasuk surat suara cadangan 2,5% dari DPT | E33: 300 | F33: 299 | G33: 295 | H33: 299 | I33: 290 | J33: 303 | K33: 301 | L33: 258 | M33: 299 | N33: 302 | O33: 292 | P33: 219 | Q33: 286 | R33: 221 | S33: 276 | T33: 273 | U33: 214 | V33: 244 | W33: 248 | X33: =SUM(E33:W33) -> 5219
A34: 2 | B34: Jumlah surat suara yang digunakan | E34: 220 | F34: 231 | G34: 232 | H34: 236 | I34: 211 | J34: 227 | K34: 225 | L34: 195 | M34: 233 | N34: 218 | O34: 208 | P34: 185 | Q34: 220 | R34: 175 | S34: 210 | T34: 205 | U34: 198 | V34: 181 | W34: 186 | X34: =SUM(E34:W34) -> 3996
A35: 3 | B35: Jumlah surat suara dikembalikan oleh pemilih (karena rusak atau keliru coblos) | E35: 0 | F35: 1 | G35: 0 | H35: 1 | I35: 0 | J35: 0 | K35: 0 | L35: 0 | M35: 4 | N35: 0 | O35: 1 | P35: 0 | Q35: 0 | R35: 0 | S35: 0 | X35: =SUM(E35:W35) -> 7
A36: 4 | B36: Jumlah surat suara yang tidak digunakan/tidak terpakai, termasuk sisa surat suara cadangan | E36: =E33-(E34+E35) -> 80 | F36: =F33-(F34+F35) -> 67 | G36: =G33-(G34+G35) -> 63 | H36: =H33-(H34+H35) -> 62 | I36: =I33-(I34+I35) -> 79 | J36: =J33-(J34+J35) -> 76 | K36: =K33-(K34+K35) -> 76 | L36: =L33-(L34+L35) -> 63 | ... W36: =W33-(W34+W35) -> 62 | X36: =SUM(E36:W36) -> 1216
A38: III | B38: DATA PEMILIH DISABILITAS
B39: Jumlah seluruh Pemilih disabilitas yang menggunakan hak pilih | D39: LK | E39: 0 | F39: 0 | G39: 5 | H39: 0 | I39: 0 | J39: 0 | K39: 0 | L39: 0 | M39: 0 | N39: 0 | O39: 0 | P39: 0 | Q39: 0 | R39: 0 | S39: 0 | V39: 4 | X39: =SUM(E39:W39) -> 9
D40: PR | E40: 0 | F40: 0 | G40: 5 | H40: 5 | I40: 0 | J40: 0 | K40: 0 | L40: 0 | M40: 0 | N40: 0 | O40: 0 | P40: 2 | Q40: 0 | R40: 2 | S40: 0 | V40: 2 | X40: =SUM(E40:W40) -> 16
D41: JML | E41: =SUM(E39:E40) -> 0 | F41: =SUM(F39:F40) -> 0 | G41: =SUM(G39:G40) -> 10 | H41: =SUM(H39:H40) -> 5 | I41: =SUM(I39:I40) -> 0 | J41: =SUM(J39:J40) -> 0 | K41: =SUM(K39:K40) -> 0 | L41: =SUM(L39:L40) -> 0 | ... W41: =SUM(W39:W40) -> 0 | X41: =SUM(E41:W41) -> 25
A43: IV | B43: DATA RINCIAN PEROLEHAN SUARA PASANGAN CALON BUPATI DAN WAKIL BUPATI
A44: NOMOR DAN NAMA CALON
A45: A.1 | B45: 1. | C45: Partai Kebangkitan Bangsa | E45: 6 | F45: 11 | G45: 8 | H45: 9 | I45: 6 | J45: 6 | K45: 4 | L45: 9 | M45: 12 | N45: 8 | O45: 10 | P45: 0 | Q45: 13 | R45: 2 | S45: 13 | T45: 3 | U45: 3 | V45: 2 | W45: 2 | X45: =SUM(E45:W45) -> 127
A46: A.2 | B46: 1 | C46: 1. Dr. Hj. NIHAYATUL WAFIROH, M.A. | E46: 22 | F46: 44 | G46: 39 | H46: 23 | I46: 16 | J46: 34 | K46: 14 | L46: 30 | M46: 32 | N46: 35 | O46: 26 | P46: 3 | Q46: 26 | R46: 20 | S46: 21 | T46: 31 | U46: 7 | V46: 17 | W46: 7 | X46: =SUM(E46:W46) -> 447
B47: 2 | C47: 2. H. M. NASIM KHAN | E47: 4 | F47: 1 | G47: 1 | H47: 4 | I47: 2 | J47: 6 | K47: 1 | L47: 3 | M47: 3 | N47: 1 | O47: 2 | P47: 0 | Q47: 3 | R47: 1 | S47: 7 | T47: 2 | U47: 0 | V47: 1 | W47: 0 | X47: =SUM(E47:W47) -> 42
B48: 3 | C48: 3. Dr. H. AKIK ZAMAN, M.Pd.I. | E48: 1 | F48: 12 | G48: 2 | H48: 0 | I48: 1 | J48: 1 | K48: 0 | L48: 1 | M48: 2 | N48: 0 | O48: 3 | P48: 0 | Q48: 1 | R48: 1 | S48: 1 | T48: 1 | U48: 0 | V48: 1 | W48: 0 | X48: =SUM(E48:W48) -> 28
B49: 4 | C49: 4. AHMAD RIFA'I, S.H. | E49: 0 | F49: 0 | G49: 1 | H49: 1 | I49: 0 | J49: 0 | K49: 1 | L49: 1 | M49: 3 | N49: 1 | O49: 2 | P49: 0 | Q49: 1 | R49: 1 | S49: 0 | T49: 4 | U49: 0 | V49: 0 | W49: 1 | X49: =SUM(E49:W49) -> 17
B50: 5 | C50: 5. Drs. H. MAHFUD M.N. | E50: 0 | F50: 0 | G50: 0 | H50: 2 | I50: 1 | J50: 0 | K50: 2 | L50: 0 | M50: 3 | N50: 1 | O50: 1 | P50: 0 | Q50: 1 | R50: 0 | S50: 0 | T50: 1 | U50: 0 | V50: 0 | W50: 1 | X50: =SUM(E50:W50) -> 13
