Workbook

Sheet DPR
C8: Kecamatan | D8: ROGOJAMPI
C9: Kabupaten | D9: BANYUWANGI
C10: Provinsi | D10: JAWA TIMUR
A12: I | B12: DATA PEMILIH DAN PENGGUNAAN HAK PILIH | E12: JUMLAH AKHIR
A13: A | B13: DATA PEMILIH
B14: Jumlah Pemilih dalam Daftar Pemilih Tetap (DPT) | D14: LK | E14: =ALIYAN!V14+BUBUK!T14+GITIK!N14+GLADAG!W14+KARANGBENDO!Z14+KEDALEMAN!S14+LEMAHBANGDEWO!O14+MANGIR!S14+PENGATIGAN!Y14+ROGOJAMPI!AM14 -> 21540
D15: PR | E15: =ALIYAN!V15+BUBUK!T15+GITIK!N15+GLADAG!W15+KARANGBENDO!Z15+KEDALEMAN!S15+LEMAHBANGDEWO!O15+MANGIR!S15+PENGATIGAN!Y15+ROGOJAMPI!AM15 -> 22247
D16: JML | E16: =SUM(E14:E15) -> 43787
A18: B | B18: PENGGUNA HAK PILIH
B19: 1. | C19: Jumlah pengguna hak pilih dalam Daftar Pemilih Tetap (DPT) | D19: LK | E19: =ALIYAN!V19+BUBUK!T19+GITIK!N19+GLADAG!W19+KARANGBENDO!Z19+KEDALEMAN!S19+LEMAHBANGDEWO!O19+MANGIR!S19+PENGATIGAN!Y19+ROGOJAMPI!AM19 -> 16685
D20: PR | E20: =ALIYAN!V20+BUBUK!T20+GITIK!N20+GLADAG!W20+KARANGBENDO!Z20+KEDALEMAN!S20+LEMAHBANGDEWO!O20+MANGIR!S20+PENGATIGAN!Y20+ROGOJAMPI!AM20 -> 18273
D21: JML | E21: =SUM(E19:E20) -> 34958
B22: 2. | C22: Jumlah pengguna hak pilih dalam Daftar Pemilih Tambahan (DPTb) | D22: LK | E22: =ALIYAN!V22+BUBUK!T22+GITIK!N22+GLADAG!W22+KARANGBENDO!Z22+KEDALEMAN!S22+LEMAHBANGDEWO!O22+MANGIR!S22+PENGATIGAN!Y22+ROGOJAMPI!AM22 -> 66
D23: PR | E23: =ALIYAN!V23+BUBUK!T23+GITIK!N23+GLADAG!W23+KARANGBENDO!Z23+KEDALEMAN!S23+LEMAHBANGDEWO!O23+MANGIR!S23+PENGATIGAN!Y23+ROGOJAMPI!AM23 -> 94
D24: JML | E24: =SUM(E22:E23) -> 160
B25: 3. | C25: Jumlah pengguna hak pilih dalam Daftar Pemilih Khusus (DPK) | D25: LK | E25: =ALIYAN!V25+BUBUK!T25+GITIK!N25+GLADAG!W25+KARANGBENDO!Z25+KEDALEMAN!S25+LEMAHBANGDEWO!O25+MANGIR!S25+PENGATIGAN!Y25+ROGOJAMPI!AM25 -> 174
D26: PR | E26: =ALIYAN!V26+BUBUK!T26+GITIK!N26+GLADAG!W26+KARANGBENDO!Z26+KEDALEMAN!S26+LEMAHBANGDEWO!O26+MANGIR!S26+PENGATIGAN!Y26+ROGOJAMPI!AM26 -> 223
D27: JML | E27: =SUM(E25:E26) -> 397
B28: 4. | C28: Jumlah Pengguna Hak Pilih (B.1+B.2+B.3) | D28: LK | E28: =E19+E22+E25 -> 16925
D29: PR | E29: =E20+E23+E26 -> 18590
D30: JML | E30: =SUM(E28:E29) -> 35515
A32: II | B32: DATA PENGGUNAAN SURAT SUARA
A33: 1 | B33: Jumlah surat suara yang diterima, termasuk surat suara cadangan 2,5% dari DPT | E33: =ALIYAN!V33+BUBUK!T33+GITIK!N33+GLADAG!W33+KARANGBENDO!Z33+KEDALEMAN!S33+LEMAHBANGDEWO!O33+MANGIR!S33+PENGATIGAN!Y33+ROGOJAMPI!AM33 -> 44639
A34: 2 | B34: Jumlah surat suara yang digunakan | E34: =ALIYAN!V34+BUBUK!T34+GITIK!N34+GLADAG!W34+KARANGBENDO!Z34+KEDALEMAN!S34+LEMAHBANGDEWO!O34+MANGIR!S34+PENGATIGAN!Y34+ROGOJAMPI!AM34 -> 35515
A35: 3 | B35: Jumlah surat suara dikembalikan oleh pemilih (karena rusak atau keliru coblos) | E35: =ALIYAN!V35+BUBUK!T35+GITIK!N35+GLADAG!W35+KARANGBENDO!Z35+KEDALEMAN!S35+LEMAHBANGDEWO!O35+MANGIR!S35+PENGATIGAN!Y35+ROGOJAMPI!AM35 -> 81
A36: 4 | B36: Jumlah surat suara yang tidak digunakan/tidak terpakai, termasuk sisa surat suara cadangan | E36: =E33-(E34+E35) -> 9043
A38: III | B38: DATA PEMILIH DISABILITAS
B39: Jumlah seluruh Pemilih disabilitas yang menggunakan hak pilih | D39: LK | E39: =ALIYAN!V39+BUBUK!T39+GITIK!N39+GLADAG!W39+KARANGBENDO!Z39+KEDALEMAN!S39+LEMAHBANGDEWO!O39+MANGIR!S39+PENGATIGAN!Y39+ROGOJAMPI!AM39 -> 46
D40: PR | E40: =ALIYAN!V40+BUBUK!T40+GITIK!N40+GLADAG!W40+KARANGBENDO!Z40+KEDALEMAN!S40+LEMAHBANGDEWO!O40+MANGIR!S40+PENGATIGAN!Y40+ROGOJAMPI!AM40 -> 51
D41: JML | E41: =SUM(E39:E40) -> 97
A43: IV | B43: DATA RINCIAN PEROLEHAN SUARA PASANGAN CALON BUPATI DAN WAKIL BUPATI
A44: NOMOR DAN NAMA CALON
A45: A.1 | B45: 1. | C45: Partai Kebangkitan Bangsa | E45: 851
A46: A.2 | B46: 1 | C46: 1. Dr. Hj. NIHAYATUL WAFIROH, M.A. | E46: 2167
B47: 2 | C47: 2. H. M. NASIM KHAN | E47: 804
B48: 3 | C48: 3. Dr. H. AKIK ZAMAN, M.Pd.I. | E48: 142
B49: 4 | C49: 4. AHMAD RIFA'I, S.H. | E49: 126
B50: 5 | C50: 5. Drs. H. MAHFUD M.N. | E50: 83
B51: 6 | C51: 6. NURHAYATI, S.Pd. | E51: 34
B52: 7 | C52: 7. MAFTUHA KISWAH | E52: 27
...

Sheet ALIYAN
C2: Kecamatan | D2: ROGOJAMPI
C3: Kabupaten | D3: BANYUWANGI
C4: Provinsi | D4: JAWA TIMUR
C9: Kelurahan | D9: ALIYAN
A12: I | B12: DATA PEMILIH DAN PENGGUNAAN HAK PILIH | V12: JUMLAH AKHIR
A13: A | B13: DATA PEMILIH | E13: TPS 001 | F13: TPS 002 | G13: TPS 003 | H13: TPS 004 | I13: TPS 005 | J13: TPS 006 | K13: TPS 007 | L13: TPS 008 | M13: TPS 009 | N13: TPS 010 | O13: TPS 011 | P13: TPS 012 | Q13: TPS 013 | R13: TPS 014 | S13: TPS 015 | T13: TPS 016 | U13: TPS 017
B14: Jumlah Pemilih dalam Daftar Pemilih Tetap (DPT) | D14: LK | E14: 76 | F14: 101 | G14: 67 | H14: 144 | I14: 143 | J14: 119 | K14: 147 | L14: 105 | M14: 114 | N14: 118 | O14: 132 | P14: 116 | Q14: 115 | R14: 137 | S14: 126 | T14: 119 | U14: 121 | V14: =SUM(E14:U14) -> 2000
D15: PR | E15: 78 | F15: 98 | G15: 73 | H15: 137 | I15: 121 | J15: 108 | K15: 145 | L15: 117 | M15: 114 | N15: 130 | O15: 138 | P15: 115 | Q15: 127 | R15: 134 | S15: 126 | T15: 123 | U15: 140 | V15: =SUM(E15:U15) -> 2024
D16: JML | E16: =SUM(E14:E15) -> 154 | F16: =SUM(F14:F15) -> 199 | G16: =SUM(G14:G15) -> 140 | H16: =SUM(H14:H15) -> 281 | I16: =SUM(I14:I15) -> 264 | J16: =SUM(J14:J15) -> 227 | K16: =SUM(K14:K15) -> 292 | L16: =SUM(L14:L15) -> 222 | ... U16: =SUM(U14:U15) -> 261 | V16: =SUM(E16:U16) -> 4024
A18: B | B18: PENGGUNA HAK PILIH
B19: 1. | C19: Jumlah pengguna hak pilih dalam Daftar Pemilih Tetap (DPT) | D19: LK | E19: 62 | F19: 87 | G19: 55 | H19: 112 | I19: 104 | J19: 91 | K19: 118 | L19: 82 | M19: 97 | N19: 93 | O19: 114 | P19: 97 | Q19: 105 | R19: 111 | S19: 96 | T19: 100 | U19: 100 | V19: =SUM(E19:U19) -> 1624
D20: PR | E20: 67 | F20: 86 | G20: 61 | H20: 118 | I20: 101 | J20: 94 | K20: 134 | L20: 97 | M20: 95 | N20: 110 | O20: 119 | P20: 106 | Q20: 116 | R20: 111 | S20: 104 | T20: 110 | U20: 122 | V20: =SUM(E20:U20) -> 1751
D21: JML | E21: =SUM(E19:E20) -> 129 | F21: =SUM(F19:F20) -> 173 | G21: =SUM(G19:G20) -> 116 | H21: =SUM(H19:H20) -> 230 | I21: =SUM(I19:I20) -> 205 | J21: =SUM(J19:J20) -> 185 | K21: =SUM(K19:K20) -> 252 | L21: =SUM(L19:L20) -> 179 | ... U21: =SUM(U19:U20) -> 222 | V21: =SUM(E21:U21) -> 3375
B22: 2. | C22: Jumlah pengguna hak pilih dalam Daftar Pemilih Tambahan (DPTb) | D22: LK | E22: 0 | F22: 0 | G22: 0 | H22: 0 | I22: 1 | J22: 1 | K22: 0 | L22: 2 | M22: 0 | N22: 2 | O22: 3 | P22: 1 | Q22: 1 | R22: 1 | S22: 0 | T22: 0 | U22: 0 | V22: =SUM(E22:U22) -> 12
D23: PR | E23: 0 | F23: 0 | G23: 0 | H23: 0 | I23: 3 | J23: 0 | K23: 3 | L23: 1 | M23: 1 | N23: 1 | O23: 2 | P23: 1 | Q23: 2 | R23: 0 | S23: 0 | T23: 1 | U23: 0 | V23: =SUM(E23:U23) -> 15
D24: JML | E24: =SUM(E22:E23) -> 0 | F24: =SUM(F22:F23) -> 0 | G24: =SUM(G22:G23) -> 0 | H24: =SUM(H22:H23) -> 0 | I24: =SUM(I22:I23) -> 4 | J24: =SUM(J22:J23) -> 1 | K24: =SUM(K22:K23) -> 3 | L24: =SUM(L22:L23) -> 3 | ... U24: =SUM(U22:U23) -> 0 | V24: =SUM(E24:U24) -> 27
B25: 3. | C25: Jumlah pengguna hak pilih dalam Daftar Pemilih Khusus (DPK) | D25: LK | E25: 0 | F25: 1 | G25: 0 | H25: 0 | I25: 0 | J25: 0 | K25: 0 | L25: 2 | M25: 0 | N25: 0 | O25: 0 | P25: 0 | Q25: 0 | R25: 0 | S25: 0 | T25: 0 | U25: 0 | V25: =SUM(E25:U25) -> 3
D26: PR | E26: 1 | F26: 0 | G26: 0 | H26: 0 | I26: 1 | J26: 0 | K26: 0 | L26: 1 | M26: 2 | N26: 0 | O26: 0 | P26: 0 | Q26: 2 | R26: 2 | S26: 3 | T26: 0 | U26: 0 | V26: =SUM(E26:U26) -> 12
D27: JML | E27: =SUM(E25:E26) -> 1 | F27: =SUM(F25:F26) -> 1 | G27: =SUM(G25:G26) -> 0 | H27: =SUM(H25:H26) -> 0 | I27: =SUM(I25:I26) -> 1 | J27: =SUM(J25:J26) -> 0 | K27: =SUM(K25:K26) -> 0 | L27: =SUM(L25:L26) -> 3 | ... U27: =SUM(U25:U26) -> 0 | V27: =SUM(E27:U27) -> 15
B28: 4. | C28: Jumlah Pengguna Hak Pilih (B.1+B.2+B.3) | D28: LK | E28: =SUM(E19,E22,E25) -> 62 | F28: =SUM(F19,F22,F25) -> 88 | G28: =SUM(G19,G22,G25) -> 55 | H28: =SUM(H19,H22,H25) -> 112 | I28: =SUM(I19,I22,I25) -> 105 | J28: =SUM(J19,J22,J25) -> 92 | K28: =SUM(K19,K22,K25) -> 118 | L28: =SUM(L19,L22,L25) -> 86 | ... U28: =SUM(U19,U22,U25) -> 100 | V28: =SUM(E28:U28) -> 1639
D29: PR | E29: =SUM(E20,E23,E26) -> 68 | F29: =SUM(F20,F23,F26) -> 86 | G29: =SUM(G20,G23,G26) -> 61 | H29: =SUM(H20,H23,H26) -> 118 | I29: =SUM(I20,I23,I26) -> 105 | J29: =SUM(J20,J23,J26) -> 94 | K29: =SUM(K20,K23,K26) -> 137 | L29: =SUM(L20,L23,L26) -> 99 | ... U29: =SUM(U20,U23,U26) -> 122 | V29: =SUM(E29:U29) -> 1778
D30: JML | E30: =SUM(E28:E29) -> 130 | F30: =SUM(F28:F29) -> 174 | G30: =SUM(G28:G29) -> 116 | H30: =SUM(H28:H29) -> 230 | I30: =SUM(I28:I29) -> 210 | J30: =SUM(J28:J29) -> 186 | K30: =SUM(K28:K29) -> 255 | L30: =SUM(L28:L29) -> 185 | ... U30: =SUM(U28:U29) -> 222 | V30: =SUM(E30:U30) -> 3417
A32: II | B32: DATA PENGGUNAAN SURAT SUARA
A33: 1 | B33: Jumlah surat suara yang diterima, termasuk surat suara cadangan 2,5% dari DPT | E33: 158 | F33: 203 | G33: 143 | H33: 287 | I33: 270 | J33: 232 | K33: 298 | L33: 227 | M33: 233 | N33: 253 | O33: 276 | P33: 236 | Q33: 247 | R33: 277 | S33: 258 | T33: 247 | U33: 267 | V33: =SUM(E33:U33) -> 4112
A34: 2 | B34: Jumlah surat suara yang digunakan | E34: 130 | F34: 174 | G34: 116 | H34: 230 | I34: 210 | J34: 186 | K34: 255 | L34: 185 | M34: 195 | N34: 206 | O34: 238 | P34: 205 | Q34: 226 | R34: 225 | S34: 203 | T34: 211 | U34: 222 | V34: =SUM(E34:U34) -> 3417
A35: 3 | B35: Jumlah surat suara dikembalikan oleh pemilih (karena rusak atau keliru coblos) | E35: 0 | F35: 0 | G35: 1 | H35: 0 | I35: 0 | J35: 1 | K35: 0 | L35: 0 | M35: 1 | N35: 2 | O35: 1 | P35: 0 | Q35: 1 | R35: 0 | S35: 0 | T35: 1 | U35: 2 | V35: =SUM(E35:U35) -> 10
A36: 4 | B36: Jumlah surat suara yang tidak digunakan/tidak terpakai, termasuk sisa surat suara cadangan | E36: =E33-(E34+E35) -> 28 | F36: =F33-(F34+F35) -> 29 | G36: =G33-(G34+G35) -> 26 | H36: =H33-(H34+H35) -> 57 | I36: =I33-(I34+I35) -> 60 | J36: =J33-(J34+J35) -> 45 | K36: =K33-(K34+K35) -> 43 | L36: =L33-(L34+L35) -> 42 | ... U36: =U33-(U34+U35) -> 43 | V36: =SUM(E36:U36) -> 685
A38: III | B38: DATA PEMILIH DISABILITAS
B39: Jumlah seluruh Pemilih disabilitas yang menggunakan hak pilih | D39: LK | E39: 0 | F39: 0 | G39: 0 | H39: 0 | I39: 2 | J39: 0 | K39: 0 | L39: 1 | M39: 0 | N39: 0 | O39: 0 | P39: 0 | Q39: 1 | R39: 0 | S39: 0 | T39: 0 | U39: 0 | V39: =SUM(E39:U39) -> 4
D40: PR | E40: 0 | F40: 0 | G40: 0 | H40: 0 | I40: 2 | J40: 0 | K40: 0 | L40: 0 | M40: 0 | N40: 3 | O40: 0 | P40: 0 | Q40: 0 | R40: 0 | S40: 0 | T40: 0 | U40: 0 | V40: =SUM(E40:U40) -> 5
D41: JML | E41: =SUM(E39:E40) -> 0 | F41: =SUM(F39:F40) -> 0 | G41: =SUM(G39:G40) -> 0 | H41: =SUM(H39:H40) -> 0 | I41: =SUM(I39:I40) -> 4 | J41: =SUM(J39:J40) -> 0 | K41: =SUM(K39:K40) -> 0 | L41: =SUM(L39:L40) -> 1 | ... U41: =SUM(U39:U40) -> 0 | V41: =SUM(E41:U41) -> 9
A43: IV | B43: DATA RINCIAN PEROLEHAN SUARA PASANGAN CALON BUPATI DAN WAKIL BUPATI
A44: NOMOR DAN NAMA CALON
A45: A.1 | B45: 1. | C45: Partai Kebangkitan Bangsa | E45: 4 | F45: 5 | G45: 11 | H45: 2 | I45: 4 | J45: 3 | K45: 1 | L45: 2 | M45: 4 | N45: 0 | O45: 0 | P45: 6 | Q45: 2 | R45: 7 | S45: 1 | T45: 4 | U45: 2 | V45: =SUM(E45:U45) -> 58
A46: A.2 | B46: 1 | C46: 1. Dr. Hj. NIHAYATUL WAFIROH, M.A. | E46: 3 | F46: 2 | G46: 7 | H46: 1 | I46: 4 | J46: 5 | K46: 9 | L46: 4 | M46: 2 | N46: 1 | O46: 8 | P46: 19 | Q46: 14 | R46: 12 | S46: 15 | T46: 16 | U46: 10 | V46: =SUM(E46:U46) -> 132
B47: 2 | C47: 2. H. M. NASIM KHAN | E47: 10 | F47: 10 | G47: 2 | H47: 2 | I47: 6 | J47: 4 | K47: 14 | L47: 9 | M47: 0 | N47: 1 | O47: 3 | P47: 4 | Q47: 5 | R47: 4 | S47: 5 | T47: 11 | U47: 5 | V47: =SUM(E47:U47) -> 95
B48: 3 | C48: 3. Dr. H. AKIK ZAMAN, M.Pd.I. | E48: 0 | F48: 0 | G48: 0 | H48: 0 | I48: 0 | J48: 0 | K48: 1 | L48: 0 | M48: 1 | N48: 0 | O48: 1 | P48: 2 | Q48: 0 | R48: 1 | S48: 0 | T48: 0 | U48: 0 | V48: =SUM(E48:U48) -> 6
B49: 4 | C49: 4. AHMAD RIFA'I, S.H. | E49: 0 | F49: 1 | G49: 0 | H49: 0 | I49: 0 | J49: 0 | K49: 0 | L49: 0 | M49: 0 | N49: 0 | O49: 1 | P49: 1 | Q49: 1 | R49: 0 | S49: 0 | T49: 0 | U49: 0 | V49: =SUM(E49:U49) -> 4
B50: 5 | C50: 5. Drs. H. MAHFUD M.N. | E50: 0 | F50: 1 | G50: 1 | H50: 1 | I50: 0 | J50: 0 | K50: 0 | L50: 0 | M50: 0 | N50: 0 | O50: 2 | P50: 0 | Q50: 0 | R50: 0 | S50: 0 | T50: 0 | U50: 0 | V50: =SUM(E50:U50) -> 5
B51: 6 | C51: 6. NURHAYATI, S.Pd. | E51: 0 | F51: 0 | G51: 0 | H51: 0 | I51: 0 | J51: 0 | K51: 0 | L51: 0 | M51: 0 | N51: 0 | O51: 0 | P51: 0 | Q51: 1 | R51: 1 | S51: 0 | T51: 0 | U51: 0 | V51: =SUM(E51:U51) -> 2
...

Sheet BUBUK
C2: Kecamatan | D2: ROGOJAMPI
C3: Kabupaten | D3: BANYUWANGI
C4: Provinsi | D4: JAWA TIMUR
C9: Kelurahan | D9: BUBUK
A12: I | B12: DATA PEMILIH DAN PENGGUNAAN HAK PILIH | T12: JUMLAH AKHIR
A13: A | B13: DATA PEMILIH | E13: TPS 001 | F13: TPS 002 | G13: TPS 003 | H13: TPS 004 | I13: TPS 005 | J13: TPS 006 | K13: TPS 007 | L13: TPS 008 | M13: TPS 009 | N13: TPS 010 | O13: TPS 011 | P13: TPS 012 | Q13: TPS 013 | R13: TPS 014 | S13: TPS 015
B14: Jumlah Pemilih dalam Daftar Pemilih Tetap (DPT) | D14: LK | E14: 133 | F14: 134 | G14: 113 | H14: 131 | I14: 63 | J14: 107 | K14: 122 | L14: 112 | M14: 141 | N14: 149 | O14: 127 | P14: 137 | Q14: 132 | R14: 107 | S14: 144 | T14: =SUM(E14:S14) -> 1852
D15: PR | E15: 139 | F15: 128 | G15: 111 | H15: 134 | I15: 75 | J15: 130 | K15: 117 | L15: 115 | M15: 117 | N15: 138 | O15: 141 | P15: 130 | Q15: 136 | R15: 99 | S15: 129 | T15: =SUM(E15:S15) -> 1839
D16: JML | E16: =SUM(E14:E15) -> 272 | F16: =SUM(F14:F15) -> 262 | G16: =SUM(G14:G15) -> 224 | H16: =SUM(H14:H15) -> 265 | I16: =SUM(I14:I15) -> 138 | J16: =SUM(J14:J15) -> 237 | K16: =SUM(K14:K15) -> 239 | L16: =SUM(L14:L15) -> 227 | ... S16: =SUM(S14:S15) -> 273 | T16: =SUM(E16:S16) -> 3691
A18: B | B18: PENGGUNA HAK PILIH
B19: 1. | C19: Jumlah pengguna hak pilih dalam Daftar Pemilih Tetap (DPT) | D19: LK | E19: 108 | F19: 88 | G19: 82 | H19: 102 | I19: 46 | J19: 90 | K19: 94 | L19: 78 | M19: 87 | N19: 113 | O19: 101 | P19: 103 | Q19: 101 | R19: 94 | S19: 122 | T19: =SUM(E19:S19) -> 1409
D20: PR | E20: 119 | F20: 92 | G20: 77 | H20: 111 | I20: 58 | J20: 113 | K20: 105 | L20: 93 | M20: 86 | N20: 117 | O20: 120 | P20: 115 | Q20: 124 | R20: 91 | S20: 113 | T20: =SUM(E20:S20) -> 1534
D21: JML | E21: =SUM(E19:E20) -> 227 | F21: =SUM(F19:F20) -> 180 | G21: =SUM(G19:G20) -> 159 | H21: =SUM(H19:H20) -> 213 | I21: =SUM(I19:I20) -> 104 | J21: =SUM(J19:J20) -> 203 | K21: =SUM(K19:K20) -> 199 | L21: =SUM(L19:L20) -> 171 | ... S21: =SUM(S19:S20) -> 235 | T21: =SUM(E21:S21) -> 2943
B22: 2. | C22: Jumlah pengguna hak pilih dalam Daftar Pemilih Tambahan (DPTb) | D22: LK | E22: 1 | F22: 2 | G22: 0 | H22: 0 | I22: 0 | J22: 1 | K22: 0 | L22: 1 | M22: 0 | N22: 0 | O22: 0 | P22: 0 | Q22: 0 | R22: 1 | S22: 0 | T22: =SUM(E22:S22) -> 6
D23: PR | E23: 1 | F23: 3 | G23: 0 | H23: 1 | I23: 0 | J23: 1 | K23: 0 | L23: 0 | M23: 0 | N23: 0 | O23: 0 | P23: 0 | Q23: 0 | R23: 1 | S23: 0 | T23: =SUM(E23:S23) -> 7
D24: JML | E24: =SUM(E22:E23) -> 2 | F24: =SUM(F22:F23) -> 5 | G24: =SUM(G22:G23) -> 0 | H24: =SUM(H22:H23) -> 1 | I24: =SUM(I22:I23) -> 0 | J24: =SUM(J22:J23) -> 2 | K24: =SUM(K22:K23) -> 0 | L24: =SUM(L22:L23) -> 1 | ... S24: =SUM(S22:S23) -> 0 | T24: =SUM(E24:S24) -> 13
B25: 3. | C25: Jumlah pengguna hak pilih dalam Daftar Pemilih Khusus (DPK) | D25: LK | E25: 1 | F25: 0 | G25: 1 | H25: 0 | I25: 0 | J25: 2 | K25: 0 | L25: 1 | M25: 1 | N25: 0 | O25: 1 | P25: 0 | Q25: 8 | R25: 1 | S25: 2 | T25: =SUM(E25:S25) -> 18
D26: PR | E26: 0 | F26: 1 | G26: 0 | H26: 0 | I26: 0 | J26: 2 | K26: 0 | L26: 2 | M26: 0 | N26: 0 | O26: 3 | P26: 0 | Q26: 8 | R26: 2 | S26: 5 | T26: =SUM(E26:S26) -> 23
D27: JML | E27: =SUM(E25:E26) -> 1 | F27: =SUM(F25:F26) -> 1 | G27: =SUM(G25:G26) -> 1 | H27: =SUM(H25:H26) -> 0 | I27: =SUM(I25:I26) -> 0 | J27: =SUM(J25:J26) -> 4 | K27: =SUM(K25:K26) -> 0 | L27: =SUM(L25:L26) -> 3 | ... S27: =SUM(S25:S26) -> 7 | T27: =SUM(E27:S27) -> 41
B28: 4. | C28: Jumlah Pengguna Hak Pilih (B.1+B.2+B.3) | D28: LK | E28: =SUM(E19,E22,E25) -> 110 | F28: =SUM(F19,F22,F25) -> 90 | G28: =SUM(G19,G22,G25) -> 83 | H28: =SUM(H19,H22,H25) -> 102 | I28: =SUM(I19,I22,I25) -> 46 | J28: =SUM(J19,J22,J25) -> 93 | K28: =SUM(K19,K22,K25) -> 94 | L28: =SUM(L19,L22,L25) -> 80 | ... S28: =SUM(S19,S22,S25) -> 124 | T28: =SUM(E28:S28) -> 1433
D29: PR | E29: =SUM(E20,E23,E26) -> 120 | F29: =SUM(F20,F23,F26) -> 96 | G29: =SUM(G20,G23,G26) -> 77 | H29: =SUM(H20,H23,H26) -> 112 | I29: =SUM(I20,I23,I26) -> 58 | J29: =SUM(J20,J23,J26) -> 116 | K29: =SUM(K20,K23,K26) -> 105 | L29: =SUM(L20,L23,L26) -> 95 | ... S29: =SUM(S20,S23,S26) -> 118 | T29: =SUM(E29:S29) -> 1564
D30: JML | E30: =SUM(E28:E29) -> 230 | F30: =SUM(F28:F29) -> 186 | G30: =SUM(G28:G29) -> 160 | H30: =SUM(H28:H29) -> 214 | I30: =SUM(I28:I29) -> 104 | J30: =SUM(J28:J29) -> 209 | K30: =SUM(K28:K29) -> 199 | L30: =SUM(L28:L29) -> 175 | ... S30: =SUM(S28:S29) -> 242 | T30: =SUM(E30:S30) -> 2997
A32: II | B32: DATA PENGGUNAAN SURAT SUARA
A33: 1 | B33: Jumlah surat suara yang diterima, termasuk surat suara cadangan 2,5% dari DPT | E33: 277 | F33: 267 | G33: 229 | H33: 270 | I33: 140 | J33: 241 | K33: 245 | L33: 231 | M33: 264 | N33: 293 | O33: 274 | P33: 273 | Q33: 274 | R33: 211 | S33: 279 | T33: =SUM(E33:S33) -> 3768
A34: 2 | B34: Jumlah surat suara yang digunakan | E34: 230 | F34: 186 | G34: 160 | H34: 214 | I34: 104 | J34: 209 | K34: 199 | L34: 175 | M34: 174 | N34: 230 | O34: 225 | P34: 218 | Q34: 241 | R34: 190 | S34: 242 | T34: =SUM(E34:S34) -> 2997
A35: 3 | B35: Jumlah surat suara dikembalikan oleh pemilih (karena rusak atau keliru coblos) | E35: 0 | F35: 0 | G35: 0 | H35: 0 | I35: 0 | J35: 1 | K35: 0 | L35: 0 | M35: 4 | N35: 0 | O35: 0 | P35: 1 | Q35: 0 | R35: 0 | S35: 1 | T35: =SUM(E35:S35) -> 7
A36: 4 | B36: Jumlah surat suara yang tidak digunakan/tidak terpakai, termasuk sisa surat suara cadangan | E36: =E33-(E34+E35) -> 47 | F36: =F33-(F34+F35) -> 81 | G36: =G33-(G34+G35) -> 69 | H36: =H33-(H34+H35) -> 56 | I36: =I33-(I34+I35) -> 36 | J36: =J33-(J34+J35) -> 31 | K36: =K33-(K34+K35) -> 46 | L36: =L33-(L34+L35) -> 56 | ... S36: =S33-(S34+S35) -> 36 | T36: =SUM(E36:S36) -> 764
A38: III | B38: DATA PEMILIH DISABILITAS
B39: Jumlah seluruh Pemilih disabilitas yang menggunakan hak pilih | D39: LK | E39: 0 | F39: 0 | G39: 2 | H39: 1 | I39: 0 | J39: 1 | K39: 0 | L39: 0 | M39: 0 | N39: 0 | O39: 0 | P39: 0 | Q39: 0 | R39: 0 | S39: 0 | T39: =SUM(E39:S39) -> 4
D40: PR | E40: 0 | F40: 0 | G40: 1 | H40: 0 | I40: 0 | J40: 0 | K40: 0 | L40: 0 | M40: 0 | N40: 0 | O40: 0 | P40: 0 | Q40: 0 | R40: 0 | S40: 1 | T40: =SUM(E40:S40) -> 2
D41: JML | E41: =SUM(E39:E40) -> 0 | F41: =SUM(F39:F40) -> 0 | G41: =SUM(G39:G40) -> 3 | H41: =SUM(H39:H40) -> 1 | I41: =SUM(I39:I40) -> 0 | J41: =SUM(J39:J40) -> 1 | K41: =SUM(K39:K40) -> 0 | L41: =SUM(L39:L40) -> 0 | ... S41: =SUM(S39:S40) -> 1 | T41: =SUM(E41:S41) -> 6
A43: IV | B43: DATA RINCIAN PEROLEHAN SUARA PASANGAN CALON BUPATI DAN WAKIL BUPATI
A44: NOMOR DAN NAMA CALON
A45: A.1 | B45: 1. | C45: Partai Kebangkitan Bangsa | E45: 8 | F45: 5 | G45: 1 | H45: 4 | I45: 1 | J45: 1 | K45: 1 | L45: 5 | M45: 3 | N45: 14 | O45: 11 | P45: 7 | Q45: 5 | R45: 7 | S45: 4 | T45: =SUM(E45:S45) -> 77
A46: A.2 | B46: 1 | C46: 1. Dr. Hj. NIHAYATUL WAFIROH, M.A. | E46: 6 | F46: 3 | G46: 2 | H46: 4 | I46: 2 | J46: 7 | K46: 5 | L46: 2 | M46: 4 | N46: 12 | O46: 27 | P46: 15 | Q46: 18 | R46: 27 | S46: 19 | T46: =SUM(E46:S46) -> 153
B47: 2 | C47: 2. H. M. NASIM KHAN | E47: 1 | F47: 3 | G47: 12 | H47: 4 | I47: 1 | J47: 2 | K47: 2 | L47: 1 | M47: 1 | N47: 1 | O47: 3 | P47: 0 | Q47: 5 | R47: 6 | S47: 1 | T47: =SUM(E47:S47) -> 43
B48: 3 | C48: 3. Dr. H. AKIK ZAMAN, M.Pd.I. | E48: 0 | F48: 1 | G48: 0 | H48: 0 | I48: 0 | J48: 0 | K48: 0 | L48: 0 | M48: 0 | N48: 0 | O48: 0 | P48: 1 | Q48: 3 | R48: 0 | S48: 0 | T48: =SUM(E48:S48) -> 5
B49: 4 | C49: 4. AHMAD RIFA'I, S.H. | E49: 0 | F49: 0 | G49: 0 | H49: 0 | I49: 0 | J49: 0 | K49: 4 | L49: 0 | M49: 2 | N49: 0 | O49: 4 | P49: 2 | Q49: 0 | R49: 1 | S49: 0 | T49: =SUM(E49:S49) -> 13
B50: 5 | C50: 5. Drs. H. MAHFUD M.N. | E50: 0 | F50: 2 | G50: 0 | H50: 0 | I50: 0 | J50: 0 | K50: 2 | L50: 0 | M50: 0 | N50: 0 | O50: 0 | P50: 0 | Q50: 0 | R50: 0 | S50: 0 | T50: =SUM(E50:S50) -> 4
B51: 6 | C51: 6. NURHAYATI, S.Pd. | E51: 0 | F51: 0 | G51: 0 | H51: 0 | I51: 0 | J51: 0 | K51: 1 | L51: 0 | M51: 0 | N51: 0 | O51: 0 | P51: 0 | Q51: 0 | R51: 0 | S51: 0 | T51: =SUM(E51:S51) -> 1
...

Sheet GITIK
C2: Kecamatan | D2: ROGOJAMPI
C3: Kabupaten | D3: BANYUWANGI
C4: Provinsi | D4: JAWA TIMUR
C9: Kelurahan | D9: GITIK
A12: I | B12: DATA PEMILIH DAN PENGGUNAAN HAK PILIH | N12: JUMLAH AKHIR
A13: A | B13: DATA PEMILIH | E13: TPS 001 | F13: TPS 002 | G13: TPS 003 | H13: TPS 004 | I13: TPS 005 | J13: TPS 006 | K13: TPS 007 | L13: TPS 008 | M13: TPS 009
B14: Jumlah Pemilih dalam Daftar Pemilih Tetap (DPT) | D14: LK | E14: 125 | F14: 119 | G14: 113 | H14: 136 | I14: 139 | J14: 128 | K14: 139 | L14: 138 | M14: 91 | N14: =SUM(E14:M14) -> 1128
D15: PR | E15: 115 | F15: 118 | G15: 131 | H15: 138 | I15: 149 | J15: 144 | K15: 143 | L15: 140 | M15: 92 | N15: =SUM(E15:M15) -> 1170
D16: JML | E16: =SUM(E14:E15) -> 240 | F16: =SUM(F14:F15) -> 237 | G16: =SUM(G14:G15) -> 244 | H16: =SUM(H14:H15) -> 274 | I16: =SUM(I14:I15) -> 288 | J16: =SUM(J14:J15) -> 272 | K16: =SUM(K14:K15) -> 282 | L16: =SUM(L14:L15) -> 278 | M16: =SUM(M14:M15) -> 183 | N16: =SUM(E16:M16) -> 2298
A18: B | B18: PENGGUNA HAK PILIH
B19: 1. | C19: Jumlah pengguna hak pilih dalam Daftar Pemilih Tetap (DPT) | D19: LK | E19: 104 | F19: 93 | G19: 88 | H19: 109 | I19: 103 | J19: 107 | K19: 103 | L19: 93 | M19: 65 | N19: =SUM(E19:M19) -> 865
D20: PR | E20: 103 | F20: 96 | G20: 109 | H20: 117 | I20: 114 | J20: 119 | K20: 111 | L20: 101 | M20: 74 | N20: =SUM(E20:M20) -> 944
D21: JML | E21: =SUM(E19:E20) -> 207 | F21: =SUM(F19:F20) -> 189 | G21: =SUM(G19:G20) -> 197 | H21: =SUM(H19:H20) -> 226 | I21: =SUM(I19:I20) -> 217 | J21: =SUM(J19:J20) -> 226 | K21: =SUM(K19:K20) -> 214 | L21: =SUM(L19:L20) -> 194 | M21: =SUM(M19:M20) -> 139 | N21: =SUM(E21:M21) -> 1809
B22: 2. | C22: Jumlah pengguna hak pilih dalam Daftar Pemilih Tambahan (DPTb) | D22: LK | E22: 0 | F22: 0 | G22: 1 | H22: 0 | I22: 0 | J22: 1 | K22: 0 | L22: 0 | M22: 0 | N22: =SUM(E22:M22) -> 2
D23: PR | E23: 1 | F23: 0 | G23: 1 | H23: 0 | I23: 0 | J23: 1 | K23: 0 | L23: 2 | M23: 0 | N23: =SUM(E23:M23) -> 5
D24: JML | E24: =SUM(E22:E23) -> 1 | F24: =SUM(F22:F23) -> 0 | G24: =SUM(G22:G23) -> 2 | H24: =SUM(H22:H23) -> 0 | I24: =SUM(I22:I23) -> 0 | J24: =SUM(J22:J23) -> 2 | K24: =SUM(K22:K23) -> 0 | L24: =SUM(L22:L23) -> 2 | M24: =SUM(M22:M23) -> 0 | N24: =SUM(E24:M24) -> 7
B25: 3. | C25: Jumlah pengguna hak pilih dalam Daftar Pemilih Khusus (DPK) | D25: LK | E25: 3 | F25: 3 | G25: 0 | H25: 0 | I25: 1 | J25: 1 | K25: 0 | L25: 2 | M25: 1 | N25: =SUM(E25:M25) -> 11
D26: PR | E26: 0 | F26: 4 | G26: 0 | H26: 0 | I26: 1 | J26: 4 | K26: 0 | L26: 0 | M26: 1 | N26: =SUM(E26:M26) -> 10
D27: JML | E27: =SUM(E25:E26) -> 3 | F27: =SUM(F25:F26) -> 7 | G27: =SUM(G25:G26) -> 0 | H27: =SUM(H25:H26) -> 0 | I27: =SUM(I25:I26) -> 2 | J27: =SUM(J25:J26) -> 5 | K27: =SUM(K25:K26) -> 0 | L27: =SUM(L25:L26) -> 2 | M27: =SUM(M25:M26) -> 2 | N27: =SUM(E27:M27) -> 21
B28: 4. | C28: Jumlah Pengguna Hak Pilih (B.1+B.2+B.3) | D28: LK | E28: =SUM(E19,E22,E25) -> 107 | F28: =SUM(F19,F22,F25) -> 96 | G28: =SUM(G19,G22,G25) -> 89 | H28: =SUM(H19,H22,H25) -> 109 | I28: =SUM(I19,I22,I25) -> 104 | J28: =SUM(J19,J22,J25) -> 109 | K28: =SUM(K19,K22,K25) -> 103 | L28: =SUM(L19,L22,L25) -> 95 | M28: =SUM(M19,M22,M25) -> 66 | N28: =SUM(E28:M28) -> 878
D29: PR | E29: =SUM(E20,E23,E26) -> 104 | F29: =SUM(F20,F23,F26) -> 100 | G29: =SUM(G20,G23,G26) -> 110 | H29: =SUM(H20,H23,H26) -> 117 | I29: =SUM(I20,I23,I26) -> 115 | J29: =SUM(J20,J23,J26) -> 124 | K29: =SUM(K20,K23,K26) -> 111 | L29: =SUM(L20,L23,L26) -> 103 | M29: =SUM(M20,M23,M26) -> 75 | N29: =SUM(E29:M29) -> 959
D30: JML | E30: =SUM(E28:E29) -> 211 | F30: =SUM(F28:F29) -> 196 | G30: =SUM(G28:G29) -> 199 | H30: =SUM(H28:H29) -> 226 | I30: =SUM(I28:I29) -> 219 | J30: =SUM(J28:J29) -> 233 | K30: =SUM(K28:K29) -> 214 | L30: =SUM(L28:L29) -> 198 | M30: =SUM(M28:M29) -> 141 | N30: =SUM(E30:M30) -> 1837
A32: II | B32: DATA PENGGUNAAN SURAT SUARA
A33: 1 | B33: Jumlah surat suara yang diterima, termasuk surat suara cadangan 2,5% dari DPT | E33: 245 | F33: 242 | G33: 249 | H33: 280 | I33: 294 | J33: 278 | K33: 283 | L33: 284 | M33: 187 | N33: =SUM(E33:M33) -> 2342
A34: 2 | B34: Jumlah surat suara yang digunakan | E34: 211 | F34: 196 | G34: 199 | H34: 226 | I34: 219 | J34: 233 | K34: 214 | L34: 198 | M34: 141 | N34: =SUM(E34:M34) -> 1837
A35: 3 | B35: Jumlah surat suara dikembalikan oleh pemilih (karena rusak atau keliru coblos) | E35: 1 | F35: 1 | G35: 3 | H35: 0 | I35: 0 | J35: 0 | K35: 0 | L35: 0 | M35: 0 | N35: =SUM(E35:M35) -> 5
A36: 4 | B36: Jumlah surat suara yang tidak digunakan/tidak terpakai, termasuk sisa surat suara cadangan | E36: =E33-(E34+E35) -> 33 | F36: =F33-(F34+F35) -> 45 | G36: =G33-(G34+G35) -> 47 | H36: =H33-(H34+H35) -> 54 | I36: =I33-(I34+I35) -> 75 | J36: =J33-(J34+J35) -> 45 | K36: =K33-(K34+K35) -> 69 | L36: =L33-(L34+L35) -> 86 | M36: =M33-(M34+M35) -> 46 | N36: =SUM(E36:M36) -> 500
A38: III | B38: DATA PEMILIH DISABILITAS
B39: Jumlah seluruh Pemilih disabilitas yang menggunakan hak pilih | D39: LK | N39: =SUM(E39:M39) -> 0
D40: PR | N40: =SUM(E40:M40) -> 0
D41: JML | E41: =SUM(E39:E40) -> 0 | F41: =SUM(F39:F40) -> 0 | G41: =SUM(G39:G40) -> 0 | H41: =SUM(H39:H40) -> 0 | I41: =SUM(I39:I40) -> 0 | J41: =SUM(J39:J40) -> 0 | K41: =SUM(K39:K40) -> 0 | L41: =SUM(L39:L40) -> 0 | M41: =SUM(M39:M40) -> 0 | N41: =SUM(E41:M41) -> 0
A43: IV | B43: DATA RINCIAN PEROLEHAN SUARA PASANGAN CALON BUPATI DAN WAKIL BUPATI
A44: NOMOR DAN NAMA CALON
A45: A.1 | B45: 1. | C45: Partai Kebangkitan Bangsa | E45: 8 | F45: 11 | G45: 3 | H45: 6 | I45: 8 | J45: 5 | K45: 3 | L45: 4 | M45: 11 | N45: =SUM(E45:M45) -> 59
A46: A.2 | B46: 1 | C46: 1. Dr. Hj. NIHAYATUL WAFIROH, M.A. | E46: 20 | F46: 25 | G46: 6 | H46: 9 | I46: 6 | J46: 16 | K46: 12 | L46: 13 | M46: 11 | N46: =SUM(E46:M46) -> 118
B47: 2 | C47: 2. H. M. NASIM KHAN | E47: 0 | F47: 1 | G47: 0 | H47: 1 | I47: 0 | J47: 2 | K47: 2 | L47: 9 | M47: 4 | N47: =SUM(E47:M47) -> 19
B48: 3 | C48: 3. Dr. H. AKIK ZAMAN, M.Pd.I. | E48: 0 | F48: 1 | G48: 0 | H48: 3 | I48: 1 | J48: 1 | K48: 0 | L48: 0 | M48: 0 | N48: =SUM(E48:M48) -> 6
B49: 4 | C49: 4. AHMAD RIFA'I, S.H. | E49: 0 | F49: 0 | G49: 0 | H49: 0 | I49: 1 | J49: 0 | K49: 1 | L49: 0 | M49: 0 | N49: =SUM(E49:M49) -> 2
B50: 5 | C50: 5. Drs. H. MAHFUD M.N. | E50: 1 | F50: 1 | G50: 2 | H50: 1 | I50: 1 | J50: 0 | K50: 0 | L50: 2 | M50: 1 | N50: =SUM(E50:M50) -> 9
B51: 6 | C51: 6. NURHAYATI, S.Pd. | E51: 0 | F51: 0 | G51: 0 | H51: 0 | I51: 0 | J51: 0 | K51: 0 | L51: 0 | M51: 0 | N51: =SUM(E51:M51) -> 0
...

Sheet GLADAG
C2: Kecamatan | D2: ROGOJAMPI
C3: Kabupaten | D3: BANYUWANGI
C4: Provinsi | D4: JAWA TIMUR
C9: Kelurahan | D9: GLADAG
A12: I | B12: DATA PEMILIH DAN PENGGUNAAN HAK PILIH | W12: JUMLAH AKHIR
A13: A | B13: DATA PEMILIH | E13: TPS 001 | F13: TPS 002 | G13: TPS 003 | H13: TPS 004 | I13: TPS 005 | J13: TPS 006 | K13: TPS 007 | L13: TPS 008 | M13: TPS 009 | N13: TPS 010 | O13: TPS 011 | P13: TPS 012 | Q13: TPS 013 | R13: TPS 014 | S13: TPS 015 | T13: TPS 016 | U13: TPS 017 | V13: TPS 018
B14: Jumlah Pemilih dalam Daftar Pemilih Tetap (DPT) | D14: LK | E14: 96 | F14: 116 | G14: 127 | H14: 102 | I14: 112 | J14: 126 | K14: 127 | L14: 140 | M14: 133 | N14: 124 | O14: 132 | P14: 136 | Q14: 131 | R14: 133 | S14: 140 | T14: 84 | U14: 110 | V14: 69 | W14: =SUM(E14:V14) -> 2138
D15: PR | E15: 123 | F15: 132 | G15: 127 | H15: 130 | I15: 125 | J15: 146 | K15: 131 | L15: 139 | M15: 137 | N15: 131 | O15: 130 | P15: 133 | Q15: 128 | R15: 140 | S15: 136 | T15: 80 | U15: 116 | V15: 74 | W15: =SUM(E15:V15) -> 2258
D16: JML | E16: =SUM(E14:E15) -> 219 | F16: =SUM(F14:F15) -> 248 | G16: =SUM(G14:G15) -> 254 | H16: =SUM(H14:H15) -> 232 | I16: =SUM(I14:I15) -> 237 | J16: =SUM(J14:J15) -> 272 | K16: =SUM(K14:K15) -> 258 | L16: =SUM(L14:L15) -> 279 | ... V16: =SUM(V14:V15) -> 143 | W16: =SUM(E16:V16) -> 4396
A18: B | B18: PENGGUNA HAK PILIH
B19: 1. | C19: Jumlah pengguna hak pilih dalam Daftar Pemilih Tetap (DPT) | D19: LK | E19: 75 | F19: 91 | G19: 90 | H19: 87 | I19: 89 | J19: 93 | K19: 92 | L19: 111 | M19: 102 | N19: 83 | O19: 89 | P19: 94 | Q19: 86 | R19: 103 | S19: 108 | T19: 56 | U19: 88 | V19: 60 | W19: =SUM(E19:V19) -> 1597
D20: PR | E20: 104 | F20: 115 | G20: 107 | H20: 115 | I20: 108 | J20: 127 | K20: 105 | L20: 120 | M20: 111 | N20: 104 | O20: 113 | P20: 114 | Q20: 105 | R20: 119 | S20: 106 | T20: 67 | U20: 100 | V20: 68 | W20: =SUM(E20:V20) -> 1908
D21: JML | E21: =SUM(E19:E20) -> 179 | F21: =SUM(F19:F20) -> 206 | G21: =SUM(G19:G20) -> 197 | H21: =SUM(H19:H20) -> 202 | I21: =SUM(I19:I20) -> 197 | J21: =SUM(J19:J20) -> 220 | K21: =SUM(K19:K20) -> 197 | L21: =SUM(L19:L20) -> 231 | ... V21: =SUM(V19:V20) -> 128 | W21: =SUM(E21:V21) -> 3505
B22: 2. | C22: Jumlah pengguna hak pilih dalam Daftar Pemilih Tambahan (DPTb) | D22: LK | E22: 3 | F22: 0 | G22: 0 | H22: 0 | I22: 0 | J22: 1 | K22: 0 | L22: 0 | M22: 1 | N22: 0 | O22: 0 | P22: 2 | Q22: 0 | R22: 0 | S22: 0 | T22: 0 | U22: 0 | V22: 0 | W22: =SUM(E22:V22) -> 7
D23: PR | E23: 2 | F23: 1 | G23: 0 | H23: 1 | I23: 0 | J23: 2 | K23: 1 | L23: 1 | M23: 0 | N23: 1 | O23: 0 | P23: 1 | Q23: 1 | R23: 0 | S23: 0 | T23: 0 | U23: 2 | V23: 0 | W23: =SUM(E23:V23) -> 13
D24: JML | E24: =SUM(E22:E23) -> 5 | F24: =SUM(F22:F23) -> 1 | G24: =SUM(G22:G23) -> 0 | H24: =SUM(H22:H23) -> 1 | I24: =SUM(I22:I23) -> 0 | J24: =SUM(J22:J23) -> 3 | K24: =SUM(K22:K23) -> 1 | L24: =SUM(L22:L23) -> 1 | ... V24: =SUM(V22:V23) -> 0 | W24: =SUM(E24:V24) -> 20
B25: 3. | C25: Jumlah pengguna hak pilih dalam Daftar Pemilih Khusus (DPK) | D25: LK | E25: 4 | F25: 2 | G25: 0 | H25: 1 | I25: 2 | J25: 2 | K25: 1 | L25: 1 | M25: 0 | N25: 0 | O25: 0 | P25: 2 | Q25: 1 | R25: 0 | S25: 0 | T25: 1 | U25: 2 | V25: 1 | W25: =SUM(E25:V25) -> 20
D26: PR | E26: 0 | F26: 0 | G26: 1 | H26: 1 | I26: 0 | J26: 0 | K26: 2 | L26: 2 | M26: 0 | N26: 3 | O26: 0 | P26: 1 | Q26: 2 | R26: 0 | S26: 0 | T26: 0 | U26: 2 | V26: 1 | W26: =SUM(E26:V26) -> 15
D27: JML | E27: =SUM(E25:E26) -> 4 | F27: =SUM(F25:F26) -> 2 | G27: =SUM(G25:G26) -> 1 | H27: =SUM(H25:H26) -> 2 | I27: =SUM(I25:I26) -> 2 | J27: =SUM(J25:J26) -> 2 | K27: =SUM(K25:K26) -> 3 | L27: =SUM(L25:L26) -> 3 | ... V27: =SUM(V25:V26) -> 2 | W27: =SUM(E27:V27) -> 35
B28: 4. | C28: Jumlah Pengguna Hak Pilih (B.1+B.2+B.3) | D28: LK | E28: =SUM(E19,E22,E25) -> 82 | F28: =SUM(F19,F22,F25) -> 93 | G28: =SUM(G19,G22,G25) -> 90 | H28: =SUM(H19,H22,H25) -> 88 | I28: =SUM(I19,I22,I25) -> 91 | J28: =SUM(J19,J22,J25) -> 96 | K28: =SUM(K19,K22,K25) -> 93 | L28: =SUM(L19,L22,L25) -> 112 | ... V28: =SUM(V19,V22,V25) -> 61 | W28: =SUM(E28:V28) -> 1624
D29: PR | E29: =SUM(E20,E23,E26) -> 106 | F29: =SUM(F20,F23,F26) -> 116 | G29: =SUM(G20,G23,G26) -> 108 | H29: =SUM(H20,H23,H26) -> 117 | I29: =SUM(I20,I23,I26) -> 108 | J29: =SUM(J20,J23,J26) -> 129 | K29: =SUM(K20,K23,K26) -> 108 | L29: =SUM(L20,L23,L26) -> 123 | ... V29: =SUM(V20,V23,V26) -> 69 | W29: =SUM(E29:V29) -> 1936
D30: JML | E30: =SUM(E28:E29) -> 188 | F30: =SUM(F28:F29) -> 209 | G30: =SUM(G28:G29) -> 198 | H30: =SUM(H28:H29) -> 205 | I30: =SUM(I28:I29) -> 199 | J30: =SUM(J28:J29) -> 225 | K30: =SUM(K28:K29) -> 201 | L30: =SUM(L28:L29) -> 235 | ... V30: =SUM(V28:V29) -> 130 | W30: =SUM(E30:V30) -> 3560
A32: II | B32: DATA PENGGUNAAN SURAT SUARA
A33: 1 | B33: Jumlah surat suara yang diterima, termasuk surat suara cadangan 2,5% dari DPT | E33: 224 | F33: 253 | G33: 260 | H33: 237 | I33: 242 | J33: 278 | K33: 264 | L33: 285 | M33: 276 | N33: 261 | O33: 268 | P33: 275 | Q33: 265 | R33: 279 | S33: 282 | T33: 179 | U33: 231 | V33: 146 | W33: =SUM(E33:V33) -> 4505
A34: 2 | B34: Jumlah surat suara yang digunakan | E34: 188 | F34: 209 | G34: 198 | H34: 205 | I34: 199 | J34: 225 | K34: 201 | L34: 235 | M34: 214 | N34: 191 | O34: 202 | P34: 214 | Q34: 195 | R34: 222 | S34: 214 | T34: 124 | U34: 194 | V34: 130 | W34: =SUM(E34:V34) -> 3560
A35: 3 | B35: Jumlah surat suara dikembalikan oleh pemilih (karena rusak atau keliru coblos) | E35: 0 | F35: 0 | G35: 1 | H35: 2 | I35: 2 | J35: 0 | K35: 1 | L35: 0 | M35: 0 | N35: 0 | O35: 0 | P35: 0 | Q35: 2 | R35: 0 | S35: 1 | T35: 0 | U35: 0 | V35: 1 | W35: =SUM(E35:V35) -> 10
A36: 4 | B36: Jumlah surat suara yang tidak digunakan/tidak terpakai, termasuk sisa surat suara cadangan | E36: =E33-(E34+E35) -> 36 | F36: =F33-(F34+F35) -> 44 | G36: =G33-(G34+G35) -> 61 | H36: =H33-(H34+H35) -> 30 | I36: =I33-(I34+I35) -> 41 | J36: =J33-(J34+J35) -> 53 | K36: =K33-(K34+K35) -> 62 | L36: =L33-(L34+L35) -> 50 | ... V36: =V33-(V34+V35) -> 15 | W36: =SUM(E36:V36) -> 935
A38: III | B38: DATA PEMILIH DISABILITAS
B39: Jumlah seluruh Pemilih disabilitas yang menggunakan hak pilih | D39: LK | E39: 0 | F39: 1 | G39: 0 | H39: 0 | I39: 0 | J39: 0 | K39: 0 | L39: 3 | M39: 0 | N39: 3 | O39: 0 | P39: 0 | Q39: 0 | R39: 0 | S39: 0 | T39: 0 | U39: 0 | V39: 0 | W39: =SUM(E39:V39) -> 7
D40: PR | E40: 0 | F40: 1 | G40: 0 | H40: 0 | I40: 0 | J40: 5 | K40: 1 | L40: 1 | M40: 0 | N40: 4 | O40: 3 | P40: 0 | Q40: 0 | R40: 0 | S40: 0 | T40: 0 | U40: 0 | V40: 0 | W40: =SUM(E40:V40) -> 15
D41: JML | E41: =SUM(E39:E40) -> 0 | F41: =SUM(F39:F40) -> 2 | G41: =SUM(G39:G40) -> 0 | H41: =SUM(H39:H40) -> 0 | I41: =SUM(I39:I40) -> 0 | J41: =SUM(J39:J40) -> 5 | K41: =SUM(K39:K40) -> 1 | L41: =SUM(L39:L40) -> 4 | ... V41: =SUM(V39:V40) -> 0 | W41: =SUM(E41:V41) -> 22
A43: IV | B43: DATA RINCIAN PEROLEHAN SUARA PASANGAN CALON BUPATI DAN WAKIL BUPATI
A44: NOMOR DAN NAMA CALON
A45: A.1 | B45: 1. | C45: Partai Kebangkitan Bangsa | E45: 5 | F45: 1 | G45: 1 | H45: 0 | I45: 4 | J45: 4 | K45: 4 | L45: 4 | M45: 6 | N45: 3 | O45: 5 | P45: 3 | Q45: 3 | R45: 1 | S45: 7 | T45: 3 | U45: 3 | V45: 3 | W45: =SUM(E45:V45) -> 60
A46: A.2 | B46: 1 | C46: 1. Dr. Hj. NIHAYATUL WAFIROH, M.A. | E46: 19 | F46: 5 | G46: 4 | H46: 18 | I46: 37 | J46: 17 | K46: 15 | L46: 20 | M46: 35 | N46: 15 | O46: 16 | P46: 15 | Q46: 6 | R46: 5 | S46: 9 | T46: 10 | U46: 0 | V46: 0 | W46: =SUM(E46:V46) -> 246
B47: 2 | C47: 2. H. M. NASIM KHAN | E47: 1 | F47: 2 | G47: 0 | H47: 0 | I47: 0 | J47: 1 | K47: 1 | L47: 1 | M47: 0 | N47: 3 | O47: 0 | P47: 2 | Q47: 0 | R47: 0 | S47: 1 | T47: 0 | U47: 0 | V47: 1 | W47: =SUM(E47:V47) -> 13
B48: 3 | C48: 3. Dr. H. AKIK ZAMAN, M.Pd.I. | E48: 0 | F48: 0 | G48: 0 | H48: 2 | I48: 1 | J48: 1 | K48: 1 | L48: 0 | M48: 3 | N48: 3 | O48: 2 | P48: 0 | Q48: 0 | R48: 0 | S48: 1 | T48: 0 | U48: 3 | V48: 0 | W48: =SUM(E48:V48) -> 17
B49: 4 | C49: 4. AHMAD RIFA'I, S.H. | E49: 0 | F49: 1 | G49: 0 | H49: 0 | I49: 0 | J49: 0 | K49: 0 | L49: 0 | M49: 1 | N49: 0 | O49: 2 | P49: 0 | Q49: 0 | R49: 0 | S49: 0 | T49: 0 | U49: 0 | V49: 0 | W49: =SUM(E49:V49) -> 4
B50: 5 | C50: 5. Drs. H. MAHFUD M.N. | E50: 0 | F50: 0 | G50: 0 | H50: 0 | I50: 0 | J50: 2 | K50: 0 | L50: 0 | M50: 0 | N50: 1 | O50: 1 | P50: 0 | Q50: 0 | R50: 0 | S50: 0 | T50: 0 | U50: 0 | V50: 0 | W50: =SUM(E50:V50) -> 4
B51: 6 | C51: 6. NURHAYATI, S.Pd. | E51: 0 | F51: 0 | G51: 1 | H51: 1 | I51: 0 | J51: 0 | K51: 0 | L51: 1 | M51: 1 | N51: 0 | O51: 0 | P51: 0 | Q51: 0 | R51: 0 | S51: 0 | T51: 0 | U51: 0 | V51: 0 | W51: =SUM(E51:V51) -> 4
...

Sheet KARANGBENDO
C2: Kecamatan | D2: ROGOJAMPI
C3: Kabupaten | D3: BANYUWANGI
C4: Provinsi | D4: JAWA TIMUR
C9: Kelurahan | D9: KARANGBENDO
A12: I | B12: DATA PEMILIH DAN PENGGUNAAN HAK PILIH | Z12: JUMLAH AKHIR
A13: A | B13: DATA PEMILIH | E13: TPS 001 | F13: TPS 002 | G13: TPS 003 | H13: TPS 004 | I13: TPS 005 | J13: TPS 006 | K13: TPS 007 | L13: TPS 008 | M13: TPS 009 | N13: TPS 010 | O13: TPS 011 | P13: TPS 012 | Q13: TPS 013 | R13: TPS 014 | S13: TPS 015 | T13: TPS 016 | U13: TPS 017 | V13: TPS 018 | W13: TPS 019 | X13: TPS 020 | Y13: TPS 021
B14: Jumlah Pemilih dalam Daftar Pemilih Tetap (DPT) | D14: LK | E14: 127 | F14: 132 | G14: 138 | H14: 128 | I14: 130 | J14: 122 | K14: 140 | L14: 124 | M14: 135 | N14: 118 | O14: 144 | P14: 109 | Q14: 145 | R14: 127 | S14: 135 | T14: 138 | U14: 140 | V14: 138 | W14: 135 | X14: 132 | Y14: 115 | Z14: =SUM(E14:Y14) -> 2752
D15: PR | E15: 142 | F15: 136 | G15: 150 | H15: 149 | I15: 140 | J15: 117 | K15: 150 | L15: 129 | M15: 152 | N15: 125 | O15: 143 | P15: 118 | Q15: 140 | R15: 121 | S15: 135 | T15: 145 | U15: 147 | V15: 137 | W15: 129 | X15: 149 | Y15: 101 | Z15: =SUM(E15:Y15) -> 2855
D16: JML | E16: =SUM(E14:E15) -> 269 | F16: =SUM(F14:F15) -> 268 | G16: =SUM(G14:G15) -> 288 | H16: =SUM(H14:H15) -> 277 | I16: =SUM(I14:I15) -> 270 | J16: =SUM(J14:J15) -> 239 | K16: =SUM(K14:K15) -> 290 | L16: =SUM(L14:L15) -> 253 | ... Y16: =SUM(Y14:Y15) -> 216 | Z16: =SUM(E16:Y16) -> 5607
A18: B | B18: PENGGUNA HAK PILIH
B19: 1. | C19: Jumlah pengguna hak pilih dalam Daftar Pemilih Tetap (DPT) | D19: LK | E19: 103 | F19: 98 | G19: 122 | H19: 105 | I19: 96 | J19: 101 | K19: 118 | L19: 101 | M19: 105 | N19: 96 | O19: 119 | P19: 85 | Q19: 107 | R19: 102 | S19: 101 | T19: 111 | U19: 108 | V19: 103 | W19: 102 | X19: 109 | Y19: 91 | Z19: =SUM(E19:Y19) -> 2183
D20: PR | E20: 111 | F20: 108 | G20: 104 | H20: 119 | I20: 121 | J20: 87 | K20: 133 | L20: 110 | M20: 123 | N20: 106 | O20: 117 | P20: 98 | Q20: 116 | R20: 106 | S20: 114 | T20: 120 | U20: 112 | V20: 104 | W20: 92 | X20: 128 | Y20: 85 | Z20: =SUM(E20:Y20) -> 2314
D21: JML | E21: =SUM(E19:E20) -> 214 | F21: =SUM(F19:F20) -> 206 | G21: =SUM(G19:G20) -> 226 | H21: =SUM(H19:H20) -> 224 | I21: =SUM(I19:I20) -> 217 | J21: =SUM(J19:J20) -> 188 | K21: =SUM(K19:K20) -> 251 | L21: =SUM(L19:L20) -> 211 | ... Y21: =SUM(Y19:Y20) -> 176 | Z21: =SUM(E21:Y21) -> 4497
B22: 2. | C22: Jumlah pengguna hak pilih dalam Daftar Pemilih Tambahan (DPTb) | D22: LK | E22: 0 | F22: 0 | G22: 0 | H22: 0 | I22: 0 | J22: 0 | K22: 0 | L22: 0 | M22: 0 | N22: 0 | O22: 0 | P22: 1 | Q22: 1 | R22: 1 | S22: 1 | T22: 0 | U22: 0 | V22: 0 | W22: 1 | X22: 0 | Y22: 1 | Z22: =SUM(E22:Y22) -> 6
D23: PR | E23: 0 | F23: 0 | G23: 0 | H23: 1 | I23: 0 | J23: 0 | K23: 0 | L23: 0 | M23: 0 | N23: 0 | O23: 0 | P23: 0 | Q23: 1 | R23: 0 | S23: 2 | T23: 0 | U23: 0 | V23: 0 | W23: 1 | X23: 0 | Y23: 0 | Z23: =SUM(E23:Y23) -> 5
D24: JML | E24: =SUM(E22:E23) -> 0 | F24: =SUM(F22:F23) -> 0 | G24: =SUM(G22:G23) -> 0 | H24: =SUM(H22:H23) -> 1 | I24: =SUM(I22:I23) -> 0 | J24: =SUM(J22:J23) -> 0 | K24: =SUM(K22:K23) -> 0 | L24: =SUM(L22:L23) -> 0 | ... Y24: =SUM(Y22:Y23) -> 1 | Z24: =SUM(E24:Y24) -> 11
B25: 3. | C25: Jumlah pengguna hak pilih dalam Daftar Pemilih Khusus (DPK) | D25: LK | E25: 1 | F25: 0 | G25: 0 | H25: 0 | I25: 1 | J25: 2 | K25: 2 | L25: 0 | M25: 1 | N25: 3 | O25: 1 | P25: 2 | Q25: 0 | R25: 1 | S25: 4 | T25: 4 | U25: 0 | V25: 1 | W25: 1 | X25: 1 | Y25: 2 | Z25: =SUM(E25:Y25) -> 27
D26: PR | E26: 1 | F26: 1 | G26: 1 | H26: 0 | I26: 2 | J26: 1 | K26: 4 | L26: 0 | M26: 4 | N26: 4 | O26: 3 | P26: 4 | Q26: 0 | R26: 3 | S26: 7 | T26: 6 | U26: 3 | V26: 0 | W26: 1 | X26: 1 | Y26: 0 | Z26: =SUM(E26:Y26) -> 46
D27: JML | E27: =SUM(E25:E26) -> 2 | F27: =SUM(F25:F26) -> 1 | G27: =SUM(G25:G26) -> 1 | H27: =SUM(H25:H26) -> 0 | I27: =SUM(I25:I26) -> 3 | J27: =SUM(J25:J26) -> 3 | K27: =SUM(K25:K26) -> 6 | L27: =SUM(L25:L26) -> 0 | ... Y27: =SUM(Y25:Y26) -> 2 | Z27: =SUM(E27:Y27) -> 73
B28: 4. | C28: Jumlah Pengguna Hak Pilih (B.1+B.2+B.3) | D28: LK | E28: =SUM(E19,E22,E25) -> 104 | F28: =SUM(F19,F22,F25) -> 98 | G28: =SUM(G19,G22,G25) -> 122 | H28: =SUM(H19,H22,H25) -> 105 | I28: =SUM(I19,I22,I25) -> 97 | J28: =SUM(J19,J22,J25) -> 103 | K28: =SUM(K19,K22,K25) -> 120 | L28: =SUM(L19,L22,L25) -> 101 | ... Y28: =SUM(Y19,Y22,Y25) -> 94 | Z28: =SUM(E28:Y28) -> 2216
D29: PR | E29: =SUM(E20,E23,E26) -> 112 | F29: =SUM(F20,F23,F26) -> 109 | G29: =SUM(G20,G23,G26) -> 105 | H29: =SUM(H20,H23,H26) -> 120 | I29: =SUM(I20,I23,I26) -> 123 | J29: =SUM(J20,J23,J26) -> 88 | K29: =SUM(K20,K23,K26) -> 137 | L29: =SUM(L20,L23,L26) -> 110 | ... Y29: =SUM(Y20,Y23,Y26) -> 85 | Z29: =SUM(E29:Y29) -> 2365
D30: JML | E30: =SUM(E28:E29) -> 216 | F30: =SUM(F28:F29) -> 207 | G30: =SUM(G28:G29) -> 227 | H30: =SUM(H28:H29) -> 225 | I30: =SUM(I28:I29) -> 220 | J30: =SUM(J28:J29) -> 191 | K30: =SUM(K28:K29) -> 257 | L30: =SUM(L28:L29) -> 211 | ... Y30: =SUM(Y28:Y29) -> 179 | Z30: =SUM(E30:Y30) -> 4581
A32: II | B32: DATA PENGGUNAAN SURAT SUARA
A33: 1 | B33: Jumlah surat suara yang diterima, termasuk surat suara cadangan 2,5% dari DPT | E33: 275 | F33: 274 | G33: 294 | H33: 283 | I33: 276 | J33: 244 | K33: 296 | L33: 259 | M33: 293 | N33: 248 | O33: 293 | P33: 232 | Q33: 291 | R33: 253 | S33: 276 | T33: 289 | U33: 293 | V33: 281 | W33: 270 | X33: 286 | Y33: 221 | Z33: =SUM(E33:Y33) -> 5727
A34: 2 | B34: Jumlah surat suara yang digunakan | E34: 216 | F34: 207 | G34: 227 | H34: 225 | I34: 220 | J34: 191 | K34: 257 | L34: 211 | M34: 233 | N34: 209 | O34: 240 | P34: 190 | Q34: 225 | R34: 213 | S34: 229 | T34: 241 | U34: 223 | V34: 208 | W34: 198 | X34: 239 | Y34: 179 | Z34: =SUM(E34:Y34) -> 4581
A35: 3 | B35: Jumlah surat suara dikembalikan oleh pemilih (karena rusak atau keliru coblos) | E35: 2 | F35: 0 | G35: 0 | H35: 0 | I35: 0 | J35: 0 | K35: 0 | L35: 0 | M35: 2 | N35: 1 | O35: 0 | P35: 0 | Q35: 1 | R35: 0 | S35: 0 | T35: 0 | U35: 0 | V35: 11 | W35: 0 | X35: 0 | Y35: 0 | Z35: =SUM(E35:Y35) -> 17
A36: 4 | B36: Jumlah surat suara yang tidak digunakan/tidak terpakai, termasuk sisa surat suara cadangan | E36: =E33-(E34+E35) -> 57 | F36: =F33-(F34+F35) -> 67 | G36: =G33-(G34+G35) -> 67 | H36: =H33-(H34+H35) -> 58 | I36: =I33-(I34+I35) -> 56 | J36: =J33-(J34+J35) -> 53 | K36: =K33-(K34+K35) -> 39 | L36: =L33-(L34+L35) -> 48 | ... Y36: =Y33-(Y34+Y35) -> 42 | Z36: =SUM(E36:Y36) -> 1129
A38: III | B38: DATA PEMILIH DISABILITAS
B39: Jumlah seluruh Pemilih disabilitas yang menggunakan hak pilih | D39: LK | E39: 0 | F39: 0 | G39: 0 | H39: 0 | I39: 0 | J39: 0 | K39: 0 | L39: 0 | M39: 0 | N39: 0 | O39: 0 | P39: 1 | Q39: 0 | R39: 1 | S39: 0 | T39: 0 | U39: 1 | V39: 0 | W39: 1 | X39: 0 | Y39: 0 | Z39: =SUM(E39:Y39) -> 4
D40: PR | E40: 0 | F40: 0 | G40: 0 | H40: 0 | I40: 0 | J40: 0 | K40: 0 | L40: 0 | M40: 0 | N40: 0 | O40: 0 | P40: 2 | Q40: 0 | R40: 2 | S40: 0 | T40: 0 | U40: 0 | V40: 0 | W40: 0 | X40: 0 | Y40: 0 | Z40: =SUM(E40:Y40) -> 4
D41: JML | E41: =SUM(E39:E40) -> 0 | F41: =SUM(F39:F40) -> 0 | G41: =SUM(G39:G40) -> 0 | H41: =SUM(H39:H40) -> 0 | I41: =SUM(I39:I40) -> 0 | J41: =SUM(J39:J40) -> 0 | K41: =SUM(K39:K40) -> 0 | L41: =SUM(L39:L40) -> 0 | ... Y41: =SUM(Y39:Y40) -> 0 | Z41: =SUM(E41:Y41) -> 8
A43: IV | B43: DATA RINCIAN PEROLEHAN SUARA PASANGAN CALON BUPATI DAN WAKIL BUPATI
A44: NOMOR DAN NAMA CALON
A45: A.1 | B45: 1. | C45: Partai Kebangkitan Bangsa | E45: 3 | F45: 3 | G45: 5 | H45: 6 | I45: 7 | J45: 13 | K45: 1 | L45: 0 | M45: 4 | N45: 3 | O45: 1 | P45: 3 | Q45: 4 | R45: 3 | S45: 1 | T45: 4 | U45: 8 | V45: 3 | W45: 1 | X45: 3 | Y45: 3 | Z45: =SUM(E45:Y45) -> 79
A46: A.2 | B46: 1 | C46: 1. Dr. Hj. NIHAYATUL WAFIROH, M.A. | E46: 15 | F46: 31 | G46: 28 | H46: 10 | I46: 18 | J46: 14 | K46: 0 | L46: 10 | M46: 19 | N46: 15 | O46: 14 | P46: 11 | Q46: 9 | R46: 4 | S46: 17 | T46: 1 | U46: 11 | V46: 4 | W46: 6 | X46: 8 | Y46: 14 | Z46: =SUM(E46:Y46) -> 259
B47: 2 | C47: 2. H. M. NASIM KHAN | E47: 2 | F47: 0 | G47: 1 | H47: 2 | I47: 4 | J47: 1 | K47: 1 | L47: 43 | M47: 4 | N47: 1 | O47: 0 | P47: 2 | Q47: 0 | R47: 2 | S47: 3 | T47: 1 | U47: 0 | V47: 1 | W47: 0 | X47: 1 | Y47: 2 | Z47: =SUM(E47:Y47) -> 71
B48: 3 | C48: 3. Dr. H. AKIK ZAMAN, M.Pd.I. | E48: 1 | F48: 0 | G48: 0 | H48: 0 | I48: 2 | J48: 0 | K48: 1 | L48: 0 | M48: 0 | N48: 2 | O48: 3 | P48: 2 | Q48: 0 | R48: 1 | S48: 0 | T48: 1 | U48: 1 | V48: 0 | W48: 1 | X48: 1 | Y48: 0 | Z48: =SUM(E48:Y48) -> 16
B49: 4 | C49: 4. AHMAD RIFA'I, S.H. | E49: 0 | F49: 0 | G49: 1 | H49: 1 | I49: 1 | J49: 0 | K49: 0 | L49: 1 | M49: 0 | N49: 0 | O49: 0 | P49: 0 | Q49: 1 | R49: 0 | S49: 1 | T49: 0 | U49: 1 | V49: 2 | W49: 0 | X49: 0 | Y49: 1 | Z49: =SUM(E49:Y49) -> 10
B50: 5 | C50: 5. Drs. H. MAHFUD M.N. | E50: 0 | F50: 0 | G50: 0 | H50: 0 | I50: 0 | J50: 0 | K50: 0 | L50: 0 | M50: 0 | N50: 1 | O50: 0 | P50: 1 | Q50: 3 | R50: 0 | S50: 0 | T50: 0 | U50: 0 | V50: 1 | W50: 0 | X50: 0 | Y50: 1 | Z50: =SUM(E50:Y50) -> 7
B51: 6 | C51: 6. NURHAYATI, S.Pd. | E51: 1 | F51: 0 | G51: 0 | H51: 0 | I51: 0 | J51: 0 | K51: 0 | L51: 0 | M51: 1 | N51: 0 | O51: 0 | P51: 0 | Q51: 0 | R51: 0 | S51: 0 | T51: 0 | U51: 0 | V51: 0 | W51: 0 | X51: 0 | Y51: 0 | Z51: =SUM(E51:Y51) -> 2
...

Sheet KEDALEMAN
C2: Kecamatan | D2: ROGOJAMPI
C3: Kabupaten | D3: BANYUWANGI
C4: Provinsi | D4: JAWA TIMUR
C9: Kelurahan | D9: KEDALEMAN
A12: I | B12: DATA PEMILIH DAN PENGGUNAAN HAK PILIH | S12: JUMLAH AKHIR
A13: A | B13: DATA PEMILIH | E13: TPS 001 | F13: TPS 002 | G13: TPS 003 | H13: TPS 004 | I13: TPS 005 | J13: TPS 006 | K13: TPS 007 | L13: TPS 008 | M13: TPS 009 | N13: TPS 010 | O13: TPS 011 | P13: TPS 012 | Q13: TPS 013 | R13: TPS 014
B14: Jumlah Pemilih dalam Daftar Pemilih Tetap (DPT) | D14: LK | E14: 130 | F14: 111 | G14: 108 | H14: 125 | I14: 145 | J14: 140 | K14: 136 | L14: 138 | M14: 131 | N14: 127 | O14: 145 | P14: 136 | Q14: 130 | R14: 144 | S14: =SUM(E14:R14) -> 1846
D15: PR | E15: 123 | F15: 102 | G15: 130 | H15: 130 | I15: 143 | J15: 139 | K15: 143 | L15: 148 | M15: 114 | N15: 123 | O15: 144 | P15: 129 | Q15: 132 | R15: 127 | S15: =SUM(E15:R15) -> 1827
D16: JML | E16: =SUM(E14:E15) -> 253 | F16: =SUM(F14:F15) -> 213 | G16: =SUM(G14:G15) -> 238 | H16: =SUM(H14:H15) -> 255 | I16: =SUM(I14:I15) -> 288 | J16: =SUM(J14:J15) -> 279 | K16: =SUM(K14:K15) -> 279 | L16: =SUM(L14:L15) -> 286 | ... R16: =SUM(R14:R15) -> 271 | S16: =SUM(E16:R16) -> 3673
A18: B | B18: PENGGUNA HAK PILIH
B19: 1. | C19: Jumlah pengguna hak pilih dalam Daftar Pemilih Tetap (DPT) | D19: LK | E19: 106 | F19: 77 | G19: 91 | H19: 95 | I19: 117 | J19: 114 | K19: 102 | L19: 109 | M19: 101 | N19: 104 | O19: 119 | P19: 122 | Q19: 112 | R19: 122 | S19: =SUM(E19:R19) -> 1491
D20: PR | E20: 107 | F20: 69 | G20: 103 | H20: 110 | I20: 93 | J20: 117 | K20: 120 | L20: 120 | M20: 94 | N20: 106 | O20: 117 | P20: 116 | Q20: 119 | R20: 111 | S20: =SUM(E20:R20) -> 1502
D21: JML | E21: =SUM(E19:E20) -> 213 | F21: =SUM(F19:F20) -> 146 | G21: =SUM(G19:G20) -> 194 | H21: =SUM(H19:H20) -> 205 | I21: =SUM(I19:I20) -> 210 | J21: =SUM(J19:J20) -> 231 | K21: =SUM(K19:K20) -> 222 | L21: =SUM(L19:L20) -> 229 | ... R21: =SUM(R19:R20) -> 233 | S21: =SUM(E21:R21) -> 2993
B22: 2. | C22: Jumlah pengguna hak pilih dalam Daftar Pemilih Tambahan (DPTb) | D22: LK | E22: 2 | F22: 0 | G22: 0 | H22: 0 | I22: 2 | J22: 0 | K22: 0 | L22: 1 | M22: 0 | N22: 0 | O22: 0 | P22: 1 | Q22: 1 | R22: 0 | S22: =SUM(E22:R22) -> 7
D23: PR | E23: 3 | F23: 0 | G23: 0 | H23: 0 | I23: 1 | J23: 0 | K23: 1 | L23: 0 | M23: 0 | N23: 1 | O23: 2 | P23: 2 | Q23: 0 | R23: 0 | S23: =SUM(E23:R23) -> 10
D24: JML | E24: =SUM(E22:E23) -> 5 | F24: =SUM(F22:F23) -> 0 | G24: =SUM(G22:G23) -> 0 | H24: =SUM(H22:H23) -> 0 | I24: =SUM(I22:I23) -> 3 | J24: =SUM(J22:J23) -> 0 | K24: =SUM(K22:K23) -> 1 | L24: =SUM(L22:L23) -> 1 | ... R24: =SUM(R22:R23) -> 0 | S24: =SUM(E24:R24) -> 17
B25: 3. | C25: Jumlah pengguna hak pilih dalam Daftar Pemilih Khusus (DPK) | D25: LK | E25: 3 | F25: 0 | G25: 1 | H25: 0 | I25: 0 | J25: 1 | K25: 0 | L25: 0 | M25: 1 | N25: 0 | O25: 1 | P25: 2 | Q25: 0 | R25: 0 | S25: =SUM(E25:R25) -> 9
D26: PR | E26: 1 | F26: 1 | G26: 4 | H26: 3 | I26: 0 | J26: 2 | K26: 0 | L26: 4 | M26: 2 | N26: 1 | O26: 1 | P26: 3 | Q26: 0 | R26: 0 | S26: =SUM(E26:R26) -> 22
D27: JML | E27: =SUM(E25:E26) -> 4 | F27: =SUM(F25:F26) -> 1 | G27: =SUM(G25:G26) -> 5 | H27: =SUM(H25:H26) -> 3 | I27: =SUM(I25:I26) -> 0 | J27: =SUM(J25:J26) -> 3 | K27: =SUM(K25:K26) -> 0 | L27: =SUM(L25:L26) -> 4 | ... R27: =SUM(R25:R26) -> 0 | S27: =SUM(E27:R27) -> 31
B28: 4. | C28: Jumlah Pengguna Hak Pilih (B.1+B.2+B.3) | D28: LK | E28: =SUM(E19,E22,E25) -> 111 | F28: =SUM(F19,F22,F25) -> 77 | G28: =SUM(G19,G22,G25) -> 92 | H28: =SUM(H19,H22,H25) -> 95 | I28: =SUM(I19,I22,I25) -> 119 | J28: =SUM(J19,J22,J25) -> 115 | K28: =SUM(K19,K22,K25) -> 102 | L28: =SUM(L19,L22,L25) -> 110 | ... R28: =SUM(R19,R22,R25) -> 122 | S28: =SUM(E28:R28) -> 1507
D29: PR | E29: =SUM(E20,E23,E26) -> 111 | F29: =SUM(F20,F23,F26) -> 70 | G29: =SUM(G20,G23,G26) -> 107 | H29: =SUM(H20,H23,H26) -> 113 | I29: =SUM(I20,I23,I26) -> 94 | J29: =SUM(J20,J23,J26) -> 119 | K29: =SUM(K20,K23,K26) -> 121 | L29: =SUM(L20,L23,L26) -> 124 | ... R29: =SUM(R20,R23,R26) -> 111 | S29: =SUM(E29:R29) -> 1534
D30: JML | E30: =SUM(E28:E29) -> 222 | F30: =SUM(F28:F29) -> 147 | G30: =SUM(G28:G29) -> 199 | H30: =SUM(H28:H29) -> 208 | I30: =SUM(I28:I29) -> 213 | J30: =SUM(J28:J29) -> 234 | K30: =SUM(K28:K29) -> 223 | L30: =SUM(L28:L29) -> 234 | ... R30: =SUM(R28:R29) -> 233 | S30: =SUM(E30:R30) -> 3041
A32: II | B32: DATA PENGGUNAAN SURAT SUARA
A33: 1 | B33: Jumlah surat suara yang diterima, termasuk surat suara cadangan 2,5% dari DPT | E33: 259 | F33: 218 | G33: 244 | H33: 261 | I33: 294 | J33: 284 | K33: 285 | L33: 292 | M33: 250 | N33: 255 | O33: 295 | P33: 271 | Q33: 268 | R33: 278 | S33: =SUM(E33:R33) -> 3754
A34: 2 | B34: Jumlah surat suara yang digunakan | E34: 222 | F34: 147 | G34: 199 | H34: 208 | I34: 213 | J34: 234 | K34: 223 | L34: 234 | M34: 198 | N34: 212 | O34: 240 | P34: 246 | Q34: 232 | R34: 233 | S34: =SUM(E34:R34) -> 3041
A35: 3 | B35: Jumlah surat suara dikembalikan oleh pemilih (karena rusak atau keliru coblos) | E35: 1 | F35: 0 | G35: 1 | H35: 1 | I35: 0 | J35: 0 | K35: 0 | L35: 0 | M35: 0 | N35: 0 | O35: 2 | P35: 0 | Q35: 0 | R35: 1 | S35: =SUM(E35:R35) -> 6
A36: 4 | B36: Jumlah surat suara yang tidak digunakan/tidak terpakai, termasuk sisa surat suara cadangan | E36: =E33-(E34+E35) -> 36 | F36: =F33-(F34+F35) -> 71 | G36: =G33-(G34+G35) -> 44 | H36: =H33-(H34+H35) -> 52 | I36: =I33-(I34+I35) -> 81 | J36: =J33-(J34+J35) -> 50 | K36: =K33-(K34+K35) -> 62 | L36: =L33-(L34+L35) -> 58 | ... R36: =R33-(R34+R35) -> 44 | S36: =SUM(E36:R36) -> 707
A38: III | B38: DATA PEMILIH DISABILITAS
B39: Jumlah seluruh Pemilih disabilitas yang menggunakan hak pilih | D39: LK | E39: 0 | F39: 0 | G39: 0 | H39: 0 | I39: 1 | J39: 0 | K39: 1 | L39: 0 | M39: 0 | N39: 0 | O39: 1 | P39: 0 | Q39: 0 | R39: 0 | S39: =SUM(E39:R39) -> 3
D40: PR | E40: 0 | F40: 0 | G40: 0 | H40: 0 | I40: 0 | J40: 1 | K40: 0 | L40: 0 | M40: 0 | N40: 0 | O40: 3 | P40: 0 | Q40: 0 | R40: 0 | S40: =SUM(E40:R40) -> 4
D41: JML | E41: =SUM(E39:E40) -> 0 | F41: =SUM(F39:F40) -> 0 | G41: =SUM(G39:G40) -> 0 | H41: =SUM(H39:H40) -> 0 | I41: =SUM(I39:I40) -> 1 | J41: =SUM(J39:J40) -> 1 | K41: =SUM(K39:K40) -> 1 | L41: =SUM(L39:L40) -> 0 | ... R41: =SUM(R39:R40) -> 0 | S41: =SUM(E41:R41) -> 7
A43: IV | B43: DATA RINCIAN PEROLEHAN SUARA PASANGAN CALON BUPATI DAN WAKIL BUPATI
A44: NOMOR DAN NAMA CALON
A45: A.1 | B45: 1. | C45: Partai Kebangkitan Bangsa | E45: 9 | F45: 11 | G45: 2 | H45: 1 | I45: 6 | J45: 8 | K45: 3 | L45: 7 | M45: 10 | N45: 4 | O45: 3 | P45: 4 | Q45: 7 | R45: 13 | S45: =SUM(E45:R45) -> 88
A46: A.2 | B46: 1 | C46: 1. Dr. Hj. NIHAYATUL WAFIROH, M.A. | E46: 50 | F46: 22 | G46: 8 | H46: 2 | I46: 5 | J46: 11 | K46: 7 | L46: 4 | M46: 14 | N46: 15 | O46: 4 | P46: 11 | Q46: 9 | R46: 15 | S46: =SUM(E46:R46) -> 177
B47: 2 | C47: 2. H. M. NASIM KHAN | E47: 3 | F47: 8 | G47: 1 | H47: 1 | I47: 6 | J47: 6 | K47: 15 | L47: 26 | M47: 20 | N47: 11 | O47: 8 | P47: 2 | Q47: 9 | R47: 17 | S47: =SUM(E47:R47) -> 133
B48: 3 | C48: 3. Dr. H. AKIK ZAMAN, M.Pd.I. | E48: 0 | F48: 2 | G48: 1 | H48: 0 | I48: 2 | J48: 0 | K48: 1 | L48: 1 | M48: 0 | N48: 0 | O48: 1 | P48: 1 | Q48: 0 | R48: 0 | S48: =SUM(E48:R48) -> 9
B49: 4 | C49: 4. AHMAD RIFA'I, S.H. | E49: 0 | F49: 1 | G49: 3 | H49: 0 | I49: 1 | J49: 1 | K49: 0 | L49: 0 | M49: 1 | N49: 0 | O49: 1 | P49: 1 | Q49: 0 | R49: 3 | S49: =SUM(E49:R49) -> 12
B50: 5 | C50: 5. Drs. H. MAHFUD M.N. | E50: 1 | F50: 1 | G50: 0 | H50: 0 | I50: 0 | J50: 1 | K50: 4 | L50: 1 | M50: 1 | N50: 1 | O50: 0 | P50: 0 | Q50: 0 | R50: 1 | S50: =SUM(E50:R50) -> 11
B51: 6 | C51: 6. NURHAYATI, S.Pd. | E51: 1 | F51: 0 | G51: 0 | H51: 0 | I51: 1 | J51: 1 | K51: 1 | L51: 0 | M51: 0 | N51: 0 | O51: 0 | P51: 0 | Q51: 0 | R51: 0 | S51: =SUM(E51:R51) -> 4
...

Sheet LEMAHBANGDEWO
C2: Kecamatan | D2: ROGOJAMPI
C3: Kabupaten | D3: BANYUWANGI
C4: Provinsi | D4: JAWA TIMUR
C9: Kelurahan | D9: LEMAHBANGDEWO
A12: I | B12: DATA PEMILIH DAN PENGGUNAAN HAK PILIH | O12: JUMLAH AKHIR
A13: A | B13: DATA PEMILIH | E13: TPS 001 | F13: TPS 002 | G13: TPS 003 | H13: TPS 004 | I13: TPS 005 | J13: TPS 006 | K13: TPS 007 | L13: TPS 008 | M13: TPS 009 | N13: TPS 010
B14: Jumlah Pemilih dalam Daftar Pemilih Tetap (DPT) | D14: LK | E14: 142 | F14: 114 | G14: 96 | H14: 133 | I14: 104 | J14: 133 | K14: 134 | L14: 141 | M14: 119 | N14: 75 | O14: =SUM(E14:N14) -> 1191
D15: PR | E15: 143 | F15: 142 | G15: 99 | H15: 146 | I15: 109 | J15: 133 | K15: 137 | L15: 152 | M15: 122 | N15: 77 | O15: =SUM(E15:N15) -> 1260
D16: JML | E16: =SUM(E14:E15) -> 285 | F16: =SUM(F14:F15) -> 256 | G16: =SUM(G14:G15) -> 195 | H16: =SUM(H14:H15) -> 279 | I16: =SUM(I14:I15) -> 213 | J16: =SUM(J14:J15) -> 266 | K16: =SUM(K14:K15) -> 271 | L16: =SUM(L14:L15) -> 293 | ... N16: =SUM(N14:N15) -> 152 | O16: =SUM(E16:N16) -> 2451
A18: B | B18: PENGGUNA HAK PILIH
B19: 1. | C19: Jumlah pengguna hak pilih dalam Daftar Pemilih Tetap (DPT) | D19: LK | E19: 115 | F19: 86 | G19: 79 | H19: 95 | I19: 70 | J19: 104 | K19: 96 | L19: 105 | M19: 90 | N19: 58 | O19: =SUM(E19:N19) -> 898
D20: PR | E20: 112 | F20: 114 | G20: 83 | H20: 115 | I20: 83 | J20: 111 | K20: 103 | L20: 115 | M20: 98 | N20: 67 | O20: =SUM(E20:N20) -> 1001
D21: JML | E21: =SUM(E19:E20) -> 227 | F21: =SUM(F19:F20) -> 200 | G21: =SUM(G19:G20) -> 162 | H21: =SUM(H19:H20) -> 210 | I21: =SUM(I19:I20) -> 153 | J21: =SUM(J19:J20) -> 215 | K21: =SUM(K19:K20) -> 199 | L21: =SUM(L19:L20) -> 220 | ... N21: =SUM(N19:N20) -> 125 | O21: =SUM(E21:N21) -> 1899
B22: 2. | C22: Jumlah pengguna hak pilih dalam Daftar Pemilih Tambahan (DPTb) | D22: LK | E22: 0 | F22: 1 | G22: 2 | H22: 1 | I22: 0 | J22: 1 | K22: 0 | L22: 0 | M22: 1 | N22: 3 | O22: =SUM(E22:N22) -> 9
D23: PR | E23: 0 | F23: 2 | G23: 0 | H23: 1 | I23: 2 | J23: 1 | K23: 2 | L23: 1 | M23: 1 | N23: 0 | O23: =SUM(E23:N23) -> 10
D24: JML | E24: =SUM(E22:E23) -> 0 | F24: =SUM(F22:F23) -> 3 | G24: =SUM(G22:G23) -> 2 | H24: =SUM(H22:H23) -> 2 | I24: =SUM(I22:I23) -> 2 | J24: =SUM(J22:J23) -> 2 | K24: =SUM(K22:K23) -> 2 | L24: =SUM(L22:L23) -> 1 | ... N24: =SUM(N22:N23) -> 3 | O24: =SUM(E24:N24) -> 19
B25: 3. | C25: Jumlah pengguna hak pilih dalam Daftar Pemilih Khusus (DPK) | D25: LK | E25: 0 | F25: 1 | G25: 3 | H25: 2 | I25: 0 | J25: 1 | K25: 2 | L25: 0 | M25: 0 | N25: 0 | O25: =SUM(E25:N25) -> 9
D26: PR | E26: 0 | F26: 0 | G26: 1 | H26: 2 | I26: 2 | J26: 0 | K26: 0 | L26: 0 | M26: 0 | N26: 2 | O26: =SUM(E26:N26) -> 7
D27: JML | E27: =SUM(E25:E26) -> 0 | F27: =SUM(F25:F26) -> 1 | G27: =SUM(G25:G26) -> 4 | H27: =SUM(H25:H26) -> 4 | I27: =SUM(I25:I26) -> 2 | J27: =SUM(J25:J26) -> 1 | K27: =SUM(K25:K26) -> 2 | L27: =SUM(L25:L26) -> 0 | ... N27: =SUM(N25:N26) -> 2 | O27: =SUM(E27:N27) -> 16
B28: 4. | C28: Jumlah Pengguna Hak Pilih (B.1+B.2+B.3) | D28: LK | E28: =SUM(E19,E22,E25) -> 115 | F28: =SUM(F19,F22,F25) -> 88 | G28: =SUM(G19,G22,G25) -> 84 | H28: =SUM(H19,H22,H25) -> 98 | I28: =SUM(I19,I22,I25) -> 70 | J28: =SUM(J19,J22,J25) -> 106 | K28: =SUM(K19,K22,K25) -> 98 | L28: =SUM(L19,L22,L25) -> 105 | ... N28: =SUM(N19,N22,N25) -> 61 | O28: =SUM(E28:N28) -> 916
D29: PR | E29: =SUM(E20,E23,E26) -> 112 | F29: =SUM(F20,F23,F26) -> 116 | G29: =SUM(G20,G23,G26) -> 84 | H29: =SUM(H20,H23,H26) -> 118 | I29: =SUM(I20,I23,I26) -> 87 | J29: =SUM(J20,J23,J26) -> 112 | K29: =SUM(K20,K23,K26) -> 105 | L29: =SUM(L20,L23,L26) -> 116 | ... N29: =SUM(N20,N23,N26) -> 69 | O29: =SUM(E29:N29) -> 1018
D30: JML | E30: =SUM(E28:E29) -> 227 | F30: =SUM(F28:F29) -> 204 | G30: =SUM(G28:G29) -> 168 | H30: =SUM(H28:H29) -> 216 | I30: =SUM(I28:I29) -> 157 | J30: =SUM(J28:J29) -> 218 | K30: =SUM(K28:K29) -> 203 | L30: =SUM(L28:L29) -> 221 | ... N30: =SUM(N28:N29) -> 130 | O30: =SUM(E30:N30) -> 1934
A32: II | B32: DATA PENGGUNAAN SURAT SUARA
A33: 1 | B33: Jumlah surat suara yang diterima, termasuk surat suara cadangan 2,5% dari DPT | E33: 291 | F33: 262 | G33: 200 | H33: 285 | I33: 218 | J33: 272 | K33: 277 | L33: 299 | M33: 246 | N33: 156 | O33: =SUM(E33:N33) -> 2506
A34: 2 | B34: Jumlah surat suara yang digunakan | E34: 227 | F34: 204 | G34: 168 | H34: 216 | I34: 157 | J34: 218 | K34: 203 | L34: 221 | M34: 190 | N34: 130 | O34: =SUM(E34:N34) -> 1934
A35: 3 | B35: Jumlah surat suara dikembalikan oleh pemilih (karena rusak atau keliru coblos) | E35: 0 | F35: 0 | G35: 0 | H35: 0 | I35: 0 | J35: 1 | K35: 2 | L35: 0 | M35: 0 | N35: 2 | O35: =SUM(E35:N35) -> 5
A36: 4 | B36: Jumlah surat suara yang tidak digunakan/tidak terpakai, termasuk sisa surat suara cadangan | E36: =E33-(E34+E35) -> 64 | F36: =F33-(F34+F35) -> 58 | G36: =G33-(G34+G35) -> 32 | H36: =H33-(H34+H35) -> 69 | I36: =I33-(I34+I35) -> 61 | J36: =J33-(J34+J35) -> 53 | K36: =K33-(K34+K35) -> 72 | L36: =L33-(L34+L35) -> 78 | ... N36: =N33-(N34+N35) -> 24 | O36: =SUM(E36:N36) -> 567
A38: III | B38: DATA PEMILIH DISABILITAS
B39: Jumlah seluruh Pemilih disabilitas yang menggunakan hak pilih | D39: LK | E39: 1 | F39: 0 | G39: 0 | H39: 5 | I39: 0 | J39: 0 | K39: 0 | L39: 3 | M39: 0 | N39: 0 | O39: =SUM(E39:N39) -> 9
D40: PR | E40: 0 | F40: 0 | G40: 1 | H40: 0 | I40: 0 | J40: 0 | K40: 0 | L40: 1 | M40: 0 | N40: 0 | O40: =SUM(E40:N40) -> 2
D41: JML | E41: =SUM(E39:E40) -> 1 | F41: =SUM(F39:F40) -> 0 | G41: =SUM(G39:G40) -> 1 | H41: =SUM(H39:H40) -> 5 | I41: =SUM(I39:I40) -> 0 | J41: =SUM(J39:J40) -> 0 | K41: =SUM(K39:K40) -> 0 | L41: =SUM(L39:L40) -> 4 | ... N41: =SUM(N39:N40) -> 0 | O41: =SUM(E41:N41) -> 11
A43: IV | B43: DATA RINCIAN PEROLEHAN SUARA PASANGAN CALON BUPATI DAN WAKIL BUPATI
A44: NOMOR DAN NAMA CALON
A45: A.1 | B45: 1. | C45: Partai Kebangkitan Bangsa | E45: 5 | F45: 1 | G45: 1 | H45: 0 | I45: 2 | J45: 3 | K45: 6 | L45: 4 | M45: 11 | N45: 10 | O45: =SUM(E45:N45) -> 43
A46: A.2 | B46: 1 | C46: 1. Dr. Hj. NIHAYATUL WAFIROH, M.A. | E46: 4 | F46: 6 | G46: 3 | H46: 9 | I46: 5 | J46: 8 | K46: 30 | L46: 12 | M46: 26 | N46: 21 | O46: =SUM(E46:N46) -> 124
B47: 2 | C47: 2. H. M. NASIM KHAN | E47: 1 | F47: 0 | G47: 0 | H47: 3 | I47: 2 | J47: 2 | K47: 9 | L47: 1 | M47: 1 | N47: 0 | O47: =SUM(E47:N47) -> 19
B48: 3 | C48: 3. Dr. H. AKIK ZAMAN, M.Pd.I. | E48: 1 | F48: 0 | G48: 1 | H48: 1 | I48: 0 | J48: 2 | K48: 2 | L48: 2 | M48: 1 | N48: 0 | O48: =SUM(E48:N48) -> 10
B49: 4 | C49: 4. AHMAD RIFA'I, S.H. | E49: 3 | F49: 1 | G49: 0 | H49: 0 | I49: 0 | J49: 0 | K49: 0 | L49: 0 | M49: 2 | N49: 0 | O49: =SUM(E49:N49) -> 6
B50: 5 | C50: 5. Drs. H. MAHFUD M.N. | E50: 0 | F50: 0 | G50: 0 | H50: 0 | I50: 0 | J50: 1 | K50: 0 | L50: 0 | M50: 0 | N50: 0 | O50: =SUM(E50:N50) -> 1
B51: 6 | C51: 6. NURHAYATI, S.Pd. | E51: 0 | F51: 0 | G51: 0 | H51: 0 | I51: 0 | J51: 0 | K51: 1 | L51: 0 | M51: 0 | N51: 1 | O51: =SUM(E51:N51) -> 2
...

Sheet MANGIR
C2: Kecamatan | D2: ROGOJAMPI
C3: Kabupaten | D3: BANYUWANGI
C4: Provinsi | D4: JAWA TIMUR
C9: Kelurahan | D9: MANGIR
A12: I | B12: DATA PEMILIH DAN PENGGUNAAN HAK PILIH | S12: JUMLAH AKHIR
A13: A | B13: DATA PEMILIH | E13: TPS 001 | F13: TPS 002 | G13: TPS 003 | H13: TPS 004 | I13: TPS 005 | J13: TPS 006 | K13: TPS 007 | L13: TPS 008 | M13: TPS 009 | N13: TPS 010 | O13: TPS 011 | P13: TPS 012 | Q13: TPS 013 | R13: TPS 014
B14: Jumlah Pemilih dalam Daftar Pemilih Tetap (DPT) | D14: LK | E14: 146 | F14: 121 | G14: 131 | H14: 119 | I14: 136 | J14: 114 | K14: 105 | L14: 122 | M14: 115 | N14: 128 | O14: 139 | P14: 134 | Q14: 116 | R14: 120 | S14: =SUM(E14:R14) -> 1746
D15: PR | E15: 137 | F15: 124 | G15: 144 | H15: 121 | I15: 152 | J15: 97 | K15: 93 | L15: 123 | M15: 111 | N15: 114 | O15: 143 | P15: 143 | Q15: 108 | R15: 130 | S15: =SUM(E15:R15) -> 1740
D16: JML | E16: =SUM(E14:E15) -> 283 | F16: =SUM(F14:F15) -> 245 | G16: =SUM(G14:G15) -> 275 | H16: =SUM(H14:H15) -> 240 | I16: =SUM(I14:I15) -> 288 | J16: =SUM(J14:J15) -> 211 | K16: =SUM(K14:K15) -> 198 | L16: =SUM(L14:L15) -> 245 | ... R16: =SUM(R14:R15) -> 250 | S16: =SUM(E16:R16) -> 3486
A18: B | B18: PENGGUNA HAK PILIH
