Workbook

Sheet DPR RI
C8: Kecamatan
C9: Kabupaten | D9: BANYUWANGI
C10: Provinsi | D10: JAWA TIMUR
A12: I | B12: DATA PEMILIH DAN PENGGUNAAN HAK PILIH | E12: JUMLAH AKHIR
A13: A | B13: DATA PEMILIH
B14: Jumlah Pemilih dalam Daftar Pemilih Tetap (DPT) | D14: LK | E14: =SONGGON!AF14+BALAK!X14+SRAGI!AG14+PARANGHARJO!S14+BEDEWANG!W14+BAYU!AB14+SUMBERARUM!X14+SUMBERBULU!Q14 -> 19458
D15: PR | E15: =SONGGON!AF15+BALAK!X15+SRAGI!AG15+PARANGHARJO!S15+BEDEWANG!W15+BAYU!AB15+SUMBERARUM!X15 -> 18057
D16: JML | E16: =SUM(E14:E15) -> 37515
A18: B | B18: PENGGUNA HAK PILIH
B19: 1. | C19: Jumlah pengguna hak pilih dalam Daftar Pemilih Tetap (DPT) | D19: LK | E19: =SONGGON!AF19+BALAK!X19+SRAGI!AG19+PARANGHARJO!S19+BEDEWANG!W19+BAYU!AB19+SUMBERARUM!X19 -> 13272
D20: PR | E20: =SONGGON!AF20+BALAK!X20+SRAGI!AG20+PARANGHARJO!S20+BEDEWANG!W20+BAYU!AB20+SUMBERARUM!X20 -> 14392
D21: JML | E21: =SUM(E19:E20) -> 27664
B22: 2. | C22: Jumlah pengguna hak pilih dalam Daftar Pemilih Tambahan (DPTb) | D22: LK | E22: =SONGGON!AF22+BALAK!X22+SRAGI!AG22+PARANGHARJO!S22+BEDEWANG!W22+BAYU!AB22+SUMBERARUM!X22 -> 3
D23: PR | E23: =SONGGON!AF23+BALAK!X23+SRAGI!AG23+PARANGHARJO!S23+BEDEWANG!W23+BAYU!AB23+SUMBERARUM!X23 -> 3
D24: JML | E24: =SUM(E22:E23) -> 6
B25: 3. | C25: Jumlah pengguna hak pilih dalam Daftar Pemilih Khusus (DPK) | D25: LK | E25: =SONGGON!AF25+BALAK!X25+SRAGI!AG25+PARANGHARJO!S25+BEDEWANG!W25+BAYU!AB25+SUMBERARUM!X25 -> 84
D26: PR | E26: =SONGGON!AF26+BALAK!X26+SRAGI!AG26+PARANGHARJO!S26+BEDEWANG!W26+BAYU!AB26+SUMBERARUM!X26 -> 72
D27: JML | E27: =SUM(E25:E26) -> 156
B28: 4. | C28: Jumlah Pengguna Hak Pilih (B.1+B.2+B.3) | D28: LK | E28: =E19+E22+E25 -> 13359
D29: PR | E29: =E20+E23+E26 -> 14467
D30: JML | E30: =SUM(E28:E29) -> 27826
A32: II | B32: DATA PENGGUNAAN SURAT SUARA
A33: 1 | B33: Jumlah surat suara yang diterima, termasuk surat suara cadangan 2,5% dari DPT | E33: =SONGGON!AF33+BALAK!X33+SRAGI!AG33+PARANGHARJO!S33+BEDEWANG!W33+BAYU!AB33+SUMBERARUM!X33 -> 36328
A34: 2 | B34: Jumlah surat suara yang digunakan | E34: =SONGGON!AF34+BALAK!X34+SRAGI!AG34+PARANGHARJO!S34+BEDEWANG!W34+BAYU!AB34+SUMBERARUM!X34 -> 27826
A35: 3 | B35: Jumlah surat suara dikembalikan oleh pemilih (karena rusak atau keliru coblos) | E35: =SONGGON!AF35+BALAK!X35+SRAGI!AG35+PARANGHARJO!S35+BEDEWANG!W35+BAYU!AB35+SUMBERARUM!X35 -> 43
A36: 4 | B36: Jumlah surat suara yang tidak digunakan/tidak terpakai, termasuk sisa surat suara cadangan | E36: =E33-(E34+E35) -> 8459
A38: III | B38: DATA PEMILIH DISABILITAS
B39: Jumlah seluruh Pemilih disabilitas yang menggunakan hak pilih | D39: LK | E39: =SONGGON!AF39+BALAK!X39+SRAGI!AG39+PARANGHARJO!S39+BEDEWANG!W39+BAYU!AB39+SUMBERARUM!X39 -> 21
D40: PR | E40: =SONGGON!AF40+BALAK!X40+SRAGI!AG40+PARANGHARJO!S40+BEDEWANG!W40+BAYU!AB40+SUMBERARUM!X40 -> 22
D41: JML | E41: =SUM(E39:E40) -> 43
A43: IV | B43: DATA RINCIAN PEROLEHAN SUARA PASANGAN CALON BUPATI DAN WAKIL BUPATI
A44: NOMOR DAN NAMA CALON
A45: A.1 | B45: 1. | C45: Partai Kebangkitan Bangsa | E45: =SONGGON!AF45+BALAK!X45+SRAGI!AG45+PARANGHARJO!S45+BEDEWANG!W45+BAYU!AB45+SUMBERARUM!X45 -> 1196
A46: A.2 | B46: 1 | C46: 1. Dr. Hj. NIHAYATUL WAFIROH, M.A. | E46: =SONGGON!AF46+BALAK!X46+SRAGI!AG46+PARANGHARJO!S46+BEDEWANG!W46+BAYU!AB46+SUMBERARUM!X46 -> 2371
B47: 2 | C47: 2. H. M. NASIM KHAN | E47: =SONGGON!AF47+BALAK!X47+SRAGI!AG47+PARANGHARJO!S47+BEDEWANG!W47+BAYU!AB47+SUMBERARUM!X47 -> 592
B48: 3 | C48: 3. Dr. H. AKIK ZAMAN, M.Pd.I. | E48: =SONGGON!AF48+BALAK!X48+SRAGI!AG48+PARANGHARJO!S48+BEDEWANG!W48+BAYU!AB48+SUMBERARUM!X48 -> 113
B49: 4 | C49: 4. AHMAD RIFA'I, S.H. | E49: =SONGGON!AF49+BALAK!X49+SRAGI!AG49+PARANGHARJO!S49+BEDEWANG!W49+BAYU!AB49+SUMBERARUM!X49 -> 116
B50: 5 | C50: 5. Drs. H. MAHFUD M.N. | E50: =SONGGON!AF50+BALAK!X50+SRAGI!AG50+PARANGHARJO!S50+BEDEWANG!W50+BAYU!AB50+SUMBERARUM!X50 -> 70
B51: 6 | C51: 6. NURHAYATI, S.Pd. | E51: =SONGGON!AF51+BALAK!X51+SRAGI!AG51+PARANGHARJO!S51+BEDEWANG!W51+BAYU!AB51+SUMBERARUM!X51 -> 36
B52: 7 | C52: 7. MAFTUHA KISWAH | E52: =SONGGON!AF52+BALAK!X52+SRAGI!AG52+PARANGHARJO!S52+BEDEWANG!W52+BAYU!AB52+SUMBERARUM!X52 -> 18
...

Sheet SONGGON
C2: Kecamatan
C3: Kabupaten | D3: BANYUWANGI
C4: Provinsi | D4: JAWA TIMUR
C9: Kelurahan
A12: I | B12: DATA PEMILIH DAN PENGGUNAAN HAK PILIH | AF12: JUMLAH AKHIR
A13: A | B13: DATA PEMILIH | E13: TPS 001 | F13: TPS 002 | G13: TPS 003 | H13: TPS 004 | I13: TPS 005 | J13: TPS 006 | K13: TPS 007 | L13: TPS 008 | M13: TPS 009 | N13: TPS 010 | O13: TPS 011 | P13: TPS 012 | Q13: TPS 013 | R13: TPS 014 | S13: TPS 015 | T13: TPS 016 | U13: TPS 017 | V13: TPS 018 | W13: TPS 019 | X13: TPS 020 | Y13: TPS 021 | Z13: TPS 022 | AA13: TPS 023 | AB13: TPS 024 | AC13: TPS 025 | AD13: TPS 026 | AE13: TPS 027
B14: Jumlah Pemilih dalam Daftar Pemilih Tetap (DPT) | D14: LK | E14: 105 | F14: 135 | G14: 112 | H14: 110 | I14: 120 | J14: 136 | K14: 146 | L14: 92 | M14: 81 | N14: 119 | O14: 140 | P14: 140 | Q14: 140 | R14: 145 | S14: 139 | T14: 94 | U14: 127 | V14: 157 | W14: 149 | X14: 127 | Y14: 140 | Z14: 127 | AA14: 122 | AB14: 147 | AC14: 150 | AD14: 148 | AE14: 136 | AF14: =SUM(E14:AE14) -> 3484
D15: PR | E15: 127 | F15: 134 | G15: 128 | H15: 110 | I15: 127 | J15: 130 | K15: 142 | L15: 98 | M15: 97 | N15: 129 | O15: 140 | P15: 136 | Q15: 134 | R15: 139 | S15: 141 | T15: 103 | U15: 127 | V15: 142 | W15: 148 | X15: 131 | Y15: 150 | Z15: 137 | AA15: 110 | AB15: 132 | AC15: 148 | AD15: 151 | AE15: 144 | AF15: =SUM(E15:AE15) -> 3535
D16: JML | E16: =SUM(E14:E15) -> 232 | F16: =SUM(F14:F15) -> 269 | G16: =SUM(G14:G15) -> 240 | H16: =SUM(H14:H15) -> 220 | I16: =SUM(I14:I15) -> 247 | J16: =SUM(J14:J15) -> 266 | K16: =SUM(K14:K15) -> 288 | L16: =SUM(L14:L15) -> 190 | ... AE16: =SUM(AE14:AE15) -> 280 | AF16: =SUM(E16:AE16) -> 7019
A18: B | B18: PENGGUNA HAK PILIH
B19: 1. | C19: Jumlah pengguna hak pilih dalam Daftar Pemilih Tetap (DPT) | D19: LK | E19: 77 | F19: 95 | G19: 67 | H19: 84 | I19: 101 | J19: 95 | K19: 104 | L19: 65 | M19: 59 | N19: 80 | O19: 108 | P19: 103 | Q19: 109 | R19: 105 | S19: 101 | T19: 76 | U19: 95 | V19: 119 | W19: 110 | X19: 95 | Y19: 99 | Z19: 98 | AA19: 95 | AB19: 110 | AC19: 115 | AD19: 127 | AE19: 112 | AF19: =SUM(E19:AE19) -> 2604
D20: PR | E20: 107 | F20: 106 | G20: 88 | H20: 90 | I20: 104 | J20: 104 | K20: 108 | L20: 69 | M20: 68 | N20: 100 | O20: 108 | P20: 115 | Q20: 103 | R20: 115 | S20: 115 | T20: 81 | U20: 105 | V20: 120 | W20: 128 | X20: 110 | Y20: 116 | Z20: 116 | AA20: 93 | AB20: 109 | AC20: 114 | AD20: 132 | AE20: 127 | AF20: =SUM(E20:AE20) -> 2851
D21: JML | E21: =SUM(E19:E20) -> 184 | F21: =SUM(F19:F20) -> 201 | G21: =SUM(G19:G20) -> 155 | H21: =SUM(H19:H20) -> 174 | I21: =SUM(I19:I20) -> 205 | J21: =SUM(J19:J20) -> 199 | K21: =SUM(K19:K20) -> 212 | L21: =SUM(L19:L20) -> 134 | ... AE21: =SUM(AE19:AE20) -> 239 | AF21: =SUM(E21:AE21) -> 5455
B22: 2. | C22: Jumlah pengguna hak pilih dalam Daftar Pemilih Tambahan (DPTb) | D22: LK | E22: 0 | F22: 0 | G22: 0 | H22: 0 | I22: 0 | J22: 0 | K22: 0 | L22: 0 | M22: 0 | N22: 0 | O22: 0 | P22: 0 | Q22: 0 | R22: 0 | S22: 0 | T22: 0 | U22: 0 | V22: 0 | W22: 1 | X22: 0 | Y22: 0 | Z22: 0 | AA22: 0 | AB22: 0 | AC22: 0 | AD22: 0 | AE22: 0 | AF22: =SUM(E22:AE22) -> 1
D23: PR | E23: 0 | F23: 0 | G23: 0 | H23: 0 | I23: 0 | J23: 0 | K23: 0 | L23: 0 | M23: 0 | N23: 0 | O23: 0 | P23: 0 | Q23: 0 | R23: 0 | S23: 0 | T23: 0 | U23: 0 | V23: 0 | W23: 1 | X23: 0 | Y23: 1 | Z23: 0 | AA23: 0 | AB23: 0 | AC23: 0 | AD23: 0 | AE23: 0 | AF23: =SUM(E23:AE23) -> 2
D24: JML | E24: =SUM(E22:E23) -> 0 | F24: =SUM(F22:F23) -> 0 | G24: =SUM(G22:G23) -> 0 | H24: =SUM(H22:H23) -> 0 | I24: =SUM(I22:I23) -> 0 | J24: =SUM(J22:J23) -> 0 | K24: =SUM(K22:K23) -> 0 | L24: =SUM(L22:L23) -> 0 | ... AE24: =SUM(AE22:AE23) -> 0 | AF24: =SUM(E24:AE24) -> 3
B25: 3. | C25: Jumlah pengguna hak pilih dalam Daftar Pemilih Khusus (DPK) | D25: LK | E25: 0 | F25: 2 | G25: 1 | H25: 1 | I25: 3 | J25: 0 | K25: 0 | L25: 0 | M25: 0 | N25: 1 | O25: 1 | P25: 2 | Q25: 1 | R25: 1 | S25: 0 | T25: 1 | U25: 0 | V25: 0 | W25: 5 | X25: 0 | Y25: 0 | Z25: 1 | AA25: 1 | AB25: 0 | AC25: 0 | AD25: 0 | AE25: 0 | AF25: =SUM(E25:AE25) -> 21
D26: PR | E26: 1 | F26: 0 | G26: 0 | H26: 0 | I26: 1 | J26: 0 | K26: 0 | L26: 0 | M26: 0 | N26: 0 | O26: 0 | P26: 0 | Q26: 1 | R26: 1 | S26: 0 | T26: 0 | U26: 0 | V26: 0 | W26: 4 | X26: 1 | Y26: 1 | Z26: 0 | AA26: 2 | AB26: 0 | AC26: 0 | AD26: 0 | AE26: 0 | AF26: =SUM(E26:AE26) -> 12
D27: JML | E27: =SUM(E25:E26) -> 1 | F27: =SUM(F25:F26) -> 2 | G27: =SUM(G25:G26) -> 1 | H27: =SUM(H25:H26) -> 1 | I27: =SUM(I25:I26) -> 4 | J27: =SUM(J25:J26) -> 0 | K27: =SUM(K25:K26) -> 0 | L27: =SUM(L25:L26) -> 0 | ... AE27: =SUM(AE25:AE26) -> 0 | AF27: =SUM(E27:AE27) -> 33
B28: 4. | C28: Jumlah Pengguna Hak Pilih (B.1+B.2+B.3) | D28: LK | E28: =SUM(E19,E22,E25) -> 77 | F28: =SUM(F19,F22,F25) -> 97 | G28: =SUM(G19,G22,G25) -> 68 | H28: =SUM(H19,H22,H25) -> 85 | I28: =SUM(I19,I22,I25) -> 104 | J28: =SUM(J19,J22,J25) -> 95 | K28: =SUM(K19,K22,K25) -> 104 | L28: =SUM(L19,L22,L25) -> 65 | ... AE28: =SUM(AE19,AE22,AE25) -> 112 | AF28: =SUM(E28:AE28) -> 2626
D29: PR | E29: =SUM(E20,E23,E26) -> 108 | F29: =SUM(F20,F23,F26) -> 106 | G29: =SUM(G20,G23,G26) -> 88 | H29: =SUM(H20,H23,H26) -> 90 | I29: =SUM(I20,I23,I26) -> 105 | J29: =SUM(J20,J23,J26) -> 104 | K29: =SUM(K20,K23,K26) -> 108 | L29: =SUM(L20,L23,L26) -> 69 | ... AE29: =SUM(AE20,AE23,AE26) -> 127 | AF29: =SUM(E29:AE29) -> 2865
D30: JML | E30: =SUM(E28:E29) -> 185 | F30: =SUM(F28:F29) -> 203 | G30: =SUM(G28:G29) -> 156 | H30: =SUM(H28:H29) -> 175 | I30: =SUM(I28:I29) -> 209 | J30: =SUM(J28:J29) -> 199 | K30: =SUM(K28:K29) -> 212 | L30: =SUM(L28:L29) -> 134 | ... AE30: =SUM(AE28:AE29) -> 239 | AF30: =SUM(E30:AE30) -> 5491
A32: II | B32: DATA PENGGUNAAN SURAT SUARA
A33: 1 | B33: Jumlah surat suara yang diterima, termasuk surat suara cadangan 2,5% dari DPT | E33: 227 | F33: 275 | G33: 245 | H33: 225 | I33: 252 | J33: 272 | K33: 294 | L33: 194 | M33: 216 | N33: 253 | O33: 275 | P33: 272 | Q33: 292 | R33: 290 | S33: 286 | T33: 198 | U33: 259 | V33: 305 | W33: 303 | X33: 264 | Y33: 297 | Z33: 270 | AA33: 237 | AB33: 275 | AC33: 274 | AD33: 305 | AE33: 276 | AF33: =SUM(E33:AE33) -> 7131
A34: 2 | B34: Jumlah surat suara yang digunakan | E34: 185 | F34: 203 | G34: 156 | H34: 175 | I34: 209 | J34: 199 | K34: 212 | L34: 134 | M34: 127 | N34: 181 | O34: 217 | P34: 220 | Q34: 214 | R34: 222 | S34: 216 | T34: 158 | U34: 200 | V34: 239 | W34: 249 | X34: 206 | Y34: 217 | Z34: 215 | AA34: 191 | AB34: 219 | AC34: 229 | AD34: 259 | AE34: 239 | AF34: =SUM(E34:AE34) -> 5491
A35: 3 | B35: Jumlah surat suara dikembalikan oleh pemilih (karena rusak atau keliru coblos) | E35: 0 | F35: 1 | G35: 0 | H35: 0 | I35: 1 | J35: 0 | K35: 0 | L35: 1 | M35: 0 | N35: 0 | O35: 0 | P35: 0 | Q35: 1 | R35: 0 | S35: 0 | T35: 0 | U35: 0 | V35: 0 | W35: 0 | X35: 1 | Y35: 2 | Z35: 0 | AA35: 0 | AB35: 0 | AC35: 0 | AD35: 0 | AE35: 0 | AF35: =SUM(E35:AE35) -> 7
A36: 4 | B36: Jumlah surat suara yang tidak digunakan/tidak terpakai, termasuk sisa surat suara cadangan | E36: =E33-(E34+E35) -> 42 | F36: =F33-(F34+F35) -> 71 | G36: =G33-(G34+G35) -> 89 | H36: =H33-(H34+H35) -> 50 | I36: =I33-(I34+I35) -> 42 | J36: =J33-(J34+J35) -> 73 | K36: =K33-(K34+K35) -> 82 | L36: =L33-(L34+L35) -> 59 | ... AE36: =AE33-(AE34+AE35) -> 37 | AF36: =SUM(E36:AE36) -> 1633
A38: III | B38: DATA PEMILIH DISABILITAS
B39: Jumlah seluruh Pemilih disabilitas yang menggunakan hak pilih | D39: LK | E39: 0 | F39: 0 | G39: 0 | H39: 0 | I39: 0 | J39: 0 | K39: 1 | L39: 0 | M39: 1 | N39: 0 | O39: 0 | P39: 0 | Q39: 0 | R39: 2 | S39: 0 | T39: 0 | U39: 0 | V39: 2 | W39: 0 | X39: 0 | Y39: 0 | Z39: 0 | AA39: 0 | AB39: 0 | AC39: 0 | AD39: 0 | AE39: 0 | AF39: =SUM(E39:AE39) -> 6
D40: PR | E40: 0 | F40: 0 | G40: 0 | H40: 0 | I40: 1 | J40: 0 | K40: 0 | L40: 0 | M40: 2 | N40: 2 | O40: 0 | P40: 0 | Q40: 0 | R40: 4 | S40: 0 | T40: 0 | U40: 0 | V40: 2 | W40: 0 | X40: 0 | Y40: 2 | Z40: 0 | AA40: 0 | AB40: 0 | AC40: 0 | AD40: 0 | AE40: 0 | AF40: =SUM(E40:AE40) -> 13
D41: JML | E41: =SUM(E39:E40) -> 0 | F41: =SUM(F39:F40) -> 0 | G41: =SUM(G39:G40) -> 0 | H41: =SUM(H39:H40) -> 0 | I41: =SUM(I39:I40) -> 1 | J41: =SUM(J39:J40) -> 0 | K41: =SUM(K39:K40) -> 1 | L41: =SUM(L39:L40) -> 0 | ... AE41: =SUM(AE39:AE40) -> 0 | AF41: =SUM(E41:AE41) -> 19
A43: IV | B43: DATA RINCIAN PEROLEHAN SUARA PASANGAN CALON BUPATI DAN WAKIL BUPATI
A44: NOMOR DAN NAMA CALON
A45: A.1 | B45: 1. | C45: Partai Kebangkitan Bangsa | E45: 8 | F45: 12 | G45: 9 | H45: 7 | I45: 6 | J45: 9 | K45: 7 | L45: 3 | M45: 11 | N45: 5 | O45: 9 | P45: 8 | Q45: 4 | R45: 10 | S45: 12 | T45: 5 | U45: 3 | V45: 11 | W45: 7 | X45: 14 | Y45: 7 | Z45: 8 | AA45: 7 | AB45: 13 | AC45: 13 | AD45: 6 | AE45: 2 | AF45: =SUM(E45:AE45) -> 216
A46: A.2 | B46: 1 | C46: 1. Dr. Hj. NIHAYATUL WAFIROH, M.A. | E46: 8 | F46: 11 | G46: 10 | H46: 12 | I46: 15 | J46: 14 | K46: 7 | L46: 4 | M46: 14 | N46: 14 | O46: 11 | P46: 5 | Q46: 8 | R46: 8 | S46: 20 | T46: 5 | U46: 3 | V46: 27 | W46: 27 | X46: 16 | Y46: 21 | Z46: 8 | AA46: 8 | AB46: 5 | AC46: 20 | AD46: 9 | AE46: 4 | AF46: =SUM(E46:AE46) -> 314
B47: 2 | C47: 2. H. M. NASIM KHAN | E47: 4 | F47: 6 | G47: 3 | H47: 2 | I47: 4 | J47: 6 | K47: 1 | L47: 0 | M47: 2 | N47: 1 | O47: 11 | P47: 6 | Q47: 6 | R47: 2 | S47: 6 | T47: 2 | U47: 2 | V47: 14 | W47: 6 | X47: 11 | Y47: 5 | Z47: 4 | AA47: 3 | AB47: 5 | AC47: 9 | AD47: 7 | AE47: 4 | AF47: =SUM(E47:AE47) -> 132
B48: 3 | C48: 3. Dr. H. AKIK ZAMAN, M.Pd.I. | E48: 1 | F48: 0 | G48: 3 | H48: 3 | I48: 1 | J48: 3 | K48: 0 | L48: 0 | M48: 1 | N48: 0 | O48: 1 | P48: 0 | Q48: 0 | R48: 1 | S48: 2 | T48: 0 | U48: 0 | V48: 1 | W48: 3 | X48: 0 | Y48: 1 | AA48: 0 | AB48: 2 | AC48: 1 | AD48: 1 | AE48: 0 | AF48: =SUM(E48:AE48) -> 25
B49: 4 | C49: 4. AHMAD RIFA'I, S.H. | F49: 1 | G49: 1 | H49: 2 | I49: 0 | K49: 0 | L49: 0 | N49: 0 | O49: 0 | P49: 1 | Q49: 0 | R49: 0 | S49: 3 | T49: 0 | U49: 0 | V49: 1 | W49: 1 | X49: 0 | Y49: 1 | Z49: 1 | AA49: 0 | AB49: 2 | AC49: 1 | AD49: 0 | AE49: 5 | AF49: =SUM(E49:AE49) -> 20
B50: 5 | C50: 5. Drs. H. MAHFUD M.N. | F50: 0 | G50: 1 | H50: 0 | I50: 0 | J50: 1 | K50: 3 | L50: 0 | N50: 1 | O50: 1 | P50: 3 | Q50: 0 | R50: 2 | S50: 1 | T50: 0 | U50: 1 | V50: 0 | W50: 2 | X50: 2 | Y50: 1 | Z50: 1 | AA50: 2 | AB50: 1 | AC50: 3 | AE50: 0 | AF50: =SUM(E50:AE50) -> 26
B51: 6 | C51: 6. NURHAYATI, S.Pd. | F51: 0 | G51: 1 | H51: 0 | I51: 1 | J51: 0 | K51: 0 | L51: 0 | N51: 0 | O51: 1 | P51: 0 | Q51: 0 | R51: 0 | S51: 0 | T51: 0 | U51: 1 | V51: 0 | W51: 1 | X51: 0 | Y51: 0 | Z51: 1 | AA51: 1 | AB51: 0 | AC51: 0 | AE51: 0 | AF51: =SUM(E51:AE51) -> 7
...

Sheet BALAK
C2: Kecamatan
C3: Kabupaten | D3: BANYUWANGI
C4: Provinsi | D4: JAWA TIMUR
C9: Kelurahan
A12: I | B12: DATA PEMILIH DAN PENGGUNAAN HAK PILIH | X12: JUMLAH AKHIR
A13: A | B13: DATA PEMILIH | E13: TPS 001 | F13: TPS 002 | G13: TPS 003 | H13: TPS 004 | I13: TPS 005 | J13: TPS 006 | K13: TPS 007 | L13: TPS 008 | M13: TPS 009 | N13: TPS 010 | O13: TPS 011 | P13: TPS 012 | Q13: TPS 013 | R13: TPS 014 | S13: TPS 015 | T13: TPS 016 | U13: TPS 017 | V13: TPS 018 | W13: TPS 019
B14: Jumlah Pemilih dalam Daftar Pemilih Tetap (DPT) | D14: LK | E14: 138 | F14: 141 | G14: 136 | H14: 140 | I14: 129 | J14: 138 | K14: 139 | L14: 139 | M14: 137 | N14: 138 | O14: 132 | P14: 140 | Q14: 134 | R14: 141 | S14: 131 | T14: 125 | U14: 136 | V14: 136 | W14: 141 | X14: =SUM(E14:W14) -> 2591
D15: PR | E15: 128 | F15: 135 | G15: 145 | H15: 126 | I15: 124 | J15: 136 | K15: 142 | L15: 143 | M15: 147 | N15: 137 | O15: 143 | P15: 150 | Q15: 149 | R15: 145 | S15: 150 | T15: 137 | U15: 141 | V15: 144 | W15: 140 | X15: =SUM(E15:W15) -> 2662
D16: JML | E16: =SUM(E14:E15) -> 266 | F16: =SUM(F14:F15) -> 276 | G16: =SUM(G14:G15) -> 281 | H16: =SUM(H14:H15) -> 266 | I16: =SUM(I14:I15) -> 253 | J16: =SUM(J14:J15) -> 274 | K16: =SUM(K14:K15) -> 281 | L16: =SUM(L14:L15) -> 282 | ... W16: =SUM(W14:W15) -> 281 | X16: =SUM(E16:W16) -> 5253
A18: B | B18: PENGGUNA HAK PILIH
B19: 1. | C19: Jumlah pengguna hak pilih dalam Daftar Pemilih Tetap (DPT) | D19: LK | E19: 73 | F19: 109 | G19: 112 | H19: 93 | I19: 95 | J19: 104 | K19: 96 | L19: 110 | M19: 98 | N19: 104 | O19: 102 | P19: 107 | Q19: 109 | R19: 97 | S19: 93 | T19: 98 | U19: 113 | V19: 104 | W19: 123 | X19: =SUM(E19:W19) -> 1940
D20: PR | E20: 90 | F20: 112 | G20: 118 | H20: 97 | I20: 88 | J20: 110 | K20: 115 | L20: 117 | M20: 127 | N20: 106 | O20: 119 | P20: 122 | Q20: 113 | R20: 122 | S20: 120 | T20: 108 | U20: 116 | V20: 119 | W20: 123 | X20: =SUM(E20:W20) -> 2142
D21: JML | E21: =SUM(E19:E20) -> 163 | F21: =SUM(F19:F20) -> 221 | G21: =SUM(G19:G20) -> 230 | H21: =SUM(H19:H20) -> 190 | I21: =SUM(I19:I20) -> 183 | J21: =SUM(J19:J20) -> 214 | K21: =SUM(K19:K20) -> 211 | L21: =SUM(L19:L20) -> 227 | ... W21: =SUM(W19:W20) -> 246 | X21: =SUM(E21:W21) -> 4082
B22: 2. | C22: Jumlah pengguna hak pilih dalam Daftar Pemilih Tambahan (DPTb) | D22: LK | E22: 0 | F22: 0 | G22: 0 | H22: 0 | I22: 0 | J22: 0 | K22: 0 | L22: 0 | M22: 0 | N22: 0 | O22: 0 | P22: 0 | Q22: 0 | R22: 0 | S22: 0 | T22: 0 | U22: 0 | V22: 0 | W22: 0 | X22: =SUM(E22:W22) -> 0
D23: PR | E23: 0 | F23: 0 | G23: 0 | H23: 0 | I23: 0 | J23: 0 | K23: 0 | L23: 0 | M23: 0 | N23: 0 | O23: 0 | P23: 0 | Q23: 0 | R23: 0 | S23: 0 | T23: 0 | U23: 0 | V23: 0 | W23: 0 | X23: =SUM(E23:W23) -> 0
D24: JML | E24: =SUM(E22:E23) -> 0 | F24: =SUM(F22:F23) -> 0 | G24: =SUM(G22:G23) -> 0 | H24: =SUM(H22:H23) -> 0 | I24: =SUM(I22:I23) -> 0 | J24: =SUM(J22:J23) -> 0 | K24: =SUM(K22:K23) -> 0 | L24: =SUM(L22:L23) -> 0 | ... W24: =SUM(W22:W23) -> 0 | X24: =SUM(E24:W24) -> 0
B25: 3. | C25: Jumlah pengguna hak pilih dalam Daftar Pemilih Khusus (DPK) | D25: LK | E25: 0 | F25: 0 | G25: 2 | H25: 3 | I25: 1 | J25: 0 | K25: 0 | L25: 3 | M25: 0 | N25: 0 | O25: 0 | P25: 0 | Q25: 0 | R25: 2 | S25: 2 | T25: 0 | U25: 2 | V25: 1 | W25: 0 | X25: =SUM(E25:W25) -> 16
D26: PR | E26: 1 | F26: 0 | G26: 1 | H26: 3 | I26: 3 | J26: 1 | K26: 0 | L26: 1 | M26: 0 | N26: 0 | O26: 1 | P26: 0 | Q26: 0 | R26: 3 | S26: 2 | T26: 0 | U26: 0 | V26: 0 | W26: 1 | X26: =SUM(E26:W26) -> 17
D27: JML | E27: =SUM(E25:E26) -> 1 | F27: =SUM(F25:F26) -> 0 | G27: =SUM(G25:G26) -> 3 | H27: =SUM(H25:H26) -> 6 | I27: =SUM(I25:I26) -> 4 | J27: =SUM(J25:J26) -> 1 | K27: =SUM(K25:K26) -> 0 | L27: =SUM(L25:L26) -> 4 | ... W27: =SUM(W25:W26) -> 1 | X27: =SUM(E27:W27) -> 33
B28: 4. | C28: Jumlah Pengguna Hak Pilih (B.1+B.2+B.3) | D28: LK | E28: =SUM(E19,E22,E25) -> 73 | F28: =SUM(F19,F22,F25) -> 109 | G28: =SUM(G19,G22,G25) -> 114 | H28: =SUM(H19,H22,H25) -> 96 | I28: =SUM(I19,I22,I25) -> 96 | J28: =SUM(J19,J22,J25) -> 104 | K28: =SUM(K19,K22,K25) -> 96 | L28: =SUM(L19,L22,L25) -> 113 | ... W28: =SUM(W19,W22,W25) -> 123 | X28: =SUM(E28:W28) -> 1956
D29: PR | E29: =SUM(E20,E23,E26) -> 91 | F29: =SUM(F20,F23,F26) -> 112 | G29: =SUM(G20,G23,G26) -> 119 | H29: =SUM(H20,H23,H26) -> 100 | I29: =SUM(I20,I23,I26) -> 91 | J29: =SUM(J20,J23,J26) -> 111 | K29: =SUM(K20,K23,K26) -> 115 | L29: =SUM(L20,L23,L26) -> 118 | ... W29: =SUM(W20,W23,W26) -> 124 | X29: =SUM(E29:W29) -> 2159
D30: JML | E30: =SUM(E28:E29) -> 164 | F30: =SUM(F28:F29) -> 221 | G30: =SUM(G28:G29) -> 233 | H30: =SUM(H28:H29) -> 196 | I30: =SUM(I28:I29) -> 187 | J30: =SUM(J28:J29) -> 215 | K30: =SUM(K28:K29) -> 211 | L30: =SUM(L28:L29) -> 231 | ... W30: =SUM(W28:W29) -> 247 | X30: =SUM(E30:W30) -> 4115
A32: II | B32: DATA PENGGUNAAN SURAT SUARA
A33: 1 | B33: Jumlah surat suara yang diterima, termasuk surat suara cadangan 2,5% dari DPT | E33: 282 | F33: 294 | G33: 277 | H33: 272 | I33: 259 | J33: 279 | K33: 287 | L33: 298 | M33: 270 | N33: 261 | O33: 271 | P33: 257 | Q33: 279 | R33: 287 | S33: 305 | T33: 269 | U33: 283 | V33: 286 | W33: 297 | X33: =SUM(E33:W33) -> 5313
A34: 2 | B34: Jumlah surat suara yang digunakan | E34: 164 | F34: 221 | G34: 233 | H34: 196 | I34: 187 | J34: 215 | K34: 211 | L34: 231 | M34: 225 | N34: 210 | O34: 222 | P34: 229 | Q34: 222 | R34: 224 | S34: 217 | T34: 206 | U34: 231 | V34: 224 | W34: 247 | X34: =SUM(E34:W34) -> 4115
A35: 3 | B35: Jumlah surat suara dikembalikan oleh pemilih (karena rusak atau keliru coblos) | E35: 0 | F35: 0 | G35: 0 | H35: 1 | I35: 0 | J35: 1 | K35: 0 | L35: 0 | M35: 1 | N35: 0 | O35: 0 | P35: 0 | Q35: 1 | R35: 0 | S35: 0 | T35: 0 | U35: 0 | V35: 1 | W35: 1 | X35: =SUM(E35:W35) -> 6
A36: 4 | B36: Jumlah surat suara yang tidak digunakan/tidak terpakai, termasuk sisa surat suara cadangan | E36: =E33-(E34+E35) -> 118 | F36: =F33-(F34+F35) -> 73 | G36: =G33-(G34+G35) -> 44 | H36: =H33-(H34+H35) -> 75 | I36: =I33-(I34+I35) -> 72 | J36: =J33-(J34+J35) -> 63 | K36: =K33-(K34+K35) -> 76 | L36: =L33-(L34+L35) -> 67 | ... W36: =W33-(W34+W35) -> 49 | X36: =SUM(E36:W36) -> 1192
A38: III | B38: DATA PEMILIH DISABILITAS
B39: Jumlah seluruh Pemilih disabilitas yang menggunakan hak pilih | D39: LK | E39: 0 | F39: 0 | G39: 0 | H39: 0 | I39: 0 | J39: 0 | K39: 0 | L39: 0 | M39: 1 | N39: 0 | O39: 0 | P39: 0 | Q39: 0 | R39: 0 | S39: 0 | T39: 0 | U39: 0 | V39: 0 | W39: 0 | X39: =SUM(E39:W39) -> 1
D40: PR | E40: 0 | F40: 0 | G40: 0 | H40: 0 | I40: 0 | J40: 0 | K40: 0 | L40: 0 | M40: 1 | N40: 0 | O40: 0 | P40: 0 | Q40: 0 | R40: 0 | S40: 0 | T40: 0 | U40: 0 | V40: 0 | W40: 0 | X40: =SUM(E40:W40) -> 1
D41: JML | E41: =SUM(E39:E40) -> 0 | F41: =SUM(F39:F40) -> 0 | G41: =SUM(G39:G40) -> 0 | H41: =SUM(H39:H40) -> 0 | I41: =SUM(I39:I40) -> 0 | J41: =SUM(J39:J40) -> 0 | K41: =SUM(K39:K40) -> 0 | L41: =SUM(L39:L40) -> 0 | ... W41: =SUM(W39:W40) -> 0 | X41: =SUM(E41:W41) -> 2
A43: IV | B43: DATA RINCIAN PEROLEHAN SUARA PASANGAN CALON BUPATI DAN WAKIL BUPATI
A44: NOMOR DAN NAMA CALON
A45: A.1 | B45: 1. | C45: Partai Kebangkitan Bangsa | E45: 15 | F45: 9 | G45: 10 | H45: 8 | I45: 10 | J45: 10 | K45: 7 | L45: 3 | M45: 3 | N45: 5 | O45: 10 | P45: 5 | Q45: 11 | R45: 10 | S45: 24 | T45: 6 | U45: 8 | V45: 10 | X45: =SUM(E45:W45) -> 164
A46: A.2 | B46: 1 | C46: 1. Dr. Hj. NIHAYATUL WAFIROH, M.A. | E46: 5 | F46: 10 | G46: 14 | H46: 19 | I46: 9 | J46: 19 | K46: 12 | L46: 19 | M46: 4 | N46: 1 | O46: 5 | P46: 8 | Q46: 42 | R46: 28 | S46: 22 | T46: 30 | U46: 32 | V46: 25 | W46: 6 | X46: =SUM(E46:W46) -> 310
B47: 2 | C47: 2. H. M. NASIM KHAN | E47: 2 | F47: 7 | G47: 5 | H47: 4 | I47: 5 | J47: 6 | K47: 8 | L47: 6 | M47: 1 | N47: 2 | O47: 7 | P47: 4 | Q47: 11 | R47: 10 | S47: 1 | T47: 13 | U47: 7 | V47: 27 | W47: 1 | X47: =SUM(E47:W47) -> 127
B48: 3 | C48: 3. Dr. H. AKIK ZAMAN, M.Pd.I. | E48: 0 | F48: 3 | G48: 1 | I48: 1 | J48: 0 | K48: 0 | L48: 0 | M48: 0 | N48: 0 | O48: 2 | P48: 2 | Q48: 1 | R48: 3 | S48: 2 | T48: 1 | U48: 1 | V48: 1 | X48: =SUM(E48:W48) -> 18
B49: 4 | C49: 4. AHMAD RIFA'I, S.H. | E49: 0 | F49: 0 | G49: 0 | H49: 1 | I49: 2 | J49: 1 | K49: 0 | L49: 1 | M49: 0 | N49: 0 | O49: 0 | P49: 1 | Q49: 0 | R49: 1 | S49: 1 | T49: 1 | V49: 2 | W49: 1 | X49: =SUM(E49:W49) -> 12
B50: 5 | C50: 5. Drs. H. MAHFUD M.N. | E50: 0 | F50: 2 | G50: 2 | I50: 0 | J50: 0 | K50: 0 | L50: 1 | M50: 0 | N50: 1 | O50: 0 | P50: 0 | Q50: 0 | R50: 0 | S50: 0 | T50: 0 | U50: 1 | X50: =SUM(E50:W50) -> 7
B51: 6 | C51: 6. NURHAYATI, S.Pd. | E51: 0 | G51: 2 | H51: 1 | I51: 0 | J51: 0 | K51: 0 | L51: 1 | M51: 0 | N51: 0 | O51: 0 | P51: 0 | Q51: 0 | R51: 0 | S51: 0 | T51: 1 | V51: 1 | X51: =SUM(E51:W51) -> 6
...

Sheet SRAGI
C2: Kecamatan
C3: Kabupaten | D3: BANYUWANGI
C4: Provinsi | D4: JAWA TIMUR
C9: Kelurahan
A12: I | B12: DATA PEMILIH DAN PENGGUNAAN HAK PILIH | AG12: JUMLAH AKHIR
A13: A | B13: DATA PEMILIH | E13: TPS 001 | F13: TPS 002 | G13: TPS 003 | H13: TPS 004 | I13: TPS 005 | J13: TPS 006 | K13: TPS 007 | L13: TPS 008 | M13: TPS 009 | N13: TPS 010 | O13: TPS 011 | P13: TPS 012 | Q13: TPS 013 | R13: TPS 014 | S13: TPS 015 | T13: TPS 016 | U13: TPS 017 | V13: TPS 018 | W13: TPS 019 | X13: TPS 020 | Y13: TPS 021 | Z13: TPS 022 | AA13: TPS 023 | AB13: TPS 024 | AC13: TPS 025 | AD13: TPS 026 | AE13: TPS 027 | AF13: TPS 028
B14: Jumlah Pemilih dalam Daftar Pemilih Tetap (DPT) | D14: LK | E14: 133 | F14: 130 | G14: 141 | H14: 116 | I14: 135 | J14: 111 | K14: 134 | L14: 150 | M14: 151 | N14: 146 | O14: 125 | P14: 115 | Q14: 115 | R14: 143 | S14: 150 | T14: 151 | U14: 157 | V14: 140 | W14: 142 | X14: 149 | Y14: 148 | Z14: 151 | AA14: 149 | AB14: 131 | AC14: 127 | AD14: 148 | AE14: 151 | AF14: 135 | AG14: =SUM(E14:AF14) -> 3874
D15: PR | E15: 137 | F15: 129 | G15: 133 | H15: 122 | I15: 125 | J15: 103 | K15: 142 | L15: 148 | M15: 148 | N15: 149 | O15: 132 | P15: 106 | Q15: 115 | R15: 148 | S15: 139 | T15: 142 | U15: 136 | V15: 156 | W15: 152 | X15: 145 | Y15: 148 | Z15: 140 | AA15: 143 | AB15: 117 | AC15: 135 | AD15: 150 | AE15: 140 | AF15: 142 | AG15: =SUM(E15:AF15) -> 3822
D16: JML | E16: =SUM(E14:E15) -> 270 | F16: =SUM(F14:F15) -> 259 | G16: =SUM(G14:G15) -> 274 | H16: =SUM(H14:H15) -> 238 | I16: =SUM(I14:I15) -> 260 | J16: =SUM(J14:J15) -> 214 | K16: =SUM(K14:K15) -> 276 | L16: =SUM(L14:L15) -> 298 | ... AF16: =SUM(AF14:AF15) -> 277 | AG16: =SUM(E16:AF16) -> 7696
A18: B | B18: PENGGUNA HAK PILIH
B19: 1. | C19: Jumlah pengguna hak pilih dalam Daftar Pemilih Tetap (DPT) | D19: LK | E19: 100 | F19: 88 | G19: 101 | H19: 67 | I19: 99 | J19: 81 | K19: 101 | L19: 101 | M19: 113 | N19: 118 | O19: 90 | P19: 90 | Q19: 86 | R19: 111 | S19: 108 | T19: 113 | U19: 101 | V19: 113 | W19: 101 | X19: 116 | Y19: 119 | Z19: 115 | AA19: 112 | AB19: 99 | AC19: 94 | AD19: 102 | AE19: 112 | AF19: 104 | AG19: =SUM(E19:AF19) -> 2855
D20: PR | E20: 104 | F20: 108 | G20: 96 | H20: 86 | I20: 102 | J20: 83 | K20: 109 | L20: 118 | M20: 129 | N20: 124 | O20: 108 | P20: 87 | Q20: 93 | R20: 119 | S20: 108 | T20: 111 | U20: 101 | V20: 126 | W20: 115 | X20: 116 | Y20: 127 | Z20: 108 | AA20: 111 | AB20: 99 | AC20: 107 | AD20: 115 | AE20: 118 | AF20: 111 | AG20: =SUM(E20:AF20) -> 3039
D21: JML | E21: =SUM(E19:E20) -> 204 | F21: =SUM(F19:F20) -> 196 | G21: =SUM(G19:G20) -> 197 | H21: =SUM(H19:H20) -> 153 | I21: =SUM(I19:I20) -> 201 | J21: =SUM(J19:J20) -> 164 | K21: =SUM(K19:K20) -> 210 | L21: =SUM(L19:L20) -> 219 | ... AF21: =SUM(AF19:AF20) -> 215 | AG21: =SUM(E21:AF21) -> 5894
B22: 2. | C22: Jumlah pengguna hak pilih dalam Daftar Pemilih Tambahan (DPTb) | D22: LK | E22: 0 | F22: 0 | G22: 0 | H22: 0 | I22: 0 | J22: 0 | K22: 0 | L22: 0 | M22: 0 | N22: 0 | O22: 0 | P22: 0 | Q22: 0 | R22: 0 | S22: 0 | T22: 0 | U22: 0 | V22: 0 | W22: 0 | X22: 0 | Y22: 0 | Z22: 0 | AA22: 0 | AB22: 0 | AC22: 0 | AD22: 0 | AE22: 0 | AF22: 0 | AG22: =SUM(E22:AF22) -> 0
D23: PR | E23: 0 | F23: 0 | G23: 0 | H23: 0 | I23: 0 | J23: 0 | K23: 0 | L23: 0 | M23: 0 | N23: 0 | O23: 0 | P23: 0 | Q23: 0 | R23: 0 | S23: 0 | T23: 0 | U23: 0 | V23: 0 | W23: 0 | X23: 0 | Y23: 0 | Z23: 0 | AA23: 0 | AB23: 0 | AC23: 0 | AD23: 0 | AE23: 0 | AF23: 0 | AG23: =SUM(E23:AF23) -> 0
D24: JML | E24: =SUM(E22:E23) -> 0 | F24: =SUM(F22:F23) -> 0 | G24: =SUM(G22:G23) -> 0 | H24: =SUM(H22:H23) -> 0 | I24: =SUM(I22:I23) -> 0 | J24: =SUM(J22:J23) -> 0 | K24: =SUM(K22:K23) -> 0 | L24: =SUM(L22:L23) -> 0 | ... AF24: =SUM(AF22:AF23) -> 0 | AG24: =SUM(E24:AF24) -> 0
B25: 3. | C25: Jumlah pengguna hak pilih dalam Daftar Pemilih Khusus (DPK) | D25: LK | E25: 1 | F25: 1 | G25: 0 | H25: 2 | I25: 0 | J25: 0 | K25: 2 | L25: 0 | M25: 1 | N25: 2 | O25: 0 | P25: 0 | Q25: 0 | R25: 0 | S25: 0 | T25: 0 | U25: 1 | V25: 1 | W25: 0 | X25: 0 | Y25: 0 | Z25: 0 | AA25: 0 | AB25: 0 | AC25: 4 | AD25: 1 | AE25: 2 | AF25: 3 | AG25: =SUM(E25:AF25) -> 21
D26: PR | E26: 0 | F26: 0 | G26: 0 | H26: 0 | I26: 1 | J26: 1 | K26: 2 | L26: 2 | M26: 1 | N26: 0 | O26: 0 | P26: 0 | Q26: 1 | R26: 0 | S26: 0 | T26: 0 | U26: 1 | V26: 1 | W26: 0 | X26: 0 | Y26: 1 | Z26: 0 | AA26: 0 | AB26: 0 | AC26: 2 | AD26: 1 | AE26: 1 | AF26: 8 | AG26: =SUM(E26:AF26) -> 23
D27: JML | E27: =SUM(E25:E26) -> 1 | F27: =SUM(F25:F26) -> 1 | G27: =SUM(G25:G26) -> 0 | H27: =SUM(H25:H26) -> 2 | I27: =SUM(I25:I26) -> 1 | J27: =SUM(J25:J26) -> 1 | K27: =SUM(K25:K26) -> 4 | L27: =SUM(L25:L26) -> 2 | ... AF27: =SUM(AF25:AF26) -> 11 | AG27: =SUM(E27:AF27) -> 44
B28: 4. | C28: Jumlah Pengguna Hak Pilih (B.1+B.2+B.3) | D28: LK | E28: =SUM(E19,E22,E25) -> 101 | F28: =SUM(F19,F22,F25) -> 89 | G28: =SUM(G19,G22,G25) -> 101 | H28: =SUM(H19,H22,H25) -> 69 | I28: =SUM(I19,I22,I25) -> 99 | J28: =SUM(J19,J22,J25) -> 81 | K28: =SUM(K19,K22,K25) -> 103 | L28: =SUM(L19,L22,L25) -> 101 | ... AF28: =SUM(AF19,AF22,AF25) -> 107 | AG28: =SUM(E28:AF28) -> 2876
D29: PR | E29: =SUM(E20,E23,E26) -> 104 | F29: =SUM(F20,F23,F26) -> 108 | G29: =SUM(G20,G23,G26) -> 96 | H29: =SUM(H20,H23,H26) -> 86 | I29: =SUM(I20,I23,I26) -> 103 | J29: =SUM(J20,J23,J26) -> 84 | K29: =SUM(K20,K23,K26) -> 111 | L29: =SUM(L20,L23,L26) -> 120 | ... AF29: =SUM(AF20,AF23,AF26) -> 119 | AG29: =SUM(E29:AF29) -> 3062
D30: JML | E30: =SUM(E28:E29) -> 205 | F30: =SUM(F28:F29) -> 197 | G30: =SUM(G28:G29) -> 197 | H30: =SUM(H28:H29) -> 155 | I30: =SUM(I28:I29) -> 202 | J30: =SUM(J28:J29) -> 165 | K30: =SUM(K28:K29) -> 214 | L30: =SUM(L28:L29) -> 221 | ... AF30: =SUM(AF28:AF29) -> 226 | AG30: =SUM(E30:AF30) -> 5938
A32: II | B32: DATA PENGGUNAAN SURAT SUARA
A33: 1 | B33: Jumlah surat suara yang diterima, termasuk surat suara cadangan 2,5% dari DPT | E33: 277 | F33: 266 | G33: 265 | H33: 243 | I33: 256 | J33: 219 | K33: 262 | L33: 304 | M33: 305 | N33: 301 | O33: 253 | P33: 226 | Q33: 235 | R33: 297 | S33: 295 | T33: 299 | U33: 299 | V33: 302 | W33: 300 | X33: 300 | Y33: 302 | Z33: 297 | AA33: 288 | AB33: 253 | AC33: 268 | AD33: 304 | AE33: 297 | AF33: 283 | AG33: =SUM(E33:AF33) -> 7796
A34: 2 | B34: Jumlah surat suara yang digunakan | E34: 205 | F34: 197 | G34: 197 | H34: 155 | I34: 202 | J34: 165 | K34: 214 | L34: 221 | M34: 244 | N34: 244 | O34: 198 | P34: 177 | Q34: 180 | R34: 230 | S34: 216 | T34: 224 | U34: 204 | V34: 241 | W34: 216 | X34: 232 | Y34: 247 | Z34: 223 | AA34: 223 | AB34: 198 | AC34: 207 | AD34: 219 | AE34: 233 | AF34: 226 | AG34: =SUM(E34:AF34) -> 5938
A35: 3 | B35: Jumlah surat suara dikembalikan oleh pemilih (karena rusak atau keliru coblos) | E35: 0 | F35: 0 | G35: 0 | H35: 0 | I35: 0 | J35: 0 | K35: 1 | L35: 0 | M35: 0 | N35: 1 | O35: 0 | P35: 0 | Q35: 2 | R35: 0 | S35: 0 | T35: 0 | U35: 1 | V35: 0 | W35: 0 | X35: 0 | Y35: 0 | Z35: 0 | AA35: 0 | AB35: 0 | AC35: 1 | AD35: 0 | AE35: 0 | AF35: 2 | AG35: =SUM(E35:AF35) -> 8
A36: 4 | B36: Jumlah surat suara yang tidak digunakan/tidak terpakai, termasuk sisa surat suara cadangan | E36: =E33-(E34+E35) -> 72 | F36: =F33-(F34+F35) -> 69 | G36: =G33-(G34+G35) -> 68 | H36: =H33-(H34+H35) -> 88 | I36: =I33-(I34+I35) -> 54 | J36: =J33-(J34+J35) -> 54 | K36: =K33-(K34+K35) -> 47 | L36: =L33-(L34+L35) -> 83 | ... AF36: =AF33-(AF34+AF35) -> 55 | AG36: =SUM(E36:AF36) -> 1850
A38: III | B38: DATA PEMILIH DISABILITAS
B39: Jumlah seluruh Pemilih disabilitas yang menggunakan hak pilih | D39: LK | E39: 0 | F39: 0 | G39: 0 | H39: 0 | I39: 0 | J39: 0 | K39: 1 | L39: 0 | M39: 0 | N39: 0 | O39: 0 | P39: 0 | Q39: 0 | R39: 0 | S39: 0 | T39: 0 | U39: 0 | V39: 0 | W39: 0 | X39: 0 | Y39: 0 | Z39: 0 | AA39: 0 | AB39: 0 | AC39: 0 | AD39: 0 | AE39: 1 | AF39: 1 | AG39: =SUM(E39:AF39) -> 3
D40: PR | E40: 0 | F40: 0 | G40: 0 | H40: 0 | I40: 0 | J40: 0 | K40: 0 | L40: 0 | M40: 0 | N40: 0 | O40: 0 | P40: 0 | Q40: 0 | R40: 0 | S40: 0 | T40: 0 | U40: 0 | V40: 0 | W40: 0 | X40: 0 | Y40: 0 | Z40: 0 | AA40: 0 | AB40: 0 | AC40: 0 | AD40: 1 | AE40: 0 | AF40: 0 | AG40: =SUM(E40:AF40) -> 1
D41: JML | E41: =SUM(E39:E40) -> 0 | F41: =SUM(F39:F40) -> 0 | G41: =SUM(G39:G40) -> 0 | H41: =SUM(H39:H40) -> 0 | I41: =SUM(I39:I40) -> 0 | J41: =SUM(J39:J40) -> 0 | K41: =SUM(K39:K40) -> 1 | L41: =SUM(L39:L40) -> 0 | ... AF41: =SUM(AF39:AF40) -> 1 | AG41: =SUM(E41:AF41) -> 4
A43: IV | B43: DATA RINCIAN PEROLEHAN SUARA PASANGAN CALON BUPATI DAN WAKIL BUPATI
A44: NOMOR DAN NAMA CALON
A45: A.1 | B45: 1. | C45: Partai Kebangkitan Bangsa | E45: 8 | F45: 17 | G45: 9 | H45: 4 | I45: 6 | J45: 1 | K45: 8 | L45: 8 | M45: 14 | N45: 16 | O45: 4 | P45: 12 | Q45: 12 | R45: 14 | S45: 11 | T45: 10 | U45: 5 | V45: 9 | W45: 2 | X45: 1 | Y45: 9 | Z45: 6 | AA45: 2 | AB45: 5 | AC45: 9 | AD45: 9 | AE45: 32 | AF45: 12 | AG45: =SUM(E45:AF45) -> 255
A46: A.2 | B46: 1 | C46: 1. Dr. Hj. NIHAYATUL WAFIROH, M.A. | E46: 10 | F46: 20 | G46: 25 | H46: 13 | I46: 20 | J46: 25 | K46: 13 | L46: 20 | M46: 60 | N46: 39 | O46: 39 | P46: 27 | Q46: 43 | R46: 26 | S46: 12 | T46: 15 | U46: 13 | V46: 2 | W46: 10 | X46: 12 | Y46: 41 | Z46: 13 | AA46: 11 | AB46: 21 | AC46: 22 | AD46: 24 | AE46: 50 | AF46: 22 | AG46: =SUM(E46:AF46) -> 648
B47: 2 | C47: 2. H. M. NASIM KHAN | E47: 0 | F47: 1 | G47: 3 | H47: 6 | I47: 11 | J47: 5 | K47: 1 | L47: 1 | M47: 5 | N47: 3 | O47: 5 | P47: 3 | Q47: 3 | R47: 1 | S47: 1 | T47: 3 | U47: 0 | V47: 1 | W47: 2 | X47: 0 | Y47: 0 | Z47: 1 | AA47: 0 | AB47: 2 | AC47: 1 | AD47: 1 | AE47: 27 | AF47: 6 | AG47: =SUM(E47:AF47) -> 93
B48: 3 | C48: 3. Dr. H. AKIK ZAMAN, M.Pd.I. | E48: 0 | F48: 0 | G48: 0 | H48: 1 | I48: 4 | J48: 0 | K48: 0 | L48: 0 | M48: 0 | N48: 1 | O48: 3 | P48: 2 | Q48: 0 | R48: 6 | S48: 0 | T48: 1 | U48: 0 | V48: 0 | W48: 0 | X48: 0 | Y48: 1 | Z48: 2 | AA48: 0 | AB48: 1 | AC48: 1 | AD48: 0 | AE48: 0 | AF48: 0 | AG48: =SUM(E48:AF48) -> 23
B49: 4 | C49: 4. AHMAD RIFA'I, S.H. | E49: 0 | F49: 1 | G49: 2 | H49: 0 | I49: 1 | J49: 0 | K49: 0 | L49: 0 | M49: 0 | N49: 1 | O49: 0 | P49: 3 | Q49: 2 | R49: 1 | S49: 1 | T49: 0 | U49: 0 | V49: 0 | W49: 0 | X49: 0 | Y49: 0 | Z49: 1 | AA49: 1 | AB49: 1 | AC49: 1 | AD49: 0 | AE49: 1 | AF49: 0 | AG49: =SUM(E49:AF49) -> 17
B50: 5 | C50: 5. Drs. H. MAHFUD M.N. | E50: 0 | F50: 0 | G50: 0 | H50: 0 | I50: 0 | J50: 0 | K50: 1 | L50: 1 | M50: 1 | N50: 0 | O50: 0 | P50: 0 | Q50: 1 | R50: 1 | S50: 0 | T50: 0 | U50: 0 | V50: 1 | W50: 0 | X50: 1 | Y50: 0 | Z50: 0 | AA50: 0 | AB50: 0 | AC50: 0 | AD50: 0 | AE50: 3 | AF50: 0 | AG50: =SUM(E50:AF50) -> 10
B51: 6 | C51: 6. NURHAYATI, S.Pd. | E51: 0 | F51: 0 | G51: 0 | H51: 0 | I51: 0 | J51: 0 | K51: 1 | L51: 0 | M51: 0 | N51: 0 | O51: 0 | P51: 1 | Q51: 0 | R51: 0 | S51: 0 | T51: 1 | U51: 1 | V51: 0 | W51: 0 | X51: 0 | Y51: 0 | Z51: 0 | AA51: 1 | AB51: 0 | AC51: 0 | AD51: 0 | AE51: 1 | AF51: 0 | AG51: =SUM(E51:AF51) -> 6
...

Sheet PARANGHARJO
C2: Kecamatan
C3: Kabupaten | D3: BANYUWANGI
C4: Provinsi | D4: JAWA TIMUR
C9: Kelurahan
A12: I | B12: DATA PEMILIH DAN PENGGUNAAN HAK PILIH | S12: JUMLAH AKHIR
A13: A | B13: DATA PEMILIH | E13: TPS 001 | F13: TPS 002 | G13: TPS 003 | H13: TPS 004 | I13: TPS 005 | J13: TPS 006 | K13: TPS 007 | L13: TPS 008 | M13: TPS 009 | N13: TPS 010 | O13: TPS 011 | P13: TPS 012 | Q13: TPS 013 | R13: TPS 014
B14: Jumlah Pemilih dalam Daftar Pemilih Tetap (DPT) | D14: LK | S14: =SUM(E14:R14) -> 0
D15: PR | S15: =SUM(E15:R15) -> 0
D16: JML | E16: =SUM(E14:E15) -> 0 | F16: =SUM(F14:F15) -> 0 | G16: =SUM(G14:G15) -> 0 | H16: =SUM(H14:H15) -> 0 | I16: =SUM(I14:I15) -> 0 | J16: =SUM(J14:J15) -> 0 | K16: =SUM(K14:K15) -> 0 | L16: =SUM(L14:L15) -> 0 | ... R16: =SUM(R14:R15) -> 0 | S16: =SUM(E16:R16) -> 0
A18: B | B18: PENGGUNA HAK PILIH
B19: 1. | C19: Jumlah pengguna hak pilih dalam Daftar Pemilih Tetap (DPT) | D19: LK | S19: =SUM(E19:R19) -> 0
D20: PR | S20: =SUM(E20:R20) -> 0
D21: JML | E21: =SUM(E19:E20) -> 0 | F21: =SUM(F19:F20) -> 0 | G21: =SUM(G19:G20) -> 0 | H21: =SUM(H19:H20) -> 0 | I21: =SUM(I19:I20) -> 0 | J21: =SUM(J19:J20) -> 0 | K21: =SUM(K19:K20) -> 0 | L21: =SUM(L19:L20) -> 0 | ... R21: =SUM(R19:R20) -> 0 | S21: =SUM(E21:R21) -> 0
B22: 2. | C22: Jumlah pengguna hak pilih dalam Daftar Pemilih Tambahan (DPTb) | D22: LK | S22: =SUM(E22:R22) -> 0
D23: PR | S23: =SUM(E23:R23) -> 0
D24: JML | E24: =SUM(E22:E23) -> 0 | F24: =SUM(F22:F23) -> 0 | G24: =SUM(G22:G23) -> 0 | H24: =SUM(H22:H23) -> 0 | I24: =SUM(I22:I23) -> 0 | J24: =SUM(J22:J23) -> 0 | K24: =SUM(K22:K23) -> 0 | L24: =SUM(L22:L23) -> 0 | ... R24: =SUM(R22:R23) -> 0 | S24: =SUM(E24:R24) -> 0
B25: 3. | C25: Jumlah pengguna hak pilih dalam Daftar Pemilih Khusus (DPK) | D25: LK | S25: =SUM(E25:R25) -> 0
D26: PR | S26: =SUM(E26:R26) -> 0
D27: JML | E27: =SUM(E25:E26) -> 0 | F27: =SUM(F25:F26) -> 0 | G27: =SUM(G25:G26) -> 0 | H27: =SUM(H25:H26) -> 0 | I27: =SUM(I25:I26) -> 0 | J27: =SUM(J25:J26) -> 0 | K27: =SUM(K25:K26) -> 0 | L27: =SUM(L25:L26) -> 0 | ... R27: =SUM(R25:R26) -> 0 | S27: =SUM(E27:R27) -> 0
B28: 4. | C28: Jumlah Pengguna Hak Pilih (B.1+B.2+B.3) | D28: LK | E28: =SUM(E19,E22,E25) -> 0 | F28: =SUM(F19,F22,F25) -> 0 | G28: =SUM(G19,G22,G25) -> 0 | H28: =SUM(H19,H22,H25) -> 0 | I28: =SUM(I19,I22,I25) -> 0 | J28: =SUM(J19,J22,J25) -> 0 | K28: =SUM(K19,K22,K25) -> 0 | L28: =SUM(L19,L22,L25) -> 0 | ... R28: =SUM(R19,R22,R25) -> 0 | S28: =SUM(E28:R28) -> 0
D29: PR | E29: =SUM(E20,E23,E26) -> 0 | F29: =SUM(F20,F23,F26) -> 0 | G29: =SUM(G20,G23,G26) -> 0 | H29: =SUM(H20,H23,H26) -> 0 | I29: =SUM(I20,I23,I26) -> 0 | J29: =SUM(J20,J23,J26) -> 0 | K29: =SUM(K20,K23,K26) -> 0 | L29: =SUM(L20,L23,L26) -> 0 | ... R29: =SUM(R20,R23,R26) -> 0 | S29: =SUM(E29:R29) -> 0
D30: JML | E30: =SUM(E28:E29) -> 0 | F30: =SUM(F28:F29) -> 0 | G30: =SUM(G28:G29) -> 0 | H30: =SUM(H28:H29) -> 0 | I30: =SUM(I28:I29) -> 0 | J30: =SUM(J28:J29) -> 0 | K30: =SUM(K28:K29) -> 0 | L30: =SUM(L28:L29) -> 0 | ... R30: =SUM(R28:R29) -> 0 | S30: =SUM(E30:R30) -> 0
A32: II | B32: DATA PENGGUNAAN SURAT SUARA
A33: 1 | B33: Jumlah surat suara yang diterima, termasuk surat suara cadangan 2,5% dari DPT | S33: =SUM(E33:R33) -> 0
A34: 2 | B34: Jumlah surat suara yang digunakan | S34: =SUM(E34:R34) -> 0
A35: 3 | B35: Jumlah surat suara dikembalikan oleh pemilih (karena rusak atau keliru coblos) | S35: =SUM(E35:R35) -> 0
A36: 4 | B36: Jumlah surat suara yang tidak digunakan/tidak terpakai, termasuk sisa surat suara cadangan | E36: =E33-(E34+E35) -> 0 | F36: =F33-(F34+F35) -> 0 | G36: =G33-(G34+G35) -> 0 | H36: =H33-(H34+H35) -> 0 | I36: =I33-(I34+I35) -> 0 | J36: =J33-(J34+J35) -> 0 | K36: =K33-(K34+K35) -> 0 | L36: =L33-(L34+L35) -> 0 | ... R36: =R33-(R34+R35) -> 0 | S36: =SUM(E36:R36) -> 0
A38: III | B38: DATA PEMILIH DISABILITAS
B39: Jumlah seluruh Pemilih disabilitas yang menggunakan hak pilih | D39: LK | S39: =SUM(E39:R39) -> 0
D40: PR | S40: =SUM(E40:R40) -> 0
D41: JML | E41: =SUM(E39:E40) -> 0 | F41: =SUM(F39:F40) -> 0 | G41: =SUM(G39:G40) -> 0 | H41: =SUM(H39:H40) -> 0 | I41: =SUM(I39:I40) -> 0 | J41: =SUM(J39:J40) -> 0 | K41: =SUM(K39:K40) -> 0 | L41: =SUM(L39:L40) -> 0 | ... R41: =SUM(R39:R40) -> 0 | S41: =SUM(E41:R41) -> 0
A43: IV | B43: DATA RINCIAN PEROLEHAN SUARA PASANGAN CALON BUPATI DAN WAKIL BUPATI
A44: NOMOR DAN NAMA CALON
A45: A.1 | B45: 1. | C45: Partai Kebangkitan Bangsa | E45: 1 | F45: 8 | G45: 5 | H45: 4 | I45: 4 | J45: 5 | K45: 11 | L45: 11 | M45: 9 | N45: 1 | O45: 10 | P45: 6 | Q45: 10 | R45: 10 | S45: =SUM(E45:R45) -> 95
A46: A.2 | B46: 1 | C46: 1. Dr. Hj. NIHAYATUL WAFIROH, M.A. | E46: 4 | F46: 8 | G46: 6 | H46: 13 | I46: 10 | J46: 7 | K46: 6 | L46: 17 | M46: 28 | N46: 7 | O46: 16 | P46: 2 | Q46: 11 | R46: 21 | S46: =SUM(E46:R46) -> 156
B47: 2 | C47: 2. H. M. NASIM KHAN | E47: 4 | F47: 0 | G47: 3 | H47: 3 | I47: 5 | J47: 4 | K47: 1 | L47: 4 | M47: 9 | N47: 2 | O47: 3 | P47: 2 | Q47: 0 | R47: 2 | S47: =SUM(E47:R47) -> 42
B48: 3 | C48: 3. Dr. H. AKIK ZAMAN, M.Pd.I. | E48: 0 | F48: 0 | G48: 1 | H48: 0 | I48: 1 | J48: 0 | K48: 0 | L48: 0 | M48: 3 | N48: 0 | O48: 1 | P48: 0 | Q48: 0 | R48: 1 | S48: =SUM(E48:R48) -> 7
B49: 4 | C49: 4. AHMAD RIFA'I, S.H. | E49: 0 | F49: 0 | G49: 1 | H49: 0 | I49: 0 | J49: 0 | K49: 1 | L49: 0 | M49: 0 | N49: 0 | O49: 0 | P49: 0 | Q49: 0 | R49: 0 | S49: =SUM(E49:R49) -> 2
B50: 5 | C50: 5. Drs. H. MAHFUD M.N. | E50: 1 | F50: 0 | G50: 0 | H50: 0 | I50: 0 | J50: 0 | K50: 1 | L50: 0 | M50: 1 | N50: 0 | O50: 0 | P50: 1 | Q50: 0 | R50: 2 | S50: =SUM(E50:R50) -> 6
B51: 6 | C51: 6. NURHAYATI, S.Pd. | E51: 0 | F51: 0 | G51: 0 | H51: 0 | I51: 0 | J51: 0 | K51: 0 | L51: 0 | M51: 0 | N51: 2 | O51: 0 | P51: 0 | Q51: 0 | R51: 0 | S51: =SUM(E51:R51) -> 2
...

Sheet BEDEWANG
C2: Kecamatan
C3: Kabupaten | D3: BANYUWANGI
C4: Provinsi | D4: JAWA TIMUR
C9: Kelurahan
A12: I | B12: DATA PEMILIH DAN PENGGUNAAN HAK PILIH | W12: JUMLAH AKHIR
A13: A | B13: DATA PEMILIH | E13: TPS 001 | F13: TPS 002 | G13: TPS 003 | H13: TPS 004 | I13: TPS 005 | J13: TPS 006 | K13: TPS 007 | L13: TPS 008 | M13: TPS 009 | N13: TPS 010 | O13: TPS 011 | P13: TPS 012 | Q13: TPS 013 | R13: TPS 014 | S13: TPS 015 | T13: TPS 016 | U13: TPS 017 | V13: TPS 018
B14: Jumlah Pemilih dalam Daftar Pemilih Tetap (DPT) | D14: LK | E14: 143 | F14: 141 | G14: 147 | H14: 147 | I14: 123 | J14: 113 | K14: 136 | L14: 122 | M14: 123 | N14: 129 | O14: 137 | P14: 145 | Q14: 131 | R14: 148 | S14: 133 | T14: 153 | U14: 111 | V14: 87 | W14: =SUM(E14:V14) -> 2369
D15: PR | E15: 149 | F15: 157 | G15: 145 | H15: 141 | I15: 133 | J15: 118 | K15: 126 | L15: 132 | M15: 128 | N15: 131 | O15: 148 | P15: 148 | Q15: 149 | R15: 134 | S15: 143 | T15: 128 | U15: 107 | V15: 79 | W15: =SUM(E15:V15) -> 2396
D16: JML | E16: =SUM(E14:E15) -> 292 | F16: =SUM(F14:F15) -> 298 | G16: =SUM(G14:G15) -> 292 | H16: =SUM(H14:H15) -> 288 | I16: =SUM(I14:I15) -> 256 | J16: =SUM(J14:J15) -> 231 | K16: =SUM(K14:K15) -> 262 | L16: =SUM(L14:L15) -> 254 | ... V16: =SUM(V14:V15) -> 166 | W16: =SUM(E16:V16) -> 4765
A18: B | B18: PENGGUNA HAK PILIH
B19: 1. | C19: Jumlah pengguna hak pilih dalam Daftar Pemilih Tetap (DPT) | D19: LK | E19: 118 | F19: 102 | G19: 113 | H19: 114 | I19: 85 | J19: 88 | K19: 106 | L19: 86 | M19: 82 | N19: 95 | O19: 95 | P19: 107 | Q19: 100 | R19: 108 | S19: 96 | T19: 108 | U19: 76 | V19: 68 | W19: =SUM(E19:V19) -> 1747
D20: PR | E20: 121 | F20: 123 | G20: 110 | H20: 113 | I20: 101 | J20: 91 | K20: 102 | L20: 97 | M20: 100 | N20: 101 | O20: 115 | P20: 114 | Q20: 122 | R20: 102 | S20: 114 | T20: 118 | U20: 83 | V20: 66 | W20: =SUM(E20:V20) -> 1893
D21: JML | E21: =SUM(E19:E20) -> 239 | F21: =SUM(F19:F20) -> 225 | G21: =SUM(G19:G20) -> 223 | H21: =SUM(H19:H20) -> 227 | I21: =SUM(I19:I20) -> 186 | J21: =SUM(J19:J20) -> 179 | K21: =SUM(K19:K20) -> 208 | L21: =SUM(L19:L20) -> 183 | ... V21: =SUM(V19:V20) -> 134 | W21: =SUM(E21:V21) -> 3640
B22: 2. | C22: Jumlah pengguna hak pilih dalam Daftar Pemilih Tambahan (DPTb) | D22: LK | E22: 0 | F22: 0 | G22: 0 | H22: 0 | I22: 0 | J22: 0 | K22: 0 | L22: 0 | M22: 0 | N22: 0 | O22: 0 | P22: 0 | Q22: 0 | R22: 0 | S22: 0 | T22: 0 | U22: 0 | V22: 0 | W22: =SUM(E22:V22) -> 0
D23: PR | E23: 0 | F23: 0 | G23: 0 | H23: 0 | I23: 0 | J23: 0 | K23: 0 | L23: 0 | M23: 0 | N23: 0 | O23: 0 | P23: 0 | Q23: 0 | R23: 0 | S23: 0 | T23: 0 | U23: 0 | V23: 0 | W23: =SUM(E23:V23) -> 0
D24: JML | E24: =SUM(E22:E23) -> 0 | F24: =SUM(F22:F23) -> 0 | G24: =SUM(G22:G23) -> 0 | H24: =SUM(H22:H23) -> 0 | I24: =SUM(I22:I23) -> 0 | J24: =SUM(J22:J23) -> 0 | K24: =SUM(K22:K23) -> 0 | L24: =SUM(L22:L23) -> 0 | ... V24: =SUM(V22:V23) -> 0 | W24: =SUM(E24:V24) -> 0
B25: 3. | C25: Jumlah pengguna hak pilih dalam Daftar Pemilih Khusus (DPK) | D25: LK | E25: 0 | F25: 0 | G25: 0 | H25: 1 | I25: 0 | J25: 0 | K25: 0 | L25: 0 | M25: 0 | N25: 0 | O25: 0 | P25: 0 | Q25: 0 | R25: 0 | S25: 0 | T25: 1 | U25: 0 | V25: 1 | W25: =SUM(E25:V25) -> 3
D26: PR | E26: 0 | F26: 0 | G26: 0 | H26: 0 | I26: 0 | J26: 0 | K26: 0 | L26: 0 | M26: 0 | N26: 0 | O26: 0 | P26: 0 | Q26: 0 | R26: 0 | S26: 0 | T26: 0 | U26: 0 | V26: 1 | W26: =SUM(E26:V26) -> 1
D27: JML | E27: =SUM(E25:E26) -> 0 | F27: =SUM(F25:F26) -> 0 | G27: =SUM(G25:G26) -> 0 | H27: =SUM(H25:H26) -> 1 | I27: =SUM(I25:I26) -> 0 | J27: =SUM(J25:J26) -> 0 | K27: =SUM(K25:K26) -> 0 | L27: =SUM(L25:L26) -> 0 | ... V27: =SUM(V25:V26) -> 2 | W27: =SUM(E27:V27) -> 4
B28: 4. | C28: Jumlah Pengguna Hak Pilih (B.1+B.2+B.3) | D28: LK | E28: =SUM(E19,E22,E25) -> 118 | F28: =SUM(F19,F22,F25) -> 102 | G28: =SUM(G19,G22,G25) -> 113 | H28: =SUM(H19,H22,H25) -> 115 | I28: =SUM(I19,I22,I25) -> 85 | J28: =SUM(J19,J22,J25) -> 88 | K28: =SUM(K19,K22,K25) -> 106 | L28: =SUM(L19,L22,L25) -> 86 | ... V28: =SUM(V19,V22,V25) -> 69 | W28: =SUM(E28:V28) -> 1750
D29: PR | E29: =SUM(E20,E23,E26) -> 121 | F29: =SUM(F20,F23,F26) -> 123 | G29: =SUM(G20,G23,G26) -> 110 | H29: =SUM(H20,H23,H26) -> 113 | I29: =SUM(I20,I23,I26) -> 101 | J29: =SUM(J20,J23,J26) -> 91 | K29: =SUM(K20,K23,K26) -> 102 | L29: =SUM(L20,L23,L26) -> 97 | ... V29: =SUM(V20,V23,V26) -> 67 | W29: =SUM(E29:V29) -> 1894
D30: JML | E30: =SUM(E28:E29) -> 239 | F30: =SUM(F28:F29) -> 225 | G30: =SUM(G28:G29) -> 223 | H30: =SUM(H28:H29) -> 228 | I30: =SUM(I28:I29) -> 186 | J30: =SUM(J28:J29) -> 179 | K30: =SUM(K28:K29) -> 208 | L30: =SUM(L28:L29) -> 183 | ... V30: =SUM(V28:V29) -> 136 | W30: =SUM(E30:V30) -> 3644
A32: II | B32: DATA PENGGUNAAN SURAT SUARA
A33: 1 | B33: Jumlah surat suara yang diterima, termasuk surat suara cadangan 2,5% dari DPT | E33: 298 | F33: 304 | G33: 298 | H33: 296 | I33: 262 | J33: 231 | K33: 268 | L33: 250 | M33: 257 | N33: 268 | O33: 291 | P33: 290 | Q33: 286 | R33: 288 | S33: 282 | T33: 286 | U33: 236 | V33: 170 | W33: =SUM(E33:V33) -> 4861
A34: 2 | B34: Jumlah surat suara yang digunakan | E34: 239 | F34: 225 | G34: 223 | H34: 228 | I34: 186 | J34: 179 | K34: 208 | L34: 183 | M34: 182 | N34: 196 | O34: 210 | P34: 221 | Q34: 222 | R34: 210 | S34: 210 | T34: 227 | U34: 159 | V34: 136 | W34: =SUM(E34:V34) -> 3644
A35: 3 | B35: Jumlah surat suara dikembalikan oleh pemilih (karena rusak atau keliru coblos) | E35: 0 | F35: 0 | G35: 0 | H35: 0 | I35: 0 | J35: 0 | K35: 0 | L35: 0 | M35: 3 | N35: 0 | O35: 0 | P35: 0 | Q35: 0 | R35: 1 | S35: 1 | T35: 0 | U35: 0 | V35: 0 | W35: =SUM(E35:V35) -> 5
A36: 4 | B36: Jumlah surat suara yang tidak digunakan/tidak terpakai, termasuk sisa surat suara cadangan | E36: =E33-(E34+E35) -> 59 | F36: =F33-(F34+F35) -> 79 | G36: =G33-(G34+G35) -> 75 | H36: =H33-(H34+H35) -> 68 | I36: =I33-(I34+I35) -> 76 | J36: =J33-(J34+J35) -> 52 | K36: =K33-(K34+K35) -> 60 | L36: =L33-(L34+L35) -> 67 | ... V36: =V33-(V34+V35) -> 34 | W36: =SUM(E36:V36) -> 1212
A38: III | B38: DATA PEMILIH DISABILITAS
B39: Jumlah seluruh Pemilih disabilitas yang menggunakan hak pilih | D39: LK | E39: 0 | F39: 0 | G39: 0 | H39: 3 | I39: 0 | J39: 0 | K39: 3 | L39: 0 | M39: 0 | N39: 0 | O39: 0 | P39: 1 | Q39: 0 | R39: 2 | S39: 0 | T39: 1 | U39: 0 | V39: 0 | W39: =SUM(E39:V39) -> 10
D40: PR | E40: 0 | F40: 0 | G40: 0 | H40: 1 | I40: 1 | J40: 0 | K40: 1 | L40: 0 | M40: 0 | N40: 0 | O40: 0 | P40: 1 | Q40: 0 | R40: 1 | S40: 0 | T40: 1 | U40: 0 | V40: 0 | W40: =SUM(E40:V40) -> 6
D41: JML | E41: =SUM(E39:E40) -> 0 | F41: =SUM(F39:F40) -> 0 | G41: =SUM(G39:G40) -> 0 | H41: =SUM(H39:H40) -> 4 | I41: =SUM(I39:I40) -> 1 | J41: =SUM(J39:J40) -> 0 | K41: =SUM(K39:K40) -> 4 | L41: =SUM(L39:L40) -> 0 | ... V41: =SUM(V39:V40) -> 0 | W41: =SUM(E41:V41) -> 16
A43: IV | B43: DATA RINCIAN PEROLEHAN SUARA PASANGAN CALON BUPATI DAN WAKIL BUPATI
A44: NOMOR DAN NAMA CALON
A45: A.1 | B45: 1. | C45: Partai Kebangkitan Bangsa | E45: 4 | F45: 6 | G45: 5 | H45: 2 | I45: 11 | J45: 13 | K45: 15 | L45: 7 | M45: 10 | N45: 15 | O45: 2 | P45: 6 | Q45: 8 | R45: 6 | S45: 9 | T45: 5 | U45: 1 | V45: 0 | W45: =SUM(E45:V45) -> 125
A46: A.2 | B46: 1 | C46: 1. Dr. Hj. NIHAYATUL WAFIROH, M.A. | E46: 14 | F46: 29 | G46: 1 | H46: 29 | I46: 33 | J46: 26 | K46: 39 | L46: 16 | M46: 14 | N46: 13 | O46: 9 | P46: 6 | Q46: 8 | R46: 10 | S46: 13 | T46: 2 | U46: 2 | V46: 0 | W46: =SUM(E46:V46) -> 264
B47: 2 | C47: 2. H. M. NASIM KHAN | E47: 4 | F47: 4 | G47: 7 | H47: 4 | I47: 9 | J47: 2 | K47: 3 | L47: 5 | M47: 4 | N47: 2 | O47: 2 | P47: 5 | Q47: 3 | R47: 2 | S47: 8 | T47: 3 | U47: 1 | V47: 0 | W47: =SUM(E47:V47) -> 68
B48: 3 | C48: 3. Dr. H. AKIK ZAMAN, M.Pd.I. | E48: 1 | F48: 1 | G48: 0 | H48: 0 | I48: 1 | J48: 0 | K48: 1 | L48: 0 | M48: 0 | N48: 2 | O48: 0 | P48: 1 | Q48: 0 | R48: 0 | S48: 1 | T48: 1 | U48: 0 | V48: 1 | W48: =SUM(E48:V48) -> 10
B49: 4 | C49: 4. AHMAD RIFA'I, S.H. | E49: 0 | F49: 0 | G49: 1 | H49: 1 | I49: 0 | J49: 0 | K49: 1 | L49: 1 | M49: 0 | N49: 0 | O49: 2 | P49: 0 | Q49: 0 | R49: 0 | S49: 0 | T49: 1 | U49: 0 | V49: 0 | W49: =SUM(E49:V49) -> 7
B50: 5 | C50: 5. Drs. H. MAHFUD M.N. | E50: 0 | F50: 0 | G50: 0 | H50: 0 | I50: 0 | J50: 1 | K50: 3 | L50: 0 | M50: 0 | N50: 0 | O50: 1 | P50: 1 | Q50: 0 | R50: 0 | S50: 0 | T50: 0 | U50: 0 | V50: 0 | W50: =SUM(E50:V50) -> 6
B51: 6 | C51: 6. NURHAYATI, S.Pd. | E51: 0 | F51: 0 | G51: 0 | H51: 0 | I51: 0 | J51: 0 | K51: 0 | L51: 1 | M51: 0 | N51: 0 | O51: 0 | P51: 0 | Q51: 0 | R51: 0 | S51: 0 | T51: 0 | U51: 0 | V51: 0 | W51: =SUM(E51:V51) -> 1
...

Sheet BAYU
C2: Kecamatan
C3: Kabupaten | D3: BANYUWANGI
C4: Provinsi | D4: JAWA TIMUR
C9: Kelurahan
A12: I | B12: DATA PEMILIH DAN PENGGUNAAN HAK PILIH | AB12: JUMLAH AKHIR
A13: A | B13: DATA PEMILIH | E13: TPS 001 | F13: TPS 002 | G13: TPS 003 | H13: TPS 004 | I13: TPS 005 | J13: TPS 006 | K13: TPS 007 | L13: TPS 008 | M13: TPS 009 | N13: TPS 010 | O13: TPS 011 | P13: TPS 012 | Q13: TPS 013 | R13: TPS 014 | S13: TPS 015 | T13: TPS 016 | U13: TPS 017 | V13: TPS 018 | W13: TPS 019 | X13: TPS 020 | Y13: TPS 021 | Z13: TPS 022 | AA13: TPS 023
B14: Jumlah Pemilih dalam Daftar Pemilih Tetap (DPT) | D14: LK | E14: 109 | F14: 118 | G14: 129 | H14: 125 | I14: 117 | J14: 132 | K14: 139 | L14: 132 | M14: 137 | N14: 140 | O14: 139 | P14: 128 | Q14: 127 | R14: 131 | S14: 83 | T14: 133 | U14: 139 | V14: 149 | W14: 140 | X14: 152 | Y14: 150 | Z14: 150 | AA14: 147 | AB14: =SUM(E14:AA14) -> 3046
D15: PR | E15: 118 | F15: 140 | G15: 133 | H15: 136 | I15: 140 | J15: 123 | K15: 131 | L15: 146 | M15: 141 | N15: 148 | O15: 135 | P15: 134 | Q15: 123 | R15: 117 | S15: 94 | T15: 151 | U15: 147 | V15: 139 | W15: 151 | X15: 144 | Y15: 144 | Z15: 148 | AA15: 146 | AB15: =SUM(E15:AA15) -> 3129
D16: JML | E16: =SUM(E14:E15) -> 227 | F16: =SUM(F14:F15) -> 258 | G16: =SUM(G14:G15) -> 262 | H16: =SUM(H14:H15) -> 261 | I16: =SUM(I14:I15) -> 257 | J16: =SUM(J14:J15) -> 255 | K16: =SUM(K14:K15) -> 270 | L16: =SUM(L14:L15) -> 278 | ... AA16: =SUM(AA14:AA15) -> 293 | AB16: =SUM(E16:AA16) -> 6175
A18: B | B18: PENGGUNA HAK PILIH
B19: 1. | C19: Jumlah pengguna hak pilih dalam Daftar Pemilih Tetap (DPT) | D19: LK | E19: 95 | F19: 107 | G19: 92 | H19: 103 | I19: 96 | J19: 93 | K19: 100 | L19: 98 | M19: 94 | N19: 108 | O19: 97 | P19: 74 | Q19: 92 | R19: 100 | S19: 66 | T19: 83 | U19: 94 | V19: 103 | W19: 103 | X19: 122 | Y19: 117 | Z19: 121 | AA19: 108 | AB19: =SUM(E19:AA19) -> 2266
D20: PR | E20: 96 | F20: 87 | G20: 105 | H20: 107 | I20: 119 | J20: 106 | K20: 105 | L20: 117 | M20: 107 | N20: 120 | O20: 101 | P20: 88 | Q20: 93 | R20: 100 | S20: 81 | T20: 117 | U20: 116 | V20: 115 | W20: 120 | X20: 106 | Y20: 119 | Z20: 106 | AA20: 109 | AB20: =SUM(E20:AA20) -> 2440
D21: JML | E21: =SUM(E19:E20) -> 191 | F21: =SUM(F19:F20) -> 194 | G21: =SUM(G19:G20) -> 197 | H21: =SUM(H19:H20) -> 210 | I21: =SUM(I19:I20) -> 215 | J21: =SUM(J19:J20) -> 199 | K21: =SUM(K19:K20) -> 205 | L21: =SUM(L19:L20) -> 215 | ... AA21: =SUM(AA19:AA20) -> 217 | AB21: =SUM(E21:AA21) -> 4706
B22: 2. | C22: Jumlah pengguna hak pilih dalam Daftar Pemilih Tambahan (DPTb) | D22: LK | E22: 0 | F22: 0 | G22: 0 | H22: 0 | I22: 0 | J22: 0 | K22: 0 | L22: 0 | M22: 0 | N22: 0 | O22: 1 | P22: 0 | Q22: 0 | R22: 0 | S22: 0 | T22: 0 | U22: 0 | V22: 0 | W22: 0 | X22: 0 | Y22: 0 | Z22: 0 | AA22: 0 | AB22: =SUM(E22:AA22) -> 1
D23: PR | E23: 0 | F23: 0 | G23: 0 | H23: 0 | I23: 0 | J23: 0 | K23: 0 | L23: 0 | M23: 0 | N23: 0 | O23: 0 | P23: 0 | Q23: 0 | R23: 0 | S23: 0 | T23: 0 | U23: 0 | V23: 0 | W23: 0 | X23: 0 | Y23: 0 | Z23: 0 | AA23: 0 | AB23: =SUM(E23:AA23) -> 0
D24: JML | E24: =SUM(E22:E23) -> 0 | F24: =SUM(F22:F23) -> 0 | G24: =SUM(G22:G23) -> 0 | H24: =SUM(H22:H23) -> 0 | I24: =SUM(I22:I23) -> 0 | J24: =SUM(J22:J23) -> 0 | K24: =SUM(K22:K23) -> 0 | L24: =SUM(L22:L23) -> 0 | ... AA24: =SUM(AA22:AA23) -> 0 | AB24: =SUM(E24:AA24) -> 1
B25: 3. | C25: Jumlah pengguna hak pilih dalam Daftar Pemilih Khusus (DPK) | D25: LK | E25: 0 | F25: 0 | G25: 1 | H25: 3 | I25: 0 | J25: 0 | K25: 0 | L25: 0 | M25: 0 | N25: 0 | O25: 0 | P25: 0 | Q25: 0 | R25: 0 | S25: 1 | T25: 2 | U25: 1 | V25: 1 | W25: 0 | X25: 0 | Y25: 2 | Z25: 1 | AA25: 0 | AB25: =SUM(E25:AA25) -> 12
D26: PR | E26: 0 | F26: 0 | G26: 0 | H26: 1 | I26: 0 | J26: 0 | K26: 0 | L26: 1 | M26: 1 | N26: 1 | O26: 0 | P26: 0 | Q26: 0 | R26: 0 | S26: 1 | T26: 1 | U26: 0 | V26: 1 | W26: 1 | X26: 0 | Y26: 0 | Z26: 1 | AA26: 0 | AB26: =SUM(E26:AA26) -> 9
D27: JML | E27: =SUM(E25:E26) -> 0 | F27: =SUM(F25:F26) -> 0 | G27: =SUM(G25:G26) -> 1 | H27: =SUM(H25:H26) -> 4 | I27: =SUM(I25:I26) -> 0 | J27: =SUM(J25:J26) -> 0 | K27: =SUM(K25:K26) -> 0 | L27: =SUM(L25:L26) -> 1 | ... AA27: =SUM(AA25:AA26) -> 0 | AB27: =SUM(E27:AA27) -> 21
B28: 4. | C28: Jumlah Pengguna Hak Pilih (B.1+B.2+B.3) | D28: LK | E28: =SUM(E19,E22,E25) -> 95 | F28: =SUM(F19,F22,F25) -> 107 | G28: =SUM(G19,G22,G25) -> 93 | H28: =SUM(H19,H22,H25) -> 106 | I28: =SUM(I19,I22,I25) -> 96 | J28: =SUM(J19,J22,J25) -> 93 | K28: =SUM(K19,K22,K25) -> 100 | L28: =SUM(L19,L22,L25) -> 98 | ... AA28: =SUM(AA19,AA22,AA25) -> 108 | AB28: =SUM(E28:AA28) -> 2279
D29: PR | E29: =SUM(E20,E23,E26) -> 96 | F29: =SUM(F20,F23,F26) -> 87 | G29: =SUM(G20,G23,G26) -> 105 | H29: =SUM(H20,H23,H26) -> 108 | I29: =SUM(I20,I23,I26) -> 119 | J29: =SUM(J20,J23,J26) -> 106 | K29: =SUM(K20,K23,K26) -> 105 | L29: =SUM(L20,L23,L26) -> 118 | ... AA29: =SUM(AA20,AA23,AA26) -> 109 | AB29: =SUM(E29:AA29) -> 2449
D30: JML | E30: =SUM(E28:E29) -> 191 | F30: =SUM(F28:F29) -> 194 | G30: =SUM(G28:G29) -> 198 | H30: =SUM(H28:H29) -> 214 | I30: =SUM(I28:I29) -> 215 | J30: =SUM(J28:J29) -> 199 | K30: =SUM(K28:K29) -> 205 | L30: =SUM(L28:L29) -> 216 | ... AA30: =SUM(AA28:AA29) -> 217 | AB30: =SUM(E30:AA30) -> 4728
A32: II | B32: DATA PENGGUNAAN SURAT SUARA
A33: 1 | B33: Jumlah surat suara yang diterima, termasuk surat suara cadangan 2,5% dari DPT | E33: 222 | F33: 264 | G33: 270 | H33: 267 | I33: 263 | J33: 250 | K33: 276 | L33: 254 | M33: 284 | N33: 294 | O33: 280 | P33: 267 | Q33: 265 | R33: 243 | S33: 181 | T33: 290 | U33: 294 | V33: 285 | W33: 299 | X33: 293 | Y33: 301 | Z33: 273 | AA33: 299 | AB33: =SUM(E33:AA33) -> 6214
A34: 2 | B34: Jumlah surat suara yang digunakan | E34: 191 | F34: 194 | G34: 198 | H34: 214 | I34: 215 | J34: 199 | K34: 205 | L34: 216 | M34: 202 | N34: 229 | O34: 199 | P34: 162 | Q34: 185 | R34: 200 | S34: 149 | T34: 203 | U34: 211 | V34: 220 | W34: 224 | X34: 228 | Y34: 238 | Z34: 229 | AA34: 217 | AB34: =SUM(E34:AA34) -> 4728
A35: 3 | B35: Jumlah surat suara dikembalikan oleh pemilih (karena rusak atau keliru coblos) | E35: 0 | F35: 0 | G35: 2 | H35: 0 | I35: 1 | J35: 2 | K35: 0 | L35: 0 | M35: 0 | N35: 0 | O35: 0 | P35: 0 | Q35: 0 | R35: 0 | S35: 0 | T35: 0 | U35: 0 | V35: 0 | W35: 0 | X35: 0 | Y35: 0 | Z35: 0 | AA35: 1 | AB35: =SUM(E35:AA35) -> 6
A36: 4 | B36: Jumlah surat suara yang tidak digunakan/tidak terpakai, termasuk sisa surat suara cadangan | E36: =E33-(E34+E35) -> 31 | F36: =F33-(F34+F35) -> 70 | G36: =G33-(G34+G35) -> 70 | H36: =H33-(H34+H35) -> 53 | I36: =I33-(I34+I35) -> 47 | J36: =J33-(J34+J35) -> 49 | K36: =K33-(K34+K35) -> 71 | L36: =L33-(L34+L35) -> 38 | ... AA36: =AA33-(AA34+AA35) -> 81 | AB36: =SUM(E36:AA36) -> 1480
A38: III | B38: DATA PEMILIH DISABILITAS
B39: Jumlah seluruh Pemilih disabilitas yang menggunakan hak pilih | D39: LK | E39: 0 | F39: 0 | G39: 1 | H39: 0 | I39: 0 | J39: 0 | K39: 0 | L39: 0 | M39: 0 | N39: 0 | O39: 0 | P39: 0 | Q39: 0 | R39: 0 | S39: 0 | T39: 0 | V39: 0 | W39: 0 | X39: 0 | Y39: 0 | Z39: 0 | AA39: 0 | AB39: =SUM(E39:AA39) -> 1
D40: PR | E40: 0 | F40: 0 | G40: 0 | H40: 0 | I40: 0 | J40: 0 | K40: 0 | L40: 0 | M40: 0 | N40: 0 | O40: 0 | P40: 0 | Q40: 0 | R40: 0 | S40: 0 | T40: 0 | V40: 0 | W40: 0 | X40: 0 | Y40: 0 | Z40: 0 | AA40: 1 | AB40: =SUM(E40:AA40) -> 1
D41: JML | E41: =SUM(E39:E40) -> 0 | F41: =SUM(F39:F40) -> 0 | G41: =SUM(G39:G40) -> 1 | H41: =SUM(H39:H40) -> 0 | I41: =SUM(I39:I40) -> 0 | J41: =SUM(J39:J40) -> 0 | K41: =SUM(K39:K40) -> 0 | L41: =SUM(L39:L40) -> 0 | ... AA41: =SUM(AA39:AA40) -> 1 | AB41: =SUM(E41:AA41) -> 2
A43: IV | B43: DATA RINCIAN PEROLEHAN SUARA PASANGAN CALON BUPATI DAN WAKIL BUPATI
A44: NOMOR DAN NAMA CALON
A45: A.1 | B45: 1. | C45: Partai Kebangkitan Bangsa | E45: 2 | F45: 10 | G45: 4 | H45: 14 | I45: 13 | J45: 9 | K45: 3 | L45: 17 | M45: 8 | N45: 1 | O45: 2 | P45: 5 | Q45: 13 | R45: 5 | S45: 5 | T45: 12 | U45: 10 | V45: 15 | W45: 9 | X45: 5 | Y45: 6 | Z45: 9 | AA45: 7 | AB45: =SUM(E45:AA45) -> 184
A46: A.2 | B46: 1 | C46: 1. Dr. Hj. NIHAYATUL WAFIROH, M.A. | E46: 1 | F46: 21 | G46: 5 | H46: 21 | I46: 28 | J46: 8 | K46: 3 | L46: 9 | M46: 10 | N46: 8 | O46: 5 | P46: 11 | Q46: 13 | R46: 13 | S46: 5 | T46: 18 | U46: 22 | V46: 25 | W46: 16 | X46: 14 | Y46: 5 | Z46: 6 | AA46: 13 | AB46: =SUM(E46:AA46) -> 280
B47: 2 | C47: 2. H. M. NASIM KHAN | E47: 0 | F47: 2 | G47: 4 | H47: 8 | I47: 5 | J47: 0 | K47: 2 | L47: 6 | M47: 5 | N47: 0 | O47: 3 | P47: 6 | Q47: 5 | R47: 5 | S47: 4 | T47: 1 | U47: 4 | V47: 2 | W47: 2 | X47: 1 | Y47: 1 | Z47: 0 | AA47: 2 | AB47: =SUM(E47:AA47) -> 68
B48: 3 | C48: 3. Dr. H. AKIK ZAMAN, M.Pd.I. | E48: 1 | F48: 0 | G48: 0 | H48: 2 | I48: 2 | J48: 0 | K48: 1 | L48: 0 | M48: 3 | N48: 0 | O48: 2 | P48: 1 | Q48: 1 | R48: 1 | S48: 0 | T48: 0 | U48: 1 | V48: 1 | W48: 0 | X48: 0 | Y48: 0 | Z48: 0 | AA48: 0 | AB48: =SUM(E48:AA48) -> 16
B49: 4 | C49: 4. AHMAD RIFA'I, S.H. | E49: 1 | F49: 0 | G49: 0 | H49: 1 | I49: 3 | J49: 1 | K49: 2 | L49: 1 | M49: 2 | N49: 3 | O49: 0 | P49: 1 | Q49: 1 | R49: 0 | S49: 0 | U49: 0 | V49: 2 | W49: 1 | X49: 9 | Y49: 6 | Z49: 1 | AA49: 0 | AB49: =SUM(E49:AA49) -> 35
B50: 5 | C50: 5. Drs. H. MAHFUD M.N. | E50: 1 | F50: 1 | G50: 0 | H50: 0 | I50: 0 | J50: 0 | K50: 0 | L50: 0 | M50: 0 | N50: 0 | O50: 0 | P50: 0 | Q50: 1 | R50: 0 | S50: 1 | U50: 1 | V50: 1 | W50: 0 | X50: 0 | Y50: 0 | Z50: 1 | AA50: 1 | AB50: =SUM(E50:AA50) -> 8
B51: 6 | C51: 6. NURHAYATI, S.Pd. | E51: 0 | G51: 0 | H51: 0 | I51: 0 | J51: 0 | K51: 0 | L51: 0 | M51: 1 | N51: 0 | O51: 1 | P51: 0 | Q51: 0 | R51: 0 | S51: 0 | V51: 0 | W51: 0 | X51: 0 | Y51: 1 | Z51: 1 | AA51: 0 | AB51: =SUM(E51:AA51) -> 4
...

Sheet SUMBERARUM
C2: Kecamatan
C3: Kabupaten | D3: BANYUWANGI
C4: Provinsi | D4: JAWA TIMUR
C9: Kelurahan
A12: I | B12: DATA PEMILIH DAN PENGGUNAAN HAK PILIH | X12: JUMLAH AKHIR
A13: A | B13: DATA PEMILIH | E13: TPS 001 | F13: TPS 002 | G13: TPS 003 | H13: TPS 004 | I13: TPS 005 | J13: TPS 006 | K13: TPS 007 | L13: TPS 008 | M13: TPS 009 | N13: TPS 010 | O13: TPS 011 | P13: TPS 012 | Q13: TPS 013 | R13: TPS 014 | S13: TPS 015 | T13: TPS 016 | U13: TPS 017 | V13: TPS 018 | W13: TPS 019
B14: Jumlah Pemilih dalam Daftar Pemilih Tetap (DPT) | D14: LK | E14: 141 | F14: 142 | G14: 143 | H14: 153 | I14: 149 | J14: 150 | K14: 144 | L14: 146 | M14: 145 | N14: 141 | O14: 79 | P14: 83 | Q14: 82 | R14: 83 | S14: 141 | T14: 129 | U14: 154 | V14: 101 | W14: 141 | X14: =SUM(E14:W14) -> 2447
D15: PR | E15: 141 | F15: 154 | G15: 147 | H15: 140 | I15: 142 | J15: 145 | K15: 148 | L15: 150 | M15: 149 | N15: 127 | O15: 84 | P15: 90 | Q15: 87 | R15: 89 | S15: 151 | T15: 157 | U15: 145 | V15: 112 | W15: 155 | X15: =SUM(E15:W15) -> 2513
D16: JML | E16: =SUM(E14:E15) -> 282 | F16: =SUM(F14:F15) -> 296 | G16: =SUM(G14:G15) -> 290 | H16: =SUM(H14:H15) -> 293 | I16: =SUM(I14:I15) -> 291 | J16: =SUM(J14:J15) -> 295 | K16: =SUM(K14:K15) -> 292 | L16: =SUM(L14:L15) -> 296 | ... W16: =SUM(W14:W15) -> 296 | X16: =SUM(E16:W16) -> 4960
A18: B | B18: PENGGUNA HAK PILIH
B19: 1. | C19: Jumlah pengguna hak pilih dalam Daftar Pemilih Tetap (DPT) | D19: LK | E19: 104 | F19: 109 | G19: 106 | H19: 110 | I19: 113 | J19: 117 | K19: 95 | L19: 120 | M19: 117 | N19: 102 | O19: 63 | P19: 64 | Q19: 69 | R19: 70 | S19: 123 | T19: 98 | U19: 119 | V19: 78 | W19: 83 | X19: =SUM(E19:W19) -> 1860
D20: PR | E20: 115 | F20: 123 | G20: 123 | H20: 116 | I20: 120 | J20: 112 | K20: 110 | L20: 122 | M20: 116 | N20: 101 | O20: 72 | P20: 79 | Q20: 73 | R20: 80 | S20: 136 | T20: 128 | U20: 108 | V20: 89 | W20: 104 | X20: =SUM(E20:W20) -> 2027
D21: JML | E21: =SUM(E19:E20) -> 219 | F21: =SUM(F19:F20) -> 232 | G21: =SUM(G19:G20) -> 229 | H21: =SUM(H19:H20) -> 226 | I21: =SUM(I19:I20) -> 233 | J21: =SUM(J19:J20) -> 229 | K21: =SUM(K19:K20) -> 205 | L21: =SUM(L19:L20) -> 242 | ... W21: =SUM(W19:W20) -> 187 | X21: =SUM(E21:W21) -> 3887
