Workbook

Sheet DPR RI
C8: Kecamatan | D8: KALIBARU
C9: Kabupaten | D9: BANYUWANGI
C10: Provinsi | D10: JAWA TIMUR
A12: I | B12: DATA PEMILIH DAN PENGGUNAAN HAK PILIH | E12: JUMLAH AKHIR
A13: A | B13: DATA PEMILIH
B14: Jumlah Pemilih dalam Daftar Pemilih Tetap (DPT) | D14: LK | E14: =BANYUANYAR!AF14+KAJARHARJO!AY14+'KALIBARU KULON'!AF14+'KALIBARU MANIS'!AK14+'KALIBARU WETAN'!AU14+KEBONREJO!AJ14 -> 25420
D15: PR | E15: =BANYUANYAR!AF15+KAJARHARJO!AY15+'KALIBARU KULON'!AF15+'KALIBARU MANIS'!AK15+'KALIBARU WETAN'!AU15+KEBONREJO!AJ15 -> 25995
D16: JML | E16: =SUM(E14:E15) -> 51415
A18: B | B18: PENGGUNA HAK PILIH
B19: 1. | C19: Jumlah pengguna hak pilih dalam Daftar Pemilih Tetap (DPT) | D19: LK | E19: =BANYUANYAR!AF19+KAJARHARJO!AY19+'KALIBARU KULON'!AF19+'KALIBARU MANIS'!AK19+'KALIBARU WETAN'!AU19+KEBONREJO!AJ19 -> 18395
D20: PR | E20: =BANYUANYAR!AF20+KAJARHARJO!AY20+'KALIBARU KULON'!AF20+'KALIBARU MANIS'!AK20+'KALIBARU WETAN'!AU20+KEBONREJO!AJ20 -> 20512
D21: JML | E21: =SUM(E19:E20) -> 38907
B22: 2. | C22: Jumlah pengguna hak pilih dalam Daftar Pemilih Tambahan (DPTb) | D22: LK | E22: =BANYUANYAR!AF22+KAJARHARJO!AY22+'KALIBARU KULON'!AF22+'KALIBARU MANIS'!AK22+'KALIBARU WETAN'!AU22+KEBONREJO!AJ22 -> 116
D23: PR | E23: =BANYUANYAR!AF23+KAJARHARJO!AY23+'KALIBARU KULON'!AF23+'KALIBARU MANIS'!AK23+'KALIBARU WETAN'!AU23+KEBONREJO!AJ23 -> 92
D24: JML | E24: =SUM(E22:E23) -> 208
B25: 3. | C25: Jumlah pengguna hak pilih dalam Daftar Pemilih Khusus (DPK) | D25: LK | E25: =BANYUANYAR!AF25+KAJARHARJO!AY25+'KALIBARU KULON'!AF25+'KALIBARU MANIS'!AK25+'KALIBARU WETAN'!AU25+KEBONREJO!AJ25 -> 192
D26: PR | E26: =BANYUANYAR!AF26+KAJARHARJO!AY26+'KALIBARU KULON'!AF26+'KALIBARU MANIS'!AK26+'KALIBARU WETAN'!AU26+KEBONREJO!AJ26 -> 218
D27: JML | E27: =SUM(E25:E26) -> 410
B28: 4. | C28: Jumlah Pengguna Hak Pilih (B.1+B.2+B.3) | D28: LK | E28: =E19+E22+E25 -> 18703
D29: PR | E29: =E20+E23+E26 -> 20822
D30: JML | E30: =SUM(E28:E29) -> 39525
A32: II | B32: DATA PENGGUNAAN SURAT SUARA
A33: 1 | B33: Jumlah surat suara yang diterima, termasuk surat suara cadangan 2,5% dari DPT | E33: =BANYUANYAR!AF33+KAJARHARJO!AY33+'KALIBARU KULON'!AF33+'KALIBARU MANIS'!AK33+'KALIBARU WETAN'!AU33+KEBONREJO!AJ33 -> 52556
A34: 2 | B34: Jumlah surat suara yang digunakan | E34: =BANYUANYAR!AF34+KAJARHARJO!AY34+'KALIBARU KULON'!AF34+'KALIBARU MANIS'!AK34+'KALIBARU WETAN'!AU34+KEBONREJO!AJ34 -> 39525
A35: 3 | B35: Jumlah surat suara dikembalikan oleh pemilih (karena rusak atau keliru coblos) | E35: =BANYUANYAR!AF35+KAJARHARJO!AY35+'KALIBARU KULON'!AF35+'KALIBARU MANIS'!AK35+'KALIBARU WETAN'!AU35+KEBONREJO!AJ35 -> 125
A36: 4 | B36: Jumlah surat suara yang tidak digunakan/tidak terpakai, termasuk sisa surat suara cadangan | E36: =E33-(E34+E35) -> 12906
A38: III | B38: DATA PEMILIH DISABILITAS
B39: Jumlah seluruh Pemilih disabilitas yang menggunakan hak pilih | D39: LK | E39: =BANYUANYAR!AF39+KAJARHARJO!AY39+'KALIBARU KULON'!AF39+'KALIBARU MANIS'!AK39+'KALIBARU WETAN'!AU39+KEBONREJO!AJ39 -> 56
D40: PR | E40: =BANYUANYAR!AF40+KAJARHARJO!AY40+'KALIBARU KULON'!AF40+'KALIBARU MANIS'!AK40+'KALIBARU WETAN'!AU40+KEBONREJO!AJ40 -> 55
D41: JML | E41: =SUM(E39:E40) -> 111
A43: IV | B43: DATA RINCIAN PEROLEHAN SUARA PASANGAN CALON BUPATI DAN WAKIL BUPATI
A44: NOMOR DAN NAMA CALON
A45: A.1 | B45: 1. | C45: Partai Kebangkitan Bangsa | E45: =BANYUANYAR!AF45+KAJARHARJO!AY45+'KALIBARU KULON'!AF45+'KALIBARU MANIS'!AK45+'KALIBARU WETAN'!AU45+KEBONREJO!AJ45 -> 1129
A46: A.2 | B46: 1 | C46: 1. Dr. Hj. NIHAYATUL WAFIROH, M.A. | E46: =BANYUANYAR!AF46+KAJARHARJO!AY46+'KALIBARU KULON'!AF46+'KALIBARU MANIS'!AK46+'KALIBARU WETAN'!AU46+KEBONREJO!AJ46 -> 3062
B47: 2 | C47: 2. H. M. NASIM KHAN | E47: =BANYUANYAR!AF47+KAJARHARJO!AY47+'KALIBARU KULON'!AF47+'KALIBARU MANIS'!AK47+'KALIBARU WETAN'!AU47+KEBONREJO!AJ47 -> 675
B48: 3 | C48: 3. Dr. H. AKIK ZAMAN, M.Pd.I. | E48: =BANYUANYAR!AF48+KAJARHARJO!AY48+'KALIBARU KULON'!AF48+'KALIBARU MANIS'!AK48+'KALIBARU WETAN'!AU48+KEBONREJO!AJ48 -> 431
B49: 4 | C49: 4. AHMAD RIFA'I, S.H. | E49: =BANYUANYAR!AF49+KAJARHARJO!AY49+'KALIBARU KULON'!AF49+'KALIBARU MANIS'!AK49+'KALIBARU WETAN'!AU49+KEBONREJO!AJ49 -> 112
B50: 5 | C50: 5. Drs. H. MAHFUD M.N. | E50: =BANYUANYAR!AF50+KAJARHARJO!AY50+'KALIBARU KULON'!AF50+'KALIBARU MANIS'!AK50+'KALIBARU WETAN'!AU50+KEBONREJO!AJ50 -> 104
B51: 6 | C51: 6. NURHAYATI, S.Pd. | E51: =BANYUANYAR!AF51+KAJARHARJO!AY51+'KALIBARU KULON'!AF51+'KALIBARU MANIS'!AK51+'KALIBARU WETAN'!AU51+KEBONREJO!AJ51 -> 30
B52: 7 | C52: 7. MAFTUHA KISWAH | E52: =BANYUANYAR!AF52+KAJARHARJO!AY52+'KALIBARU KULON'!AF52+'KALIBARU MANIS'!AK52+'KALIBARU WETAN'!AU52+KEBONREJO!AJ52 -> 18
...

Sheet BANYUANYAR
C2: Kecamatan | D2: KALIBARU
C3: Kabupaten | D3: BANYUWANGI
C4: Provinsi | D4: JAWA TIMUR
C9: Kelurahan | D9: BANYUANYAR
A12: I | B12: DATA PEMILIH DAN PENGGUNAAN HAK PILIH | AF12: JUMLAH AKHIR
A13: A | B13: DATA PEMILIH | E13: TPS 001 | F13: TPS 002 | G13: TPS 003 | H13: TPS 004 | I13: TPS 005 | J13: TPS 006 | K13: TPS 007 | L13: TPS 008 | M13: TPS 009 | N13: TPS 010 | O13: TPS 011 | P13: TPS 012 | Q13: TPS 013 | R13: TPS 014 | S13: TPS 015 | T13: TPS 016 | U13: TPS 017 | V13: TPS 018 | W13: TPS 019 | X13: TPS 020 | Y13: TPS 021 | Z13: TPS 022 | AA13: TPS 023 | AB13: TPS 024 | AC13: TPS 025 | AD13: TPS 026 | AE13: TPS 027
B14: Jumlah Pemilih dalam Daftar Pemilih Tetap (DPT) | D14: LK | E14: 132 | F14: 144 | G14: 127 | H14: 133 | I14: 128 | J14: 153 | K14: 138 | L14: 139 | M14: 144 | N14: 151 | O14: 120 | P14: 109 | Q14: 156 | R14: 137 | S14: 148 | T14: 139 | U14: 108 | V14: 59 | W14: 148 | X14: 85 | Y14: 68 | Z14: 124 | AA14: 90 | AB14: 116 | AC14: 137 | AD14: 100 | AE14: 93 | AF14: =SUM(E14:AE14) -> 3326
D15: PR | E15: 159 | F15: 140 | G15: 142 | H15: 148 | I15: 125 | J15: 145 | K15: 136 | L15: 130 | M15: 133 | N15: 139 | O15: 137 | P15: 114 | Q15: 122 | R15: 154 | S15: 134 | T15: 145 | U15: 101 | V15: 59 | W15: 136 | X15: 90 | Y15: 68 | Z15: 112 | AA15: 92 | AB15: 110 | AC15: 126 | AD15: 91 | AE15: 85 | AF15: =SUM(E15:AE15) -> 3273
D16: JML | E16: =SUM(E14:E15) -> 291 | F16: =SUM(F14:F15) -> 284 | G16: =SUM(G14:G15) -> 269 | H16: =SUM(H14:H15) -> 281 | I16: =SUM(I14:I15) -> 253 | J16: =SUM(J14:J15) -> 298 | K16: =SUM(K14:K15) -> 274 | L16: =SUM(L14:L15) -> 269 | ... AE16: =SUM(AE14:AE15) -> 178 | AF16: =SUM(E16:AE16) -> 6599
A18: B | B18: PENGGUNA HAK PILIH
B19: 1. | C19: Jumlah pengguna hak pilih dalam Daftar Pemilih Tetap (DPT) | D19: LK | E19: 114 | F19: 116 | G19: 106 | H19: 104 | I19: 85 | J19: 113 | K19: 107 | L19: 110 | M19: 106 | N19: 115 | O19: 91 | P19: 95 | Q19: 124 | R19: 115 | S19: 115 | T19: 107 | U19: 80 | V19: 43 | W19: 105 | X19: 60 | Y19: 54 | Z19: 88 | AA19: 66 | AB19: 93 | AC19: 101 | AD19: 77 | AE19: 65 | AF19: =SUM(E19:AE19) -> 2555
D20: PR | E20: 125 | F20: 117 | G20: 118 | H20: 116 | I20: 97 | J20: 117 | K20: 116 | L20: 112 | M20: 106 | N20: 118 | O20: 111 | P20: 107 | Q20: 108 | R20: 128 | S20: 112 | T20: 121 | U20: 87 | V20: 51 | W20: 105 | X20: 70 | Y20: 55 | Z20: 94 | AA20: 77 | AB20: 92 | AC20: 98 | AD20: 89 | AE20: 72 | AF20: =SUM(E20:AE20) -> 2719
D21: JML | E21: =SUM(E19:E20) -> 239 | F21: =SUM(F19:F20) -> 233 | G21: =SUM(G19:G20) -> 224 | H21: =SUM(H19:H20) -> 220 | I21: =SUM(I19:I20) -> 182 | J21: =SUM(J19:J20) -> 230 | K21: =SUM(K19:K20) -> 223 | L21: =SUM(L19:L20) -> 222 | ... AE21: =SUM(AE19:AE20) -> 137 | AF21: =SUM(E21:AE21) -> 5274
B22: 2. | C22: Jumlah pengguna hak pilih dalam Daftar Pemilih Tambahan (DPTb) | D22: LK | E22: 0 | F22: 0 | G22: 0 | H22: 0 | I22: 0 | J22: 0 | K22: 1 | L22: 0 | M22: 0 | N22: 1 | O22: 0 | P22: 0 | Q22: 0 | R22: 1 | S22: 0 | T22: 0 | U22: 0 | V22: 1 | W22: 1 | X22: 2 | Y22: 1 | Z22: 1 | AA22: 1 | AB22: 0 | AC22: 1 | AD22: 1 | AE22: 0 | AF22: =SUM(E22:AE22) -> 12
D23: PR | E23: 1 | F23: 2 | G23: 1 | H23: 1 | I23: 1 | J23: 1 | K23: 0 | L23: 1 | M23: 1 | N23: 0 | O23: 1 | P23: 1 | Q23: 1 | R23: 0 | S23: 1 | T23: 1 | U23: 1 | V23: 0 | W23: 0 | X23: 1 | Y23: 0 | Z23: 0 | AA23: 0 | AB23: 1 | AC23: 0 | AD23: 0 | AE23: 2 | AF23: =SUM(E23:AE23) -> 19
D24: JML | E24: =SUM(E22:E23) -> 1 | F24: =SUM(F22:F23) -> 2 | G24: =SUM(G22:G23) -> 1 | H24: =SUM(H22:H23) -> 1 | I24: =SUM(I22:I23) -> 1 | J24: =SUM(J22:J23) -> 1 | K24: =SUM(K22:K23) -> 1 | L24: =SUM(L22:L23) -> 1 | ... AE24: =SUM(AE22:AE23) -> 2 | AF24: =SUM(E24:AE24) -> 31
B25: 3. | C25: Jumlah pengguna hak pilih dalam Daftar Pemilih Khusus (DPK) | D25: LK | E25: 3 | F25: 0 | G25: 1 | H25: 0 | I25: 0 | J25: 0 | K25: 0 | L25: 0 | M25: 0 | N25: 1 | O25: 0 | P25: 0 | Q25: 0 | R25: 0 | S25: 0 | T25: 1 | U25: 0 | V25: 0 | W25: 0 | X25: 0 | Y25: 0 | Z25: 0 | AA25: 2 | AB25: 0 | AC25: 0 | AD25: 1 | AE25: 1 | AF25: =SUM(E25:AE25) -> 10
D26: PR | E26: 0 | F26: 0 | G26: 2 | H26: 0 | I26: 0 | J26: 2 | K26: 1 | L26: 0 | M26: 0 | N26: 1 | O26: 0 | P26: 0 | Q26: 0 | R26: 1 | S26: 1 | T26: 1 | U26: 0 | V26: 1 | W26: 0 | X26: 0 | Y26: 0 | Z26: 0 | AA26: 1 | AB26: 0 | AC26: 0 | AD26: 0 | AE26: 3 | AF26: =SUM(E26:AE26) -> 14
D27: JML | E27: =SUM(E25:E26) -> 3 | F27: =SUM(F25:F26) -> 0 | G27: =SUM(G25:G26) -> 3 | H27: =SUM(H25:H26) -> 0 | I27: =SUM(I25:I26) -> 0 | J27: =SUM(J25:J26) -> 2 | K27: =SUM(K25:K26) -> 1 | L27: =SUM(L25:L26) -> 0 | ... AE27: =SUM(AE25:AE26) -> 4 | AF27: =SUM(E27:AE27) -> 24
B28: 4. | C28: Jumlah Pengguna Hak Pilih (B.1+B.2+B.3) | D28: LK | E28: =SUM(E19,E22,E25) -> 117 | F28: =SUM(F19,F22,F25) -> 116 | G28: =SUM(G19,G22,G25) -> 107 | H28: =SUM(H19,H22,H25) -> 104 | I28: =SUM(I19,I22,I25) -> 85 | J28: =SUM(J19,J22,J25) -> 113 | K28: =SUM(K19,K22,K25) -> 108 | L28: =SUM(L19,L22,L25) -> 110 | ... AE28: =SUM(AE19,AE22,AE25) -> 66 | AF28: =SUM(E28:AE28) -> 2577
D29: PR | E29: =SUM(E20,E23,E26) -> 126 | F29: =SUM(F20,F23,F26) -> 119 | G29: =SUM(G20,G23,G26) -> 121 | H29: =SUM(H20,H23,H26) -> 117 | I29: =SUM(I20,I23,I26) -> 98 | J29: =SUM(J20,J23,J26) -> 120 | K29: =SUM(K20,K23,K26) -> 117 | L29: =SUM(L20,L23,L26) -> 113 | ... AE29: =SUM(AE20,AE23,AE26) -> 77 | AF29: =SUM(E29:AE29) -> 2752
D30: JML | E30: =SUM(E28:E29) -> 243 | F30: =SUM(F28:F29) -> 235 | G30: =SUM(G28:G29) -> 228 | H30: =SUM(H28:H29) -> 221 | I30: =SUM(I28:I29) -> 183 | J30: =SUM(J28:J29) -> 233 | K30: =SUM(K28:K29) -> 225 | L30: =SUM(L28:L29) -> 223 | ... AE30: =SUM(AE28:AE29) -> 143 | AF30: =SUM(E30:AE30) -> 5329
A32: II | B32: DATA PENGGUNAAN SURAT SUARA
A33: 1 | B33: Jumlah surat suara yang diterima, termasuk surat suara cadangan 2,5% dari DPT | E33: 304 | F33: 290 | G33: 271 | H33: 287 | I33: 260 | J33: 315 | K33: 290 | L33: 275 | M33: 282 | N33: 296 | O33: 263 | P33: 228 | Q33: 284 | R33: 298 | S33: 288 | T33: 292 | U33: 214 | V33: 121 | W33: 290 | X33: 179 | Y33: 139 | Z33: 241 | AA33: 186 | AB33: 229 | AC33: 269 | AD33: 195 | AE33: 182 | AF33: =SUM(E33:AE33) -> 6768
A34: 2 | B34: Jumlah surat suara yang digunakan | E34: 243 | F34: 235 | G34: 228 | H34: 221 | I34: 183 | J34: 233 | K34: 225 | L34: 223 | M34: 213 | N34: 236 | O34: 203 | P34: 203 | Q34: 233 | R34: 245 | S34: 229 | T34: 231 | U34: 168 | V34: 96 | W34: 211 | X34: 133 | Y34: 110 | Z34: 183 | AA34: 147 | AB34: 186 | AC34: 200 | AD34: 168 | AE34: 143 | AF34: =SUM(E34:AE34) -> 5329
A35: 3 | B35: Jumlah surat suara dikembalikan oleh pemilih (karena rusak atau keliru coblos) | E35: 1 | F35: 0 | G35: 0 | H35: 0 | I35: 0 | J35: 0 | K35: 0 | L35: 0 | M35: 0 | N35: 0 | O35: 0 | P35: 0 | Q35: 1 | R35: 1 | S35: 2 | T35: 2 | U35: 0 | V35: 0 | W35: 1 | X35: 0 | Y35: 0 | Z35: 0 | AA35: 0 | AB35: 0 | AC35: 0 | AD35: 1 | AE35: 1 | AF35: =SUM(E35:AE35) -> 10
A36: 4 | B36: Jumlah surat suara yang tidak digunakan/tidak terpakai, termasuk sisa surat suara cadangan | E36: =E33-(E34+E35) -> 60 | F36: =F33-(F34+F35) -> 55 | G36: =G33-(G34+G35) -> 43 | H36: =H33-(H34+H35) -> 66 | I36: =I33-(I34+I35) -> 77 | J36: =J33-(J34+J35) -> 82 | K36: =K33-(K34+K35) -> 65 | L36: =L33-(L34+L35) -> 52 | ... AE36: =AE33-(AE34+AE35) -> 38 | AF36: =SUM(E36:AE36) -> 1429
A38: III | B38: DATA PEMILIH DISABILITAS
B39: Jumlah seluruh Pemilih disabilitas yang menggunakan hak pilih | D39: LK | E39: 0 | F39: 0 | G39: 1 | H39: 0 | I39: 0 | J39: 0 | K39: 0 | L39: 0 | M39: 0 | N39: 0 | O39: 1 | P39: 0 | Q39: 0 | R39: 0 | S39: 1 | T39: 0 | U39: 0 | V39: 0 | W39: 1 | X39: 0 | Y39: 0 | Z39: 1 | AA39: 0 | AB39: 0 | AC39: 1 | AD39: 0 | AE39: 0 | AF39: =SUM(E39:AE39) -> 6
D40: PR | E40: 1 | F40: 0 | G40: 0 | H40: 0 | I40: 0 | J40: 0 | K40: 0 | L40: 0 | M40: 0 | N40: 0 | O40: 0 | P40: 0 | Q40: 0 | R40: 0 | S40: 0 | T40: 0 | U40: 0 | V40: 0 | W40: 0 | X40: 0 | Y40: 0 | Z40: 0 | AA40: 0 | AB40: 0 | AC40: 0 | AD40: 0 | AE40: 0 | AF40: =SUM(E40:AE40) -> 1
D41: JML | E41: =SUM(E39:E40) -> 1 | F41: =SUM(F39:F40) -> 0 | G41: =SUM(G39:G40) -> 1 | H41: =SUM(H39:H40) -> 0 | I41: =SUM(I39:I40) -> 0 | J41: =SUM(J39:J40) -> 0 | K41: =SUM(K39:K40) -> 0 | L41: =SUM(L39:L40) -> 0 | ... AE41: =SUM(AE39:AE40) -> 0 | AF41: =SUM(E41:AE41) -> 7
A43: IV | B43: DATA RINCIAN PEROLEHAN SUARA PASANGAN CALON BUPATI DAN WAKIL BUPATI
A44: NOMOR DAN NAMA CALON
A45: A.1 | B45: 1. | C45: Partai Kebangkitan Bangsa | E45: 9 | F45: 8 | G45: 17 | H45: 8 | I45: 5 | J45: 14 | K45: 15 | L45: 5 | M45: 3 | N45: 5 | O45: 13 | P45: 2 | Q45: 12 | R45: 8 | S45: 14 | T45: 5 | U45: 5 | V45: 0 | W45: 6 | X45: 2 | Y45: 1 | Z45: 0 | AA45: 1 | AB45: 0 | AC45: 1 | AD45: 8 | AE45: 4 | AF45: =SUM(E45:AE45) -> 171
A46: A.2 | B46: 1 | C46: 1. Dr. Hj. NIHAYATUL WAFIROH, M.A. | E46: 8 | F46: 15 | G46: 19 | H46: 22 | I46: 11 | J46: 80 | K46: 22 | L46: 33 | M46: 10 | N46: 24 | O46: 24 | P46: 3 | Q46: 40 | R46: 50 | S46: 54 | T46: 18 | U46: 14 | V46: 5 | W46: 4 | X46: 4 | Y46: 3 | Z46: 9 | AA46: 5 | AB46: 4 | AC46: 3 | AD46: 16 | AE46: 9 | AF46: =SUM(E46:AE46) -> 509
B47: 2 | C47: 2. H. M. NASIM KHAN | E47: 3 | F47: 5 | G47: 8 | H47: 2 | I47: 6 | J47: 6 | K47: 4 | L47: 4 | M47: 3 | N47: 2 | O47: 2 | P47: 0 | Q47: 3 | R47: 0 | S47: 0 | T47: 1 | U47: 3 | V47: 0 | W47: 0 | X47: 0 | Y47: 1 | Z47: 1 | AA47: 0 | AB47: 0 | AC47: 0 | AD47: 0 | AE47: 0 | AF47: =SUM(E47:AE47) -> 54
B48: 3 | C48: 3. Dr. H. AKIK ZAMAN, M.Pd.I. | E48: 1 | F48: 0 | G48: 3 | H48: 3 | I48: 2 | J48: 2 | K48: 3 | L48: 0 | M48: 2 | N48: 4 | O48: 0 | P48: 0 | Q48: 6 | R48: 5 | S48: 28 | T48: 33 | U48: 59 | V48: 11 | W48: 10 | X48: 0 | Y48: 0 | Z48: 0 | AA48: 1 | AB48: 0 | AC48: 0 | AD48: 0 | AE48: 0 | AF48: =SUM(E48:AE48) -> 173
B49: 4 | C49: 4. AHMAD RIFA'I, S.H. | E49: 2 | F49: 0 | G49: 1 | H49: 0 | I49: 0 | J49: 0 | K49: 2 | L49: 0 | M49: 0 | N49: 0 | O49: 0 | P49: 1 | Q49: 0 | R49: 0 | S49: 1 | T49: 1 | U49: 0 | V49: 0 | W49: 0 | X49: 1 | Y49: 0 | Z49: 0 | AA49: 0 | AB49: 0 | AC49: 1 | AD49: 0 | AE49: 0 | AF49: =SUM(E49:AE49) -> 10
B50: 5 | C50: 5. Drs. H. MAHFUD M.N. | E50: 0 | F50: 0 | G50: 0 | H50: 1 | I50: 0 | J50: 0 | K50: 2 | L50: 0 | M50: 1 | N50: 2 | O50: 0 | P50: 0 | Q50: 0 | R50: 1 | S50: 0 | T50: 1 | U50: 0 | V50: 0 | W50: 0 | X50: 0 | Y50: 0 | Z50: 0 | AA50: 2 | AB50: 0 | AC50: 0 | AD50: 1 | AE50: 3 | AF50: =SUM(E50:AE50) -> 14
B51: 6 | C51: 6. NURHAYATI, S.Pd. | E51: 1 | F51: 0 | G51: 0 | H51: 0 | I51: 1 | J51: 0 | K51: 0 | L51: 0 | M51: 0 | N51: 0 | O51: 0 | P51: 0 | Q51: 0 | R51: 0 | S51: 0 | T51: 0 | U51: 0 | V51: 0 | W51: 0 | X51: 0 | Y51: 0 | Z51: 0 | AA51: 0 | AB51: 0 | AC51: 0 | AD51: 0 | AE51: 0 | AF51: =SUM(E51:AE51) -> 2
...

Sheet KAJARHARJO
C2: Kecamatan | D2: KALIBARU
C3: Kabupaten | D3: BANYUWANGI
C4: Provinsi | D4: JAWA TIMUR
C9: Kelurahan | D9: KAJARHARJO
A12: I | B12: DATA PEMILIH DAN PENGGUNAAN HAK PILIH | AY12: JUMLAH AKHIR
A13: A | B13: DATA PEMILIH | E13: TPS 001 | F13: TPS 002 | G13: TPS 003 | H13: TPS 004 | I13: TPS 005 | J13: TPS 006 | K13: TPS 007 | L13: TPS 008 | M13: TPS 009 | N13: TPS 010 | O13: TPS 011 | P13: TPS 012 | Q13: TPS 013 | R13: TPS 014 | S13: TPS 015 | T13: TPS 016 | U13: TPS 017 | V13: TPS 018 | W13: TPS 019 | X13: TPS 020 | Y13: TPS 021 | Z13: TPS 022 | AA13: TPS 023 | AB13: TPS 024 | AC13: TPS 025 | AD13: TPS 026 | AE13: TPS 027 | AF13: TPS 028 | AG13: TPS 029 | AH13: TPS 030 | AI13: TPS 031 | AJ13: TPS 032 | AK13: TPS 033 | AL13: TPS 034 | AM13: TPS 035 | AN13: TPS 036 | AO13: TPS 037 | AP13: TPS 038 | AQ13: TPS 039 | AR13: TPS 040 | AS13: TPS 041 | AT13: TPS 042 | AU13: TPS 043 | AV13: TPS 044 | AW13: TPS 045 | AX13: TPS 046
B14: Jumlah Pemilih dalam Daftar Pemilih Tetap (DPT) | D14: LK | E14: 141 | F14: 140 | G14: 111 | H14: 122 | I14: 125 | J14: 111 | K14: 135 | L14: 141 | M14: 153 | N14: 142 | O14: 127 | P14: 144 | Q14: 124 | R14: 126 | S14: 116 | T14: 132 | U14: 89 | V14: 132 | W14: 111 | X14: 142 | Y14: 118 | Z14: 127 | AA14: 149 | AB14: 142 | AC14: 125 | AD14: 92 | AE14: 122 | AF14: 129 | AG14: 91 | AH14: 99 | AI14: 86 | AJ14: 65 | AK14: 81 | AL14: 93 | AM14: 68 | AN14: 92 | AO14: 103 | AP14: 143 | AQ14: 98 | AR14: 105 | AS14: 134 | AT14: 113 | AU14: 128 | AV14: 136 | AW14: 86 | AX14: 93 | AY14: =SUM(E14:AX14) -> 5382
D15: PR | E15: 141 | F15: 142 | G15: 104 | H15: 127 | I15: 114 | J15: 125 | K15: 129 | L15: 156 | M15: 139 | N15: 132 | O15: 141 | P15: 150 | Q15: 127 | R15: 134 | S15: 118 | T15: 145 | U15: 94 | V15: 139 | W15: 127 | X15: 154 | Y15: 109 | Z15: 140 | AA15: 148 | AB15: 150 | AC15: 128 | AD15: 99 | AE15: 144 | AF15: 121 | AG15: 96 | AH15: 104 | AI15: 88 | AJ15: 72 | AK15: 86 | AL15: 90 | AM15: 60 | AN15: 98 | AO15: 96 | AP15: 150 | AQ15: 110 | AR15: 115 | AS15: 109 | AT15: 140 | AU15: 125 | AV15: 128 | AW15: 92 | AX15: 88 | AY15: =SUM(E15:AX15) -> 5524
D16: JML | E16: =SUM(E14:E15) -> 282 | F16: =SUM(F14:F15) -> 282 | G16: =SUM(G14:G15) -> 215 | H16: =SUM(H14:H15) -> 249 | I16: =SUM(I14:I15) -> 239 | J16: =SUM(J14:J15) -> 236 | K16: =SUM(K14:K15) -> 264 | L16: =SUM(L14:L15) -> 297 | ... AX16: =SUM(AX14:AX15) -> 181 | AY16: =SUM(E16:AX16) -> 10906
A18: B | B18: PENGGUNA HAK PILIH
B19: 1. | C19: Jumlah pengguna hak pilih dalam Daftar Pemilih Tetap (DPT) | D19: LK | E19: 92 | F19: 98 | G19: 89 | H19: 90 | I19: 87 | J19: 84 | K19: 104 | L19: 108 | M19: 115 | N19: 106 | O19: 101 | P19: 113 | Q19: 95 | R19: 103 | S19: 92 | T19: 91 | U19: 65 | V19: 92 | W19: 77 | X19: 108 | Y19: 87 | Z19: 92 | AA19: 119 | AB19: 104 | AC19: 73 | AD19: 53 | AE19: 85 | AF19: 74 | AG19: 56 | AH19: 52 | AI19: 53 | AJ19: 42 | AK19: 69 | AL19: 63 | AM19: 50 | AN19: 67 | AO19: 73 | AP19: 112 | AQ19: 74 | AR19: 82 | AS19: 108 | AT19: 69 | AU19: 77 | AV19: 89 | AW19: 63 | AX19: 80 | AY19: =SUM(E19:AX19) -> 3876
D20: PR | E20: 114 | F20: 116 | G20: 84 | H20: 106 | I20: 97 | J20: 100 | K20: 108 | L20: 123 | M20: 110 | N20: 100 | O20: 113 | P20: 118 | Q20: 108 | R20: 109 | S20: 97 | T20: 106 | U20: 75 | V20: 104 | W20: 94 | X20: 125 | Y20: 96 | Z20: 108 | AA20: 121 | AB20: 116 | AC20: 101 | AD20: 79 | AE20: 113 | AF20: 92 | AG20: 82 | AH20: 76 | AI20: 70 | AJ20: 57 | AK20: 56 | AL20: 70 | AM20: 54 | AN20: 78 | AO20: 77 | AP20: 127 | AQ20: 85 | AR20: 102 | AS20: 83 | AT20: 101 | AU20: 91 | AV20: 105 | AW20: 76 | AX20: 76 | AY20: =SUM(E20:AX20) -> 4399
D21: JML | E21: =SUM(E19:E20) -> 206 | F21: =SUM(F19:F20) -> 214 | G21: =SUM(G19:G20) -> 173 | H21: =SUM(H19:H20) -> 196 | I21: =SUM(I19:I20) -> 184 | J21: =SUM(J19:J20) -> 184 | K21: =SUM(K19:K20) -> 212 | L21: =SUM(L19:L20) -> 231 | ... AX21: =SUM(AX19:AX20) -> 156 | AY21: =SUM(E21:AX21) -> 8275
B22: 2. | C22: Jumlah pengguna hak pilih dalam Daftar Pemilih Tambahan (DPTb) | D22: LK | E22: 0 | F22: 0 | G22: 0 | H22: 2 | I22: 0 | J22: 0 | K22: 1 | L22: 1 | M22: 0 | N22: 0 | O22: 1 | P22: 1 | Q22: 2 | R22: 1 | S22: 1 | T22: 0 | U22: 0 | V22: 0 | W22: 3 | X22: 0 | Y22: 0 | Z22: 0 | AA22: 1 | AB22: 1 | AC22: 0 | AD22: 1 | AE22: 0 | AF22: 0 | AG22: 1 | AH22: 1 | AI22: 3 | AJ22: 1 | AK22: 1 | AL22: 2 | AM22: 3 | AN22: 1 | AO22: 2 | AP22: 2 | AQ22: 2 | AR22: 1 | AS22: 0 | AT22: 1 | AU22: 1 | AV22: 1 | AW22: 1 | AX22: 1 | AY22: =SUM(E22:AX22) -> 41
D23: PR | E23: 2 | F23: 1 | G23: 1 | H23: 0 | I23: 1 | J23: 1 | K23: 0 | L23: 0 | M23: 1 | N23: 1 | O23: 0 | P23: 0 | Q23: 0 | R23: 0 | S23: 0 | T23: 1 | U23: 1 | V23: 1 | W23: 1 | X23: 0 | Y23: 1 | Z23: 1 | AA23: 0 | AB23: 0 | AC23: 1 | AD23: 2 | AE23: 1 | AF23: 1 | AG23: 0 | AH23: 0 | AI23: 1 | AJ23: 0 | AK23: 0 | AL23: 0 | AM23: 0 | AN23: 1 | AO23: 0 | AP23: 0 | AQ23: 0 | AR23: 0 | AS23: 1 | AT23: 0 | AU23: 1 | AV23: 0 | AW23: 0 | AX23: 0 | AY23: =SUM(E23:AX23) -> 23
D24: JML | E24: =SUM(E22:E23) -> 2 | F24: =SUM(F22:F23) -> 1 | G24: =SUM(G22:G23) -> 1 | H24: =SUM(H22:H23) -> 2 | I24: =SUM(I22:I23) -> 1 | J24: =SUM(J22:J23) -> 1 | K24: =SUM(K22:K23) -> 1 | L24: =SUM(L22:L23) -> 1 | ... AX24: =SUM(AX22:AX23) -> 1 | AY24: =SUM(E24:AX24) -> 64
B25: 3. | C25: Jumlah pengguna hak pilih dalam Daftar Pemilih Khusus (DPK) | D25: LK | E25: 1 | F25: 0 | G25: 2 | H25: 1 | I25: 2 | J25: 0 | K25: 2 | L25: 2 | M25: 0 | N25: 2 | O25: 0 | P25: 1 | Q25: 1 | R25: 0 | S25: 0 | T25: 1 | U25: 1 | V25: 2 | W25: 1 | X25: 3 | Y25: 2 | Z25: 1 | AA25: 0 | AB25: 0 | AC25: 0 | AD25: 0 | AE25: 1 | AF25: 0 | AG25: 0 | AH25: 0 | AI25: 1 | AJ25: 1 | AK25: 2 | AL25: 0 | AM25: 0 | AN25: 2 | AO25: 0 | AP25: 1 | AQ25: 0 | AR25: 1 | AS25: 2 | AT25: 0 | AU25: 0 | AV25: 0 | AW25: 0 | AX25: 4 | AY25: =SUM(E25:AX25) -> 40
D26: PR | E26: 1 | F26: 0 | G26: 5 | H26: 1 | I26: 4 | J26: 0 | K26: 1 | L26: 2 | M26: 0 | N26: 2 | O26: 1 | P26: 0 | Q26: 1 | R26: 2 | S26: 0 | T26: 1 | U26: 1 | V26: 3 | W26: 2 | X26: 1 | Y26: 0 | Z26: 0 | AA26: 0 | AB26: 0 | AC26: 0 | AD26: 0 | AE26: 0 | AF26: 0 | AG26: 0 | AH26: 0 | AI26: 2 | AJ26: 0 | AK26: 1 | AL26: 0 | AM26: 0 | AN26: 0 | AO26: 0 | AP26: 0 | AQ26: 0 | AR26: 2 | AS26: 6 | AT26: 0 | AU26: 0 | AV26: 0 | AW26: 0 | AX26: 4 | AY26: =SUM(E26:AX26) -> 43
D27: JML | E27: =SUM(E25:E26) -> 2 | F27: =SUM(F25:F26) -> 0 | G27: =SUM(G25:G26) -> 7 | H27: =SUM(H25:H26) -> 2 | I27: =SUM(I25:I26) -> 6 | J27: =SUM(J25:J26) -> 0 | K27: =SUM(K25:K26) -> 3 | L27: =SUM(L25:L26) -> 4 | ... AX27: =SUM(AX25:AX26) -> 8 | AY27: =SUM(E27:AX27) -> 83
B28: 4. | C28: Jumlah Pengguna Hak Pilih (B.1+B.2+B.3) | D28: LK | E28: =SUM(E19,E22,E25) -> 93 | F28: =SUM(F19,F22,F25) -> 98 | G28: =SUM(G19,G22,G25) -> 91 | H28: =SUM(H19,H22,H25) -> 93 | I28: =SUM(I19,I22,I25) -> 89 | J28: =SUM(J19,J22,J25) -> 84 | K28: =SUM(K19,K22,K25) -> 107 | L28: =SUM(L19,L22,L25) -> 111 | ... AX28: =SUM(AX19,AX22,AX25) -> 85 | AY28: =SUM(E28:AX28) -> 3957
D29: PR | E29: =SUM(E20,E23,E26) -> 117 | F29: =SUM(F20,F23,F26) -> 117 | G29: =SUM(G20,G23,G26) -> 90 | H29: =SUM(H20,H23,H26) -> 107 | I29: =SUM(I20,I23,I26) -> 102 | J29: =SUM(J20,J23,J26) -> 101 | K29: =SUM(K20,K23,K26) -> 109 | L29: =SUM(L20,L23,L26) -> 125 | ... AX29: =SUM(AX20,AX23,AX26) -> 80 | AY29: =SUM(E29:AX29) -> 4465
D30: JML | E30: =SUM(E28:E29) -> 210 | F30: =SUM(F28:F29) -> 215 | G30: =SUM(G28:G29) -> 181 | H30: =SUM(H28:H29) -> 200 | I30: =SUM(I28:I29) -> 191 | J30: =SUM(J28:J29) -> 185 | K30: =SUM(K28:K29) -> 216 | L30: =SUM(L28:L29) -> 236 | ... AX30: =SUM(AX28:AX29) -> 165 | AY30: =SUM(E30:AX30) -> 8422
A32: II | B32: DATA PENGGUNAAN SURAT SUARA
A33: 1 | B33: Jumlah surat suara yang diterima, termasuk surat suara cadangan 2,5% dari DPT | E33: 288 | F33: 288 | G33: 220 | H33: 254 | I33: 245 | J33: 240 | K33: 270 | L33: 303 | M33: 298 | N33: 280 | O33: 274 | P33: 300 | Q33: 257 | R33: 266 | S33: 239 | T33: 273 | U33: 187 | V33: 277 | W33: 243 | X33: 302 | Y33: 232 | Z33: 275 | AA33: 303 | AB33: 298 | AC33: 259 | AD33: 195 | AE33: 272 | AF33: 255 | AG33: 191 | AH33: 208 | AI33: 178 | AJ33: 140 | AK33: 171 | AL33: 188 | AM33: 131 | AN33: 194 | AO33: 202 | AP33: 299 | AQ33: 213 | AR33: 225 | AS33: 248 | AT33: 259 | AU33: 259 | AV33: 270 | AW33: 182 | AX33: 185 | AY33: =SUM(E33:AX33) -> 11136
A34: 2 | B34: Jumlah surat suara yang digunakan | E34: 210 | F34: 215 | G34: 181 | H34: 200 | I34: 191 | J34: 185 | K34: 216 | L34: 236 | M34: 226 | N34: 211 | O34: 216 | P34: 233 | Q34: 207 | R34: 215 | S34: 190 | T34: 200 | U34: 143 | V34: 202 | W34: 178 | X34: 237 | Y34: 186 | Z34: 202 | AA34: 241 | AB34: 221 | AC34: 175 | AD34: 135 | AE34: 200 | AF34: 167 | AG34: 139 | AH34: 129 | AI34: 130 | AJ34: 101 | AK34: 129 | AL34: 135 | AM34: 107 | AN34: 149 | AO34: 152 | AP34: 242 | AQ34: 161 | AR34: 188 | AS34: 200 | AT34: 171 | AU34: 170 | AV34: 195 | AW34: 140 | AX34: 165 | AY34: =SUM(E34:AX34) -> 8422
A35: 3 | B35: Jumlah surat suara dikembalikan oleh pemilih (karena rusak atau keliru coblos) | E35: 0 | F35: 0 | G35: 2 | H35: 1 | I35: 0 | J35: 0 | K35: 0 | L35: 0 | M35: 1 | N35: 1 | O35: 0 | P35: 4 | Q35: 2 | R35: 1 | S35: 0 | T35: 1 | U35: 0 | V35: 0 | W35: 0 | X35: 0 | Y35: 0 | Z35: 0 | AA35: 0 | AB35: 0 | AC35: 0 | AD35: 0 | AE35: 3 | AF35: 0 | AG35: 1 | AH35: 0 | AI35: 0 | AJ35: 0 | AK35: 0 | AL35: 0 | AM35: 1 | AN35: 0 | AO35: 0 | AP35: 0 | AQ35: 0 | AR35: 0 | AS35: 0 | AT35: 0 | AU35: 1 | AV35: 0 | AW35: 0 | AX35: 0 | AY35: =SUM(E35:AX35) -> 19
A36: 4 | B36: Jumlah surat suara yang tidak digunakan/tidak terpakai, termasuk sisa surat suara cadangan | E36: =E33-(E34+E35) -> 78 | F36: =F33-(F34+F35) -> 73 | G36: =G33-(G34+G35) -> 37 | H36: =H33-(H34+H35) -> 53 | I36: =I33-(I34+I35) -> 54 | J36: =J33-(J34+J35) -> 55 | K36: =K33-(K34+K35) -> 54 | L36: =L33-(L34+L35) -> 67 | ... AX36: =AX33-(AX34+AX35) -> 20 | AY36: =SUM(E36:AX36) -> 2695
A38: III | B38: DATA PEMILIH DISABILITAS
B39: Jumlah seluruh Pemilih disabilitas yang menggunakan hak pilih | D39: LK | E39: 0 | F39: 0 | G39: 0 | H39: 0 | I39: 0 | J39: 0 | K39: 0 | L39: 1 | M39: 0 | N39: 0 | O39: 0 | P39: 0 | Q39: 2 | R39: 0 | S39: 0 | T39: 0 | U39: 0 | V39: 0 | W39: 0 | X39: 0 | Y39: 0 | Z39: 1 | AA39: 0 | AB39: 0 | AC39: 0 | AD39: 0 | AE39: 0 | AF39: 0 | AG39: 0 | AH39: 0 | AI39: 0 | AJ39: 0 | AK39: 1 | AL39: 0 | AM39: 0 | AN39: 0 | AO39: 0 | AP39: 0 | AQ39: 0 | AR39: 0 | AS39: 0 | AT39: 0 | AU39: 0 | AV39: 0 | AW39: 0 | AX39: 0 | AY39: =SUM(E39:AX39) -> 5
D40: PR | E40: 0 | F40: 0 | G40: 0 | H40: 0 | I40: 0 | J40: 0 | K40: 0 | L40: 0 | M40: 0 | N40: 0 | O40: 0 | P40: 0 | Q40: 3 | R40: 0 | S40: 0 | T40: 0 | U40: 0 | V40: 0 | W40: 0 | X40: 0 | Y40: 0 | Z40: 1 | AA40: 0 | AB40: 0 | AC40: 0 | AD40: 0 | AE40: 0 | AF40: 0 | AG40: 0 | AH40: 0 | AI40: 0 | AJ40: 0 | AK40: 2 | AL40: 0 | AM40: 0 | AN40: 0 | AO40: 0 | AP40: 0 | AQ40: 0 | AR40: 0 | AS40: 1 | AT40: 0 | AU40: 0 | AV40: 0 | AW40: 0 | AX40: 0 | AY40: =SUM(E40:AX40) -> 7
D41: JML | E41: =SUM(E39:E40) -> 0 | F41: =SUM(F39:F40) -> 0 | G41: =SUM(G39:G40) -> 0 | H41: =SUM(H39:H40) -> 0 | I41: =SUM(I39:I40) -> 0 | J41: =SUM(J39:J40) -> 0 | K41: =SUM(K39:K40) -> 0 | L41: =SUM(L39:L40) -> 1 | ... AX41: =SUM(AX39:AX40) -> 0 | AY41: =SUM(E41:AX41) -> 12
A43: IV | B43: DATA RINCIAN PEROLEHAN SUARA PASANGAN CALON BUPATI DAN WAKIL BUPATI
A44: NOMOR DAN NAMA CALON
A45: A.1 | B45: 1. | C45: Partai Kebangkitan Bangsa | E45: 4 | F45: 7 | G45: 7 | H45: 5 | I45: 3 | J45: 1 | K45: 3 | L45: 9 | M45: 15 | N45: 13 | O45: 17 | P45: 13 | Q45: 15 | R45: 14 | S45: 2 | T45: 3 | U45: 8 | V45: 11 | W45: 7 | X45: 15 | Y45: 5 | Z45: 7 | AA45: 3 | AB45: 10 | AC45: 8 | AD45: 3 | AE45: 9 | AF45: 4 | AG45: 4 | AH45: 2 | AI45: 4 | AJ45: 0 | AK45: 4 | AL45: 8 | AM45: 3 | AN45: 9 | AO45: 2 | AP45: 2 | AQ45: 5 | AR45: 3 | AS45: 2 | AT45: 5 | AU45: 4 | AV45: 2 | AW45: 2 | AX45: 3 | AY45: =SUM(E45:AX45) -> 285
A46: A.2 | B46: 1 | C46: 1. Dr. Hj. NIHAYATUL WAFIROH, M.A. | E46: 18 | F46: 34 | G46: 19 | H46: 15 | I46: 5 | J46: 8 | K46: 4 | L46: 14 | M46: 44 | N46: 41 | O46: 59 | P46: 35 | Q46: 78 | R46: 59 | S46: 35 | T46: 21 | U46: 8 | V46: 14 | W46: 13 | X46: 34 | Y46: 25 | Z46: 11 | AA46: 16 | AB46: 17 | AC46: 24 | AD46: 5 | AE46: 11 | AF46: 8 | AG46: 11 | AH46: 12 | AI46: 9 | AJ46: 10 | AK46: 15 | AL46: 6 | AM46: 11 | AN46: 24 | AO46: 2 | AP46: 3 | AQ46: 5 | AR46: 35 | AS46: 15 | AT46: 8 | AU46: 8 | AV46: 11 | AW46: 5 | AX46: 1 | AY46: =SUM(E46:AX46) -> 866
B47: 2 | C47: 2. H. M. NASIM KHAN | E47: 0 | F47: 6 | G47: 1 | H47: 3 | I47: 0 | J47: 1 | K47: 3 | L47: 3 | M47: 3 | N47: 0 | O47: 1 | P47: 5 | Q47: 4 | R47: 1 | S47: 3 | T47: 0 | U47: 31 | V47: 2 | W47: 0 | X47: 2 | Y47: 2 | Z47: 2 | AA47: 15 | AB47: 7 | AC47: 5 | AD47: 4 | AE47: 3 | AF47: 8 | AG47: 8 | AH47: 7 | AI47: 2 | AJ47: 2 | AK47: 1 | AL47: 4 | AM47: 4 | AN47: 2 | AO47: 0 | AP47: 2 | AQ47: 1 | AR47: 3 | AS47: 1 | AT47: 0 | AU47: 1 | AV47: 0 | AW47: 1 | AX47: 0 | AY47: =SUM(E47:AX47) -> 154
B48: 3 | C48: 3. Dr. H. AKIK ZAMAN, M.Pd.I. | E48: 1 | F48: 2 | G48: 0 | H48: 7 | I48: 3 | J48: 1 | K48: 1 | L48: 1 | M48: 3 | N48: 1 | O48: 0 | P48: 1 | Q48: 1 | R48: 1 | S48: 9 | T48: 4 | U48: 1 | V48: 0 | W48: 3 | X48: 1 | Y48: 2 | Z48: 6 | AA48: 4 | AB48: 3 | AC48: 5 | AD48: 0 | AE48: 5 | AF48: 0 | AG48: 1 | AH48: 2 | AI48: 1 | AJ48: 5 | AK48: 4 | AL48: 2 | AM48: 0 | AN48: 1 | AO48: 1 | AP48: 0 | AQ48: 0 | AR48: 0 | AS48: 0 | AT48: 0 | AU48: 0 | AV48: 0 | AW48: 0 | AX48: 1 | AY48: =SUM(E48:AX48) -> 84
B49: 4 | C49: 4. AHMAD RIFA'I, S.H. | E49: 1 | F49: 3 | G49: 0 | H49: 1 | I49: 0 | J49: 0 | K49: 0 | L49: 1 | M49: 0 | N49: 0 | O49: 1 | P49: 0 | Q49: 3 | R49: 0 | S49: 1 | T49: 1 | U49: 0 | V49: 2 | W49: 0 | X49: 0 | Y49: 1 | Z49: 0 | AA49: 0 | AB49: 0 | AC49: 0 | AD49: 1 | AE49: 2 | AF49: 1 | AG49: 1 | AH49: 0 | AI49: 1 | AJ49: 0 | AK49: 0 | AL49: 2 | AM49: 0 | AN49: 0 | AO49: 0 | AP49: 0 | AQ49: 0 | AR49: 0 | AS49: 0 | AT49: 1 | AU49: 1 | AV49: 0 | AW49: 0 | AX49: 0 | AY49: =SUM(E49:AX49) -> 25
B50: 5 | C50: 5. Drs. H. MAHFUD M.N. | E50: 1 | F50: 1 | G50: 0 | H50: 1 | I50: 0 | J50: 0 | K50: 3 | L50: 0 | M50: 0 | N50: 1 | O50: 0 | P50: 0 | Q50: 0 | R50: 0 | S50: 1 | T50: 1 | U50: 0 | V50: 0 | W50: 0 | X50: 1 | Y50: 1 | Z50: 0 | AA50: 0 | AB50: 0 | AC50: 0 | AD50: 2 | AE50: 0 | AF50: 0 | AG50: 0 | AH50: 4 | AI50: 1 | AJ50: 1 | AK50: 0 | AL50: 2 | AM50: 1 | AN50: 3 | AO50: 0 | AP50: 0 | AQ50: 0 | AR50: 0 | AS50: 0 | AT50: 0 | AU50: 1 | AV50: 0 | AW50: 0 | AX50: 0 | AY50: =SUM(E50:AX50) -> 26
B51: 6 | C51: 6. NURHAYATI, S.Pd. | E51: 1 | F51: 0 | G51: 0 | H51: 0 | I51: 0 | J51: 0 | K51: 0 | L51: 0 | M51: 0 | N51: 0 | O51: 0 | P51: 0 | Q51: 0 | R51: 1 | S51: 0 | T51: 0 | U51: 0 | V51: 0 | W51: 0 | X51: 1 | Y51: 0 | Z51: 0 | AA51: 0 | AB51: 1 | AC51: 0 | AD51: 0 | AE51: 0 | AF51: 0 | AG51: 0 | AH51: 0 | AI51: 0 | AJ51: 0 | AK51: 0 | AL51: 1 | AM51: 0 | AN51: 1 | AO51: 0 | AP51: 0 | AQ51: 1 | AR51: 0 | AS51: 0 | AT51: 0 | AU51: 1 | AV51: 0 | AW51: 0 | AX51: 0 | AY51: =SUM(E51:AX51) -> 8
...

Sheet KALIBARU KULON
C2: Kecamatan | D2: KALIBARU
C3: Kabupaten | D3: BANYUWANGI
C4: Provinsi | D4: JAWA TIMUR
C9: Kelurahan | D9: KALIBARU KULON
A12: I | B12: DATA PEMILIH DAN PENGGUNAAN HAK PILIH | AF12: JUMLAH AKHIR
A13: A | B13: DATA PEMILIH | E13: TPS 001 | F13: TPS 002 | G13: TPS 003 | H13: TPS 004 | I13: TPS 005 | J13: TPS 006 | K13: TPS 007 | L13: TPS 008 | M13: TPS 009 | N13: TPS 010 | O13: TPS 011 | P13: TPS 012 | Q13: TPS 013 | R13: TPS 014 | S13: TPS 015 | T13: TPS 016 | U13: TPS 017 | V13: TPS 018 | W13: TPS 019 | X13: TPS 020 | Y13: TPS 021 | Z13: TPS 022 | AA13: TPS 023 | AB13: TPS 024 | AC13: TPS 025 | AD13: TPS 026 | AE13: TPS 027
B14: Jumlah Pemilih dalam Daftar Pemilih Tetap (DPT) | D14: LK | E14: 121 | F14: 105 | G14: 122 | H14: 112 | I14: 100 | J14: 104 | K14: 131 | L14: 115 | M14: 115 | N14: 128 | O14: 137 | P14: 129 | Q14: 142 | R14: 95 | S14: 65 | T14: 145 | U14: 118 | V14: 104 | W14: 104 | X14: 138 | Y14: 100 | Z14: 153 | AA14: 91 | AB14: 98 | AC14: 74 | AD14: 140 | AE14: 125 | AF14: =SUM(E14:AE14) -> 3111
D15: PR | E15: 124 | F15: 131 | G15: 126 | H15: 114 | I15: 113 | J15: 102 | K15: 136 | L15: 139 | M15: 108 | N15: 141 | O15: 146 | P15: 121 | Q15: 157 | R15: 106 | S15: 58 | T15: 153 | U15: 108 | V15: 119 | W15: 113 | X15: 143 | Y15: 104 | Z15: 143 | AA15: 97 | AB15: 95 | AC15: 77 | AD15: 155 | AE15: 136 | AF15: =SUM(E15:AE15) -> 3265
D16: JML | E16: =SUM(E14:E15) -> 245 | F16: =SUM(F14:F15) -> 236 | G16: =SUM(G14:G15) -> 248 | H16: =SUM(H14:H15) -> 226 | I16: =SUM(I14:I15) -> 213 | J16: =SUM(J14:J15) -> 206 | K16: =SUM(K14:K15) -> 267 | L16: =SUM(L14:L15) -> 254 | ... AE16: =SUM(AE14:AE15) -> 261 | AF16: =SUM(E16:AE16) -> 6376
A18: B | B18: PENGGUNA HAK PILIH
B19: 1. | C19: Jumlah pengguna hak pilih dalam Daftar Pemilih Tetap (DPT) | D19: LK | E19: 90 | F19: 86 | G19: 102 | H19: 88 | I19: 76 | J19: 80 | K19: 96 | L19: 85 | M19: 89 | N19: 80 | O19: 96 | P19: 94 | Q19: 103 | R19: 84 | S19: 49 | T19: 101 | U19: 88 | V19: 77 | W19: 87 | X19: 98 | Y19: 75 | Z19: 116 | AA19: 71 | AB19: 65 | AC19: 48 | AD19: 103 | AE19: 82 | AF19: =SUM(E19:AE19) -> 2309
D20: PR | E20: 99 | F20: 110 | G20: 102 | H20: 95 | I20: 94 | J20: 87 | K20: 105 | L20: 118 | M20: 91 | N20: 105 | O20: 108 | P20: 93 | Q20: 118 | R20: 92 | S20: 46 | T20: 136 | U20: 95 | V20: 86 | W20: 91 | X20: 113 | Y20: 83 | Z20: 111 | AA20: 76 | AB20: 76 | AC20: 59 | AD20: 127 | AE20: 117 | AF20: =SUM(E20:AE20) -> 2633
D21: JML | E21: =SUM(E19:E20) -> 189 | F21: =SUM(F19:F20) -> 196 | G21: =SUM(G19:G20) -> 204 | H21: =SUM(H19:H20) -> 183 | I21: =SUM(I19:I20) -> 170 | J21: =SUM(J19:J20) -> 167 | K21: =SUM(K19:K20) -> 201 | L21: =SUM(L19:L20) -> 203 | ... AE21: =SUM(AE19:AE20) -> 199 | AF21: =SUM(E21:AE21) -> 4942
B22: 2. | C22: Jumlah pengguna hak pilih dalam Daftar Pemilih Tambahan (DPTb) | D22: LK | E22: 1 | F22: 0 | G22: 1 | H22: 0 | I22: 0 | J22: 0 | K22: 1 | L22: 1 | M22: 0 | N22: 0 | O22: 0 | P22: 0 | Q22: 0 | R22: 0 | S22: 0 | T22: 0 | U22: 0 | V22: 1 | W22: 0 | X22: 0 | Y22: 1 | Z22: 0 | AA22: 0 | AB22: 0 | AC22: 0 | AD22: 0 | AE22: 1 | AF22: =SUM(E22:AE22) -> 7
D23: PR | E23: 0 | F23: 1 | G23: 0 | H23: 0 | I23: 0 | J23: 0 | K23: 0 | L23: 0 | M23: 0 | N23: 0 | O23: 1 | P23: 1 | Q23: 0 | R23: 0 | S23: 1 | T23: 1 | U23: 0 | V23: 1 | W23: 0 | X23: 0 | Y23: 0 | Z23: 0 | AA23: 0 | AB23: 1 | AC23: 0 | AD23: 0 | AE23: 0 | AF23: =SUM(E23:AE23) -> 7
D24: JML | E24: =SUM(E22:E23) -> 1 | F24: =SUM(F22:F23) -> 1 | G24: =SUM(G22:G23) -> 1 | H24: =SUM(H22:H23) -> 0 | I24: =SUM(I22:I23) -> 0 | J24: =SUM(J22:J23) -> 0 | K24: =SUM(K22:K23) -> 1 | L24: =SUM(L22:L23) -> 1 | ... AE24: =SUM(AE22:AE23) -> 1 | AF24: =SUM(E24:AE24) -> 14
B25: 3. | C25: Jumlah pengguna hak pilih dalam Daftar Pemilih Khusus (DPK) | D25: LK | E25: 7 | F25: 2 | G25: 1 | H25: 2 | I25: 4 | J25: 2 | K25: 1 | L25: 1 | M25: 1 | N25: 3 | O25: 1 | P25: 1 | Q25: 4 | R25: 1 | S25: 2 | T25: 1 | U25: 1 | V25: 2 | W25: 3 | X25: 0 | Y25: 1 | Z25: 3 | AA25: 5 | AB25: 2 | AC25: 2 | AD25: 2 | AE25: 0 | AF25: =SUM(E25:AE25) -> 55
D26: PR | E26: 7 | F26: 2 | G26: 1 | H26: 2 | I26: 4 | J26: 1 | K26: 5 | L26: 1 | M26: 0 | N26: 1 | O26: 1 | P26: 2 | Q26: 4 | R26: 3 | S26: 5 | T26: 1 | U26: 2 | V26: 5 | W26: 2 | X26: 0 | Y26: 0 | Z26: 4 | AA26: 5 | AB26: 2 | AC26: 2 | AD26: 2 | AE26: 0 | AF26: =SUM(E26:AE26) -> 64
D27: JML | E27: =SUM(E25:E26) -> 14 | F27: =SUM(F25:F26) -> 4 | G27: =SUM(G25:G26) -> 2 | H27: =SUM(H25:H26) -> 4 | I27: =SUM(I25:I26) -> 8 | J27: =SUM(J25:J26) -> 3 | K27: =SUM(K25:K26) -> 6 | L27: =SUM(L25:L26) -> 2 | ... AE27: =SUM(AE25:AE26) -> 0 | AF27: =SUM(E27:AE27) -> 119
B28: 4. | C28: Jumlah Pengguna Hak Pilih (B.1+B.2+B.3) | D28: LK | E28: =SUM(E19,E22,E25) -> 98 | F28: =SUM(F19,F22,F25) -> 88 | G28: =SUM(G19,G22,G25) -> 104 | H28: =SUM(H19,H22,H25) -> 90 | I28: =SUM(I19,I22,I25) -> 80 | J28: =SUM(J19,J22,J25) -> 82 | K28: =SUM(K19,K22,K25) -> 98 | L28: =SUM(L19,L22,L25) -> 87 | ... AE28: =SUM(AE19,AE22,AE25) -> 83 | AF28: =SUM(E28:AE28) -> 2371
D29: PR | E29: =SUM(E20,E23,E26) -> 106 | F29: =SUM(F20,F23,F26) -> 113 | G29: =SUM(G20,G23,G26) -> 103 | H29: =SUM(H20,H23,H26) -> 97 | I29: =SUM(I20,I23,I26) -> 98 | J29: =SUM(J20,J23,J26) -> 88 | K29: =SUM(K20,K23,K26) -> 110 | L29: =SUM(L20,L23,L26) -> 119 | ... AE29: =SUM(AE20,AE23,AE26) -> 117 | AF29: =SUM(E29:AE29) -> 2704
D30: JML | E30: =SUM(E28:E29) -> 204 | F30: =SUM(F28:F29) -> 201 | G30: =SUM(G28:G29) -> 207 | H30: =SUM(H28:H29) -> 187 | I30: =SUM(I28:I29) -> 178 | J30: =SUM(J28:J29) -> 170 | K30: =SUM(K28:K29) -> 208 | L30: =SUM(L28:L29) -> 206 | ... AE30: =SUM(AE28:AE29) -> 200 | AF30: =SUM(E30:AE30) -> 5075
A32: II | B32: DATA PENGGUNAAN SURAT SUARA
A33: 1 | B33: Jumlah surat suara yang diterima, termasuk surat suara cadangan 2,5% dari DPT | E33: 250 | F33: 241 | G33: 253 | H33: 231 | I33: 218 | J33: 211 | K33: 272 | L33: 259 | M33: 228 | N33: 276 | O33: 289 | P33: 255 | Q33: 305 | R33: 205 | S33: 126 | T33: 304 | U33: 231 | V33: 228 | W33: 222 | X33: 287 | Y33: 202 | Z33: 302 | AA33: 192 | AB33: 197 | AC33: 155 | AD33: 301 | AE33: 262 | AF33: =SUM(E33:AE33) -> 6502
A34: 2 | B34: Jumlah surat suara yang digunakan | E34: 204 | F34: 201 | G34: 207 | H34: 187 | I34: 178 | J34: 170 | K34: 208 | L34: 206 | M34: 181 | N34: 189 | O34: 207 | P34: 191 | Q34: 229 | R34: 180 | S34: 103 | T34: 240 | U34: 186 | V34: 172 | W34: 183 | X34: 211 | Y34: 160 | Z34: 234 | AA34: 157 | AB34: 146 | AC34: 111 | AD34: 234 | AE34: 200 | AF34: =SUM(E34:AE34) -> 5075
A35: 3 | B35: Jumlah surat suara dikembalikan oleh pemilih (karena rusak atau keliru coblos) | E35: 0 | F35: 1 | G35: 0 | H35: 1 | I35: 0 | J35: 0 | K35: 0 | L35: 1 | M35: 0 | N35: 5 | O35: 1 | P35: 0 | Q35: 1 | R35: 0 | S35: 0 | T35: 0 | U35: 0 | V35: 0 | W35: 1 | X35: 1 | Y35: 1 | Z35: 0 | AA35: 0 | AB35: 1 | AC35: 0 | AD35: 4 | AF35: =SUM(E35:AE35) -> 18
A36: 4 | B36: Jumlah surat suara yang tidak digunakan/tidak terpakai, termasuk sisa surat suara cadangan | E36: =E33-(E34+E35) -> 46 | F36: =F33-(F34+F35) -> 39 | G36: =G33-(G34+G35) -> 46 | H36: =H33-(H34+H35) -> 43 | I36: =I33-(I34+I35) -> 40 | J36: =J33-(J34+J35) -> 41 | K36: =K33-(K34+K35) -> 64 | L36: =L33-(L34+L35) -> 52 | ... AE36: =AE33-(AE34+AE35) -> 62 | AF36: =SUM(E36:AE36) -> 1409
A38: III | B38: DATA PEMILIH DISABILITAS
B39: Jumlah seluruh Pemilih disabilitas yang menggunakan hak pilih | D39: LK | E39: 0 | F39: 1 | G39: 0 | H39: 0 | I39: 0 | J39: 0 | K39: 0 | L39: 2 | M39: 0 | N39: 2 | O39: 1 | P39: 0 | Q39: 0 | R39: 0 | S39: 2 | T39: 0 | U39: 0 | V39: 0 | W39: 0 | X39: 0 | Y39: 0 | Z39: 0 | AA39: 0 | AB39: 1 | AC39: 0 | AD39: 0 | AE39: 0 | AF39: =SUM(E39:AE39) -> 9
D40: PR | E40: 0 | F40: 0 | G40: 0 | H40: 0 | I40: 0 | J40: 0 | K40: 0 | L40: 3 | M40: 0 | N40: 8 | O40: 0 | P40: 0 | Q40: 1 | R40: 0 | S40: 0 | T40: 0 | U40: 0 | V40: 0 | W40: 0 | X40: 0 | Y40: 0 | Z40: 0 | AA40: 0 | AB40: 1 | AC40: 0 | AD40: 0 | AE40: 0 | AF40: =SUM(E40:AE40) -> 13
D41: JML | E41: =SUM(E39:E40) -> 0 | F41: =SUM(F39:F40) -> 1 | G41: =SUM(G39:G40) -> 0 | H41: =SUM(H39:H40) -> 0 | I41: =SUM(I39:I40) -> 0 | J41: =SUM(J39:J40) -> 0 | K41: =SUM(K39:K40) -> 0 | L41: =SUM(L39:L40) -> 5 | ... AE41: =SUM(AE39:AE40) -> 0 | AF41: =SUM(E41:AE41) -> 22
A43: IV | B43: DATA RINCIAN PEROLEHAN SUARA PASANGAN CALON BUPATI DAN WAKIL BUPATI
A44: NOMOR DAN NAMA CALON
A45: A.1 | B45: 1. | C45: Partai Kebangkitan Bangsa | E45: 3 | F45: 3 | G45: 3 | H45: 2 | I45: 2 | J45: 2 | K45: 10 | L45: 4 | M45: 6 | N45: 1 | O45: 3 | P45: 3 | Q45: 3 | R45: 5 | S45: 1 | T45: 2 | U45: 7 | V45: 3 | W45: 3 | X45: 4 | Y45: 3 | Z45: 11 | AA45: 5 | AB45: 4 | AC45: 4 | AD45: 4 | AE45: 2 | AF45: =SUM(E45:AE45) -> 103
A46: A.2 | B46: 1 | C46: 1. Dr. Hj. NIHAYATUL WAFIROH, M.A. | E46: 14 | F46: 25 | G46: 9 | H46: 47 | I46: 16 | J46: 20 | K46: 28 | L46: 9 | M46: 15 | N46: 10 | O46: 6 | P46: 15 | Q46: 13 | R46: 16 | S46: 12 | T46: 15 | U46: 22 | V46: 27 | W46: 18 | X46: 5 | Y46: 8 | Z46: 23 | AA46: 11 | AB46: 15 | AC46: 18 | AD46: 3 | AE46: 10 | AF46: =SUM(E46:AE46) -> 430
B47: 2 | C47: 2. H. M. NASIM KHAN | E47: 0 | F47: 29 | G47: 13 | H47: 2 | I47: 0 | J47: 0 | K47: 4 | L47: 12 | M47: 3 | N47: 1 | O47: 1 | P47: 1 | Q47: 0 | R47: 2 | S47: 0 | T47: 1 | U47: 2 | V47: 1 | W47: 5 | X47: 2 | Y47: 1 | Z47: 0 | AA47: 0 | AB47: 1 | AC47: 0 | AD47: 1 | AE47: 0 | AF47: =SUM(E47:AE47) -> 82
B48: 3 | C48: 3. Dr. H. AKIK ZAMAN, M.Pd.I. | E48: 2 | F48: 6 | G48: 1 | H48: 2 | I48: 1 | J48: 0 | K48: 4 | L48: 3 | M48: 0 | N48: 0 | O48: 1 | P48: 0 | Q48: 1 | R48: 0 | S48: 0 | T48: 11 | U48: 1 | V48: 2 | W48: 1 | X48: 2 | Y48: 3 | Z48: 0 | AA48: 0 | AB48: 1 | AC48: 0 | AD48: 2 | AE48: 1 | AF48: =SUM(E48:AE48) -> 45
B49: 4 | C49: 4. AHMAD RIFA'I, S.H. | E49: 1 | F49: 0 | G49: 0 | H49: 0 | I49: 1 | J49: 0 | K49: 1 | L49: 1 | M49: 0 | N49: 2 | O49: 0 | P49: 0 | Q49: 1 | R49: 0 | S49: 0 | T49: 1 | U49: 0 | V49: 0 | W49: 0 | X49: 0 | Y49: 3 | Z49: 0 | AA49: 0 | AB49: 1 | AC49: 0 | AD49: 0 | AE49: 0 | AF49: =SUM(E49:AE49) -> 12
B50: 5 | C50: 5. Drs. H. MAHFUD M.N. | E50: 2 | F50: 2 | G50: 1 | H50: 0 | I50: 0 | J50: 0 | K50: 0 | L50: 1 | M50: 0 | N50: 0 | O50: 0 | P50: 0 | Q50: 0 | R50: 1 | S50: 0 | T50: 1 | U50: 1 | V50: 0 | W50: 0 | X50: 0 | Y50: 0 | Z50: 1 | AA50: 0 | AB50: 0 | AC50: 0 | AD50: 1 | AE50: 0 | AF50: =SUM(E50:AE50) -> 11
B51: 6 | C51: 6. NURHAYATI, S.Pd. | E51: 0 | F51: 0 | G51: 0 | H51: 0 | I51: 0 | J51: 0 | K51: 0 | L51: 0 | M51: 1 | N51: 0 | O51: 0 | P51: 0 | Q51: 0 | R51: 0 | S51: 0 | T51: 0 | U51: 0 | V51: 0 | W51: 0 | X51: 0 | Y51: 0 | Z51: 1 | AA51: 0 | AB51: 1 | AC51: 0 | AD51: 0 | AE51: 0 | AF51: =SUM(E51:AE51) -> 3
...

Sheet KALIBARU MANIS
C2: Kecamatan | D2: KALIBARU
C3: Kabupaten | D3: BANYUWANGI
C4: Provinsi | D4: JAWA TIMUR
C9: Kelurahan | D9: KALIBARU MANIS
A12: I | B12: DATA PEMILIH DAN PENGGUNAAN HAK PILIH | AK12: JUMLAH AKHIR
A13: A | B13: DATA PEMILIH | E13: TPS 001 | F13: TPS 002 | G13: TPS 003 | H13: TPS 004 | I13: TPS 005 | J13: TPS 006 | K13: TPS 007 | L13: TPS 008 | M13: TPS 009 | N13: TPS 010 | O13: TPS 011 | P13: TPS 012 | Q13: TPS 013 | R13: TPS 014 | S13: TPS 015 | T13: TPS 016 | U13: TPS 017 | V13: TPS 018 | W13: TPS 019 | X13: TPS 020 | Y13: TPS 021 | Z13: TPS 022 | AA13: TPS 023 | AB13: TPS 024 | AC13: TPS 025 | AD13: TPS 026 | AE13: TPS 027 | AF13: TPS 028 | AG13: TPS 029 | AH13: TPS 030 | AI13: TPS 031 | AJ13: TPS 032
B14: Jumlah Pemilih dalam Daftar Pemilih Tetap (DPT) | D14: LK | E14: 139 | F14: 116 | G14: 147 | H14: 149 | I14: 147 | J14: 128 | K14: 140 | L14: 129 | M14: 148 | N14: 138 | O14: 136 | P14: 124 | Q14: 126 | R14: 143 | S14: 148 | T14: 147 | U14: 117 | V14: 139 | W14: 131 | X14: 139 | Y14: 130 | Z14: 143 | AA14: 115 | AB14: 120 | AC14: 108 | AD14: 124 | AE14: 127 | AF14: 140 | AG14: 139 | AH14: 126 | AI14: 91 | AJ14: 119 | AK14: =SUM(E14:AJ14) -> 4213
D15: PR | E15: 140 | F15: 126 | G15: 140 | H15: 141 | I15: 140 | J15: 136 | K15: 146 | L15: 145 | M15: 139 | N15: 152 | O15: 138 | P15: 141 | Q15: 140 | R15: 152 | S15: 146 | T15: 146 | U15: 126 | V15: 136 | W15: 159 | X15: 150 | Y15: 147 | Z15: 147 | AA15: 112 | AB15: 114 | AC15: 117 | AD15: 117 | AE15: 121 | AF15: 133 | AG15: 133 | AH15: 136 | AI15: 91 | AJ15: 115 | AK15: =SUM(E15:AJ15) -> 4322
D16: JML | E16: =SUM(E14:E15) -> 279 | F16: =SUM(F14:F15) -> 242 | G16: =SUM(G14:G15) -> 287 | H16: =SUM(H14:H15) -> 290 | I16: =SUM(I14:I15) -> 287 | J16: =SUM(J14:J15) -> 264 | K16: =SUM(K14:K15) -> 286 | L16: =SUM(L14:L15) -> 274 | ... AJ16: =SUM(AJ14:AJ15) -> 234 | AK16: =SUM(E16:AJ16) -> 8535
A18: B | B18: PENGGUNA HAK PILIH
B19: 1. | C19: Jumlah pengguna hak pilih dalam Daftar Pemilih Tetap (DPT) | D19: LK | E19: 101 | F19: 98 | G19: 114 | H19: 96 | I19: 104 | J19: 94 | K19: 110 | L19: 104 | M19: 110 | N19: 99 | O19: 99 | P19: 84 | Q19: 87 | R19: 115 | S19: 100 | T19: 104 | U19: 95 | V19: 100 | W19: 99 | X19: 89 | Y19: 72 | Z19: 77 | AA19: 75 | AB19: 87 | AC19: 69 | AD19: 84 | AE19: 81 | AF19: 101 | AG19: 88 | AH19: 88 | AI19: 61 | AJ19: 82 | AK19: =SUM(E19:AJ19) -> 2967
D20: PR | E20: 106 | F20: 109 | G20: 111 | H20: 108 | I20: 112 | J20: 105 | K20: 120 | L20: 123 | M20: 118 | N20: 117 | O20: 112 | P20: 111 | Q20: 112 | R20: 126 | S20: 100 | T20: 110 | U20: 97 | V20: 91 | W20: 120 | X20: 111 | Y20: 104 | Z20: 110 | AA20: 84 | AB20: 90 | AC20: 80 | AD20: 87 | AE20: 92 | AF20: 95 | AG20: 93 | AH20: 105 | AI20: 61 | AJ20: 76 | AK20: =SUM(E20:AJ20) -> 3296
D21: JML | E21: =SUM(E19:E20) -> 207 | F21: =SUM(F19:F20) -> 207 | G21: =SUM(G19:G20) -> 225 | H21: =SUM(H19:H20) -> 204 | I21: =SUM(I19:I20) -> 216 | J21: =SUM(J19:J20) -> 199 | K21: =SUM(K19:K20) -> 230 | L21: =SUM(L19:L20) -> 227 | ... AJ21: =SUM(AJ19:AJ20) -> 158 | AK21: =SUM(E21:AJ21) -> 6263
B22: 2. | C22: Jumlah pengguna hak pilih dalam Daftar Pemilih Tambahan (DPTb) | D22: LK | E22: 4 | F22: 1 | G22: 0 | H22: 0 | I22: 1 | J22: 0 | K22: 0 | L22: 1 | M22: 0 | N22: 0 | O22: 0 | P22: 1 | Q22: 0 | R22: 0 | S22: 1 | T22: 1 | U22: 0 | V22: 1 | W22: 0 | X22: 0 | Y22: 0 | Z22: 0 | AA22: 0 | AB22: 0 | AC22: 0 | AD22: 0 | AE22: 2 | AF22: 2 | AG22: 1 | AH22: 0 | AI22: 1 | AJ22: 1 | AK22: =SUM(E22:AJ22) -> 18
D23: PR | E23: 0 | F23: 0 | G23: 1 | H23: 1 | I23: 0 | J23: 1 | K23: 1 | L23: 0 | M23: 1 | N23: 1 | O23: 0 | P23: 2 | Q23: 1 | R23: 0 | S23: 0 | T23: 0 | U23: 0 | V23: 0 | W23: 0 | X23: 1 | Y23: 0 | Z23: 1 | AA23: 1 | AB23: 1 | AC23: 1 | AD23: 1 | AE23: 0 | AF23: 0 | AG23: 1 | AH23: 1 | AI23: 0 | AJ23: 0 | AK23: =SUM(E23:AJ23) -> 17
D24: JML | E24: =SUM(E22:E23) -> 4 | F24: =SUM(F22:F23) -> 1 | G24: =SUM(G22:G23) -> 1 | H24: =SUM(H22:H23) -> 1 | I24: =SUM(I22:I23) -> 1 | J24: =SUM(J22:J23) -> 1 | K24: =SUM(K22:K23) -> 1 | L24: =SUM(L22:L23) -> 1 | ... AJ24: =SUM(AJ22:AJ23) -> 1 | AK24: =SUM(E24:AJ24) -> 35
B25: 3. | C25: Jumlah pengguna hak pilih dalam Daftar Pemilih Khusus (DPK) | D25: LK | E25: 0 | F25: 0 | G25: 2 | H25: 0 | I25: 0 | J25: 0 | K25: 0 | L25: 0 | M25: 0 | N25: 0 | O25: 0 | P25: 1 | Q25: 0 | R25: 0 | S25: 1 | T25: 0 | U25: 2 | V25: 3 | W25: 2 | X25: 0 | Y25: 0 | Z25: 1 | AA25: 0 | AB25: 0 | AC25: 0 | AD25: 0 | AE25: 0 | AF25: 1 | AG25: 0 | AH25: 0 | AI25: 0 | AJ25: 0 | AK25: =SUM(E25:AJ25) -> 13
D26: PR | E26: 0 | F26: 0 | G26: 2 | H26: 0 | I26: 0 | J26: 0 | K26: 0 | L26: 0 | M26: 0 | N26: 0 | O26: 0 | P26: 2 | Q26: 0 | R26: 0 | S26: 0 | T26: 0 | U26: 1 | V26: 4 | W26: 1 | X26: 0 | Y26: 0 | Z26: 0 | AA26: 0 | AB26: 0 | AC26: 0 | AD26: 0 | AE26: 0 | AF26: 2 | AG26: 0 | AH26: 0 | AI26: 0 | AJ26: 0 | AK26: =SUM(E26:AJ26) -> 12
D27: JML | E27: =SUM(E25:E26) -> 0 | F27: =SUM(F25:F26) -> 0 | G27: =SUM(G25:G26) -> 4 | H27: =SUM(H25:H26) -> 0 | I27: =SUM(I25:I26) -> 0 | J27: =SUM(J25:J26) -> 0 | K27: =SUM(K25:K26) -> 0 | L27: =SUM(L25:L26) -> 0 | ... AJ27: =SUM(AJ25:AJ26) -> 0 | AK27: =SUM(E27:AJ27) -> 25
B28: 4. | C28: Jumlah Pengguna Hak Pilih (B.1+B.2+B.3) | D28: LK | E28: =SUM(E19,E22,E25) -> 105 | F28: =SUM(F19,F22,F25) -> 99 | G28: =SUM(G19,G22,G25) -> 116 | H28: =SUM(H19,H22,H25) -> 96 | I28: =SUM(I19,I22,I25) -> 105 | J28: =SUM(J19,J22,J25) -> 94 | K28: =SUM(K19,K22,K25) -> 110 | L28: =SUM(L19,L22,L25) -> 105 | ... AJ28: =SUM(AJ19,AJ22,AJ25) -> 83 | AK28: =SUM(E28:AJ28) -> 2998
D29: PR | E29: =SUM(E20,E23,E26) -> 106 | F29: =SUM(F20,F23,F26) -> 109 | G29: =SUM(G20,G23,G26) -> 114 | H29: =SUM(H20,H23,H26) -> 109 | I29: =SUM(I20,I23,I26) -> 112 | J29: =SUM(J20,J23,J26) -> 106 | K29: =SUM(K20,K23,K26) -> 121 | L29: =SUM(L20,L23,L26) -> 123 | ... AJ29: =SUM(AJ20,AJ23,AJ26) -> 76 | AK29: =SUM(E29:AJ29) -> 3325
D30: JML | E30: =SUM(E28:E29) -> 211 | F30: =SUM(F28:F29) -> 208 | G30: =SUM(G28:G29) -> 230 | H30: =SUM(H28:H29) -> 205 | I30: =SUM(I28:I29) -> 217 | J30: =SUM(J28:J29) -> 200 | K30: =SUM(K28:K29) -> 231 | L30: =SUM(L28:L29) -> 228 | ... AJ30: =SUM(AJ28:AJ29) -> 159 | AK30: =SUM(E30:AJ30) -> 6323
A32: II | B32: DATA PENGGUNAAN SURAT SUARA
A33: 1 | B33: Jumlah surat suara yang diterima, termasuk surat suara cadangan 2,5% dari DPT | E33: 285 | F33: 247 | G33: 293 | H33: 296 | I33: 295 | J33: 270 | K33: 292 | L33: 280 | M33: 293 | N33: 296 | O33: 280 | P33: 275 | Q33: 272 | R33: 300 | S33: 299 | T33: 300 | U33: 248 | V33: 288 | W33: 295 | X33: 295 | Y33: 283 | Z33: 296 | AA33: 232 | AB33: 237 | AC33: 230 | AD33: 247 | AE33: 253 | AF33: 281 | AG33: 279 | AH33: 269 | AI33: 195 | AJ33: 248 | AK33: =SUM(E33:AJ33) -> 8749
A34: 2 | B34: Jumlah surat suara yang digunakan | E34: 211 | F34: 208 | G34: 230 | H34: 205 | I34: 217 | J34: 200 | K34: 231 | L34: 228 | M34: 229 | N34: 217 | O34: 211 | P34: 201 | Q34: 200 | R34: 241 | S34: 202 | T34: 215 | U34: 195 | V34: 199 | W34: 222 | X34: 201 | Y34: 176 | Z34: 189 | AA34: 160 | AB34: 178 | AC34: 150 | AD34: 172 | AE34: 175 | AF34: 201 | AG34: 183 | AH34: 194 | AI34: 123 | AJ34: 159 | AK34: =SUM(E34:AJ34) -> 6323
A35: 3 | B35: Jumlah surat suara dikembalikan oleh pemilih (karena rusak atau keliru coblos) | E35: 6 | F35: 0 | G35: 0 | H35: 0 | I35: 0 | J35: 0 | K35: 2 | L35: 1 | M35: 0 | N35: 0 | O35: 0 | P35: 0 | Q35: 0 | R35: 0 | S35: 0 | T35: 36 | U35: 0 | V35: 0 | W35: 0 | X35: 3 | Y35: 0 | Z35: 1 | AA35: 0 | AB35: 0 | AC35: 0 | AD35: 0 | AE35: 0 | AF35: 0 | AG35: 0 | AH35: 0 | AI35: 2 | AJ35: 0 | AK35: =SUM(E35:AJ35) -> 51
A36: 4 | B36: Jumlah surat suara yang tidak digunakan/tidak terpakai, termasuk sisa surat suara cadangan | E36: =E33-(E34+E35) -> 68 | F36: =F33-(F34+F35) -> 39 | G36: =G33-(G34+G35) -> 63 | H36: =H33-(H34+H35) -> 91 | I36: =I33-(I34+I35) -> 78 | J36: =J33-(J34+J35) -> 70 | K36: =K33-(K34+K35) -> 59 | L36: =L33-(L34+L35) -> 51 | ... AJ36: =AJ33-(AJ34+AJ35) -> 89 | AK36: =SUM(E36:AJ36) -> 2375
A38: III | B38: DATA PEMILIH DISABILITAS
B39: Jumlah seluruh Pemilih disabilitas yang menggunakan hak pilih | D39: LK | E39: 1 | F39: 0 | G39: 2 | H39: 0 | I39: 0 | J39: 0 | K39: 0 | L39: 0 | M39: 0 | N39: 0 | O39: 0 | P39: 0 | Q39: 0 | R39: 0 | S39: 0 | T39: 0 | U39: 0 | V39: 0 | W39: 0 | X39: 0 | Y39: 0 | Z39: 0 | AA39: 0 | AB39: 0 | AC39: 0 | AD39: 0 | AE39: 0 | AF39: 0 | AG39: 0 | AH39: 0 | AI39: 0 | AJ39: 0 | AK39: =SUM(E39:AJ39) -> 3
D40: PR | E40: 1 | F40: 0 | G40: 1 | H40: 0 | I40: 0 | J40: 0 | K40: 0 | L40: 0 | M40: 0 | N40: 0 | O40: 0 | P40: 0 | Q40: 0 | R40: 0 | S40: 0 | T40: 0 | U40: 0 | V40: 0 | W40: 0 | X40: 0 | Y40: 0 | Z40: 1 | AA40: 0 | AB40: 0 | AC40: 0 | AD40: 0 | AE40: 0 | AF40: 0 | AG40: 0 | AH40: 0 | AI40: 0 | AJ40: 0 | AK40: =SUM(E40:AJ40) -> 3
D41: JML | E41: =SUM(E39:E40) -> 2 | F41: =SUM(F39:F40) -> 0 | G41: =SUM(G39:G40) -> 3 | H41: =SUM(H39:H40) -> 0 | I41: =SUM(I39:I40) -> 0 | J41: =SUM(J39:J40) -> 0 | K41: =SUM(K39:K40) -> 0 | L41: =SUM(L39:L40) -> 0 | ... AJ41: =SUM(AJ39:AJ40) -> 0 | AK41: =SUM(E41:AJ41) -> 6
A43: IV | B43: DATA RINCIAN PEROLEHAN SUARA PASANGAN CALON BUPATI DAN WAKIL BUPATI
A44: NOMOR DAN NAMA CALON
A45: A.1 | B45: 1. | C45: Partai Kebangkitan Bangsa | E45: 4 | F45: 1 | G45: 6 | H45: 8 | I45: 3 | J45: 7 | K45: 8 | L45: 6 | M45: 14 | N45: 7 | O45: 11 | P45: 13 | Q45: 5 | R45: 13 | S45: 5 | T45: 15 | U45: 10 | V45: 12 | W45: 13 | X45: 8 | Y45: 12 | Z45: 5 | AA45: 6 | AB45: 10 | AC45: 7 | AD45: 7 | AE45: 3 | AF45: 3 | AG45: 7 | AH45: 6 | AI45: 2 | AJ45: 9 | AK45: =SUM(E45:AJ45) -> 246
A46: A.2 | B46: 1 | C46: 1. Dr. Hj. NIHAYATUL WAFIROH, M.A. | E46: 8 | F46: 6 | G46: 12 | H46: 7 | I46: 9 | J46: 10 | K46: 14 | L46: 14 | M46: 25 | N46: 14 | O46: 21 | P46: 29 | Q46: 18 | R46: 32 | S46: 9 | T46: 23 | U46: 17 | V46: 8 | W46: 18 | X46: 6 | Y46: 12 | Z46: 11 | AA46: 10 | AB46: 17 | AC46: 1 | AD46: 6 | AE46: 5 | AF46: 8 | AG46: 11 | AH46: 18 | AI46: 8 | AJ46: 12 | AK46: =SUM(E46:AJ46) -> 419
B47: 2 | C47: 2. H. M. NASIM KHAN | E47: 3 | F47: 3 | G47: 3 | H47: 3 | I47: 0 | J47: 3 | K47: 1 | L47: 2 | M47: 14 | N47: 1 | O47: 3 | P47: 9 | Q47: 6 | R47: 8 | S47: 2 | T47: 45 | U47: 26 | V47: 13 | W47: 6 | X47: 5 | Y47: 2 | Z47: 5 | AA47: 2 | AB47: 0 | AC47: 2 | AD47: 2 | AE47: 2 | AF47: 2 | AG47: 2 | AH47: 2 | AI47: 3 | AJ47: 2 | AK47: =SUM(E47:AJ47) -> 182
B48: 3 | C48: 3. Dr. H. AKIK ZAMAN, M.Pd.I. | E48: 1 | F48: 0 | G48: 1 | H48: 2 | I48: 2 | J48: 0 | K48: 1 | L48: 0 | M48: 0 | N48: 3 | O48: 0 | P48: 3 | Q48: 0 | R48: 1 | S48: 1 | T48: 4 | U48: 3 | V48: 3 | W48: 5 | X48: 6 | Y48: 8 | Z48: 3 | AA48: 2 | AB48: 0 | AC48: 1 | AD48: 0 | AE48: 0 | AF48: 1 | AG48: 1 | AH48: 1 | AI48: 1 | AJ48: 1 | AK48: =SUM(E48:AJ48) -> 55
B49: 4 | C49: 4. AHMAD RIFA'I, S.H. | E49: 2 | F49: 0 | G49: 3 | H49: 0 | I49: 0 | J49: 1 | K49: 0 | L49: 0 | M49: 1 | N49: 4 | O49: 2 | P49: 1 | Q49: 1 | R49: 2 | S49: 1 | T49: 0 | U49: 0 | V49: 1 | W49: 0 | X49: 1 | Y49: 0 | Z49: 2 | AA49: 1 | AB49: 0 | AC49: 0 | AD49: 0 | AE49: 1 | AF49: 2 | AG49: 1 | AH49: 1 | AI49: 0 | AJ49: 0 | AK49: =SUM(E49:AJ49) -> 28
B50: 5 | C50: 5. Drs. H. MAHFUD M.N. | E50: 3 | F50: 1 | G50: 1 | H50: 0 | I50: 1 | J50: 0 | K50: 0 | L50: 0 | M50: 2 | N50: 0 | O50: 1 | P50: 0 | Q50: 1 | R50: 2 | S50: 2 | T50: 2 | U50: 0 | V50: 1 | W50: 1 | X50: 0 | Y50: 1 | Z50: 0 | AA50: 1 | AB50: 1 | AC50: 1 | AD50: 1 | AE50: 0 | AF50: 1 | AG50: 0 | AH50: 0 | AI50: 0 | AJ50: 0 | AK50: =SUM(E50:AJ50) -> 24
B51: 6 | C51: 6. NURHAYATI, S.Pd. | E51: 1 | F51: 0 | G51: 1 | H51: 0 | I51: 0 | J51: 0 | K51: 0 | L51: 0 | M51: 0 | N51: 0 | O51: 1 | P51: 1 | Q51: 0 | R51: 1 | S51: 1 | T51: 0 | U51: 1 | V51: 0 | W51: 0 | X51: 0 | Y51: 0 | Z51: 0 | AA51: 0 | AB51: 0 | AC51: 0 | AD51: 0 | AE51: 0 | AF51: 0 | AG51: 0 | AH51: 0 | AI51: 0 | AJ51: 0 | AK51: =SUM(E51:AJ51) -> 7
...

Sheet KALIBARU WETAN
C2: Kecamatan | D2: KALIBARU
C3: Kabupaten | D3: BANYUWANGI
C4: Provinsi | D4: JAWA TIMUR
C9: Kelurahan | D9: KALIBARU WETAN
A12: I | B12: DATA PEMILIH DAN PENGGUNAAN HAK PILIH | AU12: JUMLAH AKHIR
A13: A | B13: DATA PEMILIH | E13: TPS 001 | F13: TPS 002 | G13: TPS 003 | H13: TPS 004 | I13: TPS 005 | J13: TPS 006 | K13: TPS 007 | L13: TPS 008 | M13: TPS 009 | N13: TPS 010 | O13: TPS 011 | P13: TPS 012 | Q13: TPS 013 | R13: TPS 014 | S13: TPS 015 | T13: TPS 016 | U13: TPS 017 | V13: TPS 018 | W13: TPS 019 | X13: TPS 020 | Y13: TPS 021 | Z13: TPS 022 | AA13: TPS 023 | AB13: TPS 024 | AC13: TPS 025 | AD13: TPS 026 | AE13: TPS 027 | AF13: TPS 028 | AG13: TPS 029 | AH13: TPS 030 | AI13: TPS 031 | AJ13: TPS 032 | AK13: TPS 033 | AL13: TPS 034 | AM13: TPS 035 | AN13: TPS 036 | AO13: TPS 037 | AP13: TPS 038 | AQ13: TPS 039 | AR13: TPS 040 | AS13: TPS 041 | AT13: TPS 042
B14: Jumlah Pemilih dalam Daftar Pemilih Tetap (DPT) | D14: LK | E14: 119 | F14: 148 | G14: 140 | H14: 99 | I14: 127 | J14: 131 | K14: 86 | L14: 129 | M14: 124 | N14: 132 | O14: 127 | P14: 133 | Q14: 144 | R14: 142 | S14: 141 | T14: 139 | U14: 136 | V14: 135 | W14: 142 | X14: 148 | Y14: 127 | Z14: 140 | AA14: 133 | AB14: 116 | AC14: 112 | AD14: 143 | AE14: 123 | AF14: 114 | AG14: 122 | AH14: 130 | AI14: 120 | AJ14: 151 | AK14: 123 | AL14: 106 | AM14: 103 | AN14: 147 | AO14: 142 | AP14: 141 | AQ14: 152 | AR14: 158 | AS14: 150 | AT14: 117 | AU14: =SUM(E14:AT14) -> 5492
D15: PR | E15: 127 | F15: 144 | G15: 142 | H15: 83 | I15: 121 | J15: 128 | K15: 86 | L15: 142 | M15: 127 | N15: 127 | O15: 113 | P15: 140 | Q15: 145 | R15: 143 | S15: 150 | T15: 138 | U15: 156 | V15: 155 | W15: 141 | X15: 147 | Y15: 159 | Z15: 138 | AA15: 158 | AB15: 121 | AC15: 139 | AD15: 152 | AE15: 110 | AF15: 118 | AG15: 136 | AH15: 127 | AI15: 128 | AJ15: 137 | AK15: 131 | AL15: 119 | AM15: 115 | AN15: 147 | AO15: 147 | AP15: 153 | AQ15: 143 | AR15: 141 | AS15: 144 | AT15: 120 | AU15: =SUM(E15:AT15) -> 5638
D16: JML | E16: =SUM(E14:E15) -> 246 | F16: =SUM(F14:F15) -> 292 | G16: =SUM(G14:G15) -> 282 | H16: =SUM(H14:H15) -> 182 | I16: =SUM(I14:I15) -> 248 | J16: =SUM(J14:J15) -> 259 | K16: =SUM(K14:K15) -> 172 | L16: =SUM(L14:L15) -> 271 | ... AT16: =SUM(AT14:AT15) -> 237 | AU16: =SUM(E16:AT16) -> 11130
A18: B | B18: PENGGUNA HAK PILIH
B19: 1. | C19: Jumlah pengguna hak pilih dalam Daftar Pemilih Tetap (DPT) | D19: LK | E19: 89 | F19: 93 | G19: 98 | H19: 74 | I19: 82 | J19: 91 | K19: 64 | L19: 84 | M19: 83 | N19: 93 | O19: 97 | P19: 84 | Q19: 92 | R19: 91 | S19: 91 | T19: 87 | U19: 96 | V19: 86 | W19: 92 | X19: 101 | Y19: 83 | Z19: 101 | AA19: 99 | AB19: 90 | AC19: 70 | AD19: 93 | AE19: 86 | AF19: 85 | AG19: 80 | AH19: 78 | AI19: 83 | AJ19: 98 | AK19: 101 | AL19: 78 | AM19: 64 | AN19: 88 | AO19: 101 | AP19: 103 | AQ19: 93 | AR19: 110 | AS19: 115 | AT19: 88 | AU19: =SUM(E19:AT19) -> 3755
D20: PR | E20: 95 | F20: 110 | G20: 104 | H20: 71 | I20: 90 | J20: 95 | K20: 69 | L20: 109 | M20: 99 | N20: 93 | O20: 87 | P20: 101 | Q20: 116 | R20: 107 | S20: 113 | T20: 105 | U20: 118 | V20: 118 | W20: 104 | X20: 108 | Y20: 108 | Z20: 114 | AA20: 128 | AB20: 98 | AC20: 101 | AD20: 101 | AE20: 84 | AF20: 93 | AG20: 90 | AH20: 96 | AI20: 109 | AJ20: 101 | AK20: 101 | AL20: 84 | AM20: 86 | AN20: 107 | AO20: 116 | AP20: 118 | AQ20: 109 | AR20: 118 | AS20: 127 | AT20: 100 | AU20: =SUM(E20:AT20) -> 4301
D21: JML | E21: =SUM(E19:E20) -> 184 | F21: =SUM(F19:F20) -> 203 | G21: =SUM(G19:G20) -> 202 | H21: =SUM(H19:H20) -> 145 | I21: =SUM(I19:I20) -> 172 | J21: =SUM(J19:J20) -> 186 | K21: =SUM(K19:K20) -> 133 | L21: =SUM(L19:L20) -> 193 | ... AT21: =SUM(AT19:AT20) -> 188 | AU21: =SUM(E21:AT21) -> 8056
B22: 2. | C22: Jumlah pengguna hak pilih dalam Daftar Pemilih Tambahan (DPTb) | D22: LK | E22: 0 | F22: 0 | G22: 1 | H22: 0 | I22: 0 | J22: 1 | K22: 0 | L22: 2 | M22: 0 | N22: 3 | O22: 1 | P22: 1 | Q22: 0 | R22: 1 | S22: 1 | T22: 1 | U22: 1 | V22: 1 | W22: 0 | X22: 1 | Y22: 1 | Z22: 0 | AA22: 0 | AB22: 1 | AC22: 0 | AD22: 1 | AE22: 1 | AF22: 1 | AG22: 0 | AH22: 0 | AI22: 0 | AJ22: 0 | AK22: 2 | AL22: 1 | AM22: 1 | AN22: 0 | AO22: 0 | AP22: 0 | AQ22: 0 | AR22: 1 | AS22: 1 | AT22: 0 | AU22: =SUM(E22:AT22) -> 26
D23: PR | E23: 0 | F23: 0 | G23: 0 | H23: 0 | I23: 1 | J23: 0 | K23: 0 | L23: 0 | M23: 1 | N23: 1 | O23: 0 | P23: 0 | Q23: 1 | R23: 0 | S23: 0 | T23: 0 | U23: 0 | V23: 0 | W23: 0 | X23: 1 | Y23: 0 | Z23: 0 | AA23: 1 | AB23: 2 | AC23: 0 | AD23: 0 | AE23: 1 | AF23: 0 | AG23: 1 | AH23: 1 | AI23: 1 | AJ23: 1 | AK23: 0 | AL23: 0 | AM23: 0 | AN23: 1 | AO23: 1 | AP23: 1 | AQ23: 1 | AR23: 0 | AS23: 0 | AT23: 0 | AU23: =SUM(E23:AT23) -> 17
D24: JML | E24: =SUM(E22:E23) -> 0 | F24: =SUM(F22:F23) -> 0 | G24: =SUM(G22:G23) -> 1 | H24: =SUM(H22:H23) -> 0 | I24: =SUM(I22:I23) -> 1 | J24: =SUM(J22:J23) -> 1 | K24: =SUM(K22:K23) -> 0 | L24: =SUM(L22:L23) -> 2 | ... AT24: =SUM(AT22:AT23) -> 0 | AU24: =SUM(E24:AT24) -> 43
B25: 3. | C25: Jumlah pengguna hak pilih dalam Daftar Pemilih Khusus (DPK) | D25: LK | E25: 1 | F25: 0 | G25: 3 | H25: 0 | I25: 0 | J25: 1 | K25: 0 | L25: 1 | M25: 3 | N25: 0 | O25: 1 | P25: 4 | Q25: 1 | R25: 1 | S25: 1 | T25: 1 | U25: 1 | V25: 3 | W25: 3 | X25: 1 | Y25: 2 | Z25: 1 | AA25: 1 | AB25: 3 | AC25: 2 | AD25: 1 | AE25: 0 | AF25: 1 | AG25: 0 | AH25: 0 | AI25: 0 | AJ25: 6 | AK25: 0 | AL25: 0 | AM25: 1 | AN25: 2 | AO25: 6 | AP25: 2 | AQ25: 0 | AR25: 2 | AS25: 2 | AT25: 0 | AU25: =SUM(E25:AT25) -> 58
D26: PR | E26: 3 | F26: 0 | G26: 3 | H26: 0 | I26: 0 | J26: 0 | K26: 0 | L26: 2 | M26: 3 | N26: 1 | O26: 1 | P26: 4 | Q26: 2 | R26: 0 | S26: 2 | T26: 1 | U26: 5 | V26: 1 | W26: 2 | X26: 0 | Y26: 0 | Z26: 1 | AA26: 3 | AB26: 2 | AC26: 1 | AD26: 0 | AE26: 1 | AF26: 0 | AG26: 2 | AH26: 0 | AI26: 0 | AJ26: 5 | AK26: 1 | AL26: 3 | AM26: 0 | AN26: 3 | AO26: 2 | AP26: 2 | AQ26: 0 | AR26: 0 | AS26: 1 | AT26: 0 | AU26: =SUM(E26:AT26) -> 57
D27: JML | E27: =SUM(E25:E26) -> 4 | F27: =SUM(F25:F26) -> 0 | G27: =SUM(G25:G26) -> 6 | H27: =SUM(H25:H26) -> 0 | I27: =SUM(I25:I26) -> 0 | J27: =SUM(J25:J26) -> 1 | K27: =SUM(K25:K26) -> 0 | L27: =SUM(L25:L26) -> 3 | ... AT27: =SUM(AT25:AT26) -> 0 | AU27: =SUM(E27:AT27) -> 115
B28: 4. | C28: Jumlah Pengguna Hak Pilih (B.1+B.2+B.3) | D28: LK | E28: =SUM(E19,E22,E25) -> 90 | F28: =SUM(F19,F22,F25) -> 93 | G28: =SUM(G19,G22,G25) -> 102 | H28: =SUM(H19,H22,H25) -> 74 | I28: =SUM(I19,I22,I25) -> 82 | J28: =SUM(J19,J22,J25) -> 93 | K28: =SUM(K19,K22,K25) -> 64 | L28: =SUM(L19,L22,L25) -> 87 | ... AT28: =SUM(AT19,AT22,AT25) -> 88 | AU28: =SUM(E28:AT28) -> 3839
D29: PR | E29: =SUM(E20,E23,E26) -> 98 | F29: =SUM(F20,F23,F26) -> 110 | G29: =SUM(G20,G23,G26) -> 107 | H29: =SUM(H20,H23,H26) -> 71 | I29: =SUM(I20,I23,I26) -> 91 | J29: =SUM(J20,J23,J26) -> 95 | K29: =SUM(K20,K23,K26) -> 69 | L29: =SUM(L20,L23,L26) -> 111 | ... AT29: =SUM(AT20,AT23,AT26) -> 100 | AU29: =SUM(E29:AT29) -> 4375
D30: JML | E30: =SUM(E28:E29) -> 188 | F30: =SUM(F28:F29) -> 203 | G30: =SUM(G28:G29) -> 209 | H30: =SUM(H28:H29) -> 145 | I30: =SUM(I28:I29) -> 173 | J30: =SUM(J28:J29) -> 188 | K30: =SUM(K28:K29) -> 133 | L30: =SUM(L28:L29) -> 198 | ... AT30: =SUM(AT28:AT29) -> 188 | AU30: =SUM(E30:AT30) -> 8214
A32: II | B32: DATA PENGGUNAAN SURAT SUARA
