Workbook

Sheet DPR RI
C8: Kecamatan | D8: CLURING
C9: Kabupaten | D9: BANYUWANGI
C10: Provinsi | D10: JAWA TIMUR
A12: I | B12: DATA PEMILIH DAN PENGGUNAAN HAK PILIH | E12: JUMLAH AKHIR
A13: A | B13: DATA PEMILIH
B14: Jumlah Pemilih dalam Daftar Pemilih Tetap (DPT) | D14: LK | E14: =BENCULUK!AS14+CLURING!AL14+KALIPLOSO!Q14+PLAMPANGREJO!AE14+SARIMULYO!AA14+SEMBULUNG!AC14+SRATEN!AB14+TAMANAGUNG!AH14+TAMPO!AB14 -> 20590
D15: PR | E15: =BENCULUK!AS15+CLURING!AL15+KALIPLOSO!Q15+PLAMPANGREJO!AE15+SARIMULYO!AA15+SEMBULUNG!AC15+SRATEN!AB15+TAMANAGUNG!AH15+TAMPO!AB15 -> 20719
D16: JML | E16: =SUM(E14:E15) -> 41309
A18: B | B18: PENGGUNA HAK PILIH
B19: 1. | C19: Jumlah pengguna hak pilih dalam Daftar Pemilih Tetap (DPT) | D19: LK | E19: =BENCULUK!AS19+CLURING!AL19+KALIPLOSO!Q19+PLAMPANGREJO!AE19+SARIMULYO!AA19+SEMBULUNG!AC19+SRATEN!AB19+TAMANAGUNG!AH19+TAMPO!AB19 -> 16716
D20: PR | E20: =BENCULUK!AS20+CLURING!AL20+KALIPLOSO!Q20+PLAMPANGREJO!AE20+SARIMULYO!AA20+SEMBULUNG!AC20+SRATEN!AB20+TAMANAGUNG!AH20+TAMPO!AB20 -> 17715
D21: JML | E21: =SUM(E19:E20) -> 34431
B22: 2. | C22: Jumlah pengguna hak pilih dalam Daftar Pemilih Tambahan (DPTb) | D22: LK | E22: =BENCULUK!AS22+CLURING!AL22+KALIPLOSO!Q22+PLAMPANGREJO!AE22+SARIMULYO!AA22+SEMBULUNG!AC22+SRATEN!AB22+TAMANAGUNG!AH22+TAMPO!AB22 -> 18
D23: PR | E23: =BENCULUK!AS23+CLURING!AL23+KALIPLOSO!Q23+PLAMPANGREJO!AE23+SARIMULYO!AA23+SEMBULUNG!AC23+SRATEN!AB23+TAMANAGUNG!AH23+TAMPO!AB23 -> 20
D24: JML | E24: =SUM(E22:E23) -> 38
B25: 3. | C25: Jumlah pengguna hak pilih dalam Daftar Pemilih Khusus (DPK) | D25: LK | E25: =BENCULUK!AS25+CLURING!AL25+KALIPLOSO!Q25+PLAMPANGREJO!AE25+SARIMULYO!AA25+SEMBULUNG!AC25+SRATEN!AB25+TAMANAGUNG!AH25+TAMPO!AB25 -> 169
D26: PR | E26: =BENCULUK!AS26+CLURING!AL26+KALIPLOSO!Q26+PLAMPANGREJO!AE26+SARIMULYO!AA26+SEMBULUNG!AC26+SRATEN!AB26+TAMANAGUNG!AH26+TAMPO!AB26 -> 222
D27: JML | E27: =SUM(E25:E26) -> 391
B28: 4. | C28: Jumlah Pengguna Hak Pilih (B.1+B.2+B.3) | D28: LK | E28: =E19+E22+E25 -> 16903
D29: PR | E29: =E20+E23+E26 -> 17957
D30: JML | E30: =SUM(E28:E29) -> 34860
A32: II | B32: DATA PENGGUNAAN SURAT SUARA
A33: 1 | B33: Jumlah surat suara yang diterima, termasuk surat suara cadangan 2,5% dari DPT | E33: =BENCULUK!AS33+CLURING!AL33+KALIPLOSO!Q33+PLAMPANGREJO!AE33+SARIMULYO!AA33+SEMBULUNG!AC33+SRATEN!AB33+TAMANAGUNG!AH33+TAMPO!AB33 -> 45250
A34: 2 | B34: Jumlah surat suara yang digunakan | E34: =BENCULUK!AS34+CLURING!AL34+KALIPLOSO!Q34+PLAMPANGREJO!AE34+SARIMULYO!AA34+SEMBULUNG!AC34+SRATEN!AB34+TAMANAGUNG!AH34+TAMPO!AB34 -> 34874
A35: 3 | B35: Jumlah surat suara dikembalikan oleh pemilih (karena rusak atau keliru coblos) | E35: =BENCULUK!AS35+CLURING!AL35+KALIPLOSO!Q35+PLAMPANGREJO!AE35+SARIMULYO!AA35+SEMBULUNG!AC35+SRATEN!AB35+TAMANAGUNG!AH35+TAMPO!AB35 -> 78
A36: 4 | B36: Jumlah surat suara yang tidak digunakan/tidak terpakai, termasuk sisa surat suara cadangan | E36: =E33-(E34+E35) -> 10298
A38: III | B38: DATA PEMILIH DISABILITAS
B39: Jumlah seluruh Pemilih disabilitas yang menggunakan hak pilih | D39: LK | E39: =BENCULUK!AS39+CLURING!AL39+KALIPLOSO!Q39+PLAMPANGREJO!AE39+SARIMULYO!AA39+SEMBULUNG!AC39+SRATEN!AB39+TAMANAGUNG!AH39+TAMPO!AB39 -> 22
D40: PR | E40: =BENCULUK!AS40+CLURING!AL40+KALIPLOSO!Q40+PLAMPANGREJO!AE40+SARIMULYO!AA40+SEMBULUNG!AC40+SRATEN!AB40+TAMANAGUNG!AH40+TAMPO!AB40 -> 21
D41: JML | E41: =SUM(E39:E40) -> 43
A43: IV | B43: DATA RINCIAN PEROLEHAN SUARA PASANGAN CALON BUPATI DAN WAKIL BUPATI
A44: NOMOR DAN NAMA CALON
A45: A.1 | B45: 1. | C45: Partai Kebangkitan Bangsa | E45: =BENCULUK!AS45+CLURING!AL45+KALIPLOSO!Q45+PLAMPANGREJO!AE45+SARIMULYO!AA45+SEMBULUNG!AC45+SRATEN!AB45+TAMANAGUNG!AH45+TAMPO!AB45 -> 886
A46: A.2 | B46: 1 | C46: 1. Dr. Hj. NIHAYATUL WAFIROH, M.A. | E46: =BENCULUK!AS46+CLURING!AL46+KALIPLOSO!Q46+PLAMPANGREJO!AE46+SARIMULYO!AA46+SEMBULUNG!AC46+SRATEN!AB46+TAMANAGUNG!AH46+TAMPO!AB46 -> 2536
B47: 2 | C47: 2. H. M. NASIM KHAN | E47: =BENCULUK!AS47+CLURING!AL47+KALIPLOSO!Q47+PLAMPANGREJO!AE47+SARIMULYO!AA47+SEMBULUNG!AC47+SRATEN!AB47+TAMANAGUNG!AH47+TAMPO!AB47 -> 710
B48: 3 | C48: 3. Dr. H. AKIK ZAMAN, M.Pd.I. | E48: =BENCULUK!AS48+CLURING!AL48+KALIPLOSO!Q48+PLAMPANGREJO!AE48+SARIMULYO!AA48+SEMBULUNG!AC48+SRATEN!AB48+TAMANAGUNG!AH48+TAMPO!AB48 -> 99
B49: 4 | C49: 4. AHMAD RIFA'I, S.H. | E49: =BENCULUK!AS49+CLURING!AL49+KALIPLOSO!Q49+PLAMPANGREJO!AE49+SARIMULYO!AA49+SEMBULUNG!AC49+SRATEN!AB49+TAMANAGUNG!AH49+TAMPO!AB49 -> 66
B50: 5 | C50: 5. Drs. H. MAHFUD M.N. | E50: =BENCULUK!AS50+CLURING!AL50+KALIPLOSO!Q50+PLAMPANGREJO!AE50+SARIMULYO!AA50+SEMBULUNG!AC50+SRATEN!AB50+TAMANAGUNG!AH50+TAMPO!AB50 -> 61
B51: 6 | C51: 6. NURHAYATI, S.Pd. | E51: =BENCULUK!AS51+CLURING!AL51+KALIPLOSO!Q51+PLAMPANGREJO!AE51+SARIMULYO!AA51+SEMBULUNG!AC51+SRATEN!AB51+TAMANAGUNG!AH51+TAMPO!AB51 -> 111
B52: 7 | C52: 7. MAFTUHA KISWAH | E52: =BENCULUK!AS52+CLURING!AL52+KALIPLOSO!Q52+PLAMPANGREJO!AE52+SARIMULYO!AA52+SEMBULUNG!AC52+SRATEN!AB52+TAMANAGUNG!AH52+TAMPO!AB52 -> 27
...

Sheet BENCULUK
C2: Kecamatan | D2: CLURING
C3: Kabupaten | D3: BANYUWANGI
C4: Provinsi | D4: JAWA TIMUR
C9: Kelurahan | D9: BENCULUK
A12: I | B12: DATA PEMILIH DAN PENGGUNAAN HAK PILIH | AS12: JUMLAH AKHIR
A13: A | B13: DATA PEMILIH | E13: TPS 001 | F13: TPS 002 | G13: TPS 003 | H13: TPS 004 | I13: TPS 005 | J13: TPS 006 | K13: TPS 007 | L13: TPS 008 | M13: TPS 009 | N13: TPS 010 | O13: TPS 011 | P13: TPS 012 | Q13: TPS 013 | R13: TPS 014 | S13: TPS 015 | T13: TPS 016 | U13: TPS 017 | V13: TPS 018 | W13: TPS 019 | X13: TPS 020 | Y13: TPS 021 | Z13: TPS 022 | AA13: TPS 023 | AB13: TPS 024 | AC13: TPS 025 | AD13: TPS 026 | AE13: TPS 027 | AF13: TPS 028 | AG13: TPS 029 | AH13: TPS 030 | AI13: TPS 031 | AJ13: TPS 032 | AK13: TPS 033 | AL13: TPS 034 | AM13: TPS 035 | AN13: TPS 036 | AO13: TPS 037 | AP13: TPS 038 | AQ13: TPS 039 | AR13: TPS 040
B14: Jumlah Pemilih dalam Daftar Pemilih Tetap (DPT) | D14: LK | AS14: =SUM(E14:AR14) -> 0
D15: PR | AS15: =SUM(E15:AR15) -> 0
D16: JML | E16: =SUM(E14:E15) -> 0 | F16: =SUM(F14:F15) -> 0 | G16: =SUM(G14:G15) -> 0 | H16: =SUM(H14:H15) -> 0 | I16: =SUM(I14:I15) -> 0 | J16: =SUM(J14:J15) -> 0 | K16: =SUM(K14:K15) -> 0 | L16: =SUM(L14:L15) -> 0 | ... AR16: =SUM(AR14:AR15) -> 0 | AS16: =SUM(E16:AR16) -> 0
A18: B | B18: PENGGUNA HAK PILIH
B19: 1. | C19: Jumlah pengguna hak pilih dalam Daftar Pemilih Tetap (DPT) | D19: LK | AS19: =SUM(E19:AR19) -> 0
D20: PR | AS20: =SUM(E20:AR20) -> 0
D21: JML | E21: =SUM(E19:E20) -> 0 | F21: =SUM(F19:F20) -> 0 | G21: =SUM(G19:G20) -> 0 | H21: =SUM(H19:H20) -> 0 | I21: =SUM(I19:I20) -> 0 | J21: =SUM(J19:J20) -> 0 | K21: =SUM(K19:K20) -> 0 | L21: =SUM(L19:L20) -> 0 | ... AR21: =SUM(AR19:AR20) -> 0 | AS21: =SUM(E21:AR21) -> 0
B22: 2. | C22: Jumlah pengguna hak pilih dalam Daftar Pemilih Tambahan (DPTb) | D22: LK | AS22: =SUM(E22:AR22) -> 0
D23: PR | AS23: =SUM(E23:AR23) -> 0
D24: JML | E24: =SUM(E22:E23) -> 0 | F24: =SUM(F22:F23) -> 0 | G24: =SUM(G22:G23) -> 0 | H24: =SUM(H22:H23) -> 0 | I24: =SUM(I22:I23) -> 0 | J24: =SUM(J22:J23) -> 0 | K24: =SUM(K22:K23) -> 0 | L24: =SUM(L22:L23) -> 0 | ... AR24: =SUM(AR22:AR23) -> 0 | AS24: =SUM(E24:AR24) -> 0
B25: 3. | C25: Jumlah pengguna hak pilih dalam Daftar Pemilih Khusus (DPK) | D25: LK | AS25: =SUM(E25:AR25) -> 0
D26: PR | AS26: =SUM(E26:AR26) -> 0
D27: JML | E27: =SUM(E25:E26) -> 0 | F27: =SUM(F25:F26) -> 0 | G27: =SUM(G25:G26) -> 0 | H27: =SUM(H25:H26) -> 0 | I27: =SUM(I25:I26) -> 0 | J27: =SUM(J25:J26) -> 0 | K27: =SUM(K25:K26) -> 0 | L27: =SUM(L25:L26) -> 0 | ... AR27: =SUM(AR25:AR26) -> 0 | AS27: =SUM(E27:AR27) -> 0
B28: 4. | C28: Jumlah Pengguna Hak Pilih (B.1+B.2+B.3) | D28: LK | E28: =SUM(E19,E22,E25) -> 0 | F28: =SUM(F19,F22,F25) -> 0 | G28: =SUM(G19,G22,G25) -> 0 | H28: =SUM(H19,H22,H25) -> 0 | I28: =SUM(I19,I22,I25) -> 0 | J28: =SUM(J19,J22,J25) -> 0 | K28: =SUM(K19,K22,K25) -> 0 | L28: =SUM(L19,L22,L25) -> 0 | ... AR28: =SUM(AR19,AR22,AR25) -> 0 | AS28: =SUM(E28:AR28) -> 0
D29: PR | E29: =SUM(E20,E23,E26) -> 0 | F29: =SUM(F20,F23,F26) -> 0 | G29: =SUM(G20,G23,G26) -> 0 | H29: =SUM(H20,H23,H26) -> 0 | I29: =SUM(I20,I23,I26) -> 0 | J29: =SUM(J20,J23,J26) -> 0 | K29: =SUM(K20,K23,K26) -> 0 | L29: =SUM(L20,L23,L26) -> 0 | ... AR29: =SUM(AR20,AR23,AR26) -> 0 | AS29: =SUM(E29:AR29) -> 0
D30: JML | E30: =SUM(E28:E29) -> 0 | F30: =SUM(F28:F29) -> 0 | G30: =SUM(G28:G29) -> 0 | H30: =SUM(H28:H29) -> 0 | I30: =SUM(I28:I29) -> 0 | J30: =SUM(J28:J29) -> 0 | K30: =SUM(K28:K29) -> 0 | L30: =SUM(L28:L29) -> 0 | ... AR30: =SUM(AR28:AR29) -> 0 | AS30: =SUM(E30:AR30) -> 0
A32: II | B32: DATA PENGGUNAAN SURAT SUARA
A33: 1 | B33: Jumlah surat suara yang diterima, termasuk surat suara cadangan 2,5% dari DPT | AS33: =SUM(E33:AR33) -> 0
A34: 2 | B34: Jumlah surat suara yang digunakan | AS34: =SUM(E34:AR34) -> 0
A35: 3 | B35: Jumlah surat suara dikembalikan oleh pemilih (karena rusak atau keliru coblos) | AS35: =SUM(E35:AR35) -> 0
A36: 4 | B36: Jumlah surat suara yang tidak digunakan/tidak terpakai, termasuk sisa surat suara cadangan | E36: =E33-(E34+E35) -> 0 | F36: =F33-(F34+F35) -> 0 | G36: =G33-(G34+G35) -> 0 | H36: =H33-(H34+H35) -> 0 | I36: =I33-(I34+I35) -> 0 | J36: =J33-(J34+J35) -> 0 | K36: =K33-(K34+K35) -> 0 | L36: =L33-(L34+L35) -> 0 | ... AR36: =AR33-(AR34+AR35) -> 0 | AS36: =SUM(E36:AR36) -> 0
A38: III | B38: DATA PEMILIH DISABILITAS
B39: Jumlah seluruh Pemilih disabilitas yang menggunakan hak pilih | D39: LK | AS39: =SUM(E39:AR39) -> 0
D40: PR | AS40: =SUM(E40:AR40) -> 0
D41: JML | E41: =SUM(E39:E40) -> 0 | F41: =SUM(F39:F40) -> 0 | G41: =SUM(G39:G40) -> 0 | H41: =SUM(H39:H40) -> 0 | I41: =SUM(I39:I40) -> 0 | J41: =SUM(J39:J40) -> 0 | K41: =SUM(K39:K40) -> 0 | L41: =SUM(L39:L40) -> 0 | ... AR41: =SUM(AR39:AR40) -> 0 | AS41: =SUM(E41:AR41) -> 0
A43: IV | B43: DATA RINCIAN PEROLEHAN SUARA PASANGAN CALON BUPATI DAN WAKIL BUPATI
A44: NOMOR DAN NAMA CALON
A45: A.1 | B45: 1. | C45: Partai Kebangkitan Bangsa | AS45: =SUM(E45:AR45) -> 0
A46: A.2 | B46: 1 | C46: 1. Dr. Hj. NIHAYATUL WAFIROH, M.A. | AS46: =SUM(E46:AR46) -> 0
B47: 2 | C47: 2. H. M. NASIM KHAN | AS47: =SUM(E47:AR47) -> 0
B48: 3 | C48: 3. Dr. H. AKIK ZAMAN, M.Pd.I. | AS48: =SUM(E48:AR48) -> 0
B49: 4 | C49: 4. AHMAD RIFA'I, S.H. | AS49: =SUM(E49:AR49) -> 0
B50: 5 | C50: 5. Drs. H. MAHFUD M.N. | AS50: =SUM(E50:AR50) -> 0
B51: 6 | C51: 6. NURHAYATI, S.Pd. | AS51: =SUM(E51:AR51) -> 0
...

Sheet CLURING
C2: Kecamatan | D2: CLURING
C3: Kabupaten | D3: BANYUWANGI
C4: Provinsi | D4: JAWA TIMUR
C9: Kelurahan | D9: CLURING
A12: I | B12: DATA PEMILIH DAN PENGGUNAAN HAK PILIH | AL12: JUMLAH AKHIR
A13: A | B13: DATA PEMILIH | E13: TPS 001 | F13: TPS 002 | G13: TPS 003 | H13: TPS 004 | I13: TPS 005 | J13: TPS 006 | K13: TPS 007 | L13: TPS 008 | M13: TPS 009 | N13: TPS 010 | O13: TPS 011 | P13: TPS 012 | Q13: TPS 013 | R13: TPS 014 | S13: TPS 015 | T13: TPS 016 | U13: TPS 017 | V13: TPS 018 | W13: TPS 019 | X13: TPS 020 | Y13: TPS 021 | Z13: TPS 022 | AA13: TPS 023 | AB13: TPS 024 | AC13: TPS 025 | AD13: TPS 026 | AE13: TPS 027 | AF13: TPS 028 | AG13: TPS 029 | AH13: TPS 030 | AI13: TPS 031 | AJ13: TPS 032 | AK13: TPS 033
B14: Jumlah Pemilih dalam Daftar Pemilih Tetap (DPT) | D14: LK | E14: 136 | F14: 136 | G14: 145 | H14: 148 | I14: 114 | J14: 134 | K14: 130 | L14: 136 | M14: 132 | N14: 123 | O14: 117 | P14: 133 | Q14: 130 | R14: 132 | S14: 145 | T14: 128 | U14: 136 | V14: 122 | W14: 135 | X14: 135 | Y14: 141 | Z14: 133 | AA14: 142 | AB14: 158 | AC14: 141 | AD14: 146 | AE14: 131 | AF14: 140 | AG14: 134 | AH14: 133 | AI14: 121 | AJ14: 131 | AK14: 134 | AL14: =SUM(E14:AK14) -> 4432
D15: PR | E15: 138 | F15: 128 | G15: 154 | H15: 150 | I15: 139 | J15: 132 | K15: 136 | L15: 129 | M15: 126 | N15: 136 | O15: 124 | P15: 141 | Q15: 129 | R15: 122 | S15: 141 | T15: 122 | U15: 132 | V15: 129 | W15: 134 | X15: 137 | Y15: 131 | Z15: 129 | AA15: 150 | AB15: 132 | AC15: 146 | AD15: 146 | AE15: 146 | AF15: 131 | AG15: 136 | AH15: 138 | AI15: 146 | AJ15: 140 | AK15: 132 | AL15: =SUM(E15:AK15) -> 4482
D16: JML | E16: =SUM(E14:E15) -> 274 | F16: =SUM(F14:F15) -> 264 | G16: =SUM(G14:G15) -> 299 | H16: =SUM(H14:H15) -> 298 | I16: =SUM(I14:I15) -> 253 | J16: =SUM(J14:J15) -> 266 | K16: =SUM(K14:K15) -> 266 | L16: =SUM(L14:L15) -> 265 | ... AK16: =SUM(AK14:AK15) -> 266 | AL16: =SUM(E16:AK16) -> 8914
A18: B | B18: PENGGUNA HAK PILIH
B19: 1. | C19: Jumlah pengguna hak pilih dalam Daftar Pemilih Tetap (DPT) | D19: LK | E19: 98 | F19: 91 | G19: 115 | H19: 156 | I19: 75 | J19: 99 | K19: 86 | L19: 95 | M19: 93 | N19: 101 | O19: 68 | P19: 101 | Q19: 76 | R19: 101 | S19: 96 | T19: 92 | U19: 106 | V19: 95 | W19: 98 | X19: 102 | Y19: 104 | Z19: 102 | AA19: 107 | AB19: 109 | AC19: 107 | AD19: 104 | AE19: 112 | AF19: 111 | AG19: 108 | AH19: 104 | AI19: 100 | AJ19: 97 | AK19: 105 | AL19: =SUM(E19:AK19) -> 3314
D20: PR | E20: 102 | F20: 103 | G20: 123 | H20: 90 | I20: 92 | J20: 103 | K20: 98 | L20: 101 | M20: 98 | N20: 118 | O20: 86 | P20: 115 | Q20: 92 | R20: 98 | S20: 103 | T20: 95 | U20: 108 | V20: 108 | W20: 101 | X20: 108 | Y20: 102 | Z20: 103 | AA20: 112 | AB20: 104 | AC20: 109 | AD20: 117 | AE20: 120 | AF20: 107 | AG20: 106 | AH20: 108 | AI20: 119 | AJ20: 118 | AK20: 106 | AL20: =SUM(E20:AK20) -> 3473
D21: JML | E21: 200 | F21: 194 | G21: 238 | H21: 246 | I21: 167 | J21: 202 | K21: 184 | L21: 196 | M21: 191 | N21: 219 | O21: 154 | P21: 216 | Q21: 168 | R21: 199 | S21: 199 | T21: 187 | U21: 214 | V21: 203 | W21: 199 | X21: 210 | Y21: 206 | Z21: 205 | AA21: 219 | AB21: 213 | AC21: 216 | AD21: 221 | AE21: 232 | AF21: 218 | AG21: 214 | AH21: 212 | AI21: =SUM(AI19:AI20) -> 219 | AJ21: =SUM(AJ19:AJ20) -> 215 | AK21: =SUM(AK19:AK20) -> 211 | AL21: =SUM(E21:AK21) -> 6787
B22: 2. | C22: Jumlah pengguna hak pilih dalam Daftar Pemilih Tambahan (DPTb) | D22: LK | E22: 0 | F22: 0 | G22: 1 | H22: 0 | I22: 0 | J22: 0 | K22: 0 | L22: 0 | M22: 1 | N22: 0 | O22: 2 | P22: 0 | Q22: 0 | R22: 0 | S22: 0 | T22: 1 | U22: 0 | V22: 0 | W22: 0 | X22: 0 | Y22: 0 | Z22: 0 | AA22: 0 | AB22: 0 | AC22: 0 | AD22: 0 | AE22: 0 | AF22: 0 | AG22: 0 | AH22: 0 | AI22: 0 | AJ22: 0 | AK22: 0 | AL22: =SUM(E22:AK22) -> 5
D23: PR | E23: 0 | F23: 0 | G23: 0 | H23: 0 | I23: 0 | J23: 0 | K23: 0 | L23: 1 | M23: 0 | N23: 0 | O23: 2 | P23: 0 | Q23: 0 | R23: 0 | S23: 0 | T23: 1 | U23: 0 | V23: 0 | W23: 0 | X23: 0 | Y23: 0 | Z23: 0 | AA23: 0 | AB23: 0 | AC23: 0 | AD23: 0 | AE23: 0 | AF23: 0 | AG23: 0 | AH23: 0 | AI23: 0 | AJ23: 0 | AK23: 0 | AL23: =SUM(E23:AK23) -> 4
D24: JML | E24: 0 | F24: 0 | G24: 1 | H24: 0 | I24: 0 | J24: 0 | K24: 0 | L24: 1 | M24: 1 | N24: 0 | O24: 4 | P24: 0 | Q24: 0 | R24: 0 | S24: 0 | T24: 2 | U24: 0 | V24: 0 | W24: 0 | X24: 0 | Y24: 0 | Z24: 0 | AA24: 0 | AB24: 0 | AC24: 0 | AD24: 0 | AE24: 0 | AF24: 0 | AG24: 0 | AH24: 0 | AI24: =SUM(AI22:AI23) -> 0 | AJ24: =SUM(AJ22:AJ23) -> 0 | AK24: =SUM(AK22:AK23) -> 0 | AL24: =SUM(E24:AK24) -> 9
B25: 3. | C25: Jumlah pengguna hak pilih dalam Daftar Pemilih Khusus (DPK) | D25: LK | E25: 0 | F25: 0 | G25: 0 | H25: 3 | I25: 0 | J25: 4 | K25: 1 | L25: 1 | M25: 0 | N25: 3 | O25: 1 | P25: 2 | Q25: 1 | R25: 4 | S25: 2 | T25: 1 | U25: 0 | V25: 1 | W25: 0 | X25: 0 | Y25: 1 | Z25: 1 | AA25: 0 | AB25: 1 | AC25: 2 | AD25: 1 | AE25: 2 | AF25: 5 | AG25: 3 | AH25: 0 | AI25: 3 | AJ25: 2 | AK25: 3 | AL25: =SUM(E25:AK25) -> 48
D26: PR | E26: 2 | F26: 1 | G26: 0 | H26: 3 | I26: 1 | J26: 2 | K26: 2 | L26: 3 | M26: 1 | N26: 3 | O26: 2 | P26: 3 | Q26: 4 | R26: 1 | S26: 0 | T26: 0 | U26: 2 | V26: 1 | W26: 0 | X26: 0 | Y26: 1 | Z26: 5 | AA26: 1 | AB26: 3 | AC26: 1 | AD26: 4 | AE26: 3 | AF26: 3 | AG26: 2 | AH26: 0 | AI26: 3 | AJ26: 4 | AK26: 5 | AL26: =SUM(E26:AK26) -> 66
D27: JML | E27: 2 | F27: 1 | G27: 0 | H27: 6 | I27: 1 | J27: 6 | K27: 3 | L27: 4 | M27: 1 | N27: 6 | O27: 3 | P27: 5 | Q27: 5 | R27: 5 | S27: 2 | T27: 1 | U27: 2 | V27: 2 | W27: 0 | X27: 0 | Y27: 2 | Z27: 6 | AA27: 1 | AB27: 4 | AC27: 3 | AD27: 5 | AE27: 5 | AF27: 8 | AG27: 5 | AH27: 0 | AI27: =SUM(AI25:AI26) -> 6 | AJ27: =SUM(AJ25:AJ26) -> 6 | AK27: =SUM(AK25:AK26) -> 8 | AL27: =SUM(E27:AK27) -> 114
B28: 4. | C28: Jumlah Pengguna Hak Pilih (B.1+B.2+B.3) | D28: LK | E28: 98 | F28: 91 | G28: 116 | H28: 159 | I28: 75 | J28: 103 | K28: 87 | L28: 96 | M28: 94 | N28: 104 | O28: 71 | P28: 103 | Q28: 77 | R28: 105 | S28: 98 | T28: 94 | U28: 106 | V28: 96 | W28: 98 | X28: 102 | Y28: 105 | Z28: 103 | AA28: 107 | AB28: 110 | AC28: 109 | AD28: 105 | AE28: 114 | AF28: 116 | AG28: 111 | AH28: 104 | AI28: =SUM(AI19,AI22,AI25) -> 103 | AJ28: =SUM(AJ19,AJ22,AJ25) -> 99 | AK28: =SUM(AK19,AK22,AK25) -> 108 | AL28: =SUM(E28:AK28) -> 3367
D29: PR | E29: 104 | F29: 104 | G29: 123 | H29: 93 | I29: 93 | J29: 105 | K29: 100 | L29: 105 | M29: 99 | N29: 121 | O29: 90 | P29: 118 | Q29: 96 | R29: 99 | S29: 103 | T29: 96 | U29: 110 | V29: 109 | W29: 101 | X29: 108 | Y29: 103 | Z29: 108 | AA29: 113 | AB29: 107 | AC29: 110 | AD29: 121 | AE29: 123 | AF29: 110 | AG29: 108 | AH29: 108 | AI29: =SUM(AI20,AI23,AI26) -> 122 | AJ29: =SUM(AJ20,AJ23,AJ26) -> 122 | AK29: =SUM(AK20,AK23,AK26) -> 111 | AL29: =SUM(E29:AK29) -> 3543
D30: JML | E30: 202 | F30: 195 | G30: 239 | H30: 252 | I30: 168 | J30: 208 | K30: 187 | L30: 201 | M30: 193 | N30: 225 | O30: 161 | P30: 221 | Q30: 173 | R30: 204 | S30: 201 | T30: 190 | U30: 216 | V30: 205 | W30: 199 | X30: 210 | Y30: 208 | Z30: 211 | AA30: 220 | AB30: 217 | AC30: 219 | AD30: 226 | AE30: 237 | AF30: 226 | AG30: 219 | AH30: 212 | AI30: =SUM(AI28:AI29) -> 225 | AJ30: =SUM(AJ28:AJ29) -> 221 | AK30: =SUM(AK28:AK29) -> 219 | AL30: =SUM(E30:AK30) -> 6910
A32: II | B32: DATA PENGGUNAAN SURAT SUARA
A33: 1 | B33: Jumlah surat suara yang diterima, termasuk surat suara cadangan 2,5% dari DPT | E33: 280 | F33: 270 | G33: 305 | H33: 284 | I33: 259 | J33: 271 | K33: 272 | L33: 271 | M33: 264 | N33: 255 | O33: 236 | P33: 280 | Q33: 265 | R33: 259 | S33: 262 | T33: 255 | U33: 274 | V33: 288 | W33: 265 | X33: 278 | Y33: 288 | Z33: 268 | AA33: 298 | AB33: 276 | AC33: 293 | AD33: 279 | AE33: 283 | AF33: 278 | AG33: 276 | AH33: 267 | AI33: 243 | AJ33: 277 | AK33: 262 | AL33: =SUM(E33:AK33) -> 8981
A34: 2 | B34: Jumlah surat suara yang digunakan | E34: 202 | F34: 195 | G34: 239 | H34: 252 | I34: 168 | J34: 208 | K34: 187 | L34: 201 | M34: 193 | N34: 225 | O34: 161 | P34: 221 | Q34: 173 | R34: 204 | S34: 201 | T34: 190 | U34: 216 | V34: 205 | W34: 199 | X34: 210 | Y34: 208 | Z34: 211 | AA34: 220 | AB34: 217 | AC34: 219 | AD34: 226 | AE34: 237 | AF34: 226 | AG34: 219 | AH34: 212 | AI34: 225 | AJ34: 221 | AK34: 219 | AL34: =SUM(E34:AK34) -> 6910
A35: 3 | B35: Jumlah surat suara dikembalikan oleh pemilih (karena rusak atau keliru coblos) | E35: 0 | F35: 0 | G35: 2 | H35: 0 | I35: 0 | J35: 0 | K35: 0 | L35: 0 | M35: 0 | N35: 1 | O35: 0 | P35: 0 | Q35: 0 | R35: 0 | S35: 2 | T35: 0 | U35: 0 | V35: 2 | W35: 0 | X35: 0 | Y35: 0 | Z35: 1 | AA35: 0 | AB35: 0 | AC35: 3 | AD35: 0 | AE35: 2 | AF35: 0 | AG35: 0 | AH35: 0 | AI35: 6 | AJ35: 0 | AK35: 8 | AL35: =SUM(E35:AK35) -> 27
A36: 4 | B36: Jumlah surat suara yang tidak digunakan/tidak terpakai, termasuk sisa surat suara cadangan | E36: 78 | F36: 75 | G36: 64 | H36: 32 | I36: 91 | J36: 63 | K36: 85 | L36: 70 | M36: 71 | N36: 29 | O36: 75 | P36: 59 | Q36: 92 | R36: 55 | S36: 59 | T36: 65 | U36: 58 | V36: 81 | W36: 66 | X36: 68 | Y36: 80 | Z36: 56 | AA36: 78 | AB36: 59 | AC36: 71 | AD36: 53 | AE36: 44 | AF36: 52 | AG36: 57 | AH36: 55 | AI36: =AI33-(AI34+AI35) -> 12 | AJ36: =AJ33-(AJ34+AJ35) -> 56 | AK36: =AK33-(AK34+AK35) -> 35 | AL36: =SUM(E36:AK36) -> 2044
A38: III | B38: DATA PEMILIH DISABILITAS
B39: Jumlah seluruh Pemilih disabilitas yang menggunakan hak pilih | D39: LK | E39: 0 | F39: 0 | G39: 1 | H39: 0 | I39: 0 | J39: 2 | K39: 0 | L39: 0 | M39: 0 | N39: 0 | O39: 0 | P39: 0 | Q39: 0 | R39: 0 | S39: 0 | T39: 0 | U39: 0 | V39: 0 | W39: 0 | X39: 0 | Y39: 0 | Z39: 2 | AA39: 0 | AB39: 0 | AC39: 0 | AD39: 0 | AE39: 0 | AF39: 0 | AG39: 0 | AH39: 0 | AI39: 0 | AJ39: 0 | AK39: 0 | AL39: =SUM(E39:AK39) -> 5
D40: PR | E40: 0 | F40: 0 | G40: 1 | H40: 0 | I40: 0 | J40: 1 | K40: 0 | L40: 0 | M40: 1 | N40: 0 | O40: 0 | P40: 0 | Q40: 0 | R40: 0 | S40: 0 | T40: 0 | U40: 0 | V40: 0 | W40: 1 | X40: 0 | Y40: 0 | Z40: 1 | AA40: 0 | AB40: 0 | AC40: 0 | AD40: 0 | AE40: 0 | AF40: 1 | AG40: 0 | AH40: 0 | AI40: 0 | AJ40: 0 | AK40: 0 | AL40: =SUM(E40:AK40) -> 6
D41: JML | E41: =SUM(E39:E40) -> 0 | F41: =SUM(F39:F40) -> 0 | G41: =SUM(G39:G40) -> 2 | H41: =SUM(H39:H40) -> 0 | I41: =SUM(I39:I40) -> 0 | J41: =SUM(J39:J40) -> 3 | K41: =SUM(K39:K40) -> 0 | L41: =SUM(L39:L40) -> 0 | ... AK41: =SUM(AK39:AK40) -> 0 | AL41: =SUM(E41:AK41) -> 11
A43: IV | B43: DATA RINCIAN PEROLEHAN SUARA PASANGAN CALON BUPATI DAN WAKIL BUPATI
A44: NOMOR DAN NAMA CALON
A45: A.1 | B45: 1. | C45: Partai Kebangkitan Bangsa | E45: 3 | F45: 0 | G45: 3 | H45: 4 | I45: 1 | J45: 4 | K45: 4 | L45: 7 | M45: 7 | N45: 4 | O45: 3 | P45: 4 | Q45: 6 | R45: 7 | S45: 11 | T45: 15 | U45: 4 | V45: 5 | W45: 3 | X45: 6 | Y45: 2 | Z45: 9 | AA45: 5 | AB45: 7 | AC45: 6 | AD45: 1 | AE45: 8 | AF45: 1 | AG45: 8 | AH45: 7 | AI45: 9 | AJ45: 11 | AK45: 9 | AL45: =SUM(E45:AK45) -> 184
A46: A.2 | B46: 1 | C46: 1. Dr. Hj. NIHAYATUL WAFIROH, M.A. | E46: 5 | F46: 7 | G46: 11 | H46: 20 | I46: 2 | J46: 6 | K46: 10 | L46: 8 | M46: 10 | N46: 14 | O46: 15 | P46: 16 | Q46: 4 | R46: 12 | S46: 31 | T46: 40 | U46: 16 | V46: 15 | W46: 5 | X46: 2 | Y46: 8 | Z46: 5 | AA46: 11 | AB46: 9 | AC46: 11 | AD46: 5 | AE46: 16 | AF46: 8 | AG46: 15 | AH46: 17 | AI46: 23 | AJ46: 23 | AK46: 20 | AL46: =SUM(E46:AK46) -> 420
B47: 2 | C47: 2. H. M. NASIM KHAN | E47: 0 | F47: 2 | G47: 5 | H47: 2 | I47: 1 | J47: 0 | K47: 2 | L47: 1 | M47: 1 | N47: 0 | O47: 4 | P47: 1 | Q47: 0 | R47: 2 | S47: 3 | T47: 12 | U47: 2 | V47: 1 | W47: 1 | X47: 0 | Y47: 1 | Z47: 0 | AA47: 1 | AB47: 1 | AC47: 0 | AD47: 4 | AE47: 0 | AF47: 1 | AG47: 5 | AH47: 7 | AI47: 3 | AJ47: 1 | AK47: 3 | AL47: =SUM(E47:AK47) -> 67
B48: 3 | C48: 3. Dr. H. AKIK ZAMAN, M.Pd.I. | E48: 1 | F48: 0 | G48: 0 | H48: 2 | I48: 1 | J48: 0 | K48: 0 | L48: 1 | M48: 0 | N48: 0 | O48: 0 | P48: 0 | Q48: 1 | R48: 0 | S48: 1 | T48: 0 | U48: 0 | V48: 0 | W48: 1 | X48: 0 | Y48: 0 | Z48: 1 | AA48: 0 | AB48: 1 | AC48: 0 | AD48: 2 | AE48: 1 | AF48: 1 | AG48: 2 | AH48: 5 | AI48: 0 | AJ48: 0 | AK48: 1 | AL48: =SUM(E48:AK48) -> 22
B49: 4 | C49: 4. AHMAD RIFA'I, S.H. | E49: 1 | F49: 0 | G49: 0 | H49: 0 | I49: 0 | J49: 0 | K49: 1 | L49: 0 | M49: 0 | N49: 0 | O49: 0 | P49: 0 | Q49: 1 | R49: 1 | S49: 0 | T49: 0 | U49: 1 | V49: 2 | W49: 2 | X49: 0 | Y49: 2 | Z49: 0 | AA49: 1 | AB49: 0 | AC49: 0 | AD49: 0 | AE49: 0 | AF49: 0 | AG49: 1 | AH49: 1 | AI49: 0 | AJ49: 0 | AK49: 0 | AL49: =SUM(E49:AK49) -> 14
B50: 5 | C50: 5. Drs. H. MAHFUD M.N. | E50: 2 | F50: 0 | G50: 2 | H50: 1 | I50: 0 | J50: 0 | K50: 0 | L50: 1 | M50: 0 | N50: 0 | O50: 0 | P50: 0 | Q50: 0 | R50: 0 | S50: 1 | T50: 2 | U50: 1 | V50: 1 | W50: 1 | X50: 0 | Y50: 0 | Z50: 0 | AA50: 0 | AB50: 0 | AC50: 0 | AD50: 0 | AE50: 0 | AF50: 0 | AG50: 0 | AH50: 1 | AI50: 0 | AJ50: 0 | AK50: 0 | AL50: =SUM(E50:AK50) -> 13
B51: 6 | C51: 6. NURHAYATI, S.Pd. | E51: 1 | F51: 0 | G51: 0 | H51: 2 | I51: 0 | J51: 0 | K51: 1 | L51: 0 | M51: 2 | N51: 2 | O51: 0 | P51: 0 | Q51: 0 | R51: 0 | S51: 0 | T51: 0 | U51: 1 | V51: 1 | W51: 0 | X51: 0 | Y51: 0 | Z51: 0 | AA51: 0 | AB51: 1 | AC51: 0 | AD51: 4 | AE51: 3 | AF51: 1 | AG51: 0 | AH51: 0 | AI51: 1 | AJ51: 0 | AK51: 0 | AL51: =SUM(E51:AK51) -> 20
...

Sheet KALIPLOSO
C2: Kecamatan | D2: CLURING
C3: Kabupaten | D3: BANYUWANGI
C4: Provinsi | D4: JAWA TIMUR
C9: Kelurahan | D9: KALIPLOSO
A12: I | B12: DATA PEMILIH DAN PENGGUNAAN HAK PILIH | Q12: JUMLAH AKHIR
A13: A | B13: DATA PEMILIH | E13: TPS 001 | F13: TPS 002 | G13: TPS 003 | H13: TPS 004 | I13: TPS 005 | J13: TPS 006 | K13: TPS 007 | L13: TPS 008 | M13: TPS 009 | N13: TPS 010 | O13: TPS 011 | P13: TPS 012
B14: Jumlah Pemilih dalam Daftar Pemilih Tetap (DPT) | D14: LK | E14: 137 | F14: 152 | G14: 135 | H14: 160 | I14: 142 | J14: 143 | K14: 128 | L14: 122 | M14: 107 | N14: 132 | O14: 142 | P14: 144
D15: PR | E15: 149 | F15: 144 | G15: 156 | H15: 137 | I15: 149 | J15: 143 | K15: 117 | L15: 122 | M15: 98 | N15: 124 | O15: 147 | P15: 150
D16: JML | E16: 286 | F16: 296 | G16: 291 | H16: 297 | I16: 291 | J16: 286 | K16: 245 | L16: 244 | M16: 205 | N16: 256 | O16: 289 | P16: 294
A18: B | B18: PENGGUNA HAK PILIH
B19: 1. | C19: Jumlah pengguna hak pilih dalam Daftar Pemilih Tetap (DPT) | D19: LK | E19: 81 | F19: 107 | G19: 100 | H19: 113 | I19: 121 | J19: 113 | K19: 103 | L19: 97 | M19: 75 | N19: 114 | O19: 116 | P19: 112 | Q19: =SUM(E19:P19) -> 1252
D20: PR | E20: 112 | F20: 117 | G20: 124 | H20: 127 | I20: 121 | J20: 117 | K20: 94 | L20: 95 | M20: 71 | N20: 87 | O20: 127 | P20: 123 | Q20: =SUM(E20:P20) -> 1315
D21: JML | E21: 193 | F21: 224 | G21: 224 | H21: 240 | I21: 242 | J21: 230 | K21: 197 | L21: 192 | M21: 146 | N21: 201 | O21: 243 | P21: 235 | Q21: =SUM(E21:P21) -> 2567
B22: 2. | C22: Jumlah pengguna hak pilih dalam Daftar Pemilih Tambahan (DPTb) | D22: LK | E22: 0 | F22: 1 | G22: 0 | H22: 0 | I22: 0 | J22: 0 | K22: 0 | L22: 0 | M22: 0 | N22: 0 | O22: 0 | P22: 0 | Q22: =SUM(E22:P22) -> 1
D23: PR | E23: 0 | F23: 2 | G23: 0 | H23: 0 | I23: 1 | J23: 0 | K23: 0 | L23: 0 | M23: 0 | N23: 0 | O23: 0 | P23: 1 | Q23: =SUM(E23:P23) -> 4
D24: JML | E24: 0 | F24: 3 | G24: 0 | H24: 0 | I24: 1 | J24: 0 | K24: 0 | L24: 0 | M24: 0 | N24: 0 | O24: 0 | P24: 1 | Q24: =SUM(E24:P24) -> 5
B25: 3. | C25: Jumlah pengguna hak pilih dalam Daftar Pemilih Khusus (DPK) | D25: LK | E25: 1 | F25: 1 | G25: 0 | H25: 0 | I25: 1 | J25: 1 | K25: 1 | L25: 0 | M25: 1 | N25: 0 | O25: 0 | P25: 0 | Q25: =SUM(E25:P25) -> 6
D26: PR | E26: 2 | F26: 1 | G26: 2 | H26: 0 | I26: 2 | J26: 3 | K26: 2 | L26: 0 | M26: 2 | N26: 0 | O26: 0 | P26: 0 | Q26: =SUM(E26:P26) -> 14
D27: JML | E27: 3 | F27: 2 | G27: 2 | H27: 0 | I27: 3 | J27: 4 | K27: 3 | L27: 0 | M27: 3 | N27: 0 | O27: 0 | P27: 0 | Q27: =SUM(E27:P27) -> 20
B28: 4. | C28: Jumlah Pengguna Hak Pilih (B.1+B.2+B.3) | D28: LK | E28: 82 | F28: 109 | G28: 100 | H28: 113 | I28: 122 | J28: 114 | K28: 104 | L28: 97 | M28: 76 | N28: 114 | O28: 116 | P28: 112 | Q28: =SUM(E28:P28) -> 1259
D29: PR | E29: 114 | F29: 120 | G29: 126 | H29: 127 | I29: 124 | J29: 120 | K29: 96 | L29: 95 | M29: 73 | N29: 87 | O29: 127 | P29: 124 | Q29: =SUM(E29:P29) -> 1333
D30: JML | E30: 196 | F30: 229 | G30: 226 | H30: 240 | I30: 246 | J30: 234 | K30: 200 | L30: 192 | M30: 149 | N30: 201 | O30: 243 | P30: 236 | Q30: =SUM(E30:P30) -> 2592
A32: II | B32: DATA PENGGUNAAN SURAT SUARA
A33: 1 | B33: Jumlah surat suara yang diterima, termasuk surat suara cadangan 2,5% dari DPT | E33: 302 | F33: 292 | G33: 289 | H33: 313 | I33: 297 | J33: 292 | K33: 240 | L33: 250 | M33: 211 | N33: 263 | O33: 285 | P33: 300 | Q33: =SUM(E33:P33) -> 3334
A34: 2 | B34: Jumlah surat suara yang digunakan | E34: 196 | F34: 229 | G34: 226 | H34: 240 | I34: 246 | J34: 234 | K34: 200 | L34: 192 | M34: 149 | N34: 201 | O34: 243 | P34: 236 | Q34: =SUM(E34:P34) -> 2592
A35: 3 | B35: Jumlah surat suara dikembalikan oleh pemilih (karena rusak atau keliru coblos) | E35: 0 | F35: 2 | G35: 0 | H35: 0 | I35: 3 | J35: 0 | K35: 2 | L35: 0 | M35: 1 | N35: 0 | O35: 0 | P35: 3 | Q35: =SUM(E35:P35) -> 11
A36: 4 | B36: Jumlah surat suara yang tidak digunakan/tidak terpakai, termasuk sisa surat suara cadangan | E36: 106 | F36: 61 | G36: 63 | H36: 73 | I36: 48 | J36: 58 | K36: 38 | L36: 58 | M36: 61 | N36: 62 | O36: 42 | P36: 61 | Q36: =SUM(E36:P36) -> 731
A38: III | B38: DATA PEMILIH DISABILITAS
B39: Jumlah seluruh Pemilih disabilitas yang menggunakan hak pilih | D39: LK | E39: 0 | F39: 0 | G39: 0 | H39: 0 | I39: 0 | J39: 0 | K39: 0 | L39: 0 | M39: 0 | N39: 0 | O39: 0 | P39: 0 | Q39: =SUM(E39:P39) -> 0
D40: PR | E40: 0 | F40: 0 | G40: 0 | H40: 0 | I40: 0 | J40: 0 | K40: 0 | L40: 0 | M40: 0 | N40: 0 | O40: 0 | P40: 0 | Q40: =SUM(E40:P40) -> 0
D41: JML | E41: =SUM(E39:E40) -> 0 | F41: =SUM(F39:F40) -> 0 | G41: =SUM(G39:G40) -> 0 | H41: =SUM(H39:H40) -> 0 | I41: =SUM(I39:I40) -> 0 | J41: =SUM(J39:J40) -> 0 | K41: =SUM(K39:K40) -> 0 | L41: =SUM(L39:L40) -> 0 | ... P41: =SUM(P39:P40) -> 0 | Q41: =SUM(E41:P41) -> 0
A43: IV | B43: DATA RINCIAN PEROLEHAN SUARA PASANGAN CALON BUPATI DAN WAKIL BUPATI
A44: NOMOR DAN NAMA CALON
A45: A.1 | B45: 1. | C45: Partai Kebangkitan Bangsa | E45: 11 | F45: 2 | G45: 10 | H45: 3 | I45: 6 | J45: 3 | K45: 3 | L45: 1 | M45: 0 | N45: 3 | O45: 0 | P45: 4 | Q45: =SUM(E45:P45) -> 46
A46: A.2 | B46: 1 | C46: 1. Dr. Hj. NIHAYATUL WAFIROH, M.A. | E46: 14 | F46: 6 | G46: 22 | H46: 6 | I46: 22 | J46: 20 | K46: 3 | L46: 4 | M46: 1 | N46: 2 | O46: 5 | P46: 28 | Q46: =SUM(E46:P46) -> 133
B47: 2 | C47: 2. H. M. NASIM KHAN | E47: 0 | F47: 1 | G47: 1 | H47: 0 | I47: 4 | J47: 0 | K47: 0 | L47: 0 | M47: 0 | N47: 0 | O47: 0 | P47: 0 | Q47: =SUM(E47:P47) -> 6
B48: 3 | C48: 3. Dr. H. AKIK ZAMAN, M.Pd.I. | E48: 0 | F48: 0 | G48: 0 | H48: 1 | I48: 2 | J48: 0 | K48: 0 | L48: 1 | M48: 0 | N48: 0 | O48: 0 | P48: 0 | Q48: =SUM(E48:P48) -> 4
B49: 4 | C49: 4. AHMAD RIFA'I, S.H. | E49: 1 | F49: 1 | G49: 0 | H49: 0 | I49: 0 | J49: 0 | K49: 0 | L49: 0 | M49: 0 | N49: 0 | O49: 0 | P49: 2 | Q49: =SUM(E49:P49) -> 4
B50: 5 | C50: 5. Drs. H. MAHFUD M.N. | E50: 0 | F50: 0 | G50: 0 | H50: 0 | I50: 4 | J50: 0 | K50: 0 | L50: 0 | M50: 0 | N50: 0 | O50: 0 | P50: 0 | Q50: =SUM(E50:P50) -> 4
B51: 6 | C51: 6. NURHAYATI, S.Pd. | E51: 0 | F51: 0 | G51: 0 | H51: 0 | I51: 1 | J51: 1 | K51: 0 | L51: 0 | M51: 0 | N51: 0 | O51: 0 | P51: 0 | Q51: =SUM(E51:P51) -> 2
...

Sheet PLAMPANGREJO
C2: Kecamatan | D2: CLURING
C3: Kabupaten | D3: BANYUWANGI
C4: Provinsi | D4: JAWA TIMUR
C9: Kelurahan | D9: PLAMPANGREJO
A12: I | B12: DATA PEMILIH DAN PENGGUNAAN HAK PILIH | AE12: JUMLAH AKHIR
A13: A | B13: DATA PEMILIH | E13: TPS 001 | F13: TPS 002 | G13: TPS 003 | H13: TPS 004 | I13: TPS 005 | J13: TPS 006 | K13: TPS 007 | L13: TPS 008 | M13: TPS 009 | N13: TPS 010 | O13: TPS 011 | P13: TPS 012 | Q13: TPS 013 | R13: TPS 014 | S13: TPS 015 | T13: TPS 016 | U13: TPS 017 | V13: TPS 018 | W13: TPS 019 | X13: TPS 020 | Y13: TPS 021 | Z13: TPS 022 | AA13: TPS 023 | AB13: TPS 024 | AC13: TPS 025 | AD13: TPS 026
B14: Jumlah Pemilih dalam Daftar Pemilih Tetap (DPT) | D14: LK | E14: 128 | F14: 141 | G14: 138 | H14: 130 | I14: 137 | J14: 101 | K14: 144 | L14: 119 | M14: 133 | N14: 116 | O14: 121 | P14: 145 | Q14: 148 | R14: 147 | S14: 130 | T14: 136 | U14: 150 | V14: 157 | W14: 148 | X14: 143 | Y14: 152 | Z14: 138 | AA14: 120 | AB14: 109 | AC14: 130 | AD14: 107 | AE14: =SUM(E14:AD14) -> 3468
D15: PR | E15: 130 | F15: 137 | G15: 148 | H15: 121 | I15: 128 | J15: 105 | K15: 140 | L15: 128 | M15: 134 | N15: 125 | O15: 122 | P15: 133 | Q15: 150 | R15: 145 | S15: 134 | T15: 141 | U15: 134 | V15: 141 | W15: 143 | X15: 151 | Y15: 143 | Z15: 150 | AA15: 128 | AB15: 109 | AC15: 139 | AD15: 119 | AE15: =SUM(E15:AD15) -> 3478
D16: JML | E16: 258 | F16: 278 | G16: 286 | H16: 251 | I16: 265 | J16: 206 | K16: 284 | L16: 247 | M16: 267 | N16: 241 | O16: 243 | P16: 278 | Q16: 298 | R16: 292 | S16: 264 | T16: 277 | U16: 284 | V16: 298 | W16: 291 | X16: 294 | Y16: 295 | Z16: 288 | AA16: 248 | AB16: 218 | AC16: 269 | AD16: 226 | AE16: =SUM(E16:AD16) -> 6946
A18: B | B18: PENGGUNA HAK PILIH
B19: 1. | C19: Jumlah pengguna hak pilih dalam Daftar Pemilih Tetap (DPT) | D19: LK | E19: 100 | F19: 106 | G19: 117 | H19: 94 | I19: 103 | J19: 80 | K19: 116 | L19: 89 | M19: 90 | N19: 93 | O19: 93 | P19: 109 | Q19: 114 | R19: 118 | S19: 96 | T19: 102 | U19: 106 | V19: 125 | W19: 119 | X19: 113 | Y19: 112 | Z19: 96 | AA19: 91 | AB19: 89 | AC19: 107 | AD19: 84 | AE19: =SUM(E19:AD19) -> 2662
D20: PR | E20: 108 | F20: 106 | G20: 117 | H20: 98 | I20: 105 | J20: 85 | K20: 119 | L20: 107 | M20: 110 | N20: 98 | O20: 100 | P20: 102 | Q20: 126 | R20: 114 | S20: 106 | T20: 106 | U20: 116 | V20: 110 | W20: 113 | X20: 107 | Y20: 101 | Z20: 113 | AA20: 97 | AB20: 86 | AC20: 112 | AD20: 96 | AE20: =SUM(E20:AD20) -> 2758
D21: JML | E21: 208 | F21: 212 | G21: 234 | H21: 192 | I21: 208 | J21: 165 | K21: 235 | L21: 196 | M21: 200 | N21: 191 | O21: 193 | P21: 211 | Q21: 240 | R21: 232 | S21: =SUM(S19:S20) -> 202 | T21: 208 | U21: 222 | V21: 235 | W21: 232 | X21: 220 | Y21: 213 | Z21: 209 | AA21: 188 | AB21: 175 | AC21: 219 | AD21: 180 | AE21: =SUM(E21:AD21) -> 5420
B22: 2. | C22: Jumlah pengguna hak pilih dalam Daftar Pemilih Tambahan (DPTb) | D22: LK | E22: 0 | F22: 0 | G22: 0 | H22: 0 | I22: 0 | J22: 1 | K22: 1 | L22: 0 | M22: 0 | N22: 0 | O22: 0 | P22: 0 | Q22: 0 | R22: 1 | S22: 1 | T22: 0 | U22: 2 | V22: 0 | W22: 0 | X22: 0 | Y22: 0 | Z22: 0 | AA22: 0 | AB22: 0 | AC22: 0 | AD22: 0 | AE22: =SUM(E22:AD22) -> 6
D23: PR | E23: 0 | F23: 0 | G23: 0 | H23: 0 | I23: 0 | J23: 0 | K23: 1 | L23: 0 | M23: 0 | N23: 1 | O23: 1 | P23: 0 | Q23: 0 | R23: 1 | S23: 0 | T23: 0 | U23: 0 | V23: 1 | W23: 1 | X23: 0 | Y23: 0 | Z23: 0 | AA23: 0 | AB23: 0 | AC23: 0 | AD23: 0 | AE23: =SUM(E23:AD23) -> 6
D24: JML | E24: 0 | F24: 0 | G24: 0 | H24: 0 | I24: 0 | J24: 1 | K24: 2 | L24: 0 | M24: 0 | N24: 1 | O24: 1 | P24: 0 | Q24: 0 | R24: 2 | S24: =SUM(S22:S23) -> 1 | T24: 0 | U24: 2 | V24: 1 | W24: 1 | X24: 0 | Y24: 0 | Z24: 0 | AA24: 0 | AB24: 0 | AC24: 0 | AD24: 0 | AE24: =SUM(E24:AD24) -> 12
B25: 3. | C25: Jumlah pengguna hak pilih dalam Daftar Pemilih Khusus (DPK) | D25: LK | E25: 1 | F25: 1 | G25: 1 | H25: 0 | I25: 1 | J25: 0 | K25: 0 | L25: 0 | M25: 4 | N25: 1 | O25: 0 | P25: 1 | Q25: 0 | R25: 2 | S25: 2 | T25: 0 | U25: 0 | V25: 0 | W25: 1 | X25: 0 | Y25: 0 | Z25: 2 | AA25: 0 | AB25: 0 | AC25: 1 | AD25: 0 | AE25: =SUM(E25:AD25) -> 18
D26: PR | E26: 1 | F26: 1 | G26: 1 | H26: 0 | I26: 2 | J26: 0 | K26: 0 | L26: 0 | M26: 1 | N26: 0 | O26: 1 | P26: 0 | Q26: 0 | R26: 0 | S26: 4 | T26: 1 | U26: 0 | V26: 1 | W26: 0 | X26: 0 | Y26: 1 | Z26: 2 | AA26: 0 | AB26: 0 | AC26: 0 | AD26: 1 | AE26: =SUM(E26:AD26) -> 17
D27: JML | E27: 2 | F27: 2 | G27: 2 | H27: 0 | I27: 3 | J27: 0 | K27: 0 | L27: 0 | M27: 5 | N27: 1 | O27: 1 | P27: 1 | Q27: 0 | R27: 2 | S27: =SUM(S25:S26) -> 6 | T27: 1 | U27: 0 | V27: 1 | W27: 1 | X27: 0 | Y27: 1 | Z27: 4 | AA27: 0 | AB27: 0 | AC27: 1 | AD27: 1 | AE27: =SUM(E27:AD27) -> 35
B28: 4. | C28: Jumlah Pengguna Hak Pilih (B.1+B.2+B.3) | D28: LK | E28: 101 | F28: 107 | G28: 118 | H28: 94 | I28: 104 | J28: 81 | K28: 117 | L28: 89 | M28: 94 | N28: 94 | O28: 93 | P28: 110 | Q28: 114 | R28: 121 | S28: =SUM(S19,S22,S25) -> 99 | T28: 102 | U28: 108 | V28: 125 | W28: 120 | X28: 113 | Y28: 112 | Z28: 98 | AA28: 91 | AB28: 89 | AC28: 108 | AD28: 84 | AE28: =SUM(E28:AD28) -> 2686
D29: PR | E29: 109 | F29: 107 | G29: 118 | H29: 98 | I29: 107 | J29: 85 | K29: 120 | L29: 107 | M29: 111 | N29: 99 | O29: 102 | P29: 102 | Q29: 126 | R29: 115 | S29: =SUM(S20,S23,S26) -> 110 | T29: 107 | U29: 116 | V29: 112 | W29: 114 | X29: 107 | Y29: 102 | Z29: 115 | AA29: 97 | AB29: 86 | AC29: 112 | AD29: 97 | AE29: =SUM(E29:AD29) -> 2781
D30: JML | E30: 210 | F30: 214 | G30: 236 | H30: 192 | I30: 211 | J30: 166 | K30: 237 | L30: 196 | M30: 205 | N30: 193 | O30: 195 | P30: 212 | Q30: 240 | R30: 236 | S30: =SUM(S28:S29) -> 209 | T30: 209 | U30: 224 | V30: 237 | W30: 234 | X30: 220 | Y30: 214 | Z30: 213 | AA30: 188 | AB30: 175 | AC30: 220 | AD30: 181 | AE30: =SUM(E30:AD30) -> 5467
A32: II | B32: DATA PENGGUNAAN SURAT SUARA
A33: 1 | B33: Jumlah surat suara yang diterima, termasuk surat suara cadangan 2,5% dari DPT | E33: 264 | F33: 284 | G33: 262 | H33: 252 | I33: 271 | J33: 212 | K33: 290 | L33: 252 | M33: 273 | N33: 246 | O33: 248 | P33: 284 | Q33: 304 | R33: 298 | S33: 270 | T33: 283 | U33: 290 | V33: 304 | W33: 297 | X33: 300 | Y33: 292 | Z33: 294 | AA33: 253 | AB33: 223 | AC33: 275 | AD33: 253 | AE33: =SUM(E33:AD33) -> 7074
A34: 2 | B34: Jumlah surat suara yang digunakan | E34: 210 | F34: 214 | G34: 236 | H34: 192 | I34: 211 | J34: 166 | K34: 237 | L34: 196 | M34: 205 | N34: 193 | O34: 195 | P34: 212 | Q34: 240 | R34: 236 | S34: 209 | T34: 209 | U34: 224 | V34: 237 | W34: 234 | X34: 220 | Y34: 214 | Z34: 213 | AA34: 188 | AB34: 175 | AC34: 220 | AD34: 181 | AE34: =SUM(E34:AD34) -> 5467
A35: 3 | B35: Jumlah surat suara dikembalikan oleh pemilih (karena rusak atau keliru coblos) | E35: 0 | F35: 0 | G35: 2 | H35: 1 | I35: 0 | J35: 0 | K35: 0 | L35: 0 | M35: 0 | N35: 1 | O35: 0 | P35: 2 | Q35: 1 | R35: 0 | S35: 0 | T35: 0 | U35: 0 | V35: 0 | W35: 0 | X35: 0 | Y35: 1 | Z35: 0 | AA35: 0 | AB35: 3 | AC35: 0 | AD35: 0 | AE35: =SUM(E35:AD35) -> 11
A36: 4 | B36: Jumlah surat suara yang tidak digunakan/tidak terpakai, termasuk sisa surat suara cadangan | E36: 54 | F36: 70 | G36: 24 | H36: 59 | I36: 60 | J36: 46 | K36: 53 | L36: 56 | M36: 68 | N36: 52 | O36: 53 | P36: 70 | Q36: 63 | R36: 62 | S36: 61 | T36: 74 | U36: 66 | V36: 67 | W36: 63 | X36: 80 | Y36: 77 | Z36: 81 | AA36: 65 | AB36: 45 | AC36: 55 | AD36: 72 | AE36: =SUM(E36:AD36) -> 1596
A38: III | B38: DATA PEMILIH DISABILITAS
B39: Jumlah seluruh Pemilih disabilitas yang menggunakan hak pilih | D39: LK | E39: 1 | F39: 0 | G39: 0 | H39: 0 | I39: 0 | J39: 0 | K39: 0 | L39: 0 | M39: 0 | N39: 0 | O39: 0 | P39: 5 | Q39: 0 | R39: 0 | S39: 0 | T39: 0 | U39: 0 | V39: 0 | W39: 0 | X39: 0 | Y39: 0 | Z39: 0 | AA39: 0 | AB39: 0 | AC39: 0 | AD39: 0 | AE39: =SUM(E39:AD39) -> 6
D40: PR | E40: 0 | F40: 0 | G40: 0 | H40: 0 | I40: 0 | J40: 0 | K40: 0 | L40: 0 | M40: 0 | N40: 0 | O40: 0 | P40: 4 | Q40: 0 | R40: 0 | S40: 0 | T40: 0 | U40: 0 | V40: 0 | W40: 0 | X40: 0 | Y40: 0 | Z40: 0 | AA40: 0 | AB40: 0 | AC40: 0 | AD40: 0 | AE40: =SUM(E40:AD40) -> 4
D41: JML | E41: 1 | F41: 0 | G41: 0 | H41: 0 | I41: 0 | J41: 0 | K41: 0 | L41: 0 | M41: 0 | N41: 0 | O41: 0 | P41: 9 | Q41: 0 | R41: 0 | S41: 0 | T41: =SUM(T39:T40) -> 0 | U41: =SUM(U39:U40) -> 0 | V41: =SUM(V39:V40) -> 0 | W41: =SUM(W39:W40) -> 0 | X41: =SUM(X39:X40) -> 0 | Y41: =SUM(Y39:Y40) -> 0 | Z41: =SUM(Z39:Z40) -> 0 | AA41: =SUM(AA39:AA40) -> 0 | ... AD41: =SUM(AD39:AD40) -> 0 | AE41: =SUM(E41:AD41) -> 10
A43: IV | B43: DATA RINCIAN PEROLEHAN SUARA PASANGAN CALON BUPATI DAN WAKIL BUPATI
A44: NOMOR DAN NAMA CALON
A45: A.1 | B45: 1. | C45: Partai Kebangkitan Bangsa | E45: 4 | F45: 1 | G45: 4 | H45: 1 | I45: 5 | J45: 1 | K45: 5 | L45: 11 | M45: 9 | N45: 6 | O45: 6 | P45: 5 | Q45: 2 | R45: 5 | S45: 15 | T45: 10 | U45: 15 | V45: 4 | W45: 3 | X45: 6 | Y45: 7 | Z45: 6 | AA45: 16 | AB45: 3 | AC45: 17 | AD45: 1 | AE45: =SUM(E45:AD45) -> 168
A46: A.2 | B46: 1 | C46: 1. Dr. Hj. NIHAYATUL WAFIROH, M.A. | E46: 1 | F46: 4 | G46: 11 | H46: 5 | I46: 14 | J46: 6 | K46: 9 | L46: 37 | M46: 68 | N46: 59 | O46: 38 | P46: 1 | Q46: 9 | R46: 25 | S46: 42 | T46: 42 | U46: 39 | V46: 6 | W46: 7 | X46: 11 | Y46: 12 | Z46: 39 | AA46: 63 | AB46: 9 | AC46: 48 | AD46: 16 | AE46: =SUM(E46:AD46) -> 621
B47: 2 | C47: 2. H. M. NASIM KHAN | E47: 1 | F47: 1 | G47: 1 | H47: 1 | I47: 2 | J47: 1 | K47: 2 | L47: 4 | M47: 6 | N47: 0 | O47: 1 | P47: 1 | Q47: 2 | R47: 2 | S47: 1 | T47: 3 | U47: 5 | V47: 1 | W47: 0 | X47: 2 | Y47: 5 | Z47: 7 | AA47: 5 | AB47: 0 | AC47: 3 | AD47: 10 | AE47: =SUM(E47:AD47) -> 67
B48: 3 | C48: 3. Dr. H. AKIK ZAMAN, M.Pd.I. | E48: 0 | F48: 1 | G48: 1 | H48: 1 | I48: 2 | J48: 0 | K48: 1 | L48: 1 | M48: 1 | N48: 0 | O48: 2 | P48: 0 | Q48: 0 | R48: 1 | S48: 2 | T48: 0 | U48: 0 | V48: 1 | W48: 1 | X48: 1 | Y48: 0 | Z48: 1 | AA48: 6 | AB48: 1 | AC48: 1 | AD48: 1 | AE48: =SUM(E48:AD48) -> 26
B49: 4 | C49: 4. AHMAD RIFA'I, S.H. | E49: 0 | F49: 2 | G49: 0 | H49: 0 | I49: 0 | J49: 1 | K49: 0 | L49: 2 | M49: 1 | N49: 2 | O49: 0 | P49: 1 | Q49: 0 | R49: 0 | S49: 0 | T49: 0 | U49: 2 | V49: 0 | W49: 0 | X49: 0 | Y49: 1 | Z49: 1 | AA49: 0 | AB49: 1 | AC49: 0 | AD49: 1 | AE49: =SUM(E49:AD49) -> 15
B50: 5 | C50: 5. Drs. H. MAHFUD M.N. | E50: 0 | F50: 1 | G50: 0 | H50: 1 | I50: 3 | J50: 0 | K50: 1 | L50: 0 | M50: 0 | N50: 0 | O50: 0 | P50: 0 | Q50: 0 | R50: 0 | S50: 0 | T50: 0 | U50: 1 | V50: 0 | W50: 1 | X50: 0 | Y50: 0 | Z50: 1 | AA50: 2 | AB50: 0 | AC50: 3 | AD50: 0 | AE50: =SUM(E50:AD50) -> 14
B51: 6 | C51: 6. NURHAYATI, S.Pd. | E51: 1 | F51: 0 | G51: 0 | H51: 0 | I51: 0 | J51: 0 | K51: 0 | L51: 1 | M51: 1 | N51: 0 | O51: 2 | P51: 0 | Q51: 0 | R51: 0 | S51: 0 | T51: 1 | U51: 0 | V51: 0 | W51: 0 | X51: 0 | Y51: 1 | Z51: 3 | AA51: 0 | AB51: 0 | AC51: 1 | AD51: 0 | AE51: =SUM(E51:AD51) -> 11
...

Sheet SARIMULYO
C2: Kecamatan | D2: CLURING
C3: Kabupaten | D3: BANYUWANGI
C4: Provinsi | D4: JAWA TIMUR
C9: Kelurahan | D9: SARIMULYO
A12: I | B12: DATA PEMILIH DAN PENGGUNAAN HAK PILIH | AA12: JUMLAH AKHIR
A13: A | B13: DATA PEMILIH | E13: TPS 001 | F13: TPS 002 | G13: TPS 003 | H13: TPS 004 | I13: TPS 005 | J13: TPS 006 | K13: TPS 007 | L13: TPS 008 | M13: TPS 009 | N13: TPS 010 | O13: TPS 011 | P13: TPS 012 | Q13: TPS 013 | R13: TPS 014 | S13: TPS 015 | T13: TPS 016 | U13: TPS 017 | V13: TPS 018 | W13: TPS 019 | X13: TPS 020 | Y13: TPS 021 | Z13: TPS 022
B14: Jumlah Pemilih dalam Daftar Pemilih Tetap (DPT) | D14: LK | E14: 143 | F14: 119 | G14: 113 | H14: 127 | I14: 135 | J14: 129 | K14: 128 | L14: 102 | M14: 122 | N14: 114 | O14: 136 | P14: 113 | Q14: 124 | R14: 135 | S14: 125 | T14: 110 | U14: 115 | V14: 126 | W14: 143 | X14: 155 | Y14: 143 | Z14: 137 | AA14: =SUM(E14:Z14) -> 2794
D15: PR | E15: 125 | F15: 134 | G15: 114 | H15: 133 | I15: 137 | J15: 152 | K15: 136 | L15: 110 | M15: 120 | N15: 117 | O15: 129 | P15: 135 | Q15: 118 | R15: 137 | S15: 122 | T15: 115 | U15: 114 | V15: 139 | W15: 137 | X15: 142 | Y15: 149 | Z15: 132 | AA15: =SUM(E15:Z15) -> 2847
D16: JML | E16: 268 | F16: 253 | G16: 227 | H16: 260 | I16: 272 | J16: 281 | K16: 264 | L16: 212 | M16: 242 | N16: 231 | O16: 265 | P16: 248 | Q16: 242 | R16: 272 | S16: 247 | T16: 225 | U16: 229 | V16: 265 | W16: 280 | X16: 297 | Y16: 292 | Z16: 269 | AA16: =SUM(E16:Z16) -> 5641
A18: B | B18: PENGGUNA HAK PILIH
B19: 1. | C19: Jumlah pengguna hak pilih dalam Daftar Pemilih Tetap (DPT) | D19: LK | E19: 103 | F19: 93 | G19: 79 | H19: 82 | I19: 98 | J19: 95 | K19: 91 | L19: 71 | M19: 92 | N19: 78 | O19: 103 | P19: 94 | Q19: 96 | R19: 96 | S19: 88 | T19: 78 | U19: 94 | V19: 85 | W19: 85 | X19: 119 | Y19: 103 | Z19: 115 | AA19: =SUM(E19:Z19) -> 2038
D20: PR | E20: 104 | F20: 113 | G20: 88 | H20: 106 | I20: 104 | J20: 124 | K20: 107 | L20: 74 | M20: 101 | N20: 84 | O20: 103 | P20: 113 | Q20: 97 | R20: 111 | S20: 94 | T20: 87 | U20: 87 | V20: 118 | W20: 118 | X20: 122 | Y20: 122 | Z20: 113 | AA20: =SUM(E20:Z20) -> 2290
D21: JML | E21: 207 | F21: 206 | G21: 167 | H21: 188 | I21: 202 | J21: 219 | K21: 198 | L21: 145 | M21: 193 | N21: 162 | O21: 206 | P21: 207 | Q21: 193 | R21: 207 | S21: 182 | T21: 165 | U21: 181 | V21: 203 | W21: 203 | X21: 241 | Y21: 225 | Z21: 228 | AA21: =SUM(E21:Z21) -> 4328
B22: 2. | C22: Jumlah pengguna hak pilih dalam Daftar Pemilih Tambahan (DPTb) | D22: LK | E22: 0 | F22: 0 | G22: 0 | H22: 0 | I22: 0 | J22: 0 | K22: 1 | L22: 0 | M22: 0 | N22: 0 | O22: 0 | P22: 0 | Q22: 0 | R22: 0 | S22: 0 | T22: 0 | U22: 0 | V22: 0 | W22: 0 | X22: 0 | Y22: 0 | Z22: 0 | AA22: =SUM(E22:Z22) -> 1
D23: PR | E23: 0 | F23: 0 | G23: 0 | H23: 0 | I23: 0 | J23: 0 | K23: 0 | L23: 0 | M23: 0 | N23: 0 | O23: 0 | P23: 0 | Q23: 0 | R23: 0 | S23: 0 | T23: 0 | U23: 0 | V23: 0 | W23: 0 | X23: 0 | Y23: 0 | Z23: 0 | AA23: =SUM(E23:Z23) -> 0
D24: JML | E24: 0 | F24: 0 | G24: 0 | H24: 0 | I24: 0 | J24: 0 | K24: 1 | L24: 0 | M24: 0 | N24: 0 | O24: 0 | P24: 0 | Q24: 0 | R24: 0 | S24: 0 | T24: 0 | U24: 0 | V24: 0 | W24: 0 | X24: 0 | Y24: 0 | Z24: 0 | AA24: =SUM(E24:Z24) -> 1
B25: 3. | C25: Jumlah pengguna hak pilih dalam Daftar Pemilih Khusus (DPK) | D25: LK | E25: 3 | F25: 1 | G25: 2 | H25: 0 | I25: 2 | J25: 3 | K25: 1 | L25: 1 | M25: 1 | N25: 2 | O25: 0 | P25: 0 | Q25: 2 | R25: 3 | S25: 2 | T25: 0 | U25: 1 | V25: 2 | W25: 2 | X25: 0 | Y25: 0 | Z25: 0 | AA25: =SUM(E25:Z25) -> 28
D26: PR | E26: 2 | F26: 3 | G26: 2 | H26: 1 | I26: 2 | J26: 2 | K26: 0 | L26: 3 | M26: 4 | N26: 3 | O26: 3 | P26: 3 | Q26: 2 | R26: 3 | S26: 4 | T26: 0 | U26: 4 | V26: 2 | W26: 0 | X26: 0 | Y26: 0 | Z26: 0 | AA26: =SUM(E26:Z26) -> 43
D27: JML | E27: 5 | F27: 4 | G27: 4 | H27: 1 | I27: 4 | J27: 5 | K27: 1 | L27: 4 | M27: 5 | N27: 5 | O27: 3 | P27: 3 | Q27: 4 | R27: 6 | S27: 6 | T27: 0 | U27: 5 | V27: 4 | W27: 2 | X27: 0 | Y27: 0 | Z27: 0 | AA27: =SUM(E27:Z27) -> 71
B28: 4. | C28: Jumlah Pengguna Hak Pilih (B.1+B.2+B.3) | D28: LK | E28: 106 | F28: 94 | G28: 81 | H28: 82 | I28: 100 | J28: 98 | K28: 93 | L28: 72 | M28: 93 | N28: 80 | O28: 103 | P28: 94 | Q28: 98 | R28: 99 | S28: 90 | T28: 78 | U28: 95 | V28: 87 | W28: 98 | X28: 119 | Y28: 103 | Z28: 115 | AA28: =SUM(E28:Z28) -> 2078
D29: PR | E29: 106 | F29: 116 | G29: 90 | H29: 107 | I29: 106 | J29: 126 | K29: 107 | L29: 77 | M29: 105 | N29: 87 | O29: 106 | P29: 116 | Q29: 99 | R29: 114 | S29: 98 | T29: 87 | U29: 91 | V29: 120 | W29: 104 | X29: 122 | Y29: 122 | Z29: 113 | AA29: =SUM(E29:Z29) -> 2319
D30: JML | E30: 212 | F30: 210 | G30: 171 | H30: 189 | I30: 206 | J30: 224 | K30: 200 | L30: 149 | M30: 198 | N30: 167 | O30: 209 | P30: 210 | Q30: 197 | R30: 213 | S30: 188 | T30: 165 | U30: 186 | V30: 207 | W30: 202 | X30: 241 | Y30: 225 | Z30: 228 | AA30: =SUM(E30:Z30) -> 4397
A32: II | B32: DATA PENGGUNAAN SURAT SUARA
A33: 1 | B33: Jumlah surat suara yang diterima, termasuk surat suara cadangan 2,5% dari DPT | E33: 275 | F33: 259 | G33: 232 | H33: 256 | I33: 278 | J33: 277 | K33: 270 | L33: 218 | M33: 237 | N33: 236 | O33: 261 | P33: 253 | Q33: 247 | R33: 257 | S33: 252 | T33: 210 | U33: 234 | V33: 271 | W33: 275 | X33: 303 | Y33: 298 | Z33: 275 | AA33: =SUM(E33:Z33) -> 5674
A34: 2 | B34: Jumlah surat suara yang digunakan | E34: 212 | F34: 210 | G34: 171 | H34: 189 | I34: 206 | J34: 224 | K34: 200 | L34: 149 | M34: 203 | N34: 179 | O34: 209 | P34: 210 | Q34: 197 | R34: 213 | S34: 188 | T34: 165 | U34: 186 | V34: 207 | W34: 202 | X34: 241 | Y34: 225 | Z34: 228 | AA34: =SUM(E34:Z34) -> 4414
A35: 3 | B35: Jumlah surat suara dikembalikan oleh pemilih (karena rusak atau keliru coblos) | E35: 0 | F35: 0 | G35: 0 | H35: 1 | I35: 0 | J35: 1 | K35: 0 | L35: 0 | M35: 0 | N35: 0 | O35: 0 | P35: 1 | Q35: 1 | R35: 0 | S35: 0 | T35: 0 | U35: 0 | V35: 2 | W35: 0 | X35: 0 | Y35: 0 | Z35: 0 | AA35: =SUM(E35:Z35) -> 6
A36: 4 | B36: Jumlah surat suara yang tidak digunakan/tidak terpakai, termasuk sisa surat suara cadangan | E36: 63 | F36: 49 | G36: 61 | H36: 66 | I36: 72 | J36: 82 | K36: 70 | L36: 69 | M36: 39 | N36: 69 | O36: 52 | P36: 42 | Q36: 49 | R36: 44 | S36: 64 | T36: 45 | U36: 48 | V36: 62 | W36: 73 | X36: 62 | Y36: 73 | Z36: 47 | AA36: =SUM(E36:Z36) -> 1301
A38: III | B38: DATA PEMILIH DISABILITAS
B39: Jumlah seluruh Pemilih disabilitas yang menggunakan hak pilih | D39: LK | E39: 0 | F39: 0 | G39: 0 | H39: 0 | I39: 0 | J39: 0 | K39: 0 | L39: 0 | M39: 0 | N39: 0 | O39: 0 | P39: 0 | Q39: 0 | R39: 2 | S39: 0 | T39: 0 | U39: 0 | V39: 0 | W39: 0 | X39: 0 | Y39: 0 | Z39: 0 | AA39: =SUM(E39:Z39) -> 2
D40: PR | E40: 0 | F40: 0 | G40: 0 | H40: 0 | I40: 0 | J40: 0 | K40: 0 | L40: 0 | M40: 0 | N40: 0 | O40: 0 | P40: 0 | Q40: 0 | R40: 0 | S40: 0 | T40: 0 | U40: 0 | V40: 0 | W40: 0 | X40: 0 | Y40: 0 | Z40: 0 | AA40: =SUM(E40:Z40) -> 0
D41: JML | E41: =SUM(E39:E40) -> 0 | F41: =SUM(F39:F40) -> 0 | G41: =SUM(G39:G40) -> 0 | H41: =SUM(H39:H40) -> 0 | I41: =SUM(I39:I40) -> 0 | J41: =SUM(J39:J40) -> 0 | K41: =SUM(K39:K40) -> 0 | L41: =SUM(L39:L40) -> 0 | ... Z41: =SUM(Z39:Z40) -> 0 | AA41: =SUM(E41:Z41) -> 2
A43: IV | B43: DATA RINCIAN PEROLEHAN SUARA PASANGAN CALON BUPATI DAN WAKIL BUPATI
A44: NOMOR DAN NAMA CALON
A45: A.1 | B45: 1. | C45: Partai Kebangkitan Bangsa | E45: 22 | F45: 5 | G45: 4 | H45: 8 | I45: 12 | J45: 7 | K45: 5 | L45: 1 | M45: 5 | N45: 5 | O45: 12 | P45: 5 | Q45: 2 | R45: 6 | S45: 1 | T45: 2 | U45: 3 | V45: 8 | W45: 8 | X45: 4 | Y45: 6 | Z45: 4 | AA45: =SUM(E45:Z45) -> 135
A46: A.2 | B46: 1 | C46: 1. Dr. Hj. NIHAYATUL WAFIROH, M.A. | E46: 52 | F46: 19 | G46: 8 | H46: 24 | I46: 28 | J46: 31 | K46: 18 | L46: 7 | M46: 8 | N46: 7 | O46: 21 | P46: 7 | Q46: 10 | R46: 2 | S46: 7 | T46: 5 | U46: 13 | V46: 21 | W46: 9 | X46: 42 | Y46: 20 | Z46: 7 | AA46: =SUM(E46:Z46) -> 366
B47: 2 | C47: 2. H. M. NASIM KHAN | E47: 19 | F47: 22 | G47: 0 | H47: 7 | I47: 7 | J47: 3 | K47: 2 | L47: 16 | M47: 6 | N47: 12 | O47: 10 | P47: 0 | Q47: 2 | R47: 3 | S47: 1 | T47: 1 | U47: 3 | V47: 76 | W47: 75 | X47: 33 | Y47: 16 | Z47: 39 | AA47: =SUM(E47:Z47) -> 353
B48: 3 | C48: 3. Dr. H. AKIK ZAMAN, M.Pd.I. | E48: 1 | F48: 1 | G48: 2 | H48: 1 | I48: 0 | J48: 0 | K48: 0 | L48: 0 | M48: 0 | N48: 1 | O48: 0 | P48: 0 | Q48: 0 | R48: 0 | S48: 0 | T48: 1 | U48: 0 | V48: 1 | W48: 7 | X48: 2 | Y48: 0 | Z48: 1 | AA48: =SUM(E48:Z48) -> 18
B49: 4 | C49: 4. AHMAD RIFA'I, S.H. | E49: 0 | F49: 0 | G49: 1 | H49: 2 | I49: 0 | J49: 0 | K49: 2 | L49: 2 | M49: 1 | N49: 1 | O49: 0 | P49: 0 | Q49: 1 | R49: 0 | S49: 0 | T49: 1 | U49: 0 | V49: 3 | W49: 0 | X49: 1 | Y49: 2 | Z49: 0 | AA49: =SUM(E49:Z49) -> 17
B50: 5 | C50: 5. Drs. H. MAHFUD M.N. | E50: 0 | F50: 0 | G50: 0 | H50: 1 | I50: 0 | J50: 0 | K50: 0 | L50: 0 | M50: 0 | N50: 0 | O50: 1 | P50: 0 | Q50: 1 | R50: 0 | S50: 0 | T50: 0 | U50: 1 | V50: 2 | W50: 1 | X50: 0 | Y50: 0 | Z50: 0 | AA50: =SUM(E50:Z50) -> 7
B51: 6 | C51: 6. NURHAYATI, S.Pd. | E51: 1 | F51: 0 | G51: 0 | H51: 2 | I51: 1 | J51: 0 | K51: 1 | L51: 0 | M51: 0 | N51: 1 | O51: 0 | P51: 0 | Q51: 0 | R51: 1 | S51: 0 | T51: 0 | U51: 0 | V51: 1 | W51: 2 | X51: 1 | Y51: 1 | Z51: 0 | AA51: =SUM(E51:Z51) -> 12
...

Sheet SEMBULUNG
C2: Kecamatan | D2: CLURING
C3: Kabupaten | D3: BANYUWANGI
C4: Provinsi | D4: JAWA TIMUR
C9: Kelurahan | D9: SEMBULUNG
A12: I | B12: DATA PEMILIH DAN PENGGUNAAN HAK PILIH | AC12: JUMLAH AKHIR
A13: A | B13: DATA PEMILIH | E13: TPS 001 | F13: TPS 002 | G13: TPS 003 | H13: TPS 004 | I13: TPS 005 | J13: TPS 006 | K13: TPS 007 | L13: TPS 008 | M13: TPS 009 | N13: TPS 010 | O13: TPS 011 | P13: TPS 012 | Q13: TPS 013 | R13: TPS 014 | S13: TPS 015 | T13: TPS 016 | U13: TPS 017 | V13: TPS 018 | W13: TPS 019 | X13: TPS 020 | Y13: TPS 021 | Z13: TPS 022 | AA13: TPS 023 | AB13: TPS 024
B14: Jumlah Pemilih dalam Daftar Pemilih Tetap (DPT) | D14: LK | E14: 123 | F14: 126 | G14: 140 | H14: 149 | I14: 141 | J14: 133 | K14: 140 | L14: 143 | M14: 128 | N14: 131 | O14: 126 | P14: 120 | Q14: 133 | R14: 139 | S14: 136 | T14: 139 | U14: 134 | V14: 136 | W14: 146 | X14: 127 | Y14: 128 | Z14: 132 | AA14: 133 | AB14: 122 | AC14: =SUM(E14:AB14) -> 3205
D15: PR | E15: 146 | F15: 131 | G15: 129 | H15: 138 | I15: 132 | J15: 144 | K15: 136 | L15: 148 | M15: 127 | N15: 123 | O15: 129 | P15: 117 | Q15: 120 | R15: 153 | S15: 135 | T15: 142 | U15: 130 | V15: 157 | W15: 133 | X15: 162 | Y15: 127 | Z15: 145 | AA15: 124 | AB15: 112 | AC15: =SUM(E15:AB15) -> 3240
D16: JML | E16: =SUM(E14:E15) -> 269 | F16: =SUM(F14:F15) -> 257 | G16: =SUM(G14:G15) -> 269 | H16: =SUM(H14:H15) -> 287 | I16: =SUM(I14:I15) -> 273 | J16: =SUM(J14:J15) -> 277 | K16: =SUM(K14:K15) -> 276 | L16: =SUM(L14:L15) -> 291 | ... AB16: =SUM(AB14:AB15) -> 234 | AC16: =SUM(E16:AB16) -> 6445
A18: B | B18: PENGGUNA HAK PILIH
B19: 1. | C19: Jumlah pengguna hak pilih dalam Daftar Pemilih Tetap (DPT) | D19: LK | E19: 89 | F19: 100 | G19: 104 | H19: 110 | I19: 120 | J19: 101 | K19: 105 | L19: 112 | M19: 104 | N19: 99 | O19: 95 | P19: 92 | Q19: 91 | R19: 106 | S19: 91 | T19: 100 | U19: 102 | V19: 104 | W19: 116 | X19: 106 | Y19: 93 | Z19: 102 | AA19: 101 | AB19: 97 | AC19: =SUM(E19:AB19) -> 2440
D20: PR | E20: 115 | F20: 107 | G20: 103 | H20: 110 | I20: 114 | J20: 116 | K20: 112 | L20: 123 | M20: 110 | N20: 98 | O20: 102 | P20: 93 | Q20: 86 | R20: 121 | S20: 107 | T20: 109 | U20: 106 | V20: 119 | W20: 110 | X20: 133 | Y20: 99 | Z20: 107 | AA20: 110 | AB20: 87 | AC20: =SUM(E20:AB20) -> 2597
D21: JML | E21: =SUM(E19:E20) -> 204 | F21: =SUM(F19:F20) -> 207 | G21: =SUM(G19:G20) -> 207 | H21: =SUM(H19:H20) -> 220 | I21: =SUM(I19:I20) -> 234 | J21: =SUM(J19:J20) -> 217 | K21: =SUM(K19:K20) -> 217 | L21: =SUM(L19:L20) -> 235 | ... AB21: =SUM(AB19:AB20) -> 184 | AC21: =SUM(E21:AB21) -> 5037
B22: 2. | C22: Jumlah pengguna hak pilih dalam Daftar Pemilih Tambahan (DPTb) | D22: LK | E22: 0 | F22: 0 | G22: 0 | H22: 0 | I22: 0 | J22: 0 | K22: 0 | L22: 0 | M22: 0 | N22: 0 | O22: 0 | P22: 0 | Q22: 0 | R22: 0 | S22: 0 | T22: 0 | U22: 0 | V22: 0 | W22: 0 | X22: 0 | Y22: 0 | Z22: 0 | AA22: 0 | AB22: 1 | AC22: =SUM(E22:AB22) -> 1
D23: PR | E23: 0 | F23: 1 | G23: 0 | H23: 0 | I23: 0 | J23: 0 | K23: 0 | L23: 0 | M23: 0 | N23: 0 | O23: 0 | P23: 0 | Q23: 0 | R23: 1 | S23: 0 | T23: 0 | U23: 0 | V23: 0 | W23: 0 | X23: 0 | Y23: 0 | Z23: 0 | AA23: 0 | AB23: 0 | AC23: =SUM(E23:AB23) -> 2
D24: JML | E24: =SUM(E22:E23) -> 0 | F24: =SUM(F22:F23) -> 1 | G24: =SUM(G22:G23) -> 0 | H24: =SUM(H22:H23) -> 0 | I24: =SUM(I22:I23) -> 0 | J24: =SUM(J22:J23) -> 0 | K24: =SUM(K22:K23) -> 0 | L24: =SUM(L22:L23) -> 0 | ... S24: =SUM(S22:S23) -> 0 | T24: 0 | U24: =SUM(U22:U23) -> 0 | V24: =SUM(V22:V23) -> 0 | W24: =SUM(W22:W23) -> 0 | X24: =SUM(X22:X23) -> 0 | Y24: =SUM(Y22:Y23) -> 0 | Z24: =SUM(Z22:Z23) -> 0 | AA24: =SUM(AA22:AA23) -> 0 | AB24: =SUM(AB22:AB23) -> 1 | AC24: =SUM(E24:AB24) -> 3
B25: 3. | C25: Jumlah pengguna hak pilih dalam Daftar Pemilih Khusus (DPK) | D25: LK | E25: 0 | F25: 1 | G25: 1 | H25: 1 | I25: 0 | J25: 0 | K25: 0 | L25: 1 | M25: 0 | N25: 0 | O25: 3 | P25: 1 | Q25: 2 | R25: 3 | S25: 0 | T25: 0 | U25: 0 | V25: 1 | W25: 0 | X25: 0 | Y25: 0 | Z25: 0 | AA25: 1 | AB25: 0 | AC25: =SUM(E25:AB25) -> 15
D26: PR | E26: 0 | F26: 1 | G26: 0 | H26: 1 | I26: 0 | J26: 2 | K26: 0 | L26: 0 | M26: 0 | N26: 0 | O26: 1 | P26: 0 | Q26: 1 | R26: 0 | S26: 0 | T26: 1 | U26: 0 | V26: 0 | W26: 1 | X26: 0 | Y26: 0 | Z26: 1 | AA26: 1 | AB26: 2 | AC26: =SUM(E26:AB26) -> 12
D27: JML | E27: =SUM(E25:E26) -> 0 | F27: =SUM(F25:F26) -> 2 | G27: =SUM(G25:G26) -> 1 | H27: =SUM(H25:H26) -> 2 | I27: =SUM(I25:I26) -> 0 | J27: =SUM(J25:J26) -> 2 | K27: =SUM(K25:K26) -> 0 | L27: =SUM(L25:L26) -> 1 | ... AB27: =SUM(AB25:AB26) -> 2 | AC27: =SUM(E27:AB27) -> 27
B28: 4. | C28: Jumlah Pengguna Hak Pilih (B.1+B.2+B.3) | D28: LK | E28: =SUM(E19,E22,E25) -> 89 | F28: =SUM(F19,F22,F25) -> 101 | G28: =SUM(G19,G22,G25) -> 105 | H28: =SUM(H19,H22,H25) -> 111 | I28: =SUM(I19,I22,I25) -> 120 | J28: =SUM(J19,J22,J25) -> 101 | K28: =SUM(K19,K22,K25) -> 105 | L28: =SUM(L19,L22,L25) -> 113 | ... AB28: =SUM(AB19,AB22,AB25) -> 98 | AC28: =SUM(E28:AB28) -> 2456
D29: PR | E29: =SUM(E20,E23,E26) -> 115 | F29: =SUM(F20,F23,F26) -> 109 | G29: =SUM(G20,G23,G26) -> 103 | H29: =SUM(H20,H23,H26) -> 111 | I29: =SUM(I20,I23,I26) -> 114 | J29: =SUM(J20,J23,J26) -> 118 | K29: =SUM(K20,K23,K26) -> 112 | L29: =SUM(L20,L23,L26) -> 123 | ... AB29: =SUM(AB20,AB23,AB26) -> 89 | AC29: =SUM(E29:AB29) -> 2611
D30: JML | E30: =SUM(E28:E29) -> 204 | F30: =SUM(F28:F29) -> 210 | G30: =SUM(G28:G29) -> 208 | H30: =SUM(H28:H29) -> 222 | I30: =SUM(I28:I29) -> 234 | J30: =SUM(J28:J29) -> 219 | K30: =SUM(K28:K29) -> 217 | L30: =SUM(L28:L29) -> 236 | ... AB30: =SUM(AB28:AB29) -> 187 | AC30: =SUM(E30:AB30) -> 5067
A32: II | B32: DATA PENGGUNAAN SURAT SUARA
A33: 1 | B33: Jumlah surat suara yang diterima, termasuk surat suara cadangan 2,5% dari DPT | E33: 275 | F33: 263 | G33: 275 | H33: 293 | I33: 279 | J33: 283 | K33: 282 | L33: 297 | M33: 261 | N33: 261 | O33: 261 | P33: 242 | Q33: 259 | R33: 299 | S33: 277 | T33: 285 | U33: 270 | V33: 299 | W33: 285 | X33: 295 | Y33: 261 | Z33: 283 | AA33: 263 | AB33: 239 | AC33: =SUM(E33:AB33) -> 6587
A34: 2 | B34: Jumlah surat suara yang digunakan | E34: 204 | F34: 210 | G34: 208 | H34: 222 | I34: 234 | J34: 219 | K34: 217 | L34: 236 | M34: 214 | N34: 197 | O34: 201 | P34: 186 | Q34: 180 | R34: 231 | S34: 198 | T34: 210 | U34: 208 | V34: 224 | W34: 227 | X34: 239 | Y34: 192 | Z34: 210 | AA34: 213 | AB34: 187 | AC34: =SUM(E34:AB34) -> 5067
A35: 3 | B35: Jumlah surat suara dikembalikan oleh pemilih (karena rusak atau keliru coblos) | E35: 0 | F35: 0 | G35: 0 | H35: 1 | I35: 0 | J35: 0 | K35: 0 | L35: 0 | M35: 0 | N35: 0 | O35: 0 | P35: 0 | Q35: 0 | R35: 0 | S35: 0 | T35: 0 | U35: 0 | V35: 1 | W35: 0 | X35: 0 | Y35: 0 | Z35: 0 | AA35: 0 | AB35: 0 | AC35: =SUM(E35:AB35) -> 2
A36: 4 | B36: Jumlah surat suara yang tidak digunakan/tidak terpakai, termasuk sisa surat suara cadangan | E36: =E33-(E34+E35) -> 71 | F36: =F33-(F34+F35) -> 53 | G36: =G33-(G34+G35) -> 67 | H36: =H33-(H34+H35) -> 70 | I36: =I33-(I34+I35) -> 45 | J36: =J33-(J34+J35) -> 64 | K36: =K33-(K34+K35) -> 65 | L36: =L33-(L34+L35) -> 61 | ... AB36: =AB33-(AB34+AB35) -> 52 | AC36: =SUM(E36:AB36) -> 1518
A38: III | B38: DATA PEMILIH DISABILITAS
B39: Jumlah seluruh Pemilih disabilitas yang menggunakan hak pilih | D39: LK | E39: 0 | F39: 0 | G39: 0 | H39: 0 | I39: 0 | J39: 0 | K39: 0 | L39: 0 | M39: 0 | N39: 0 | O39: 0 | P39: 0 | Q39: 0 | R39: 0 | S39: 0 | T39: 0 | U39: 0 | V39: 0 | W39: 2 | X39: 0 | Y39: 1 | Z39: 0 | AA39: 0 | AB39: 0 | AC39: =SUM(E39:AB39) -> 3
D40: PR | E40: 0 | F40: 0 | G40: 0 | H40: 0 | I40: 0 | J40: 0 | K40: 0 | L40: 0 | M40: 0 | N40: 0 | O40: 0 | P40: 0 | Q40: 0 | R40: 0 | S40: 1 | T40: 0 | U40: 0 | V40: 1 | W40: 1 | X40: 0 | Y40: 0 | Z40: 0 | AA40: 0 | AB40: 0 | AC40: =SUM(E40:AB40) -> 3
D41: JML | E41: =SUM(E39:E40) -> 0 | F41: =SUM(F39:F40) -> 0 | G41: =SUM(G39:G40) -> 0 | H41: =SUM(H39:H40) -> 0 | I41: =SUM(I39:I40) -> 0 | J41: =SUM(J39:J40) -> 0 | K41: =SUM(K39:K40) -> 0 | L41: =SUM(L39:L40) -> 0 | ... AB41: =SUM(AB39:AB40) -> 0 | AC41: =SUM(E41:AB41) -> 6
A43: IV | B43: DATA RINCIAN PEROLEHAN SUARA PASANGAN CALON BUPATI DAN WAKIL BUPATI
A44: NOMOR DAN NAMA CALON
A45: A.1 | B45: 1. | C45: Partai Kebangkitan Bangsa | E45: 6 | F45: 8 | G45: 7 | H45: 10 | I45: 6 | J45: 11 | K45: 7 | L45: 10 | M45: 5 | N45: 9 | O45: 2 | P45: 6 | Q45: 5 | R45: 4 | S45: 8 | T45: 8 | U45: 13 | V45: 9 | W45: 16 | X45: 6 | Y45: 5 | Z45: 8 | AA45: 5 | AB45: 15 | AC45: =SUM(E45:AB45) -> 189
A46: A.2 | B46: 1 | C46: 1. Dr. Hj. NIHAYATUL WAFIROH, M.A. | E46: 20 | F46: 25 | G46: 40 | H46: 19 | I46: 32 | J46: 34 | K46: 40 | L46: 19 | M46: 15 | N46: 7 | O46: 12 | P46: 23 | Q46: 1 | R46: 5 | S46: 6 | T46: 6 | U46: 15 | V46: 17 | W46: 19 | X46: 28 | Y46: 21 | Z46: 20 | AA46: 18 | AB46: 41 | AC46: =SUM(E46:AB46) -> 483
B47: 2 | C47: 2. H. M. NASIM KHAN | E47: 2 | F47: 3 | G47: 1 | H47: 4 | I47: 2 | J47: 7 | K47: 1 | L47: 4 | M47: 3 | N47: 3 | O47: 0 | P47: 8 | Q47: 5 | R47: 3 | S47: 3 | T47: 0 | U47: 6 | V47: 1 | W47: 9 | X47: 2 | Y47: 2 | Z47: 1 | AA47: 1 | AB47: 2 | AC47: =SUM(E47:AB47) -> 73
B48: 3 | C48: 3. Dr. H. AKIK ZAMAN, M.Pd.I. | E48: 0 | F48: 0 | G48: 0 | H48: 2 | I48: 1 | J48: 2 | K48: 1 | L48: 0 | M48: 2 | N48: 0 | O48: 1 | P48: 1 | Q48: 0 | R48: 0 | S48: 0 | T48: 0 | U48: 0 | V48: 0 | W48: 0 | X48: 1 | Y48: 0 | Z48: 0 | AA48: 0 | AB48: 0 | AC48: =SUM(E48:AB48) -> 11
B49: 4 | C49: 4. AHMAD RIFA'I, S.H. | E49: 2 | F49: 0 | G49: 0 | H49: 1 | I49: 0 | J49: 0 | K49: 1 | L49: 0 | M49: 0 | N49: 1 | O49: 0 | P49: 4 | Q49: 0 | R49: 0 | S49: 0 | T49: 0 | U49: 1 | V49: 0 | W49: 0 | X49: 0 | Y49: 0 | Z49: 0 | AA49: 2 | AB49: 0 | AC49: =SUM(E49:AB49) -> 12
B50: 5 | C50: 5. Drs. H. MAHFUD M.N. | E50: 0 | F50: 0 | G50: 1 | H50: 0 | I50: 0 | J50: 1 | K50: 0 | L50: 0 | M50: 1 | N50: 0 | O50: 0 | P50: 2 | Q50: 0 | R50: 0 | S50: 0 | T50: 0 | U50: 1 | V50: 1 | W50: 2 | X50: 1 | Y50: 0 | Z50: 0 | AA50: 0 | AB50: 0 | AC50: =SUM(E50:AB50) -> 10
B51: 6 | C51: 6. NURHAYATI, S.Pd. | E51: 1 | F51: 0 | G51: 2 | H51: 1 | I51: 0 | J51: 2 | K51: 2 | L51: 1 | M51: 0 | N51: 0 | O51: 1 | P51: 2 | Q51: 1 | R51: 1 | S51: 0 | T51: 1 | U51: 2 | V51: 1 | W51: 5 | X51: 1 | Y51: 1 | Z51: 1 | AA51: 0 | AB51: 1 | AC51: =SUM(E51:AB51) -> 27
...

Sheet SRATEN
C2: Kecamatan | D2: CLURING
C3: Kabupaten | D3: BANYUWANGI
C4: Provinsi | D4: JAWA TIMUR
C9: Kelurahan | D9: SRATEN
A12: I | B12: DATA PEMILIH DAN PENGGUNAAN HAK PILIH | AB12: JUMLAH AKHIR
A13: A | B13: DATA PEMILIH | E13: TPS 001 | F13: TPS 002 | G13: TPS 003 | H13: TPS 004 | I13: TPS 005 | J13: TPS 006 | K13: TPS 007 | L13: TPS 008 | M13: TPS 009 | N13: TPS 010 | O13: TPS 011 | P13: TPS 012 | Q13: TPS 013 | R13: TPS 014 | S13: TPS 015 | T13: TPS 016 | U13: TPS 017 | V13: TPS 018 | W13: TPS 019 | X13: TPS 020 | Y13: TPS 021 | Z13: TPS 022 | AA13: TPS 023
B14: Jumlah Pemilih dalam Daftar Pemilih Tetap (DPT) | D14: LK | AB14: =SUM(E14:AA14) -> 0
D15: PR | AB15: =SUM(E15:AA15) -> 0
