Workbook

Sheet DPRD KABUPATEN
C8: Kecamatan | D8: SINGOJURUH
C9: Kabupaten | D9: BANYUWANGI
C10: Provinsi | D10: JAWA TIMUR
A12: I | B12: DATA PEMILIH DAN PENGGUNAAN HAK PILIH | E12: JUMLAH AKHIR
A13: A | B13: DATA PEMILIH
B14: Jumlah Pemilih dalam Daftar Pemilih Tetap (DPT) | D14: LK | E14: =ALASMALANG!V14+'BENELAN KIDUL'!S14+CANTUK!T14+GAMBOR!N14+GUMIRIH!S14+KEMIRI!U14+LEMAHBANGKULON!Q14+PADANG!Q14+SINGOJURUH!AC14+SINGOLATREN!T14+SUMBERBARU!S14 -> 19838
D15: PR | E15: =ALASMALANG!V15+'BENELAN KIDUL'!S15+CANTUK!T15+GAMBOR!N15+GUMIRIH!S15+KEMIRI!U15+LEMAHBANGKULON!Q15+PADANG!Q15+SINGOJURUH!AC15+SINGOLATREN!T15+SUMBERBARU!S15 -> 20150
D16: JML | E16: =SUM(E14:E15) -> 39988
A18: B | B18: PENGGUNA HAK PILIH
B19: 1. | C19: Jumlah pengguna hak pilih dalam Daftar Pemilih Tetap (DPT) | D19: LK | E19: =ALASMALANG!V19+'BENELAN KIDUL'!S19+CANTUK!T19+GAMBOR!N19+GUMIRIH!S19+KEMIRI!U19+LEMAHBANGKULON!Q19+PADANG!Q19+SINGOJURUH!AC19+SINGOLATREN!T19+SUMBERBARU!S19 -> 14812
D20: PR | E20: =ALASMALANG!V20+'BENELAN KIDUL'!S20+CANTUK!T20+GAMBOR!N20+GUMIRIH!S20+KEMIRI!U20+LEMAHBANGKULON!Q20+PADANG!Q20+SINGOJURUH!AC20+SINGOLATREN!T20+SUMBERBARU!S20 -> 16084
D21: JML | E21: =SUM(E19:E20) -> 30896
B22: 2. | C22: Jumlah pengguna hak pilih dalam Daftar Pemilih Tambahan (DPTb) | D22: LK | E22: =ALASMALANG!V22+'BENELAN KIDUL'!S22+CANTUK!T22+GAMBOR!N22+GUMIRIH!S22+KEMIRI!U22+LEMAHBANGKULON!Q22+PADANG!Q22+SINGOJURUH!AC22+SINGOLATREN!T22+SUMBERBARU!S22 -> 50
D23: PR | E23: =ALASMALANG!V23+'BENELAN KIDUL'!S23+CANTUK!T23+GAMBOR!N23+GUMIRIH!S23+KEMIRI!U23+LEMAHBANGKULON!Q23+PADANG!Q23+SINGOJURUH!AC23+SINGOLATREN!T23+SUMBERBARU!S23 -> 46
D24: JML | E24: =SUM(E22:E23) -> 96
B25: 3. | C25: Jumlah pengguna hak pilih dalam Daftar Pemilih Khusus (DPK) | D25: LK | E25: =ALASMALANG!V25+'BENELAN KIDUL'!S25+CANTUK!T25+GAMBOR!N25+GUMIRIH!S25+KEMIRI!U25+LEMAHBANGKULON!Q25+PADANG!Q25+SINGOJURUH!AC25+SINGOLATREN!T25+SUMBERBARU!S25 -> 135
D26: PR | E26: =ALASMALANG!V26+'BENELAN KIDUL'!S26+CANTUK!T26+GAMBOR!N26+GUMIRIH!S26+KEMIRI!U26+LEMAHBANGKULON!Q26+PADANG!Q26+SINGOJURUH!AC26+SINGOLATREN!T26+SUMBERBARU!S26 -> 163
D27: JML | E27: =SUM(E25:E26) -> 298
B28: 4. | C28: Jumlah Pengguna Hak Pilih (B.1+B.2+B.3) | D28: LK | E28: =E19+E22+E25 -> 14997
D29: PR | E29: =E20+E23+E26 -> 16293
D30: JML | E30: =SUM(E28:E29) -> 31290
A32: II | B32: DATA PENGGUNAAN SURAT SUARA
A33: 1 | B33: Jumlah surat suara yang diterima, termasuk surat suara cadangan 2,5% dari DPT | E33: =ALASMALANG!V33+'BENELAN KIDUL'!S33+CANTUK!T33+GAMBOR!N33+GUMIRIH!S33+KEMIRI!U33+LEMAHBANGKULON!Q33+PADANG!Q33+SINGOJURUH!AC33+SINGOLATREN!T33+SUMBERBARU!S33 -> 40760
A34: 2 | B34: Jumlah surat suara yang digunakan | E34: =ALASMALANG!V34+'BENELAN KIDUL'!S34+CANTUK!T34+GAMBOR!N34+GUMIRIH!S34+KEMIRI!U34+LEMAHBANGKULON!Q34+PADANG!Q34+SINGOJURUH!AC34+SINGOLATREN!T34+SUMBERBARU!S34 -> 31290
A35: 3 | B35: Jumlah surat suara dikembalikan oleh pemilih (karena rusak atau keliru coblos) | E35: =ALASMALANG!V35+'BENELAN KIDUL'!S35+CANTUK!T35+GAMBOR!N35+GUMIRIH!S35+KEMIRI!U35+LEMAHBANGKULON!Q35+PADANG!Q35+SINGOJURUH!AC35+SINGOLATREN!T35+SUMBERBARU!S35 -> 95
A36: 4 | B36: Jumlah surat suara yang tidak digunakan/tidak terpakai, termasuk sisa surat suara cadangan | E36: =E33-(E34+E35) -> 9375
A38: III | B38: DATA PEMILIH DISABILITAS
B39: Jumlah seluruh Pemilih disabilitas yang menggunakan hak pilih | D39: LK | E39: =ALASMALANG!V39+'BENELAN KIDUL'!S39+CANTUK!T39+GAMBOR!N39+GUMIRIH!S39+KEMIRI!U39+LEMAHBANGKULON!Q39+PADANG!Q39+SINGOJURUH!AC39+SINGOLATREN!T39+SUMBERBARU!S39 -> 32
D40: PR | E40: =ALASMALANG!V40+'BENELAN KIDUL'!S40+CANTUK!T40+GAMBOR!N40+GUMIRIH!S40+KEMIRI!U40+LEMAHBANGKULON!Q40+PADANG!Q40+SINGOJURUH!AC40+SINGOLATREN!T40+SUMBERBARU!S40 -> 55
D41: JML | E41: =SUM(E39:E40) -> 87
A43: IV | B43: DATA RINCIAN PEROLEHAN SUARA PASANGAN CALON BUPATI DAN WAKIL BUPATI
A44: NOMOR DAN NAMA CALON
A45: A.1 | B45: 1. | C45: Partai Kebangkitan Bangsa | E45: =ALASMALANG!V45+'BENELAN KIDUL'!S45+CANTUK!T45+GAMBOR!N45+GUMIRIH!S45+KEMIRI!U45+LEMAHBANGKULON!Q45+PADANG!Q45+SINGOJURUH!AC45+SINGOLATREN!T45+SUMBERBARU!S45 -> 1065
A46: A.2 | C46: 1. H. MUHAMMAD ALI MAHRUS, S.H.I., M.H | E46: =ALASMALANG!V46+'BENELAN KIDUL'!S46+CANTUK!T46+GAMBOR!N46+GUMIRIH!S46+KEMIRI!U46+LEMAHBANGKULON!Q46+PADANG!Q46+SINGOJURUH!AC46+SINGOLATREN!T46+SUMBERBARU!S46 -> 2901
C47: 2. TUPANG SOEDARGO | E47: =ALASMALANG!V47+'BENELAN KIDUL'!S47+CANTUK!T47+GAMBOR!N47+GUMIRIH!S47+KEMIRI!U47+LEMAHBANGKULON!Q47+PADANG!Q47+SINGOJURUH!AC47+SINGOLATREN!T47+SUMBERBARU!S47 -> 4472
C48: 3. Hj. KHOLIFATUL HASANAH | E48: =ALASMALANG!V48+'BENELAN KIDUL'!S48+CANTUK!T48+GAMBOR!N48+GUMIRIH!S48+KEMIRI!U48+LEMAHBANGKULON!Q48+PADANG!Q48+SINGOJURUH!AC48+SINGOLATREN!T48+SUMBERBARU!S48 -> 95
C49: 4. FUAD HUMAIDI, S.H.I. | E49: =ALASMALANG!V49+'BENELAN KIDUL'!S49+CANTUK!T49+GAMBOR!N49+GUMIRIH!S49+KEMIRI!U49+LEMAHBANGKULON!Q49+PADANG!Q49+SINGOJURUH!AC49+SINGOLATREN!T49+SUMBERBARU!S49 -> 14
C50: 5. ENI WIJI LESTARI | E50: =ALASMALANG!V50+'BENELAN KIDUL'!S50+CANTUK!T50+GAMBOR!N50+GUMIRIH!S50+KEMIRI!U50+LEMAHBANGKULON!Q50+PADANG!Q50+SINGOJURUH!AC50+SINGOLATREN!T50+SUMBERBARU!S50 -> 15
C51: 6. SONNY AGUS SETIAWAN | E51: =ALASMALANG!V51+'BENELAN KIDUL'!S51+CANTUK!T51+GAMBOR!N51+GUMIRIH!S51+KEMIRI!U51+LEMAHBANGKULON!Q51+PADANG!Q51+SINGOJURUH!AC51+SINGOLATREN!T51+SUMBERBARU!S51 -> 65
A52: B | B52: JUMLAH SUARA SAH PARTAI POLITIK DAN CALON (A1 + A2) | E52: =SUM(E45:E51) -> 8627
...

Sheet ALASMALANG
C2: Kecamatan | D2: SINGOJURUH
C3: Kabupaten | D3: BANYUWANGI
C4: Provinsi | D4: JAWA TIMUR
C9: Kelurahan | D9: ALASMALANG
A12: I | B12: DATA PEMILIH DAN PENGGUNAAN HAK PILIH | V12: JUMLAH AKHIR
A13: A | B13: DATA PEMILIH | E13: TPS 001 | F13: TPS 002 | G13: TPS 003 | H13: TPS 004 | I13: TPS 005 | J13: TPS 006 | K13: TPS 007 | L13: TPS 008 | M13: TPS 009 | N13: TPS 010 | O13: TPS 011 | P13: TPS 012 | Q13: TPS 013 | R13: TPS 014 | S13: TPS 015 | T13: TPS 016 | U13: TPS 017
B14: Jumlah Pemilih dalam Daftar Pemilih Tetap (DPT) | D14: LK | E14: 124 | F14: 110 | G14: 95 | H14: 116 | I14: 101 | J14: 88 | K14: 79 | L14: 121 | M14: 101 | N14: 107 | O14: 99 | P14: 103 | Q14: 128 | R14: 83 | S14: 104 | T14: 93 | U14: 127 | V14: =SUM(E14:U14) -> 1779
D15: PR | E15: 128 | F15: 102 | G15: 92 | H15: 125 | I15: 117 | J15: 94 | K15: 93 | L15: 124 | M15: 94 | N15: 117 | O15: 90 | P15: 108 | Q15: 126 | R15: 85 | S15: 113 | T15: 113 | U15: 110 | V15: =SUM(E15:U15) -> 1831
D16: JML | E16: =SUM(E14:E15) -> 252 | F16: =SUM(F14:F15) -> 212 | G16: =SUM(G14:G15) -> 187 | H16: =SUM(H14:H15) -> 241 | I16: =SUM(I14:I15) -> 218 | J16: =SUM(J14:J15) -> 182 | K16: =SUM(K14:K15) -> 172 | L16: =SUM(L14:L15) -> 245 | ... U16: =SUM(U14:U15) -> 237 | V16: =SUM(E16:U16) -> 3610
A18: B | B18: PENGGUNA HAK PILIH
B19: 1. | C19: Jumlah pengguna hak pilih dalam Daftar Pemilih Tetap (DPT) | D19: LK | E19: 114 | F19: 90 | G19: 71 | H19: 89 | I19: 80 | J19: 65 | K19: 63 | L19: 92 | M19: 82 | N19: 86 | O19: 81 | P19: 83 | Q19: 81 | R19: 66 | S19: 81 | T19: 82 | U19: 107 | V19: =SUM(E19:U19) -> 1413
D20: PR | E20: 94 | F20: 90 | G20: 81 | H20: 95 | I20: 102 | J20: 77 | K20: 74 | L20: 100 | M20: 79 | N20: 95 | O20: 74 | P20: 86 | Q20: 96 | R20: 74 | S20: 95 | T20: 102 | U20: 104 | V20: =SUM(E20:U20) -> 1518
D21: JML | E21: =SUM(E19:E20) -> 208 | F21: =SUM(F19:F20) -> 180 | G21: =SUM(G19:G20) -> 152 | H21: =SUM(H19:H20) -> 184 | I21: =SUM(I19:I20) -> 182 | J21: =SUM(J19:J20) -> 142 | K21: =SUM(K19:K20) -> 137 | L21: =SUM(L19:L20) -> 192 | ... U21: =SUM(U19:U20) -> 211 | V21: =SUM(E21:U21) -> 2931
B22: 2. | C22: Jumlah pengguna hak pilih dalam Daftar Pemilih Tambahan (DPTb) | D22: LK | V22: =SUM(E22:U22) -> 0
D23: PR | U23: 1 | V23: =SUM(E23:U23) -> 1
D24: JML | E24: =SUM(E22:E23) -> 0 | F24: =SUM(F22:F23) -> 0 | G24: =SUM(G22:G23) -> 0 | H24: =SUM(H22:H23) -> 0 | I24: =SUM(I22:I23) -> 0 | J24: =SUM(J22:J23) -> 0 | K24: =SUM(K22:K23) -> 0 | L24: =SUM(L22:L23) -> 0 | ... U24: =SUM(U22:U23) -> 1 | V24: =SUM(E24:U24) -> 1
B25: 3. | C25: Jumlah pengguna hak pilih dalam Daftar Pemilih Khusus (DPK) | D25: LK | E25: 5 | F25: 6 | G25: 1 | H25: 0 | I25: 0 | J25: 1 | K25: 0 | L25: 1 | M25: 0 | N25: 4 | O25: 1 | P25: 2 | Q25: 3 | R25: 0 | S25: 3 | T25: 2 | V25: =SUM(E25:U25) -> 29
D26: PR | E26: 3 | F26: 6 | G26: 2 | H26: 0 | I26: 0 | J26: 2 | K26: 0 | L26: 2 | M26: 0 | N26: 1 | O26: 1 | P26: 1 | Q26: 1 | R26: 1 | S26: 1 | T26: 3 | V26: =SUM(E26:U26) -> 24
D27: JML | E27: =SUM(E25:E26) -> 8 | F27: =SUM(F25:F26) -> 12 | G27: =SUM(G25:G26) -> 3 | H27: =SUM(H25:H26) -> 0 | I27: =SUM(I25:I26) -> 0 | J27: =SUM(J25:J26) -> 3 | K27: =SUM(K25:K26) -> 0 | L27: =SUM(L25:L26) -> 3 | ... U27: =SUM(U25:U26) -> 0 | V27: =SUM(E27:U27) -> 53
B28: 4. | C28: Jumlah Pengguna Hak Pilih (B.1+B.2+B.3) | D28: LK | E28: =SUM(E19,E22,E25) -> 119 | F28: =SUM(F19,F22,F25) -> 96 | G28: =SUM(G19,G22,G25) -> 72 | H28: =SUM(H19,H22,H25) -> 89 | I28: =SUM(I19,I22,I25) -> 80 | J28: =SUM(J19,J22,J25) -> 66 | K28: =SUM(K19,K22,K25) -> 63 | L28: =SUM(L19,L22,L25) -> 93 | ... U28: =SUM(U19,U22,U25) -> 107 | V28: =SUM(E28:U28) -> 1442
D29: PR | E29: =SUM(E20,E23,E26) -> 97 | F29: =SUM(F20,F23,F26) -> 96 | G29: =SUM(G20,G23,G26) -> 83 | H29: =SUM(H20,H23,H26) -> 95 | I29: =SUM(I20,I23,I26) -> 102 | J29: =SUM(J20,J23,J26) -> 79 | K29: =SUM(K20,K23,K26) -> 74 | L29: =SUM(L20,L23,L26) -> 102 | ... U29: =SUM(U20,U23,U26) -> 105 | V29: =SUM(E29:U29) -> 1543
D30: JML | E30: =SUM(E28:E29) -> 216 | F30: =SUM(F28:F29) -> 192 | G30: =SUM(G28:G29) -> 155 | H30: =SUM(H28:H29) -> 184 | I30: =SUM(I28:I29) -> 182 | J30: =SUM(J28:J29) -> 145 | K30: =SUM(K28:K29) -> 137 | L30: =SUM(L28:L29) -> 195 | ... U30: =SUM(U28:U29) -> 212 | V30: =SUM(E30:U30) -> 2985
A32: II | B32: DATA PENGGUNAAN SURAT SUARA
A33: 1 | B33: Jumlah surat suara yang diterima, termasuk surat suara cadangan 2,5% dari DPT | E33: 258 | F33: 207 | G33: 192 | H33: 246 | I33: 223 | J33: 186 | K33: 176 | L33: 250 | M33: 199 | N33: 229 | O33: 193 | P33: 216 | Q33: 260 | R33: 172 | S33: 223 | T33: 210 | U33: 244 | V33: =SUM(E33:U33) -> 3684
A34: 2 | B34: Jumlah surat suara yang digunakan | E34: 216 | F34: 192 | G34: 155 | H34: 184 | I34: 182 | J34: 145 | K34: 137 | L34: 195 | M34: 161 | N34: 186 | O34: 157 | P34: 172 | Q34: 181 | R34: 141 | S34: 180 | T34: 189 | U34: 212 | V34: =SUM(E34:U34) -> 2985
A35: 3 | B35: Jumlah surat suara dikembalikan oleh pemilih (karena rusak atau keliru coblos) | E35: 0 | F35: 3 | G35: 0 | H35: 0 | I35: 2 | J35: 0 | K35: 0 | L35: 6 | M35: 2 | N35: 0 | O35: 0 | P35: 0 | Q35: 2 | R35: 2 | S35: 0 | T35: 3 | U35: 0 | V35: =SUM(E35:U35) -> 20
A36: 4 | B36: Jumlah surat suara yang tidak digunakan/tidak terpakai, termasuk sisa surat suara cadangan | E36: =E33-(E34+E35) -> 42 | F36: =F33-(F34+F35) -> 12 | G36: =G33-(G34+G35) -> 37 | H36: =H33-(H34+H35) -> 62 | I36: =I33-(I34+I35) -> 39 | J36: =J33-(J34+J35) -> 41 | K36: =K33-(K34+K35) -> 39 | L36: =L33-(L34+L35) -> 49 | ... U36: =U33-(U34+U35) -> 32 | V36: =SUM(E36:U36) -> 679
A38: III | B38: DATA PEMILIH DISABILITAS
B39: Jumlah seluruh Pemilih disabilitas yang menggunakan hak pilih | D39: LK | R39: 1 | V39: =SUM(E39:U39) -> 1
D40: PR | V40: =SUM(E40:U40) -> 0
D41: JML | E41: =SUM(E39:E40) -> 0 | F41: =SUM(F39:F40) -> 0 | G41: =SUM(G39:G40) -> 0 | H41: =SUM(H39:H40) -> 0 | I41: =SUM(I39:I40) -> 0 | J41: =SUM(J39:J40) -> 0 | K41: =SUM(K39:K40) -> 0 | L41: =SUM(L39:L40) -> 0 | ... U41: =SUM(U39:U40) -> 0 | V41: =SUM(E41:U41) -> 1
A43: IV | B43: DATA RINCIAN PEROLEHAN SUARA PASANGAN CALON BUPATI DAN WAKIL BUPATI
A44: NOMOR DAN NAMA CALON
A45: A.1 | B45: 1. | C45: Partai Kebangkitan Bangsa | E45: 6 | F45: 4 | G45: 5 | H45: 4 | I45: 3 | J45: 2 | K45: 8 | L45: 9 | M45: 0 | N45: 4 | O45: 5 | P45: 0 | Q45: 2 | R45: 3 | S45: 5 | T45: 8 | U45: 10 | V45: =SUM(E45:U45) -> 78
A46: A.2 | C46: 1. H. MUHAMMAD ALI MAHRUS, S.H.I., M.H | E46: 16 | F46: 18 | G46: 14 | H46: 18 | I46: 50 | J46: 5 | K46: 14 | L46: 14 | M46: 3 | N46: 0 | O46: 1 | P46: 3 | Q46: 6 | R46: 6 | S46: 13 | T46: 15 | U46: 18 | V46: =SUM(E46:U46) -> 214
C47: 2. TUPANG SOEDARGO | E47: 20 | F47: 25 | G47: 37 | H47: 31 | I47: 43 | J47: 10 | K47: 12 | L47: 71 | M47: 95 | N47: 65 | O47: 38 | P47: 75 | Q47: 29 | R47: 38 | S47: 71 | T47: 70 | U47: 98 | V47: =SUM(E47:U47) -> 828
C48: 3. Hj. KHOLIFATUL HASANAH | E48: 0 | F48: 0 | G48: 1 | H48: 0 | I48: 0 | J48: 1 | K48: 0 | L48: 1 | M48: 0 | N48: 3 | O48: 1 | P48: 0 | Q48: 0 | R48: 1 | S48: 0 | T48: 3 | U48: 1 | V48: =SUM(E48:U48) -> 12
C49: 4. FUAD HUMAIDI, S.H.I. | E49: 0 | F49: 0 | G49: 0 | H49: 0 | I49: 0 | J49: 0 | K49: 0 | L49: 0 | M49: 0 | N49: 0 | O49: 0 | P49: 0 | Q49: 0 | R49: 0 | S49: 0 | T49: 0 | U49: 0 | V49: =SUM(E49:U49) -> 0
C50: 5. ENI WIJI LESTARI | E50: 0 | F50: 0 | G50: 0 | H50: 0 | I50: 0 | J50: 0 | K50: 0 | L50: 1 | M50: 0 | N50: 1 | O50: 0 | P50: 0 | Q50: 0 | R50: 0 | S50: 0 | T50: 0 | U50: 0 | V50: =SUM(E50:U50) -> 2
C51: 6. SONNY AGUS SETIAWAN | E51: 0 | F51: 0 | G51: 0 | H51: 0 | I51: 0 | J51: 0 | K51: 1 | L51: 2 | M51: 0 | N51: 0 | O51: 0 | P51: 0 | Q51: 0 | R51: 0 | S51: 0 | T51: 0 | U51: 1 | V51: =SUM(E51:U51) -> 4
...

Sheet BENELAN KIDUL
C2: Kecamatan | D2: SINGOJURUH
C3: Kabupaten | D3: BANYUWANGI
C4: Provinsi | D4: JAWA TIMUR
C9: Kelurahan | D9: BENELAN KIDUL
A12: I | B12: DATA PEMILIH DAN PENGGUNAAN HAK PILIH | S12: JUMLAH AKHIR
A13: A | B13: DATA PEMILIH | E13: TPS 001 | F13: TPS 002 | G13: TPS 003 | H13: TPS 004 | I13: TPS 005 | J13: TPS 006 | K13: TPS 007 | L13: TPS 008 | M13: TPS 009 | N13: TPS 010 | O13: TPS 011 | P13: TPS 012 | Q13: TPS 013 | R13: TPS 014
B14: Jumlah Pemilih dalam Daftar Pemilih Tetap (DPT) | D14: LK | E14: 138 | F14: 130 | G14: 130 | H14: 146 | I14: 139 | J14: 137 | K14: 149 | L14: 133 | M14: 123 | N14: 136 | O14: 128 | P14: 107 | Q14: 127 | R14: 117 | S14: =SUM(E14:R14) -> 1840
D15: PR | E15: 126 | F15: 119 | G15: 135 | H15: 133 | I15: 129 | J15: 144 | K15: 133 | L15: 134 | M15: 115 | N15: 125 | O15: 139 | P15: 101 | Q15: 123 | R15: 112 | S15: =SUM(E15:R15) -> 1768
D16: JML | E16: =SUM(E14:E15) -> 264 | F16: =SUM(F14:F15) -> 249 | G16: =SUM(G14:G15) -> 265 | H16: =SUM(H14:H15) -> 279 | I16: =SUM(I14:I15) -> 268 | J16: =SUM(J14:J15) -> 281 | K16: =SUM(K14:K15) -> 282 | L16: =SUM(L14:L15) -> 267 | ... R16: =SUM(R14:R15) -> 229 | S16: =SUM(E16:R16) -> 3608
A18: B | B18: PENGGUNA HAK PILIH
B19: 1. | C19: Jumlah pengguna hak pilih dalam Daftar Pemilih Tetap (DPT) | D19: LK | E19: 111 | F19: 107 | G19: 102 | H19: 112 | I19: 110 | J19: 105 | K19: 117 | L19: 102 | M19: 86 | N19: 101 | O19: 93 | P19: 82 | Q19: 97 | R19: 96 | S19: =SUM(E19:R19) -> 1421
D20: PR | E20: 108 | F20: 99 | G20: 113 | H20: 114 | I20: 106 | J20: 117 | K20: 115 | L20: 108 | M20: 93 | N20: 83 | O20: 108 | P20: 78 | Q20: 107 | R20: 98 | S20: =SUM(E20:R20) -> 1447
D21: JML | E21: =SUM(E19:E20) -> 219 | F21: =SUM(F19:F20) -> 206 | G21: =SUM(G19:G20) -> 215 | H21: =SUM(H19:H20) -> 226 | I21: =SUM(I19:I20) -> 216 | J21: =SUM(J19:J20) -> 222 | K21: =SUM(K19:K20) -> 232 | L21: =SUM(L19:L20) -> 210 | ... R21: =SUM(R19:R20) -> 194 | S21: =SUM(E21:R21) -> 2868
B22: 2. | C22: Jumlah pengguna hak pilih dalam Daftar Pemilih Tambahan (DPTb) | D22: LK | F22: 1 | H22: 2 | M22: 1 | S22: =SUM(E22:R22) -> 4
D23: PR | F23: 1 | H23: 1 | M23: 1 | S23: =SUM(E23:R23) -> 3
D24: JML | E24: =SUM(E22:E23) -> 0 | F24: =SUM(F22:F23) -> 2 | G24: =SUM(G22:G23) -> 0 | H24: =SUM(H22:H23) -> 3 | I24: =SUM(I22:I23) -> 0 | J24: =SUM(J22:J23) -> 0 | K24: =SUM(K22:K23) -> 0 | L24: =SUM(L22:L23) -> 0 | ... R24: =SUM(R22:R23) -> 0 | S24: =SUM(E24:R24) -> 7
B25: 3. | C25: Jumlah pengguna hak pilih dalam Daftar Pemilih Khusus (DPK) | D25: LK | F25: 4 | G25: 1 | M25: 2 | O25: 3 | S25: =SUM(E25:R25) -> 10
D26: PR | F26: 6 | G26: 1 | J26: 2 | M26: 3 | O26: 2 | S26: =SUM(E26:R26) -> 14
D27: JML | E27: =SUM(E25:E26) -> 0 | F27: =SUM(F25:F26) -> 10 | G27: =SUM(G25:G26) -> 2 | H27: =SUM(H25:H26) -> 0 | I27: =SUM(I25:I26) -> 0 | J27: =SUM(J25:J26) -> 2 | K27: =SUM(K25:K26) -> 0 | L27: =SUM(L25:L26) -> 0 | ... R27: =SUM(R25:R26) -> 0 | S27: =SUM(E27:R27) -> 24
B28: 4. | C28: Jumlah Pengguna Hak Pilih (B.1+B.2+B.3) | D28: LK | E28: =SUM(E19,E22,E25) -> 111 | F28: =SUM(F19,F22,F25) -> 112 | G28: =SUM(G19,G22,G25) -> 103 | H28: =SUM(H19,H22,H25) -> 114 | I28: =SUM(I19,I22,I25) -> 110 | J28: =SUM(J19,J22,J25) -> 105 | K28: =SUM(K19,K22,K25) -> 117 | L28: =SUM(L19,L22,L25) -> 102 | ... R28: =SUM(R19,R22,R25) -> 96 | S28: =SUM(E28:R28) -> 1435
D29: PR | E29: =SUM(E20,E23,E26) -> 108 | F29: =SUM(F20,F23,F26) -> 106 | G29: =SUM(G20,G23,G26) -> 114 | H29: =SUM(H20,H23,H26) -> 115 | I29: =SUM(I20,I23,I26) -> 106 | J29: =SUM(J20,J23,J26) -> 119 | K29: =SUM(K20,K23,K26) -> 115 | L29: =SUM(L20,L23,L26) -> 108 | ... R29: =SUM(R20,R23,R26) -> 98 | S29: =SUM(E29:R29) -> 1464
D30: JML | E30: =SUM(E28:E29) -> 219 | F30: =SUM(F28:F29) -> 218 | G30: =SUM(G28:G29) -> 217 | H30: =SUM(H28:H29) -> 229 | I30: =SUM(I28:I29) -> 216 | J30: =SUM(J28:J29) -> 224 | K30: =SUM(K28:K29) -> 232 | L30: =SUM(L28:L29) -> 210 | ... R30: =SUM(R28:R29) -> 194 | S30: =SUM(E30:R30) -> 2899
A32: II | B32: DATA PENGGUNAAN SURAT SUARA
A33: 1 | B33: Jumlah surat suara yang diterima, termasuk surat suara cadangan 2,5% dari DPT | E33: 270 | F33: 255 | G33: 271 | H33: 285 | I33: 274 | J33: 287 | K33: 289 | L33: 273 | M33: 243 | N33: 267 | O33: 275 | P33: 211 | Q33: 255 | R33: 234 | S33: =SUM(E33:R33) -> 3689
A34: 2 | B34: Jumlah surat suara yang digunakan | E34: 219 | F34: 218 | G34: 217 | H34: 229 | I34: 216 | J34: 224 | K34: 232 | L34: 210 | M34: 186 | N34: 184 | O34: 206 | P34: 160 | Q34: 204 | R34: 194 | S34: =SUM(E34:R34) -> 2899
A35: 3 | B35: Jumlah surat suara dikembalikan oleh pemilih (karena rusak atau keliru coblos) | F35: 2 | G35: 4 | I35: 2 | J35: 1 | K35: 1 | O35: 1 | S35: =SUM(E35:R35) -> 11
A36: 4 | B36: Jumlah surat suara yang tidak digunakan/tidak terpakai, termasuk sisa surat suara cadangan | E36: =E33-(E34+E35) -> 51 | F36: =F33-(F34+F35) -> 35 | G36: =G33-(G34+G35) -> 50 | H36: =H33-(H34+H35) -> 56 | I36: =I33-(I34+I35) -> 56 | J36: =J33-(J34+J35) -> 62 | K36: =K33-(K34+K35) -> 56 | L36: =L33-(L34+L35) -> 63 | ... R36: =R33-(R34+R35) -> 40 | S36: =SUM(E36:R36) -> 779
A38: III | B38: DATA PEMILIH DISABILITAS
B39: Jumlah seluruh Pemilih disabilitas yang menggunakan hak pilih | D39: LK | F39: 1 | H39: 2 | N39: 2 | S39: =SUM(E39:R39) -> 5
D40: PR | F40: 3 | H40: 4 | J40: 4 | N40: 2 | S40: =SUM(E40:R40) -> 13
D41: JML | E41: =SUM(E39:E40) -> 0 | F41: =SUM(F39:F40) -> 4 | G41: =SUM(G39:G40) -> 0 | H41: =SUM(H39:H40) -> 6 | I41: =SUM(I39:I40) -> 0 | J41: =SUM(J39:J40) -> 4 | K41: =SUM(K39:K40) -> 0 | L41: =SUM(L39:L40) -> 0 | ... R41: =SUM(R39:R40) -> 0 | S41: =SUM(E41:R41) -> 18
A43: IV | B43: DATA RINCIAN PEROLEHAN SUARA PASANGAN CALON BUPATI DAN WAKIL BUPATI
A44: NOMOR DAN NAMA CALON
A45: A.1 | B45: 1. | C45: Partai Kebangkitan Bangsa | E45: 3 | F45: 10 | G45: 9 | H45: 6 | I45: 7 | J45: 10 | K45: 10 | L45: 16 | M45: 13 | N45: 9 | O45: 4 | P45: 3 | Q45: 11 | R45: 6 | S45: =SUM(E45:R45) -> 117
A46: A.2 | C46: 1. H. MUHAMMAD ALI MAHRUS, S.H.I., M.H | E46: 17 | F46: 45 | G46: 32 | H46: 14 | I46: 42 | J46: 52 | K46: 24 | L46: 30 | M46: 71 | N46: 14 | O46: 15 | P46: 4 | Q46: 18 | R46: 8 | S46: =SUM(E46:R46) -> 386
C47: 2. TUPANG SOEDARGO | E47: 3 | F47: 3 | G47: 2 | H47: 20 | I47: 14 | J47: 25 | K47: 87 | L47: 67 | M47: 30 | N47: 58 | O47: 38 | P47: 39 | Q47: 58 | R47: 27 | S47: =SUM(E47:R47) -> 471
C48: 3. Hj. KHOLIFATUL HASANAH | E48: 3 | F48: 2 | G48: 0 | H48: 0 | I48: 0 | J48: 1 | K48: 2 | L48: 0 | M48: 1 | N48: 0 | O48: 1 | P48: 1 | Q48: 1 | R48: 1 | S48: =SUM(E48:R48) -> 13
C49: 4. FUAD HUMAIDI, S.H.I. | E49: 0 | F49: 0 | G49: 0 | H49: 0 | I49: 0 | J49: 1 | K49: 0 | L49: 0 | M49: 0 | N49: 0 | O49: 0 | P49: 0 | Q49: 0 | R49: 0 | S49: =SUM(E49:R49) -> 1
C50: 5. ENI WIJI LESTARI | E50: 0 | F50: 1 | G50: 0 | H50: 1 | I50: 0 | J50: 0 | K50: 0 | L50: 0 | M50: 0 | N50: 0 | O50: 0 | P50: 0 | Q50: 0 | R50: 0 | S50: =SUM(E50:R50) -> 2
C51: 6. SONNY AGUS SETIAWAN | E51: 0 | F51: 0 | G51: 2 | H51: 0 | I51: 1 | J51: 0 | K51: 0 | L51: 0 | M51: 0 | N51: 1 | O51: 0 | P51: 0 | Q51: 1 | R51: 0 | S51: =SUM(E51:R51) -> 5
...

Sheet CANTUK
C2: Kecamatan | D2: SINGOJURUH
C3: Kabupaten | D3: BANYUWANGI
C4: Provinsi | D4: JAWA TIMUR
C9: Kelurahan | D9: CANTUK
A12: I | B12: DATA PEMILIH DAN PENGGUNAAN HAK PILIH | T12: JUMLAH AKHIR
A13: A | B13: DATA PEMILIH | E13: TPS 001 | F13: TPS 002 | G13: TPS 003 | H13: TPS 004 | I13: TPS 005 | J13: TPS 006 | K13: TPS 007 | L13: TPS 008 | M13: TPS 009 | N13: TPS 010 | O13: TPS 011 | P13: TPS 012 | Q13: TPS 013 | R13: TPS 014 | S13: TPS 015
B14: Jumlah Pemilih dalam Daftar Pemilih Tetap (DPT) | D14: LK | E14: 135 | F14: 130 | G14: 131 | H14: 142 | I14: 130 | J14: 128 | K14: 127 | L14: 118 | M14: 126 | N14: 132 | O14: 97 | P14: 102 | Q14: 121 | R14: 118 | S14: 124 | T14: =SUM(E14:S14) -> 1861
D15: PR | E15: 136 | F15: 128 | G15: 126 | H15: 128 | I15: 129 | J15: 134 | K15: 121 | L15: 131 | M15: 129 | N15: 152 | O15: 107 | P15: 111 | Q15: 124 | R15: 125 | S15: 117 | T15: =SUM(E15:S15) -> 1898
D16: JML | E16: =SUM(E14:E15) -> 271 | F16: =SUM(F14:F15) -> 258 | G16: =SUM(G14:G15) -> 257 | H16: =SUM(H14:H15) -> 270 | I16: =SUM(I14:I15) -> 259 | J16: =SUM(J14:J15) -> 262 | K16: =SUM(K14:K15) -> 248 | L16: =SUM(L14:L15) -> 249 | ... S16: =SUM(S14:S15) -> 241 | T16: =SUM(E16:S16) -> 3759
A18: B | B18: PENGGUNA HAK PILIH
B19: 1. | C19: Jumlah pengguna hak pilih dalam Daftar Pemilih Tetap (DPT) | D19: LK | E19: 92 | F19: 99 | G19: 93 | H19: 104 | I19: 99 | J19: 101 | K19: 98 | L19: 92 | M19: 82 | N19: 87 | O19: 64 | P19: 71 | Q19: 91 | R19: 90 | S19: 104 | T19: =SUM(E19:S19) -> 1367
D20: PR | E20: 110 | F20: 102 | G20: 97 | H20: 104 | I20: 108 | J20: 111 | K20: 96 | L20: 108 | M20: 89 | N20: 109 | O20: 89 | P20: 84 | Q20: 108 | R20: 104 | S20: 98 | T20: =SUM(E20:S20) -> 1517
D21: JML | E21: =SUM(E19:E20) -> 202 | F21: =SUM(F19:F20) -> 201 | G21: =SUM(G19:G20) -> 190 | H21: =SUM(H19:H20) -> 208 | I21: =SUM(I19:I20) -> 207 | J21: =SUM(J19:J20) -> 212 | K21: =SUM(K19:K20) -> 194 | L21: =SUM(L19:L20) -> 200 | ... S21: =SUM(S19:S20) -> 202 | T21: =SUM(E21:S21) -> 2884
B22: 2. | C22: Jumlah pengguna hak pilih dalam Daftar Pemilih Tambahan (DPTb) | D22: LK | E22: 0 | F22: 0 | G22: 1 | H22: 0 | I22: 0 | J22: 0 | K22: 0 | L22: 0 | M22: 0 | N22: 0 | O22: 2 | P22: 0 | Q22: 1 | R22: 1 | S22: 2 | T22: =SUM(E22:S22) -> 7
D23: PR | E23: 1 | F23: 0 | G23: 0 | H23: 1 | I23: 0 | J23: 0 | K23: 0 | L23: 2 | M23: 1 | N23: 0 | O23: 0 | P23: 1 | Q23: 1 | R23: 1 | S23: 2 | T23: =SUM(E23:S23) -> 10
D24: JML | E24: =SUM(E22:E23) -> 1 | F24: =SUM(F22:F23) -> 0 | G24: =SUM(G22:G23) -> 1 | H24: =SUM(H22:H23) -> 1 | I24: =SUM(I22:I23) -> 0 | J24: =SUM(J22:J23) -> 0 | K24: =SUM(K22:K23) -> 0 | L24: =SUM(L22:L23) -> 2 | ... S24: =SUM(S22:S23) -> 4 | T24: =SUM(E24:S24) -> 17
B25: 3. | C25: Jumlah pengguna hak pilih dalam Daftar Pemilih Khusus (DPK) | D25: LK | E25: 1 | F25: 0 | G25: 0 | H25: 0 | I25: 1 | J25: 0 | K25: 0 | L25: 0 | M25: 1 | N25: 2 | O25: 2 | P25: 0 | Q25: 1 | R25: 1 | S25: 0 | T25: =SUM(E25:S25) -> 9
D26: PR | E26: 2 | F26: 0 | G26: 0 | H26: 0 | I26: 1 | J26: 0 | K26: 2 | L26: 1 | M26: 0 | N26: 1 | O26: 1 | P26: 1 | Q26: 0 | R26: 0 | S26: 0 | T26: =SUM(E26:S26) -> 9
D27: JML | E27: =SUM(E25:E26) -> 3 | F27: =SUM(F25:F26) -> 0 | G27: =SUM(G25:G26) -> 0 | H27: =SUM(H25:H26) -> 0 | I27: =SUM(I25:I26) -> 2 | J27: =SUM(J25:J26) -> 0 | K27: =SUM(K25:K26) -> 2 | L27: =SUM(L25:L26) -> 1 | ... S27: =SUM(S25:S26) -> 0 | T27: =SUM(E27:S27) -> 18
B28: 4. | C28: Jumlah Pengguna Hak Pilih (B.1+B.2+B.3) | D28: LK | E28: =SUM(E19,E22,E25) -> 93 | F28: =SUM(F19,F22,F25) -> 99 | G28: =SUM(G19,G22,G25) -> 94 | H28: =SUM(H19,H22,H25) -> 104 | I28: =SUM(I19,I22,I25) -> 100 | J28: =SUM(J19,J22,J25) -> 101 | K28: =SUM(K19,K22,K25) -> 98 | L28: =SUM(L19,L22,L25) -> 92 | ... S28: =SUM(S19,S22,S25) -> 106 | T28: =SUM(E28:S28) -> 1383
D29: PR | E29: =SUM(E20,E23,E26) -> 113 | F29: =SUM(F20,F23,F26) -> 102 | G29: =SUM(G20,G23,G26) -> 97 | H29: =SUM(H20,H23,H26) -> 105 | I29: =SUM(I20,I23,I26) -> 109 | J29: =SUM(J20,J23,J26) -> 111 | K29: =SUM(K20,K23,K26) -> 98 | L29: =SUM(L20,L23,L26) -> 111 | ... S29: =SUM(S20,S23,S26) -> 100 | T29: =SUM(E29:S29) -> 1536
D30: JML | E30: =SUM(E28:E29) -> 206 | F30: =SUM(F28:F29) -> 201 | G30: =SUM(G28:G29) -> 191 | H30: =SUM(H28:H29) -> 209 | I30: =SUM(I28:I29) -> 209 | J30: =SUM(J28:J29) -> 212 | K30: =SUM(K28:K29) -> 196 | L30: =SUM(L28:L29) -> 203 | ... S30: =SUM(S28:S29) -> 206 | T30: =SUM(E30:S30) -> 2919
A32: II | B32: DATA PENGGUNAAN SURAT SUARA
A33: 1 | B33: Jumlah surat suara yang diterima, termasuk surat suara cadangan 2,5% dari DPT | E33: 277 | F33: 264 | G33: 263 | H33: 277 | I33: 265 | J33: 258 | K33: 253 | L33: 254 | M33: 261 | N33: 290 | O33: 209 | P33: 218 | Q33: 250 | R33: 248 | S33: 246 | T33: =SUM(E33:S33) -> 3833
A34: 2 | B34: Jumlah surat suara yang digunakan | E34: 206 | F34: 201 | G34: 191 | H34: 209 | I34: 209 | J34: 212 | K34: 196 | L34: 203 | M34: 173 | N34: 199 | O34: 158 | P34: 157 | Q34: 202 | R34: 197 | S34: 206 | T34: =SUM(E34:S34) -> 2919
A35: 3 | B35: Jumlah surat suara dikembalikan oleh pemilih (karena rusak atau keliru coblos) | E35: 3 | F35: 0 | G35: 0 | H35: 0 | I35: 0 | J35: 1 | K35: 0 | L35: 0 | M35: 0 | N35: 1 | O35: 0 | P35: 1 | Q35: 1 | R35: 1 | S35: 0 | T35: =SUM(E35:S35) -> 8
A36: 4 | B36: Jumlah surat suara yang tidak digunakan/tidak terpakai, termasuk sisa surat suara cadangan | E36: =E33-(E34+E35) -> 68 | F36: =F33-(F34+F35) -> 63 | G36: =G33-(G34+G35) -> 72 | H36: =H33-(H34+H35) -> 68 | I36: =I33-(I34+I35) -> 56 | J36: =J33-(J34+J35) -> 45 | K36: =K33-(K34+K35) -> 57 | L36: =L33-(L34+L35) -> 51 | ... S36: =S33-(S34+S35) -> 40 | T36: =SUM(E36:S36) -> 906
A38: III | B38: DATA PEMILIH DISABILITAS
B39: Jumlah seluruh Pemilih disabilitas yang menggunakan hak pilih | D39: LK | E39: 0 | F39: 0 | G39: 0 | H39: 0 | I39: 0 | J39: 0 | K39: 2 | L39: 0 | M39: 0 | N39: 0 | O39: 0 | P39: 1 | Q39: 0 | R39: 0 | S39: 1 | T39: =SUM(E39:S39) -> 4
D40: PR | E40: 0 | F40: 0 | G40: 0 | H40: 0 | I40: 0 | J40: 0 | K40: 1 | L40: 0 | M40: 0 | N40: 0 | O40: 0 | P40: 1 | Q40: 1 | R40: 0 | S40: 0 | T40: =SUM(E40:S40) -> 3
D41: JML | E41: =SUM(E39:E40) -> 0 | F41: =SUM(F39:F40) -> 0 | G41: =SUM(G39:G40) -> 0 | H41: =SUM(H39:H40) -> 0 | I41: =SUM(I39:I40) -> 0 | J41: =SUM(J39:J40) -> 0 | K41: =SUM(K39:K40) -> 3 | L41: =SUM(L39:L40) -> 0 | ... S41: =SUM(S39:S40) -> 1 | T41: =SUM(E41:S41) -> 7
A43: IV | B43: DATA RINCIAN PEROLEHAN SUARA PASANGAN CALON BUPATI DAN WAKIL BUPATI
A44: NOMOR DAN NAMA CALON
A45: A.1 | B45: 1. | C45: Partai Kebangkitan Bangsa | E45: 14 | F45: 4 | G45: 9 | H45: 3 | I45: 6 | J45: 11 | K45: 10 | L45: 7 | M45: 7 | N45: 1 | O45: 11 | P45: 11 | Q45: 3 | R45: 5 | S45: 4 | T45: =SUM(E45:S45) -> 106
A46: A.2 | C46: 1. H. MUHAMMAD ALI MAHRUS, S.H.I., M.H | E46: 19 | F46: 8 | G46: 4 | H46: 21 | I46: 41 | J46: 37 | K46: 22 | L46: 27 | M46: 20 | N46: 30 | O46: 10 | P46: 25 | Q46: 10 | R46: 29 | S46: 15 | T46: =SUM(E46:S46) -> 318
C47: 2. TUPANG SOEDARGO | E47: 33 | F47: 6 | G47: 11 | H47: 6 | I47: 26 | J47: 60 | K47: 14 | L47: 46 | M47: 8 | N47: 12 | O47: 35 | P47: 27 | Q47: 54 | R47: 41 | S47: 40 | T47: =SUM(E47:S47) -> 419
C48: 3. Hj. KHOLIFATUL HASANAH | E48: 0 | F48: 1 | G48: 0 | H48: 0 | I48: 1 | J48: 2 | K48: 1 | L48: 0 | M48: 0 | N48: 0 | O48: 0 | P48: 0 | Q48: 0 | R48: 0 | S48: 0 | T48: =SUM(E48:S48) -> 5
C49: 4. FUAD HUMAIDI, S.H.I. | E49: 0 | F49: 0 | G49: 0 | H49: 0 | I49: 0 | J49: 0 | K49: 0 | L49: 0 | M49: 0 | N49: 0 | O49: 0 | P49: 0 | Q49: 0 | R49: 0 | S49: 0 | T49: =SUM(E49:S49) -> 0
C50: 5. ENI WIJI LESTARI | E50: 0 | F50: 0 | G50: 0 | H50: 0 | I50: 1 | J50: 0 | K50: 0 | L50: 0 | M50: 0 | N50: 0 | O50: 2 | P50: 0 | Q50: 0 | R50: 0 | S50: 0 | T50: =SUM(E50:S50) -> 3
C51: 6. SONNY AGUS SETIAWAN | E51: 0 | F51: 0 | G51: 0 | H51: 0 | I51: 0 | J51: 0 | K51: 0 | L51: 0 | M51: 0 | N51: 0 | O51: 0 | P51: 0 | Q51: 2 | R51: 4 | S51: 9 | T51: =SUM(E51:S51) -> 15
...

Sheet GAMBOR
C2: Kecamatan | D2: SINGOJURUH
C3: Kabupaten | D3: BANYUWANGI
C4: Provinsi | D4: JAWA TIMUR
C9: Kelurahan | D9: GAMBOR
A12: I | B12: DATA PEMILIH DAN PENGGUNAAN HAK PILIH | N12: JUMLAH AKHIR
A13: A | B13: DATA PEMILIH | E13: TPS 001 | F13: TPS 002 | G13: TPS 003 | H13: TPS 004 | I13: TPS 005 | J13: TPS 006 | K13: TPS 007 | L13: TPS 008 | M13: TPS 009
B14: Jumlah Pemilih dalam Daftar Pemilih Tetap (DPT) | D14: LK | E14: 125 | F14: 146 | G14: 125 | H14: 119 | I14: 115 | J14: 132 | K14: 150 | L14: 127 | M14: 112 | N14: =SUM(E14:M14) -> 1151
D15: PR | E15: 125 | F15: 131 | G15: 134 | H15: 117 | I15: 120 | J15: 120 | K15: 132 | L15: 128 | M15: 122 | N15: =SUM(E15:M15) -> 1129
D16: JML | E16: =SUM(E14:E15) -> 250 | F16: =SUM(F14:F15) -> 277 | G16: =SUM(G14:G15) -> 259 | H16: =SUM(H14:H15) -> 236 | I16: =SUM(I14:I15) -> 235 | J16: =SUM(J14:J15) -> 252 | K16: =SUM(K14:K15) -> 282 | L16: =SUM(L14:L15) -> 255 | M16: =SUM(M14:M15) -> 234 | N16: =SUM(E16:M16) -> 2280
A18: B | B18: PENGGUNA HAK PILIH
B19: 1. | C19: Jumlah pengguna hak pilih dalam Daftar Pemilih Tetap (DPT) | D19: LK | E19: 91 | F19: 124 | G19: 88 | H19: 88 | I19: 94 | J19: 106 | K19: 115 | L19: 83 | M19: 96 | N19: =SUM(E19:M19) -> 885
D20: PR | E20: 97 | F20: 115 | G20: 95 | H20: 91 | I20: 102 | J20: 92 | K20: 105 | L20: 101 | M20: 100 | N20: =SUM(E20:M20) -> 898
D21: JML | E21: =SUM(E19:E20) -> 188 | F21: =SUM(F19:F20) -> 239 | G21: =SUM(G19:G20) -> 183 | H21: =SUM(H19:H20) -> 179 | I21: =SUM(I19:I20) -> 196 | J21: =SUM(J19:J20) -> 198 | K21: =SUM(K19:K20) -> 220 | L21: =SUM(L19:L20) -> 184 | M21: =SUM(M19:M20) -> 196 | N21: =SUM(E21:M21) -> 1783
B22: 2. | C22: Jumlah pengguna hak pilih dalam Daftar Pemilih Tambahan (DPTb) | D22: LK | K22: 1 | N22: =SUM(E22:M22) -> 1
D23: PR | N23: =SUM(E23:M23) -> 0
D24: JML | E24: =SUM(E22:E23) -> 0 | F24: =SUM(F22:F23) -> 0 | G24: =SUM(G22:G23) -> 0 | H24: =SUM(H22:H23) -> 0 | I24: =SUM(I22:I23) -> 0 | J24: =SUM(J22:J23) -> 0 | K24: =SUM(K22:K23) -> 1 | L24: =SUM(L22:L23) -> 0 | M24: =SUM(M22:M23) -> 0 | N24: =SUM(E24:M24) -> 1
B25: 3. | C25: Jumlah pengguna hak pilih dalam Daftar Pemilih Khusus (DPK) | D25: LK | G25: 4 | H25: 1 | I25: 1 | K25: 1 | L25: 1 | M25: 1 | N25: =SUM(E25:M25) -> 9
D26: PR | E26: 3 | F26: 1 | G26: 1 | H26: 3 | I26: 2 | K26: 1 | L26: 3 | M26: 1 | N26: =SUM(E26:M26) -> 15
D27: JML | E27: =SUM(E25:E26) -> 3 | F27: =SUM(F25:F26) -> 1 | G27: =SUM(G25:G26) -> 5 | H27: =SUM(H25:H26) -> 4 | I27: =SUM(I25:I26) -> 3 | J27: =SUM(J25:J26) -> 0 | K27: =SUM(K25:K26) -> 2 | L27: =SUM(L25:L26) -> 4 | M27: =SUM(M25:M26) -> 2 | N27: =SUM(E27:M27) -> 24
B28: 4. | C28: Jumlah Pengguna Hak Pilih (B.1+B.2+B.3) | D28: LK | E28: =SUM(E19,E22,E25) -> 91 | F28: =SUM(F19,F22,F25) -> 124 | G28: =SUM(G19,G22,G25) -> 92 | H28: =SUM(H19,H22,H25) -> 89 | I28: =SUM(I19,I22,I25) -> 95 | J28: =SUM(J19,J22,J25) -> 106 | K28: =SUM(K19,K22,K25) -> 117 | L28: =SUM(L19,L22,L25) -> 84 | M28: =SUM(M19,M22,M25) -> 97 | N28: =SUM(E28:M28) -> 895
D29: PR | E29: =SUM(E20,E23,E26) -> 100 | F29: =SUM(F20,F23,F26) -> 116 | G29: =SUM(G20,G23,G26) -> 96 | H29: =SUM(H20,H23,H26) -> 94 | I29: =SUM(I20,I23,I26) -> 104 | J29: =SUM(J20,J23,J26) -> 92 | K29: =SUM(K20,K23,K26) -> 106 | L29: =SUM(L20,L23,L26) -> 104 | M29: =SUM(M20,M23,M26) -> 101 | N29: =SUM(E29:M29) -> 913
D30: JML | E30: =SUM(E28:E29) -> 191 | F30: =SUM(F28:F29) -> 240 | G30: =SUM(G28:G29) -> 188 | H30: =SUM(H28:H29) -> 183 | I30: =SUM(I28:I29) -> 199 | J30: =SUM(J28:J29) -> 198 | K30: =SUM(K28:K29) -> 223 | L30: =SUM(L28:L29) -> 188 | M30: =SUM(M28:M29) -> 198 | N30: =SUM(E30:M30) -> 1808
A32: II | B32: DATA PENGGUNAAN SURAT SUARA
A33: 1 | B33: Jumlah surat suara yang diterima, termasuk surat suara cadangan 2,5% dari DPT | E33: 255 | F33: 283 | G33: 255 | H33: 241 | I33: 239 | J33: 245 | K33: 280 | L33: 261 | M33: 239 | N33: =SUM(E33:M33) -> 2298
A34: 2 | B34: Jumlah surat suara yang digunakan | E34: 191 | F34: 240 | G34: 188 | H34: 183 | I34: 199 | J34: 198 | K34: 223 | L34: 188 | M34: 198 | N34: =SUM(E34:M34) -> 1808
A35: 3 | B35: Jumlah surat suara dikembalikan oleh pemilih (karena rusak atau keliru coblos) | F35: 1 | N35: =SUM(E35:M35) -> 1
A36: 4 | B36: Jumlah surat suara yang tidak digunakan/tidak terpakai, termasuk sisa surat suara cadangan | E36: =E33-(E34+E35) -> 64 | F36: =F33-(F34+F35) -> 42 | G36: =G33-(G34+G35) -> 67 | H36: =H33-(H34+H35) -> 58 | I36: =I33-(I34+I35) -> 40 | J36: =J33-(J34+J35) -> 47 | K36: =K33-(K34+K35) -> 57 | L36: =L33-(L34+L35) -> 73 | M36: =M33-(M34+M35) -> 41 | N36: =SUM(E36:M36) -> 489
A38: III | B38: DATA PEMILIH DISABILITAS
B39: Jumlah seluruh Pemilih disabilitas yang menggunakan hak pilih | D39: LK | N39: =SUM(E39:M39) -> 0
D40: PR | H40: 1 | J40: 1 | N40: =SUM(E40:M40) -> 2
D41: JML | E41: =SUM(E39:E40) -> 0 | F41: =SUM(F39:F40) -> 0 | G41: =SUM(G39:G40) -> 0 | H41: =SUM(H39:H40) -> 1 | I41: =SUM(I39:I40) -> 0 | J41: =SUM(J39:J40) -> 1 | K41: =SUM(K39:K40) -> 0 | L41: =SUM(L39:L40) -> 0 | M41: =SUM(M39:M40) -> 0 | N41: =SUM(E41:M41) -> 2
A43: IV | B43: DATA RINCIAN PEROLEHAN SUARA PASANGAN CALON BUPATI DAN WAKIL BUPATI
A44: NOMOR DAN NAMA CALON
A45: A.1 | B45: 1. | C45: Partai Kebangkitan Bangsa | E45: 10 | F45: 9 | G45: 7 | H45: 20 | I45: 15 | J45: 5 | K45: 12 | L45: 9 | M45: 16 | N45: =SUM(E45:M45) -> 103
A46: A.2 | C46: 1. H. MUHAMMAD ALI MAHRUS, S.H.I., M.H | E46: 14 | F46: 27 | G46: 26 | H46: 14 | I46: 32 | J46: 26 | K46: 16 | L46: 10 | M46: 55 | N46: =SUM(E46:M46) -> 220
C47: 2. TUPANG SOEDARGO | E47: 47 | F47: 65 | G47: 21 | H47: 13 | I47: 10 | J47: 21 | K47: 22 | L47: 9 | M47: 45 | N47: =SUM(E47:M47) -> 253
C48: 3. Hj. KHOLIFATUL HASANAH | E48: 1 | F48: 3 | G48: 1 | H48: 0 | I48: 0 | J48: 3 | K48: 3 | L48: 0 | M48: 0 | N48: =SUM(E48:M48) -> 11
C49: 4. FUAD HUMAIDI, S.H.I. | E49: 0 | F49: 1 | G49: 0 | H49: 0 | I49: 0 | J49: 0 | K49: 1 | L49: 0 | M49: 0 | N49: =SUM(E49:M49) -> 2
C50: 5. ENI WIJI LESTARI | E50: 0 | F50: 1 | G50: 0 | H50: 0 | I50: 0 | J50: 0 | K50: 0 | L50: 0 | M50: 0 | N50: =SUM(E50:M50) -> 1
C51: 6. SONNY AGUS SETIAWAN | E51: 0 | F51: 0 | G51: 1 | H51: 0 | I51: 0 | J51: 0 | K51: 1 | L51: 0 | M51: 0 | N51: =SUM(E51:M51) -> 2
...

Sheet GUMIRIH
C2: Kecamatan | D2: SINGOJURUH
C3: Kabupaten | D3: BANYUWANGI
C4: Provinsi | D4: JAWA TIMUR
C9: Kelurahan | D9: GUMIRIH
A12: I | B12: DATA PEMILIH DAN PENGGUNAAN HAK PILIH | S12: JUMLAH AKHIR
A13: A | B13: DATA PEMILIH | E13: TPS 001 | F13: TPS 002 | G13: TPS 003 | H13: TPS 004 | I13: TPS 005 | J13: TPS 006 | K13: TPS 007 | L13: TPS 008 | M13: TPS 009 | N13: TPS 010 | O13: TPS 011 | P13: TPS 012 | Q13: TPS 013 | R13: TPS 014
B14: Jumlah Pemilih dalam Daftar Pemilih Tetap (DPT) | D14: LK | E14: 118 | F14: 97 | G14: 102 | H14: 133 | I14: 136 | J14: 127 | K14: 134 | L14: 118 | M14: 141 | N14: 140 | O14: 132 | P14: 134 | Q14: 143 | R14: 94 | S14: =SUM(E14:R14) -> 1749
D15: PR | E15: 116 | F15: 103 | G15: 110 | H15: 126 | I15: 128 | J15: 130 | K15: 141 | L15: 131 | M15: 133 | N15: 124 | O15: 144 | P15: 143 | Q15: 129 | R15: 86 | S15: =SUM(E15:R15) -> 1744
D16: JML | E16: =SUM(E14:E15) -> 234 | F16: =SUM(F14:F15) -> 200 | G16: =SUM(G14:G15) -> 212 | H16: =SUM(H14:H15) -> 259 | I16: =SUM(I14:I15) -> 264 | J16: =SUM(J14:J15) -> 257 | K16: =SUM(K14:K15) -> 275 | L16: =SUM(L14:L15) -> 249 | ... R16: =SUM(R14:R15) -> 180 | S16: =SUM(E16:R16) -> 3493
A18: B | B18: PENGGUNA HAK PILIH
B19: 1. | C19: Jumlah pengguna hak pilih dalam Daftar Pemilih Tetap (DPT) | D19: LK | E19: 85 | F19: 60 | G19: 73 | H19: 92 | I19: 96 | J19: 94 | K19: 100 | L19: 77 | M19: 96 | N19: 106 | O19: 109 | P19: 96 | Q19: 95 | R19: 74 | S19: =SUM(E19:R19) -> 1253
D20: PR | E20: 88 | F20: 72 | G20: 85 | H20: 100 | I20: 108 | J20: 89 | K20: 113 | L20: 96 | M20: 101 | N20: 111 | O20: 99 | P20: 102 | Q20: 103 | R20: 65 | S20: =SUM(E20:R20) -> 1332
D21: JML | E21: =SUM(E19:E20) -> 173 | F21: =SUM(F19:F20) -> 132 | G21: =SUM(G19:G20) -> 158 | H21: =SUM(H19:H20) -> 192 | I21: =SUM(I19:I20) -> 204 | J21: =SUM(J19:J20) -> 183 | K21: =SUM(K19:K20) -> 213 | L21: =SUM(L19:L20) -> 173 | ... R21: =SUM(R19:R20) -> 139 | S21: =SUM(E21:R21) -> 2585
B22: 2. | C22: Jumlah pengguna hak pilih dalam Daftar Pemilih Tambahan (DPTb) | D22: LK | E22: 1 | F22: 0 | G22: 1 | H22: 0 | I22: 0 | J22: 0 | K22: 2 | L22: 1 | M22: 0 | N22: 0 | O22: 0 | P22: 0 | Q22: 0 | R22: 0 | S22: =SUM(E22:R22) -> 5
D23: PR | E23: 1 | F23: 0 | G23: 0 | H23: 0 | I23: 0 | J23: 0 | K23: 0 | L23: 1 | M23: 1 | N23: 0 | O23: 0 | P23: 1 | Q23: 1 | R23: 0 | S23: =SUM(E23:R23) -> 5
D24: JML | E24: =SUM(E22:E23) -> 2 | F24: =SUM(F22:F23) -> 0 | G24: =SUM(G22:G23) -> 1 | H24: =SUM(H22:H23) -> 0 | I24: =SUM(I22:I23) -> 0 | J24: =SUM(J22:J23) -> 0 | K24: =SUM(K22:K23) -> 2 | L24: =SUM(L22:L23) -> 2 | ... R24: =SUM(R22:R23) -> 0 | S24: =SUM(E24:R24) -> 10
B25: 3. | C25: Jumlah pengguna hak pilih dalam Daftar Pemilih Khusus (DPK) | D25: LK | E25: 0 | F25: 0 | G25: 0 | H25: 0 | I25: 0 | J25: 0 | K25: 0 | L25: 3 | M25: 0 | N25: 0 | O25: 3 | P25: 0 | Q25: 0 | R25: 0 | S25: =SUM(E25:R25) -> 6
D26: PR | E26: 0 | F26: 0 | G26: 0 | H26: 1 | I26: 0 | J26: 0 | K26: 1 | L26: 1 | M26: 3 | N26: 0 | O26: 3 | P26: 3 | Q26: 0 | R26: 0 | S26: =SUM(E26:R26) -> 12
D27: JML | E27: =SUM(E25:E26) -> 0 | F27: =SUM(F25:F26) -> 0 | G27: =SUM(G25:G26) -> 0 | H27: =SUM(H25:H26) -> 1 | I27: =SUM(I25:I26) -> 0 | J27: =SUM(J25:J26) -> 0 | K27: =SUM(K25:K26) -> 1 | L27: =SUM(L25:L26) -> 4 | ... R27: =SUM(R25:R26) -> 0 | S27: =SUM(E27:R27) -> 18
B28: 4. | C28: Jumlah Pengguna Hak Pilih (B.1+B.2+B.3) | D28: LK | E28: =SUM(E19,E22,E25) -> 86 | F28: =SUM(F19,F22,F25) -> 60 | G28: =SUM(G19,G22,G25) -> 74 | H28: =SUM(H19,H22,H25) -> 92 | I28: =SUM(I19,I22,I25) -> 96 | J28: =SUM(J19,J22,J25) -> 94 | K28: =SUM(K19,K22,K25) -> 102 | L28: =SUM(L19,L22,L25) -> 81 | ... R28: =SUM(R19,R22,R25) -> 74 | S28: =SUM(E28:R28) -> 1264
D29: PR | E29: =SUM(E20,E23,E26) -> 89 | F29: =SUM(F20,F23,F26) -> 72 | G29: =SUM(G20,G23,G26) -> 85 | H29: =SUM(H20,H23,H26) -> 101 | I29: =SUM(I20,I23,I26) -> 108 | J29: =SUM(J20,J23,J26) -> 89 | K29: =SUM(K20,K23,K26) -> 114 | L29: =SUM(L20,L23,L26) -> 98 | ... R29: =SUM(R20,R23,R26) -> 65 | S29: =SUM(E29:R29) -> 1349
D30: JML | E30: =SUM(E28:E29) -> 175 | F30: =SUM(F28:F29) -> 132 | G30: =SUM(G28:G29) -> 159 | H30: =SUM(H28:H29) -> 193 | I30: =SUM(I28:I29) -> 204 | J30: =SUM(J28:J29) -> 183 | K30: =SUM(K28:K29) -> 216 | L30: =SUM(L28:L29) -> 179 | ... R30: =SUM(R28:R29) -> 139 | S30: =SUM(E30:R30) -> 2613
A32: II | B32: DATA PENGGUNAAN SURAT SUARA
A33: 1 | B33: Jumlah surat suara yang diterima, termasuk surat suara cadangan 2,5% dari DPT | E33: 239 | F33: 204 | G33: 216 | H33: 264 | I33: 269 | J33: 262 | K33: 281 | L33: 254 | M33: 279 | N33: 269 | O33: 282 | P33: 283 | Q33: 278 | R33: 169 | S33: =SUM(E33:R33) -> 3549
A34: 2 | B34: Jumlah surat suara yang digunakan | E34: 175 | F34: 132 | G34: 159 | H34: 193 | I34: 204 | J34: 183 | K34: 216 | L34: 179 | M34: 201 | N34: 217 | O34: 214 | P34: 202 | Q34: 199 | R34: 139 | S34: =SUM(E34:R34) -> 2613
A35: 3 | B35: Jumlah surat suara dikembalikan oleh pemilih (karena rusak atau keliru coblos) | E35: 0 | F35: 0 | G35: 2 | H35: 0 | I35: 0 | J35: 0 | K35: 3 | L35: 0 | M35: 0 | N35: 0 | O35: 1 | P35: 1 | Q35: 0 | R35: 0 | S35: =SUM(E35:R35) -> 7
A36: 4 | B36: Jumlah surat suara yang tidak digunakan/tidak terpakai, termasuk sisa surat suara cadangan | E36: =E33-(E34+E35) -> 64 | F36: =F33-(F34+F35) -> 72 | G36: =G33-(G34+G35) -> 55 | H36: =H33-(H34+H35) -> 71 | I36: =I33-(I34+I35) -> 65 | J36: =J33-(J34+J35) -> 79 | K36: =K33-(K34+K35) -> 62 | L36: =L33-(L34+L35) -> 75 | ... R36: =R33-(R34+R35) -> 30 | S36: =SUM(E36:R36) -> 929
A38: III | B38: DATA PEMILIH DISABILITAS
B39: Jumlah seluruh Pemilih disabilitas yang menggunakan hak pilih | D39: LK | E39: 0 | F39: 0 | G39: 0 | H39: 0 | I39: 0 | J39: 0 | K39: 0 | L39: 0 | M39: 0 | N39: 0 | O39: 0 | P39: 1 | Q39: 0 | R39: 0 | S39: =SUM(E39:R39) -> 1
D40: PR | E40: 0 | F40: 0 | G40: 0 | H40: 0 | I40: 0 | J40: 0 | K40: 0 | L40: 0 | M40: 0 | N40: 0 | O40: 0 | P40: 0 | Q40: 0 | R40: 0 | S40: =SUM(E40:R40) -> 0
D41: JML | E41: =SUM(E39:E40) -> 0 | F41: =SUM(F39:F40) -> 0 | G41: =SUM(G39:G40) -> 0 | H41: =SUM(H39:H40) -> 0 | I41: =SUM(I39:I40) -> 0 | J41: =SUM(J39:J40) -> 0 | K41: =SUM(K39:K40) -> 0 | L41: =SUM(L39:L40) -> 0 | ... R41: =SUM(R39:R40) -> 0 | S41: =SUM(E41:R41) -> 1
A43: IV | B43: DATA RINCIAN PEROLEHAN SUARA PASANGAN CALON BUPATI DAN WAKIL BUPATI
A44: NOMOR DAN NAMA CALON
A45: A.1 | B45: 1. | C45: Partai Kebangkitan Bangsa | E45: 9 | F45: 8 | G45: 3 | H45: 3 | I45: 1 | J45: 3 | K45: 6 | L45: 5 | M45: 3 | N45: 5 | O45: 9 | P45: 2 | Q45: 3 | R45: 14 | S45: =SUM(E45:R45) -> 74
A46: A.2 | C46: 1. H. MUHAMMAD ALI MAHRUS, S.H.I., M.H | E46: 23 | F46: 13 | G46: 7 | H46: 27 | I46: 3 | J46: 0 | K46: 24 | L46: 16 | M46: 4 | N46: 1 | O46: 1 | P46: 3 | Q46: 3 | R46: 43 | S46: =SUM(E46:R46) -> 168
C47: 2. TUPANG SOEDARGO | E47: 10 | F47: 2 | G47: 5 | H47: 1 | I47: 0 | J47: 0 | K47: 0 | L47: 0 | M47: 10 | N47: 32 | O47: 4 | P47: 5 | Q47: 12 | R47: 3 | S47: =SUM(E47:R47) -> 84
C48: 3. Hj. KHOLIFATUL HASANAH | E48: 0 | F48: 0 | G48: 0 | H48: 2 | I48: 0 | J48: 0 | K48: 0 | L48: 0 | M48: 0 | N48: 2 | O48: 0 | P48: 1 | Q48: 0 | R48: 0 | S48: =SUM(E48:R48) -> 5
C49: 4. FUAD HUMAIDI, S.H.I. | E49: 0 | F49: 0 | G49: 0 | H49: 0 | I49: 0 | J49: 0 | K49: 0 | L49: 1 | M49: 0 | N49: 0 | O49: 0 | P49: 0 | Q49: 0 | R49: 0 | S49: =SUM(E49:R49) -> 1
C50: 5. ENI WIJI LESTARI | E50: 0 | F50: 0 | G50: 0 | H50: 0 | I50: 0 | J50: 0 | K50: 0 | L50: 0 | M50: 0 | N50: 0 | O50: 0 | P50: 0 | Q50: 0 | R50: 0 | S50: =SUM(E50:R50) -> 0
C51: 6. SONNY AGUS SETIAWAN | E51: 0 | F51: 0 | G51: 0 | H51: 0 | I51: 0 | J51: 0 | K51: 0 | L51: 0 | M51: 0 | N51: 0 | O51: 0 | P51: 0 | Q51: 2 | R51: 0 | S51: =SUM(E51:R51) -> 2
...

Sheet KEMIRI
C2: Kecamatan | D2: SINGOJURUH
C3: Kabupaten | D3: BANYUWANGI
C4: Provinsi | D4: JAWA TIMUR
C9: Kelurahan | D9: KEMIRI
A12: I | B12: DATA PEMILIH DAN PENGGUNAAN HAK PILIH | U12: JUMLAH AKHIR
A13: A | B13: DATA PEMILIH | E13: TPS 001 | F13: TPS 002 | G13: TPS 003 | H13: TPS 004 | I13: TPS 005 | J13: TPS 006 | K13: TPS 007 | L13: TPS 008 | M13: TPS 009 | N13: TPS 010 | O13: TPS 011 | P13: TPS 012 | Q13: TPS 013 | R13: TPS 014 | S13: TPS 015 | T13: TPS 016
B14: Jumlah Pemilih dalam Daftar Pemilih Tetap (DPT) | D14: LK | E14: 118 | F14: 114 | G14: 110 | H14: 97 | I14: 115 | J14: 147 | K14: 110 | L14: 151 | M14: 134 | N14: 138 | O14: 112 | P14: 118 | Q14: 120 | R14: 125 | S14: 125 | T14: 113 | U14: =SUM(E14:T14) -> 1947
D15: PR | E15: 114 | F15: 126 | G15: 114 | H15: 93 | I15: 112 | J15: 148 | K15: 113 | L15: 130 | M15: 146 | N15: 140 | O15: 159 | P15: 115 | Q15: 119 | R15: 120 | S15: 129 | T15: 128 | U15: =SUM(E15:T15) -> 2006
D16: JML | E16: =SUM(E14:E15) -> 232 | F16: =SUM(F14:F15) -> 240 | G16: =SUM(G14:G15) -> 224 | H16: =SUM(H14:H15) -> 190 | I16: =SUM(I14:I15) -> 227 | J16: =SUM(J14:J15) -> 295 | K16: =SUM(K14:K15) -> 223 | L16: =SUM(L14:L15) -> 281 | ... T16: =SUM(T14:T15) -> 241 | U16: =SUM(E16:T16) -> 3953
A18: B | B18: PENGGUNA HAK PILIH
B19: 1. | C19: Jumlah pengguna hak pilih dalam Daftar Pemilih Tetap (DPT) | D19: LK | E19: 78 | F19: 84 | G19: 80 | H19: 57 | I19: 69 | J19: 94 | K19: 81 | L19: 107 | M19: 86 | N19: 87 | O19: 78 | P19: 84 | Q19: 77 | R19: 87 | S19: 93 | T19: 74 | U19: =SUM(E19:T19) -> 1316
D20: PR | E20: 74 | F20: 95 | G20: 88 | H20: 63 | I20: 88 | J20: 103 | K20: 83 | L20: 106 | M20: 110 | N20: 109 | O20: 92 | P20: 86 | Q20: 90 | R20: 92 | S20: 108 | T20: 95 | U20: =SUM(E20:T20) -> 1482
D21: JML | E21: =SUM(E19:E20) -> 152 | F21: =SUM(F19:F20) -> 179 | G21: =SUM(G19:G20) -> 168 | H21: =SUM(H19:H20) -> 120 | I21: =SUM(I19:I20) -> 157 | J21: =SUM(J19:J20) -> 197 | K21: =SUM(K19:K20) -> 164 | L21: =SUM(L19:L20) -> 213 | ... T21: =SUM(T19:T20) -> 169 | U21: =SUM(E21:T21) -> 2798
B22: 2. | C22: Jumlah pengguna hak pilih dalam Daftar Pemilih Tambahan (DPTb) | D22: LK | E22: 1 | F22: 0 | G22: 0 | H22: 0 | I22: 0 | J22: 0 | K22: 0 | L22: 1 | M22: 0 | N22: 0 | O22: 2 | P22: 0 | Q22: 1 | R22: 0 | S22: 2 | U22: =SUM(E22:T22) -> 7
D23: PR | E23: 2 | F23: 0 | G23: 0 | H23: 1 | I23: 0 | J23: 0 | K23: 0 | L23: 0 | M23: 0 | N23: 0 | O23: 0 | P23: 0 | Q23: 1 | R23: 1 | S23: 1 | U23: =SUM(E23:T23) -> 6
D24: JML | E24: =SUM(E22:E23) -> 3 | F24: =SUM(F22:F23) -> 0 | G24: =SUM(G22:G23) -> 0 | H24: =SUM(H22:H23) -> 1 | I24: =SUM(I22:I23) -> 0 | J24: =SUM(J22:J23) -> 0 | K24: =SUM(K22:K23) -> 0 | L24: =SUM(L22:L23) -> 1 | ... T24: =SUM(T22:T23) -> 0 | U24: =SUM(E24:T24) -> 13
B25: 3. | C25: Jumlah pengguna hak pilih dalam Daftar Pemilih Khusus (DPK) | D25: LK | E25: 0 | F25: 1 | G25: 1 | H25: 0 | I25: 0 | J25: 0 | K25: 4 | L25: 0 | M25: 3 | N25: 2 | O25: 0 | P25: 1 | Q25: 0 | R25: 1 | S25: 3 | U25: =SUM(E25:T25) -> 16
D26: PR | E26: 1 | F26: 0 | G26: 1 | H26: 1 | I26: 1 | J26: 0 | K26: 4 | L26: 0 | M26: 0 | N26: 3 | O26: 0 | P26: 2 | Q26: 0 | R26: 3 | S26: 2 | U26: =SUM(E26:T26) -> 18
D27: JML | E27: =SUM(E25:E26) -> 1 | F27: =SUM(F25:F26) -> 1 | G27: =SUM(G25:G26) -> 2 | H27: =SUM(H25:H26) -> 1 | I27: =SUM(I25:I26) -> 1 | J27: =SUM(J25:J26) -> 0 | K27: =SUM(K25:K26) -> 8 | L27: =SUM(L25:L26) -> 0 | ... T27: =SUM(T25:T26) -> 0 | U27: =SUM(E27:T27) -> 34
B28: 4. | C28: Jumlah Pengguna Hak Pilih (B.1+B.2+B.3) | D28: LK | E28: =SUM(E19,E22,E25) -> 79 | F28: =SUM(F19,F22,F25) -> 85 | G28: =SUM(G19,G22,G25) -> 81 | H28: =SUM(H19,H22,H25) -> 57 | I28: =SUM(I19,I22,I25) -> 69 | J28: =SUM(J19,J22,J25) -> 94 | K28: =SUM(K19,K22,K25) -> 85 | L28: =SUM(L19,L22,L25) -> 108 | ... T28: =SUM(T19,T22,T25) -> 74 | U28: =SUM(E28:T28) -> 1339
D29: PR | E29: =SUM(E20,E23,E26) -> 77 | F29: =SUM(F20,F23,F26) -> 95 | G29: =SUM(G20,G23,G26) -> 89 | H29: =SUM(H20,H23,H26) -> 65 | I29: =SUM(I20,I23,I26) -> 89 | J29: =SUM(J20,J23,J26) -> 103 | K29: =SUM(K20,K23,K26) -> 87 | L29: =SUM(L20,L23,L26) -> 106 | ... T29: =SUM(T20,T23,T26) -> 95 | U29: =SUM(E29:T29) -> 1506
D30: JML | E30: =SUM(E28:E29) -> 156 | F30: =SUM(F28:F29) -> 180 | G30: =SUM(G28:G29) -> 170 | H30: =SUM(H28:H29) -> 122 | I30: =SUM(I28:I29) -> 158 | J30: =SUM(J28:J29) -> 197 | K30: =SUM(K28:K29) -> 172 | L30: =SUM(L28:L29) -> 214 | ... T30: =SUM(T28:T29) -> 169 | U30: =SUM(E30:T30) -> 2845
A32: II | B32: DATA PENGGUNAAN SURAT SUARA
A33: 1 | B33: Jumlah surat suara yang diterima, termasuk surat suara cadangan 2,5% dari DPT | E33: 236 | F33: 245 | G33: 229 | H33: 194 | I33: 232 | J33: 301 | K33: 228 | L33: 287 | M33: 286 | N33: 282 | O33: 277 | P33: 238 | Q33: 244 | R33: 250 | S33: 260 | T33: 246 | U33: =SUM(E33:T33) -> 4035
A34: 2 | B34: Jumlah surat suara yang digunakan | E34: 156 | F34: 180 | G34: 170 | H34: 122 | I34: 158 | J34: 197 | K34: 172 | L34: 214 | M34: 199 | N34: 201 | O34: 172 | P34: 173 | Q34: 169 | R34: 184 | S34: 209 | T34: 169 | U34: =SUM(E34:T34) -> 2845
A35: 3 | B35: Jumlah surat suara dikembalikan oleh pemilih (karena rusak atau keliru coblos) | E35: 0 | F35: 0 | G35: 0 | H35: 0 | I35: 0 | J35: 2 | K35: 0 | L35: 0 | M35: 0 | N35: 0 | O35: 0 | P35: 0 | Q35: 0 | R35: 0 | S35: 0 | U35: =SUM(E35:T35) -> 2
A36: 4 | B36: Jumlah surat suara yang tidak digunakan/tidak terpakai, termasuk sisa surat suara cadangan | E36: =E33-(E34+E35) -> 80 | F36: =F33-(F34+F35) -> 65 | G36: =G33-(G34+G35) -> 59 | H36: =H33-(H34+H35) -> 72 | I36: =I33-(I34+I35) -> 74 | J36: =J33-(J34+J35) -> 102 | K36: =K33-(K34+K35) -> 56 | L36: =L33-(L34+L35) -> 73 | ... T36: =T33-(T34+T35) -> 77 | U36: =SUM(E36:T36) -> 1188
A38: III | B38: DATA PEMILIH DISABILITAS
B39: Jumlah seluruh Pemilih disabilitas yang menggunakan hak pilih | D39: LK | E39: 0 | F39: 0 | G39: 3 | H39: 0 | I39: 1 | J39: 0 | K39: 0 | L39: 2 | M39: 0 | N39: 0 | O39: 0 | P39: 0 | Q39: 0 | R39: 0 | S39: 0 | U39: =SUM(E39:T39) -> 6
D40: PR | E40: 1 | F40: 1 | G40: 1 | H40: 0 | I40: 0 | J40: 0 | K40: 0 | L40: 0 | M40: 0 | N40: 0 | O40: 0 | P40: 0 | Q40: 1 | R40: 0 | S40: 0 | U40: =SUM(E40:T40) -> 4
D41: JML | E41: =SUM(E39:E40) -> 1 | F41: =SUM(F39:F40) -> 1 | G41: =SUM(G39:G40) -> 4 | H41: =SUM(H39:H40) -> 0 | I41: =SUM(I39:I40) -> 1 | J41: =SUM(J39:J40) -> 0 | K41: =SUM(K39:K40) -> 0 | L41: =SUM(L39:L40) -> 2 | ... T41: =SUM(T39:T40) -> 0 | U41: =SUM(E41:T41) -> 10
A43: IV | B43: DATA RINCIAN PEROLEHAN SUARA PASANGAN CALON BUPATI DAN WAKIL BUPATI
A44: NOMOR DAN NAMA CALON
A45: A.1 | B45: 1. | C45: Partai Kebangkitan Bangsa | E45: 6 | F45: 1 | G45: 0 | H45: 3 | I45: 2 | J45: 6 | K45: 7 | L45: 6 | M45: 8 | N45: 8 | O45: 8 | P45: 5 | Q45: 4 | R45: 2 | S45: 2 | T45: 4 | U45: =SUM(E45:T45) -> 72
A46: A.2 | C46: 1. H. MUHAMMAD ALI MAHRUS, S.H.I., M.H | E46: 11 | F46: 4 | G46: 1 | H46: 16 | I46: 7 | J46: 9 | K46: 4 | L46: 15 | M46: 40 | N46: 13 | O46: 17 | P46: 9 | Q46: 12 | R46: 2 | S46: 9 | T46: 3 | U46: =SUM(E46:T46) -> 172
C47: 2. TUPANG SOEDARGO | E47: 0 | F47: 7 | G47: 10 | H47: 3 | I47: 4 | J47: 11 | K47: 6 | L47: 3 | M47: 2 | N47: 2 | O47: 6 | P47: 3 | Q47: 4 | R47: 6 | S47: 0 | T47: 1 | U47: =SUM(E47:T47) -> 68
C48: 3. Hj. KHOLIFATUL HASANAH | E48: 1 | F48: 0 | G48: 0 | H48: 1 | I48: 0 | J48: 0 | K48: 0 | L48: 0 | M48: 2 | N48: 3 | O48: 2 | P48: 0 | Q48: 0 | R48: 3 | S48: 1 | T48: 0 | U48: =SUM(E48:T48) -> 13
C49: 4. FUAD HUMAIDI, S.H.I. | E49: 0 | F49: 0 | G49: 1 | H49: 0 | I49: 0 | J49: 0 | K49: 0 | L49: 0 | M49: 0 | N49: 0 | O49: 0 | P49: 0 | Q49: 0 | R49: 0 | S49: 1 | T49: 0 | U49: =SUM(E49:T49) -> 2
C50: 5. ENI WIJI LESTARI | E50: 0 | F50: 1 | G50: 0 | H50: 0 | I50: 0 | J50: 0 | K50: 0 | L50: 2 | M50: 0 | N50: 0 | O50: 0 | P50: 0 | Q50: 0 | R50: 0 | S50: 0 | T50: 0 | U50: =SUM(E50:T50) -> 3
C51: 6. SONNY AGUS SETIAWAN | E51: 0 | F51: 0 | G51: 1 | H51: 1 | I51: 0 | J51: 0 | K51: 1 | L51: 5 | M51: 3 | N51: 0 | O51: 0 | P51: 0 | Q51: 0 | R51: 0 | S51: 3 | T51: 0 | U51: =SUM(E51:T51) -> 14
...

Sheet LEMAHBANGKULON
C2: Kecamatan | D2: SINGOJURUH
C3: Kabupaten | D3: BANYUWANGI
C4: Provinsi | D4: JAWA TIMUR
C9: Kelurahan | D9: LEMAHBANGKULON
A12: I | B12: DATA PEMILIH DAN PENGGUNAAN HAK PILIH | Q12: JUMLAH AKHIR
A13: A | B13: DATA PEMILIH | E13: TPS 001 | F13: TPS 002 | G13: TPS 003 | H13: TPS 004 | I13: TPS 005 | J13: TPS 006 | K13: TPS 007 | L13: TPS 008 | M13: TPS 009 | N13: TPS 010 | O13: TPS 011 | P13: TPS 012
B14: Jumlah Pemilih dalam Daftar Pemilih Tetap (DPT) | D14: LK | E14: 124 | F14: 96 | G14: 127 | H14: 128 | I14: 121 | J14: 117 | K14: 127 | L14: 141 | M14: 108 | N14: 125 | O14: 84 | P14: 68 | Q14: =SUM(E14:P14) -> 1366
D15: PR | E15: 125 | F15: 98 | G15: 137 | H15: 122 | I15: 141 | J15: 139 | K15: 142 | L15: 138 | M15: 119 | N15: 141 | O15: 99 | P15: 83 | Q15: =SUM(E15:P15) -> 1484
D16: JML | E16: =SUM(E14:E15) -> 249 | F16: =SUM(F14:F15) -> 194 | G16: =SUM(G14:G15) -> 264 | H16: =SUM(H14:H15) -> 250 | I16: =SUM(I14:I15) -> 262 | J16: =SUM(J14:J15) -> 256 | K16: =SUM(K14:K15) -> 269 | L16: =SUM(L14:L15) -> 279 | ... P16: =SUM(P14:P15) -> 151 | Q16: =SUM(E16:P16) -> 2850
A18: B | B18: PENGGUNA HAK PILIH
B19: 1. | C19: Jumlah pengguna hak pilih dalam Daftar Pemilih Tetap (DPT) | D19: LK | E19: 85 | F19: 79 | G19: 88 | H19: 86 | I19: 93 | J19: 76 | K19: 105 | L19: 108 | M19: 75 | N19: 94 | O19: 62 | P19: 54 | Q19: =SUM(E19:P19) -> 1005
D20: PR | E20: 101 | F20: 79 | G20: 101 | H20: 94 | I20: 110 | J20: 111 | K20: 124 | L20: 105 | M20: 98 | N20: 106 | O20: 80 | P20: 62 | Q20: =SUM(E20:P20) -> 1171
D21: JML | E21: =SUM(E19:E20) -> 186 | F21: =SUM(F19:F20) -> 158 | G21: =SUM(G19:G20) -> 189 | H21: =SUM(H19:H20) -> 180 | I21: =SUM(I19:I20) -> 203 | J21: =SUM(J19:J20) -> 187 | K21: =SUM(K19:K20) -> 229 | L21: =SUM(L19:L20) -> 213 | ... P21: =SUM(P19:P20) -> 116 | Q21: =SUM(E21:P21) -> 2176
B22: 2. | C22: Jumlah pengguna hak pilih dalam Daftar Pemilih Tambahan (DPTb) | D22: LK | E22: 0 | F22: 0 | G22: 0 | H22: 0 | I22: 0 | J22: 1 | K22: 0 | L22: 1 | M22: 1 | N22: 4 | O22: 0 | P22: 1 | Q22: =SUM(E22:P22) -> 8
D23: PR | E23: 0 | F23: 1 | G23: 0 | H23: 0 | I23: 0 | J23: 1 | K23: 0 | L23: 0 | M23: 0 | N23: 3 | O23: 0 | P23: 0 | Q23: =SUM(E23:P23) -> 5
D24: JML | E24: =SUM(E22:E23) -> 0 | F24: =SUM(F22:F23) -> 1 | G24: =SUM(G22:G23) -> 0 | H24: =SUM(H22:H23) -> 0 | I24: =SUM(I22:I23) -> 0 | J24: =SUM(J22:J23) -> 2 | K24: =SUM(K22:K23) -> 0 | L24: =SUM(L22:L23) -> 1 | ... P24: =SUM(P22:P23) -> 1 | Q24: =SUM(E24:P24) -> 13
B25: 3. | C25: Jumlah pengguna hak pilih dalam Daftar Pemilih Khusus (DPK) | D25: LK | E25: 0 | F25: 2 | G25: 2 | H25: 1 | I25: 0 | J25: 1 | K25: 0 | L25: 0 | M25: 0 | N25: 0 | O25: 0 | P25: 1 | Q25: =SUM(E25:P25) -> 7
D26: PR | E26: 0 | F26: 0 | G26: 2 | H26: 0 | I26: 0 | J26: 1 | K26: 1 | L26: 0 | M26: 1 | N26: 0 | O26: 2 | P26: 1 | Q26: =SUM(E26:P26) -> 8
D27: JML | E27: =SUM(E25:E26) -> 0 | F27: =SUM(F25:F26) -> 2 | G27: =SUM(G25:G26) -> 4 | H27: =SUM(H25:H26) -> 1 | I27: =SUM(I25:I26) -> 0 | J27: =SUM(J25:J26) -> 2 | K27: =SUM(K25:K26) -> 1 | L27: =SUM(L25:L26) -> 0 | ... P27: =SUM(P25:P26) -> 2 | Q27: =SUM(E27:P27) -> 15
B28: 4. | C28: Jumlah Pengguna Hak Pilih (B.1+B.2+B.3) | D28: LK | E28: =SUM(E19,E22,E25) -> 85 | F28: =SUM(F19,F22,F25) -> 81 | G28: =SUM(G19,G22,G25) -> 90 | H28: =SUM(H19,H22,H25) -> 87 | I28: =SUM(I19,I22,I25) -> 93 | J28: =SUM(J19,J22,J25) -> 78 | K28: =SUM(K19,K22,K25) -> 105 | L28: =SUM(L19,L22,L25) -> 109 | ... P28: =SUM(P19,P22,P25) -> 56 | Q28: =SUM(E28:P28) -> 1020
D29: PR | E29: =SUM(E20,E23,E26) -> 101 | F29: =SUM(F20,F23,F26) -> 80 | G29: =SUM(G20,G23,G26) -> 103 | H29: =SUM(H20,H23,H26) -> 94 | I29: =SUM(I20,I23,I26) -> 110 | J29: =SUM(J20,J23,J26) -> 113 | K29: =SUM(K20,K23,K26) -> 125 | L29: =SUM(L20,L23,L26) -> 105 | ... P29: =SUM(P20,P23,P26) -> 63 | Q29: =SUM(E29:P29) -> 1184
D30: JML | E30: =SUM(E28:E29) -> 186 | F30: =SUM(F28:F29) -> 161 | G30: =SUM(G28:G29) -> 193 | H30: =SUM(H28:H29) -> 181 | I30: =SUM(I28:I29) -> 203 | J30: =SUM(J28:J29) -> 191 | K30: =SUM(K28:K29) -> 230 | L30: =SUM(L28:L29) -> 214 | ... P30: =SUM(P28:P29) -> 119 | Q30: =SUM(E30:P30) -> 2204
A32: II | B32: DATA PENGGUNAAN SURAT SUARA
A33: 1 | B33: Jumlah surat suara yang diterima, termasuk surat suara cadangan 2,5% dari DPT | E33: 254 | F33: 198 | G33: 270 | H33: 255 | I33: 258 | J33: 263 | K33: 275 | L33: 283 | M33: 232 | N33: 272 | O33: 187 | P33: 155 | Q33: =SUM(E33:P33) -> 2902
A34: 2 | B34: Jumlah surat suara yang digunakan | E34: 186 | F34: 161 | G34: 193 | H34: 181 | I34: 203 | J34: 191 | K34: 230 | L34: 214 | M34: 175 | N34: 207 | O34: 144 | P34: 119 | Q34: =SUM(E34:P34) -> 2204
A35: 3 | B35: Jumlah surat suara dikembalikan oleh pemilih (karena rusak atau keliru coblos) | E35: 0 | F35: 0 | G35: 1 | H35: 0 | I35: 0 | J35: 3 | K35: 1 | L35: 2 | M35: 1 | N35: 0 | O35: 0 | P35: 0 | Q35: =SUM(E35:P35) -> 8
A36: 4 | B36: Jumlah surat suara yang tidak digunakan/tidak terpakai, termasuk sisa surat suara cadangan | E36: =E33-(E34+E35) -> 68 | F36: =F33-(F34+F35) -> 37 | G36: =G33-(G34+G35) -> 76 | H36: =H33-(H34+H35) -> 74 | I36: =I33-(I34+I35) -> 55 | J36: =J33-(J34+J35) -> 69 | K36: =K33-(K34+K35) -> 44 | L36: =L33-(L34+L35) -> 67 | ... P36: =P33-(P34+P35) -> 36 | Q36: =SUM(E36:P36) -> 690
A38: III | B38: DATA PEMILIH DISABILITAS
B39: Jumlah seluruh Pemilih disabilitas yang menggunakan hak pilih | D39: LK | F39: 2 | N39: 1 | Q39: =SUM(E39:P39) -> 3
D40: PR | J40: 4 | N40: 4 | Q40: =SUM(E40:P40) -> 8
D41: JML | E41: =SUM(E39:E40) -> 0 | F41: =SUM(F39:F40) -> 2 | G41: =SUM(G39:G40) -> 0 | H41: =SUM(H39:H40) -> 0 | I41: =SUM(I39:I40) -> 0 | J41: =SUM(J39:J40) -> 4 | K41: =SUM(K39:K40) -> 0 | L41: =SUM(L39:L40) -> 0 | ... P41: =SUM(P39:P40) -> 0 | Q41: =SUM(E41:P41) -> 11
A43: IV | B43: DATA RINCIAN PEROLEHAN SUARA PASANGAN CALON BUPATI DAN WAKIL BUPATI
A44: NOMOR DAN NAMA CALON
A45: A.1 | B45: 1. | C45: Partai Kebangkitan Bangsa | E45: 12 | F45: 11 | G45: 4 | H45: 2 | I45: 5 | J45: 7 | K45: 7 | L45: 4 | M45: 7 | N45: 12 | O45: 3 | P45: 6 | Q45: =SUM(E45:P45) -> 80
A46: A.2 | C46: 1. H. MUHAMMAD ALI MAHRUS, S.H.I., M.H | E46: 9 | F46: 5 | G46: 8 | H46: 7 | I46: 29 | J46: 9 | K46: 5 | L46: 13 | M46: 29 | N46: 31 | O46: 10 | P46: 3 | Q46: =SUM(E46:P46) -> 158
C47: 2. TUPANG SOEDARGO | E47: 69 | F47: 63 | G47: 54 | H47: 29 | I47: 44 | J47: 54 | K47: 71 | L47: 67 | M47: 28 | N47: 67 | O47: 45 | P47: 18 | Q47: =SUM(E47:P47) -> 609
C48: 3. Hj. KHOLIFATUL HASANAH | E48: 1 | F48: 1 | G48: 0 | H48: 1 | I48: 1 | J48: 0 | K48: 0 | L48: 0 | M48: 3 | N48: 2 | O48: 1 | P48: 0 | Q48: =SUM(E48:P48) -> 10
C49: 4. FUAD HUMAIDI, S.H.I. | E49: 0 | F49: 0 | G49: 0 | H49: 0 | I49: 0 | J49: 0 | K49: 0 | L49: 0 | M49: 0 | N49: 0 | O49: 0 | P49: 1 | Q49: =SUM(E49:P49) -> 1
C50: 5. ENI WIJI LESTARI | E50: 0 | F50: 0 | G50: 0 | H50: 0 | I50: 0 | J50: 0 | K50: 0 | L50: 0 | M50: 0 | N50: 0 | O50: 0 | P50: 0 | Q50: =SUM(E50:P50) -> 0
C51: 6. SONNY AGUS SETIAWAN | E51: 0 | F51: 0 | G51: 0 | H51: 0 | I51: 0 | J51: 0 | K51: 0 | L51: 0 | M51: 0 | N51: 0 | O51: 0 | P51: 0 | Q51: =SUM(E51:P51) -> 0
...

Sheet PADANG
C2: Kecamatan | D2: SINGOJURUH
C3: Kabupaten | D3: BANYUWANGI
C4: Provinsi | D4: JAWA TIMUR
C9: Kelurahan | D9: PADANG
A12: I | B12: DATA PEMILIH DAN PENGGUNAAN HAK PILIH | Q12: JUMLAH AKHIR
A13: A | B13: DATA PEMILIH | E13: TPS 001 | F13: TPS 002 | G13: TPS 003 | H13: TPS 004 | I13: TPS 005 | J13: TPS 006 | K13: TPS 007 | L13: TPS 008 | M13: TPS 009 | N13: TPS 010 | O13: TPS 011 | P13: TPS 012
B14: Jumlah Pemilih dalam Daftar Pemilih Tetap (DPT) | D14: LK | E14: 139 | F14: 134 | G14: 138 | H14: 136 | I14: 114 | J14: 128 | K14: 115 | L14: 133 | M14: 112 | N14: 135 | O14: 124 | P14: 119 | Q14: =SUM(E14:P14) -> 1527
D15: PR | E15: 140 | F15: 129 | G15: 141 | H15: 137 | I15: 124 | J15: 138 | K15: 118 | L15: 138 | M15: 118 | N15: 146 | O15: 138 | P15: 120 | Q15: =SUM(E15:P15) -> 1587
D16: JML | E16: =SUM(E14:E15) -> 279 | F16: =SUM(F14:F15) -> 263 | G16: =SUM(G14:G15) -> 279 | H16: =SUM(H14:H15) -> 273 | I16: =SUM(I14:I15) -> 238 | J16: =SUM(J14:J15) -> 266 | K16: =SUM(K14:K15) -> 233 | L16: =SUM(L14:L15) -> 271 | ... P16: =SUM(P14:P15) -> 239 | Q16: =SUM(E16:P16) -> 3114
A18: B | B18: PENGGUNA HAK PILIH
B19: 1. | C19: Jumlah pengguna hak pilih dalam Daftar Pemilih Tetap (DPT) | D19: LK | E19: 120 | F19: 107 | G19: 100 | H19: 100 | I19: 93 | J19: 107 | K19: 90 | L19: 110 | M19: 88 | N19: 100 | O19: 88 | P19: 90 | Q19: =SUM(E19:P19) -> 1193
D20: PR | E20: 116 | F20: 115 | G20: 111 | H20: 109 | I20: 113 | J20: 120 | K20: 102 | L20: 119 | M20: 95 | N20: 107 | O20: 110 | P20: 97 | Q20: =SUM(E20:P20) -> 1314
D21: JML | E21: =SUM(E19:E20) -> 236 | F21: =SUM(F19:F20) -> 222 | G21: =SUM(G19:G20) -> 211 | H21: =SUM(H19:H20) -> 209 | I21: =SUM(I19:I20) -> 206 | J21: =SUM(J19:J20) -> 227 | K21: =SUM(K19:K20) -> 192 | L21: =SUM(L19:L20) -> 229 | ... P21: =SUM(P19:P20) -> 187 | Q21: =SUM(E21:P21) -> 2507
B22: 2. | C22: Jumlah pengguna hak pilih dalam Daftar Pemilih Tambahan (DPTb) | D22: LK | E22: 2 | F22: 0 | G22: 1 | H22: 0 | I22: 0 | J22: 1 | K22: 1 | L22: 0 | M22: 0 | N22: 0 | O22: 0 | P22: 2 | Q22: =SUM(E22:P22) -> 7
D23: PR | E23: 3 | F23: 2 | G23: 0 | H23: 1 | I23: 0 | J23: 0 | K23: 0 | L23: 0 | M23: 1 | N23: 1 | O23: 0 | P23: 0 | Q23: =SUM(E23:P23) -> 8
D24: JML | E24: =SUM(E22:E23) -> 5 | F24: =SUM(F22:F23) -> 2 | G24: =SUM(G22:G23) -> 1 | H24: =SUM(H22:H23) -> 1 | I24: =SUM(I22:I23) -> 0 | J24: =SUM(J22:J23) -> 1 | K24: =SUM(K22:K23) -> 1 | L24: =SUM(L22:L23) -> 0 | ... P24: =SUM(P22:P23) -> 2 | Q24: =SUM(E24:P24) -> 15
B25: 3. | C25: Jumlah pengguna hak pilih dalam Daftar Pemilih Khusus (DPK) | D25: LK | E25: 0 | F25: 1 | G25: 0 | H25: 1 | I25: 2 | J25: 0 | K25: 1 | L25: 2 | M25: 0 | N25: 2 | O25: 1 | P25: 2 | Q25: =SUM(E25:P25) -> 12
D26: PR | E26: 0 | F26: 0 | G26: 0 | H26: 2 | I26: 2 | J26: 1 | K26: 3 | L26: 2 | M26: 0 | N26: 1 | O26: 3 | P26: 0 | Q26: =SUM(E26:P26) -> 14
D27: JML | E27: =SUM(E25:E26) -> 0 | F27: =SUM(F25:F26) -> 1 | G27: =SUM(G25:G26) -> 0 | H27: =SUM(H25:H26) -> 3 | I27: =SUM(I25:I26) -> 4 | J27: =SUM(J25:J26) -> 1 | K27: =SUM(K25:K26) -> 4 | L27: =SUM(L25:L26) -> 4 | ... P27: =SUM(P25:P26) -> 2 | Q27: =SUM(E27:P27) -> 26
