Workbook

Sheet DPRD KAB
C8: Kecamatan | D8: PURWOHARJO
C9: Kabupaten | D9: BANYUWANGI
C10: Provinsi | D10: JAWA TIMUR
A12: I | B12: DATA PEMILIH DAN PENGGUNAAN HAK PILIH | E12: JUMLAH AKHIR
A13: A | B13: DATA PEMILIH
B14: Jumlah Pemilih dalam Daftar Pemilih Tetap (DPT) | D14: LK | E14: =BULUREJO!AF14+GLAGAHAGUNG!AA14+GRAJAGAN!AV14+KARETAN!O14+KRADENAN!AK14+PURWOHARJO!AK14+SIDOREJO!AA14+SUMBERASRI!X14 -> 27886
D15: PR | E15: =BULUREJO!AF15+GLAGAHAGUNG!AA15+GRAJAGAN!AV15+KARETAN!O15+KRADENAN!AK15+PURWOHARJO!AK15+SIDOREJO!AA15+SUMBERASRI!X15 -> 27699
D16: JML | E16: =SUM(E14:E15) -> 55585
A18: B | B18: PENGGUNA HAK PILIH
B19: 1. | C19: Jumlah pengguna hak pilih dalam Daftar Pemilih Tetap (DPT) | D19: LK | E19: =BULUREJO!AF19+GLAGAHAGUNG!AA19+GRAJAGAN!AV19+KARETAN!O19+KRADENAN!AK19+PURWOHARJO!AK19+SIDOREJO!AA19+SUMBERASRI!X19 -> 21193
D20: PR | E20: =BULUREJO!AF20+GLAGAHAGUNG!AA20+GRAJAGAN!AV20+KARETAN!O20+KRADENAN!AK20+PURWOHARJO!AK20+SIDOREJO!AA20+SUMBERASRI!X20 -> 21906
D21: JML | E21: =SUM(E19:E20) -> 43099
B22: 2. | C22: Jumlah pengguna hak pilih dalam Daftar Pemilih Tambahan (DPTb) | D22: LK | E22: =BULUREJO!AF22+GLAGAHAGUNG!AA22+GRAJAGAN!AV22+KARETAN!O22+KRADENAN!AK22+PURWOHARJO!AK22+SIDOREJO!AA22+SUMBERASRI!X22 -> 22
D23: PR | E23: =BULUREJO!AF23+GLAGAHAGUNG!AA23+GRAJAGAN!AV23+KARETAN!O23+KRADENAN!AK23+PURWOHARJO!AK23+SIDOREJO!AA23+SUMBERASRI!X23 -> 13
D24: JML | E24: =SUM(E22:E23) -> 35
B25: 3. | C25: Jumlah pengguna hak pilih dalam Daftar Pemilih Khusus (DPK) | D25: LK | E25: =BULUREJO!AF25+GLAGAHAGUNG!AA25+GRAJAGAN!AV25+KARETAN!O25+KRADENAN!AK25+PURWOHARJO!AK25+SIDOREJO!AA25+SUMBERASRI!X25 -> 225
D26: PR | E26: =BULUREJO!AF26+GLAGAHAGUNG!AA26+GRAJAGAN!AV26+KARETAN!O26+KRADENAN!AK26+PURWOHARJO!AK26+SIDOREJO!AA26+SUMBERASRI!X26 -> 277
D27: JML | E27: =SUM(E25:E26) -> 502
B28: 4. | C28: Jumlah Pengguna Hak Pilih (B.1+B.2+B.3) | D28: LK | E28: =E19+E22+E25 -> 21440
D29: PR | E29: =E20+E23+E26 -> 22196
D30: JML | E30: =SUM(E28:E29) -> 43636
A32: II | B32: DATA PENGGUNAAN SURAT SUARA
A33: 1 | B33: Jumlah surat suara yang diterima, termasuk surat suara cadangan 2,5% dari DPT | E33: =BULUREJO!AF33+GLAGAHAGUNG!AA33+GRAJAGAN!AV33+KARETAN!O33+KRADENAN!AK33+PURWOHARJO!AK33+SIDOREJO!AA33+SUMBERASRI!X33 -> 56890
A34: 2 | B34: Jumlah surat suara yang digunakan | E34: =BULUREJO!AF34+GLAGAHAGUNG!AA34+GRAJAGAN!AV34+KARETAN!O34+KRADENAN!AK34+PURWOHARJO!AK34+SIDOREJO!AA34+SUMBERASRI!X34 -> 43636
A35: 3 | B35: Jumlah surat suara dikembalikan oleh pemilih (karena rusak atau keliru coblos) | E35: =BULUREJO!AF35+GLAGAHAGUNG!AA35+GRAJAGAN!AV35+KARETAN!O35+KRADENAN!AK35+PURWOHARJO!AK35+SIDOREJO!AA35+SUMBERASRI!X35 -> 111
A36: 4 | B36: Jumlah surat suara yang tidak digunakan/tidak terpakai, termasuk sisa surat suara cadangan | E36: =E33-(E34+E35) -> 13143
A38: III | B38: DATA PEMILIH DISABILITAS
B39: Jumlah seluruh Pemilih disabilitas yang menggunakan hak pilih | D39: LK | E39: =BULUREJO!AF39+GLAGAHAGUNG!AA39+GRAJAGAN!AV39+KARETAN!O39+KRADENAN!AK39+PURWOHARJO!AK39+SIDOREJO!AA39+SUMBERASRI!X39 -> 19
D40: PR | E40: =BULUREJO!AF40+GLAGAHAGUNG!AA40+GRAJAGAN!AV40+KARETAN!O40+KRADENAN!AK40+PURWOHARJO!AK40+SIDOREJO!AA40+SUMBERASRI!X40 -> 20
D41: JML | E41: =SUM(E39:E40) -> 39
A43: IV | B43: DATA RINCIAN PEROLEHAN SUARA PASANGAN CALON BUPATI DAN WAKIL BUPATI
A44: NOMOR DAN NAMA CALON
A45: A.1 | B45: 1. | C45: Partai Kebangkitan Bangsa | E45: =BULUREJO!AF45+GLAGAHAGUNG!AA45+GRAJAGAN!AV45+KARETAN!O45+KRADENAN!AK45+PURWOHARJO!AK45+SIDOREJO!AA45+SUMBERASRI!X45 -> 984
A46: A.2 | C46: 1. MUKHTAR NABALI MUFAUWIQ | E46: =BULUREJO!AF46+GLAGAHAGUNG!AA46+GRAJAGAN!AV46+KARETAN!O46+KRADENAN!AK46+PURWOHARJO!AK46+SIDOREJO!AA46+SUMBERASRI!X46 -> 877
C47: 2. H. SUSIYANTO | E47: =BULUREJO!AF47+GLAGAHAGUNG!AA47+GRAJAGAN!AV47+KARETAN!O47+KRADENAN!AK47+PURWOHARJO!AK47+SIDOREJO!AA47+SUMBERASRI!X47 -> 6637
C48: 3. DUWI HASTRENI, S.H. | E48: =BULUREJO!AF48+GLAGAHAGUNG!AA48+GRAJAGAN!AV48+KARETAN!O48+KRADENAN!AK48+PURWOHARJO!AK48+SIDOREJO!AA48+SUMBERASRI!X48 -> 877
C49: 4. MIFTAKHODIN | E49: =BULUREJO!AF49+GLAGAHAGUNG!AA49+GRAJAGAN!AV49+KARETAN!O49+KRADENAN!AK49+PURWOHARJO!AK49+SIDOREJO!AA49+SUMBERASRI!X49 -> 22
C50: 5. SITI MUSTIKAH | E50: =BULUREJO!AF50+GLAGAHAGUNG!AA50+GRAJAGAN!AV50+KARETAN!O50+KRADENAN!AK50+PURWOHARJO!AK50+SIDOREJO!AA50+SUMBERASRI!X50 -> 50
C51: 6. ABDUL GHOFUR | E51: =BULUREJO!AF51+GLAGAHAGUNG!AA51+GRAJAGAN!AV51+KARETAN!O51+KRADENAN!AK51+PURWOHARJO!AK51+SIDOREJO!AA51+SUMBERASRI!X51 -> 31
C52: 7. ABDUL ROHMAN, S.Pd. | E52: =BULUREJO!AF52+GLAGAHAGUNG!AA52+GRAJAGAN!AV52+KARETAN!O52+KRADENAN!AK52+PURWOHARJO!AK52+SIDOREJO!AA52+SUMBERASRI!X52 -> 421
...

Sheet GRAJAGAN
C2: Kecamatan | D2: PURWOHARJO
C3: Kabupaten | D3: BANYUWANGI
C4: Provinsi | D4: JAWA TIMUR
C9: Kelurahan | D9: GRAJAGAN
A12: I | B12: DATA PEMILIH DAN PENGGUNAAN HAK PILIH | AV12: JUMLAH AKHIR
A13: A | B13: DATA PEMILIH | E13: TPS 001 | F13: TPS 002 | G13: TPS 003 | H13: TPS 004 | I13: TPS 005 | J13: TPS 006 | K13: TPS 007 | L13: TPS 008 | M13: TPS 009 | N13: TPS 010 | O13: TPS 011 | P13: TPS 012 | Q13: TPS 013 | R13: TPS 014 | S13: TPS 015 | T13: TPS 016 | U13: TPS 017 | V13: TPS 018 | W13: TPS 019 | X13: TPS 020 | Y13: TPS 021 | Z13: TPS 022 | AA13: TPS 023 | AB13: TPS 024 | AC13: TPS 025 | AD13: TPS 026 | AE13: TPS 027 | AF13: TPS 028 | AG13: TPS 029 | AH13: TPS 030 | AI13: TPS 031 | AJ13: TPS 032 | AK13: TPS 033 | AL13: TPS 034 | AM13: TPS 035 | AN13: TPS 036 | AO13: TPS 037 | AP13: TPS 038 | AQ13: TPS 039 | AR13: TPS 040 | AS13: TPS 041 | AT13: TPS 042 | AU13: TPS 043
B14: Jumlah Pemilih dalam Daftar Pemilih Tetap (DPT) | D14: LK | E14: 133 | F14: 134 | G14: 131 | H14: 125 | I14: 129 | J14: 128 | K14: 127 | L14: 128 | M14: 131 | N14: 133 | O14: 130 | P14: 142 | Q14: 127 | R14: 133 | S14: 135 | T14: 131 | U14: 136 | V14: 131 | W14: 143 | X14: 129 | Y14: 127 | Z14: 131 | AA14: 137 | AB14: 134 | AC14: 141 | AD14: 130 | AE14: 131 | AF14: 138 | AG14: 138 | AH14: 142 | AI14: 133 | AJ14: 139 | AK14: 129 | AL14: 125 | AM14: 132 | AN14: 133 | AO14: 128 | AP14: 149 | AQ14: 130 | AR14: 143 | AS14: 130 | AT14: 136 | AU14: 141 | AV14: =SUM(E14:AU14) -> 5733
D15: PR | E15: 131 | F15: 127 | G15: 135 | H15: 127 | I15: 141 | J15: 136 | K15: 136 | L15: 139 | M15: 138 | N15: 132 | O15: 137 | P15: 121 | Q15: 130 | R15: 130 | S15: 134 | T15: 127 | U15: 129 | V15: 125 | W15: 124 | X15: 124 | Y15: 134 | Z15: 138 | AA15: 140 | AB15: 138 | AC15: 138 | AD15: 128 | AE15: 140 | AF15: 139 | AG15: 134 | AH15: 128 | AI15: 115 | AJ15: 122 | AK15: 138 | AL15: 124 | AM15: 133 | AN15: 124 | AO15: 141 | AP15: 117 | AQ15: 126 | AR15: 121 | AS15: 130 | AT15: 135 | AU15: 133 | AV15: =SUM(E15:AU15) -> 5639
D16: JML | E16: =SUM(E14:E15) -> 264 | F16: =SUM(F14:F15) -> 261 | G16: =SUM(G14:G15) -> 266 | H16: =SUM(H14:H15) -> 252 | I16: =SUM(I14:I15) -> 270 | J16: =SUM(J14:J15) -> 264 | K16: =SUM(K14:K15) -> 263 | L16: =SUM(L14:L15) -> 267 | ... AU16: =SUM(AU14:AU15) -> 274 | AV16: =SUM(E16:AU16) -> 11372
A18: B | B18: PENGGUNA HAK PILIH
B19: 1. | C19: Jumlah pengguna hak pilih dalam Daftar Pemilih Tetap (DPT) | D19: LK | E19: 90 | F19: 97 | G19: 95 | H19: 92 | I19: 89 | J19: 92 | K19: 88 | L19: 95 | M19: 95 | N19: 96 | O19: 93 | P19: 99 | Q19: 93 | R19: 90 | S19: 97 | T19: 88 | U19: 102 | V19: 110 | W19: 106 | X19: 95 | Y19: 108 | Z19: 104 | AA19: 97 | AB19: 106 | AC19: 108 | AD19: 89 | AE19: 101 | AF19: 99 | AG19: 101 | AH19: 105 | AI19: 84 | AJ19: 113 | AK19: 96 | AL19: 86 | AM19: 97 | AN19: 85 | AO19: 98 | AP19: 117 | AQ19: 91 | AR19: 109 | AS19: 100 | AT19: 102 | AU19: 114 | AV19: =SUM(E19:AU19) -> 4212
D20: PR | E20: 104 | F20: 99 | G20: 110 | H20: 94 | I20: 98 | J20: 98 | K20: 106 | L20: 110 | M20: 99 | N20: 96 | O20: 108 | P20: 95 | Q20: 91 | R20: 84 | S20: 100 | T20: 94 | U20: 94 | V20: 108 | W20: 101 | X20: 98 | Y20: 113 | Z20: 117 | AA20: 109 | AB20: 107 | AC20: 112 | AD20: 98 | AE20: 104 | AF20: 113 | AG20: 96 | AH20: 105 | AI20: 81 | AJ20: 88 | AK20: 93 | AL20: 89 | AM20: 94 | AN20: 76 | AO20: 103 | AP20: 93 | AQ20: 96 | AR20: 89 | AS20: 103 | AT20: 105 | AU20: 104 | AV20: =SUM(E20:AU20) -> 4275
D21: JML | E21: =SUM(E19:E20) -> 194 | F21: =SUM(F19:F20) -> 196 | G21: =SUM(G19:G20) -> 205 | H21: =SUM(H19:H20) -> 186 | I21: =SUM(I19:I20) -> 187 | J21: =SUM(J19:J20) -> 190 | K21: =SUM(K19:K20) -> 194 | L21: =SUM(L19:L20) -> 205 | ... AU21: =SUM(AU19:AU20) -> 218 | AV21: =SUM(E21:AU21) -> 8487
B22: 2. | C22: Jumlah pengguna hak pilih dalam Daftar Pemilih Tambahan (DPTb) | D22: LK | E22: 0 | F22: 0 | G22: 0 | H22: 0 | I22: 0 | J22: 0 | K22: 0 | L22: 0 | M22: 0 | N22: 0 | O22: 0 | P22: 0 | Q22: 0 | R22: 0 | S22: 0 | T22: 0 | U22: 0 | V22: 0 | W22: 0 | X22: 0 | Y22: 0 | Z22: 0 | AA22: 0 | AB22: 0 | AC22: 0 | AD22: 0 | AE22: 0 | AF22: 0 | AG22: 0 | AH22: 0 | AI22: 0 | AJ22: 0 | AK22: 0 | AL22: 0 | AM22: 1 | AN22: 0 | AO22: 0 | AP22: 0 | AQ22: 0 | AR22: 0 | AS22: 0 | AT22: 0 | AU22: 0 | AV22: =SUM(E22:AU22) -> 1
D23: PR | E23: 0 | F23: 0 | G23: 0 | H23: 0 | I23: 0 | J23: 0 | K23: 0 | L23: 0 | M23: 0 | N23: 0 | O23: 0 | P23: 0 | Q23: 0 | R23: 0 | S23: 0 | T23: 0 | U23: 0 | V23: 0 | W23: 0 | X23: 0 | Y23: 0 | Z23: 0 | AA23: 0 | AB23: 0 | AC23: 0 | AD23: 0 | AE23: 0 | AF23: 0 | AG23: 0 | AH23: 0 | AI23: 0 | AJ23: 0 | AK23: 0 | AL23: 0 | AM23: 0 | AN23: 0 | AO23: 0 | AP23: 0 | AQ23: 0 | AR23: 0 | AS23: 0 | AT23: 0 | AU23: 0 | AV23: =SUM(E23:AU23) -> 0
D24: JML | E24: =SUM(E22:E23) -> 0 | F24: =SUM(F22:F23) -> 0 | G24: =SUM(G22:G23) -> 0 | H24: =SUM(H22:H23) -> 0 | I24: =SUM(I22:I23) -> 0 | J24: =SUM(J22:J23) -> 0 | K24: =SUM(K22:K23) -> 0 | L24: =SUM(L22:L23) -> 0 | ... AU24: =SUM(AU22:AU23) -> 0 | AV24: =SUM(E24:AU24) -> 1
B25: 3. | C25: Jumlah pengguna hak pilih dalam Daftar Pemilih Khusus (DPK) | D25: LK | E25: 2 | F25: 3 | G25: 2 | H25: 3 | I25: 1 | J25: 5 | K25: 0 | L25: 1 | M25: 2 | N25: 3 | O25: 0 | P25: 0 | Q25: 0 | R25: 1 | S25: 0 | T25: 1 | U25: 0 | V25: 0 | W25: 3 | X25: 4 | Y25: 0 | Z25: 1 | AA25: 0 | AB25: 3 | AC25: 0 | AD25: 0 | AE25: 1 | AF25: 2 | AG25: 2 | AH25: 0 | AI25: 2 | AJ25: 1 | AK25: 0 | AL25: 7 | AM25: 0 | AN25: 6 | AO25: 1 | AP25: 1 | AQ25: 2 | AR25: 3 | AS25: 2 | AT25: 0 | AU25: 0 | AV25: =SUM(E25:AU25) -> 65
D26: PR | E26: 4 | F26: 4 | G26: 1 | H26: 5 | I26: 1 | J26: 9 | K26: 0 | L26: 1 | M26: 1 | N26: 1 | O26: 1 | P26: 0 | Q26: 1 | R26: 1 | S26: 0 | T26: 4 | U26: 1 | V26: 0 | W26: 4 | X26: 4 | Y26: 0 | Z26: 2 | AA26: 0 | AB26: 2 | AC26: 0 | AD26: 1 | AE26: 1 | AF26: 1 | AG26: 2 | AH26: 1 | AI26: 2 | AJ26: 2 | AK26: 0 | AL26: 12 | AM26: 0 | AN26: 7 | AO26: 2 | AP26: 2 | AQ26: 2 | AR26: 1 | AS26: 0 | AT26: 1 | AU26: 0 | AV26: =SUM(E26:AU26) -> 84
D27: JML | E27: =SUM(E25:E26) -> 6 | F27: =SUM(F25:F26) -> 7 | G27: =SUM(G25:G26) -> 3 | H27: =SUM(H25:H26) -> 8 | I27: =SUM(I25:I26) -> 2 | J27: =SUM(J25:J26) -> 14 | K27: =SUM(K25:K26) -> 0 | L27: =SUM(L25:L26) -> 2 | ... AU27: =SUM(AU25:AU26) -> 0 | AV27: =SUM(E27:AU27) -> 149
B28: 4. | C28: Jumlah Pengguna Hak Pilih (B.1+B.2+B.3) | D28: LK | E28: =SUM(E19,E22,E25) -> 92 | F28: =SUM(F19,F22,F25) -> 100 | G28: =SUM(G19,G22,G25) -> 97 | H28: =SUM(H19,H22,H25) -> 95 | I28: =SUM(I19,I22,I25) -> 90 | J28: =SUM(J19,J22,J25) -> 97 | K28: =SUM(K19,K22,K25) -> 88 | L28: =SUM(L19,L22,L25) -> 96 | ... AU28: =SUM(AU19,AU22,AU25) -> 114 | AV28: =SUM(E28:AU28) -> 4278
D29: PR | E29: =SUM(E20,E23,E26) -> 108 | F29: =SUM(F20,F23,F26) -> 103 | G29: =SUM(G20,G23,G26) -> 111 | H29: =SUM(H20,H23,H26) -> 99 | I29: =SUM(I20,I23,I26) -> 99 | J29: =SUM(J20,J23,J26) -> 107 | K29: =SUM(K20,K23,K26) -> 106 | L29: =SUM(L20,L23,L26) -> 111 | ... AU29: =SUM(AU20,AU23,AU26) -> 104 | AV29: =SUM(E29:AU29) -> 4359
D30: JML | E30: =SUM(E28:E29) -> 200 | F30: =SUM(F28:F29) -> 203 | G30: =SUM(G28:G29) -> 208 | H30: =SUM(H28:H29) -> 194 | I30: =SUM(I28:I29) -> 189 | J30: =SUM(J28:J29) -> 204 | K30: =SUM(K28:K29) -> 194 | L30: =SUM(L28:L29) -> 207 | ... AU30: =SUM(AU28:AU29) -> 218 | AV30: =SUM(E30:AU30) -> 8637
A32: II | B32: DATA PENGGUNAAN SURAT SUARA
A33: 1 | B33: Jumlah surat suara yang diterima, termasuk surat suara cadangan 2,5% dari DPT | E33: 270 | F33: 267 | G33: 272 | H33: 258 | I33: 276 | J33: 270 | K33: 269 | L33: 273 | M33: 275 | N33: 271 | O33: 274 | P33: 269 | Q33: 263 | R33: 269 | S33: 275 | T33: 264 | U33: 271 | V33: 263 | W33: 273 | X33: 259 | Y33: 267 | Z33: 275 | AA33: 283 | AB33: 278 | AC33: 285 | AD33: 264 | AE33: 297 | AF33: 283 | AG33: 278 | AH33: 276 | AI33: 253 | AJ33: 267 | AK33: 273 | AL33: 255 | AM33: 270 | AN33: 263 | AO33: 275 | AP33: 272 | AQ33: 262 | AR33: 270 | AS33: 266 | AT33: 277 | AU33: 280 | AV33: =SUM(E33:AU33) -> 11650
A34: 2 | B34: Jumlah surat suara yang digunakan | E34: 200 | F34: 203 | G34: 208 | H34: 194 | I34: 189 | J34: 204 | K34: 194 | L34: 207 | M34: 197 | N34: 196 | O34: 202 | P34: 194 | Q34: 185 | R34: 176 | S34: 197 | T34: 187 | U34: 197 | V34: 218 | W34: 214 | X34: 201 | Y34: 221 | Z34: 224 | AA34: 206 | AB34: 218 | AC34: 220 | AD34: 188 | AE34: 207 | AF34: 215 | AG34: 201 | AH34: 211 | AI34: 169 | AJ34: 204 | AK34: 189 | AL34: 194 | AM34: 192 | AN34: 174 | AO34: 204 | AP34: 213 | AQ34: 191 | AR34: 202 | AS34: 205 | AT34: 208 | AU34: 218 | AV34: =SUM(E34:AU34) -> 8637
A35: 3 | B35: Jumlah surat suara dikembalikan oleh pemilih (karena rusak atau keliru coblos) | E35: 1 | F35: 0 | G35: 0 | H35: 0 | I35: 0 | J35: 0 | K35: 0 | L35: 1 | M35: 0 | N35: 0 | O35: 0 | P35: 0 | Q35: 0 | R35: 0 | S35: 0 | T35: 0 | U35: 0 | V35: 1 | W35: 0 | X35: 0 | Y35: 0 | Z35: 1 | AA35: 0 | AB35: 1 | AC35: 1 | AD35: 1 | AE35: 2 | AF35: 0 | AG35: 1 | AH35: 0 | AI35: 0 | AJ35: 0 | AK35: 0 | AL35: 0 | AM35: 0 | AN35: 0 | AO35: 1 | AP35: 0 | AQ35: 0 | AR35: 0 | AS35: 1 | AT35: 0 | AU35: 0 | AV35: =SUM(E35:AU35) -> 12
A36: 4 | B36: Jumlah surat suara yang tidak digunakan/tidak terpakai, termasuk sisa surat suara cadangan | E36: =E33-(E34+E35) -> 69 | F36: =F33-(F34+F35) -> 64 | G36: =G33-(G34+G35) -> 64 | H36: =H33-(H34+H35) -> 64 | I36: =I33-(I34+I35) -> 87 | J36: =J33-(J34+J35) -> 66 | K36: =K33-(K34+K35) -> 75 | L36: =L33-(L34+L35) -> 65 | ... AU36: =AU33-(AU34+AU35) -> 62 | AV36: =SUM(E36:AU36) -> 3001
A38: III | B38: DATA PEMILIH DISABILITAS
B39: Jumlah seluruh Pemilih disabilitas yang menggunakan hak pilih | D39: LK | E39: 0 | F39: 0 | G39: 0 | H39: 0 | I39: 0 | J39: 0 | K39: 0 | L39: 0 | M39: 0 | N39: 0 | O39: 0 | P39: 0 | Q39: 0 | R39: 0 | S39: 0 | T39: 0 | U39: 0 | V39: 0 | W39: 0 | X39: 0 | Y39: 0 | Z39: 0 | AA39: 0 | AB39: 0 | AC39: 0 | AD39: 0 | AE39: 0 | AF39: 0 | AG39: 0 | AH39: 0 | AI39: 0 | AJ39: 0 | AK39: 0 | AL39: 0 | AM39: 0 | AN39: 0 | AO39: 0 | AP39: 0 | AQ39: 0 | AR39: 1 | AS39: 0 | AT39: 0 | AU39: 0 | AV39: =SUM(E39:AU39) -> 1
D40: PR | E40: 0 | F40: 0 | G40: 0 | H40: 0 | I40: 0 | J40: 0 | K40: 0 | L40: 0 | M40: 0 | N40: 0 | O40: 0 | P40: 0 | Q40: 0 | R40: 0 | S40: 0 | T40: 0 | U40: 0 | V40: 0 | W40: 0 | X40: 0 | Y40: 0 | Z40: 0 | AA40: 0 | AB40: 0 | AC40: 0 | AD40: 0 | AE40: 0 | AF40: 0 | AG40: 0 | AH40: 0 | AI40: 0 | AJ40: 0 | AK40: 0 | AL40: 0 | AM40: 0 | AN40: 0 | AO40: 0 | AP40: 0 | AQ40: 0 | AR40: 0 | AS40: 0 | AT40: 0 | AU40: 0 | AV40: =SUM(E40:AU40) -> 0
D41: JML | E41: =SUM(E39:E40) -> 0 | F41: =SUM(F39:F40) -> 0 | G41: =SUM(G39:G40) -> 0 | H41: =SUM(H39:H40) -> 0 | I41: =SUM(I39:I40) -> 0 | J41: =SUM(J39:J40) -> 0 | K41: =SUM(K39:K40) -> 0 | L41: =SUM(L39:L40) -> 0 | ... AU41: =SUM(AU39:AU40) -> 0 | AV41: =SUM(E41:AU41) -> 1
A43: IV | B43: DATA RINCIAN PEROLEHAN SUARA PASANGAN CALON BUPATI DAN WAKIL BUPATI
A44: NOMOR DAN NAMA CALON
A45: A.1 | B45: 1. | C45: Partai Kebangkitan Bangsa | E45: 4 | F45: 6 | G45: 6 | H45: 1 | I45: 1 | J45: 3 | K45: 6 | L45: 8 | M45: 1 | N45: 3 | O45: 2 | P45: 2 | Q45: 5 | R45: 0 | S45: 0 | T45: 4 | U45: 1 | V45: 0 | W45: 3 | X45: 1 | Y45: 1 | Z45: 8 | AA45: 6 | AB45: 7 | AC45: 3 | AD45: 3 | AE45: 4 | AF45: 4 | AG45: 7 | AH45: 0 | AI45: 2 | AJ45: 1 | AK45: 3 | AL45: 4 | AM45: 2 | AN45: 4 | AO45: 7 | AP45: 1 | AQ45: 5 | AR45: 5 | AS45: 7 | AT45: 4 | AU45: 4 | AV45: =SUM(E45:AU45) -> 149
A46: A.2 | C46: 1. MUKHTAR NABALI MUFAUWIQ | E46: 2 | F46: 1 | G46: 3 | H46: 6 | I46: 1 | J46: 2 | K46: 2 | L46: 1 | M46: 1 | N46: 2 | O46: 0 | P46: 2 | Q46: 0 | R46: 2 | S46: 0 | T46: 4 | U46: 1 | V46: 0 | W46: 2 | X46: 1 | Y46: 1 | Z46: 2 | AA46: 0 | AB46: 3 | AC46: 5 | AD46: 1 | AE46: 3 | AF46: 2 | AG46: 1 | AH46: 2 | AI46: 1 | AJ46: 4 | AK46: 2 | AL46: 4 | AM46: 6 | AN46: 0 | AO46: 4 | AP46: 9 | AQ46: 2 | AR46: 7 | AS46: 4 | AT46: 2 | AU46: 4 | AV46: =SUM(E46:AU46) -> 102
C47: 2. H. SUSIYANTO | E47: 18 | F47: 43 | G47: 44 | H47: 30 | I47: 43 | J47: 25 | K47: 24 | L47: 29 | M47: 39 | N47: 29 | O47: 64 | P47: 16 | Q47: 26 | R47: 20 | S47: 11 | T47: 57 | U47: 26 | V47: 32 | W47: 31 | X47: 14 | Y47: 3 | Z47: 41 | AA47: 31 | AB47: 56 | AC47: 63 | AD47: 58 | AE47: 66 | AF47: 41 | AG47: 53 | AH47: 99 | AI47: 4 | AJ47: 4 | AK47: 8 | AL47: 1 | AM47: 1 | AN47: 1 | AO47: 2 | AP47: 14 | AQ47: 4 | AR47: 4 | AS47: 5 | AT47: 6 | AU47: 3 | AV47: =SUM(E47:AU47) -> 1189
C48: 3. DUWI HASTRENI, S.H. | E48: 0 | F48: 0 | G48: 1 | H48: 0 | I48: 0 | J48: 0 | K48: 0 | L48: 0 | M48: 1 | N48: 0 | O48: 0 | P48: 0 | Q48: 0 | R48: 1 | S48: 0 | T48: 0 | U48: 1 | V48: 0 | W48: 1 | X48: 0 | Y48: 0 | Z48: 2 | AA48: 0 | AB48: 3 | AC48: 14 | AD48: 1 | AE48: 1 | AF48: 0 | AG48: 0 | AH48: 1 | AI48: 0 | AJ48: 5 | AK48: 3 | AL48: 1 | AM48: 0 | AN48: 0 | AO48: 2 | AP48: 1 | AQ48: 0 | AR48: 6 | AS48: 0 | AT48: 1 | AU48: 1 | AV48: =SUM(E48:AU48) -> 47
C49: 4. MIFTAKHODIN | E49: 0 | F49: 0 | G49: 0 | H49: 0 | I49: 0 | J49: 0 | K49: 0 | L49: 0 | M49: 0 | N49: 0 | O49: 0 | P49: 0 | Q49: 0 | R49: 0 | S49: 0 | T49: 0 | U49: 0 | V49: 0 | W49: 0 | X49: 0 | Y49: 0 | Z49: 0 | AA49: 0 | AB49: 0 | AC49: 0 | AD49: 0 | AE49: 0 | AF49: 0 | AG49: 0 | AH49: 0 | AI49: 0 | AJ49: 0 | AK49: 0 | AL49: 0 | AM49: 0 | AN49: 0 | AO49: 0 | AP49: 0 | AQ49: 0 | AR49: 0 | AS49: 1 | AT49: 1 | AU49: 0 | AV49: =SUM(E49:AU49) -> 2
C50: 5. SITI MUSTIKAH | E50: 0 | F50: 0 | G50: 0 | H50: 0 | I50: 0 | J50: 0 | K50: 0 | L50: 0 | M50: 0 | N50: 0 | O50: 0 | P50: 0 | Q50: 0 | R50: 2 | S50: 0 | T50: 0 | U50: 0 | V50: 0 | W50: 0 | X50: 0 | Y50: 0 | Z50: 0 | AA50: 1 | AB50: 1 | AC50: 0 | AD50: 0 | AE50: 1 | AF50: 0 | AG50: 0 | AH50: 0 | AI50: 0 | AJ50: 2 | AK50: 1 | AL50: 0 | AM50: 1 | AN50: 0 | AO50: 0 | AP50: 0 | AQ50: 0 | AR50: 0 | AS50: 0 | AT50: 0 | AU50: 1 | AV50: =SUM(E50:AU50) -> 10
C51: 6. ABDUL GHOFUR | E51: 0 | F51: 0 | G51: 0 | H51: 0 | I51: 0 | J51: 0 | K51: 0 | L51: 0 | M51: 0 | N51: 0 | O51: 0 | P51: 0 | Q51: 1 | R51: 0 | S51: 0 | T51: 0 | U51: 0 | V51: 0 | W51: 0 | X51: 0 | Y51: 0 | Z51: 0 | AA51: 0 | AB51: 0 | AC51: 0 | AD51: 0 | AE51: 0 | AF51: 0 | AG51: 0 | AH51: 0 | AI51: 0 | AJ51: 0 | AK51: 0 | AL51: 0 | AM51: 0 | AN51: 0 | AO51: 1 | AP51: 1 | AQ51: 0 | AR51: 1 | AS51: 0 | AT51: 1 | AU51: 0 | AV51: =SUM(E51:AU51) -> 5
...

Sheet SUMBERASRI
C2: Kecamatan | D2: PURWOHARJO
C3: Kabupaten | D3: BANYUWANGI
C4: Provinsi | D4: JAWA TIMUR
C9: Kelurahan | D9: SUMBERSARI
A12: I | B12: DATA PEMILIH DAN PENGGUNAAN HAK PILIH | X12: JUMLAH AKHIR
A13: A | B13: DATA PEMILIH | E13: TPS 001 | F13: TPS 002 | G13: TPS 003 | H13: TPS 004 | I13: TPS 005 | J13: TPS 006 | K13: TPS 007 | L13: TPS 008 | M13: TPS 009 | N13: TPS 010 | O13: TPS 011 | P13: TPS 012 | Q13: TPS 013 | R13: TPS 014 | S13: TPS 015 | T13: TPS 016 | U13: TPS 017 | V13: TPS 018 | W13: TPS 019
B14: Jumlah Pemilih dalam Daftar Pemilih Tetap (DPT) | D14: LK | E14: 143 | F14: 127 | G14: 140 | H14: 144 | I14: 152 | J14: 149 | K14: 125 | L14: 146 | M14: 146 | N14: 148 | O14: 147 | P14: 143 | Q14: 143 | R14: 118 | S14: 111 | T14: 153 | U14: 151 | V14: 150 | W14: 143 | X14: =SUM(E14:W14) -> 2679
D15: PR | E15: 140 | F15: 131 | G15: 134 | H15: 142 | I15: 137 | J15: 143 | K15: 119 | L15: 132 | M15: 137 | N15: 145 | O15: 135 | P15: 140 | Q15: 143 | R15: 125 | S15: 115 | T15: 140 | U15: 141 | V15: 145 | W15: 148 | X15: =SUM(E15:W15) -> 2592
D16: JML | E16: =SUM(E14:E15) -> 283 | F16: =SUM(F14:F15) -> 258 | G16: =SUM(G14:G15) -> 274 | H16: =SUM(H14:H15) -> 286 | I16: =SUM(I14:I15) -> 289 | J16: =SUM(J14:J15) -> 292 | K16: =SUM(K14:K15) -> 244 | L16: =SUM(L14:L15) -> 278 | ... W16: =SUM(W14:W15) -> 291 | X16: =SUM(E16:W16) -> 5271
A18: B | B18: PENGGUNA HAK PILIH
B19: 1. | C19: Jumlah pengguna hak pilih dalam Daftar Pemilih Tetap (DPT) | D19: LK | E19: 109 | F19: 97 | G19: 106 | H19: 113 | I19: 115 | J19: 111 | K19: 91 | L19: 113 | M19: 124 | N19: 112 | O19: 113 | P19: 112 | Q19: 114 | R19: 78 | S19: 88 | T19: 120 | U19: 113 | V19: 124 | W19: 133 | X19: =SUM(E19:W19) -> 2086
D20: PR | E20: 118 | F20: 109 | G20: 102 | H20: 113 | I20: 112 | J20: 113 | K20: 96 | L20: 102 | M20: 119 | N20: 117 | O20: 117 | P20: 120 | Q20: 118 | R20: 90 | S20: 93 | T20: 112 | U20: 111 | V20: 116 | W20: 140 | X20: =SUM(E20:W20) -> 2118
D21: JML | E21: =SUM(E19:E20) -> 227 | F21: =SUM(F19:F20) -> 206 | G21: =SUM(G19:G20) -> 208 | H21: =SUM(H19:H20) -> 226 | I21: =SUM(I19:I20) -> 227 | J21: =SUM(J19:J20) -> 224 | K21: =SUM(K19:K20) -> 187 | L21: =SUM(L19:L20) -> 215 | ... W21: =SUM(W19:W20) -> 273 | X21: =SUM(E21:W21) -> 4204
B22: 2. | C22: Jumlah pengguna hak pilih dalam Daftar Pemilih Tambahan (DPTb) | D22: LK | E22: 0 | F22: 1 | G22: 1 | H22: 0 | I22: 0 | J22: 0 | K22: 0 | L22: 0 | M22: 0 | N22: 0 | O22: 0 | P22: 0 | Q22: 1 | R22: 0 | S22: 1 | T22: 0 | U22: 0 | V22: 3 | W22: 1 | X22: =SUM(E22:W22) -> 8
D23: PR | E23: 0 | F23: 0 | G23: 1 | H23: 0 | I23: 0 | J23: 0 | K23: 0 | L23: 0 | M23: 0 | N23: 0 | O23: 0 | P23: 0 | Q23: 2 | R23: 0 | S23: 0 | T23: 0 | U23: 1 | V23: 1 | W23: 1 | X23: =SUM(E23:W23) -> 6
D24: JML | E24: =SUM(E22:E23) -> 0 | F24: =SUM(F22:F23) -> 1 | G24: =SUM(G22:G23) -> 2 | H24: =SUM(H22:H23) -> 0 | I24: =SUM(I22:I23) -> 0 | J24: =SUM(J22:J23) -> 0 | K24: =SUM(K22:K23) -> 0 | L24: =SUM(L22:L23) -> 0 | ... W24: =SUM(W22:W23) -> 2 | X24: =SUM(E24:W24) -> 14
B25: 3. | C25: Jumlah pengguna hak pilih dalam Daftar Pemilih Khusus (DPK) | D25: LK | E25: 0 | F25: 0 | G25: 1 | H25: 1 | I25: 1 | J25: 0 | K25: 0 | L25: 0 | M25: 0 | N25: 0 | O25: 3 | P25: 1 | Q25: 0 | R25: 2 | S25: 1 | T25: 1 | U25: 1 | V25: 1 | W25: 1 | X25: =SUM(E25:W25) -> 14
D26: PR | E26: 2 | F26: 0 | G26: 0 | H26: 0 | I26: 1 | J26: 4 | K26: 0 | L26: 0 | M26: 1 | N26: 2 | O26: 2 | P26: 4 | Q26: 0 | R26: 0 | S26: 1 | T26: 2 | U26: 0 | V26: 1 | W26: 0 | X26: =SUM(E26:W26) -> 20
D27: JML | E27: =SUM(E25:E26) -> 2 | F27: =SUM(F25:F26) -> 0 | G27: =SUM(G25:G26) -> 1 | H27: =SUM(H25:H26) -> 1 | I27: =SUM(I25:I26) -> 2 | J27: =SUM(J25:J26) -> 4 | K27: =SUM(K25:K26) -> 0 | L27: =SUM(L25:L26) -> 0 | ... W27: =SUM(W25:W26) -> 1 | X27: =SUM(E27:W27) -> 34
B28: 4. | C28: Jumlah Pengguna Hak Pilih (B.1+B.2+B.3) | D28: LK | E28: =SUM(E19,E22,E25) -> 109 | F28: =SUM(F19,F22,F25) -> 98 | G28: =SUM(G19,G22,G25) -> 108 | H28: =SUM(H19,H22,H25) -> 114 | I28: =SUM(I19,I22,I25) -> 116 | J28: =SUM(J19,J22,J25) -> 111 | K28: =SUM(K19,K22,K25) -> 91 | L28: =SUM(L19,L22,L25) -> 113 | ... W28: =SUM(W19,W22,W25) -> 135 | X28: =SUM(E28:W28) -> 2108
D29: PR | E29: =SUM(E20,E23,E26) -> 120 | F29: =SUM(F20,F23,F26) -> 109 | G29: =SUM(G20,G23,G26) -> 103 | H29: =SUM(H20,H23,H26) -> 113 | I29: =SUM(I20,I23,I26) -> 113 | J29: =SUM(J20,J23,J26) -> 117 | K29: =SUM(K20,K23,K26) -> 96 | L29: =SUM(L20,L23,L26) -> 102 | ... W29: =SUM(W20,W23,W26) -> 141 | X29: =SUM(E29:W29) -> 2144
D30: JML | E30: =SUM(E28:E29) -> 229 | F30: =SUM(F28:F29) -> 207 | G30: =SUM(G28:G29) -> 211 | H30: =SUM(H28:H29) -> 227 | I30: =SUM(I28:I29) -> 229 | J30: =SUM(J28:J29) -> 228 | K30: =SUM(K28:K29) -> 187 | L30: =SUM(L28:L29) -> 215 | ... W30: =SUM(W28:W29) -> 276 | X30: =SUM(E30:W30) -> 4252
A32: II | B32: DATA PENGGUNAAN SURAT SUARA
A33: 1 | B33: Jumlah surat suara yang diterima, termasuk surat suara cadangan 2,5% dari DPT | E33: 293 | F33: 264 | G33: 280 | H33: 292 | I33: 295 | J33: 298 | K33: 249 | L33: 284 | M33: 289 | N33: 299 | O33: 288 | P33: 289 | Q33: 292 | R33: 248 | S33: 231 | T33: 299 | U33: 298 | V33: 301 | W33: 297 | X33: =SUM(E33:W33) -> 5386
A34: 2 | B34: Jumlah surat suara yang digunakan | E34: 229 | F34: 207 | G34: 211 | H34: 227 | I34: 229 | J34: 228 | K34: 187 | L34: 215 | M34: 244 | N34: 231 | O34: 235 | P34: 237 | Q34: 235 | R34: 170 | S34: 184 | T34: 235 | U34: 226 | V34: 246 | W34: 276 | X34: =SUM(E34:W34) -> 4252
A35: 3 | B35: Jumlah surat suara dikembalikan oleh pemilih (karena rusak atau keliru coblos) | E35: 0 | F35: 12 | G35: 1 | H35: 2 | I35: 1 | J35: 0 | K35: 0 | L35: 2 | M35: 0 | N35: 1 | O35: 0 | P35: 0 | Q35: 1 | R35: 0 | S35: 0 | T35: 1 | U35: 0 | V35: 0 | W35: 6 | X35: =SUM(E35:W35) -> 27
A36: 4 | B36: Jumlah surat suara yang tidak digunakan/tidak terpakai, termasuk sisa surat suara cadangan | E36: =E33-(E34+E35) -> 64 | F36: =F33-(F34+F35) -> 45 | G36: =G33-(G34+G35) -> 68 | H36: =H33-(H34+H35) -> 63 | I36: =I33-(I34+I35) -> 65 | J36: =J33-(J34+J35) -> 70 | K36: =K33-(K34+K35) -> 62 | L36: =L33-(L34+L35) -> 67 | ... W36: =W33-(W34+W35) -> 15 | X36: =SUM(E36:W36) -> 1107
A38: III | B38: DATA PEMILIH DISABILITAS
B39: Jumlah seluruh Pemilih disabilitas yang menggunakan hak pilih | D39: LK | E39: 0 | F39: 0 | G39: 1 | H39: 0 | I39: 0 | J39: 0 | K39: 0 | L39: 0 | M39: 0 | N39: 0 | O39: 0 | P39: 0 | Q39: 0 | R39: 0 | S39: 0 | T39: 0 | U39: 0 | V39: 0 | W39: 0 | X39: =SUM(E39:W39) -> 1
D40: PR | E40: 0 | F40: 0 | G40: 2 | H40: 0 | I40: 0 | J40: 0 | K40: 0 | L40: 0 | M40: 0 | N40: 0 | O40: 0 | P40: 1 | Q40: 1 | R40: 0 | S40: 0 | T40: 0 | U40: 0 | V40: 0 | W40: 0 | X40: =SUM(E40:W40) -> 4
D41: JML | E41: =SUM(E39:E40) -> 0 | F41: =SUM(F39:F40) -> 0 | G41: =SUM(G39:G40) -> 3 | H41: =SUM(H39:H40) -> 0 | I41: =SUM(I39:I40) -> 0 | J41: =SUM(J39:J40) -> 0 | K41: =SUM(K39:K40) -> 0 | L41: =SUM(L39:L40) -> 0 | ... W41: =SUM(W39:W40) -> 0 | X41: =SUM(E41:W41) -> 5
A43: IV | B43: DATA RINCIAN PEROLEHAN SUARA PASANGAN CALON BUPATI DAN WAKIL BUPATI
A44: NOMOR DAN NAMA CALON
A45: A.1 | B45: 1. | C45: Partai Kebangkitan Bangsa | E45: 11 | F45: 12 | G45: 7 | H45: 3 | I45: 8 | J45: 7 | K45: 15 | L45: 2 | M45: 2 | N45: 1 | O45: 6 | P45: 7 | Q45: 10 | R45: 8 | S45: 1 | T45: 11 | U45: 3 | V45: 0 | W45: 0 | X45: =SUM(E45:W45) -> 114
A46: A.2 | C46: 1. MUKHTAR NABALI MUFAUWIQ | E46: 4 | F46: 3 | G46: 2 | H46: 4 | I46: 25 | J46: 3 | K46: 3 | L46: 6 | M46: 2 | N46: 3 | O46: 6 | P46: 12 | Q46: 7 | R46: 7 | S46: 1 | T46: 11 | U46: 8 | V46: 2 | W46: 0 | X46: =SUM(E46:W46) -> 109
C47: 2. H. SUSIYANTO | E47: 65 | F47: 85 | G47: 79 | H47: 58 | I47: 58 | J47: 40 | K47: 75 | L47: 65 | M47: 47 | N47: 130 | O47: 25 | P47: 38 | Q47: 41 | R47: 28 | S47: 19 | T47: 3 | U47: 3 | V47: 0 | W47: 0 | X47: =SUM(E47:W47) -> 859
C48: 3. DUWI HASTRENI, S.H. | E48: 9 | F48: 1 | G48: 4 | H48: 5 | I48: 8 | J48: 4 | K48: 2 | L48: 11 | M48: 0 | N48: 1 | O48: 0 | P48: 3 | Q48: 0 | R48: 10 | S48: 0 | T48: 1 | U48: 0 | V48: 0 | W48: 0 | X48: =SUM(E48:W48) -> 59
C49: 4. MIFTAKHODIN | E49: 0 | F49: 1 | G49: 0 | H49: 0 | I49: 0 | J49: 0 | K49: 1 | L49: 1 | M49: 0 | N49: 0 | O49: 0 | P49: 0 | Q49: 0 | R49: 0 | S49: 0 | T49: 0 | U49: 0 | V49: 0 | W49: 0 | X49: =SUM(E49:W49) -> 3
C50: 5. SITI MUSTIKAH | E50: 0 | F50: 0 | G50: 0 | H50: 0 | I50: 0 | J50: 0 | K50: 0 | L50: 0 | M50: 1 | N50: 0 | O50: 0 | P50: 1 | Q50: 0 | R50: 1 | S50: 0 | T50: 0 | U50: 1 | V50: 0 | W50: 0 | X50: =SUM(E50:W50) -> 4
C51: 6. ABDUL GHOFUR | E51: 1 | F51: 0 | G51: 0 | H51: 1 | I51: 1 | J51: 0 | K51: 0 | L51: 1 | M51: 0 | N51: 0 | O51: 0 | P51: 0 | Q51: 1 | R51: 0 | S51: 0 | T51: 1 | U51: 1 | V51: 0 | W51: 0 | X51: =SUM(E51:W51) -> 7
...

Sheet GLAGAHAGUNG
C2: Kecamatan | D2: PURWOHARJO
C3: Kabupaten | D3: BANYUWANGI
C4: Provinsi | D4: JAWA TIMUR
C9: Kelurahan | D9: GLAGAHAGUNG
A12: I | B12: DATA PEMILIH DAN PENGGUNAAN HAK PILIH | AA12: JUMLAH AKHIR
A13: A | B13: DATA PEMILIH | E13: TPS 001 | F13: TPS 002 | G13: TPS 003 | H13: TPS 004 | I13: TPS 005 | J13: TPS 006 | K13: TPS 007 | L13: TPS 008 | M13: TPS 009 | N13: TPS 010 | O13: TPS 011 | P13: TPS 012 | Q13: TPS 013 | R13: TPS 014 | S13: TPS 015 | T13: TPS 016 | U13: TPS 017 | V13: TPS 018 | W13: TPS 019 | X13: TPS 020 | Y13: TPS 021 | Z13: TPS 022
B14: Jumlah Pemilih dalam Daftar Pemilih Tetap (DPT) | D14: LK | E14: 142 | F14: 147 | G14: 140 | H14: 141 | I14: 141 | J14: 142 | K14: 122 | L14: 153 | M14: 154 | N14: 113 | O14: 131 | P14: 136 | Q14: 146 | R14: 138 | S14: 147 | T14: 127 | U14: 136 | V14: 142 | W14: 132 | X14: 133 | Y14: 134 | Z14: 148 | AA14: =SUM(E14:Z14) -> 3045
D15: PR | E15: 153 | F15: 130 | G15: 144 | H15: 149 | I15: 141 | J15: 129 | K15: 122 | L15: 125 | M15: 139 | N15: 115 | O15: 144 | P15: 150 | Q15: 135 | R15: 135 | S15: 148 | T15: 117 | U15: 142 | V15: 138 | W15: 141 | X15: 130 | Y15: 148 | Z15: 147 | AA15: =SUM(E15:Z15) -> 3022
D16: JML | E16: =SUM(E14:E15) -> 295 | F16: =SUM(F14:F15) -> 277 | G16: =SUM(G14:G15) -> 284 | H16: =SUM(H14:H15) -> 290 | I16: =SUM(I14:I15) -> 282 | J16: =SUM(J14:J15) -> 271 | K16: =SUM(K14:K15) -> 244 | L16: =SUM(L14:L15) -> 278 | ... Z16: =SUM(Z14:Z15) -> 295 | AA16: =SUM(E16:Z16) -> 6067
A18: B | B18: PENGGUNA HAK PILIH
B19: 1. | C19: Jumlah pengguna hak pilih dalam Daftar Pemilih Tetap (DPT) | D19: LK | E19: 102 | F19: 119 | G19: 113 | H19: 114 | I19: 112 | J19: 109 | K19: 100 | L19: 100 | M19: 118 | N19: 93 | O19: 111 | P19: 104 | Q19: 111 | R19: 111 | S19: 110 | T19: 102 | U19: 107 | V19: 118 | W19: 99 | X19: 100 | Y19: 106 | Z19: 129 | AA19: =SUM(E19:Z19) -> 2388
D20: PR | E20: 116 | F20: 106 | G20: 117 | H20: 115 | I20: 125 | J20: 99 | K20: 101 | L20: 96 | M20: 109 | N20: 101 | O20: 132 | P20: 134 | Q20: 120 | R20: 104 | S20: 107 | T20: 107 | U20: 121 | V20: 125 | W20: 111 | X20: 103 | Y20: 129 | Z20: 129 | AA20: =SUM(E20:Z20) -> 2507
D21: JML | E21: =SUM(E19:E20) -> 218 | F21: =SUM(F19:F20) -> 225 | G21: =SUM(G19:G20) -> 230 | H21: =SUM(H19:H20) -> 229 | I21: =SUM(I19:I20) -> 237 | J21: =SUM(J19:J20) -> 208 | K21: =SUM(K19:K20) -> 201 | L21: =SUM(L19:L20) -> 196 | ... Z21: =SUM(Z19:Z20) -> 258 | AA21: =SUM(E21:Z21) -> 4895
B22: 2. | C22: Jumlah pengguna hak pilih dalam Daftar Pemilih Tambahan (DPTb) | D22: LK | E22: 0 | F22: 0 | G22: 0 | H22: 0 | I22: 0 | J22: 1 | K22: 0 | L22: 1 | M22: 1 | N22: 0 | O22: 0 | P22: 0 | Q22: 0 | R22: 0 | S22: 0 | T22: 1 | U22: 0 | V22: 0 | W22: 1 | X22: 0 | Y22: 0 | Z22: 0 | AA22: =SUM(E22:Z22) -> 5
D23: PR | E23: 0 | F23: 0 | G23: 0 | H23: 0 | I23: 0 | J23: 1 | K23: 0 | L23: 0 | M23: 0 | N23: 0 | O23: 0 | P23: 0 | Q23: 1 | R23: 0 | S23: 0 | T23: 0 | U23: 0 | V23: 0 | W23: 0 | X23: 0 | Y23: 0 | Z23: 0 | AA23: =SUM(E23:Z23) -> 2
D24: JML | E24: =SUM(E22:E23) -> 0 | F24: =SUM(F22:F23) -> 0 | G24: =SUM(G22:G23) -> 0 | H24: =SUM(H22:H23) -> 0 | I24: =SUM(I22:I23) -> 0 | J24: =SUM(J22:J23) -> 2 | K24: =SUM(K22:K23) -> 0 | L24: =SUM(L22:L23) -> 1 | ... Z24: =SUM(Z22:Z23) -> 0 | AA24: =SUM(E24:Z24) -> 7
B25: 3. | C25: Jumlah pengguna hak pilih dalam Daftar Pemilih Khusus (DPK) | D25: LK | E25: 0 | F25: 1 | G25: 0 | H25: 0 | I25: 1 | J25: 1 | K25: 1 | L25: 1 | M25: 2 | N25: 1 | O25: 0 | P25: 0 | Q25: 0 | R25: 3 | S25: 0 | T25: 1 | U25: 2 | V25: 0 | W25: 0 | X25: 2 | Y25: 1 | Z25: 0 | AA25: =SUM(E25:Z25) -> 17
D26: PR | E26: 1 | F26: 1 | G26: 3 | H26: 1 | I26: 2 | J26: 1 | K26: 1 | L26: 2 | M26: 2 | N26: 4 | O26: 0 | P26: 0 | Q26: 0 | R26: 1 | S26: 2 | T26: 1 | U26: 0 | V26: 0 | W26: 0 | X26: 1 | Y26: 1 | Z26: 0 | AA26: =SUM(E26:Z26) -> 24
D27: JML | E27: =SUM(E25:E26) -> 1 | F27: =SUM(F25:F26) -> 2 | G27: =SUM(G25:G26) -> 3 | H27: =SUM(H25:H26) -> 1 | I27: =SUM(I25:I26) -> 3 | J27: =SUM(J25:J26) -> 2 | K27: =SUM(K25:K26) -> 2 | L27: =SUM(L25:L26) -> 3 | ... Z27: =SUM(Z25:Z26) -> 0 | AA27: =SUM(E27:Z27) -> 41
B28: 4. | C28: Jumlah Pengguna Hak Pilih (B.1+B.2+B.3) | D28: LK | E28: =SUM(E19,E22,E25) -> 102 | F28: =SUM(F19,F22,F25) -> 120 | G28: =SUM(G19,G22,G25) -> 113 | H28: =SUM(H19,H22,H25) -> 114 | I28: =SUM(I19,I22,I25) -> 113 | J28: =SUM(J19,J22,J25) -> 111 | K28: =SUM(K19,K22,K25) -> 101 | L28: =SUM(L19,L22,L25) -> 102 | ... Z28: =SUM(Z19,Z22,Z25) -> 129 | AA28: =SUM(E28:Z28) -> 2410
D29: PR | E29: =SUM(E20,E23,E26) -> 117 | F29: =SUM(F20,F23,F26) -> 107 | G29: =SUM(G20,G23,G26) -> 120 | H29: =SUM(H20,H23,H26) -> 116 | I29: =SUM(I20,I23,I26) -> 127 | J29: =SUM(J20,J23,J26) -> 101 | K29: =SUM(K20,K23,K26) -> 102 | L29: =SUM(L20,L23,L26) -> 98 | ... Z29: =SUM(Z20,Z23,Z26) -> 129 | AA29: =SUM(E29:Z29) -> 2533
D30: JML | E30: =SUM(E28:E29) -> 219 | F30: =SUM(F28:F29) -> 227 | G30: =SUM(G28:G29) -> 233 | H30: =SUM(H28:H29) -> 230 | I30: =SUM(I28:I29) -> 240 | J30: =SUM(J28:J29) -> 212 | K30: =SUM(K28:K29) -> 203 | L30: =SUM(L28:L29) -> 200 | ... Z30: =SUM(Z28:Z29) -> 258 | AA30: =SUM(E30:Z30) -> 4943
A32: II | B32: DATA PENGGUNAAN SURAT SUARA
A33: 1 | B33: Jumlah surat suara yang diterima, termasuk surat suara cadangan 2,5% dari DPT | E33: 301 | F33: 283 | G33: 290 | H33: 296 | I33: 288 | J33: 277 | K33: 249 | L33: 294 | M33: 299 | N33: 253 | O33: 281 | P33: 292 | Q33: 298 | R33: 280 | S33: 301 | T33: 250 | U33: 284 | V33: 286 | W33: 279 | X33: 269 | Y33: 288 | Z33: 301 | AA33: =SUM(E33:Z33) -> 6239
A34: 2 | B34: Jumlah surat suara yang digunakan | E34: 219 | F34: 227 | G34: 233 | H34: 230 | I34: 240 | J34: 212 | K34: 203 | L34: 200 | M34: 232 | N34: 199 | O34: 243 | P34: 238 | Q34: 232 | R34: 219 | S34: 219 | T34: 212 | U34: 230 | V34: 243 | W34: 211 | X34: 206 | Y34: 237 | Z34: 258 | AA34: =SUM(E34:Z34) -> 4943
A35: 3 | B35: Jumlah surat suara dikembalikan oleh pemilih (karena rusak atau keliru coblos) | E35: 0 | F35: 2 | G35: 0 | H35: 0 | I35: 2 | J35: 0 | K35: 0 | L35: 0 | M35: 2 | N35: 0 | O35: 0 | P35: 0 | Q35: 2 | R35: 1 | S35: 0 | T35: 0 | U35: 1 | V35: 1 | W35: 0 | X35: 2 | Y35: 0 | Z35: 0 | AA35: =SUM(E35:Z35) -> 13
A36: 4 | B36: Jumlah surat suara yang tidak digunakan/tidak terpakai, termasuk sisa surat suara cadangan | E36: =E33-(E34+E35) -> 82 | F36: =F33-(F34+F35) -> 54 | G36: =G33-(G34+G35) -> 57 | H36: =H33-(H34+H35) -> 66 | I36: =I33-(I34+I35) -> 46 | J36: =J33-(J34+J35) -> 65 | K36: =K33-(K34+K35) -> 46 | L36: =L33-(L34+L35) -> 94 | ... Z36: =Z33-(Z34+Z35) -> 43 | AA36: =SUM(E36:Z36) -> 1283
A38: III | B38: DATA PEMILIH DISABILITAS
B39: Jumlah seluruh Pemilih disabilitas yang menggunakan hak pilih | D39: LK | E39: 1 | F39: 0 | G39: 0 | H39: 0 | I39: 0 | J39: 0 | K39: 0 | L39: 0 | M39: 0 | N39: 0 | O39: 0 | P39: 0 | Q39: 0 | R39: 0 | S39: 2 | T39: 0 | U39: 0 | V39: 0 | W39: 0 | X39: 0 | Y39: 0 | Z39: 0 | AA39: =SUM(E39:Z39) -> 3
D40: PR | E40: 0 | F40: 0 | G40: 0 | H40: 0 | I40: 0 | J40: 0 | K40: 0 | L40: 0 | M40: 0 | N40: 0 | O40: 0 | P40: 0 | Q40: 0 | R40: 0 | S40: 1 | T40: 0 | U40: 1 | V40: 0 | W40: 0 | X40: 0 | Y40: 0 | Z40: 0 | AA40: =SUM(E40:Z40) -> 2
D41: JML | E41: =SUM(E39:E40) -> 1 | F41: =SUM(F39:F40) -> 0 | G41: =SUM(G39:G40) -> 0 | H41: =SUM(H39:H40) -> 0 | I41: =SUM(I39:I40) -> 0 | J41: =SUM(J39:J40) -> 0 | K41: =SUM(K39:K40) -> 0 | L41: =SUM(L39:L40) -> 0 | ... Z41: =SUM(Z39:Z40) -> 0 | AA41: =SUM(E41:Z41) -> 5
A43: IV | B43: DATA RINCIAN PEROLEHAN SUARA PASANGAN CALON BUPATI DAN WAKIL BUPATI
A44: NOMOR DAN NAMA CALON
A45: A.1 | B45: 1. | C45: Partai Kebangkitan Bangsa | E45: 2 | F45: 5 | G45: 6 | H45: 5 | I45: 6 | J45: 9 | K45: 3 | L45: 2 | M45: 4 | N45: 2 | O45: 2 | P45: 1 | Q45: 5 | R45: 4 | S45: 4 | T45: 3 | U45: 2 | V45: 5 | W45: 2 | X45: 1 | Y45: 3 | Z45: 7 | AA45: =SUM(E45:Z45) -> 83
A46: A.2 | C46: 1. MUKHTAR NABALI MUFAUWIQ | E46: 6 | F46: 20 | G46: 6 | H46: 3 | I46: 7 | J46: 11 | K46: 6 | L46: 1 | M46: 3 | N46: 3 | O46: 1 | P46: 1 | Q46: 0 | R46: 3 | S46: 0 | T46: 0 | U46: 4 | V46: 1 | W46: 2 | X46: 0 | Y46: 1 | Z46: 16 | AA46: =SUM(E46:Z46) -> 95
C47: 2. H. SUSIYANTO | E47: 43 | F47: 35 | G47: 25 | H47: 11 | I47: 42 | J47: 23 | K47: 18 | L47: 0 | M47: 22 | N47: 0 | O47: 3 | P47: 2 | Q47: 9 | R47: 11 | S47: 21 | T47: 9 | U47: 19 | V47: 5 | W47: 12 | X47: 11 | Y47: 14 | Z47: 10 | AA47: =SUM(E47:Z47) -> 345
C48: 3. DUWI HASTRENI, S.H. | E48: 0 | F48: 1 | G48: 0 | H48: 0 | I48: 1 | J48: 0 | K48: 0 | L48: 0 | M48: 0 | N48: 0 | O48: 0 | P48: 1 | Q48: 1 | R48: 1 | S48: 0 | T48: 0 | U48: 0 | V48: 0 | W48: 0 | X48: 0 | Y48: 0 | Z48: 0 | AA48: =SUM(E48:Z48) -> 5
C49: 4. MIFTAKHODIN | E49: 0 | F49: 0 | G49: 0 | H49: 4 | I49: 0 | J49: 0 | K49: 0 | L49: 0 | M49: 1 | N49: 0 | O49: 0 | P49: 0 | Q49: 0 | R49: 0 | S49: 0 | T49: 0 | U49: 0 | V49: 0 | W49: 0 | X49: 0 | Y49: 0 | Z49: 0 | AA49: =SUM(E49:Z49) -> 5
C50: 5. SITI MUSTIKAH | E50: 0 | F50: 0 | G50: 0 | H50: 0 | I50: 0 | J50: 0 | K50: 0 | L50: 0 | M50: 0 | N50: 0 | O50: 0 | P50: 0 | Q50: 0 | R50: 0 | S50: 0 | T50: 0 | U50: 0 | V50: 0 | W50: 0 | X50: 0 | Y50: 0 | Z50: 0 | AA50: =SUM(E50:Z50) -> 0
C51: 6. ABDUL GHOFUR | E51: 0 | F51: 0 | G51: 0 | H51: 0 | I51: 0 | J51: 0 | K51: 0 | L51: 0 | M51: 0 | N51: 0 | O51: 0 | P51: 0 | Q51: 0 | R51: 0 | S51: 0 | T51: 0 | U51: 1 | V51: 0 | W51: 0 | X51: 1 | Y51: 0 | Z51: 0 | AA51: =SUM(E51:Z51) -> 2
...

Sheet SIDOREJO
C2: Kecamatan | D2: PURWOHARJO
C3: Kabupaten | D3: BANYUWANGI
C4: Provinsi | D4: JAWA TIMUR
C9: Kelurahan | D9: SIDOREJO
A12: I | B12: DATA PEMILIH DAN PENGGUNAAN HAK PILIH | AA12: JUMLAH AKHIR
A13: A | B13: DATA PEMILIH | E13: TPS 001 | F13: TPS 002 | G13: TPS 003 | H13: TPS 004 | I13: TPS 005 | J13: TPS 006 | K13: TPS 007 | L13: TPS 008 | M13: TPS 009 | N13: TPS 010 | O13: TPS 011 | P13: TPS 012 | Q13: TPS 013 | R13: TPS 014 | S13: TPS 015 | T13: TPS 016 | U13: TPS 017 | V13: TPS 018 | W13: TPS 019 | X13: TPS 020 | Y13: TPS 021 | Z13: TPS 022
B14: Jumlah Pemilih dalam Daftar Pemilih Tetap (DPT) | D14: LK | E14: 131 | F14: 134 | G14: 136 | H14: 143 | I14: 134 | J14: 129 | K14: 142 | L14: 141 | M14: 138 | N14: 150 | O14: 141 | P14: 147 | Q14: 156 | R14: 137 | S14: 123 | T14: 139 | U14: 132 | V14: 132 | W14: 133 | X14: 137 | Y14: 125 | Z14: 139 | AA14: =SUM(E14:Z14) -> 3019
D15: PR | E15: 144 | F15: 132 | G15: 137 | H15: 144 | I15: 136 | J15: 145 | K15: 134 | L15: 136 | M15: 148 | N15: 145 | O15: 140 | P15: 146 | Q15: 141 | R15: 124 | S15: 129 | T15: 125 | U15: 133 | V15: 137 | W15: 133 | X15: 137 | Y15: 133 | Z15: 133 | AA15: =SUM(E15:Z15) -> 3012
D16: JML | E16: =SUM(E14:E15) -> 275 | F16: =SUM(F14:F15) -> 266 | G16: =SUM(G14:G15) -> 273 | H16: =SUM(H14:H15) -> 287 | I16: =SUM(I14:I15) -> 270 | J16: =SUM(J14:J15) -> 274 | K16: =SUM(K14:K15) -> 276 | L16: =SUM(L14:L15) -> 277 | ... Z16: =SUM(Z14:Z15) -> 272 | AA16: =SUM(E16:Z16) -> 6031
A18: B | B18: PENGGUNA HAK PILIH
B19: 1. | C19: Jumlah pengguna hak pilih dalam Daftar Pemilih Tetap (DPT) | D19: LK | E19: 102 | F19: 99 | G19: 104 | H19: 112 | I19: 106 | J19: 100 | K19: 106 | L19: 113 | M19: 101 | N19: 111 | O19: 108 | P19: 122 | Q19: 121 | R19: 111 | S19: 102 | T19: 110 | U19: 103 | V19: 94 | W19: 110 | X19: 100 | Y19: 99 | Z19: 108 | AA19: =SUM(E19:Z19) -> 2342
D20: PR | E20: 123 | F20: 109 | G20: 107 | H20: 111 | I20: 113 | J20: 117 | K20: 113 | L20: 108 | M20: 125 | N20: 113 | O20: 113 | P20: 118 | Q20: 110 | R20: 105 | S20: 115 | T20: 104 | U20: 95 | V20: 105 | W20: 105 | X20: 107 | Y20: 102 | Z20: 109 | AA20: =SUM(E20:Z20) -> 2427
D21: JML | E21: =SUM(E19:E20) -> 225 | F21: =SUM(F19:F20) -> 208 | G21: =SUM(G19:G20) -> 211 | H21: =SUM(H19:H20) -> 223 | I21: =SUM(I19:I20) -> 219 | J21: =SUM(J19:J20) -> 217 | K21: =SUM(K19:K20) -> 219 | L21: =SUM(L19:L20) -> 221 | ... Z21: =SUM(Z19:Z20) -> 217 | AA21: =SUM(E21:Z21) -> 4769
B22: 2. | C22: Jumlah pengguna hak pilih dalam Daftar Pemilih Tambahan (DPTb) | D22: LK | E22: 1 | F22: 0 | G22: 0 | H22: 0 | I22: 0 | J22: 0 | K22: 0 | L22: 0 | M22: 0 | N22: 0 | O22: 0 | P22: 0 | Q22: 0 | R22: 0 | S22: 0 | T22: 0 | U22: 0 | V22: 0 | W22: 0 | X22: 0 | Y22: 0 | Z22: 0 | AA22: =SUM(E22:Z22) -> 1
D23: PR | E23: 0 | F23: 0 | G23: 0 | H23: 0 | I23: 0 | J23: 0 | K23: 0 | L23: 0 | M23: 0 | N23: 0 | O23: 0 | P23: 0 | Q23: 0 | R23: 0 | S23: 0 | T23: 0 | U23: 1 | V23: 0 | W23: 0 | X23: 0 | Y23: 0 | Z23: 0 | AA23: =SUM(E23:Z23) -> 1
D24: JML | E24: =SUM(E22:E23) -> 1 | F24: =SUM(F22:F23) -> 0 | G24: =SUM(G22:G23) -> 0 | H24: =SUM(H22:H23) -> 0 | I24: =SUM(I22:I23) -> 0 | J24: =SUM(J22:J23) -> 0 | K24: =SUM(K22:K23) -> 0 | L24: =SUM(L22:L23) -> 0 | ... Z24: =SUM(Z22:Z23) -> 0 | AA24: =SUM(E24:Z24) -> 2
B25: 3. | C25: Jumlah pengguna hak pilih dalam Daftar Pemilih Khusus (DPK) | D25: LK | E25: 2 | F25: 0 | G25: 3 | H25: 0 | I25: 1 | J25: 0 | K25: 1 | L25: 1 | M25: 0 | N25: 0 | O25: 0 | P25: 0 | Q25: 0 | R25: 0 | S25: 2 | T25: 0 | U25: 1 | V25: 1 | W25: 0 | X25: 2 | Y25: 1 | Z25: 1 | AA25: =SUM(E25:Z25) -> 16
D26: PR | E26: 2 | F26: 0 | G26: 1 | H26: 0 | I26: 3 | J26: 2 | K26: 2 | L26: 1 | M26: 0 | N26: 0 | O26: 6 | P26: 2 | Q26: 0 | R26: 1 | S26: 0 | T26: 0 | U26: 2 | V26: 0 | W26: 0 | X26: 2 | Y26: 1 | Z26: 2 | AA26: =SUM(E26:Z26) -> 27
D27: JML | E27: =SUM(E25:E26) -> 4 | F27: =SUM(F25:F26) -> 0 | G27: =SUM(G25:G26) -> 4 | H27: =SUM(H25:H26) -> 0 | I27: =SUM(I25:I26) -> 4 | J27: =SUM(J25:J26) -> 2 | K27: =SUM(K25:K26) -> 3 | L27: =SUM(L25:L26) -> 2 | ... Z27: =SUM(Z25:Z26) -> 3 | AA27: =SUM(E27:Z27) -> 43
B28: 4. | C28: Jumlah Pengguna Hak Pilih (B.1+B.2+B.3) | D28: LK | E28: =SUM(E19,E22,E25) -> 105 | F28: =SUM(F19,F22,F25) -> 99 | G28: =SUM(G19,G22,G25) -> 107 | H28: =SUM(H19,H22,H25) -> 112 | I28: =SUM(I19,I22,I25) -> 107 | J28: =SUM(J19,J22,J25) -> 100 | K28: =SUM(K19,K22,K25) -> 107 | L28: =SUM(L19,L22,L25) -> 114 | ... Z28: =SUM(Z19,Z22,Z25) -> 109 | AA28: =SUM(E28:Z28) -> 2359
D29: PR | E29: =SUM(E20,E23,E26) -> 125 | F29: =SUM(F20,F23,F26) -> 109 | G29: =SUM(G20,G23,G26) -> 108 | H29: =SUM(H20,H23,H26) -> 111 | I29: =SUM(I20,I23,I26) -> 116 | J29: =SUM(J20,J23,J26) -> 119 | K29: =SUM(K20,K23,K26) -> 115 | L29: =SUM(L20,L23,L26) -> 109 | ... Z29: =SUM(Z20,Z23,Z26) -> 111 | AA29: =SUM(E29:Z29) -> 2455
D30: JML | E30: =SUM(E28:E29) -> 230 | F30: =SUM(F28:F29) -> 208 | G30: =SUM(G28:G29) -> 215 | H30: =SUM(H28:H29) -> 223 | I30: =SUM(I28:I29) -> 223 | J30: =SUM(J28:J29) -> 219 | K30: =SUM(K28:K29) -> 222 | L30: =SUM(L28:L29) -> 223 | ... Z30: =SUM(Z28:Z29) -> 220 | AA30: =SUM(E30:Z30) -> 4814
A32: II | B32: DATA PENGGUNAAN SURAT SUARA
A33: 1 | B33: Jumlah surat suara yang diterima, termasuk surat suara cadangan 2,5% dari DPT | E33: 280 | F33: 272 | G33: 279 | H33: 293 | I33: 276 | J33: 280 | K33: 282 | L33: 283 | M33: 292 | N33: 300 | O33: 287 | P33: 299 | Q33: 303 | R33: 266 | S33: 258 | T33: 270 | U33: 271 | V33: 275 | W33: 272 | X33: 280 | Y33: 264 | Z33: 278 | AA33: =SUM(E33:Z33) -> 6160
A34: 2 | B34: Jumlah surat suara yang digunakan | E34: 230 | F34: 208 | G34: 215 | H34: 223 | I34: 223 | J34: 219 | K34: 222 | L34: 223 | M34: 226 | N34: 224 | O34: 227 | P34: 242 | Q34: 231 | R34: 217 | S34: 219 | T34: 214 | U34: 202 | V34: 200 | W34: 215 | X34: 211 | Y34: 203 | Z34: 220 | AA34: =SUM(E34:Z34) -> 4814
A35: 3 | B35: Jumlah surat suara dikembalikan oleh pemilih (karena rusak atau keliru coblos) | E35: 1 | F35: 0 | G35: 1 | H35: 0 | I35: 0 | J35: 0 | K35: 3 | L35: 0 | M35: 0 | N35: 0 | O35: 0 | P35: 1 | Q35: 2 | R35: 0 | S35: 0 | T35: 0 | U35: 0 | V35: 0 | W35: 0 | X35: 0 | Y35: 0 | Z35: 0 | AA35: =SUM(E35:Z35) -> 8
A36: 4 | B36: Jumlah surat suara yang tidak digunakan/tidak terpakai, termasuk sisa surat suara cadangan | E36: =E33-(E34+E35) -> 49 | F36: =F33-(F34+F35) -> 64 | G36: =G33-(G34+G35) -> 63 | H36: =H33-(H34+H35) -> 70 | I36: =I33-(I34+I35) -> 53 | J36: =J33-(J34+J35) -> 61 | K36: =K33-(K34+K35) -> 57 | L36: =L33-(L34+L35) -> 60 | ... Z36: =Z33-(Z34+Z35) -> 58 | AA36: =SUM(E36:Z36) -> 1338
A38: III | B38: DATA PEMILIH DISABILITAS
B39: Jumlah seluruh Pemilih disabilitas yang menggunakan hak pilih | D39: LK | E39: 0 | F39: 0 | G39: 0 | H39: 1 | I39: 0 | J39: 0 | K39: 0 | L39: 0 | M39: 0 | N39: 0 | O39: 0 | P39: 0 | Q39: 0 | R39: 0 | S39: 0 | T39: 0 | U39: 0 | V39: 0 | W39: 0 | X39: 0 | Y39: 0 | Z39: 0 | AA39: =SUM(E39:Z39) -> 1
D40: PR | E40: 0 | F40: 0 | G40: 0 | H40: 0 | I40: 0 | J40: 0 | K40: 0 | L40: 0 | M40: 0 | N40: 0 | O40: 0 | P40: 0 | Q40: 0 | R40: 0 | S40: 0 | T40: 0 | U40: 0 | V40: 0 | W40: 0 | X40: 0 | Y40: 0 | Z40: 0 | AA40: =SUM(E40:Z40) -> 0
D41: JML | E41: =SUM(E39:E40) -> 0 | F41: =SUM(F39:F40) -> 0 | G41: =SUM(G39:G40) -> 0 | H41: =SUM(H39:H40) -> 1 | I41: =SUM(I39:I40) -> 0 | J41: =SUM(J39:J40) -> 0 | K41: =SUM(K39:K40) -> 0 | L41: =SUM(L39:L40) -> 0 | ... Z41: =SUM(Z39:Z40) -> 0 | AA41: =SUM(E41:Z41) -> 1
A43: IV | B43: DATA RINCIAN PEROLEHAN SUARA PASANGAN CALON BUPATI DAN WAKIL BUPATI
A44: NOMOR DAN NAMA CALON
A45: A.1 | B45: 1. | C45: Partai Kebangkitan Bangsa | E45: 15 | F45: 6 | G45: 8 | H45: 10 | I45: 13 | J45: 8 | K45: 9 | L45: 3 | M45: 4 | N45: 5 | O45: 6 | P45: 12 | Q45: 3 | R45: 4 | S45: 1 | T45: 12 | U45: 7 | V45: 11 | W45: 1 | X45: 4 | Y45: 4 | Z45: 9 | AA45: =SUM(E45:Z45) -> 155
A46: A.2 | C46: 1. MUKHTAR NABALI MUFAUWIQ | E46: 15 | F46: 8 | G46: 0 | H46: 1 | I46: 7 | J46: 2 | K46: 3 | L46: 3 | M46: 4 | N46: 1 | O46: 3 | P46: 2 | Q46: 7 | R46: 7 | S46: 9 | T46: 1 | U46: 1 | V46: 1 | W46: 0 | X46: 1 | Y46: 2 | Z46: 1 | AA46: =SUM(E46:Z46) -> 79
C47: 2. H. SUSIYANTO | E47: 125 | F47: 86 | G47: 96 | H47: 127 | I47: 132 | J47: 127 | K47: 88 | L47: 54 | M47: 61 | N47: 84 | O47: 45 | P47: 67 | Q47: 47 | R47: 29 | S47: 31 | T47: 89 | U47: 78 | V47: 72 | W47: 45 | X47: 35 | Y47: 67 | Z47: 72 | AA47: =SUM(E47:Z47) -> 1657
C48: 3. DUWI HASTRENI, S.H. | E48: 5 | F48: 2 | G48: 1 | H48: 1 | I48: 1 | J48: 1 | K48: 5 | L48: 2 | M48: 0 | N48: 2 | O48: 2 | P48: 0 | Q48: 0 | R48: 0 | S48: 2 | T48: 2 | U48: 2 | V48: 1 | W48: 2 | X48: 3 | Y48: 1 | Z48: 0 | AA48: =SUM(E48:Z48) -> 35
C49: 4. MIFTAKHODIN | E49: 0 | F49: 0 | G49: 0 | H49: 0 | I49: 0 | J49: 0 | K49: 0 | L49: 0 | M49: 1 | N49: 0 | O49: 0 | P49: 0 | Q49: 0 | R49: 0 | S49: 0 | T49: 0 | U49: 0 | V49: 0 | W49: 0 | X49: 0 | Y49: 0 | Z49: 0 | AA49: =SUM(E49:Z49) -> 1
C50: 5. SITI MUSTIKAH | E50: 0 | F50: 0 | G50: 0 | H50: 1 | I50: 0 | J50: 0 | K50: 1 | L50: 1 | M50: 0 | N50: 0 | O50: 0 | P50: 1 | Q50: 0 | R50: 0 | S50: 0 | T50: 0 | U50: 2 | V50: 0 | W50: 2 | X50: 0 | Y50: 0 | Z50: 0 | AA50: =SUM(E50:Z50) -> 8
C51: 6. ABDUL GHOFUR | E51: 1 | F51: 0 | G51: 0 | H51: 0 | I51: 0 | J51: 0 | K51: 1 | L51: 0 | M51: 0 | N51: 0 | O51: 0 | P51: 0 | Q51: 0 | R51: 0 | S51: 0 | T51: 0 | U51: 0 | V51: 1 | W51: 0 | X51: 0 | Y51: 0 | Z51: 0 | AA51: =SUM(E51:Z51) -> 3
...

Sheet PURWOHARJO
C2: Kecamatan | D2: PURWOHARJO
C3: Kabupaten | D3: BANYUWANGI
C4: Provinsi | D4: JAWA TIMUR
C9: Kelurahan | D9: PURWOHARJO
A12: I | B12: DATA PEMILIH DAN PENGGUNAAN HAK PILIH | AK12: JUMLAH AKHIR
A13: A | B13: DATA PEMILIH | E13: TPS 001 | F13: TPS 002 | G13: TPS 003 | H13: TPS 004 | I13: TPS 005 | J13: TPS 006 | K13: TPS 007 | L13: TPS 008 | M13: TPS 009 | N13: TPS 010 | O13: TPS 011 | P13: TPS 012 | Q13: TPS 013 | R13: TPS 014 | S13: TPS 015 | T13: TPS 016 | U13: TPS 017 | V13: TPS 018 | W13: TPS 019 | X13: TPS 020 | Y13: TPS 021 | Z13: TPS 022 | AA13: TPS 023 | AB13: TPS 024 | AC13: TPS 025 | AD13: TPS 026 | AE13: TPS 027 | AF13: TPS 028 | AG13: TPS 029 | AH13: TPS 030 | AI13: TPS 031 | AJ13: TPS 032
B14: Jumlah Pemilih dalam Daftar Pemilih Tetap (DPT) | D14: LK | E14: 128 | F14: 130 | G14: 145 | H14: 137 | I14: 140 | J14: 140 | K14: 126 | L14: 133 | M14: 131 | N14: 137 | O14: 140 | P14: 134 | Q14: 129 | R14: 129 | S14: 128 | T14: 130 | U14: 130 | V14: 134 | W14: 128 | X14: 134 | Y14: 133 | Z14: 127 | AA14: 137 | AB14: 130 | AC14: 142 | AD14: 133 | AE14: 138 | AF14: 135 | AG14: 125 | AH14: 140 | AI14: 135 | AJ14: 135 | AK14: =SUM(E14:AJ14) -> 4273
D15: PR | E15: 123 | F15: 135 | G15: 138 | H15: 133 | I15: 125 | J15: 139 | K15: 135 | L15: 135 | M15: 140 | N15: 136 | O15: 131 | P15: 138 | Q15: 135 | R15: 137 | S15: 140 | T15: 132 | U15: 138 | V15: 125 | W15: 140 | X15: 134 | Y15: 130 | Z15: 135 | AA15: 133 | AB15: 130 | AC15: 135 | AD15: 133 | AE15: 135 | AF15: 122 | AG15: 121 | AH15: 126 | AI15: 133 | AJ15: 133 | AK15: =SUM(E15:AJ15) -> 4255
D16: JML | E16: =SUM(E14:E15) -> 251 | F16: =SUM(F14:F15) -> 265 | G16: =SUM(G14:G15) -> 283 | H16: =SUM(H14:H15) -> 270 | I16: =SUM(I14:I15) -> 265 | J16: =SUM(J14:J15) -> 279 | K16: =SUM(K14:K15) -> 261 | L16: =SUM(L14:L15) -> 268 | ... AJ16: =SUM(AJ14:AJ15) -> 268 | AK16: =SUM(E16:AJ16) -> 8528
A18: B | B18: PENGGUNA HAK PILIH
B19: 1. | C19: Jumlah pengguna hak pilih dalam Daftar Pemilih Tetap (DPT) | D19: LK | E19: 96 | F19: 92 | G19: 111 | H19: 107 | I19: 106 | J19: 108 | K19: 97 | L19: 102 | M19: 97 | N19: 114 | O19: 101 | P19: 90 | Q19: 99 | R19: 84 | S19: 83 | T19: 102 | U19: 97 | V19: 98 | W19: 102 | X19: 99 | Y19: 100 | Z19: 105 | AA19: 103 | AB19: 101 | AC19: 114 | AD19: 107 | AE19: 106 | AF19: 106 | AG19: 98 | AH19: 108 | AI19: 87 | AJ19: 108 | AK19: =SUM(E19:AJ19) -> 3228
D20: PR | E20: 100 | F20: 103 | G20: 109 | H20: 110 | I20: 112 | J20: 110 | K20: 105 | L20: 112 | M20: 106 | N20: 112 | O20: 103 | P20: 107 | Q20: 113 | R20: 106 | S20: 94 | T20: 109 | U20: 101 | V20: 100 | W20: 115 | X20: 90 | Y20: 101 | Z20: 108 | AA20: 106 | AB20: 105 | AC20: 112 | AD20: 104 | AE20: 100 | AF20: 101 | AG20: 85 | AH20: 95 | AI20: 105 | AJ20: 104 | AK20: =SUM(E20:AJ20) -> 3343
D21: JML | E21: =SUM(E19:E20) -> 196 | F21: =SUM(F19:F20) -> 195 | G21: =SUM(G19:G20) -> 220 | H21: =SUM(H19:H20) -> 217 | I21: =SUM(I19:I20) -> 218 | J21: =SUM(J19:J20) -> 218 | K21: =SUM(K19:K20) -> 202 | L21: =SUM(L19:L20) -> 214 | ... AJ21: =SUM(AJ19:AJ20) -> 212 | AK21: =SUM(E21:AJ21) -> 6571
B22: 2. | C22: Jumlah pengguna hak pilih dalam Daftar Pemilih Tambahan (DPTb) | D22: LK | E22: 0 | F22: 0 | G22: 0 | H22: 0 | I22: 1 | J22: 0 | K22: 0 | L22: 0 | M22: 0 | N22: 0 | O22: 1 | P22: 0 | Q22: 1 | R22: 0 | S22: 0 | T22: 0 | U22: 0 | V22: 0 | W22: 0 | X22: 0 | Y22: 0 | Z22: 1 | AA22: 0 | AB22: 0 | AC22: 0 | AD22: 0 | AE22: 0 | AF22: 1 | AG22: 0 | AH22: 0 | AI22: 0 | AJ22: 0 | AK22: =SUM(E22:AJ22) -> 5
D23: PR | E23: 0 | F23: 0 | G23: 0 | H23: 0 | I23: 1 | J23: 0 | K23: 0 | L23: 0 | M23: 0 | N23: 0 | O23: 1 | P23: 0 | Q23: 0 | R23: 0 | S23: 0 | T23: 0 | U23: 1 | V23: 0 | W23: 0 | X23: 0 | Y23: 0 | Z23: 0 | AA23: 0 | AB23: 0 | AC23: 0 | AD23: 0 | AE23: 0 | AF23: 0 | AG23: 0 | AH23: 0 | AI23: 0 | AJ23: 0 | AK23: =SUM(E23:AJ23) -> 3
D24: JML | E24: =SUM(E22:E23) -> 0 | F24: =SUM(F22:F23) -> 0 | G24: =SUM(G22:G23) -> 0 | H24: =SUM(H22:H23) -> 0 | I24: =SUM(I22:I23) -> 2 | J24: =SUM(J22:J23) -> 0 | K24: =SUM(K22:K23) -> 0 | L24: =SUM(L22:L23) -> 0 | ... AJ24: =SUM(AJ22:AJ23) -> 0 | AK24: =SUM(E24:AJ24) -> 8
B25: 3. | C25: Jumlah pengguna hak pilih dalam Daftar Pemilih Khusus (DPK) | D25: LK | E25: 2 | F25: 2 | G25: 2 | H25: 0 | I25: 0 | J25: 1 | K25: 1 | L25: 0 | M25: 1 | N25: 0 | O25: 1 | P25: 2 | Q25: 2 | R25: 0 | S25: 0 | T25: 1 | U25: 0 | V25: 1 | W25: 0 | X25: 3 | Y25: 0 | Z25: 1 | AA25: 0 | AB25: 1 | AC25: 1 | AD25: 3 | AE25: 2 | AF25: 0 | AG25: 3 | AH25: 1 | AI25: 2 | AJ25: 2 | AK25: =SUM(E25:AJ25) -> 35
D26: PR | E26: 1 | F26: 2 | G26: 3 | H26: 0 | I26: 1 | J26: 1 | K26: 2 | L26: 0 | M26: 2 | N26: 4 | O26: 1 | P26: 2 | Q26: 2 | R26: 1 | S26: 0 | T26: 0 | U26: 2 | V26: 0 | W26: 0 | X26: 5 | Y26: 0 | Z26: 0 | AA26: 4 | AB26: 2 | AC26: 3 | AD26: 0 | AE26: 3 | AF26: 0 | AG26: 2 | AH26: 3 | AI26: 1 | AJ26: 1 | AK26: =SUM(E26:AJ26) -> 48
D27: JML | E27: =SUM(E25:E26) -> 3 | F27: =SUM(F25:F26) -> 4 | G27: =SUM(G25:G26) -> 5 | H27: =SUM(H25:H26) -> 0 | I27: =SUM(I25:I26) -> 1 | J27: =SUM(J25:J26) -> 2 | K27: =SUM(K25:K26) -> 3 | L27: =SUM(L25:L26) -> 0 | ... AJ27: =SUM(AJ25:AJ26) -> 3 | AK27: =SUM(E27:AJ27) -> 83
B28: 4. | C28: Jumlah Pengguna Hak Pilih (B.1+B.2+B.3) | D28: LK | E28: =SUM(E19,E22,E25) -> 98 | F28: =SUM(F19,F22,F25) -> 94 | G28: =SUM(G19,G22,G25) -> 113 | H28: =SUM(H19,H22,H25) -> 107 | I28: =SUM(I19,I22,I25) -> 107 | J28: =SUM(J19,J22,J25) -> 109 | K28: =SUM(K19,K22,K25) -> 98 | L28: =SUM(L19,L22,L25) -> 102 | ... AJ28: =SUM(AJ19,AJ22,AJ25) -> 110 | AK28: =SUM(E28:AJ28) -> 3268
D29: PR | E29: =SUM(E20,E23,E26) -> 101 | F29: =SUM(F20,F23,F26) -> 105 | G29: =SUM(G20,G23,G26) -> 112 | H29: =SUM(H20,H23,H26) -> 110 | I29: =SUM(I20,I23,I26) -> 114 | J29: =SUM(J20,J23,J26) -> 111 | K29: =SUM(K20,K23,K26) -> 107 | L29: =SUM(L20,L23,L26) -> 112 | ... AJ29: =SUM(AJ20,AJ23,AJ26) -> 105 | AK29: =SUM(E29:AJ29) -> 3394
D30: JML | E30: =SUM(E28:E29) -> 199 | F30: =SUM(F28:F29) -> 199 | G30: =SUM(G28:G29) -> 225 | H30: =SUM(H28:H29) -> 217 | I30: =SUM(I28:I29) -> 221 | J30: =SUM(J28:J29) -> 220 | K30: =SUM(K28:K29) -> 205 | L30: =SUM(L28:L29) -> 214 | ... AJ30: =SUM(AJ28:AJ29) -> 215 | AK30: =SUM(E30:AJ30) -> 6662
A32: II | B32: DATA PENGGUNAAN SURAT SUARA
A33: 1 | B33: Jumlah surat suara yang diterima, termasuk surat suara cadangan 2,5% dari DPT | E33: 257 | F33: 271 | G33: 289 | H33: 276 | I33: 271 | J33: 285 | K33: 267 | L33: 284 | M33: 277 | N33: 279 | O33: 277 | P33: 278 | Q33: 269 | R33: 272 | S33: 274 | T33: 268 | U33: 274 | V33: 265 | W33: 274 | X33: 274 | Y33: 269 | Z33: 268 | AA33: 276 | AB33: 266 | AC33: 283 | AD33: 272 | AE33: 280 | AF33: 263 | AG33: 251 | AH33: 272 | AI33: 274 | AJ33: 274 | AK33: =SUM(E33:AJ33) -> 8729
A34: 2 | B34: Jumlah surat suara yang digunakan | E34: 199 | F34: 199 | G34: 225 | H34: 217 | I34: 221 | J34: 220 | K34: 205 | L34: 214 | M34: 206 | N34: 230 | O34: 208 | P34: 201 | Q34: 217 | R34: 191 | S34: 177 | T34: 212 | U34: 201 | V34: 199 | W34: 217 | X34: 197 | Y34: 201 | Z34: 215 | AA34: 213 | AB34: 209 | AC34: 230 | AD34: 214 | AE34: 211 | AF34: 208 | AG34: 188 | AH34: 207 | AI34: 195 | AJ34: 215 | AK34: =SUM(E34:AJ34) -> 6662
A35: 3 | B35: Jumlah surat suara dikembalikan oleh pemilih (karena rusak atau keliru coblos) | E35: 1 | F35: 0 | G35: 2 | H35: 0 | I35: 0 | J35: 0 | K35: 0 | L35: 2 | M35: 0 | N35: 0 | O35: 1 | P35: 0 | Q35: 0 | R35: 0 | S35: 0 | T35: 0 | U35: 0 | V35: 0 | W35: 0 | X35: 2 | Y35: 1 | Z35: 0 | AA35: 0 | AB35: 0 | AC35: 3 | AD35: 0 | AE35: 0 | AF35: 0 | AG35: 0 | AH35: 0 | AI35: 2 | AJ35: 0 | AK35: =SUM(E35:AJ35) -> 14
A36: 4 | B36: Jumlah surat suara yang tidak digunakan/tidak terpakai, termasuk sisa surat suara cadangan | E36: =E33-(E34+E35) -> 57 | F36: =F33-(F34+F35) -> 72 | G36: =G33-(G34+G35) -> 62 | H36: =H33-(H34+H35) -> 59 | I36: =I33-(I34+I35) -> 50 | J36: =J33-(J34+J35) -> 65 | K36: =K33-(K34+K35) -> 62 | L36: =L33-(L34+L35) -> 68 | ... AJ36: =AJ33-(AJ34+AJ35) -> 59 | AK36: =SUM(E36:AJ36) -> 2053
A38: III | B38: DATA PEMILIH DISABILITAS
B39: Jumlah seluruh Pemilih disabilitas yang menggunakan hak pilih | D39: LK | E39: 0 | F39: 0 | G39: 0 | H39: 0 | I39: 0 | J39: 0 | K39: 0 | L39: 0 | M39: 0 | N39: 0 | O39: 1 | P39: 0 | Q39: 0 | R39: 0 | S39: 0 | T39: 0 | U39: 1 | V39: 0 | W39: 0 | X39: 0 | Y39: 0 | Z39: 0 | AA39: 0 | AB39: 0 | AC39: 0 | AD39: 0 | AE39: 0 | AF39: 0 | AG39: 0 | AH39: 0 | AI39: 0 | AJ39: 0 | AK39: =SUM(E39:AJ39) -> 2
D40: PR | E40: 0 | F40: 0 | G40: 0 | H40: 0 | I40: 0 | J40: 0 | K40: 0 | L40: 0 | M40: 0 | N40: 0 | O40: 0 | P40: 0 | Q40: 0 | R40: 0 | S40: 0 | T40: 0 | U40: 2 | V40: 0 | W40: 0 | X40: 0 | Y40: 0 | Z40: 0 | AA40: 0 | AB40: 0 | AC40: 0 | AD40: 0 | AE40: 0 | AF40: 0 | AG40: 0 | AH40: 1 | AI40: 0 | AJ40: 0 | AK40: =SUM(E40:AJ40) -> 3
D41: JML | E41: =SUM(E39:E40) -> 0 | F41: =SUM(F39:F40) -> 0 | G41: =SUM(G39:G40) -> 0 | H41: =SUM(H39:H40) -> 0 | I41: =SUM(I39:I40) -> 0 | J41: =SUM(J39:J40) -> 0 | K41: =SUM(K39:K40) -> 0 | L41: =SUM(L39:L40) -> 0 | ... AJ41: =SUM(AJ39:AJ40) -> 0 | AK41: =SUM(E41:AJ41) -> 5
A43: IV | B43: DATA RINCIAN PEROLEHAN SUARA PASANGAN CALON BUPATI DAN WAKIL BUPATI
A44: NOMOR DAN NAMA CALON
A45: A.1 | B45: 1. | C45: Partai Kebangkitan Bangsa | E45: 4 | F45: 3 | G45: 2 | H45: 2 | I45: 2 | J45: 5 | K45: 3 | L45: 3 | M45: 2 | N45: 2 | O45: 6 | P45: 2 | Q45: 3 | R45: 1 | S45: 1 | T45: 8 | U45: 5 | V45: 5 | W45: 4 | X45: 9 | Y45: 4 | Z45: 3 | AA45: 2 | AB45: 4 | AC45: 3 | AD45: 10 | AE45: 7 | AF45: 4 | AG45: 0 | AH45: 0 | AI45: 1 | AJ45: 6 | AK45: =SUM(E45:AJ45) -> 116
A46: A.2 | C46: 1. MUKHTAR NABALI MUFAUWIQ | E46: 12 | F46: 8 | G46: 4 | H46: 13 | I46: 6 | J46: 13 | K46: 6 | L46: 6 | M46: 8 | N46: 4 | O46: 6 | P46: 4 | Q46: 4 | R46: 4 | S46: 1 | T46: 5 | U46: 2 | V46: 17 | W46: 2 | X46: 7 | Y46: 2 | Z46: 2 | AA46: 5 | AB46: 0 | AC46: 4 | AD46: 6 | AE46: 1 | AF46: 8 | AG46: 1 | AH46: 0 | AI46: 3 | AJ46: 3 | AK46: =SUM(E46:AJ46) -> 167
C47: 2. H. SUSIYANTO | E47: 8 | F47: 16 | G47: 24 | H47: 27 | I47: 12 | J47: 15 | K47: 10 | L47: 8 | M47: 8 | N47: 10 | O47: 28 | P47: 13 | Q47: 28 | R47: 18 | S47: 24 | T47: 33 | U47: 50 | V47: 22 | W47: 30 | X47: 40 | Y47: 24 | Z47: 22 | AA47: 23 | AB47: 25 | AC47: 30 | AD47: 43 | AE47: 34 | AF47: 8 | AG47: 17 | AH47: 21 | AI47: 4 | AJ47: 68 | AK47: =SUM(E47:AJ47) -> 743
C48: 3. DUWI HASTRENI, S.H. | E48: 0 | F48: 10 | G48: 4 | H48: 5 | I48: 16 | J48: 0 | K48: 1 | L48: 3 | M48: 6 | N48: 0 | O48: 1 | P48: 0 | Q48: 1 | R48: 0 | S48: 0 | T48: 2 | U48: 1 | V48: 1 | W48: 0 | X48: 1 | Y48: 1 | Z48: 1 | AA48: 4 | AB48: 0 | AC48: 1 | AD48: 4 | AE48: 0 | AF48: 0 | AG48: 0 | AH48: 0 | AI48: 0 | AJ48: 0 | AK48: =SUM(E48:AJ48) -> 63
C49: 4. MIFTAKHODIN | E49: 1 | F49: 0 | G49: 0 | H49: 0 | I49: 0 | J49: 0 | K49: 0 | L49: 0 | M49: 0 | N49: 0 | O49: 0 | P49: 0 | Q49: 0 | R49: 0 | S49: 0 | T49: 0 | U49: 1 | V49: 0 | W49: 0 | X49: 0 | Y49: 0 | Z49: 1 | AA49: 0 | AB49: 0 | AC49: 0 | AD49: 0 | AE49: 0 | AF49: 0 | AG49: 0 | AH49: 0 | AI49: 0 | AJ49: 0 | AK49: =SUM(E49:AJ49) -> 3
C50: 5. SITI MUSTIKAH | E50: 1 | F50: 1 | G50: 1 | H50: 0 | I50: 0 | J50: 2 | K50: 0 | L50: 0 | M50: 1 | N50: 0 | O50: 0 | P50: 0 | Q50: 0 | R50: 0 | S50: 0 | T50: 0 | U50: 0 | V50: 0 | W50: 0 | X50: 0 | Y50: 0 | Z50: 0 | AA50: 0 | AB50: 0 | AC50: 1 | AD50: 0 | AE50: 0 | AF50: 0 | AG50: 1 | AH50: 0 | AI50: 0 | AJ50: 0 | AK50: =SUM(E50:AJ50) -> 8
C51: 6. ABDUL GHOFUR | E51: 0 | F51: 0 | G51: 0 | H51: 0 | I51: 0 | J51: 0 | K51: 0 | L51: 0 | M51: 1 | N51: 0 | O51: 0 | P51: 0 | Q51: 1 | R51: 1 | S51: 0 | T51: 0 | U51: 1 | V51: 0 | W51: 0 | X51: 1 | Y51: 0 | Z51: 0 | AA51: 0 | AB51: 0 | AC51: 0 | AD51: 0 | AE51: 0 | AF51: 0 | AG51: 0 | AH51: 1 | AI51: 0 | AJ51: 0 | AK51: =SUM(E51:AJ51) -> 6
...

Sheet BULUREJO
C2: Kecamatan | D2: PURWOHARJO
C3: Kabupaten | D3: BANYUWANGI
C4: Provinsi | D4: JAWA TIMUR
C9: Kelurahan | D9: BULUREJO
A12: I | B12: DATA PEMILIH DAN PENGGUNAAN HAK PILIH | AF12: JUMLAH AKHIR
A13: A | B13: DATA PEMILIH | E13: TPS 001 | F13: TPS 002 | G13: TPS 003 | H13: TPS 004 | I13: TPS 005 | J13: TPS 006 | K13: TPS 007 | L13: TPS 008 | M13: TPS 009 | N13: TPS 010 | O13: TPS 011 | P13: TPS 012 | Q13: TPS 013 | R13: TPS 014 | S13: TPS 015 | T13: TPS 016 | U13: TPS 017 | V13: TPS 018 | W13: TPS 019 | X13: TPS 020 | Y13: TPS 021 | Z13: TPS 022 | AA13: TPS 023 | AB13: TPS 024 | AC13: TPS 025 | AD13: TPS 026 | AE13: TPS 027
B14: Jumlah Pemilih dalam Daftar Pemilih Tetap (DPT) | D14: LK | E14: 135 | F14: 123 | G14: 136 | H14: 133 | I14: 128 | J14: 133 | K14: 136 | L14: 143 | M14: 129 | N14: 138 | O14: 134 | P14: 128 | Q14: 143 | R14: 137 | S14: 135 | T14: 129 | U14: 110 | V14: 120 | W14: 117 | X14: 112 | Y14: 116 | Z14: 117 | AA14: 127 | AB14: 133 | AC14: 147 | AD14: 143 | AE14: 147 | AF14: =SUM(E14:AE14) -> 3529
D15: PR | E15: 136 | F15: 136 | G15: 135 | H15: 122 | I15: 135 | J15: 133 | K15: 128 | L15: 118 | M15: 140 | N15: 122 | O15: 126 | P15: 148 | Q15: 125 | R15: 131 | S15: 135 | T15: 138 | U15: 118 | V15: 121 | W15: 130 | X15: 131 | Y15: 128 | Z15: 119 | AA15: 141 | AB15: 146 | AC15: 142 | AD15: 153 | AE15: 147 | AF15: =SUM(E15:AE15) -> 3584
D16: JML | E16: =SUM(E14:E15) -> 271 | F16: =SUM(F14:F15) -> 259 | G16: =SUM(G14:G15) -> 271 | H16: =SUM(H14:H15) -> 255 | I16: =SUM(I14:I15) -> 263 | J16: =SUM(J14:J15) -> 266 | K16: =SUM(K14:K15) -> 264 | L16: =SUM(L14:L15) -> 261 | ... AE16: =SUM(AE14:AE15) -> 294 | AF16: =SUM(E16:AE16) -> 7113
A18: B | B18: PENGGUNA HAK PILIH
B19: 1. | C19: Jumlah pengguna hak pilih dalam Daftar Pemilih Tetap (DPT) | D19: LK | E19: 104 | F19: 105 | G19: 100 | H19: 102 | I19: 90 | J19: 99 | K19: 108 | L19: 103 | M19: 86 | N19: 102 | O19: 98 | P19: 96 | Q19: 99 | R19: 93 | S19: 103 | T19: 99 | U19: 89 | V19: 109 | W19: 88 | X19: 85 | Y19: 94 | Z19: 98 | AA19: 105 | AB19: 104 | AC19: 123 | AD19: 119 | AE19: 110 | AF19: =SUM(E19:AE19) -> 2711
