Workbook

Sheet DPRD KABUPATEN
C8: Kecamatan
C9: Kabupaten | D9: BANYUWANGI
C10: Provinsi | D10: JAWA TIMUR
A12: I | B12: DATA PEMILIH DAN PENGGUNAAN HAK PILIH | E12: JUMLAH AKHIR
A13: A | B13: DATA PEMILIH
B14: Jumlah Pemilih dalam Daftar Pemilih Tetap (DPT) | D14: LK | E14: =SONGGON!AF14+BALAK!X14+SRAGI!AG14+PARANGHARJO!S14+BEDEWANG!W14+BAYU!AB14+SUMBERARUM!X14+SUMBERBULU!Q14+BANGUNSARI!O14 -> 22660
D15: PR | E15: =SONGGON!AF15+BALAK!X15+SRAGI!AG15+PARANGHARJO!S15+BEDEWANG!W15+BAYU!AB15+SUMBERARUM!X15+SUMBERBULU!Q15+BANGUNSARI!O15 -> 22859
D16: JML | E16: =SUM(E14:E15) -> 45519
A18: B | B18: PENGGUNA HAK PILIH
B19: 1. | C19: Jumlah pengguna hak pilih dalam Daftar Pemilih Tetap (DPT) | D19: LK | E19: =SONGGON!AF19+BALAK!X19+SRAGI!AG19+PARANGHARJO!S19+BEDEWANG!W19+BAYU!AB19+SUMBERARUM!X19+SUMBERBULU!Q19+BANGUNSARI!O19 -> 16766
D20: PR | E20: =SONGGON!AF20+BALAK!X20+SRAGI!AG20+PARANGHARJO!S20+BEDEWANG!W20+BAYU!AB20+SUMBERARUM!X20+SUMBERBULU!Q20+BANGUNSARI!O20 -> 18135
D21: JML | E21: =SUM(E19:E20) -> 34901
B22: 2. | C22: Jumlah pengguna hak pilih dalam Daftar Pemilih Tambahan (DPTb) | D22: LK | E22: =SONGGON!AF22+BALAK!X22+SRAGI!AG22+PARANGHARJO!S22+BEDEWANG!W22+BAYU!AB22+SUMBERARUM!X22+SUMBERBULU!Q22+BANGUNSARI!O22 -> 5
D23: PR | E23: =SONGGON!AF23+BALAK!X23+SRAGI!AG23+PARANGHARJO!S23+BEDEWANG!W23+BAYU!AB23+SUMBERARUM!X23+SUMBERBULU!Q23+BANGUNSARI!O23 -> 22
D24: JML | E24: =SUM(E22:E23) -> 27
B25: 3. | C25: Jumlah pengguna hak pilih dalam Daftar Pemilih Khusus (DPK) | D25: LK | E25: =SONGGON!AF25+BALAK!X25+SRAGI!AG25+PARANGHARJO!S25+BEDEWANG!W25+BAYU!AB25+SUMBERARUM!X25+SUMBERBULU!Q25+BANGUNSARI!O25 -> 108
D26: PR | E26: =SONGGON!AF26+BALAK!X26+SRAGI!AG26+PARANGHARJO!S26+BEDEWANG!W26+BAYU!AB26+SUMBERARUM!X26+SUMBERBULU!Q26+BANGUNSARI!O26 -> 109
D27: JML | E27: =SUM(E25:E26) -> 217
B28: 4. | C28: Jumlah Pengguna Hak Pilih (B.1+B.2+B.3) | D28: LK | E28: =E19+E22+E25 -> 16879
D29: PR | E29: =E20+E23+E26 -> 18266
D30: JML | E30: =SUM(E28:E29) -> 35145
A32: II | B32: DATA PENGGUNAAN SURAT SUARA
A33: 1 | B33: Jumlah surat suara yang diterima, termasuk surat suara cadangan 2,5% dari DPT | E33: =SONGGON!AF33+BALAK!X33+SRAGI!AG33+PARANGHARJO!S33+BEDEWANG!W33+BAYU!AB33+SUMBERARUM!X33+SUMBERBULU!Q33+BANGUNSARI!O33 -> 46368
A34: 2 | B34: Jumlah surat suara yang digunakan | E34: =SONGGON!AF34+BALAK!X34+SRAGI!AG34+PARANGHARJO!S34+BEDEWANG!W34+BAYU!AB34+SUMBERARUM!X34+SUMBERBULU!Q34+BANGUNSARI!O34 -> 35145
A35: 3 | B35: Jumlah surat suara dikembalikan oleh pemilih (karena rusak atau keliru coblos) | E35: =SONGGON!AF35+BALAK!X35+SRAGI!AG35+PARANGHARJO!S35+BEDEWANG!W35+BAYU!AB35+SUMBERARUM!X35+SUMBERBULU!Q35+BANGUNSARI!O35 -> 58
A36: 4 | B36: Jumlah surat suara yang tidak digunakan/tidak terpakai, termasuk sisa surat suara cadangan | E36: =E33-(E34+E35) -> 11165
A38: III | B38: DATA PEMILIH DISABILITAS
B39: Jumlah seluruh Pemilih disabilitas yang menggunakan hak pilih | D39: LK | E39: =SONGGON!AF39+BALAK!X39+SRAGI!AG39+PARANGHARJO!S39+BEDEWANG!W39+BAYU!AB39+SUMBERARUM!X39+SUMBERBULU!Q39+BANGUNSARI!O39 -> 20
D40: PR | E40: =SONGGON!AF40+BALAK!X40+SRAGI!AG40+PARANGHARJO!S40+BEDEWANG!W40+BAYU!AB40+SUMBERARUM!X40+SUMBERBULU!Q40+BANGUNSARI!O40 -> 27
D41: JML | E41: =SUM(E39:E40) -> 47
A43: IV | B43: DATA RINCIAN PEROLEHAN SUARA PASANGAN CALON BUPATI DAN WAKIL BUPATI
A44: NOMOR DAN NAMA CALON | E44: =SONGGON!AF44+BALAK!X44+SRAGI!AG44+PARANGHARJO!S44+BEDEWANG!W44+BAYU!AB44+SUMBERARUM!X44+SUMBERBULU!Q44+BANGUNSARI!O44 -> 0
A45: A.1 | B45: 1. | C45: Partai Kebangkitan Bangsa | E45: =SONGGON!AF45+BALAK!X45+SRAGI!AG45+PARANGHARJO!S45+BEDEWANG!W45+BAYU!AB45+SUMBERARUM!X45+SUMBERBULU!Q45+BANGUNSARI!O45 -> 1425
A46: A.2 | C46: 1. H. MUHAMMAD ALI MAHRUS, S.H.I., M.H | E46: =SONGGON!AF46+BALAK!X46+SRAGI!AG46+PARANGHARJO!S46+BEDEWANG!W46+BAYU!AB46+SUMBERARUM!X46+SUMBERBULU!Q46+BANGUNSARI!O46 -> 5082
C47: 2. TUPANG SOEDARGO | E47: =SONGGON!AF47+BALAK!X47+SRAGI!AG47+PARANGHARJO!S47+BEDEWANG!W47+BAYU!AB47+SUMBERARUM!X47+SUMBERBULU!Q47+BANGUNSARI!O47 -> 1392
C48: 3. Hj. KHOLIFATUL HASANAH | E48: =SONGGON!AF48+BALAK!X48+SRAGI!AG48+PARANGHARJO!S48+BEDEWANG!W48+BAYU!AB48+SUMBERARUM!X48+SUMBERBULU!Q48+BANGUNSARI!O48 -> 102
C49: 4. FUAD HUMAIDI, S.H.I. | E49: =SONGGON!AF49+BALAK!X49+SRAGI!AG49+PARANGHARJO!S49+BEDEWANG!W49+BAYU!AB49+SUMBERARUM!X49+SUMBERBULU!Q49+BANGUNSARI!O49 -> 55
C50: 5. ENI WIJI LESTARI | E50: =SONGGON!AF50+BALAK!X50+SRAGI!AG50+PARANGHARJO!S50+BEDEWANG!W50+BAYU!AB50+SUMBERARUM!X50+SUMBERBULU!Q50+BANGUNSARI!O50 -> 22
C51: 6. SONNY AGUS SETIAWAN | E51: =SONGGON!AF51+BALAK!X51+SRAGI!AG51+PARANGHARJO!S51+BEDEWANG!W51+BAYU!AB51+SUMBERARUM!X51+SUMBERBULU!Q51+BANGUNSARI!O51 -> 179
A52: B | B52: JUMLAH SUARA SAH PARTAI POLITIK DAN CALON (A1 + A2) | E52: =SUM(E45:E51) -> 8257
...

Sheet SONGGON
C2: Kecamatan
C3: Kabupaten | D3: BANYUWANGI
C4: Provinsi | D4: JAWA TIMUR
C9: Kelurahan
A12: I | B12: DATA PEMILIH DAN PENGGUNAAN HAK PILIH | AF12: JUMLAH AKHIR
A13: A | B13: DATA PEMILIH | E13: TPS 001 | F13: TPS 002 | G13: TPS 003 | H13: TPS 004 | I13: TPS 005 | J13: TPS 006 | K13: TPS 007 | L13: TPS 008 | M13: TPS 009 | N13: TPS 010 | O13: TPS 011 | P13: TPS 012 | Q13: TPS 013 | R13: TPS 014 | S13: TPS 015 | T13: TPS 016 | U13: TPS 017 | V13: TPS 018 | W13: TPS 019 | X13: TPS 020 | Y13: TPS 021 | Z13: TPS 022 | AA13: TPS 023 | AB13: TPS 024 | AC13: TPS 025 | AD13: TPS 026 | AE13: TPS 027
B14: Jumlah Pemilih dalam Daftar Pemilih Tetap (DPT) | D14: LK | E14: 105 | F14: 135 | G14: 112 | H14: 110 | I14: 120 | J14: 136 | K14: 146 | L14: 92 | M14: 81 | N14: 119 | O14: 140 | P14: 140 | Q14: 140 | R14: 145 | S14: 139 | T14: 94 | U14: 127 | V14: 157 | W14: 149 | X14: 127 | Y14: 140 | Z14: 127 | AA14: 122 | AB14: 147 | AC14: 150 | AD14: 148 | AE14: 136 | AF14: =SUM(E14:AE14) -> 3484
D15: PR | E15: 127 | F15: 134 | G15: 128 | H15: 110 | I15: 127 | J15: 130 | K15: 142 | L15: 98 | M15: 97 | N15: 129 | O15: 140 | P15: 136 | Q15: 134 | R15: 139 | S15: 141 | T15: 103 | U15: 127 | V15: 142 | W15: 148 | X15: 131 | Y15: 150 | Z15: 137 | AA15: 110 | AB15: 132 | AC15: 148 | AD15: 151 | AE15: 144 | AF15: =SUM(E15:AE15) -> 3535
D16: JML | E16: =SUM(E14:E15) -> 232 | F16: =SUM(F14:F15) -> 269 | G16: =SUM(G14:G15) -> 240 | H16: =SUM(H14:H15) -> 220 | I16: =SUM(I14:I15) -> 247 | J16: =SUM(J14:J15) -> 266 | K16: =SUM(K14:K15) -> 288 | L16: =SUM(L14:L15) -> 190 | ... AE16: =SUM(AE14:AE15) -> 280 | AF16: =SUM(E16:AE16) -> 7019
A18: B | B18: PENGGUNA HAK PILIH
B19: 1. | C19: Jumlah pengguna hak pilih dalam Daftar Pemilih Tetap (DPT) | D19: LK | E19: 77 | F19: 95 | G19: 67 | H19: 84 | I19: 101 | J19: 95 | K19: 104 | L19: 65 | M19: 59 | N19: 80 | O19: 108 | P19: 103 | Q19: 109 | R19: 105 | S19: 101 | T19: 76 | U19: 95 | V19: 119 | W19: 110 | X19: 95 | Y19: 99 | Z19: 98 | AA19: 95 | AB19: 110 | AC19: 115 | AD19: 127 | AE19: 112 | AF19: =SUM(E19:AE19) -> 2604
D20: PR | E20: 107 | F20: 106 | G20: 88 | H20: 90 | I20: 104 | J20: 104 | K20: 108 | L20: 69 | M20: 68 | N20: 100 | O20: 108 | P20: 115 | Q20: 103 | R20: 115 | S20: 115 | T20: 81 | U20: 105 | V20: 120 | W20: 128 | X20: 110 | Y20: 116 | Z20: 116 | AA20: 93 | AB20: 109 | AC20: 114 | AD20: 132 | AE20: 127 | AF20: =SUM(E20:AE20) -> 2851
D21: JML | E21: =SUM(E19:E20) -> 184 | F21: =SUM(F19:F20) -> 201 | G21: =SUM(G19:G20) -> 155 | H21: =SUM(H19:H20) -> 174 | I21: =SUM(I19:I20) -> 205 | J21: =SUM(J19:J20) -> 199 | K21: =SUM(K19:K20) -> 212 | L21: =SUM(L19:L20) -> 134 | ... AE21: =SUM(AE19:AE20) -> 239 | AF21: =SUM(E21:AE21) -> 5455
B22: 2. | C22: Jumlah pengguna hak pilih dalam Daftar Pemilih Tambahan (DPTb) | D22: LK | E22: 0 | F22: 0 | G22: 0 | H22: 0 | I22: 0 | J22: 0 | K22: 0 | L22: 0 | M22: 0 | N22: 0 | O22: 0 | P22: 0 | Q22: 0 | R22: 0 | S22: 0 | T22: 0 | U22: 0 | V22: 0 | W22: 1 | X22: 0 | Y22: 0 | Z22: 0 | AA22: 0 | AB22: 0 | AC22: 0 | AD22: 0 | AE22: 0 | AF22: =SUM(E22:AE22) -> 1
D23: PR | E23: 0 | F23: 0 | G23: 0 | H23: 0 | I23: 0 | J23: 0 | K23: 0 | L23: 0 | M23: 0 | N23: 0 | O23: 0 | P23: 0 | Q23: 0 | R23: 0 | S23: 0 | T23: 0 | U23: 0 | V23: 0 | W23: 1 | X23: 0 | Y23: 1 | Z23: 0 | AA23: 0 | AB23: 0 | AC23: 0 | AD23: 0 | AE23: 0 | AF23: =SUM(E23:AE23) -> 2
D24: JML | E24: =SUM(E22:E23) -> 0 | F24: =SUM(F22:F23) -> 0 | G24: =SUM(G22:G23) -> 0 | H24: =SUM(H22:H23) -> 0 | I24: =SUM(I22:I23) -> 0 | J24: =SUM(J22:J23) -> 0 | K24: =SUM(K22:K23) -> 0 | L24: =SUM(L22:L23) -> 0 | ... AE24: =SUM(AE22:AE23) -> 0 | AF24: =SUM(E24:AE24) -> 3
B25: 3. | C25: Jumlah pengguna hak pilih dalam Daftar Pemilih Khusus (DPK) | D25: LK | E25: 0 | F25: 2 | G25: 1 | H25: 1 | I25: 3 | J25: 0 | K25: 0 | L25: 0 | M25: 0 | N25: 1 | O25: 1 | P25: 2 | Q25: 1 | R25: 1 | S25: 0 | T25: 1 | U25: 0 | V25: 0 | W25: 5 | X25: 0 | Y25: 0 | Z25: 1 | AA25: 1 | AB25: 0 | AC25: 0 | AD25: 0 | AE25: 0 | AF25: =SUM(E25:AE25) -> 21
D26: PR | E26: 1 | F26: 0 | G26: 0 | H26: 0 | I26: 1 | J26: 0 | K26: 0 | L26: 0 | M26: 0 | N26: 0 | O26: 0 | P26: 0 | Q26: 0 | R26: 1 | S26: 0 | T26: 0 | U26: 0 | V26: 0 | W26: 4 | X26: 1 | Y26: 1 | Z26: 0 | AA26: 2 | AB26: 0 | AC26: 0 | AD26: 0 | AE26: 0 | AF26: =SUM(E26:AE26) -> 11
D27: JML | E27: =SUM(E25:E26) -> 1 | F27: =SUM(F25:F26) -> 2 | G27: =SUM(G25:G26) -> 1 | H27: =SUM(H25:H26) -> 1 | I27: =SUM(I25:I26) -> 4 | J27: =SUM(J25:J26) -> 0 | K27: =SUM(K25:K26) -> 0 | L27: =SUM(L25:L26) -> 0 | ... AE27: =SUM(AE25:AE26) -> 0 | AF27: =SUM(E27:AE27) -> 32
B28: 4. | C28: Jumlah Pengguna Hak Pilih (B.1+B.2+B.3) | D28: LK | E28: =SUM(E19,E22,E25) -> 77 | F28: =SUM(F19,F22,F25) -> 97 | G28: =SUM(G19,G22,G25) -> 68 | H28: =SUM(H19,H22,H25) -> 85 | I28: =SUM(I19,I22,I25) -> 104 | J28: =SUM(J19,J22,J25) -> 95 | K28: =SUM(K19,K22,K25) -> 104 | L28: =SUM(L19,L22,L25) -> 65 | ... AE28: =SUM(AE19,AE22,AE25) -> 112 | AF28: =SUM(E28:AE28) -> 2626
D29: PR | E29: =SUM(E20,E23,E26) -> 108 | F29: =SUM(F20,F23,F26) -> 106 | G29: =SUM(G20,G23,G26) -> 88 | H29: =SUM(H20,H23,H26) -> 90 | I29: =SUM(I20,I23,I26) -> 105 | J29: =SUM(J20,J23,J26) -> 104 | K29: =SUM(K20,K23,K26) -> 108 | L29: =SUM(L20,L23,L26) -> 69 | ... AE29: =SUM(AE20,AE23,AE26) -> 127 | AF29: =SUM(E29:AE29) -> 2864
D30: JML | E30: =SUM(E28:E29) -> 185 | F30: =SUM(F28:F29) -> 203 | G30: =SUM(G28:G29) -> 156 | H30: =SUM(H28:H29) -> 175 | I30: =SUM(I28:I29) -> 209 | J30: =SUM(J28:J29) -> 199 | K30: =SUM(K28:K29) -> 212 | L30: =SUM(L28:L29) -> 134 | ... AE30: =SUM(AE28:AE29) -> 239 | AF30: =SUM(E30:AE30) -> 5490
A32: II | B32: DATA PENGGUNAAN SURAT SUARA
A33: 1 | B33: Jumlah surat suara yang diterima, termasuk surat suara cadangan 2,5% dari DPT | E33: 237 | F33: 275 | G33: 246 | H33: 225 | I33: 252 | J33: 270 | K33: 294 | L33: 184 | M33: 182 | N33: 253 | O33: 287 | P33: 290 | Q33: 280 | R33: 290 | S33: 286 | T33: 201 | U33: 259 | V33: 305 | W33: 303 | X33: 264 | Y33: 296 | Z33: 270 | AA33: 238 | AB33: 286 | AC33: 304 | AD33: 305 | AE33: 280 | AF33: =SUM(E33:AE33) -> 7162
A34: 2 | B34: Jumlah surat suara yang digunakan | E34: 185 | F34: 203 | G34: 156 | H34: 175 | I34: 209 | J34: 199 | K34: 212 | L34: 134 | M34: 127 | N34: 181 | O34: 217 | P34: 220 | Q34: 213 | R34: 222 | S34: 216 | T34: 158 | U34: 200 | V34: 239 | W34: 249 | X34: 206 | Y34: 217 | Z34: 215 | AA34: 191 | AB34: 219 | AC34: 229 | AD34: 259 | AE34: 239 | AF34: =SUM(E34:AE34) -> 5490
A35: 3 | B35: Jumlah surat suara dikembalikan oleh pemilih (karena rusak atau keliru coblos) | E35: 1 | F35: 0 | G35: 0 | H35: 0 | I35: 1 | J35: 0 | K35: 0 | L35: 3 | M35: 3 | N35: 1 | O35: 2 | P35: 0 | Q35: 1 | R35: 0 | S35: 0 | T35: 1 | U35: 0 | V35: 0 | W35: 0 | X35: 1 | Y35: 1 | Z35: 0 | AA35: 0 | AB35: 0 | AC35: 0 | AD35: 0 | AE35: 0 | AF35: =SUM(E35:AE35) -> 15
A36: 4 | B36: Jumlah surat suara yang tidak digunakan/tidak terpakai, termasuk sisa surat suara cadangan | E36: =E33-(E34+E35) -> 51 | F36: =F33-(F34+F35) -> 72 | G36: =G33-(G34+G35) -> 90 | H36: =H33-(H34+H35) -> 50 | I36: =I33-(I34+I35) -> 42 | J36: =J33-(J34+J35) -> 71 | K36: =K33-(K34+K35) -> 82 | L36: =L33-(L34+L35) -> 47 | ... AE36: =AE33-(AE34+AE35) -> 41 | AF36: =SUM(E36:AE36) -> 1657
A38: III | B38: DATA PEMILIH DISABILITAS
B39: Jumlah seluruh Pemilih disabilitas yang menggunakan hak pilih | D39: LK | E39: 0 | F39: 0 | G39: 0 | H39: 0 | I39: 0 | J39: 0 | K39: 1 | L39: 0 | M39: 0 | N39: 0 | O39: 0 | P39: 0 | Q39: 0 | R39: 2 | S39: 0 | T39: 0 | U39: 0 | V39: 2 | W39: 0 | X39: 0 | Y39: 0 | Z39: 0 | AA39: 0 | AB39: 0 | AC39: 0 | AD39: 0 | AE39: 0 | AF39: =SUM(E39:AE39) -> 5
D40: PR | E40: 0 | F40: 0 | G40: 0 | H40: 0 | I40: 1 | J40: 0 | K40: 0 | L40: 0 | M40: 0 | N40: 2 | O40: 0 | P40: 0 | Q40: 0 | R40: 4 | S40: 0 | T40: 0 | U40: 0 | V40: 2 | W40: 0 | X40: 0 | Y40: 2 | Z40: 0 | AA40: 0 | AB40: 0 | AC40: 0 | AD40: 0 | AE40: 0 | AF40: =SUM(E40:AE40) -> 11
D41: JML | E41: =SUM(E39:E40) -> 0 | F41: =SUM(F39:F40) -> 0 | G41: =SUM(G39:G40) -> 0 | H41: =SUM(H39:H40) -> 0 | I41: =SUM(I39:I40) -> 1 | J41: =SUM(J39:J40) -> 0 | K41: =SUM(K39:K40) -> 1 | L41: =SUM(L39:L40) -> 0 | ... AE41: =SUM(AE39:AE40) -> 0 | AF41: =SUM(E41:AE41) -> 16
A43: IV | B43: DATA RINCIAN PEROLEHAN SUARA PASANGAN CALON BUPATI DAN WAKIL BUPATI
A44: NOMOR DAN NAMA CALON
A45: A.1 | B45: 1. | C45: Partai Kebangkitan Bangsa | E45: 13 | F45: 7 | G45: 4 | H45: 3 | I45: 5 | J45: 6 | K45: 5 | L45: 3 | M45: 11 | N45: 3 | O45: 10 | P45: 10 | Q45: 5 | R45: 8 | S45: 13 | T45: 3 | U45: 2 | V45: 5 | W45: 7 | X45: 8 | Y45: 4 | Z45: 7 | AA45: 5 | AB45: 11 | AC45: 9 | AD45: 8 | AE45: 5 | AF45: =SUM(E45:AE45) -> 180
A46: A.2 | C46: 1. H. MUHAMMAD ALI MAHRUS, S.H.I., M.H | E46: 25 | F46: 28 | G46: 14 | H46: 11 | I46: 23 | J46: 25 | K46: 8 | L46: 39 | M46: 43 | N46: 29 | O46: 39 | P46: 24 | Q46: 29 | R46: 43 | S46: 53 | T46: 4 | U46: 2 | V46: 22 | W46: 22 | X46: 11 | Y46: 7 | Z46: 18 | AA46: 35 | AB46: 49 | AC46: 37 | AD46: 34 | AE46: 9 | AF46: =SUM(E46:AE46) -> 683
C47: 2. TUPANG SOEDARGO | E47: 6 | F47: 10 | G47: 12 | H47: 13 | I47: 12 | J47: 0 | K47: 2 | L47: 1 | M47: 10 | N47: 4 | O47: 15 | P47: 26 | Q47: 13 | R47: 4 | S47: 8 | T47: 21 | U47: 35 | V47: 19 | W47: 28 | X47: 27 | Y47: 35 | Z47: 12 | AA47: 8 | AB47: 9 | AC47: 27 | AD47: 1 | AE47: 0 | AF47: =SUM(E47:AE47) -> 358
C48: 3. Hj. KHOLIFATUL HASANAH | E48: 1 | F48: 0 | G48: 0 | H48: 1 | I48: 0 | J48: 0 | K48: 0 | L48: 0 | M48: 0 | N48: 0 | O48: 2 | P48: 2 | Q48: 1 | R48: 0 | S48: 0 | U48: 0 | V48: 0 | W48: 1 | X48: 0 | Y48: 0 | Z48: 1 | AA48: 0 | AB48: 0 | AC48: 1 | AD48: 1 | AE48: 0 | AF48: =SUM(E48:AE48) -> 11
C49: 4. FUAD HUMAIDI, S.H.I. | F49: 0 | H49: 0 | I49: 0 | J49: 0 | K49: 1 | L49: 0 | M49: 0 | N49: 0 | O49: 0 | P49: 0 | Q49: 0 | R49: 0 | S49: 0 | U49: 0 | V49: 0 | W49: 0 | X49: 0 | Y49: 0 | Z49: 0 | AA49: 1 | AB49: 5 | AC49: 0 | AD49: 0 | AE49: 1 | AF49: =SUM(E49:AE49) -> 8
C50: 5. ENI WIJI LESTARI | F50: 0 | H50: 1 | I50: 0 | J50: 0 | K50: 1 | L50: 0 | M50: 2 | N50: 0 | O50: 0 | P50: 0 | Q50: 0 | R50: 1 | S50: 0 | T50: 1 | U50: 0 | V50: 0 | W50: 0 | X50: 0 | Y50: 0 | Z50: 1 | AA50: 0 | AB50: 0 | AC50: 0 | AD50: 0 | AE50: 1 | AF50: =SUM(E50:AE50) -> 8
C51: 6. SONNY AGUS SETIAWAN | F51: 0 | G51: 1 | H51: 1 | I51: 5 | J51: 1 | K51: 2 | L51: 0 | M51: 0 | N51: 3 | O51: 0 | P51: 5 | Q51: 1 | R51: 0 | S51: 6 | U51: 1 | V51: 0 | W51: 0 | X51: 4 | Y51: 2 | Z51: 2 | AA51: 1 | AB51: 0 | AC51: 0 | AD51: 2 | AE51: 1 | AF51: =SUM(E51:AE51) -> 38
...

Sheet BALAK
C2: Kecamatan
C3: Kabupaten | D3: BANYUWANGI
C4: Provinsi | D4: JAWA TIMUR
C9: Kelurahan
A12: I | B12: DATA PEMILIH DAN PENGGUNAAN HAK PILIH | X12: JUMLAH AKHIR
A13: A | B13: DATA PEMILIH | E13: TPS 001 | F13: TPS 002 | G13: TPS 003 | H13: TPS 004 | I13: TPS 005 | J13: TPS 006 | K13: TPS 007 | L13: TPS 008 | M13: TPS 009 | N13: TPS 010 | O13: TPS 011 | P13: TPS 012 | Q13: TPS 013 | R13: TPS 014 | S13: TPS 015 | T13: TPS 016 | U13: TPS 017 | V13: TPS 018 | W13: TPS 019
B14: Jumlah Pemilih dalam Daftar Pemilih Tetap (DPT) | D14: LK | E14: 138 | F14: 141 | G14: 136 | H14: 140 | I14: 129 | J14: 138 | K14: 139 | L14: 139 | M14: 137 | N14: 138 | O14: 132 | P14: 140 | Q14: 134 | R14: 141 | S14: 131 | T14: 125 | U14: 136 | V14: 136 | W14: 141 | X14: =SUM(E14:W14) -> 2591
D15: PR | E15: 128 | F15: 135 | G15: 145 | H15: 126 | I15: 124 | J15: 136 | K15: 142 | L15: 143 | M15: 147 | N15: 137 | O15: 143 | P15: 150 | Q15: 149 | R15: 145 | S15: 150 | T15: 137 | U15: 141 | V15: 144 | W15: 140 | X15: =SUM(E15:W15) -> 2662
D16: JML | E16: =SUM(E14:E15) -> 266 | F16: =SUM(F14:F15) -> 276 | G16: =SUM(G14:G15) -> 281 | H16: =SUM(H14:H15) -> 266 | I16: =SUM(I14:I15) -> 253 | J16: =SUM(J14:J15) -> 274 | K16: =SUM(K14:K15) -> 281 | L16: =SUM(L14:L15) -> 282 | ... W16: =SUM(W14:W15) -> 281 | X16: =SUM(E16:W16) -> 5253
A18: B | B18: PENGGUNA HAK PILIH
B19: 1. | C19: Jumlah pengguna hak pilih dalam Daftar Pemilih Tetap (DPT) | D19: LK | E19: 73 | F19: 109 | G19: 112 | H19: 93 | I19: 95 | J19: 104 | K19: 96 | L19: 110 | M19: 98 | N19: 104 | O19: 102 | P19: 107 | Q19: 109 | R19: 97 | S19: 93 | T19: 98 | U19: 113 | V19: 104 | W19: 123 | X19: =SUM(E19:W19) -> 1940
D20: PR | E20: 90 | F20: 112 | G20: 118 | H20: 97 | I20: 88 | J20: 110 | K20: 115 | L20: 117 | M20: 127 | N20: 106 | O20: 119 | P20: 122 | Q20: 113 | R20: 122 | S20: 120 | T20: 108 | U20: 116 | V20: 119 | W20: 123 | X20: =SUM(E20:W20) -> 2142
D21: JML | E21: =SUM(E19:E20) -> 163 | F21: =SUM(F19:F20) -> 221 | G21: =SUM(G19:G20) -> 230 | H21: =SUM(H19:H20) -> 190 | I21: =SUM(I19:I20) -> 183 | J21: =SUM(J19:J20) -> 214 | K21: =SUM(K19:K20) -> 211 | L21: =SUM(L19:L20) -> 227 | ... W21: =SUM(W19:W20) -> 246 | X21: =SUM(E21:W21) -> 4082
B22: 2. | C22: Jumlah pengguna hak pilih dalam Daftar Pemilih Tambahan (DPTb) | D22: LK | E22: 0 | F22: 0 | G22: 0 | H22: 0 | I22: 0 | J22: 0 | K22: 0 | L22: 0 | M22: 0 | N22: 0 | O22: 0 | P22: 0 | Q22: 0 | R22: 0 | S22: 0 | T22: 0 | U22: 0 | V22: 0 | W22: 0 | X22: =SUM(E22:W22) -> 0
D23: PR | E23: 0 | F23: 0 | G23: 0 | H23: 0 | I23: 0 | J23: 0 | K23: 0 | L23: 0 | M23: 0 | N23: 0 | O23: 0 | P23: 0 | Q23: 0 | R23: 0 | S23: 0 | T23: 0 | U23: 0 | V23: 0 | W23: 1 | X23: =SUM(E23:W23) -> 1
D24: JML | E24: =SUM(E22:E23) -> 0 | F24: =SUM(F22:F23) -> 0 | G24: =SUM(G22:G23) -> 0 | H24: =SUM(H22:H23) -> 0 | I24: =SUM(I22:I23) -> 0 | J24: =SUM(J22:J23) -> 0 | K24: =SUM(K22:K23) -> 0 | L24: =SUM(L22:L23) -> 0 | ... W24: =SUM(W22:W23) -> 1 | X24: =SUM(E24:W24) -> 1
B25: 3. | C25: Jumlah pengguna hak pilih dalam Daftar Pemilih Khusus (DPK) | D25: LK | E25: 0 | F25: 0 | G25: 2 | H25: 3 | I25: 1 | J25: 0 | K25: 0 | L25: 3 | M25: 0 | N25: 0 | O25: 0 | P25: 0 | Q25: 0 | R25: 2 | S25: 2 | T25: 0 | U25: 0 | V25: 1 | W25: 0 | X25: =SUM(E25:W25) -> 14
D26: PR | E26: 1 | F26: 0 | G26: 1 | H26: 3 | I26: 3 | J26: 1 | K26: 0 | L26: 1 | M26: 0 | N26: 0 | O26: 1 | P26: 0 | Q26: 0 | R26: 3 | S26: 2 | T26: 0 | U26: 2 | V26: 0 | W26: 0 | X26: =SUM(E26:W26) -> 18
D27: JML | E27: =SUM(E25:E26) -> 1 | F27: =SUM(F25:F26) -> 0 | G27: =SUM(G25:G26) -> 3 | H27: =SUM(H25:H26) -> 6 | I27: =SUM(I25:I26) -> 4 | J27: =SUM(J25:J26) -> 1 | K27: =SUM(K25:K26) -> 0 | L27: =SUM(L25:L26) -> 4 | ... W27: =SUM(W25:W26) -> 0 | X27: =SUM(E27:W27) -> 32
B28: 4. | C28: Jumlah Pengguna Hak Pilih (B.1+B.2+B.3) | D28: LK | E28: =SUM(E19,E22,E25) -> 73 | F28: =SUM(F19,F22,F25) -> 109 | G28: =SUM(G19,G22,G25) -> 114 | H28: =SUM(H19,H22,H25) -> 96 | I28: =SUM(I19,I22,I25) -> 96 | J28: =SUM(J19,J22,J25) -> 104 | K28: =SUM(K19,K22,K25) -> 96 | L28: =SUM(L19,L22,L25) -> 113 | ... W28: =SUM(W19,W22,W25) -> 123 | X28: =SUM(E28:W28) -> 1954
D29: PR | E29: =SUM(E20,E23,E26) -> 91 | F29: =SUM(F20,F23,F26) -> 112 | G29: =SUM(G20,G23,G26) -> 119 | H29: =SUM(H20,H23,H26) -> 100 | I29: =SUM(I20,I23,I26) -> 91 | J29: =SUM(J20,J23,J26) -> 111 | K29: =SUM(K20,K23,K26) -> 115 | L29: =SUM(L20,L23,L26) -> 118 | ... W29: =SUM(W20,W23,W26) -> 124 | X29: =SUM(E29:W29) -> 2161
D30: JML | E30: =SUM(E28:E29) -> 164 | F30: =SUM(F28:F29) -> 221 | G30: =SUM(G28:G29) -> 233 | H30: =SUM(H28:H29) -> 196 | I30: =SUM(I28:I29) -> 187 | J30: =SUM(J28:J29) -> 215 | K30: =SUM(K28:K29) -> 211 | L30: =SUM(L28:L29) -> 231 | ... W30: =SUM(W28:W29) -> 247 | X30: =SUM(E30:W30) -> 4115
A32: II | B32: DATA PENGGUNAAN SURAT SUARA
A33: 1 | B33: Jumlah surat suara yang diterima, termasuk surat suara cadangan 2,5% dari DPT | E33: 272 | F33: 282 | G33: 287 | H33: 272 | I33: 259 | J33: 280 | K33: 287 | L33: 288 | M33: 290 | N33: 281 | O33: 306 | P33: 296 | Q33: 289 | R33: 292 | S33: 287 | T33: 268 | U33: 285 | V33: 286 | W33: 290 | X33: =SUM(E33:W33) -> 5397
A34: 2 | B34: Jumlah surat suara yang digunakan | E34: 164 | F34: 221 | G34: 233 | H34: 196 | I34: 187 | J34: 215 | K34: 211 | L34: 231 | M34: 225 | N34: 210 | O34: 222 | P34: 229 | Q34: 222 | R34: 224 | S34: 217 | T34: 206 | U34: 231 | V34: 224 | W34: 247 | X34: =SUM(E34:W34) -> 4115
A35: 3 | B35: Jumlah surat suara dikembalikan oleh pemilih (karena rusak atau keliru coblos) | E35: 0 | F35: 0 | G35: 1 | H35: 0 | I35: 0 | J35: 0 | K35: 0 | L35: 0 | M35: 0 | N35: 0 | O35: 0 | P35: 0 | Q35: 0 | R35: 0 | S35: 0 | T35: 0 | U35: 0 | V35: 1 | W35: 0 | X35: =SUM(E35:W35) -> 2
A36: 4 | B36: Jumlah surat suara yang tidak digunakan/tidak terpakai, termasuk sisa surat suara cadangan | E36: =E33-(E34+E35) -> 108 | F36: =F33-(F34+F35) -> 61 | G36: =G33-(G34+G35) -> 53 | H36: =H33-(H34+H35) -> 76 | I36: =I33-(I34+I35) -> 72 | J36: =J33-(J34+J35) -> 65 | K36: =K33-(K34+K35) -> 76 | L36: =L33-(L34+L35) -> 57 | ... W36: =W33-(W34+W35) -> 43 | X36: =SUM(E36:W36) -> 1280
A38: III | B38: DATA PEMILIH DISABILITAS
B39: Jumlah seluruh Pemilih disabilitas yang menggunakan hak pilih | D39: LK | E39: 0 | F39: 0 | G39: 0 | H39: 0 | I39: 0 | J39: 0 | K39: 0 | L39: 0 | M39: 1 | N39: 0 | O39: 0 | P39: 0 | Q39: 0 | R39: 0 | S39: 0 | T39: 0 | U39: 0 | V39: 0 | W39: 0 | X39: =SUM(E39:W39) -> 1
D40: PR | E40: 0 | F40: 0 | G40: 0 | H40: 0 | I40: 0 | J40: 0 | K40: 0 | L40: 0 | M40: 1 | N40: 0 | O40: 0 | P40: 0 | Q40: 0 | R40: 0 | S40: 0 | T40: 0 | U40: 0 | V40: 0 | W40: 0 | X40: =SUM(E40:W40) -> 1
D41: JML | E41: =SUM(E39:E40) -> 0 | F41: =SUM(F39:F40) -> 0 | G41: =SUM(G39:G40) -> 0 | H41: =SUM(H39:H40) -> 0 | I41: =SUM(I39:I40) -> 0 | J41: =SUM(J39:J40) -> 0 | K41: =SUM(K39:K40) -> 0 | L41: =SUM(L39:L40) -> 0 | ... W41: =SUM(W39:W40) -> 0 | X41: =SUM(E41:W41) -> 2
A43: IV | B43: DATA RINCIAN PEROLEHAN SUARA PASANGAN CALON BUPATI DAN WAKIL BUPATI
A44: NOMOR DAN NAMA CALON
A45: A.1 | B45: 1. | C45: Partai Kebangkitan Bangsa | E45: 19 | F45: 6 | G45: 6 | H45: 4 | I45: 11 | J45: 11 | K45: 7 | L45: 2 | M45: 5 | N45: 4 | O45: 8 | P45: 11 | Q45: 11 | R45: 14 | S45: 20 | T45: 14 | U45: 19 | V45: 18 | W45: 4 | X45: =SUM(E45:W45) -> 194
A46: A.2 | C46: 1. H. MUHAMMAD ALI MAHRUS, S.H.I., M.H | E46: 44 | F46: 17 | G46: 27 | H46: 7 | I46: 21 | J46: 15 | K46: 15 | L46: 22 | M46: 5 | N46: 1 | O46: 18 | P46: 19 | Q46: 84 | R46: 61 | S46: 63 | T46: 55 | U46: 116 | V46: 149 | W46: 17 | X46: =SUM(E46:W46) -> 756
C47: 2. TUPANG SOEDARGO | E47: 14 | F47: 18 | G47: 19 | H47: 5 | I47: 16 | J47: 16 | K47: 36 | L47: 27 | M47: 13 | N47: 14 | O47: 7 | P47: 5 | Q47: 11 | R47: 23 | S47: 18 | T47: 18 | U47: 2 | V47: 7 | W47: 3 | X47: =SUM(E47:W47) -> 272
C48: 3. Hj. KHOLIFATUL HASANAH | E48: 0 | F48: 0 | G48: 0 | H48: 3 | I48: 1 | J48: 0 | K48: 0 | L48: 1 | M48: 0 | N48: 0 | O48: 1 | P48: 1 | Q48: 2 | R48: 2 | S48: 0 | T48: 1 | U48: 0 | V48: 0 | W48: 0 | X48: =SUM(E48:W48) -> 12
C49: 4. FUAD HUMAIDI, S.H.I. | E49: 0 | F49: 0 | G49: 1 | H49: 0 | I49: 0 | J49: 0 | K49: 1 | L49: 0 | M49: 0 | N49: 0 | O49: 0 | P49: 0 | Q49: 0 | R49: 1 | S49: 0 | T49: 0 | U49: 0 | V49: 0 | W49: 0 | X49: =SUM(E49:W49) -> 3
C50: 5. ENI WIJI LESTARI | E50: 0 | F50: 0 | G50: 1 | H50: 0 | I50: 1 | J50: 0 | K50: 1 | L50: 0 | M50: 0 | N50: 0 | O50: 0 | P50: 0 | Q50: 0 | R50: 0 | S50: 1 | T50: 0 | U50: 0 | V50: 1 | W50: 0 | X50: =SUM(E50:W50) -> 5
C51: 6. SONNY AGUS SETIAWAN | E51: 0 | F51: 1 | G51: 1 | H51: 0 | I51: 1 | J51: 0 | K51: 7 | L51: 1 | M51: 0 | N51: 0 | O51: 0 | P51: 0 | Q51: 0 | R51: 0 | S51: 0 | T51: 0 | U51: 0 | V51: 0 | W51: 0 | X51: =SUM(E51:W51) -> 11
...

Sheet SRAGI
C2: Kecamatan
C3: Kabupaten | D3: BANYUWANGI
C4: Provinsi | D4: JAWA TIMUR
C9: Kelurahan
A12: I | B12: DATA PEMILIH DAN PENGGUNAAN HAK PILIH | AG12: JUMLAH AKHIR
A13: A | B13: DATA PEMILIH | E13: TPS 001 | F13: TPS 002 | G13: TPS 003 | H13: TPS 004 | I13: TPS 005 | J13: TPS 006 | K13: TPS 007 | L13: TPS 008 | M13: TPS 009 | N13: TPS 010 | O13: TPS 011 | P13: TPS 012 | Q13: TPS 013 | R13: TPS 014 | S13: TPS 015 | T13: TPS 016 | U13: TPS 017 | V13: TPS 018 | W13: TPS 019 | X13: TPS 020 | Y13: TPS 021 | Z13: TPS 022 | AA13: TPS 023 | AB13: TPS 024 | AC13: TPS 025 | AD13: TPS 026 | AE13: TPS 027 | AF13: TPS 028
B14: Jumlah Pemilih dalam Daftar Pemilih Tetap (DPT) | D14: LK | E14: 133 | F14: 130 | G14: 141 | H14: 116 | I14: 135 | J14: 111 | K14: 134 | L14: 150 | M14: 151 | N14: 146 | O14: 125 | P14: 115 | Q14: 115 | R14: 143 | S14: 150 | T14: 151 | U14: 157 | V14: 140 | W14: 142 | X14: 149 | Y14: 148 | Z14: 151 | AA14: 149 | AB14: 131 | AC14: 127 | AD14: 148 | AE14: 151 | AF14: 135 | AG14: =SUM(E14:AF14) -> 3874
D15: PR | E15: 137 | F15: 129 | G15: 133 | H15: 122 | I15: 125 | J15: 103 | K15: 142 | L15: 148 | M15: 148 | N15: 149 | O15: 132 | P15: 106 | Q15: 115 | R15: 148 | S15: 139 | T15: 142 | U15: 136 | V15: 156 | W15: 152 | X15: 145 | Y15: 148 | Z15: 140 | AA15: 143 | AB15: 117 | AC15: 135 | AD15: 150 | AE15: 140 | AF15: 142 | AG15: =SUM(E15:AF15) -> 3822
D16: JML | E16: =SUM(E14:E15) -> 270 | F16: =SUM(F14:F15) -> 259 | G16: =SUM(G14:G15) -> 274 | H16: =SUM(H14:H15) -> 238 | I16: =SUM(I14:I15) -> 260 | J16: =SUM(J14:J15) -> 214 | K16: =SUM(K14:K15) -> 276 | L16: =SUM(L14:L15) -> 298 | ... AF16: =SUM(AF14:AF15) -> 277 | AG16: =SUM(E16:AF16) -> 7696
A18: B | B18: PENGGUNA HAK PILIH
B19: 1. | C19: Jumlah pengguna hak pilih dalam Daftar Pemilih Tetap (DPT) | D19: LK | E19: 100 | F19: 88 | G19: 101 | H19: 67 | I19: 99 | J19: 81 | K19: 101 | L19: 101 | M19: 113 | N19: 118 | O19: 90 | P19: 90 | Q19: 86 | R19: 111 | S19: 108 | T19: 113 | U19: 101 | V19: 113 | W19: 101 | X19: 116 | Y19: 119 | Z19: 115 | AA19: 112 | AB19: 99 | AC19: 94 | AD19: 102 | AE19: 112 | AF19: 104 | AG19: =SUM(E19:AF19) -> 2855
D20: PR | E20: 104 | F20: 108 | G20: 96 | H20: 86 | I20: 102 | J20: 83 | K20: 109 | L20: 118 | M20: 129 | N20: 124 | O20: 108 | P20: 87 | Q20: 93 | R20: 119 | S20: 108 | T20: 111 | U20: 101 | V20: 126 | W20: 115 | X20: 116 | Y20: 127 | Z20: 108 | AA20: 111 | AB20: 99 | AC20: 107 | AD20: 115 | AE20: 118 | AF20: 111 | AG20: =SUM(E20:AF20) -> 3039
D21: JML | E21: =SUM(E19:E20) -> 204 | F21: =SUM(F19:F20) -> 196 | G21: =SUM(G19:G20) -> 197 | H21: =SUM(H19:H20) -> 153 | I21: =SUM(I19:I20) -> 201 | J21: =SUM(J19:J20) -> 164 | K21: =SUM(K19:K20) -> 210 | L21: =SUM(L19:L20) -> 219 | ... AF21: =SUM(AF19:AF20) -> 215 | AG21: =SUM(E21:AF21) -> 5894
B22: 2. | C22: Jumlah pengguna hak pilih dalam Daftar Pemilih Tambahan (DPTb) | D22: LK | E22: 0 | F22: 0 | G22: 0 | H22: 0 | I22: 0 | J22: 0 | K22: 0 | L22: 0 | M22: 0 | N22: 0 | O22: 0 | P22: 0 | Q22: 0 | R22: 0 | S22: 0 | T22: 0 | U22: 0 | V22: 0 | W22: 0 | X22: 0 | Y22: 0 | Z22: 0 | AA22: 0 | AB22: 0 | AC22: 0 | AD22: 0 | AE22: 0 | AF22: 0 | AG22: =SUM(E22:AF22) -> 0
D23: PR | E23: 0 | F23: 0 | G23: 0 | H23: 0 | I23: 0 | J23: 0 | K23: 0 | L23: 0 | M23: 0 | N23: 0 | O23: 0 | P23: 0 | Q23: 0 | R23: 0 | S23: 0 | T23: 0 | U23: 0 | V23: 0 | W23: 0 | X23: 0 | Y23: 0 | Z23: 0 | AA23: 0 | AB23: 0 | AC23: 0 | AD23: 0 | AE23: 0 | AF23: 0 | AG23: =SUM(E23:AF23) -> 0
D24: JML | E24: =SUM(E22:E23) -> 0 | F24: =SUM(F22:F23) -> 0 | G24: =SUM(G22:G23) -> 0 | H24: =SUM(H22:H23) -> 0 | I24: =SUM(I22:I23) -> 0 | J24: =SUM(J22:J23) -> 0 | K24: =SUM(K22:K23) -> 0 | L24: =SUM(L22:L23) -> 0 | ... AF24: =SUM(AF22:AF23) -> 0 | AG24: =SUM(E24:AF24) -> 0
B25: 3. | C25: Jumlah pengguna hak pilih dalam Daftar Pemilih Khusus (DPK) | D25: LK | E25: 1 | F25: 1 | G25: 0 | H25: 2 | I25: 0 | J25: 0 | K25: 2 | L25: 0 | M25: 1 | N25: 2 | O25: 0 | P25: 0 | Q25: 0 | R25: 0 | S25: 0 | T25: 0 | U25: 1 | V25: 1 | W25: 0 | X25: 0 | Y25: 0 | Z25: 0 | AA25: 0 | AB25: 0 | AC25: 4 | AD25: 1 | AE25: 2 | AF25: 3 | AG25: =SUM(E25:AF25) -> 21
D26: PR | E26: 0 | F26: 0 | G26: 0 | H26: 0 | I26: 1 | J26: 1 | K26: 2 | L26: 2 | M26: 1 | N26: 0 | O26: 0 | P26: 0 | Q26: 1 | R26: 0 | S26: 0 | T26: 0 | U26: 1 | V26: 1 | W26: 0 | X26: 0 | Y26: 1 | Z26: 0 | AA26: 0 | AB26: 0 | AC26: 2 | AD26: 1 | AE26: 1 | AF26: 8 | AG26: =SUM(E26:AF26) -> 23
D27: JML | E27: =SUM(E25:E26) -> 1 | F27: =SUM(F25:F26) -> 1 | G27: =SUM(G25:G26) -> 0 | H27: =SUM(H25:H26) -> 2 | I27: =SUM(I25:I26) -> 1 | J27: =SUM(J25:J26) -> 1 | K27: =SUM(K25:K26) -> 4 | L27: =SUM(L25:L26) -> 2 | ... AF27: =SUM(AF25:AF26) -> 11 | AG27: =SUM(E27:AF27) -> 44
B28: 4. | C28: Jumlah Pengguna Hak Pilih (B.1+B.2+B.3) | D28: LK | E28: =SUM(E19,E22,E25) -> 101 | F28: =SUM(F19,F22,F25) -> 89 | G28: =SUM(G19,G22,G25) -> 101 | H28: =SUM(H19,H22,H25) -> 69 | I28: =SUM(I19,I22,I25) -> 99 | J28: =SUM(J19,J22,J25) -> 81 | K28: =SUM(K19,K22,K25) -> 103 | L28: =SUM(L19,L22,L25) -> 101 | ... AF28: =SUM(AF19,AF22,AF25) -> 107 | AG28: =SUM(E28:AF28) -> 2876
D29: PR | E29: =SUM(E20,E23,E26) -> 104 | F29: =SUM(F20,F23,F26) -> 108 | G29: =SUM(G20,G23,G26) -> 96 | H29: =SUM(H20,H23,H26) -> 86 | I29: =SUM(I20,I23,I26) -> 103 | J29: =SUM(J20,J23,J26) -> 84 | K29: =SUM(K20,K23,K26) -> 111 | L29: =SUM(L20,L23,L26) -> 120 | ... AF29: =SUM(AF20,AF23,AF26) -> 119 | AG29: =SUM(E29:AF29) -> 3062
D30: JML | E30: =SUM(E28:E29) -> 205 | F30: =SUM(F28:F29) -> 197 | G30: =SUM(G28:G29) -> 197 | H30: =SUM(H28:H29) -> 155 | I30: =SUM(I28:I29) -> 202 | J30: =SUM(J28:J29) -> 165 | K30: =SUM(K28:K29) -> 214 | L30: =SUM(L28:L29) -> 221 | ... AF30: =SUM(AF28:AF29) -> 226 | AG30: =SUM(E30:AF30) -> 5938
A32: II | B32: DATA PENGGUNAAN SURAT SUARA
A33: 1 | B33: Jumlah surat suara yang diterima, termasuk surat suara cadangan 2,5% dari DPT | E33: 276 | F33: 265 | G33: 280 | H33: 243 | I33: 267 | J33: 219 | K33: 282 | L33: 294 | M33: 305 | N33: 301 | O33: 263 | P33: 226 | Q33: 235 | R33: 297 | S33: 295 | T33: 299 | U33: 300 | V33: 302 | W33: 301 | X33: 301 | Y33: 302 | Z33: 296 | AA33: 290 | AB33: 253 | AC33: 268 | AD33: 304 | AE33: 297 | AF33: 283 | AG33: =SUM(E33:AF33) -> 7844
A34: 2 | B34: Jumlah surat suara yang digunakan | E34: 205 | F34: 197 | G34: 197 | H34: 155 | I34: 202 | J34: 165 | K34: 214 | L34: 221 | M34: 244 | N34: 244 | O34: 198 | P34: 177 | Q34: 180 | R34: 230 | S34: 216 | T34: 224 | U34: 204 | V34: 241 | W34: 216 | X34: 232 | Y34: 247 | Z34: 223 | AA34: 223 | AB34: 198 | AC34: 207 | AD34: 219 | AE34: 233 | AF34: 226 | AG34: =SUM(E34:AF34) -> 5938
A35: 3 | B35: Jumlah surat suara dikembalikan oleh pemilih (karena rusak atau keliru coblos) | E35: 1 | F35: 0 | G35: 0 | H35: 0 | I35: 0 | J35: 0 | K35: 0 | L35: 0 | M35: 0 | N35: 2 | O35: 0 | P35: 1 | Q35: 0 | R35: 0 | S35: 1 | T35: 0 | U35: 0 | V35: 0 | W35: 0 | X35: 0 | Y35: 4 | Z35: 0 | AA35: 0 | AB35: 0 | AC35: 0 | AD35: 0 | AE35: 0 | AF35: 1 | AG35: =SUM(E35:AF35) -> 10
A36: 4 | B36: Jumlah surat suara yang tidak digunakan/tidak terpakai, termasuk sisa surat suara cadangan | E36: =E33-(E34+E35) -> 70 | F36: =F33-(F34+F35) -> 68 | G36: =G33-(G34+G35) -> 83 | H36: =H33-(H34+H35) -> 88 | I36: =I33-(I34+I35) -> 65 | J36: =J33-(J34+J35) -> 54 | K36: =K33-(K34+K35) -> 68 | L36: =L33-(L34+L35) -> 73 | ... AF36: =AF33-(AF34+AF35) -> 56 | AG36: =SUM(E36:AF36) -> 1896
A38: III | B38: DATA PEMILIH DISABILITAS
B39: Jumlah seluruh Pemilih disabilitas yang menggunakan hak pilih | D39: LK | E39: 0 | F39: 0 | G39: 0 | H39: 0 | I39: 0 | J39: 0 | K39: 2 | L39: 0 | M39: 0 | N39: 0 | O39: 0 | P39: 0 | Q39: 0 | R39: 0 | S39: 0 | T39: 0 | U39: 0 | V39: 0 | W39: 0 | X39: 0 | Y39: 0 | Z39: 0 | AA39: 0 | AB39: 0 | AC39: 0 | AD39: 0 | AE39: 1 | AF39: 1 | AG39: =SUM(E39:AF39) -> 4
D40: PR | E40: 0 | F40: 0 | G40: 0 | H40: 0 | I40: 0 | J40: 0 | K40: 0 | L40: 0 | M40: 0 | N40: 0 | O40: 0 | P40: 0 | Q40: 0 | R40: 0 | S40: 0 | T40: 0 | U40: 0 | V40: 0 | W40: 0 | X40: 0 | Y40: 0 | Z40: 0 | AA40: 0 | AB40: 0 | AC40: 0 | AD40: 1 | AE40: 0 | AF40: 0 | AG40: =SUM(E40:AF40) -> 1
D41: JML | E41: =SUM(E39:E40) -> 0 | F41: =SUM(F39:F40) -> 0 | G41: =SUM(G39:G40) -> 0 | H41: =SUM(H39:H40) -> 0 | I41: =SUM(I39:I40) -> 0 | J41: =SUM(J39:J40) -> 0 | K41: =SUM(K39:K40) -> 2 | L41: =SUM(L39:L40) -> 0 | ... AF41: =SUM(AF39:AF40) -> 1 | AG41: =SUM(E41:AF41) -> 5
A43: IV | B43: DATA RINCIAN PEROLEHAN SUARA PASANGAN CALON BUPATI DAN WAKIL BUPATI
A44: NOMOR DAN NAMA CALON
A45: A.1 | B45: 1. | C45: Partai Kebangkitan Bangsa | E45: 12 | F45: 21 | G45: 6 | H45: 5 | I45: 4 | J45: 4 | K45: 9 | L45: 8 | M45: 10 | N45: 10 | O45: 2 | P45: 14 | Q45: 14 | R45: 13 | S45: 15 | T45: 6 | U45: 3 | V45: 5 | W45: 9 | X45: 1 | Y45: 9 | Z45: 10 | AA45: 2 | AB45: 4 | AC45: 6 | AD45: 6 | AE45: 33 | AF45: 13 | AG45: =SUM(E45:AF45) -> 254
A46: A.2 | C46: 1. H. MUHAMMAD ALI MAHRUS, S.H.I., M.H | E46: 7 | F46: 30 | G46: 12 | H46: 10 | I46: 24 | J46: 13 | K46: 5 | L46: 5 | M46: 22 | N46: 16 | O46: 15 | P46: 18 | Q46: 41 | R46: 35 | S46: 44 | T46: 37 | U46: 20 | V46: 8 | W46: 36 | X46: 7 | Y46: 36 | Z46: 79 | AA46: 7 | AB46: 16 | AC46: 14 | AD46: 40 | AE46: 102 | AF46: 29 | AG46: =SUM(E46:AF46) -> 728
C47: 2. TUPANG SOEDARGO | E47: 1 | F47: 3 | G47: 2 | H47: 0 | I47: 3 | J47: 1 | K47: 4 | L47: 6 | M47: 14 | N47: 10 | O47: 12 | P47: 9 | Q47: 29 | R47: 4 | S47: 2 | T47: 1 | U47: 4 | V47: 4 | W47: 0 | X47: 0 | Y47: 1 | Z47: 1 | AA47: 4 | AB47: 2 | AC47: 3 | AD47: 0 | AE47: 1 | AF47: 2 | AG47: =SUM(E47:AF47) -> 123
C48: 3. Hj. KHOLIFATUL HASANAH | E48: 1 | F48: 1 | G48: 3 | H48: 0 | I48: 0 | J48: 1 | K48: 0 | L48: 0 | M48: 0 | N48: 0 | O48: 0 | P48: 3 | Q48: 2 | R48: 0 | S48: 0 | T48: 0 | U48: 0 | V48: 0 | W48: 0 | X48: 0 | Y48: 0 | Z48: 5 | AA48: 0 | AB48: 1 | AC48: 0 | AD48: 0 | AE48: 1 | AF48: 1 | AG48: =SUM(E48:AF48) -> 19
C49: 4. FUAD HUMAIDI, S.H.I. | E49: 0 | F49: 0 | G49: 3 | H49: 4 | I49: 1 | J49: 0 | K49: 0 | L49: 0 | M49: 1 | N49: 0 | O49: 0 | P49: 0 | Q49: 0 | R49: 0 | S49: 0 | T49: 0 | U49: 1 | V49: 0 | W49: 1 | X49: 0 | Y49: 0 | Z49: 0 | AA49: 0 | AB49: 0 | AC49: 1 | AD49: 0 | AE49: 0 | AF49: 1 | AG49: =SUM(E49:AF49) -> 13
C50: 5. ENI WIJI LESTARI | E50: 0 | F50: 0 | G50: 0 | H50: 0 | I50: 0 | J50: 0 | K50: 1 | L50: 0 | M50: 0 | N50: 0 | O50: 0 | P50: 0 | Q50: 0 | R50: 0 | S50: 1 | T50: 0 | U50: 0 | V50: 0 | W50: 0 | X50: 0 | Y50: 0 | Z50: 0 | AA50: 0 | AB50: 0 | AC50: 0 | AD50: 0 | AE50: 0 | AF50: 0 | AG50: =SUM(E50:AF50) -> 2
C51: 6. SONNY AGUS SETIAWAN | E51: 0 | F51: 0 | G51: 0 | H51: 0 | I51: 0 | J51: 2 | K51: 0 | L51: 2 | M51: 0 | N51: 0 | O51: 0 | P51: 7 | Q51: 1 | R51: 0 | S51: 0 | T51: 2 | U51: 0 | V51: 0 | W51: 0 | X51: 0 | Y51: 0 | Z51: 0 | AA51: 11 | AB51: 3 | AC51: 2 | AD51: 0 | AE51: 0 | AF51: 2 | AG51: =SUM(E51:AF51) -> 32
...

Sheet PARANGHARJO
C2: Kecamatan
C3: Kabupaten | D3: BANYUWANGI
C4: Provinsi | D4: JAWA TIMUR
C9: Kelurahan
A12: I | B12: DATA PEMILIH DAN PENGGUNAAN HAK PILIH | S12: JUMLAH AKHIR
A13: A | B13: DATA PEMILIH | E13: TPS 001 | F13: TPS 002 | G13: TPS 003 | H13: TPS 004 | I13: TPS 005 | J13: TPS 006 | K13: TPS 007 | L13: TPS 008 | M13: TPS 009 | N13: TPS 010 | O13: TPS 011 | P13: TPS 012 | Q13: TPS 013 | R13: TPS 014
B14: Jumlah Pemilih dalam Daftar Pemilih Tetap (DPT) | D14: LK | E14: 142 | F14: 126 | G14: 141 | H14: 137 | I14: 124 | J14: 138 | K14: 148 | L14: 124 | M14: 140 | N14: 140 | O14: 112 | P14: 97 | Q14: 113 | R14: 122 | S14: =SUM(E14:R14) -> 1804
D15: PR | E15: 147 | F15: 137 | G15: 137 | H15: 156 | I15: 130 | J15: 126 | K15: 134 | L15: 107 | M15: 129 | N15: 129 | O15: 121 | P15: 103 | Q15: 107 | R15: 113 | S15: =SUM(E15:R15) -> 1776
D16: JML | E16: =SUM(E14:E15) -> 289 | F16: =SUM(F14:F15) -> 263 | G16: =SUM(G14:G15) -> 278 | H16: =SUM(H14:H15) -> 293 | I16: =SUM(I14:I15) -> 254 | J16: =SUM(J14:J15) -> 264 | K16: =SUM(K14:K15) -> 282 | L16: =SUM(L14:L15) -> 231 | ... R16: =SUM(R14:R15) -> 235 | S16: =SUM(E16:R16) -> 3580
A18: B | B18: PENGGUNA HAK PILIH
B19: 1. | C19: Jumlah pengguna hak pilih dalam Daftar Pemilih Tetap (DPT) | D19: LK | E19: 114 | F19: 88 | G19: 96 | H19: 92 | I19: 83 | J19: 95 | K19: 107 | L19: 86 | M19: 110 | N19: 95 | O19: 82 | P19: 60 | Q19: 77 | R19: 91 | S19: =SUM(E19:R19) -> 1276
D20: PR | E20: 121 | F20: 104 | G20: 115 | H20: 115 | I20: 96 | J20: 105 | K20: 104 | L20: 83 | M20: 109 | N20: 113 | O20: 89 | P20: 73 | Q20: 74 | R20: 104 | S20: =SUM(E20:R20) -> 1405
D21: JML | E21: =SUM(E19:E20) -> 235 | F21: =SUM(F19:F20) -> 192 | G21: =SUM(G19:G20) -> 211 | H21: =SUM(H19:H20) -> 207 | I21: =SUM(I19:I20) -> 179 | J21: =SUM(J19:J20) -> 200 | K21: =SUM(K19:K20) -> 211 | L21: =SUM(L19:L20) -> 169 | ... R21: =SUM(R19:R20) -> 195 | S21: =SUM(E21:R21) -> 2681
B22: 2. | C22: Jumlah pengguna hak pilih dalam Daftar Pemilih Tambahan (DPTb) | D22: LK | E22: 0 | F22: 0 | G22: 0 | H22: 0 | I22: 0 | J22: 0 | K22: 0 | L22: 0 | M22: 0 | N22: 0 | O22: 0 | P22: 1 | Q22: 0 | R22: 0 | S22: =SUM(E22:R22) -> 1
D23: PR | E23: 10 | F23: 5 | G23: 3 | H23: 0 | I23: 0 | J23: 0 | K23: 0 | L23: 0 | M23: 0 | N23: 0 | O23: 0 | P23: 1 | Q23: 0 | R23: 0 | S23: =SUM(E23:R23) -> 19
D24: JML | E24: =SUM(E22:E23) -> 10 | F24: =SUM(F22:F23) -> 5 | G24: =SUM(G22:G23) -> 3 | H24: =SUM(H22:H23) -> 0 | I24: =SUM(I22:I23) -> 0 | J24: =SUM(J22:J23) -> 0 | K24: =SUM(K22:K23) -> 0 | L24: =SUM(L22:L23) -> 0 | ... R24: =SUM(R22:R23) -> 0 | S24: =SUM(E24:R24) -> 20
B25: 3. | C25: Jumlah pengguna hak pilih dalam Daftar Pemilih Khusus (DPK) | D25: LK | E25: 3 | F25: 0 | G25: 0 | H25: 0 | I25: 2 | J25: 2 | K25: 0 | L25: 1 | M25: 1 | N25: 0 | O25: 0 | P25: 1 | Q25: 1 | R25: 2 | S25: =SUM(E25:R25) -> 13
D26: PR | E26: 0 | F26: 0 | G26: 1 | H26: 0 | I26: 3 | J26: 2 | K26: 0 | L26: 1 | M26: 2 | N26: 0 | O26: 0 | P26: 6 | Q26: 1 | R26: 2 | S26: =SUM(E26:R26) -> 18
D27: JML | E27: =SUM(E25:E26) -> 3 | F27: =SUM(F25:F26) -> 0 | G27: =SUM(G25:G26) -> 1 | H27: =SUM(H25:H26) -> 0 | I27: =SUM(I25:I26) -> 5 | J27: =SUM(J25:J26) -> 4 | K27: =SUM(K25:K26) -> 0 | L27: =SUM(L25:L26) -> 2 | ... R27: =SUM(R25:R26) -> 4 | S27: =SUM(E27:R27) -> 31
B28: 4. | C28: Jumlah Pengguna Hak Pilih (B.1+B.2+B.3) | D28: LK | E28: =SUM(E19,E22,E25) -> 117 | F28: =SUM(F19,F22,F25) -> 88 | G28: =SUM(G19,G22,G25) -> 96 | H28: =SUM(H19,H22,H25) -> 92 | I28: =SUM(I19,I22,I25) -> 85 | J28: =SUM(J19,J22,J25) -> 97 | K28: =SUM(K19,K22,K25) -> 107 | L28: =SUM(L19,L22,L25) -> 87 | ... R28: =SUM(R19,R22,R25) -> 93 | S28: =SUM(E28:R28) -> 1290
D29: PR | E29: =SUM(E20,E23,E26) -> 131 | F29: =SUM(F20,F23,F26) -> 109 | G29: =SUM(G20,G23,G26) -> 119 | H29: =SUM(H20,H23,H26) -> 115 | I29: =SUM(I20,I23,I26) -> 99 | J29: =SUM(J20,J23,J26) -> 107 | K29: =SUM(K20,K23,K26) -> 104 | L29: =SUM(L20,L23,L26) -> 84 | ... R29: =SUM(R20,R23,R26) -> 106 | S29: =SUM(E29:R29) -> 1442
D30: JML | E30: =SUM(E28:E29) -> 248 | F30: =SUM(F28:F29) -> 197 | G30: =SUM(G28:G29) -> 215 | H30: =SUM(H28:H29) -> 207 | I30: =SUM(I28:I29) -> 184 | J30: =SUM(J28:J29) -> 204 | K30: =SUM(K28:K29) -> 211 | L30: =SUM(L28:L29) -> 171 | ... R30: =SUM(R28:R29) -> 199 | S30: =SUM(E30:R30) -> 2732
A32: II | B32: DATA PENGGUNAAN SURAT SUARA
A33: 1 | B33: Jumlah surat suara yang diterima, termasuk surat suara cadangan 2,5% dari DPT | E33: 295 | F33: 269 | G33: 284 | H33: 299 | I33: 260 | J33: 270 | K33: 289 | L33: 236 | M33: 275 | N33: 275 | O33: 238 | P33: 206 | Q33: 225 | R33: 240 | S33: =SUM(E33:R33) -> 3661
A34: 2 | B34: Jumlah surat suara yang digunakan | E34: 248 | F34: 197 | G34: 215 | H34: 207 | I34: 184 | J34: 204 | K34: 211 | L34: 171 | M34: 222 | N34: 208 | O34: 171 | P34: 142 | Q34: 153 | R34: 199 | S34: =SUM(E34:R34) -> 2732
A35: 3 | B35: Jumlah surat suara dikembalikan oleh pemilih (karena rusak atau keliru coblos) | E35: 0 | F35: 0 | G35: 1 | H35: 0 | I35: 0 | J35: 0 | K35: 0 | L35: 1 | M35: 0 | N35: 2 | O35: 0 | P35: 0 | Q35: 3 | R35: 0 | S35: =SUM(E35:R35) -> 7
A36: 4 | B36: Jumlah surat suara yang tidak digunakan/tidak terpakai, termasuk sisa surat suara cadangan | E36: =E33-(E34+E35) -> 47 | F36: =F33-(F34+F35) -> 72 | G36: =G33-(G34+G35) -> 68 | H36: =H33-(H34+H35) -> 92 | I36: =I33-(I34+I35) -> 76 | J36: =J33-(J34+J35) -> 66 | K36: =K33-(K34+K35) -> 78 | L36: =L33-(L34+L35) -> 64 | ... R36: =R33-(R34+R35) -> 41 | S36: =SUM(E36:R36) -> 922
A38: III | B38: DATA PEMILIH DISABILITAS
B39: Jumlah seluruh Pemilih disabilitas yang menggunakan hak pilih | D39: LK | E39: 0 | F39: 0 | G39: 0 | H39: 0 | I39: 0 | J39: 0 | K39: 0 | L39: 0 | M39: 0 | N39: 0 | O39: 0 | P39: 0 | Q39: 0 | R39: 0 | S39: =SUM(E39:R39) -> 0
D40: PR | E40: 0 | F40: 0 | G40: 0 | H40: 0 | I40: 0 | J40: 0 | K40: 0 | L40: 0 | M40: 0 | N40: 0 | O40: 0 | P40: 0 | Q40: 0 | R40: 2 | S40: =SUM(E40:R40) -> 2
D41: JML | E41: =SUM(E39:E40) -> 0 | F41: =SUM(F39:F40) -> 0 | G41: =SUM(G39:G40) -> 0 | H41: =SUM(H39:H40) -> 0 | I41: =SUM(I39:I40) -> 0 | J41: =SUM(J39:J40) -> 0 | K41: =SUM(K39:K40) -> 0 | L41: =SUM(L39:L40) -> 0 | ... R41: =SUM(R39:R40) -> 2 | S41: =SUM(E41:R41) -> 2
A43: IV | B43: DATA RINCIAN PEROLEHAN SUARA PASANGAN CALON BUPATI DAN WAKIL BUPATI
A44: NOMOR DAN NAMA CALON
A45: A.1 | B45: 1. | C45: Partai Kebangkitan Bangsa | E45: 2 | F45: 4 | G45: 5 | H45: 8 | I45: 7 | J45: 1 | K45: 16 | L45: 11 | M45: 10 | N45: 3 | O45: 11 | P45: 2 | Q45: 7 | R45: 6 | S45: =SUM(E45:R45) -> 93
A46: A.2 | C46: 1. H. MUHAMMAD ALI MAHRUS, S.H.I., M.H | E46: 6 | F46: 3 | G46: 6 | H46: 8 | I46: 9 | J46: 10 | K46: 146 | L46: 63 | M46: 32 | N46: 10 | O46: 37 | P46: 46 | Q46: 67 | R46: 12 | S46: =SUM(E46:R46) -> 455
C47: 2. TUPANG SOEDARGO | E47: 7 | F47: 11 | G47: 16 | H47: 19 | I47: 30 | J47: 47 | K47: 1 | L47: 1 | M47: 9 | N47: 2 | O47: 0 | P47: 0 | Q47: 3 | R47: 5 | S47: =SUM(E47:R47) -> 151
C48: 3. Hj. KHOLIFATUL HASANAH | E48: 1 | F48: 0 | G48: 0 | H48: 0 | I48: 0 | J48: 1 | K48: 0 | L48: 0 | M48: 0 | N48: 1 | O48: 2 | P48: 0 | Q48: 0 | R48: 0 | S48: =SUM(E48:R48) -> 5
C49: 4. FUAD HUMAIDI, S.H.I. | E49: 0 | F49: 0 | G49: 1 | H49: 0 | I49: 0 | J49: 0 | K49: 0 | L49: 0 | M49: 1 | N49: 0 | O49: 1 | P49: 0 | Q49: 0 | R49: 0 | S49: =SUM(E49:R49) -> 3
C50: 5. ENI WIJI LESTARI | E50: 1 | F50: 0 | G50: 0 | H50: 0 | I50: 0 | J50: 0 | K50: 0 | L50: 0 | M50: 0 | N50: 0 | O50: 0 | P50: 0 | Q50: 0 | R50: 0 | S50: =SUM(E50:R50) -> 1
C51: 6. SONNY AGUS SETIAWAN | E51: 1 | F51: 0 | G51: 0 | H51: 2 | I51: 1 | J51: 3 | K51: 0 | L51: 8 | M51: 10 | N51: 1 | O51: 0 | P51: 0 | Q51: 0 | R51: 0 | S51: =SUM(E51:R51) -> 26
...

Sheet BEDEWANG
C2: Kecamatan
C3: Kabupaten | D3: BANYUWANGI
C4: Provinsi | D4: JAWA TIMUR
C9: Kelurahan
A12: I | B12: DATA PEMILIH DAN PENGGUNAAN HAK PILIH | W12: JUMLAH AKHIR
A13: A | B13: DATA PEMILIH | E13: TPS 001 | F13: TPS 002 | G13: TPS 003 | H13: TPS 004 | I13: TPS 005 | J13: TPS 006 | K13: TPS 007 | L13: TPS 008 | M13: TPS 009 | N13: TPS 010 | O13: TPS 011 | P13: TPS 012 | Q13: TPS 013 | R13: TPS 014 | S13: TPS 015 | T13: TPS 016 | U13: TPS 017 | V13: TPS 018
B14: Jumlah Pemilih dalam Daftar Pemilih Tetap (DPT) | D14: LK | E14: 143 | F14: 141 | G14: 147 | H14: 147 | I14: 123 | J14: 113 | K14: 136 | L14: 122 | M14: 123 | N14: 129 | O14: 137 | P14: 145 | Q14: 131 | R14: 148 | S14: 133 | T14: 153 | U14: 111 | V14: 87 | W14: =SUM(E14:V14) -> 2369
D15: PR | E15: 149 | F15: 157 | G15: 145 | H15: 141 | I15: 133 | J15: 118 | K15: 126 | L15: 132 | M15: 128 | N15: 131 | O15: 148 | P15: 148 | Q15: 149 | R15: 134 | S15: 143 | T15: 128 | U15: 107 | V15: 79 | W15: =SUM(E15:V15) -> 2396
D16: JML | E16: =SUM(E14:E15) -> 292 | F16: =SUM(F14:F15) -> 298 | G16: =SUM(G14:G15) -> 292 | H16: =SUM(H14:H15) -> 288 | I16: =SUM(I14:I15) -> 256 | J16: =SUM(J14:J15) -> 231 | K16: =SUM(K14:K15) -> 262 | L16: =SUM(L14:L15) -> 254 | ... V16: =SUM(V14:V15) -> 166 | W16: =SUM(E16:V16) -> 4765
A18: B | B18: PENGGUNA HAK PILIH
B19: 1. | C19: Jumlah pengguna hak pilih dalam Daftar Pemilih Tetap (DPT) | D19: LK | E19: 118 | F19: 102 | G19: 113 | H19: 114 | I19: 85 | J19: 88 | K19: 106 | L19: 86 | M19: 82 | N19: 95 | O19: 95 | P19: 107 | Q19: 100 | R19: 108 | S19: 96 | T19: 108 | U19: 76 | V19: 68 | W19: =SUM(E19:V19) -> 1747
D20: PR | E20: 121 | F20: 123 | G20: 110 | H20: 113 | I20: 101 | J20: 91 | K20: 102 | L20: 97 | M20: 100 | N20: 101 | O20: 115 | P20: 114 | Q20: 122 | R20: 102 | S20: 114 | T20: 118 | U20: 83 | V20: 66 | W20: =SUM(E20:V20) -> 1893
D21: JML | E21: =SUM(E19:E20) -> 239 | F21: =SUM(F19:F20) -> 225 | G21: =SUM(G19:G20) -> 223 | H21: =SUM(H19:H20) -> 227 | I21: =SUM(I19:I20) -> 186 | J21: =SUM(J19:J20) -> 179 | K21: =SUM(K19:K20) -> 208 | L21: =SUM(L19:L20) -> 183 | ... V21: =SUM(V19:V20) -> 134 | W21: =SUM(E21:V21) -> 3640
B22: 2. | C22: Jumlah pengguna hak pilih dalam Daftar Pemilih Tambahan (DPTb) | D22: LK | E22: 0 | F22: 0 | G22: 0 | H22: 0 | I22: 0 | J22: 0 | K22: 0 | L22: 0 | M22: 0 | N22: 0 | O22: 0 | P22: 0 | Q22: 0 | R22: 0 | S22: 0 | T22: 0 | U22: 0 | V22: 0 | W22: =SUM(E22:V22) -> 0
D23: PR | E23: 0 | F23: 0 | G23: 0 | H23: 0 | I23: 0 | J23: 0 | K23: 0 | L23: 0 | M23: 0 | N23: 0 | O23: 0 | P23: 0 | Q23: 0 | R23: 0 | S23: 0 | T23: 0 | U23: 0 | V23: 0 | W23: =SUM(E23:V23) -> 0
D24: JML | E24: =SUM(E22:E23) -> 0 | F24: =SUM(F22:F23) -> 0 | G24: =SUM(G22:G23) -> 0 | H24: =SUM(H22:H23) -> 0 | I24: =SUM(I22:I23) -> 0 | J24: =SUM(J22:J23) -> 0 | K24: =SUM(K22:K23) -> 0 | L24: =SUM(L22:L23) -> 0 | ... V24: =SUM(V22:V23) -> 0 | W24: =SUM(E24:V24) -> 0
B25: 3. | C25: Jumlah pengguna hak pilih dalam Daftar Pemilih Khusus (DPK) | D25: LK | E25: 0 | F25: 0 | G25: 0 | H25: 1 | I25: 0 | J25: 0 | K25: 0 | L25: 0 | M25: 0 | N25: 0 | O25: 0 | P25: 0 | Q25: 0 | R25: 0 | S25: 0 | T25: 1 | U25: 0 | V25: 1 | W25: =SUM(E25:V25) -> 3
D26: PR | E26: 0 | F26: 0 | G26: 0 | H26: 0 | I26: 0 | J26: 0 | K26: 0 | L26: 0 | M26: 0 | N26: 0 | O26: 0 | P26: 0 | Q26: 0 | R26: 0 | S26: 0 | T26: 0 | U26: 0 | V26: 1 | W26: =SUM(E26:V26) -> 1
D27: JML | E27: =SUM(E25:E26) -> 0 | F27: =SUM(F25:F26) -> 0 | G27: =SUM(G25:G26) -> 0 | H27: =SUM(H25:H26) -> 1 | I27: =SUM(I25:I26) -> 0 | J27: =SUM(J25:J26) -> 0 | K27: =SUM(K25:K26) -> 0 | L27: =SUM(L25:L26) -> 0 | ... V27: =SUM(V25:V26) -> 2 | W27: =SUM(E27:V27) -> 4
B28: 4. | C28: Jumlah Pengguna Hak Pilih (B.1+B.2+B.3) | D28: LK | E28: =SUM(E19,E22,E25) -> 118 | F28: =SUM(F19,F22,F25) -> 102 | G28: =SUM(G19,G22,G25) -> 113 | H28: =SUM(H19,H22,H25) -> 115 | I28: =SUM(I19,I22,I25) -> 85 | J28: =SUM(J19,J22,J25) -> 88 | K28: =SUM(K19,K22,K25) -> 106 | L28: =SUM(L19,L22,L25) -> 86 | ... V28: =SUM(V19,V22,V25) -> 69 | W28: =SUM(E28:V28) -> 1750
D29: PR | E29: =SUM(E20,E23,E26) -> 121 | F29: =SUM(F20,F23,F26) -> 123 | G29: =SUM(G20,G23,G26) -> 110 | H29: =SUM(H20,H23,H26) -> 113 | I29: =SUM(I20,I23,I26) -> 101 | J29: =SUM(J20,J23,J26) -> 91 | K29: =SUM(K20,K23,K26) -> 102 | L29: =SUM(L20,L23,L26) -> 97 | ... V29: =SUM(V20,V23,V26) -> 67 | W29: =SUM(E29:V29) -> 1894
D30: JML | E30: =SUM(E28:E29) -> 239 | F30: =SUM(F28:F29) -> 225 | G30: =SUM(G28:G29) -> 223 | H30: =SUM(H28:H29) -> 228 | I30: =SUM(I28:I29) -> 186 | J30: =SUM(J28:J29) -> 179 | K30: =SUM(K28:K29) -> 208 | L30: =SUM(L28:L29) -> 183 | ... V30: =SUM(V28:V29) -> 136 | W30: =SUM(E30:V30) -> 3644
A32: II | B32: DATA PENGGUNAAN SURAT SUARA
A33: 1 | B33: Jumlah surat suara yang diterima, termasuk surat suara cadangan 2,5% dari DPT | E33: 298 | F33: 304 | G33: 298 | H33: 299 | I33: 264 | J33: 236 | K33: 268 | L33: 260 | M33: 257 | N33: 266 | O33: 291 | P33: 229 | Q33: 286 | R33: 288 | S33: 282 | T33: 286 | U33: 216 | V33: 170 | W33: =SUM(E33:V33) -> 4798
A34: 2 | B34: Jumlah surat suara yang digunakan | E34: 239 | F34: 225 | G34: 223 | H34: 228 | I34: 186 | J34: 179 | K34: 208 | L34: 183 | M34: 182 | N34: 196 | O34: 210 | P34: 221 | Q34: 222 | R34: 210 | S34: 210 | T34: 227 | U34: 159 | V34: 136 | W34: =SUM(E34:V34) -> 3644
A35: 3 | B35: Jumlah surat suara dikembalikan oleh pemilih (karena rusak atau keliru coblos) | E35: 0 | F35: 0 | G35: 0 | H35: 3 | I35: 0 | J35: 0 | K35: 0 | L35: 0 | M35: 3 | N35: 0 | O35: 0 | P35: 0 | Q35: 0 | R35: 1 | S35: 4 | T35: 0 | U35: 0 | V35: 0 | W35: =SUM(E35:V35) -> 11
A36: 4 | B36: Jumlah surat suara yang tidak digunakan/tidak terpakai, termasuk sisa surat suara cadangan | E36: =E33-(E34+E35) -> 59 | F36: =F33-(F34+F35) -> 79 | G36: =G33-(G34+G35) -> 75 | H36: =H33-(H34+H35) -> 68 | I36: =I33-(I34+I35) -> 78 | J36: =J33-(J34+J35) -> 57 | K36: =K33-(K34+K35) -> 60 | L36: =L33-(L34+L35) -> 77 | ... V36: =V33-(V34+V35) -> 34 | W36: =SUM(E36:V36) -> 1143
A38: III | B38: DATA PEMILIH DISABILITAS
B39: Jumlah seluruh Pemilih disabilitas yang menggunakan hak pilih | D39: LK | E39: 0 | F39: 0 | G39: 0 | H39: 2 | I39: 0 | J39: 0 | K39: 0 | L39: 0 | M39: 0 | N39: 0 | O39: 0 | P39: 1 | Q39: 0 | R39: 0 | S39: 0 | T39: 1 | U39: 0 | V39: 0 | W39: =SUM(E39:V39) -> 4
D40: PR | E40: 0 | F40: 0 | G40: 0 | H40: 1 | I40: 1 | J40: 0 | K40: 0 | L40: 0 | M40: 0 | N40: 0 | O40: 0 | P40: 1 | Q40: 0 | R40: 0 | S40: 0 | T40: 1 | U40: 0 | V40: 0 | W40: =SUM(E40:V40) -> 4
D41: JML | E41: =SUM(E39:E40) -> 0 | F41: =SUM(F39:F40) -> 0 | G41: =SUM(G39:G40) -> 0 | H41: =SUM(H39:H40) -> 3 | I41: =SUM(I39:I40) -> 1 | J41: =SUM(J39:J40) -> 0 | K41: =SUM(K39:K40) -> 0 | L41: =SUM(L39:L40) -> 0 | ... V41: =SUM(V39:V40) -> 0 | W41: =SUM(E41:V41) -> 8
A43: IV | B43: DATA RINCIAN PEROLEHAN SUARA PASANGAN CALON BUPATI DAN WAKIL BUPATI
A44: NOMOR DAN NAMA CALON
A45: A.1 | B45: 1. | C45: Partai Kebangkitan Bangsa | E45: 4 | F45: 10 | G45: 8 | H45: 4 | I45: 10 | J45: 7 | K45: 16 | L45: 7 | M45: 10 | N45: 8 | O45: 7 | P45: 3 | Q45: 13 | R45: 5 | S45: 8 | T45: 2 | U45: 1 | V45: 4 | W45: =SUM(E45:V45) -> 127
A46: A.2 | C46: 1. H. MUHAMMAD ALI MAHRUS, S.H.I., M.H | E46: 42 | F46: 29 | G46: 10 | H46: 36 | I46: 46 | J46: 79 | K46: 65 | L46: 35 | M46: 18 | N46: 20 | O46: 12 | P46: 20 | Q46: 16 | R46: 7 | S46: 20 | T46: 3 | U46: 6 | V46: 124 | W46: =SUM(E46:V46) -> 588
C47: 2. TUPANG SOEDARGO | E47: 0 | F47: 1 | G47: 8 | H47: 1 | I47: 1 | J47: 0 | K47: 1 | L47: 2 | M47: 0 | N47: 2 | O47: 2 | P47: 1 | Q47: 0 | R47: 0 | S47: 0 | T47: 14 | U47: 13 | V47: 1 | W47: =SUM(E47:V47) -> 47
C48: 3. Hj. KHOLIFATUL HASANAH | E48: 1 | F48: 0 | G48: 0 | H48: 1 | I48: 0 | J48: 1 | K48: 1 | L48: 0 | M48: 0 | N48: 2 | O48: 0 | P48: 1 | Q48: 1 | R48: 0 | S48: 2 | T48: 0 | U48: 0 | V48: 0 | W48: =SUM(E48:V48) -> 10
C49: 4. FUAD HUMAIDI, S.H.I. | E49: 0 | F49: 0 | G49: 1 | H49: 1 | I49: 0 | J49: 1 | K49: 0 | L49: 1 | M49: 0 | N49: 0 | O49: 0 | P49: 0 | Q49: 0 | R49: 0 | S49: 0 | T49: 0 | U49: 0 | V49: 0 | W49: =SUM(E49:V49) -> 4
C50: 5. ENI WIJI LESTARI | E50: 1 | F50: 0 | G50: 0 | H50: 1 | I50: 0 | J50: 0 | K50: 0 | L50: 0 | M50: 0 | N50: 0 | O50: 0 | P50: 0 | Q50: 0 | R50: 0 | S50: 0 | T50: 2 | U50: 0 | V50: 0 | W50: =SUM(E50:V50) -> 4
C51: 6. SONNY AGUS SETIAWAN | E51: 0 | F51: 0 | G51: 1 | H51: 0 | I51: 0 | J51: 0 | K51: 0 | L51: 0 | M51: 0 | N51: 0 | O51: 0 | P51: 0 | Q51: 0 | R51: 0 | S51: 0 | T51: 0 | U51: 0 | V51: 1 | W51: =SUM(E51:V51) -> 2
...

Sheet BAYU
C2: Kecamatan
C3: Kabupaten | D3: BANYUWANGI
C4: Provinsi | D4: JAWA TIMUR
C9: Kelurahan
A12: I | B12: DATA PEMILIH DAN PENGGUNAAN HAK PILIH | AB12: JUMLAH AKHIR
A13: A | B13: DATA PEMILIH | E13: TPS 001 | F13: TPS 002 | G13: TPS 003 | H13: TPS 004 | I13: TPS 005 | J13: TPS 006 | K13: TPS 007 | L13: TPS 008 | M13: TPS 009 | N13: TPS 010 | O13: TPS 011 | P13: TPS 012 | Q13: TPS 013 | R13: TPS 014 | S13: TPS 015 | T13: TPS 016 | U13: TPS 017 | V13: TPS 018 | W13: TPS 019 | X13: TPS 020 | Y13: TPS 021 | Z13: TPS 022 | AA13: TPS 023
B14: Jumlah Pemilih dalam Daftar Pemilih Tetap (DPT) | D14: LK | E14: 109 | F14: 118 | G14: 129 | H14: 125 | I14: 117 | J14: 132 | K14: 139 | L14: 132 | M14: 137 | N14: 140 | O14: 139 | P14: 128 | Q14: 127 | R14: 131 | S14: 83 | T14: 133 | U14: 139 | V14: 149 | W14: 140 | X14: 152 | Y14: 150 | Z14: 150 | AA14: 147 | AB14: =SUM(E14:AA14) -> 3046
D15: PR | E15: 118 | F15: 140 | G15: 133 | H15: 136 | I15: 140 | J15: 123 | K15: 131 | L15: 146 | M15: 141 | N15: 148 | O15: 135 | P15: 134 | Q15: 123 | R15: 117 | S15: 94 | T15: 151 | U15: 147 | V15: 139 | W15: 151 | X15: 144 | Y15: 144 | Z15: 148 | AA15: 146 | AB15: =SUM(E15:AA15) -> 3129
D16: JML | E16: =SUM(E14:E15) -> 227 | F16: =SUM(F14:F15) -> 258 | G16: =SUM(G14:G15) -> 262 | H16: =SUM(H14:H15) -> 261 | I16: =SUM(I14:I15) -> 257 | J16: =SUM(J14:J15) -> 255 | K16: =SUM(K14:K15) -> 270 | L16: =SUM(L14:L15) -> 278 | ... AA16: =SUM(AA14:AA15) -> 293 | AB16: =SUM(E16:AA16) -> 6175
A18: B | B18: PENGGUNA HAK PILIH
B19: 1. | C19: Jumlah pengguna hak pilih dalam Daftar Pemilih Tetap (DPT) | D19: LK | E19: 95 | F19: 107 | G19: 92 | H19: 103 | I19: 96 | J19: 93 | K19: 100 | L19: 98 | M19: 94 | N19: 108 | O19: 97 | P19: 74 | Q19: 92 | R19: 100 | S19: 66 | T19: 83 | U19: 94 | V19: 103 | W19: 103 | X19: 122 | Y19: 117 | Z19: 121 | AA19: 108 | AB19: =SUM(E19:AA19) -> 2266
D20: PR | E20: 96 | F20: 87 | G20: 105 | H20: 107 | I20: 119 | J20: 106 | K20: 105 | L20: 117 | M20: 107 | N20: 120 | O20: 101 | P20: 88 | Q20: 93 | R20: 100 | S20: 81 | T20: 117 | U20: 116 | V20: 115 | W20: 120 | X20: 106 | Y20: 119 | Z20: 106 | AA20: 109 | AB20: =SUM(E20:AA20) -> 2440
D21: JML | E21: =SUM(E19:E20) -> 191 | F21: =SUM(F19:F20) -> 194 | G21: =SUM(G19:G20) -> 197 | H21: =SUM(H19:H20) -> 210 | I21: =SUM(I19:I20) -> 215 | J21: =SUM(J19:J20) -> 199 | K21: =SUM(K19:K20) -> 205 | L21: =SUM(L19:L20) -> 215 | ... AA21: =SUM(AA19:AA20) -> 217 | AB21: =SUM(E21:AA21) -> 4706
B22: 2. | C22: Jumlah pengguna hak pilih dalam Daftar Pemilih Tambahan (DPTb) | D22: LK | E22: 0 | F22: 0 | G22: 0 | H22: 0 | I22: 0 | J22: 0 | K22: 0 | L22: 0 | M22: 0 | N22: 0 | O22: 1 | P22: 0 | Q22: 0 | R22: 0 | S22: 0 | T22: 0 | U22: 0 | V22: 0 | W22: 0 | X22: 0 | Y22: 0 | Z22: 0 | AA22: 0 | AB22: =SUM(E22:AA22) -> 1
D23: PR | E23: 0 | F23: 0 | G23: 0 | H23: 0 | I23: 0 | J23: 0 | K23: 0 | L23: 0 | M23: 0 | N23: 0 | O23: 0 | P23: 0 | Q23: 0 | R23: 0 | S23: 0 | T23: 0 | U23: 0 | V23: 0 | W23: 0 | X23: 0 | Y23: 0 | Z23: 0 | AA23: 0 | AB23: =SUM(E23:AA23) -> 0
D24: JML | E24: =SUM(E22:E23) -> 0 | F24: =SUM(F22:F23) -> 0 | G24: =SUM(G22:G23) -> 0 | H24: =SUM(H22:H23) -> 0 | I24: =SUM(I22:I23) -> 0 | J24: =SUM(J22:J23) -> 0 | K24: =SUM(K22:K23) -> 0 | L24: =SUM(L22:L23) -> 0 | ... AA24: =SUM(AA22:AA23) -> 0 | AB24: =SUM(E24:AA24) -> 1
B25: 3. | C25: Jumlah pengguna hak pilih dalam Daftar Pemilih Khusus (DPK) | D25: LK | E25: 0 | F25: 0 | G25: 1 | H25: 3 | I25: 0 | J25: 0 | K25: 0 | L25: 0 | M25: 0 | N25: 0 | O25: 0 | P25: 0 | Q25: 0 | R25: 0 | S25: 1 | T25: 2 | U25: 1 | V25: 1 | W25: 0 | X25: 0 | Y25: 2 | Z25: 1 | AA25: 0 | AB25: =SUM(E25:AA25) -> 12
D26: PR | E26: 0 | F26: 0 | G26: 0 | H26: 1 | I26: 0 | J26: 0 | K26: 0 | L26: 1 | M26: 1 | N26: 1 | O26: 0 | P26: 0 | Q26: 0 | R26: 0 | S26: 1 | T26: 1 | U26: 0 | V26: 1 | W26: 1 | X26: 0 | Y26: 0 | Z26: 1 | AA26: 0 | AB26: =SUM(E26:AA26) -> 9
D27: JML | E27: =SUM(E25:E26) -> 0 | F27: =SUM(F25:F26) -> 0 | G27: =SUM(G25:G26) -> 1 | H27: =SUM(H25:H26) -> 4 | I27: =SUM(I25:I26) -> 0 | J27: =SUM(J25:J26) -> 0 | K27: =SUM(K25:K26) -> 0 | L27: =SUM(L25:L26) -> 1 | ... AA27: =SUM(AA25:AA26) -> 0 | AB27: =SUM(E27:AA27) -> 21
B28: 4. | C28: Jumlah Pengguna Hak Pilih (B.1+B.2+B.3) | D28: LK | E28: =SUM(E19,E22,E25) -> 95 | F28: =SUM(F19,F22,F25) -> 107 | G28: =SUM(G19,G22,G25) -> 93 | H28: =SUM(H19,H22,H25) -> 106 | I28: =SUM(I19,I22,I25) -> 96 | J28: =SUM(J19,J22,J25) -> 93 | K28: =SUM(K19,K22,K25) -> 100 | L28: =SUM(L19,L22,L25) -> 98 | ... AA28: =SUM(AA19,AA22,AA25) -> 108 | AB28: =SUM(E28:AA28) -> 2279
D29: PR | E29: =SUM(E20,E23,E26) -> 96 | F29: =SUM(F20,F23,F26) -> 87 | G29: =SUM(G20,G23,G26) -> 105 | H29: =SUM(H20,H23,H26) -> 108 | I29: =SUM(I20,I23,I26) -> 119 | J29: =SUM(J20,J23,J26) -> 106 | K29: =SUM(K20,K23,K26) -> 105 | L29: =SUM(L20,L23,L26) -> 118 | ... AA29: =SUM(AA20,AA23,AA26) -> 109 | AB29: =SUM(E29:AA29) -> 2449
D30: JML | E30: =SUM(E28:E29) -> 191 | F30: =SUM(F28:F29) -> 194 | G30: =SUM(G28:G29) -> 198 | H30: =SUM(H28:H29) -> 214 | I30: =SUM(I28:I29) -> 215 | J30: =SUM(J28:J29) -> 199 | K30: =SUM(K28:K29) -> 205 | L30: =SUM(L28:L29) -> 216 | ... AA30: =SUM(AA28:AA29) -> 217 | AB30: =SUM(E30:AA30) -> 4728
A32: II | B32: DATA PENGGUNAAN SURAT SUARA
A33: 1 | B33: Jumlah surat suara yang diterima, termasuk surat suara cadangan 2,5% dari DPT | E33: 202 | F33: 264 | G33: 268 | H33: 267 | I33: 263 | J33: 261 | K33: 276 | L33: 284 | M33: 283 | N33: 281 | O33: 280 | P33: 267 | Q33: 255 | R33: 253 | S33: 181 | T33: 290 | U33: 292 | V33: 294 | W33: 297 | X33: 312 | Y33: 300 | Z33: 304 | AA33: 298 | AB33: =SUM(E33:AA33) -> 6272
A34: 2 | B34: Jumlah surat suara yang digunakan | E34: 191 | F34: 194 | G34: 198 | H34: 214 | I34: 215 | J34: 199 | K34: 205 | L34: 216 | M34: 202 | N34: 229 | O34: 199 | P34: 162 | Q34: 185 | R34: 200 | S34: 149 | T34: 203 | U34: 211 | V34: 220 | W34: 224 | X34: 228 | Y34: 238 | Z34: 229 | AA34: 217 | AB34: =SUM(E34:AA34) -> 4728
A35: 3 | B35: Jumlah surat suara dikembalikan oleh pemilih (karena rusak atau keliru coblos) | E35: 0 | F35: 0 | G35: 0 | H35: 0 | I35: 0 | J35: 1 | K35: 0 | L35: 0 | M35: 0 | N35: 0 | O35: 0 | P35: 0 | Q35: 0 | R35: 0 | S35: 0 | T35: 1 | U35: 0 | V35: 0 | W35: 0 | X35: 0 | Y35: 0 | Z35: 0 | AA35: 0 | AB35: =SUM(E35:AA35) -> 2
A36: 4 | B36: Jumlah surat suara yang tidak digunakan/tidak terpakai, termasuk sisa surat suara cadangan | E36: =E33-(E34+E35) -> 11 | F36: =F33-(F34+F35) -> 70 | G36: =G33-(G34+G35) -> 70 | H36: =H33-(H34+H35) -> 53 | I36: =I33-(I34+I35) -> 48 | J36: =J33-(J34+J35) -> 61 | K36: =K33-(K34+K35) -> 71 | L36: =L33-(L34+L35) -> 68 | ... AA36: =AA33-(AA34+AA35) -> 81 | AB36: =SUM(E36:AA36) -> 1542
A38: III | B38: DATA PEMILIH DISABILITAS
B39: Jumlah seluruh Pemilih disabilitas yang menggunakan hak pilih | D39: LK | E39: 0 | F39: 0 | G39: 1 | H39: 0 | I39: 0 | J39: 0 | K39: 0 | L39: 0 | M39: 0 | N39: 0 | O39: 0 | P39: 0 | Q39: 0 | R39: 0 | S39: 0 | T39: 0 | U39: 0 | V39: 0 | W39: 0 | X39: 0 | Y39: 0 | Z39: 0 | AA39: 0 | AB39: =SUM(E39:AA39) -> 1
D40: PR | E40: 0 | F40: 0 | G40: 0 | H40: 0 | I40: 0 | J40: 0 | K40: 0 | L40: 0 | M40: 0 | N40: 0 | O40: 0 | P40: 0 | Q40: 0 | R40: 0 | S40: 0 | T40: 0 | U40: 0 | V40: 0 | W40: 0 | X40: 0 | Y40: 0 | Z40: 0 | AA40: 1 | AB40: =SUM(E40:AA40) -> 1
D41: JML | E41: =SUM(E39:E40) -> 0 | F41: =SUM(F39:F40) -> 0 | G41: =SUM(G39:G40) -> 1 | H41: =SUM(H39:H40) -> 0 | I41: =SUM(I39:I40) -> 0 | J41: =SUM(J39:J40) -> 0 | K41: =SUM(K39:K40) -> 0 | L41: =SUM(L39:L40) -> 0 | ... AA41: =SUM(AA39:AA40) -> 1 | AB41: =SUM(E41:AA41) -> 2
A43: IV | B43: DATA RINCIAN PEROLEHAN SUARA PASANGAN CALON BUPATI DAN WAKIL BUPATI
A44: NOMOR DAN NAMA CALON
A45: A.1 | B45: 1. | C45: Partai Kebangkitan Bangsa | E45: 2 | F45: 10 | G45: 10 | H45: 8 | I45: 12 | J45: 9 | K45: 4 | L45: 19 | M45: 9 | N45: 3 | O45: 3 | P45: 5 | Q45: 17 | R45: 5 | S45: 2 | T45: 15 | U45: 19 | V45: 19 | W45: 8 | X45: 6 | Y45: 8 | Z45: 9 | AA45: 5 | AB45: =SUM(E45:AA45) -> 207
A46: A.2 | C46: 1. H. MUHAMMAD ALI MAHRUS, S.H.I., M.H | E46: 12 | F46: 70 | G46: 8 | H46: 29 | I46: 23 | J46: 10 | K46: 7 | L46: 36 | M46: 42 | N46: 4 | O46: 2 | P46: 12 | Q46: 26 | R46: 24 | S46: 8 | T46: 26 | U46: 37 | V46: 33 | W46: 20 | X46: 26 | Y46: 8 | Z46: 14 | AA46: 20 | AB46: =SUM(E46:AA46) -> 497
C47: 2. TUPANG SOEDARGO | E47: 2 | F47: 4 | G47: 0 | H47: 15 | I47: 22 | J47: 9 | K47: 6 | L47: 4 | M47: 2 | N47: 3 | O47: 20 | P47: 12 | Q47: 38 | R47: 17 | S47: 24 | T47: 13 | U47: 8 | V47: 9 | W47: 2 | X47: 4 | Y47: 1 | Z47: 0 | AA47: 8 | AB47: =SUM(E47:AA47) -> 223
C48: 3. Hj. KHOLIFATUL HASANAH | E48: 1 | H48: 2 | I48: 1 | J48: 1 | K48: 0 | L48: 0 | M48: 0 | N48: 2 | O48: 0 | P48: 0 | Q48: 2 | R48: 1 | U48: 2 | V48: 0 | W48: 1 | X48: 0 | Y48: 0 | Z48: 0 | AA48: 1 | AB48: =SUM(E48:AA48) -> 14
C49: 4. FUAD HUMAIDI, S.H.I. | E49: 0 | G49: 1 | H49: 0 | I49: 1 | J49: 0 | L49: 1 | M49: 0 | N49: 5 | O49: 0 | P49: 0 | U49: 0 | V49: 0 | W49: 1 | X49: 1 | Y49: 1 | Z49: 0 | AA49: 1 | AB49: =SUM(E49:AA49) -> 12
C50: 5. ENI WIJI LESTARI | H50: 0 | I50: 0 | J50: 0 | L50: 0 | M50: 0 | N50: 0 | O50: 0 | P50: 0 | V50: 0 | W50: 0 | X50: 0 | Y50: 0 | Z50: 0 | AA50: 0 | AB50: =SUM(E50:AA50) -> 0
C51: 6. SONNY AGUS SETIAWAN | G51: 1 | H51: 0 | I51: 0 | J51: 0 | L51: 0 | M51: 0 | N51: 0 | O51: 0 | P51: 0 | U51: 1 | V51: 0 | W51: 1 | X51: 0 | Y51: 1 | Z51: 3 | AA51: 0 | AB51: =SUM(E51:AA51) -> 7
...

Sheet SUMBERARUM
C2: Kecamatan
C3: Kabupaten | D3: BANYUWANGI
