Workbook

Sheet DPRD KABUPATEN
C8: Kecamatan | D8: GLAGAH
C9: Kabupaten | D9: BANYUWANGI
C10: Provinsi | D10: JAWA TIMUR
A12: I | B12: DATA PEMILIH DAN PENGGUNAAN HAK PILIH | E12: JUMLAH AKHIR
A13: A | B13: DATA PEMILIH
B14: Jumlah Pemilih dalam Daftar Pemilih Tetap (DPT) | D14: LK | E14: =BAKUNGAN!U14+BANJARSARI!X14+REJOSARI!N14+KEMIREN!M14+OLEHSARI!N14+GLAGAH!M14+PASPAN!P14+TAMANSURUH!S14+KENJO!K14+KAMPUNGANYAR!T14 -> 13866
D15: PR | E15: =BAKUNGAN!U15+BANJARSARI!X15+REJOSARI!N15+KEMIREN!M15+OLEHSARI!N15+GLAGAH!M15+PASPAN!P15+TAMANSURUH!S15+KENJO!K15+KAMPUNGANYAR!T15 -> 14693
D16: JML | E16: =SUM(E14:E15) -> 28559
A18: B | B18: PENGGUNA HAK PILIH
B19: 1. | C19: Jumlah pengguna hak pilih dalam Daftar Pemilih Tetap (DPT) | D19: LK | E19: =BAKUNGAN!U19+BANJARSARI!X19+REJOSARI!N19+KEMIREN!M19+OLEHSARI!N19+GLAGAH!M19+PASPAN!P19+TAMANSURUH!S19+KENJO!K19+KAMPUNGANYAR!T19 -> 11310
D20: PR | E20: =BAKUNGAN!U20+BANJARSARI!X20+REJOSARI!N20+KEMIREN!M20+OLEHSARI!N20+GLAGAH!M20+PASPAN!P20+TAMANSURUH!S20+KENJO!K20+KAMPUNGANYAR!T20 -> 12650
D21: JML | E21: =SUM(E19:E20) -> 23960
B22: 2. | C22: Jumlah pengguna hak pilih dalam Daftar Pemilih Tambahan (DPTb) | D22: LK | E22: =BAKUNGAN!U22+BANJARSARI!X22+REJOSARI!N22+KEMIREN!M22+OLEHSARI!N22+GLAGAH!M22+PASPAN!P22+TAMANSURUH!S22+KENJO!K22+KAMPUNGANYAR!T22 -> 30
D23: PR | E23: =BAKUNGAN!U23+BANJARSARI!X23+REJOSARI!N23+KEMIREN!M23+OLEHSARI!N23+GLAGAH!M23+PASPAN!P23+TAMANSURUH!S23+KENJO!K23+KAMPUNGANYAR!T23 -> 52
D24: JML | E24: =SUM(E22:E23) -> 82
B25: 3. | C25: Jumlah pengguna hak pilih dalam Daftar Pemilih Khusus (DPK) | D25: LK | E25: =BAKUNGAN!U25+BANJARSARI!X25+REJOSARI!N25+KEMIREN!M25+OLEHSARI!N25+GLAGAH!M25+PASPAN!P25+TAMANSURUH!S25+KENJO!K25+KAMPUNGANYAR!T25 -> 129
D26: PR | E26: =BAKUNGAN!U26+BANJARSARI!X26+REJOSARI!N26+KEMIREN!M26+OLEHSARI!N26+GLAGAH!M26+PASPAN!P26+TAMANSURUH!S26+KENJO!K26+KAMPUNGANYAR!T26 -> 169
D27: JML | E27: =SUM(E25:E26) -> 298
B28: 4. | C28: Jumlah Pengguna Hak Pilih (B.1+B.2+B.3) | D28: LK | E28: =E19+E22+E25 -> 11469
D29: PR | E29: =E20+E23+E26 -> 12871
D30: JML | E30: =SUM(E28:E29) -> 24340
A32: II | B32: DATA PENGGUNAAN SURAT SUARA
A33: 1 | B33: Jumlah surat suara yang diterima, termasuk surat suara cadangan 2% dari DPT | E33: =BAKUNGAN!U33+BANJARSARI!X33+REJOSARI!N33+KEMIREN!M33+OLEHSARI!N33+GLAGAH!M33+PASPAN!P33+TAMANSURUH!S33+KENJO!K33+KAMPUNGANYAR!T33 -> 29209
A34: 2 | B34: Jumlah surat suara yang digunakan | E34: =BAKUNGAN!U34+BANJARSARI!X34+REJOSARI!N34+KEMIREN!M34+OLEHSARI!N34+GLAGAH!M34+PASPAN!P34+TAMANSURUH!S34+KENJO!K34+KAMPUNGANYAR!T34 -> 24340
A35: 3 | B35: Jumlah surat suara dikembalikan oleh pemilih (karena rusak atau keliru coblos) | E35: =BAKUNGAN!U35+BANJARSARI!X35+REJOSARI!N35+KEMIREN!M35+OLEHSARI!N35+GLAGAH!M35+PASPAN!P35+TAMANSURUH!S35+KENJO!K35+KAMPUNGANYAR!T35 -> 35
A36: 4 | B36: Jumlah surat suara yang tidak digunakan/tidak terpakai, termasuk sisa surat suara cadangan | E36: =E33-(E34+E35) -> 4834
A38: III | B38: DATA PEMILIH DISABILITAS
B39: Jumlah seluruh Pemilih disabilitas yang menggunakan hak pilih | D39: LK | E39: =BAKUNGAN!U39+BANJARSARI!X39+REJOSARI!N39+KEMIREN!M39+OLEHSARI!N39+GLAGAH!M39+PASPAN!P39+TAMANSURUH!S39+KENJO!K39+KAMPUNGANYAR!T39 -> 25
D40: PR | E40: =BAKUNGAN!U40+BANJARSARI!X40+REJOSARI!N40+KEMIREN!M40+OLEHSARI!N40+GLAGAH!M40+PASPAN!P40+TAMANSURUH!S40+KENJO!K40+KAMPUNGANYAR!T40 -> 23
D41: JML | E41: =SUM(E39:E40) -> 48
A43: IV | B43: DATA RINCIAN PEROLEHAN SUARA PASANGAN CALON BUPATI DAN WAKIL BUPATI
A44: NOMOR DAN NAMA CALON
A45: A.1 | B45: 1. | C45: Partai Kebangkitan Bangsa | E45: =BAKUNGAN!U45+BANJARSARI!X45+REJOSARI!N45+KEMIREN!M45+OLEHSARI!N45+GLAGAH!M45+PASPAN!P45+TAMANSURUH!S45+KENJO!K45+KAMPUNGANYAR!T45 -> 642
A46: A.2 | C46: 1. ANITA RANI, S.H. | E46: =BAKUNGAN!U46+BANJARSARI!X46+REJOSARI!N46+KEMIREN!M46+OLEHSARI!N46+GLAGAH!M46+PASPAN!P46+TAMANSURUH!S46+KENJO!K46+KAMPUNGANYAR!T46 -> 530
C47: 2. ANISAH MAHSUNAH, S.E. | E47: =BAKUNGAN!U47+BANJARSARI!X47+REJOSARI!N47+KEMIREN!M47+OLEHSARI!N47+GLAGAH!M47+PASPAN!P47+TAMANSURUH!S47+KENJO!K47+KAMPUNGANYAR!T47 -> 184
C48: 3. SENARI, S.Sos. | E48: =BAKUNGAN!U48+BANJARSARI!X48+REJOSARI!N48+KEMIREN!M48+OLEHSARI!N48+GLAGAH!M48+PASPAN!P48+TAMANSURUH!S48+KENJO!K48+KAMPUNGANYAR!T48 -> 298
C49: 4. VERAGAWATI, S.H. | E49: =BAKUNGAN!U49+BANJARSARI!X49+REJOSARI!N49+KEMIREN!M49+OLEHSARI!N49+GLAGAH!M49+PASPAN!P49+TAMANSURUH!S49+KENJO!K49+KAMPUNGANYAR!T49 -> 14
C50: 5. KURDI EHSAN | E50: =BAKUNGAN!U50+BANJARSARI!X50+REJOSARI!N50+KEMIREN!M50+OLEHSARI!N50+GLAGAH!M50+PASPAN!P50+TAMANSURUH!S50+KENJO!K50+KAMPUNGANYAR!T50 -> 23
C51: 6. BONDAN ARDYWIJAYA | E51: =BAKUNGAN!U51+BANJARSARI!X51+REJOSARI!N51+KEMIREN!M51+OLEHSARI!N51+GLAGAH!M51+PASPAN!P51+TAMANSURUH!S51+KENJO!K51+KAMPUNGANYAR!T51 -> 295
A52: B | B52: JUMLAH SUARA SAH PARTAI POLITIK DAN CALON (A1 + A2) | E52: =SUM(E45:E51) -> 1986
...

Sheet BAKUNGAN
C2: Kecamatan | D2: GLAGAH
C3: Kabupaten | D3: BANYUWANGI
C4: Provinsi | D4: JAWA TIMUR
C9: Kelurahan | D9: BAKUNGAN
A12: I | B12: DATA PEMILIH DAN PENGGUNAAN HAK PILIH | U12: JUMLAH AKHIR
A13: A | B13: DATA PEMILIH | E13: TPS 001 | F13: TPS 002 | G13: TPS 003 | H13: TPS 004 | I13: TPS 005 | J13: TPS 006 | K13: TPS 007 | L13: TPS 008 | M13: TPS 009 | N13: TPS 010 | O13: TPS 011 | P13: TPS 012 | Q13: TPS 013 | R13: TPS 014 | S13: TPS 015 | T13: TPS 016
B14: Jumlah Pemilih dalam Daftar Pemilih Tetap (DPT) | D14: LK | E14: 119 | F14: 137 | G14: 132 | H14: 130 | I14: 138 | J14: 132 | K14: 139 | L14: 131 | M14: 97 | N14: 134 | O14: 112 | P14: 111 | Q14: 136 | R14: 120 | S14: 140 | T14: 106 | U14: =SUM(E14:T14) -> 2014
D15: PR | E15: 147 | F15: 142 | G15: 128 | H15: 137 | I15: 156 | J15: 166 | K15: 142 | L15: 128 | M15: 93 | N15: 145 | O15: 123 | P15: 119 | Q15: 137 | R15: 111 | S15: 159 | T15: 104 | U15: =SUM(E15:T15) -> 2137
D16: JML | E16: =SUM(E14:E15) -> 266 | F16: =SUM(F14:F15) -> 279 | G16: =SUM(G14:G15) -> 260 | H16: =SUM(H14:H15) -> 267 | I16: =SUM(I14:I15) -> 294 | J16: =SUM(J14:J15) -> 298 | K16: =SUM(K14:K15) -> 281 | L16: =SUM(L14:L15) -> 259 | ... T16: =SUM(T14:T15) -> 210 | U16: =SUM(E16:T16) -> 4151
A18: B | B18: PENGGUNA HAK PILIH
B19: 1. | C19: Jumlah pengguna hak pilih dalam Daftar Pemilih Tetap (DPT) | D19: LK | E19: 93 | F19: 110 | G19: 101 | H19: 91 | I19: 95 | J19: 93 | K19: 111 | L19: 94 | M19: 75 | N19: 112 | O19: 83 | P19: 83 | Q19: 92 | R19: 92 | S19: 110 | T19: 90 | U19: =SUM(E19:T19) -> 1525
D20: PR | E20: 122 | F20: 117 | G20: 107 | H20: 129 | I20: 133 | J20: 131 | K20: 122 | L20: 113 | M20: 77 | N20: 127 | O20: 95 | P20: 99 | Q20: 105 | R20: 85 | S20: 119 | T20: 88 | U20: =SUM(E20:T20) -> 1769
D21: JML | E21: =SUM(E19:E20) -> 215 | F21: =SUM(F19:F20) -> 227 | G21: =SUM(G19:G20) -> 208 | H21: =SUM(H19:H20) -> 220 | I21: =SUM(I19:I20) -> 228 | J21: =SUM(J19:J20) -> 224 | K21: =SUM(K19:K20) -> 233 | L21: =SUM(L19:L20) -> 207 | ... T21: =SUM(T19:T20) -> 178 | U21: =SUM(E21:T21) -> 3294
B22: 2. | C22: Jumlah pengguna hak pilih dalam Daftar Pemilih Tambahan (DPTb) | D22: LK | E22: 0 | F22: 0 | G22: 0 | H22: 0 | I22: 0 | J22: 0 | K22: 0 | L22: 0 | M22: 0 | N22: 1 | O22: 0 | P22: 2 | Q22: 0 | R22: 0 | S22: 0 | T22: 0 | U22: =SUM(E22:T22) -> 3
D23: PR | E23: 0 | F23: 0 | G23: 0 | H23: 0 | I23: 0 | J23: 0 | K23: 0 | L23: 0 | M23: 0 | N23: 2 | O23: 0 | P23: 2 | Q23: 3 | R23: 0 | S23: 0 | T23: 0 | U23: =SUM(E23:T23) -> 7
D24: JML | E24: =SUM(E22:E23) -> 0 | F24: =SUM(F22:F23) -> 0 | G24: =SUM(G22:G23) -> 0 | H24: =SUM(H22:H23) -> 0 | I24: =SUM(I22:I23) -> 0 | J24: =SUM(J22:J23) -> 0 | K24: =SUM(K22:K23) -> 0 | L24: =SUM(L22:L23) -> 0 | ... T24: =SUM(T22:T23) -> 0 | U24: =SUM(E24:T24) -> 10
B25: 3. | C25: Jumlah pengguna hak pilih dalam Daftar Pemilih Khusus (DPK) | D25: LK | E25: 1 | F25: 1 | G25: 2 | H25: 1 | I25: 5 | J25: 10 | K25: 1 | L25: 0 | M25: 0 | N25: 1 | O25: 1 | P25: 3 | Q25: 5 | R25: 1 | S25: 2 | T25: 1 | U25: =SUM(E25:T25) -> 35
D26: PR | E26: 0 | F26: 0 | G26: 1 | H26: 2 | I26: 1 | J26: 8 | K26: 2 | L26: 0 | M26: 1 | N26: 0 | O26: 2 | P26: 1 | Q26: 8 | R26: 2 | S26: 4 | T26: 0 | U26: =SUM(E26:T26) -> 32
D27: JML | E27: =SUM(E25:E26) -> 1 | F27: =SUM(F25:F26) -> 1 | G27: =SUM(G25:G26) -> 3 | H27: =SUM(H25:H26) -> 3 | I27: =SUM(I25:I26) -> 6 | J27: =SUM(J25:J26) -> 18 | K27: =SUM(K25:K26) -> 3 | L27: =SUM(L25:L26) -> 0 | ... T27: =SUM(T25:T26) -> 1 | U27: =SUM(E27:T27) -> 67
B28: 4. | C28: Jumlah Pengguna Hak Pilih (B.1+B.2+B.3) | D28: LK | E28: =SUM(E19,E22,E25) -> 94 | F28: =SUM(F19,F22,F25) -> 111 | G28: =SUM(G19,G22,G25) -> 103 | H28: =SUM(H19,H22,H25) -> 92 | I28: =SUM(I19,I22,I25) -> 100 | J28: =SUM(J19,J22,J25) -> 103 | K28: =SUM(K19,K22,K25) -> 112 | L28: =SUM(L19,L22,L25) -> 94 | ... T28: =SUM(T19,T22,T25) -> 91 | U28: =SUM(E28:T28) -> 1563
D29: PR | E29: =SUM(E20,E23,E26) -> 122 | F29: =SUM(F20,F23,F26) -> 117 | G29: =SUM(G20,G23,G26) -> 108 | H29: =SUM(H20,H23,H26) -> 131 | I29: =SUM(I20,I23,I26) -> 134 | J29: =SUM(J20,J23,J26) -> 139 | K29: =SUM(K20,K23,K26) -> 124 | L29: =SUM(L20,L23,L26) -> 113 | ... T29: =SUM(T20,T23,T26) -> 88 | U29: =SUM(E29:T29) -> 1808
D30: JML | E30: =SUM(E28:E29) -> 216 | F30: =SUM(F28:F29) -> 228 | G30: =SUM(G28:G29) -> 211 | H30: =SUM(H28:H29) -> 223 | I30: =SUM(I28:I29) -> 234 | J30: =SUM(J28:J29) -> 242 | K30: =SUM(K28:K29) -> 236 | L30: =SUM(L28:L29) -> 207 | ... T30: =SUM(T28:T29) -> 179 | U30: =SUM(E30:T30) -> 3371
A32: II | B32: DATA PENGGUNAAN SURAT SUARA
A33: 1 | B33: Jumlah surat suara yang diterima, termasuk surat suara cadangan 2% dari DPT | E33: 272 | F33: 285 | G33: 266 | H33: 273 | I33: 300 | J33: 304 | K33: 287 | L33: 265 | M33: 194 | N33: 285 | O33: 240 | P33: 235 | Q33: 279 | R33: 236 | S33: 305 | T33: 215 | U33: =SUM(E33:T33) -> 4241
A34: 2 | B34: Jumlah surat suara yang digunakan | E34: 216 | F34: 228 | G34: 211 | H34: 223 | I34: 234 | J34: 242 | K34: 236 | L34: 207 | M34: 153 | N34: 243 | O34: 181 | P34: 190 | Q34: 213 | R34: 180 | S34: 235 | T34: 179 | U34: =SUM(E34:T34) -> 3371
A35: 3 | B35: Jumlah surat suara dikembalikan oleh pemilih (karena rusak atau keliru coblos) | E35: 0 | F35: 3 | G35: 0 | H35: 0 | I35: 0 | J35: 4 | K35: 0 | L35: 0 | M35: 0 | N35: 0 | O35: 0 | P35: 0 | Q35: 1 | R35: 0 | S35: 0 | T35: 1 | U35: =SUM(E35:T35) -> 9
A36: 4 | B36: Jumlah surat suara yang tidak digunakan/tidak terpakai, termasuk sisa surat suara cadangan | E36: =E33-(E34+E35) -> 56 | F36: =F33-(F34+F35) -> 54 | G36: =G33-(G34+G35) -> 55 | H36: =H33-(H34+H35) -> 50 | I36: =I33-(I34+I35) -> 66 | J36: =J33-(J34+J35) -> 58 | K36: =K33-(K34+K35) -> 51 | L36: =L33-(L34+L35) -> 58 | ... T36: =T33-(T34+T35) -> 35 | U36: =SUM(E36:T36) -> 861
A38: III | B38: DATA PEMILIH DISABILITAS
B39: Jumlah seluruh Pemilih disabilitas yang menggunakan hak pilih | D39: LK | F39: 1 | J39: 1 | S39: 1 | U39: =SUM(E39:T39) -> 3
D40: PR | F40: 1 | J40: 1 | S40: 1 | U40: =SUM(E40:T40) -> 3
D41: JML | E41: =SUM(E39:E40) -> 0 | F41: =SUM(F39:F40) -> 2 | G41: =SUM(G39:G40) -> 0 | H41: =SUM(H39:H40) -> 0 | I41: =SUM(I39:I40) -> 0 | J41: =SUM(J39:J40) -> 2 | K41: =SUM(K39:K40) -> 0 | L41: =SUM(L39:L40) -> 0 | ... T41: =SUM(T39:T40) -> 0 | U41: =SUM(E41:T41) -> 6
A43: IV | B43: DATA RINCIAN PEROLEHAN SUARA PASANGAN CALON BUPATI DAN WAKIL BUPATI
A44: NOMOR DAN NAMA CALON
A45: A.1 | B45: 1. | C45: Partai Kebangkitan Bangsa | E45: 1 | F45: 3 | G45: 6 | H45: 4 | I45: 5 | J45: 5 | K45: 5 | L45: 6 | M45: 2 | N45: 5 | O45: 2 | P45: 5 | Q45: 3 | R45: 1 | S45: 0 | T45: 3 | U45: =SUM(E45:T45) -> 56
A46: A.2 | C46: 1. ANITA RANI, S.H. | E46: 4 | F46: 1 | G46: 1 | H46: 4 | I46: 4 | J46: 3 | K46: 0 | L46: 2 | M46: 1 | N46: 1 | O46: 2 | P46: 1 | Q46: 1 | R46: 1 | S46: 5 | T46: 1 | U46: =SUM(E46:T46) -> 32
C47: 2. ANISAH MAHSUNAH, S.E. | E47: 2 | F47: 1 | G47: 0 | H47: 3 | I47: 0 | J47: 1 | K47: 1 | L47: 0 | M47: 0 | N47: 0 | O47: 0 | P47: 0 | Q47: 1 | R47: 1 | S47: 1 | U47: =SUM(E47:T47) -> 11
C48: 3. SENARI, S.Sos. | E48: 3 | F48: 2 | G48: 1 | H48: 2 | I48: 3 | J48: 0 | K48: 5 | L48: 0 | M48: 1 | N48: 0 | O48: 0 | P48: 1 | Q48: 1 | R48: 1 | S48: 0 | U48: =SUM(E48:T48) -> 20
C49: 4. VERAGAWATI, S.H. | E49: 1 | F49: 1 | G49: 0 | H49: 0 | I49: 0 | J49: 1 | K49: 1 | L49: 0 | M49: 0 | N49: 0 | O49: 1 | P49: 1 | Q49: 0 | R49: 0 | S49: 0 | U49: =SUM(E49:T49) -> 6
C50: 5. KURDI EHSAN | E50: 2 | F50: 1 | G50: 0 | H50: 0 | I50: 0 | J50: 2 | K50: 0 | L50: 0 | M50: 0 | N50: 0 | O50: 0 | P50: 0 | Q50: 1 | R50: 2 | S50: 0 | U50: =SUM(E50:T50) -> 8
C51: 6. BONDAN ARDYWIJAYA | E51: 0 | F51: 0 | G51: 3 | H51: 0 | I51: 0 | J51: 0 | K51: 1 | L51: 3 | M51: 0 | N51: 0 | O51: 6 | P51: 17 | Q51: 28 | R51: 15 | S51: 8 | T51: 1 | U51: =SUM(E51:T51) -> 82
...

Sheet BANJARSARI
C2: Kecamatan | D2: GLAGAH
C3: Kabupaten | D3: BANYUWANGI
C4: Provinsi | D4: JAWA TIMUR
C9: Kelurahan | D9: BANJARSARI
A12: I | B12: DATA PEMILIH DAN PENGGUNAAN HAK PILIH | X12: JUMLAH AKHIR
A13: A | B13: DATA PEMILIH | E13: TPS 001 | F13: TPS 002 | G13: TPS 003 | H13: TPS 004 | I13: TPS 005 | J13: TPS 006 | K13: TPS 007 | L13: TPS 008 | M13: TPS 009 | N13: TPS 010 | O13: TPS 011 | P13: TPS 012 | Q13: TPS 013 | R13: TPS 014 | S13: TPS 015 | T13: TPS 016 | U13: TPS 017 | V13: TPS 018 | W13: TPS 019
B14: Jumlah Pemilih dalam Daftar Pemilih Tetap (DPT) | D14: LK | E14: 140 | F14: 149 | G14: 130 | H14: 134 | I14: 135 | J14: 130 | K14: 140 | L14: 132 | M14: 136 | N14: 154 | O14: 124 | P14: 111 | Q14: 113 | R14: 137 | S14: 97 | T14: 116 | U14: 119 | V14: 119 | W14: 135 | X14: =SUM(E14:W14) -> 2451
D15: PR | E15: 154 | F15: 139 | G15: 149 | H15: 149 | I15: 147 | J15: 152 | K15: 146 | L15: 155 | M15: 152 | N15: 144 | O15: 140 | P15: 118 | Q15: 120 | R15: 136 | S15: 114 | T15: 117 | U15: 113 | V15: 124 | W15: 153 | X15: =SUM(E15:W15) -> 2622
D16: JML | E16: =SUM(E14:E15) -> 294 | F16: =SUM(F14:F15) -> 288 | G16: =SUM(G14:G15) -> 279 | H16: =SUM(H14:H15) -> 283 | I16: =SUM(I14:I15) -> 282 | J16: =SUM(J14:J15) -> 282 | K16: =SUM(K14:K15) -> 286 | L16: =SUM(L14:L15) -> 287 | ... W16: =SUM(W14:W15) -> 288 | X16: =SUM(E16:W16) -> 5073
A18: B | B18: PENGGUNA HAK PILIH
B19: 1. | C19: Jumlah pengguna hak pilih dalam Daftar Pemilih Tetap (DPT) | D19: LK | E19: 110 | F19: 108 | G19: 103 | H19: 106 | I19: 108 | J19: 96 | K19: 108 | L19: 83 | M19: 115 | N19: 120 | O19: 101 | P19: 91 | Q19: 92 | R19: 99 | S19: 80 | T19: 87 | U19: 106 | V19: 94 | W19: 100 | X19: =SUM(E19:W19) -> 1907
D20: PR | E20: 125 | F20: 115 | G20: 118 | H20: 107 | I20: 120 | J20: 122 | K20: 132 | L20: 119 | M20: 125 | N20: 117 | O20: 120 | P20: 104 | Q20: 99 | R20: 115 | S20: 95 | T20: 101 | U20: 104 | V20: 105 | W20: 129 | X20: =SUM(E20:W20) -> 2172
D21: JML | E21: =SUM(E19:E20) -> 235 | F21: =SUM(F19:F20) -> 223 | G21: =SUM(G19:G20) -> 221 | H21: =SUM(H19:H20) -> 213 | I21: =SUM(I19:I20) -> 228 | J21: =SUM(J19:J20) -> 218 | K21: =SUM(K19:K20) -> 240 | L21: =SUM(L19:L20) -> 202 | ... W21: =SUM(W19:W20) -> 229 | X21: =SUM(E21:W21) -> 4079
B22: 2. | C22: Jumlah pengguna hak pilih dalam Daftar Pemilih Tambahan (DPTb) | D22: LK | E22: 0 | F22: 0 | G22: 0 | H22: 0 | I22: 0 | J22: 0 | K22: 0 | L22: 0 | M22: 0 | N22: 0 | O22: 0 | P22: 0 | Q22: 0 | R22: 0 | S22: 0 | T22: 0 | U22: 1 | V22: 0 | W22: 1 | X22: =SUM(E22:W22) -> 2
D23: PR | E23: 0 | F23: 0 | G23: 2 | H23: 0 | I23: 0 | J23: 0 | K23: 0 | L23: 0 | M23: 0 | N23: 1 | O23: 1 | P23: 0 | Q23: 1 | R23: 2 | S23: 1 | T23: 0 | U23: 1 | V23: 0 | W23: 2 | X23: =SUM(E23:W23) -> 11
D24: JML | E24: =SUM(E22:E23) -> 0 | F24: =SUM(F22:F23) -> 0 | G24: =SUM(G22:G23) -> 2 | H24: =SUM(H22:H23) -> 0 | I24: =SUM(I22:I23) -> 0 | J24: =SUM(J22:J23) -> 0 | K24: =SUM(K22:K23) -> 0 | L24: =SUM(L22:L23) -> 0 | ... W24: =SUM(W22:W23) -> 3 | X24: =SUM(E24:W24) -> 13
B25: 3. | C25: Jumlah pengguna hak pilih dalam Daftar Pemilih Khusus (DPK) | D25: LK | E25: 1 | F25: 0 | G25: 0 | H25: 0 | I25: 2 | J25: 0 | K25: 3 | L25: 2 | M25: 1 | N25: 3 | O25: 0 | P25: 0 | Q25: 0 | R25: 1 | S25: 2 | T25: 0 | U25: 2 | V25: 0 | W25: 0 | X25: =SUM(E25:W25) -> 17
D26: PR | E26: 1 | F26: 0 | G26: 0 | H26: 1 | I26: 1 | J26: 3 | K26: 2 | L26: 6 | M26: 1 | N26: 2 | O26: 1 | P26: 0 | Q26: 2 | R26: 2 | S26: 3 | T26: 0 | U26: 5 | V26: 1 | W26: 1 | X26: =SUM(E26:W26) -> 32
D27: JML | E27: =SUM(E25:E26) -> 2 | F27: =SUM(F25:F26) -> 0 | G27: =SUM(G25:G26) -> 0 | H27: =SUM(H25:H26) -> 1 | I27: =SUM(I25:I26) -> 3 | J27: =SUM(J25:J26) -> 3 | K27: =SUM(K25:K26) -> 5 | L27: =SUM(L25:L26) -> 8 | ... W27: =SUM(W25:W26) -> 1 | X27: =SUM(E27:W27) -> 49
B28: 4. | C28: Jumlah Pengguna Hak Pilih (B.1+B.2+B.3) | D28: LK | E28: =SUM(E19,E22,E25) -> 111 | F28: =SUM(F19,F22,F25) -> 108 | G28: =SUM(G19,G22,G25) -> 103 | H28: =SUM(H19,H22,H25) -> 106 | I28: =SUM(I19,I22,I25) -> 110 | J28: =SUM(J19,J22,J25) -> 96 | K28: =SUM(K19,K22,K25) -> 111 | L28: =SUM(L19,L22,L25) -> 85 | ... W28: =SUM(W19,W22,W25) -> 101 | X28: =SUM(E28:W28) -> 1926
D29: PR | E29: =SUM(E20,E23,E26) -> 126 | F29: =SUM(F20,F23,F26) -> 115 | G29: =SUM(G20,G23,G26) -> 120 | H29: =SUM(H20,H23,H26) -> 108 | I29: =SUM(I20,I23,I26) -> 121 | J29: =SUM(J20,J23,J26) -> 125 | K29: =SUM(K20,K23,K26) -> 134 | L29: =SUM(L20,L23,L26) -> 125 | ... W29: =SUM(W20,W23,W26) -> 132 | X29: =SUM(E29:W29) -> 2215
D30: JML | E30: =SUM(E28:E29) -> 237 | F30: =SUM(F28:F29) -> 223 | G30: =SUM(G28:G29) -> 223 | H30: =SUM(H28:H29) -> 214 | I30: =SUM(I28:I29) -> 231 | J30: =SUM(J28:J29) -> 221 | K30: =SUM(K28:K29) -> 245 | L30: =SUM(L28:L29) -> 210 | ... W30: =SUM(W28:W29) -> 233 | X30: =SUM(E30:W30) -> 4141
A32: II | B32: DATA PENGGUNAAN SURAT SUARA
A33: 1 | B33: Jumlah surat suara yang diterima, termasuk surat suara cadangan 2% dari DPT | E33: 300 | F33: 294 | G33: 285 | H33: 289 | I33: 288 | J33: 288 | K33: 296 | L33: 293 | M33: 294 | N33: 304 | O33: 270 | P33: 234 | Q33: 238 | R33: 279 | S33: 217 | T33: 238 | U33: 237 | V33: 248 | W33: 294 | X33: =SUM(E33:W33) -> 5186
A34: 2 | B34: Jumlah surat suara yang digunakan | E34: 237 | F34: 223 | G34: 223 | H34: 214 | I34: 231 | J34: 221 | K34: 245 | L34: 210 | M34: 242 | N34: 243 | O34: 223 | P34: 195 | Q34: 194 | R34: 219 | S34: 181 | T34: 188 | U34: 219 | V34: 200 | W34: 233 | X34: =SUM(E34:W34) -> 4141
A35: 3 | B35: Jumlah surat suara dikembalikan oleh pemilih (karena rusak atau keliru coblos) | E35: 0 | F35: 1 | G35: 0 | H35: 0 | I35: 0 | J35: 0 | K35: 0 | L35: 0 | M35: 0 | N35: 0 | O35: 0 | P35: 0 | Q35: 1 | R35: 0 | S35: 0 | T35: 3 | U35: 0 | V35: 0 | W35: 0 | X35: =SUM(E35:W35) -> 5
A36: 4 | B36: Jumlah surat suara yang tidak digunakan/tidak terpakai, termasuk sisa surat suara cadangan | E36: =E33-(E34+E35) -> 63 | F36: =F33-(F34+F35) -> 70 | G36: =G33-(G34+G35) -> 62 | H36: =H33-(H34+H35) -> 75 | I36: =I33-(I34+I35) -> 57 | J36: =J33-(J34+J35) -> 67 | K36: =K33-(K34+K35) -> 51 | L36: =L33-(L34+L35) -> 83 | ... W36: =W33-(W34+W35) -> 61 | X36: =SUM(E36:W36) -> 1040
A38: III | B38: DATA PEMILIH DISABILITAS
B39: Jumlah seluruh Pemilih disabilitas yang menggunakan hak pilih | D39: LK | K39: 2 | L39: 1 | M39: 1 | U39: 1 | X39: =SUM(E39:W39) -> 5
D40: PR | G40: 2 | L40: 2 | X40: =SUM(E40:W40) -> 4
D41: JML | E41: =SUM(E39:E40) -> 0 | F41: =SUM(F39:F40) -> 0 | G41: =SUM(G39:G40) -> 2 | H41: =SUM(H39:H40) -> 0 | I41: =SUM(I39:I40) -> 0 | J41: =SUM(J39:J40) -> 0 | K41: =SUM(K39:K40) -> 2 | L41: =SUM(L39:L40) -> 3 | ... W41: =SUM(W39:W40) -> 0 | X41: =SUM(E41:W41) -> 9
A43: IV | B43: DATA RINCIAN PEROLEHAN SUARA PASANGAN CALON BUPATI DAN WAKIL BUPATI
A44: NOMOR DAN NAMA CALON
A45: A.1 | B45: 1. | C45: Partai Kebangkitan Bangsa | E45: 3 | F45: 1 | G45: 8 | H45: 5 | I45: 2 | J45: 3 | K45: 4 | L45: 1 | M45: 2 | N45: 3 | O45: 6 | P45: 6 | Q45: 5 | R45: 6 | S45: 6 | T45: 2 | U45: 0 | V45: 4 | W45: 2 | X45: =SUM(E45:W45) -> 69
A46: A.2 | C46: 1. ANITA RANI, S.H. | E46: 5 | F46: 5 | G46: 1 | H46: 6 | I46: 1 | J46: 2 | K46: 2 | L46: 1 | M46: 1 | N46: 2 | O46: 3 | P46: 3 | Q46: 4 | R46: 1 | S46: 1 | T46: 1 | U46: 1 | V46: 1 | W46: 2 | X46: =SUM(E46:W46) -> 43
C47: 2. ANISAH MAHSUNAH, S.E. | E47: 4 | F47: 0 | G47: 3 | H47: 0 | I47: 1 | J47: 2 | K47: 2 | L47: 1 | M47: 2 | N47: 1 | O47: 0 | P47: 3 | Q47: 3 | R47: 0 | S47: 0 | T47: 0 | U47: 0 | V47: 0 | W47: 0 | X47: =SUM(E47:W47) -> 22
C48: 3. SENARI, S.Sos. | E48: 1 | F48: 2 | G48: 1 | H48: 11 | I48: 8 | J48: 3 | K48: 5 | L48: 7 | M48: 16 | N48: 4 | O48: 2 | P48: 2 | Q48: 11 | R48: 3 | S48: 3 | T48: 4 | U48: 0 | V48: 0 | W48: 3 | X48: =SUM(E48:W48) -> 86
C49: 4. VERAGAWATI, S.H. | E49: 0 | F49: 0 | G49: 0 | H49: 0 | I49: 0 | J49: 0 | K49: 0 | L49: 0 | M49: 0 | N49: 1 | O49: 0 | P49: 0 | Q49: 0 | R49: 0 | S49: 0 | T49: 0 | U49: 0 | V49: 0 | W49: 0 | X49: =SUM(E49:W49) -> 1
C50: 5. KURDI EHSAN | E50: 0 | F50: 0 | G50: 0 | H50: 1 | I50: 0 | J50: 0 | K50: 0 | L50: 2 | M50: 0 | N50: 1 | O50: 1 | P50: 0 | Q50: 0 | R50: 1 | S50: 0 | T50: 0 | U50: 0 | V50: 0 | W50: 0 | X50: =SUM(E50:W50) -> 6
C51: 6. BONDAN ARDYWIJAYA | E51: 0 | F51: 0 | G51: 0 | H51: 2 | I51: 1 | J51: 8 | K51: 2 | L51: 0 | M51: 1 | N51: 0 | O51: 10 | P51: 16 | Q51: 2 | R51: 0 | S51: 2 | T51: 0 | U51: 0 | V51: 0 | W51: 0 | X51: =SUM(E51:W51) -> 44
...

Sheet REJOSARI
C2: Kecamatan | D2: GLAGAH
C3: Kabupaten | D3: BANYUWANGI
C4: Provinsi | D4: JAWA TIMUR
C9: Kelurahan | D9: REJOSARI
A12: I | B12: DATA PEMILIH DAN PENGGUNAAN HAK PILIH | N12: JUMLAH AKHIR
A13: A | B13: DATA PEMILIH | E13: TPS 001 | F13: TPS 002 | G13: TPS 003 | H13: TPS 004 | I13: TPS 005 | J13: TPS 006 | K13: TPS 007 | L13: TPS 008 | M13: TPS 009
B14: Jumlah Pemilih dalam Daftar Pemilih Tetap (DPT) | D14: LK | E14: 149 | F14: 125 | G14: 137 | H14: 133 | I14: 133 | J14: 121 | K14: 124 | L14: 126 | M14: 131 | N14: =SUM(E14:M14) -> 1179
D15: PR | E15: 126 | F15: 135 | G15: 127 | H15: 129 | I15: 130 | J15: 145 | K15: 135 | L15: 138 | M15: 127 | N15: =SUM(E15:M15) -> 1192
D16: JML | E16: =SUM(E14:E15) -> 275 | F16: =SUM(F14:F15) -> 260 | G16: =SUM(G14:G15) -> 264 | H16: =SUM(H14:H15) -> 262 | I16: =SUM(I14:I15) -> 263 | J16: =SUM(J14:J15) -> 266 | K16: =SUM(K14:K15) -> 259 | L16: =SUM(L14:L15) -> 264 | M16: =SUM(M14:M15) -> 258 | N16: =SUM(E16:M16) -> 2371
A18: B | B18: PENGGUNA HAK PILIH
B19: 1. | C19: Jumlah pengguna hak pilih dalam Daftar Pemilih Tetap (DPT) | D19: LK | E19: 127 | F19: 108 | G19: 110 | H19: 108 | I19: 106 | J19: 95 | K19: 88 | L19: 105 | M19: 105 | N19: =SUM(E19:M19) -> 952
D20: PR | E20: 113 | F20: 116 | G20: 115 | H20: 108 | I20: 104 | J20: 122 | K20: 111 | L20: 120 | M20: 104 | N20: =SUM(E20:M20) -> 1013
D21: JML | E21: =SUM(E19:E20) -> 240 | F21: =SUM(F19:F20) -> 224 | G21: =SUM(G19:G20) -> 225 | H21: =SUM(H19:H20) -> 216 | I21: =SUM(I19:I20) -> 210 | J21: =SUM(J19:J20) -> 217 | K21: =SUM(K19:K20) -> 199 | L21: =SUM(L19:L20) -> 225 | M21: =SUM(M19:M20) -> 209 | N21: =SUM(E21:M21) -> 1965
B22: 2. | C22: Jumlah pengguna hak pilih dalam Daftar Pemilih Tambahan (DPTb) | D22: LK | E22: 1 | F22: 1 | G22: 2 | H22: 0 | I22: 1 | J22: 1 | K22: 2 | L22: 0 | M22: 1 | N22: =SUM(E22:M22) -> 9
D23: PR | E23: 4 | F23: 1 | G23: 2 | H23: 0 | I23: 1 | J23: 2 | K23: 2 | L23: 0 | M23: 1 | N23: =SUM(E23:M23) -> 13
D24: JML | E24: =SUM(E22:E23) -> 5 | F24: =SUM(F22:F23) -> 2 | G24: =SUM(G22:G23) -> 4 | H24: =SUM(H22:H23) -> 0 | I24: =SUM(I22:I23) -> 2 | J24: =SUM(J22:J23) -> 3 | K24: =SUM(K22:K23) -> 4 | L24: =SUM(L22:L23) -> 0 | M24: =SUM(M22:M23) -> 2 | N24: =SUM(E24:M24) -> 22
B25: 3. | C25: Jumlah pengguna hak pilih dalam Daftar Pemilih Khusus (DPK) | D25: LK | E25: 0 | F25: 0 | G25: 2 | H25: 0 | I25: 1 | J25: 0 | K25: 0 | L25: 0 | M25: 0 | N25: =SUM(E25:M25) -> 3
D26: PR | E26: 1 | F26: 1 | G26: 2 | H26: 0 | I26: 0 | J26: 1 | K26: 1 | L26: 1 | M26: 0 | N26: =SUM(E26:M26) -> 7
D27: JML | E27: =SUM(E25:E26) -> 1 | F27: =SUM(F25:F26) -> 1 | G27: =SUM(G25:G26) -> 4 | H27: =SUM(H25:H26) -> 0 | I27: =SUM(I25:I26) -> 1 | J27: =SUM(J25:J26) -> 1 | K27: =SUM(K25:K26) -> 1 | L27: =SUM(L25:L26) -> 1 | M27: =SUM(M25:M26) -> 0 | N27: =SUM(E27:M27) -> 10
B28: 4. | C28: Jumlah Pengguna Hak Pilih (B.1+B.2+B.3) | D28: LK | E28: =SUM(E19,E22,E25) -> 128 | F28: =SUM(F19,F22,F25) -> 109 | G28: =SUM(G19,G22,G25) -> 114 | H28: =SUM(H19,H22,H25) -> 108 | I28: =SUM(I19,I22,I25) -> 108 | J28: =SUM(J19,J22,J25) -> 96 | K28: =SUM(K19,K22,K25) -> 90 | L28: =SUM(L19,L22,L25) -> 105 | M28: =SUM(M19,M22,M25) -> 106 | N28: =SUM(E28:M28) -> 964
D29: PR | E29: =SUM(E20,E23,E26) -> 118 | F29: =SUM(F20,F23,F26) -> 118 | G29: =SUM(G20,G23,G26) -> 119 | H29: =SUM(H20,H23,H26) -> 108 | I29: =SUM(I20,I23,I26) -> 105 | J29: =SUM(J20,J23,J26) -> 125 | K29: =SUM(K20,K23,K26) -> 114 | L29: =SUM(L20,L23,L26) -> 121 | M29: =SUM(M20,M23,M26) -> 105 | N29: =SUM(E29:M29) -> 1033
D30: JML | E30: =SUM(E28:E29) -> 246 | F30: =SUM(F28:F29) -> 227 | G30: =SUM(G28:G29) -> 233 | H30: =SUM(H28:H29) -> 216 | I30: =SUM(I28:I29) -> 213 | J30: =SUM(J28:J29) -> 221 | K30: =SUM(K28:K29) -> 204 | L30: =SUM(L28:L29) -> 226 | M30: =SUM(M28:M29) -> 211 | N30: =SUM(E30:M30) -> 1997
A32: II | B32: DATA PENGGUNAAN SURAT SUARA
A33: 1 | B33: Jumlah surat suara yang diterima, termasuk surat suara cadangan 2% dari DPT | E33: 281 | F33: 266 | G33: 270 | H33: 268 | I33: 268 | J33: 272 | K33: 265 | L33: 270 | M33: 264 | N33: =SUM(E33:M33) -> 2424
A34: 2 | B34: Jumlah surat suara yang digunakan | E34: 246 | F34: 227 | G34: 233 | H34: 216 | I34: 213 | J34: 221 | K34: 204 | L34: 226 | M34: 211 | N34: =SUM(E34:M34) -> 1997
A35: 3 | B35: Jumlah surat suara dikembalikan oleh pemilih (karena rusak atau keliru coblos) | E35: 1 | F35: 2 | G35: 1 | H35: 0 | I35: 0 | J35: 0 | K35: 0 | L35: 0 | M35: 0 | N35: =SUM(E35:M35) -> 4
A36: 4 | B36: Jumlah surat suara yang tidak digunakan/tidak terpakai, termasuk sisa surat suara cadangan | E36: =E33-(E34+E35) -> 34 | F36: =F33-(F34+F35) -> 37 | G36: =G33-(G34+G35) -> 36 | H36: =H33-(H34+H35) -> 52 | I36: =I33-(I34+I35) -> 55 | J36: =J33-(J34+J35) -> 51 | K36: =K33-(K34+K35) -> 61 | L36: =L33-(L34+L35) -> 44 | M36: =M33-(M34+M35) -> 53 | N36: =SUM(E36:M36) -> 423
A38: III | B38: DATA PEMILIH DISABILITAS
B39: Jumlah seluruh Pemilih disabilitas yang menggunakan hak pilih | D39: LK | E39: 4 | F39: 1 | G39: 1 | K39: 1 | M39: 1 | N39: =SUM(E39:M39) -> 8
D40: PR | E40: 2 | N40: =SUM(E40:M40) -> 2
D41: JML | E41: =SUM(E39:E40) -> 6 | F41: =SUM(F39:F40) -> 1 | G41: =SUM(G39:G40) -> 1 | H41: =SUM(H39:H40) -> 0 | I41: =SUM(I39:I40) -> 0 | J41: =SUM(J39:J40) -> 0 | K41: =SUM(K39:K40) -> 1 | L41: =SUM(L39:L40) -> 0 | M41: =SUM(M39:M40) -> 1 | N41: =SUM(E41:M41) -> 10
A43: IV | B43: DATA RINCIAN PEROLEHAN SUARA PASANGAN CALON BUPATI DAN WAKIL BUPATI
A44: NOMOR DAN NAMA CALON
A45: A.1 | B45: 1. | C45: Partai Kebangkitan Bangsa | E45: 6 | F45: 8 | G45: 7 | H45: 5 | I45: 11 | J45: 6 | K45: 5 | L45: 5 | M45: 3 | N45: =SUM(E45:M45) -> 56
A46: A.2 | C46: 1. ANITA RANI, S.H. | E46: 1 | F46: 8 | G46: 19 | H46: 1 | I46: 0 | J46: 4 | K46: 1 | L46: 6 | M46: 3 | N46: =SUM(E46:M46) -> 43
C47: 2. ANISAH MAHSUNAH, S.E. | E47: 1 | F47: 2 | G47: 5 | H47: 1 | I47: 1 | J47: 1 | K47: 1 | L47: 1 | M47: 1 | N47: =SUM(E47:M47) -> 14
C48: 3. SENARI, S.Sos. | E48: 0 | F48: 0 | G48: 1 | H48: 1 | I48: 0 | J48: 0 | K48: 1 | L48: 0 | M48: 0 | N48: =SUM(E48:M48) -> 3
C49: 4. VERAGAWATI, S.H. | E49: 0 | F49: 0 | G49: 0 | H49: 0 | I49: 0 | J49: 0 | K49: 0 | L49: 0 | M49: 0 | N49: =SUM(E49:M49) -> 0
C50: 5. KURDI EHSAN | E50: 0 | F50: 0 | G50: 0 | H50: 0 | I50: 0 | J50: 0 | K50: 0 | L50: 0 | M50: 0 | N50: =SUM(E50:M50) -> 0
C51: 6. BONDAN ARDYWIJAYA | E51: 0 | F51: 2 | G51: 9 | H51: 2 | I51: 1 | J51: 2 | K51: 16 | L51: 3 | M51: 0 | N51: =SUM(E51:M51) -> 35
...

Sheet KEMIREN
C2: Kecamatan | D2: GLAGAH
C3: Kabupaten | D3: BANYUWANGI
C4: Provinsi | D4: JAWA TIMUR
C9: Kelurahan | D9: KEMIREN
A12: I | B12: DATA PEMILIH DAN PENGGUNAAN HAK PILIH | M12: JUMLAH AKHIR
A13: A | B13: DATA PEMILIH | E13: TPS 001 | F13: TPS 002 | G13: TPS 003 | H13: TPS 004 | I13: TPS 005 | J13: TPS 006 | K13: TPS 007 | L13: TPS 008
B14: Jumlah Pemilih dalam Daftar Pemilih Tetap (DPT) | D14: LK | E14: 128 | F14: 118 | G14: 115 | H14: 119 | I14: 121 | J14: 126 | K14: 121 | L14: 133 | M14: =SUM(E14:L14) -> 981
D15: PR | E15: 141 | F15: 135 | G15: 137 | H15: 143 | I15: 133 | J15: 135 | K15: 137 | L15: 126 | M15: =SUM(E15:L15) -> 1087
D16: JML | E16: =SUM(E14:E15) -> 269 | F16: =SUM(F14:F15) -> 253 | G16: =SUM(G14:G15) -> 252 | H16: =SUM(H14:H15) -> 262 | I16: =SUM(I14:I15) -> 254 | J16: =SUM(J14:J15) -> 261 | K16: =SUM(K14:K15) -> 258 | L16: =SUM(L14:L15) -> 259 | M16: =SUM(E16:L16) -> 2068
A18: B | B18: PENGGUNA HAK PILIH
B19: 1. | C19: Jumlah pengguna hak pilih dalam Daftar Pemilih Tetap (DPT) | D19: LK | E19: 114 | F19: 106 | G19: 99 | H19: 111 | I19: 111 | J19: 116 | K19: 108 | L19: 104 | M19: =SUM(E19:L19) -> 869
D20: PR | E20: 130 | F20: 128 | G20: 123 | H20: 131 | I20: 117 | J20: 128 | K20: 123 | L20: 118 | M20: =SUM(E20:L20) -> 998
D21: JML | E21: =SUM(E19:E20) -> 244 | F21: =SUM(F19:F20) -> 234 | G21: =SUM(G19:G20) -> 222 | H21: =SUM(H19:H20) -> 242 | I21: =SUM(I19:I20) -> 228 | J21: =SUM(J19:J20) -> 244 | K21: =SUM(K19:K20) -> 231 | L21: =SUM(L19:L20) -> 222 | M21: =SUM(E21:L21) -> 1867
B22: 2. | C22: Jumlah pengguna hak pilih dalam Daftar Pemilih Tambahan (DPTb) | D22: LK | E22: 2 | F22: 1 | G22: 0 | H22: 2 | I22: 0 | J22: 0 | K22: 1 | L22: 2 | M22: =SUM(E22:L22) -> 8
D23: PR | E23: 1 | F23: 0 | G23: 2 | H23: 0 | I23: 0 | J23: 1 | K23: 1 | L23: 2 | M23: =SUM(E23:L23) -> 7
D24: JML | E24: =SUM(E22:E23) -> 3 | F24: =SUM(F22:F23) -> 1 | G24: =SUM(G22:G23) -> 2 | H24: =SUM(H22:H23) -> 2 | I24: =SUM(I22:I23) -> 0 | J24: =SUM(J22:J23) -> 1 | K24: =SUM(K22:K23) -> 2 | L24: =SUM(L22:L23) -> 4 | M24: =SUM(E24:L24) -> 15
B25: 3. | C25: Jumlah pengguna hak pilih dalam Daftar Pemilih Khusus (DPK) | D25: LK | E25: 0 | F25: 0 | G25: 0 | H25: 0 | I25: 0 | J25: 0 | K25: 0 | L25: 0 | M25: =SUM(E25:L25) -> 0
D26: PR | E26: 0 | F26: 0 | G26: 0 | H26: 0 | I26: 0 | J26: 0 | K26: 1 | L26: 0 | M26: =SUM(E26:L26) -> 1
D27: JML | E27: =SUM(E25:E26) -> 0 | F27: =SUM(F25:F26) -> 0 | G27: =SUM(G25:G26) -> 0 | H27: =SUM(H25:H26) -> 0 | I27: =SUM(I25:I26) -> 0 | J27: =SUM(J25:J26) -> 0 | K27: =SUM(K25:K26) -> 1 | L27: =SUM(L25:L26) -> 0 | M27: =SUM(E27:L27) -> 1
B28: 4. | C28: Jumlah Pengguna Hak Pilih (B.1+B.2+B.3) | D28: LK | E28: =SUM(E19,E22,E25) -> 116 | F28: =SUM(F19,F22,F25) -> 107 | G28: =SUM(G19,G22,G25) -> 99 | H28: =SUM(H19,H22,H25) -> 113 | I28: =SUM(I19,I22,I25) -> 111 | J28: =SUM(J19,J22,J25) -> 116 | K28: =SUM(K19,K22,K25) -> 109 | L28: =SUM(L19,L22,L25) -> 106 | M28: =SUM(E28:L28) -> 877
D29: PR | E29: =SUM(E20,E23,E26) -> 131 | F29: =SUM(F20,F23,F26) -> 128 | G29: =SUM(G20,G23,G26) -> 125 | H29: =SUM(H20,H23,H26) -> 131 | I29: =SUM(I20,I23,I26) -> 117 | J29: =SUM(J20,J23,J26) -> 129 | K29: =SUM(K20,K23,K26) -> 125 | L29: =SUM(L20,L23,L26) -> 120 | M29: =SUM(E29:L29) -> 1006
D30: JML | E30: =SUM(E28:E29) -> 247 | F30: =SUM(F28:F29) -> 235 | G30: =SUM(G28:G29) -> 224 | H30: =SUM(H28:H29) -> 244 | I30: =SUM(I28:I29) -> 228 | J30: =SUM(J28:J29) -> 245 | K30: =SUM(K28:K29) -> 234 | L30: =SUM(L28:L29) -> 226 | M30: =SUM(E30:L30) -> 1883
A32: II | B32: DATA PENGGUNAAN SURAT SUARA
A33: 1 | B33: Jumlah surat suara yang diterima, termasuk surat suara cadangan 2% dari DPT | E33: 275 | F33: 259 | G33: 258 | H33: 268 | I33: 260 | J33: 267 | K33: 264 | L33: 265 | M33: =SUM(E33:L33) -> 2116
A34: 2 | B34: Jumlah surat suara yang digunakan | E34: 247 | F34: 235 | G34: 224 | H34: 244 | I34: 228 | J34: 245 | K34: 234 | L34: 226 | M34: =SUM(E34:L34) -> 1883
A35: 3 | B35: Jumlah surat suara dikembalikan oleh pemilih (karena rusak atau keliru coblos) | E35: 0 | F35: 0 | G35: 0 | H35: 0 | I35: 0 | J35: 0 | K35: 0 | L35: 0 | M35: =SUM(E35:L35) -> 0
A36: 4 | B36: Jumlah surat suara yang tidak digunakan/tidak terpakai, termasuk sisa surat suara cadangan | E36: =E33-(E34+E35) -> 28 | F36: =F33-(F34+F35) -> 24 | G36: =G33-(G34+G35) -> 34 | H36: =H33-(H34+H35) -> 24 | I36: =I33-(I34+I35) -> 32 | J36: =J33-(J34+J35) -> 22 | K36: =K33-(K34+K35) -> 30 | L36: =L33-(L34+L35) -> 39 | M36: =SUM(E36:L36) -> 233
A38: III | B38: DATA PEMILIH DISABILITAS
B39: Jumlah seluruh Pemilih disabilitas yang menggunakan hak pilih | D39: LK | M39: =SUM(E39:L39) -> 0
D40: PR | M40: =SUM(E40:L40) -> 0
D41: JML | E41: =SUM(E39:E40) -> 0 | F41: =SUM(F39:F40) -> 0 | G41: =SUM(G39:G40) -> 0 | H41: =SUM(H39:H40) -> 0 | I41: =SUM(I39:I40) -> 0 | J41: =SUM(J39:J40) -> 0 | K41: =SUM(K39:K40) -> 0 | L41: =SUM(L39:L40) -> 0 | M41: =SUM(E41:L41) -> 0
A43: IV | B43: DATA RINCIAN PEROLEHAN SUARA PASANGAN CALON BUPATI DAN WAKIL BUPATI
A44: NOMOR DAN NAMA CALON
A45: A.1 | B45: 1. | C45: Partai Kebangkitan Bangsa | E45: 2 | F45: 3 | G45: 9 | H45: 6 | I45: 9 | J45: 7 | K45: 4 | L45: 2 | M45: =SUM(E45:L45) -> 42
A46: A.2 | C46: 1. ANITA RANI, S.H. | E46: 2 | F46: 3 | G46: 19 | H46: 4 | I46: 2 | J46: 1 | K46: 4 | L46: 0 | M46: =SUM(E46:L46) -> 35
C47: 2. ANISAH MAHSUNAH, S.E. | E47: 2 | F47: 1 | G47: 3 | H47: 1 | I47: 2 | J47: 0 | K47: 3 | L47: 4 | M47: =SUM(E47:L47) -> 16
C48: 3. SENARI, S.Sos. | E48: 12 | F48: 7 | G48: 37 | H48: 22 | I48: 20 | J48: 9 | K48: 6 | L48: 1 | M48: =SUM(E48:L48) -> 114
C49: 4. VERAGAWATI, S.H. | E49: 0 | F49: 0 | G49: 0 | H49: 0 | I49: 0 | J49: 0 | K49: 0 | L49: 0 | M49: =SUM(E49:L49) -> 0
C50: 5. KURDI EHSAN | E50: 1 | F50: 0 | G50: 0 | H50: 0 | I50: 0 | J50: 0 | K50: 0 | L50: 0 | M50: =SUM(E50:L50) -> 1
C51: 6. BONDAN ARDYWIJAYA | E51: 0 | F51: 0 | G51: 2 | H51: 0 | I51: 0 | J51: 1 | K51: 2 | L51: 0 | M51: =SUM(E51:L51) -> 5
...

Sheet OLEHSARI
C2: Kecamatan | D2: GLAGAH
C3: Kabupaten | D3: BANYUWANGI
C4: Provinsi | D4: JAWA TIMUR
C9: Kelurahan | D9: OLEHSARI
A12: I | B12: DATA PEMILIH DAN PENGGUNAAN HAK PILIH | N12: JUMLAH AKHIR
A13: A | B13: DATA PEMILIH | E13: TPS 001 | F13: TPS 002 | G13: TPS 003 | H13: TPS 004 | I13: TPS 005 | J13: TPS 006 | K13: TPS 007 | L13: TPS 008 | M13: TPS 009
B14: Jumlah Pemilih dalam Daftar Pemilih Tetap (DPT) | D14: LK | E14: 125 | F14: 102 | G14: 108 | H14: 107 | I14: 107 | J14: 101 | K14: 116 | L14: 108 | M14: 104 | N14: =SUM(E14:M14) -> 978
D15: PR | E15: 137 | F15: 112 | G15: 133 | H15: 114 | I15: 125 | J15: 119 | K15: 107 | L15: 115 | M15: 114 | N15: =SUM(E15:M15) -> 1076
D16: JML | E16: =SUM(E14:E15) -> 262 | F16: =SUM(F14:F15) -> 214 | G16: =SUM(G14:G15) -> 241 | H16: =SUM(H14:H15) -> 221 | I16: =SUM(I14:I15) -> 232 | J16: =SUM(J14:J15) -> 220 | K16: =SUM(K14:K15) -> 223 | L16: =SUM(L14:L15) -> 223 | M16: =SUM(M14:M15) -> 218 | N16: =SUM(E16:M16) -> 2054
A18: B | B18: PENGGUNA HAK PILIH
B19: 1. | C19: Jumlah pengguna hak pilih dalam Daftar Pemilih Tetap (DPT) | D19: LK | E19: 108 | F19: 78 | G19: 96 | H19: 100 | I19: 89 | J19: 90 | K19: 101 | L19: 93 | M19: 84 | N19: =SUM(E19:M19) -> 839
D20: PR | E20: 117 | F20: 92 | G20: 117 | H20: 106 | I20: 115 | J20: 110 | K20: 102 | L20: 105 | M20: 104 | N20: =SUM(E20:M20) -> 968
D21: JML | E21: =SUM(E19:E20) -> 225 | F21: =SUM(F19:F20) -> 170 | G21: =SUM(G19:G20) -> 213 | H21: =SUM(H19:H20) -> 206 | I21: =SUM(I19:I20) -> 204 | J21: =SUM(J19:J20) -> 200 | K21: =SUM(K19:K20) -> 203 | L21: =SUM(L19:L20) -> 198 | M21: =SUM(M19:M20) -> 188 | N21: =SUM(E21:M21) -> 1807
B22: 2. | C22: Jumlah pengguna hak pilih dalam Daftar Pemilih Tambahan (DPTb) | D22: LK | E22: 0 | F22: 1 | G22: 0 | H22: 0 | I22: 0 | J22: 0 | K22: 2 | L22: 1 | M22: 0 | N22: =SUM(E22:M22) -> 4
D23: PR | E23: 0 | F23: 2 | G23: 0 | H23: 0 | I23: 0 | J23: 0 | K23: 1 | L23: 1 | M23: 0 | N23: =SUM(E23:M23) -> 4
D24: JML | E24: =SUM(E22:E23) -> 0 | F24: =SUM(F22:F23) -> 3 | G24: =SUM(G22:G23) -> 0 | H24: =SUM(H22:H23) -> 0 | I24: =SUM(I22:I23) -> 0 | J24: =SUM(J22:J23) -> 0 | K24: =SUM(K22:K23) -> 3 | L24: =SUM(L22:L23) -> 2 | M24: =SUM(M22:M23) -> 0 | N24: =SUM(E24:M24) -> 8
B25: 3. | C25: Jumlah pengguna hak pilih dalam Daftar Pemilih Khusus (DPK) | D25: LK | E25: 0 | F25: 2 | G25: 0 | H25: 0 | I25: 0 | J25: 0 | K25: 0 | L25: 0 | M25: 0 | N25: =SUM(E25:M25) -> 2
D26: PR | E26: 1 | F26: 2 | G26: 0 | H26: 0 | I26: 2 | J26: 0 | K26: 0 | L26: 0 | M26: 0 | N26: =SUM(E26:M26) -> 5
D27: JML | E27: =SUM(E25:E26) -> 1 | F27: =SUM(F25:F26) -> 4 | G27: =SUM(G25:G26) -> 0 | H27: =SUM(H25:H26) -> 0 | I27: =SUM(I25:I26) -> 2 | J27: =SUM(J25:J26) -> 0 | K27: =SUM(K25:K26) -> 0 | L27: =SUM(L25:L26) -> 0 | M27: =SUM(M25:M26) -> 0 | N27: =SUM(E27:M27) -> 7
B28: 4. | C28: Jumlah Pengguna Hak Pilih (B.1+B.2+B.3) | D28: LK | E28: =SUM(E19,E22,E25) -> 108 | F28: =SUM(F19,F22,F25) -> 81 | G28: =SUM(G19,G22,G25) -> 96 | H28: =SUM(H19,H22,H25) -> 100 | I28: =SUM(I19,I22,I25) -> 89 | J28: =SUM(J19,J22,J25) -> 90 | K28: =SUM(K19,K22,K25) -> 103 | L28: =SUM(L19,L22,L25) -> 94 | M28: =SUM(M19,M22,M25) -> 84 | N28: =SUM(E28:M28) -> 845
D29: PR | E29: =SUM(E20,E23,E26) -> 118 | F29: =SUM(F20,F23,F26) -> 96 | G29: =SUM(G20,G23,G26) -> 117 | H29: =SUM(H20,H23,H26) -> 106 | I29: =SUM(I20,I23,I26) -> 117 | J29: =SUM(J20,J23,J26) -> 110 | K29: =SUM(K20,K23,K26) -> 103 | L29: =SUM(L20,L23,L26) -> 106 | M29: =SUM(M20,M23,M26) -> 104 | N29: =SUM(E29:M29) -> 977
D30: JML | E30: =SUM(E28:E29) -> 226 | F30: =SUM(F28:F29) -> 177 | G30: =SUM(G28:G29) -> 213 | H30: =SUM(H28:H29) -> 206 | I30: =SUM(I28:I29) -> 206 | J30: =SUM(J28:J29) -> 200 | K30: =SUM(K28:K29) -> 206 | L30: =SUM(L28:L29) -> 200 | M30: =SUM(M28:M29) -> 188 | N30: =SUM(E30:M30) -> 1822
A32: II | B32: DATA PENGGUNAAN SURAT SUARA
A33: 1 | B33: Jumlah surat suara yang diterima, termasuk surat suara cadangan 2% dari DPT | E33: 268 | F33: 218 | G33: 246 | H33: 226 | I33: 237 | J33: 225 | K33: 228 | L33: 228 | M33: 223 | N33: =SUM(E33:M33) -> 2099
A34: 2 | B34: Jumlah surat suara yang digunakan | E34: 226 | F34: 177 | G34: 213 | H34: 206 | I34: 206 | J34: 200 | K34: 206 | L34: 200 | M34: 188 | N34: =SUM(E34:M34) -> 1822
A35: 3 | B35: Jumlah surat suara dikembalikan oleh pemilih (karena rusak atau keliru coblos) | E35: 0 | F35: 0 | G35: 0 | H35: 0 | I35: 0 | J35: 0 | K35: 0 | L35: 0 | M35: 0 | N35: =SUM(E35:M35) -> 0
A36: 4 | B36: Jumlah surat suara yang tidak digunakan/tidak terpakai, termasuk sisa surat suara cadangan | E36: =E33-(E34+E35) -> 42 | F36: =F33-(F34+F35) -> 41 | G36: =G33-(G34+G35) -> 33 | H36: =H33-(H34+H35) -> 20 | I36: =I33-(I34+I35) -> 31 | J36: =J33-(J34+J35) -> 25 | K36: =K33-(K34+K35) -> 22 | L36: =L33-(L34+L35) -> 28 | M36: =M33-(M34+M35) -> 35 | N36: =SUM(E36:M36) -> 277
A38: III | B38: DATA PEMILIH DISABILITAS
B39: Jumlah seluruh Pemilih disabilitas yang menggunakan hak pilih | D39: LK | E39: 1 | I39: 1 | N39: =SUM(E39:M39) -> 2
D40: PR | K40: 2 | M40: 2 | N40: =SUM(E40:M40) -> 4
D41: JML | E41: =SUM(E39:E40) -> 1 | F41: =SUM(F39:F40) -> 0 | G41: =SUM(G39:G40) -> 0 | H41: =SUM(H39:H40) -> 0 | I41: =SUM(I39:I40) -> 1 | J41: =SUM(J39:J40) -> 0 | K41: =SUM(K39:K40) -> 2 | L41: =SUM(L39:L40) -> 0 | M41: =SUM(M39:M40) -> 2 | N41: =SUM(E41:M41) -> 6
A43: IV | B43: DATA RINCIAN PEROLEHAN SUARA PASANGAN CALON BUPATI DAN WAKIL BUPATI
A44: NOMOR DAN NAMA CALON
A45: A.1 | B45: 1. | C45: Partai Kebangkitan Bangsa | E45: 5 | F45: 1 | G45: 4 | H45: 1 | I45: 3 | J45: 6 | K45: 11 | L45: 4 | M45: 2 | N45: =SUM(E45:M45) -> 37
A46: A.2 | C46: 1. ANITA RANI, S.H. | E46: 5 | F46: 1 | G46: 5 | H46: 19 | I46: 6 | J46: 9 | K46: 7 | L46: 4 | M46: 6 | N46: =SUM(E46:M46) -> 62
C47: 2. ANISAH MAHSUNAH, S.E. | E47: 0 | F47: 0 | G47: 2 | H47: 0 | I47: 2 | J47: 0 | K47: 5 | L47: 2 | M47: 0 | N47: =SUM(E47:M47) -> 11
C48: 3. SENARI, S.Sos. | E48: 0 | F48: 1 | G48: 0 | H48: 0 | I48: 1 | J48: 0 | K48: 0 | L48: 0 | M48: 2 | N48: =SUM(E48:M48) -> 4
C49: 4. VERAGAWATI, S.H. | E49: 0 | F49: 0 | G49: 0 | H49: 0 | I49: 0 | J49: 0 | K49: 0 | L49: 0 | M49: 0 | N49: =SUM(E49:M49) -> 0
C50: 5. KURDI EHSAN | E50: 0 | F50: 0 | G50: 0 | H50: 0 | I50: 0 | J50: 0 | K50: 0 | L50: 0 | M50: 0 | N50: =SUM(E50:M50) -> 0
C51: 6. BONDAN ARDYWIJAYA | E51: 0 | F51: 1 | G51: 0 | H51: 1 | I51: 0 | J51: 1 | K51: 2 | L51: 3 | M51: 1 | N51: =SUM(E51:M51) -> 9
...

Sheet GLAGAH
C2: Kecamatan | D2: GLAGAH
C3: Kabupaten | D3: BANYUWANGI
C4: Provinsi | D4: JAWA TIMUR
C9: Kelurahan | D9: GLAGAH
A12: I | B12: DATA PEMILIH DAN PENGGUNAAN HAK PILIH | M12: JUMLAH AKHIR
A13: A | B13: DATA PEMILIH | E13: TPS 001 | F13: TPS 002 | G13: TPS 003 | H13: TPS 004 | I13: TPS 005 | J13: TPS 006 | K13: TPS 007 | L13: TPS 008
B14: Jumlah Pemilih dalam Daftar Pemilih Tetap (DPT) | D14: LK | E14: 129 | F14: 118 | G14: 128 | H14: 113 | I14: 131 | J14: 112 | K14: 123 | L14: 88 | M14: =SUM(E14:L14) -> 942
D15: PR | E15: 126 | F15: 117 | G15: 116 | H15: 129 | I15: 138 | J15: 128 | K15: 163 | L15: 106 | M15: =SUM(E15:L15) -> 1023
D16: JML | E16: =SUM(E14:E15) -> 255 | F16: =SUM(F14:F15) -> 235 | G16: =SUM(G14:G15) -> 244 | H16: =SUM(H14:H15) -> 242 | I16: =SUM(I14:I15) -> 269 | J16: =SUM(J14:J15) -> 240 | K16: =SUM(K14:K15) -> 286 | L16: =SUM(L14:L15) -> 194 | M16: =SUM(E16:L16) -> 1965
A18: B | B18: PENGGUNA HAK PILIH
B19: 1. | C19: Jumlah pengguna hak pilih dalam Daftar Pemilih Tetap (DPT) | D19: LK | E19: 106 | F19: 99 | G19: 105 | H19: 97 | I19: 112 | J19: 98 | K19: 99 | L19: 72 | M19: =SUM(E19:L19) -> 788
D20: PR | E20: 101 | F20: 105 | G20: 96 | H20: 120 | I20: 115 | J20: 116 | K20: 131 | L20: 90 | M20: =SUM(E20:L20) -> 874
D21: JML | E21: =SUM(E19:E20) -> 207 | F21: =SUM(F19:F20) -> 204 | G21: =SUM(G19:G20) -> 201 | H21: =SUM(H19:H20) -> 217 | I21: =SUM(I19:I20) -> 227 | J21: =SUM(J19:J20) -> 214 | K21: =SUM(K19:K20) -> 230 | L21: =SUM(L19:L20) -> 162 | M21: =SUM(E21:L21) -> 1662
B22: 2. | C22: Jumlah pengguna hak pilih dalam Daftar Pemilih Tambahan (DPTb) | D22: LK | E22: 0 | F22: 0 | G22: 0 | H22: 0 | I22: 0 | J22: 1 | K22: 0 | L22: 0 | M22: =SUM(E22:L22) -> 1
D23: PR | E23: 0 | F23: 0 | G23: 0 | H23: 0 | I23: 0 | J23: 0 | K23: 0 | L23: 0 | M23: =SUM(E23:L23) -> 0
D24: JML | E24: =SUM(E22:E23) -> 0 | F24: =SUM(F22:F23) -> 0 | G24: =SUM(G22:G23) -> 0 | H24: =SUM(H22:H23) -> 0 | I24: =SUM(I22:I23) -> 0 | J24: =SUM(J22:J23) -> 1 | K24: =SUM(K22:K23) -> 0 | L24: =SUM(L22:L23) -> 0 | M24: =SUM(E24:L24) -> 1
B25: 3. | C25: Jumlah pengguna hak pilih dalam Daftar Pemilih Khusus (DPK) | D25: LK | E25: 1 | F25: 1 | G25: 1 | H25: 2 | I25: 2 | J25: 0 | K25: 2 | L25: 0 | M25: =SUM(E25:L25) -> 9
D26: PR | E26: 2 | F26: 0 | G26: 6 | H26: 1 | I26: 1 | J26: 1 | K26: 7 | L26: 1 | M26: =SUM(E26:L26) -> 19
D27: JML | E27: =SUM(E25:E26) -> 3 | F27: =SUM(F25:F26) -> 1 | G27: =SUM(G25:G26) -> 7 | H27: =SUM(H25:H26) -> 3 | I27: =SUM(I25:I26) -> 3 | J27: =SUM(J25:J26) -> 1 | K27: =SUM(K25:K26) -> 9 | L27: =SUM(L25:L26) -> 1 | M27: =SUM(E27:L27) -> 28
B28: 4. | C28: Jumlah Pengguna Hak Pilih (B.1+B.2+B.3) | D28: LK | E28: =SUM(E19,E22,E25) -> 107 | F28: =SUM(F19,F22,F25) -> 100 | G28: =SUM(G19,G22,G25) -> 106 | H28: =SUM(H19,H22,H25) -> 99 | I28: =SUM(I19,I22,I25) -> 114 | J28: =SUM(J19,J22,J25) -> 99 | K28: =SUM(K19,K22,K25) -> 101 | L28: =SUM(L19,L22,L25) -> 72 | M28: =SUM(E28:L28) -> 798
D29: PR | E29: =SUM(E20,E23,E26) -> 103 | F29: =SUM(F20,F23,F26) -> 105 | G29: =SUM(G20,G23,G26) -> 102 | H29: =SUM(H20,H23,H26) -> 121 | I29: =SUM(I20,I23,I26) -> 116 | J29: =SUM(J20,J23,J26) -> 117 | K29: =SUM(K20,K23,K26) -> 138 | L29: =SUM(L20,L23,L26) -> 91 | M29: =SUM(E29:L29) -> 893
D30: JML | E30: =SUM(E28:E29) -> 210 | F30: =SUM(F28:F29) -> 205 | G30: =SUM(G28:G29) -> 208 | H30: =SUM(H28:H29) -> 220 | I30: =SUM(I28:I29) -> 230 | J30: =SUM(J28:J29) -> 216 | K30: =SUM(K28:K29) -> 239 | L30: =SUM(L28:L29) -> 163 | M30: =SUM(E30:L30) -> 1691
A32: II | B32: DATA PENGGUNAAN SURAT SUARA
A33: 1 | B33: Jumlah surat suara yang diterima, termasuk surat suara cadangan 2% dari DPT | E33: 261 | F33: 240 | G33: 249 | H33: 247 | I33: 275 | J33: 245 | K33: 292 | L33: 199 | M33: =SUM(E33:L33) -> 2008
A34: 2 | B34: Jumlah surat suara yang digunakan | E34: 210 | F34: 205 | G34: 208 | H34: 220 | I34: 230 | J34: 216 | K34: 239 | L34: 163 | M34: =SUM(E34:L34) -> 1691
A35: 3 | B35: Jumlah surat suara dikembalikan oleh pemilih (karena rusak atau keliru coblos) | E35: 0 | F35: 0 | G35: 0 | H35: 0 | I35: 0 | J35: 0 | K35: 0 | L35: 0 | M35: =SUM(E35:L35) -> 0
A36: 4 | B36: Jumlah surat suara yang tidak digunakan/tidak terpakai, termasuk sisa surat suara cadangan | E36: =E33-(E34+E35) -> 51 | F36: =F33-(F34+F35) -> 35 | G36: =G33-(G34+G35) -> 41 | H36: =H33-(H34+H35) -> 27 | I36: =I33-(I34+I35) -> 45 | J36: =J33-(J34+J35) -> 29 | K36: =K33-(K34+K35) -> 53 | L36: =L33-(L34+L35) -> 36 | M36: =SUM(E36:L36) -> 317
A38: III | B38: DATA PEMILIH DISABILITAS
B39: Jumlah seluruh Pemilih disabilitas yang menggunakan hak pilih | D39: LK | G39: 1 | M39: =SUM(E39:L39) -> 1
D40: PR | G40: 3 | L40: 1 | M40: =SUM(E40:L40) -> 4
D41: JML | E41: =SUM(E39:E40) -> 0 | F41: =SUM(F39:F40) -> 0 | G41: =SUM(G39:G40) -> 4 | H41: =SUM(H39:H40) -> 0 | I41: =SUM(I39:I40) -> 0 | J41: =SUM(J39:J40) -> 0 | K41: =SUM(K39:K40) -> 0 | L41: =SUM(L39:L40) -> 1 | M41: =SUM(E41:L41) -> 5
A43: IV | B43: DATA RINCIAN PEROLEHAN SUARA PASANGAN CALON BUPATI DAN WAKIL BUPATI
A44: NOMOR DAN NAMA CALON
A45: A.1 | B45: 1. | C45: Partai Kebangkitan Bangsa | E45: 2 | F45: 7 | G45: 4 | H45: 4 | I45: 3 | J45: 4 | K45: 3 | L45: 1 | M45: =SUM(E45:L45) -> 28
A46: A.2 | C46: 1. ANITA RANI, S.H. | E46: 1 | F46: 1 | G46: 3 | H46: 1 | I46: 2 | J46: 2 | K46: 2 | L46: 0 | M46: =SUM(E46:L46) -> 12
C47: 2. ANISAH MAHSUNAH, S.E. | E47: 0 | F47: 3 | G47: 1 | H47: 1 | I47: 0 | J47: 1 | K47: 1 | L47: 0 | M47: =SUM(E47:L47) -> 7
C48: 3. SENARI, S.Sos. | E48: 0 | F48: 0 | G48: 2 | H48: 0 | I48: 0 | J48: 0 | K48: 5 | L48: 0 | M48: =SUM(E48:L48) -> 7
C49: 4. VERAGAWATI, S.H. | E49: 0 | F49: 0 | G49: 0 | H49: 0 | I49: 0 | J49: 0 | K49: 0 | L49: 0 | M49: =SUM(E49:L49) -> 0
C50: 5. KURDI EHSAN | E50: 0 | F50: 0 | G50: 0 | H50: 0 | I50: 0 | J50: 0 | K50: 0 | L50: 0 | M50: =SUM(E50:L50) -> 0
C51: 6. BONDAN ARDYWIJAYA | E51: 0 | F51: 0 | G51: 1 | H51: 3 | I51: 0 | J51: 0 | K51: 0 | L51: 0 | M51: =SUM(E51:L51) -> 4
...

Sheet PASPAN
C2: Kecamatan | D2: GLAGAH
C3: Kabupaten | D3: BANYUWANGI
C4: Provinsi | D4: JAWA TIMUR
C9: Kelurahan | D9: PASPAN
A12: I | B12: DATA PEMILIH DAN PENGGUNAAN HAK PILIH | P12: JUMLAH AKHIR
A13: A | B13: DATA PEMILIH | E13: TPS 001 | F13: TPS 002 | G13: TPS 003 | H13: TPS 004 | I13: TPS 005 | J13: TPS 006 | K13: TPS 007 | L13: TPS 008 | M13: TPS 009 | N13: TPS 010 | O13: TPS 011
B14: Jumlah Pemilih dalam Daftar Pemilih Tetap (DPT) | D14: LK | E14: 113 | F14: 114 | G14: 111 | H14: 115 | I14: 110 | J14: 116 | K14: 124 | L14: 125 | M14: 124 | N14: 122 | O14: 129 | P14: =SUM(E14:O14) -> 1303
D15: PR | E15: 109 | F15: 113 | G15: 111 | H15: 112 | I15: 112 | J15: 113 | K15: 112 | L15: 128 | M15: 102 | N15: 112 | O15: 129 | P15: =SUM(E15:O15) -> 1253
D16: JML | E16: =SUM(E14:E15) -> 222 | F16: =SUM(F14:F15) -> 227 | G16: =SUM(G14:G15) -> 222 | H16: =SUM(H14:H15) -> 227 | I16: =SUM(I14:I15) -> 222 | J16: =SUM(J14:J15) -> 229 | K16: =SUM(K14:K15) -> 236 | L16: =SUM(L14:L15) -> 253 | ... O16: =SUM(O14:O15) -> 258 | P16: =SUM(E16:O16) -> 2556
A18: B | B18: PENGGUNA HAK PILIH
B19: 1. | C19: Jumlah pengguna hak pilih dalam Daftar Pemilih Tetap (DPT) | D19: LK | E19: 90 | F19: 100 | G19: 93 | H19: 97 | I19: 97 | J19: 97 | K19: 112 | L19: 105 | M19: 102 | N19: 97 | O19: 117 | P19: =SUM(E19:O19) -> 1107
D20: PR | E20: 99 | F20: 108 | G20: 99 | H20: 103 | I20: 110 | J20: 109 | K20: 103 | L20: 118 | M20: 88 | N20: 95 | O20: 117 | P20: =SUM(E20:O20) -> 1149
D21: JML | E21: =SUM(E19:E20) -> 189 | F21: =SUM(F19:F20) -> 208 | G21: =SUM(G19:G20) -> 192 | H21: =SUM(H19:H20) -> 200 | I21: =SUM(I19:I20) -> 207 | J21: =SUM(J19:J20) -> 206 | K21: =SUM(K19:K20) -> 215 | L21: =SUM(L19:L20) -> 223 | ... O21: =SUM(O19:O20) -> 234 | P21: =SUM(E21:O21) -> 2256
B22: 2. | C22: Jumlah pengguna hak pilih dalam Daftar Pemilih Tambahan (DPTb) | D22: LK | E22: 0 | F22: 0 | G22: 0 | H22: 0 | I22: 0 | J22: 0 | K22: 0 | L22: 0 | M22: 0 | N22: 0 | O22: 0 | P22: =SUM(E22:O22) -> 0
D23: PR | E23: 1 | F23: 0 | G23: 0 | H23: 0 | I23: 0 | J23: 0 | K23: 0 | L23: 0 | M23: 0 | N23: 1 | O23: 1 | P23: =SUM(E23:O23) -> 3
D24: JML | E24: =SUM(E22:E23) -> 1 | F24: =SUM(F22:F23) -> 0 | G24: =SUM(G22:G23) -> 0 | H24: =SUM(H22:H23) -> 0 | I24: =SUM(I22:I23) -> 0 | J24: =SUM(J22:J23) -> 0 | K24: =SUM(K22:K23) -> 0 | L24: =SUM(L22:L23) -> 0 | ... O24: =SUM(O22:O23) -> 1 | P24: =SUM(E24:O24) -> 3
B25: 3. | C25: Jumlah pengguna hak pilih dalam Daftar Pemilih Khusus (DPK) | D25: LK | E25: 0 | F25: 0 | G25: 0 | H25: 2 | I25: 0 | J25: 0 | K25: 0 | L25: 0 | M25: 0 | N25: 0 | O25: 1 | P25: =SUM(E25:O25) -> 3
D26: PR | E26: 0 | F26: 0 | G26: 0 | H26: 3 | I26: 2 | J26: 0 | K26: 0 | L26: 2 | M26: 0 | N26: 0 | O26: 1 | P26: =SUM(E26:O26) -> 8
D27: JML | E27: =SUM(E25:E26) -> 0 | F27: =SUM(F25:F26) -> 0 | G27: =SUM(G25:G26) -> 0 | H27: =SUM(H25:H26) -> 5 | I27: =SUM(I25:I26) -> 2 | J27: =SUM(J25:J26) -> 0 | K27: =SUM(K25:K26) -> 0 | L27: =SUM(L25:L26) -> 2 | ... O27: =SUM(O25:O26) -> 2 | P27: =SUM(E27:O27) -> 11
B28: 4. | C28: Jumlah Pengguna Hak Pilih (B.1+B.2+B.3) | D28: LK | E28: =SUM(E19,E22,E25) -> 90 | F28: =SUM(F19,F22,F25) -> 100 | G28: =SUM(G19,G22,G25) -> 93 | H28: =SUM(H19,H22,H25) -> 99 | I28: =SUM(I19,I22,I25) -> 97 | J28: =SUM(J19,J22,J25) -> 97 | K28: =SUM(K19,K22,K25) -> 112 | L28: =SUM(L19,L22,L25) -> 105 | ... O28: =SUM(O19,O22,O25) -> 118 | P28: =SUM(E28:O28) -> 1110
D29: PR | E29: =SUM(E20,E23,E26) -> 100 | F29: =SUM(F20,F23,F26) -> 108 | G29: =SUM(G20,G23,G26) -> 99 | H29: =SUM(H20,H23,H26) -> 106 | I29: =SUM(I20,I23,I26) -> 112 | J29: =SUM(J20,J23,J26) -> 109 | K29: =SUM(K20,K23,K26) -> 103 | L29: =SUM(L20,L23,L26) -> 120 | ... O29: =SUM(O20,O23,O26) -> 119 | P29: =SUM(E29:O29) -> 1160
D30: JML | E30: =SUM(E28:E29) -> 190 | F30: =SUM(F28:F29) -> 208 | G30: =SUM(G28:G29) -> 192 | H30: =SUM(H28:H29) -> 205 | I30: =SUM(I28:I29) -> 209 | J30: =SUM(J28:J29) -> 206 | K30: =SUM(K28:K29) -> 215 | L30: =SUM(L28:L29) -> 225 | ... O30: =SUM(O28:O29) -> 237 | P30: =SUM(E30:O30) -> 2270
A32: II | B32: DATA PENGGUNAAN SURAT SUARA
A33: 1 | B33: Jumlah surat suara yang diterima, termasuk surat suara cadangan 2% dari DPT | E33: 227 | F33: 232 | G33: 227 | H33: 232 | I33: 227 | J33: 234 | K33: 239 | L33: 259 | M33: 228 | N33: 239 | O33: 264 | P33: =SUM(E33:O33) -> 2608
A34: 2 | B34: Jumlah surat suara yang digunakan | E34: 190 | F34: 208 | G34: 192 | H34: 205 | I34: 209 | J34: 206 | K34: 215 | L34: 225 | M34: 190 | N34: 193 | O34: 237 | P34: =SUM(E34:O34) -> 2270
A35: 3 | B35: Jumlah surat suara dikembalikan oleh pemilih (karena rusak atau keliru coblos) | E35: 5 | F35: 1 | G35: 0 | H35: 0 | I35: 0 | J35: 0 | K35: 0 | L35: 0 | M35: 0 | N35: 0 | O35: 0 | P35: =SUM(E35:O35) -> 6
A36: 4 | B36: Jumlah surat suara yang tidak digunakan/tidak terpakai, termasuk sisa surat suara cadangan | E36: =E33-(E34+E35) -> 32 | F36: =F33-(F34+F35) -> 23 | G36: =G33-(G34+G35) -> 35 | H36: =H33-(H34+H35) -> 27 | I36: =I33-(I34+I35) -> 18 | J36: =J33-(J34+J35) -> 28 | K36: =K33-(K34+K35) -> 24 | L36: =L33-(L34+L35) -> 34 | ... O36: =O33-(O34+O35) -> 27 | P36: =SUM(E36:O36) -> 332
A38: III | B38: DATA PEMILIH DISABILITAS
B39: Jumlah seluruh Pemilih disabilitas yang menggunakan hak pilih | D39: LK | P39: =SUM(E39:O39) -> 0
D40: PR | P40: =SUM(E40:O40) -> 0
D41: JML | E41: =SUM(E39:E40) -> 0 | F41: =SUM(F39:F40) -> 0 | G41: =SUM(G39:G40) -> 0 | H41: =SUM(H39:H40) -> 0 | I41: =SUM(I39:I40) -> 0 | J41: =SUM(J39:J40) -> 0 | K41: =SUM(K39:K40) -> 0 | L41: =SUM(L39:L40) -> 0 | ... O41: =SUM(O39:O40) -> 0 | P41: =SUM(E41:O41) -> 0
A43: IV | B43: DATA RINCIAN PEROLEHAN SUARA PASANGAN CALON BUPATI DAN WAKIL BUPATI
A44: NOMOR DAN NAMA CALON
A45: A.1 | B45: 1. | C45: Partai Kebangkitan Bangsa | E45: 10 | F45: 7 | G45: 6 | H45: 9 | I45: 3 | J45: 4 | K45: 2 | L45: 3 | M45: 1 | N45: 7 | O45: 2 | P45: =SUM(E45:O45) -> 54
A46: A.2 | C46: 1. ANITA RANI, S.H. | E46: 7 | F46: 9 | G46: 10 | H46: 4 | I46: 0 | J46: 1 | K46: 3 | L46: 3 | M46: 4 | N46: 3 | O46: 3 | P46: =SUM(E46:O46) -> 47
C47: 2. ANISAH MAHSUNAH, S.E. | E47: 4 | F47: 3 | G47: 5 | H47: 5 | I47: 2 | J47: 1 | K47: 0 | L47: 2 | M47: 0 | N47: 1 | O47: 5 | P47: =SUM(E47:O47) -> 28
C48: 3. SENARI, S.Sos. | E48: 1 | F48: 0 | G48: 0 | H48: 0 | I48: 0 | J48: 1 | K48: 0 | L48: 0 | M48: 1 | N48: 1 | O48: 1 | P48: =SUM(E48:O48) -> 5
C49: 4. VERAGAWATI, S.H. | E49: 0 | F49: 0 | G49: 0 | H49: 1 | I49: 0 | J49: 0 | K49: 0 | L49: 0 | M49: 0 | N49: 2 | O49: 0 | P49: =SUM(E49:O49) -> 3
C50: 5. KURDI EHSAN | E50: 0 | F50: 0 | G50: 1 | H50: 0 | I50: 0 | J50: 0 | K50: 1 | L50: 0 | M50: 0 | N50: 0 | O50: 0 | P50: =SUM(E50:O50) -> 2
C51: 6. BONDAN ARDYWIJAYA | E51: 2 | F51: 0 | G51: 0 | H51: 0 | I51: 0 | J51: 0 | K51: 0 | L51: 0 | M51: 0 | N51: 0 | O51: 0 | P51: =SUM(E51:O51) -> 2
...

Sheet TAMANSURUH
C2: Kecamatan | D2: GLAGAH
C3: Kabupaten | D3: BANYUWANGI
C4: Provinsi | D4: JAWA TIMUR
C9: Kelurahan | D9: TAMANSURUH
A12: I | B12: DATA PEMILIH DAN PENGGUNAAN HAK PILIH | S12: JUMLAH AKHIR
A13: A | B13: DATA PEMILIH | E13: TPS 001 | F13: TPS 002 | G13: TPS 003 | H13: TPS 004 | I13: TPS 005 | J13: TPS 006 | K13: TPS 007 | L13: TPS 008 | M13: TPS 009 | N13: TPS 010 | O13: TPS 011 | P13: TPS 012 | Q13: TPS 013 | R13: TPS 014
B14: Jumlah Pemilih dalam Daftar Pemilih Tetap (DPT) | D14: LK | E14: 101 | F14: 113 | G14: 135 | H14: 101 | I14: 113 | J14: 120 | K14: 126 | L14: 142 | M14: 130 | N14: 136 | O14: 120 | P14: 135 | Q14: 102 | R14: 105 | S14: =SUM(E14:R14) -> 1679
D15: PR | E15: 113 | F15: 124 | G15: 140 | H15: 124 | I15: 132 | J15: 121 | K15: 143 | L15: 143 | M15: 153 | N15: 141 | O15: 123 | P15: 158 | Q15: 96 | R15: 106 | S15: =SUM(E15:R15) -> 1817
D16: JML | E16: =SUM(E14:E15) -> 214 | F16: =SUM(F14:F15) -> 237 | G16: =SUM(G14:G15) -> 275 | H16: =SUM(H14:H15) -> 225 | I16: =SUM(I14:I15) -> 245 | J16: =SUM(J14:J15) -> 241 | K16: =SUM(K14:K15) -> 269 | L16: =SUM(L14:L15) -> 285 | ... R16: =SUM(R14:R15) -> 211 | S16: =SUM(E16:R16) -> 3496
A18: B | B18: PENGGUNA HAK PILIH
B19: 1. | C19: Jumlah pengguna hak pilih dalam Daftar Pemilih Tetap (DPT) | D19: LK | E19: 97 | F19: 101 | G19: 113 | H19: 85 | I19: 92 | J19: 102 | K19: 91 | L19: 107 | M19: 102 | N19: 112 | O19: 91 | P19: 121 | Q19: 92 | R19: 83 | S19: =SUM(E19:R19) -> 1389
D20: PR | E20: 105 | F20: 103 | G20: 125 | H20: 107 | I20: 113 | J20: 103 | K20: 113 | L20: 115 | M20: 128 | N20: 122 | O20: 105 | P20: 138 | Q20: 90 | R20: 93 | S20: =SUM(E20:R20) -> 1560
D21: JML | E21: =SUM(E19:E20) -> 202 | F21: =SUM(F19:F20) -> 204 | G21: =SUM(G19:G20) -> 238 | H21: =SUM(H19:H20) -> 192 | I21: =SUM(I19:I20) -> 205 | J21: =SUM(J19:J20) -> 205 | K21: =SUM(K19:K20) -> 204 | L21: =SUM(L19:L20) -> 222 | ... R21: =SUM(R19:R20) -> 176 | S21: =SUM(E21:R21) -> 2949
B22: 2. | C22: Jumlah pengguna hak pilih dalam Daftar Pemilih Tambahan (DPTb) | D22: LK | E22: 0 | F22: 0 | G22: 0 | H22: 0 | I22: 1 | J22: 0 | K22: 0 | L22: 0 | M22: 0 | N22: 0 | O22: 0 | P22: 0 | Q22: 0 | R22: 1 | S22: =SUM(E22:R22) -> 2
D23: PR | E23: 0 | F23: 0 | G23: 0 | H23: 0 | I23: 1 | J23: 0 | K23: 3 | L23: 0 | M23: 0 | N23: 0 | O23: 0 | P23: 0 | Q23: 0 | R23: 0 | S23: =SUM(E23:R23) -> 4
D24: JML | E24: =SUM(E22:E23) -> 0 | F24: =SUM(F22:F23) -> 0 | G24: =SUM(G22:G23) -> 0 | H24: =SUM(H22:H23) -> 0 | I24: =SUM(I22:I23) -> 2 | J24: =SUM(J22:J23) -> 0 | K24: =SUM(K22:K23) -> 3 | L24: =SUM(L22:L23) -> 0 | ... R24: =SUM(R22:R23) -> 1 | S24: =SUM(E24:R24) -> 6
B25: 3. | C25: Jumlah pengguna hak pilih dalam Daftar Pemilih Khusus (DPK) | D25: LK | E25: 0 | F25: 0 | G25: 0 | H25: 0 | I25: 0 | J25: 1 | K25: 1 | L25: 0 | M25: 1 | N25: 0 | O25: 0 | P25: 0 | Q25: 0 | R25: 0 | S25: =SUM(E25:R25) -> 3
D26: PR | E26: 0 | F26: 0 | G26: 0 | H26: 0 | I26: 0 | J26: 2 | K26: 2 | L26: 0 | M26: 4 | N26: 0 | O26: 0 | P26: 0 | Q26: 0 | R26: 0 | S26: =SUM(E26:R26) -> 8
D27: JML | E27: =SUM(E25:E26) -> 0 | F27: =SUM(F25:F26) -> 0 | G27: =SUM(G25:G26) -> 0 | H27: =SUM(H25:H26) -> 0 | I27: =SUM(I25:I26) -> 0 | J27: =SUM(J25:J26) -> 3 | K27: =SUM(K25:K26) -> 3 | L27: =SUM(L25:L26) -> 0 | ... R27: =SUM(R25:R26) -> 0 | S27: =SUM(E27:R27) -> 11
B28: 4. | C28: Jumlah Pengguna Hak Pilih (B.1+B.2+B.3) | D28: LK | E28: =SUM(E19,E22,E25) -> 97 | F28: =SUM(F19,F22,F25) -> 101 | G28: =SUM(G19,G22,G25) -> 113 | H28: =SUM(H19,H22,H25) -> 85 | I28: =SUM(I19,I22,I25) -> 93 | J28: =SUM(J19,J22,J25) -> 103 | K28: =SUM(K19,K22,K25) -> 92 | L28: =SUM(L19,L22,L25) -> 107 | ... R28: =SUM(R19,R22,R25) -> 84 | S28: =SUM(E28:R28) -> 1394
D29: PR | E29: =SUM(E20,E23,E26) -> 105 | F29: =SUM(F20,F23,F26) -> 103 | G29: =SUM(G20,G23,G26) -> 125 | H29: =SUM(H20,H23,H26) -> 107 | I29: =SUM(I20,I23,I26) -> 114 | J29: =SUM(J20,J23,J26) -> 105 | K29: =SUM(K20,K23,K26) -> 118 | L29: =SUM(L20,L23,L26) -> 115 | ... R29: =SUM(R20,R23,R26) -> 93 | S29: =SUM(E29:R29) -> 1572
D30: JML | E30: =SUM(E28:E29) -> 202 | F30: =SUM(F28:F29) -> 204 | G30: =SUM(G28:G29) -> 238 | H30: =SUM(H28:H29) -> 192 | I30: =SUM(I28:I29) -> 207 | J30: =SUM(J28:J29) -> 208 | K30: =SUM(K28:K29) -> 210 | L30: =SUM(L28:L29) -> 222 | ... R30: =SUM(R28:R29) -> 177 | S30: =SUM(E30:R30) -> 2966
A32: II | B32: DATA PENGGUNAAN SURAT SUARA
A33: 1 | B33: Jumlah surat suara yang diterima, termasuk surat suara cadangan 2% dari DPT | E33: 219 | F33: 244 | G33: 281 | H33: 230 | I33: 250 | J33: 246 | K33: 275 | L33: 291 | M33: 289 | N33: 284 | O33: 250 | P33: 299 | Q33: 212 | R33: 226 | S33: =SUM(E33:R33) -> 3596
A34: 2 | B34: Jumlah surat suara yang digunakan | E34: 202 | F34: 204 | G34: 238 | H34: 192 | I34: 207 | J34: 208 | K34: 210 | L34: 222 | M34: 235 | N34: 234 | O34: 196 | P34: 259 | Q34: 182 | R34: 177 | S34: =SUM(E34:R34) -> 2966
A35: 3 | B35: Jumlah surat suara dikembalikan oleh pemilih (karena rusak atau keliru coblos) | E35: 0 | F35: 0 | G35: 0 | H35: 1 | I35: 1 | J35: 0 | K35: 2 | L35: 0 | M35: 0 | N35: 0 | O35: 0 | P35: 0 | Q35: 0 | R35: 0 | S35: =SUM(E35:R35) -> 4
A36: 4 | B36: Jumlah surat suara yang tidak digunakan/tidak terpakai, termasuk sisa surat suara cadangan | E36: =E33-(E34+E35) -> 17 | F36: =F33-(F34+F35) -> 40 | G36: =G33-(G34+G35) -> 43 | H36: =H33-(H34+H35) -> 37 | I36: =I33-(I34+I35) -> 42 | J36: =J33-(J34+J35) -> 38 | K36: =K33-(K34+K35) -> 63 | L36: =L33-(L34+L35) -> 69 | ... R36: =R33-(R34+R35) -> 49 | S36: =SUM(E36:R36) -> 626
A38: III | B38: DATA PEMILIH DISABILITAS
B39: Jumlah seluruh Pemilih disabilitas yang menggunakan hak pilih | D39: LK | S39: =SUM(E39:R39) -> 0
D40: PR | S40: =SUM(E40:R40) -> 0
D41: JML | E41: =SUM(E39:E40) -> 0 | F41: =SUM(F39:F40) -> 0 | G41: =SUM(G39:G40) -> 0 | H41: =SUM(H39:H40) -> 0 | I41: =SUM(I39:I40) -> 0 | J41: =SUM(J39:J40) -> 0 | K41: =SUM(K39:K40) -> 0 | L41: =SUM(L39:L40) -> 0 | ... R41: =SUM(R39:R40) -> 0 | S41: =SUM(E41:R41) -> 0
A43: IV | B43: DATA RINCIAN PEROLEHAN SUARA PASANGAN CALON BUPATI DAN WAKIL BUPATI
A44: NOMOR DAN NAMA CALON
A45: A.1 | B45: 1. | C45: Partai Kebangkitan Bangsa | E45: 25 | F45: 16 | G45: 14 | H45: 17 | I45: 10 | J45: 4 | K45: 12 | L45: 8 | M45: 7 | N45: 10 | O45: 12 | P45: 10 | Q45: 9 | R45: 12 | S45: =SUM(E45:R45) -> 166
A46: A.2 | C46: 1. ANITA RANI, S.H. | E46: 18 | F46: 20 | G46: 27 | H46: 22 | I46: 11 | J46: 19 | K46: 13 | L46: 17 | M46: 4 | N46: 12 | O46: 28 | P46: 4 | Q46: 5 | R46: 3 | S46: =SUM(E46:R46) -> 203
C47: 2. ANISAH MAHSUNAH, S.E. | E47: 7 | F47: 20 | G47: 6 | H47: 9 | I47: 1 | J47: 0 | K47: 4 | L47: 1 | M47: 0 | N47: 3 | O47: 0 | P47: 1 | Q47: 1 | R47: 2 | S47: =SUM(E47:R47) -> 55
C48: 3. SENARI, S.Sos. | E48: 14 | F48: 5 | G48: 3 | H48: 2 | I48: 6 | J48: 8 | K48: 0 | L48: 2 | M48: 0 | N48: 0 | O48: 2 | P48: 1 | Q48: 0 | R48: 0 | S48: =SUM(E48:R48) -> 43
C49: 4. VERAGAWATI, S.H. | E49: 0 | F49: 0 | G49: 0 | H49: 1 | I49: 0 | J49: 0 | K49: 1 | L49: 1 | M49: 0 | N49: 0 | O49: 0 | P49: 0 | Q49: 0 | R49: 0 | S49: =SUM(E49:R49) -> 3
C50: 5. KURDI EHSAN | E50: 0 | F50: 1 | G50: 0 | H50: 0 | I50: 1 | J50: 0 | K50: 0 | L50: 0 | M50: 0 | N50: 0 | O50: 2 | P50: 0 | Q50: 0 | R50: 0 | S50: =SUM(E50:R50) -> 4
C51: 6. BONDAN ARDYWIJAYA | E51: 0 | F51: 1 | G51: 1 | H51: 2 | I51: 10 | J51: 4 | K51: 2 | L51: 3 | M51: 1 | N51: 5 | O51: 0 | P51: 0 | Q51: 14 | R51: 14 | S51: =SUM(E51:R51) -> 57
...

Sheet KENJO
C2: Kecamatan | D2: GLAGAH
C3: Kabupaten | D3: BANYUWANGI
C4: Provinsi | D4: JAWA TIMUR
C9: Kelurahan | D9: KENJO
A12: I | B12: DATA PEMILIH DAN PENGGUNAAN HAK PILIH | K12: JUMLAH AKHIR
A13: A | B13: DATA PEMILIH | E13: TPS 001 | F13: TPS 002 | G13: TPS 003 | H13: TPS 004 | I13: TPS 005 | J13: TPS 006
