Workbook

Sheet DPRD KABUPATEN
C8: Kecamatan | D8: SILIRAGUNG
C9: Kabupaten | D9: BANYUWANGI
C10: Provinsi | D10: JAWA TIMUR
A12: I | B12: DATA PEMILIH DAN PENGGUNAAN HAK PILIH | E12: JUMLAH AKHIR
A13: A | B13: DATA PEMILIH
B14: Jumlah Pemilih dalam Daftar Pemilih Tetap (DPT) | D14: LK | E14: =BARUREJO!AX14+BULUAGUNG!AC14+KESILIR!AJ14+SENEPOREJO!AB14+SILIRAGUNG!AB14 -> 19220
D15: PR | E15: =BARUREJO!AX15+BULUAGUNG!AC15+KESILIR!AJ15+SENEPOREJO!AB15+SILIRAGUNG!AB15 -> 18803
D16: JML | E16: =SUM(E14:E15) -> 38023
A18: B | B18: PENGGUNA HAK PILIH
B19: 1. | C19: Jumlah pengguna hak pilih dalam Daftar Pemilih Tetap (DPT) | D19: LK | E19: =BARUREJO!AX19+BULUAGUNG!AC19+KESILIR!AJ19+SENEPOREJO!AB19+SILIRAGUNG!AB19 -> 14553
D20: PR | E20: =BARUREJO!AX20+BULUAGUNG!AC20+KESILIR!AJ20+SENEPOREJO!AB20+SILIRAGUNG!AB20 -> 14882
D21: JML | E21: =SUM(E19:E20) -> 29435
B22: 2. | C22: Jumlah pengguna hak pilih dalam Daftar Pemilih Tambahan (DPTb) | D22: LK | E22: =BARUREJO!AX22+BULUAGUNG!AC22+KESILIR!AJ22+SENEPOREJO!AB22+SILIRAGUNG!AB22 -> 10
D23: PR | E23: =BARUREJO!AX23+BULUAGUNG!AC23+KESILIR!AJ23+SENEPOREJO!AB23+SILIRAGUNG!AB23 -> 3
D24: JML | E24: =SUM(E22:E23) -> 13
B25: 3. | C25: Jumlah pengguna hak pilih dalam Daftar Pemilih Khusus (DPK) | D25: LK | E25: =BARUREJO!AX25+BULUAGUNG!AC25+KESILIR!AJ25+SENEPOREJO!AB25+SILIRAGUNG!AB25 -> 272
D26: PR | E26: =BARUREJO!AX26+BULUAGUNG!AC26+KESILIR!AJ26+SENEPOREJO!AB26+SILIRAGUNG!AB26 -> 391
D27: JML | E27: =SUM(E25:E26) -> 663
B28: 4. | C28: Jumlah Pengguna Hak Pilih (B.1+B.2+B.3) | D28: LK | E28: =E19+E22+E25 -> 14835
D29: PR | E29: =E20+E23+E26 -> 15276
D30: JML | E30: =SUM(E28:E29) -> 30111
A32: II | B32: DATA PENGGUNAAN SURAT SUARA
A33: 1 | B33: Jumlah surat suara yang diterima, termasuk surat suara cadangan 2,5% dari DPT | E33: =BARUREJO!AX33+BULUAGUNG!AC33+KESILIR!AJ33+SENEPOREJO!AB33+SILIRAGUNG!AB33 -> 38867
A34: 2 | B34: Jumlah surat suara yang digunakan | E34: =BARUREJO!AX34+BULUAGUNG!AC34+KESILIR!AJ34+SENEPOREJO!AB34+SILIRAGUNG!AB34 -> 30111
A35: 3 | B35: Jumlah surat suara dikembalikan oleh pemilih (karena rusak atau keliru coblos) | E35: =BARUREJO!AX35+BULUAGUNG!AC35+KESILIR!AJ35+SENEPOREJO!AB35+SILIRAGUNG!AB35 -> 75
A36: 4 | B36: Jumlah surat suara yang tidak digunakan/tidak terpakai, termasuk sisa surat suara cadangan | E36: =E33-(E34+E35) -> 8681
A38: III | B38: DATA PEMILIH DISABILITAS
B39: Jumlah seluruh Pemilih disabilitas yang menggunakan hak pilih | D39: LK | E39: =BARUREJO!AX39+BULUAGUNG!AC39+KESILIR!AJ39+SENEPOREJO!AB39+SILIRAGUNG!AB39 -> 11
D40: PR | E40: =BARUREJO!AX40+BULUAGUNG!AC40+KESILIR!AJ40+SENEPOREJO!AB40+SILIRAGUNG!AB40 -> 21
D41: JML | E41: =SUM(E39:E40) -> 32
A43: IV | B43: DATA RINCIAN PEROLEHAN SUARA PASANGAN CALON BUPATI DAN WAKIL BUPATI
A44: NOMOR DAN NAMA CALON
A45: A.1 | B45: 1. | C45: Partai Kebangkitan Bangsa | E45: =BARUREJO!AX45+BULUAGUNG!AC45+KESILIR!AJ45+SENEPOREJO!AB45+SILIRAGUNG!AB45 -> 432
A46: A.2 | C46: 1. MUKHTAR NABALI MUFAUWIQ | E46: =BARUREJO!AX46+BULUAGUNG!AC46+KESILIR!AJ46+SENEPOREJO!AB46+SILIRAGUNG!AB46 -> 1013
C47: 2. H. SUSIYANTO | E47: =BARUREJO!AX47+BULUAGUNG!AC47+KESILIR!AJ47+SENEPOREJO!AB47+SILIRAGUNG!AB47 -> 137
C48: 3. DUWI HASTRENI, S.H. | E48: =BARUREJO!AX48+BULUAGUNG!AC48+KESILIR!AJ48+SENEPOREJO!AB48+SILIRAGUNG!AB48 -> 57
C49: 4. MIFTAKHODIN | E49: =BARUREJO!AX49+BULUAGUNG!AC49+KESILIR!AJ49+SENEPOREJO!AB49+SILIRAGUNG!AB49 -> 37
C50: 5. SITI MUSTIKAH | E50: =BARUREJO!AX50+BULUAGUNG!AC50+KESILIR!AJ50+SENEPOREJO!AB50+SILIRAGUNG!AB50 -> 147
C51: 6. ABDUL GHOFUR | E51: =BARUREJO!AX51+BULUAGUNG!AC51+KESILIR!AJ51+SENEPOREJO!AB51+SILIRAGUNG!AB51 -> 22
C52: 7. ABDUL ROHMAN, S.Pd. | E52: =BARUREJO!AX52+BULUAGUNG!AC52+KESILIR!AJ52+SENEPOREJO!AB52+SILIRAGUNG!AB52 -> 277
...

Sheet BARUREJO
C2: Kecamatan | D2: SILIRAGUNG
C3: Kabupaten | D3: BANYUWANGI
C4: Provinsi | D4: JAWA TIMUR
C9: Kelurahan | D9: BARUREJO
A12: I | B12: DATA PEMILIH DAN PENGGUNAAN HAK PILIH | AX12: JUMLAH AKHIR
A13: A | B13: DATA PEMILIH | E13: TPS 001 | F13: TPS 002 | G13: TPS 003 | H13: TPS 004 | I13: TPS 005 | J13: TPS 006 | K13: TPS 007 | L13: TPS 008 | M13: TPS 009 | N13: TPS 010 | O13: TPS 011 | P13: TPS 012 | Q13: TPS 013 | R13: TPS 014 | S13: TPS 015 | T13: TPS 016 | U13: TPS 017 | V13: TPS 018 | W13: TPS 019 | X13: TPS 020 | Y13: TPS 021 | Z13: TPS 022 | AA13: TPS 023 | AB13: TPS 024 | AC13: TPS 025 | AD13: TPS 026 | AE13: TPS 027 | AF13: TPS 028 | AG13: TPS 029 | AH13: TPS 030 | AI13: TPS 031 | AJ13: TPS 032 | AK13: TPS 033 | AL13: TPS 034 | AM13: TPS 035 | AN13: TPS 036 | AO13: TPS 037 | AP13: TPS 038 | AQ13: TPS 039 | AR13: TPS 040 | AS13: TPS 041 | AT13: TPS 042 | AU13: TPS 043 | AV13: TPS 044 | AW13: TPS 045
B14: Jumlah Pemilih dalam Daftar Pemilih Tetap (DPT) | D14: LK | E14: 139 | F14: 140 | G14: 131 | H14: 134 | I14: 139 | J14: 143 | K14: 137 | L14: 144 | M14: 148 | N14: 142 | O14: 153 | P14: 138 | Q14: 148 | R14: 151 | S14: 122 | T14: 96 | U14: 104 | V14: 146 | W14: 135 | X14: 127 | Y14: 143 | Z14: 139 | AA14: 129 | AB14: 135 | AC14: 119 | AD14: 140 | AE14: 123 | AF14: 132 | AG14: 122 | AH14: 146 | AI14: 142 | AJ14: 153 | AK14: 119 | AL14: 102 | AM14: 84 | AN14: 152 | AO14: 142 | AP14: 154 | AQ14: 105 | AR14: 117 | AS14: 144 | AT14: 143 | AU14: 128 | AV14: 86 | AW14: 36 | AX14: =SUM(E14:AW14) -> 5852
D15: PR | E15: 128 | F15: 121 | G15: 118 | H15: 129 | I15: 140 | J15: 137 | K15: 126 | L15: 148 | M15: 135 | N15: 142 | O15: 139 | P15: 128 | Q15: 140 | R15: 129 | S15: 121 | T15: 94 | U15: 119 | V15: 130 | W15: 127 | X15: 119 | Y15: 128 | Z15: 123 | AA15: 133 | AB15: 147 | AC15: 107 | AD15: 140 | AE15: 124 | AF15: 127 | AG15: 110 | AH15: 147 | AI15: 148 | AJ15: 142 | AK15: 136 | AL15: 87 | AM15: 61 | AN15: 138 | AO15: 130 | AP15: 144 | AQ15: 94 | AR15: 127 | AS15: 153 | AT15: 143 | AU15: 141 | AV15: 71 | AW15: 39 | AX15: =SUM(E15:AW15) -> 5610
D16: JML | E16: =SUM(E14:E15) -> 267 | F16: =SUM(F14:F15) -> 261 | G16: =SUM(G14:G15) -> 249 | H16: =SUM(H14:H15) -> 263 | I16: =SUM(I14:I15) -> 279 | J16: =SUM(J14:J15) -> 280 | K16: =SUM(K14:K15) -> 263 | L16: =SUM(L14:L15) -> 292 | ... AW16: =SUM(AW14:AW15) -> 75 | AX16: =SUM(E16:AW16) -> 11462
A18: B | B18: PENGGUNA HAK PILIH
B19: 1. | C19: Jumlah pengguna hak pilih dalam Daftar Pemilih Tetap (DPT) | D19: LK | E19: 100 | F19: 112 | G19: 114 | H19: 100 | I19: 100 | J19: 99 | K19: 117 | L19: 101 | M19: 93 | N19: 93 | O19: 114 | P19: 109 | Q19: 109 | R19: 114 | S19: 92 | T19: 69 | U19: 80 | V19: 104 | W19: 109 | X19: 89 | Y19: 102 | Z19: 117 | AA19: 99 | AB19: 105 | AC19: 71 | AD19: 96 | AE19: 82 | AF19: 92 | AG19: 92 | AH19: 106 | AI19: 95 | AJ19: 98 | AK19: 95 | AL19: 79 | AM19: 48 | AN19: 102 | AO19: 103 | AP19: 100 | AQ19: 77 | AR19: 81 | AS19: 96 | AT19: 90 | AU19: 100 | AV19: 74 | AW19: 23 | AX19: =SUM(E19:AW19) -> 4241
D20: PR | E20: 93 | F20: 102 | G20: 87 | H20: 101 | I20: 100 | J20: 110 | K20: 98 | L20: 118 | M20: 113 | N20: 108 | O20: 114 | P20: 103 | Q20: 109 | R20: 98 | S20: 96 | T20: 69 | U20: 95 | V20: 106 | W20: 99 | X20: 95 | Y20: 100 | Z20: 105 | AA20: 100 | AB20: 119 | AC20: 81 | AD20: 112 | AE20: 97 | AF20: 95 | AG20: 89 | AH20: 115 | AI20: 113 | AJ20: 102 | AK20: 111 | AL20: 63 | AM20: 42 | AN20: 100 | AO20: 98 | AP20: 108 | AQ20: 72 | AR20: 97 | AS20: 103 | AT20: 100 | AU20: 109 | AV20: 58 | AW20: 28 | AX20: =SUM(E20:AW20) -> 4331
D21: JML | E21: =SUM(E19:E20) -> 193 | F21: =SUM(F19:F20) -> 214 | G21: =SUM(G19:G20) -> 201 | H21: =SUM(H19:H20) -> 201 | I21: =SUM(I19:I20) -> 200 | J21: =SUM(J19:J20) -> 209 | K21: =SUM(K19:K20) -> 215 | L21: =SUM(L19:L20) -> 219 | ... AW21: =SUM(AW19:AW20) -> 51 | AX21: =SUM(E21:AW21) -> 8572
B22: 2. | C22: Jumlah pengguna hak pilih dalam Daftar Pemilih Tambahan (DPTb) | D22: LK | E22: 0 | F22: 0 | G22: 0 | H22: 0 | I22: 0 | J22: 0 | K22: 1 | L22: 0 | M22: 1 | N22: 0 | O22: 0 | P22: 0 | Q22: 0 | R22: 0 | S22: 1 | T22: 0 | U22: 0 | V22: 0 | W22: 0 | X22: 0 | Y22: 0 | Z22: 0 | AA22: 0 | AB22: 0 | AC22: 0 | AD22: 0 | AE22: 0 | AF22: 0 | AG22: 0 | AH22: 0 | AX22: =SUM(E22:AW22) -> 3
D23: PR | E23: 0 | F23: 0 | G23: 0 | H23: 0 | I23: 0 | J23: 0 | K23: 0 | L23: 0 | M23: 0 | N23: 0 | O23: 0 | P23: 0 | Q23: 0 | R23: 0 | T23: 0 | U23: 0 | V23: 0 | W23: 0 | X23: 0 | Y23: 0 | Z23: 0 | AA23: 0 | AB23: 0 | AC23: 0 | AD23: 0 | AE23: 0 | AF23: 0 | AG23: 0 | AH23: 0 | AX23: =SUM(E23:AW23) -> 0
D24: JML | E24: =SUM(E22:E23) -> 0 | F24: =SUM(F22:F23) -> 0 | G24: =SUM(G22:G23) -> 0 | H24: =SUM(H22:H23) -> 0 | I24: =SUM(I22:I23) -> 0 | J24: =SUM(J22:J23) -> 0 | K24: =SUM(K22:K23) -> 1 | L24: =SUM(L22:L23) -> 0 | ... AW24: =SUM(AW22:AW23) -> 0 | AX24: =SUM(E24:AW24) -> 3
B25: 3. | C25: Jumlah pengguna hak pilih dalam Daftar Pemilih Khusus (DPK) | D25: LK | E25: 4 | F25: 0 | G25: 4 | H25: 3 | I25: 1 | J25: 3 | K25: 4 | L25: 2 | M25: 3 | N25: 1 | O25: 5 | P25: 0 | Q25: 3 | R25: 4 | S25: 6 | T25: 5 | U25: 8 | V25: 3 | W25: 1 | X25: 2 | Y25: 1 | Z25: 2 | AA25: 2 | AB25: 0 | AC25: 3 | AD25: 3 | AE25: 5 | AF25: 6 | AG25: 0 | AH25: 1 | AI25: 0 | AJ25: 2 | AK25: 3 | AL25: 4 | AM25: 1 | AN25: 2 | AO25: 0 | AP25: 0 | AQ25: 1 | AR25: 1 | AS25: 1 | AT25: 4 | AU25: 3 | AV25: 0 | AW25: 0 | AX25: =SUM(E25:AW25) -> 107
D26: PR | E26: 5 | F26: 1 | G26: 7 | H26: 10 | I26: 4 | J26: 3 | K26: 2 | L26: 2 | M26: 3 | N26: 3 | O26: 5 | P26: 0 | Q26: 5 | R26: 7 | S26: 3 | T26: 6 | U26: 9 | V26: 3 | W26: 2 | X26: 2 | Y26: 1 | Z26: 3 | AA26: 2 | AB26: 4 | AC26: 5 | AD26: 1 | AE26: 4 | AF26: 5 | AG26: 2 | AH26: 6 | AI26: 0 | AJ26: 7 | AK26: 3 | AL26: 3 | AM26: 3 | AN26: 1 | AO26: 2 | AP26: 0 | AQ26: 2 | AR26: 0 | AS26: 5 | AT26: 9 | AU26: 6 | AV26: 0 | AW26: 0 | AX26: =SUM(E26:AW26) -> 156
D27: JML | E27: =SUM(E25:E26) -> 9 | F27: =SUM(F25:F26) -> 1 | G27: =SUM(G25:G26) -> 11 | H27: =SUM(H25:H26) -> 13 | I27: =SUM(I25:I26) -> 5 | J27: =SUM(J25:J26) -> 6 | K27: =SUM(K25:K26) -> 6 | L27: =SUM(L25:L26) -> 4 | ... AW27: =SUM(AW25:AW26) -> 0 | AX27: =SUM(E27:AW27) -> 263
B28: 4. | C28: Jumlah Pengguna Hak Pilih (B.1+B.2+B.3) | D28: LK | E28: =SUM(E19,E22,E25) -> 104 | F28: =SUM(F19,F22,F25) -> 112 | G28: =SUM(G19,G22,G25) -> 118 | H28: =SUM(H19,H22,H25) -> 103 | I28: =SUM(I19,I22,I25) -> 101 | J28: =SUM(J19,J22,J25) -> 102 | K28: =SUM(K19,K22,K25) -> 122 | L28: =SUM(L19,L22,L25) -> 103 | ... AW28: =SUM(AW19,AW22,AW25) -> 23 | AX28: =SUM(E28:AW28) -> 4351
D29: PR | E29: =SUM(E20,E23,E26) -> 98 | F29: =SUM(F20,F23,F26) -> 103 | G29: =SUM(G20,G23,G26) -> 94 | H29: =SUM(H20,H23,H26) -> 111 | I29: =SUM(I20,I23,I26) -> 104 | J29: =SUM(J20,J23,J26) -> 113 | K29: =SUM(K20,K23,K26) -> 100 | L29: =SUM(L20,L23,L26) -> 120 | ... AW29: =SUM(AW20,AW23,AW26) -> 28 | AX29: =SUM(E29:AW29) -> 4487
D30: JML | E30: =SUM(E28:E29) -> 202 | F30: =SUM(F28:F29) -> 215 | G30: =SUM(G28:G29) -> 212 | H30: =SUM(H28:H29) -> 214 | I30: =SUM(I28:I29) -> 205 | J30: =SUM(J28:J29) -> 215 | K30: =SUM(K28:K29) -> 222 | L30: =SUM(L28:L29) -> 223 | ... AW30: =SUM(AW28:AW29) -> 51 | AX30: =SUM(E30:AW30) -> 8838
A32: II | B32: DATA PENGGUNAAN SURAT SUARA
A33: 1 | B33: Jumlah surat suara yang diterima, termasuk surat suara cadangan 2,5% dari DPT | E33: 273 | F33: 267 | G33: 254 | H33: 269 | I33: 285 | J33: 286 | K33: 269 | L33: 308 | M33: 282 | N33: 290 | O33: 298 | P33: 274 | Q33: 294 | R33: 284 | S33: 248 | T33: 194 | U33: 228 | V33: 289 | W33: 266 | X33: 251 | Y33: 277 | Z33: 268 | AA33: 268 | AB33: 288 | AC33: 231 | AD33: 286 | AE33: 252 | AF33: 267 | AG33: 237 | AH33: 299 | AI33: 296 | AJ33: 301 | AK33: 262 | AL33: 193 | AM33: 148 | AN33: 297 | AO33: 278 | AP33: 304 | AQ33: 203 | AR33: 249 | AS33: 303 | AT33: 292 | AU33: 275 | AV33: 161 | AW33: 77 | AX33: =SUM(E33:AW33) -> 11721
A34: 2 | B34: Jumlah surat suara yang digunakan | E34: 202 | F34: 215 | G34: 212 | H34: 214 | I34: 205 | J34: 215 | K34: 222 | L34: 223 | M34: 213 | N34: 205 | O34: 238 | P34: 212 | Q34: 226 | R34: 223 | S34: 198 | T34: 149 | U34: 192 | V34: 216 | W34: 211 | X34: 188 | Y34: 204 | Z34: 227 | AA34: 203 | AB34: 228 | AC34: 160 | AD34: 212 | AE34: 188 | AF34: 198 | AG34: 183 | AH34: 228 | AI34: 208 | AJ34: 209 | AK34: 212 | AL34: 149 | AM34: 94 | AN34: 205 | AO34: 203 | AP34: 208 | AQ34: 152 | AR34: 179 | AS34: 205 | AT34: 203 | AU34: 218 | AV34: 132 | AW34: 51 | AX34: =SUM(E34:AW34) -> 8838
A35: 3 | B35: Jumlah surat suara dikembalikan oleh pemilih (karena rusak atau keliru coblos) | E35: 0 | F35: 0 | G35: 0 | H35: 0 | I35: 0 | J35: 1 | K35: 1 | L35: 1 | M35: 0 | N35: 0 | O35: 0 | P35: 9 | Q35: 0 | R35: 0 | S35: 0 | T35: 1 | U35: 0 | V35: 1 | W35: 7 | X35: 0 | Y35: 0 | Z35: 0 | AA35: 0 | AB35: 0 | AC35: 0 | AD35: 0 | AE35: 0 | AF35: 0 | AG35: 0 | AH35: 0 | AI35: 0 | AJ35: 0 | AK35: 2 | AL35: 1 | AM35: 0 | AN35: 1 | AO35: 0 | AP35: 0 | AQ35: 0 | AR35: 0 | AS35: 1 | AT35: 0 | AU35: 2 | AV35: 0 | AW35: 0 | AX35: =SUM(E35:AW35) -> 28
A36: 4 | B36: Jumlah surat suara yang tidak digunakan/tidak terpakai, termasuk sisa surat suara cadangan | E36: =E33-(E34+E35) -> 71 | F36: =F33-(F34+F35) -> 52 | G36: =G33-(G34+G35) -> 42 | H36: =H33-(H34+H35) -> 55 | I36: =I33-(I34+I35) -> 80 | J36: =J33-(J34+J35) -> 70 | K36: =K33-(K34+K35) -> 46 | L36: =L33-(L34+L35) -> 84 | ... AW36: =AW33-(AW34+AW35) -> 26 | AX36: =SUM(E36:AW36) -> 2855
A38: III | B38: DATA PEMILIH DISABILITAS
B39: Jumlah seluruh Pemilih disabilitas yang menggunakan hak pilih | D39: LK | E39: 0 | F39: 0 | G39: 0 | H39: 0 | I39: 0 | J39: 0 | K39: 0 | L39: 0 | M39: 0 | N39: 0 | O39: 0 | P39: 0 | Q39: 0 | R39: 0 | S39: 0 | T39: 0 | U39: 0 | V39: 0 | W39: 1 | X39: 0 | Y39: 0 | Z39: 0 | AA39: 0 | AB39: 0 | AC39: 0 | AD39: 0 | AE39: 0 | AF39: 0 | AG39: 0 | AH39: 0 | AX39: =SUM(E39:AW39) -> 1
D40: PR | E40: 0 | F40: 0 | G40: 0 | H40: 0 | I40: 0 | J40: 0 | K40: 0 | L40: 0 | M40: 0 | N40: 1 | O40: 0 | P40: 0 | Q40: 0 | R40: 0 | S40: 2 | T40: 1 | U40: 0 | V40: 0 | W40: 0 | X40: 0 | Y40: 0 | Z40: 0 | AA40: 0 | AB40: 0 | AC40: 0 | AD40: 0 | AE40: 0 | AF40: 0 | AG40: 0 | AH40: 0 | AI40: 0 | AJ40: 0 | AK40: 0 | AL40: 0 | AM40: 0 | AN40: 0 | AO40: 0 | AP40: 0 | AQ40: 0 | AR40: 1 | AS40: 1 | AT40: 0 | AU40: 0 | AV40: 0 | AW40: 0 | AX40: =SUM(E40:AW40) -> 6
D41: JML | E41: =SUM(E39:E40) -> 0 | F41: =SUM(F39:F40) -> 0 | G41: =SUM(G39:G40) -> 0 | H41: =SUM(H39:H40) -> 0 | I41: =SUM(I39:I40) -> 0 | J41: =SUM(J39:J40) -> 0 | K41: =SUM(K39:K40) -> 0 | L41: =SUM(L39:L40) -> 0 | ... AW41: =SUM(AW39:AW40) -> 0 | AX41: =SUM(E41:AW41) -> 7
A43: IV | B43: DATA RINCIAN PEROLEHAN SUARA PASANGAN CALON BUPATI DAN WAKIL BUPATI
A44: NOMOR DAN NAMA CALON
A45: A.1 | B45: 1. | C45: Partai Kebangkitan Bangsa | AX45: =SUM(E45:AW45) -> 0
A46: A.2 | C46: 1. MUKHTAR NABALI MUFAUWIQ | AX46: =SUM(E46:AW46) -> 0
C47: 2. H. SUSIYANTO | AX47: =SUM(E47:AW47) -> 0
C48: 3. DUWI HASTRENI, S.H. | AX48: =SUM(E48:AW48) -> 0
C49: 4. MIFTAKHODIN | AX49: =SUM(E49:AW49) -> 0
C50: 5. SITI MUSTIKAH | AX50: =SUM(E50:AW50) -> 0
C51: 6. ABDUL GHOFUR | AX51: =SUM(E51:AW51) -> 0
...

Sheet BULUAGUNG
C2: Kecamatan | D2: SILIRAGUNG
C3: Kabupaten | D3: BANYUWANGI
C4: Provinsi | D4: JAWA TIMUR
C9: Kelurahan | D9: BULUAGUNG
A12: I | B12: DATA PEMILIH DAN PENGGUNAAN HAK PILIH | AC12: JUMLAH AKHIR
A13: A | B13: DATA PEMILIH | E13: TPS 001 | F13: TPS 002 | G13: TPS 003 | H13: TPS 004 | I13: TPS 005 | J13: TPS 006 | K13: TPS 007 | L13: TPS 008 | M13: TPS 009 | N13: TPS 010 | O13: TPS 011 | P13: TPS 012 | Q13: TPS 013 | R13: TPS 014 | S13: TPS 015 | T13: TPS 016 | U13: TPS 017 | V13: TPS 018 | W13: TPS 019 | X13: TPS 020 | Y13: TPS 021 | Z13: TPS 022 | AA13: TPS 023 | AB13: TPS 024
B14: Jumlah Pemilih dalam Daftar Pemilih Tetap (DPT) | D14: LK | E14: 136 | F14: 147 | G14: 138 | H14: 129 | I14: 138 | J14: 136 | K14: 136 | L14: 134 | M14: 130 | N14: 135 | O14: 134 | P14: 131 | Q14: 147 | R14: 140 | S14: 144 | T14: 140 | U14: 150 | V14: 143 | W14: 162 | X14: 149 | Y14: 145 | Z14: 141 | AA14: 143 | AB14: 118 | AC14: =SUM(E14:AB14) -> 3346
D15: PR | E15: 146 | F15: 143 | G15: 130 | H15: 130 | I15: 136 | J15: 126 | K15: 125 | L15: 135 | M15: 130 | N15: 137 | O15: 137 | P15: 132 | Q15: 146 | R15: 150 | S15: 143 | T15: 148 | U15: 142 | V15: 150 | W15: 134 | X15: 127 | Y15: 143 | Z15: 134 | AA15: 131 | AB15: 104 | AC15: =SUM(E15:AB15) -> 3259
D16: JML | E16: =SUM(E14:E15) -> 282 | F16: =SUM(F14:F15) -> 290 | G16: =SUM(G14:G15) -> 268 | H16: =SUM(H14:H15) -> 259 | I16: =SUM(I14:I15) -> 274 | J16: =SUM(J14:J15) -> 262 | K16: =SUM(K14:K15) -> 261 | L16: =SUM(L14:L15) -> 269 | ... AB16: =SUM(AB14:AB15) -> 222 | AC16: =SUM(E16:AB16) -> 6605
A18: B | B18: PENGGUNA HAK PILIH
B19: 1. | C19: Jumlah pengguna hak pilih dalam Daftar Pemilih Tetap (DPT) | D19: LK | E19: 106 | F19: 114 | G19: 103 | H19: 86 | I19: 102 | J19: 107 | K19: 96 | L19: 96 | M19: 95 | N19: 95 | O19: 104 | P19: 116 | Q19: 106 | R19: 105 | S19: 117 | T19: 105 | U19: 108 | V19: 107 | W19: 120 | X19: 112 | Y19: 106 | Z19: 105 | AA19: 117 | AB19: 76 | AC19: =SUM(E19:AB19) -> 2504
D20: PR | E20: 103 | F20: 108 | G20: 98 | H20: 115 | I20: 95 | J20: 95 | K20: 97 | L20: 110 | M20: 95 | N20: 108 | O20: 100 | P20: 112 | Q20: 118 | R20: 112 | S20: 114 | T20: 108 | U20: 117 | V20: 129 | W20: 106 | X20: 93 | Y20: 108 | Z20: 106 | AA20: 106 | AB20: 69 | AC20: =SUM(E20:AB20) -> 2522
D21: JML | E21: =SUM(E19:E20) -> 209 | F21: =SUM(F19:F20) -> 222 | G21: =SUM(G19:G20) -> 201 | H21: =SUM(H19:H20) -> 201 | I21: =SUM(I19:I20) -> 197 | J21: =SUM(J19:J20) -> 202 | K21: =SUM(K19:K20) -> 193 | L21: =SUM(L19:L20) -> 206 | ... AB21: =SUM(AB19:AB20) -> 145 | AC21: =SUM(E21:AB21) -> 5026
B22: 2. | C22: Jumlah pengguna hak pilih dalam Daftar Pemilih Tambahan (DPTb) | D22: LK | E22: 1 | F22: 0 | G22: 0 | H22: 1 | I22: 0 | J22: 0 | K22: 0 | L22: 0 | M22: 0 | N22: 1 | O22: 0 | P22: 0 | Q22: 0 | R22: 0 | S22: 0 | AC22: =SUM(E22:AB22) -> 3
D23: PR | E23: 0 | F23: 0 | G23: 0 | H23: 1 | I23: 0 | J23: 0 | K23: 0 | L23: 0 | M23: 0 | N23: 0 | O23: 0 | P23: 0 | Q23: 0 | R23: 0 | S23: 0 | AC23: =SUM(E23:AB23) -> 1
D24: JML | E24: =SUM(E22:E23) -> 1 | F24: =SUM(F22:F23) -> 0 | G24: =SUM(G22:G23) -> 0 | H24: =SUM(H22:H23) -> 2 | I24: =SUM(I22:I23) -> 0 | J24: =SUM(J22:J23) -> 0 | K24: =SUM(K22:K23) -> 0 | L24: =SUM(L22:L23) -> 0 | ... AB24: =SUM(AB22:AB23) -> 0 | AC24: =SUM(E24:AB24) -> 4
B25: 3. | C25: Jumlah pengguna hak pilih dalam Daftar Pemilih Khusus (DPK) | D25: LK | E25: 1 | F25: 0 | G25: 0 | H25: 1 | I25: 0 | J25: 1 | K25: 2 | L25: 3 | M25: 0 | N25: 0 | O25: 2 | P25: 1 | Q25: 4 | R25: 1 | S25: 0 | T25: 6 | U25: 2 | V25: 0 | W25: 1 | X25: 1 | Y25: 0 | Z25: 0 | AA25: 2 | AB25: 0 | AC25: =SUM(E25:AB25) -> 28
D26: PR | E26: 4 | F26: 1 | G26: 0 | H26: 0 | I26: 0 | J26: 4 | K26: 3 | L26: 1 | M26: 0 | N26: 2 | O26: 3 | P26: 1 | Q26: 4 | R26: 4 | S26: 0 | T26: 5 | U26: 3 | V26: 4 | W26: 0 | X26: 0 | Y26: 1 | Z26: 2 | AA26: 0 | AB26: 1 | AC26: =SUM(E26:AB26) -> 43
D27: JML | E27: =SUM(E25:E26) -> 5 | F27: =SUM(F25:F26) -> 1 | G27: =SUM(G25:G26) -> 0 | H27: =SUM(H25:H26) -> 1 | I27: =SUM(I25:I26) -> 0 | J27: =SUM(J25:J26) -> 5 | K27: =SUM(K25:K26) -> 5 | L27: =SUM(L25:L26) -> 4 | ... AB27: =SUM(AB25:AB26) -> 1 | AC27: =SUM(E27:AB27) -> 71
B28: 4. | C28: Jumlah Pengguna Hak Pilih (B.1+B.2+B.3) | D28: LK | E28: =SUM(E19,E22,E25) -> 108 | F28: =SUM(F19,F22,F25) -> 114 | G28: =SUM(G19,G22,G25) -> 103 | H28: =SUM(H19,H22,H25) -> 88 | I28: =SUM(I19,I22,I25) -> 102 | J28: =SUM(J19,J22,J25) -> 108 | K28: =SUM(K19,K22,K25) -> 98 | L28: =SUM(L19,L22,L25) -> 99 | ... AB28: =SUM(AB19,AB22,AB25) -> 76 | AC28: =SUM(E28:AB28) -> 2535
D29: PR | E29: =SUM(E20,E23,E26) -> 107 | F29: =SUM(F20,F23,F26) -> 109 | G29: =SUM(G20,G23,G26) -> 98 | H29: =SUM(H20,H23,H26) -> 116 | I29: =SUM(I20,I23,I26) -> 95 | J29: =SUM(J20,J23,J26) -> 99 | K29: =SUM(K20,K23,K26) -> 100 | L29: =SUM(L20,L23,L26) -> 111 | ... AB29: =SUM(AB20,AB23,AB26) -> 70 | AC29: =SUM(E29:AB29) -> 2566
D30: JML | E30: =SUM(E28:E29) -> 215 | F30: =SUM(F28:F29) -> 223 | G30: =SUM(G28:G29) -> 201 | H30: =SUM(H28:H29) -> 204 | I30: =SUM(I28:I29) -> 197 | J30: =SUM(J28:J29) -> 207 | K30: =SUM(K28:K29) -> 198 | L30: =SUM(L28:L29) -> 210 | ... AB30: =SUM(AB28:AB29) -> 146 | AC30: =SUM(E30:AB30) -> 5101
A32: II | B32: DATA PENGGUNAAN SURAT SUARA
A33: 1 | B33: Jumlah surat suara yang diterima, termasuk surat suara cadangan 2,5% dari DPT | E33: 289 | F33: 298 | G33: 274 | H33: 265 | I33: 280 | J33: 268 | K33: 263 | L33: 275 | M33: 266 | N33: 278 | O33: 277 | P33: 269 | Q33: 299 | R33: 296 | S33: 293 | T33: 294 | U33: 298 | V33: 299 | W33: 302 | X33: 282 | Y33: 294 | Z33: 281 | AA33: 280 | AB33: 227 | AC33: =SUM(E33:AB33) -> 6747
A34: 2 | B34: Jumlah surat suara yang digunakan | E34: 215 | F34: 223 | G34: 201 | H34: 204 | I34: 197 | J34: 207 | K34: 198 | L34: 210 | M34: 190 | N34: 206 | O34: 209 | P34: 230 | Q34: 232 | R34: 222 | S34: 231 | T34: 224 | U34: 230 | V34: 240 | W34: 227 | X34: 206 | Y34: 215 | Z34: 213 | AA34: 225 | AB34: 146 | AC34: =SUM(E34:AB34) -> 5101
A35: 3 | B35: Jumlah surat suara dikembalikan oleh pemilih (karena rusak atau keliru coblos) | E35: 0 | F35: 0 | G35: 0 | H35: 0 | I35: 0 | J35: 0 | K35: 0 | L35: 0 | M35: 0 | N35: 0 | O35: 1 | P35: 0 | Q35: 0 | R35: 1 | S35: 0 | T35: 7 | U35: 1 | V35: 0 | W35: 0 | X35: 0 | Y35: 0 | Z35: 0 | AA35: 0 | AB35: 0 | AC35: =SUM(E35:AB35) -> 10
A36: 4 | B36: Jumlah surat suara yang tidak digunakan/tidak terpakai, termasuk sisa surat suara cadangan | E36: =E33-(E34+E35) -> 74 | F36: =F33-(F34+F35) -> 75 | G36: =G33-(G34+G35) -> 73 | H36: =H33-(H34+H35) -> 61 | I36: =I33-(I34+I35) -> 83 | J36: =J33-(J34+J35) -> 61 | K36: =K33-(K34+K35) -> 65 | L36: =L33-(L34+L35) -> 65 | ... AB36: =AB33-(AB34+AB35) -> 81 | AC36: =SUM(E36:AB36) -> 1636
A38: III | B38: DATA PEMILIH DISABILITAS
B39: Jumlah seluruh Pemilih disabilitas yang menggunakan hak pilih | D39: LK | E39: 0 | F39: 0 | G39: 0 | H39: 1 | I39: 0 | J39: 0 | K39: 0 | L39: 0 | M39: 0 | N39: 0 | O39: 0 | P39: 0 | Q39: 0 | R39: 0 | S39: 0 | Y39: 1 | AC39: =SUM(E39:AB39) -> 2
D40: PR | E40: 1 | F40: 0 | G40: 2 | H40: 2 | I40: 0 | J40: 0 | K40: 0 | L40: 0 | M40: 0 | N40: 1 | O40: 0 | P40: 0 | Q40: 0 | R40: 0 | S40: 0 | Y40: 1 | AA40: 1 | AC40: =SUM(E40:AB40) -> 8
D41: JML | E41: =SUM(E39:E40) -> 1 | F41: =SUM(F39:F40) -> 0 | G41: =SUM(G39:G40) -> 2 | H41: =SUM(H39:H40) -> 3 | I41: =SUM(I39:I40) -> 0 | J41: =SUM(J39:J40) -> 0 | K41: =SUM(K39:K40) -> 0 | L41: =SUM(L39:L40) -> 0 | ... AB41: =SUM(AB39:AB40) -> 0 | AC41: =SUM(E41:AB41) -> 10
A43: IV | B43: DATA RINCIAN PEROLEHAN SUARA PASANGAN CALON BUPATI DAN WAKIL BUPATI
A44: NOMOR DAN NAMA CALON
A45: A.1 | B45: 1. | C45: Partai Kebangkitan Bangsa | E45: 8 | F45: 7 | G45: 9 | H45: 11 | I45: 12 | J45: 6 | K45: 4 | L45: 9 | M45: 9 | N45: 1 | O45: 7 | P45: 3 | Q45: 2 | R45: 1 | S45: 3 | T45: 8 | U45: 7 | V45: 13 | W45: 8 | X45: 0 | Y45: 6 | Z45: 0 | AA45: 1 | AB45: 2 | AC45: =SUM(E45:AB45) -> 137
A46: A.2 | C46: 1. MUKHTAR NABALI MUFAUWIQ | E46: 17 | F46: 21 | G46: 25 | H46: 27 | I46: 39 | J46: 22 | K46: 19 | L46: 23 | M46: 33 | N46: 16 | O46: 6 | P46: 8 | Q46: 6 | R46: 5 | S46: 4 | T46: 15 | U46: 35 | V46: 36 | W46: 14 | X46: 0 | Y46: 3 | Z46: 1 | AA46: 1 | AB46: 10 | AC46: =SUM(E46:AB46) -> 386
C47: 2. H. SUSIYANTO | E47: 0 | F47: 4 | G47: 0 | H47: 1 | I47: 1 | J47: 0 | K47: 1 | L47: 3 | M47: 2 | N47: 0 | O47: 0 | P47: 1 | Q47: 2 | R47: 1 | S47: 2 | T47: 2 | U47: 0 | V47: 3 | W47: 1 | X47: 1 | Y47: 1 | Z47: 0 | AA47: 3 | AB47: 0 | AC47: =SUM(E47:AB47) -> 29
C48: 3. DUWI HASTRENI, S.H. | E48: 1 | F48: 0 | G48: 1 | H48: 1 | I48: 1 | J48: 0 | K48: 0 | L48: 0 | M48: 0 | N48: 0 | O48: 1 | P48: 0 | Q48: 1 | R48: 0 | S48: 0 | T48: 0 | U48: 1 | V48: 8 | W48: 0 | X48: 0 | Y48: 0 | Z48: 0 | AA48: 0 | AB48: 1 | AC48: =SUM(E48:AB48) -> 16
C49: 4. MIFTAKHODIN | E49: 1 | F49: 0 | G49: 0 | H49: 0 | I49: 0 | J49: 0 | K49: 0 | L49: 1 | M49: 3 | N49: 0 | O49: 2 | P49: 0 | Q49: 0 | R49: 0 | S49: 0 | T49: 0 | U49: 0 | V49: 1 | W49: 1 | X49: 0 | Y49: 0 | Z49: 0 | AA49: 0 | AB49: 0 | AC49: =SUM(E49:AB49) -> 9
C50: 5. SITI MUSTIKAH | E50: 3 | F50: 1 | G50: 1 | H50: 2 | I50: 2 | J50: 0 | K50: 0 | L50: 2 | M50: 4 | N50: 0 | O50: 0 | P50: 1 | Q50: 0 | R50: 0 | S50: 0 | T50: 2 | U50: 0 | V50: 0 | W50: 0 | X50: 0 | Y50: 0 | Z50: 0 | AA50: 0 | AB50: 0 | AC50: =SUM(E50:AB50) -> 18
C51: 6. ABDUL GHOFUR | E51: 0 | F51: 0 | G51: 0 | H51: 0 | I51: 4 | J51: 0 | K51: 0 | L51: 1 | M51: 0 | N51: 0 | O51: 0 | P51: 0 | Q51: 0 | R51: 0 | S51: 0 | T51: 0 | U51: 0 | V51: 0 | W51: 0 | X51: 0 | Y51: 0 | Z51: 0 | AA51: 0 | AB51: 0 | AC51: =SUM(E51:AB51) -> 5
...

Sheet KESILIR
C2: Kecamatan | D2: SILIRAGUNG
C3: Kabupaten | D3: BANYUWANGI
C4: Provinsi | D4: JAWA TIMUR
C9: Kelurahan | D9: KESILIR
A12: I | B12: DATA PEMILIH DAN PENGGUNAAN HAK PILIH | AJ12: JUMLAH AKHIR
A13: A | B13: DATA PEMILIH | E13: TPS 001 | F13: TPS 002 | G13: TPS 003 | H13: TPS 004 | I13: TPS 005 | J13: TPS 006 | K13: TPS 007 | L13: TPS 008 | M13: TPS 009 | N13: TPS 010 | O13: TPS 011 | P13: TPS 012 | Q13: TPS 013 | R13: TPS 014 | S13: TPS 015 | T13: TPS 016 | U13: TPS 017 | V13: TPS 018 | W13: TPS 019 | X13: TPS 020 | Y13: TPS 021 | Z13: TPS 022 | AA13: TPS 023 | AB13: TPS 024 | AC13: TPS 025 | AD13: TPS 026 | AE13: TPS 027 | AF13: TPS 028 | AG13: TPS 029 | AH13: TPS 030 | AI13: TPS 031
B14: Jumlah Pemilih dalam Daftar Pemilih Tetap (DPT) | D14: LK | E14: 136 | F14: 134 | G14: 138 | H14: 149 | I14: 111 | J14: 124 | K14: 130 | L14: 121 | M14: 121 | N14: 142 | O14: 141 | P14: 134 | Q14: 120 | R14: 141 | S14: 131 | T14: 123 | U14: 125 | V14: 131 | W14: 132 | X14: 127 | Y14: 142 | Z14: 122 | AA14: 134 | AB14: 125 | AC14: 128 | AD14: 136 | AE14: 135 | AF14: 115 | AG14: 126 | AH14: 141 | AI14: 132 | AJ14: =SUM(E14:AI14) -> 4047
D15: PR | E15: 114 | F15: 111 | G15: 135 | H15: 138 | I15: 123 | J15: 131 | K15: 131 | L15: 118 | M15: 127 | N15: 126 | O15: 131 | P15: 149 | Q15: 111 | R15: 124 | S15: 130 | T15: 117 | U15: 130 | V15: 121 | W15: 122 | X15: 116 | Y15: 119 | Z15: 128 | AA15: 142 | AB15: 128 | AC15: 130 | AD15: 140 | AE15: 123 | AF15: 127 | AG15: 142 | AH15: 128 | AI15: 133 | AJ15: =SUM(E15:AI15) -> 3945
D16: JML | E16: =SUM(E14:E15) -> 250 | F16: =SUM(F14:F15) -> 245 | G16: =SUM(G14:G15) -> 273 | H16: =SUM(H14:H15) -> 287 | I16: =SUM(I14:I15) -> 234 | J16: =SUM(J14:J15) -> 255 | K16: =SUM(K14:K15) -> 261 | L16: =SUM(L14:L15) -> 239 | ... AI16: =SUM(AI14:AI15) -> 265 | AJ16: =SUM(E16:AI16) -> 7992
A18: B | B18: PENGGUNA HAK PILIH
B19: 1. | C19: Jumlah pengguna hak pilih dalam Daftar Pemilih Tetap (DPT) | D19: LK | E19: 108 | F19: 107 | G19: 111 | H19: 110 | I19: 91 | J19: 99 | K19: 109 | L19: 92 | M19: 102 | N19: 116 | O19: 107 | P19: 110 | Q19: 108 | R19: 108 | S19: 95 | T19: 93 | U19: 105 | V19: 96 | W19: 98 | X19: 98 | Y19: 108 | Z19: 98 | AA19: 111 | AB19: 94 | AC19: 110 | AD19: 101 | AE19: 115 | AF19: 102 | AG19: 108 | AH19: 115 | AI19: 110 | AJ19: =SUM(E19:AI19) -> 3235
D20: PR | E20: 94 | F20: 96 | G20: 111 | H20: 113 | I20: 100 | J20: 103 | K20: 112 | L20: 94 | M20: 93 | N20: 104 | O20: 105 | P20: 119 | Q20: 91 | R20: 103 | S20: 100 | T20: 95 | U20: 116 | V20: 101 | W20: 91 | X20: 92 | Y20: 108 | Z20: 111 | AA20: 114 | AB20: 90 | AC20: 109 | AD20: 105 | AE20: 101 | AF20: 111 | AG20: 116 | AH20: 102 | AI20: 112 | AJ20: =SUM(E20:AI20) -> 3212
D21: JML | E21: =SUM(E19:E20) -> 202 | F21: =SUM(F19:F20) -> 203 | G21: =SUM(G19:G20) -> 222 | H21: =SUM(H19:H20) -> 223 | I21: =SUM(I19:I20) -> 191 | J21: =SUM(J19:J20) -> 202 | K21: =SUM(K19:K20) -> 221 | L21: =SUM(L19:L20) -> 186 | ... AI21: =SUM(AI19:AI20) -> 222 | AJ21: =SUM(E21:AI21) -> 6447
B22: 2. | C22: Jumlah pengguna hak pilih dalam Daftar Pemilih Tambahan (DPTb) | D22: LK | E22: 0 | F22: 0 | G22: 0 | H22: 0 | I22: 0 | J22: 0 | K22: 0 | L22: 0 | M22: 0 | N22: 0 | O22: 0 | P22: 0 | Q22: 0 | R22: 0 | S22: 0 | T22: 0 | U22: 0 | V22: 0 | W22: 0 | X22: 0 | Y22: 0 | Z22: 1 | AA22: 0 | AB22: 0 | AC22: 0 | AD22: 0 | AE22: 0 | AF22: 0 | AG22: 0 | AH22: 0 | AJ22: =SUM(E22:AI22) -> 1
D23: PR | E23: 0 | F23: 0 | G23: 0 | H23: 0 | I23: 0 | J23: 0 | K23: 0 | L23: 0 | M23: 0 | N23: 0 | O23: 0 | P23: 0 | Q23: 0 | R23: 0 | S23: 0 | T23: 0 | U23: 0 | V23: 0 | W23: 0 | X23: 0 | Y23: 0 | Z23: 0 | AA23: 0 | AB23: 0 | AC23: 0 | AD23: 0 | AE23: 0 | AF23: 0 | AG23: 0 | AH23: 0 | AJ23: =SUM(E23:AI23) -> 0
D24: JML | E24: =SUM(E22:E23) -> 0 | F24: =SUM(F22:F23) -> 0 | G24: =SUM(G22:G23) -> 0 | H24: =SUM(H22:H23) -> 0 | I24: =SUM(I22:I23) -> 0 | J24: =SUM(J22:J23) -> 0 | K24: =SUM(K22:K23) -> 0 | L24: =SUM(L22:L23) -> 0 | ... AI24: =SUM(AI22:AI23) -> 0 | AJ24: =SUM(E24:AI24) -> 1
B25: 3. | C25: Jumlah pengguna hak pilih dalam Daftar Pemilih Khusus (DPK) | D25: LK | E25: 4 | F25: 3 | G25: 3 | H25: 1 | I25: 0 | J25: 6 | K25: 3 | L25: 3 | M25: 3 | N25: 0 | O25: 1 | P25: 0 | Q25: 0 | R25: 1 | S25: 6 | T25: 3 | U25: 1 | V25: 4 | W25: 6 | X25: 4 | Y25: 3 | Z25: 1 | AA25: 4 | AB25: 3 | AC25: 0 | AD25: 0 | AE25: 4 | AF25: 0 | AG25: 2 | AH25: 5 | AI25: 1 | AJ25: =SUM(E25:AI25) -> 75
D26: PR | E26: 5 | F26: 6 | G26: 4 | H26: 2 | I26: 0 | J26: 7 | K26: 5 | L26: 6 | M26: 5 | N26: 1 | O26: 1 | P26: 3 | Q26: 0 | R26: 1 | S26: 11 | T26: 6 | U26: 1 | V26: 3 | W26: 8 | X26: 2 | Y26: 4 | Z26: 1 | AA26: 3 | AB26: 2 | AC26: 0 | AD26: 1 | AE26: 3 | AF26: 0 | AG26: 1 | AH26: 5 | AI26: 4 | AJ26: =SUM(E26:AI26) -> 101
D27: JML | E27: =SUM(E25:E26) -> 9 | F27: =SUM(F25:F26) -> 9 | G27: =SUM(G25:G26) -> 7 | H27: =SUM(H25:H26) -> 3 | I27: =SUM(I25:I26) -> 0 | J27: =SUM(J25:J26) -> 13 | K27: =SUM(K25:K26) -> 8 | L27: =SUM(L25:L26) -> 9 | ... AI27: =SUM(AI25:AI26) -> 5 | AJ27: =SUM(E27:AI27) -> 176
B28: 4. | C28: Jumlah Pengguna Hak Pilih (B.1+B.2+B.3) | D28: LK | E28: =SUM(E19,E22,E25) -> 112 | F28: =SUM(F19,F22,F25) -> 110 | G28: =SUM(G19,G22,G25) -> 114 | H28: =SUM(H19,H22,H25) -> 111 | I28: =SUM(I19,I22,I25) -> 91 | J28: =SUM(J19,J22,J25) -> 105 | K28: =SUM(K19,K22,K25) -> 112 | L28: =SUM(L19,L22,L25) -> 95 | ... AI28: =SUM(AI19,AI22,AI25) -> 111 | AJ28: =SUM(E28:AI28) -> 3311
D29: PR | E29: =SUM(E20,E23,E26) -> 99 | F29: =SUM(F20,F23,F26) -> 102 | G29: =SUM(G20,G23,G26) -> 115 | H29: =SUM(H20,H23,H26) -> 115 | I29: =SUM(I20,I23,I26) -> 100 | J29: =SUM(J20,J23,J26) -> 110 | K29: =SUM(K20,K23,K26) -> 117 | L29: =SUM(L20,L23,L26) -> 100 | ... AI29: =SUM(AI20,AI23,AI26) -> 116 | AJ29: =SUM(E29:AI29) -> 3313
D30: JML | E30: =SUM(E28:E29) -> 211 | F30: =SUM(F28:F29) -> 212 | G30: =SUM(G28:G29) -> 229 | H30: =SUM(H28:H29) -> 226 | I30: =SUM(I28:I29) -> 191 | J30: =SUM(J28:J29) -> 215 | K30: =SUM(K28:K29) -> 229 | L30: =SUM(L28:L29) -> 195 | ... AI30: =SUM(AI28:AI29) -> 227 | AJ30: =SUM(E30:AI30) -> 6624
A32: II | B32: DATA PENGGUNAAN SURAT SUARA
A33: 1 | B33: Jumlah surat suara yang diterima, termasuk surat suara cadangan 2,5% dari DPT | E33: 255 | F33: 250 | G33: 279 | H33: 292 | I33: 239 | J33: 261 | K33: 267 | L33: 244 | M33: 253 | N33: 274 | O33: 278 | P33: 289 | Q33: 236 | R33: 273 | S33: 267 | T33: 245 | U33: 261 | V33: 258 | W33: 260 | X33: 248 | Y33: 267 | Z33: 255 | AA33: 282 | AB33: 259 | AC33: 264 | AD33: 282 | AE33: 274 | AF33: 246 | AG33: 273 | AH33: 275 | AI33: 271 | AJ33: =SUM(E33:AI33) -> 8177
A34: 2 | B34: Jumlah surat suara yang digunakan | E34: 211 | F34: 212 | G34: 229 | H34: 226 | I34: 191 | J34: 215 | K34: 229 | L34: 195 | M34: 203 | N34: 221 | O34: 214 | P34: 232 | Q34: 199 | R34: 213 | S34: 212 | T34: 197 | U34: 223 | V34: 204 | W34: 203 | X34: 196 | Y34: 223 | Z34: 212 | AA34: 232 | AB34: 189 | AC34: 219 | AD34: 207 | AE34: 223 | AF34: 213 | AG34: 227 | AH34: 227 | AI34: 227 | AJ34: =SUM(E34:AI34) -> 6624
A35: 3 | B35: Jumlah surat suara dikembalikan oleh pemilih (karena rusak atau keliru coblos) | E35: 3 | F35: 0 | G35: 0 | H35: 0 | I35: 0 | J35: 0 | K35: 0 | L35: 0 | M35: 0 | N35: 0 | O35: 0 | P35: 0 | Q35: 0 | R35: 0 | S35: 0 | T35: 0 | U35: 0 | V35: 0 | W35: 0 | X35: 0 | Y35: 0 | Z35: 0 | AA35: 0 | AB35: 0 | AC35: 0 | AD35: 0 | AE35: 0 | AF35: 0 | AG35: 1 | AH35: 0 | AI35: 2 | AJ35: =SUM(E35:AI35) -> 6
A36: 4 | B36: Jumlah surat suara yang tidak digunakan/tidak terpakai, termasuk sisa surat suara cadangan | E36: =E33-(E34+E35) -> 41 | F36: =F33-(F34+F35) -> 38 | G36: =G33-(G34+G35) -> 50 | H36: =H33-(H34+H35) -> 66 | I36: =I33-(I34+I35) -> 48 | J36: =J33-(J34+J35) -> 46 | K36: =K33-(K34+K35) -> 38 | L36: =L33-(L34+L35) -> 49 | ... AI36: =AI33-(AI34+AI35) -> 42 | AJ36: =SUM(E36:AI36) -> 1547
A38: III | B38: DATA PEMILIH DISABILITAS
B39: Jumlah seluruh Pemilih disabilitas yang menggunakan hak pilih | D39: LK | E39: 0 | F39: 0 | G39: 0 | H39: 0 | I39: 0 | J39: 0 | K39: 0 | L39: 1 | M39: 0 | N39: 2 | O39: 0 | P39: 0 | Q39: 0 | R39: 0 | S39: 0 | T39: 0 | U39: 0 | V39: 0 | W39: 0 | X39: 1 | Y39: 0 | Z39: 0 | AA39: 0 | AB39: 0 | AC39: 0 | AD39: 0 | AE39: 0 | AF39: 0 | AG39: 0 | AH39: 0 | AJ39: =SUM(E39:AI39) -> 4
D40: PR | E40: 0 | F40: 0 | G40: 0 | H40: 0 | I40: 0 | J40: 0 | K40: 0 | L40: 0 | M40: 0 | N40: 0 | O40: 0 | P40: 0 | Q40: 0 | R40: 0 | S40: 0 | T40: 0 | U40: 0 | V40: 0 | W40: 0 | X40: 0 | Y40: 0 | Z40: 0 | AA40: 0 | AB40: 0 | AC40: 0 | AD40: 0 | AE40: 0 | AF40: 0 | AG40: 0 | AH40: 0 | AJ40: =SUM(E40:AI40) -> 0
D41: JML | E41: =SUM(E39:E40) -> 0 | F41: =SUM(F39:F40) -> 0 | G41: =SUM(G39:G40) -> 0 | H41: =SUM(H39:H40) -> 0 | I41: =SUM(I39:I40) -> 0 | J41: =SUM(J39:J40) -> 0 | K41: =SUM(K39:K40) -> 0 | L41: =SUM(L39:L40) -> 1 | ... AI41: =SUM(AI39:AI40) -> 0 | AJ41: =SUM(E41:AI41) -> 4
A43: IV | B43: DATA RINCIAN PEROLEHAN SUARA PASANGAN CALON BUPATI DAN WAKIL BUPATI
A44: NOMOR DAN NAMA CALON
A45: A.1 | B45: 1. | C45: Partai Kebangkitan Bangsa | E45: 1 | F45: 4 | G45: 2 | H45: 4 | I45: 6 | J45: 3 | K45: 6 | L45: 4 | M45: 4 | N45: 3 | O45: 6 | P45: 5 | Q45: 2 | R45: 3 | S45: 4 | T45: 3 | U45: 7 | V45: 12 | W45: 4 | X45: 3 | Y45: 5 | Z45: 7 | AA45: 1 | AB45: 5 | AC45: 5 | AD45: 0 | AE45: 3 | AF45: 2 | AG45: 3 | AH45: 6 | AI45: 6 | AJ45: =SUM(E45:AI45) -> 129
A46: A.2 | C46: 1. MUKHTAR NABALI MUFAUWIQ | E46: 2 | F46: 1 | G46: 4 | H46: 3 | I46: 15 | J46: 8 | K46: 26 | L46: 10 | M46: 20 | N46: 18 | O46: 9 | P46: 10 | Q46: 1 | R46: 8 | S46: 10 | T46: 12 | U46: 18 | V46: 16 | W46: 11 | X46: 2 | Y46: 15 | Z46: 23 | AA46: 6 | AB46: 4 | AC46: 21 | AD46: 2 | AE46: 8 | AF46: 2 | AG46: 7 | AH46: 2 | AI46: 4 | AJ46: =SUM(E46:AI46) -> 298
C47: 2. H. SUSIYANTO | E47: 0 | F47: 1 | G47: 4 | H47: 2 | I47: 0 | J47: 0 | K47: 0 | L47: 0 | M47: 0 | N47: 0 | O47: 2 | P47: 1 | Q47: 0 | R47: 2 | T47: 1 | U47: 1 | V47: 0 | W47: 1 | X47: 0 | Y47: 0 | Z47: 1 | AA47: 2 | AB47: 0 | AC47: 1 | AD47: 0 | AE47: 1 | AF47: 1 | AG47: 0 | AH47: 0 | AI47: 0 | AJ47: =SUM(E47:AI47) -> 21
C48: 3. DUWI HASTRENI, S.H. | E48: 0 | F48: 1 | G48: 0 | H48: 0 | I48: 0 | J48: 0 | K48: 1 | L48: 0 | M48: 0 | N48: 0 | O48: 0 | P48: 0 | Q48: 0 | R48: 0 | T48: 0 | U48: 0 | V48: 0 | W48: 3 | X48: 1 | Y48: 0 | Z48: 0 | AA48: 2 | AB48: 1 | AC48: 0 | AD48: 1 | AE48: 0 | AF48: 2 | AG48: 1 | AH48: 0 | AI48: 0 | AJ48: =SUM(E48:AI48) -> 13
C49: 4. MIFTAKHODIN | E49: 0 | F49: 1 | G49: 0 | H49: 1 | I49: 1 | J49: 0 | K49: 2 | L49: 0 | M49: 0 | N49: 0 | O49: 0 | P49: 3 | Q49: 0 | R49: 0 | T49: 0 | U49: 0 | V49: 0 | W49: 0 | X49: 0 | Y49: 0 | Z49: 0 | AA49: 0 | AB49: 0 | AC49: 0 | AD49: 0 | AE49: 1 | AF49: 0 | AG49: 2 | AH49: 1 | AI49: 2 | AJ49: =SUM(E49:AI49) -> 14
C50: 5. SITI MUSTIKAH | E50: 0 | F50: 0 | G50: 0 | H50: 0 | I50: 0 | J50: 0 | K50: 1 | L50: 0 | M50: 0 | N50: 2 | O50: 0 | P50: 0 | Q50: 0 | R50: 0 | S50: 1 | T50: 1 | U50: 1 | V50: 1 | W50: 0 | X50: 0 | Y50: 1 | Z50: 0 | AA50: 1 | AB50: 0 | AC50: 1 | AD50: 0 | AE50: 1 | AF50: 0 | AG50: 2 | AH50: 2 | AI50: 0 | AJ50: =SUM(E50:AI50) -> 15
C51: 6. ABDUL GHOFUR | E51: 0 | F51: 0 | G51: 0 | H51: 0 | I51: 1 | J51: 1 | K51: 1 | L51: 1 | M51: 0 | N51: 0 | O51: 0 | P51: 0 | Q51: 0 | R51: 0 | T51: 0 | U51: 0 | V51: 0 | W51: 0 | X51: 1 | Y51: 0 | Z51: 0 | AA51: 0 | AB51: 0 | AC51: 1 | AD51: 0 | AE51: 0 | AF51: 0 | AG51: 0 | AH51: 0 | AI51: 0 | AJ51: =SUM(E51:AI51) -> 6
...

Sheet SENEPOREJO
C2: Kecamatan | D2: SILIRAGUNG
C3: Kabupaten | D3: BANYUWANGI
C4: Provinsi | D4: JAWA TIMUR
C9: Kelurahan | D9: SENEPOREJO
A12: I | B12: DATA PEMILIH DAN PENGGUNAAN HAK PILIH | AB12: JUMLAH AKHIR
A13: A | B13: DATA PEMILIH | E13: TPS 001 | F13: TPS 002 | G13: TPS 003 | H13: TPS 004 | I13: TPS 005 | J13: TPS 006 | K13: TPS 007 | L13: TPS 008 | M13: TPS 009 | N13: TPS 010 | O13: TPS 011 | P13: TPS 012 | Q13: TPS 013 | R13: TPS 014 | S13: TPS 015 | T13: TPS 016 | U13: TPS 017 | V13: TPS 018 | W13: TPS 019 | X13: TPS 020 | Y13: TPS 021 | Z13: TPS 022 | AA13: TPS 023
B14: Jumlah Pemilih dalam Daftar Pemilih Tetap (DPT) | D14: LK | E14: 133 | F14: 132 | G14: 142 | H14: 138 | I14: 136 | J14: 115 | K14: 118 | L14: 107 | M14: 150 | N14: 140 | O14: 90 | P14: 91 | Q14: 134 | R14: 109 | S14: 136 | T14: 100 | U14: 130 | V14: 139 | W14: 134 | X14: 135 | Y14: 123 | Z14: 149 | AA14: 143 | AB14: =SUM(E14:AA14) -> 2924
D15: PR | E15: 148 | F15: 134 | G15: 140 | H15: 136 | I15: 142 | J15: 119 | K15: 112 | L15: 104 | M15: 127 | N15: 144 | O15: 88 | P15: 85 | Q15: 119 | R15: 119 | S15: 143 | T15: 99 | U15: 146 | V15: 139 | W15: 131 | X15: 148 | Y15: 120 | Z15: 144 | AA15: 140 | AB15: =SUM(E15:AA15) -> 2927
D16: JML | E16: =SUM(E14:E15) -> 281 | F16: =SUM(F14:F15) -> 266 | G16: =SUM(G14:G15) -> 282 | H16: =SUM(H14:H15) -> 274 | I16: =SUM(I14:I15) -> 278 | J16: =SUM(J14:J15) -> 234 | K16: =SUM(K14:K15) -> 230 | L16: =SUM(L14:L15) -> 211 | ... AA16: =SUM(AA14:AA15) -> 283 | AB16: =SUM(E16:AA16) -> 5851
A18: B | B18: PENGGUNA HAK PILIH
B19: 1. | C19: Jumlah pengguna hak pilih dalam Daftar Pemilih Tetap (DPT) | D19: LK | E19: 105 | F19: 102 | G19: 111 | H19: 105 | I19: 108 | J19: 91 | K19: 95 | L19: 80 | M19: 109 | N19: 124 | O19: 77 | P19: 80 | Q19: 100 | R19: 89 | S19: 110 | T19: 79 | U19: 106 | V19: 107 | W19: 113 | X19: 111 | Y19: 100 | Z19: 103 | AA19: 116 | AB19: =SUM(E19:AA19) -> 2321
D20: PR | E20: 116 | F20: 114 | G20: 116 | H20: 105 | I20: 119 | J20: 101 | K20: 95 | L20: 87 | M20: 102 | N20: 126 | O20: 75 | P20: 75 | Q20: 93 | R20: 98 | S20: 122 | T20: 73 | U20: 125 | V20: 115 | W20: 114 | X20: 125 | Y20: 99 | Z20: 117 | AA20: 112 | AB20: =SUM(E20:AA20) -> 2424
D21: JML | E21: =SUM(E19:E20) -> 221 | F21: =SUM(F19:F20) -> 216 | G21: =SUM(G19:G20) -> 227 | H21: =SUM(H19:H20) -> 210 | I21: =SUM(I19:I20) -> 227 | J21: =SUM(J19:J20) -> 192 | K21: =SUM(K19:K20) -> 190 | L21: =SUM(L19:L20) -> 167 | ... AA21: =SUM(AA19:AA20) -> 228 | AB21: =SUM(E21:AA21) -> 4745
B22: 2. | C22: Jumlah pengguna hak pilih dalam Daftar Pemilih Tambahan (DPTb) | D22: LK | E22: 0 | F22: 0 | G22: 0 | H22: 2 | I22: 0 | J22: 0 | K22: 0 | L22: 0 | M22: 0 | N22: 0 | O22: 0 | P22: 0 | Q22: 0 | R22: 0 | S22: 0 | AB22: =SUM(E22:AA22) -> 2
D23: PR | E23: 0 | F23: 1 | G23: 0 | H23: 1 | I23: 0 | J23: 0 | K23: 0 | L23: 0 | M23: 0 | N23: 0 | O23: 0 | P23: 0 | Q23: 0 | R23: 0 | S23: 0 | AB23: =SUM(E23:AA23) -> 2
D24: JML | E24: =SUM(E22:E23) -> 0 | F24: =SUM(F22:F23) -> 1 | G24: =SUM(G22:G23) -> 0 | H24: =SUM(H22:H23) -> 3 | I24: =SUM(I22:I23) -> 0 | J24: =SUM(J22:J23) -> 0 | K24: =SUM(K22:K23) -> 0 | L24: =SUM(L22:L23) -> 0 | ... AA24: =SUM(AA22:AA23) -> 0 | AB24: =SUM(E24:AA24) -> 4
B25: 3. | C25: Jumlah pengguna hak pilih dalam Daftar Pemilih Khusus (DPK) | D25: LK | E25: 0 | F25: 0 | G25: 0 | H25: 3 | I25: 1 | J25: 2 | K25: 2 | L25: 0 | M25: 0 | N25: 0 | O25: 1 | P25: 1 | Q25: 2 | R25: 0 | S25: 0 | T25: 0 | U25: 0 | V25: 1 | W25: 0 | X25: 1 | Y25: 0 | Z25: 1 | AA25: 0 | AB25: =SUM(E25:AA25) -> 15
D26: PR | E26: 2 | F26: 0 | G26: 2 | H26: 1 | I26: 0 | J26: 0 | K26: 3 | L26: 1 | M26: 0 | N26: 0 | O26: 1 | P26: 0 | Q26: 0 | R26: 2 | S26: 0 | T26: 0 | U26: 1 | V26: 3 | W26: 0 | X26: 0 | Y26: 0 | Z26: 0 | AA26: 0 | AB26: =SUM(E26:AA26) -> 16
D27: JML | E27: =SUM(E25:E26) -> 2 | F27: =SUM(F25:F26) -> 0 | G27: =SUM(G25:G26) -> 2 | H27: =SUM(H25:H26) -> 4 | I27: =SUM(I25:I26) -> 1 | J27: =SUM(J25:J26) -> 2 | K27: =SUM(K25:K26) -> 5 | L27: =SUM(L25:L26) -> 1 | ... AA27: =SUM(AA25:AA26) -> 0 | AB27: =SUM(E27:AA27) -> 31
B28: 4. | C28: Jumlah Pengguna Hak Pilih (B.1+B.2+B.3) | D28: LK | E28: =SUM(E19,E22,E25) -> 105 | F28: =SUM(F19,F22,F25) -> 102 | G28: =SUM(G19,G22,G25) -> 111 | H28: =SUM(H19,H22,H25) -> 110 | I28: =SUM(I19,I22,I25) -> 109 | J28: =SUM(J19,J22,J25) -> 93 | K28: =SUM(K19,K22,K25) -> 97 | L28: =SUM(L19,L22,L25) -> 80 | ... AA28: =SUM(AA19,AA22,AA25) -> 116 | AB28: =SUM(E28:AA28) -> 2338
D29: PR | E29: =SUM(E20,E23,E26) -> 118 | F29: =SUM(F20,F23,F26) -> 115 | G29: =SUM(G20,G23,G26) -> 118 | H29: =SUM(H20,H23,H26) -> 107 | I29: =SUM(I20,I23,I26) -> 119 | J29: =SUM(J20,J23,J26) -> 101 | K29: =SUM(K20,K23,K26) -> 98 | L29: =SUM(L20,L23,L26) -> 88 | ... AA29: =SUM(AA20,AA23,AA26) -> 112 | AB29: =SUM(E29:AA29) -> 2442
D30: JML | E30: =SUM(E28:E29) -> 223 | F30: =SUM(F28:F29) -> 217 | G30: =SUM(G28:G29) -> 229 | H30: =SUM(H28:H29) -> 217 | I30: =SUM(I28:I29) -> 228 | J30: =SUM(J28:J29) -> 194 | K30: =SUM(K28:K29) -> 195 | L30: =SUM(L28:L29) -> 168 | ... AA30: =SUM(AA28:AA29) -> 228 | AB30: =SUM(E30:AA30) -> 4780
A32: II | B32: DATA PENGGUNAAN SURAT SUARA
A33: 1 | B33: Jumlah surat suara yang diterima, termasuk surat suara cadangan 2,5% dari DPT | E33: 287 | F33: 272 | G33: 288 | H33: 280 | I33: 284 | J33: 239 | K33: 235 | L33: 217 | M33: 283 | N33: 290 | O33: 182 | P33: 180 | Q33: 259 | R33: 233 | S33: 285 | T33: 203 | U33: 282 | V33: 284 | W33: 271 | X33: 289 | Y33: 248 | Z33: 299 | AA33: 289 | AB33: =SUM(E33:AA33) -> 5979
A34: 2 | B34: Jumlah surat suara yang digunakan | E34: 223 | F34: 217 | G34: 229 | H34: 217 | I34: 228 | J34: 194 | K34: 195 | L34: 168 | M34: 211 | N34: 250 | O34: 154 | P34: 156 | Q34: 195 | R34: 189 | S34: 232 | T34: 152 | U34: 232 | V34: 226 | W34: 227 | X34: 237 | Y34: 199 | Z34: 221 | AA34: 228 | AB34: =SUM(E34:AA34) -> 4780
A35: 3 | B35: Jumlah surat suara dikembalikan oleh pemilih (karena rusak atau keliru coblos) | E35: 1 | F35: 1 | G35: 0 | H35: 3 | I35: 1 | J35: 1 | K35: 0 | L35: 0 | M35: 0 | N35: 1 | O35: 0 | P35: 0 | Q35: 0 | R35: 0 | S35: 1 | T35: 0 | U35: 0 | V35: 1 | W35: 2 | X35: 2 | Y35: 3 | Z35: 4 | AA35: 0 | AB35: =SUM(E35:AA35) -> 21
A36: 4 | B36: Jumlah surat suara yang tidak digunakan/tidak terpakai, termasuk sisa surat suara cadangan | E36: =E33-(E34+E35) -> 63 | F36: =F33-(F34+F35) -> 54 | G36: =G33-(G34+G35) -> 59 | H36: =H33-(H34+H35) -> 60 | I36: =I33-(I34+I35) -> 55 | J36: =J33-(J34+J35) -> 44 | K36: =K33-(K34+K35) -> 40 | L36: =L33-(L34+L35) -> 49 | ... AA36: =AA33-(AA34+AA35) -> 61 | AB36: =SUM(E36:AA36) -> 1178
A38: III | B38: DATA PEMILIH DISABILITAS
B39: Jumlah seluruh Pemilih disabilitas yang menggunakan hak pilih | D39: LK | E39: 0 | F39: 0 | G39: 0 | H39: 0 | I39: 1 | J39: 0 | K39: 0 | L39: 0 | M39: 0 | N39: 0 | O39: 0 | P39: 0 | Q39: 0 | R39: 0 | S39: 1 | AB39: =SUM(E39:AA39) -> 2
D40: PR | E40: 0 | F40: 0 | G40: 0 | H40: 0 | I40: 1 | J40: 0 | K40: 0 | L40: 1 | M40: 0 | N40: 0 | O40: 0 | P40: 0 | Q40: 0 | R40: 0 | S40: 0 | T40: 0 | AB40: =SUM(E40:AA40) -> 2
D41: JML | E41: =SUM(E39:E40) -> 0 | F41: =SUM(F39:F40) -> 0 | G41: =SUM(G39:G40) -> 0 | H41: =SUM(H39:H40) -> 0 | I41: =SUM(I39:I40) -> 2 | J41: =SUM(J39:J40) -> 0 | K41: =SUM(K39:K40) -> 0 | L41: =SUM(L39:L40) -> 1 | ... AA41: =SUM(AA39:AA40) -> 0 | AB41: =SUM(E41:AA41) -> 4
A43: IV | B43: DATA RINCIAN PEROLEHAN SUARA PASANGAN CALON BUPATI DAN WAKIL BUPATI
A44: NOMOR DAN NAMA CALON
A45: A.1 | B45: 1. | C45: Partai Kebangkitan Bangsa | E45: 1 | F45: 3 | G45: 6 | H45: 5 | I45: 0 | J45: 2 | K45: 1 | L45: 1 | M45: 1 | N45: 4 | O45: 0 | P45: 0 | Q45: 4 | R45: 2 | S45: 3 | T45: 2 | U45: 4 | V45: 0 | W45: 3 | X45: 5 | Y45: 6 | Z45: 2 | AA45: 1 | AB45: =SUM(E45:AA45) -> 56
A46: A.2 | C46: 1. MUKHTAR NABALI MUFAUWIQ | E46: 4 | F46: 7 | G46: 5 | H46: 3 | I46: 1 | J46: 0 | K46: 0 | L46: 6 | M46: 4 | N46: 0 | O46: 1 | P46: 0 | Q46: 4 | R46: 5 | S46: 7 | T46: 2 | U46: 4 | V46: 1 | W46: 0 | X46: 0 | Y46: 0 | Z46: 3 | AA46: 0 | AB46: =SUM(E46:AA46) -> 57
C47: 2. H. SUSIYANTO | E47: 0 | F47: 0 | G47: 1 | H47: 0 | I47: 0 | J47: 0 | K47: 0 | L47: 0 | M47: 0 | N47: 2 | O47: 0 | P47: 0 | Q47: 1 | R47: 0 | S47: 0 | T47: 2 | U47: 2 | V47: 1 | W47: 7 | X47: 11 | Y47: 2 | Z47: 12 | AA47: 18 | AB47: =SUM(E47:AA47) -> 59
C48: 3. DUWI HASTRENI, S.H. | E48: 2 | F48: 1 | G48: 0 | H48: 1 | I48: 0 | J48: 1 | K48: 0 | L48: 0 | M48: 0 | N48: 0 | O48: 0 | P48: 0 | Q48: 0 | R48: 0 | S48: 1 | T48: 0 | U48: 3 | V48: 0 | W48: 0 | X48: 0 | Y48: 0 | Z48: 0 | AA48: 0 | AB48: =SUM(E48:AA48) -> 9
C49: 4. MIFTAKHODIN | E49: 1 | F49: 1 | G49: 0 | H49: 0 | I49: 0 | J49: 0 | K49: 0 | L49: 1 | M49: 0 | N49: 0 | O49: 0 | P49: 0 | Q49: 0 | R49: 0 | S49: 0 | T49: 4 | U49: 0 | V49: 0 | W49: 0 | X49: 0 | Y49: 0 | Z49: 0 | AA49: 0 | AB49: =SUM(E49:AA49) -> 7
C50: 5. SITI MUSTIKAH | E50: 31 | F50: 18 | G50: 5 | H50: 5 | I50: 3 | J50: 3 | K50: 1 | L50: 6 | M50: 3 | N50: 3 | O50: 2 | P50: 1 | Q50: 7 | R50: 5 | S50: 0 | T50: 3 | U50: 0 | V50: 1 | W50: 0 | X50: 2 | Y50: 2 | Z50: 2 | AA50: 1 | AB50: =SUM(E50:AA50) -> 104
C51: 6. ABDUL GHOFUR | E51: 0 | F51: 0 | G51: 1 | H51: 0 | I51: 0 | J51: 0 | K51: 0 | L51: 0 | M51: 1 | N51: 0 | O51: 0 | P51: 0 | Q51: 0 | R51: 0 | S51: 0 | T51: 0 | U51: 0 | V51: 0 | W51: 0 | X51: 0 | Y51: 0 | Z51: 0 | AA51: 0 | AB51: =SUM(E51:AA51) -> 2
...

Sheet SILIRAGUNG
C2: Kecamatan | D2: SILIRAGUNG
C3: Kabupaten | D3: BANYUWANGI
C4: Provinsi | D4: JAWA TIMUR
C9: Kelurahan | D9: SILIRAGUNG
A12: I | B12: DATA PEMILIH DAN PENGGUNAAN HAK PILIH | AB12: JUMLAH AKHIR
A13: A | B13: DATA PEMILIH | E13: TPS 001 | F13: TPS 002 | G13: TPS 003 | H13: TPS 004 | I13: TPS 005 | J13: TPS 006 | K13: TPS 007 | L13: TPS 008 | M13: TPS 009 | N13: TPS 010 | O13: TPS 011 | P13: TPS 012 | Q13: TPS 013 | R13: TPS 014 | S13: TPS 015 | T13: TPS 016 | U13: TPS 017 | V13: TPS 018 | W13: TPS 019 | X13: TPS 020 | Y13: TPS 021 | Z13: TPS 022 | AA13: TPS 023
B14: Jumlah Pemilih dalam Daftar Pemilih Tetap (DPT) | D14: LK | E14: 145 | F14: 131 | G14: 134 | H14: 122 | I14: 121 | J14: 109 | K14: 127 | L14: 130 | M14: 140 | N14: 125 | O14: 136 | P14: 142 | Q14: 134 | R14: 131 | S14: 124 | T14: 148 | U14: 136 | V14: 131 | W14: 138 | X14: 139 | Y14: 139 | Z14: 133 | AA14: 136 | AB14: =SUM(E14:AA14) -> 3051
D15: PR | E15: 125 | F15: 123 | G15: 135 | H15: 131 | I15: 133 | J15: 129 | K15: 126 | L15: 137 | M15: 131 | N15: 144 | O15: 134 | P15: 126 | Q15: 133 | R15: 140 | S15: 142 | T15: 125 | U15: 143 | V15: 124 | W15: 145 | X15: 141 | Y15: 137 | Z15: 126 | AA15: 132 | AB15: =SUM(E15:AA15) -> 3062
D16: JML | E16: =SUM(E14:E15) -> 270 | F16: =SUM(F14:F15) -> 254 | G16: =SUM(G14:G15) -> 269 | H16: =SUM(H14:H15) -> 253 | I16: =SUM(I14:I15) -> 254 | J16: =SUM(J14:J15) -> 238 | K16: =SUM(K14:K15) -> 253 | L16: =SUM(L14:L15) -> 267 | ... AA16: =SUM(AA14:AA15) -> 268 | AB16: =SUM(E16:AA16) -> 6113
A18: B | B18: PENGGUNA HAK PILIH
B19: 1. | C19: Jumlah pengguna hak pilih dalam Daftar Pemilih Tetap (DPT) | D19: LK | E19: 109 | F19: 97 | G19: 104 | H19: 86 | I19: 89 | J19: 83 | K19: 89 | L19: 100 | M19: 107 | N19: 93 | O19: 91 | P19: 94 | Q19: 97 | R19: 96 | S19: 88 | T19: 113 | U19: 109 | V19: 90 | W19: 109 | X19: 110 | Y19: 104 | Z19: 94 | AA19: 100 | AB19: =SUM(E19:AA19) -> 2252
D20: PR | E20: 98 | F20: 104 | G20: 107 | H20: 98 | I20: 105 | J20: 108 | K20: 100 | L20: 108 | M20: 104 | N20: 112 | O20: 101 | P20: 87 | Q20: 99 | R20: 109 | S20: 95 | T20: 98 | U20: 120 | V20: 94 | W20: 119 | X20: 122 | Y20: 111 | Z20: 95 | AA20: 99 | AB20: =SUM(E20:AA20) -> 2393
D21: JML | E21: =SUM(E19:E20) -> 207 | F21: =SUM(F19:F20) -> 201 | G21: =SUM(G19:G20) -> 211 | H21: =SUM(H19:H20) -> 184 | I21: =SUM(I19:I20) -> 194 | J21: =SUM(J19:J20) -> 191 | K21: =SUM(K19:K20) -> 189 | L21: =SUM(L19:L20) -> 208 | ... AA21: =SUM(AA19:AA20) -> 199 | AB21: =SUM(E21:AA21) -> 4645
B22: 2. | C22: Jumlah pengguna hak pilih dalam Daftar Pemilih Tambahan (DPTb) | D22: LK | E22: 0 | F22: 0 | G22: 0 | H22: 0 | I22: 0 | J22: 0 | K22: 0 | L22: 0 | M22: 0 | N22: 0 | O22: 0 | P22: 0 | Q22: 0 | R22: 0 | S22: 1 | T22: 0 | U22: 0 | V22: 0 | W22: 0 | X22: 0 | Y22: 0 | Z22: 0 | AA22: 0 | AB22: =SUM(E22:AA22) -> 1
D23: PR | E23: 0 | F23: 0 | G23: 0 | H23: 0 | I23: 0 | J23: 0 | K23: 0 | L23: 0 | M23: 0 | N23: 0 | O23: 0 | P23: 0 | Q23: 0 | R23: 0 | S23: 0 | T23: 0 | U23: 0 | V23: 0 | W23: 0 | X23: 0 | Y23: 0 | Z23: 0 | AA23: 0 | AB23: =SUM(E23:AA23) -> 0
D24: JML | E24: =SUM(E22:E23) -> 0 | F24: =SUM(F22:F23) -> 0 | G24: =SUM(G22:G23) -> 0 | H24: =SUM(H22:H23) -> 0 | I24: =SUM(I22:I23) -> 0 | J24: =SUM(J22:J23) -> 0 | K24: =SUM(K22:K23) -> 0 | L24: =SUM(L22:L23) -> 0 | ... AA24: =SUM(AA22:AA23) -> 0 | AB24: =SUM(E24:AA24) -> 1
B25: 3. | C25: Jumlah pengguna hak pilih dalam Daftar Pemilih Khusus (DPK) | D25: LK | E25: 2 | F25: 2 | G25: 4 | H25: 1 | I25: 1 | J25: 6 | K25: 5 | L25: 1 | M25: 0 | N25: 1 | O25: 0 | P25: 4 | Q25: 0 | R25: 3 | S25: 2 | T25: 2 | U25: 4 | V25: 2 | W25: 0 | X25: 0 | Y25: 1 | Z25: 5 | AA25: 1 | AB25: =SUM(E25:AA25) -> 47
D26: PR | E26: 3 | F26: 6 | G26: 6 | H26: 3 | I26: 4 | J26: 4 | K26: 4 | L26: 0 | M26: 5 | N26: 5 | O26: 1 | P26: 9 | Q26: 1 | R26: 2 | S26: 1 | T26: 5 | U26: 3 | V26: 2 | W26: 2 | X26: 2 | Y26: 2 | Z26: 3 | AA26: 2 | AB26: =SUM(E26:AA26) -> 75
D27: JML | E27: =SUM(E25:E26) -> 5 | F27: =SUM(F25:F26) -> 8 | G27: =SUM(G25:G26) -> 10 | H27: =SUM(H25:H26) -> 4 | I27: =SUM(I25:I26) -> 5 | J27: =SUM(J25:J26) -> 10 | K27: =SUM(K25:K26) -> 9 | L27: =SUM(L25:L26) -> 1 | ... AA27: =SUM(AA25:AA26) -> 3 | AB27: =SUM(E27:AA27) -> 122
B28: 4. | C28: Jumlah Pengguna Hak Pilih (B.1+B.2+B.3) | D28: LK | E28: =SUM(E19,E22,E25) -> 111 | F28: =SUM(F19,F22,F25) -> 99 | G28: =SUM(G19,G22,G25) -> 108 | H28: =SUM(H19,H22,H25) -> 87 | I28: =SUM(I19,I22,I25) -> 90 | J28: =SUM(J19,J22,J25) -> 89 | K28: =SUM(K19,K22,K25) -> 94 | L28: =SUM(L19,L22,L25) -> 101 | ... AA28: =SUM(AA19,AA22,AA25) -> 101 | AB28: =SUM(E28:AA28) -> 2300
D29: PR | E29: =SUM(E20,E23,E26) -> 101 | F29: =SUM(F20,F23,F26) -> 110 | G29: =SUM(G20,G23,G26) -> 113 | H29: =SUM(H20,H23,H26) -> 101 | I29: =SUM(I20,I23,I26) -> 109 | J29: =SUM(J20,J23,J26) -> 112 | K29: =SUM(K20,K23,K26) -> 104 | L29: =SUM(L20,L23,L26) -> 108 | ... AA29: =SUM(AA20,AA23,AA26) -> 101 | AB29: =SUM(E29:AA29) -> 2468
D30: JML | E30: =SUM(E28:E29) -> 212 | F30: =SUM(F28:F29) -> 209 | G30: =SUM(G28:G29) -> 221 | H30: =SUM(H28:H29) -> 188 | I30: =SUM(I28:I29) -> 199 | J30: =SUM(J28:J29) -> 201 | K30: =SUM(K28:K29) -> 198 | L30: =SUM(L28:L29) -> 209 | ... AA30: =SUM(AA28:AA29) -> 202 | AB30: =SUM(E30:AA30) -> 4768
A32: II | B32: DATA PENGGUNAAN SURAT SUARA
A33: 1 | B33: Jumlah surat suara yang diterima, termasuk surat suara cadangan 2,5% dari DPT | E33: 276 | F33: 260 | G33: 275 | H33: 259 | I33: 260 | J33: 243 | K33: 259 | L33: 273 | M33: 277 | N33: 275 | O33: 276 | P33: 274 | Q33: 273 | R33: 277 | S33: 273 | T33: 279 | U33: 285 | V33: 261 | W33: 289 | X33: 286 | Y33: 274 | Z33: 265 | AA33: 274 | AB33: =SUM(E33:AA33) -> 6243
A34: 2 | B34: Jumlah surat suara yang digunakan | E34: 212 | F34: 209 | G34: 221 | H34: 188 | I34: 199 | J34: 201 | K34: 198 | L34: 209 | M34: 216 | N34: 211 | O34: 193 | P34: 194 | Q34: 197 | R34: 210 | S34: 187 | T34: 218 | U34: 236 | V34: 188 | W34: 230 | X34: 234 | Y34: 218 | Z34: 197 | AA34: 202 | AB34: =SUM(E34:AA34) -> 4768
A35: 3 | B35: Jumlah surat suara dikembalikan oleh pemilih (karena rusak atau keliru coblos) | E35: 2 | F35: 0 | G35: 0 | H35: 0 | I35: 0 | J35: 0 | K35: 0 | L35: 0 | M35: 0 | N35: 0 | O35: 0 | P35: 3 | Q35: 0 | R35: 0 | S35: 2 | T35: 0 | U35: 0 | V35: 0 | W35: 0 | X35: 0 | Y35: 2 | Z35: 0 | AA35: 1 | AB35: =SUM(E35:AA35) -> 10
A36: 4 | B36: Jumlah surat suara yang tidak digunakan/tidak terpakai, termasuk sisa surat suara cadangan | E36: =E33-(E34+E35) -> 62 | F36: =F33-(F34+F35) -> 51 | G36: =G33-(G34+G35) -> 54 | H36: =H33-(H34+H35) -> 71 | I36: =I33-(I34+I35) -> 61 | J36: =J33-(J34+J35) -> 42 | K36: =K33-(K34+K35) -> 61 | L36: =L33-(L34+L35) -> 64 | ... AA36: =AA33-(AA34+AA35) -> 71 | AB36: =SUM(E36:AA36) -> 1465
A38: III | B38: DATA PEMILIH DISABILITAS
B39: Jumlah seluruh Pemilih disabilitas yang menggunakan hak pilih | D39: LK | E39: 0 | F39: 0 | G39: 0 | H39: 0 | I39: 0 | J39: 0 | K39: 0 | L39: 0 | M39: 0 | N39: 1 | O39: 0 | P39: 0 | Q39: 0 | R39: 0 | S39: 0 | T39: 0 | U39: 0 | V39: 0 | W39: 0 | X39: 0 | Y39: 0 | Z39: 0 | AA39: 1 | AB39: =SUM(E39:AA39) -> 2
D40: PR | E40: 0 | F40: 0 | G40: 0 | H40: 0 | I40: 0 | J40: 1 | K40: 0 | L40: 0 | M40: 0 | N40: 1 | O40: 0 | P40: 0 | Q40: 0 | R40: 0 | S40: 0 | T40: 0 | U40: 0 | V40: 0 | W40: 0 | X40: 2 | Y40: 0 | Z40: 0 | AA40: 1 | AB40: =SUM(E40:AA40) -> 5
D41: JML | E41: =SUM(E39:E40) -> 0 | F41: =SUM(F39:F40) -> 0 | G41: =SUM(G39:G40) -> 0 | H41: =SUM(H39:H40) -> 0 | I41: =SUM(I39:I40) -> 0 | J41: =SUM(J39:J40) -> 1 | K41: =SUM(K39:K40) -> 0 | L41: =SUM(L39:L40) -> 0 | ... AA41: =SUM(AA39:AA40) -> 2 | AB41: =SUM(E41:AA41) -> 7
A43: IV | B43: DATA RINCIAN PEROLEHAN SUARA PASANGAN CALON BUPATI DAN WAKIL BUPATI
A44: NOMOR DAN NAMA CALON
A45: A.1 | B45: 1. | C45: Partai Kebangkitan Bangsa | E45: 7 | F45: 4 | G45: 4 | H45: 1 | I45: 3 | J45: 5 | K45: 4 | L45: 8 | M45: 1 | N45: 4 | O45: 4 | P45: 4 | Q45: 13 | R45: 7 | S45: 5 | T45: 10 | U45: 7 | V45: 1 | W45: 4 | X45: 1 | Y45: 6 | Z45: 5 | AA45: 2 | AB45: =SUM(E45:AA45) -> 110
A46: A.2 | C46: 1. MUKHTAR NABALI MUFAUWIQ | E46: 14 | F46: 3 | G46: 5 | H46: 6 | I46: 9 | J46: 18 | K46: 17 | L46: 7 | M46: 1 | N46: 11 | O46: 11 | P46: 8 | Q46: 33 | R46: 30 | S46: 11 | T46: 17 | U46: 11 | V46: 7 | W46: 2 | X46: 12 | Y46: 22 | Z46: 9 | AA46: 8 | AB46: =SUM(E46:AA46) -> 272
C47: 2. H. SUSIYANTO | E47: 2 | F47: 2 | G47: 4 | H47: 2 | I47: 3 | J47: 3 | K47: 1 | L47: 2 | M47: 2 | N47: 0 | O47: 1 | P47: 1 | Q47: 1 | R47: 0 | S47: 0 | T47: 2 | U47: 1 | V47: 0 | W47: 0 | X47: 0 | Y47: 0 | Z47: 1 | AA47: 0 | AB47: =SUM(E47:AA47) -> 28
C48: 3. DUWI HASTRENI, S.H. | E48: 0 | F48: 0 | G48: 0 | H48: 0 | I48: 0 | J48: 0 | K48: 1 | L48: 0 | M48: 0 | N48: 0 | O48: 0 | P48: 0 | Q48: 0 | R48: 0 | S48: 0 | T48: 0 | U48: 0 | V48: 0 | W48: 0 | X48: 0 | Y48: 3 | Z48: 9 | AA48: 6 | AB48: =SUM(E48:AA48) -> 19
C49: 4. MIFTAKHODIN | E49: 1 | F49: 0 | G49: 0 | H49: 0 | I49: 1 | J49: 0 | K49: 0 | L49: 0 | M49: 0 | N49: 0 | O49: 0 | P49: 2 | Q49: 0 | R49: 0 | S49: 0 | T49: 0 | U49: 0 | V49: 0 | W49: 0 | X49: 0 | Y49: 2 | Z49: 1 | AA49: 0 | AB49: =SUM(E49:AA49) -> 7
C50: 5. SITI MUSTIKAH | E50: 2 | F50: 1 | G50: 0 | H50: 2 | I50: 0 | J50: 0 | K50: 0 | L50: 1 | M50: 0 | N50: 0 | O50: 0 | P50: 0 | Q50: 1 | R50: 0 | S50: 2 | T50: 0 | U50: 0 | V50: 0 | W50: 0 | X50: 0 | Y50: 1 | Z50: 0 | AA50: 0 | AB50: =SUM(E50:AA50) -> 10
C51: 6. ABDUL GHOFUR | E51: 1 | F51: 0 | G51: 1 | H51: 0 | I51: 0 | J51: 1 | K51: 0 | L51: 0 | M51: 0 | N51: 0 | O51: 0 | P51: 2 | Q51: 1 | R51: 0 | S51: 0 | T51: 1 | U51: 1 | V51: 0 | W51: 1 | X51: 0 | Y51: 0 | Z51: 0 | AA51: 0 | AB51: =SUM(E51:AA51) -> 9
...
