Workbook

Sheet DPRD KABUPATEN
C8: Kecamatan | D8: WONGSOREJO
C9: Kabupaten | D9: BANYUWANGI
C10: Provinsi | D10: JAWA TIMUR
A12: I | B12: DATA PEMILIH DAN PENGGUNAAN HAK PILIH | E12: JUMLAH AKHIR
A13: A | B13: DATA PEMILIH
B14: Jumlah Pemilih dalam Daftar Pemilih Tetap (DPT) | D14: LK | E14: =ALASBULUH!AG14+ALASREJO!U14+BAJULMATI!AD14+BANGSRING!W14+BENGKAK!Y14+BIMOREJO!R14+SIDODADI!U14+SIDOWANGI!P14+SUMBERANYAR!N14+SUMBERKENCONO!T14+WATUKEBO!Y14+WONGSOREJO!AM14 -> 29810
D15: PR | E15: =ALASBULUH!AG15+ALASREJO!U15+BAJULMATI!AD15+BANGSRING!W15+BENGKAK!Y15+BIMOREJO!R15+SIDODADI!U15+SIDOWANGI!P15+SUMBERANYAR!N15+SUMBERKENCONO!T15+WATUKEBO!Y15+WONGSOREJO!AM15 -> 30473
D16: JML | E16: =SUM(E14:E15) -> 60283
A18: B | B18: PENGGUNA HAK PILIH
B19: 1. | C19: Jumlah pengguna hak pilih dalam Daftar Pemilih Tetap (DPT) | D19: LK | E19: =ALASBULUH!AG19+ALASREJO!U19+BAJULMATI!AD19+BANGSRING!W19+BENGKAK!Y19+BIMOREJO!R19+SIDODADI!U19+SIDOWANGI!P19+SUMBERANYAR!N19+SUMBERKENCONO!T19+WATUKEBO!Y19+WONGSOREJO!AM19 -> 22279
D20: PR | E20: =ALASBULUH!AG20+ALASREJO!U20+BAJULMATI!AD20+BANGSRING!W20+BENGKAK!Y20+BIMOREJO!R20+SIDODADI!U20+SIDOWANGI!P20+SUMBERANYAR!N20+SUMBERKENCONO!T20+WATUKEBO!Y20+WONGSOREJO!AM20 -> 24259
D21: JML | E21: =SUM(E19:E20) -> 46538
B22: 2. | C22: Jumlah pengguna hak pilih dalam Daftar Pemilih Tambahan (DPTb) | D22: LK | E22: =ALASBULUH!AG22+ALASREJO!U22+BAJULMATI!AD22+BANGSRING!W22+BENGKAK!Y22+BIMOREJO!R22+SIDODADI!U22+SIDOWANGI!P22+SUMBERANYAR!N22+SUMBERKENCONO!T22+WATUKEBO!Y22+WONGSOREJO!AM22 -> 36
D23: PR | E23: =ALASBULUH!AG23+ALASREJO!U23+BAJULMATI!AD23+BANGSRING!W23+BENGKAK!Y23+BIMOREJO!R23+SIDODADI!U23+SIDOWANGI!P23+SUMBERANYAR!N23+SUMBERKENCONO!T23+WATUKEBO!Y23+WONGSOREJO!AM23 -> 24
D24: JML | E24: =SUM(E22:E23) -> 60
B25: 3. | C25: Jumlah pengguna hak pilih dalam Daftar Pemilih Khusus (DPK) | D25: LK | E25: =ALASBULUH!AG25+ALASREJO!U25+BAJULMATI!AD25+BANGSRING!W25+BENGKAK!Y25+BIMOREJO!R25+SIDODADI!U25+SIDOWANGI!P25+SUMBERANYAR!N25+SUMBERKENCONO!T25+WATUKEBO!Y25+WONGSOREJO!AM25 -> 160
D26: PR | E26: =ALASBULUH!AG26+ALASREJO!U26+BAJULMATI!AD26+BANGSRING!W26+BENGKAK!Y26+BIMOREJO!R26+SIDODADI!U26+SIDOWANGI!P26+SUMBERANYAR!N26+SUMBERKENCONO!T26+WATUKEBO!Y26+WONGSOREJO!AM26 -> 195
D27: JML | E27: =SUM(E25:E26) -> 355
B28: 4. | C28: Jumlah Pengguna Hak Pilih (B.1+B.2+B.3) | D28: LK | E28: =E19+E22+E25 -> 22475
D29: PR | E29: =E20+E23+E26 -> 24478
D30: JML | E30: =SUM(E28:E29) -> 46953
A32: II | B32: DATA PENGGUNAAN SURAT SUARA
A33: 1 | B33: Jumlah surat suara yang diterima, termasuk surat suara cadangan 2,5% dari DPT | E33: =ALASBULUH!AG33+ALASREJO!U33+BAJULMATI!AD33+BANGSRING!W33+BENGKAK!Y33+BIMOREJO!R33+SIDODADI!U33+SIDOWANGI!P33+SUMBERANYAR!N33+SUMBERKENCONO!T33+WATUKEBO!Y33+WONGSOREJO!AM33 -> 61506
A34: 2 | B34: Jumlah surat suara yang digunakan | E34: =ALASBULUH!AG34+ALASREJO!U34+BAJULMATI!AD34+BANGSRING!W34+BENGKAK!Y34+BIMOREJO!R34+SIDODADI!U34+SIDOWANGI!P34+SUMBERANYAR!N34+SUMBERKENCONO!T34+WATUKEBO!Y34+WONGSOREJO!AM34 -> 46953
A35: 3 | B35: Jumlah surat suara dikembalikan oleh pemilih (karena rusak atau keliru coblos) | E35: =ALASBULUH!AG35+ALASREJO!U35+BAJULMATI!AD35+BANGSRING!W35+BENGKAK!Y35+BIMOREJO!R35+SIDODADI!U35+SIDOWANGI!P35+SUMBERANYAR!N35+SUMBERKENCONO!T35+WATUKEBO!Y35+WONGSOREJO!AM35 -> 90
A36: 4 | B36: Jumlah surat suara yang tidak digunakan/tidak terpakai, termasuk sisa surat suara cadangan | E36: =E33-(E34+E35) -> 14463
A38: III | B38: DATA PEMILIH DISABILITAS
B39: Jumlah seluruh Pemilih disabilitas yang menggunakan hak pilih | D39: LK | E39: =ALASBULUH!AG39+ALASREJO!U39+BAJULMATI!AD39+BANGSRING!W39+BENGKAK!Y39+BIMOREJO!R39+SIDODADI!U39+SIDOWANGI!P39+SUMBERANYAR!N39+SUMBERKENCONO!T39+WATUKEBO!Y39+WONGSOREJO!AM39 -> 11
D40: PR | E40: =ALASBULUH!AG40+ALASREJO!U40+BAJULMATI!AD40+BANGSRING!W40+BENGKAK!Y40+BIMOREJO!R40+SIDODADI!U40+SIDOWANGI!P40+SUMBERANYAR!N40+SUMBERKENCONO!T40+WATUKEBO!Y40+WONGSOREJO!AM40 -> 27
D41: JML | E41: =SUM(E39:E40) -> 38
A43: IV | B43: DATA RINCIAN PEROLEHAN SUARA PASANGAN CALON BUPATI DAN WAKIL BUPATI
A44: NOMOR DAN NAMA CALON
A45: A.1 | B45: 1. | C45: Partai Kebangkitan Bangsa | E45: =ALASBULUH!AG45+ALASREJO!U45+BAJULMATI!AD45+BANGSRING!W45+BENGKAK!Y45+BIMOREJO!R45+SIDODADI!U45+SIDOWANGI!P45+SUMBERANYAR!N45+SUMBERKENCONO!T45+WATUKEBO!Y45+WONGSOREJO!AM45 -> 1680
A46: A.2 | B46: 1 | C46: HJ. SITI MAKHROCHATIN NI’MAH, S.PD., M.M. | E46: =ALASBULUH!AG46+ALASREJO!U46+BAJULMATI!AD46+BANGSRING!W46+BENGKAK!Y46+BIMOREJO!R46+SIDODADI!U46+SIDOWANGI!P46+SUMBERANYAR!N46+SUMBERKENCONO!T46+WATUKEBO!Y46+WONGSOREJO!AM46 -> 1754
B47: 2 | C47: A. TAUFIK | E47: =ALASBULUH!AG47+ALASREJO!U47+BAJULMATI!AD47+BANGSRING!W47+BENGKAK!Y47+BIMOREJO!R47+SIDODADI!U47+SIDOWANGI!P47+SUMBERANYAR!N47+SUMBERKENCONO!T47+WATUKEBO!Y47+WONGSOREJO!AM47 -> 6354
B48: 3 | C48: KHOIRUL FAHMI ISKANDAR, S.PD | E48: =ALASBULUH!AG48+ALASREJO!U48+BAJULMATI!AD48+BANGSRING!W48+BENGKAK!Y48+BIMOREJO!R48+SIDODADI!U48+SIDOWANGI!P48+SUMBERANYAR!N48+SUMBERKENCONO!T48+WATUKEBO!Y48+WONGSOREJO!AM48 -> 125
B49: 4 | C49: AKHMAD, S.PD., M.M. | E49: =ALASBULUH!AG49+ALASREJO!U49+BAJULMATI!AD49+BANGSRING!W49+BENGKAK!Y49+BIMOREJO!R49+SIDODADI!U49+SIDOWANGI!P49+SUMBERANYAR!N49+SUMBERKENCONO!T49+WATUKEBO!Y49+WONGSOREJO!AM49 -> 772
B50: 5 | C50: SOFI WULANDARI, S.H. | E50: =ALASBULUH!AG50+ALASREJO!U50+BAJULMATI!AD50+BANGSRING!W50+BENGKAK!Y50+BIMOREJO!R50+SIDODADI!U50+SIDOWANGI!P50+SUMBERANYAR!N50+SUMBERKENCONO!T50+WATUKEBO!Y50+WONGSOREJO!AM50 -> 16
B51: 6 | C51: AL MA’ARIF | E51: =ALASBULUH!AG51+ALASREJO!U51+BAJULMATI!AD51+BANGSRING!W51+BENGKAK!Y51+BIMOREJO!R51+SIDODADI!U51+SIDOWANGI!P51+SUMBERANYAR!N51+SUMBERKENCONO!T51+WATUKEBO!Y51+WONGSOREJO!AM51 -> 44
A55: B | B55: JUMLAH SUARA SAH PARTAI POLITIK DAN CALON (A1 + A2) | E55: =SUM(E45:E54) -> 10745
...

Sheet BANGSRING
C2: Kecamatan | D2: WONGSOREJO
C3: Kabupaten | D3: BANYUWANGI
C4: Provinsi | D4: JAWA TIMUR
C9: Kelurahan | D9: BANGSRING
A12: I | B12: DATA PEMILIH DAN PENGGUNAAN HAK PILIH | W12: JUMLAH AKHIR
A13: A | B13: DATA PEMILIH | E13: TPS 001 | F13: TPS 002 | G13: TPS 003 | H13: TPS 004 | I13: TPS 005 | J13: TPS 006 | K13: TPS 007 | L13: TPS 008 | M13: TPS 009 | N13: TPS 010 | O13: TPS 011 | P13: TPS 012 | Q13: TPS 013 | R13: TPS 014 | S13: TPS 015 | T13: TPS 016 | U13: TPS 017 | V13: TPS 018
B14: Jumlah Pemilih dalam Daftar Pemilih Tetap (DPT) | D14: LK | E14: 142 | F14: 135 | G14: 133 | H14: 137 | I14: 142 | J14: 148 | K14: 143 | L14: 147 | M14: 143 | N14: 61 | O14: 150 | P14: 143 | Q14: 122 | R14: 136 | S14: 147 | T14: 115 | U14: 122 | V14: 126 | W14: =SUM(E14:V14) -> 2392
D15: PR | E15: 138 | F15: 131 | G15: 149 | H15: 140 | I15: 150 | J15: 149 | K15: 143 | L15: 151 | M15: 140 | N15: 64 | O15: 142 | P15: 149 | Q15: 134 | R15: 152 | S15: 146 | T15: 121 | U15: 131 | V15: 125 | W15: =SUM(E15:V15) -> 2455
D16: JML | E16: =SUM(E14:E15) -> 280 | F16: =SUM(F14:F15) -> 266 | G16: =SUM(G14:G15) -> 282 | H16: =SUM(H14:H15) -> 277 | I16: =SUM(I14:I15) -> 292 | J16: =SUM(J14:J15) -> 297 | K16: =SUM(K14:K15) -> 286 | L16: =SUM(L14:L15) -> 298 | ... V16: =SUM(V14:V15) -> 251 | W16: =SUM(E16:V16) -> 4847
A18: B | B18: PENGGUNA HAK PILIH
B19: 1. | C19: Jumlah pengguna hak pilih dalam Daftar Pemilih Tetap (DPT) | D19: LK | E19: 107 | F19: 95 | G19: 93 | H19: 91 | I19: 106 | J19: 111 | K19: 108 | L19: 107 | M19: 121 | N19: 50 | O19: 123 | P19: 121 | Q19: 95 | R19: 96 | S19: 113 | T19: 96 | U19: 98 | V19: 100 | W19: =SUM(E19:V19) -> 1831
D20: PR | E20: 112 | F20: 100 | G20: 132 | H20: 113 | I20: 120 | J20: 127 | K20: 119 | L20: 129 | M20: 118 | N20: 56 | O20: 113 | P20: 113 | Q20: 110 | R20: 116 | S20: 120 | T20: 88 | U20: 112 | V20: 106 | W20: =SUM(E20:V20) -> 2004
D21: JML | E21: =SUM(E19:E20) -> 219 | F21: =SUM(F19:F20) -> 195 | G21: =SUM(G19:G20) -> 225 | H21: =SUM(H19:H20) -> 204 | I21: =SUM(I19:I20) -> 226 | J21: =SUM(J19:J20) -> 238 | K21: =SUM(K19:K20) -> 227 | L21: =SUM(L19:L20) -> 236 | ... V21: =SUM(V19:V20) -> 206 | W21: =SUM(E21:V21) -> 3835
B22: 2. | C22: Jumlah pengguna hak pilih dalam Daftar Pemilih Tambahan (DPTb) | D22: LK | W22: =SUM(E22:V22) -> 0
D23: PR | W23: =SUM(E23:V23) -> 0
D24: JML | E24: =SUM(E22:E23) -> 0 | F24: =SUM(F22:F23) -> 0 | G24: =SUM(G22:G23) -> 0 | H24: =SUM(H22:H23) -> 0 | I24: =SUM(I22:I23) -> 0 | J24: =SUM(J22:J23) -> 0 | K24: =SUM(K22:K23) -> 0 | L24: =SUM(L22:L23) -> 0 | ... V24: =SUM(V22:V23) -> 0 | W24: =SUM(E24:V24) -> 0
B25: 3. | C25: Jumlah pengguna hak pilih dalam Daftar Pemilih Khusus (DPK) | D25: LK | E25: 3 | F25: 3 | G25: 0 | H25: 4 | I25: 2 | J25: 0 | K25: 3 | L25: 0 | M25: 0 | N25: 1 | O25: 0 | P25: 3 | Q25: 6 | R25: 0 | S25: 0 | T25: 1 | U25: 3 | V25: 0 | W25: =SUM(E25:V25) -> 29
D26: PR | E26: 5 | F26: 7 | G26: 1 | H26: 4 | I26: 0 | J26: 1 | K26: 3 | L26: 0 | M26: 1 | N26: 1 | O26: 0 | P26: 9 | Q26: 2 | R26: 0 | S26: 0 | T26: 2 | U26: 6 | V26: 0 | W26: =SUM(E26:V26) -> 42
D27: JML | E27: =SUM(E25:E26) -> 8 | F27: =SUM(F25:F26) -> 10 | G27: =SUM(G25:G26) -> 1 | H27: =SUM(H25:H26) -> 8 | I27: =SUM(I25:I26) -> 2 | J27: =SUM(J25:J26) -> 1 | K27: =SUM(K25:K26) -> 6 | L27: =SUM(L25:L26) -> 0 | ... V27: =SUM(V25:V26) -> 0 | W27: =SUM(E27:V27) -> 71
B28: 4. | C28: Jumlah Pengguna Hak Pilih (B.1+B.2+B.3) | D28: LK | E28: =SUM(E19,E22,E25) -> 110 | F28: =SUM(F19,F22,F25) -> 98 | G28: =SUM(G19,G22,G25) -> 93 | H28: =SUM(H19,H22,H25) -> 95 | I28: =SUM(I19,I22,I25) -> 108 | J28: =SUM(J19,J22,J25) -> 111 | K28: =SUM(K19,K22,K25) -> 111 | L28: =SUM(L19,L22,L25) -> 107 | ... V28: =SUM(V19,V22,V25) -> 100 | W28: =SUM(E28:V28) -> 1860
D29: PR | E29: =SUM(E20,E23,E26) -> 117 | F29: =SUM(F20,F23,F26) -> 107 | G29: =SUM(G20,G23,G26) -> 133 | H29: =SUM(H20,H23,H26) -> 117 | I29: =SUM(I20,I23,I26) -> 120 | J29: =SUM(J20,J23,J26) -> 128 | K29: =SUM(K20,K23,K26) -> 122 | L29: =SUM(L20,L23,L26) -> 129 | ... V29: =SUM(V20,V23,V26) -> 106 | W29: =SUM(E29:V29) -> 2046
D30: JML | E30: =SUM(E28:E29) -> 227 | F30: =SUM(F28:F29) -> 205 | G30: =SUM(G28:G29) -> 226 | H30: =SUM(H28:H29) -> 212 | I30: =SUM(I28:I29) -> 228 | J30: =SUM(J28:J29) -> 239 | K30: =SUM(K28:K29) -> 233 | L30: =SUM(L28:L29) -> 236 | ... V30: =SUM(V28:V29) -> 206 | W30: =SUM(E30:V30) -> 3906
A32: II | B32: DATA PENGGUNAAN SURAT SUARA
A33: 1 | B33: Jumlah surat suara yang diterima, termasuk surat suara cadangan 2,5% dari DPT | E33: 286 | F33: 272 | G33: 288 | H33: 280 | I33: 298 | J33: 303 | K33: 288 | L33: 304 | M33: 289 | N33: 128 | O33: 298 | P33: 298 | Q33: 262 | R33: 293 | S33: 299 | T33: 237 | U33: 263 | V33: 257 | W33: =SUM(E33:V33) -> 4943
A34: 2 | B34: Jumlah surat suara yang digunakan | E34: 227 | F34: 205 | G34: 226 | H34: 212 | I34: 228 | J34: 239 | K34: 233 | L34: 236 | M34: 240 | N34: 108 | O34: 236 | P34: 246 | Q34: 213 | R34: 212 | S34: 233 | T34: 187 | U34: 219 | V34: 206 | W34: =SUM(E34:V34) -> 3906
A35: 3 | B35: Jumlah surat suara dikembalikan oleh pemilih (karena rusak atau keliru coblos) | E35: 0 | F35: 0 | G35: 0 | H35: 0 | I35: 0 | J35: 0 | K35: 0 | L35: 0 | M35: 0 | N35: 0 | O35: 0 | P35: 0 | Q35: 2 | R35: 0 | S35: 0 | T35: 9 | U35: 0 | V35: 0 | W35: =SUM(E35:V35) -> 11
A36: 4 | B36: Jumlah surat suara yang tidak digunakan/tidak terpakai, termasuk sisa surat suara cadangan | E36: =E33-(E34+E35) -> 59 | F36: =F33-(F34+F35) -> 67 | G36: =G33-(G34+G35) -> 62 | H36: =H33-(H34+H35) -> 68 | I36: =I33-(I34+I35) -> 70 | J36: =J33-(J34+J35) -> 64 | K36: =K33-(K34+K35) -> 55 | L36: =L33-(L34+L35) -> 68 | ... V36: =V33-(V34+V35) -> 51 | W36: =SUM(E36:V36) -> 1026
A38: III | B38: DATA PEMILIH DISABILITAS
B39: Jumlah seluruh Pemilih disabilitas yang menggunakan hak pilih | D39: LK | E39: 0 | F39: 2 | G39: 1 | H39: 0 | I39: 0 | J39: 0 | K39: 0 | L39: 0 | M39: 0 | N39: 0 | O39: 0 | P39: 0 | Q39: 0 | R39: 0 | S39: 0 | T39: 0 | U39: 0 | V39: 0 | W39: =SUM(E39:V39) -> 3
D40: PR | E40: 0 | F40: 2 | G40: 0 | H40: 0 | I40: 0 | J40: 0 | K40: 0 | L40: 0 | M40: 0 | N40: 0 | O40: 0 | P40: 0 | Q40: 0 | R40: 2 | S40: 0 | T40: 0 | U40: 0 | V40: 0 | W40: =SUM(E40:V40) -> 4
D41: JML | E41: =SUM(E39:E40) -> 0 | F41: =SUM(F39:F40) -> 4 | G41: =SUM(G39:G40) -> 1 | H41: =SUM(H39:H40) -> 0 | I41: =SUM(I39:I40) -> 0 | J41: =SUM(J39:J40) -> 0 | K41: =SUM(K39:K40) -> 0 | L41: =SUM(L39:L40) -> 0 | ... V41: =SUM(V39:V40) -> 0 | W41: =SUM(E41:V41) -> 7
A43: IV | B43: DATA RINCIAN PEROLEHAN SUARA PASANGAN CALON BUPATI DAN WAKIL BUPATI
A44: NOMOR DAN NAMA CALON
A45: A.1 | B45: 1. | C45: Partai Kebangkitan Bangsa | E45: 14 | F45: 3 | G45: 12 | H45: 9 | I45: 7 | J45: 8 | K45: 5 | L45: 4 | M45: 8 | N45: 1 | O45: 6 | P45: 5 | Q45: 5 | R45: 9 | S45: 11 | T45: 11 | U45: 4 | V45: 2 | W45: =SUM(E45:V45) -> 124
A46: A.2 | B46: 1 | C46: HJ. SITI MAKHROCHATIN NI’MAH, S.PD., M.M. | E46: 4 | F46: 3 | G46: 7 | H46: 12 | I46: 5 | J46: 6 | K46: 4 | L46: 2 | M46: 2 | N46: 0 | O46: 2 | P46: 6 | Q46: 0 | R46: 5 | S46: 7 | T46: 3 | U46: 8 | V46: 2 | W46: =SUM(E46:V46) -> 78
B47: 2 | C47: A. TAUFIK | E47: 27 | F47: 17 | G47: 54 | H47: 16 | I47: 14 | J47: 29 | K47: 12 | L47: 4 | M47: 38 | N47: 2 | O47: 53 | P47: 42 | Q47: 24 | R47: 17 | S47: 25 | T47: 22 | U47: 70 | V47: 24 | W47: =SUM(E47:V47) -> 490
B48: 3 | C48: KHOIRUL FAHMI ISKANDAR, S.PD | E48: 0 | F48: 1 | G48: 0 | H48: 2 | I48: 0 | J48: 0 | K48: 0 | L48: 1 | M48: 0 | N48: 0 | O48: 0 | P48: 0 | Q48: 0 | R48: 0 | S48: 2 | T48: 1 | U48: 0 | V48: 2 | W48: =SUM(E48:V48) -> 9
B49: 4 | C49: AKHMAD, S.PD., M.M. | E49: 1 | F49: 1 | G49: 0 | H49: 0 | I49: 0 | J49: 0 | K49: 0 | L49: 3 | M49: 0 | N49: 0 | O49: 0 | P49: 1 | Q49: 3 | R49: 0 | S49: 1 | T49: 0 | U49: 2 | V49: 1 | W49: =SUM(E49:V49) -> 13
B50: 5 | C50: SOFI WULANDARI, S.H. | E50: 0 | F50: 0 | G50: 0 | H50: 0 | I50: 0 | J50: 0 | K50: 1 | L50: 0 | M50: 0 | N50: 0 | O50: 0 | P50: 0 | Q50: 0 | R50: 0 | S50: 0 | T50: 1 | U50: 0 | V50: 0 | W50: =SUM(E50:V50) -> 2
B51: 6 | C51: AL MA’ARIF | E51: 1 | F51: 0 | G51: 0 | H51: 0 | I51: 0 | J51: 0 | K51: 0 | L51: 0 | M51: 0 | N51: 0 | O51: 0 | P51: 0 | Q51: 0 | R51: 0 | S51: 0 | T51: 1 | U51: 0 | V51: 0 | W51: =SUM(E51:V51) -> 2
...

Sheet BENGKAK
C2: Kecamatan | D2: WONGSOREJO
C3: Kabupaten | D3: BANYUWANGI
C4: Provinsi | D4: JAWA TIMUR
C9: Kelurahan | D9: BENGKAK
A12: I | B12: DATA PEMILIH DAN PENGGUNAAN HAK PILIH | Y12: JUMLAH AKHIR
A13: A | B13: DATA PEMILIH | E13: TPS 001 | F13: TPS 002 | G13: TPS 003 | H13: TPS 004 | I13: TPS 005 | J13: TPS 006 | K13: TPS 007 | L13: TPS 008 | M13: TPS 009 | N13: TPS 010 | O13: TPS 011 | P13: TPS 012 | Q13: TPS 013 | R13: TPS 014 | S13: TPS 015 | T13: TPS 016 | U13: TPS 017 | V13: TPS 018 | W13: TPS 019 | X13: TPS 020
B14: Jumlah Pemilih dalam Daftar Pemilih Tetap (DPT) | D14: LK | E14: 121 | F14: 137 | G14: 150 | H14: 141 | I14: 129 | J14: 142 | K14: 142 | L14: 142 | M14: 132 | N14: 111 | O14: 121 | P14: 140 | Q14: 115 | R14: 135 | S14: 139 | T14: 110 | U14: 151 | V14: 139 | W14: 133 | X14: 132 | Y14: =SUM(E14:X14) -> 2662
D15: PR | E15: 114 | F15: 156 | G15: 148 | H15: 137 | I15: 143 | J15: 151 | K15: 148 | L15: 141 | M15: 135 | N15: 129 | O15: 129 | P15: 121 | Q15: 115 | R15: 147 | S15: 152 | T15: 132 | U15: 146 | V15: 149 | W15: 147 | X15: 144 | Y15: =SUM(E15:X15) -> 2784
D16: JML | E16: =SUM(E14:E15) -> 235 | F16: =SUM(F14:F15) -> 293 | G16: =SUM(G14:G15) -> 298 | H16: =SUM(H14:H15) -> 278 | I16: =SUM(I14:I15) -> 272 | J16: =SUM(J14:J15) -> 293 | K16: =SUM(K14:K15) -> 290 | L16: =SUM(L14:L15) -> 283 | ... X16: =SUM(X14:X15) -> 276 | Y16: =SUM(E16:X16) -> 5446
A18: B | B18: PENGGUNA HAK PILIH
B19: 1. | C19: Jumlah pengguna hak pilih dalam Daftar Pemilih Tetap (DPT) | D19: LK | E19: 98 | F19: 99 | G19: 122 | H19: 107 | I19: 94 | J19: 114 | K19: 107 | L19: 116 | M19: 97 | N19: 83 | O19: 89 | P19: 107 | Q19: 93 | R19: 96 | S19: 99 | T19: 75 | U19: 137 | V19: 107 | W19: 109 | X19: 101 | Y19: =SUM(E19:X19) -> 2050
D20: PR | E20: 102 | F20: 117 | G20: 109 | H20: 100 | I20: 110 | J20: 129 | K20: 123 | L20: 110 | M20: 112 | N20: 110 | O20: 116 | P20: 106 | Q20: 100 | R20: 118 | S20: 123 | T20: 94 | U20: 138 | V20: 124 | W20: 116 | X20: 114 | Y20: =SUM(E20:X20) -> 2271
D21: JML | E21: =SUM(E19:E20) -> 200 | F21: =SUM(F19:F20) -> 216 | G21: =SUM(G19:G20) -> 231 | H21: =SUM(H19:H20) -> 207 | I21: =SUM(I19:I20) -> 204 | J21: =SUM(J19:J20) -> 243 | K21: =SUM(K19:K20) -> 230 | L21: =SUM(L19:L20) -> 226 | ... X21: =SUM(X19:X20) -> 215 | Y21: =SUM(E21:X21) -> 4321
B22: 2. | C22: Jumlah pengguna hak pilih dalam Daftar Pemilih Tambahan (DPTb) | D22: LK | Y22: =SUM(E22:X22) -> 0
D23: PR | Y23: =SUM(E23:X23) -> 0
D24: JML | E24: =SUM(E22:E23) -> 0 | F24: =SUM(F22:F23) -> 0 | G24: =SUM(G22:G23) -> 0 | H24: =SUM(H22:H23) -> 0 | I24: =SUM(I22:I23) -> 0 | J24: =SUM(J22:J23) -> 0 | K24: =SUM(K22:K23) -> 0 | L24: =SUM(L22:L23) -> 0 | ... X24: =SUM(X22:X23) -> 0 | Y24: =SUM(E24:X24) -> 0
B25: 3. | C25: Jumlah pengguna hak pilih dalam Daftar Pemilih Khusus (DPK) | D25: LK | E25: 0 | F25: 0 | G25: 0 | H25: 0 | I25: 0 | J25: 0 | K25: 0 | L25: 0 | M25: 0 | N25: 0 | O25: 0 | P25: 0 | Q25: 0 | R25: 0 | S25: 0 | T25: 0 | U25: 1 | V25: 0 | W25: 0 | X25: 1 | Y25: =SUM(E25:X25) -> 2
D26: PR | E26: 0 | F26: 0 | G26: 0 | H26: 0 | I26: 0 | J26: 0 | K26: 0 | L26: 0 | M26: 0 | N26: 0 | O26: 0 | P26: 0 | Q26: 0 | R26: 0 | S26: 0 | T26: 0 | U26: 0 | V26: 0 | W26: 0 | X26: 1 | Y26: =SUM(E26:X26) -> 1
D27: JML | E27: =SUM(E25:E26) -> 0 | F27: =SUM(F25:F26) -> 0 | G27: =SUM(G25:G26) -> 0 | H27: =SUM(H25:H26) -> 0 | I27: =SUM(I25:I26) -> 0 | J27: =SUM(J25:J26) -> 0 | K27: =SUM(K25:K26) -> 0 | L27: =SUM(L25:L26) -> 0 | ... X27: =SUM(X25:X26) -> 2 | Y27: =SUM(E27:X27) -> 3
B28: 4. | C28: Jumlah Pengguna Hak Pilih (B.1+B.2+B.3) | D28: LK | E28: =SUM(E19,E22,E25) -> 98 | F28: =SUM(F19,F22,F25) -> 99 | G28: =SUM(G19,G22,G25) -> 122 | H28: =SUM(H19,H22,H25) -> 107 | I28: =SUM(I19,I22,I25) -> 94 | J28: =SUM(J19,J22,J25) -> 114 | K28: =SUM(K19,K22,K25) -> 107 | L28: =SUM(L19,L22,L25) -> 116 | ... X28: =SUM(X19,X22,X25) -> 102 | Y28: =SUM(E28:X28) -> 2052
D29: PR | E29: =SUM(E20,E23,E26) -> 102 | F29: =SUM(F20,F23,F26) -> 117 | G29: =SUM(G20,G23,G26) -> 109 | H29: =SUM(H20,H23,H26) -> 100 | I29: =SUM(I20,I23,I26) -> 110 | J29: =SUM(J20,J23,J26) -> 129 | K29: =SUM(K20,K23,K26) -> 123 | L29: =SUM(L20,L23,L26) -> 110 | ... X29: =SUM(X20,X23,X26) -> 115 | Y29: =SUM(E29:X29) -> 2272
D30: JML | E30: =SUM(E28:E29) -> 200 | F30: =SUM(F28:F29) -> 216 | G30: =SUM(G28:G29) -> 231 | H30: =SUM(H28:H29) -> 207 | I30: =SUM(I28:I29) -> 204 | J30: =SUM(J28:J29) -> 243 | K30: =SUM(K28:K29) -> 230 | L30: =SUM(L28:L29) -> 226 | ... X30: =SUM(X28:X29) -> 217 | Y30: =SUM(E30:X30) -> 4324
A32: II | B32: DATA PENGGUNAAN SURAT SUARA
A33: 1 | B33: Jumlah surat suara yang diterima, termasuk surat suara cadangan 2,5% dari DPT | E33: 240 | F33: 299 | G33: 304 | H33: 284 | I33: 277 | J33: 298 | K33: 296 | L33: 290 | M33: 274 | N33: 245 | O33: 255 | P33: 267 | Q33: 235 | R33: 287 | S33: 297 | T33: 248 | U33: 303 | V33: 294 | W33: 286 | X33: 282 | Y33: =SUM(E33:X33) -> 5561
A34: 2 | B34: Jumlah surat suara yang digunakan | E34: 200 | F34: 216 | G34: 231 | H34: 207 | I34: 204 | J34: 243 | K34: 230 | L34: 226 | M34: 209 | N34: 193 | O34: 205 | P34: 213 | Q34: 193 | R34: 214 | S34: 222 | T34: 169 | U34: 276 | V34: 231 | W34: 225 | X34: 217 | Y34: =SUM(E34:X34) -> 4324
A35: 3 | B35: Jumlah surat suara dikembalikan oleh pemilih (karena rusak atau keliru coblos) | E35: 0 | F35: 0 | G35: 1 | H35: 0 | I35: 0 | J35: 0 | K35: 0 | L35: 0 | M35: 0 | N35: 0 | O35: 0 | P35: 0 | Q35: 0 | R35: 0 | S35: 0 | T35: 0 | U35: 0 | V35: 1 | W35: 0 | X35: 0 | Y35: =SUM(E35:X35) -> 2
A36: 4 | B36: Jumlah surat suara yang tidak digunakan/tidak terpakai, termasuk sisa surat suara cadangan | E36: =E33-(E34+E35) -> 40 | F36: =F33-(F34+F35) -> 83 | G36: =G33-(G34+G35) -> 72 | H36: =H33-(H34+H35) -> 77 | I36: =I33-(I34+I35) -> 73 | J36: =J33-(J34+J35) -> 55 | K36: =K33-(K34+K35) -> 66 | L36: =L33-(L34+L35) -> 64 | ... X36: =X33-(X34+X35) -> 65 | Y36: =SUM(E36:X36) -> 1235
A38: III | B38: DATA PEMILIH DISABILITAS
B39: Jumlah seluruh Pemilih disabilitas yang menggunakan hak pilih | D39: LK | E39: 0 | F39: 0 | G39: 0 | H39: 0 | I39: 0 | J39: 0 | K39: 0 | L39: 0 | M39: 0 | N39: 0 | O39: 0 | P39: 0 | Q39: 0 | R39: 0 | S39: 0 | T39: 0 | U39: 0 | V39: 0 | W39: 0 | X39: 0 | Y39: =SUM(E39:X39) -> 0
D40: PR | E40: 0 | F40: 0 | G40: 0 | H40: 0 | I40: 0 | J40: 0 | K40: 0 | L40: 0 | M40: 0 | N40: 0 | O40: 1 | P40: 0 | Q40: 0 | R40: 0 | S40: 0 | T40: 0 | U40: 0 | V40: 0 | W40: 0 | X40: 0 | Y40: =SUM(E40:X40) -> 1
D41: JML | E41: =SUM(E39:E40) -> 0 | F41: =SUM(F39:F40) -> 0 | G41: =SUM(G39:G40) -> 0 | H41: =SUM(H39:H40) -> 0 | I41: =SUM(I39:I40) -> 0 | J41: =SUM(J39:J40) -> 0 | K41: =SUM(K39:K40) -> 0 | L41: =SUM(L39:L40) -> 0 | ... X41: =SUM(X39:X40) -> 0 | Y41: =SUM(E41:X41) -> 1
A43: IV | B43: DATA RINCIAN PEROLEHAN SUARA PASANGAN CALON BUPATI DAN WAKIL BUPATI
A44: NOMOR DAN NAMA CALON
A45: A.1 | B45: 1. | C45: Partai Kebangkitan Bangsa | E45: 1 | F45: 5 | G45: 2 | H45: 2 | I45: 1 | J45: 6 | K45: 3 | L45: 9 | M45: 10 | N45: 3 | O45: 13 | P45: 9 | Q45: 3 | R45: 9 | S45: 7 | T45: 3 | U45: 7 | V45: 10 | W45: 3 | X45: 9 | Y45: =SUM(E45:X45) -> 115
A46: A.2 | B46: 1 | C46: HJ. SITI MAKHROCHATIN NI’MAH, S.PD., M.M. | E46: 0 | F46: 2 | G46: 1 | H46: 4 | I46: 0 | J46: 1 | K46: 6 | L46: 2 | M46: 5 | N46: 2 | O46: 20 | P46: 11 | Q46: 9 | R46: 7 | S46: 3 | T46: 2 | U46: 19 | V46: 6 | W46: 8 | X46: 26 | Y46: =SUM(E46:X46) -> 134
B47: 2 | C47: A. TAUFIK | E47: 9 | F47: 25 | G47: 13 | H47: 10 | I47: 4 | J47: 5 | K47: 32 | L47: 24 | M47: 24 | N47: 25 | O47: 29 | P47: 28 | Q47: 10 | R47: 37 | S47: 30 | T47: 20 | U47: 6 | V47: 32 | W47: 19 | X47: 31 | Y47: =SUM(E47:X47) -> 413
B48: 3 | C48: KHOIRUL FAHMI ISKANDAR, S.PD | E48: 2 | F48: 1 | G48: 1 | H48: 1 | I48: 0 | J48: 0 | K48: 0 | L48: 0 | M48: 0 | N48: 2 | O48: 2 | P48: 3 | Q48: 0 | R48: 1 | S48: 0 | T48: 1 | U48: 0 | V48: 1 | W48: 0 | X48: 0 | Y48: =SUM(E48:X48) -> 15
B49: 4 | C49: AKHMAD, S.PD., M.M. | E49: 0 | F49: 0 | G49: 0 | H49: 0 | I49: 0 | J49: 2 | K49: 1 | L49: 0 | M49: 4 | N49: 4 | O49: 2 | P49: 1 | Q49: 1 | R49: 9 | S49: 3 | T49: 0 | U49: 0 | V49: 1 | W49: 0 | X49: 0 | Y49: =SUM(E49:X49) -> 28
B50: 5 | C50: SOFI WULANDARI, S.H. | E50: 0 | F50: 0 | G50: 0 | H50: 0 | I50: 0 | J50: 0 | K50: 0 | L50: 0 | M50: 0 | N50: 0 | O50: 0 | P50: 0 | Q50: 0 | R50: 0 | S50: 0 | T50: 0 | U50: 0 | V50: 0 | W50: 0 | X50: 0 | Y50: =SUM(E50:X50) -> 0
B51: 6 | C51: AL MA’ARIF | E51: 0 | F51: 0 | G51: 0 | H51: 0 | I51: 0 | J51: 0 | K51: 0 | L51: 0 | M51: 0 | N51: 0 | O51: 0 | P51: 0 | Q51: 0 | R51: 0 | S51: 0 | T51: 1 | U51: 0 | V51: 0 | W51: 0 | X51: 0 | Y51: =SUM(E51:X51) -> 1
...

Sheet ALASBULUH
C2: Kecamatan | D2: WONGSOREJO
C3: Kabupaten | D3: BANYUWANGI
C4: Provinsi | D4: JAWA TIMUR
C9: Kelurahan | D9: ALASBULUH
A12: I | B12: DATA PEMILIH DAN PENGGUNAAN HAK PILIH | AG12: JUMLAH AKHIR
A13: A | B13: DATA PEMILIH | E13: TPS 001 | F13: TPS 002 | G13: TPS 003 | H13: TPS 004 | I13: TPS 005 | J13: TPS 006 | K13: TPS 007 | L13: TPS 008 | M13: TPS 009 | N13: TPS 010 | O13: TPS 011 | P13: TPS 012 | Q13: TPS 013 | R13: TPS 014 | S13: TPS 015 | T13: TPS 016 | U13: TPS 017 | V13: TPS 018 | W13: TPS 019 | X13: TPS 020 | Y13: TPS 021 | Z13: TPS 022 | AA13: TPS 023 | AB13: TPS 024 | AC13: TPS 025 | AD13: TPS 026 | AE13: TPS 027 | AF13: TPS 028
B14: Jumlah Pemilih dalam Daftar Pemilih Tetap (DPT) | D14: LK | E14: 152 | F14: 132 | G14: 152 | H14: 172 | I14: 136 | J14: 167 | K14: 143 | L14: 151 | M14: 160 | N14: 142 | O14: 147 | P14: 140 | Q14: 116 | R14: 134 | S14: 135 | T14: 154 | U14: 129 | V14: 155 | W14: 147 | X14: 147 | Y14: 128 | Z14: 123 | AA14: 151 | AB14: 115 | AC14: 135 | AD14: 141 | AE14: 118 | AF14: 124 | AG14: =SUM(E14:AF14) -> 3946
D15: PR | E15: 145 | F15: 168 | G15: 145 | H15: 127 | I15: 163 | J15: 130 | K15: 156 | L15: 148 | M15: 139 | N15: 157 | O15: 139 | P15: 154 | Q15: 126 | R15: 151 | S15: 145 | T15: 143 | U15: 133 | V15: 142 | W15: 152 | X15: 153 | Y15: 141 | Z15: 120 | AA15: 149 | AB15: 100 | AC15: 145 | AD15: 137 | AE15: 120 | AF15: 141 | AG15: =SUM(E15:AF15) -> 3969
D16: JML | E16: =SUM(E14:E15) -> 297 | F16: =SUM(F14:F15) -> 300 | G16: =SUM(G14:G15) -> 297 | H16: =SUM(H14:H15) -> 299 | I16: =SUM(I14:I15) -> 299 | J16: =SUM(J14:J15) -> 297 | K16: =SUM(K14:K15) -> 299 | L16: =SUM(L14:L15) -> 299 | ... AF16: =SUM(AF14:AF15) -> 265 | AG16: =SUM(E16:AF16) -> 7915
A18: B | B18: PENGGUNA HAK PILIH
B19: 1. | C19: Jumlah pengguna hak pilih dalam Daftar Pemilih Tetap (DPT) | D19: LK | E19: 109 | F19: 86 | G19: 113 | H19: 126 | I19: 83 | J19: 116 | K19: 93 | L19: 97 | M19: 125 | N19: 109 | O19: 111 | P19: 118 | Q19: 85 | R19: 101 | S19: 97 | T19: 98 | U19: 99 | V19: 104 | W19: 93 | X19: 124 | Y19: 104 | Z19: 89 | AA19: 101 | AB19: 92 | AC19: 113 | AD19: 104 | AE19: 101 | AF19: 85 | AG19: =SUM(E19:AF19) -> 2876
D20: PR | E20: 106 | F20: 120 | G20: 99 | H20: 104 | I20: 137 | J20: 101 | K20: 110 | L20: 127 | M20: 122 | N20: 137 | O20: 109 | P20: 126 | Q20: 94 | R20: 115 | S20: 101 | T20: 92 | U20: 98 | V20: 98 | W20: 117 | X20: 124 | Y20: 110 | Z20: 92 | AA20: 115 | AB20: 87 | AC20: 120 | AD20: 122 | AE20: 97 | AF20: 102 | AG20: =SUM(E20:AF20) -> 3082
D21: JML | E21: =SUM(E19:E20) -> 215 | F21: =SUM(F19:F20) -> 206 | G21: =SUM(G19:G20) -> 212 | H21: =SUM(H19:H20) -> 230 | I21: =SUM(I19:I20) -> 220 | J21: =SUM(J19:J20) -> 217 | K21: =SUM(K19:K20) -> 203 | L21: =SUM(L19:L20) -> 224 | ... AF21: =SUM(AF19:AF20) -> 187 | AG21: =SUM(E21:AF21) -> 5958
B22: 2. | C22: Jumlah pengguna hak pilih dalam Daftar Pemilih Tambahan (DPTb) | D22: LK | E22: 0 | F22: 1 | G22: 0 | H22: 0 | I22: 0 | J22: 0 | K22: 1 | L22: 0 | M22: 0 | N22: 0 | O22: 0 | P22: 0 | Q22: 0 | R22: 0 | S22: 0 | T22: 0 | U22: 0 | V22: 0 | W22: 0 | X22: 0 | Y22: 0 | Z22: 0 | AA22: 0 | AB22: 0 | AC22: 0 | AD22: 0 | AE22: 1 | AF22: 0 | AG22: =SUM(E22:AF22) -> 3
D23: PR | E23: 0 | F23: 1 | G23: 0 | H23: 0 | I23: 0 | J23: 0 | K23: 0 | L23: 0 | M23: 0 | N23: 0 | O23: 0 | P23: 0 | Q23: 0 | R23: 0 | S23: 0 | T23: 0 | U23: 0 | V23: 0 | W23: 0 | X23: 0 | Y23: 0 | Z23: 0 | AA23: 0 | AB23: 0 | AC23: 0 | AD23: 0 | AE23: 0 | AF23: 0 | AG23: =SUM(E23:AF23) -> 1
D24: JML | E24: =SUM(E22:E23) -> 0 | F24: =SUM(F22:F23) -> 2 | G24: =SUM(G22:G23) -> 0 | H24: =SUM(H22:H23) -> 0 | I24: =SUM(I22:I23) -> 0 | J24: =SUM(J22:J23) -> 0 | K24: =SUM(K22:K23) -> 1 | L24: =SUM(L22:L23) -> 0 | ... AF24: =SUM(AF22:AF23) -> 0 | AG24: =SUM(E24:AF24) -> 4
B25: 3. | C25: Jumlah pengguna hak pilih dalam Daftar Pemilih Khusus (DPK) | D25: LK | E25: 0 | F25: 0 | G25: 0 | H25: 0 | I25: 0 | J25: 0 | K25: 0 | L25: 0 | M25: 0 | N25: 0 | O25: 0 | P25: 0 | Q25: 1 | R25: 0 | S25: 0 | T25: 0 | U25: 0 | V25: 0 | W25: 0 | X25: 0 | Y25: 6 | Z25: 0 | AA25: 0 | AB25: 0 | AC25: 0 | AD25: 0 | AE25: 0 | AF25: 8 | AG25: =SUM(E25:AF25) -> 15
D26: PR | E26: 0 | F26: 0 | G26: 0 | H26: 0 | I26: 0 | J26: 0 | K26: 0 | L26: 0 | M26: 0 | N26: 0 | O26: 0 | P26: 0 | Q26: 2 | R26: 0 | S26: 0 | T26: 0 | U26: 0 | V26: 0 | W26: 0 | X26: 0 | Y26: 10 | Z26: 0 | AA26: 0 | AB26: 0 | AC26: 0 | AD26: 0 | AE26: 0 | AF26: 6 | AG26: =SUM(E26:AF26) -> 18
D27: JML | E27: =SUM(E25:E26) -> 0 | F27: =SUM(F25:F26) -> 0 | G27: =SUM(G25:G26) -> 0 | H27: =SUM(H25:H26) -> 0 | I27: =SUM(I25:I26) -> 0 | J27: =SUM(J25:J26) -> 0 | K27: =SUM(K25:K26) -> 0 | L27: =SUM(L25:L26) -> 0 | ... AF27: =SUM(AF25:AF26) -> 14 | AG27: =SUM(E27:AF27) -> 33
B28: 4. | C28: Jumlah Pengguna Hak Pilih (B.1+B.2+B.3) | D28: LK | E28: =SUM(E19,E22,E25) -> 109 | F28: =SUM(F19,F22,F25) -> 87 | G28: =SUM(G19,G22,G25) -> 113 | H28: =SUM(H19,H22,H25) -> 126 | I28: =SUM(I19,I22,I25) -> 83 | J28: =SUM(J19,J22,J25) -> 116 | K28: =SUM(K19,K22,K25) -> 94 | L28: =SUM(L19,L22,L25) -> 97 | ... AF28: =SUM(AF19,AF22,AF25) -> 93 | AG28: =SUM(E28:AF28) -> 2894
D29: PR | E29: =SUM(E20,E23,E26) -> 106 | F29: =SUM(F20,F23,F26) -> 121 | G29: =SUM(G20,G23,G26) -> 99 | H29: =SUM(H20,H23,H26) -> 104 | I29: =SUM(I20,I23,I26) -> 137 | J29: =SUM(J20,J23,J26) -> 101 | K29: =SUM(K20,K23,K26) -> 110 | L29: =SUM(L20,L23,L26) -> 127 | ... AF29: =SUM(AF20,AF23,AF26) -> 108 | AG29: =SUM(E29:AF29) -> 3101
D30: JML | E30: =SUM(E28:E29) -> 215 | F30: =SUM(F28:F29) -> 208 | G30: =SUM(G28:G29) -> 212 | H30: =SUM(H28:H29) -> 230 | I30: =SUM(I28:I29) -> 220 | J30: =SUM(J28:J29) -> 217 | K30: =SUM(K28:K29) -> 204 | L30: =SUM(L28:L29) -> 224 | ... AF30: =SUM(AF28:AF29) -> 201 | AG30: =SUM(E30:AF30) -> 5995
A32: II | B32: DATA PENGGUNAAN SURAT SUARA
A33: 1 | B33: Jumlah surat suara yang diterima, termasuk surat suara cadangan 2,5% dari DPT | E33: 303 | F33: 306 | G33: 303 | H33: 305 | I33: 305 | J33: 303 | K33: 305 | L33: 305 | M33: 305 | N33: 305 | O33: 292 | P33: 300 | Q33: 247 | R33: 291 | S33: 286 | T33: 303 | U33: 268 | V33: 303 | W33: 304 | X33: 306 | Y33: 275 | Z33: 248 | AA33: 306 | AB33: 220 | AC33: 286 | AD33: 284 | AE33: 243 | AF33: 269 | AG33: =SUM(E33:AF33) -> 8076
A34: 2 | B34: Jumlah surat suara yang digunakan | E34: 215 | F34: 208 | G34: 212 | H34: 230 | I34: 220 | J34: 217 | K34: 204 | L34: 224 | M34: 247 | N34: 246 | O34: 220 | P34: 244 | Q34: 182 | R34: 216 | S34: 198 | T34: 190 | U34: 197 | V34: 202 | W34: 210 | X34: 248 | Y34: 230 | Z34: 181 | AA34: 216 | AB34: 179 | AC34: 233 | AD34: 226 | AE34: 199 | AF34: 201 | AG34: =SUM(E34:AF34) -> 5995
A35: 3 | B35: Jumlah surat suara dikembalikan oleh pemilih (karena rusak atau keliru coblos) | E35: 0 | F35: 0 | G35: 0 | H35: 0 | I35: 0 | J35: 1 | K35: 3 | L35: 0 | M35: 0 | N35: 1 | O35: 0 | P35: 0 | Q35: 0 | R35: 0 | S35: 0 | T35: 0 | U35: 0 | V35: 0 | W35: 0 | X35: 0 | Y35: 0 | Z35: 0 | AA35: 0 | AB35: 0 | AC35: 4 | AD35: 1 | AE35: 0 | AF35: 0 | AG35: =SUM(E35:AF35) -> 10
A36: 4 | B36: Jumlah surat suara yang tidak digunakan/tidak terpakai, termasuk sisa surat suara cadangan | E36: =E33-(E34+E35) -> 88 | F36: =F33-(F34+F35) -> 98 | G36: =G33-(G34+G35) -> 91 | H36: =H33-(H34+H35) -> 75 | I36: =I33-(I34+I35) -> 85 | J36: =J33-(J34+J35) -> 85 | K36: =K33-(K34+K35) -> 98 | L36: =L33-(L34+L35) -> 81 | ... AF36: =AF33-(AF34+AF35) -> 68 | AG36: =SUM(E36:AF36) -> 2071
A38: III | B38: DATA PEMILIH DISABILITAS
B39: Jumlah seluruh Pemilih disabilitas yang menggunakan hak pilih | D39: LK | AG39: =SUM(E39:AF39) -> 0
D40: PR | E40: 0 | F40: 0 | G40: 0 | H40: 0 | I40: 0 | J40: 0 | K40: 0 | L40: 0 | M40: 0 | N40: 0 | O40: 0 | P40: 0 | Q40: 0 | R40: 0 | S40: 0 | T40: 0 | U40: 0 | V40: 0 | W40: 0 | X40: 0 | Y40: 0 | Z40: 0 | AA40: 2 | AB40: 0 | AC40: 0 | AD40: 0 | AE40: 0 | AF40: 0 | AG40: =SUM(E40:AF40) -> 2
D41: JML | E41: =SUM(E39:E40) -> 0 | F41: =SUM(F39:F40) -> 0 | G41: =SUM(G39:G40) -> 0 | H41: =SUM(H39:H40) -> 0 | I41: =SUM(I39:I40) -> 0 | J41: =SUM(J39:J40) -> 0 | K41: =SUM(K39:K40) -> 0 | L41: =SUM(L39:L40) -> 0 | ... AF41: =SUM(AF39:AF40) -> 0 | AG41: =SUM(E41:AF41) -> 2
A43: IV | B43: DATA RINCIAN PEROLEHAN SUARA PASANGAN CALON BUPATI DAN WAKIL BUPATI
A44: NOMOR DAN NAMA CALON
A45: A.1 | B45: 1. | C45: Partai Kebangkitan Bangsa | E45: 11 | F45: 4 | G45: 8 | H45: 6 | I45: 17 | J45: 5 | K45: 19 | L45: 14 | M45: 12 | N45: 8 | O45: 11 | P45: 15 | Q45: 10 | R45: 7 | S45: 5 | T45: 11 | U45: 11 | V45: 20 | W45: 13 | X45: 22 | Y45: 11 | Z45: 20 | AA45: 15 | AB45: 1 | AC45: 4 | AD45: 7 | AE45: 4 | AF45: 15 | AG45: =SUM(E45:AF45) -> 306
A46: A.2 | B46: 1 | C46: HJ. SITI MAKHROCHATIN NI’MAH, S.PD., M.M. | E46: 20 | F46: 4 | G46: 6 | H46: 2 | I46: 8 | J46: 4 | K46: 13 | L46: 17 | M46: 7 | N46: 4 | O46: 5 | P46: 11 | Q46: 3 | R46: 2 | S46: 5 | T46: 1 | U46: 12 | V46: 5 | W46: 3 | X46: 7 | Y46: 5 | Z46: 5 | AA46: 2 | AB46: 7 | AC46: 4 | AD46: 4 | AE46: 4 | AF46: 19 | AG46: =SUM(E46:AF46) -> 189
B47: 2 | C47: A. TAUFIK | E47: 19 | F47: 21 | G47: 17 | H47: 8 | I47: 25 | J47: 21 | K47: 6 | L47: 13 | M47: 117 | N47: 88 | O47: 35 | P47: 61 | Q47: 8 | R47: 26 | S47: 51 | T47: 34 | U47: 25 | V47: 51 | W47: 49 | X47: 29 | Y47: 13 | Z47: 24 | AA47: 7 | AB47: 5 | AC47: 47 | AD47: 79 | AE47: 85 | AF47: 30 | AG47: =SUM(E47:AF47) -> 994
B48: 3 | C48: KHOIRUL FAHMI ISKANDAR, S.PD | E48: 1 | F48: 1 | G48: 1 | H48: 0 | I48: 1 | J48: 3 | K48: 1 | L48: 3 | M48: 0 | N48: 1 | O48: 1 | P48: 1 | Q48: 0 | R48: 0 | S48: 4 | T48: 1 | U48: 1 | V48: 2 | W48: 0 | X48: 1 | Y48: 0 | Z48: 0 | AA48: 1 | AB48: 0 | AC48: 1 | AD48: 1 | AE48: 0 | AF48: 0 | AG48: =SUM(E48:AF48) -> 26
B49: 4 | C49: AKHMAD, S.PD., M.M. | E49: 4 | F49: 4 | G49: 4 | H49: 4 | I49: 1 | J49: 12 | K49: 2 | L49: 8 | M49: 0 | N49: 0 | O49: 1 | P49: 2 | Q49: 0 | R49: 0 | S49: 1 | T49: 2 | U49: 3 | V49: 1 | W49: 2 | X49: 0 | Y49: 0 | Z49: 3 | AA49: 0 | AB49: 1 | AC49: 1 | AD49: 0 | AE49: 0 | AF49: 1 | AG49: =SUM(E49:AF49) -> 57
B50: 5 | C50: SOFI WULANDARI, S.H. | E50: 0 | F50: 0 | G50: 0 | H50: 0 | I50: 0 | J50: 0 | K50: 0 | L50: 0 | M50: 0 | N50: 0 | O50: 0 | P50: 1 | Q50: 0 | R50: 0 | S50: 0 | T50: 0 | U50: 0 | V50: 0 | W50: 0 | X50: 0 | Y50: 0 | Z50: 1 | AA50: 0 | AB50: 0 | AC50: 0 | AD50: 1 | AE50: 0 | AF50: 0 | AG50: =SUM(E50:AF50) -> 3
B51: 6 | C51: AL MA’ARIF | E51: 0 | F51: 0 | G51: 0 | H51: 0 | I51: 0 | J51: 0 | K51: 1 | L51: 0 | M51: 1 | N51: 0 | O51: 0 | P51: 0 | Q51: 0 | R51: 0 | S51: 0 | T51: 0 | U51: 0 | V51: 0 | W51: 0 | X51: 0 | Y51: 0 | Z51: 0 | AA51: 0 | AB51: 0 | AC51: 0 | AD51: 1 | AE51: 1 | AF51: 1 | AG51: =SUM(E51:AF51) -> 5
...

Sheet WONGSOREJO
C2: Kecamatan | D2: WONGSOREJO
C3: Kabupaten | D3: BANYUWANGI
C4: Provinsi | D4: JAWA TIMUR
C9: Kelurahan | D9: WONGSOREJO
A12: I | B12: DATA PEMILIH DAN PENGGUNAAN HAK PILIH | AM12: JUMLAH AKHIR
A13: A | B13: DATA PEMILIH | E13: TPS 001 | F13: TPS 002 | G13: TPS 003 | H13: TPS 004 | I13: TPS 005 | J13: TPS 006 | K13: TPS 007 | L13: TPS 008 | M13: TPS 009 | N13: TPS 010 | O13: TPS 011 | P13: TPS 012 | Q13: TPS 013 | R13: TPS 014 | S13: TPS 015 | T13: TPS 016 | U13: TPS 017 | V13: TPS 018 | W13: TPS 019 | X13: TPS 020 | Y13: TPS 021 | Z13: TPS 022 | AA13: TPS 023 | AB13: TPS 024 | AC13: TPS 025 | AD13: TPS 026 | AE13: TPS 027 | AF13: TPS 028 | AG13: TPS 029 | AH13: TPS 030 | AI13: TPS 031 | AJ13: TPS 032 | AK13: TPS 033 | AL13: TPS 034
B14: Jumlah Pemilih dalam Daftar Pemilih Tetap (DPT) | D14: LK | E14: 119 | F14: 124 | G14: 138 | H14: 131 | I14: 132 | J14: 132 | K14: 122 | L14: 113 | M14: 135 | N14: 124 | O14: 121 | P14: 123 | Q14: 132 | R14: 132 | S14: 144 | T14: 130 | U14: 123 | V14: 132 | W14: 120 | X14: 125 | Y14: 90 | Z14: 116 | AA14: 127 | AB14: 120 | AC14: 118 | AD14: 139 | AE14: 119 | AF14: 114 | AG14: 137 | AH14: 116 | AI14: 141 | AJ14: 117 | AK14: 101 | AL14: 106 | AM14: =SUM(E14:AL14) -> 4213
D15: PR | E15: 124 | F15: 149 | G15: 136 | H15: 131 | I15: 132 | J15: 139 | K15: 148 | L15: 115 | M15: 134 | N15: 119 | O15: 130 | P15: 131 | Q15: 138 | R15: 128 | S15: 142 | T15: 134 | U15: 125 | V15: 146 | W15: 131 | X15: 124 | Y15: 107 | Z15: 146 | AA15: 142 | AB15: 138 | AC15: 130 | AD15: 138 | AE15: 122 | AF15: 115 | AG15: 138 | AH15: 110 | AI15: 135 | AJ15: 115 | AK15: 111 | AL15: 101 | AM15: =SUM(E15:AL15) -> 4404
D16: JML | E16: =SUM(E14:E15) -> 243 | F16: =SUM(F14:F15) -> 273 | G16: =SUM(G14:G15) -> 274 | H16: =SUM(H14:H15) -> 262 | I16: =SUM(I14:I15) -> 264 | J16: =SUM(J14:J15) -> 271 | K16: =SUM(K14:K15) -> 270 | L16: =SUM(L14:L15) -> 228 | ... AL16: =SUM(AL14:AL15) -> 207 | AM16: =SUM(E16:AL16) -> 8617
A18: B | B18: PENGGUNA HAK PILIH
B19: 1. | C19: Jumlah pengguna hak pilih dalam Daftar Pemilih Tetap (DPT) | D19: LK | E19: 82 | F19: 86 | G19: 111 | H19: 92 | I19: 98 | J19: 93 | K19: 94 | L19: 90 | M19: 94 | N19: 97 | O19: 90 | P19: 97 | Q19: 109 | R19: 97 | S19: 118 | T19: 100 | U19: 89 | V19: 105 | W19: 81 | X19: 88 | Y19: 58 | Z19: 85 | AA19: 99 | AB19: 105 | AC19: 88 | AD19: 100 | AE19: 83 | AF19: 89 | AG19: 96 | AH19: 81 | AI19: 92 | AJ19: 103 | AK19: 74 | AL19: 79 | AM19: =SUM(E19:AL19) -> 3143
D20: PR | E20: 93 | F20: 102 | G20: 111 | H20: 123 | I20: 112 | J20: 118 | K20: 117 | L20: 96 | M20: 107 | N20: 100 | O20: 102 | P20: 102 | Q20: 118 | R20: 106 | S20: 121 | T20: 106 | U20: 93 | V20: 116 | W20: 94 | X20: 91 | Y20: 79 | Z20: 109 | AA20: 105 | AB20: 118 | AC20: 99 | AD20: 113 | AE20: 84 | AF20: 87 | AG20: 109 | AH20: 76 | AI20: 80 | AJ20: 100 | AK20: 83 | AL20: 73 | AM20: =SUM(E20:AL20) -> 3443
D21: JML | E21: =SUM(E19:E20) -> 175 | F21: =SUM(F19:F20) -> 188 | G21: =SUM(G19:G20) -> 222 | H21: =SUM(H19:H20) -> 215 | I21: =SUM(I19:I20) -> 210 | J21: =SUM(J19:J20) -> 211 | K21: =SUM(K19:K20) -> 211 | L21: =SUM(L19:L20) -> 186 | ... AL21: =SUM(AL19:AL20) -> 152 | AM21: =SUM(E21:AL21) -> 6586
B22: 2. | C22: Jumlah pengguna hak pilih dalam Daftar Pemilih Tambahan (DPTb) | D22: LK | E22: 0 | F22: 0 | G22: 0 | H22: 0 | I22: 0 | J22: 0 | K22: 0 | L22: 0 | M22: 0 | N22: 0 | O22: 0 | P22: 1 | Q22: 0 | R22: 0 | S22: 0 | T22: 0 | U22: 0 | V22: 0 | W22: 0 | X22: 0 | Y22: 0 | Z22: 0 | AA22: 0 | AB22: 0 | AC22: 0 | AD22: 0 | AE22: 1 | AF22: 1 | AG22: 4 | AH22: 3 | AI22: 0 | AJ22: 1 | AK22: 4 | AL22: 0 | AM22: =SUM(E22:AL22) -> 15
D23: PR | E23: 0 | F23: 0 | G23: 0 | H23: 0 | I23: 0 | J23: 0 | K23: 0 | L23: 0 | M23: 0 | N23: 1 | O23: 0 | P23: 1 | Q23: 0 | R23: 0 | S23: 0 | T23: 0 | U23: 0 | V23: 0 | W23: 0 | X23: 0 | Y23: 0 | Z23: 1 | AA23: 1 | AB23: 0 | AC23: 1 | AD23: 1 | AE23: 2 | AF23: 0 | AG23: 0 | AH23: 2 | AI23: 0 | AJ23: 0 | AK23: 1 | AL23: 0 | AM23: =SUM(E23:AL23) -> 11
D24: JML | E24: =SUM(E22:E23) -> 0 | F24: =SUM(F22:F23) -> 0 | G24: =SUM(G22:G23) -> 0 | H24: =SUM(H22:H23) -> 0 | I24: =SUM(I22:I23) -> 0 | J24: =SUM(J22:J23) -> 0 | K24: =SUM(K22:K23) -> 0 | L24: =SUM(L22:L23) -> 0 | ... AL24: =SUM(AL22:AL23) -> 0 | AM24: =SUM(E24:AL24) -> 26
B25: 3. | C25: Jumlah pengguna hak pilih dalam Daftar Pemilih Khusus (DPK) | D25: LK | E25: 1 | F25: 2 | G25: 0 | H25: 5 | I25: 0 | J25: 0 | K25: 0 | L25: 0 | M25: 0 | N25: 0 | O25: 0 | P25: 2 | Q25: 0 | R25: 0 | S25: 0 | T25: 0 | U25: 0 | V25: 1 | W25: 0 | X25: 1 | Y25: 0 | Z25: 1 | AA25: 1 | AB25: 2 | AC25: 3 | AD25: 1 | AE25: 0 | AF25: 0 | AG25: 1 | AH25: 0 | AI25: 4 | AJ25: 1 | AK25: 0 | AL25: 0 | AM25: =SUM(E25:AL25) -> 26
D26: PR | E26: 2 | F26: 1 | G26: 0 | H26: 4 | I26: 0 | J26: 3 | K26: 0 | L26: 0 | M26: 0 | N26: 0 | O26: 0 | P26: 0 | Q26: 0 | R26: 0 | S26: 0 | T26: 0 | U26: 0 | V26: 3 | W26: 0 | X26: 2 | Y26: 1 | Z26: 1 | AA26: 1 | AB26: 1 | AC26: 1 | AD26: 3 | AE26: 0 | AF26: 0 | AG26: 1 | AH26: 0 | AI26: 2 | AJ26: 1 | AK26: 0 | AL26: 0 | AM26: =SUM(E26:AL26) -> 27
D27: JML | E27: =SUM(E25:E26) -> 3 | F27: =SUM(F25:F26) -> 3 | G27: =SUM(G25:G26) -> 0 | H27: =SUM(H25:H26) -> 9 | I27: =SUM(I25:I26) -> 0 | J27: =SUM(J25:J26) -> 3 | K27: =SUM(K25:K26) -> 0 | L27: =SUM(L25:L26) -> 0 | ... AL27: =SUM(AL25:AL26) -> 0 | AM27: =SUM(E27:AL27) -> 53
B28: 4. | C28: Jumlah Pengguna Hak Pilih (B.1+B.2+B.3) | D28: LK | E28: =SUM(E19,E22,E25) -> 83 | F28: =SUM(F19,F22,F25) -> 88 | G28: =SUM(G19,G22,G25) -> 111 | H28: =SUM(H19,H22,H25) -> 97 | I28: =SUM(I19,I22,I25) -> 98 | J28: =SUM(J19,J22,J25) -> 93 | K28: =SUM(K19,K22,K25) -> 94 | L28: =SUM(L19,L22,L25) -> 90 | ... AL28: =SUM(AL19,AL22,AL25) -> 79 | AM28: =SUM(E28:AL28) -> 3184
D29: PR | E29: =SUM(E20,E23,E26) -> 95 | F29: =SUM(F20,F23,F26) -> 103 | G29: =SUM(G20,G23,G26) -> 111 | H29: =SUM(H20,H23,H26) -> 127 | I29: =SUM(I20,I23,I26) -> 112 | J29: =SUM(J20,J23,J26) -> 121 | K29: =SUM(K20,K23,K26) -> 117 | L29: =SUM(L20,L23,L26) -> 96 | ... AL29: =SUM(AL20,AL23,AL26) -> 73 | AM29: =SUM(E29:AL29) -> 3481
D30: JML | E30: =SUM(E28:E29) -> 178 | F30: =SUM(F28:F29) -> 191 | G30: =SUM(G28:G29) -> 222 | H30: =SUM(H28:H29) -> 224 | I30: =SUM(I28:I29) -> 210 | J30: =SUM(J28:J29) -> 214 | K30: =SUM(K28:K29) -> 211 | L30: =SUM(L28:L29) -> 186 | ... AL30: =SUM(AL28:AL29) -> 152 | AM30: =SUM(E30:AL30) -> 6665
A32: II | B32: DATA PENGGUNAAN SURAT SUARA
A33: 1 | B33: Jumlah surat suara yang diterima, termasuk surat suara cadangan 2,5% dari DPT | E33: 248 | F33: 279 | G33: 280 | H33: 264 | I33: 270 | J33: 277 | K33: 276 | L33: 233 | M33: 275 | N33: 248 | O33: 257 | P33: 260 | Q33: 276 | R33: 266 | S33: 292 | T33: 270 | U33: 253 | V33: 284 | W33: 257 | X33: 254 | Y33: 197 | Z33: 268 | AA33: 275 | AB33: 264 | AC33: 253 | AD33: 283 | AE33: 246 | AF33: 234 | AG33: 281 | AH33: 231 | AI33: 282 | AJ33: 237 | AK33: 217 | AL33: 212 | AM33: =SUM(E33:AL33) -> 8799
A34: 2 | B34: Jumlah surat suara yang digunakan | E34: 178 | F34: 191 | G34: 222 | H34: 224 | I34: 210 | J34: 214 | K34: 211 | L34: 186 | M34: 201 | N34: 198 | O34: 192 | P34: 203 | Q34: 227 | R34: 203 | S34: 239 | T34: 206 | U34: 182 | V34: 225 | W34: 175 | X34: 182 | Y34: 138 | Z34: 197 | AA34: 207 | AB34: 226 | AC34: 192 | AD34: 218 | AE34: 170 | AF34: 177 | AG34: 211 | AH34: 162 | AI34: 178 | AJ34: 206 | AK34: 162 | AL34: 152 | AM34: =SUM(E34:AL34) -> 6665
A35: 3 | B35: Jumlah surat suara dikembalikan oleh pemilih (karena rusak atau keliru coblos) | E35: 2 | F35: 2 | G35: 2 | H35: 0 | I35: 1 | J35: 1 | K35: 0 | L35: 0 | M35: 0 | N35: 0 | O35: 0 | P35: 0 | Q35: 0 | R35: 0 | S35: 0 | T35: 0 | U35: 7 | V35: 2 | W35: 1 | X35: 0 | Y35: 0 | Z35: 0 | AA35: 1 | AB35: 0 | AC35: 0 | AD35: 0 | AE35: 0 | AF35: 0 | AG35: 0 | AH35: 0 | AI35: 0 | AJ35: 0 | AK35: 0 | AL35: 0 | AM35: =SUM(E35:AL35) -> 19
A36: 4 | B36: Jumlah surat suara yang tidak digunakan/tidak terpakai, termasuk sisa surat suara cadangan | E36: =E33-(E34+E35) -> 68 | F36: =F33-(F34+F35) -> 86 | G36: =G33-(G34+G35) -> 56 | H36: =H33-(H34+H35) -> 40 | I36: =I33-(I34+I35) -> 59 | J36: =J33-(J34+J35) -> 62 | K36: =K33-(K34+K35) -> 65 | L36: =L33-(L34+L35) -> 47 | ... AL36: =AL33-(AL34+AL35) -> 60 | AM36: =SUM(E36:AL36) -> 2115
A38: III | B38: DATA PEMILIH DISABILITAS
B39: Jumlah seluruh Pemilih disabilitas yang menggunakan hak pilih | D39: LK | E39: 0 | F39: 0 | G39: 0 | H39: 2 | I39: 0 | J39: 0 | K39: 0 | L39: 0 | M39: 0 | N39: 0 | O39: 0 | P39: 0 | Q39: 0 | R39: 0 | S39: 0 | T39: 0 | U39: 0 | V39: 0 | W39: 0 | X39: 0 | Y39: 0 | Z39: 0 | AA39: 0 | AB39: 0 | AC39: 0 | AD39: 0 | AE39: 0 | AF39: 0 | AG39: 0 | AH39: 0 | AI39: 0 | AJ39: 0 | AK39: 0 | AL39: 0 | AM39: =SUM(E39:AL39) -> 2
D40: PR | E40: 0 | F40: 0 | G40: 0 | H40: 0 | I40: 0 | J40: 0 | K40: 0 | L40: 0 | M40: 0 | N40: 0 | O40: 0 | P40: 0 | Q40: 0 | R40: 0 | S40: 0 | T40: 0 | U40: 0 | V40: 0 | W40: 0 | X40: 0 | Y40: 0 | Z40: 0 | AA40: 1 | AB40: 0 | AC40: 0 | AD40: 0 | AE40: 0 | AF40: 0 | AG40: 1 | AH40: 0 | AI40: 0 | AJ40: 0 | AK40: 0 | AL40: 0 | AM40: =SUM(E40:AL40) -> 2
D41: JML | E41: =SUM(E39:E40) -> 0 | F41: =SUM(F39:F40) -> 0 | G41: =SUM(G39:G40) -> 0 | H41: =SUM(H39:H40) -> 2 | I41: =SUM(I39:I40) -> 0 | J41: =SUM(J39:J40) -> 0 | K41: =SUM(K39:K40) -> 0 | L41: =SUM(L39:L40) -> 0 | ... AL41: =SUM(AL39:AL40) -> 0 | AM41: =SUM(E41:AL41) -> 4
A43: IV | B43: DATA RINCIAN PEROLEHAN SUARA PASANGAN CALON BUPATI DAN WAKIL BUPATI
A44: NOMOR DAN NAMA CALON
A45: A.1 | B45: 1. | C45: Partai Kebangkitan Bangsa | E45: 18 | F45: 8 | G45: 3 | H45: 11 | I45: 7 | J45: 3 | K45: 2 | L45: 15 | M45: 3 | N45: 14 | O45: 13 | P45: 15 | Q45: 7 | R45: 12 | S45: 7 | T45: 9 | U45: 8 | V45: 5 | W45: 4 | X45: 13 | Y45: 7 | Z45: 8 | AA45: 11 | AB45: 5 | AC45: 5 | AD45: 5 | AE45: 14 | AF45: 8 | AG45: 19 | AH45: 16 | AI45: 10 | AJ45: 1 | AK45: 4 | AL45: 5 | AM45: =SUM(E45:AL45) -> 295
A46: A.2 | B46: 1 | C46: HJ. SITI MAKHROCHATIN NI’MAH, S.PD., M.M. | E46: 6 | F46: 6 | G46: 6 | H46: 7 | I46: 3 | J46: 0 | K46: 3 | L46: 2 | M46: 3 | N46: 4 | O46: 9 | P46: 3 | Q46: 8 | R46: 5 | S46: 2 | T46: 2 | U46: 4 | V46: 4 | W46: 3 | X46: 6 | Y46: 4 | Z46: 6 | AA46: 7 | AB46: 1 | AC46: 2 | AD46: 5 | AE46: 17 | AF46: 3 | AG46: 6 | AH46: 8 | AI46: 3 | AJ46: 5 | AK46: 2 | AL46: 1 | AM46: =SUM(E46:AL46) -> 156
B47: 2 | C47: A. TAUFIK | E47: 36 | F47: 39 | G47: 37 | H47: 54 | I47: 45 | J47: 39 | K47: 37 | L47: 33 | M47: 37 | N47: 31 | O47: 22 | P47: 57 | Q47: 32 | R47: 16 | S47: 21 | T47: 38 | U47: 48 | V47: 46 | W47: 28 | X47: 31 | Y47: 25 | Z47: 35 | AA47: 68 | AB47: 132 | AC47: 101 | AD47: 55 | AE47: 33 | AF47: 59 | AG47: 72 | AH47: 34 | AI47: 23 | AJ47: 59 | AK47: 15 | AL47: 23 | AM47: =SUM(E47:AL47) -> 1461
B48: 3 | C48: KHOIRUL FAHMI ISKANDAR, S.PD | E48: 3 | F48: 1 | G48: 0 | H48: 2 | I48: 0 | J48: 1 | K48: 0 | L48: 0 | M48: 2 | N48: 1 | O48: 0 | P48: 0 | Q48: 0 | R48: 1 | S48: 0 | T48: 0 | U48: 0 | V48: 0 | W48: 0 | X48: 0 | Y48: 1 | Z48: 0 | AA48: 0 | AB48: 0 | AC48: 0 | AD48: 0 | AE48: 1 | AF48: 0 | AG48: 0 | AH48: 0 | AI48: 0 | AJ48: 0 | AK48: 0 | AL48: 0 | AM48: =SUM(E48:AL48) -> 13
B49: 4 | C49: AKHMAD, S.PD., M.M. | E49: 0 | F49: 2 | G49: 9 | H49: 2 | I49: 2 | J49: 0 | K49: 0 | L49: 1 | M49: 3 | N49: 1 | O49: 0 | P49: 3 | Q49: 0 | R49: 0 | S49: 1 | T49: 0 | U49: 5 | V49: 3 | W49: 0 | X49: 2 | Y49: 0 | Z49: 0 | AA49: 1 | AB49: 0 | AC49: 0 | AD49: 0 | AE49: 2 | AF49: 0 | AG49: 0 | AH49: 0 | AI49: 1 | AJ49: 0 | AK49: 2 | AL49: 1 | AM49: =SUM(E49:AL49) -> 41
B50: 5 | C50: SOFI WULANDARI, S.H. | E50: 0 | F50: 0 | G50: 0 | H50: 1 | I50: 0 | J50: 0 | K50: 0 | L50: 0 | M50: 0 | N50: 0 | O50: 0 | P50: 0 | Q50: 0 | R50: 1 | S50: 0 | T50: 1 | U50: 0 | V50: 0 | W50: 0 | X50: 0 | Y50: 0 | Z50: 0 | AA50: 0 | AB50: 0 | AC50: 0 | AD50: 0 | AE50: 0 | AF50: 0 | AG50: 0 | AH50: 0 | AI50: 0 | AJ50: 0 | AK50: 0 | AL50: 0 | AM50: =SUM(E50:AL50) -> 3
B51: 6 | C51: AL MA’ARIF | E51: 0 | F51: 0 | G51: 0 | H51: 1 | I51: 0 | J51: 0 | K51: 0 | L51: 0 | M51: 0 | N51: 0 | O51: 0 | P51: 0 | Q51: 0 | R51: 0 | S51: 0 | T51: 0 | U51: 0 | V51: 0 | W51: 0 | X51: 0 | Y51: 0 | Z51: 0 | AA51: 0 | AB51: 0 | AC51: 0 | AD51: 0 | AE51: 0 | AF51: 0 | AG51: 0 | AH51: 0 | AI51: 0 | AJ51: 0 | AK51: 1 | AL51: 0 | AM51: =SUM(E51:AL51) -> 2
...

Sheet SUMBERKENCONO
C2: Kecamatan | D2: WONGSOREJO
C3: Kabupaten | D3: BANYUWANGI
C4: Provinsi | D4: JAWA TIMUR
C9: Kelurahan | D9: SUMBERKENCONO
A12: I | B12: DATA PEMILIH DAN PENGGUNAAN HAK PILIH | T12: JUMLAH AKHIR
A13: A | B13: DATA PEMILIH | E13: TPS 001 | F13: TPS 002 | G13: TPS 003 | H13: TPS 004 | I13: TPS 005 | J13: TPS 006 | K13: TPS 007 | L13: TPS 008 | M13: TPS 009 | N13: TPS 010 | O13: TPS 011 | P13: TPS 012 | Q13: TPS 013 | R13: TPS 014 | S13: TPS 015
B14: Jumlah Pemilih dalam Daftar Pemilih Tetap (DPT) | D14: LK | E14: 140 | F14: 147 | G14: 125 | H14: 131 | I14: 134 | J14: 149 | K14: 141 | L14: 143 | M14: 154 | N14: 131 | O14: 140 | P14: 148 | Q14: 146 | R14: 131 | S14: 141 | T14: =SUM(E14:S14) -> 2101
D15: PR | E15: 127 | F15: 140 | G15: 123 | H15: 145 | I15: 129 | J15: 145 | K15: 149 | L15: 149 | M15: 144 | N15: 150 | O15: 146 | P15: 138 | Q15: 150 | R15: 156 | S15: 152 | T15: =SUM(E15:S15) -> 2143
D16: JML | E16: =SUM(E14:E15) -> 267 | F16: =SUM(F14:F15) -> 287 | G16: =SUM(G14:G15) -> 248 | H16: =SUM(H14:H15) -> 276 | I16: =SUM(I14:I15) -> 263 | J16: =SUM(J14:J15) -> 294 | K16: =SUM(K14:K15) -> 290 | L16: =SUM(L14:L15) -> 292 | ... S16: =SUM(S14:S15) -> 293 | T16: =SUM(E16:S16) -> 4244
A18: B | B18: PENGGUNA HAK PILIH
B19: 1. | C19: Jumlah pengguna hak pilih dalam Daftar Pemilih Tetap (DPT) | D19: LK | E19: 99 | F19: 108 | G19: 94 | H19: 91 | I19: 106 | J19: 109 | K19: 118 | L19: 101 | M19: 108 | N19: 97 | O19: 104 | P19: 117 | Q19: 105 | R19: 105 | S19: 111 | T19: =SUM(E19:S19) -> 1573
D20: PR | E20: 112 | F20: 111 | G20: 98 | H20: 110 | I20: 114 | J20: 111 | K20: 125 | L20: 111 | M20: 107 | N20: 121 | O20: 118 | P20: 114 | Q20: 121 | R20: 120 | S20: 132 | T20: =SUM(E20:S20) -> 1725
D21: JML | E21: =SUM(E19:E20) -> 211 | F21: =SUM(F19:F20) -> 219 | G21: =SUM(G19:G20) -> 192 | H21: =SUM(H19:H20) -> 201 | I21: =SUM(I19:I20) -> 220 | J21: =SUM(J19:J20) -> 220 | K21: =SUM(K19:K20) -> 243 | L21: =SUM(L19:L20) -> 212 | ... S21: =SUM(S19:S20) -> 243 | T21: =SUM(E21:S21) -> 3298
B22: 2. | C22: Jumlah pengguna hak pilih dalam Daftar Pemilih Tambahan (DPTb) | D22: LK | E22: 0 | F22: 0 | G22: 0 | H22: 0 | I22: 1 | J22: 0 | K22: 0 | L22: 0 | M22: 0 | N22: 0 | O22: 0 | P22: 0 | Q22: 0 | R22: 0 | S22: 0 | T22: =SUM(E22:S22) -> 1
D23: PR | E23: 0 | F23: 0 | G23: 0 | H23: 0 | I23: 1 | J23: 0 | K23: 0 | L23: 0 | M23: 0 | N23: 0 | O23: 0 | P23: 0 | Q23: 0 | R23: 0 | S23: 0 | T23: =SUM(E23:S23) -> 1
D24: JML | E24: =SUM(E22:E23) -> 0 | F24: =SUM(F22:F23) -> 0 | G24: =SUM(G22:G23) -> 0 | H24: =SUM(H22:H23) -> 0 | I24: =SUM(I22:I23) -> 2 | J24: =SUM(J22:J23) -> 0 | K24: =SUM(K22:K23) -> 0 | L24: =SUM(L22:L23) -> 0 | ... S24: =SUM(S22:S23) -> 0 | T24: =SUM(E24:S24) -> 2
B25: 3. | C25: Jumlah pengguna hak pilih dalam Daftar Pemilih Khusus (DPK) | D25: LK | E25: 0 | F25: 0 | G25: 0 | H25: 0 | I25: 0 | J25: 0 | K25: 0 | L25: 0 | M25: 0 | N25: 0 | O25: 0 | P25: 0 | Q25: 0 | R25: 1 | S25: 2 | T25: =SUM(E25:S25) -> 3
D26: PR | E26: 0 | F26: 0 | G26: 0 | H26: 0 | I26: 0 | J26: 0 | K26: 0 | L26: 0 | M26: 2 | N26: 0 | O26: 0 | P26: 0 | Q26: 0 | R26: 0 | S26: 1 | T26: =SUM(E26:S26) -> 3
D27: JML | E27: =SUM(E25:E26) -> 0 | F27: =SUM(F25:F26) -> 0 | G27: =SUM(G25:G26) -> 0 | H27: =SUM(H25:H26) -> 0 | I27: =SUM(I25:I26) -> 0 | J27: =SUM(J25:J26) -> 0 | K27: =SUM(K25:K26) -> 0 | L27: =SUM(L25:L26) -> 0 | ... S27: =SUM(S25:S26) -> 3 | T27: =SUM(E27:S27) -> 6
B28: 4. | C28: Jumlah Pengguna Hak Pilih (B.1+B.2+B.3) | D28: LK | E28: =SUM(E19,E22,E25) -> 99 | F28: =SUM(F19,F22,F25) -> 108 | G28: =SUM(G19,G22,G25) -> 94 | H28: =SUM(H19,H22,H25) -> 91 | I28: =SUM(I19,I22,I25) -> 107 | J28: =SUM(J19,J22,J25) -> 109 | K28: =SUM(K19,K22,K25) -> 118 | L28: =SUM(L19,L22,L25) -> 101 | ... S28: =SUM(S19,S22,S25) -> 113 | T28: =SUM(E28:S28) -> 1577
D29: PR | E29: =SUM(E20,E23,E26) -> 112 | F29: =SUM(F20,F23,F26) -> 111 | G29: =SUM(G20,G23,G26) -> 98 | H29: =SUM(H20,H23,H26) -> 110 | I29: =SUM(I20,I23,I26) -> 115 | J29: =SUM(J20,J23,J26) -> 111 | K29: =SUM(K20,K23,K26) -> 125 | L29: =SUM(L20,L23,L26) -> 111 | ... S29: =SUM(S20,S23,S26) -> 133 | T29: =SUM(E29:S29) -> 1729
D30: JML | E30: =SUM(E28:E29) -> 211 | F30: =SUM(F28:F29) -> 219 | G30: =SUM(G28:G29) -> 192 | H30: =SUM(H28:H29) -> 201 | I30: =SUM(I28:I29) -> 222 | J30: =SUM(J28:J29) -> 220 | K30: =SUM(K28:K29) -> 243 | L30: =SUM(L28:L29) -> 212 | ... S30: =SUM(S28:S29) -> 246 | T30: =SUM(E30:S30) -> 3306
A32: II | B32: DATA PENGGUNAAN SURAT SUARA
A33: 1 | B33: Jumlah surat suara yang diterima, termasuk surat suara cadangan 2,5% dari DPT | E33: 273 | F33: 293 | G33: 253 | H33: 282 | I33: 269 | J33: 300 | K33: 296 | L33: 298 | M33: 304 | N33: 287 | O33: 292 | P33: 292 | Q33: 302 | R33: 293 | S33: 299 | T33: =SUM(E33:S33) -> 4333
A34: 2 | B34: Jumlah surat suara yang digunakan | E34: 211 | F34: 219 | G34: 192 | H34: 201 | I34: 222 | J34: 220 | K34: 243 | L34: 212 | M34: 217 | N34: 218 | O34: 222 | P34: 231 | Q34: 226 | R34: 226 | S34: 246 | T34: =SUM(E34:S34) -> 3306
A35: 3 | B35: Jumlah surat suara dikembalikan oleh pemilih (karena rusak atau keliru coblos) | E35: 0 | F35: 0 | G35: 0 | H35: 0 | I35: 3 | J35: 1 | K35: 0 | L35: 0 | M35: 1 | N35: 1 | O35: 0 | P35: 1 | Q35: 0 | R35: 0 | S35: 0 | T35: =SUM(E35:S35) -> 7
A36: 4 | B36: Jumlah surat suara yang tidak digunakan/tidak terpakai, termasuk sisa surat suara cadangan | E36: =E33-(E34+E35) -> 62 | F36: =F33-(F34+F35) -> 74 | G36: =G33-(G34+G35) -> 61 | H36: =H33-(H34+H35) -> 81 | I36: =I33-(I34+I35) -> 44 | J36: =J33-(J34+J35) -> 79 | K36: =K33-(K34+K35) -> 53 | L36: =L33-(L34+L35) -> 86 | ... S36: =S33-(S34+S35) -> 53 | T36: =SUM(E36:S36) -> 1020
A38: III | B38: DATA PEMILIH DISABILITAS
B39: Jumlah seluruh Pemilih disabilitas yang menggunakan hak pilih | D39: LK | E39: 0 | F39: 0 | G39: 0 | H39: 0 | I39: 0 | J39: 0 | K39: 1 | L39: 0 | M39: 0 | N39: 0 | O39: 0 | P39: 0 | Q39: 0 | R39: 0 | S39: 0 | T39: =SUM(E39:S39) -> 1
D40: PR | E40: 0 | F40: 0 | G40: 0 | H40: 0 | I40: 0 | J40: 0 | K40: 0 | L40: 0 | M40: 0 | N40: 0 | O40: 0 | P40: 0 | Q40: 0 | R40: 0 | S40: 0 | T40: =SUM(E40:S40) -> 0
D41: JML | E41: =SUM(E39:E40) -> 0 | F41: =SUM(F39:F40) -> 0 | G41: =SUM(G39:G40) -> 0 | H41: =SUM(H39:H40) -> 0 | I41: =SUM(I39:I40) -> 0 | J41: =SUM(J39:J40) -> 0 | K41: =SUM(K39:K40) -> 1 | L41: =SUM(L39:L40) -> 0 | ... S41: =SUM(S39:S40) -> 0 | T41: =SUM(E41:S41) -> 1
A43: IV | B43: DATA RINCIAN PEROLEHAN SUARA PASANGAN CALON BUPATI DAN WAKIL BUPATI
A44: NOMOR DAN NAMA CALON
A45: A.1 | B45: 1. | C45: Partai Kebangkitan Bangsa | E45: 17 | F45: 3 | G45: 6 | H45: 8 | I45: 4 | J45: 0 | K45: 6 | L45: 12 | M45: 6 | N45: 11 | O45: 5 | P45: 3 | Q45: 4 | R45: 10 | S45: 14 | T45: =SUM(E45:S45) -> 109
A46: A.2 | B46: 1 | C46: HJ. SITI MAKHROCHATIN NI’MAH, S.PD., M.M. | E46: 14 | F46: 6 | G46: 4 | H46: 11 | I46: 36 | J46: 2 | K46: 12 | L46: 5 | M46: 2 | N46: 3 | O46: 8 | P46: 7 | Q46: 4 | R46: 6 | S46: 12 | T46: =SUM(E46:S46) -> 132
B47: 2 | C47: A. TAUFIK | E47: 39 | F47: 24 | G47: 23 | H47: 17 | I47: 29 | J47: 20 | K47: 24 | L47: 14 | M47: 12 | N47: 17 | O47: 12 | P47: 25 | Q47: 25 | R47: 29 | S47: 41 | T47: =SUM(E47:S47) -> 351
B48: 3 | C48: KHOIRUL FAHMI ISKANDAR, S.PD | E48: 0 | F48: 0 | G48: 1 | H48: 2 | I48: 0 | J48: 1 | K48: 1 | L48: 0 | M48: 0 | N48: 0 | O48: 2 | P48: 2 | Q48: 2 | R48: 0 | S48: 0 | T48: =SUM(E48:S48) -> 11
B49: 4 | C49: AKHMAD, S.PD., M.M. | E49: 8 | F49: 4 | G49: 13 | H49: 1 | I49: 0 | J49: 0 | K49: 12 | L49: 0 | M49: 0 | N49: 2 | O49: 0 | P49: 1 | Q49: 1 | R49: 4 | S49: 6 | T49: =SUM(E49:S49) -> 52
B50: 5 | C50: SOFI WULANDARI, S.H. | E50: 0 | F50: 0 | G50: 0 | H50: 0 | I50: 1 | J50: 0 | K50: 1 | L50: 0 | M50: 0 | N50: 0 | O50: 0 | P50: 0 | Q50: 0 | R50: 0 | S50: 0 | T50: =SUM(E50:S50) -> 2
B51: 6 | C51: AL MA’ARIF | E51: 0 | F51: 0 | G51: 0 | H51: 1 | I51: 0 | J51: 0 | K51: 0 | L51: 0 | M51: 0 | N51: 0 | O51: 0 | P51: 0 | Q51: 0 | R51: 0 | S51: 0 | T51: =SUM(E51:S51) -> 1
...

Sheet BAJULMATI
C2: Kecamatan | D2: WONGSOREJO
C3: Kabupaten | D3: BANYUWANGI
C4: Provinsi | D4: JAWA TIMUR
C9: Kelurahan | D9: BAJULMATI
A12: I | B12: DATA PEMILIH DAN PENGGUNAAN HAK PILIH | AD12: JUMLAH AKHIR
A13: A | B13: DATA PEMILIH | E13: TPS 001 | F13: TPS 002 | G13: TPS 003 | H13: TPS 004 | I13: TPS 005 | J13: TPS 006 | K13: TPS 007 | L13: TPS 008 | M13: TPS 009 | N13: TPS 010 | O13: TPS 011 | P13: TPS 012 | Q13: TPS 013 | R13: TPS 014 | S13: TPS 015 | T13: TPS 016 | U13: TPS 017 | V13: TPS 018 | W13: TPS 019 | X13: TPS 020 | Y13: TPS 021 | Z13: TPS 022 | AA13: TPS 023 | AB13: TPS 024 | AC13: TPS 025
B14: Jumlah Pemilih dalam Daftar Pemilih Tetap (DPT) | D14: LK | E14: 135 | F14: 140 | G14: 137 | H14: 147 | I14: 154 | J14: 129 | K14: 124 | L14: 140 | M14: 144 | N14: 125 | O14: 113 | P14: 137 | Q14: 104 | R14: 126 | S14: 131 | T14: 125 | U14: 131 | V14: 149 | W14: 142 | X14: 134 | Y14: 131 | Z14: 115 | AA14: 141 | AB14: 130 | AC14: 114 | AD14: =SUM(E14:AC14) -> 3298
D15: PR | E15: 145 | F15: 132 | G15: 135 | H15: 140 | I15: 134 | J15: 131 | K15: 136 | L15: 152 | M15: 148 | N15: 129 | O15: 125 | P15: 138 | Q15: 147 | R15: 118 | S15: 153 | T15: 116 | U15: 151 | V15: 145 | W15: 136 | X15: 147 | Y15: 141 | Z15: 113 | AA15: 140 | AB15: 127 | AC15: 131 | AD15: =SUM(E15:AC15) -> 3410
D16: JML | E16: =SUM(E14:E15) -> 280 | F16: =SUM(F14:F15) -> 272 | G16: =SUM(G14:G15) -> 272 | H16: =SUM(H14:H15) -> 287 | I16: =SUM(I14:I15) -> 288 | J16: =SUM(J14:J15) -> 260 | K16: =SUM(K14:K15) -> 260 | L16: =SUM(L14:L15) -> 292 | ... AC16: =SUM(AC14:AC15) -> 245 | AD16: =SUM(E16:AC16) -> 6708
A18: B | B18: PENGGUNA HAK PILIH
B19: 1. | C19: Jumlah pengguna hak pilih dalam Daftar Pemilih Tetap (DPT) | D19: LK | E19: 111 | F19: 99 | G19: 97 | H19: 93 | I19: 112 | J19: 91 | K19: 85 | L19: 98 | M19: 79 | N19: 99 | O19: 85 | P19: 93 | Q19: 66 | R19: 88 | S19: 82 | T19: 96 | U19: 89 | V19: 115 | W19: 99 | X19: 102 | Y19: 93 | Z19: 73 | AA19: 96 | AB19: 88 | AC19: 102 | AD19: =SUM(E19:AC19) -> 2331
D20: PR | E20: 117 | F20: 96 | G20: 107 | H20: 95 | I20: 111 | J20: 88 | K20: 99 | L20: 117 | M20: 95 | N20: 104 | O20: 103 | P20: 106 | Q20: 106 | R20: 91 | S20: 113 | T20: 86 | U20: 108 | V20: 110 | W20: 106 | X20: 123 | Y20: 113 | Z20: 72 | AA20: 104 | AB20: 95 | AC20: 98 | AD20: =SUM(E20:AC20) -> 2563
D21: JML | E21: =SUM(E19:E20) -> 228 | F21: =SUM(F19:F20) -> 195 | G21: =SUM(G19:G20) -> 204 | H21: =SUM(H19:H20) -> 188 | I21: =SUM(I19:I20) -> 223 | J21: =SUM(J19:J20) -> 179 | K21: =SUM(K19:K20) -> 184 | L21: =SUM(L19:L20) -> 215 | ... AC21: =SUM(AC19:AC20) -> 200 | AD21: =SUM(E21:AC21) -> 4894
B22: 2. | C22: Jumlah pengguna hak pilih dalam Daftar Pemilih Tambahan (DPTb) | D22: LK | E22: 0 | F22: 0 | G22: 0 | H22: 0 | I22: 0 | J22: 1 | K22: 1 | L22: 0 | M22: 0 | N22: 0 | O22: 0 | P22: 1 | Q22: 0 | R22: 0 | S22: 0 | T22: 0 | U22: 0 | V22: 0 | W22: 0 | X22: 0 | Y22: 0 | Z22: 0 | AA22: 0 | AB22: 0 | AC22: 0 | AD22: =SUM(E22:AC22) -> 3
D23: PR | E23: 0 | F23: 0 | G23: 0 | H23: 0 | I23: 0 | J23: 0 | K23: 0 | L23: 0 | M23: 0 | N23: 0 | O23: 0 | P23: 0 | Q23: 0 | R23: 0 | S23: 0 | T23: 0 | U23: 0 | V23: 0 | W23: 0 | X23: 0 | Y23: 0 | Z23: 1 | AA23: 0 | AB23: 0 | AC23: 1 | AD23: =SUM(E23:AC23) -> 2
D24: JML | E24: =SUM(E22:E23) -> 0 | F24: =SUM(F22:F23) -> 0 | G24: =SUM(G22:G23) -> 0 | H24: =SUM(H22:H23) -> 0 | I24: =SUM(I22:I23) -> 0 | J24: =SUM(J22:J23) -> 1 | K24: =SUM(K22:K23) -> 1 | L24: =SUM(L22:L23) -> 0 | ... AC24: =SUM(AC22:AC23) -> 1 | AD24: =SUM(E24:AC24) -> 5
B25: 3. | C25: Jumlah pengguna hak pilih dalam Daftar Pemilih Khusus (DPK) | D25: LK | E25: 0 | F25: 1 | G25: 0 | H25: 0 | I25: 0 | J25: 3 | K25: 3 | L25: 0 | M25: 0 | N25: 0 | O25: 4 | P25: 0 | Q25: 2 | R25: 2 | S25: 1 | T25: 2 | U25: 4 | V25: 1 | W25: 1 | X25: 0 | Y25: 0 | Z25: 0 | AA25: 5 | AB25: 4 | AC25: 3 | AD25: =SUM(E25:AC25) -> 36
D26: PR | E26: 0 | F26: 3 | G26: 0 | H26: 1 | I26: 0 | J26: 7 | K26: 2 | L26: 0 | M26: 2 | N26: 0 | O26: 2 | P26: 3 | Q26: 3 | R26: 2 | S26: 1 | T26: 5 | U26: 2 | V26: 1 | W26: 2 | X26: 0 | Y26: 0 | Z26: 0 | AA26: 6 | AB26: 3 | AC26: 6 | AD26: =SUM(E26:AC26) -> 51
D27: JML | E27: =SUM(E25:E26) -> 0 | F27: =SUM(F25:F26) -> 4 | G27: =SUM(G25:G26) -> 0 | H27: =SUM(H25:H26) -> 1 | I27: =SUM(I25:I26) -> 0 | J27: =SUM(J25:J26) -> 10 | K27: =SUM(K25:K26) -> 5 | L27: =SUM(L25:L26) -> 0 | ... AC27: =SUM(AC25:AC26) -> 9 | AD27: =SUM(E27:AC27) -> 87
B28: 4. | C28: Jumlah Pengguna Hak Pilih (B.1+B.2+B.3) | D28: LK | E28: =SUM(E19,E22,E25) -> 111 | F28: =SUM(F19,F22,F25) -> 100 | G28: =SUM(G19,G22,G25) -> 97 | H28: =SUM(H19,H22,H25) -> 93 | I28: =SUM(I19,I22,I25) -> 112 | J28: =SUM(J19,J22,J25) -> 95 | K28: =SUM(K19,K22,K25) -> 89 | L28: =SUM(L19,L22,L25) -> 98 | ... AC28: =SUM(AC19,AC22,AC25) -> 105 | AD28: =SUM(E28:AC28) -> 2370
D29: PR | E29: =SUM(E20,E23,E26) -> 117 | F29: =SUM(F20,F23,F26) -> 99 | G29: =SUM(G20,G23,G26) -> 107 | H29: =SUM(H20,H23,H26) -> 96 | I29: =SUM(I20,I23,I26) -> 111 | J29: =SUM(J20,J23,J26) -> 95 | K29: =SUM(K20,K23,K26) -> 101 | L29: =SUM(L20,L23,L26) -> 117 | ... AC29: =SUM(AC20,AC23,AC26) -> 105 | AD29: =SUM(E29:AC29) -> 2616
D30: JML | E30: =SUM(E28:E29) -> 228 | F30: =SUM(F28:F29) -> 199 | G30: =SUM(G28:G29) -> 204 | H30: =SUM(H28:H29) -> 189 | I30: =SUM(I28:I29) -> 223 | J30: =SUM(J28:J29) -> 190 | K30: =SUM(K28:K29) -> 190 | L30: =SUM(L28:L29) -> 215 | ... AC30: =SUM(AC28:AC29) -> 210 | AD30: =SUM(E30:AC30) -> 4986
A32: II | B32: DATA PENGGUNAAN SURAT SUARA
A33: 1 | B33: Jumlah surat suara yang diterima, termasuk surat suara cadangan 2,5% dari DPT | E33: 286 | F33: 278 | G33: 278 | H33: 293 | I33: 294 | J33: 266 | K33: 266 | L33: 298 | M33: 298 | N33: 260 | O33: 243 | P33: 281 | Q33: 257 | R33: 249 | S33: 290 | T33: 246 | U33: 288 | V33: 296 | W33: 284 | X33: 287 | Y33: 278 | Z33: 232 | AA33: 277 | AB33: 257 | AC33: 250 | AD33: =SUM(E33:AC33) -> 6832
A34: 2 | B34: Jumlah surat suara yang digunakan | E34: 228 | F34: 199 | G34: 204 | H34: 189 | I34: 223 | J34: 190 | K34: 190 | L34: 215 | M34: 176 | N34: 203 | O34: 194 | P34: 203 | Q34: 177 | R34: 183 | S34: 197 | T34: 189 | U34: 203 | V34: 227 | W34: 208 | X34: 225 | Y34: 206 | Z34: 146 | AA34: 211 | AB34: 190 | AC34: 210 | AD34: =SUM(E34:AC34) -> 4986
A35: 3 | B35: Jumlah surat suara dikembalikan oleh pemilih (karena rusak atau keliru coblos) | E35: 0 | F35: 0 | G35: 0 | H35: 0 | I35: 0 | J35: 0 | K35: 0 | L35: 1 | M35: 0 | N35: 0 | O35: 0 | P35: 0 | Q35: 0 | R35: 0 | S35: 0 | T35: 0 | U35: 0 | V35: 0 | W35: 0 | X35: 0 | Y35: 0 | Z35: 0 | AA35: 0 | AB35: 0 | AC35: 0 | AD35: =SUM(E35:AC35) -> 1
