Workbook

Sheet DPRD KAB
C8: Kecamatan | D8: GENTENG
C9: Kabupaten | D9: BANYUWANGI
C10: Provinsi | D10: JAWA TIMUR
A12: I | B12: DATA PEMILIH DAN PENGGUNAAN HAK PILIH | E12: JUMLAH AKHIR
A13: A | B13: DATA PEMILIH
B14: Jumlah Pemilih dalam Daftar Pemilih Tetap (DPT) | D14: LK | E14: ='GENTENG KULON'!BK14+'GENTENG WETAN'!BL14+KALIGONDO!BB14+KEMBIRITAN!BQ14+SETAIL!BC14 -> 36085
D15: PR | E15: ='GENTENG KULON'!BK15+'GENTENG WETAN'!BL15+KALIGONDO!BB15+KEMBIRITAN!BQ15+SETAIL!BC15 -> 36168
D16: JML | E16: =SUM(E14:E15) -> 72253
A18: B | B18: PENGGUNA HAK PILIH
B19: 1. | C19: Jumlah pengguna hak pilih dalam Daftar Pemilih Tetap (DPT) | D19: LK | E19: ='GENTENG KULON'!BK19+'GENTENG WETAN'!BL19+KALIGONDO!BB19+KEMBIRITAN!BQ19+SETAIL!BC19 -> 26160
D20: PR | E20: ='GENTENG KULON'!BK20+'GENTENG WETAN'!BL20+KALIGONDO!BB20+KEMBIRITAN!BQ20+SETAIL!BC20 -> 28216
D21: JML | E21: =SUM(E19:E20) -> 54376
B22: 2. | C22: Jumlah pengguna hak pilih dalam Daftar Pemilih Tambahan (DPTb) | D22: LK | E22: ='GENTENG KULON'!BK22+'GENTENG WETAN'!BL22+KALIGONDO!BB22+KEMBIRITAN!BQ22+SETAIL!BC22 -> 68
D23: PR | E23: ='GENTENG KULON'!BK23+'GENTENG WETAN'!BL23+KALIGONDO!BB23+KEMBIRITAN!BQ23+SETAIL!BC23 -> 68
D24: JML | E24: =SUM(E22:E23) -> 136
B25: 3. | C25: Jumlah pengguna hak pilih dalam Daftar Pemilih Khusus (DPK) | D25: LK | E25: ='GENTENG KULON'!BK25+'GENTENG WETAN'!BL25+KALIGONDO!BB25+KEMBIRITAN!BQ25+SETAIL!BC25 -> 281
D26: PR | E26: ='GENTENG KULON'!BK26+'GENTENG WETAN'!BL26+KALIGONDO!BB26+KEMBIRITAN!BQ26+SETAIL!BC26 -> 393
D27: JML | E27: =SUM(E25:E26) -> 674
B28: 4. | C28: Jumlah Pengguna Hak Pilih (B.1+B.2+B.3) | D28: LK | E28: =E19+E22+E25 -> 26509
D29: PR | E29: =E20+E23+E26 -> 28677
D30: JML | E30: =SUM(E28:E29) -> 55186
A32: II | B32: DATA PENGGUNAAN SURAT SUARA
A33: 1 | B33: Jumlah surat suara yang diterima, termasuk surat suara cadangan 2,5% dari DPT | E33: ='GENTENG KULON'!BK33+'GENTENG WETAN'!BL33+KALIGONDO!BB33+KEMBIRITAN!BQ33+SETAIL!BC33 -> 73795
A34: 2 | B34: Jumlah surat suara yang digunakan | E34: ='GENTENG KULON'!BK34+'GENTENG WETAN'!BL34+KALIGONDO!BB34+KEMBIRITAN!BQ34+SETAIL!BC34 -> 55188
A35: 3 | B35: Jumlah surat suara dikembalikan oleh pemilih (karena rusak atau keliru coblos) | E35: ='GENTENG KULON'!BK35+'GENTENG WETAN'!BL35+KALIGONDO!BB35+KEMBIRITAN!BQ35+SETAIL!BC35 -> 91
A36: 4 | B36: Jumlah surat suara yang tidak digunakan/tidak terpakai, termasuk sisa surat suara cadangan | E36: =E33-(E34+E35) -> 18516
A38: III | B38: DATA PEMILIH DISABILITAS
B39: Jumlah seluruh Pemilih disabilitas yang menggunakan hak pilih | D39: LK | E39: ='GENTENG KULON'!BK39+'GENTENG WETAN'!BL39+KALIGONDO!BB39+KEMBIRITAN!BQ39+SETAIL!BC39 -> 44
D40: PR | E40: ='GENTENG KULON'!BK40+'GENTENG WETAN'!BL40+KALIGONDO!BB40+KEMBIRITAN!BQ40+SETAIL!BC40 -> 48
D41: JML | E41: =SUM(E39:E40) -> 92
A43: IV | B43: DATA RINCIAN PEROLEHAN SUARA PASANGAN CALON BUPATI DAN WAKIL BUPATI
A44: NOMOR DAN NAMA CALON
A45: A.1 | B45: 1. | C45: Partai Kebangkitan Bangsa | E45: ='GENTENG KULON'!BK45+'GENTENG WETAN'!BL45+KALIGONDO!BB45+KEMBIRITAN!BQ45+SETAIL!BC45 -> 1409
A46: A.2 | C46: 1. H. KHUSNAN, S.Ag., M.Pd.I. | E46: ='GENTENG KULON'!BK46+'GENTENG WETAN'!BL46+KALIGONDO!BB46+KEMBIRITAN!BQ46+SETAIL!BC46 -> 2228
C47: 2. MARA QONITHA LAYLIA | E47: ='GENTENG KULON'!BK47+'GENTENG WETAN'!BL47+KALIGONDO!BB47+KEMBIRITAN!BQ47+SETAIL!BC47 -> 678
C48: 3. ZAKI AL MUBAROK, M.Si. | E48: ='GENTENG KULON'!BK48+'GENTENG WETAN'!BL48+KALIGONDO!BB48+KEMBIRITAN!BQ48+SETAIL!BC48 -> 3924
C49: 4. INAYATUL MAHMUDAH, S.Pd. | E49: ='GENTENG KULON'!BK49+'GENTENG WETAN'!BL49+KALIGONDO!BB49+KEMBIRITAN!BQ49+SETAIL!BC49 -> 228
C50: 5. HABIBURRAHMAN AL KHOLILI | E50: ='GENTENG KULON'!BK50+'GENTENG WETAN'!BL50+KALIGONDO!BB50+KEMBIRITAN!BQ50+SETAIL!BC50 -> 75
C51: 6. INDIARTI NOVIDA, A.Md. | E51: ='GENTENG KULON'!BK51+'GENTENG WETAN'!BL51+KALIGONDO!BB51+KEMBIRITAN!BQ51+SETAIL!BC51 -> 25
C52: 7. RUDI DARMAWAN, S.Pd.I. | E52: ='GENTENG KULON'!BK52+'GENTENG WETAN'!BL52+KALIGONDO!BB52+KEMBIRITAN!BQ52+SETAIL!BC52 -> 45
...

Sheet GENTENG KULON
C2: Kecamatan | D2: GENTENG
C3: Kabupaten | D3: BANYUWANGI
C4: Provinsi | D4: JAWA TIMUR
C9: Kelurahan | D9: GENTENG KULON
A12: I | B12: DATA PEMILIH DAN PENGGUNAAN HAK PILIH | BK12: JUMLAH AKHIR
A13: A | B13: DATA PEMILIH | E13: TPS 001 | F13: TPS 002 | G13: TPS 003 | H13: TPS 004 | I13: TPS 005 | J13: TPS 006 | K13: TPS 007 | L13: TPS 008 | M13: TPS 009 | N13: TPS 010 | O13: TPS 011 | P13: TPS 012 | Q13: TPS 013 | R13: TPS 014 | S13: TPS 015 | T13: TPS 016 | U13: TPS 017 | V13: TPS 018 | W13: TPS 019 | X13: TPS 020 | Y13: TPS 021 | Z13: TPS 022 | AA13: TPS 023 | AB13: TPS 024 | AC13: TPS 025 | AD13: TPS 026 | AE13: TPS 027 | AF13: TPS 028 | AG13: TPS 029 | AH13: TPS 030 | AI13: TPS 031 | AJ13: TPS 032 | AK13: TPS 033 | AL13: TPS 034 | AM13: TPS 035 | AN13: TPS 036 | AO13: TPS 037 | AP13: TPS 038 | AQ13: TPS 039 | AR13: TPS 040 | AS13: TPS 041 | AT13: TPS 042 | AU13: TPS 043 | AV13: TPS 044 | AW13: TPS 045 | AX13: TPS 046 | AY13: TPS 047 | AZ13: TPS 048 | BA13: TPS 049 | BB13: TPS 050 | BC13: TPS 051 | BD13: TPS 052 | BE13: TPS 053 | BF13: TPS 054 | BG13: TPS 055 | BH13: TPS 056 | BI13: TPS 057 | BJ13: TPS 058
B14: Jumlah Pemilih dalam Daftar Pemilih Tetap (DPT) | D14: LK | E14: 131 | F14: 130 | G14: 125 | H14: 107 | I14: 129 | J14: 136 | K14: 143 | L14: 137 | M14: 136 | N14: 124 | O14: 130 | P14: 128 | Q14: 134 | R14: 106 | S14: 122 | T14: 126 | U14: 133 | V14: 140 | W14: 137 | X14: 141 | Y14: 134 | Z14: 127 | AA14: 135 | AB14: 127 | AC14: 133 | AD14: 139 | AE14: 134 | AF14: 139 | AG14: 136 | AH14: 137 | AI14: 128 | AJ14: 148 | AK14: 131 | AL14: 142 | AM14: 115 | AN14: 136 | AO14: 105 | AP14: 103 | AQ14: 145 | AR14: 150 | AS14: 125 | AT14: 126 | AU14: 141 | AV14: 141 | AW14: 154 | AX14: 130 | AY14: 145 | AZ14: 138 | BA14: 150 | BB14: 148 | BC14: 132 | BD14: 129 | BE14: 136 | BF14: 127 | BG14: 137 | BH14: 143 | BI14: 124 | BJ14: 135 | BK14: =SUM(E14:BJ14) -> 7700
D15: PR | E15: 121 | F15: 134 | G15: 121 | H15: 141 | I15: 126 | J15: 147 | K15: 133 | L15: 145 | M15: 143 | N15: 139 | O15: 153 | P15: 148 | Q15: 149 | R15: 114 | S15: 159 | T15: 138 | U15: 145 | V15: 136 | W15: 138 | X15: 137 | Y15: 147 | Z15: 149 | AA15: 139 | AB15: 149 | AC15: 142 | AD15: 142 | AE15: 132 | AF15: 132 | AG15: 143 | AH15: 141 | AI15: 149 | AJ15: 137 | AK15: 156 | AL15: 147 | AM15: 137 | AN15: 140 | AO15: 118 | AP15: 116 | AQ15: 143 | AR15: 142 | AS15: 145 | AT15: 151 | AU15: 150 | AV15: 145 | AW15: 138 | AX15: 153 | AY15: 141 | AZ15: 144 | BA15: 137 | BB15: 141 | BC15: 149 | BD15: 135 | BE15: 142 | BF15: 121 | BG15: 130 | BH15: 128 | BI15: 133 | BJ15: 128 | BK15: =SUM(E15:BJ15) -> 8079
D16: JML | E16: =SUM(E14:E15) -> 252 | F16: =SUM(F14:F15) -> 264 | G16: =SUM(G14:G15) -> 246 | H16: =SUM(H14:H15) -> 248 | I16: =SUM(I14:I15) -> 255 | J16: =SUM(J14:J15) -> 283 | K16: =SUM(K14:K15) -> 276 | L16: =SUM(L14:L15) -> 282 | ... BJ16: =SUM(BJ14:BJ15) -> 263 | BK16: =SUM(E16:BJ16) -> 15779
A18: B | B18: PENGGUNA HAK PILIH
B19: 1. | C19: Jumlah pengguna hak pilih dalam Daftar Pemilih Tetap (DPT) | D19: LK | E19: 92 | F19: 92 | G19: 90 | H19: 70 | I19: 93 | J19: 91 | K19: 106 | L19: 94 | M19: 90 | N19: 78 | O19: 90 | P19: 95 | Q19: 103 | R19: 82 | S19: 84 | T19: 80 | U19: 93 | V19: 101 | W19: 98 | X19: 98 | Y19: 91 | Z19: 84 | AA19: 106 | AB19: 93 | AC19: 96 | AD19: 89 | AE19: 99 | AF19: 107 | AG19: 99 | AH19: 91 | AI19: 107 | AJ19: 104 | AK19: 97 | AL19: 101 | AM19: 78 | AN19: 95 | AO19: 77 | AP19: 85 | AQ19: 102 | AR19: 108 | AS19: 89 | AT19: 91 | AU19: 105 | AV19: 98 | AW19: 119 | AX19: 102 | AY19: 105 | AZ19: 105 | BA19: 118 | BB19: 119 | BC19: 94 | BD19: 96 | BE19: 105 | BF19: 93 | BG19: 105 | BH19: 104 | BI19: 101 | BJ19: 102 | BK19: =SUM(E19:BJ19) -> 5580
D20: PR | E20: 96 | F20: 101 | G20: 93 | H20: 102 | I20: 92 | J20: 108 | K20: 105 | L20: 106 | M20: 96 | N20: 97 | O20: 115 | P20: 99 | Q20: 107 | R20: 86 | S20: 125 | T20: 102 | U20: 99 | V20: 108 | W20: 95 | X20: 105 | Y20: 108 | Z20: 110 | AA20: 110 | AB20: 111 | AC20: 114 | AD20: 105 | AE20: 104 | AF20: 104 | AG20: 121 | AH20: 98 | AI20: 98 | AJ20: 100 | AK20: 117 | AL20: 112 | AM20: 96 | AN20: 106 | AO20: 93 | AP20: 94 | AQ20: 106 | AR20: 111 | AS20: 100 | AT20: 110 | AU20: 137 | AV20: 104 | AW20: 105 | AX20: 112 | AY20: 113 | AZ20: 116 | BA20: 115 | BB20: 119 | BC20: 114 | BD20: 106 | BE20: 124 | BF20: 95 | BG20: 107 | BH20: 104 | BI20: 111 | BJ20: 106 | BK20: =SUM(E20:BJ20) -> 6153
D21: JML | E21: =SUM(E19:E20) -> 188 | F21: =SUM(F19:F20) -> 193 | G21: =SUM(G19:G20) -> 183 | H21: =SUM(H19:H20) -> 172 | I21: =SUM(I19:I20) -> 185 | J21: =SUM(J19:J20) -> 199 | K21: =SUM(K19:K20) -> 211 | L21: =SUM(L19:L20) -> 200 | ... BJ21: =SUM(BJ19:BJ20) -> 208 | BK21: =SUM(E21:BJ21) -> 11733
B22: 2. | C22: Jumlah pengguna hak pilih dalam Daftar Pemilih Tambahan (DPTb) | D22: LK | E22: 1 | F22: 0 | G22: 0 | H22: 0 | I22: 0 | J22: 0 | K22: 0 | L22: 0 | M22: 0 | N22: 0 | O22: 0 | P22: 0 | Q22: 0 | R22: 0 | S22: 0 | T22: 0 | U22: 0 | V22: 1 | W22: 1 | X22: 0 | Y22: 0 | Z22: 0 | AA22: 0 | AB22: 0 | AC22: 0 | AD22: 0 | AE22: 0 | AF22: 1 | AG22: 0 | AH22: 0 | AI22: 0 | AJ22: 0 | AK22: 0 | AL22: 0 | AM22: 0 | AN22: 0 | AO22: 0 | AP22: 1 | AQ22: 0 | AR22: 0 | AS22: 0 | AT22: 0 | AU22: 0 | AV22: 0 | AW22: 0 | AX22: 0 | AY22: 0 | AZ22: 0 | BA22: 0 | BB22: 2 | BC22: 1 | BD22: 0 | BE22: 0 | BF22: 0 | BG22: 0 | BH22: 0 | BI22: 3 | BJ22: 0 | BK22: =SUM(E22:BJ22) -> 11
D23: PR | E23: 0 | F23: 2 | G23: 0 | H23: 0 | I23: 0 | J23: 0 | K23: 0 | L23: 1 | M23: 0 | N23: 0 | O23: 0 | P23: 0 | Q23: 0 | R23: 0 | S23: 1 | T23: 0 | U23: 0 | V23: 1 | W23: 0 | X23: 0 | Y23: 0 | Z23: 0 | AA23: 0 | AB23: 1 | AC23: 0 | AD23: 0 | AE23: 0 | AF23: 1 | AG23: 0 | AH23: 0 | AI23: 0 | AJ23: 0 | AK23: 0 | AL23: 0 | AM23: 0 | AN23: 0 | AO23: 0 | AP23: 0 | AQ23: 0 | AR23: 0 | AS23: 0 | AT23: 0 | AU23: 0 | AV23: 0 | AW23: 0 | AX23: 0 | AY23: 0 | AZ23: 0 | BA23: 0 | BB23: 2 | BC23: 0 | BD23: 0 | BE23: 0 | BF23: 0 | BG23: 0 | BH23: 0 | BI23: 3 | BJ23: 1 | BK23: =SUM(E23:BJ23) -> 13
D24: JML | E24: =SUM(E22:E23) -> 1 | F24: =SUM(F22:F23) -> 2 | G24: =SUM(G22:G23) -> 0 | H24: =SUM(H22:H23) -> 0 | I24: =SUM(I22:I23) -> 0 | J24: =SUM(J22:J23) -> 0 | K24: =SUM(K22:K23) -> 0 | L24: =SUM(L22:L23) -> 1 | ... BJ24: =SUM(BJ22:BJ23) -> 1 | BK24: =SUM(E24:BJ24) -> 24
B25: 3. | C25: Jumlah pengguna hak pilih dalam Daftar Pemilih Khusus (DPK) | D25: LK | E25: 1 | F25: 3 | G25: 1 | H25: 1 | I25: 1 | J25: 3 | K25: 4 | L25: 0 | M25: 0 | N25: 1 | O25: 1 | P25: 2 | Q25: 0 | R25: 1 | S25: 0 | T25: 0 | U25: 1 | V25: 1 | W25: 0 | X25: 1 | Y25: 0 | Z25: 0 | AA25: 1 | AB25: 0 | AC25: 0 | AD25: 1 | AE25: 2 | AF25: 4 | AG25: 0 | AH25: 0 | AI25: 0 | AJ25: 0 | AK25: 0 | AL25: 4 | AM25: 2 | AN25: 3 | AO25: 3 | AP25: 0 | AQ25: 0 | AR25: 0 | AS25: 0 | AT25: 0 | AU25: 2 | AV25: 0 | AW25: 0 | AX25: 6 | AY25: 1 | AZ25: 0 | BA25: 3 | BB25: 6 | BC25: 0 | BD25: 4 | BE25: 0 | BF25: 0 | BG25: 0 | BH25: 0 | BI25: 0 | BJ25: 0 | BK25: =SUM(E25:BJ25) -> 64
D26: PR | E26: 0 | F26: 3 | G26: 1 | H26: 0 | I26: 4 | J26: 6 | K26: 2 | L26: 0 | M26: 0 | N26: 0 | O26: 1 | P26: 5 | Q26: 1 | R26: 0 | S26: 1 | T26: 2 | U26: 1 | V26: 0 | W26: 0 | X26: 2 | Y26: 1 | Z26: 0 | AA26: 3 | AB26: 0 | AC26: 2 | AD26: 1 | AE26: 0 | AF26: 1 | AG26: 0 | AH26: 0 | AI26: 0 | AJ26: 2 | AK26: 1 | AL26: 2 | AM26: 1 | AN26: 2 | AO26: 1 | AP26: 0 | AQ26: 0 | AR26: 1 | AS26: 0 | AT26: 0 | AU26: 1 | AV26: 0 | AW26: 1 | AX26: 4 | AY26: 2 | AZ26: 0 | BA26: 4 | BB26: 3 | BC26: 1 | BD26: 3 | BE26: 0 | BF26: 0 | BG26: 0 | BH26: 1 | BI26: 0 | BJ26: 0 | BK26: =SUM(E26:BJ26) -> 67
D27: JML | E27: =SUM(E25:E26) -> 1 | F27: =SUM(F25:F26) -> 6 | G27: =SUM(G25:G26) -> 2 | H27: =SUM(H25:H26) -> 1 | I27: =SUM(I25:I26) -> 5 | J27: =SUM(J25:J26) -> 9 | K27: =SUM(K25:K26) -> 6 | L27: =SUM(L25:L26) -> 0 | ... BJ27: =SUM(BJ25:BJ26) -> 0 | BK27: =SUM(E27:BJ27) -> 131
B28: 4. | C28: Jumlah Pengguna Hak Pilih (B.1+B.2+B.3) | D28: LK | E28: =SUM(E19,E22,E25) -> 94 | F28: =SUM(F19,F22,F25) -> 95 | G28: =SUM(G19,G22,G25) -> 91 | H28: =SUM(H19,H22,H25) -> 71 | I28: =SUM(I19,I22,I25) -> 94 | J28: =SUM(J19,J22,J25) -> 94 | K28: =SUM(K19,K22,K25) -> 110 | L28: =SUM(L19,L22,L25) -> 94 | ... BJ28: =SUM(BJ19,BJ22,BJ25) -> 102 | BK28: =SUM(E28:BJ28) -> 5655
D29: PR | E29: =SUM(E20,E23,E26) -> 96 | F29: =SUM(F20,F23,F26) -> 106 | G29: =SUM(G20,G23,G26) -> 94 | H29: =SUM(H20,H23,H26) -> 102 | I29: =SUM(I20,I23,I26) -> 96 | J29: =SUM(J20,J23,J26) -> 114 | K29: =SUM(K20,K23,K26) -> 107 | L29: =SUM(L20,L23,L26) -> 107 | ... BJ29: =SUM(BJ20,BJ23,BJ26) -> 107 | BK29: =SUM(E29:BJ29) -> 6233
D30: JML | E30: =SUM(E28:E29) -> 190 | F30: =SUM(F28:F29) -> 201 | G30: =SUM(G28:G29) -> 185 | H30: =SUM(H28:H29) -> 173 | I30: =SUM(I28:I29) -> 190 | J30: =SUM(J28:J29) -> 208 | K30: =SUM(K28:K29) -> 217 | L30: =SUM(L28:L29) -> 201 | ... BJ30: =SUM(BJ28:BJ29) -> 209 | BK30: =SUM(E30:BJ30) -> 11888
A32: II | B32: DATA PENGGUNAAN SURAT SUARA
A33: 1 | B33: Jumlah surat suara yang diterima, termasuk surat suara cadangan 2,5% dari DPT | E33: 258 | F33: 270 | G33: 251 | H33: 253 | I33: 261 | J33: 286 | K33: 282 | L33: 304 | M33: 285 | N33: 269 | O33: 289 | P33: 282 | Q33: 289 | R33: 225 | S33: 287 | T33: 271 | U33: 284 | V33: 283 | W33: 281 | X33: 284 | Y33: 287 | Z33: 282 | AA33: 280 | AB33: 282 | AC33: 282 | AD33: 287 | AE33: 271 | AF33: 277 | AG33: 285 | AH33: 284 | AI33: 283 | AJ33: 292 | AK33: 293 | AL33: 295 | AM33: 238 | AN33: 282 | AO33: 229 | AP33: 224 | AQ33: 294 | AR33: 298 | AS33: 276 | AT33: 283 | AU33: 297 | AV33: 292 | AW33: 299 | AX33: 299 | AY33: 292 | AZ33: 288 | BA33: 293 | BB33: 295 | BC33: 287 | BD33: 270 | BE33: 284 | BF33: 253 | BG33: 273 | BH33: 277 | BI33: 273 | BJ33: 269 | BK33: =SUM(E33:BJ33) -> 16139
A34: 2 | B34: Jumlah surat suara yang digunakan | E34: 190 | F34: 201 | G34: 185 | H34: 173 | I34: 190 | J34: 208 | K34: 217 | L34: 201 | M34: 186 | N34: 176 | O34: 207 | P34: 201 | Q34: 211 | R34: 169 | S34: 211 | T34: 184 | U34: 194 | V34: 212 | W34: 194 | X34: 206 | Y34: 200 | Z34: 194 | AA34: 220 | AB34: 205 | AC34: 212 | AD34: 196 | AE34: 205 | AF34: 218 | AG34: 220 | AH34: 189 | AI34: 205 | AJ34: 206 | AK34: 215 | AL34: 219 | AM34: 177 | AN34: 206 | AO34: 174 | AP34: 180 | AQ34: 208 | AR34: 220 | AS34: 189 | AT34: 201 | AU34: 245 | AV34: 202 | AW34: 225 | AX34: 224 | AY34: 221 | AZ34: 221 | BA34: 240 | BB34: 251 | BC34: 210 | BD34: 209 | BE34: 229 | BF34: 188 | BG34: 212 | BH34: 209 | BI34: 218 | BJ34: 209 | BK34: =SUM(E34:BJ34) -> 11888
A35: 3 | B35: Jumlah surat suara dikembalikan oleh pemilih (karena rusak atau keliru coblos) | E35: 1 | F35: 0 | G35: 3 | H35: 0 | I35: 0 | J35: 1 | K35: 0 | L35: 0 | M35: 0 | N35: 1 | O35: 0 | P35: 0 | Q35: 1 | R35: 0 | S35: 0 | AI35: 0 | AJ35: 1 | AK35: 0 | AL35: 0 | AM35: 0 | AN35: 0 | AO35: 0 | AP35: 0 | AQ35: 1 | AR35: 0 | AS35: 0 | AT35: 0 | AU35: 0 | AV35: 0 | AW35: 0 | AX35: 0 | AY35: 0 | AZ35: 0 | BA35: 0 | BB35: 0 | BC35: 0 | BD35: 0 | BE35: 0 | BF35: 0 | BG35: 0 | BH35: 1 | BI35: 0 | BJ35: 0 | BK35: =SUM(E35:BJ35) -> 10
A36: 4 | B36: Jumlah surat suara yang tidak digunakan/tidak terpakai, termasuk sisa surat suara cadangan | E36: =E33-(E34+E35) -> 67 | F36: =F33-(F34+F35) -> 69 | G36: =G33-(G34+G35) -> 63 | H36: =H33-(H34+H35) -> 80 | I36: =I33-(I34+I35) -> 71 | J36: =J33-(J34+J35) -> 77 | K36: =K33-(K34+K35) -> 65 | L36: =L33-(L34+L35) -> 103 | ... BJ36: =BJ33-(BJ34+BJ35) -> 60 | BK36: =SUM(E36:BJ36) -> 4241
A38: III | B38: DATA PEMILIH DISABILITAS
B39: Jumlah seluruh Pemilih disabilitas yang menggunakan hak pilih | D39: LK | E39: 0 | F39: 0 | G39: 0 | H39: 0 | I39: 0 | J39: 0 | K39: 0 | L39: 0 | M39: 0 | N39: 0 | O39: 0 | P39: 0 | Q39: 2 | R39: 0 | S39: 0 | T39: 0 | U39: 0 | V39: 0 | W39: 0 | X39: 0 | Y39: 0 | Z39: 0 | AA39: 2 | AB39: 1 | AC39: 0 | AD39: 0 | AE39: 0 | AF39: 0 | AG39: 0 | AH39: 0 | AI39: 0 | AJ39: 0 | AK39: 0 | AL39: 0 | AM39: 0 | AN39: 0 | AO39: 0 | AP39: 0 | AQ39: 0 | AR39: 0 | AS39: 0 | AT39: 0 | AU39: 0 | AV39: 0 | AW39: 0 | AX39: 1 | AY39: 0 | AZ39: 0 | BA39: 0 | BB39: 2 | BC39: 0 | BD39: 0 | BE39: 2 | BF39: 0 | BG39: 0 | BH39: 1 | BI39: 0 | BJ39: 0 | BK39: =SUM(E39:BJ39) -> 11
D40: PR | E40: 0 | F40: 0 | G40: 0 | H40: 0 | I40: 0 | J40: 0 | K40: 0 | L40: 0 | M40: 0 | N40: 1 | O40: 0 | P40: 0 | Q40: 0 | R40: 0 | S40: 0 | T40: 0 | U40: 0 | V40: 0 | W40: 0 | X40: 0 | Y40: 0 | Z40: 0 | AA40: 2 | AB40: 1 | AC40: 0 | AD40: 0 | AE40: 0 | AF40: 0 | AG40: 0 | AH40: 0 | AI40: 0 | AJ40: 0 | AK40: 0 | AL40: 0 | AM40: 0 | AN40: 0 | AO40: 0 | AP40: 1 | AQ40: 0 | AR40: 0 | AS40: 0 | AT40: 0 | AU40: 0 | AV40: 0 | AW40: 0 | AX40: 1 | AY40: 0 | AZ40: 0 | BA40: 0 | BB40: 0 | BC40: 0 | BD40: 0 | BE40: 2 | BF40: 0 | BG40: 0 | BH40: 1 | BI40: 0 | BJ40: 0 | BK40: =SUM(E40:BJ40) -> 9
D41: JML | E41: =SUM(E39:E40) -> 0 | F41: =SUM(F39:F40) -> 0 | G41: =SUM(G39:G40) -> 0 | H41: =SUM(H39:H40) -> 0 | I41: =SUM(I39:I40) -> 0 | J41: =SUM(J39:J40) -> 0 | K41: =SUM(K39:K40) -> 0 | L41: =SUM(L39:L40) -> 0 | ... BJ41: =SUM(BJ39:BJ40) -> 0 | BK41: =SUM(E41:BJ41) -> 20
A43: IV | B43: DATA RINCIAN PEROLEHAN SUARA PASANGAN CALON BUPATI DAN WAKIL BUPATI
A44: NOMOR DAN NAMA CALON
A45: A.1 | B45: 1. | C45: Partai Kebangkitan Bangsa | E45: 4 | F45: 5 | G45: 1 | H45: 5 | I45: 4 | J45: 4 | K45: 9 | L45: 5 | M45: 1 | N45: 4 | O45: 2 | P45: 4 | Q45: 3 | R45: 1 | S45: 4 | T45: 2 | U45: 4 | V45: 8 | W45: 7 | X45: 3 | Y45: 4 | Z45: 5 | AA45: 0 | AB45: 1 | AC45: 5 | AD45: 1 | AE45: 8 | AF45: 3 | AG45: 2 | AH45: 4 | AI45: 1 | AJ45: 6 | AK45: 1 | AL45: 3 | AM45: 4 | AN45: 0 | AO45: 0 | AP45: 1 | AQ45: 0 | AR45: 2 | AS45: 1 | AT45: 0 | AU45: 1 | AV45: 1 | AW45: 5 | AX45: 1 | AY45: 2 | AZ45: 8 | BA45: 4 | BB45: 2 | BC45: 3 | BD45: 8 | BE45: 7 | BF45: 7 | BG45: 4 | BH45: 8 | BI45: 12 | BJ45: 10 | BK45: =SUM(E45:BJ45) -> 215
A46: A.2 | C46: 1. H. KHUSNAN, S.Ag., M.Pd.I. | E46: 2 | F46: 2 | G46: 2 | H46: 21 | I46: 5 | J46: 7 | K46: 7 | L46: 6 | M46: 1 | N46: 3 | O46: 1 | P46: 11 | Q46: 6 | R46: 4 | S46: 5 | T46: 3 | U46: 14 | V46: 36 | W46: 42 | X46: 11 | Y46: 3 | Z46: 9 | AA46: 5 | AB46: 3 | AC46: 2 | AD46: 4 | AE46: 13 | AF46: 0 | AG46: 8 | AH46: 2 | AI46: 8 | AJ46: 4 | AK46: 0 | AL46: 1 | AM46: 0 | AN46: 2 | AO46: 3 | AP46: 0 | AQ46: 2 | AR46: 2 | AS46: 4 | AT46: 1 | AU46: 4 | AV46: 2 | AW46: 4 | AX46: 1 | AY46: 2 | AZ46: 5 | BA46: 4 | BB46: 4 | BC46: 1 | BD46: 2 | BE46: 14 | BF46: 10 | BG46: 7 | BH46: 13 | BI46: 28 | BJ46: 12 | BK46: =SUM(E46:BJ46) -> 378
C47: 2. MARA QONITHA LAYLIA | E47: 2 | F47: 1 | G47: 1 | H47: 1 | I47: 1 | J47: 2 | K47: 17 | L47: 1 | M47: 2 | N47: 0 | O47: 5 | P47: 5 | Q47: 0 | R47: 1 | S47: 2 | T47: 1 | U47: 2 | V47: 0 | W47: 2 | X47: 0 | Y47: 0 | Z47: 2 | AA47: 0 | AB47: 0 | AC47: 1 | AD47: 2 | AE47: 1 | AF47: 1 | AG47: 15 | AH47: 0 | AI47: 0 | AJ47: 2 | AK47: 0 | AL47: 0 | AM47: 0 | AN47: 1 | AO47: 0 | AP47: 0 | AQ47: 0 | AR47: 0 | AS47: 2 | AT47: 0 | AU47: 1 | AV47: 0 | AW47: 0 | AX47: 3 | AY47: 4 | AZ47: 3 | BA47: 0 | BB47: 2 | BC47: 1 | BD47: 4 | BE47: 9 | BF47: 7 | BG47: 4 | BH47: 2 | BI47: 1 | BJ47: 8 | BK47: =SUM(E47:BJ47) -> 122
C48: 3. ZAKI AL MUBAROK, M.Si. | E48: 1 | F48: 9 | G48: 0 | H48: 0 | I48: 3 | J48: 0 | K48: 2 | L48: 0 | M48: 0 | N48: 1 | O48: 3 | P48: 0 | Q48: 5 | R48: 0 | S48: 2 | T48: 1 | U48: 6 | V48: 9 | W48: 5 | X48: 0 | Y48: 1 | Z48: 8 | AA48: 11 | AB48: 15 | AC48: 25 | AD48: 10 | AE48: 3 | AF48: 4 | AG48: 0 | AH48: 2 | AI48: 4 | AJ48: 0 | AK48: 0 | AL48: 9 | AM48: 2 | AN48: 5 | AO48: 1 | AP48: 2 | AQ48: 0 | AR48: 1 | AS48: 2 | AT48: 1 | AU48: 1 | AV48: 1 | AW48: 8 | AX48: 5 | AY48: 51 | AZ48: 65 | BA48: 99 | BB48: 65 | BC48: 65 | BD48: 88 | BE48: 29 | BF48: 24 | BG48: 25 | BH48: 46 | BI48: 50 | BJ48: 71 | BK48: =SUM(E48:BJ48) -> 846
C49: 4. INAYATUL MAHMUDAH, S.Pd. | E49: 0 | F49: 0 | G49: 0 | H49: 0 | I49: 2 | J49: 0 | K49: 0 | L49: 0 | M49: 0 | N49: 0 | O49: 1 | P49: 0 | Q49: 0 | R49: 1 | S49: 0 | T49: 0 | U49: 0 | V49: 0 | W49: 0 | X49: 0 | Y49: 0 | Z49: 0 | AA49: 0 | AB49: 0 | AC49: 1 | AD49: 0 | AE49: 1 | AF49: 2 | AG49: 0 | AH49: 0 | AI49: 1 | AJ49: 0 | AK49: 0 | AL49: 0 | AM49: 1 | AN49: 1 | AO49: 0 | AP49: 0 | AQ49: 0 | AR49: 0 | AS49: 0 | AT49: 0 | AU49: 0 | AV49: 0 | AW49: 1 | AX49: 0 | AY49: 0 | AZ49: 3 | BA49: 2 | BB49: 2 | BC49: 2 | BD49: 1 | BE49: 0 | BF49: 0 | BG49: 1 | BH49: 2 | BI49: 0 | BJ49: 1 | BK49: =SUM(E49:BJ49) -> 26
C50: 5. HABIBURRAHMAN AL KHOLILI | E50: 0 | F50: 0 | G50: 0 | H50: 1 | I50: 0 | J50: 0 | K50: 1 | L50: 0 | M50: 0 | N50: 0 | O50: 0 | P50: 0 | Q50: 0 | R50: 0 | S50: 0 | T50: 0 | U50: 1 | V50: 1 | W50: 0 | X50: 0 | Y50: 0 | Z50: 0 | AA50: 0 | AB50: 0 | AC50: 0 | AD50: 0 | AE50: 0 | AF50: 0 | AG50: 0 | AH50: 0 | AI50: 1 | AJ50: 0 | AK50: 0 | AL50: 0 | AM50: 0 | AN50: 0 | AO50: 1 | AP50: 0 | AQ50: 0 | AR50: 0 | AS50: 0 | AT50: 1 | AU50: 0 | AV50: 1 | AW50: 0 | AX50: 0 | AY50: 1 | AZ50: 0 | BA50: 0 | BB50: 0 | BC50: 0 | BD50: 0 | BE50: 0 | BF50: 0 | BG50: 1 | BH50: 0 | BI50: 0 | BJ50: 1 | BK50: =SUM(E50:BJ50) -> 11
C51: 6. INDIARTI NOVIDA, A.Md. | E51: 0 | F51: 0 | G51: 0 | H51: 0 | I51: 0 | J51: 0 | K51: 0 | L51: 0 | M51: 0 | N51: 0 | O51: 1 | P51: 0 | Q51: 0 | R51: 0 | S51: 0 | T51: 0 | U51: 0 | V51: 0 | W51: 1 | X51: 0 | Y51: 0 | Z51: 0 | AA51: 0 | AB51: 0 | AC51: 0 | AD51: 0 | AE51: 0 | AF51: 0 | AG51: 0 | AH51: 0 | AI51: 0 | AJ51: 1 | AK51: 0 | AL51: 0 | AM51: 0 | AN51: 0 | AO51: 0 | AP51: 0 | AQ51: 0 | AR51: 0 | AS51: 0 | AT51: 0 | AU51: 0 | AV51: 0 | AW51: 0 | AX51: 0 | AY51: 0 | AZ51: 0 | BA51: 0 | BB51: 0 | BC51: 0 | BD51: 0 | BE51: 0 | BF51: 0 | BG51: 0 | BH51: 0 | BI51: 0 | BJ51: 0 | BK51: =SUM(E51:BJ51) -> 3
...

Sheet GENTENG WETAN
C2: Kecamatan | D2: GENTENG
C3: Kabupaten | D3: BANYUWANGI
C4: Provinsi | D4: JAWA TIMUR
C9: Kelurahan | D9: GENTENG WETAN
A12: I | B12: DATA PEMILIH DAN PENGGUNAAN HAK PILIH | BL12: JUMLAH AKHIR
A13: A | B13: DATA PEMILIH | E13: TPS 001 | F13: TPS 002 | G13: TPS 003 | H13: TPS 004 | I13: TPS 005 | J13: TPS 006 | K13: TPS 007 | L13: TPS 008 | M13: TPS 009 | N13: TPS 010 | O13: TPS 011 | P13: TPS 012 | Q13: TPS 013 | R13: TPS 014 | S13: TPS 015 | T13: TPS 016 | U13: TPS 017 | V13: TPS 018 | W13: TPS 019 | X13: TPS 020 | Y13: TPS 021 | Z13: TPS 022 | AA13: TPS 023 | AB13: TPS 024 | AC13: TPS 025 | AD13: TPS 026 | AE13: TPS 027 | AF13: TPS 028 | AG13: TPS 029 | AH13: TPS 030 | AI13: TPS 031 | AJ13: TPS 032 | AK13: TPS 033 | AL13: TPS 034 | AM13: TPS 035 | AN13: TPS 036 | AO13: TPS 037 | AP13: TPS 038 | AQ13: TPS 039 | AR13: TPS 040 | AS13: TPS 041 | AT13: TPS 042 | AU13: TPS 043 | AV13: TPS 044 | AW13: TPS 045 | AX13: TPS 046 | AY13: TPS 047 | AZ13: TPS 048 | BA13: TPS 049 | BB13: TPS 050 | BC13: TPS 051 | BD13: TPS 052 | BE13: TPS 053 | BF13: TPS 054 | BG13: TPS 055 | BH13: TPS 056 | BI13: TPS 057 | BJ13: TPS 058 | BK13: TPS 059
B14: Jumlah Pemilih dalam Daftar Pemilih Tetap (DPT) | D14: LK | E14: 135 | F14: 138 | G14: 127 | H14: 144 | I14: 151 | J14: 137 | K14: 134 | L14: 144 | M14: 137 | N14: 140 | O14: 137 | P14: 141 | Q14: 142 | R14: 129 | S14: 138 | T14: 149 | U14: 151 | V14: 148 | W14: 151 | X14: 143 | Y14: 141 | Z14: 154 | AA14: 147 | AB14: 148 | AC14: 153 | AD14: 139 | AE14: 134 | AF14: 130 | AG14: 126 | AH14: 135 | AI14: 107 | AJ14: 120 | AK14: 109 | AL14: 145 | AM14: 117 | AN14: 116 | AO14: 121 | AP14: 118 | AQ14: 125 | AR14: 132 | AS14: 110 | AT14: 119 | AU14: 119 | AV14: 139 | AW14: 124 | AX14: 140 | AY14: 134 | AZ14: 141 | BA14: 148 | BB14: 138 | BC14: 140 | BD14: 131 | BE14: 143 | BF14: 135 | BG14: 121 | BH14: 152 | BI14: 141 | BJ14: 140 | BK14: 126 | BL14: =SUM(E14:BK14) -> 7974
D15: PR | E15: 137 | F15: 150 | G15: 144 | H15: 133 | I15: 142 | J15: 127 | K15: 141 | L15: 126 | M15: 150 | N15: 112 | O15: 145 | P15: 124 | Q15: 122 | R15: 114 | S15: 151 | T15: 145 | U15: 130 | V15: 139 | W15: 128 | X15: 151 | Y15: 132 | Z15: 134 | AA15: 140 | AB15: 146 | AC15: 141 | AD15: 139 | AE15: 129 | AF15: 123 | AG15: 148 | AH15: 138 | AI15: 101 | AJ15: 112 | AK15: 117 | AL15: 146 | AM15: 128 | AN15: 126 | AO15: 122 | AP15: 129 | AQ15: 152 | AR15: 133 | AS15: 114 | AT15: 98 | AU15: 115 | AV15: 147 | AW15: 126 | AX15: 139 | AY15: 138 | AZ15: 139 | BA15: 144 | BB15: 136 | BC15: 132 | BD15: 144 | BE15: 132 | BF15: 144 | BG15: 134 | BH15: 141 | BI15: 140 | BJ15: 143 | BK15: 156 | BL15: =SUM(E15:BK15) -> 7909
D16: JML | E16: =SUM(E14:E15) -> 272 | F16: =SUM(F14:F15) -> 288 | G16: =SUM(G14:G15) -> 271 | H16: =SUM(H14:H15) -> 277 | I16: =SUM(I14:I15) -> 293 | J16: =SUM(J14:J15) -> 264 | K16: =SUM(K14:K15) -> 275 | L16: =SUM(L14:L15) -> 270 | ... BK16: =SUM(BK14:BK15) -> 282 | BL16: =SUM(E16:BK16) -> 15883
A18: B | B18: PENGGUNA HAK PILIH
B19: 1. | C19: Jumlah pengguna hak pilih dalam Daftar Pemilih Tetap (DPT) | D19: LK | E19: 85 | F19: 99 | G19: 93 | H19: 108 | I19: 112 | J19: 104 | K19: 91 | L19: 115 | M19: 112 | N19: 98 | O19: 97 | P19: 96 | Q19: 118 | R19: 99 | S19: 93 | T19: 106 | U19: 107 | V19: 106 | W19: 116 | X19: 109 | Y19: 87 | Z19: 99 | AA19: 101 | AB19: 105 | AC19: 104 | AD19: 109 | AE19: 109 | AF19: 102 | AG19: 102 | AH19: 96 | AI19: 70 | AJ19: 92 | AK19: 78 | AL19: 105 | AM19: 86 | AN19: 86 | AO19: 90 | AP19: 79 | AQ19: 90 | AR19: 97 | AS19: 80 | AT19: 80 | AU19: 77 | AV19: 86 | AW19: 97 | AX19: 109 | AY19: 84 | AZ19: 101 | BA19: 106 | BB19: 91 | BC19: 92 | BD19: 91 | BE19: 81 | BF19: 81 | BG19: 83 | BH19: 123 | BI19: 101 | BJ19: 90 | BK19: 88 | BL19: =SUM(E19:BK19) -> 5692
D20: PR | E20: 93 | F20: 127 | G20: 117 | H20: 112 | I20: 113 | J20: 104 | K20: 107 | L20: 103 | M20: 108 | N20: 93 | O20: 119 | P20: 100 | Q20: 105 | R20: 92 | S20: 109 | T20: 111 | U20: 100 | V20: 118 | W20: 100 | X20: 122 | Y20: 101 | Z20: 112 | AA20: 108 | AB20: 109 | AC20: 110 | AD20: 103 | AE20: 102 | AF20: 102 | AG20: 115 | AH20: 105 | AI20: 76 | AJ20: 85 | AK20: 89 | AL20: 112 | AM20: 98 | AN20: 106 | AO20: 91 | AP20: 96 | AQ20: 120 | AR20: 101 | AS20: 82 | AT20: 70 | AU20: 91 | AV20: 102 | AW20: 95 | AX20: 115 | AY20: 103 | AZ20: 110 | BA20: 109 | BB20: 113 | BC20: 88 | BD20: 107 | BE20: 82 | BF20: 103 | BG20: 99 | BH20: 117 | BI20: 110 | BJ20: 103 | BK20: 112 | BL20: =SUM(E20:BK20) -> 6105
D21: JML | E21: =SUM(E19:E20) -> 178 | F21: =SUM(F19:F20) -> 226 | G21: =SUM(G19:G20) -> 210 | H21: =SUM(H19:H20) -> 220 | I21: =SUM(I19:I20) -> 225 | J21: =SUM(J19:J20) -> 208 | K21: =SUM(K19:K20) -> 198 | L21: =SUM(L19:L20) -> 218 | ... BK21: =SUM(BK19:BK20) -> 200 | BL21: =SUM(E21:BK21) -> 11797
B22: 2. | C22: Jumlah pengguna hak pilih dalam Daftar Pemilih Tambahan (DPTb) | D22: LK | E22: 0 | F22: 0 | G22: 1 | H22: 0 | I22: 1 | J22: 3 | K22: 0 | L22: 0 | M22: 1 | N22: 0 | O22: 1 | P22: 0 | Q22: 0 | R22: 0 | S22: 0 | T22: 1 | U22: 0 | V22: 0 | W22: 2 | X22: 0 | Y22: 0 | Z22: 0 | AA22: 0 | AB22: 0 | AC22: 1 | AD22: 0 | AE22: 0 | AF22: 0 | AG22: 0 | AH22: 0 | AI22: 0 | AJ22: 0 | AK22: 0 | AL22: 1 | AM22: 0 | AN22: 0 | AO22: 0 | AP22: 0 | AQ22: 0 | AR22: 0 | AS22: 0 | AT22: 0 | AU22: 1 | AV22: 0 | AW22: 0 | AX22: 0 | AY22: 0 | AZ22: 0 | BA22: 0 | BB22: 0 | BC22: 0 | BD22: 0 | BE22: 0 | BF22: 1 | BG22: 1 | BH22: 0 | BI22: 0 | BJ22: 1 | BK22: 0 | BL22: =SUM(E22:BK22) -> 16
D23: PR | E23: 0 | F23: 0 | G23: 0 | H23: 0 | I23: 0 | J23: 1 | K23: 0 | L23: 0 | M23: 3 | N23: 0 | O23: 0 | P23: 0 | Q23: 0 | R23: 0 | S23: 0 | T23: 1 | U23: 0 | V23: 0 | W23: 1 | X23: 0 | Y23: 0 | Z23: 0 | AA23: 0 | AB23: 0 | AC23: 0 | AD23: 0 | AE23: 1 | AF23: 0 | AG23: 0 | AH23: 0 | AI23: 1 | AJ23: 1 | AK23: 0 | AL23: 0 | AM23: 1 | AN23: 1 | AO23: 1 | AP23: 0 | AQ23: 0 | AR23: 0 | AS23: 0 | AT23: 1 | AU23: 0 | AV23: 1 | AW23: 0 | AX23: 0 | AY23: 1 | AZ23: 0 | BA23: 0 | BB23: 1 | BC23: 0 | BD23: 0 | BE23: 0 | BF23: 0 | BG23: 0 | BH23: 0 | BI23: 0 | BJ23: 0 | BK23: 0 | BL23: =SUM(E23:BK23) -> 16
D24: JML | E24: =SUM(E22:E23) -> 0 | F24: =SUM(F22:F23) -> 0 | G24: =SUM(G22:G23) -> 1 | H24: =SUM(H22:H23) -> 0 | I24: =SUM(I22:I23) -> 1 | J24: =SUM(J22:J23) -> 4 | K24: =SUM(K22:K23) -> 0 | L24: =SUM(L22:L23) -> 0 | ... BK24: =SUM(BK22:BK23) -> 0 | BL24: =SUM(E24:BK24) -> 32
B25: 3. | C25: Jumlah pengguna hak pilih dalam Daftar Pemilih Khusus (DPK) | D25: LK | E25: 2 | F25: 0 | G25: 0 | H25: 0 | I25: 2 | J25: 0 | K25: 1 | L25: 0 | M25: 0 | N25: 1 | O25: 1 | P25: 4 | Q25: 3 | R25: 1 | S25: 2 | T25: 2 | U25: 3 | V25: 2 | W25: 5 | X25: 0 | Y25: 5 | Z25: 0 | AA25: 0 | AB25: 5 | AC25: 1 | AD25: 2 | AE25: 0 | AF25: 2 | AG25: 1 | AH25: 0 | AI25: 2 | AJ25: 0 | AK25: 1 | AL25: 0 | AM25: 0 | AN25: 0 | AO25: 1 | AP25: 0 | AQ25: 0 | AR25: 3 | AS25: 1 | AT25: 4 | AU25: 1 | AV25: 4 | AW25: 0 | AX25: 0 | AY25: 0 | AZ25: 0 | BA25: 0 | BB25: 0 | BC25: 2 | BD25: 3 | BE25: 0 | BF25: 4 | BG25: 1 | BH25: 0 | BI25: 0 | BJ25: 1 | BK25: 2 | BL25: =SUM(E25:BK25) -> 75
D26: PR | E26: 1 | F26: 0 | G26: 0 | H26: 1 | I26: 1 | J26: 1 | K26: 0 | L26: 3 | M26: 0 | N26: 2 | O26: 2 | P26: 3 | Q26: 4 | R26: 5 | S26: 5 | T26: 3 | U26: 4 | V26: 2 | W26: 4 | X26: 1 | Y26: 0 | Z26: 3 | AA26: 4 | AB26: 3 | AC26: 4 | AD26: 3 | AE26: 3 | AF26: 2 | AG26: 4 | AH26: 0 | AI26: 1 | AJ26: 1 | AK26: 3 | AL26: 2 | AM26: 2 | AN26: 0 | AO26: 5 | AP26: 0 | AQ26: 1 | AR26: 2 | AS26: 1 | AT26: 2 | AU26: 2 | AV26: 5 | AW26: 2 | AX26: 0 | AY26: 0 | AZ26: 0 | BA26: 0 | BB26: 0 | BC26: 3 | BD26: 2 | BE26: 1 | BF26: 5 | BG26: 0 | BH26: 0 | BI26: 0 | BJ26: 1 | BK26: 6 | BL26: =SUM(E26:BK26) -> 115
D27: JML | E27: =SUM(E25:E26) -> 3 | F27: =SUM(F25:F26) -> 0 | G27: =SUM(G25:G26) -> 0 | H27: =SUM(H25:H26) -> 1 | I27: =SUM(I25:I26) -> 3 | J27: =SUM(J25:J26) -> 1 | K27: =SUM(K25:K26) -> 1 | L27: =SUM(L25:L26) -> 3 | ... BK27: =SUM(BK25:BK26) -> 8 | BL27: =SUM(E27:BK27) -> 190
B28: 4. | C28: Jumlah Pengguna Hak Pilih (B.1+B.2+B.3) | D28: LK | E28: =SUM(E19,E22,E25) -> 87 | F28: =SUM(F19,F22,F25) -> 99 | G28: =SUM(G19,G22,G25) -> 94 | H28: =SUM(H19,H22,H25) -> 108 | I28: =SUM(I19,I22,I25) -> 115 | J28: =SUM(J19,J22,J25) -> 107 | K28: =SUM(K19,K22,K25) -> 92 | L28: =SUM(L19,L22,L25) -> 115 | ... BK28: =SUM(BK19,BK22,BK25) -> 90 | BL28: =SUM(E28:BK28) -> 5783
D29: PR | E29: =SUM(E20,E23,E26) -> 94 | F29: =SUM(F20,F23,F26) -> 127 | G29: =SUM(G20,G23,G26) -> 117 | H29: =SUM(H20,H23,H26) -> 113 | I29: =SUM(I20,I23,I26) -> 114 | J29: =SUM(J20,J23,J26) -> 106 | K29: =SUM(K20,K23,K26) -> 107 | L29: =SUM(L20,L23,L26) -> 106 | ... BK29: =SUM(BK20,BK23,BK26) -> 118 | BL29: =SUM(E29:BK29) -> 6236
D30: JML | E30: =SUM(E28:E29) -> 181 | F30: =SUM(F28:F29) -> 226 | G30: =SUM(G28:G29) -> 211 | H30: =SUM(H28:H29) -> 221 | I30: =SUM(I28:I29) -> 229 | J30: =SUM(J28:J29) -> 213 | K30: =SUM(K28:K29) -> 199 | L30: =SUM(L28:L29) -> 221 | ... BK30: =SUM(BK28:BK29) -> 208 | BL30: =SUM(E30:BK30) -> 12019
A32: II | B32: DATA PENGGUNAAN SURAT SUARA
A33: 1 | B33: Jumlah surat suara yang diterima, termasuk surat suara cadangan 2,5% dari DPT | E33: 278 | F33: 294 | G33: 277 | H33: 284 | I33: 288 | J33: 269 | K33: 281 | L33: 276 | M33: 294 | N33: 257 | O33: 288 | P33: 269 | Q33: 271 | R33: 248 | S33: 289 | T33: 300 | U33: 287 | V33: 293 | W33: 295 | X33: 300 | Y33: 279 | Z33: 294 | AA33: 293 | AB33: 291 | AC33: 300 | AD33: 294 | AE33: 269 | AF33: 259 | AG33: 279 | AH33: 279 | AI33: 192 | AJ33: 235 | AK33: 231 | AL33: 297 | AM33: 260 | AN33: 247 | AO33: 248 | AP33: 252 | AQ33: 282 | AR33: 273 | AS33: 231 | AT33: 242 | AU33: 240 | AV33: 286 | AW33: 235 | AX33: 285 | AY33: 278 | AZ33: 266 | BA33: 297 | BB33: 278 | BC33: 278 | BD33: 281 | BE33: 281 | BF33: 287 | BG33: 261 | BH33: 299 | BI33: 287 | BJ33: 269 | BK33: 248 | BL33: =SUM(E33:BK33) -> 16121
A34: 2 | B34: Jumlah surat suara yang digunakan | E34: 181 | F34: 226 | G34: 211 | H34: 221 | I34: 229 | J34: 213 | K34: 199 | L34: 221 | M34: 224 | N34: 194 | O34: 220 | P34: 203 | Q34: 230 | R34: 197 | S34: 209 | T34: 224 | U34: 214 | V34: 228 | W34: 228 | X34: 232 | Y34: 193 | Z34: 214 | AA34: 213 | AB34: 222 | AC34: 220 | AD34: 217 | AE34: 215 | AF34: 208 | AG34: 222 | AH34: 201 | AI34: 150 | AJ34: 179 | AK34: 171 | AL34: 220 | AM34: 187 | AN34: 193 | AO34: 188 | AP34: 175 | AQ34: 211 | AR34: 203 | AS34: 164 | AT34: 157 | AU34: 172 | AV34: 198 | AW34: 194 | AX34: 224 | AY34: 188 | AZ34: 211 | BA34: 215 | BB34: 205 | BC34: 185 | BD34: 203 | BE34: 164 | BF34: 194 | BG34: 184 | BH34: 240 | BI34: 211 | BJ34: 196 | BK34: 208 | BL34: =SUM(E34:BK34) -> 12019
A35: 3 | B35: Jumlah surat suara dikembalikan oleh pemilih (karena rusak atau keliru coblos) | E35: 1 | F35: 0 | G35: 0 | H35: 0 | I35: 0 | J35: 0 | K35: 1 | L35: 0 | M35: 0 | N35: 0 | O35: 3 | P35: 3 | Q35: 0 | R35: 0 | S35: 0 | T35: 0 | U35: 0 | V35: 0 | W35: 0 | X35: 0 | Y35: 0 | Z35: 0 | AA35: 0 | AB35: 0 | AC35: 0 | AD35: 0 | AE35: 0 | AF35: 0 | AG35: 0 | AH35: 1 | AI35: 0 | AJ35: 0 | AK35: 2 | AL35: 0 | AM35: 0 | AN35: 1 | AO35: 1 | AP35: 0 | AQ35: 0 | AR35: 1 | AS35: 0 | AT35: 0 | AU35: 1 | AV35: 0 | AW35: 0 | AX35: 0 | AY35: 0 | AZ35: 0 | BA35: 0 | BB35: 1 | BC35: 0 | BD35: 1 | BE35: 0 | BF35: 2 | BG35: 0 | BH35: 0 | BI35: 0 | BJ35: 0 | BK35: 2 | BL35: =SUM(E35:BK35) -> 21
A36: 4 | B36: Jumlah surat suara yang tidak digunakan/tidak terpakai, termasuk sisa surat suara cadangan | E36: =E33-(E34+E35) -> 96 | F36: =F33-(F34+F35) -> 68 | G36: =G33-(G34+G35) -> 66 | H36: =H33-(H34+H35) -> 63 | I36: =I33-(I34+I35) -> 59 | J36: =J33-(J34+J35) -> 56 | K36: =K33-(K34+K35) -> 81 | L36: =L33-(L34+L35) -> 55 | ... BK36: =BK33-(BK34+BK35) -> 38 | BL36: =SUM(E36:BK36) -> 4081
A38: III | B38: DATA PEMILIH DISABILITAS
B39: Jumlah seluruh Pemilih disabilitas yang menggunakan hak pilih | D39: LK | T39: 0 | U39: 0 | V39: 0 | W39: 1 | X39: 0 | Y39: 0 | Z39: 0 | AA39: 0 | AB39: 0 | AC39: 0 | AD39: 0 | AE39: 0 | AF39: 0 | AG39: 0 | AH39: 2 | AI39: 0 | AJ39: 0 | AK39: 2 | AL39: 0 | AM39: 2 | AN39: 0 | AO39: 4 | AP39: 0 | AQ39: 0 | AR39: 0 | AS39: 0 | AT39: 0 | AU39: 0 | AV39: 0 | AW39: 1 | AX39: 0 | AY39: 0 | AZ39: 0 | BA39: 0 | BB39: 0 | BC39: 0 | BD39: 0 | BE39: 0 | BF39: 1 | BG39: 0 | BH39: 0 | BI39: 1 | BJ39: 0 | BK39: 0 | BL39: =SUM(E39:BK39) -> 14
D40: PR | T40: 0 | U40: 0 | V40: 0 | W40: 2 | X40: 1 | Y40: 0 | Z40: 0 | AA40: 0 | AB40: 0 | AC40: 0 | AD40: 0 | AE40: 0 | AF40: 0 | AG40: 0 | AH40: 3 | AI40: 0 | AJ40: 0 | AK40: 4 | AL40: 0 | AM40: 0 | AN40: 0 | AO40: 0 | AP40: 0 | AQ40: 1 | AR40: 0 | AS40: 0 | AT40: 0 | AU40: 0 | AV40: 0 | AW40: 2 | AX40: 0 | AY40: 0 | AZ40: 1 | BA40: 0 | BB40: 0 | BC40: 0 | BD40: 0 | BE40: 0 | BF40: 1 | BG40: 1 | BH40: 1 | BI40: 0 | BJ40: 0 | BK40: 0 | BL40: =SUM(E40:BK40) -> 17
D41: JML | E41: =SUM(E39:E40) -> 0 | F41: =SUM(F39:F40) -> 0 | G41: =SUM(G39:G40) -> 0 | H41: =SUM(H39:H40) -> 0 | I41: =SUM(I39:I40) -> 0 | J41: =SUM(J39:J40) -> 0 | K41: =SUM(K39:K40) -> 0 | L41: =SUM(L39:L40) -> 0 | ... BK41: =SUM(BK39:BK40) -> 0 | BL41: =SUM(E41:BK41) -> 31
A43: IV | B43: DATA RINCIAN PEROLEHAN SUARA PASANGAN CALON BUPATI DAN WAKIL BUPATI
A44: NOMOR DAN NAMA CALON
A45: A.1 | B45: 1. | C45: Partai Kebangkitan Bangsa | E45: 4 | F45: 7 | G45: 2 | H45: 3 | I45: 4 | J45: 10 | K45: 10 | L45: 7 | M45: 7 | N45: 13 | O45: 7 | P45: 13 | Q45: 2 | R45: 9 | S45: 2 | T45: 2 | U45: 5 | V45: 6 | W45: 9 | X45: 13 | Y45: 10 | Z45: 13 | AA45: 10 | AB45: 11 | AC45: 7 | AD45: 5 | AE45: 2 | AF45: 2 | AG45: 5 | AH45: 3 | AI45: 4 | AJ45: 2 | AK45: 4 | AL45: 8 | AM45: 3 | AN45: 5 | AO45: 2 | AP45: 2 | AQ45: 11 | AR45: 6 | AS45: 4 | AT45: 11 | AU45: 10 | AV45: 9 | AW45: 7 | AX45: 0 | AY45: 6 | AZ45: 5 | BA45: 8 | BB45: 8 | BC45: 9 | BD45: 0 | BE45: 5 | BF45: 2 | BG45: 14 | BH45: 15 | BI45: 0 | BJ45: 7 | BK45: 4 | BL45: =SUM(E45:BK45) -> 374
A46: A.2 | C46: 1. H. KHUSNAN, S.Ag., M.Pd.I. | E46: 10 | F46: 13 | G46: 17 | H46: 21 | I46: 25 | J46: 8 | K46: 17 | L46: 8 | M46: 15 | N46: 17 | O46: 25 | P46: 25 | Q46: 16 | R46: 9 | S46: 11 | T46: 13 | U46: 9 | V46: 35 | W46: 38 | X46: 29 | Y46: 34 | Z46: 37 | AA46: 20 | AB46: 7 | AC46: 26 | AD46: 12 | AE46: 5 | AF46: 3 | AG46: 1 | AH46: 16 | AI46: 11 | AJ46: 1 | AK46: 0 | AL46: 12 | AM46: 8 | AN46: 6 | AO46: 10 | AP46: 0 | AQ46: 12 | AR46: 4 | AS46: 0 | AT46: 5 | AU46: 19 | AV46: 17 | AW46: 7 | AX46: 4 | AY46: 11 | AZ46: 9 | BA46: 9 | BB46: 15 | BC46: 7 | BD46: 8 | BE46: 3 | BF46: 9 | BG46: 36 | BH46: 63 | BI46: 2 | BJ46: 1 | BK46: 3 | BL46: =SUM(E46:BK46) -> 814
C47: 2. MARA QONITHA LAYLIA | E47: 2 | F47: 0 | G47: 1 | H47: 0 | I47: 5 | J47: 3 | K47: 4 | L47: 3 | M47: 0 | N47: 2 | O47: 2 | P47: 2 | Q47: 1 | R47: 0 | S47: 0 | T47: 1 | U47: 5 | V47: 0 | W47: 1 | X47: 0 | Y47: 4 | Z47: 1 | AA47: 4 | AB47: 0 | AC47: 8 | AD47: 3 | AE47: 1 | AF47: 0 | AG47: 2 | AH47: 3 | AI47: 0 | AJ47: 4 | AK47: 1 | AL47: 5 | AM47: 6 | AN47: 6 | AO47: 2 | AP47: 1 | AQ47: 3 | AR47: 0 | AS47: 0 | AT47: 3 | AU47: 3 | AV47: 3 | AW47: 0 | AX47: 1 | AY47: 0 | AZ47: 0 | BA47: 4 | BB47: 5 | BC47: 1 | BD47: 0 | BE47: 0 | BF47: 4 | BG47: 0 | BH47: 3 | BI47: 2 | BJ47: 0 | BK47: 4 | BL47: =SUM(E47:BK47) -> 119
C48: 3. ZAKI AL MUBAROK, M.Si. | E48: 7 | F48: 14 | G48: 3 | H48: 18 | I48: 9 | J48: 1 | K48: 7 | L48: 22 | M48: 15 | N48: 8 | O48: 12 | P48: 11 | Q48: 3 | R48: 11 | S48: 12 | T48: 13 | U48: 19 | V48: 18 | W48: 18 | X48: 28 | Y48: 17 | Z48: 24 | AA48: 38 | AB48: 50 | AC48: 30 | AD48: 12 | AE48: 13 | AF48: 0 | AG48: 8 | AH48: 0 | AI48: 3 | AJ48: 2 | AK48: 6 | AL48: 11 | AM48: 3 | AN48: 3 | AO48: 21 | AP48: 5 | AQ48: 13 | AR48: 19 | AS48: 4 | AT48: 6 | AU48: 8 | AV48: 6 | AW48: 8 | AX48: 5 | AY48: 23 | AZ48: 19 | BA48: 2 | BB48: 3 | BC48: 1 | BD48: 2 | BE48: 5 | BF48: 1 | BG48: 2 | BH48: 4 | BI48: 4 | BJ48: 0 | BK48: 7 | BL48: =SUM(E48:BK48) -> 637
C49: 4. INAYATUL MAHMUDAH, S.Pd. | E49: 2 | F49: 1 | G49: 2 | H49: 0 | I49: 1 | J49: 1 | K49: 2 | L49: 2 | M49: 1 | N49: 0 | O49: 2 | P49: 2 | Q49: 0 | R49: 2 | S49: 0 | T49: 1 | U49: 1 | V49: 1 | W49: 3 | X49: 1 | Y49: 0 | Z49: 1 | AA49: 2 | AB49: 2 | AC49: 2 | AD49: 0 | AE49: 4 | AF49: 1 | AG49: 1 | AH49: 0 | AI49: 0 | AJ49: 0 | AK49: 0 | AL49: 0 | AM49: 5 | AN49: 1 | AO49: 2 | AP49: 0 | AQ49: 2 | AR49: 0 | AS49: 1 | AT49: 1 | AU49: 0 | AV49: 0 | AW49: 0 | AX49: 0 | AY49: 0 | AZ49: 0 | BA49: 1 | BB49: 0 | BC49: 1 | BD49: 0 | BE49: 3 | BF49: 1 | BG49: 0 | BH49: 0 | BI49: 0 | BJ49: 0 | BK49: 1 | BL49: =SUM(E49:BK49) -> 57
C50: 5. HABIBURRAHMAN AL KHOLILI | E50: 1 | F50: 0 | G50: 1 | H50: 1 | I50: 0 | J50: 0 | K50: 0 | L50: 1 | M50: 0 | N50: 0 | O50: 1 | P50: 0 | Q50: 1 | R50: 0 | S50: 0 | T50: 1 | U50: 0 | V50: 1 | W50: 3 | X50: 4 | Y50: 0 | Z50: 0 | AA50: 0 | AB50: 0 | AC50: 0 | AD50: 1 | AE50: 0 | AF50: 0 | AG50: 0 | AH50: 1 | AI50: 0 | AJ50: 0 | AK50: 0 | AL50: 1 | AM50: 0 | AN50: 1 | AO50: 0 | AP50: 0 | AQ50: 0 | AR50: 0 | AS50: 0 | AT50: 0 | AU50: 0 | AV50: 1 | AW50: 1 | AX50: 2 | AY50: 0 | AZ50: 1 | BA50: 0 | BB50: 1 | BC50: 0 | BD50: 2 | BE50: 0 | BF50: 0 | BG50: 0 | BH50: 0 | BI50: 0 | BJ50: 0 | BK50: 0 | BL50: =SUM(E50:BK50) -> 27
C51: 6. INDIARTI NOVIDA, A.Md. | E51: 2 | F51: 0 | G51: 1 | H51: 0 | I51: 0 | J51: 0 | K51: 0 | L51: 0 | M51: 0 | N51: 0 | O51: 0 | P51: 2 | Q51: 1 | R51: 0 | S51: 0 | T51: 0 | U51: 0 | V51: 0 | W51: 0 | X51: 0 | Y51: 0 | Z51: 0 | AA51: 0 | AB51: 0 | AC51: 0 | AD51: 0 | AE51: 0 | AF51: 0 | AG51: 0 | AH51: 0 | AI51: 0 | AJ51: 0 | AK51: 0 | AL51: 0 | AM51: 0 | AN51: 0 | AO51: 0 | AP51: 0 | AQ51: 0 | AR51: 0 | AS51: 2 | AT51: 0 | AU51: 0 | AV51: 0 | AW51: 0 | AX51: 0 | AY51: 0 | AZ51: 0 | BA51: 0 | BB51: 1 | BC51: 0 | BD51: 0 | BE51: 0 | BF51: 0 | BG51: 0 | BH51: 0 | BI51: 0 | BJ51: 0 | BK51: 0 | BL51: =SUM(E51:BK51) -> 9
...

Sheet KALIGONDO
C2: Kecamatan | D2: GENTENG
C3: Kabupaten | D3: BANYUWANGI
C4: Provinsi | D4: JAWA TIMUR
C9: Kelurahan | D9: KALIGONDO
A12: I | B12: DATA PEMILIH DAN PENGGUNAAN HAK PILIH | BB12: JUMLAH AKHIR
A13: A | B13: DATA PEMILIH | E13: TPS 001 | F13: TPS 002 | G13: TPS 003 | H13: TPS 004 | I13: TPS 005 | J13: TPS 006 | K13: TPS 007 | L13: TPS 008 | M13: TPS 009 | N13: TPS 010 | O13: TPS 011 | P13: TPS 012 | Q13: TPS 013 | R13: TPS 014 | S13: TPS 015 | T13: TPS 016 | U13: TPS 017 | V13: TPS 018 | W13: TPS 019 | X13: TPS 020 | Y13: TPS 021 | Z13: TPS 022 | AA13: TPS 023 | AB13: TPS 024 | AC13: TPS 025 | AD13: TPS 026 | AE13: TPS 027 | AF13: TPS 028 | AG13: TPS 029 | AH13: TPS 030 | AI13: TPS 031 | AJ13: TPS 032 | AK13: TPS 033 | AL13: TPS 034 | AM13: TPS 035 | AN13: TPS 036 | AO13: TPS 037 | AP13: TPS 038 | AQ13: TPS 039 | AR13: TPS 040 | AS13: TPS 041 | AT13: TPS 042 | AU13: TPS 043 | AV13: TPS 044 | AW13: TPS 045 | AX13: TPS 046 | AY13: TPS 047 | AZ13: TPS 048 | BA13: TPS 049
B14: Jumlah Pemilih dalam Daftar Pemilih Tetap (DPT) | D14: LK | E14: 96 | F14: 109 | G14: 105 | H14: 130 | I14: 123 | J14: 96 | K14: 115 | L14: 95 | M14: 114 | N14: 104 | O14: 110 | P14: 113 | Q14: 120 | R14: 86 | S14: 114 | T14: 114 | U14: 102 | V14: 125 | W14: 117 | X14: 90 | Y14: 112 | Z14: 88 | AA14: 87 | AB14: 130 | AC14: 106 | AD14: 116 | AE14: 119 | AF14: 120 | AG14: 105 | AH14: 102 | AI14: 101 | AJ14: 96 | AK14: 110 | AL14: 111 | AM14: 113 | AN14: 122 | AO14: 102 | AP14: 114 | AQ14: 105 | AR14: 94 | AS14: 109 | AT14: 109 | AU14: 107 | AV14: 121 | AW14: 132 | AX14: 119 | AY14: 132 | AZ14: 133 | BA14: 118 | BB14: =SUM(E14:BA14) -> 5411
D15: PR | E15: 117 | F15: 107 | G15: 98 | H15: 124 | I15: 124 | J15: 117 | K15: 108 | L15: 96 | M15: 121 | N15: 115 | O15: 105 | P15: 107 | Q15: 123 | R15: 79 | S15: 106 | T15: 114 | U15: 105 | V15: 114 | W15: 125 | X15: 108 | Y15: 120 | Z15: 90 | AA15: 87 | AB15: 107 | AC15: 117 | AD15: 111 | AE15: 120 | AF15: 120 | AG15: 98 | AH15: 101 | AI15: 101 | AJ15: 110 | AK15: 111 | AL15: 110 | AM15: 92 | AN15: 110 | AO15: 109 | AP15: 120 | AQ15: 97 | AR15: 103 | AS15: 101 | AT15: 143 | AU15: 106 | AV15: 124 | AW15: 133 | AX15: 118 | AY15: 139 | AZ15: 135 | BA15: 126 | BB15: =SUM(E15:BA15) -> 5472
D16: JML | E16: =SUM(E14:E15) -> 213 | F16: =SUM(F14:F15) -> 216 | G16: =SUM(G14:G15) -> 203 | H16: =SUM(H14:H15) -> 254 | I16: =SUM(I14:I15) -> 247 | J16: =SUM(J14:J15) -> 213 | K16: =SUM(K14:K15) -> 223 | L16: =SUM(L14:L15) -> 191 | ... BA16: =SUM(BA14:BA15) -> 244 | BB16: =SUM(E16:BA16) -> 10883
A18: B | B18: PENGGUNA HAK PILIH
B19: 1. | C19: Jumlah pengguna hak pilih dalam Daftar Pemilih Tetap (DPT) | D19: LK | E19: 64 | F19: 70 | G19: 64 | H19: 93 | I19: 94 | J19: 53 | K19: 76 | L19: 63 | M19: 87 | N19: 73 | O19: 70 | P19: 79 | Q19: 91 | R19: 60 | S19: 88 | T19: 87 | U19: 72 | V19: 81 | W19: 79 | X19: 70 | Y19: 92 | Z19: 60 | AA19: 52 | AB19: 100 | AC19: 86 | AD19: 88 | AE19: 92 | AF19: 87 | AG19: 76 | AH19: 76 | AI19: 77 | AJ19: 74 | AK19: 83 | AL19: 63 | AM19: 72 | AN19: 92 | AO19: 65 | AP19: 90 | AQ19: 77 | AR19: 65 | AS19: 81 | AT19: 79 | AU19: 78 | AV19: 93 | AW19: 97 | AX19: 87 | AY19: 102 | AZ19: 97 | BA19: 81 | BB19: =SUM(E19:BA19) -> 3876
D20: PR | E20: 96 | F20: 74 | G20: 72 | H20: 103 | I20: 93 | J20: 74 | K20: 79 | L20: 64 | M20: 89 | N20: 88 | O20: 78 | P20: 83 | Q20: 94 | R20: 62 | S20: 89 | T20: 94 | U20: 76 | V20: 86 | W20: 94 | X20: 76 | Y20: 91 | Z20: 72 | AA20: 68 | AB20: 89 | AC20: 89 | AD20: 85 | AE20: 103 | AF20: 92 | AG20: 76 | AH20: 76 | AI20: 78 | AJ20: 94 | AK20: 74 | AL20: 70 | AM20: 70 | AN20: 90 | AO20: 75 | AP20: 94 | AQ20: 76 | AR20: 84 | AS20: 81 | AT20: 105 | AU20: 84 | AV20: 103 | AW20: 96 | AX20: 90 | AY20: 109 | AZ20: 105 | BA20: 93 | BB20: =SUM(E20:BA20) -> 4176
D21: JML | E21: =SUM(E19:E20) -> 160 | F21: =SUM(F19:F20) -> 144 | G21: =SUM(G19:G20) -> 136 | H21: =SUM(H19:H20) -> 196 | I21: =SUM(I19:I20) -> 187 | J21: =SUM(J19:J20) -> 127 | K21: =SUM(K19:K20) -> 155 | L21: =SUM(L19:L20) -> 127 | ... BA21: =SUM(BA19:BA20) -> 174 | BB21: =SUM(E21:BA21) -> 8052
B22: 2. | C22: Jumlah pengguna hak pilih dalam Daftar Pemilih Tambahan (DPTb) | D22: LK | G22: 1 | AG22: 1 | AI22: 2 | AU22: 1 | BB22: =SUM(E22:BA22) -> 5
D23: PR | N23: 1 | P23: 1 | W23: 1 | X23: 1 | Z23: 1 | AG23: 1 | AI23: 1 | AN23: 1 | AR23: 1 | AU23: 1 | BB23: =SUM(E23:BA23) -> 10
D24: JML | E24: =SUM(E22:E23) -> 0 | F24: =SUM(F22:F23) -> 0 | G24: =SUM(G22:G23) -> 1 | H24: =SUM(H22:H23) -> 0 | I24: =SUM(I22:I23) -> 0 | J24: =SUM(J22:J23) -> 0 | K24: =SUM(K22:K23) -> 0 | L24: =SUM(L22:L23) -> 0 | ... BA24: =SUM(BA22:BA23) -> 0 | BB24: =SUM(E24:BA24) -> 15
B25: 3. | C25: Jumlah pengguna hak pilih dalam Daftar Pemilih Khusus (DPK) | D25: LK | J25: 1 | K25: 1 | L25: 7 | M25: 1 | R25: 1 | S25: 3 | U25: 1 | V25: 2 | Z25: 3 | AB25: 1 | AE25: 1 | AG25: 2 | AH25: 3 | AI25: 1 | AJ25: 2 | AK25: 1 | AN25: 1 | AQ25: 1 | AR25: 2 | AS25: 2 | AT25: 1 | BA25: 1 | BB25: =SUM(E25:BA25) -> 39
D26: PR | J26: 1 | K26: 1 | L26: 5 | M26: 1 | O26: 1 | R26: 3 | S26: 2 | T26: 2 | V26: 2 | W26: 1 | Z26: 5 | AA26: 1 | AB26: 1 | AE26: 2 | AG26: 2 | AH26: 1 | AI26: 2 | AJ26: 2 | AK26: 2 | AM26: 5 | AN26: 1 | AQ26: 4 | AR26: 1 | AS26: 2 | AT26: 4 | AX26: 1 | BA26: 2 | BB26: =SUM(E26:BA26) -> 57
D27: JML | E27: =SUM(E25:E26) -> 0 | F27: =SUM(F25:F26) -> 0 | G27: =SUM(G25:G26) -> 0 | H27: =SUM(H25:H26) -> 0 | I27: =SUM(I25:I26) -> 0 | J27: =SUM(J25:J26) -> 2 | K27: =SUM(K25:K26) -> 2 | L27: =SUM(L25:L26) -> 12 | ... BA27: =SUM(BA25:BA26) -> 3 | BB27: =SUM(E27:BA27) -> 96
B28: 4. | C28: Jumlah Pengguna Hak Pilih (B.1+B.2+B.3) | D28: LK | E28: =SUM(E19,E22,E25) -> 64 | F28: =SUM(F19,F22,F25) -> 70 | G28: =SUM(G19,G22,G25) -> 65 | H28: =SUM(H19,H22,H25) -> 93 | I28: =SUM(I19,I22,I25) -> 94 | J28: =SUM(J19,J22,J25) -> 54 | K28: =SUM(K19,K22,K25) -> 77 | L28: =SUM(L19,L22,L25) -> 70 | ... BA28: =SUM(BA19,BA22,BA25) -> 82 | BB28: =SUM(E28:BA28) -> 3920
D29: PR | E29: =SUM(E20,E23,E26) -> 96 | F29: =SUM(F20,F23,F26) -> 74 | G29: =SUM(G20,G23,G26) -> 72 | H29: =SUM(H20,H23,H26) -> 103 | I29: =SUM(I20,I23,I26) -> 93 | J29: =SUM(J20,J23,J26) -> 75 | K29: =SUM(K20,K23,K26) -> 80 | L29: =SUM(L20,L23,L26) -> 69 | ... BA29: =SUM(BA20,BA23,BA26) -> 95 | BB29: =SUM(E29:BA29) -> 4243
D30: JML | E30: =SUM(E28:E29) -> 160 | F30: =SUM(F28:F29) -> 144 | G30: =SUM(G28:G29) -> 137 | H30: =SUM(H28:H29) -> 196 | I30: =SUM(I28:I29) -> 187 | J30: =SUM(J28:J29) -> 129 | K30: =SUM(K28:K29) -> 157 | L30: =SUM(L28:L29) -> 139 | ... BA30: =SUM(BA28:BA29) -> 177 | BB30: =SUM(E30:BA30) -> 8163
A32: II | B32: DATA PENGGUNAAN SURAT SUARA
A33: 1 | B33: Jumlah surat suara yang diterima, termasuk surat suara cadangan 2,5% dari DPT | E33: 221 | F33: 221 | G33: 208 | H33: 260 | I33: 253 | J33: 218 | K33: 228 | L33: 195 | M33: 240 | N33: 221 | O33: 220 | P33: 225 | Q33: 246 | R33: 171 | S33: 225 | T33: 233 | U33: 212 | V33: 245 | W33: 247 | X33: 201 | Y33: 240 | Z33: 181 | AA33: 178 | AB33: 242 | AC33: 228 | AD33: 232 | AE33: 243 | AF33: 246 | AG33: 209 | AH33: 209 | AI33: 207 | AJ33: 211 | AK33: 236 | AL33: 244 | AM33: 211 | AN33: 237 | AO33: 215 | AP33: 240 | AQ33: 207 | AR33: 201 | AS33: 217 | AT33: 257 | AU33: 218 | AV33: 250 | AW33: 270 | AX33: 242 | AY33: 277 | AZ33: 274 | BA33: 250 | BB33: =SUM(E33:BA33) -> 11162
A34: 2 | B34: Jumlah surat suara yang digunakan | E34: 160 | F34: 144 | G34: 137 | H34: 196 | I34: 187 | J34: 129 | K34: 157 | L34: 139 | M34: 178 | N34: 162 | O34: 149 | P34: 163 | Q34: 185 | R34: 126 | S34: 182 | T34: 183 | U34: 149 | V34: 171 | W34: 175 | X34: 147 | Y34: 183 | Z34: 141 | AA34: 121 | AB34: 191 | AC34: 175 | AD34: 173 | AE34: 198 | AF34: 179 | AG34: 158 | AH34: 156 | AI34: 161 | AJ34: 172 | AK34: 160 | AL34: 133 | AM34: 147 | AN34: 185 | AO34: 140 | AP34: 184 | AQ34: 158 | AR34: 153 | AS34: 166 | AT34: 189 | AU34: 164 | AV34: 196 | AW34: 193 | AX34: 178 | AY34: 211 | AZ34: 202 | BA34: 177 | BB34: =SUM(E34:BA34) -> 8163
A35: 3 | B35: Jumlah surat suara dikembalikan oleh pemilih (karena rusak atau keliru coblos) | F35: 1 | L35: 1 | M35: 1 | S35: 1 | V35: 1 | W35: 1 | AB35: 2 | AM35: 7 | AU35: 1 | AV35: 2 | AX35: 1 | BB35: =SUM(E35:BA35) -> 19
A36: 4 | B36: Jumlah surat suara yang tidak digunakan/tidak terpakai, termasuk sisa surat suara cadangan | E36: =E33-(E34+E35) -> 61 | F36: =F33-(F34+F35) -> 76 | G36: =G33-(G34+G35) -> 71 | H36: =H33-(H34+H35) -> 64 | I36: =I33-(I34+I35) -> 66 | J36: =J33-(J34+J35) -> 89 | K36: =K33-(K34+K35) -> 71 | L36: =L33-(L34+L35) -> 55 | ... BA36: =BA33-(BA34+BA35) -> 73 | BB36: =SUM(E36:BA36) -> 2980
A38: III | B38: DATA PEMILIH DISABILITAS
B39: Jumlah seluruh Pemilih disabilitas yang menggunakan hak pilih | D39: LK | AM39: 1 | BB39: =SUM(E39:BA39) -> 1
D40: PR | L40: 1 | P40: 1 | BB40: =SUM(E40:BA40) -> 2
D41: JML | E41: =SUM(E39:E40) -> 0 | F41: =SUM(F39:F40) -> 0 | G41: =SUM(G39:G40) -> 0 | H41: =SUM(H39:H40) -> 0 | I41: =SUM(I39:I40) -> 0 | J41: =SUM(J39:J40) -> 0 | K41: =SUM(K39:K40) -> 0 | L41: =SUM(L39:L40) -> 1 | ... BA41: =SUM(BA39:BA40) -> 0 | BB41: =SUM(E41:BA41) -> 3
A43: IV | B43: DATA RINCIAN PEROLEHAN SUARA PASANGAN CALON BUPATI DAN WAKIL BUPATI
A44: NOMOR DAN NAMA CALON
A45: A.1 | B45: 1. | C45: Partai Kebangkitan Bangsa | E45: 6 | F45: 4 | G45: 2 | H45: 2 | I45: 2 | J45: 8 | K45: 6 | L45: 3 | M45: 1 | N45: 7 | O45: 4 | P45: 2 | Q45: 3 | R45: 6 | S45: 2 | T45: 4 | U45: 1 | V45: 3 | W45: 7 | X45: 2 | Y45: 6 | AA45: 3 | AB45: 5 | AC45: 10 | AD45: 4 | AE45: 4 | AF45: 3 | AH45: 1 | AI45: 4 | AJ45: 2 | AM45: 4 | AN45: 3 | AP45: 2 | AQ45: 1 | AR45: 3 | AS45: 4 | AT45: 3 | AU45: 4 | AW45: 1 | AX45: 5 | AY45: 6 | AZ45: 4 | BA45: 1 | BB45: =SUM(E45:BA45) -> 158
A46: A.2 | C46: 1. H. KHUSNAN, S.Ag., M.Pd.I. | E46: 1 | F46: 2 | H46: 1 | I46: 2 | K46: 4 | L46: 4 | M46: 3 | N46: 3 | O46: 1 | P46: 1 | Q46: 3 | R46: 6 | S46: 6 | U46: 1 | V46: 3 | W46: 2 | X46: 7 | Y46: 10 | AB46: 3 | AC46: 9 | AD46: 9 | AE46: 2 | AF46: 2 | AH46: 5 | AI46: 4 | AK46: 3 | AM46: 1 | AN46: 1 | AO46: 1 | AP46: 2 | AR46: 1 | AS46: 4 | AT46: 1 | AU46: 1 | AY46: 3 | AZ46: 4 | BA46: 1 | BB46: =SUM(E46:BA46) -> 117
C47: 2. MARA QONITHA LAYLIA | E47: 2 | F47: 3 | G47: 4 | H47: 1 | I47: 1 | J47: 3 | K47: 7 | L47: 3 | M47: 3 | N47: 15 | Q47: 2 | R47: 1 | S47: 5 | T47: 7 | U47: 2 | V47: 1 | W47: 2 | X47: 1 | Y47: 1 | AB47: 2 | AC47: 2 | AD47: 4 | AG47: 2 | AH47: 2 | AI47: 1 | AJ47: 2 | AK47: 1 | AM47: 3 | AN47: 6 | AO47: 8 | AP47: 8 | AQ47: 3 | AR47: 2 | AT47: 3 | AV47: 1 | AX47: 1 | AY47: 14 | AZ47: 12 | BA47: 3 | BB47: =SUM(E47:BA47) -> 144
C48: 3. ZAKI AL MUBAROK, M.Si. | E48: 2 | F48: 8 | G48: 6 | H48: 7 | I48: 1 | J48: 19 | K48: 5 | L48: 1 | M48: 12 | N48: 13 | O48: 16 | P48: 8 | Q48: 18 | S48: 2 | T48: 1 | U48: 2 | V48: 3 | W48: 6 | X48: 4 | Y48: 5 | AA48: 3 | AB48: 11 | AC48: 11 | AD48: 10 | AE48: 9 | AF48: 1 | AG48: 7 | AH48: 15 | AI48: 11 | AJ48: 2 | AK48: 1 | AL48: 2 | AM48: 3 | AN48: 1 | AO48: 1 | AP48: 9 | AR48: 3 | AS48: 7 | AT48: 5 | AU48: 12 | AV48: 6 | AW48: 2 | AX48: 3 | AY48: 8 | AZ48: 2 | BA48: 1 | BB48: =SUM(E48:BA48) -> 285
C49: 4. INAYATUL MAHMUDAH, S.Pd. | E49: 1 | F49: 1 | I49: 1 | L49: 1 | U49: 1 | V49: 1 | Y49: 2 | AC49: 1 | AE49: 1 | AI49: 2 | AM49: 1 | AN49: 1 | AP49: 1 | AQ49: 1 | AR49: 1 | AS49: 1 | AU49: 1 | AW49: 1 | BB49: =SUM(E49:BA49) -> 20
C50: 5. HABIBURRAHMAN AL KHOLILI | M50: 1 | AP50: 1 | AU50: 1 | BB50: =SUM(E50:BA50) -> 3
C51: 6. INDIARTI NOVIDA, A.Md. | AI51: 1 | AP51: 1 | BB51: =SUM(E51:BA51) -> 2
...

Sheet KEMBIRITAN
C2: Kecamatan | D2: GENTENG
C3: Kabupaten | D3: BANYUWANGI
C4: Provinsi | D4: JAWA TIMUR
C9: Kelurahan | D9: KEMBIRITAN
A12: I | B12: DATA PEMILIH DAN PENGGUNAAN HAK PILIH | BQ12: JUMLAH AKHIR
A13: A | B13: DATA PEMILIH | E13: TPS 001 | F13: TPS 002 | G13: TPS 003 | H13: TPS 004 | I13: TPS 005 | J13: TPS 006 | K13: TPS 007 | L13: TPS 008 | M13: TPS 009 | N13: TPS 010 | O13: TPS 011 | P13: TPS 012 | Q13: TPS 013 | R13: TPS 014 | S13: TPS 015 | T13: TPS 016 | U13: TPS 017 | V13: TPS 018 | W13: TPS 019 | X13: TPS 020 | Y13: TPS 021 | Z13: TPS 022 | AA13: TPS 023 | AB13: TPS 024 | AC13: TPS 025 | AD13: TPS 026 | AE13: TPS 027 | AF13: TPS 028 | AG13: TPS 029 | AH13: TPS 030 | AI13: TPS 031 | AJ13: TPS 032 | AK13: TPS 033 | AL13: TPS 034 | AM13: TPS 035 | AN13: TPS 036 | AO13: TPS 037 | AP13: TPS 038 | AQ13: TPS 039 | AR13: TPS 040 | AS13: TPS 041 | AT13: TPS 042 | AU13: TPS 043 | AV13: TPS 044 | AW13: TPS 045 | AX13: TPS 046 | AY13: TPS 047 | AZ13: TPS 048 | BA13: TPS 049 | BB13: TPS 050 | BC13: TPS 051 | BD13: TPS 052 | BE13: TPS 053 | BF13: TPS 054 | BG13: TPS 055 | BH13: TPS 056 | BI13: TPS 057 | BJ13: TPS 058 | BK13: TPS 059 | BL13: TPS 060 | BM13: TPS 061 | BN13: TPS 062 | BO13: TPS 063 | BP13: TPS 064
B14: Jumlah Pemilih dalam Daftar Pemilih Tetap (DPT) | D14: LK | E14: 129 | F14: 130 | G14: 147 | H14: 138 | I14: 120 | J14: 116 | K14: 110 | L14: 116 | M14: 115 | N14: 118 | O14: 135 | P14: 139 | Q14: 147 | R14: 119 | S14: 151 | T14: 127 | U14: 128 | V14: 135 | W14: 132 | X14: 126 | Y14: 137 | Z14: 123 | AA14: 137 | AB14: 115 | AC14: 125 | AD14: 116 | AE14: 130 | AF14: 135 | AG14: 141 | AH14: 141 | AI14: 141 | AJ14: 143 | AK14: 136 | AL14: 132 | AM14: 139 | AN14: 135 | AO14: 141 | AP14: 131 | AQ14: 136 | AR14: 138 | AS14: 154 | AT14: 138 | AU14: 114 | AV14: 148 | AW14: 147 | AX14: 151 | AY14: 147 | AZ14: 134 | BA14: 146 | BB14: 139 | BC14: 141 | BD14: 133 | BE14: 129 | BF14: 145 | BG14: 143 | BH14: 157 | BI14: 126 | BJ14: 138 | BK14: 118 | BL14: 139 | BM14: 126 | BN14: 123 | BO14: 122 | BP14: 126 | BQ14: =SUM(E14:BP14) -> 8534
D15: PR | E15: 137 | F15: 134 | G15: 134 | H15: 117 | I15: 115 | J15: 119 | K15: 115 | L15: 117 | M15: 108 | N15: 119 | O15: 125 | P15: 132 | Q15: 124 | R15: 123 | S15: 138 | T15: 136 | U15: 133 | V15: 132 | W15: 138 | X15: 129 | Y15: 118 | Z15: 135 | AA15: 122 | AB15: 113 | AC15: 117 | AD15: 122 | AE15: 131 | AF15: 127 | AG15: 135 | AH15: 133 | AI15: 134 | AJ15: 133 | AK15: 133 | AL15: 137 | AM15: 142 | AN15: 127 | AO15: 128 | AP15: 142 | AQ15: 127 | AR15: 120 | AS15: 124 | AT15: 121 | AU15: 116 | AV15: 149 | AW15: 144 | AX15: 142 | AY15: 144 | AZ15: 147 | BA15: 140 | BB15: 151 | BC15: 146 | BD15: 155 | BE15: 145 | BF15: 151 | BG15: 152 | BH15: 137 | BI15: 129 | BJ15: 126 | BK15: 127 | BL15: 136 | BM15: 137 | BN15: 125 | BO15: 122 | BP15: 119 | BQ15: =SUM(E15:BP15) -> 8386
D16: JML | E16: =SUM(E14:E15) -> 266 | F16: =SUM(F14:F15) -> 264 | G16: =SUM(G14:G15) -> 281 | H16: =SUM(H14:H15) -> 255 | I16: =SUM(I14:I15) -> 235 | J16: =SUM(J14:J15) -> 235 | K16: =SUM(K14:K15) -> 225 | L16: =SUM(L14:L15) -> 233 | ... BP16: =SUM(BP14:BP15) -> 245 | BQ16: =SUM(E16:BP16) -> 16920
A18: B | B18: PENGGUNA HAK PILIH
B19: 1. | C19: Jumlah pengguna hak pilih dalam Daftar Pemilih Tetap (DPT) | D19: LK | E19: 92 | F19: 90 | G19: 93 | H19: 94 | I19: 78 | J19: 91 | K19: 74 | L19: 99 | M19: 98 | N19: 92 | O19: 108 | P19: 105 | Q19: 101 | R19: 88 | S19: 115 | T19: 90 | U19: 83 | V19: 91 | W19: 94 | X19: 80 | Y19: 95 | Z19: 98 | AA19: 99 | AB19: 90 | AC19: 96 | AD19: 90 | AE19: 94 | AF19: 110 | AG19: 104 | AH19: 93 | AI19: 89 | AJ19: 97 | AK19: 91 | AL19: 96 | AM19: 95 | AN19: 89 | AO19: 93 | AP19: 90 | AQ19: 89 | AR19: 95 | AS19: 107 | AT19: 91 | AU19: 73 | AV19: 103 | AW19: 98 | AX19: 114 | AY19: 111 | AZ19: 99 | BA19: 114 | BB19: 106 | BC19: 111 | BD19: 104 | BE19: 98 | BF19: 98 | BG19: 92 | BH19: 108 | BI19: 75 | BJ19: 98 | BK19: 89 | BL19: 108 | BM19: 86 | BN19: 95 | BO19: 103 | BP19: 100 | BQ19: =SUM(E19:BP19) -> 6130
D20: PR | E20: 105 | F20: 99 | G20: 109 | H20: 94 | I20: 82 | J20: 93 | K20: 93 | L20: 92 | M20: 84 | N20: 104 | O20: 97 | P20: 118 | Q20: 95 | R20: 103 | S20: 113 | T20: 109 | U20: 99 | V20: 104 | W20: 109 | X20: 105 | Y20: 88 | Z20: 116 | AA20: 104 | AB20: 96 | AC20: 83 | AD20: 87 | AE20: 99 | AF20: 100 | AG20: 114 | AH20: 108 | AI20: 120 | AJ20: 104 | AK20: 106 | AL20: 99 | AM20: 106 | AN20: 94 | AO20: 104 | AP20: 114 | AQ20: 94 | AR20: 95 | AS20: 99 | AT20: 92 | AU20: 78 | AV20: 110 | AW20: 103 | AX20: 98 | AY20: 117 | AZ20: 102 | BA20: 119 | BB20: 117 | BC20: 122 | BD20: 123 | BE20: 122 | BF20: 110 | BG20: 108 | BH20: 117 | BI20: 102 | BJ20: 99 | BK20: 110 | BL20: 108 | BM20: 109 | BN20: 102 | BO20: 103 | BP20: 102 | BQ20: =SUM(E20:BP20) -> 6610
D21: JML | E21: =SUM(E19:E20) -> 197 | F21: =SUM(F19:F20) -> 189 | G21: =SUM(G19:G20) -> 202 | H21: =SUM(H19:H20) -> 188 | I21: =SUM(I19:I20) -> 160 | J21: =SUM(J19:J20) -> 184 | K21: =SUM(K19:K20) -> 167 | L21: =SUM(L19:L20) -> 191 | ... BP21: =SUM(BP19:BP20) -> 202 | BQ21: =SUM(E21:BP21) -> 12740
B22: 2. | C22: Jumlah pengguna hak pilih dalam Daftar Pemilih Tambahan (DPTb) | D22: LK | E22: 0 | F22: 0 | G22: 0 | H22: 0 | I22: 4 | J22: 0 | K22: 0 | L22: 0 | M22: 0 | N22: 0 | O22: 0 | P22: 0 | Q22: 0 | R22: 0 | S22: 0 | T22: 0 | U22: 0 | V22: 1 | W22: 0 | X22: 0 | Y22: 0 | Z22: 0 | AA22: 0 | AB22: 0 | AC22: 0 | AD22: 0 | AE22: 0 | AF22: 2 | AG22: 0 | AH22: 0 | AI22: 0 | AJ22: 0 | AK22: 1 | AL22: 0 | AM22: 0 | AN22: 0 | AO22: 0 | AP22: 0 | AQ22: 2 | AR22: 0 | AS22: 1 | AT22: 0 | AU22: 0 | AV22: 0 | AW22: 0 | AX22: 0 | AY22: 1 | AZ22: 0 | BA22: 0 | BB22: 0 | BC22: 0 | BD22: 1 | BE22: 2 | BF22: 1 | BG22: 0 | BH22: 0 | BI22: 0 | BJ22: 0 | BK22: 0 | BL22: 6 | BM22: 0 | BN22: 0 | BO22: 0 | BP22: 0 | BQ22: =SUM(E22:BP22) -> 22
D23: PR | E23: 0 | F23: 0 | G23: 0 | H23: 0 | I23: 1 | J23: 0 | K23: 0 | L23: 0 | M23: 0 | N23: 1 | O23: 0 | P23: 0 | Q23: 0 | R23: 0 | S23: 0 | T23: 1 | U23: 0 | V23: 1 | W23: 0 | X23: 0 | Y23: 0 | Z23: 0 | AA23: 0 | AB23: 0 | AC23: 0 | AD23: 0 | AE23: 0 | AF23: 0 | AG23: 0 | AH23: 0 | AI23: 0 | AJ23: 0 | AK23: 1 | AL23: 0 | AM23: 1 | AN23: 0 | AO23: 0 | AP23: 0 | AQ23: 0 | AR23: 1 | AS23: 0 | AT23: 0 | AU23: 0 | AV23: 0 | AW23: 0 | AX23: 0 | AY23: 1 | AZ23: 0 | BA23: 1 | BB23: 0 | BC23: 0 | BD23: 1 | BE23: 1 | BF23: 2 | BG23: 0 | BH23: 1 | BI23: 0 | BJ23: 0 | BK23: 0 | BL23: 0 | BM23: 0 | BN23: 0 | BO23: 0 | BP23: 1 | BQ23: =SUM(E23:BP23) -> 15
D24: JML | E24: =SUM(E22:E23) -> 0 | F24: =SUM(F22:F23) -> 0 | G24: =SUM(G22:G23) -> 0 | H24: =SUM(H22:H23) -> 0 | I24: =SUM(I22:I23) -> 5 | J24: =SUM(J22:J23) -> 0 | K24: =SUM(K22:K23) -> 0 | L24: =SUM(L22:L23) -> 0 | ... BP24: =SUM(BP22:BP23) -> 1 | BQ24: =SUM(E24:BP24) -> 37
B25: 3. | C25: Jumlah pengguna hak pilih dalam Daftar Pemilih Khusus (DPK) | D25: LK | E25: 0 | F25: 0 | G25: 0 | H25: 0 | I25: 0 | J25: 0 | K25: 0 | L25: 0 | M25: 1 | N25: 0 | O25: 0 | P25: 0 | Q25: 0 | R25: 2 | S25: 0 | T25: 0 | U25: 1 | V25: 0 | W25: 2 | X25: 0 | Y25: 0 | Z25: 0 | AA25: 4 | AB25: 0 | AC25: 2 | AD25: 0 | AE25: 1 | AF25: 1 | AG25: 0 | AH25: 1 | AI25: 2 | AJ25: 2 | AK25: 7 | AL25: 1 | AM25: 0 | AN25: 0 | AO25: 2 | AP25: 0 | AQ25: 0 | AR25: 0 | AS25: 0 | AT25: 0 | AU25: 2 | AV25: 0 | AW25: 1 | AX25: 0 | AY25: 1 | AZ25: 2 | BA25: 4 | BB25: 2 | BC25: 0 | BD25: 0 | BE25: 2 | BF25: 1 | BG25: 0 | BH25: 1 | BI25: 0 | BJ25: 3 | BK25: 0 | BL25: 2 | BM25: 0 | BN25: 0 | BO25: 0 | BP25: 0 | BQ25: =SUM(E25:BP25) -> 50
D26: PR | E26: 0 | F26: 0 | G26: 0 | H26: 1 | I26: 2 | J26: 0 | K26: 0 | L26: 1 | M26: 2 | N26: 5 | O26: 1 | P26: 0 | Q26: 0 | R26: 4 | S26: 0 | T26: 0 | U26: 0 | V26: 0 | W26: 2 | X26: 0 | Y26: 0 | Z26: 0 | AA26: 3 | AB26: 0 | AC26: 3 | AD26: 1 | AE26: 3 | AF26: 3 | AG26: 0 | AH26: 2 | AI26: 1 | AJ26: 7 | AK26: 6 | AL26: 6 | AM26: 0 | AN26: 0 | AO26: 3 | AP26: 0 | AQ26: 0 | AR26: 1 | AS26: 2 | AT26: 0 | AU26: 4 | AV26: 2 | AW26: 5 | AX26: 0 | AY26: 1 | AZ26: 1 | BA26: 3 | BB26: 1 | BC26: 0 | BD26: 0 | BE26: 0 | BF26: 0 | BG26: 0 | BH26: 3 | BI26: 0 | BJ26: 3 | BK26: 0 | BL26: 2 | BM26: 1 | BN26: 0 | BO26: 1 | BP26: 0 | BQ26: =SUM(E26:BP26) -> 86
D27: JML | E27: =SUM(E25:E26) -> 0 | F27: =SUM(F25:F26) -> 0 | G27: =SUM(G25:G26) -> 0 | H27: =SUM(H25:H26) -> 1 | I27: =SUM(I25:I26) -> 2 | J27: =SUM(J25:J26) -> 0 | K27: =SUM(K25:K26) -> 0 | L27: =SUM(L25:L26) -> 1 | ... BP27: =SUM(BP25:BP26) -> 0 | BQ27: =SUM(E27:BP27) -> 136
B28: 4. | C28: Jumlah Pengguna Hak Pilih (B.1+B.2+B.3) | D28: LK | E28: =SUM(E19,E22,E25) -> 92 | F28: =SUM(F19,F22,F25) -> 90 | G28: =SUM(G19,G22,G25) -> 93 | H28: 95 | I28: =SUM(I19,I22,I25) -> 82 | J28: =SUM(J19,J22,J25) -> 91 | K28: =SUM(K19,K22,K25) -> 74 | L28: =SUM(L19,L22,L25) -> 99 | M28: =SUM(M19,M22,M25) -> 99 | N28: =SUM(N19,N22,N25) -> 92 | O28: =SUM(O19,O22,O25) -> 108 | P28: =SUM(P19,P22,P25) -> 105 | ... BP28: =SUM(BP19,BP22,BP25) -> 100 | BQ28: =SUM(E28:BP28) -> 6203
D29: PR | E29: =SUM(E20,E23,E26) -> 105 | F29: =SUM(F20,F23,F26) -> 99 | G29: =SUM(G20,G23,G26) -> 109 | H29: 96 | I29: =SUM(I20,I23,I26) -> 85 | J29: =SUM(J20,J23,J26) -> 93 | K29: =SUM(K20,K23,K26) -> 93 | L29: =SUM(L20,L23,L26) -> 93 | M29: =SUM(M20,M23,M26) -> 86 | N29: =SUM(N20,N23,N26) -> 110 | O29: =SUM(O20,O23,O26) -> 98 | P29: =SUM(P20,P23,P26) -> 118 | ... BP29: =SUM(BP20,BP23,BP26) -> 103 | BQ29: =SUM(E29:BP29) -> 6712
