Workbook

Sheet DPRD KAB
C8: Kecamatan | D8: CLURING
C9: Kabupaten | D9: BANYUWANGI
C10: Provinsi | D10: JAWA TIMUR
A12: I | B12: DATA PEMILIH DAN PENGGUNAAN HAK PILIH | E12: JUMLAH AKHIR
A13: A | B13: DATA PEMILIH
B14: Jumlah Pemilih dalam Daftar Pemilih Tetap (DPT) | D14: LK | E14: =BENCULUK!AS14+CLURING!AL14+KALIPLOSO!Q14+PLAMPANGREJO!AE14+SARIMULYO!AA14+SEMBULUNG!AC14+SRATEN!AB14+TAMANAGUNG!AH14+TAMPO!AB14 -> 30609
D15: PR | E15: =BENCULUK!AS15+CLURING!AL15+KALIPLOSO!Q15+PLAMPANGREJO!AE15+SARIMULYO!AA15+SEMBULUNG!AC15+SRATEN!AB15+TAMANAGUNG!AH15+TAMPO!AB15 -> 30796
D16: JML | E16: =SUM(E14:E15) -> 61405
A18: B | B18: PENGGUNA HAK PILIH
B19: 1. | C19: Jumlah pengguna hak pilih dalam Daftar Pemilih Tetap (DPT) | D19: LK | E19: =BENCULUK!AS19+CLURING!AL19+KALIPLOSO!Q19+PLAMPANGREJO!AE19+SARIMULYO!AA19+SEMBULUNG!AC19+SRATEN!AB19+TAMANAGUNG!AH19+TAMPO!AB19 -> 22884
D20: PR | E20: =BENCULUK!AS20+CLURING!AL20+KALIPLOSO!Q20+PLAMPANGREJO!AE20+SARIMULYO!AA20+SEMBULUNG!AC20+SRATEN!AB20+TAMANAGUNG!AH20+TAMPO!AB20 -> 24364
D21: JML | E21: =SUM(E19:E20) -> 47248
B22: 2. | C22: Jumlah pengguna hak pilih dalam Daftar Pemilih Tambahan (DPTb) | D22: LK | E22: =BENCULUK!AS22+CLURING!AL22+KALIPLOSO!Q22+PLAMPANGREJO!AE22+SARIMULYO!AA22+SEMBULUNG!AC22+SRATEN!AB22+TAMANAGUNG!AH22+TAMPO!AB22 -> 23
D23: PR | E23: =BENCULUK!AS23+CLURING!AL23+KALIPLOSO!Q23+PLAMPANGREJO!AE23+SARIMULYO!AA23+SEMBULUNG!AC23+SRATEN!AB23+TAMANAGUNG!AH23+TAMPO!AB23 -> 23
D24: JML | E24: =SUM(E22:E23) -> 46
B25: 3. | C25: Jumlah pengguna hak pilih dalam Daftar Pemilih Khusus (DPK) | D25: LK | E25: =BENCULUK!AS25+CLURING!AL25+KALIPLOSO!Q25+PLAMPANGREJO!AE25+SARIMULYO!AA25+SEMBULUNG!AC25+SRATEN!AB25+TAMANAGUNG!AH25+TAMPO!AB25 -> 220
D26: PR | E26: =BENCULUK!AS26+CLURING!AL26+KALIPLOSO!Q26+PLAMPANGREJO!AE26+SARIMULYO!AA26+SEMBULUNG!AC26+SRATEN!AB26+TAMANAGUNG!AH26+TAMPO!AB26 -> 282
D27: JML | E27: =SUM(E25:E26) -> 502
B28: 4. | C28: Jumlah Pengguna Hak Pilih (B.1+B.2+B.3) | D28: LK | E28: =E19+E22+E25 -> 23127
D29: PR | E29: =E20+E23+E26 -> 24669
D30: JML | E30: =SUM(E28:E29) -> 47796
A32: II | B32: DATA PENGGUNAAN SURAT SUARA
A33: 1 | B33: Jumlah surat suara yang diterima, termasuk surat suara cadangan 2,5% dari DPT | E33: =BENCULUK!AS33+CLURING!AL33+KALIPLOSO!Q33+PLAMPANGREJO!AE33+SARIMULYO!AA33+SEMBULUNG!AC33+SRATEN!AB33+TAMANAGUNG!AH33+TAMPO!AB33 -> 62653
A34: 2 | B34: Jumlah surat suara yang digunakan | E34: =BENCULUK!AS34+CLURING!AL34+KALIPLOSO!Q34+PLAMPANGREJO!AE34+SARIMULYO!AA34+SEMBULUNG!AC34+SRATEN!AB34+TAMANAGUNG!AH34+TAMPO!AB34 -> 47796
A35: 3 | B35: Jumlah surat suara dikembalikan oleh pemilih (karena rusak atau keliru coblos) | E35: =BENCULUK!AS35+CLURING!AL35+KALIPLOSO!Q35+PLAMPANGREJO!AE35+SARIMULYO!AA35+SEMBULUNG!AC35+SRATEN!AB35+TAMANAGUNG!AH35+TAMPO!AB35 -> 156
A36: 4 | B36: Jumlah surat suara yang tidak digunakan/tidak terpakai, termasuk sisa surat suara cadangan | E36: =E33-(E34+E35) -> 14701
A38: III | B38: DATA PEMILIH DISABILITAS
B39: Jumlah seluruh Pemilih disabilitas yang menggunakan hak pilih | D39: LK | E39: =BENCULUK!AS39+CLURING!AL39+KALIPLOSO!Q39+PLAMPANGREJO!AE39+SARIMULYO!AA39+SEMBULUNG!AC39+SRATEN!AB39+TAMANAGUNG!AH39+TAMPO!AB39 -> 34
D40: PR | E40: =BENCULUK!AS40+CLURING!AL40+KALIPLOSO!Q40+PLAMPANGREJO!AE40+SARIMULYO!AA40+SEMBULUNG!AC40+SRATEN!AB40+TAMANAGUNG!AH40+TAMPO!AB40 -> 48
D41: JML | E41: =SUM(E39:E40) -> 82
A43: IV | B43: DATA RINCIAN PEROLEHAN SUARA PASANGAN CALON BUPATI DAN WAKIL BUPATI
A44: NOMOR DAN NAMA CALON
A45: A.1 | B45: 1. | C45: Partai Kebangkitan Bangsa | E45: =BENCULUK!AS45+CLURING!AL45+KALIPLOSO!Q45+PLAMPANGREJO!AE45+SARIMULYO!AA45+SEMBULUNG!AC45+SRATEN!AB45+TAMANAGUNG!AH45+TAMPO!AB45 -> 1207
A46: A.2 | B46: 1 | C46: KH. MUHAMMAD RIZA AZIZY, M.IEB. | E46: =BENCULUK!AS46+CLURING!AL46+KALIPLOSO!Q46+PLAMPANGREJO!AE46+SARIMULYO!AA46+SEMBULUNG!AC46+SRATEN!AB46+TAMANAGUNG!AH46+TAMPO!AB46 -> 1047
B47: 2 | C47: INAYANTI KUSUMASARI, S.E. | E47: =BENCULUK!AS47+CLURING!AL47+KALIPLOSO!Q47+PLAMPANGREJO!AE47+SARIMULYO!AA47+SEMBULUNG!AC47+SRATEN!AB47+TAMANAGUNG!AH47+TAMPO!AB47 -> 6700
B48: 3 | C48: TOPAN HADI SUCIPTO, S.H. | E48: =BENCULUK!AS48+CLURING!AL48+KALIPLOSO!Q48+PLAMPANGREJO!AE48+SARIMULYO!AA48+SEMBULUNG!AC48+SRATEN!AB48+TAMANAGUNG!AH48+TAMPO!AB48 -> 253
B49: 4 | C49: HAULA KARIMA AKBAR, S.PD. | E49: =BENCULUK!AS49+CLURING!AL49+KALIPLOSO!Q49+PLAMPANGREJO!AE49+SARIMULYO!AA49+SEMBULUNG!AC49+SRATEN!AB49+TAMANAGUNG!AH49+TAMPO!AB49 -> 23
B50: 5 | C50: SUGENG HARYONO | E50: =BENCULUK!AS50+CLURING!AL50+KALIPLOSO!Q50+PLAMPANGREJO!AE50+SARIMULYO!AA50+SEMBULUNG!AC50+SRATEN!AB50+TAMANAGUNG!AH50+TAMPO!AB50 -> 23
B51: 6 | C51: MOH. RIYADUS SHOLIHIN, A.MD. | E51: =BENCULUK!AS51+CLURING!AL51+KALIPLOSO!Q51+PLAMPANGREJO!AE51+SARIMULYO!AA51+SEMBULUNG!AC51+SRATEN!AB51+TAMANAGUNG!AH51+TAMPO!AB51 -> 1095
A52: B | B52: JUMLAH SUARA SAH PARTAI POLITIK DAN CALON (A1 + A2) | E52: =SUM(E45:E51) -> 10348
...

Sheet BENCULUK
C2: Kecamatan | D2: CLURING
C3: Kabupaten | D3: BANYUWANGI
C4: Provinsi | D4: JAWA TIMUR
C9: Kelurahan | D9: BENCULUK
A12: I | B12: DATA PEMILIH DAN PENGGUNAAN HAK PILIH | AS12: JUMLAH AKHIR
A13: A | B13: DATA PEMILIH | E13: TPS 001 | F13: TPS 002 | G13: TPS 003 | H13: TPS 004 | I13: TPS 005 | J13: TPS 006 | K13: TPS 007 | L13: TPS 008 | M13: TPS 009 | N13: TPS 010 | O13: TPS 011 | P13: TPS 012 | Q13: TPS 013 | R13: TPS 014 | S13: TPS 015 | T13: TPS 016 | U13: TPS 017 | V13: TPS 018 | W13: TPS 019 | X13: TPS 020 | Y13: TPS 021 | Z13: TPS 022 | AA13: TPS 023 | AB13: TPS 024 | AC13: TPS 025 | AD13: TPS 026 | AE13: TPS 027 | AF13: TPS 028 | AG13: TPS 029 | AH13: TPS 030 | AI13: TPS 031 | AJ13: TPS 032 | AK13: TPS 033 | AL13: TPS 034 | AM13: TPS 035 | AN13: TPS 036 | AO13: TPS 037 | AP13: TPS 038 | AQ13: TPS 039 | AR13: TPS 040
B14: Jumlah Pemilih dalam Daftar Pemilih Tetap (DPT) | D14: LK | E14: 136 | F14: 122 | G14: 131 | H14: 114 | I14: 125 | J14: 123 | K14: 119 | L14: 115 | M14: 138 | N14: 121 | O14: 126 | P14: 124 | Q14: 141 | R14: 144 | S14: 139 | T14: 124 | U14: 123 | V14: 119 | W14: 123 | X14: 134 | Y14: 129 | Z14: 139 | AA14: 138 | AB14: 118 | AC14: 140 | AD14: 136 | AE14: 153 | AF14: 141 | AG14: 133 | AH14: 131 | AI14: 135 | AJ14: 127 | AK14: 141 | AL14: 127 | AM14: 130 | AN14: 132 | AO14: 125 | AP14: 143 | AQ14: 146 | AR14: 130 | AS14: =SUM(E14:AR14) -> 5235
D15: PR | E15: 123 | F15: 131 | G15: 122 | H15: 141 | I15: 121 | J15: 120 | K15: 126 | L15: 120 | M15: 134 | N15: 138 | O15: 125 | P15: 144 | Q15: 142 | R15: 133 | S15: 141 | T15: 137 | U15: 129 | V15: 113 | W15: 146 | X15: 131 | Y15: 146 | Z15: 145 | AA15: 142 | AB15: 132 | AC15: 123 | AD15: 136 | AE15: 136 | AF15: 143 | AG15: 137 | AH15: 122 | AI15: 131 | AJ15: 123 | AK15: 125 | AL15: 130 | AM15: 135 | AN15: 133 | AO15: 132 | AP15: 147 | AQ15: 126 | AR15: 140 | AS15: =SUM(E15:AR15) -> 5301
D16: JML | E16: =SUM(E14:E15) -> 259 | F16: =SUM(F14:F15) -> 253 | G16: =SUM(G14:G15) -> 253 | H16: =SUM(H14:H15) -> 255 | I16: =SUM(I14:I15) -> 246 | J16: =SUM(J14:J15) -> 243 | K16: =SUM(K14:K15) -> 245 | L16: =SUM(L14:L15) -> 235 | ... AR16: =SUM(AR14:AR15) -> 270 | AS16: =SUM(E16:AR16) -> 10536
A18: B | B18: PENGGUNA HAK PILIH
B19: 1. | C19: Jumlah pengguna hak pilih dalam Daftar Pemilih Tetap (DPT) | D19: LK | E19: 106 | F19: 98 | G19: 88 | H19: 84 | I19: 89 | J19: 83 | K19: 79 | L19: 92 | M19: 94 | N19: 87 | O19: 92 | P19: 81 | Q19: 98 | R19: 92 | S19: 102 | T19: 99 | U19: 85 | V19: 77 | W19: 97 | X19: 100 | Y19: 86 | Z19: 106 | AA19: 104 | AB19: 89 | AC19: 103 | AD19: 120 | AE19: 118 | AF19: 112 | AG19: 110 | AH19: 92 | AI19: 109 | AJ19: 92 | AK19: 108 | AL19: 99 | AM19: 93 | AN19: 113 | AO19: 96 | AP19: 111 | AQ19: 92 | AR19: 90 | AS19: =SUM(E19:AR19) -> 3866
D20: PR | E20: 92 | F20: 93 | G20: 89 | H20: 114 | I20: 98 | J20: 82 | K20: 86 | L20: 87 | M20: 104 | N20: 103 | O20: 97 | P20: 92 | Q20: 99 | R20: 85 | S20: 119 | T20: 108 | U20: 103 | V20: 79 | W20: 118 | X20: 108 | Y20: 115 | Z20: 116 | AA20: 124 | AB20: 101 | AC20: 94 | AD20: 118 | AE20: 113 | AF20: 117 | AG20: 112 | AH20: 91 | AI20: 111 | AJ20: 105 | AK20: 109 | AL20: 105 | AM20: 105 | AN20: 120 | AO20: 104 | AP20: 120 | AQ20: 101 | AR20: 106 | AS20: =SUM(E20:AR20) -> 4143
D21: JML | E21: 198 | F21: 191 | G21: 177 | H21: 198 | I21: 187 | J21: 165 | K21: 165 | L21: 179 | M21: 198 | N21: 190 | O21: 189 | P21: 173 | Q21: 197 | R21: 177 | S21: 221 | T21: 207 | U21: 188 | V21: 156 | W21: 215 | X21: 208 | Y21: 201 | Z21: 222 | AA21: 228 | AB21: 190 | AC21: 197 | AD21: 238 | AE21: 231 | AF21: 229 | AG21: 222 | AH21: 183 | AI21: 220 | AJ21: 197 | AK21: 217 | AL21: 204 | AM21: 198 | AN21: 233 | AO21: 200 | AP21: 231 | AQ21: 193 | AR21: 196 | AS21: =SUM(E21:AR21) -> 8009
B22: 2. | C22: Jumlah pengguna hak pilih dalam Daftar Pemilih Tambahan (DPTb) | D22: LK | E22: 0 | F22: 0 | G22: 1 | H22: 0 | I22: 0 | J22: 0 | K22: 0 | L22: 0 | M22: 0 | N22: 0 | O22: 0 | P22: 0 | Q22: 0 | R22: 0 | S22: 0 | T22: 0 | U22: 0 | V22: 0 | W22: 0 | X22: 1 | Y22: 0 | Z22: 0 | AA22: 0 | AB22: 0 | AC22: 0 | AD22: 0 | AE22: 0 | AF22: 0 | AG22: 0 | AH22: 0 | AI22: 0 | AJ22: 0 | AK22: 0 | AL22: 0 | AM22: 0 | AN22: 0 | AO22: 0 | AP22: 0 | AQ22: 0 | AR22: 0 | AS22: =SUM(E22:AR22) -> 2
D23: PR | E23: 0 | F23: 0 | G23: 0 | H23: 0 | I23: 0 | J23: 0 | K23: 0 | L23: 0 | M23: 0 | N23: 0 | O23: 0 | P23: 0 | Q23: 0 | R23: 0 | S23: 0 | T23: 0 | U23: 0 | V23: 0 | W23: 0 | X23: 0 | Y23: 0 | Z23: 0 | AA23: 0 | AB23: 0 | AC23: 0 | AD23: 0 | AE23: 0 | AF23: 0 | AG23: 0 | AH23: 0 | AI23: 0 | AJ23: 0 | AK23: 0 | AL23: 0 | AM23: 0 | AN23: 0 | AO23: 0 | AP23: 0 | AQ23: 0 | AR23: 0 | AS23: =SUM(E23:AR23) -> 0
D24: JML | E24: 0 | F24: 0 | G24: 1 | H24: 0 | I24: 0 | J24: 0 | K24: 0 | L24: 0 | M24: 0 | N24: 0 | O24: 0 | P24: 0 | Q24: 0 | R24: 0 | S24: 0 | T24: 0 | U24: 0 | V24: 0 | W24: 0 | X24: 1 | Y24: 0 | Z24: 0 | AA24: 0 | AB24: 0 | AC24: 0 | AD24: 0 | AE24: 0 | AF24: 0 | AG24: 0 | AH24: 0 | AI24: 0 | AJ24: 0 | AK24: 0 | AL24: 0 | AM24: 0 | AN24: 0 | AO24: 0 | AP24: 0 | AQ24: 0 | AR24: 0 | AS24: =SUM(E24:AR24) -> 2
B25: 3. | C25: Jumlah pengguna hak pilih dalam Daftar Pemilih Khusus (DPK) | D25: LK | E25: 3 | F25: 0 | G25: 0 | H25: 1 | I25: 0 | J25: 1 | K25: 0 | L25: 0 | M25: 0 | N25: 0 | O25: 1 | P25: 0 | Q25: 2 | R25: 0 | S25: 0 | T25: 5 | U25: 0 | V25: 0 | W25: 0 | X25: 0 | Y25: 2 | Z25: 1 | AA25: 4 | AB25: 1 | AC25: 0 | AD25: 0 | AE25: 0 | AF25: 0 | AG25: 0 | AH25: 3 | AI25: 0 | AJ25: 0 | AK25: 0 | AL25: 1 | AM25: 1 | AN25: 1 | AO25: 0 | AP25: 1 | AQ25: 1 | AR25: 0 | AS25: =SUM(E25:AR25) -> 29
D26: PR | E26: 3 | F26: 0 | G26: 0 | H26: 1 | I26: 0 | J26: 0 | K26: 1 | L26: 0 | M26: 0 | N26: 0 | O26: 2 | P26: 1 | Q26: 3 | R26: 0 | S26: 0 | T26: 0 | U26: 0 | V26: 0 | W26: 0 | X26: 0 | Y26: 3 | Z26: 0 | AA26: 1 | AB26: 2 | AC26: 2 | AD26: 0 | AE26: 0 | AF26: 0 | AG26: 0 | AH26: 1 | AI26: 1 | AJ26: 0 | AK26: 0 | AL26: 0 | AM26: 1 | AN26: 1 | AO26: 0 | AP26: 1 | AQ26: 3 | AR26: 0 | AS26: =SUM(E26:AR26) -> 27
D27: JML | E27: 6 | F27: 0 | G27: 0 | H27: 2 | I27: 0 | J27: 1 | K27: 1 | L27: 0 | M27: 0 | N27: 0 | O27: 3 | P27: 1 | Q27: 5 | R27: 0 | S27: 0 | T27: 5 | U27: 0 | V27: 0 | W27: 0 | X27: 0 | Y27: 5 | Z27: 1 | AA27: 5 | AB27: 3 | AC27: 2 | AD27: 0 | AE27: 0 | AF27: 0 | AG27: 0 | AH27: 4 | AI27: 1 | AJ27: 0 | AK27: 0 | AL27: 1 | AM27: 2 | AN27: 2 | AO27: 0 | AP27: 2 | AQ27: 4 | AR27: 0 | AS27: =SUM(E27:AR27) -> 56
B28: 4. | C28: Jumlah Pengguna Hak Pilih (B.1+B.2+B.3) | D28: LK | E28: 109 | F28: 98 | G28: 89 | H28: 85 | I28: 89 | J28: 84 | K28: 79 | L28: 92 | M28: 94 | N28: 87 | O28: 93 | P28: 81 | Q28: 100 | R28: 92 | S28: 102 | T28: 104 | U28: 85 | V28: 77 | W28: 97 | X28: 101 | Y28: 88 | Z28: 107 | AA28: 108 | AB28: 90 | AC28: 103 | AD28: 120 | AE28: 118 | AF28: 112 | AG28: 110 | AH28: 95 | AI28: 109 | AJ28: 92 | AK28: 108 | AL28: 100 | AM28: 94 | AN28: 114 | AO28: 96 | AP28: 112 | AQ28: 93 | AR28: 90 | AS28: =SUM(E28:AR28) -> 3897
D29: PR | E29: 95 | F29: 93 | G29: 89 | H29: 115 | I29: 98 | J29: 82 | K29: 87 | L29: 87 | M29: 104 | N29: 103 | O29: 99 | P29: 93 | Q29: 102 | R29: 85 | S29: 119 | T29: 108 | U29: 103 | V29: 79 | W29: 118 | X29: 108 | Y29: 118 | Z29: 116 | AA29: 125 | AB29: 103 | AC29: 96 | AD29: 118 | AE29: 113 | AF29: 117 | AG29: 112 | AH29: 92 | AI29: 112 | AJ29: 105 | AK29: 109 | AL29: 105 | AM29: 106 | AN29: 121 | AO29: 104 | AP29: 121 | AQ29: 104 | AR29: 106 | AS29: =SUM(E29:AR29) -> 4170
D30: JML | E30: =SUM(E28:E29) -> 204 | F30: =SUM(F28:F29) -> 191 | G30: =SUM(G28:G29) -> 178 | H30: =SUM(H28:H29) -> 200 | I30: =SUM(I28:I29) -> 187 | J30: =SUM(J28:J29) -> 166 | K30: =SUM(K28:K29) -> 166 | L30: =SUM(L28:L29) -> 179 | ... AR30: =SUM(AR28:AR29) -> 196 | AS30: =SUM(E30:AR30) -> 8067
A32: II | B32: DATA PENGGUNAAN SURAT SUARA
A33: 1 | B33: Jumlah surat suara yang diterima, termasuk surat suara cadangan 2,5% dari DPT | E33: 265 | F33: 260 | G33: 259 | H33: 261 | I33: 251 | J33: 248 | K33: 250 | L33: 240 | M33: 278 | N33: 265 | O33: 257 | P33: 274 | Q33: 289 | R33: 283 | S33: 286 | T33: 267 | U33: 258 | V33: 237 | W33: 275 | X33: 271 | Y33: 281 | Z33: 290 | AA33: 288 | AB33: 255 | AC33: 259 | AD33: 278 | AE33: 295 | AF33: 288 | AG33: 276 | AH33: 249 | AI33: 272 | AJ33: 254 | AK33: 272 | AL33: 263 | AM33: 271 | AN33: 270 | AO33: 263 | AP33: 296 | AQ33: 278 | AR33: 276 | AS33: =SUM(E33:AR33) -> 10748
A34: 2 | B34: Jumlah surat suara yang digunakan | E34: 204 | F34: 191 | G34: 178 | H34: 200 | I34: 187 | J34: 166 | K34: 166 | L34: 179 | M34: 198 | N34: 190 | O34: 192 | P34: 174 | Q34: 202 | R34: 177 | S34: 221 | T34: 212 | U34: 188 | V34: 156 | W34: 215 | X34: 209 | Y34: 206 | Z34: 223 | AA34: 233 | AB34: 193 | AC34: 199 | AD34: 238 | AE34: 231 | AF34: 229 | AG34: 222 | AH34: 187 | AI34: 221 | AJ34: 197 | AK34: 217 | AL34: 205 | AM34: 200 | AN34: 235 | AO34: 200 | AP34: 233 | AQ34: 197 | AR34: 196 | AS34: =SUM(E34:AR34) -> 8067
A35: 3 | B35: Jumlah surat suara dikembalikan oleh pemilih (karena rusak atau keliru coblos) | E35: 3 | F35: 3 | G35: 0 | H35: 5 | I35: 0 | J35: 0 | K35: 0 | L35: 0 | M35: 2 | N35: 0 | O35: 1 | P35: 1 | Q35: 0 | R35: 0 | S35: 1 | T35: 3 | U35: 2 | V35: 0 | W35: 0 | X35: 2 | Y35: 0 | Z35: 1 | AA35: 0 | AB35: 0 | AC35: 0 | AD35: 4 | AE35: 2 | AF35: 0 | AG35: 2 | AH35: 1 | AI35: 2 | AJ35: 0 | AK35: 0 | AL35: 0 | AM35: 1 | AN35: 1 | AO35: 0 | AP35: 0 | AQ35: 3 | AR35: 1 | AS35: =SUM(E35:AR35) -> 41
A36: 4 | B36: Jumlah surat suara yang tidak digunakan/tidak terpakai, termasuk sisa surat suara cadangan | E36: 58 | F36: 66 | G36: 81 | H36: 56 | I36: 64 | J36: 82 | K36: 84 | L36: 61 | M36: 78 | N36: 75 | O36: 64 | P36: 99 | Q36: 87 | R36: 106 | S36: 64 | T36: 52 | U36: 68 | V36: 81 | W36: 60 | X36: 60 | Y36: 75 | Z36: 66 | AA36: 55 | AB36: 62 | AC36: 60 | AD36: 36 | AE36: 62 | AF36: 59 | AG36: 52 | AH36: 61 | AI36: 49 | AJ36: 57 | AK36: 55 | AL36: 58 | AM36: 70 | AN36: 34 | AO36: 63 | AP36: 63 | AQ36: 78 | AR36: 79 | AS36: =SUM(E36:AR36) -> 2640
A38: III | B38: DATA PEMILIH DISABILITAS
B39: Jumlah seluruh Pemilih disabilitas yang menggunakan hak pilih | D39: LK | E39: 0 | F39: 1 | G39: 0 | H39: 0 | I39: 0 | J39: 0 | K39: 0 | L39: 0 | M39: 0 | N39: 0 | O39: 0 | P39: 0 | Q39: 0 | R39: 0 | S39: 0 | T39: 0 | U39: 0 | V39: 0 | W39: 0 | X39: 1 | Y39: 0 | Z39: 1 | AA39: 0 | AB39: 1 | AC39: 1 | AD39: 0 | AE39: 0 | AF39: 0 | AG39: 1 | AH39: 0 | AI39: 0 | AJ39: 0 | AK39: 0 | AL39: 1 | AM39: 0 | AN39: 3 | AO39: 0 | AP39: 0 | AQ39: 0 | AR39: 0 | AS39: =SUM(E39:AR39) -> 10
D40: PR | E40: 0 | F40: 0 | G40: 0 | H40: 0 | I40: 0 | J40: 0 | K40: 0 | L40: 0 | M40: 0 | N40: 0 | O40: 0 | P40: 1 | Q40: 0 | R40: 0 | S40: 0 | T40: 0 | U40: 0 | V40: 0 | W40: 0 | X40: 1 | Y40: 0 | Z40: 4 | AA40: 0 | AB40: 1 | AC40: 0 | AD40: 0 | AE40: 0 | AF40: 0 | AG40: 0 | AH40: 0 | AI40: 0 | AJ40: 0 | AK40: 0 | AL40: 1 | AM40: 0 | AN40: 9 | AO40: 0 | AP40: 0 | AQ40: 0 | AR40: 0 | AS40: =SUM(E40:AR40) -> 17
D41: JML | E41: =SUM(E39:E40) -> 0 | F41: =SUM(F39:F40) -> 1 | G41: =SUM(G39:G40) -> 0 | H41: =SUM(H39:H40) -> 0 | I41: =SUM(I39:I40) -> 0 | J41: =SUM(J39:J40) -> 0 | K41: =SUM(K39:K40) -> 0 | L41: =SUM(L39:L40) -> 0 | ... AR41: =SUM(AR39:AR40) -> 0 | AS41: =SUM(E41:AR41) -> 27
A43: IV | B43: DATA RINCIAN PEROLEHAN SUARA PASANGAN CALON BUPATI DAN WAKIL BUPATI
A44: NOMOR DAN NAMA CALON
A45: A.1 | B45: 1. | C45: Partai Kebangkitan Bangsa | E45: 3 | F45: 1 | G45: 4 | H45: 7 | I45: 2 | J45: 3 | K45: 8 | L45: 4 | M45: 3 | N45: 0 | O45: 3 | P45: 4 | Q45: 5 | R45: 5 | S45: 3 | T45: 6 | U45: 6 | V45: 5 | W45: 5 | X45: 3 | Y45: 4 | Z45: 6 | AA45: 7 | AB45: 9 | AC45: 3 | AD45: 2 | AE45: 4 | AF45: 5 | AG45: 7 | AH45: 6 | AI45: 2 | AJ45: 3 | AK45: 7 | AL45: 1 | AM45: 2 | AN45: 2 | AO45: 10 | AP45: 6 | AQ45: 5 | AR45: 2 | AS45: =SUM(E45:AR45) -> 173
A46: A.2 | B46: 1 | C46: KH. MUHAMMAD RIZA AZIZY, M.IEB. | E46: 2 | F46: 1 | G46: 0 | H46: 5 | I46: 3 | J46: 3 | K46: 1 | L46: 0 | M46: 0 | N46: 2 | O46: 0 | P46: 0 | Q46: 2 | R46: 3 | S46: 17 | T46: 4 | U46: 4 | V46: 5 | W46: 2 | X46: 5 | Y46: 7 | Z46: 12 | AA46: 12 | AB46: 17 | AC46: 13 | AD46: 2 | AE46: 8 | AF46: 14 | AG46: 8 | AH46: 15 | AI46: 2 | AJ46: 13 | AK46: 5 | AL46: 11 | AM46: 10 | AN46: 7 | AO46: 2 | AP46: 0 | AQ46: 4 | AR46: 3 | AS46: =SUM(E46:AR46) -> 224
B47: 2 | C47: INAYANTI KUSUMASARI, S.E. | E47: 4 | F47: 19 | G47: 27 | H47: 17 | I47: 29 | J47: 9 | K47: 11 | L47: 23 | M47: 11 | N47: 4 | O47: 0 | P47: 13 | Q47: 5 | R47: 4 | S47: 4 | T47: 4 | U47: 5 | V47: 6 | W47: 1 | X47: 6 | Y47: 23 | Z47: 10 | AA47: 6 | AB47: 5 | AC47: 14 | AD47: 6 | AE47: 9 | AF47: 9 | AG47: 12 | AH47: 15 | AI47: 9 | AJ47: 5 | AK47: 2 | AL47: 1 | AM47: 9 | AN47: 12 | AO47: 20 | AP47: 13 | AQ47: 6 | AR47: 9 | AS47: =SUM(E47:AR47) -> 397
B48: 3 | C48: TOPAN HADI SUCIPTO, S.H. | E48: 0 | F48: 0 | G48: 0 | H48: 0 | I48: 0 | J48: 1 | K48: 0 | L48: 0 | M48: 0 | N48: 0 | O48: 0 | P48: 0 | Q48: 0 | R48: 0 | S48: 0 | T48: 0 | U48: 0 | V48: 4 | W48: 1 | X48: 0 | Y48: 0 | Z48: 0 | AA48: 1 | AB48: 0 | AC48: 0 | AD48: 1 | AE48: 0 | AF48: 1 | AG48: 0 | AH48: 1 | AI48: 1 | AJ48: 0 | AK48: 0 | AL48: 0 | AM48: 0 | AN48: 0 | AO48: 0 | AP48: 1 | AQ48: 0 | AR48: 0 | AS48: =SUM(E48:AR48) -> 12
B49: 4 | C49: HAULA KARIMA AKBAR, S.PD. | E49: 0 | F49: 0 | G49: 0 | H49: 0 | I49: 1 | J49: 0 | K49: 0 | L49: 0 | M49: 0 | N49: 1 | O49: 0 | P49: 0 | Q49: 0 | R49: 0 | S49: 0 | T49: 0 | U49: 1 | V49: 0 | W49: 0 | X49: 0 | Y49: 0 | Z49: 0 | AA49: 0 | AB49: 0 | AC49: 0 | AD49: 0 | AE49: 0 | AF49: 0 | AG49: 1 | AH49: 0 | AI49: 0 | AJ49: 0 | AK49: 0 | AL49: 0 | AM49: 0 | AN49: 0 | AO49: 0 | AP49: 0 | AQ49: 0 | AR49: 0 | AS49: =SUM(E49:AR49) -> 4
B50: 5 | C50: SUGENG HARYONO | E50: 0 | F50: 0 | G50: 0 | H50: 0 | I50: 0 | J50: 0 | K50: 0 | L50: 0 | M50: 1 | N50: 0 | O50: 0 | P50: 0 | Q50: 0 | R50: 0 | S50: 0 | T50: 0 | U50: 0 | V50: 0 | W50: 0 | X50: 0 | Y50: 0 | Z50: 0 | AA50: 0 | AB50: 0 | AC50: 0 | AD50: 0 | AE50: 0 | AF50: 0 | AG50: 0 | AH50: 0 | AI50: 0 | AJ50: 0 | AK50: 0 | AL50: 0 | AM50: 0 | AN50: 1 | AO50: 0 | AP50: 0 | AQ50: 0 | AR50: 0 | AS50: =SUM(E50:AR50) -> 2
B51: 6 | C51: MOH. RIYADUS SHOLIHIN, A.MD. | E51: 9 | F51: 8 | G51: 3 | H51: 0 | I51: 6 | J51: 1 | K51: 0 | L51: 5 | M51: 6 | N51: 8 | O51: 0 | P51: 5 | Q51: 12 | R51: 1 | S51: 1 | T51: 2 | U51: 1 | V51: 1 | W51: 2 | X51: 0 | Y51: 0 | Z51: 0 | AA51: 0 | AB51: 0 | AC51: 0 | AD51: 1 | AE51: 0 | AF51: 0 | AG51: 0 | AH51: 0 | AI51: 0 | AJ51: 0 | AK51: 1 | AL51: 0 | AM51: 0 | AN51: 1 | AO51: 7 | AP51: 0 | AQ51: 0 | AR51: 2 | AS51: =SUM(E51:AR51) -> 83
...

Sheet CLURING
C2: Kecamatan | D2: CLURING
C3: Kabupaten | D3: BANYUWANGI
C4: Provinsi | D4: JAWA TIMUR
C9: Kelurahan | D9: CLURING
A12: I | B12: DATA PEMILIH DAN PENGGUNAAN HAK PILIH | AL12: JUMLAH AKHIR
A13: A | B13: DATA PEMILIH | E13: TPS 001 | F13: TPS 002 | G13: TPS 003 | H13: TPS 004 | I13: TPS 005 | J13: TPS 006 | K13: TPS 007 | L13: TPS 008 | M13: TPS 009 | N13: TPS 010 | O13: TPS 011 | P13: TPS 012 | Q13: TPS 013 | R13: TPS 014 | S13: TPS 015 | T13: TPS 016 | U13: TPS 017 | V13: TPS 018 | W13: TPS 019 | X13: TPS 020 | Y13: TPS 021 | Z13: TPS 022 | AA13: TPS 023 | AB13: TPS 024 | AC13: TPS 025 | AD13: TPS 026 | AE13: TPS 027 | AF13: TPS 028 | AG13: TPS 029 | AH13: TPS 030 | AI13: TPS 031 | AJ13: TPS 032 | AK13: TPS 033
B14: Jumlah Pemilih dalam Daftar Pemilih Tetap (DPT) | D14: LK | E14: 136 | F14: 136 | G14: 145 | H14: 148 | I14: 114 | J14: 134 | K14: 130 | L14: 136 | M14: 132 | N14: 123 | O14: 117 | P14: 133 | Q14: 130 | R14: 132 | S14: 145 | T14: 128 | U14: 136 | V14: 122 | W14: 135 | X14: 135 | Y14: 141 | Z14: 133 | AA14: 142 | AB14: 158 | AC14: 141 | AD14: 146 | AE14: 131 | AF14: 140 | AG14: 134 | AH14: 133 | AI14: 121 | AJ14: 131 | AK14: 134 | AL14: =SUM(E14:AK14) -> 4432
D15: PR | E15: 138 | F15: 128 | G15: 154 | H15: 150 | I15: 139 | J15: 132 | K15: 136 | L15: 129 | M15: 126 | N15: 136 | O15: 124 | P15: 141 | Q15: 129 | R15: 122 | S15: 141 | T15: 122 | U15: 132 | V15: 129 | W15: 134 | X15: 137 | Y15: 131 | Z15: 129 | AA15: 150 | AB15: 132 | AC15: 146 | AD15: 146 | AE15: 146 | AF15: 131 | AG15: 136 | AH15: 138 | AI15: 146 | AJ15: 140 | AK15: 132 | AL15: =SUM(E15:AK15) -> 4482
D16: JML | E16: =SUM(E14:E15) -> 274 | F16: =SUM(F14:F15) -> 264 | G16: =SUM(G14:G15) -> 299 | H16: =SUM(H14:H15) -> 298 | I16: =SUM(I14:I15) -> 253 | J16: =SUM(J14:J15) -> 266 | K16: =SUM(K14:K15) -> 266 | L16: =SUM(L14:L15) -> 265 | ... AK16: =SUM(AK14:AK15) -> 266 | AL16: =SUM(E16:AK16) -> 8914
A18: B | B18: PENGGUNA HAK PILIH
B19: 1. | C19: Jumlah pengguna hak pilih dalam Daftar Pemilih Tetap (DPT) | D19: LK | E19: 98 | F19: 91 | G19: 115 | H19: 156 | I19: 75 | J19: 99 | K19: 86 | L19: 95 | M19: 93 | N19: 101 | O19: 68 | P19: 101 | Q19: 76 | R19: 101 | S19: 96 | T19: 92 | U19: 102 | V19: 95 | W19: 98 | X19: 102 | Y19: 104 | Z19: 102 | AA19: 107 | AB19: 109 | AC19: 107 | AD19: 104 | AE19: 112 | AF19: 111 | AG19: 108 | AH19: 104 | AI19: 100 | AJ19: 97 | AK19: 105 | AL19: =SUM(E19:AK19) -> 3310
D20: PR | E20: 102 | F20: 103 | G20: 123 | H20: 90 | I20: 92 | J20: 103 | K20: 98 | L20: 101 | M20: 98 | N20: 118 | O20: 86 | P20: 115 | Q20: 92 | R20: 98 | S20: 103 | T20: 95 | U20: 112 | V20: 108 | W20: 101 | X20: 108 | Y20: 102 | Z20: 103 | AA20: 112 | AB20: 104 | AC20: 109 | AD20: 117 | AE20: 120 | AF20: 107 | AG20: 106 | AH20: 108 | AI20: 119 | AJ20: 118 | AK20: 106 | AL20: =SUM(E20:AK20) -> 3477
D21: JML | E21: 200 | F21: 194 | G21: 238 | H21: 246 | I21: 167 | J21: 202 | K21: 184 | L21: 196 | M21: 191 | N21: 219 | O21: 154 | P21: 216 | Q21: 168 | R21: 199 | S21: 199 | T21: 187 | U21: 214 | V21: 203 | W21: 199 | X21: 210 | Y21: 206 | Z21: 205 | AA21: 219 | AB21: 213 | AC21: 216 | AD21: 221 | AE21: 232 | AF21: 218 | AG21: 214 | AH21: 212 | AI21: =SUM(AI19:AI20) -> 219 | AJ21: =SUM(AJ19:AJ20) -> 215 | AK21: =SUM(AK19:AK20) -> 211 | AL21: =SUM(E21:AK21) -> 6787
B22: 2. | C22: Jumlah pengguna hak pilih dalam Daftar Pemilih Tambahan (DPTb) | D22: LK | E22: 0 | F22: 0 | G22: 0 | H22: 0 | I22: 0 | J22: 0 | K22: 0 | L22: 0 | M22: 0 | N22: 0 | O22: 1 | P22: 0 | Q22: 0 | R22: 0 | S22: 0 | T22: 1 | U22: 0 | V22: 0 | W22: 0 | X22: 0 | Y22: 0 | Z22: 0 | AA22: 0 | AB22: 0 | AC22: 0 | AD22: 0 | AE22: 0 | AF22: 0 | AG22: 0 | AH22: 0 | AI22: 0 | AJ22: 0 | AK22: 0 | AL22: =SUM(E22:AK22) -> 2
D23: PR | E23: 0 | F23: 0 | G23: 0 | H23: 0 | I23: 0 | J23: 0 | K23: 0 | L23: 1 | M23: 0 | N23: 0 | O23: 1 | P23: 0 | Q23: 0 | R23: 0 | S23: 0 | T23: 1 | U23: 0 | V23: 0 | W23: 0 | X23: 0 | Y23: 0 | Z23: 0 | AA23: 0 | AB23: 0 | AC23: 0 | AD23: 0 | AE23: 0 | AF23: 0 | AG23: 0 | AH23: 0 | AI23: 0 | AJ23: 0 | AK23: 0 | AL23: =SUM(E23:AK23) -> 3
D24: JML | E24: 0 | F24: 0 | G24: 0 | H24: 0 | I24: 0 | J24: 0 | K24: 0 | L24: 1 | M24: 0 | N24: 0 | O24: 2 | P24: 0 | Q24: 0 | R24: 0 | S24: 0 | T24: 2 | U24: 0 | V24: 0 | W24: 0 | X24: 0 | Y24: 0 | Z24: 0 | AA24: 0 | AB24: 0 | AC24: 0 | AD24: 0 | AE24: 0 | AF24: 0 | AG24: 0 | AH24: 0 | AI24: =SUM(AI22:AI23) -> 0 | AJ24: =SUM(AJ22:AJ23) -> 0 | AK24: =SUM(AK22:AK23) -> 0 | AL24: =SUM(E24:AK24) -> 5
B25: 3. | C25: Jumlah pengguna hak pilih dalam Daftar Pemilih Khusus (DPK) | D25: LK | E25: 0 | F25: 0 | G25: 0 | H25: 3 | I25: 0 | J25: 4 | K25: 1 | L25: 1 | M25: 0 | N25: 3 | O25: 1 | P25: 2 | Q25: 1 | R25: 4 | S25: 2 | T25: 1 | U25: 0 | V25: 1 | W25: 0 | X25: 0 | Y25: 1 | Z25: 1 | AA25: 0 | AB25: 1 | AC25: 2 | AD25: 1 | AE25: 2 | AF25: 5 | AG25: 3 | AH25: 0 | AI25: 3 | AJ25: 2 | AK25: 3 | AL25: =SUM(E25:AK25) -> 48
D26: PR | E26: 2 | F26: 1 | G26: 2 | H26: 3 | I26: 1 | J26: 2 | K26: 2 | L26: 3 | M26: 1 | N26: 3 | O26: 2 | P26: 3 | Q26: 4 | R26: 1 | S26: 0 | T26: 0 | U26: 2 | V26: 1 | W26: 0 | X26: 0 | Y26: 1 | Z26: 5 | AA26: 1 | AB26: 3 | AC26: 1 | AD26: 4 | AE26: 3 | AF26: 3 | AG26: 2 | AH26: 0 | AI26: 3 | AJ26: 4 | AK26: 5 | AL26: =SUM(E26:AK26) -> 68
D27: JML | E27: 2 | F27: 1 | G27: 2 | H27: 6 | I27: 1 | J27: 6 | K27: 3 | L27: 4 | M27: 1 | N27: 6 | O27: 3 | P27: 5 | Q27: 5 | R27: 5 | S27: 2 | T27: 1 | U27: 2 | V27: 2 | W27: 0 | X27: 0 | Y27: 2 | Z27: 6 | AA27: 1 | AB27: 4 | AC27: 3 | AD27: 5 | AE27: 5 | AF27: 8 | AG27: 5 | AH27: 0 | AI27: =SUM(AI25:AI26) -> 6 | AJ27: =SUM(AJ25:AJ26) -> 6 | AK27: =SUM(AK25:AK26) -> 8 | AL27: =SUM(E27:AK27) -> 116
B28: 4. | C28: Jumlah Pengguna Hak Pilih (B.1+B.2+B.3) | D28: LK | E28: 98 | F28: 91 | G28: 115 | H28: 159 | I28: 75 | J28: 103 | K28: 87 | L28: 96 | M28: 93 | N28: 104 | O28: 70 | P28: 103 | Q28: 77 | R28: 105 | S28: 98 | T28: 94 | U28: 102 | V28: 96 | W28: 98 | X28: 102 | Y28: 105 | Z28: 103 | AA28: 107 | AB28: 110 | AC28: 109 | AD28: 105 | AE28: 114 | AF28: 116 | AG28: 111 | AH28: 104 | AI28: =SUM(AI19,AI22,AI25) -> 103 | AJ28: =SUM(AJ19,AJ22,AJ25) -> 99 | AK28: =SUM(AK19,AK22,AK25) -> 108 | AL28: =SUM(E28:AK28) -> 3360
D29: PR | E29: 104 | F29: 104 | G29: 125 | H29: 93 | I29: 93 | J29: 105 | K29: 100 | L29: 105 | M29: 99 | N29: 121 | O29: 89 | P29: 118 | Q29: 96 | R29: 99 | S29: 103 | T29: 96 | U29: 114 | V29: 109 | W29: 101 | X29: 108 | Y29: 103 | Z29: 108 | AA29: 113 | AB29: 107 | AC29: 110 | AD29: 121 | AE29: 123 | AF29: 110 | AG29: 108 | AH29: 108 | AI29: =SUM(AI20,AI23,AI26) -> 122 | AJ29: =SUM(AJ20,AJ23,AJ26) -> 122 | AK29: =SUM(AK20,AK23,AK26) -> 111 | AL29: =SUM(E29:AK29) -> 3548
D30: JML | E30: =SUM(E28:E29) -> 202 | F30: =SUM(F28:F29) -> 195 | G30: =SUM(G28:G29) -> 240 | H30: =SUM(H28:H29) -> 252 | I30: =SUM(I28:I29) -> 168 | J30: =SUM(J28:J29) -> 208 | K30: =SUM(K28:K29) -> 187 | L30: =SUM(L28:L29) -> 201 | ... AK30: =SUM(AK28:AK29) -> 219 | AL30: =SUM(E30:AK30) -> 6908
A32: II | B32: DATA PENGGUNAAN SURAT SUARA
A33: 1 | B33: Jumlah surat suara yang diterima, termasuk surat suara cadangan 2,5% dari DPT | E33: 280 | F33: 259 | G33: 305 | H33: 313 | I33: 259 | J33: 272 | K33: 272 | L33: 271 | M33: 264 | N33: 262 | O33: 246 | P33: 280 | Q33: 265 | R33: 262 | S33: 292 | T33: 255 | U33: 274 | V33: 257 | W33: 265 | X33: 278 | Y33: 278 | Z33: 278 | AA33: 298 | AB33: 296 | AC33: 293 | AD33: 298 | AE33: 283 | AF33: 268 | AG33: 275 | AH33: 267 | AI33: 273 | AJ33: 277 | AK33: 273 | AL33: =SUM(E33:AK33) -> 9088
A34: 2 | B34: Jumlah surat suara yang digunakan | E34: 202 | F34: 195 | G34: 240 | H34: 252 | I34: 168 | J34: 208 | K34: 187 | L34: 201 | M34: 192 | N34: 225 | O34: 159 | P34: 221 | Q34: 173 | R34: 204 | S34: 201 | T34: 190 | U34: 216 | V34: 205 | W34: 199 | X34: 210 | Y34: 208 | Z34: 211 | AA34: 220 | AB34: 217 | AC34: 219 | AD34: 226 | AE34: 237 | AF34: 226 | AG34: 219 | AH34: 212 | AI34: 225 | AJ34: 221 | AK34: 219 | AL34: =SUM(E34:AK34) -> 6908
A35: 3 | B35: Jumlah surat suara dikembalikan oleh pemilih (karena rusak atau keliru coblos) | E35: 0 | F35: 0 | G35: 0 | H35: 0 | I35: 0 | J35: 0 | K35: 0 | L35: 0 | M35: 0 | N35: 0 | O35: 0 | P35: 0 | Q35: 0 | R35: 0 | S35: 3 | T35: 0 | U35: 0 | V35: 0 | W35: 0 | X35: 0 | Y35: 0 | Z35: 0 | AA35: 0 | AB35: 0 | AC35: 4 | AD35: 0 | AE35: 0 | AF35: 2 | AG35: 0 | AH35: 0 | AI35: 3 | AJ35: 0 | AK35: 0 | AL35: =SUM(E35:AK35) -> 12
A36: 4 | B36: Jumlah surat suara yang tidak digunakan/tidak terpakai, termasuk sisa surat suara cadangan | E36: 78 | F36: 64 | G36: 65 | H36: 61 | I36: 91 | J36: 64 | K36: 85 | L36: 70 | M36: 72 | N36: 37 | O36: 87 | P36: 59 | Q36: 92 | R36: 58 | S36: 88 | T36: 65 | U36: 58 | V36: 52 | W36: 66 | X36: 68 | Y36: 70 | Z36: 67 | AA36: 78 | AB36: 79 | AC36: 70 | AD36: 72 | AE36: 46 | AF36: 40 | AG36: 56 | AH36: 55 | AI36: =AI33-(AI34+AI35) -> 45 | AJ36: =AJ33-(AJ34+AJ35) -> 56 | AK36: =AK33-(AK34+AK35) -> 54 | AL36: =SUM(E36:AK36) -> 2168
A38: III | B38: DATA PEMILIH DISABILITAS
B39: Jumlah seluruh Pemilih disabilitas yang menggunakan hak pilih | D39: LK | E39: 0 | F39: 0 | G39: 1 | H39: 0 | I39: 0 | J39: 2 | K39: 0 | L39: 0 | M39: 0 | N39: 0 | O39: 0 | P39: 0 | Q39: 0 | R39: 0 | S39: 0 | T39: 0 | U39: 0 | V39: 0 | W39: 0 | X39: 0 | Y39: 0 | Z39: 2 | AA39: 0 | AB39: 0 | AC39: 0 | AD39: 0 | AE39: 0 | AF39: 0 | AG39: 0 | AH39: 0 | AI39: 0 | AJ39: 0 | AK39: 0 | AL39: =SUM(E39:AK39) -> 5
D40: PR | E40: 0 | F40: 0 | G40: 1 | H40: 0 | I40: 0 | J40: 1 | K40: 0 | L40: 0 | M40: 1 | N40: 0 | O40: 0 | P40: 0 | Q40: 0 | R40: 0 | S40: 0 | T40: 0 | U40: 0 | V40: 0 | W40: 1 | X40: 0 | Y40: 0 | Z40: 1 | AA40: 0 | AB40: 0 | AC40: 0 | AD40: 0 | AE40: 0 | AF40: 1 | AG40: 0 | AH40: 0 | AI40: 0 | AJ40: 0 | AK40: 0 | AL40: =SUM(E40:AK40) -> 6
D41: JML | E41: =SUM(E39:E40) -> 0 | F41: =SUM(F39:F40) -> 0 | G41: =SUM(G39:G40) -> 2 | H41: =SUM(H39:H40) -> 0 | I41: =SUM(I39:I40) -> 0 | J41: =SUM(J39:J40) -> 3 | K41: =SUM(K39:K40) -> 0 | L41: =SUM(L39:L40) -> 0 | ... AK41: =SUM(AK39:AK40) -> 0 | AL41: =SUM(E41:AK41) -> 11
A43: IV | B43: DATA RINCIAN PEROLEHAN SUARA PASANGAN CALON BUPATI DAN WAKIL BUPATI
A44: NOMOR DAN NAMA CALON
A45: A.1 | B45: 1. | C45: Partai Kebangkitan Bangsa | E45: 1 | F45: 0 | G45: 5 | H45: 6 | I45: 1 | J45: 2 | K45: 3 | L45: 5 | M45: 8 | N45: 7 | O45: 2 | P45: 1 | Q45: 5 | R45: 4 | S45: 8 | T45: 12 | U45: 4 | V45: 4 | W45: 4 | X45: 5 | Y45: 0 | Z45: 5 | AA45: 3 | AB45: 8 | AC45: 6 | AD45: 2 | AE45: 5 | AF45: 1 | AG45: 4 | AH45: 6 | AI45: 7 | AJ45: 11 | AK45: 9 | AL45: =SUM(E45:AK45) -> 154
A46: A.2 | B46: 1 | C46: KH. MUHAMMAD RIZA AZIZY, M.IEB. | E46: 3 | F46: 3 | G46: 2 | H46: 6 | I46: 2 | J46: 2 | K46: 2 | L46: 1 | M46: 1 | N46: 1 | O46: 5 | P46: 2 | Q46: 2 | R46: 1 | S46: 1 | T46: 6 | U46: 4 | V46: 4 | W46: 3 | X46: 1 | Y46: 3 | Z46: 3 | AA46: 1 | AB46: 2 | AC46: 1 | AD46: 2 | AE46: 1 | AF46: 1 | AG46: 1 | AH46: 1 | AI46: 8 | AJ46: 17 | AK46: 1 | AL46: =SUM(E46:AK46) -> 94
B47: 2 | C47: INAYANTI KUSUMASARI, S.E. | E47: 15 | F47: 7 | G47: 29 | H47: 23 | I47: 4 | J47: 7 | K47: 16 | L47: 22 | M47: 19 | N47: 25 | O47: 25 | P47: 20 | Q47: 13 | R47: 15 | S47: 40 | T47: 65 | U47: 27 | V47: 19 | W47: 3 | X47: 6 | Y47: 5 | Z47: 4 | AA47: 26 | AB47: 4 | AC47: 21 | AD47: 8 | AE47: 4 | AF47: 5 | AG47: 20 | AH47: 47 | AI47: 22 | AJ47: 16 | AK47: 24 | AL47: =SUM(E47:AK47) -> 606
B48: 3 | C48: TOPAN HADI SUCIPTO, S.H. | E48: 0 | F48: 1 | G48: 0 | H48: 1 | I48: 0 | J48: 3 | K48: 1 | L48: 1 | M48: 0 | N48: 0 | O48: 0 | P48: 0 | Q48: 0 | R48: 1 | S48: 0 | T48: 0 | U48: 0 | V48: 1 | W48: 0 | X48: 0 | Y48: 0 | Z48: 1 | AA48: 4 | AB48: 0 | AC48: 1 | AD48: 2 | AE48: 3 | AF48: 1 | AG48: 29 | AH48: 13 | AI48: 3 | AJ48: 2 | AK48: 0 | AL48: =SUM(E48:AK48) -> 68
B49: 4 | C49: HAULA KARIMA AKBAR, S.PD. | E49: 0 | F49: 0 | G49: 0 | H49: 1 | I49: 0 | J49: 2 | K49: 0 | L49: 0 | M49: 0 | N49: 0 | O49: 1 | P49: 0 | Q49: 0 | R49: 0 | S49: 0 | T49: 0 | U49: 0 | V49: 0 | W49: 0 | X49: 0 | Y49: 0 | Z49: 0 | AA49: 0 | AB49: 0 | AC49: 0 | AD49: 0 | AE49: 0 | AF49: 0 | AG49: 0 | AH49: 0 | AI49: 0 | AJ49: 1 | AK49: 0 | AL49: =SUM(E49:AK49) -> 5
B50: 5 | C50: SUGENG HARYONO | E50: 0 | F50: 1 | G50: 0 | H50: 0 | I50: 0 | J50: 0 | K50: 1 | L50: 0 | M50: 0 | N50: 0 | O50: 0 | P50: 0 | Q50: 0 | R50: 0 | S50: 0 | T50: 0 | U50: 0 | V50: 0 | W50: 0 | X50: 0 | Y50: 0 | Z50: 0 | AA50: 0 | AB50: 0 | AC50: 0 | AD50: 0 | AE50: 0 | AF50: 0 | AG50: 0 | AH50: 0 | AI50: 0 | AJ50: 0 | AK50: 0 | AL50: =SUM(E50:AK50) -> 2
B51: 6 | C51: MOH. RIYADUS SHOLIHIN, A.MD. | E51: 3 | F51: 4 | G51: 0 | H51: 4 | I51: 0 | J51: 0 | K51: 1 | L51: 3 | M51: 16 | N51: 2 | O51: 4 | P51: 4 | Q51: 2 | R51: 0 | S51: 2 | T51: 0 | U51: 6 | V51: 1 | W51: 13 | X51: 0 | Y51: 5 | Z51: 1 | AA51: 1 | AB51: 0 | AC51: 3 | AD51: 16 | AE51: 13 | AF51: 3 | AG51: 4 | AH51: 2 | AI51: 13 | AJ51: 2 | AK51: 2 | AL51: =SUM(E51:AK51) -> 130
...

Sheet KALIPLOSO
C2: Kecamatan | D2: CLURING
C3: Kabupaten | D3: BANYUWANGI
C4: Provinsi | D4: JAWA TIMUR
C9: Kelurahan | D9: KALIPLOSO
A12: I | B12: DATA PEMILIH DAN PENGGUNAAN HAK PILIH | Q12: JUMLAH AKHIR
A13: A | B13: DATA PEMILIH | E13: TPS 001 | F13: TPS 002 | G13: TPS 003 | H13: TPS 004 | I13: TPS 005 | J13: TPS 006 | K13: TPS 007 | L13: TPS 008 | M13: TPS 009 | N13: TPS 010 | O13: TPS 011 | P13: TPS 012
B14: Jumlah Pemilih dalam Daftar Pemilih Tetap (DPT) | D14: LK | E14: 137 | F14: 152 | G14: 135 | H14: 160 | I14: 142 | J14: 143 | K14: 128 | L14: 122 | M14: 107 | N14: 132 | O14: 142 | P14: 144 | Q14: =SUM(E14:P14) -> 1644
D15: PR | E15: 149 | F15: 144 | G15: 156 | H15: 137 | I15: 149 | J15: 143 | K15: 117 | L15: 122 | M15: 98 | N15: 124 | O15: 147 | P15: 150 | Q15: =SUM(E15:P15) -> 1636
D16: JML | E16: =SUM(E14:E15) -> 286 | F16: =SUM(F14:F15) -> 296 | G16: =SUM(G14:G15) -> 291 | H16: =SUM(H14:H15) -> 297 | I16: =SUM(I14:I15) -> 291 | J16: =SUM(J14:J15) -> 286 | K16: =SUM(K14:K15) -> 245 | L16: =SUM(L14:L15) -> 244 | ... P16: =SUM(P14:P15) -> 294 | Q16: =SUM(E16:P16) -> 3280
A18: B | B18: PENGGUNA HAK PILIH
B19: 1. | C19: Jumlah pengguna hak pilih dalam Daftar Pemilih Tetap (DPT) | D19: LK | E19: 81 | F19: 107 | G19: 100 | H19: 113 | I19: 121 | J19: 113 | K19: 103 | L19: 97 | M19: 75 | N19: 114 | O19: 116 | P19: 112 | Q19: =SUM(E19:P19) -> 1252
D20: PR | E20: 112 | F20: 117 | G20: 124 | H20: 127 | I20: 121 | J20: 117 | K20: 94 | L20: 95 | M20: 71 | N20: 87 | O20: 127 | P20: 123 | Q20: =SUM(E20:P20) -> 1315
D21: JML | E21: 193 | F21: 224 | G21: 224 | H21: 240 | I21: 242 | J21: 230 | K21: 197 | L21: 192 | M21: 146 | N21: 201 | O21: 243 | P21: 235 | Q21: =SUM(E21:P21) -> 2567
B22: 2. | C22: Jumlah pengguna hak pilih dalam Daftar Pemilih Tambahan (DPTb) | D22: LK | E22: 0 | F22: 1 | G22: 0 | H22: 0 | I22: 0 | J22: 0 | K22: 0 | L22: 0 | M22: 0 | N22: 0 | O22: 0 | P22: 0 | Q22: =SUM(E22:P22) -> 1
D23: PR | E23: 0 | F23: 2 | G23: 0 | H23: 0 | I23: 1 | J23: 0 | K23: 0 | L23: 0 | M23: 0 | N23: 0 | O23: 0 | P23: 1 | Q23: =SUM(E23:P23) -> 4
D24: JML | E24: 0 | F24: 3 | G24: 0 | H24: 0 | I24: 1 | J24: 0 | K24: 0 | L24: 0 | M24: 0 | N24: 0 | O24: 0 | P24: 1 | Q24: =SUM(E24:P24) -> 5
B25: 3. | C25: Jumlah pengguna hak pilih dalam Daftar Pemilih Khusus (DPK) | D25: LK | E25: 1 | F25: 1 | G25: 0 | H25: 0 | I25: 1 | J25: 1 | K25: 1 | L25: 0 | M25: 1 | N25: 0 | O25: 0 | P25: 0 | Q25: =SUM(E25:P25) -> 6
D26: PR | E26: 2 | F26: 1 | G26: 2 | H26: 0 | I26: 2 | J26: 3 | K26: 2 | L26: 0 | M26: 2 | N26: 0 | O26: 0 | P26: 0 | Q26: =SUM(E26:P26) -> 14
D27: JML | E27: 3 | F27: 2 | G27: 2 | H27: 0 | I27: 3 | J27: 4 | K27: 3 | L27: 0 | M27: 3 | N27: 0 | O27: 0 | P27: 0 | Q27: =SUM(E27:P27) -> 20
B28: 4. | C28: Jumlah Pengguna Hak Pilih (B.1+B.2+B.3) | D28: LK | E28: 82 | F28: 109 | G28: 100 | H28: 113 | I28: 122 | J28: 114 | K28: 104 | L28: 97 | M28: 76 | N28: 114 | O28: 116 | P28: 112 | Q28: =SUM(E28:P28) -> 1259
D29: PR | E29: 114 | F29: 120 | G29: 126 | H29: 127 | I29: 124 | J29: 120 | K29: 96 | L29: 95 | M29: 73 | N29: 87 | O29: 127 | P29: 124 | Q29: =SUM(E29:P29) -> 1333
D30: JML | E30: =SUM(E28:E29) -> 196 | F30: =SUM(F28:F29) -> 229 | G30: =SUM(G28:G29) -> 226 | H30: =SUM(H28:H29) -> 240 | I30: =SUM(I28:I29) -> 246 | J30: =SUM(J28:J29) -> 234 | K30: =SUM(K28:K29) -> 200 | L30: =SUM(L28:L29) -> 192 | ... P30: =SUM(P28:P29) -> 236 | Q30: =SUM(E30:P30) -> 2592
A32: II | B32: DATA PENGGUNAAN SURAT SUARA
A33: 1 | B33: Jumlah surat suara yang diterima, termasuk surat suara cadangan 2,5% dari DPT | E33: 300 | F33: 302 | G33: 298 | H33: 302 | I33: 295 | J33: 292 | K33: 250 | L33: 248 | M33: 210 | N33: 263 | O33: 293 | P33: 300 | Q33: =SUM(E33:P33) -> 3353
A34: 2 | B34: Jumlah surat suara yang digunakan | E34: 196 | F34: 229 | G34: 226 | H34: 240 | I34: 246 | J34: 234 | K34: 200 | L34: 192 | M34: 149 | N34: 201 | O34: 243 | P34: 236 | Q34: =SUM(E34:P34) -> 2592
A35: 3 | B35: Jumlah surat suara dikembalikan oleh pemilih (karena rusak atau keliru coblos) | E35: 1 | F35: 2 | G35: 0 | H35: 0 | I35: 2 | J35: 0 | K35: 1 | L35: 0 | M35: 2 | N35: 0 | O35: 0 | P35: 2 | Q35: =SUM(E35:P35) -> 10
A36: 4 | B36: Jumlah surat suara yang tidak digunakan/tidak terpakai, termasuk sisa surat suara cadangan | E36: 103 | F36: 71 | G36: 72 | H36: 62 | I36: 47 | J36: 58 | K36: 49 | L36: 56 | M36: 59 | N36: 62 | O36: 50 | P36: 62 | Q36: =SUM(E36:P36) -> 751
A38: III | B38: DATA PEMILIH DISABILITAS
B39: Jumlah seluruh Pemilih disabilitas yang menggunakan hak pilih | D39: LK | E39: 0 | F39: 0 | G39: 0 | H39: 0 | I39: 0 | J39: 0 | K39: 0 | L39: 0 | M39: 0 | N39: 0 | O39: 0 | P39: 0 | Q39: =SUM(E39:P39) -> 0
D40: PR | E40: 0 | F40: 0 | G40: 0 | H40: 0 | I40: 0 | J40: 0 | K40: 0 | L40: 0 | M40: 0 | N40: 0 | O40: 0 | P40: 0 | Q40: =SUM(E40:P40) -> 0
D41: JML | E41: =SUM(E39:E40) -> 0 | F41: =SUM(F39:F40) -> 0 | G41: =SUM(G39:G40) -> 0 | H41: =SUM(H39:H40) -> 0 | I41: =SUM(I39:I40) -> 0 | J41: =SUM(J39:J40) -> 0 | K41: =SUM(K39:K40) -> 0 | L41: =SUM(L39:L40) -> 0 | ... P41: =SUM(P39:P40) -> 0 | Q41: =SUM(E41:P41) -> 0
A43: IV | B43: DATA RINCIAN PEROLEHAN SUARA PASANGAN CALON BUPATI DAN WAKIL BUPATI
A44: NOMOR DAN NAMA CALON
A45: A.1 | B45: 1. | C45: Partai Kebangkitan Bangsa | E45: 12 | F45: 0 | G45: 10 | H45: 3 | I45: 6 | J45: 1 | K45: 5 | L45: 1 | M45: 1 | N45: 1 | O45: 1 | P45: 0 | Q45: 41
A46: A.2 | B46: 1 | C46: KH. MUHAMMAD RIZA AZIZY, M.IEB. | E46: 2 | F46: 4 | G46: 4 | H46: 1 | I46: 4 | J46: 6 | K46: 2 | L46: 1 | M46: 3 | N46: 4 | O46: 3 | P46: 7 | Q46: 41
B47: 2 | C47: INAYANTI KUSUMASARI, S.E. | E47: 16 | F47: 5 | G47: 20 | H47: 19 | I47: 44 | J47: 29 | K47: 4 | L47: 4 | M47: 2 | N47: 1 | O47: 5 | P47: 24 | Q47: 173
B48: 3 | C48: TOPAN HADI SUCIPTO, S.H. | E48: 0 | F48: 1 | G48: 0 | H48: 0 | I48: 1 | J48: 0 | K48: 0 | L48: 0 | M48: 0 | N48: 0 | O48: 0 | P48: 0 | Q48: 2
B49: 4 | C49: HAULA KARIMA AKBAR, S.PD. | E49: 1 | F49: 0 | G49: 0 | H49: 0 | I49: 0 | J49: 0 | K49: 0 | L49: 0 | M49: 0 | N49: 0 | O49: 0 | P49: 0 | Q49: 1
B50: 5 | C50: SUGENG HARYONO | E50: 0 | F50: 0 | G50: 0 | H50: 0 | I50: 1 | J50: 0 | K50: 0 | L50: 0 | M50: 0 | N50: 0 | O50: 0 | P50: 0 | Q50: 1
B51: 6 | C51: MOH. RIYADUS SHOLIHIN, A.MD. | E51: 5 | F51: 12 | G51: 8 | H51: 2 | I51: 12 | J51: 0 | K51: 0 | L51: 1 | M51: 0 | N51: 5 | O51: 1 | P51: 9 | Q51: 55
...

Sheet PLAMPANGREJO
C2: Kecamatan | D2: CLURING
C3: Kabupaten | D3: BANYUWANGI
C4: Provinsi | D4: JAWA TIMUR
C9: Kelurahan | D9: PLAMPANGREJO
A12: I | B12: DATA PEMILIH DAN PENGGUNAAN HAK PILIH | AE12: JUMLAH AKHIR
A13: A | B13: DATA PEMILIH | E13: TPS 001 | F13: TPS 002 | G13: TPS 003 | H13: TPS 004 | I13: TPS 005 | J13: TPS 006 | K13: TPS 007 | L13: TPS 008 | M13: TPS 009 | N13: TPS 010 | O13: TPS 011 | P13: TPS 012 | Q13: TPS 013 | R13: TPS 014 | S13: TPS 015 | T13: TPS 016 | U13: TPS 017 | V13: TPS 018 | W13: TPS 019 | X13: TPS 020 | Y13: TPS 021 | Z13: TPS 022 | AA13: TPS 023 | AB13: TPS 024 | AC13: TPS 025 | AD13: TPS 026
B14: Jumlah Pemilih dalam Daftar Pemilih Tetap (DPT) | D14: LK | E14: 128 | F14: 141 | G14: 138 | H14: 130 | I14: 137 | J14: 101 | K14: 144 | L14: 119 | M14: 133 | N14: 116 | O14: 121 | P14: 145 | Q14: 148 | R14: 147 | S14: 130 | T14: 136 | U14: 150 | V14: 157 | W14: 148 | X14: 143 | Y14: 152 | Z14: 138 | AA14: 120 | AB14: 109 | AC14: 130 | AD14: 107 | AE14: =SUM(E14:AD14) -> 3468
D15: PR | E15: 130 | F15: 137 | G15: 148 | H15: 121 | I15: 128 | J15: 105 | K15: 140 | L15: 128 | M15: 134 | N15: 125 | O15: 122 | P15: 133 | Q15: 150 | R15: 145 | S15: 134 | T15: 141 | U15: 134 | V15: 141 | W15: 143 | X15: 151 | Y15: 143 | Z15: 150 | AA15: 128 | AB15: 109 | AC15: 139 | AD15: 119 | AE15: =SUM(E15:AD15) -> 3478
D16: JML | E16: =SUM(E14:E15) -> 258 | F16: =SUM(F14:F15) -> 278 | G16: =SUM(G14:G15) -> 286 | H16: =SUM(H14:H15) -> 251 | I16: =SUM(I14:I15) -> 265 | J16: =SUM(J14:J15) -> 206 | K16: =SUM(K14:K15) -> 284 | L16: =SUM(L14:L15) -> 247 | ... AD16: =SUM(AD14:AD15) -> 226 | AE16: =SUM(E16:AD16) -> 6946
A18: B | B18: PENGGUNA HAK PILIH
B19: 1. | C19: Jumlah pengguna hak pilih dalam Daftar Pemilih Tetap (DPT) | D19: LK | E19: 100 | F19: 106 | G19: 117 | H19: 94 | I19: 103 | J19: 80 | K19: 116 | L19: 89 | M19: 90 | N19: 93 | O19: 93 | P19: 109 | Q19: 114 | R19: 118 | S19: 96 | T19: 102 | U19: 106 | V19: 125 | W19: 119 | X19: 113 | Y19: 112 | Z19: 96 | AA19: 91 | AB19: 89 | AC19: 107 | AD19: 84 | AE19: =SUM(E19:AD19) -> 2662
D20: PR | E20: 108 | F20: 106 | G20: 117 | H20: 98 | I20: 105 | J20: 85 | K20: 119 | L20: 107 | M20: 110 | N20: 98 | O20: 100 | P20: 102 | Q20: 126 | R20: 114 | S20: 106 | T20: 106 | U20: 116 | V20: 110 | W20: 113 | X20: 107 | Y20: 101 | Z20: 113 | AA20: 97 | AB20: 86 | AC20: 112 | AD20: 96 | AE20: =SUM(E20:AD20) -> 2758
D21: JML | E21: 208 | F21: 212 | G21: 234 | H21: 192 | I21: 208 | J21: 165 | K21: 235 | L21: 196 | M21: 200 | N21: 191 | O21: 193 | P21: 211 | Q21: 240 | R21: 232 | S21: 202 | T21: 208 | U21: 222 | V21: 235 | W21: 232 | X21: 220 | Y21: 213 | Z21: 209 | AA21: 188 | AB21: 175 | AC21: 219 | AD21: 180 | AE21: =SUM(E21:AD21) -> 5420
B22: 2. | C22: Jumlah pengguna hak pilih dalam Daftar Pemilih Tambahan (DPTb) | D22: LK | E22: 0 | F22: 0 | G22: 0 | H22: 0 | I22: 0 | J22: 1 | K22: 1 | L22: 0 | M22: 0 | N22: 0 | O22: 0 | P22: 0 | Q22: 0 | R22: 1 | S22: 1 | T22: 0 | U22: 2 | V22: 0 | W22: 0 | X22: 0 | Y22: 0 | Z22: 0 | AA22: 0 | AB22: 0 | AC22: 0 | AD22: 0 | AE22: =SUM(E22:AD22) -> 6
D23: PR | E23: 0 | F23: 0 | G23: 0 | H23: 0 | I23: 0 | J23: 0 | K23: 1 | L23: 0 | M23: 0 | N23: 1 | O23: 1 | P23: 0 | Q23: 0 | R23: 1 | S23: 0 | T23: 0 | U23: 0 | V23: 1 | W23: 1 | X23: 0 | Y23: 0 | Z23: 0 | AA23: 0 | AB23: 0 | AC23: 0 | AD23: 0 | AE23: =SUM(E23:AD23) -> 6
D24: JML | E24: 0 | F24: 0 | G24: 0 | H24: 0 | I24: 0 | J24: 1 | K24: 2 | L24: 0 | M24: 0 | N24: 1 | O24: 1 | P24: 0 | Q24: 0 | R24: 2 | S24: 1 | T24: 0 | U24: 2 | V24: 1 | W24: 1 | X24: 0 | Y24: 0 | Z24: 0 | AA24: 0 | AB24: 0 | AC24: 0 | AD24: 0 | AE24: =SUM(E24:AD24) -> 12
B25: 3. | C25: Jumlah pengguna hak pilih dalam Daftar Pemilih Khusus (DPK) | D25: LK | E25: 1 | F25: 1 | G25: 1 | H25: 0 | I25: 1 | J25: 0 | K25: 0 | L25: 0 | M25: 4 | N25: 1 | O25: 0 | P25: 1 | Q25: 0 | R25: 2 | S25: 2 | T25: 0 | U25: 0 | V25: 0 | W25: 1 | X25: 0 | Y25: 0 | Z25: 2 | AA25: 0 | AB25: 0 | AC25: 1 | AD25: 0 | AE25: =SUM(E25:AD25) -> 18
D26: PR | E26: 1 | F26: 1 | G26: 1 | H26: 0 | I26: 2 | J26: 0 | K26: 0 | L26: 0 | M26: 1 | N26: 0 | O26: 1 | P26: 0 | Q26: 0 | R26: 0 | S26: 4 | T26: 1 | U26: 0 | V26: 1 | W26: 0 | X26: 0 | Y26: 1 | Z26: 2 | AA26: 0 | AB26: 0 | AC26: 0 | AD26: 1 | AE26: =SUM(E26:AD26) -> 17
D27: JML | E27: 2 | F27: 2 | G27: 2 | H27: 0 | I27: 3 | J27: 0 | K27: 0 | L27: 0 | M27: 5 | N27: 1 | O27: 1 | P27: 1 | Q27: 0 | R27: 2 | S27: 6 | T27: 1 | U27: 0 | V27: 1 | W27: 1 | X27: 0 | Y27: 1 | Z27: 4 | AA27: 0 | AB27: 0 | AC27: 1 | AD27: 1 | AE27: =SUM(E27:AD27) -> 35
B28: 4. | C28: Jumlah Pengguna Hak Pilih (B.1+B.2+B.3) | D28: LK | E28: 101 | F28: 107 | G28: 118 | H28: 94 | I28: 104 | J28: 81 | K28: 117 | L28: 89 | M28: 94 | N28: 94 | O28: 93 | P28: 110 | Q28: 114 | R28: 121 | S28: 99 | T28: 102 | U28: 108 | V28: 125 | W28: 120 | X28: 113 | Y28: 112 | Z28: 98 | AA28: 91 | AB28: 89 | AC28: 108 | AD28: 84 | AE28: =SUM(E28:AD28) -> 2686
D29: PR | E29: 109 | F29: 107 | G29: 118 | H29: 98 | I29: 107 | J29: 85 | K29: 120 | L29: 107 | M29: 111 | N29: 99 | O29: 102 | P29: 102 | Q29: 126 | R29: 115 | S29: 110 | T29: 107 | U29: 116 | V29: 112 | W29: 114 | X29: 107 | Y29: 102 | Z29: 115 | AA29: 97 | AB29: 86 | AC29: 112 | AD29: 97 | AE29: =SUM(E29:AD29) -> 2781
D30: JML | E30: =SUM(E28:E29) -> 210 | F30: =SUM(F28:F29) -> 214 | G30: =SUM(G28:G29) -> 236 | H30: =SUM(H28:H29) -> 192 | I30: =SUM(I28:I29) -> 211 | J30: =SUM(J28:J29) -> 166 | K30: =SUM(K28:K29) -> 237 | L30: =SUM(L28:L29) -> 196 | ... AD30: =SUM(AD28:AD29) -> 181 | AE30: =SUM(E30:AD30) -> 5467
A32: II | B32: DATA PENGGUNAAN SURAT SUARA
A33: 1 | B33: Jumlah surat suara yang diterima, termasuk surat suara cadangan 2,5% dari DPT | E33: 264 | F33: 284 | G33: 292 | H33: 257 | I33: 271 | J33: 211 | K33: 290 | L33: 252 | M33: 273 | N33: 246 | O33: 240 | P33: 284 | Q33: 304 | R33: 298 | S33: 270 | T33: 283 | U33: 290 | V33: 304 | W33: 297 | X33: 300 | Y33: 301 | Z33: 294 | AA33: 253 | AB33: 223 | AC33: 275 | AD33: 231 | AE33: =SUM(E33:AD33) -> 7087
A34: 2 | B34: Jumlah surat suara yang digunakan | E34: 210 | F34: 214 | G34: 236 | H34: 192 | I34: 211 | J34: 166 | K34: 237 | L34: 196 | M34: 205 | N34: 193 | O34: 195 | P34: 212 | Q34: 240 | R34: 236 | S34: 209 | T34: 209 | U34: 224 | V34: 237 | W34: 234 | X34: 220 | Y34: 214 | Z34: 213 | AA34: 188 | AB34: 175 | AC34: 220 | AD34: 181 | AE34: =SUM(E34:AD34) -> 5467
A35: 3 | B35: Jumlah surat suara dikembalikan oleh pemilih (karena rusak atau keliru coblos) | E35: 0 | F35: 0 | G35: 5 | H35: 1 | I35: 0 | J35: 0 | K35: 3 | L35: 0 | M35: 0 | N35: 2 | O35: 2 | P35: 5 | Q35: 2 | R35: 0 | S35: 0 | T35: 0 | U35: 0 | V35: 0 | W35: 1 | X35: 0 | Y35: 3 | Z35: 1 | AA35: 0 | AB35: 1 | AC35: 0 | AD35: 1 | AE35: =SUM(E35:AD35) -> 27
A36: 4 | B36: Jumlah surat suara yang tidak digunakan/tidak terpakai, termasuk sisa surat suara cadangan | E36: 54 | F36: 70 | G36: 51 | H36: 64 | I36: 60 | J36: 45 | K36: 50 | L36: 56 | M36: 68 | N36: 51 | O36: 43 | P36: 67 | Q36: 62 | R36: 62 | S36: 61 | T36: 74 | U36: 66 | V36: 67 | W36: 62 | X36: 80 | Y36: 84 | Z36: 80 | AA36: 65 | AB36: 47 | AC36: 55 | AD36: 49 | AE36: =SUM(E36:AD36) -> 1593
A38: III | B38: DATA PEMILIH DISABILITAS
B39: Jumlah seluruh Pemilih disabilitas yang menggunakan hak pilih | D39: LK | E39: 1 | F39: 0 | G39: 0 | H39: 0 | I39: 0 | J39: 0 | K39: 0 | L39: 0 | M39: 0 | N39: 0 | O39: 0 | P39: 0 | Q39: 5 | R39: 0 | S39: 0 | T39: 0 | U39: 0 | V39: 0 | W39: 0 | X39: 0 | Y39: 0 | Z39: 0 | AA39: 0 | AB39: 1 | AC39: 0 | AD39: 0 | AE39: =SUM(E39:AD39) -> 7
D40: PR | E40: 0 | F40: 0 | G40: 0 | H40: 0 | I40: 0 | J40: 0 | K40: 0 | L40: 0 | M40: 0 | N40: 0 | O40: 0 | P40: 0 | Q40: 4 | R40: 0 | S40: 0 | T40: 0 | U40: 0 | V40: 0 | W40: 0 | X40: 0 | Y40: 0 | Z40: 0 | AA40: 0 | AB40: 3 | AC40: 0 | AD40: 0 | AE40: =SUM(E40:AD40) -> 7
D41: JML | E41: =SUM(E39:E40) -> 1 | F41: =SUM(F39:F40) -> 0 | G41: =SUM(G39:G40) -> 0 | H41: =SUM(H39:H40) -> 0 | I41: =SUM(I39:I40) -> 0 | J41: =SUM(J39:J40) -> 0 | K41: =SUM(K39:K40) -> 0 | L41: =SUM(L39:L40) -> 0 | ... AD41: =SUM(AD39:AD40) -> 0 | AE41: =SUM(E41:AD41) -> 14
A43: IV | B43: DATA RINCIAN PEROLEHAN SUARA PASANGAN CALON BUPATI DAN WAKIL BUPATI
A44: NOMOR DAN NAMA CALON
A45: A.1 | B45: 1. | C45: Partai Kebangkitan Bangsa | E45: 5 | F45: 4 | G45: 4 | H45: 2 | I45: 1 | J45: 1 | K45: 4 | L45: 10 | M45: 4 | N45: 9 | O45: 5 | P45: 5 | Q45: 0 | R45: 6 | S45: 12 | T45: 8 | U45: 8 | V45: 1 | W45: 3 | X45: 7 | Y45: 5 | Z45: 9 | AA45: 13 | AB45: 2 | AC45: 11 | AD45: 2 | AE45: =SUM(E45:AD45) -> 141
A46: A.2 | B46: 1 | C46: KH. MUHAMMAD RIZA AZIZY, M.IEB. | E46: 0 | F46: 0 | G46: 1 | H46: 0 | I46: 1 | J46: 0 | K46: 1 | L46: 9 | M46: 14 | N46: 8 | O46: 5 | P46: 0 | Q46: 2 | R46: 3 | S46: 8 | T46: 8 | U46: 7 | V46: 1 | W46: 1 | X46: 6 | Y46: 2 | Z46: 5 | AA46: 6 | AB46: 0 | AC46: 4 | AD46: 4 | AE46: =SUM(E46:AD46) -> 96
B47: 2 | C47: INAYANTI KUSUMASARI, S.E. | E47: 49 | F47: 14 | G47: 16 | H47: 21 | I47: 22 | J47: 14 | K47: 19 | L47: 40 | M47: 54 | N47: 51 | O47: 43 | P47: 7 | Q47: 7 | R47: 22 | S47: 44 | T47: 60 | U47: 65 | V47: 11 | W47: 38 | X47: 40 | Y47: 34 | Z47: 113 | AA47: 111 | AB47: 29 | AC47: 140 | AD47: 86 | AE47: =SUM(E47:AD47) -> 1150
B48: 3 | C48: TOPAN HADI SUCIPTO, S.H. | E48: 1 | F48: 0 | G48: 0 | H48: 0 | I48: 0 | J48: 0 | K48: 1 | L48: 0 | M48: 0 | N48: 1 | O48: 0 | P48: 0 | Q48: 0 | R48: 0 | S48: 0 | T48: 0 | U48: 1 | V48: 1 | W48: 1 | X48: 1 | Y48: 0 | Z48: 1 | AA48: 2 | AB48: 1 | AC48: 2 | AD48: 1 | AE48: =SUM(E48:AD48) -> 14
B49: 4 | C49: HAULA KARIMA AKBAR, S.PD. | E49: 0 | F49: 0 | G49: 0 | H49: 0 | I49: 0 | J49: 0 | K49: 1 | L49: 0 | M49: 0 | N49: 1 | O49: 0 | P49: 0 | Q49: 0 | R49: 0 | S49: 1 | T49: 0 | U49: 1 | V49: 0 | W49: 0 | X49: 0 | Y49: 0 | Z49: 0 | AA49: 0 | AB49: 0 | AC49: 0 | AD49: 0 | AE49: =SUM(E49:AD49) -> 4
B50: 5 | C50: SUGENG HARYONO | E50: 0 | F50: 0 | G50: 0 | H50: 0 | I50: 1 | J50: 0 | K50: 0 | L50: 0 | M50: 0 | N50: 0 | O50: 0 | P50: 1 | Q50: 0 | R50: 1 | S50: 0 | T50: 0 | U50: 0 | V50: 0 | W50: 0 | X50: 0 | Y50: 0 | Z50: 0 | AA50: 0 | AB50: 0 | AC50: 0 | AD50: 0 | AE50: =SUM(E50:AD50) -> 3
B51: 6 | C51: MOH. RIYADUS SHOLIHIN, A.MD. | E51: 0 | F51: 0 | G51: 0 | H51: 0 | I51: 0 | J51: 0 | K51: 0 | L51: 0 | M51: 0 | N51: 0 | O51: 1 | P51: 0 | Q51: 0 | R51: 0 | S51: 0 | T51: 0 | U51: 1 | V51: 3 | W51: 0 | X51: 0 | Y51: 0 | Z51: 1 | AA51: 0 | AB51: 0 | AC51: 0 | AD51: 0 | AE51: =SUM(E51:AD51) -> 6
...

Sheet SARIMULYO
C2: Kecamatan | D2: CLURING
C3: Kabupaten | D3: BANYUWANGI
C4: Provinsi | D4: JAWA TIMUR
C9: Kelurahan | D9: SARIMULYO
A12: I | B12: DATA PEMILIH DAN PENGGUNAAN HAK PILIH | AA12: JUMLAH AKHIR
A13: A | B13: DATA PEMILIH | E13: TPS 001 | F13: TPS 002 | G13: TPS 003 | H13: TPS 004 | I13: TPS 005 | J13: TPS 006 | K13: TPS 007 | L13: TPS 008 | M13: TPS 009 | N13: TPS 010 | O13: TPS 011 | P13: TPS 012 | Q13: TPS 013 | R13: TPS 014 | S13: TPS 015 | T13: TPS 016 | U13: TPS 017 | V13: TPS 018 | W13: TPS 019 | X13: TPS 020 | Y13: TPS 021 | Z13: TPS 022
B14: Jumlah Pemilih dalam Daftar Pemilih Tetap (DPT) | D14: LK | E14: 143 | F14: 118 | G14: 113 | H14: 127 | I14: 135 | J14: 129 | K14: 128 | L14: 102 | M14: 122 | N14: 114 | O14: 136 | P14: 113 | Q14: 124 | R14: 135 | S14: 125 | T14: 110 | U14: 115 | V14: 126 | W14: 143 | X14: 155 | Y14: 143 | Z14: 137 | AA14: =SUM(E14:Z14) -> 2793
D15: PR | E15: 125 | F15: 134 | G15: 114 | H15: 133 | I15: 137 | J15: 152 | K15: 136 | L15: 110 | M15: 120 | N15: 117 | O15: 129 | P15: 135 | Q15: 118 | R15: 137 | S15: 122 | T15: 115 | U15: 114 | V15: 139 | W15: 137 | X15: 142 | Y15: 149 | Z15: 132 | AA15: =SUM(E15:Z15) -> 2847
D16: JML | E16: =SUM(E14:E15) -> 268 | F16: =SUM(F14:F15) -> 252 | G16: =SUM(G14:G15) -> 227 | H16: =SUM(H14:H15) -> 260 | I16: =SUM(I14:I15) -> 272 | J16: =SUM(J14:J15) -> 281 | K16: =SUM(K14:K15) -> 264 | L16: =SUM(L14:L15) -> 212 | ... Z16: =SUM(Z14:Z15) -> 269 | AA16: =SUM(E16:Z16) -> 5640
A18: B | B18: PENGGUNA HAK PILIH
B19: 1. | C19: Jumlah pengguna hak pilih dalam Daftar Pemilih Tetap (DPT) | D19: LK | E19: 103 | F19: 93 | G19: 79 | H19: 82 | I19: 98 | J19: 95 | K19: 91 | L19: 71 | M19: 92 | N19: 78 | O19: 103 | P19: 94 | Q19: 96 | R19: 96 | S19: 88 | T19: 78 | U19: 94 | V19: 85 | W19: 96 | X19: 119 | Y19: 103 | Z19: 115 | AA19: =SUM(E19:Z19) -> 2049
D20: PR | E20: 104 | F20: 113 | G20: 88 | H20: 106 | I20: 104 | J20: 124 | K20: 107 | L20: 74 | M20: 101 | N20: 84 | O20: 103 | P20: 113 | Q20: 97 | R20: 111 | S20: 94 | T20: 87 | U20: 87 | V20: 118 | W20: 104 | X20: 122 | Y20: 122 | Z20: 113 | AA20: =SUM(E20:Z20) -> 2276
D21: JML | E21: =SUM(E19:E20) -> 207 | F21: =SUM(F19:F20) -> 206 | G21: =SUM(G19:G20) -> 167 | H21: =SUM(H19:H20) -> 188 | I21: =SUM(I19:I20) -> 202 | J21: =SUM(J19:J20) -> 219 | K21: =SUM(K19:K20) -> 198 | L21: =SUM(L19:L20) -> 145 | ... Z21: =SUM(Z19:Z20) -> 228 | AA21: =SUM(E21:Z21) -> 4325
B22: 2. | C22: Jumlah pengguna hak pilih dalam Daftar Pemilih Tambahan (DPTb) | D22: LK | E22: 0 | F22: 0 | G22: 0 | H22: 0 | I22: 0 | J22: 0 | K22: 1 | L22: 0 | M22: 0 | N22: 0 | O22: 0 | P22: 0 | Q22: 0 | R22: 0 | S22: 0 | T22: 0 | U22: 0 | V22: 0 | W22: 0 | X22: 0 | Y22: 0 | Z22: 0 | AA22: =SUM(E22:Z22) -> 1
D23: PR | E23: 0 | F23: 0 | G23: 0 | H23: 0 | I23: 0 | J23: 0 | K23: 0 | L23: 0 | M23: 0 | N23: 0 | O23: 0 | P23: 0 | Q23: 0 | R23: 0 | S23: 0 | T23: 0 | U23: 0 | V23: 0 | W23: 0 | X23: 0 | Y23: 0 | Z23: 0 | AA23: =SUM(E23:Z23) -> 0
D24: JML | E24: =SUM(E22:E23) -> 0 | F24: =SUM(F22:F23) -> 0 | G24: =SUM(G22:G23) -> 0 | H24: =SUM(H22:H23) -> 0 | I24: =SUM(I22:I23) -> 0 | J24: =SUM(J22:J23) -> 0 | K24: =SUM(K22:K23) -> 1 | L24: =SUM(L22:L23) -> 0 | ... Z24: =SUM(Z22:Z23) -> 0 | AA24: =SUM(E24:Z24) -> 1
B25: 3. | C25: Jumlah pengguna hak pilih dalam Daftar Pemilih Khusus (DPK) | D25: LK | E25: 3 | F25: 1 | G25: 2 | H25: 0 | I25: 2 | J25: 3 | K25: 1 | L25: 1 | M25: 1 | N25: 2 | O25: 0 | P25: 0 | Q25: 2 | R25: 3 | S25: 2 | T25: 0 | U25: 1 | V25: 2 | W25: 2 | X25: 0 | Y25: 0 | Z25: 0 | AA25: =SUM(E25:Z25) -> 28
D26: PR | E26: 2 | F26: 3 | G26: 2 | H26: 1 | I26: 2 | J26: 2 | K26: 0 | L26: 3 | M26: 4 | N26: 3 | O26: 3 | P26: 3 | Q26: 2 | R26: 3 | S26: 4 | T26: 0 | U26: 4 | V26: 2 | W26: 0 | X26: 0 | Y26: 0 | Z26: 0 | AA26: =SUM(E26:Z26) -> 43
D27: JML | E27: =SUM(E25:E26) -> 5 | F27: =SUM(F25:F26) -> 4 | G27: =SUM(G25:G26) -> 4 | H27: =SUM(H25:H26) -> 1 | I27: =SUM(I25:I26) -> 4 | J27: =SUM(J25:J26) -> 5 | K27: =SUM(K25:K26) -> 1 | L27: =SUM(L25:L26) -> 4 | ... Z27: =SUM(Z25:Z26) -> 0 | AA27: =SUM(E27:Z27) -> 71
B28: 4. | C28: Jumlah Pengguna Hak Pilih (B.1+B.2+B.3) | D28: LK | E28: =E19+E22+E25 -> 106 | F28: =F19+F22+F25 -> 94 | G28: =G19+G22+G25 -> 81 | H28: =H19+H22+H25 -> 82 | I28: =I19+I22+I25 -> 100 | J28: =J19+J22+J25 -> 98 | K28: =K19+K22+K25 -> 93 | L28: =L19+L22+L25 -> 72 | ... Z28: =Z19+Z22+Z25 -> 115 | AA28: =SUM(E28:Z28) -> 2078
D29: PR | E29: =E20+E23+E26 -> 106 | F29: =F20+F23+F26 -> 116 | G29: =G20+G23+G26 -> 90 | H29: =H20+H23+H26 -> 107 | I29: =I20+I23+I26 -> 106 | J29: =J20+J23+J26 -> 126 | K29: =K20+K23+K26 -> 107 | L29: =L20+L23+L26 -> 77 | ... Z29: =Z20+Z23+Z26 -> 113 | AA29: =SUM(E29:Z29) -> 2319
D30: JML | E30: =SUM(E28:E29) -> 212 | F30: =SUM(F28:F29) -> 210 | G30: =SUM(G28:G29) -> 171 | H30: =SUM(H28:H29) -> 189 | I30: =SUM(I28:I29) -> 206 | J30: =SUM(J28:J29) -> 224 | K30: =SUM(K28:K29) -> 200 | L30: =SUM(L28:L29) -> 149 | ... Z30: =SUM(Z28:Z29) -> 228 | AA30: =SUM(E30:Z30) -> 4397
A32: II | B32: DATA PENGGUNAAN SURAT SUARA
A33: 1 | B33: Jumlah surat suara yang diterima, termasuk surat suara cadangan 2,5% dari DPT | E33: 272 | F33: 256 | G33: 232 | H33: 264 | I33: 276 | J33: 287 | K33: 270 | L33: 217 | M33: 248 | N33: 233 | O33: 269 | P33: 251 | Q33: 247 | R33: 276 | S33: 252 | T33: 230 | U33: 234 | V33: 278 | W33: 286 | X33: 300 | Y33: 298 | Z33: 275 | AA33: =SUM(E33:Z33) -> 5751
A34: 2 | B34: Jumlah surat suara yang digunakan | E34: 212 | F34: 210 | G34: 171 | H34: 189 | I34: 206 | J34: 224 | K34: 200 | L34: 149 | M34: 198 | N34: 167 | O34: 209 | P34: 210 | Q34: 197 | R34: 213 | S34: 188 | T34: 165 | U34: 186 | V34: 207 | W34: 202 | X34: 241 | Y34: 225 | Z34: 228 | AA34: =SUM(E34:Z34) -> 4397
A35: 3 | B35: Jumlah surat suara dikembalikan oleh pemilih (karena rusak atau keliru coblos) | E35: 2 | F35: 0 | G35: 0 | H35: 0 | I35: 0 | J35: 0 | K35: 0 | L35: 0 | M35: 0 | N35: 0 | O35: 0 | P35: 1 | Q35: 1 | R35: 0 | S35: 0 | T35: 0 | U35: 0 | V35: 2 | W35: 0 | X35: 2 | Y35: 0 | Z35: 0 | AA35: =SUM(E35:Z35) -> 8
A36: 4 | B36: Jumlah surat suara yang tidak digunakan/tidak terpakai, termasuk sisa surat suara cadangan | E36: =E33-E34-E35 -> 58 | F36: =F33-F34-F35 -> 46 | G36: =G33-G34-G35 -> 61 | H36: =H33-H34-H35 -> 75 | I36: =I33-I34-I35 -> 70 | J36: =J33-J34-J35 -> 63 | K36: =K33-K34-K35 -> 70 | L36: =L33-L34-L35 -> 68 | ... Z36: =Z33-Z34-Z35 -> 47 | AA36: =SUM(E36:Z36) -> 1346
A38: III | B38: DATA PEMILIH DISABILITAS
B39: Jumlah seluruh Pemilih disabilitas yang menggunakan hak pilih | D39: LK | E39: 0 | F39: 0 | G39: 0 | H39: 0 | I39: 0 | J39: 0 | K39: 0 | L39: 0 | M39: 0 | N39: 0 | O39: 0 | P39: 0 | Q39: 0 | R39: 0 | S39: 0 | T39: 0 | U39: 0 | V39: 0 | W39: 0 | X39: 0 | Y39: 0 | Z39: 0 | AA39: =SUM(E39:Z39) -> 0
D40: PR | E40: 0 | F40: 0 | G40: 0 | H40: 0 | I40: 0 | J40: 0 | K40: 0 | L40: 0 | M40: 0 | N40: 0 | O40: 0 | P40: 0 | Q40: 0 | R40: 2 | S40: 0 | T40: 0 | U40: 0 | V40: 0 | W40: 0 | X40: 0 | Y40: 0 | Z40: 0 | AA40: =SUM(E40:Z40) -> 2
D41: JML | E41: =SUM(E39:E40) -> 0 | F41: =SUM(F39:F40) -> 0 | G41: =SUM(G39:G40) -> 0 | H41: =SUM(H39:H40) -> 0 | I41: =SUM(I39:I40) -> 0 | J41: =SUM(J39:J40) -> 0 | K41: =SUM(K39:K40) -> 0 | L41: =SUM(L39:L40) -> 0 | ... Z41: =SUM(Z39:Z40) -> 0 | AA41: =SUM(E41:Z41) -> 2
A43: IV | B43: DATA RINCIAN PEROLEHAN SUARA PASANGAN CALON BUPATI DAN WAKIL BUPATI
A44: NOMOR DAN NAMA CALON
A45: A.1 | B45: 1. | C45: Partai Kebangkitan Bangsa | E45: 11 | F45: 3 | G45: 7 | H45: 8 | I45: 8 | J45: 10 | K45: 3 | L45: 3 | M45: 4 | N45: 4 | O45: 5 | P45: 2 | Q45: 2 | R45: 5 | S45: 1 | T45: 3 | U45: 3 | V45: 11 | W45: 8 | X45: 4 | Y45: 6 | Z45: 4 | AA45: =SUM(E45:Z45) -> 115
A46: A.2 | B46: 1 | C46: KH. MUHAMMAD RIZA AZIZY, M.IEB. | E46: 7 | F46: 2 | G46: 4 | H46: 4 | I46: 9 | J46: 3 | K46: 11 | L46: 2 | M46: 3 | N46: 2 | O46: 5 | P46: 1 | Q46: 2 | R46: 0 | S46: 1 | T46: 4 | U46: 4 | V46: 3 | W46: 5 | X46: 8 | Y46: 4 | Z46: 5 | AA46: =SUM(E46:Z46) -> 89
B47: 2 | C47: INAYANTI KUSUMASARI, S.E. | E47: 76 | F47: 31 | G47: 63 | H47: 68 | I47: 44 | J47: 52 | K47: 20 | L47: 45 | M47: 22 | N47: 38 | O47: 39 | P47: 17 | Q47: 11 | R47: 14 | S47: 33 | T47: 27 | U47: 42 | V47: 124 | W47: 96 | X47: 78 | Y47: 38 | Z47: 16 | AA47: =SUM(E47:Z47) -> 994
B48: 3 | C48: TOPAN HADI SUCIPTO, S.H. | E48: 29 | F48: 15 | G48: 1 | H48: 14 | I48: 1 | J48: 1 | K48: 1 | L48: 0 | M48: 0 | N48: 0 | O48: 1 | P48: 0 | Q48: 0 | R48: 0 | S48: 0 | T48: 0 | U48: 2 | V48: 0 | W48: 2 | X48: 3 | Y48: 0 | Z48: 1 | AA48: =SUM(E48:Z48) -> 71
B49: 4 | C49: HAULA KARIMA AKBAR, S.PD. | E49: 0 | F49: 0 | G49: 0 | H49: 1 | I49: 0 | J49: 0 | K49: 0 | L49: 0 | M49: 0 | N49: 0 | O49: 0 | P49: 0 | Q49: 0 | R49: 0 | S49: 1 | T49: 0 | U49: 0 | V49: 0 | W49: 0 | X49: 0 | Y49: 0 | Z49: 0 | AA49: =SUM(E49:Z49) -> 2
B50: 5 | C50: SUGENG HARYONO | E50: 0 | F50: 0 | G50: 0 | H50: 0 | I50: 0 | J50: 0 | K50: 0 | L50: 0 | M50: 0 | N50: 0 | O50: 1 | P50: 0 | Q50: 0 | R50: 0 | S50: 0 | T50: 0 | U50: 0 | V50: 0 | W50: 0 | X50: 0 | Y50: 0 | Z50: 0 | AA50: =SUM(E50:Z50) -> 1
B51: 6 | C51: MOH. RIYADUS SHOLIHIN, A.MD. | E51: 2 | F51: 0 | G51: 0 | H51: 0 | I51: 0 | J51: 0 | K51: 1 | L51: 0 | M51: 0 | N51: 1 | O51: 4 | P51: 4 | Q51: 0 | R51: 1 | S51: 0 | T51: 3 | U51: 1 | V51: 0 | W51: 1 | X51: 0 | Y51: 0 | Z51: 0 | AA51: =SUM(E51:Z51) -> 18
...

Sheet SEMBULUNG
C2: Kecamatan | D2: CLURING
C3: Kabupaten | D3: BANYUWANGI
C4: Provinsi | D4: JAWA TIMUR
C9: Kelurahan | D9: SEMBULUNG
A12: I | B12: DATA PEMILIH DAN PENGGUNAAN HAK PILIH | AC12: JUMLAH AKHIR
A13: A | B13: DATA PEMILIH | E13: TPS 001 | F13: TPS 002 | G13: TPS 003 | H13: TPS 004 | I13: TPS 005 | J13: TPS 006 | K13: TPS 007 | L13: TPS 008 | M13: TPS 009 | N13: TPS 010 | O13: TPS 011 | P13: TPS 012 | Q13: TPS 013 | R13: TPS 014 | S13: TPS 015 | T13: TPS 016 | U13: TPS 017 | V13: TPS 018 | W13: TPS 019 | X13: TPS 020 | Y13: TPS 021 | Z13: TPS 022 | AA13: TPS 023 | AB13: TPS 024
B14: Jumlah Pemilih dalam Daftar Pemilih Tetap (DPT) | D14: LK | E14: 123 | F14: 126 | G14: 140 | H14: 149 | I14: 141 | J14: 133 | K14: 140 | L14: 143 | M14: 128 | N14: 131 | O14: 126 | P14: 120 | Q14: 133 | R14: 139 | S14: 136 | T14: 139 | U14: 134 | V14: 136 | W14: 146 | X14: 127 | Y14: 128 | Z14: 132 | AA14: 133 | AB14: 122 | AC14: =SUM(E14:AB14) -> 3205
D15: PR | E15: 146 | F15: 131 | G15: 129 | H15: 138 | I15: 132 | J15: 144 | K15: 136 | L15: 148 | M15: 127 | N15: 123 | O15: 129 | P15: 117 | Q15: 120 | R15: 153 | S15: 135 | T15: 142 | U15: 130 | V15: 157 | W15: 133 | X15: 162 | Y15: 127 | Z15: 145 | AA15: 124 | AB15: 112 | AC15: =SUM(E15:AB15) -> 3240
D16: JML | E16: =SUM(E14:E15) -> 269 | F16: =SUM(F14:F15) -> 257 | G16: =SUM(G14:G15) -> 269 | H16: =SUM(H14:H15) -> 287 | I16: =SUM(I14:I15) -> 273 | J16: =SUM(J14:J15) -> 277 | K16: =SUM(K14:K15) -> 276 | L16: =SUM(L14:L15) -> 291 | ... AB16: =SUM(AB14:AB15) -> 234 | AC16: =SUM(E16:AB16) -> 6445
A18: B | B18: PENGGUNA HAK PILIH
