Workbook

Sheet DPRD KABUPATEN
C8: Kecamatan | D8: GLENMORE
C9: Kabupaten | D9: BANYUWANGI
C10: Provinsi | D10: JAWA TIMUR
A12: I | B12: DATA PEMILIH DAN PENGGUNAAN HAK PILIH | E12: JUMLAH AKHIR
A13: A | B13: DATA PEMILIH
B14: Jumlah Pemilih dalam Daftar Pemilih Tetap (DPT) | D14: LK | E14: =BUMIHARJO!AE14+KARANGHARJO!BK14+MARGOMULYO!S14+SEPANJANG!AJ14+SUMBERGONDO!AB14+TEGALHARJO!AP14+TULUNGREJO!BL14 -> 29418
D15: PR | E15: =BUMIHARJO!AE15+KARANGHARJO!BK15+MARGOMULYO!S15+SEPANJANG!AJ15+SUMBERGONDO!AB15+TEGALHARJO!AP15+TULUNGREJO!BL15 -> 30287
D16: JML | E16: =SUM(E14:E15) -> 59705
A18: B | B18: PENGGUNA HAK PILIH
B19: 1. | C19: Jumlah pengguna hak pilih dalam Daftar Pemilih Tetap (DPT) | D19: LK | E19: =BUMIHARJO!AE19+KARANGHARJO!BK19+MARGOMULYO!S19+SEPANJANG!AJ19+SUMBERGONDO!AB19+TEGALHARJO!AP19+TULUNGREJO!BL19 -> 21583
D20: PR | E20: =BUMIHARJO!AE20+KARANGHARJO!BK20+MARGOMULYO!S20+SEPANJANG!AJ20+SUMBERGONDO!AB20+TEGALHARJO!AP20+TULUNGREJO!BL20 -> 23929
D21: JML | E21: =SUM(E19:E20) -> 45512
B22: 2. | C22: Jumlah pengguna hak pilih dalam Daftar Pemilih Tambahan (DPTb) | D22: LK | E22: =BUMIHARJO!AE22+KARANGHARJO!BK22+MARGOMULYO!S22+SEPANJANG!AJ22+SUMBERGONDO!AB22+TEGALHARJO!AP22+TULUNGREJO!BL22 -> 74
D23: PR | E23: =BUMIHARJO!AE23+KARANGHARJO!BK23+MARGOMULYO!S23+SEPANJANG!AJ23+SUMBERGONDO!AB23+TEGALHARJO!AP23+TULUNGREJO!BL23 -> 54
D24: JML | E24: =SUM(E22:E23) -> 128
B25: 3. | C25: Jumlah pengguna hak pilih dalam Daftar Pemilih Khusus (DPK) | D25: LK | E25: =BUMIHARJO!AE25+KARANGHARJO!BK25+MARGOMULYO!S25+SEPANJANG!AJ25+SUMBERGONDO!AB25+TEGALHARJO!AP25+TULUNGREJO!BL25 -> 143
D26: PR | E26: =BUMIHARJO!AE26+KARANGHARJO!BK26+MARGOMULYO!S26+SEPANJANG!AJ26+SUMBERGONDO!AB26+TEGALHARJO!AP26+TULUNGREJO!BL26 -> 197
D27: JML | E27: =SUM(E25:E26) -> 340
B28: 4. | C28: Jumlah Pengguna Hak Pilih (B.1+B.2+B.3) | D28: LK | E28: =E19+E22+E25 -> 21800
D29: PR | E29: =E20+E23+E26 -> 24180
D30: JML | E30: =SUM(E28:E29) -> 45980
A32: II | B32: DATA PENGGUNAAN SURAT SUARA
A33: 1 | B33: Jumlah surat suara yang diterima, termasuk surat suara cadangan 2,5% dari DPT | E33: =BUMIHARJO!AE33+KARANGHARJO!BK33+MARGOMULYO!S33+SEPANJANG!AJ33+SUMBERGONDO!AB33+TEGALHARJO!AP33+TULUNGREJO!BL33 -> 61110
A34: 2 | B34: Jumlah surat suara yang digunakan | E34: =BUMIHARJO!AE34+KARANGHARJO!BK34+MARGOMULYO!S34+SEPANJANG!AJ34+SUMBERGONDO!AB34+TEGALHARJO!AP34+TULUNGREJO!BL34 -> 45980
A35: 3 | B35: Jumlah surat suara dikembalikan oleh pemilih (karena rusak atau keliru coblos) | E35: =BUMIHARJO!AE35+KARANGHARJO!BK35+MARGOMULYO!S35+SEPANJANG!AJ35+SUMBERGONDO!AB35+TEGALHARJO!AP35+TULUNGREJO!BL35 -> 83
A36: 4 | B36: Jumlah surat suara yang tidak digunakan/tidak terpakai, termasuk sisa surat suara cadangan | E36: =E33-(E34+E35) -> 15047
A38: III | B38: DATA PEMILIH DISABILITAS
B39: Jumlah seluruh Pemilih disabilitas yang menggunakan hak pilih | D39: LK | E39: =BUMIHARJO!AE39+KARANGHARJO!BK39+MARGOMULYO!S39+SEPANJANG!AJ39+SUMBERGONDO!AB39+TEGALHARJO!AP39+TULUNGREJO!BL39 -> 38
D40: PR | E40: =BUMIHARJO!AE40+KARANGHARJO!BK40+MARGOMULYO!S40+SEPANJANG!AJ40+SUMBERGONDO!AB40+TEGALHARJO!AP40+TULUNGREJO!BL40 -> 65
D41: JML | E41: =SUM(E39:E40) -> 103
A43: IV | B43: DATA RINCIAN PEROLEHAN SUARA PASANGAN CALON BUPATI DAN WAKIL BUPATI
A44: NOMOR DAN NAMA CALON
A45: A.1 | B45: 1. | C45: Partai Kebangkitan Bangsa | E45: =BUMIHARJO!AE45+KARANGHARJO!BK45+MARGOMULYO!S45+SEPANJANG!AJ45+SUMBERGONDO!AB45+TEGALHARJO!AP45+TULUNGREJO!BL45 -> 933
A46: A.2 | C46: 1. H. KHUSNAN, S.Ag., M.Pd.I. | E46: =BUMIHARJO!AE46+KARANGHARJO!BK46+MARGOMULYO!S46+SEPANJANG!AJ46+SUMBERGONDO!AB46+TEGALHARJO!AP46+TULUNGREJO!BL46 -> 830
C47: 2. MARA QONITHA LAYLIA | E47: =BUMIHARJO!AE47+KARANGHARJO!BK47+MARGOMULYO!S47+SEPANJANG!AJ47+SUMBERGONDO!AB47+TEGALHARJO!AP47+TULUNGREJO!BL47 -> 1882
C48: 3. ZAKI AL MUBAROK, M.Si. | E48: =BUMIHARJO!AE48+KARANGHARJO!BK48+MARGOMULYO!S48+SEPANJANG!AJ48+SUMBERGONDO!AB48+TEGALHARJO!AP48+TULUNGREJO!BL48 -> 2289
C49: 4. INAYATUL MAHMUDAH, S.Pd. | E49: =BUMIHARJO!AE49+KARANGHARJO!BK49+MARGOMULYO!S49+SEPANJANG!AJ49+SUMBERGONDO!AB49+TEGALHARJO!AP49+TULUNGREJO!BL49 -> 97
C50: 5. HABIBURRAHMAN AL KHOLILI | E50: =BUMIHARJO!AE50+KARANGHARJO!BK50+MARGOMULYO!S50+SEPANJANG!AJ50+SUMBERGONDO!AB50+TEGALHARJO!AP50+TULUNGREJO!BL50 -> 45
C51: 6. INDIARTI NOVIDA, A.Md. | E51: =BUMIHARJO!AE51+KARANGHARJO!BK51+MARGOMULYO!S51+SEPANJANG!AJ51+SUMBERGONDO!AB51+TEGALHARJO!AP51+TULUNGREJO!BL51 -> 8
C52: 7. RUDI DARMAWAN, S.Pd.I. | E52: =BUMIHARJO!AE52+KARANGHARJO!BK52+MARGOMULYO!S52+SEPANJANG!AJ52+SUMBERGONDO!AB52+TEGALHARJO!AP52+TULUNGREJO!BL52 -> 23
...

Sheet BUMIHARJO
C2: Kecamatan | D2: GLENMORE
C3: Kabupaten | D3: BANYUWANGI
C4: Provinsi | D4: JAWA TIMUR
C9: Kelurahan | D9: BUMIHARJO
A12: I | B12: DATA PEMILIH DAN PENGGUNAAN HAK PILIH | AE12: JUMLAH AKHIR
A13: A | B13: DATA PEMILIH | E13: TPS 001 | F13: TPS 002 | G13: TPS 003 | H13: TPS 004 | I13: TPS 005 | J13: TPS 006 | K13: TPS 007 | L13: TPS 008 | M13: TPS 009 | N13: TPS 010 | O13: TPS 011 | P13: TPS 012 | Q13: TPS 013 | R13: TPS 014 | S13: TPS 015 | T13: TPS 016 | U13: TPS 017 | V13: TPS 018 | W13: TPS 019 | X13: TPS 020 | Y13: TPS 021 | Z13: TPS 022 | AA13: TPS 023 | AB13: TPS 024 | AC13: TPS 025 | AD13: TPS 026
B14: Jumlah Pemilih dalam Daftar Pemilih Tetap (DPT) | D14: LK | E14: 132 | F14: 118 | G14: 130 | H14: 112 | I14: 147 | J14: 159 | K14: 144 | L14: 151 | M14: 141 | N14: 144 | O14: 122 | P14: 124 | Q14: 123 | R14: 92 | S14: 142 | T14: 126 | U14: 127 | V14: 116 | W14: 145 | X14: 142 | Y14: 119 | Z14: 140 | AA14: 108 | AB14: 103 | AC14: 123 | AD14: 138 | AE14: =SUM(E14:AD14) -> 3368
D15: PR | E15: 127 | F15: 126 | G15: 123 | H15: 114 | I15: 142 | J15: 141 | K15: 149 | L15: 145 | M15: 147 | N15: 153 | O15: 116 | P15: 128 | Q15: 116 | R15: 106 | S15: 126 | T15: 124 | U15: 145 | V15: 97 | W15: 134 | X15: 137 | Y15: 126 | Z15: 151 | AA15: 115 | AB15: 118 | AC15: 132 | AD15: 149 | AE15: =SUM(E15:AD15) -> 3387
D16: JML | E16: =SUM(E14:E15) -> 259 | F16: =SUM(F14:F15) -> 244 | G16: =SUM(G14:G15) -> 253 | H16: =SUM(H14:H15) -> 226 | I16: =SUM(I14:I15) -> 289 | J16: =SUM(J14:J15) -> 300 | K16: =SUM(K14:K15) -> 293 | L16: =SUM(L14:L15) -> 296 | ... AD16: =SUM(AD14:AD15) -> 287 | AE16: =SUM(E16:AD16) -> 6755
A18: B | B18: PENGGUNA HAK PILIH
B19: 1. | C19: Jumlah pengguna hak pilih dalam Daftar Pemilih Tetap (DPT) | D19: LK | E19: 105 | F19: 100 | G19: 94 | H19: 91 | I19: 104 | J19: 118 | K19: 109 | L19: 115 | M19: 105 | N19: 107 | O19: 87 | P19: 97 | Q19: 90 | R19: 68 | S19: 113 | T19: 89 | U19: 87 | V19: 95 | W19: 113 | X19: 101 | Y19: 87 | Z19: 96 | AA19: 77 | AB19: 76 | AC19: 80 | AD19: 95 | AE19: =SUM(E19:AD19) -> 2499
D20: PR | E20: 101 | F20: 100 | G20: 107 | H20: 93 | I20: 104 | J20: 112 | K20: 115 | L20: 114 | M20: 118 | N20: 119 | O20: 89 | P20: 116 | Q20: 93 | R20: 86 | S20: 107 | T20: 105 | U20: 112 | V20: 86 | W20: 110 | X20: 105 | Y20: 104 | Z20: 126 | AA20: 100 | AB20: 78 | AC20: 92 | AD20: 112 | AE20: =SUM(E20:AD20) -> 2704
D21: JML | E21: =SUM(E19:E20) -> 206 | F21: =SUM(F19:F20) -> 200 | G21: =SUM(G19:G20) -> 201 | H21: =SUM(H19:H20) -> 184 | I21: =SUM(I19:I20) -> 208 | J21: =SUM(J19:J20) -> 230 | K21: =SUM(K19:K20) -> 224 | L21: =SUM(L19:L20) -> 229 | ... AD21: =SUM(AD19:AD20) -> 207 | AE21: =SUM(E21:AD21) -> 5203
B22: 2. | C22: Jumlah pengguna hak pilih dalam Daftar Pemilih Tambahan (DPTb) | D22: LK | N22: 2 | P22: 1 | AE22: =SUM(E22:AD22) -> 3
D23: PR | N23: 1 | O23: 1 | S23: 1 | V23: 1 | AE23: =SUM(E23:AD23) -> 4
D24: JML | E24: =SUM(E22:E23) -> 0 | F24: =SUM(F22:F23) -> 0 | G24: =SUM(G22:G23) -> 0 | H24: =SUM(H22:H23) -> 0 | I24: =SUM(I22:I23) -> 0 | J24: =SUM(J22:J23) -> 0 | K24: =SUM(K22:K23) -> 0 | L24: =SUM(L22:L23) -> 0 | ... AD24: =SUM(AD22:AD23) -> 0 | AE24: =SUM(E24:AD24) -> 7
B25: 3. | C25: Jumlah pengguna hak pilih dalam Daftar Pemilih Khusus (DPK) | D25: LK | E25: 1 | I25: 2 | R25: 1 | V25: 2 | W25: 1 | AE25: =SUM(E25:AD25) -> 7
D26: PR | P26: 1 | V26: 1 | W26: 1 | X26: 4 | AE26: =SUM(E26:AD26) -> 7
D27: JML | E27: =SUM(E25:E26) -> 1 | F27: =SUM(F25:F26) -> 0 | G27: =SUM(G25:G26) -> 0 | H27: =SUM(H25:H26) -> 0 | I27: =SUM(I25:I26) -> 2 | J27: =SUM(J25:J26) -> 0 | K27: =SUM(K25:K26) -> 0 | L27: =SUM(L25:L26) -> 0 | ... AD27: =SUM(AD25:AD26) -> 0 | AE27: =SUM(E27:AD27) -> 14
B28: 4. | C28: Jumlah Pengguna Hak Pilih (B.1+B.2+B.3) | D28: LK | E28: =SUM(E19,E22,E25) -> 106 | F28: =SUM(F19,F22,F25) -> 100 | G28: =SUM(G19,G22,G25) -> 94 | H28: =SUM(H19,H22,H25) -> 91 | I28: =SUM(I19,I22,I25) -> 106 | J28: =SUM(J19,J22,J25) -> 118 | K28: =SUM(K19,K22,K25) -> 109 | L28: =SUM(L19,L22,L25) -> 115 | ... AD28: =SUM(AD19,AD22,AD25) -> 95 | AE28: =SUM(E28:AD28) -> 2509
D29: PR | E29: =SUM(E20,E23,E26) -> 101 | F29: =SUM(F20,F23,F26) -> 100 | G29: =SUM(G20,G23,G26) -> 107 | H29: =SUM(H20,H23,H26) -> 93 | I29: =SUM(I20,I23,I26) -> 104 | J29: =SUM(J20,J23,J26) -> 112 | K29: =SUM(K20,K23,K26) -> 115 | L29: =SUM(L20,L23,L26) -> 114 | ... AD29: =SUM(AD20,AD23,AD26) -> 112 | AE29: =SUM(E29:AD29) -> 2715
D30: JML | E30: =SUM(E28:E29) -> 207 | F30: =SUM(F28:F29) -> 200 | G30: =SUM(G28:G29) -> 201 | H30: =SUM(H28:H29) -> 184 | I30: =SUM(I28:I29) -> 210 | J30: =SUM(J28:J29) -> 230 | K30: =SUM(K28:K29) -> 224 | L30: =SUM(L28:L29) -> 229 | ... AD30: =SUM(AD28:AD29) -> 207 | AE30: =SUM(E30:AD30) -> 5224
A32: II | B32: DATA PENGGUNAAN SURAT SUARA
A33: 1 | B33: Jumlah surat suara yang diterima, termasuk surat suara cadangan 2,5% dari DPT | E33: 265 | F33: 249 | G33: 259 | H33: 231 | I33: 295 | J33: 306 | K33: 299 | L33: 302 | M33: 294 | N33: 303 | O33: 243 | P33: 258 | Q33: 244 | R33: 202 | S33: 274 | T33: 255 | U33: 278 | V33: 218 | W33: 285 | X33: 285 | Y33: 250 | Z33: 297 | AA33: 228 | AB33: 226 | AC33: 261 | AD33: 293 | AE33: =SUM(E33:AD33) -> 6900
A34: 2 | B34: Jumlah surat suara yang digunakan | E34: 207 | F34: 200 | G34: 201 | H34: 184 | I34: 210 | J34: 230 | K34: 224 | L34: 229 | M34: 223 | N34: 229 | O34: 177 | P34: 215 | Q34: 183 | R34: 155 | S34: 221 | T34: 194 | U34: 199 | V34: 185 | W34: 225 | X34: 210 | Y34: 191 | Z34: 222 | AA34: 177 | AB34: 154 | AC34: 172 | AD34: 207 | AE34: =SUM(E34:AD34) -> 5224
A35: 3 | B35: Jumlah surat suara dikembalikan oleh pemilih (karena rusak atau keliru coblos) | F35: 1 | H35: 2 | AA35: 1 | AE35: =SUM(E35:AD35) -> 4
A36: 4 | B36: Jumlah surat suara yang tidak digunakan/tidak terpakai, termasuk sisa surat suara cadangan | E36: =E33-(E34+E35) -> 58 | F36: =F33-(F34+F35) -> 48 | G36: =G33-(G34+G35) -> 58 | H36: =H33-(H34+H35) -> 45 | I36: =I33-(I34+I35) -> 85 | J36: =J33-(J34+J35) -> 76 | K36: =K33-(K34+K35) -> 75 | L36: =L33-(L34+L35) -> 73 | ... AD36: =AD33-(AD34+AD35) -> 86 | AE36: =SUM(E36:AD36) -> 1672
A38: III | B38: DATA PEMILIH DISABILITAS
B39: Jumlah seluruh Pemilih disabilitas yang menggunakan hak pilih | D39: LK | E39: 2 | J39: 1 | U39: 1 | V39: 1 | Y39: 1 | AA39: 3 | AB39: 1 | AE39: =SUM(E39:AD39) -> 10
D40: PR | E40: 2 | I40: 1 | R40: 2 | W40: 2 | Y40: 1 | Z40: 1 | AA40: 2 | AB40: 3 | AE40: =SUM(E40:AD40) -> 14
D41: JML | E41: =SUM(E39:E40) -> 4 | F41: =SUM(F39:F40) -> 0 | G41: =SUM(G39:G40) -> 0 | H41: =SUM(H39:H40) -> 0 | I41: =SUM(I39:I40) -> 1 | J41: =SUM(J39:J40) -> 1 | K41: =SUM(K39:K40) -> 0 | L41: =SUM(L39:L40) -> 0 | ... AD41: =SUM(AD39:AD40) -> 0 | AE41: =SUM(E41:AD41) -> 24
A43: IV | B43: DATA RINCIAN PEROLEHAN SUARA PASANGAN CALON BUPATI DAN WAKIL BUPATI
A44: NOMOR DAN NAMA CALON
A45: A.1 | B45: 1. | C45: Partai Kebangkitan Bangsa | E45: 4 | F45: 6 | G45: 2 | H45: 1 | I45: 6 | J45: 5 | K45: 5 | L45: 4 | M45: 5 | N45: 2 | O45: 4 | P45: 6 | Q45: 4 | R45: 1 | S45: 4 | T45: 4 | U45: 3 | V45: 1 | W45: 5 | X45: 5 | Y45: 11 | Z45: 5 | AA45: 4 | AB45: 2 | AC45: 1 | AD45: 6 | AE45: =SUM(E45:AD45) -> 106
A46: A.2 | C46: 1. H. KHUSNAN, S.Ag., M.Pd.I. | E46: 3 | G46: 3 | H46: 2 | I46: 4 | J46: 2 | K46: 3 | L46: 5 | M46: 3 | N46: 5 | P46: 1 | Q46: 3 | R46: 1 | S46: 1 | T46: 4 | U46: 2 | W46: 1 | Y46: 61 | Z46: 12 | AA46: 8 | AB46: 1 | AC46: 3 | AD46: 6 | AE46: =SUM(E46:AD46) -> 134
C47: 2. MARA QONITHA LAYLIA | E47: 7 | F47: 17 | G47: 24 | H47: 11 | I47: 9 | J47: 10 | L47: 13 | M47: 13 | N47: 13 | O47: 13 | P47: 16 | Q47: 8 | R47: 6 | S47: 35 | T47: 30 | U47: 6 | V47: 5 | W47: 6 | X47: 4 | Y47: 11 | Z47: 4 | AA47: 9 | AB47: 2 | AC47: 8 | AD47: 10 | AE47: =SUM(E47:AD47) -> 290
C48: 3. ZAKI AL MUBAROK, M.Si. | E48: 7 | F48: 11 | G48: 35 | I48: 5 | J48: 5 | K48: 4 | L48: 16 | M48: 46 | N48: 14 | O48: 40 | P48: 2 | Q48: 29 | R48: 3 | S48: 8 | T48: 7 | U48: 5 | V48: 1 | W48: 22 | X48: 16 | Y48: 14 | Z48: 44 | AA48: 10 | AB48: 7 | AC48: 15 | AD48: 9 | AE48: =SUM(E48:AD48) -> 375
C49: 4. INAYATUL MAHMUDAH, S.Pd. | G49: 1 | I49: 4 | N49: 2 | P49: 1 | U49: 1 | AA49: 2 | AD49: 1 | AE49: =SUM(E49:AD49) -> 12
C50: 5. HABIBURRAHMAN AL KHOLILI | J50: 1 | N50: 1 | S50: 3 | W50: 4 | AD50: 1 | AE50: =SUM(E50:AD50) -> 10
C51: 6. INDIARTI NOVIDA, A.Md. | K51: 1 | S51: 1 | AA51: 1 | AE51: =SUM(E51:AD51) -> 3
...

Sheet KARANGHARJO
C2: Kecamatan | D2: GLENMORE
C3: Kabupaten | D3: BANYUWANGI
C4: Provinsi | D4: JAWA TIMUR
C9: Kelurahan | D9: KARANGHARJO
A12: I | B12: DATA PEMILIH DAN PENGGUNAAN HAK PILIH | BK12: JUMLAH AKHIR
A13: A | B13: DATA PEMILIH | E13: TPS 001 | F13: TPS 002 | G13: TPS 003 | H13: TPS 004 | I13: TPS 005 | J13: TPS 006 | K13: TPS 007 | L13: TPS 008 | M13: TPS 009 | N13: TPS 010 | O13: TPS 011 | P13: TPS 012 | Q13: TPS 013 | R13: TPS 014 | S13: TPS 015 | T13: TPS 016 | U13: TPS 017 | V13: TPS 018 | W13: TPS 019 | X13: TPS 020 | Y13: TPS 021 | Z13: TPS 022 | AA13: TPS 023 | AB13: TPS 024 | AC13: TPS 025 | AD13: TPS 026 | AE13: TPS 027 | AF13: TPS 028 | AG13: TPS 029 | AH13: TPS 030 | AI13: TPS 031 | AJ13: TPS 032 | AK13: TPS 033 | AL13: TPS 034 | AM13: TPS 035 | AN13: TPS 036 | AO13: TPS 037 | AP13: TPS 038 | AQ13: TPS 039 | AR13: TPS 040 | AS13: TPS 041 | AT13: TPS 042 | AU13: TPS 043 | AV13: TPS 044 | AW13: TPS 045 | AX13: TPS 046 | AY13: TPS 047 | AZ13: TPS 048 | BA13: TPS 049 | BB13: TPS 050 | BC13: TPS 051 | BD13: TPS 052 | BE13: TPS 053 | BF13: TPS 054 | BG13: TPS 055 | BH13: TPS 056 | BI13: TPS 057 | BJ13: TPS 058
B14: Jumlah Pemilih dalam Daftar Pemilih Tetap (DPT) | D14: LK | E14: 48 | F14: 60 | G14: 57 | H14: 49 | I14: 111 | J14: 137 | K14: 142 | L14: 129 | M14: 134 | N14: 50 | O14: 120 | P14: 109 | Q14: 109 | R14: 73 | S14: 120 | T14: 78 | U14: 127 | V14: 147 | W14: 111 | X14: 150 | Y14: 128 | Z14: 100 | AA14: 119 | AB14: 97 | AC14: 150 | AD14: 108 | AE14: 87 | AF14: 66 | AG14: 128 | AH14: 143 | AI14: 113 | AJ14: 92 | AK14: 99 | AL14: 130 | AM14: 107 | AN14: 94 | AO14: 81 | AP14: 102 | AQ14: 90 | AR14: 99 | AS14: 81 | AT14: 145 | AU14: 141 | AV14: 131 | AW14: 138 | AX14: 105 | AY14: 132 | AZ14: 81 | BA14: 103 | BB14: 87 | BC14: 128 | BD14: 117 | BE14: 132 | BF14: 84 | BG14: 135 | BH14: 139 | BI14: 117 | BJ14: 134 | BK14: =SUM(E14:BJ14) -> 6324
D15: PR | E15: 53 | F15: 48 | G15: 58 | H15: 39 | I15: 110 | J15: 137 | K15: 146 | L15: 145 | M15: 132 | N15: 43 | O15: 152 | P15: 115 | Q15: 101 | R15: 68 | S15: 123 | T15: 84 | U15: 118 | V15: 147 | W15: 122 | X15: 138 | Y15: 125 | Z15: 109 | AA15: 136 | AB15: 82 | AC15: 144 | AD15: 97 | AE15: 95 | AF15: 74 | AG15: 139 | AH15: 154 | AI15: 125 | AJ15: 101 | AK15: 99 | AL15: 139 | AM15: 121 | AN15: 91 | AO15: 77 | AP15: 109 | AQ15: 91 | AR15: 89 | AS15: 77 | AT15: 151 | AU15: 133 | AV15: 156 | AW15: 159 | AX15: 121 | AY15: 162 | AZ15: 93 | BA15: 108 | BB15: 89 | BC15: 130 | BD15: 129 | BE15: 148 | BF15: 99 | BG15: 147 | BH15: 152 | BI15: 121 | BJ15: 138 | BK15: =SUM(E15:BJ15) -> 6589
D16: JML | E16: =SUM(E14:E15) -> 101 | F16: =SUM(F14:F15) -> 108 | G16: =SUM(G14:G15) -> 115 | H16: =SUM(H14:H15) -> 88 | I16: =SUM(I14:I15) -> 221 | J16: =SUM(J14:J15) -> 274 | K16: =SUM(K14:K15) -> 288 | L16: =SUM(L14:L15) -> 274 | ... BJ16: =SUM(BJ14:BJ15) -> 272 | BK16: =SUM(E16:BJ16) -> 12913
A18: B | B18: PENGGUNA HAK PILIH
B19: 1. | C19: Jumlah pengguna hak pilih dalam Daftar Pemilih Tetap (DPT) | D19: LK | E19: 39 | F19: 49 | G19: 45 | H19: 30 | I19: 77 | J19: 91 | K19: 77 | L19: 83 | M19: 88 | N19: 50 | O19: 85 | P19: 70 | Q19: 75 | R19: 44 | S19: 92 | T19: 54 | U19: 94 | V19: 99 | W19: 95 | X19: 120 | Y19: 76 | Z19: 72 | AA19: 82 | AB19: 56 | AC19: 109 | AD19: 59 | AE19: 67 | AF19: 55 | AG19: 75 | AH19: 109 | AI19: 78 | AJ19: 64 | AK19: 73 | AL19: 112 | AM19: 74 | AN19: 64 | AO19: 69 | AP19: 86 | AQ19: 75 | AR19: 79 | AS19: 64 | AT19: 98 | AU19: 101 | AV19: 92 | AW19: 86 | AX19: 68 | AY19: 96 | AZ19: 59 | BA19: 72 | BB19: 67 | BC19: 99 | BD19: 83 | BE19: 80 | BF19: 72 | BG19: 86 | BH19: 95 | BI19: 99 | BJ19: 87 | BK19: =SUM(E19:BJ19) -> 4495
D20: PR | E20: 35 | F20: 37 | G20: 50 | H20: 21 | I20: 82 | J20: 102 | K20: 103 | L20: 110 | M20: 90 | N20: 42 | O20: 120 | P20: 78 | Q20: 76 | R20: 46 | S20: 88 | T20: 65 | U20: 102 | V20: 121 | W20: 107 | X20: 126 | Y20: 89 | Z20: 85 | AA20: 112 | AB20: 68 | AC20: 112 | AD20: 72 | AE20: 78 | AF20: 59 | AG20: 103 | AH20: 116 | AI20: 104 | AJ20: 71 | AK20: 69 | AL20: 123 | AM20: 86 | AN20: 66 | AO20: 71 | AP20: 86 | AQ20: 74 | AR20: 79 | AS20: 62 | AT20: 116 | AU20: 100 | AV20: 106 | AW20: 108 | AX20: 92 | AY20: 124 | AZ20: 83 | BA20: 80 | BB20: 71 | BC20: 102 | BD20: 99 | BE20: 100 | BF20: 86 | BG20: 110 | BH20: 128 | BI20: 99 | BJ20: 103 | BK20: =SUM(E20:BJ20) -> 5093
D21: JML | E21: =SUM(E19:E20) -> 74 | F21: =SUM(F19:F20) -> 86 | G21: =SUM(G19:G20) -> 95 | H21: =SUM(H19:H20) -> 51 | I21: =SUM(I19:I20) -> 159 | J21: =SUM(J19:J20) -> 193 | K21: =SUM(K19:K20) -> 180 | L21: =SUM(L19:L20) -> 193 | ... BJ21: =SUM(BJ19:BJ20) -> 190 | BK21: =SUM(E21:BJ21) -> 9588
B22: 2. | C22: Jumlah pengguna hak pilih dalam Daftar Pemilih Tambahan (DPTb) | D22: LK | E22: 1 | F22: 1 | G22: 1 | H22: 1 | I22: 1 | J22: 1 | K22: 1 | L22: 1 | M22: 1 | N22: 1 | O22: 1 | R22: 1 | U22: 1 | V22: 1 | W22: 1 | Z22: 1 | AA22: 1 | AB22: 1 | AC22: 1 | AD22: 1 | AF22: 2 | AI22: 1 | AJ22: 1 | AL22: 1 | AP22: 1 | AS22: 1 | AU22: 1 | AX22: 1 | BA22: 2 | BB22: 1 | BH22: 1 | BK22: =SUM(E22:BJ22) -> 33
D23: PR | Q23: 1 | X23: 1 | AF23: 1 | AK23: 1 | AM23: 1 | AN23: 1 | AT23: 1 | AV23: 1 | AX23: 1 | AY23: 2 | AZ23: 1 | BA23: 2 | BE23: 1 | BF23: 1 | BG23: 1 | BI23: 1 | BJ23: 1 | BK23: =SUM(E23:BJ23) -> 19
D24: JML | E24: =SUM(E22:E23) -> 1 | F24: =SUM(F22:F23) -> 1 | G24: =SUM(G22:G23) -> 1 | H24: =SUM(H22:H23) -> 1 | I24: =SUM(I22:I23) -> 1 | J24: =SUM(J22:J23) -> 1 | K24: =SUM(K22:K23) -> 1 | L24: =SUM(L22:L23) -> 1 | ... BJ24: =SUM(BJ22:BJ23) -> 1 | BK24: =SUM(E24:BJ24) -> 52
B25: 3. | C25: Jumlah pengguna hak pilih dalam Daftar Pemilih Khusus (DPK) | D25: LK | AA25: 3 | AB25: 1 | AV25: 6 | AX25: 1 | BD25: 3 | BE25: 1 | BH25: 1 | BI25: 1 | BK25: =SUM(E25:BJ25) -> 17
D26: PR | M26: 3 | AA26: 5 | AB26: 2 | AF26: 1 | AQ26: 1 | AV26: 3 | AY26: 2 | BA26: 2 | BD26: 1 | BG26: 4 | BI26: 4 | BJ26: 2 | BK26: =SUM(E26:BJ26) -> 30
D27: JML | E27: =SUM(E25:E26) -> 0 | F27: =SUM(F25:F26) -> 0 | G27: =SUM(G25:G26) -> 0 | H27: =SUM(H25:H26) -> 0 | I27: =SUM(I25:I26) -> 0 | J27: =SUM(J25:J26) -> 0 | K27: =SUM(K25:K26) -> 0 | L27: =SUM(L25:L26) -> 0 | ... BJ27: =SUM(BJ25:BJ26) -> 2 | BK27: =SUM(E27:BJ27) -> 47
B28: 4. | C28: Jumlah Pengguna Hak Pilih (B.1+B.2+B.3) | D28: LK | E28: =SUM(E19,E22,E25) -> 40 | F28: =SUM(F19,F22,F25) -> 50 | G28: =SUM(G19,G22,G25) -> 46 | H28: =SUM(H19,H22,H25) -> 31 | I28: =SUM(I19,I22,I25) -> 78 | J28: =SUM(J19,J22,J25) -> 92 | K28: =SUM(K19,K22,K25) -> 78 | L28: =SUM(L19,L22,L25) -> 84 | ... BJ28: =SUM(BJ19,BJ22,BJ25) -> 87 | BK28: =SUM(E28:BJ28) -> 4545
D29: PR | E29: =SUM(E20,E23,E26) -> 35 | F29: =SUM(F20,F23,F26) -> 37 | G29: =SUM(G20,G23,G26) -> 50 | H29: =SUM(H20,H23,H26) -> 21 | I29: =SUM(I20,I23,I26) -> 82 | J29: =SUM(J20,J23,J26) -> 102 | K29: =SUM(K20,K23,K26) -> 103 | L29: =SUM(L20,L23,L26) -> 110 | ... BJ29: =SUM(BJ20,BJ23,BJ26) -> 106 | BK29: =SUM(E29:BJ29) -> 5142
D30: JML | E30: =SUM(E28:E29) -> 75 | F30: =SUM(F28:F29) -> 87 | G30: =SUM(G28:G29) -> 96 | H30: =SUM(H28:H29) -> 52 | I30: =SUM(I28:I29) -> 160 | J30: =SUM(J28:J29) -> 194 | K30: =SUM(K28:K29) -> 181 | L30: =SUM(L28:L29) -> 194 | ... BJ30: =SUM(BJ28:BJ29) -> 193 | BK30: =SUM(E30:BJ30) -> 9687
A32: II | B32: DATA PENGGUNAAN SURAT SUARA
A33: 1 | B33: Jumlah surat suara yang diterima, termasuk surat suara cadangan 2,5% dari DPT | E33: 104 | F33: 111 | G33: 118 | H33: 90 | I33: 226 | J33: 280 | K33: 292 | L33: 280 | M33: 272 | N33: 95 | O33: 278 | P33: 259 | Q33: 215 | R33: 120 | S33: 248 | T33: 166 | U33: 250 | V33: 310 | W33: 238 | X33: 294 | Y33: 259 | Z33: 214 | AA33: 261 | AB33: 183 | AC33: 300 | AD33: 210 | AE33: 186 | AF33: 143 | AG33: 273 | AH33: 303 | AI33: 243 | AJ33: 197 | AK33: 202 | AL33: 275 | AM33: 233 | AN33: 189 | AO33: 162 | AP33: 216 | AQ33: 185 | AR33: 192 | AS33: 162 | AT33: 302 | AU33: 281 | AV33: 307 | AW33: 303 | AX33: 231 | AY33: 300 | AZ33: 178 | BA33: 216 | BB33: 180 | BC33: 264 | BD33: 253 | BE33: 286 | BF33: 187 | BG33: 288 | BH33: 297 | BI33: 243 | BJ33: 278 | BK33: =SUM(E33:BJ33) -> 13228
A34: 2 | B34: Jumlah surat suara yang digunakan | E34: 75 | F34: 87 | G34: 96 | H34: 52 | I34: 160 | J34: 194 | K34: 181 | L34: 194 | M34: 182 | N34: 93 | O34: 206 | P34: 148 | Q34: 152 | R34: 91 | S34: 180 | T34: 119 | U34: 197 | V34: 221 | W34: 203 | X34: 247 | Y34: 165 | Z34: 158 | AA34: 203 | AB34: 128 | AC34: 222 | AD34: 132 | AE34: 145 | AF34: 118 | AG34: 178 | AH34: 225 | AI34: 183 | AJ34: 136 | AK34: 143 | AL34: 236 | AM34: 161 | AN34: 131 | AO34: 140 | AP34: 173 | AQ34: 150 | AR34: 158 | AS34: 127 | AT34: 215 | AU34: 202 | AV34: 208 | AW34: 194 | AX34: 163 | AY34: 224 | AZ34: 143 | BA34: 158 | BB34: 139 | BC34: 201 | BD34: 186 | BE34: 182 | BF34: 159 | BG34: 201 | BH34: 225 | BI34: 204 | BJ34: 193 | BK34: =SUM(E34:BJ34) -> 9687
A35: 3 | B35: Jumlah surat suara dikembalikan oleh pemilih (karena rusak atau keliru coblos) | L35: 1 | V35: 1 | W35: 1 | AA35: 1 | AD35: 3 | AG35: 2 | AH35: 1 | AM35: 1 | AO35: 1 | AU35: 1 | AV35: 14 | BF35: 1 | BI35: 2 | BJ35: 2 | BK35: =SUM(E35:BJ35) -> 32
A36: 4 | B36: Jumlah surat suara yang tidak digunakan/tidak terpakai, termasuk sisa surat suara cadangan | E36: =E33-(E34+E35) -> 29 | F36: =F33-(F34+F35) -> 24 | G36: =G33-(G34+G35) -> 22 | H36: =H33-(H34+H35) -> 38 | I36: =I33-(I34+I35) -> 66 | J36: =J33-(J34+J35) -> 86 | K36: =K33-(K34+K35) -> 111 | L36: =L33-(L34+L35) -> 85 | ... BJ36: =BJ33-(BJ34+BJ35) -> 83 | BK36: =SUM(E36:BJ36) -> 3509
A38: III | B38: DATA PEMILIH DISABILITAS
B39: Jumlah seluruh Pemilih disabilitas yang menggunakan hak pilih | D39: LK | S39: 1 | X39: 1 | Y39: 1 | Z39: 1 | AG39: 1 | AI39: 2 | AR39: 1 | AX39: 1 | BK39: =SUM(E39:BJ39) -> 9
D40: PR | O40: 1 | S40: 2 | T40: 1 | X40: 3 | Z40: 1 | AI40: 3 | AS40: 1 | AX40: 3 | BK40: =SUM(E40:BJ40) -> 15
D41: JML | E41: =SUM(E39:E40) -> 0 | F41: =SUM(F39:F40) -> 0 | G41: =SUM(G39:G40) -> 0 | H41: =SUM(H39:H40) -> 0 | I41: =SUM(I39:I40) -> 0 | J41: =SUM(J39:J40) -> 0 | K41: =SUM(K39:K40) -> 0 | L41: =SUM(L39:L40) -> 0 | ... BJ41: =SUM(BJ39:BJ40) -> 0 | BK41: =SUM(E41:BJ41) -> 24
A43: IV | B43: DATA RINCIAN PEROLEHAN SUARA PASANGAN CALON BUPATI DAN WAKIL BUPATI
A44: NOMOR DAN NAMA CALON
A45: A.1 | B45: 1. | C45: Partai Kebangkitan Bangsa | I45: 4 | J45: 4 | K45: 6 | L45: 4 | M45: 6 | O45: 4 | P45: 4 | Q45: 2 | R45: 1 | S45: 1 | U45: 5 | V45: 3 | W45: 3 | X45: 2 | Y45: 4 | Z45: 2 | AA45: 3 | AB45: 5 | AC45: 4 | AD45: 8 | AE45: 3 | AG45: 3 | AH45: 8 | AI45: 7 | AJ45: 5 | AK45: 3 | AL45: 3 | AM45: 4 | AN45: 2 | AO45: 2 | AQ45: 4 | AT45: 7 | AU45: 4 | AV45: 5 | AW45: 3 | AX45: 1 | AY45: 5 | BA45: 1 | BB45: 3 | BC45: 1 | BD45: 3 | BE45: 8 | BF45: 7 | BG45: 9 | BH45: 20 | BI45: 3 | BK45: =SUM(E45:BJ45) -> 199
A46: A.2 | C46: 1. H. KHUSNAN, S.Ag., M.Pd.I. | E46: 2 | I46: 3 | J46: 1 | K46: 4 | L46: 1 | M46: 6 | O46: 3 | P46: 2 | Q46: 1 | X46: 2 | Y46: 1 | AA46: 1 | AC46: 4 | AD46: 2 | AE46: 2 | AF46: 2 | AG46: 2 | AH46: 2 | AI46: 5 | AJ46: 1 | AL46: 1 | AN46: 2 | AR46: 1 | AS46: 2 | AT46: 3 | AU46: 6 | AV46: 1 | AW46: 2 | AX46: 2 | AY46: 4 | AZ46: 1 | BA46: 1 | BC46: 3 | BE46: 1 | BF46: 12 | BG46: 34 | BH46: 43 | BI46: 4 | BK46: =SUM(E46:BJ46) -> 170
C47: 2. MARA QONITHA LAYLIA | E47: 1 | F47: 1 | G47: 1 | H47: 3 | I47: 1 | J47: 5 | K47: 1 | L47: 2 | M47: 6 | O47: 4 | P47: 1 | Q47: 1 | R47: 3 | V47: 5 | W47: 1 | X47: 2 | Z47: 1 | AA47: 1 | AB47: 2 | AC47: 1 | AD47: 3 | AG47: 2 | AH47: 1 | AI47: 3 | AJ47: 1 | AK47: 1 | AL47: 1 | AM47: 2 | AN47: 2 | AO47: 2 | AP47: 3 | AQ47: 3 | AT47: 9 | AU47: 6 | AV47: 1 | AW47: 4 | AY47: 4 | AZ47: 1 | BC47: 1 | BD47: 1 | BE47: 12 | BF47: 6 | BH47: 9 | BI47: 2 | BK47: =SUM(E47:BJ47) -> 123
C48: 3. ZAKI AL MUBAROK, M.Si. | E48: 1 | F48: 1 | G48: 2 | H48: 10 | I48: 7 | J48: 5 | K48: 8 | L48: 2 | M48: 20 | O48: 13 | P48: 3 | Q48: 2 | R48: 8 | S48: 4 | T48: 2 | U48: 1 | W48: 8 | X48: 3 | Y48: 2 | AA48: 1 | AC48: 7 | AD48: 6 | AE48: 2 | AF48: 2 | AG48: 35 | AH48: 3 | AI48: 6 | AJ48: 7 | AK48: 1 | AL48: 6 | AM48: 2 | AN48: 1 | AO48: 3 | AP48: 3 | AS48: 1 | AT48: 10 | AU48: 36 | AV48: 21 | AW48: 18 | AX48: 6 | AY48: 12 | AZ48: 8 | BA48: 1 | BC48: 3 | BD48: 4 | BF48: 3 | BG48: 3 | BH48: 10 | BI48: 2 | BJ48: 5 | BK48: =SUM(E48:BJ48) -> 330
C49: 4. INAYATUL MAHMUDAH, S.Pd. | I49: 1 | J49: 2 | M49: 2 | O49: 1 | P49: 1 | U49: 1 | V49: 1 | Y49: 1 | AD49: 1 | AF49: 1 | AG49: 1 | AH49: 1 | AK49: 2 | AN49: 1 | AT49: 2 | AW49: 1 | BF49: 1 | BG49: 2 | BH49: 1 | BK49: =SUM(E49:BJ49) -> 24
C50: 5. HABIBURRAHMAN AL KHOLILI | M50: 1 | V50: 1 | AA50: 1 | AK50: 1 | AX50: 1 | BC50: 1 | BF50: 1 | BG50: 1 | BH50: 1 | BK50: =SUM(E50:BJ50) -> 9
C51: 6. INDIARTI NOVIDA, A.Md. | BK51: =SUM(E51:BJ51) -> 0
...

Sheet MARGOMULYO
C2: Kecamatan | D2: GLENMORE
C3: Kabupaten | D3: BANYUWANGI
C4: Provinsi | D4: JAWA TIMUR
C9: Kelurahan | D9: MARGOMULYO
A12: I | B12: DATA PEMILIH DAN PENGGUNAAN HAK PILIH | S12: JUMLAH AKHIR
A13: A | B13: DATA PEMILIH | E13: TPS 001 | F13: TPS 002 | G13: TPS 003 | H13: TPS 004 | I13: TPS 005 | J13: TPS 006 | K13: TPS 007 | L13: TPS 008 | M13: TPS 009 | N13: TPS 010 | O13: TPS 011 | P13: TPS 012 | Q13: TPS 013 | R13: TPS 014
B14: Jumlah Pemilih dalam Daftar Pemilih Tetap (DPT) | D14: LK | E14: 100 | F14: 130 | G14: 131 | H14: 141 | I14: 115 | J14: 138 | K14: 136 | L14: 115 | M14: 146 | N14: 142 | O14: 79 | P14: 101 | Q14: 123 | R14: 146 | S14: =SUM(E14:R14) -> 1743
D15: PR | E15: 86 | F15: 114 | G15: 125 | H15: 145 | I15: 108 | J15: 127 | K15: 145 | L15: 124 | M15: 138 | N15: 126 | O15: 89 | P15: 106 | Q15: 143 | R15: 146 | S15: =SUM(E15:R15) -> 1722
D16: JML | E16: =SUM(E14:E15) -> 186 | F16: =SUM(F14:F15) -> 244 | G16: =SUM(G14:G15) -> 256 | H16: =SUM(H14:H15) -> 286 | I16: =SUM(I14:I15) -> 223 | J16: =SUM(J14:J15) -> 265 | K16: =SUM(K14:K15) -> 281 | L16: =SUM(L14:L15) -> 239 | ... R16: =SUM(R14:R15) -> 292 | S16: =SUM(E16:R16) -> 3465
A18: B | B18: PENGGUNA HAK PILIH
B19: 1. | C19: Jumlah pengguna hak pilih dalam Daftar Pemilih Tetap (DPT) | D19: LK | E19: 77 | F19: 90 | G19: 89 | H19: 93 | I19: 98 | J19: 105 | K19: 110 | L19: 70 | M19: 91 | N19: 105 | O19: 59 | P19: 84 | Q19: 96 | R19: 103 | S19: =SUM(E19:R19) -> 1270
D20: PR | E20: 69 | F20: 88 | G20: 102 | H20: 112 | I20: 95 | J20: 104 | K20: 121 | L20: 85 | M20: 106 | N20: 108 | O20: 67 | P20: 85 | Q20: 116 | R20: 118 | S20: =SUM(E20:R20) -> 1376
D21: JML | E21: =SUM(E19:E20) -> 146 | F21: =SUM(F19:F20) -> 178 | G21: =SUM(G19:G20) -> 191 | H21: =SUM(H19:H20) -> 205 | I21: =SUM(I19:I20) -> 193 | J21: =SUM(J19:J20) -> 209 | K21: =SUM(K19:K20) -> 231 | L21: =SUM(L19:L20) -> 155 | ... R21: =SUM(R19:R20) -> 221 | S21: =SUM(E21:R21) -> 2646
B22: 2. | C22: Jumlah pengguna hak pilih dalam Daftar Pemilih Tambahan (DPTb) | D22: LK | S22: =SUM(E22:R22) -> 0
D23: PR | S23: =SUM(E23:R23) -> 0
D24: JML | E24: =SUM(E22:E23) -> 0 | F24: =SUM(F22:F23) -> 0 | G24: =SUM(G22:G23) -> 0 | H24: =SUM(H22:H23) -> 0 | I24: =SUM(I22:I23) -> 0 | J24: =SUM(J22:J23) -> 0 | K24: =SUM(K22:K23) -> 0 | L24: =SUM(L22:L23) -> 0 | ... R24: =SUM(R22:R23) -> 0 | S24: =SUM(E24:R24) -> 0
B25: 3. | C25: Jumlah pengguna hak pilih dalam Daftar Pemilih Khusus (DPK) | D25: LK | F25: 1 | I25: 1 | M25: 2 | N25: 3 | P25: 4 | Q25: 3 | R25: 1 | S25: =SUM(E25:R25) -> 15
D26: PR | E26: 1 | F26: 1 | H26: 1 | M26: 1 | P26: 3 | Q26: 2 | R26: 2 | S26: =SUM(E26:R26) -> 11
D27: JML | E27: =SUM(E25:E26) -> 1 | F27: =SUM(F25:F26) -> 2 | G27: =SUM(G25:G26) -> 0 | H27: =SUM(H25:H26) -> 1 | I27: =SUM(I25:I26) -> 1 | J27: =SUM(J25:J26) -> 0 | K27: =SUM(K25:K26) -> 0 | L27: =SUM(L25:L26) -> 0 | ... R27: =SUM(R25:R26) -> 3 | S27: =SUM(E27:R27) -> 26
B28: 4. | C28: Jumlah Pengguna Hak Pilih (B.1+B.2+B.3) | D28: LK | E28: =SUM(E19,E22,E25) -> 77 | F28: =SUM(F19,F22,F25) -> 91 | G28: =SUM(G19,G22,G25) -> 89 | H28: =SUM(H19,H22,H25) -> 93 | I28: =SUM(I19,I22,I25) -> 99 | J28: =SUM(J19,J22,J25) -> 105 | K28: =SUM(K19,K22,K25) -> 110 | L28: =SUM(L19,L22,L25) -> 70 | ... R28: =SUM(R19,R22,R25) -> 104 | S28: =SUM(E28:R28) -> 1285
D29: PR | E29: =SUM(E20,E23,E26) -> 70 | F29: =SUM(F20,F23,F26) -> 89 | G29: =SUM(G20,G23,G26) -> 102 | H29: =SUM(H20,H23,H26) -> 113 | I29: =SUM(I20,I23,I26) -> 95 | J29: =SUM(J20,J23,J26) -> 104 | K29: =SUM(K20,K23,K26) -> 121 | L29: =SUM(L20,L23,L26) -> 85 | ... R29: =SUM(R20,R23,R26) -> 120 | S29: =SUM(E29:R29) -> 1387
D30: JML | E30: =SUM(E28:E29) -> 147 | F30: =SUM(F28:F29) -> 180 | G30: =SUM(G28:G29) -> 191 | H30: =SUM(H28:H29) -> 206 | I30: =SUM(I28:I29) -> 194 | J30: =SUM(J28:J29) -> 209 | K30: =SUM(K28:K29) -> 231 | L30: =SUM(L28:L29) -> 155 | ... R30: =SUM(R28:R29) -> 224 | S30: =SUM(E30:R30) -> 2672
A32: II | B32: DATA PENGGUNAAN SURAT SUARA
A33: 1 | B33: Jumlah surat suara yang diterima, termasuk surat suara cadangan 2,5% dari DPT | E33: 190 | F33: 249 | G33: 265 | H33: 292 | I33: 228 | J33: 271 | K33: 287 | L33: 244 | M33: 290 | N33: 274 | O33: 172 | P33: 212 | Q33: 273 | R33: 298 | S33: =SUM(E33:R33) -> 3545
A34: 2 | B34: Jumlah surat suara yang digunakan | E34: 147 | F34: 180 | G34: 191 | H34: 206 | I34: 194 | J34: 209 | K34: 231 | L34: 155 | M34: 200 | N34: 216 | O34: 126 | P34: 176 | Q34: 217 | R34: 224 | S34: =SUM(E34:R34) -> 2672
A35: 3 | B35: Jumlah surat suara dikembalikan oleh pemilih (karena rusak atau keliru coblos) | J35: 2 | K35: 2 | L35: 1 | Q35: 1 | S35: =SUM(E35:R35) -> 6
A36: 4 | B36: Jumlah surat suara yang tidak digunakan/tidak terpakai, termasuk sisa surat suara cadangan | E36: =E33-(E34+E35) -> 43 | F36: =F33-(F34+F35) -> 69 | G36: =G33-(G34+G35) -> 74 | H36: =H33-(H34+H35) -> 86 | I36: =I33-(I34+I35) -> 34 | J36: =J33-(J34+J35) -> 60 | K36: =K33-(K34+K35) -> 54 | L36: =L33-(L34+L35) -> 88 | ... R36: =R33-(R34+R35) -> 74 | S36: =SUM(E36:R36) -> 867
A38: III | B38: DATA PEMILIH DISABILITAS
B39: Jumlah seluruh Pemilih disabilitas yang menggunakan hak pilih | D39: LK | E39: 2 | M39: 2 | P39: 1 | R39: 1 | S39: =SUM(E39:R39) -> 6
D40: PR | L40: 1 | R40: 2 | S40: =SUM(E40:R40) -> 3
D41: JML | E41: =SUM(E39:E40) -> 2 | F41: =SUM(F39:F40) -> 0 | G41: =SUM(G39:G40) -> 0 | H41: =SUM(H39:H40) -> 0 | I41: =SUM(I39:I40) -> 0 | J41: =SUM(J39:J40) -> 0 | K41: =SUM(K39:K40) -> 0 | L41: =SUM(L39:L40) -> 1 | ... R41: =SUM(R39:R40) -> 3 | S41: =SUM(E41:R41) -> 9
A43: IV | B43: DATA RINCIAN PEROLEHAN SUARA PASANGAN CALON BUPATI DAN WAKIL BUPATI
A44: NOMOR DAN NAMA CALON
A45: A.1 | B45: 1. | C45: Partai Kebangkitan Bangsa | E45: 3 | F45: 6 | G45: 1 | I45: 1 | J45: 3 | K45: 1 | L45: 4 | M45: 4 | N45: 1 | O45: 2 | P45: 3 | Q45: 1 | R45: 1 | S45: =SUM(E45:R45) -> 31
A46: A.2 | C46: 1. H. KHUSNAN, S.Ag., M.Pd.I. | F46: 2 | G46: 1 | I46: 1 | J46: 5 | K46: 1 | L46: 2 | M46: 4 | O46: 3 | P46: 1 | Q46: 2 | S46: =SUM(E46:R46) -> 22
C47: 2. MARA QONITHA LAYLIA | E47: 2 | F47: 4 | G47: 8 | H47: 12 | I47: 5 | J47: 6 | K47: 8 | L47: 5 | M47: 16 | N47: 17 | O47: 3 | P47: 4 | Q47: 9 | S47: =SUM(E47:R47) -> 99
C48: 3. ZAKI AL MUBAROK, M.Si. | E48: 2 | F48: 7 | G48: 6 | H48: 6 | I48: 4 | J48: 7 | K48: 2 | L48: 3 | M48: 27 | N48: 15 | O48: 5 | P48: 1 | Q48: 7 | R48: 1 | S48: =SUM(E48:R48) -> 93
C49: 4. INAYATUL MAHMUDAH, S.Pd. | G49: 1 | P49: 1 | Q49: 2 | S49: =SUM(E49:R49) -> 4
C50: 5. HABIBURRAHMAN AL KHOLILI | J50: 1 | S50: =SUM(E50:R50) -> 1
C51: 6. INDIARTI NOVIDA, A.Md. | S51: =SUM(E51:R51) -> 0
...

Sheet SEPANJANG
C2: Kecamatan | D2: GLENMORE
C3: Kabupaten | D3: BANYUWANGI
C4: Provinsi | D4: JAWA TIMUR
C9: Kelurahan | D9: SEPANJANG
A12: I | B12: DATA PEMILIH DAN PENGGUNAAN HAK PILIH | AJ12: JUMLAH AKHIR
A13: A | B13: DATA PEMILIH | E13: TPS 001 | F13: TPS 002 | G13: TPS 003 | H13: TPS 004 | I13: TPS 005 | J13: TPS 006 | K13: TPS 007 | L13: TPS 008 | M13: TPS 009 | N13: TPS 010 | O13: TPS 011 | P13: TPS 012 | Q13: TPS 013 | R13: TPS 014 | S13: TPS 015 | T13: TPS 016 | U13: TPS 017 | V13: TPS 018 | W13: TPS 019 | X13: TPS 020 | Y13: TPS 021 | Z13: TPS 022 | AA13: TPS 023 | AB13: TPS 024 | AC13: TPS 025 | AD13: TPS 026 | AE13: TPS 027 | AF13: TPS 028 | AG13: TPS 029 | AH13: TPS 030 | AI13: TPS 031
B14: Jumlah Pemilih dalam Daftar Pemilih Tetap (DPT) | D14: LK | E14: 148 | F14: 122 | G14: 150 | H14: 138 | I14: 116 | J14: 149 | K14: 118 | L14: 112 | M14: 137 | N14: 138 | O14: 106 | P14: 129 | Q14: 135 | R14: 147 | S14: 122 | T14: 136 | U14: 125 | V14: 138 | W14: 128 | X14: 146 | Y14: 110 | Z14: 102 | AA14: 121 | AB14: 122 | AC14: 116 | AD14: 128 | AE14: 125 | AF14: 134 | AG14: 117 | AH14: 139 | AI14: 152 | AJ14: =SUM(E14:AI14) -> 4006
D15: PR | E15: 143 | F15: 129 | G15: 144 | H15: 147 | I15: 116 | J15: 146 | K15: 131 | L15: 126 | M15: 158 | N15: 154 | O15: 126 | P15: 136 | Q15: 143 | R15: 144 | S15: 130 | T15: 135 | U15: 140 | V15: 122 | W15: 127 | X15: 148 | Y15: 108 | Z15: 100 | AA15: 121 | AB15: 114 | AC15: 131 | AD15: 147 | AE15: 133 | AF15: 156 | AG15: 113 | AH15: 146 | AI15: 140 | AJ15: =SUM(E15:AI15) -> 4154
D16: JML | E16: =SUM(E14:E15) -> 291 | F16: =SUM(F14:F15) -> 251 | G16: =SUM(G14:G15) -> 294 | H16: =SUM(H14:H15) -> 285 | I16: =SUM(I14:I15) -> 232 | J16: =SUM(J14:J15) -> 295 | K16: =SUM(K14:K15) -> 249 | L16: =SUM(L14:L15) -> 238 | ... AI16: =SUM(AI14:AI15) -> 292 | AJ16: =SUM(E16:AI16) -> 8160
A18: B | B18: PENGGUNA HAK PILIH
B19: 1. | C19: Jumlah pengguna hak pilih dalam Daftar Pemilih Tetap (DPT) | D19: LK | E19: 110 | F19: 89 | G19: 114 | H19: 97 | I19: 90 | J19: 113 | K19: 84 | L19: 68 | M19: 105 | N19: 100 | O19: 84 | P19: 103 | Q19: 103 | R19: 112 | S19: 91 | T19: 105 | U19: 84 | V19: 99 | W19: 94 | X19: 98 | Y19: 87 | Z19: 82 | AA19: 86 | AB19: 84 | AC19: 80 | AD19: 84 | AE19: 94 | AF19: 95 | AG19: 95 | AH19: 107 | AI19: 116 | AJ19: =SUM(E19:AI19) -> 2953
D20: PR | E20: 111 | F20: 107 | G20: 117 | H20: 118 | I20: 95 | J20: 117 | K20: 93 | L20: 97 | M20: 124 | N20: 113 | O20: 101 | P20: 110 | Q20: 111 | R20: 121 | S20: 108 | T20: 99 | U20: 99 | V20: 98 | W20: 97 | X20: 117 | Y20: 92 | Z20: 83 | AA20: 101 | AB20: 86 | AC20: 99 | AD20: 105 | AE20: 104 | AF20: 118 | AG20: 89 | AH20: 119 | AI20: 127 | AJ20: =SUM(E20:AI20) -> 3276
D21: JML | E21: =SUM(E19:E20) -> 221 | F21: =SUM(F19:F20) -> 196 | G21: =SUM(G19:G20) -> 231 | H21: =SUM(H19:H20) -> 215 | I21: =SUM(I19:I20) -> 185 | J21: =SUM(J19:J20) -> 230 | K21: =SUM(K19:K20) -> 177 | L21: =SUM(L19:L20) -> 165 | ... AI21: =SUM(AI19:AI20) -> 243 | AJ21: =SUM(E21:AI21) -> 6229
B22: 2. | C22: Jumlah pengguna hak pilih dalam Daftar Pemilih Tambahan (DPTb) | D22: LK | I22: 1 | K22: 1 | L22: 1 | O22: 1 | S22: 1 | T22: 1 | X22: 1 | AA22: 1 | AB22: 1 | AC22: 1 | AD22: 2 | AE22: 1 | AH22: 1 | AI22: 1 | AJ22: =SUM(E22:AI22) -> 15
D23: PR | E23: 1 | L23: 1 | N23: 1 | T23: 2 | V23: 1 | W23: 1 | Y23: 1 | Z23: 1 | AD23: 1 | AF23: 1 | AG23: 1 | AJ23: =SUM(E23:AI23) -> 12
D24: JML | E24: =SUM(E22:E23) -> 1 | F24: =SUM(F22:F23) -> 0 | G24: =SUM(G22:G23) -> 0 | H24: =SUM(H22:H23) -> 0 | I24: =SUM(I22:I23) -> 1 | J24: =SUM(J22:J23) -> 0 | K24: =SUM(K22:K23) -> 1 | L24: =SUM(L22:L23) -> 2 | ... AI24: =SUM(AI22:AI23) -> 1 | AJ24: =SUM(E24:AI24) -> 27
B25: 3. | C25: Jumlah pengguna hak pilih dalam Daftar Pemilih Khusus (DPK) | D25: LK | F25: 2 | H25: 1 | J25: 7 | K25: 1 | O25: 1 | Q25: 2 | S25: 2 | T25: 1 | U25: 1 | W25: 1 | AD25: 1 | AF25: 2 | AJ25: =SUM(E25:AI25) -> 22
D26: PR | H26: 1 | J26: 5 | K26: 2 | O26: 1 | Q26: 4 | S26: 5 | T26: 2 | U26: 1 | W26: 2 | AA26: 1 | AE26: 1 | AF26: 1 | AJ26: =SUM(E26:AI26) -> 26
D27: JML | E27: =SUM(E25:E26) -> 0 | F27: =SUM(F25:F26) -> 2 | G27: =SUM(G25:G26) -> 0 | H27: =SUM(H25:H26) -> 2 | I27: =SUM(I25:I26) -> 0 | J27: =SUM(J25:J26) -> 12 | K27: =SUM(K25:K26) -> 3 | L27: =SUM(L25:L26) -> 0 | ... AI27: =SUM(AI25:AI26) -> 0 | AJ27: =SUM(E27:AI27) -> 48
B28: 4. | C28: Jumlah Pengguna Hak Pilih (B.1+B.2+B.3) | D28: LK | E28: =SUM(E19,E22,E25) -> 110 | F28: =SUM(F19,F22,F25) -> 91 | G28: =SUM(G19,G22,G25) -> 114 | H28: =SUM(H19,H22,H25) -> 98 | I28: =SUM(I19,I22,I25) -> 91 | J28: =SUM(J19,J22,J25) -> 120 | K28: =SUM(K19,K22,K25) -> 86 | L28: =SUM(L19,L22,L25) -> 69 | ... AI28: =SUM(AI19,AI22,AI25) -> 117 | AJ28: =SUM(E28:AI28) -> 2990
D29: PR | E29: =SUM(E20,E23,E26) -> 112 | F29: =SUM(F20,F23,F26) -> 107 | G29: =SUM(G20,G23,G26) -> 117 | H29: =SUM(H20,H23,H26) -> 119 | I29: =SUM(I20,I23,I26) -> 95 | J29: =SUM(J20,J23,J26) -> 122 | K29: =SUM(K20,K23,K26) -> 95 | L29: =SUM(L20,L23,L26) -> 98 | ... AI29: =SUM(AI20,AI23,AI26) -> 127 | AJ29: =SUM(E29:AI29) -> 3314
D30: JML | E30: =SUM(E28:E29) -> 222 | F30: =SUM(F28:F29) -> 198 | G30: =SUM(G28:G29) -> 231 | H30: =SUM(H28:H29) -> 217 | I30: =SUM(I28:I29) -> 186 | J30: =SUM(J28:J29) -> 242 | K30: =SUM(K28:K29) -> 181 | L30: =SUM(L28:L29) -> 167 | ... AI30: =SUM(AI28:AI29) -> 244 | AJ30: =SUM(E30:AI30) -> 6304
A32: II | B32: DATA PENGGUNAAN SURAT SUARA
A33: 1 | B33: Jumlah surat suara yang diterima, termasuk surat suara cadangan 2,5% dari DPT | E33: 298 | F33: 257 | G33: 300 | H33: 291 | I33: 236 | J33: 310 | K33: 254 | L33: 243 | M33: 301 | N33: 298 | O33: 237 | P33: 270 | Q33: 284 | R33: 297 | S33: 258 | T33: 277 | U33: 271 | V33: 265 | W33: 261 | X33: 300 | Y33: 223 | Z33: 207 | AA33: 247 | AB33: 241 | AC33: 253 | AD33: 281 | AE33: 264 | AF33: 296 | AG33: 235 | AH33: 291 | AI33: 298 | AJ33: =SUM(E33:AI33) -> 8344
A34: 2 | B34: Jumlah surat suara yang digunakan | E34: 222 | F34: 198 | G34: 231 | H34: 217 | I34: 186 | J34: 242 | K34: 181 | L34: 167 | M34: 229 | N34: 214 | O34: 188 | P34: 213 | Q34: 220 | R34: 233 | S34: 207 | T34: 210 | U34: 185 | V34: 198 | W34: 195 | X34: 216 | Y34: 180 | Z34: 166 | AA34: 189 | AB34: 171 | AC34: 180 | AD34: 193 | AE34: 200 | AF34: 217 | AG34: 185 | AH34: 227 | AI34: 244 | AJ34: =SUM(E34:AI34) -> 6304
A35: 3 | B35: Jumlah surat suara dikembalikan oleh pemilih (karena rusak atau keliru coblos) | L35: 1 | T35: 1 | Y35: 3 | AB35: 2 | AJ35: =SUM(E35:AI35) -> 7
A36: 4 | B36: Jumlah surat suara yang tidak digunakan/tidak terpakai, termasuk sisa surat suara cadangan | E36: =E33-(E34+E35) -> 76 | F36: =F33-(F34+F35) -> 59 | G36: =G33-(G34+G35) -> 69 | H36: =H33-(H34+H35) -> 74 | I36: =I33-(I34+I35) -> 50 | J36: =J33-(J34+J35) -> 68 | K36: =K33-(K34+K35) -> 73 | L36: =L33-(L34+L35) -> 75 | ... AI36: =AI33-(AI34+AI35) -> 54 | AJ36: =SUM(E36:AI36) -> 2033
A38: III | B38: DATA PEMILIH DISABILITAS
B39: Jumlah seluruh Pemilih disabilitas yang menggunakan hak pilih | D39: LK | N39: 2 | AJ39: =SUM(E39:AI39) -> 2
D40: PR | K40: 1 | L40: 1 | N40: 6 | AJ40: =SUM(E40:AI40) -> 8
D41: JML | E41: =SUM(E39:E40) -> 0 | F41: =SUM(F39:F40) -> 0 | G41: =SUM(G39:G40) -> 0 | H41: =SUM(H39:H40) -> 0 | I41: =SUM(I39:I40) -> 0 | J41: =SUM(J39:J40) -> 0 | K41: =SUM(K39:K40) -> 1 | L41: =SUM(L39:L40) -> 1 | ... AI41: =SUM(AI39:AI40) -> 0 | AJ41: =SUM(E41:AI41) -> 10
A43: IV | B43: DATA RINCIAN PEROLEHAN SUARA PASANGAN CALON BUPATI DAN WAKIL BUPATI
A44: NOMOR DAN NAMA CALON
A45: A.1 | B45: 1. | C45: Partai Kebangkitan Bangsa | E45: 6 | F45: 2 | H45: 3 | I45: 2 | J45: 5 | K45: 1 | L45: 2 | M45: 2 | N45: 3 | O45: 2 | P45: 2 | Q45: 2 | R45: 3 | S45: 2 | T45: 1 | U45: 4 | V45: 1 | W45: 3 | X45: 3 | Y45: 2 | Z45: 3 | AA45: 8 | AB45: 7 | AC45: 1 | AD45: 2 | AE45: 1 | AF45: 1 | AH45: 3 | AI45: 1 | AJ45: =SUM(E45:AI45) -> 78
A46: A.2 | C46: 1. H. KHUSNAN, S.Ag., M.Pd.I. | F46: 5 | G46: 1 | H46: 1 | I46: 1 | J46: 19 | L46: 1 | M46: 1 | N46: 1 | Q46: 3 | R46: 2 | S46: 2 | T46: 2 | U46: 1 | W46: 3 | X46: 23 | Y46: 1 | Z46: 2 | AA46: 10 | AB46: 13 | AD46: 1 | AF46: 2 | AH46: 1 | AI46: 2 | AJ46: =SUM(E46:AI46) -> 98
C47: 2. MARA QONITHA LAYLIA | E47: 6 | F47: 9 | G47: 1 | H47: 1 | I47: 9 | J47: 6 | K47: 5 | M47: 5 | N47: 6 | O47: 1 | P47: 12 | Q47: 3 | R47: 2 | S47: 6 | T47: 2 | U47: 3 | V47: 2 | W47: 19 | X47: 20 | Y47: 1 | Z47: 2 | AA47: 4 | AB47: 9 | AC47: 3 | AD47: 2 | AE47: 2 | AF47: 6 | AG47: 6 | AH47: 4 | AI47: 3 | AJ47: =SUM(E47:AI47) -> 160
C48: 3. ZAKI AL MUBAROK, M.Si. | E48: 3 | F48: 1 | G48: 8 | H48: 5 | I48: 3 | J48: 18 | L48: 5 | M48: 16 | N48: 7 | O48: 4 | P48: 8 | Q48: 2 | R48: 6 | S48: 1 | V48: 2 | W48: 5 | X48: 5 | Y48: 13 | Z48: 16 | AA48: 30 | AB48: 14 | AC48: 6 | AD48: 9 | AE48: 12 | AF48: 2 | AG48: 3 | AH48: 15 | AI48: 33 | AJ48: =SUM(E48:AI48) -> 252
C49: 4. INAYATUL MAHMUDAH, S.Pd. | G49: 1 | H49: 1 | I49: 1 | M49: 2 | P49: 1 | Q49: 1 | T49: 1 | X49: 2 | Z49: 1 | AA49: 1 | AB49: 1 | AJ49: =SUM(E49:AI49) -> 13
C50: 5. HABIBURRAHMAN AL KHOLILI | J50: 1 | V50: 1 | X50: 1 | AC50: 1 | AJ50: =SUM(E50:AI50) -> 4
C51: 6. INDIARTI NOVIDA, A.Md. | J51: 1 | AF51: 1 | AJ51: =SUM(E51:AI51) -> 2
...

Sheet SUMBERGONDO
C2: Kecamatan | D2: GLENMORE
C3: Kabupaten | D3: BANYUWANGI
C4: Provinsi | D4: JAWA TIMUR
C9: Kelurahan | D9: SUMBERGONDO
A12: I | B12: DATA PEMILIH DAN PENGGUNAAN HAK PILIH | AB12: JUMLAH AKHIR
A13: A | B13: DATA PEMILIH | E13: TPS 001 | F13: TPS 002 | G13: TPS 003 | H13: TPS 004 | I13: TPS 005 | J13: TPS 006 | K13: TPS 007 | L13: TPS 008 | M13: TPS 009 | N13: TPS 010 | O13: TPS 011 | P13: TPS 012 | Q13: TPS 013 | R13: TPS 014 | S13: TPS 015 | T13: TPS 016 | U13: TPS 017 | V13: TPS 018 | W13: TPS 019 | X13: TPS 020 | Y13: TPS 021 | Z13: TPS 022 | AA13: TPS 023
B14: Jumlah Pemilih dalam Daftar Pemilih Tetap (DPT) | D14: LK | E14: 126 | F14: 129 | G14: 134 | H14: 125 | I14: 79 | J14: 90 | K14: 102 | L14: 83 | M14: 154 | N14: 128 | O14: 152 | P14: 134 | Q14: 146 | R14: 144 | S14: 137 | T14: 130 | U14: 143 | V14: 131 | W14: 124 | X14: 143 | Y14: 134 | Z14: 117 | AA14: 86 | AB14: =SUM(E14:AA14) -> 2871
D15: PR | E15: 123 | F15: 119 | G15: 158 | H15: 130 | I15: 81 | J15: 80 | K15: 96 | L15: 86 | M15: 146 | N15: 122 | O15: 141 | P15: 144 | Q15: 133 | R15: 148 | S15: 137 | T15: 143 | U15: 155 | V15: 130 | W15: 144 | X15: 146 | Y15: 124 | Z15: 113 | AA15: 80 | AB15: =SUM(E15:AA15) -> 2879
D16: JML | E16: =SUM(E14:E15) -> 249 | F16: =SUM(F14:F15) -> 248 | G16: =SUM(G14:G15) -> 292 | H16: =SUM(H14:H15) -> 255 | I16: =SUM(I14:I15) -> 160 | J16: =SUM(J14:J15) -> 170 | K16: =SUM(K14:K15) -> 198 | L16: =SUM(L14:L15) -> 169 | ... AA16: =SUM(AA14:AA15) -> 166 | AB16: =SUM(E16:AA16) -> 5750
A18: B | B18: PENGGUNA HAK PILIH
B19: 1. | C19: Jumlah pengguna hak pilih dalam Daftar Pemilih Tetap (DPT) | D19: LK | E19: 81 | F19: 83 | G19: 103 | H19: 97 | I19: 59 | J19: 71 | K19: 74 | L19: 61 | M19: 112 | N19: 98 | O19: 109 | P19: 105 | Q19: 95 | R19: 105 | S19: 88 | T19: 96 | U19: 116 | V19: 90 | W19: 93 | X19: 93 | Y19: 103 | Z19: 63 | AA19: 59 | AB19: =SUM(E19:AA19) -> 2054
D20: PR | E20: 91 | F20: 105 | G20: 131 | H20: 98 | I20: 62 | J20: 63 | K20: 67 | L20: 64 | M20: 117 | N20: 89 | O20: 119 | P20: 109 | Q20: 106 | R20: 117 | S20: 99 | T20: 114 | U20: 124 | V20: 100 | W20: 108 | X20: 126 | Y20: 91 | Z20: 79 | AA20: 61 | AB20: =SUM(E20:AA20) -> 2240
D21: JML | E21: =SUM(E19:E20) -> 172 | F21: =SUM(F19:F20) -> 188 | G21: =SUM(G19:G20) -> 234 | H21: =SUM(H19:H20) -> 195 | I21: =SUM(I19:I20) -> 121 | J21: =SUM(J19:J20) -> 134 | K21: =SUM(K19:K20) -> 141 | L21: =SUM(L19:L20) -> 125 | ... AA21: =SUM(AA19:AA20) -> 120 | AB21: =SUM(E21:AA21) -> 4294
B22: 2. | C22: Jumlah pengguna hak pilih dalam Daftar Pemilih Tambahan (DPTb) | D22: LK | F22: 1 | I22: 2 | AB22: =SUM(E22:AA22) -> 3
D23: PR | I23: 1 | P23: 1 | Q23: 1 | AB23: =SUM(E23:AA23) -> 3
D24: JML | E24: =SUM(E22:E23) -> 0 | F24: =SUM(F22:F23) -> 1 | G24: =SUM(G22:G23) -> 0 | H24: =SUM(H22:H23) -> 0 | I24: =SUM(I22:I23) -> 3 | J24: =SUM(J22:J23) -> 0 | K24: =SUM(K22:K23) -> 0 | L24: =SUM(L22:L23) -> 0 | ... AA24: =SUM(AA22:AA23) -> 0 | AB24: =SUM(E24:AA24) -> 6
B25: 3. | C25: Jumlah pengguna hak pilih dalam Daftar Pemilih Khusus (DPK) | D25: LK | H25: 1 | J25: 1 | P25: 2 | Q25: 2 | V25: 1 | X25: 4 | Y25: 1 | AB25: =SUM(E25:AA25) -> 12
D26: PR | E26: 3 | F26: 1 | G26: 1 | H26: 1 | J26: 3 | K26: 3 | L26: 1 | N26: 1 | P26: 2 | T26: 1 | U26: 1 | V26: 2 | W26: 1 | X26: 3 | Y26: 4 | AA26: 1 | AB26: =SUM(E26:AA26) -> 29
D27: JML | E27: =SUM(E25:E26) -> 3 | F27: =SUM(F25:F26) -> 1 | G27: =SUM(G25:G26) -> 1 | H27: =SUM(H25:H26) -> 2 | I27: =SUM(I25:I26) -> 0 | J27: =SUM(J25:J26) -> 4 | K27: =SUM(K25:K26) -> 3 | L27: =SUM(L25:L26) -> 1 | ... AA27: =SUM(AA25:AA26) -> 1 | AB27: =SUM(E27:AA27) -> 41
B28: 4. | C28: Jumlah Pengguna Hak Pilih (B.1+B.2+B.3) | D28: LK | E28: =SUM(E19,E22,E25) -> 81 | F28: =SUM(F19,F22,F25) -> 84 | G28: =SUM(G19,G22,G25) -> 103 | H28: =SUM(H19,H22,H25) -> 98 | I28: =SUM(I19,I22,I25) -> 61 | J28: =SUM(J19,J22,J25) -> 72 | K28: =SUM(K19,K22,K25) -> 74 | L28: =SUM(L19,L22,L25) -> 61 | ... AA28: =SUM(AA19,AA22,AA25) -> 59 | AB28: =SUM(E28:AA28) -> 2069
D29: PR | E29: =SUM(E20,E23,E26) -> 94 | F29: =SUM(F20,F23,F26) -> 106 | G29: =SUM(G20,G23,G26) -> 132 | H29: =SUM(H20,H23,H26) -> 99 | I29: =SUM(I20,I23,I26) -> 63 | J29: =SUM(J20,J23,J26) -> 66 | K29: =SUM(K20,K23,K26) -> 70 | L29: =SUM(L20,L23,L26) -> 65 | ... AA29: =SUM(AA20,AA23,AA26) -> 62 | AB29: =SUM(E29:AA29) -> 2272
D30: JML | E30: =SUM(E28:E29) -> 175 | F30: =SUM(F28:F29) -> 190 | G30: =SUM(G28:G29) -> 235 | H30: =SUM(H28:H29) -> 197 | I30: =SUM(I28:I29) -> 124 | J30: =SUM(J28:J29) -> 138 | K30: =SUM(K28:K29) -> 144 | L30: =SUM(L28:L29) -> 126 | ... AA30: =SUM(AA28:AA29) -> 121 | AB30: =SUM(E30:AA30) -> 4341
A32: II | B32: DATA PENGGUNAAN SURAT SUARA
A33: 1 | B33: Jumlah surat suara yang diterima, termasuk surat suara cadangan 2,5% dari DPT | E33: 254 | F33: 253 | G33: 298 | H33: 261 | I33: 164 | J33: 174 | K33: 202 | L33: 173 | M33: 306 | N33: 254 | O33: 299 | P33: 284 | Q33: 285 | R33: 298 | S33: 280 | T33: 279 | U33: 304 | V33: 267 | W33: 274 | X33: 295 | Y33: 268 | Z33: 235 | AA33: 170 | AB33: =SUM(E33:AA33) -> 5877
A34: 2 | B34: Jumlah surat suara yang digunakan | E34: 175 | F34: 190 | G34: 235 | H34: 197 | I34: 124 | J34: 138 | K34: 144 | L34: 126 | M34: 229 | N34: 188 | O34: 228 | P34: 219 | Q34: 204 | R34: 222 | S34: 187 | T34: 211 | U34: 241 | V34: 193 | W34: 202 | X34: 226 | Y34: 199 | Z34: 142 | AA34: 121 | AB34: =SUM(E34:AA34) -> 4341
A35: 3 | B35: Jumlah surat suara dikembalikan oleh pemilih (karena rusak atau keliru coblos) | N35: 1 | U35: 1 | V35: 1 | W35: 1 | AB35: =SUM(E35:AA35) -> 4
A36: 4 | B36: Jumlah surat suara yang tidak digunakan/tidak terpakai, termasuk sisa surat suara cadangan | E36: =E33-(E34+E35) -> 79 | F36: =F33-(F34+F35) -> 63 | G36: =G33-(G34+G35) -> 63 | H36: =H33-(H34+H35) -> 64 | I36: =I33-(I34+I35) -> 40 | J36: =J33-(J34+J35) -> 36 | K36: =K33-(K34+K35) -> 58 | L36: =L33-(L34+L35) -> 47 | ... AA36: =AA33-(AA34+AA35) -> 49 | AB36: =SUM(E36:AA36) -> 1532
A38: III | B38: DATA PEMILIH DISABILITAS
B39: Jumlah seluruh Pemilih disabilitas yang menggunakan hak pilih | D39: LK | J39: 1 | V39: 1 | AB39: =SUM(E39:AA39) -> 2
D40: PR | AB40: =SUM(E40:AA40) -> 0
D41: JML | E41: =SUM(E39:E40) -> 0 | F41: =SUM(F39:F40) -> 0 | G41: =SUM(G39:G40) -> 0 | H41: =SUM(H39:H40) -> 0 | I41: =SUM(I39:I40) -> 0 | J41: =SUM(J39:J40) -> 1 | K41: =SUM(K39:K40) -> 0 | L41: =SUM(L39:L40) -> 0 | ... AA41: =SUM(AA39:AA40) -> 0 | AB41: =SUM(E41:AA41) -> 2
A43: IV | B43: DATA RINCIAN PEROLEHAN SUARA PASANGAN CALON BUPATI DAN WAKIL BUPATI
A44: NOMOR DAN NAMA CALON
A45: A.1 | B45: 1. | C45: Partai Kebangkitan Bangsa | E45: 3 | F45: 10 | G45: 4 | H45: 5 | I45: 2 | J45: 3 | K45: 4 | L45: 6 | M45: 1 | N45: 2 | O45: 8 | P45: 5 | Q45: 6 | S45: 11 | T45: 6 | U45: 5 | V45: 6 | W45: 3 | X45: 3 | Y45: 3 | Z45: 4 | AA45: 1 | AB45: =SUM(E45:AA45) -> 101
A46: A.2 | C46: 1. H. KHUSNAN, S.Ag., M.Pd.I. | E46: 1 | F46: 4 | G46: 3 | H46: 4 | I46: 2 | K46: 2 | L46: 2 | P46: 2 | Q46: 3 | R46: 1 | S46: 3 | T46: 5 | U46: 4 | V46: 2 | W46: 1 | X46: 4 | Y46: 2 | Z46: 1 | AA46: 1 | AB46: =SUM(E46:AA46) -> 47
C47: 2. MARA QONITHA LAYLIA | E47: 17 | F47: 64 | G47: 104 | H47: 65 | I47: 11 | J47: 9 | K47: 72 | L47: 27 | M47: 13 | N47: 2 | O47: 14 | P47: 15 | Q47: 6 | R47: 3 | S47: 16 | T47: 59 | U47: 55 | V47: 21 | W47: 29 | X47: 56 | Y47: 23 | Z47: 6 | AA47: 5 | AB47: =SUM(E47:AA47) -> 692
C48: 3. ZAKI AL MUBAROK, M.Si. | E48: 5 | F48: 3 | G48: 5 | H48: 4 | I48: 1 | K48: 1 | M48: 6 | N48: 3 | O48: 20 | P48: 29 | Q48: 20 | R48: 8 | S48: 40 | T48: 4 | U48: 4 | V48: 3 | W48: 2 | X48: 15 | Y48: 1 | Z48: 5 | AA48: 4 | AB48: =SUM(E48:AA48) -> 183
C49: 4. INAYATUL MAHMUDAH, S.Pd. | E49: 1 | F49: 2 | K49: 1 | L49: 1 | P49: 1 | T49: 2 | Z49: 1 | AB49: =SUM(E49:AA49) -> 9
C50: 5. HABIBURRAHMAN AL KHOLILI | T50: 1 | AB50: =SUM(E50:AA50) -> 1
C51: 6. INDIARTI NOVIDA, A.Md. | AB51: =SUM(E51:AA51) -> 0
...

Sheet TEGALHARJO
C2: Kecamatan | D2: GLENMORE
C3: Kabupaten | D3: BANYUWANGI
C4: Provinsi | D4: JAWA TIMUR
C9: Kelurahan | D9: TEGALHARJO
A12: I | B12: DATA PEMILIH DAN PENGGUNAAN HAK PILIH | AP12: JUMLAH AKHIR
A13: A | B13: DATA PEMILIH | E13: TPS 001 | F13: TPS 002 | G13: TPS 003 | H13: TPS 004 | I13: TPS 005 | J13: TPS 006 | K13: TPS 007 | L13: TPS 008 | M13: TPS 009 | N13: TPS 010 | O13: TPS 011 | P13: TPS 012 | Q13: TPS 013 | R13: TPS 014 | S13: TPS 015 | T13: TPS 016 | U13: TPS 017 | V13: TPS 018 | W13: TPS 019 | X13: TPS 020 | Y13: TPS 021 | Z13: TPS 022 | AA13: TPS 023 | AB13: TPS 024 | AC13: TPS 025 | AD13: TPS 026 | AE13: TPS 027 | AF13: TPS 028 | AG13: TPS 029 | AH13: TPS 030 | AI13: TPS 031 | AJ13: TPS 032 | AK13: TPS 033 | AL13: TPS 034 | AM13: TPS 035 | AN13: TPS 036 | AO13: TPS 037
B14: Jumlah Pemilih dalam Daftar Pemilih Tetap (DPT) | D14: LK | E14: 146 | F14: 90 | G14: 124 | H14: 88 | I14: 100 | J14: 130 | K14: 149 | L14: 149 | M14: 146 | N14: 129 | O14: 102 | P14: 117 | Q14: 117 | R14: 142 | S14: 147 | T14: 127 | U14: 81 | V14: 139 | W14: 98 | X14: 137 | Y14: 141 | Z14: 134 | AA14: 102 | AB14: 132 | AC14: 88 | AD14: 88 | AE14: 97 | AF14: 105 | AG14: 112 | AH14: 117 | AI14: 107 | AJ14: 104 | AK14: 109 | AL14: 143 | AM14: 126 | AN14: 109 | AO14: 99 | AP14: =SUM(E14:AO14) -> 4371
D15: PR | E15: 148 | F15: 85 | G15: 124 | H15: 94 | I15: 110 | J15: 116 | K15: 144 | L15: 145 | M15: 145 | N15: 116 | O15: 108 | P15: 114 | Q15: 135 | R15: 153 | S15: 143 | T15: 141 | U15: 80 | V15: 145 | W15: 96 | X15: 131 | Y15: 149 | Z15: 142 | AA15: 109 | AB15: 132 | AC15: 107 | AD15: 96 | AE15: 102 | AF15: 103 | AG15: 141 | AH15: 103 | AI15: 105 | AJ15: 116 | AK15: 111 | AL15: 137 | AM15: 122 | AN15: 115 | AO15: 103 | AP15: =SUM(E15:AO15) -> 4466
D16: JML | E16: =SUM(E14:E15) -> 294 | F16: =SUM(F14:F15) -> 175 | G16: =SUM(G14:G15) -> 248 | H16: =SUM(H14:H15) -> 182 | I16: =SUM(I14:I15) -> 210 | J16: =SUM(J14:J15) -> 246 | K16: =SUM(K14:K15) -> 293 | L16: =SUM(L14:L15) -> 294 | ... AO16: =SUM(AO14:AO15) -> 202 | AP16: =SUM(E16:AO16) -> 8837
A18: B | B18: PENGGUNA HAK PILIH
B19: 1. | C19: Jumlah pengguna hak pilih dalam Daftar Pemilih Tetap (DPT) | D19: LK | E19: 99 | F19: 69 | G19: 95 | H19: 53 | I19: 84 | J19: 98 | K19: 111 | L19: 112 | M19: 109 | N19: 90 | O19: 77 | P19: 80 | Q19: 95 | R19: 101 | S19: 107 | T19: 88 | U19: 64 | V19: 114 | W19: 74 | X19: 104 | Y19: 115 | Z19: 85 | AA19: 75 | AB19: 89 | AC19: 73 | AD19: 69 | AE19: 82 | AF19: 83 | AG19: 89 | AH19: 92 | AI19: 74 | AJ19: 86 | AK19: 93 | AL19: 95 | AM19: 104 | AN19: 82 | AO19: 90 | AP19: =SUM(E19:AO19) -> 3300
D20: PR | E20: 122 | F20: 69 | G20: 98 | H20: 73 | I20: 75 | J20: 97 | K20: 121 | L20: 123 | M20: 119 | N20: 94 | O20: 84 | P20: 91 | Q20: 108 | R20: 116 | S20: 106 | T20: 103 | U20: 66 | V20: 122 | W20: 79 | X20: 107 | Y20: 125 | Z20: 106 | AA20: 94 | AB20: 89 | AC20: 87 | AD20: 77 | AE20: 86 | AF20: 93 | AG20: 107 | AH20: 89 | AI20: 87 | AJ20: 98 | AK20: 92 | AL20: 115 | AM20: 99 | AN20: 98 | AO20: 98 | AP20: =SUM(E20:AO20) -> 3613
D21: JML | E21: =SUM(E19:E20) -> 221 | F21: =SUM(F19:F20) -> 138 | G21: =SUM(G19:G20) -> 193 | H21: =SUM(H19:H20) -> 126 | I21: =SUM(I19:I20) -> 159 | J21: =SUM(J19:J20) -> 195 | K21: =SUM(K19:K20) -> 232 | L21: =SUM(L19:L20) -> 235 | ... AO21: =SUM(AO19:AO20) -> 188 | AP21: =SUM(E21:AO21) -> 6913
B22: 2. | C22: Jumlah pengguna hak pilih dalam Daftar Pemilih Tambahan (DPTb) | D22: LK | I22: 1 | V22: 2 | W22: 1 | AG22: 1 | AH22: 1 | AI22: 1 | AJ22: 2 | AK22: 1 | AM22: 1 | AN22: 1 | AO22: 1 | AP22: =SUM(E22:AO22) -> 13
D23: PR | N23: 1 | V23: 2 | W23: 1 | Y23: 1 | AF23: 2 | AJ23: 2 | AP23: =SUM(E23:AO23) -> 9
D24: JML | E24: =SUM(E22:E23) -> 0 | F24: =SUM(F22:F23) -> 0 | G24: =SUM(G22:G23) -> 0 | H24: =SUM(H22:H23) -> 0 | I24: =SUM(I22:I23) -> 1 | J24: =SUM(J22:J23) -> 0 | K24: =SUM(K22:K23) -> 0 | L24: =SUM(L22:L23) -> 0 | ... AO24: =SUM(AO22:AO23) -> 1 | AP24: =SUM(E24:AO24) -> 22
B25: 3. | C25: Jumlah pengguna hak pilih dalam Daftar Pemilih Khusus (DPK) | D25: LK | F25: 1 | H25: 1 | J25: 1 | L25: 1 | R25: 4 | T25: 3 | V25: 1 | W25: 1 | X25: 2 | Z25: 2 | AA25: 4 | AB25: 4 | AE25: 3 | AH25: 5 | AI25: 2 | AK25: 1 | AP25: =SUM(E25:AO25) -> 36
D26: PR | F26: 1 | G26: 2 | H26: 1 | I26: 3 | J26: 3 | L26: 2 | M26: 1 | O26: 3 | R26: 9 | T26: 5 | V26: 1 | X26: 1 | Z26: 3 | AA26: 3 | AB26: 3 | AC26: 2 | AE26: 2 | AH26: 4 | AI26: 3 | AK26: 2 | AM26: 4 | AP26: =SUM(E26:AO26) -> 58
D27: JML | E27: =SUM(E25:E26) -> 0 | F27: =SUM(F25:F26) -> 2 | G27: =SUM(G25:G26) -> 2 | H27: =SUM(H25:H26) -> 2 | I27: =SUM(I25:I26) -> 3 | J27: =SUM(J25:J26) -> 4 | K27: =SUM(K25:K26) -> 0 | L27: =SUM(L25:L26) -> 3 | ... AO27: =SUM(AO25:AO26) -> 0 | AP27: =SUM(E27:AO27) -> 94
B28: 4. | C28: Jumlah Pengguna Hak Pilih (B.1+B.2+B.3) | D28: LK | E28: =SUM(E19,E22,E25) -> 99 | F28: =SUM(F19,F22,F25) -> 70 | G28: =SUM(G19,G22,G25) -> 95 | H28: =SUM(H19,H22,H25) -> 54 | I28: =SUM(I19,I22,I25) -> 85 | J28: =SUM(J19,J22,J25) -> 99 | K28: =SUM(K19,K22,K25) -> 111 | L28: =SUM(L19,L22,L25) -> 113 | ... AO28: =SUM(AO19,AO22,AO25) -> 91 | AP28: =SUM(E28:AO28) -> 3349
D29: PR | E29: =SUM(E20,E23,E26) -> 122 | F29: =SUM(F20,F23,F26) -> 70 | G29: =SUM(G20,G23,G26) -> 100 | H29: =SUM(H20,H23,H26) -> 74 | I29: =SUM(I20,I23,I26) -> 78 | J29: =SUM(J20,J23,J26) -> 100 | K29: =SUM(K20,K23,K26) -> 121 | L29: =SUM(L20,L23,L26) -> 125 | ... AO29: =SUM(AO20,AO23,AO26) -> 98 | AP29: =SUM(E29:AO29) -> 3680
D30: JML | E30: =SUM(E28:E29) -> 221 | F30: =SUM(F28:F29) -> 140 | G30: =SUM(G28:G29) -> 195 | H30: =SUM(H28:H29) -> 128 | I30: =SUM(I28:I29) -> 163 | J30: =SUM(J28:J29) -> 199 | K30: =SUM(K28:K29) -> 232 | L30: =SUM(L28:L29) -> 238 | ... AO30: =SUM(AO28:AO29) -> 189 | AP30: =SUM(E30:AO30) -> 7029
A32: II | B32: DATA PENGGUNAAN SURAT SUARA
A33: 1 | B33: Jumlah surat suara yang diterima, termasuk surat suara cadangan 2,5% dari DPT | E33: 300 | F33: 179 | G33: 253 | H33: 186 | I33: 215 | J33: 251 | K33: 299 | L33: 300 | M33: 297 | N33: 250 | O33: 225 | P33: 236 | Q33: 258 | R33: 302 | S33: 296 | T33: 272 | U33: 165 | V33: 310 | W33: 198 | X33: 274 | Y33: 296 | Z33: 282 | AA33: 216 | AB33: 270 | AC33: 199 | AD33: 188 | AE33: 204 | AF33: 213 | AG33: 259 | AH33: 224 | AI33: 217 | AJ33: 225 | AK33: 255 | AL33: 286 | AM33: 253 | AN33: 229 | AO33: 207 | AP33: =SUM(E33:AO33) -> 9089
A34: 2 | B34: Jumlah surat suara yang digunakan | E34: 221 | F34: 140 | G34: 195 | H34: 128 | I34: 163 | J34: 199 | K34: 232 | L34: 238 | M34: 229 | N34: 185 | O34: 164 | P34: 171 | Q34: 203 | R34: 230 | S34: 213 | T34: 199 | U34: 130 | V34: 242 | W34: 156 | X34: 214 | Y34: 241 | Z34: 196 | AA34: 176 | AB34: 185 | AC34: 162 | AD34: 146 | AE34: 173 | AF34: 178 | AG34: 197 | AH34: 191 | AI34: 167 | AJ34: 188 | AK34: 189 | AL34: 210 | AM34: 208 | AN34: 181 | AO34: 189 | AP34: =SUM(E34:AO34) -> 7029
A35: 3 | B35: Jumlah surat suara dikembalikan oleh pemilih (karena rusak atau keliru coblos) | K35: 1 | Q35: 1 | R35: 1 | V35: 1 | X35: 2 | AF35: 2 | AJ35: 1 | AN35: 1 | AO35: 2 | AP35: =SUM(E35:AO35) -> 12
A36: 4 | B36: Jumlah surat suara yang tidak digunakan/tidak terpakai, termasuk sisa surat suara cadangan | E36: =E33-(E34+E35) -> 79 | F36: =F33-(F34+F35) -> 39 | G36: =G33-(G34+G35) -> 58 | H36: =H33-(H34+H35) -> 58 | I36: =I33-(I34+I35) -> 52 | J36: =J33-(J34+J35) -> 52 | K36: =K33-(K34+K35) -> 66 | L36: =L33-(L34+L35) -> 62 | ... AO36: =AO33-(AO34+AO35) -> 16 | AP36: =SUM(E36:AO36) -> 2048
A38: III | B38: DATA PEMILIH DISABILITAS
B39: Jumlah seluruh Pemilih disabilitas yang menggunakan hak pilih | D39: LK | J39: 1 | L39: 1 | O39: 2 | W39: 2 | AF39: 1 | AP39: =SUM(E39:AO39) -> 7
D40: PR | J40: 5 | K40: 2 | L40: 2 | O40: 2 | T40: 1 | W40: 1 | AF40: 1 | AP40: =SUM(E40:AO40) -> 14
D41: JML | E41: =SUM(E39:E40) -> 0 | F41: =SUM(F39:F40) -> 0 | G41: =SUM(G39:G40) -> 0 | H41: =SUM(H39:H40) -> 0 | I41: =SUM(I39:I40) -> 0 | J41: =SUM(J39:J40) -> 6 | K41: =SUM(K39:K40) -> 2 | L41: =SUM(L39:L40) -> 3 | ... AO41: =SUM(AO39:AO40) -> 0 | AP41: =SUM(E41:AO41) -> 21
A43: IV | B43: DATA RINCIAN PEROLEHAN SUARA PASANGAN CALON BUPATI DAN WAKIL BUPATI
A44: NOMOR DAN NAMA CALON
A45: A.1 | B45: 1. | C45: Partai Kebangkitan Bangsa | E45: 11 | F45: 8 | G45: 9 | H45: 5 | I45: 7 | J45: 7 | K45: 3 | L45: 3 | M45: 2 | N45: 2 | O45: 4 | P45: 2 | Q45: 3 | R45: 5 | S45: 3 | T45: 7 | U45: 3 | V45: 0 | W45: 3 | X45: 3 | Y45: 2 | Z45: 1 | AA45: 8 | AB45: 4 | AC45: 4 | AD45: 3 | AE45: 5 | AF45: 1 | AG45: 5 | AH45: 2 | AI45: 3 | AJ45: 2 | AK45: 2 | AL45: 48 | AM45: 33 | AN45: 3 | AO45: 2 | AP45: =SUM(E45:AO45) -> 218
A46: A.2 | C46: 1. H. KHUSNAN, S.Ag., M.Pd.I. | E46: 1 | F46: 2 | G46: 3 | I46: 1 | J46: 1 | K46: 4 | M46: 4 | N46: 2 | O46: 3 | P46: 1 | Q46: 2 | R46: 5 | T46: 2 | V46: 3 | Y46: 3 | AA46: 3 | AB46: 1 | AC46: 2 | AD46: 2 | AE46: 1 | AG46: 3 | AH46: 4 | AI46: 2 | AJ46: 2 | AK46: 15 | AL46: 63 | AM46: 60 | AN46: 1 | AO46: 1 | AP46: =SUM(E46:AO46) -> 197
C47: 2. MARA QONITHA LAYLIA | E47: 5 | F47: 3 | G47: 4 | H47: 5 | I47: 5 | J47: 10 | K47: 20 | L47: 36 | N47: 7 | O47: 8 | P47: 13 | Q47: 3 | R47: 6 | S47: 3 | T47: 3 | V47: 2 | W47: 2 | X47: 1 | Z47: 1 | AA47: 9 | AB47: 6 | AC47: 3 | AD47: 8 | AE47: 9 | AF47: 2 | AG47: 17 | AH47: 25 | AI47: 3 | AJ47: 10 | AK47: 22 | AL47: 13 | AM47: 10 | AN47: 4 | AP47: =SUM(E47:AO47) -> 278
C48: 3. ZAKI AL MUBAROK, M.Si. | E48: 23 | F48: 52 | G48: 32 | H48: 24 | I48: 42 | J48: 33 | K48: 23 | L48: 25 | M48: 5 | N48: 21 | O48: 3 | P48: 7 | Q48: 2 | R48: 1 | S48: 10 | T48: 3 | U48: 32 | V48: 26 | W48: 25 | X48: 22 | Y48: 9 | AA48: 8 | AB48: 12 | AC48: 8 | AD48: 2 | AE48: 21 | AF48: 24 | AG48: 16 | AH48: 31 | AI48: 12 | AK48: 1 | AL48: 5 | AM48: 2 | AO48: 2 | AP48: =SUM(E48:AO48) -> 564
C49: 4. INAYATUL MAHMUDAH, S.Pd. | G49: 1 | H49: 2 | I49: 1 | J49: 1 | K49: 2 | L49: 1 | N49: 2 | Q49: 1 | V49: 1 | AA49: 1 | AL49: 1 | AM49: 1 | AP49: =SUM(E49:AO49) -> 15
C50: 5. HABIBURRAHMAN AL KHOLILI | O50: 2 | T50: 2 | AA50: 1 | AB50: 1 | AC50: 1 | AF50: 2 | AL50: 1 | AP50: =SUM(E50:AO50) -> 10
C51: 6. INDIARTI NOVIDA, A.Md. | W51: 1 | AA51: 1 | AP51: =SUM(E51:AO51) -> 2
...

Sheet TULUNGREJO
C2: Kecamatan | D2: GLENMORE
C3: Kabupaten | D3: BANYUWANGI
C4: Provinsi | D4: JAWA TIMUR
C9: Kelurahan | D9: TULUNGREJO
A12: I | B12: DATA PEMILIH DAN PENGGUNAAN HAK PILIH | BL12: JUMLAH AKHIR
