Workbook

Sheet PPWP
C8: Kecamatan | D8: BANYUWANGI
C9: Kabupaten | D9: BANYUWANGI
C10: Provinsi | D10: JAWA TIMUR
A12: I | B12: DATA PEMILIH DAN PENGGUNAAN HAK PILIH | E12: JUMLAH AKHIR
A13: A | B13: DATA PEMILIH
B14: Jumlah Pemilih dalam Daftar Pemilih Tetap (DPT) | D14: LK | E14: =KAMPUNGMANDAR!P14+KAMPUNGMELAYU!M14+KARANGREJO!AI14+KEBALENAN!AH14+KEPATIHAN!S14+KERTOSARI!AB14+LATENG!AD14+PAKIS!T14+PANDEREJO!R14+PENGANJURAN!T14+PENGANTIGAN!X14+SINGONEGARAN!U14+SINGOTRUNAN!AE14+SOBO!AB14+SUMBERREJO!U14+TAMANBARU!Z14+TEMENGGUNGAN!L14+TUKANGKAYU!AD14 -> 43113
D15: PR | E15: =KAMPUNGMANDAR!P15+KAMPUNGMELAYU!M15+KARANGREJO!AI15+KEBALENAN!AH15+KEPATIHAN!S15+KERTOSARI!AB15+LATENG!AD15+PAKIS!T15+PANDEREJO!R15+PENGANJURAN!T15+PENGANTIGAN!X15+SINGONEGARAN!U15+SINGOTRUNAN!AE15+SOBO!AB15+SUMBERREJO!U15+TAMANBARU!Z15+TEMENGGUNGAN!L15+TUKANGKAYU!AD15 -> 45913
D16: JML | E16: =SUM(E14:E15) -> 89026
A18: B | B18: PENGGUNA HAK PILIH
B19: 1. | C19: Jumlah pengguna hak pilih dalam Daftar Pemilih Tetap (DPT) | D19: LK | E19: =KAMPUNGMANDAR!P19+KAMPUNGMELAYU!M19+KARANGREJO!AI19+KEBALENAN!AH19+KEPATIHAN!S19+KERTOSARI!AB19+LATENG!AD19+PAKIS!T19+PANDEREJO!R19+PENGANJURAN!T19+PENGANTIGAN!X19+SINGONEGARAN!U19+SINGOTRUNAN!AE19+SOBO!AB19+SUMBERREJO!U19+TAMANBARU!Z19+TEMENGGUNGAN!L19+TUKANGKAYU!AD19 -> 31083
D20: PR | E20: =KAMPUNGMANDAR!P20+KAMPUNGMELAYU!M20+KARANGREJO!AI20+KEBALENAN!AH20+KEPATIHAN!S20+KERTOSARI!AB20+LATENG!AD20+PAKIS!T20+PANDEREJO!R20+PENGANJURAN!T20+PENGANTIGAN!X20+SINGONEGARAN!U20+SINGOTRUNAN!AE20+SOBO!AB20+SUMBERREJO!U20+TAMANBARU!Z20+TEMENGGUNGAN!L20+TUKANGKAYU!AD20 -> 36199
D21: JML | E21: =SUM(E19:E20) -> 67282
B22: 2. | C22: Jumlah pengguna hak pilih dalam Daftar Pemilih Tambahan (DPTb) | D22: LK | E22: =KAMPUNGMANDAR!P22+KAMPUNGMELAYU!M22+KARANGREJO!AI22+KEBALENAN!AH22+KEPATIHAN!S22+KERTOSARI!AB22+LATENG!AD22+PAKIS!T22+PANDEREJO!R22+PENGANJURAN!T22+PENGANTIGAN!X22+SINGONEGARAN!U22+SINGOTRUNAN!AE22+SOBO!AB22+SUMBERREJO!U22+TAMANBARU!Z22+TEMENGGUNGAN!L22+TUKANGKAYU!AD22 -> 222
D23: PR | E23: =KAMPUNGMANDAR!P23+KAMPUNGMELAYU!M23+KARANGREJO!AI23+KEBALENAN!AH23+KEPATIHAN!S23+KERTOSARI!AB23+LATENG!AD23+PAKIS!T23+PANDEREJO!R23+PENGANJURAN!T23+PENGANTIGAN!X23+SINGONEGARAN!U23+SINGOTRUNAN!AE23+SOBO!AB23+SUMBERREJO!U23+TAMANBARU!Z23+TEMENGGUNGAN!L23+TUKANGKAYU!AD23 -> 233
D24: JML | E24: =SUM(E22:E23) -> 455
B25: 3. | C25: Jumlah pengguna hak pilih dalam Daftar Pemilih Khusus (DPK) | D25: LK | E25: =KAMPUNGMANDAR!P25+KAMPUNGMELAYU!M25+KARANGREJO!AI25+KEBALENAN!AH25+KEPATIHAN!S25+KERTOSARI!AB25+LATENG!AD25+PAKIS!T25+PANDEREJO!R25+PENGANJURAN!T25+PENGANTIGAN!X25+SINGONEGARAN!U25+SINGOTRUNAN!AE25+SOBO!AB25+SUMBERREJO!U25+TAMANBARU!Z25+TEMENGGUNGAN!L25+TUKANGKAYU!AD25 -> 548
D26: PR | E26: =KAMPUNGMANDAR!P26+KAMPUNGMELAYU!M26+KARANGREJO!AI26+KEBALENAN!AH26+KEPATIHAN!S26+KERTOSARI!AB26+LATENG!AD26+PAKIS!T26+PANDEREJO!R26+PENGANJURAN!T26+PENGANTIGAN!X26+SINGONEGARAN!U26+SINGOTRUNAN!AE26+SOBO!AB26+SUMBERREJO!U26+TAMANBARU!Z26+TEMENGGUNGAN!L26+TUKANGKAYU!AD26 -> 712
D27: JML | E27: =SUM(E25:E26) -> 1260
B28: 4. | C28: Jumlah Pengguna Hak Pilih (B.1+B.2+B.3) | D28: LK | E28: =E19+E22+E25 -> 31853
D29: PR | E29: =E20+E23+E26 -> 37144
D30: JML | E30: =SUM(E28:E29) -> 68997
A32: II | B32: DATA PENGGUNAAN SURAT SUARA
A33: 1 | B33: Jumlah surat suara yang diterima, termasuk surat suara cadangan 2,5% dari DPT | E33: =KAMPUNGMANDAR!P33+KAMPUNGMELAYU!M33+KARANGREJO!AI33+KEBALENAN!AH33+KEPATIHAN!S33+KERTOSARI!AB33+LATENG!AD33+PAKIS!T33+PANDEREJO!R33+PENGANJURAN!T33+PENGANTIGAN!X33+SINGONEGARAN!U33+SINGOTRUNAN!AE33+SOBO!AB33+SUMBERREJO!U33+TAMANBARU!Z33+TEMENGGUNGAN!L33+TUKANGKAYU!AD33 -> 90826
A34: 2 | B34: Jumlah surat suara yang digunakan | E34: =KAMPUNGMANDAR!P34+KAMPUNGMELAYU!M34+KARANGREJO!AI34+KEBALENAN!AH34+KEPATIHAN!S34+KERTOSARI!AB34+LATENG!AD34+PAKIS!T34+PANDEREJO!R34+PENGANJURAN!T34+PENGANTIGAN!X34+SINGONEGARAN!U34+SINGOTRUNAN!AE34+SOBO!AB34+SUMBERREJO!U34+TAMANBARU!Z34+TEMENGGUNGAN!L34+TUKANGKAYU!AD34 -> 68997
A35: 3 | B35: Jumlah surat suara dikembalikan oleh pemilih (karena rusak atau keliru coblos) | E35: =KAMPUNGMANDAR!P35+KAMPUNGMELAYU!M35+KARANGREJO!AI35+KEBALENAN!AH35+KEPATIHAN!S35+KERTOSARI!AB35+LATENG!AD35+PAKIS!T35+PANDEREJO!R35+PENGANJURAN!T35+PENGANTIGAN!X35+SINGONEGARAN!U35+SINGOTRUNAN!AE35+SOBO!AB35+SUMBERREJO!U35+TAMANBARU!Z35+TEMENGGUNGAN!L35+TUKANGKAYU!AD35 -> 129
A36: 4 | B36: Jumlah surat suara yang tidak digunakan/tidak terpakai, termasuk sisa surat suara cadangan | E36: =E33-(E34+E35) -> 21700
A38: III | B38: DATA PEMILIH DISABILITAS
B39: Jumlah seluruh Pemilih disabilitas yang menggunakan hak pilih | D39: LK | E39: =KAMPUNGMANDAR!P39+KAMPUNGMELAYU!M39+KARANGREJO!AI39+KEBALENAN!AH39+KEPATIHAN!S39+KERTOSARI!AB39+LATENG!AD39+PAKIS!T39+PANDEREJO!R39+PENGANJURAN!T39+PENGANTIGAN!X39+SINGONEGARAN!U39+SINGOTRUNAN!AE39+SOBO!AB39+SUMBERREJO!U39+TAMANBARU!Z39+TEMENGGUNGAN!L39+TUKANGKAYU!AD39 -> 90
D40: PR | E40: =KAMPUNGMANDAR!P40+KAMPUNGMELAYU!M40+KARANGREJO!AI40+KEBALENAN!AH40+KEPATIHAN!S40+KERTOSARI!AB40+LATENG!AD40+PAKIS!T40+PANDEREJO!R40+PENGANJURAN!T40+PENGANTIGAN!X40+SINGONEGARAN!U40+SINGOTRUNAN!AE40+SOBO!AB40+SUMBERREJO!U40+TAMANBARU!Z40+TEMENGGUNGAN!L40+TUKANGKAYU!AD40 -> 78
D41: JML | E41: =SUM(E39:E40) -> 168
A43: IV | B43: DATA RINCIAN PEROLEHAN SUARA PASANGAN CALON BUPATI DAN WAKIL BUPATI
A44: NOMOR DAN NAMA CALON
B45: 1 | C45: H. ANIES RASYID BASWEDAN, Ph.D. - Dr. (H.C.) H. A. MUHAIMIN ISKANDAR | E45: =KAMPUNGMANDAR!P45+KAMPUNGMELAYU!M45+KARANGREJO!AI45+KEBALENAN!AH45+KEPATIHAN!S45+KERTOSARI!AB45+LATENG!AD45+PAKIS!T45+PANDEREJO!R45+PENGANJURAN!T45+PENGANTIGAN!X45+SINGONEGARAN!U45+SINGOTRUNAN!AE45+SOBO!AB45+SUMBERREJO!U45+TAMANBARU!Z45+TEMENGGUNGAN!L45+TUKANGKAYU!AD45 -> 13257
B46: 2 | C46: H. PRABOWO SUBIANTO - GIBRAN RAKABUMING RAKA | E46: =KAMPUNGMANDAR!P46+KAMPUNGMELAYU!M46+KARANGREJO!AI46+KEBALENAN!AH46+KEPATIHAN!S46+KERTOSARI!AB46+LATENG!AD46+PAKIS!T46+PANDEREJO!R46+PENGANJURAN!T46+PENGANTIGAN!X46+SINGONEGARAN!U46+SINGOTRUNAN!AE46+SOBO!AB46+SUMBERREJO!U46+TAMANBARU!Z46+TEMENGGUNGAN!L46+TUKANGKAYU!AD46 -> 43176
B47: 3 | C47: H. GANJAR PRANOWO, S.H., M.I.P. - Prof. Dr. H. M. MAHFUD MD | E47: =KAMPUNGMANDAR!P47+KAMPUNGMELAYU!M47+KARANGREJO!AI47+KEBALENAN!AH47+KEPATIHAN!S47+KERTOSARI!AB47+LATENG!AD47+PAKIS!T47+PANDEREJO!R47+PENGANJURAN!T47+PENGANTIGAN!X47+SINGONEGARAN!U47+SINGOTRUNAN!AE47+SOBO!AB47+SUMBERREJO!U47+TAMANBARU!Z47+TEMENGGUNGAN!L47+TUKANGKAYU!AD47 -> 11151
A49: V | B49: DATA SUARA SAH DAN TIDAK SAH
B50: A. | C50: JUMLAH SELURUH SUARA SAH | E50: =KAMPUNGMANDAR!P50+KAMPUNGMELAYU!M50+KARANGREJO!AI50+KEBALENAN!AH50+KEPATIHAN!S50+KERTOSARI!AB50+LATENG!AD50+PAKIS!T50+PANDEREJO!R50+PENGANJURAN!T50+PENGANTIGAN!X50+SINGONEGARAN!U50+SINGOTRUNAN!AE50+SOBO!AB50+SUMBERREJO!U50+TAMANBARU!Z50+TEMENGGUNGAN!L50+TUKANGKAYU!AD50 -> 67584
B51: B. | C51: JUMLAH SUARA TIDAK SAH | E51: =KAMPUNGMANDAR!P51+KAMPUNGMELAYU!M51+KARANGREJO!AI51+KEBALENAN!AH51+KEPATIHAN!S51+KERTOSARI!AB51+LATENG!AD51+PAKIS!T51+PANDEREJO!R51+PENGANJURAN!T51+PENGANTIGAN!X51+SINGONEGARAN!U51+SINGOTRUNAN!AE51+SOBO!AB51+SUMBERREJO!U51+TAMANBARU!Z51+TEMENGGUNGAN!L51+TUKANGKAYU!AD51 -> 1413
B52: C. | C52: JUMLAH SELURUH SUARA SAH DAN SUARA TIDAK SAH (V.A + V.B) | E52: =SUM(E50:E51) -> 68997

Sheet KAMPUNGMANDAR
C2: Kecamatan | D2: BANYUWANGI
C3: Kabupaten | D3: BANYUWANGI
C4: Provinsi | D4: JAWA TIMUR
C9: Kelurahan | D9: KAMPUNGMANDAR
A12: I | B12: DATA PEMILIH DAN PENGGUNAAN HAK PILIH | P12: JUMLAH AKHIR
A13: A | B13: DATA PEMILIH | E13: TPS 001 | F13: TPS 002 | G13: TPS 003 | H13: TPS 004 | I13: TPS 005 | J13: TPS 006 | K13: TPS 007 | L13: TPS 008 | M13: TPS 009 | N13: TPS 010 | O13: TPS 011
B14: Jumlah Pemilih dalam Daftar Pemilih Tetap (DPT) | D14: LK | E14: 136 | F14: 117 | G14: 134 | H14: 137 | I14: 136 | J14: 103 | K14: 131 | L14: 126 | M14: 100 | N14: 130 | O14: 146 | P14: =SUM(E14:O14) -> 1396
D15: PR | E15: 136 | F15: 131 | G15: 135 | H15: 131 | I15: 142 | J15: 98 | K15: 148 | L15: 98 | M15: 122 | N15: 151 | O15: 142 | P15: =SUM(E15:O15) -> 1434
D16: JML | E16: =SUM(E14:E15) -> 272 | F16: =SUM(F14:F15) -> 248 | G16: =SUM(G14:G15) -> 269 | H16: =SUM(H14:H15) -> 268 | I16: =SUM(I14:I15) -> 278 | J16: =SUM(J14:J15) -> 201 | K16: =SUM(K14:K15) -> 279 | L16: =SUM(L14:L15) -> 224 | ... O16: =SUM(O14:O15) -> 288 | P16: =SUM(E16:O16) -> 2830
A18: B | B18: PENGGUNA HAK PILIH
B19: 1. | C19: Jumlah pengguna hak pilih dalam Daftar Pemilih Tetap (DPT) | D19: LK | E19: 82 | F19: 79 | G19: 87 | H19: 101 | I19: 98 | J19: 86 | K19: 99 | L19: 93 | M19: 76 | N19: 88 | O19: 106 | P19: =SUM(E19:O19) -> 995
D20: PR | E20: 90 | F20: 102 | G20: 111 | H20: 102 | I20: 105 | J20: 85 | K20: 122 | L20: 80 | M20: 95 | N20: 122 | O20: 114 | P20: =SUM(E20:O20) -> 1128
D21: JML | E21: =SUM(E19:E20) -> 172 | F21: =SUM(F19:F20) -> 181 | G21: =SUM(G19:G20) -> 198 | H21: =SUM(H19:H20) -> 203 | I21: =SUM(I19:I20) -> 203 | J21: =SUM(J19:J20) -> 171 | K21: =SUM(K19:K20) -> 221 | L21: =SUM(L19:L20) -> 173 | ... O21: =SUM(O19:O20) -> 220 | P21: =SUM(E21:O21) -> 2123
B22: 2. | C22: Jumlah pengguna hak pilih dalam Daftar Pemilih Tambahan (DPTb) | D22: LK | E22: 0 | F22: 0 | G22: 0 | H22: 1 | I22: 0 | J22: 0 | K22: 0 | L22: 0 | M22: 0 | N22: 0 | O22: 0 | P22: =SUM(E22:O22) -> 1
D23: PR | E23: 0 | F23: 0 | G23: 0 | H23: 1 | I23: 0 | J23: 0 | K23: 0 | L23: 0 | M23: 0 | N23: 0 | O23: 0 | P23: =SUM(E23:O23) -> 1
D24: JML | E24: =SUM(E22:E23) -> 0 | F24: =SUM(F22:F23) -> 0 | G24: =SUM(G22:G23) -> 0 | H24: =SUM(H22:H23) -> 2 | I24: =SUM(I22:I23) -> 0 | J24: =SUM(J22:J23) -> 0 | K24: =SUM(K22:K23) -> 0 | L24: =SUM(L22:L23) -> 0 | ... O24: =SUM(O22:O23) -> 0 | P24: =SUM(E24:O24) -> 2
B25: 3. | C25: Jumlah pengguna hak pilih dalam Daftar Pemilih Khusus (DPK) | D25: LK | E25: 3 | F25: 1 | G25: 2 | H25: 1 | I25: 3 | J25: 0 | K25: 2 | L25: 0 | M25: 6 | N25: 5 | O25: 6 | P25: =SUM(E25:O25) -> 29
D26: PR | E26: 1 | F26: 1 | G26: 2 | H26: 1 | I26: 4 | J26: 0 | K26: 1 | L26: 0 | M26: 3 | N26: 8 | O26: 2 | P26: =SUM(E26:O26) -> 23
D27: JML | E27: =SUM(E25:E26) -> 4 | F27: =SUM(F25:F26) -> 2 | G27: =SUM(G25:G26) -> 4 | H27: =SUM(H25:H26) -> 2 | I27: =SUM(I25:I26) -> 7 | J27: =SUM(J25:J26) -> 0 | K27: =SUM(K25:K26) -> 3 | L27: =SUM(L25:L26) -> 0 | ... O27: =SUM(O25:O26) -> 8 | P27: =SUM(E27:O27) -> 52
B28: 4. | C28: Jumlah Pengguna Hak Pilih (B.1+B.2+B.3) | D28: LK | E28: =SUM(E19,E22,E25) -> 85 | F28: =SUM(F19,F22,F25) -> 80 | G28: =SUM(G19,G22,G25) -> 89 | H28: =SUM(H19,H22,H25) -> 103 | I28: =SUM(I19,I22,I25) -> 101 | J28: =SUM(J19,J22,J25) -> 86 | K28: =SUM(K19,K22,K25) -> 101 | L28: =SUM(L19,L22,L25) -> 93 | ... O28: =SUM(O19,O22,O25) -> 112 | P28: =SUM(E28:O28) -> 1025
D29: PR | E29: =SUM(E20,E23,E26) -> 91 | F29: =SUM(F20,F23,F26) -> 103 | G29: =SUM(G20,G23,G26) -> 113 | H29: =SUM(H20,H23,H26) -> 104 | I29: =SUM(I20,I23,I26) -> 109 | J29: =SUM(J20,J23,J26) -> 85 | K29: =SUM(K20,K23,K26) -> 123 | L29: =SUM(L20,L23,L26) -> 80 | ... O29: =SUM(O20,O23,O26) -> 116 | P29: =SUM(E29:O29) -> 1152
D30: JML | E30: =SUM(E28:E29) -> 176 | F30: =SUM(F28:F29) -> 183 | G30: =SUM(G28:G29) -> 202 | H30: =SUM(H28:H29) -> 207 | I30: =SUM(I28:I29) -> 210 | J30: =SUM(J28:J29) -> 171 | K30: =SUM(K28:K29) -> 224 | L30: =SUM(L28:L29) -> 173 | ... O30: =SUM(O28:O29) -> 228 | P30: =SUM(E30:O30) -> 2177
A32: II | B32: DATA PENGGUNAAN SURAT SUARA
A33: 1 | B33: Jumlah surat suara yang diterima, termasuk surat suara cadangan 2% dari DPT | E33: 278 | F33: 253 | G33: 275 | H33: 274 | I33: 284 | J33: 206 | K33: 285 | L33: 229 | M33: 223 | N33: 288 | O33: 294 | P33: =SUM(E33:O33) -> 2889
A34: 2 | B34: Jumlah surat suara yang digunakan | E34: 176 | F34: 183 | G34: 202 | H34: 207 | I34: 210 | J34: 171 | K34: 224 | L34: 173 | M34: 180 | N34: 223 | O34: 228 | P34: =SUM(E34:O34) -> 2177
A35: 3 | B35: Jumlah surat suara dikembalikan oleh pemilih (karena rusak atau keliru coblos) | E35: 1 | F35: 0 | G35: 2 | H35: 1 | I35: 1 | J35: 0 | K35: 0 | L35: 0 | M35: 0 | N35: 0 | O35: 0 | P35: =SUM(E35:O35) -> 5
A36: 4 | B36: Jumlah surat suara yang tidak digunakan/tidak terpakai, termasuk sisa surat suara cadangan | E36: =E33-(E34+E35) -> 101 | F36: =F33-(F34+F35) -> 70 | G36: =G33-(G34+G35) -> 71 | H36: =H33-(H34+H35) -> 66 | I36: =I33-(I34+I35) -> 73 | J36: =J33-(J34+J35) -> 35 | K36: =K33-(K34+K35) -> 61 | L36: =L33-(L34+L35) -> 56 | ... O36: =O33-(O34+O35) -> 66 | P36: =SUM(E36:O36) -> 707
A38: III | B38: DATA PEMILIH DISABILITAS
B39: Jumlah seluruh Pemilih disabilitas yang menggunakan hak pilih | D39: LK | K39: 1 | P39: =SUM(E39:O39) -> 1
D40: PR | E40: 1 | G40: 1 | K40: 1 | P40: =SUM(E40:O40) -> 3
D41: JML | E41: =SUM(E39:E40) -> 1 | F41: =SUM(F39:F40) -> 0 | G41: =SUM(G39:G40) -> 1 | H41: =SUM(H39:H40) -> 0 | I41: =SUM(I39:I40) -> 0 | J41: =SUM(J39:J40) -> 0 | K41: =SUM(K39:K40) -> 2 | L41: =SUM(L39:L40) -> 0 | ... O41: =SUM(O39:O40) -> 0 | P41: =SUM(E41:O41) -> 4
A43: IV | B43: DATA RINCIAN PEROLEHAN SUARA PASANGAN CALON BUPATI DAN WAKIL BUPATI
A44: NOMOR DAN NAMA CALON
B45: 1 | C45: H. ANIES RASYID BASWEDAN, Ph.D. - Dr. (H.C.) H. A. MUHAIMIN ISKANDAR | E45: 22 | F45: 46 | G45: 33 | H45: 22 | I45: 15 | J45: 17 | K45: 16 | L45: 39 | M45: 29 | N45: 24 | O45: 17 | P45: =SUM(E45:O45) -> 280
B46: 2 | C46: H. PRABOWO SUBIANTO - GIBRAN RAKABUMING RAKA | E46: 120 | F46: 107 | G46: 119 | H46: 111 | I46: 142 | J46: 110 | K46: 166 | L46: 94 | M46: 114 | N46: 163 | O46: 174 | P46: =SUM(E46:O46) -> 1420
B47: 3 | C47: H. GANJAR PRANOWO, S.H., M.I.P. - Prof. Dr. H. M. MAHFUD MD | E47: 30 | F47: 25 | G47: 44 | H47: 68 | I47: 49 | J47: 41 | K47: 40 | L47: 38 | M47: 36 | N47: 33 | O47: 34 | P47: =SUM(E47:O47) -> 438
A49: V | B49: DATA SUARA SAH DAN TIDAK SAH
B50: A. | C50: JUMLAH SELURUH SUARA SAH | E50: =SUM(E45:E47) -> 172 | F50: =SUM(F45:F47) -> 178 | G50: =SUM(G45:G47) -> 196 | H50: =SUM(H45:H47) -> 201 | I50: =SUM(I45:I47) -> 206 | J50: =SUM(J45:J47) -> 168 | K50: =SUM(K45:K47) -> 222 | L50: =SUM(L45:L47) -> 171 | ... O50: =SUM(O45:O47) -> 225 | P50: =SUM(E50:O50) -> 2138
B51: B. | C51: JUMLAH SUARA TIDAK SAH | E51: 4 | F51: 5 | G51: 6 | H51: 6 | I51: 4 | J51: 3 | K51: 2 | L51: 1 | M51: 2 | N51: 3 | O51: 3 | P51: =SUM(E51:O51) -> 39
B52: C. | C52: JUMLAH SELURUH SUARA SAH DAN SUARA TIDAK SAH (V.A + V.B) | E52: =SUM(E50:E51) -> 176 | F52: =SUM(F50:F51) -> 183 | G52: =SUM(G50:G51) -> 202 | H52: =SUM(H50:H51) -> 207 | I52: =SUM(I50:I51) -> 210 | J52: =SUM(J50:J51) -> 171 | K52: =SUM(K50:K51) -> 224 | L52: =SUM(L50:L51) -> 172 | ... O52: =SUM(O50:O51) -> 228 | P52: =SUM(E52:O52) -> 2177

Sheet KAMPUNGMELAYU
C2: Kecamatan | D2: BANYUWANGI
C3: Kabupaten | D3: BANYUWANGI
C4: Provinsi | D4: JAWA TIMUR
C9: Kelurahan | D9: KAMPUNGMELAYU
A12: I | B12: DATA PEMILIH DAN PENGGUNAAN HAK PILIH | M12: JUMLAH AKHIR
A13: A | B13: DATA PEMILIH | E13: TPS 001 | F13: TPS 002 | G13: TPS 003 | H13: TPS 004 | I13: TPS 005 | J13: TPS 006 | K13: TPS 007 | L13: TPS 008
B14: Jumlah Pemilih dalam Daftar Pemilih Tetap (DPT) | D14: LK | E14: 129 | F14: 143 | G14: 148 | H14: 139 | I14: 130 | J14: 128 | K14: 147 | L14: 119 | M14: =SUM(E14:L14) -> 1083
D15: PR | E15: 136 | F15: 151 | G15: 146 | H15: 151 | I15: 159 | J15: 136 | K15: 146 | L15: 130 | M15: =SUM(E15:L15) -> 1155
D16: JML | E16: =SUM(E14:E15) -> 265 | F16: =SUM(F14:F15) -> 294 | G16: =SUM(G14:G15) -> 294 | H16: =SUM(H14:H15) -> 290 | I16: =SUM(I14:I15) -> 289 | J16: =SUM(J14:J15) -> 264 | K16: =SUM(K14:K15) -> 293 | L16: =SUM(L14:L15) -> 249 | M16: =SUM(E16:L16) -> 2238
A18: B | B18: PENGGUNA HAK PILIH
B19: 1. | C19: Jumlah pengguna hak pilih dalam Daftar Pemilih Tetap (DPT) | D19: LK | E19: 85 | F19: 103 | G19: 108 | H19: 113 | I19: 100 | J19: 85 | K19: 98 | L19: 83 | M19: =SUM(E19:L19) -> 775
D20: PR | E20: 94 | F20: 122 | G20: 120 | H20: 126 | I20: 137 | J20: 102 | K20: 108 | L20: 105 | M20: =SUM(E20:L20) -> 914
D21: JML | E21: =SUM(E19:E20) -> 179 | F21: =SUM(F19:F20) -> 225 | G21: =SUM(G19:G20) -> 228 | H21: =SUM(H19:H20) -> 239 | I21: =SUM(I19:I20) -> 237 | J21: =SUM(J19:J20) -> 187 | K21: =SUM(K19:K20) -> 206 | L21: =SUM(L19:L20) -> 188 | M21: =SUM(E21:L21) -> 1689
B22: 2. | C22: Jumlah pengguna hak pilih dalam Daftar Pemilih Tambahan (DPTb) | D22: LK | E22: 0 | F22: 1 | G22: 0 | H22: 0 | I22: 0 | J22: 0 | K22: 0 | L22: 0 | M22: =SUM(E22:L22) -> 1
D23: PR | E23: 0 | F23: 0 | G23: 0 | H23: 0 | I23: 0 | J23: 0 | K23: 0 | L23: 0 | M23: =SUM(E23:L23) -> 0
D24: JML | E24: =SUM(E22:E23) -> 0 | F24: =SUM(F22:F23) -> 1 | G24: =SUM(G22:G23) -> 0 | H24: =SUM(H22:H23) -> 0 | I24: =SUM(I22:I23) -> 0 | J24: =SUM(J22:J23) -> 0 | K24: =SUM(K22:K23) -> 0 | L24: =SUM(L22:L23) -> 0 | M24: =SUM(E24:L24) -> 1
B25: 3. | C25: Jumlah pengguna hak pilih dalam Daftar Pemilih Khusus (DPK) | D25: LK | E25: 0 | F25: 0 | G25: 0 | H25: 2 | I25: 0 | J25: 0 | K25: 2 | L25: 0 | M25: =SUM(E25:L25) -> 4
D26: PR | E26: 1 | F26: 4 | H26: 1 | I26: 2 | J26: 1 | K26: 1 | L26: 2 | M26: =SUM(E26:L26) -> 12
D27: JML | E27: =SUM(E25:E26) -> 1 | F27: =SUM(F25:F26) -> 4 | G27: =SUM(G25:G26) -> 0 | H27: =SUM(H25:H26) -> 3 | I27: =SUM(I25:I26) -> 2 | J27: =SUM(J25:J26) -> 1 | K27: =SUM(K25:K26) -> 3 | L27: =SUM(L25:L26) -> 2 | M27: =SUM(E27:L27) -> 16
B28: 4. | C28: Jumlah Pengguna Hak Pilih (B.1+B.2+B.3) | D28: LK | E28: =SUM(E19,E22,E25) -> 85 | F28: =SUM(F19,F22,F25) -> 104 | G28: =SUM(G19,G22,G25) -> 108 | H28: =SUM(H19,H22,H25) -> 115 | I28: =SUM(I19,I22,I25) -> 100 | J28: =SUM(J19,J22,J25) -> 85 | K28: =SUM(K19,K22,K25) -> 100 | L28: =SUM(L19,L22,L25) -> 83 | M28: =SUM(E28:L28) -> 780
D29: PR | E29: =SUM(E20,E23,E26) -> 95 | F29: =SUM(F20,F23,F26) -> 126 | G29: =SUM(G20,G23,G26) -> 120 | H29: =SUM(H20,H23,H26) -> 127 | I29: =SUM(I20,I23,I26) -> 139 | J29: =SUM(J20,J23,J26) -> 103 | K29: =SUM(K20,K23,K26) -> 109 | L29: =SUM(L20,L23,L26) -> 107 | M29: =SUM(E29:L29) -> 926
D30: JML | E30: =SUM(E28:E29) -> 180 | F30: =SUM(F28:F29) -> 230 | G30: =SUM(G28:G29) -> 228 | H30: =SUM(H28:H29) -> 242 | I30: =SUM(I28:I29) -> 239 | J30: =SUM(J28:J29) -> 188 | K30: =SUM(K28:K29) -> 209 | L30: =SUM(L28:L29) -> 190 | M30: =SUM(E30:L30) -> 1706
A32: II | B32: DATA PENGGUNAAN SURAT SUARA
A33: 1 | B33: Jumlah surat suara yang diterima, termasuk surat suara cadangan 2,5% dari DPT | E33: 271 | F33: 300 | G33: 300 | H33: 296 | I33: 296 | J33: 285 | K33: 300 | L33: 255 | M33: =SUM(E33:L33) -> 2303
A34: 2 | B34: Jumlah surat suara yang digunakan | E34: 180 | F34: 230 | G34: 228 | H34: 242 | I34: 239 | J34: 188 | K34: 209 | L34: 190 | M34: =SUM(E34:L34) -> 1706
A35: 3 | B35: Jumlah surat suara dikembalikan oleh pemilih (karena rusak atau keliru coblos) | E35: 0 | F35: 0 | G35: 0 | H35: 1 | I35: 0 | J35: 1 | K35: 1 | L35: 0 | M35: =SUM(E35:L35) -> 3
A36: 4 | B36: Jumlah surat suara yang tidak digunakan/tidak terpakai, termasuk sisa surat suara cadangan | E36: =E33-(E34+E35) -> 91 | F36: =F33-(F34+F35) -> 70 | G36: =G33-(G34+G35) -> 72 | H36: =H33-(H34+H35) -> 53 | I36: =I33-(I34+I35) -> 57 | J36: =J33-(J34+J35) -> 96 | K36: =K33-(K34+K35) -> 90 | L36: =L33-(L34+L35) -> 65 | M36: =SUM(E36:L36) -> 594
A38: III | B38: DATA PEMILIH DISABILITAS
B39: Jumlah seluruh Pemilih disabilitas yang menggunakan hak pilih | D39: LK | E39: 1 | G39: 1 | H39: 1 | I39: 1 | K39: 3 | L39: 1 | M39: =SUM(E39:L39) -> 8
D40: PR | E40: 2 | K40: 1 | M40: =SUM(E40:L40) -> 3
D41: JML | E41: =SUM(E39:E40) -> 3 | F41: =SUM(F39:F40) -> 0 | G41: =SUM(G39:G40) -> 1 | H41: =SUM(H39:H40) -> 1 | I41: =SUM(I39:I40) -> 1 | J41: =SUM(J39:J40) -> 0 | K41: =SUM(K39:K40) -> 4 | L41: =SUM(L39:L40) -> 1 | M41: =SUM(E41:L41) -> 11
A43: IV | B43: DATA RINCIAN PEROLEHAN SUARA PASANGAN CALON BUPATI DAN WAKIL BUPATI
A44: NOMOR DAN NAMA CALON
B45: 1 | C45: H. ANIES RASYID BASWEDAN, Ph.D. - Dr. (H.C.) H. A. MUHAIMIN ISKANDAR | E45: 35 | F45: 21 | G45: 26 | H45: 26 | I45: 32 | J45: 11 | K45: 32 | L45: 22 | M45: =SUM(E45:L45) -> 205
B46: 2 | C46: H. PRABOWO SUBIANTO - GIBRAN RAKABUMING RAKA | E46: 105 | F46: 160 | G46: 167 | H46: 151 | I46: 157 | J46: 106 | K46: 141 | L46: 121 | M46: =SUM(E46:L46) -> 1108
B47: 3 | C47: H. GANJAR PRANOWO, S.H., M.I.P. - Prof. Dr. H. M. MAHFUD MD | E47: 36 | F47: 45 | G47: 30 | H47: 60 | I47: 45 | J47: 67 | K47: 32 | L47: 43 | M47: =SUM(E47:L47) -> 358
A49: V | B49: DATA SUARA SAH DAN TIDAK SAH
B50: A. | C50: JUMLAH SELURUH SUARA SAH | E50: =SUM(E45:E47) -> 176 | F50: =SUM(F45:F47) -> 226 | G50: =SUM(G45:G47) -> 223 | H50: =SUM(H45:H47) -> 237 | I50: =SUM(I45:I47) -> 234 | J50: =SUM(J45:J47) -> 184 | K50: =SUM(K45:K47) -> 205 | L50: =SUM(L45:L47) -> 186 | M50: =SUM(E50:L50) -> 1671
B51: B. | C51: JUMLAH SUARA TIDAK SAH | E51: 4 | F51: 4 | G51: 5 | H51: 5 | I51: 5 | J51: 4 | K51: 4 | L51: 4 | M51: =SUM(E51:L51) -> 35
B52: C. | C52: JUMLAH SELURUH SUARA SAH DAN SUARA TIDAK SAH (V.A + V.B) | E52: =SUM(E50:E51) -> 180 | F52: =SUM(F50:F51) -> 230 | G52: =SUM(G50:G51) -> 228 | H52: =SUM(H50:H51) -> 242 | I52: =SUM(I50:I51) -> 239 | J52: =SUM(J50:J51) -> 188 | K52: =SUM(K50:K51) -> 209 | L52: =SUM(L50:L51) -> 190 | M52: =SUM(E52:L52) -> 1706

Sheet KARANGREJO
C2: Kecamatan | D2: BANYUWANGI
C3: Kabupaten | D3: BANYUWANGI
C4: Provinsi | D4: JAWA TIMUR
C9: Kelurahan | D9: KARANGREJO
A12: I | B12: DATA PEMILIH DAN PENGGUNAAN HAK PILIH | AI12: JUMLAH AKHIR
A13: A | B13: DATA PEMILIH | E13: TPS 001 | F13: TPS 002 | G13: TPS 003 | H13: TPS 004 | I13: TPS 005 | J13: TPS 006 | K13: TPS 007 | L13: TPS 008 | M13: TPS 009 | N13: TPS 010 | O13: TPS 011 | P13: TPS 012 | Q13: TPS 013 | R13: TPS 014 | S13: TPS 015 | T13: TPS 016 | U13: TPS 017 | V13: TPS 018 | W13: TPS 019 | X13: TPS 020 | Y13: TPS 021 | Z13: TPS 022 | AA13: TPS 023 | AB13: TPS 024 | AC13: TPS 025 | AD13: TPS 026 | AE13: TPS 027 | AF13: TPS 028 | AG13: TPS 029 | AH13: TPS 030
B14: Jumlah Pemilih dalam Daftar Pemilih Tetap (DPT) | D14: LK | E14: 130 | F14: 93 | G14: 137 | H14: 140 | I14: 135 | J14: 140 | K14: 146 | L14: 133 | M14: 126 | N14: 142 | O14: 106 | P14: 141 | Q14: 132 | R14: 141 | S14: 144 | T14: 132 | U14: 128 | V14: 140 | W14: 122 | X14: 140 | Y14: 144 | Z14: 149 | AA14: 145 | AB14: 145 | AC14: 140 | AD14: 138 | AE14: 145 | AF14: 148 | AG14: 143 | AH14: 138 | AI14: =SUM(E14:AH14) -> 4083
D15: PR | E15: 124 | F15: 89 | G15: 151 | H15: 142 | I15: 143 | J15: 135 | K15: 150 | L15: 156 | M15: 149 | N15: 134 | O15: 120 | P15: 133 | Q15: 134 | R15: 135 | S15: 147 | T15: 137 | U15: 149 | V15: 141 | W15: 137 | X15: 133 | Y15: 146 | Z15: 141 | AA15: 145 | AB15: 144 | AC15: 148 | AD15: 152 | AE15: 145 | AF15: 140 | AG15: 147 | AH15: 152 | AI15: =SUM(E15:AH15) -> 4199
D16: JML | E16: =SUM(E14:E15) -> 254 | F16: =SUM(F14:F15) -> 182 | G16: =SUM(G14:G15) -> 288 | H16: =SUM(H14:H15) -> 282 | I16: =SUM(I14:I15) -> 278 | J16: =SUM(J14:J15) -> 275 | K16: =SUM(K14:K15) -> 296 | L16: =SUM(L14:L15) -> 289 | ... AH16: =SUM(AH14:AH15) -> 290 | AI16: =SUM(E16:AH16) -> 8282
A18: B | B18: PENGGUNA HAK PILIH
B19: 1. | C19: Jumlah pengguna hak pilih dalam Daftar Pemilih Tetap (DPT) | D19: LK | E19: 84 | F19: 65 | G19: 95 | H19: 94 | I19: 99 | J19: 96 | K19: 110 | L19: 84 | M19: 86 | N19: 96 | O19: 76 | P19: 96 | Q19: 99 | R19: 90 | S19: 103 | T19: 86 | U19: 92 | V19: 102 | W19: 86 | X19: 101 | Y19: 85 | Z19: 95 | AA19: 102 | AB19: 109 | AC19: 82 | AD19: 89 | AE19: 117 | AF19: 104 | AG19: 91 | AH19: 108 | AI19: =SUM(E19:AH19) -> 2822
D20: PR | E20: 94 | F20: 61 | G20: 112 | H20: 104 | I20: 111 | J20: 108 | K20: 121 | L20: 114 | M20: 105 | N20: 102 | O20: 95 | P20: 98 | Q20: 116 | R20: 108 | S20: 117 | T20: 99 | U20: 107 | V20: 110 | W20: 98 | X20: 101 | Y20: 104 | Z20: 107 | AA20: 104 | AB20: 111 | AC20: 100 | AD20: 116 | AE20: 120 | AF20: 101 | AG20: 121 | AH20: 112 | AI20: =SUM(E20:AH20) -> 3177
D21: JML | E21: =SUM(E19:E20) -> 178 | F21: =SUM(F19:F20) -> 126 | G21: =SUM(G19:G20) -> 207 | H21: =SUM(H19:H20) -> 198 | I21: =SUM(I19:I20) -> 210 | J21: =SUM(J19:J20) -> 204 | K21: =SUM(K19:K20) -> 231 | L21: =SUM(L19:L20) -> 198 | ... AH21: =SUM(AH19:AH20) -> 220 | AI21: =SUM(E21:AH21) -> 5999
B22: 2. | C22: Jumlah pengguna hak pilih dalam Daftar Pemilih Tambahan (DPTb) | D22: LK | E22: 0 | F22: 0 | G22: 0 | H22: 0 | I22: 0 | J22: 0 | K22: 0 | L22: 0 | M22: 1 | N22: 0 | O22: 0 | P22: 0 | Q22: 0 | R22: 0 | S22: 0 | T22: 0 | U22: 0 | V22: 0 | W22: 0 | X22: 0 | Y22: 0 | Z22: 0 | AA22: 0 | AB22: 0 | AC22: 1 | AD22: 0 | AE22: 0 | AF22: 0 | AG22: 0 | AH22: 0 | AI22: =SUM(E22:AH22) -> 2
D23: PR | E23: 0 | F23: 0 | G23: 0 | H23: 0 | I23: 0 | J23: 0 | K23: 0 | L23: 0 | M23: 1 | N23: 0 | O23: 0 | P23: 0 | Q23: 0 | R23: 0 | S23: 0 | T23: 0 | U23: 0 | V23: 0 | W23: 0 | X23: 0 | Y23: 0 | Z23: 0 | AA23: 0 | AB23: 0 | AC23: 2 | AD23: 0 | AE23: 0 | AF23: 0 | AG23: 1 | AH23: 0 | AI23: =SUM(E23:AH23) -> 4
D24: JML | E24: =SUM(E22:E23) -> 0 | F24: =SUM(F22:F23) -> 0 | G24: =SUM(G22:G23) -> 0 | H24: =SUM(H22:H23) -> 0 | I24: =SUM(I22:I23) -> 0 | J24: =SUM(J22:J23) -> 0 | K24: =SUM(K22:K23) -> 0 | L24: =SUM(L22:L23) -> 0 | ... AH24: =SUM(AH22:AH23) -> 0 | AI24: =SUM(E24:AH24) -> 6
B25: 3. | C25: Jumlah pengguna hak pilih dalam Daftar Pemilih Khusus (DPK) | D25: LK | E25: 0 | F25: 0 | G25: 1 | H25: 1 | I25: 0 | J25: 0 | K25: 1 | L25: 0 | M25: 1 | N25: 2 | O25: 4 | P25: 3 | Q25: 2 | R25: 1 | S25: 1 | T25: 1 | U25: 3 | V25: 2 | W25: 0 | X25: 1 | Y25: 1 | Z25: 4 | AA25: 0 | AB25: 1 | AC25: 0 | AD25: 4 | AE25: 2 | AF25: 1 | AG25: 2 | AH25: 9 | AI25: =SUM(E25:AH25) -> 48
D26: PR | E26: 4 | F26: 1 | G26: 1 | H26: 4 | I26: 0 | J26: 1 | K26: 3 | L26: 0 | M26: 4 | N26: 1 | O26: 2 | P26: 1 | Q26: 2 | R26: 4 | S26: 5 | T26: 3 | U26: 7 | V26: 2 | W26: 2 | X26: 0 | Y26: 0 | Z26: 6 | AA26: 0 | AB26: 1 | AC26: 2 | AD26: 11 | AE26: 4 | AF26: 1 | AG26: 5 | AH26: 9 | AI26: =SUM(E26:AH26) -> 86
D27: JML | E27: =SUM(E25:E26) -> 4 | F27: =SUM(F25:F26) -> 1 | G27: =SUM(G25:G26) -> 2 | H27: =SUM(H25:H26) -> 5 | I27: =SUM(I25:I26) -> 0 | J27: =SUM(J25:J26) -> 1 | K27: =SUM(K25:K26) -> 4 | L27: =SUM(L25:L26) -> 0 | ... AH27: =SUM(AH25:AH26) -> 18 | AI27: =SUM(E27:AH27) -> 134
B28: 4. | C28: Jumlah Pengguna Hak Pilih (B.1+B.2+B.3) | D28: LK | E28: =SUM(E19,E22,E25) -> 84 | F28: =SUM(F19,F22,F25) -> 65 | G28: =SUM(G19,G22,G25) -> 96 | H28: =SUM(H19,H22,H25) -> 95 | I28: =SUM(I19,I22,I25) -> 99 | J28: =SUM(J19,J22,J25) -> 96 | K28: =SUM(K19,K22,K25) -> 111 | L28: =SUM(L19,L22,L25) -> 84 | ... AH28: =SUM(AH19,AH22,AH25) -> 117 | AI28: =SUM(E28:AH28) -> 2872
D29: PR | E29: =SUM(E20,E23,E26) -> 98 | F29: =SUM(F20,F23,F26) -> 62 | G29: =SUM(G20,G23,G26) -> 113 | H29: =SUM(H20,H23,H26) -> 108 | I29: =SUM(I20,I23,I26) -> 111 | J29: =SUM(J20,J23,J26) -> 109 | K29: =SUM(K20,K23,K26) -> 124 | L29: =SUM(L20,L23,L26) -> 114 | ... AH29: =SUM(AH20,AH23,AH26) -> 121 | AI29: =SUM(E29:AH29) -> 3267
D30: JML | E30: =SUM(E28:E29) -> 182 | F30: =SUM(F28:F29) -> 127 | G30: =SUM(G28:G29) -> 209 | H30: =SUM(H28:H29) -> 203 | I30: =SUM(I28:I29) -> 210 | J30: =SUM(J28:J29) -> 205 | K30: =SUM(K28:K29) -> 235 | L30: =SUM(L28:L29) -> 198 | ... AH30: =SUM(AH28:AH29) -> 238 | AI30: =SUM(E30:AH30) -> 6139
A32: II | B32: DATA PENGGUNAAN SURAT SUARA
A33: 1 | B33: Jumlah surat suara yang diterima, termasuk surat suara cadangan 2,5% dari DPT | E33: 260 | F33: 186 | G33: 294 | H33: 289 | I33: 284 | J33: 281 | K33: 302 | L33: 295 | M33: 281 | N33: 282 | O33: 231 | P33: 280 | Q33: 273 | R33: 282 | S33: 297 | T33: 275 | U33: 283 | V33: 288 | W33: 265 | X33: 279 | Y33: 296 | Z33: 295 | AA33: 301 | AB33: 296 | AC33: 297 | AD33: 296 | AE33: 298 | AF33: 294 | AG33: 296 | AH33: 297 | AI33: =SUM(E33:AH33) -> 8473
A34: 2 | B34: Jumlah surat suara yang digunakan | E34: 182 | F34: 127 | G34: 209 | H34: 203 | I34: 210 | J34: 205 | K34: 235 | L34: 198 | M34: 198 | N34: 201 | O34: 177 | P34: 198 | Q34: 219 | R34: 203 | S34: 226 | T34: 189 | U34: 209 | V34: 216 | W34: 186 | X34: 203 | Y34: 190 | Z34: 212 | AA34: 206 | AB34: 222 | AC34: 187 | AD34: 220 | AE34: 243 | AF34: 207 | AG34: 220 | AH34: 238 | AI34: =SUM(E34:AH34) -> 6139
A35: 3 | B35: Jumlah surat suara dikembalikan oleh pemilih (karena rusak atau keliru coblos) | E35: 0 | F35: 0 | G35: 0 | H35: 0 | I35: 3 | J35: 1 | K35: 3 | L35: 0 | M35: 4 | N35: 1 | O35: 0 | P35: 0 | Q35: 0 | R35: 0 | S35: 0 | T35: 0 | U35: 0 | V35: 1 | W35: 0 | X35: 2 | Y35: 0 | Z35: 0 | AA35: 0 | AB35: 1 | AC35: 0 | AD35: 0 | AE35: 0 | AF35: 0 | AG35: 0 | AH35: 0 | AI35: =SUM(E35:AH35) -> 16
A36: 4 | B36: Jumlah surat suara yang tidak digunakan/tidak terpakai, termasuk sisa surat suara cadangan | E36: =E33-(E34+E35) -> 78 | F36: =F33-(F34+F35) -> 59 | G36: =G33-(G34+G35) -> 85 | H36: =H33-(H34+H35) -> 86 | I36: =I33-(I34+I35) -> 71 | J36: =J33-(J34+J35) -> 75 | K36: =K33-(K34+K35) -> 64 | L36: =L33-(L34+L35) -> 97 | ... AH36: =AH33-(AH34+AH35) -> 59 | AI36: =SUM(E36:AH36) -> 2318
A38: III | B38: DATA PEMILIH DISABILITAS
B39: Jumlah seluruh Pemilih disabilitas yang menggunakan hak pilih | D39: LK | E39: 0 | F39: 0 | G39: 1 | H39: 0 | I39: 0 | J39: 1 | K39: 0 | L39: 1 | M39: 0 | N39: 0 | O39: 1 | P39: 0 | Q39: 1 | R39: 0 | S39: 0 | T39: 0 | U39: 0 | V39: 0 | W39: 1 | X39: 0 | Y39: 0 | Z39: 0 | AA39: 0 | AB39: 0 | AC39: 0 | AD39: 0 | AE39: 0 | AF39: 0 | AG39: 1 | AH39: 0 | AI39: =SUM(E39:AH39) -> 7
D40: PR | E40: 1 | F40: 2 | G40: 3 | H40: 1 | I40: 0 | J40: 0 | K40: 0 | L40: 1 | M40: 0 | N40: 0 | O40: 0 | P40: 0 | Q40: 0 | R40: 0 | S40: 0 | T40: 0 | U40: 0 | V40: 0 | W40: 0 | X40: 0 | Y40: 2 | Z40: 0 | AA40: 0 | AB40: 0 | AC40: 0 | AD40: 0 | AE40: 0 | AF40: 0 | AG40: 0 | AH40: 0 | AI40: =SUM(E40:AH40) -> 10
D41: JML | E41: =SUM(E39:E40) -> 1 | F41: =SUM(F39:F40) -> 2 | G41: =SUM(G39:G40) -> 4 | H41: =SUM(H39:H40) -> 1 | I41: =SUM(I39:I40) -> 0 | J41: =SUM(J39:J40) -> 1 | K41: =SUM(K39:K40) -> 0 | L41: =SUM(L39:L40) -> 2 | ... AH41: =SUM(AH39:AH40) -> 0 | AI41: =SUM(E41:AH41) -> 17
A43: IV | B43: DATA RINCIAN PEROLEHAN SUARA PASANGAN CALON BUPATI DAN WAKIL BUPATI
A44: NOMOR DAN NAMA CALON
B45: 1 | C45: H. ANIES RASYID BASWEDAN, Ph.D. - Dr. (H.C.) H. A. MUHAIMIN ISKANDAR | E45: 12 | F45: 15 | G45: 27 | H45: 33 | I45: 26 | J45: 31 | K45: 35 | L45: 14 | M45: 32 | N45: 24 | O45: 33 | P45: 26 | Q45: 15 | R45: 11 | S45: 48 | T45: 33 | U45: 37 | V45: 23 | W45: 17 | X45: 19 | Y45: 16 | Z45: 27 | AA45: 27 | AB45: 45 | AC45: 34 | AD45: 15 | AE45: 22 | AF45: 35 | AG45: 15 | AH45: 35 | AI45: =SUM(E45:AH45) -> 782
B46: 2 | C46: H. PRABOWO SUBIANTO - GIBRAN RAKABUMING RAKA | E46: 135 | F46: 86 | G46: 142 | H46: 131 | I46: 137 | J46: 125 | K46: 175 | L46: 143 | M46: 121 | N46: 130 | O46: 123 | P46: 139 | Q46: 162 | R46: 149 | S46: 141 | T46: 131 | U46: 132 | V46: 151 | W46: 127 | X46: 129 | Y46: 118 | Z46: 140 | AA46: 131 | AB46: 131 | AC46: 107 | AD46: 150 | AE46: 170 | AF46: 126 | AG46: 146 | AH46: 162 | AI46: =SUM(E46:AH46) -> 4090
B47: 3 | C47: H. GANJAR PRANOWO, S.H., M.I.P. - Prof. Dr. H. M. MAHFUD MD | E47: 28 | F47: 23 | G47: 39 | H47: 36 | I47: 43 | J47: 43 | K47: 23 | L47: 39 | M47: 42 | N47: 42 | O47: 20 | P47: 30 | Q47: 34 | R47: 41 | S47: 36 | T47: 25 | U47: 33 | V47: 41 | W47: 42 | X47: 52 | Y47: 51 | Z47: 38 | AA47: 38 | AB47: 36 | AC47: 29 | AD47: 49 | AE47: 44 | AF47: 35 | AG47: 48 | AH47: 36 | AI47: =SUM(E47:AH47) -> 1116
A49: V | B49: DATA SUARA SAH DAN TIDAK SAH
B50: A. | C50: JUMLAH SELURUH SUARA SAH | E50: =SUM(E45:E47) -> 175 | F50: =SUM(F45:F47) -> 124 | G50: =SUM(G45:G47) -> 208 | H50: =SUM(H45:H47) -> 200 | I50: =SUM(I45:I47) -> 206 | J50: =SUM(J45:J47) -> 199 | K50: =SUM(K45:K47) -> 233 | L50: =SUM(L45:L47) -> 196 | ... AH50: =SUM(AH45:AH47) -> 233 | AI50: =SUM(E50:AH50) -> 5988
B51: B. | C51: JUMLAH SUARA TIDAK SAH | E51: 7 | F51: 3 | G51: 1 | H51: 3 | I51: 4 | J51: 6 | K51: 2 | L51: 2 | M51: 3 | N51: 5 | O51: 1 | P51: 3 | Q51: 8 | R51: 2 | S51: 1 | T51: 0 | U51: 7 | V51: 1 | W51: 0 | X51: 3 | Y51: 5 | Z51: 7 | AA51: 10 | AB51: 10 | AC51: 17 | AD51: 6 | AE51: 7 | AF51: 11 | AG51: 11 | AH51: 5 | AI51: =SUM(E51:AH51) -> 151
B52: C. | C52: JUMLAH SELURUH SUARA SAH DAN SUARA TIDAK SAH (V.A + V.B) | E52: =SUM(E50:E51) -> 182 | F52: =SUM(F50:F51) -> 127 | G52: =SUM(G50:G51) -> 209 | H52: =SUM(H50:H51) -> 203 | I52: =SUM(I50:I51) -> 210 | J52: =SUM(J50:J51) -> 205 | K52: =SUM(K50:K51) -> 235 | L52: =SUM(L50:L51) -> 198 | ... AH52: =SUM(AH50:AH51) -> 238 | AI52: =SUM(E52:AH52) -> 6139

Sheet KEBALENAN
C2: Kecamatan | D2: BANYUWANGI
C3: Kabupaten | D3: BANYUWANGI
C4: Provinsi | D4: JAWA TIMUR
C9: Kelurahan | D9: KEBALENAN
A12: I | B12: DATA PEMILIH DAN PENGGUNAAN HAK PILIH | AH12: JUMLAH AKHIR
A13: A | B13: DATA PEMILIH | E13: TPS 001 | F13: TPS 002 | G13: TPS 003 | H13: TPS 004 | I13: TPS 005 | J13: TPS 006 | K13: TPS 007 | L13: TPS 008 | M13: TPS 009 | N13: TPS 010 | O13: TPS 011 | P13: TPS 012 | Q13: TPS 013 | R13: TPS 014 | S13: TPS 015 | T13: TPS 016 | U13: TPS 017 | V13: TPS 018 | W13: TPS 019 | X13: TPS 020 | Y13: TPS 021 | Z13: TPS 022 | AA13: TPS 023 | AB13: TPS 024 | AC13: TPS 025 | AD13: TPS 026 | AE13: TPS 027 | AF13: TPS 028 | AG13: TPS 029
B14: Jumlah Pemilih dalam Daftar Pemilih Tetap (DPT) | D14: LK | E14: 135 | F14: 150 | G14: 140 | H14: 130 | I14: 145 | J14: 139 | K14: 138 | L14: 138 | M14: 146 | N14: 141 | O14: 134 | P14: 136 | Q14: 135 | R14: 127 | S14: 124 | T14: 127 | U14: 138 | V14: 147 | W14: 129 | X14: 120 | Y14: 130 | Z14: 135 | AA14: 136 | AB14: 125 | AC14: 136 | AD14: 135 | AE14: 82 | AF14: 74 | AG14: 148 | AH14: =SUM(E14:AG14) -> 3820
D15: PR | E15: 155 | F15: 142 | G15: 154 | H15: 159 | I15: 146 | J15: 140 | K15: 149 | L15: 154 | M15: 144 | N15: 155 | O15: 162 | P15: 143 | Q15: 129 | R15: 147 | S15: 144 | T15: 143 | U15: 153 | V15: 146 | W15: 146 | X15: 150 | Y15: 153 | Z15: 149 | AA15: 154 | AB15: 152 | AC15: 160 | AD15: 148 | AE15: 96 | AF15: 83 | AG15: 150 | AH15: =SUM(E15:AG15) -> 4206
D16: JML | E16: =SUM(E14:E15) -> 290 | F16: =SUM(F14:F15) -> 292 | G16: =SUM(G14:G15) -> 294 | H16: =SUM(H14:H15) -> 289 | I16: =SUM(I14:I15) -> 291 | J16: =SUM(J14:J15) -> 279 | K16: =SUM(K14:K15) -> 287 | L16: =SUM(L14:L15) -> 292 | ... AG16: =SUM(AG14:AG15) -> 298 | AH16: =SUM(E16:AG16) -> 8026
A18: B | B18: PENGGUNA HAK PILIH
B19: 1. | C19: Jumlah pengguna hak pilih dalam Daftar Pemilih Tetap (DPT) | D19: LK | E19: 94 | F19: 111 | G19: 95 | H19: 95 | I19: 112 | J19: 109 | K19: 103 | L19: 99 | M19: 113 | N19: 91 | O19: 101 | P19: 92 | Q19: 97 | R19: 92 | S19: 89 | T19: 92 | U19: 96 | V19: 118 | W19: 100 | X19: 88 | Y19: 93 | Z19: 94 | AA19: 101 | AB19: 87 | AC19: 102 | AD19: 96 | AE19: 56 | AF19: 53 | AG19: 123 | AH19: =SUM(E19:AG19) -> 2792
D20: PR | E20: 121 | F20: 112 | G20: 112 | H20: 127 | I20: 127 | J20: 104 | K20: 116 | L20: 126 | M20: 120 | N20: 111 | O20: 122 | P20: 116 | Q20: 112 | R20: 111 | S20: 117 | T20: 107 | U20: 124 | V20: 128 | W20: 120 | X20: 123 | Y20: 127 | Z20: 118 | AA20: 121 | AB20: 113 | AC20: 128 | AD20: 126 | AE20: 70 | AF20: 67 | AG20: 128 | AH20: =SUM(E20:AG20) -> 3354
D21: JML | E21: =SUM(E19:E20) -> 215 | F21: =SUM(F19:F20) -> 223 | G21: =SUM(G19:G20) -> 207 | H21: =SUM(H19:H20) -> 222 | I21: =SUM(I19:I20) -> 239 | J21: =SUM(J19:J20) -> 213 | K21: =SUM(K19:K20) -> 219 | L21: =SUM(L19:L20) -> 225 | ... AG21: =SUM(AG19:AG20) -> 251 | AH21: =SUM(E21:AG21) -> 6146
B22: 2. | C22: Jumlah pengguna hak pilih dalam Daftar Pemilih Tambahan (DPTb) | D22: LK | E22: 0 | F22: 1 | G22: 2 | H22: 0 | I22: 0 | J22: 0 | K22: 2 | L22: 3 | M22: 1 | N22: 0 | O22: 0 | P22: 4 | Q22: 0 | R22: 1 | S22: 3 | T22: 9 | U22: 2 | V22: 1 | W22: 0 | X22: 0 | Y22: 1 | Z22: 1 | AA22: 0 | AB22: 2 | AC22: 2 | AD22: 11 | AE22: 9 | AF22: 0 | AG22: 0 | AH22: =SUM(E22:AG22) -> 55
D23: PR | E23: 2 | F23: 2 | G23: 1 | H23: 1 | I23: 0 | J23: 0 | K23: 2 | L23: 3 | M23: 0 | N23: 0 | O23: 0 | P23: 4 | Q23: 1 | R23: 0 | S23: 3 | T23: 3 | U23: 3 | V23: 1 | W23: 0 | X23: 0 | Y23: 5 | Z23: 2 | AA23: 1 | AB23: 2 | AC23: 4 | AD23: 1 | AE23: 0 | AF23: 0 | AG23: 0 | AH23: =SUM(E23:AG23) -> 41
D24: JML | E24: =SUM(E22:E23) -> 2 | F24: =SUM(F22:F23) -> 3 | G24: =SUM(G22:G23) -> 3 | H24: =SUM(H22:H23) -> 1 | I24: =SUM(I22:I23) -> 0 | J24: =SUM(J22:J23) -> 0 | K24: =SUM(K22:K23) -> 4 | L24: =SUM(L22:L23) -> 6 | ... AG24: =SUM(AG22:AG23) -> 0 | AH24: =SUM(E24:AG24) -> 96
B25: 3. | C25: Jumlah pengguna hak pilih dalam Daftar Pemilih Khusus (DPK) | D25: LK | E25: 1 | F25: 0 | G25: 2 | H25: 1 | I25: 0 | J25: 0 | K25: 4 | L25: 2 | M25: 1 | N25: 1 | O25: 1 | P25: 0 | Q25: 4 | R25: 4 | S25: 4 | T25: 0 | U25: 0 | V25: 1 | W25: 0 | X25: 0 | Y25: 1 | Z25: 1 | AA25: 0 | AB25: 0 | AC25: 2 | AD25: 1 | AE25: 2 | AF25: 2 | AG25: 0 | AH25: =SUM(E25:AG25) -> 35
D26: PR | E26: 0 | F26: 3 | G26: 2 | H26: 2 | I26: 0 | J26: 1 | K26: 5 | L26: 1 | M26: 5 | N26: 1 | O26: 1 | P26: 1 | Q26: 2 | R26: 2 | S26: 5 | T26: 2 | U26: 0 | V26: 1 | W26: 2 | X26: 4 | Y26: 2 | Z26: 2 | AA26: 0 | AB26: 0 | AC26: 0 | AD26: 2 | AE26: 3 | AF26: 5 | AG26: 0 | AH26: =SUM(E26:AG26) -> 54
D27: JML | E27: =SUM(E25:E26) -> 1 | F27: =SUM(F25:F26) -> 3 | G27: =SUM(G25:G26) -> 4 | H27: =SUM(H25:H26) -> 3 | I27: =SUM(I25:I26) -> 0 | J27: =SUM(J25:J26) -> 1 | K27: =SUM(K25:K26) -> 9 | L27: =SUM(L25:L26) -> 3 | ... AG27: =SUM(AG25:AG26) -> 0 | AH27: =SUM(E27:AG27) -> 89
B28: 4. | C28: Jumlah Pengguna Hak Pilih (B.1+B.2+B.3) | D28: LK | E28: =SUM(E19,E22,E25) -> 95 | F28: =SUM(F19,F22,F25) -> 112 | G28: =SUM(G19,G22,G25) -> 99 | H28: =SUM(H19,H22,H25) -> 96 | I28: =SUM(I19,I22,I25) -> 112 | J28: =SUM(J19,J22,J25) -> 109 | K28: =SUM(K19,K22,K25) -> 109 | L28: =SUM(L19,L22,L25) -> 104 | ... AG28: =SUM(AG19,AG22,AG25) -> 123 | AH28: =SUM(E28:AG28) -> 2882
D29: PR | E29: =SUM(E20,E23,E26) -> 123 | F29: =SUM(F20,F23,F26) -> 117 | G29: =SUM(G20,G23,G26) -> 115 | H29: =SUM(H20,H23,H26) -> 130 | I29: =SUM(I20,I23,I26) -> 127 | J29: =SUM(J20,J23,J26) -> 105 | K29: =SUM(K20,K23,K26) -> 123 | L29: =SUM(L20,L23,L26) -> 130 | ... AG29: =SUM(AG20,AG23,AG26) -> 128 | AH29: =SUM(E29:AG29) -> 3449
D30: JML | E30: =SUM(E28:E29) -> 218 | F30: =SUM(F28:F29) -> 229 | G30: =SUM(G28:G29) -> 214 | H30: =SUM(H28:H29) -> 226 | I30: =SUM(I28:I29) -> 239 | J30: =SUM(J28:J29) -> 214 | K30: =SUM(K28:K29) -> 232 | L30: =SUM(L28:L29) -> 234 | ... AG30: =SUM(AG28:AG29) -> 251 | AH30: =SUM(E30:AG30) -> 6331
A32: II | B32: DATA PENGGUNAAN SURAT SUARA
A33: 1 | B33: Jumlah surat suara yang diterima, termasuk surat suara cadangan 2,5% dari DPT | E33: 296 | F33: 289 | G33: 290 | H33: 295 | I33: 285 | J33: 282 | K33: 283 | L33: 278 | M33: 286 | N33: 283 | O33: 292 | P33: 266 | Q33: 252 | R33: 260 | S33: 275 | T33: 276 | U33: 300 | V33: 301 | W33: 281 | X33: 276 | Y33: 289 | Z33: 290 | AA33: 281 | AB33: 285 | AC33: 302 | AD33: 289 | AE33: 182 | AF33: 162 | AG33: 303 | AH33: =SUM(E33:AG33) -> 8029
A34: 2 | B34: Jumlah surat suara yang digunakan | E34: 218 | F34: 229 | G34: 214 | H34: 226 | I34: 239 | J34: 214 | K34: 232 | L34: 234 | M34: 240 | N34: 204 | O34: 225 | P34: 217 | Q34: 216 | R34: 210 | S34: 221 | T34: 213 | U34: 225 | V34: 250 | W34: 222 | X34: 215 | Y34: 229 | Z34: 218 | AA34: 223 | AB34: 204 | AC34: 238 | AD34: 237 | AE34: 140 | AF34: 127 | AG34: 251 | AH34: =SUM(E34:AG34) -> 6331
A35: 3 | B35: Jumlah surat suara dikembalikan oleh pemilih (karena rusak atau keliru coblos) | E35: 2 | F35: 1 | G35: 0 | H35: 1 | I35: 0 | J35: 0 | K35: 0 | L35: 0 | M35: 0 | N35: 0 | O35: 0 | P35: 1 | Q35: 0 | R35: 0 | S35: 0 | T35: 0 | U35: 0 | V35: 0 | W35: 0 | X35: 0 | Y35: 0 | Z35: 0 | AA35: 0 | AB35: 0 | AC35: 0 | AD35: 0 | AE35: 0 | AF35: 0 | AG35: 0 | AH35: =SUM(E35:AG35) -> 5
A36: 4 | B36: Jumlah surat suara yang tidak digunakan/tidak terpakai, termasuk sisa surat suara cadangan | E36: =E33-(E34+E35) -> 76 | F36: =F33-(F34+F35) -> 59 | G36: =G33-(G34+G35) -> 76 | H36: =H33-(H34+H35) -> 68 | I36: =I33-(I34+I35) -> 46 | J36: =J33-(J34+J35) -> 68 | K36: =K33-(K34+K35) -> 51 | L36: =L33-(L34+L35) -> 44 | ... AG36: =AG33-(AG34+AG35) -> 52 | AH36: =SUM(E36:AG36) -> 1693
A38: III | B38: DATA PEMILIH DISABILITAS
B39: Jumlah seluruh Pemilih disabilitas yang menggunakan hak pilih | D39: LK | E39: 0 | F39: 0 | G39: 0 | H39: 0 | I39: 0 | J39: 0 | K39: 0 | L39: 0 | M39: 0 | N39: 0 | O39: 1 | P39: 0 | Q39: 0 | R39: 2 | S39: 0 | T39: 0 | U39: 0 | V39: 0 | W39: 0 | X39: 1 | Y39: 0 | Z39: 0 | AA39: 0 | AB39: 0 | AC39: 1 | AD39: 0 | AE39: 1 | AF39: 0 | AG39: 0 | AH39: =SUM(E39:AG39) -> 6
D40: PR | E40: 0 | F40: 0 | G40: 0 | H40: 0 | I40: 0 | J40: 0 | K40: 0 | L40: 1 | M40: 0 | N40: 0 | O40: 0 | P40: 0 | Q40: 0 | R40: 1 | S40: 0 | T40: 0 | U40: 1 | V40: 0 | W40: 0 | X40: 1 | Y40: 0 | Z40: 1 | AA40: 0 | AB40: 0 | AC40: 0 | AD40: 0 | AE40: 0 | AF40: 0 | AG40: 0 | AH40: =SUM(E40:AG40) -> 5
D41: JML | E41: =SUM(E39:E40) -> 0 | F41: =SUM(F39:F40) -> 0 | G41: =SUM(G39:G40) -> 0 | H41: =SUM(H39:H40) -> 0 | I41: =SUM(I39:I40) -> 0 | J41: =SUM(J39:J40) -> 0 | K41: =SUM(K39:K40) -> 0 | L41: =SUM(L39:L40) -> 1 | ... AC41: =SUM(AC39:AC40) -> 1 | AD41: 0 | AE41: =SUM(AE39:AE40) -> 1 | AF41: =SUM(AF39:AF40) -> 0 | AG41: =SUM(AG39:AG40) -> 0 | AH41: =SUM(E41:AG41) -> 11
A43: IV | B43: DATA RINCIAN PEROLEHAN SUARA PASANGAN CALON BUPATI DAN WAKIL BUPATI
A44: NOMOR DAN NAMA CALON
B45: 1 | C45: H. ANIES RASYID BASWEDAN, Ph.D. - Dr. (H.C.) H. A. MUHAIMIN ISKANDAR | E45: 46 | F45: 39 | G45: 38 | H45: 36 | I45: 34 | J45: 61 | K45: 54 | L45: 61 | M45: 47 | N45: 53 | O45: 50 | P45: 48 | Q45: 55 | R45: 34 | S45: 41 | T45: 69 | U45: 73 | V45: 59 | W45: 93 | X45: 41 | Y45: 53 | Z45: 42 | AA45: 40 | AB45: 43 | AC45: 59 | AD45: 65 | AE45: 26 | AF45: 22 | AG45: 27 | AH45: =SUM(E45:AG45) -> 1409
B46: 2 | C46: H. PRABOWO SUBIANTO - GIBRAN RAKABUMING RAKA | E46: 139 | F46: 151 | G46: 137 | H46: 138 | I46: 147 | J46: 116 | K46: 144 | L46: 134 | M46: 147 | N46: 141 | O46: 147 | P46: 132 | Q46: 125 | R46: 131 | S46: 152 | T46: 114 | U46: 115 | V46: 146 | W46: 106 | X46: 129 | Y46: 138 | Z46: 141 | AA46: 146 | AB46: 140 | AC46: 146 | AD46: 134 | AE46: 94 | AF46: 79 | AG46: 184 | AH46: =SUM(E46:AG46) -> 3893
B47: 3 | C47: H. GANJAR PRANOWO, S.H., M.I.P. - Prof. Dr. H. M. MAHFUD MD | E47: 31 | F47: 33 | G47: 35 | H47: 45 | I47: 52 | J47: 32 | K47: 32 | L47: 38 | M47: 40 | N47: 9 | O47: 26 | P47: 34 | Q47: 32 | R47: 44 | S47: 26 | T47: 25 | U47: 28 | V47: 38 | W47: 20 | X47: 43 | Y47: 35 | Z47: 30 | AA47: 32 | AB47: 18 | AC47: 31 | AD47: 28 | AE47: 16 | AF47: 24 | AG47: 38 | AH47: =SUM(E47:AG47) -> 915
A49: V | B49: DATA SUARA SAH DAN TIDAK SAH
B50: A. | C50: JUMLAH SELURUH SUARA SAH | E50: =SUM(E45:E47) -> 216 | F50: =SUM(F45:F47) -> 223 | G50: =SUM(G45:G47) -> 210 | H50: =SUM(H45:H47) -> 219 | I50: =SUM(I45:I47) -> 233 | J50: =SUM(J45:J47) -> 209 | K50: =SUM(K45:K47) -> 230 | L50: =SUM(L45:L47) -> 233 | ... AG50: =SUM(AG45:AG47) -> 249 | AH50: =SUM(E50:AG50) -> 6217
B51: B. | C51: JUMLAH SUARA TIDAK SAH | E51: 2 | F51: 6 | G51: 4 | H51: 7 | I51: 6 | J51: 5 | K51: 2 | L51: 1 | M51: 6 | N51: 1 | O51: 2 | P51: 3 | Q51: 4 | R51: 1 | S51: 2 | T51: 5 | U51: 9 | V51: 7 | W51: 3 | X51: 2 | Y51: 3 | Z51: 5 | AA51: 5 | AB51: 3 | AC51: 2 | AD51: 10 | AE51: 4 | AF51: 2 | AG51: 2 | AH51: =SUM(E51:AG51) -> 114
B52: C. | C52: JUMLAH SELURUH SUARA SAH DAN SUARA TIDAK SAH (V.A + V.B) | E52: =SUM(E50:E51) -> 218 | F52: =SUM(F50:F51) -> 229 | G52: =SUM(G50:G51) -> 214 | H52: =SUM(H50:H51) -> 226 | I52: =SUM(I50:I51) -> 239 | J52: =SUM(J50:J51) -> 214 | K52: =SUM(K50:K51) -> 232 | L52: =SUM(L50:L51) -> 234 | ... AG52: =SUM(AG50:AG51) -> 251 | AH52: =SUM(E52:AG52) -> 6331

Sheet KEPATIHAN
C2: Kecamatan | D2: BANYUWANGI
C3: Kabupaten | D3: BANYUWANGI
C4: Provinsi | D4: JAWA TIMUR
C9: Kelurahan | D9: KEPATIHAN
A12: I | B12: DATA PEMILIH DAN PENGGUNAAN HAK PILIH | S12: JUMLAH AKHIR
A13: A | B13: DATA PEMILIH | E13: TPS 001 | F13: TPS 002 | G13: TPS 003 | H13: TPS 004 | I13: TPS 005 | J13: TPS 006 | K13: TPS 007 | L13: TPS 008 | M13: TPS 009 | N13: TPS 010 | O13: TPS 011 | P13: TPS 012 | Q13: TPS 013 | R13: TPS 014
B14: Jumlah Pemilih dalam Daftar Pemilih Tetap (DPT) | D14: LK | E14: 99 | F14: 85 | G14: 115 | H14: 126 | I14: 128 | J14: 122 | K14: 134 | L14: 141 | M14: 129 | N14: 99 | O14: 72 | P14: 132 | Q14: 136 | R14: 131 | S14: =SUM(E14:R14) -> 1649
D15: PR | E15: 104 | F15: 87 | G15: 106 | H15: 148 | I15: 147 | J15: 148 | K15: 162 | L15: 152 | M15: 122 | N15: 106 | O15: 75 | P15: 131 | Q15: 141 | R15: 140 | S15: =SUM(E15:R15) -> 1769
D16: JML | E16: =SUM(E14:E15) -> 203 | F16: =SUM(F14:F15) -> 172 | G16: =SUM(G14:G15) -> 221 | H16: =SUM(H14:H15) -> 274 | I16: =SUM(I14:I15) -> 275 | J16: =SUM(J14:J15) -> 270 | K16: =SUM(K14:K15) -> 296 | L16: =SUM(L14:L15) -> 293 | ... R16: =SUM(R14:R15) -> 271 | S16: =SUM(E16:R16) -> 3418
A18: B | B18: PENGGUNA HAK PILIH
B19: 1. | C19: Jumlah pengguna hak pilih dalam Daftar Pemilih Tetap (DPT) | D19: LK | E19: 69 | F19: 61 | G19: 73 | H19: 117 | I19: 84 | J19: 111 | K19: 90 | L19: 105 | M19: 78 | N19: 64 | O19: 51 | P19: 91 | Q19: 96 | R19: 90 | S19: =SUM(E19:R19) -> 1180
D20: PR | E20: 81 | F20: 66 | G20: 82 | H20: 94 | I20: 114 | J20: 85 | K20: 126 | L20: 117 | M20: 88 | N20: 76 | O20: 54 | P20: 103 | Q20: 117 | R20: 100 | S20: =SUM(E20:R20) -> 1303
D21: JML | E21: =SUM(E19:E20) -> 150 | F21: =SUM(F19:F20) -> 127 | G21: =SUM(G19:G20) -> 155 | H21: =SUM(H19:H20) -> 211 | I21: =SUM(I19:I20) -> 198 | J21: =SUM(J19:J20) -> 196 | K21: =SUM(K19:K20) -> 216 | L21: =SUM(L19:L20) -> 222 | ... R21: =SUM(R19:R20) -> 190 | S21: =SUM(E21:R21) -> 2483
B22: 2. | C22: Jumlah pengguna hak pilih dalam Daftar Pemilih Tambahan (DPTb) | D22: LK | E22: 0 | F22: 0 | G22: 0 | H22: 1 | I22: 1 | J22: 1 | K22: 0 | L22: 0 | M22: 1 | N22: 0 | O22: 0 | P22: 1 | Q22: 0 | R22: 0 | S22: =SUM(E22:R22) -> 5
D23: PR | E23: 0 | F23: 0 | G23: 1 | H23: 1 | I23: 1 | J23: 1 | K23: 0 | L23: 0 | M23: 0 | N23: 0 | O23: 0 | P23: 0 | Q23: 0 | R23: 0 | S23: =SUM(E23:R23) -> 4
D24: JML | E24: =SUM(E22:E23) -> 0 | F24: =SUM(F22:F23) -> 0 | G24: =SUM(G22:G23) -> 1 | H24: =SUM(H22:H23) -> 2 | I24: =SUM(I22:I23) -> 2 | J24: =SUM(J22:J23) -> 2 | K24: =SUM(K22:K23) -> 0 | L24: =SUM(L22:L23) -> 0 | ... R24: =SUM(R22:R23) -> 0 | S24: =SUM(E24:R24) -> 9
B25: 3. | C25: Jumlah pengguna hak pilih dalam Daftar Pemilih Khusus (DPK) | D25: LK | E25: 0 | F25: 4 | G25: 3 | H25: 0 | I25: 0 | J25: 0 | K25: 3 | L25: 4 | M25: 0 | N25: 2 | O25: 1 | P25: 2 | Q25: 0 | R25: 0 | S25: =SUM(E25:R25) -> 19
D26: PR | E26: 1 | F26: 2 | G26: 3 | H26: 0 | I26: 0 | J26: 1 | K26: 3 | L26: 3 | M26: 0 | N26: 6 | O26: 0 | P26: 1 | Q26: 0 | R26: 1 | S26: =SUM(E26:R26) -> 21
D27: JML | E27: =SUM(E25:E26) -> 1 | F27: =SUM(F25:F26) -> 6 | G27: =SUM(G25:G26) -> 6 | H27: =SUM(H25:H26) -> 0 | I27: =SUM(I25:I26) -> 0 | J27: =SUM(J25:J26) -> 1 | K27: =SUM(K25:K26) -> 6 | L27: =SUM(L25:L26) -> 7 | ... R27: =SUM(R25:R26) -> 1 | S27: =SUM(E27:R27) -> 40
B28: 4. | C28: Jumlah Pengguna Hak Pilih (B.1+B.2+B.3) | D28: LK | E28: =SUM(E19,E22,E25) -> 69 | F28: =SUM(F19,F22,F25) -> 65 | G28: =SUM(G19,G22,G25) -> 76 | H28: =SUM(H19,H22,H25) -> 118 | I28: =SUM(I19,I22,I25) -> 85 | J28: =SUM(J19,J22,J25) -> 112 | K28: =SUM(K19,K22,K25) -> 93 | L28: =SUM(L19,L22,L25) -> 109 | ... R28: =SUM(R19,R22,R25) -> 90 | S28: =SUM(E28:R28) -> 1204
D29: PR | E29: =SUM(E20,E23,E26) -> 82 | F29: =SUM(F20,F23,F26) -> 68 | G29: =SUM(G20,G23,G26) -> 86 | H29: =SUM(H20,H23,H26) -> 95 | I29: =SUM(I20,I23,I26) -> 115 | J29: =SUM(J20,J23,J26) -> 87 | K29: =SUM(K20,K23,K26) -> 129 | L29: =SUM(L20,L23,L26) -> 120 | ... R29: =SUM(R20,R23,R26) -> 101 | S29: =SUM(E29:R29) -> 1328
D30: JML | E30: =SUM(E28:E29) -> 151 | F30: =SUM(F28:F29) -> 133 | G30: =SUM(G28:G29) -> 162 | H30: =SUM(H28:H29) -> 213 | I30: =SUM(I28:I29) -> 200 | J30: =SUM(J28:J29) -> 199 | K30: =SUM(K28:K29) -> 222 | L30: =SUM(L28:L29) -> 229 | ... R30: =SUM(R28:R29) -> 191 | S30: =SUM(E30:R30) -> 2532
A32: II | B32: DATA PENGGUNAAN SURAT SUARA
A33: 1 | B33: Jumlah surat suara yang diterima, termasuk surat suara cadangan 2,5% dari DPT | E33: 208 | F33: 176 | G33: 226 | H33: 281 | I33: 281 | J33: 276 | K33: 301 | L33: 299 | M33: 257 | N33: 211 | O33: 150 | P33: 269 | Q33: 283 | R33: 280 | S33: =SUM(E33:R33) -> 3498
A34: 2 | B34: Jumlah surat suara yang digunakan | E34: 151 | F34: 133 | G34: 162 | H34: 213 | I34: 200 | J34: 199 | K34: 222 | L34: 229 | M34: 167 | N34: 148 | O34: 106 | P34: 198 | Q34: 213 | R34: 191 | S34: =SUM(E34:R34) -> 2532
A35: 3 | B35: Jumlah surat suara dikembalikan oleh pemilih (karena rusak atau keliru coblos) | E35: 0 | F35: 0 | G35: 1 | H35: 1 | I35: 4 | J35: 3 | K35: 0 | L35: 1 | M35: 0 | N35: 0 | O35: 0 | P35: 0 | Q35: 0 | R35: 0 | S35: =SUM(E35:R35) -> 10
A36: 4 | B36: Jumlah surat suara yang tidak digunakan/tidak terpakai, termasuk sisa surat suara cadangan | E36: =E33-(E34+E35) -> 57 | F36: =F33-(F34+F35) -> 43 | G36: =G33-(G34+G35) -> 63 | H36: =H33-(H34+H35) -> 67 | I36: =I33-(I34+I35) -> 77 | J36: =J33-(J34+J35) -> 74 | K36: =K33-(K34+K35) -> 79 | L36: =L33-(L34+L35) -> 69 | ... R36: =R33-(R34+R35) -> 89 | S36: =SUM(E36:R36) -> 956
A38: III | B38: DATA PEMILIH DISABILITAS
B39: Jumlah seluruh Pemilih disabilitas yang menggunakan hak pilih | D39: LK | E39: 0 | F39: 0 | G39: 0 | H39: 0 | I39: 0 | J39: 0 | K39: 2 | L39: 0 | M39: 0 | N39: 1 | O39: 0 | P39: 0 | Q39: 0 | R39: 0 | S39: =SUM(E39:R39) -> 3
D40: PR | E40: 0 | F40: 0 | G40: 1 | H40: 0 | I40: 0 | J40: 0 | K40: 0 | L40: 0 | M40: 0 | N40: 0 | O40: 0 | P40: 0 | Q40: 0 | R40: 0 | S40: =SUM(E40:R40) -> 1
D41: JML | E41: =SUM(E39:E40) -> 0 | F41: =SUM(F39:F40) -> 0 | G41: =SUM(G39:G40) -> 1 | H41: =SUM(H39:H40) -> 0 | I41: =SUM(I39:I40) -> 0 | J41: =SUM(J39:J40) -> 0 | K41: =SUM(K39:K40) -> 2 | L41: =SUM(L39:L40) -> 0 | ... R41: =SUM(R39:R40) -> 0 | S41: =SUM(E41:R41) -> 4
A43: IV | B43: DATA RINCIAN PEROLEHAN SUARA PASANGAN CALON PRESIDEN DAN WAKIL PRESIDEN
A44: NOMOR DAN NAMA CALON
B45: 1 | C45: H. ANIES RASYID BASWEDAN, Ph.D. - Dr. (H.C.) H. A. MUHAIMIN ISKANDAR | E45: 43 | F45: 61 | G45: 24 | H45: 21 | I45: 27 | J45: 30 | K45: 13 | L45: 21 | M45: 16 | N45: 14 | O45: 10 | P45: 9 | Q45: 14 | R45: 21 | S45: =SUM(E45:R45) -> 324
B46: 2 | C46: H. PRABOWO SUBIANTO - GIBRAN RAKABUMING RAKA | E46: 80 | F46: 64 | G46: 105 | H46: 135 | I46: 138 | J46: 124 | K46: 143 | L46: 172 | M46: 125 | N46: 94 | O46: 73 | P46: 144 | Q46: 148 | R46: 117 | S46: =SUM(E46:R46) -> 1662
B47: 3 | C47: H. GANJAR PRANOWO, S.H., M.I.P. - Prof. Dr. H. M. MAHFUD MD | E47: 25 | F47: 7 | G47: 31 | H47: 55 | I47: 33 | J47: 45 | K47: 58 | L47: 30 | M47: 21 | N47: 32 | O47: 18 | P47: 37 | Q47: 49 | R47: 44 | S47: =SUM(E47:R47) -> 485
A49: V | B49: DATA SUARA SAH DAN TIDAK SAH
B50: A. | C50: JUMLAH SELURUH SUARA SAH | E50: =SUM(E45:E47) -> 148 | F50: =SUM(F45:F47) -> 132 | G50: =SUM(G45:G47) -> 160 | H50: =SUM(H45:H47) -> 211 | I50: =SUM(I45:I47) -> 198 | J50: =SUM(J45:J47) -> 199 | K50: =SUM(K45:K47) -> 214 | L50: =SUM(L45:L47) -> 223 | ... R50: =SUM(R45:R47) -> 182 | S50: =SUM(E50:R50) -> 2471
B51: B. | C51: JUMLAH SUARA TIDAK SAH | E51: 3 | F51: 1 | G51: 2 | H51: 2 | I51: 2 | J51: 0 | K51: 8 | L51: 6 | M51: 5 | N51: 8 | O51: 5 | P51: 8 | Q51: 2 | R51: 9 | S51: =SUM(E51:R51) -> 61
B52: C. | C52: JUMLAH SELURUH SUARA SAH DAN SUARA TIDAK SAH (V.A + V.B) | E52: =SUM(E50:E51) -> 151 | F52: =SUM(F50:F51) -> 133 | G52: =SUM(G50:G51) -> 162 | H52: =SUM(H50:H51) -> 213 | I52: =SUM(I50:I51) -> 200 | J52: =SUM(J50:J51) -> 199 | K52: =SUM(K50:K51) -> 222 | L52: =SUM(L50:L51) -> 229 | ... R52: =SUM(R50:R51) -> 191 | S52: =SUM(E52:R52) -> 2532

Sheet KERTOSARI
C2: Kecamatan | D2: BANYUWANGI
C3: Kabupaten | D3: BANYUWANGI
C4: Provinsi | D4: JAWA TIMUR
C9: Kelurahan | D9: KERTOSARI
A12: I | B12: DATA PEMILIH DAN PENGGUNAAN HAK PILIH | AB12: JUMLAH AKHIR
A13: A | B13: DATA PEMILIH | E13: TPS 001 | F13: TPS 002 | G13: TPS 003 | H13: TPS 004 | I13: TPS 005 | J13: TPS 006 | K13: TPS 007 | L13: TPS 008 | M13: TPS 009 | N13: TPS 010 | O13: TPS 011 | P13: TPS 012 | Q13: TPS 013 | R13: TPS 014 | S13: TPS 015 | T13: TPS 016 | U13: TPS 017 | V13: TPS 018 | W13: TPS 019 | X13: TPS 020 | Y13: TPS 021 | Z13: TPS 022 | AA13: TPS 023
B14: Jumlah Pemilih dalam Daftar Pemilih Tetap (DPT) | D14: LK | E14: 135 | F14: 141 | G14: 138 | H14: 132 | I14: 126 | J14: 129 | K14: 113 | L14: 146 | M14: 142 | N14: 130 | O14: 120 | P14: 129 | Q14: 140 | R14: 142 | S14: 142 | T14: 142 | U14: 144 | V14: 125 | W14: 141 | X14: 135 | Y14: 138 | Z14: 130 | AA14: 101 | AB14: =SUM(E14:AA14) -> 3061
D15: PR | E15: 146 | F15: 143 | G15: 145 | H15: 150 | I15: 142 | J15: 132 | K15: 117 | L15: 132 | M15: 136 | N15: 137 | O15: 134 | P15: 138 | Q15: 140 | R15: 148 | S15: 146 | T15: 144 | U15: 134 | V15: 115 | W15: 142 | X15: 124 | Y15: 136 | Z15: 140 | AA15: 106 | AB15: =SUM(E15:AA15) -> 3127
D16: JML | E16: =SUM(E14:E15) -> 281 | F16: =SUM(F14:F15) -> 284 | G16: =SUM(G14:G15) -> 283 | H16: =SUM(H14:H15) -> 282 | I16: =SUM(I14:I15) -> 268 | J16: =SUM(J14:J15) -> 261 | K16: =SUM(K14:K15) -> 230 | L16: =SUM(L14:L15) -> 278 | ... AA16: =SUM(AA14:AA15) -> 207 | AB16: =SUM(E16:AA16) -> 6188
A18: B | B18: PENGGUNA HAK PILIH
B19: 1. | C19: Jumlah pengguna hak pilih dalam Daftar Pemilih Tetap (DPT) | D19: LK | E19: 95 | F19: 118 | G19: 103 | H19: 100 | I19: 97 | J19: 96 | K19: 90 | L19: 86 | M19: 85 | N19: 98 | O19: 80 | P19: 79 | Q19: 96 | R19: 105 | S19: 97 | T19: 97 | U19: 99 | V19: 105 | W19: 97 | X19: 91 | Y19: 95 | Z19: 94 | AA19: 67 | AB19: =SUM(E19:AA19) -> 2170
D20: PR | E20: 117 | F20: 122 | G20: 106 | H20: 122 | I20: 114 | J20: 113 | K20: 93 | L20: 124 | M20: 96 | N20: 102 | O20: 98 | P20: 108 | Q20: 114 | R20: 122 | S20: 116 | T20: 108 | U20: 98 | V20: 96 | W20: 117 | X20: 96 | Y20: 106 | Z20: 103 | AA20: 80 | AB20: =SUM(E20:AA20) -> 2471
D21: JML | E21: =SUM(E19:E20) -> 212 | F21: =SUM(F19:F20) -> 240 | G21: =SUM(G19:G20) -> 209 | H21: =SUM(H19:H20) -> 222 | I21: =SUM(I19:I20) -> 211 | J21: =SUM(J19:J20) -> 209 | K21: =SUM(K19:K20) -> 183 | L21: =SUM(L19:L20) -> 210 | ... AA21: =SUM(AA19:AA20) -> 147 | AB21: =SUM(E21:AA21) -> 4641
B22: 2. | C22: Jumlah pengguna hak pilih dalam Daftar Pemilih Tambahan (DPTb) | D22: LK | E22: 0 | F22: 0 | G22: 0 | H22: 0 | I22: 0 | J22: 0 | K22: 0 | L22: 1 | M22: 2 | N22: 0 | O22: 0 | P22: 3 | Q22: 0 | R22: 1 | S22: 1 | T22: 0 | U22: 0 | V22: 1 | W22: 0 | X22: 0 | Y22: 0 | Z22: 0 | AA22: 0 | AB22: =SUM(E22:AA22) -> 9
D23: PR | E23: 0 | F23: 0 | G23: 0 | H23: 0 | I23: 2 | J23: 0 | K23: 0 | L23: 0 | M23: 6 | N23: 0 | O23: 0 | P23: 2 | Q23: 0 | R23: 0 | S23: 1 | T23: 0 | U23: 0 | V23: 1 | W23: 0 | X23: 0 | Y23: 0 | Z23: 0 | AA23: 0 | AB23: =SUM(E23:AA23) -> 12
D24: JML | E24: =SUM(E22:E23) -> 0 | F24: =SUM(F22:F23) -> 0 | G24: =SUM(G22:G23) -> 0 | H24: =SUM(H22:H23) -> 0 | I24: =SUM(I22:I23) -> 2 | J24: =SUM(J22:J23) -> 0 | K24: =SUM(K22:K23) -> 0 | L24: =SUM(L22:L23) -> 1 | ... AA24: =SUM(AA22:AA23) -> 0 | AB24: =SUM(E24:AA24) -> 21
B25: 3. | C25: Jumlah pengguna hak pilih dalam Daftar Pemilih Khusus (DPK) | D25: LK | E25: 1 | F25: 0 | G25: 0 | H25: 1 | I25: 1 | J25: 3 | K25: 0 | L25: 1 | M25: 0 | N25: 2 | O25: 6 | P25: 0 | Q25: 0 | R25: 7 | S25: 1 | T25: 1 | U25: 3 | V25: 3 | W25: 0 | X25: 3 | Y25: 0 | Z25: 4 | AA25: 0 | AB25: =SUM(E25:AA25) -> 37
D26: PR | E26: 0 | F26: 1 | G26: 1 | H26: 1 | I26: 0 | J26: 3 | K26: 0 | L26: 2 | M26: 0 | N26: 2 | O26: 3 | P26: 0 | Q26: 0 | R26: 6 | S26: 3 | T26: 1 | U26: 4 | V26: 6 | W26: 0 | X26: 2 | Y26: 0 | Z26: 5 | AA26: 1 | AB26: =SUM(E26:AA26) -> 41
D27: JML | E27: =SUM(E25:E26) -> 1 | F27: =SUM(F25:F26) -> 1 | G27: =SUM(G25:G26) -> 1 | H27: =SUM(H25:H26) -> 2 | I27: =SUM(I25:I26) -> 1 | J27: =SUM(J25:J26) -> 6 | K27: =SUM(K25:K26) -> 0 | L27: =SUM(L25:L26) -> 3 | ... AA27: =SUM(AA25:AA26) -> 1 | AB27: =SUM(E27:AA27) -> 78
B28: 4. | C28: Jumlah Pengguna Hak Pilih (B.1+B.2+B.3) | D28: LK | E28: =SUM(E19,E22,E25) -> 96 | F28: =SUM(F19,F22,F25) -> 118 | G28: =SUM(G19,G22,G25) -> 103 | H28: =SUM(H19,H22,H25) -> 101 | I28: =SUM(I19,I22,I25) -> 98 | J28: =SUM(J19,J22,J25) -> 99 | K28: =SUM(K19,K22,K25) -> 90 | L28: =SUM(L19,L22,L25) -> 88 | ... AA28: =SUM(AA19,AA22,AA25) -> 67 | AB28: =SUM(E28:AA28) -> 2216
D29: PR | E29: =SUM(E20,E23,E26) -> 117 | F29: =SUM(F20,F23,F26) -> 123 | G29: =SUM(G20,G23,G26) -> 107 | H29: =SUM(H20,H23,H26) -> 123 | I29: =SUM(I20,I23,I26) -> 116 | J29: =SUM(J20,J23,J26) -> 116 | K29: =SUM(K20,K23,K26) -> 93 | L29: =SUM(L20,L23,L26) -> 126 | ... AA29: =SUM(AA20,AA23,AA26) -> 81 | AB29: =SUM(E29:AA29) -> 2524
D30: JML | E30: =SUM(E28:E29) -> 213 | F30: =SUM(F28:F29) -> 241 | G30: =SUM(G28:G29) -> 210 | H30: =SUM(H28:H29) -> 224 | I30: =SUM(I28:I29) -> 214 | J30: =SUM(J28:J29) -> 215 | K30: =SUM(K28:K29) -> 183 | L30: =SUM(L28:L29) -> 214 | ... AA30: =SUM(AA28:AA29) -> 148 | AB30: =SUM(E30:AA30) -> 4740
A32: II | B32: DATA PENGGUNAAN SURAT SUARA
A33: 1 | B33: Jumlah surat suara yang diterima, termasuk surat suara cadangan 2,5% dari DPT | E33: 293 | F33: 290 | G33: 289 | H33: 288 | I33: 274 | J33: 267 | K33: 235 | L33: 284 | M33: 284 | N33: 273 | O33: 259 | P33: 273 | Q33: 286 | R33: 297 | S33: 296 | T33: 292 | U33: 286 | V33: 245 | W33: 293 | X33: 265 | Y33: 281 | Z33: 276 | AA33: 212 | AB33: =SUM(E33:AA33) -> 6338
A34: 2 | B34: Jumlah surat suara yang digunakan | E34: 213 | F34: 241 | G34: 210 | H34: 224 | I34: 214 | J34: 215 | K34: 183 | L34: 214 | M34: 189 | N34: 204 | O34: 187 | P34: 192 | Q34: 210 | R34: 241 | S34: 219 | T34: 207 | U34: 204 | V34: 212 | W34: 214 | X34: 192 | Y34: 201 | Z34: 206 | AA34: 148 | AB34: =SUM(E34:AA34) -> 4740
A35: 3 | B35: Jumlah surat suara dikembalikan oleh pemilih (karena rusak atau keliru coblos) | E35: 0 | F35: 0 | G35: 0 | H35: 0 | I35: 0 | J35: 0 | K35: 0 | L35: 1 | M35: 1 | N35: 0 | O35: 1 | P35: 1 | Q35: 0 | R35: 0 | S35: 0 | T35: 0 | U35: 0 | V35: 1 | W35: 0 | X35: 1 | Y35: 0 | Z35: 0 | AA35: 1 | AB35: =SUM(E35:AA35) -> 7
A36: 4 | B36: Jumlah surat suara yang tidak digunakan/tidak terpakai, termasuk sisa surat suara cadangan | E36: =E33-(E34+E35) -> 80 | F36: =F33-(F34+F35) -> 49 | G36: =G33-(G34+G35) -> 79 | H36: =H33-(H34+H35) -> 64 | I36: =I33-(I34+I35) -> 60 | J36: =J33-(J34+J35) -> 52 | K36: =K33-(K34+K35) -> 52 | L36: =L33-(L34+L35) -> 69 | ... AA36: =AA33-(AA34+AA35) -> 63 | AB36: =SUM(E36:AA36) -> 1591
A38: III | B38: DATA PEMILIH DISABILITAS
B39: Jumlah seluruh Pemilih disabilitas yang menggunakan hak pilih | D39: LK | E39: 0 | F39: 0 | G39: 0 | H39: 0 | I39: 0 | J39: 0 | K39: 0 | L39: 0 | M39: 0 | N39: 0 | O39: 0 | P39: 0 | Q39: 1 | R39: 0 | S39: 0 | T39: 0 | U39: 0 | V39: 2 | W39: 0 | X39: 0 | Y39: 0 | Z39: 0 | AA39: 0 | AB39: =SUM(E39:AA39) -> 3
D40: PR | E40: 0 | F40: 0 | G40: 0 | H40: 0 | I40: 0 | J40: 0 | K40: 0 | L40: 0 | M40: 0 | N40: 0 | O40: 0 | P40: 0 | Q40: 0 | R40: 0 | S40: 0 | T40: 0 | U40: 0 | V40: 1 | W40: 0 | X40: 0 | Y40: 0 | Z40: 0 | AA40: 0 | AB40: =SUM(E40:AA40) -> 1
D41: JML | E41: =SUM(E39:E40) -> 0 | F41: =SUM(F39:F40) -> 0 | G41: =SUM(G39:G40) -> 0 | H41: =SUM(H39:H40) -> 0 | I41: =SUM(I39:I40) -> 0 | J41: =SUM(J39:J40) -> 0 | K41: =SUM(K39:K40) -> 0 | L41: =SUM(L39:L40) -> 0 | ... AA41: =SUM(AA39:AA40) -> 0 | AB41: =SUM(E41:AA41) -> 4
A43: IV | B43: DATA RINCIAN PEROLEHAN SUARA PASANGAN CALON PRESIDEN DAN WAKIL BUPATI
A44: NOMOR DAN NAMA CALON
B45: 1 | C45: H. ANIES RASYID BASWEDAN, Ph.D. - Dr. (H.C.) H. A. MUHAIMIN ISKANDAR | E45: 23 | F45: 11 | G45: 24 | H45: 26 | I45: 28 | J45: 25 | K45: 16 | L45: 30 | M45: 34 | N45: 39 | O45: 33 | P45: 42 | Q45: 36 | R45: 29 | S45: 33 | T45: 18 | U45: 20 | V45: 26 | W45: 15 | X45: 22 | Y45: 22 | Z45: 20 | AA45: 3 | AB45: =SUM(E45:AA45) -> 575
B46: 2 | C46: H. PRABOWO SUBIANTO - GIBRAN RAKABUMING RAKA | E46: 141 | F46: 193 | G46: 148 | H46: 168 | I46: 147 | J46: 163 | K46: 140 | L46: 138 | M46: 121 | N46: 137 | O46: 133 | P46: 126 | Q46: 130 | R46: 180 | S46: 154 | T46: 171 | U46: 155 | V46: 150 | W46: 177 | X46: 143 | Y46: 155 | Z46: 174 | AA46: 116 | AB46: =SUM(E46:AA46) -> 3460
B47: 3 | C47: H. GANJAR PRANOWO, S.H., M.I.P. - Prof. Dr. H. M. MAHFUD MD | E47: 46 | F47: 29 | G47: 30 | H47: 29 | I47: 31 | J47: 22 | K47: 21 | L47: 42 | M47: 28 | N47: 26 | O47: 21 | P47: 21 | Q47: 35 | R47: 27 | S47: 27 | T47: 14 | U47: 25 | V47: 34 | W47: 17 | X47: 23 | Y47: 17 | Z47: 7 | AA47: 24 | AB47: =SUM(E47:AA47) -> 596
A49: V | B49: DATA SUARA SAH DAN TIDAK SAH
B50: A. | C50: JUMLAH SELURUH SUARA SAH | E50: =SUM(E45:E47) -> 210 | F50: =SUM(F45:F47) -> 233 | G50: =SUM(G45:G47) -> 202 | H50: =SUM(H45:H47) -> 223 | I50: =SUM(I45:I47) -> 206 | J50: =SUM(J45:J47) -> 210 | K50: =SUM(K45:K47) -> 177 | L50: =SUM(L45:L47) -> 210 | ... AA50: =SUM(AA45:AA47) -> 143 | AB50: =SUM(E50:AA50) -> 4631
