Workbook

Sheet PPWP
C8: Kecamatan | D8: SINGOJURUH
C9: Kabupaten | D9: BANYUWANGI
C10: Provinsi | D10: JAWA TIMUR
A12: I | B12: DATA PEMILIH DAN PENGGUNAAN HAK PILIH | E12: JUMLAH AKHIR
A13: A | B13: DATA PEMILIH
B14: Jumlah Pemilih dalam Daftar Pemilih Tetap (DPT) | D14: LK | E14: =ALASMALANG!V14+'BENELAN KIDUL'!S14+CANTUK!T14+GAMBOR!N14+GUMIRIH!S14+KEMIRI!U14+LEMAHBANGKULON!Q14+PADANG!Q14+SINGOJURUH!AC14+SINGOLATREN!T14+SUMBERBARU!S14 -> 19829
D15: PR | E15: =ALASMALANG!V15+'BENELAN KIDUL'!S15+CANTUK!T15+GAMBOR!N15+GUMIRIH!S15+KEMIRI!U15+LEMAHBANGKULON!Q15+PADANG!Q15+SINGOJURUH!AC15+SINGOLATREN!T15+SUMBERBARU!S15 -> 20143
D16: JML | E16: =SUM(E14:E15) -> 39972
A18: B | B18: PENGGUNA HAK PILIH
B19: 1. | C19: Jumlah pengguna hak pilih dalam Daftar Pemilih Tetap (DPT) | D19: LK | E19: =ALASMALANG!V19+'BENELAN KIDUL'!S19+CANTUK!T19+GAMBOR!N19+GUMIRIH!S19+KEMIRI!U19+LEMAHBANGKULON!Q19+PADANG!Q19+SINGOJURUH!AC19+SINGOLATREN!T19+SUMBERBARU!S19 -> 14837
D20: PR | E20: =ALASMALANG!V20+'BENELAN KIDUL'!S20+CANTUK!T20+GAMBOR!N20+GUMIRIH!S20+KEMIRI!U20+LEMAHBANGKULON!Q20+PADANG!Q20+SINGOJURUH!AC20+SINGOLATREN!T20+SUMBERBARU!S20 -> 16054
D21: JML | E21: =SUM(E19:E20) -> 30891
B22: 2. | C22: Jumlah pengguna hak pilih dalam Daftar Pemilih Tambahan (DPTb) | D22: LK | E22: =ALASMALANG!V22+'BENELAN KIDUL'!S22+CANTUK!T22+GAMBOR!N22+GUMIRIH!S22+KEMIRI!U22+LEMAHBANGKULON!Q22+PADANG!Q22+SINGOJURUH!AC22+SINGOLATREN!T22+SUMBERBARU!S22 -> 55
D23: PR | E23: =ALASMALANG!V23+'BENELAN KIDUL'!S23+CANTUK!T23+GAMBOR!N23+GUMIRIH!S23+KEMIRI!U23+LEMAHBANGKULON!Q23+PADANG!Q23+SINGOJURUH!AC23+SINGOLATREN!T23+SUMBERBARU!S23 -> 54
D24: JML | E24: =SUM(E22:E23) -> 109
B25: 3. | C25: Jumlah pengguna hak pilih dalam Daftar Pemilih Khusus (DPK) | D25: LK | E25: =ALASMALANG!V25+'BENELAN KIDUL'!S25+CANTUK!T25+GAMBOR!N25+GUMIRIH!S25+KEMIRI!U25+LEMAHBANGKULON!Q25+PADANG!Q25+SINGOJURUH!AC25+SINGOLATREN!T25+SUMBERBARU!S25 -> 142
D26: PR | E26: =ALASMALANG!V26+'BENELAN KIDUL'!S26+CANTUK!T26+GAMBOR!N26+GUMIRIH!S26+KEMIRI!U26+LEMAHBANGKULON!Q26+PADANG!Q26+SINGOJURUH!AC26+SINGOLATREN!T26+SUMBERBARU!S26 -> 171
D27: JML | E27: =SUM(E25:E26) -> 313
B28: 4. | C28: Jumlah Pengguna Hak Pilih (B.1+B.2+B.3) | D28: LK | E28: =E19+E22+E25 -> 15034
D29: PR | E29: =E20+E23+E26 -> 16279
D30: JML | E30: =SUM(E28:E29) -> 31313
A32: II | B32: DATA PENGGUNAAN SURAT SUARA
A33: 1 | B33: Jumlah surat suara yang diterima, termasuk surat suara cadangan 2,5% dari DPT | E33: =ALASMALANG!V33+'BENELAN KIDUL'!S33+CANTUK!T33+GAMBOR!N33+GUMIRIH!S33+KEMIRI!U33+LEMAHBANGKULON!Q33+PADANG!Q33+SINGOJURUH!AC33+SINGOLATREN!T33+SUMBERBARU!S33 -> 39691
A34: 2 | B34: Jumlah surat suara yang digunakan | E34: =ALASMALANG!V34+'BENELAN KIDUL'!S34+CANTUK!T34+GAMBOR!N34+GUMIRIH!S34+KEMIRI!U34+LEMAHBANGKULON!Q34+PADANG!Q34+SINGOJURUH!AC34+SINGOLATREN!T34+SUMBERBARU!S34 -> 31276
A35: 3 | B35: Jumlah surat suara dikembalikan oleh pemilih (karena rusak atau keliru coblos) | E35: =ALASMALANG!V35+'BENELAN KIDUL'!S35+CANTUK!T35+GAMBOR!N35+GUMIRIH!S35+KEMIRI!U35+LEMAHBANGKULON!Q35+PADANG!Q35+SINGOJURUH!AC35+SINGOLATREN!T35+SUMBERBARU!S35 -> 94
A36: 4 | B36: Jumlah surat suara yang tidak digunakan/tidak terpakai, termasuk sisa surat suara cadangan | E36: =E33-(E34+E35) -> 8321
A38: III | B38: DATA PEMILIH DISABILITAS
B39: Jumlah seluruh Pemilih disabilitas yang menggunakan hak pilih | D39: LK | E39: =ALASMALANG!V39+'BENELAN KIDUL'!S39+CANTUK!T39+GAMBOR!N39+GUMIRIH!S39+KEMIRI!U39+LEMAHBANGKULON!Q39+PADANG!Q39+SINGOJURUH!AC39+SINGOLATREN!T39+SUMBERBARU!S39 -> 33
D40: PR | E40: =ALASMALANG!V40+'BENELAN KIDUL'!S40+CANTUK!T40+GAMBOR!N40+GUMIRIH!S40+KEMIRI!U40+LEMAHBANGKULON!Q40+PADANG!Q40+SINGOJURUH!AC40+SINGOLATREN!T40+SUMBERBARU!S40 -> 55
D41: JML | E41: =SUM(E39:E40) -> 88
A43: IV | B43: DATA RINCIAN PEROLEHAN SUARA PASANGAN CALON BUPATI DAN WAKIL BUPATI
A44: NOMOR DAN NAMA CALON
B45: 1 | C45: H. ANIES RASYID BASWEDAN, Ph.D. - Dr. (H.C.) H. A. MUHAIMIN ISKANDAR | E45: =ALASMALANG!V45+'BENELAN KIDUL'!S45+CANTUK!T45+GAMBOR!N45+GUMIRIH!S45+KEMIRI!U45+LEMAHBANGKULON!Q45+PADANG!Q45+SINGOJURUH!AC45+SINGOLATREN!T45+SUMBERBARU!S45 -> 2722
B46: 2 | C46: H. PRABOWO SUBIANTO - GIBRAN RAKABUMING RAKA | E46: =ALASMALANG!V46+'BENELAN KIDUL'!S46+CANTUK!T46+GAMBOR!N46+GUMIRIH!S46+KEMIRI!U46+LEMAHBANGKULON!Q46+PADANG!Q46+SINGOJURUH!AC46+SINGOLATREN!T46+SUMBERBARU!S46 -> 22888
B47: 3 | C47: H. GANJAR PRANOWO, S.H., M.I.P. - Prof. Dr. H. M. MAHFUD MD | E47: =ALASMALANG!V47+'BENELAN KIDUL'!S47+CANTUK!T47+GAMBOR!N47+GUMIRIH!S47+KEMIRI!U47+LEMAHBANGKULON!Q47+PADANG!Q47+SINGOJURUH!AC47+SINGOLATREN!T47+SUMBERBARU!S47 -> 4817
A49: V | B49: DATA SUARA SAH DAN TIDAK SAH
B50: A. | C50: JUMLAH SELURUH SUARA SAH | E50: =ALASMALANG!V50+'BENELAN KIDUL'!S50+CANTUK!T50+GAMBOR!N50+GUMIRIH!S50+KEMIRI!U50+LEMAHBANGKULON!Q50+PADANG!Q50+SINGOJURUH!AC50+SINGOLATREN!T50+SUMBERBARU!S50 -> 30427
B51: B. | C51: JUMLAH SUARA TIDAK SAH | E51: =ALASMALANG!V51+'BENELAN KIDUL'!S51+CANTUK!T51+GAMBOR!N51+GUMIRIH!S51+KEMIRI!U51+LEMAHBANGKULON!Q51+PADANG!Q51+SINGOJURUH!AC51+SINGOLATREN!T51+SUMBERBARU!S51 -> 640
B52: C. | C52: JUMLAH SELURUH SUARA SAH DAN SUARA TIDAK SAH (V.A + V.B) | E52: =SUM(E50:E51) -> 31067

Sheet ALASMALANG
C2: Kecamatan | D2: SINGOJURUH
C3: Kabupaten | D3: BANYUWANGI
C4: Provinsi | D4: JAWA TIMUR
C9: Kelurahan | D9: ALASMALANG
A12: I | B12: DATA PEMILIH DAN PENGGUNAAN HAK PILIH | V12: JUMLAH AKHIR
A13: A | B13: DATA PEMILIH | E13: TPS 001 | F13: TPS 002 | G13: TPS 003 | H13: TPS 004 | I13: TPS 005 | J13: TPS 006 | K13: TPS 007 | L13: TPS 008 | M13: TPS 009 | N13: TPS 010 | O13: TPS 011 | P13: TPS 012 | Q13: TPS 013 | R13: TPS 014 | S13: TPS 015 | T13: TPS 016 | U13: TPS 017
B14: Jumlah Pemilih dalam Daftar Pemilih Tetap (DPT) | D14: LK | E14: 124 | F14: 110 | G14: 95 | H14: 116 | I14: 101 | J14: 88 | K14: 79 | L14: 121 | M14: 101 | N14: 107 | O14: 99 | P14: 103 | Q14: 128 | R14: 83 | S14: 104 | T14: 93 | U14: 127 | V14: =SUM(E14:U14) -> 1779
D15: PR | E15: 128 | F15: 102 | G15: 92 | H15: 125 | I15: 117 | J15: 94 | K15: 93 | L15: 124 | M15: 94 | N15: 117 | O15: 90 | P15: 108 | Q15: 126 | R15: 85 | S15: 113 | T15: 113 | U15: 110 | V15: =SUM(E15:U15) -> 1831
D16: JML | E16: =SUM(E14:E15) -> 252 | F16: =SUM(F14:F15) -> 212 | G16: =SUM(G14:G15) -> 187 | H16: =SUM(H14:H15) -> 241 | I16: =SUM(I14:I15) -> 218 | J16: =SUM(J14:J15) -> 182 | K16: =SUM(K14:K15) -> 172 | L16: =SUM(L14:L15) -> 245 | ... U16: =SUM(U14:U15) -> 237 | V16: =SUM(E16:U16) -> 3610
A18: B | B18: PENGGUNA HAK PILIH
B19: 1. | C19: Jumlah pengguna hak pilih dalam Daftar Pemilih Tetap (DPT) | D19: LK | E19: 114 | F19: 90 | G19: 71 | H19: 89 | I19: 80 | J19: 65 | K19: 63 | L19: 92 | M19: 82 | N19: 86 | O19: 81 | P19: 83 | Q19: 81 | R19: 66 | S19: 81 | T19: 82 | U19: 107 | V19: =SUM(E19:U19) -> 1413
D20: PR | E20: 94 | F20: 90 | G20: 81 | H20: 95 | I20: 102 | J20: 77 | K20: 74 | L20: 100 | M20: 79 | N20: 95 | O20: 74 | P20: 86 | Q20: 96 | R20: 74 | S20: 95 | T20: 102 | U20: 104 | V20: =SUM(E20:U20) -> 1518
D21: JML | E21: =SUM(E19:E20) -> 208 | F21: =SUM(F19:F20) -> 180 | G21: =SUM(G19:G20) -> 152 | H21: =SUM(H19:H20) -> 184 | I21: =SUM(I19:I20) -> 182 | J21: =SUM(J19:J20) -> 142 | K21: =SUM(K19:K20) -> 137 | L21: =SUM(L19:L20) -> 192 | ... U21: =SUM(U19:U20) -> 211 | V21: =SUM(E21:U21) -> 2931
B22: 2. | C22: Jumlah pengguna hak pilih dalam Daftar Pemilih Tambahan (DPTb) | D22: LK | V22: =SUM(E22:U22) -> 0
D23: PR | U23: 1 | V23: =SUM(E23:U23) -> 1
D24: JML | E24: =SUM(E22:E23) -> 0 | F24: =SUM(F22:F23) -> 0 | G24: =SUM(G22:G23) -> 0 | H24: =SUM(H22:H23) -> 0 | I24: =SUM(I22:I23) -> 0 | J24: =SUM(J22:J23) -> 0 | K24: =SUM(K22:K23) -> 0 | L24: =SUM(L22:L23) -> 0 | ... U24: =SUM(U22:U23) -> 1 | V24: =SUM(E24:U24) -> 1
B25: 3. | C25: Jumlah pengguna hak pilih dalam Daftar Pemilih Khusus (DPK) | D25: LK | E25: 5 | F25: 6 | G25: 1 | H25: 0 | I25: 0 | J25: 1 | K25: 0 | L25: 1 | M25: 0 | N25: 4 | O25: 1 | P25: 2 | Q25: 3 | R25: 0 | S25: 3 | T25: 2 | V25: =SUM(E25:U25) -> 29
D26: PR | E26: 3 | F26: 6 | G26: 2 | H26: 0 | I26: 0 | J26: 2 | K26: 0 | L26: 2 | M26: 0 | N26: 1 | O26: 1 | P26: 1 | Q26: 1 | R26: 1 | S26: 1 | T26: 3 | V26: =SUM(E26:U26) -> 24
D27: JML | E27: =SUM(E25:E26) -> 8 | F27: =SUM(F25:F26) -> 12 | G27: =SUM(G25:G26) -> 3 | H27: =SUM(H25:H26) -> 0 | I27: =SUM(I25:I26) -> 0 | J27: =SUM(J25:J26) -> 3 | K27: =SUM(K25:K26) -> 0 | L27: =SUM(L25:L26) -> 3 | ... U27: =SUM(U25:U26) -> 0 | V27: =SUM(E27:U27) -> 53
B28: 4. | C28: Jumlah Pengguna Hak Pilih (B.1+B.2+B.3) | D28: LK | E28: =SUM(E19,E22,E25) -> 119 | F28: =SUM(F19,F22,F25) -> 96 | G28: =SUM(G19,G22,G25) -> 72 | H28: =SUM(H19,H22,H25) -> 89 | I28: =SUM(I19,I22,I25) -> 80 | J28: =SUM(J19,J22,J25) -> 66 | K28: =SUM(K19,K22,K25) -> 63 | L28: =SUM(L19,L22,L25) -> 93 | ... U28: =SUM(U19,U22,U25) -> 107 | V28: =SUM(E28:U28) -> 1442
D29: PR | E29: =SUM(E20,E23,E26) -> 97 | F29: =SUM(F20,F23,F26) -> 96 | G29: =SUM(G20,G23,G26) -> 83 | H29: =SUM(H20,H23,H26) -> 95 | I29: =SUM(I20,I23,I26) -> 102 | J29: =SUM(J20,J23,J26) -> 79 | K29: =SUM(K20,K23,K26) -> 74 | L29: =SUM(L20,L23,L26) -> 102 | ... U29: =SUM(U20,U23,U26) -> 105 | V29: =SUM(E29:U29) -> 1543
D30: JML | E30: =SUM(E28:E29) -> 216 | F30: =SUM(F28:F29) -> 192 | G30: =SUM(G28:G29) -> 155 | H30: =SUM(H28:H29) -> 184 | I30: =SUM(I28:I29) -> 182 | J30: =SUM(J28:J29) -> 145 | K30: =SUM(K28:K29) -> 137 | L30: =SUM(L28:L29) -> 195 | ... U30: =SUM(U28:U29) -> 212 | V30: =SUM(E30:U30) -> 2985
A32: II | B32: DATA PENGGUNAAN SURAT SUARA
A33: 1 | B33: Jumlah surat suara yang diterima, termasuk surat suara cadangan 2,5% dari DPT | E33: 248 | F33: 208 | G33: 184 | H33: 238 | I33: 212 | J33: 173 | K33: 185 | L33: 240 | M33: 189 | N33: 220 | O33: 183 | P33: 208 | Q33: 254 | R33: 172 | S33: 212 | T33: 203 | U33: 233 | V33: =SUM(E33:U33) -> 3562
A34: 2 | B34: Jumlah surat suara yang digunakan | E34: 216 | F34: 192 | G34: 155 | H34: 184 | I34: 182 | J34: 145 | K34: 137 | L34: 195 | M34: 161 | N34: 186 | O34: 157 | P34: 172 | Q34: 181 | R34: 141 | S34: 180 | T34: 189 | U34: 212 | V34: =SUM(E34:U34) -> 2985
A35: 3 | B35: Jumlah surat suara dikembalikan oleh pemilih (karena rusak atau keliru coblos) | E35: 0 | F35: 0 | G35: 0 | H35: 0 | I35: 0 | J35: 0 | K35: 0 | L35: 0 | M35: 0 | N35: 0 | O35: 0 | P35: 0 | Q35: 0 | R35: 3 | S35: 0 | V35: =SUM(E35:U35) -> 3
A36: 4 | B36: Jumlah surat suara yang tidak digunakan/tidak terpakai, termasuk sisa surat suara cadangan | E36: =E33-(E34+E35) -> 32 | F36: =F33-(F34+F35) -> 16 | G36: =G33-(G34+G35) -> 29 | H36: =H33-(H34+H35) -> 54 | I36: =I33-(I34+I35) -> 30 | J36: =J33-(J34+J35) -> 28 | K36: =K33-(K34+K35) -> 48 | L36: =L33-(L34+L35) -> 45 | ... U36: =U33-(U34+U35) -> 21 | V36: =SUM(E36:U36) -> 574
A38: III | B38: DATA PEMILIH DISABILITAS
B39: Jumlah seluruh Pemilih disabilitas yang menggunakan hak pilih | D39: LK | R39: 2 | S39: 1 | V39: =SUM(E39:U39) -> 3
D40: PR | S40: 2 | V40: =SUM(E40:U40) -> 2
D41: JML | E41: =SUM(E39:E40) -> 0 | F41: =SUM(F39:F40) -> 0 | G41: =SUM(G39:G40) -> 0 | H41: =SUM(H39:H40) -> 0 | I41: =SUM(I39:I40) -> 0 | J41: =SUM(J39:J40) -> 0 | K41: =SUM(K39:K40) -> 0 | L41: =SUM(L39:L40) -> 0 | ... U41: =SUM(U39:U40) -> 0 | V41: =SUM(E41:U41) -> 5
A43: IV | B43: DATA RINCIAN PEROLEHAN SUARA PASANGAN CALON BUPATI DAN WAKIL BUPATI
A44: NOMOR DAN NAMA CALON
B45: 1 | C45: H. ANIES RASYID BASWEDAN, Ph.D. - Dr. (H.C.) H. A. MUHAIMIN ISKANDAR | E45: 14 | F45: 19 | G45: 12 | H45: 16 | I45: 13 | J45: 21 | K45: 20 | L45: 17 | M45: 13 | N45: 14 | O45: 5 | P45: 12 | Q45: 8 | R45: 10 | S45: 17 | T45: 10 | U45: 32 | V45: =SUM(E45:U45) -> 253
B46: 2 | C46: H. PRABOWO SUBIANTO - GIBRAN RAKABUMING RAKA | E46: 157 | F46: 125 | G46: 97 | H46: 130 | I46: 140 | J46: 107 | K46: 92 | L46: 128 | M46: 68 | N46: 144 | O46: 124 | P46: 134 | Q46: 132 | R46: 107 | S46: 121 | T46: 133 | U46: 156 | V46: =SUM(E46:U46) -> 2095
B47: 3 | C47: H. GANJAR PRANOWO, S.H., M.I.P. - Prof. Dr. H. M. MAHFUD MD | E47: 35 | F47: 46 | G47: 44 | H47: 42 | I47: 24 | J47: 16 | K47: 18 | L47: 49 | M47: 78 | N47: 25 | O47: 25 | P47: 34 | Q47: 41 | R47: 22 | S47: 33 | T47: 34 | U47: 14 | V47: =SUM(E47:U47) -> 580
A49: V | B49: DATA SUARA SAH DAN TIDAK SAH
B50: A. | C50: JUMLAH SELURUH SUARA SAH | E50: =SUM(E45:E47) -> 206 | F50: =SUM(F45:F47) -> 190 | G50: =SUM(G45:G47) -> 153 | H50: =SUM(H45:H47) -> 188 | I50: =SUM(I45:I47) -> 177 | J50: =SUM(J45:J47) -> 144 | K50: =SUM(K45:K47) -> 130 | L50: =SUM(L45:L47) -> 194 | ... U50: =SUM(U45:U47) -> 202 | V50: =SUM(E50:U50) -> 2928
B51: B. | C51: JUMLAH SUARA TIDAK SAH | E51: 7 | F51: 2 | G51: 2 | H51: 2 | I51: 5 | J51: 1 | K51: 1 | L51: 1 | M51: 2 | N51: 3 | O51: 3 | P51: 2 | Q51: 2 | R51: 2 | S51: 2 | T51: 8 | U51: 5 | V51: =SUM(E51:U51) -> 50
B52: C. | C52: JUMLAH SELURUH SUARA SAH DAN SUARA TIDAK SAH (V.A + V.B) | E52: =SUM(E50:E51) -> 213 | F52: =SUM(F50:F51) -> 192 | G52: =SUM(G50:G51) -> 155 | H52: =SUM(H50:H51) -> 190 | I52: =SUM(I50:I51) -> 182 | J52: =SUM(J50:J51) -> 145 | K52: =SUM(K50:K51) -> 131 | L52: =SUM(L50:L51) -> 195 | ... U52: =SUM(U50:U51) -> 207 | V52: =SUM(E52:U52) -> 2978

Sheet BENELAN KIDUL
C2: Kecamatan | D2: SINGOJURUH
C3: Kabupaten | D3: BANYUWANGI
C4: Provinsi | D4: JAWA TIMUR
C9: Kelurahan | D9: BENELAN KIDUL
A12: I | B12: DATA PEMILIH DAN PENGGUNAAN HAK PILIH | S12: JUMLAH AKHIR
A13: A | B13: DATA PEMILIH | E13: TPS 001 | F13: TPS 002 | G13: TPS 003 | H13: TPS 004 | I13: TPS 005 | J13: TPS 006 | K13: TPS 007 | L13: TPS 008 | M13: TPS 009 | N13: TPS 010 | O13: TPS 011 | P13: TPS 012 | Q13: TPS 013 | R13: TPS 014
B14: Jumlah Pemilih dalam Daftar Pemilih Tetap (DPT) | D14: LK | E14: 138 | F14: 130 | G14: 130 | H14: 146 | I14: 139 | J14: 137 | K14: 149 | L14: 133 | M14: 123 | N14: 136 | O14: 128 | P14: 107 | Q14: 127 | R14: 117 | S14: =SUM(E14:R14) -> 1840
D15: PR | E15: 126 | F15: 119 | G15: 135 | H15: 133 | I15: 129 | J15: 144 | K15: 133 | L15: 134 | M15: 115 | N15: 125 | O15: 139 | P15: 101 | Q15: 123 | R15: 112 | S15: =SUM(E15:R15) -> 1768
D16: JML | E16: =SUM(E14:E15) -> 264 | F16: =SUM(F14:F15) -> 249 | G16: =SUM(G14:G15) -> 265 | H16: =SUM(H14:H15) -> 279 | I16: =SUM(I14:I15) -> 268 | J16: =SUM(J14:J15) -> 281 | K16: =SUM(K14:K15) -> 282 | L16: =SUM(L14:L15) -> 267 | ... R16: =SUM(R14:R15) -> 229 | S16: =SUM(E16:R16) -> 3608
A18: B | B18: PENGGUNA HAK PILIH
B19: 1. | C19: Jumlah pengguna hak pilih dalam Daftar Pemilih Tetap (DPT) | D19: LK | E19: 111 | F19: 107 | G19: 102 | H19: 112 | I19: 110 | J19: 105 | K19: 117 | L19: 102 | M19: 86 | N19: 101 | O19: 93 | P19: 82 | Q19: 97 | R19: 96 | S19: =SUM(E19:R19) -> 1421
D20: PR | E20: 108 | F20: 99 | G20: 113 | H20: 114 | I20: 106 | J20: 117 | K20: 115 | L20: 108 | M20: 93 | N20: 83 | O20: 108 | P20: 78 | Q20: 107 | R20: 98 | S20: =SUM(E20:R20) -> 1447
D21: JML | E21: =SUM(E19:E20) -> 219 | F21: =SUM(F19:F20) -> 206 | G21: =SUM(G19:G20) -> 215 | H21: =SUM(H19:H20) -> 226 | I21: =SUM(I19:I20) -> 216 | J21: =SUM(J19:J20) -> 222 | K21: =SUM(K19:K20) -> 232 | L21: =SUM(L19:L20) -> 210 | ... R21: =SUM(R19:R20) -> 194 | S21: =SUM(E21:R21) -> 2868
B22: 2. | C22: Jumlah pengguna hak pilih dalam Daftar Pemilih Tambahan (DPTb) | D22: LK | E22: 0 | F22: 1 | G22: 0 | H22: 3 | I22: 1 | J22: 0 | K22: 0 | L22: 0 | M22: 1 | N22: 0 | O22: 0 | P22: 0 | Q22: 0 | R22: 0 | S22: =SUM(E22:R22) -> 6
D23: PR | E23: 0 | F23: 1 | G23: 1 | H23: 3 | I23: 2 | J23: 0 | K23: 0 | L23: 0 | M23: 1 | N23: 0 | O23: 0 | P23: 0 | Q23: 0 | R23: 0 | S23: =SUM(E23:R23) -> 8
D24: JML | E24: =SUM(E22:E23) -> 0 | F24: =SUM(F22:F23) -> 2 | G24: =SUM(G22:G23) -> 1 | H24: =SUM(H22:H23) -> 6 | I24: =SUM(I22:I23) -> 3 | J24: =SUM(J22:J23) -> 0 | K24: =SUM(K22:K23) -> 0 | L24: =SUM(L22:L23) -> 0 | ... R24: =SUM(R22:R23) -> 0 | S24: =SUM(E24:R24) -> 14
B25: 3. | C25: Jumlah pengguna hak pilih dalam Daftar Pemilih Khusus (DPK) | D25: LK | E25: 0 | F25: 5 | G25: 1 | H25: 1 | I25: 0 | J25: 0 | K25: 0 | L25: 0 | M25: 2 | N25: 0 | O25: 2 | P25: 0 | Q25: 0 | R25: 0 | S25: =SUM(E25:R25) -> 11
D26: PR | E26: 0 | F26: 6 | G26: 1 | H26: 0 | I26: 0 | J26: 2 | K26: 0 | L26: 0 | M26: 3 | N26: 0 | O26: 3 | P26: 0 | Q26: 0 | R26: 0 | S26: =SUM(E26:R26) -> 15
D27: JML | E27: =SUM(E25:E26) -> 0 | F27: =SUM(F25:F26) -> 11 | G27: =SUM(G25:G26) -> 2 | H27: =SUM(H25:H26) -> 1 | I27: =SUM(I25:I26) -> 0 | J27: =SUM(J25:J26) -> 2 | K27: =SUM(K25:K26) -> 0 | L27: =SUM(L25:L26) -> 0 | ... R27: =SUM(R25:R26) -> 0 | S27: =SUM(E27:R27) -> 26
B28: 4. | C28: Jumlah Pengguna Hak Pilih (B.1+B.2+B.3) | D28: LK | E28: =SUM(E19,E22,E25) -> 111 | F28: =SUM(F19,F22,F25) -> 113 | G28: =SUM(G19,G22,G25) -> 103 | H28: =SUM(H19,H22,H25) -> 116 | I28: =SUM(I19,I22,I25) -> 111 | J28: =SUM(J19,J22,J25) -> 105 | K28: =SUM(K19,K22,K25) -> 117 | L28: =SUM(L19,L22,L25) -> 102 | ... R28: =SUM(R19,R22,R25) -> 96 | S28: =SUM(E28:R28) -> 1438
D29: PR | E29: =SUM(E20,E23,E26) -> 108 | F29: =SUM(F20,F23,F26) -> 106 | G29: =SUM(G20,G23,G26) -> 115 | H29: =SUM(H20,H23,H26) -> 117 | I29: =SUM(I20,I23,I26) -> 108 | J29: =SUM(J20,J23,J26) -> 119 | K29: =SUM(K20,K23,K26) -> 115 | L29: =SUM(L20,L23,L26) -> 108 | ... R29: =SUM(R20,R23,R26) -> 98 | S29: =SUM(E29:R29) -> 1470
D30: JML | E30: =SUM(E28:E29) -> 219 | F30: =SUM(F28:F29) -> 219 | G30: =SUM(G28:G29) -> 218 | H30: =SUM(H28:H29) -> 233 | I30: =SUM(I28:I29) -> 219 | J30: =SUM(J28:J29) -> 224 | K30: =SUM(K28:K29) -> 232 | L30: =SUM(L28:L29) -> 210 | ... R30: =SUM(R28:R29) -> 194 | S30: =SUM(E30:R30) -> 2908
A32: II | B32: DATA PENGGUNAAN SURAT SUARA
A33: 1 | B33: Jumlah surat suara yang diterima, termasuk surat suara cadangan 2,5% dari DPT | E33: 261 | F33: 240 | G33: 258 | H33: 272 | I33: 260 | J33: 275 | K33: 274 | L33: 283 | M33: 234 | N33: 233 | O33: 259 | P33: 201 | Q33: 245 | R33: 236 | S33: =SUM(E33:R33) -> 3531
A34: 2 | B34: Jumlah surat suara yang digunakan | E34: 219 | F34: 219 | G34: 218 | H34: 233 | I34: 219 | J34: 224 | K34: 232 | L34: 210 | M34: 186 | N34: 184 | O34: 206 | P34: 160 | Q34: 204 | R34: 194 | S34: =SUM(E34:R34) -> 2908
A35: 3 | B35: Jumlah surat suara dikembalikan oleh pemilih (karena rusak atau keliru coblos) | E35: 0 | F35: 0 | G35: 4 | H35: 0 | I35: 1 | J35: 0 | K35: 0 | L35: 1 | M35: 0 | N35: 0 | O35: 0 | P35: 0 | Q35: 0 | R35: 0 | S35: =SUM(E35:R35) -> 6
A36: 4 | B36: Jumlah surat suara yang tidak digunakan/tidak terpakai, termasuk sisa surat suara cadangan | E36: =E33-(E34+E35) -> 42 | F36: =F33-(F34+F35) -> 21 | G36: =G33-(G34+G35) -> 36 | H36: =H33-(H34+H35) -> 39 | I36: =I33-(I34+I35) -> 40 | J36: =J33-(J34+J35) -> 51 | K36: =K33-(K34+K35) -> 42 | L36: =L33-(L34+L35) -> 72 | ... R36: =R33-(R34+R35) -> 42 | S36: =SUM(E36:R36) -> 617
A38: III | B38: DATA PEMILIH DISABILITAS
B39: Jumlah seluruh Pemilih disabilitas yang menggunakan hak pilih | D39: LK | E39: 0 | F39: 1 | G39: 0 | H39: 2 | I39: 0 | J39: 0 | K39: 0 | L39: 0 | M39: 0 | N39: 2 | O39: 0 | P39: 0 | Q39: 0 | R39: 0 | S39: =SUM(E39:R39) -> 5
D40: PR | E40: 0 | F40: 3 | G40: 0 | H40: 4 | I40: 0 | J40: 4 | K40: 0 | L40: 0 | M40: 0 | N40: 2 | O40: 0 | P40: 0 | Q40: 0 | R40: 0 | S40: =SUM(E40:R40) -> 13
D41: JML | E41: =SUM(E39:E40) -> 0 | F41: =SUM(F39:F40) -> 4 | G41: =SUM(G39:G40) -> 0 | H41: =SUM(H39:H40) -> 6 | I41: =SUM(I39:I40) -> 0 | J41: =SUM(J39:J40) -> 4 | K41: =SUM(K39:K40) -> 0 | L41: =SUM(L39:L40) -> 0 | ... R41: =SUM(R39:R40) -> 0 | S41: =SUM(E41:R41) -> 18
A43: IV | B43: DATA RINCIAN PEROLEHAN SUARA PASANGAN CALON BUPATI DAN WAKIL BUPATI
A44: NOMOR DAN NAMA CALON
B45: 1 | C45: H. ANIES RASYID BASWEDAN, Ph.D. - Dr. (H.C.) H. A. MUHAIMIN ISKANDAR | E45: 15 | F45: 40 | G45: 39 | H45: 12 | I45: 21 | J45: 26 | K45: 18 | L45: 17 | M45: 37 | N45: 22 | O45: 11 | P45: 13 | Q45: 17 | R45: 8 | S45: =SUM(E45:R45) -> 296
B46: 2 | C46: H. PRABOWO SUBIANTO - GIBRAN RAKABUMING RAKA | E46: 122 | F46: 125 | G46: 112 | H46: 171 | I46: 147 | J46: 167 | K46: 178 | L46: 175 | M46: 122 | N46: 120 | O46: 163 | P46: 109 | Q46: 153 | R46: 147 | S46: =SUM(E46:R46) -> 2011
B47: 3 | C47: H. GANJAR PRANOWO, S.H., M.I.P. - Prof. Dr. H. M. MAHFUD MD | E47: 80 | F47: 53 | G47: 66 | H47: 46 | I47: 45 | J47: 30 | K47: 32 | L47: 12 | M47: 13 | N47: 41 | O47: 29 | P47: 34 | Q47: 21 | R47: 36 | S47: =SUM(E47:R47) -> 538
A49: V | B49: DATA SUARA SAH DAN TIDAK SAH
B50: A. | C50: JUMLAH SELURUH SUARA SAH | E50: =SUM(E45:E47) -> 217 | F50: =SUM(F45:F47) -> 218 | G50: =SUM(G45:G47) -> 217 | H50: =SUM(H45:H47) -> 229 | I50: =SUM(I45:I47) -> 213 | J50: =SUM(J45:J47) -> 223 | K50: =SUM(K45:K47) -> 228 | L50: =SUM(L45:L47) -> 204 | ... R50: =SUM(R45:R47) -> 191 | S50: =SUM(E50:R50) -> 2845
B51: B. | C51: JUMLAH SUARA TIDAK SAH | E51: 2 | F51: 1 | G51: 1 | H51: 4 | I51: 5 | J51: 1 | K51: 4 | L51: 6 | M51: 4 | N51: 1 | O51: 2 | P51: 4 | Q51: 2 | R51: 2 | S51: =SUM(E51:R51) -> 39
B52: C. | C52: JUMLAH SELURUH SUARA SAH DAN SUARA TIDAK SAH (V.A + V.B) | E52: =SUM(E50:E51) -> 219 | F52: =SUM(F50:F51) -> 219 | G52: =SUM(G50:G51) -> 218 | H52: =SUM(H50:H51) -> 233 | I52: =SUM(I50:I51) -> 218 | J52: =SUM(J50:J51) -> 224 | K52: =SUM(K50:K51) -> 232 | L52: =SUM(L50:L51) -> 210 | ... R52: =SUM(R50:R51) -> 193 | S52: =SUM(E52:R52) -> 2884

Sheet CANTUK
C2: Kecamatan | D2: SINGOJURUH
C3: Kabupaten | D3: BANYUWANGI
C4: Provinsi | D4: JAWA TIMUR
C9: Kelurahan | D9: CANTUK
A12: I | B12: DATA PEMILIH DAN PENGGUNAAN HAK PILIH | T12: JUMLAH AKHIR
A13: A | B13: DATA PEMILIH | E13: TPS 001 | F13: TPS 002 | G13: TPS 003 | H13: TPS 004 | I13: TPS 005 | J13: TPS 006 | K13: TPS 007 | L13: TPS 008 | M13: TPS 009 | N13: TPS 010 | O13: TPS 011 | P13: TPS 012 | Q13: TPS 013 | R13: TPS 014 | S13: TPS 015
B14: Jumlah Pemilih dalam Daftar Pemilih Tetap (DPT) | D14: LK | E14: 135 | F14: 130 | G14: 131 | H14: 142 | I14: 130 | J14: 128 | K14: 117 | L14: 118 | M14: 126 | N14: 132 | O14: 97 | P14: 102 | Q14: 121 | R14: 118 | S14: 124 | T14: =SUM(E14:S14) -> 1851
D15: PR | E15: 136 | F15: 128 | G15: 126 | H15: 128 | I15: 129 | J15: 134 | K15: 131 | L15: 131 | M15: 129 | N15: 152 | O15: 107 | P15: 111 | Q15: 124 | R15: 125 | S15: 117 | T15: =SUM(E15:S15) -> 1908
D16: JML | E16: =SUM(E14:E15) -> 271 | F16: =SUM(F14:F15) -> 258 | G16: =SUM(G14:G15) -> 257 | H16: =SUM(H14:H15) -> 270 | I16: =SUM(I14:I15) -> 259 | J16: =SUM(J14:J15) -> 262 | K16: =SUM(K14:K15) -> 248 | L16: =SUM(L14:L15) -> 249 | ... S16: =SUM(S14:S15) -> 241 | T16: =SUM(E16:S16) -> 3759
A18: B | B18: PENGGUNA HAK PILIH
B19: 1. | C19: Jumlah pengguna hak pilih dalam Daftar Pemilih Tetap (DPT) | D19: LK | E19: 92 | F19: 99 | G19: 93 | H19: 104 | I19: 99 | J19: 101 | K19: 98 | L19: 92 | M19: 82 | N19: 87 | O19: 84 | P19: 71 | Q19: 91 | R19: 90 | S19: 104 | T19: =SUM(E19:S19) -> 1387
D20: PR | E20: 110 | F20: 102 | G20: 97 | H20: 104 | I20: 108 | J20: 111 | K20: 96 | L20: 108 | M20: 89 | N20: 109 | O20: 69 | P20: 84 | Q20: 103 | R20: 104 | S20: 98 | T20: =SUM(E20:S20) -> 1492
D21: JML | E21: =SUM(E19:E20) -> 202 | F21: =SUM(F19:F20) -> 201 | G21: =SUM(G19:G20) -> 190 | H21: =SUM(H19:H20) -> 208 | I21: =SUM(I19:I20) -> 207 | J21: =SUM(J19:J20) -> 212 | K21: =SUM(K19:K20) -> 194 | L21: =SUM(L19:L20) -> 200 | ... S21: =SUM(S19:S20) -> 202 | T21: =SUM(E21:S21) -> 2879
B22: 2. | C22: Jumlah pengguna hak pilih dalam Daftar Pemilih Tambahan (DPTb) | D22: LK | E22: 0 | F22: 0 | G22: 1 | H22: 0 | I22: 0 | J22: 0 | K22: 0 | L22: 0 | M22: 0 | N22: 0 | O22: 2 | P22: 0 | Q22: 1 | R22: 1 | S22: 2 | T22: =SUM(E22:S22) -> 7
D23: PR | E23: 1 | F23: 0 | G23: 0 | H23: 1 | I23: 0 | J23: 0 | K23: 0 | L23: 2 | M23: 1 | N23: 0 | O23: 0 | P23: 1 | Q23: 1 | R23: 1 | S23: 2 | T23: =SUM(E23:S23) -> 10
D24: JML | E24: =SUM(E22:E23) -> 1 | F24: =SUM(F22:F23) -> 0 | G24: =SUM(G22:G23) -> 1 | H24: =SUM(H22:H23) -> 1 | I24: =SUM(I22:I23) -> 0 | J24: =SUM(J22:J23) -> 0 | K24: =SUM(K22:K23) -> 0 | L24: =SUM(L22:L23) -> 2 | ... S24: =SUM(S22:S23) -> 4 | T24: =SUM(E24:S24) -> 17
B25: 3. | C25: Jumlah pengguna hak pilih dalam Daftar Pemilih Khusus (DPK) | D25: LK | E25: 1 | F25: 0 | G25: 0 | H25: 0 | I25: 1 | J25: 0 | K25: 0 | L25: 0 | M25: 1 | N25: 2 | O25: 2 | P25: 0 | Q25: 1 | R25: 1 | S25: 0 | T25: =SUM(E25:S25) -> 9
D26: PR | E26: 2 | F26: 0 | G26: 0 | H26: 0 | I26: 1 | J26: 0 | K26: 2 | L26: 1 | M26: 0 | N26: 1 | O26: 1 | P26: 1 | Q26: 0 | R26: 0 | S26: 0 | T26: =SUM(E26:S26) -> 9
D27: JML | E27: =SUM(E25:E26) -> 3 | F27: =SUM(F25:F26) -> 0 | G27: =SUM(G25:G26) -> 0 | H27: =SUM(H25:H26) -> 0 | I27: =SUM(I25:I26) -> 2 | J27: =SUM(J25:J26) -> 0 | K27: =SUM(K25:K26) -> 2 | L27: =SUM(L25:L26) -> 1 | ... S27: =SUM(S25:S26) -> 0 | T27: =SUM(E27:S27) -> 18
B28: 4. | C28: Jumlah Pengguna Hak Pilih (B.1+B.2+B.3) | D28: LK | E28: =SUM(E19,E22,E25) -> 93 | F28: =SUM(F19,F22,F25) -> 99 | G28: =SUM(G19,G22,G25) -> 94 | H28: =SUM(H19,H22,H25) -> 104 | I28: =SUM(I19,I22,I25) -> 100 | J28: =SUM(J19,J22,J25) -> 101 | K28: =SUM(K19,K22,K25) -> 98 | L28: =SUM(L19,L22,L25) -> 92 | ... S28: =SUM(S19,S22,S25) -> 106 | T28: =SUM(E28:S28) -> 1403
D29: PR | E29: =SUM(E20,E23,E26) -> 113 | F29: =SUM(F20,F23,F26) -> 102 | G29: =SUM(G20,G23,G26) -> 97 | H29: =SUM(H20,H23,H26) -> 105 | I29: =SUM(I20,I23,I26) -> 109 | J29: =SUM(J20,J23,J26) -> 111 | K29: =SUM(K20,K23,K26) -> 98 | L29: =SUM(L20,L23,L26) -> 111 | ... S29: =SUM(S20,S23,S26) -> 100 | T29: =SUM(E29:S29) -> 1511
D30: JML | E30: =SUM(E28:E29) -> 206 | F30: =SUM(F28:F29) -> 201 | G30: =SUM(G28:G29) -> 191 | H30: =SUM(H28:H29) -> 209 | I30: =SUM(I28:I29) -> 209 | J30: =SUM(J28:J29) -> 212 | K30: =SUM(K28:K29) -> 196 | L30: =SUM(L28:L29) -> 203 | ... S30: =SUM(S28:S29) -> 206 | T30: =SUM(E30:S30) -> 2914
A32: II | B32: DATA PENGGUNAAN SURAT SUARA
A33: 1 | B33: Jumlah surat suara yang diterima, termasuk surat suara cadangan 2,5% dari DPT | E33: 266 | F33: 254 | G33: 253 | H33: 266 | I33: 255 | J33: 258 | K33: 248 | L33: 241 | M33: 250 | N33: 280 | O33: 202 | P33: 207 | Q33: 241 | R33: 239 | S33: 238 | T33: =SUM(E33:S33) -> 3698
A34: 2 | B34: Jumlah surat suara yang digunakan | E34: 206 | F34: 201 | G34: 191 | H34: 209 | I34: 209 | J34: 212 | K34: 196 | L34: 203 | M34: 173 | N34: 199 | O34: 158 | P34: 137 | Q34: 202 | R34: 197 | S34: 206 | T34: =SUM(E34:S34) -> 2899
A35: 3 | B35: Jumlah surat suara dikembalikan oleh pemilih (karena rusak atau keliru coblos) | E35: 0 | F35: 0 | G35: 1 | H35: 0 | I35: 0 | J35: 0 | K35: 0 | L35: 0 | M35: 0 | N35: 0 | O35: 0 | P35: 0 | Q35: 0 | R35: 2 | S35: 0 | T35: =SUM(E35:S35) -> 3
A36: 4 | B36: Jumlah surat suara yang tidak digunakan/tidak terpakai, termasuk sisa surat suara cadangan | E36: =E33-(E34+E35) -> 60 | F36: =F33-(F34+F35) -> 53 | G36: =G33-(G34+G35) -> 61 | H36: =H33-(H34+H35) -> 57 | I36: =I33-(I34+I35) -> 46 | J36: =J33-(J34+J35) -> 46 | K36: =K33-(K34+K35) -> 52 | L36: =L33-(L34+L35) -> 38 | ... S36: =S33-(S34+S35) -> 32 | T36: =SUM(E36:S36) -> 796
A38: III | B38: DATA PEMILIH DISABILITAS
B39: Jumlah seluruh Pemilih disabilitas yang menggunakan hak pilih | D39: LK | E39: 0 | F39: 0 | G39: 0 | H39: 0 | I39: 0 | J39: 0 | K39: 0 | L39: 0 | M39: 0 | N39: 0 | O39: 1 | P39: 0 | Q39: 0 | R39: 0 | S39: 1 | T39: =SUM(E39:S39) -> 2
D40: PR | E40: 0 | F40: 0 | G40: 0 | H40: 0 | I40: 0 | J40: 0 | K40: 0 | L40: 0 | M40: 0 | N40: 0 | O40: 1 | P40: 1 | Q40: 0 | R40: 0 | S40: 0 | T40: =SUM(E40:S40) -> 2
D41: JML | E41: =SUM(E39:E40) -> 0 | F41: =SUM(F39:F40) -> 0 | G41: =SUM(G39:G40) -> 0 | H41: =SUM(H39:H40) -> 0 | I41: =SUM(I39:I40) -> 0 | J41: =SUM(J39:J40) -> 0 | K41: =SUM(K39:K40) -> 0 | L41: =SUM(L39:L40) -> 0 | ... S41: =SUM(S39:S40) -> 1 | T41: =SUM(E41:S41) -> 4
A43: IV | B43: DATA RINCIAN PEROLEHAN SUARA PASANGAN CALON BUPATI DAN WAKIL BUPATI
A44: NOMOR DAN NAMA CALON
B45: 1 | C45: H. ANIES RASYID BASWEDAN, Ph.D. - Dr. (H.C.) H. A. MUHAIMIN ISKANDAR | E45: 3 | F45: 12 | G45: 21 | H45: 15 | I45: 12 | J45: 25 | K45: 23 | L45: 8 | M45: 7 | N45: 14 | O45: 9 | P45: 18 | Q45: 8 | R45: 21 | S45: 8 | T45: =SUM(E45:S45) -> 204
B46: 2 | C46: H. PRABOWO SUBIANTO - GIBRAN RAKABUMING RAKA | E46: 174 | F46: 162 | G46: 133 | H46: 179 | I46: 165 | J46: 166 | K46: 148 | L46: 171 | M46: 152 | N46: 156 | O46: 159 | P46: 134 | Q46: 168 | R46: 143 | S46: 163 | T46: =SUM(E46:S46) -> 2373
B47: 3 | C47: H. GANJAR PRANOWO, S.H., M.I.P. - Prof. Dr. H. M. MAHFUD MD | E47: 26 | F47: 29 | G47: 36 | H47: 11 | I47: 27 | J47: 19 | K47: 19 | L47: 16 | M47: 12 | N47: 25 | O47: 11 | P47: 14 | Q47: 14 | R47: 29 | S47: 32 | T47: =SUM(E47:S47) -> 320
A49: V | B49: DATA SUARA SAH DAN TIDAK SAH
B50: A. | C50: JUMLAH SELURUH SUARA SAH | E50: =SUM(E45:E47) -> 203 | F50: =SUM(F45:F47) -> 203 | G50: =SUM(G45:G47) -> 190 | H50: =SUM(H45:H47) -> 205 | I50: =SUM(I45:I47) -> 204 | J50: =SUM(J45:J47) -> 210 | K50: =SUM(K45:K47) -> 190 | L50: =SUM(L45:L47) -> 195 | ... S50: =SUM(S45:S47) -> 203 | T50: =SUM(E50:S50) -> 2897
B51: B. | C51: JUMLAH SUARA TIDAK SAH | E51: 3 | F51: 5 | G51: 1 | H51: 4 | I51: 5 | J51: 2 | K51: 6 | L51: 8 | M51: 2 | N51: 3 | O51: 9 | P51: 1 | Q51: 12 | R51: 4 | S51: 4 | T51: =SUM(E51:S51) -> 69
B52: C. | C52: JUMLAH SELURUH SUARA SAH DAN SUARA TIDAK SAH (V.A + V.B) | E52: =SUM(E50:E51) -> 206 | F52: =SUM(F50:F51) -> 208 | G52: =SUM(G50:G51) -> 191 | H52: =SUM(H50:H51) -> 209 | I52: =SUM(I50:I51) -> 209 | J52: =SUM(J50:J51) -> 212 | K52: =SUM(K50:K51) -> 196 | L52: =SUM(L50:L51) -> 203 | ... S52: =SUM(S50:S51) -> 207 | T52: =SUM(E52:S52) -> 2966

Sheet GAMBOR
C2: Kecamatan | D2: SINGOJURUH
C3: Kabupaten | D3: BANYUWANGI
C4: Provinsi | D4: JAWA TIMUR
C9: Kelurahan | D9: GAMBOR
A12: I | B12: DATA PEMILIH DAN PENGGUNAAN HAK PILIH | N12: JUMLAH AKHIR
A13: A | B13: DATA PEMILIH | E13: TPS 001 | F13: TPS 002 | G13: TPS 003 | H13: TPS 004 | I13: TPS 005 | J13: TPS 006 | K13: TPS 007 | L13: TPS 008 | M13: TPS 009
B14: Jumlah Pemilih dalam Daftar Pemilih Tetap (DPT) | D14: LK | E14: 125 | F14: 146 | G14: 125 | H14: 119 | I14: 115 | J14: 132 | K14: 150 | L14: 127 | M14: 112 | N14: =SUM(E14:M14) -> 1151
D15: PR | E15: 125 | F15: 131 | G15: 134 | H15: 117 | I15: 120 | J15: 120 | K15: 132 | L15: 128 | M15: 122 | N15: =SUM(E15:M15) -> 1129
D16: JML | E16: =SUM(E14:E15) -> 250 | F16: =SUM(F14:F15) -> 277 | G16: =SUM(G14:G15) -> 259 | H16: =SUM(H14:H15) -> 236 | I16: =SUM(I14:I15) -> 235 | J16: =SUM(J14:J15) -> 252 | K16: =SUM(K14:K15) -> 282 | L16: =SUM(L14:L15) -> 255 | M16: =SUM(M14:M15) -> 234 | N16: =SUM(E16:M16) -> 2280
A18: B | B18: PENGGUNA HAK PILIH
B19: 1. | C19: Jumlah pengguna hak pilih dalam Daftar Pemilih Tetap (DPT) | D19: LK | E19: 91 | F19: 124 | G19: 88 | H19: 88 | I19: 94 | J19: 106 | K19: 115 | L19: 83 | M19: 96 | N19: =SUM(E19:M19) -> 885
D20: PR | E20: 97 | F20: 115 | G20: 95 | H20: 91 | I20: 102 | J20: 92 | K20: 105 | L20: 101 | M20: 100 | N20: =SUM(E20:M20) -> 898
D21: JML | E21: =SUM(E19:E20) -> 188 | F21: =SUM(F19:F20) -> 239 | G21: =SUM(G19:G20) -> 183 | H21: =SUM(H19:H20) -> 179 | I21: =SUM(I19:I20) -> 196 | J21: =SUM(J19:J20) -> 198 | K21: =SUM(K19:K20) -> 220 | L21: =SUM(L19:L20) -> 184 | M21: =SUM(M19:M20) -> 196 | N21: =SUM(E21:M21) -> 1783
B22: 2. | C22: Jumlah pengguna hak pilih dalam Daftar Pemilih Tambahan (DPTb) | D22: LK | K22: 1 | N22: =SUM(E22:M22) -> 1
D23: PR | N23: =SUM(E23:M23) -> 0
D24: JML | E24: =SUM(E22:E23) -> 0 | F24: =SUM(F22:F23) -> 0 | G24: =SUM(G22:G23) -> 0 | H24: =SUM(H22:H23) -> 0 | I24: =SUM(I22:I23) -> 0 | J24: =SUM(J22:J23) -> 0 | K24: =SUM(K22:K23) -> 1 | L24: =SUM(L22:L23) -> 0 | M24: =SUM(M22:M23) -> 0 | N24: =SUM(E24:M24) -> 1
B25: 3. | C25: Jumlah pengguna hak pilih dalam Daftar Pemilih Khusus (DPK) | D25: LK | G25: 4 | H25: 1 | I25: 1 | K25: 1 | L25: 1 | M25: 1 | N25: =SUM(E25:M25) -> 9
D26: PR | E26: 3 | F26: 1 | G26: 1 | H26: 3 | I26: 2 | K26: 1 | L26: 3 | M26: 1 | N26: =SUM(E26:M26) -> 15
D27: JML | E27: =SUM(E25:E26) -> 3 | F27: =SUM(F25:F26) -> 1 | G27: =SUM(G25:G26) -> 5 | H27: =SUM(H25:H26) -> 4 | I27: =SUM(I25:I26) -> 3 | J27: =SUM(J25:J26) -> 0 | K27: =SUM(K25:K26) -> 2 | L27: =SUM(L25:L26) -> 4 | M27: =SUM(M25:M26) -> 2 | N27: =SUM(E27:M27) -> 24
B28: 4. | C28: Jumlah Pengguna Hak Pilih (B.1+B.2+B.3) | D28: LK | E28: =SUM(E19,E22,E25) -> 91 | F28: =SUM(F19,F22,F25) -> 124 | G28: =SUM(G19,G22,G25) -> 92 | H28: =SUM(H19,H22,H25) -> 89 | I28: =SUM(I19,I22,I25) -> 95 | J28: =SUM(J19,J22,J25) -> 106 | K28: =SUM(K19,K22,K25) -> 117 | L28: =SUM(L19,L22,L25) -> 84 | M28: =SUM(M19,M22,M25) -> 97 | N28: =SUM(E28:M28) -> 895
D29: PR | E29: =SUM(E20,E23,E26) -> 100 | F29: =SUM(F20,F23,F26) -> 116 | G29: =SUM(G20,G23,G26) -> 96 | H29: =SUM(H20,H23,H26) -> 94 | I29: =SUM(I20,I23,I26) -> 104 | J29: =SUM(J20,J23,J26) -> 92 | K29: =SUM(K20,K23,K26) -> 106 | L29: =SUM(L20,L23,L26) -> 104 | M29: =SUM(M20,M23,M26) -> 101 | N29: =SUM(E29:M29) -> 913
D30: JML | E30: =SUM(E28:E29) -> 191 | F30: =SUM(F28:F29) -> 240 | G30: =SUM(G28:G29) -> 188 | H30: =SUM(H28:H29) -> 183 | I30: =SUM(I28:I29) -> 199 | J30: =SUM(J28:J29) -> 198 | K30: =SUM(K28:K29) -> 223 | L30: =SUM(L28:L29) -> 188 | M30: =SUM(M28:M29) -> 198 | N30: =SUM(E30:M30) -> 1808
A32: II | B32: DATA PENGGUNAAN SURAT SUARA
A33: 1 | B33: Jumlah surat suara yang diterima, termasuk surat suara cadangan 2,5% dari DPT | E33: 244 | F33: 283 | G33: 256 | H33: 241 | I33: 241 | J33: 248 | K33: 278 | L33: 250 | M33: 229 | N33: =SUM(E33:M33) -> 2270
A34: 2 | B34: Jumlah surat suara yang digunakan | E34: 191 | F34: 240 | G34: 188 | H34: 183 | I34: 199 | J34: 198 | K34: 223 | L34: 188 | M34: 198 | N34: =SUM(E34:M34) -> 1808
A35: 3 | B35: Jumlah surat suara dikembalikan oleh pemilih (karena rusak atau keliru coblos) | G35: 1 | I35: 5 | N35: =SUM(E35:M35) -> 6
A36: 4 | B36: Jumlah surat suara yang tidak digunakan/tidak terpakai, termasuk sisa surat suara cadangan | E36: =E33-(E34+E35) -> 53 | F36: =F33-(F34+F35) -> 43 | G36: =G33-(G34+G35) -> 67 | H36: =H33-(H34+H35) -> 58 | I36: =I33-(I34+I35) -> 37 | J36: =J33-(J34+J35) -> 50 | K36: =K33-(K34+K35) -> 55 | L36: =L33-(L34+L35) -> 62 | M36: =M33-(M34+M35) -> 31 | N36: =SUM(E36:M36) -> 456
A38: III | B38: DATA PEMILIH DISABILITAS
B39: Jumlah seluruh Pemilih disabilitas yang menggunakan hak pilih | D39: LK | N39: =SUM(E39:M39) -> 0
D40: PR | G40: 1 | J40: 1 | N40: =SUM(E40:M40) -> 2
D41: JML | E41: =SUM(E39:E40) -> 0 | F41: =SUM(F39:F40) -> 0 | G41: =SUM(G39:G40) -> 1 | H41: =SUM(H39:H40) -> 0 | I41: =SUM(I39:I40) -> 0 | J41: =SUM(J39:J40) -> 1 | K41: =SUM(K39:K40) -> 0 | L41: =SUM(L39:L40) -> 0 | M41: =SUM(M39:M40) -> 0 | N41: =SUM(E41:M41) -> 2
A43: IV | B43: DATA RINCIAN PEROLEHAN SUARA PASANGAN CALON BUPATI DAN WAKIL BUPATI
A44: NOMOR DAN NAMA CALON
B45: 1 | C45: H. ANIES RASYID BASWEDAN, Ph.D. - Dr. (H.C.) H. A. MUHAIMIN ISKANDAR | E45: 12 | F45: 27 | G45: 19 | H45: 8 | I45: 21 | J45: 30 | K45: 34 | L45: 21 | M45: 25 | N45: =SUM(E45:M45) -> 197 | O45: ga jelas
B46: 2 | C46: H. PRABOWO SUBIANTO - GIBRAN RAKABUMING RAKA | E46: 155 | F46: 189 | G46: 151 | H46: 153 | I46: 151 | J46: 152 | K46: 164 | L46: 153 | M46: 140 | N46: =SUM(E46:M46) -> 1408
B47: 3 | C47: H. GANJAR PRANOWO, S.H., M.I.P. - Prof. Dr. H. M. MAHFUD MD | E47: 16 | F47: 17 | G47: 11 | H47: 15 | I47: 23 | J47: 10 | K47: 19 | L47: 12 | M47: 22 | N47: =SUM(E47:M47) -> 145
A49: V | B49: DATA SUARA SAH DAN TIDAK SAH
B50: A. | C50: JUMLAH SELURUH SUARA SAH | E50: =SUM(E45:E47) -> 183 | F50: =SUM(F45:F47) -> 233 | G50: =SUM(G45:G47) -> 181 | H50: =SUM(H45:H47) -> 176 | I50: =SUM(I45:I47) -> 195 | J50: =SUM(J45:J47) -> 192 | K50: =SUM(K45:K47) -> 217 | L50: =SUM(L45:L47) -> 186 | M50: =SUM(M45:M47) -> 187 | N50: =SUM(E50:M50) -> 1750
B51: B. | C51: JUMLAH SUARA TIDAK SAH | E51: 8 | F51: 7 | G51: 7 | H51: 7 | I51: 6 | J51: 6 | K51: 6 | L51: 2 | M51: 1 | N51: =SUM(E51:M51) -> 50
B52: C. | C52: JUMLAH SELURUH SUARA SAH DAN SUARA TIDAK SAH (V.A + V.B) | E52: =SUM(E50:E51) -> 191 | F52: =SUM(F50:F51) -> 240 | G52: =SUM(G50:G51) -> 188 | H52: =SUM(H50:H51) -> 183 | I52: =SUM(I50:I51) -> 201 | J52: =SUM(J50:J51) -> 198 | K52: =SUM(K50:K51) -> 223 | L52: =SUM(L50:L51) -> 188 | M52: =SUM(M50:M51) -> 188 | N52: =SUM(E52:M52) -> 1800

Sheet GUMIRIH
C2: Kecamatan | D2: SINGOJURUH
C3: Kabupaten | D3: BANYUWANGI
C4: Provinsi | D4: JAWA TIMUR
C9: Kelurahan | D9: GUMIRIH
A12: I | B12: DATA PEMILIH DAN PENGGUNAAN HAK PILIH | S12: JUMLAH AKHIR
A13: A | B13: DATA PEMILIH | E13: TPS 001 | F13: TPS 002 | G13: TPS 003 | H13: TPS 004 | I13: TPS 005 | J13: TPS 006 | K13: TPS 007 | L13: TPS 008 | M13: TPS 009 | N13: TPS 010 | O13: TPS 011 | P13: TPS 012 | Q13: TPS 013 | R13: TPS 014
B14: Jumlah Pemilih dalam Daftar Pemilih Tetap (DPT) | D14: LK | E14: 118 | F14: 97 | G14: 102 | H14: 133 | I14: 126 | J14: 127 | K14: 134 | L14: 118 | M14: 141 | N14: 140 | O14: 132 | P14: 134 | Q14: 143 | R14: 94 | S14: =SUM(E14:R14) -> 1739
D15: PR | E15: 116 | F15: 103 | G15: 110 | H15: 126 | I15: 128 | J15: 130 | K15: 141 | L15: 131 | M15: 133 | N15: 124 | O15: 144 | P15: 143 | Q15: 129 | R15: 86 | S15: =SUM(E15:R15) -> 1744
D16: JML | E16: =SUM(E14:E15) -> 234 | F16: =SUM(F14:F15) -> 200 | G16: =SUM(G14:G15) -> 212 | H16: =SUM(H14:H15) -> 259 | I16: =SUM(I14:I15) -> 254 | J16: =SUM(J14:J15) -> 257 | K16: =SUM(K14:K15) -> 275 | L16: =SUM(L14:L15) -> 249 | ... R16: =SUM(R14:R15) -> 180 | S16: =SUM(E16:R16) -> 3483
A18: B | B18: PENGGUNA HAK PILIH
B19: 1. | C19: Jumlah pengguna hak pilih dalam Daftar Pemilih Tetap (DPT) | D19: LK | E19: 85 | F19: 60 | G19: 73 | H19: 92 | I19: 96 | J19: 94 | K19: 100 | L19: 77 | M19: 96 | N19: 106 | O19: 109 | P19: 96 | Q19: 95 | R19: 74 | S19: =SUM(E19:R19) -> 1253
D20: PR | E20: 88 | F20: 72 | G20: 85 | H20: 100 | I20: 108 | J20: 89 | K20: 113 | L20: 96 | M20: 101 | N20: 111 | O20: 99 | P20: 102 | Q20: 103 | R20: 65 | S20: =SUM(E20:R20) -> 1332
D21: JML | E21: =SUM(E19:E20) -> 173 | F21: =SUM(F19:F20) -> 132 | G21: =SUM(G19:G20) -> 158 | H21: =SUM(H19:H20) -> 192 | I21: =SUM(I19:I20) -> 204 | J21: =SUM(J19:J20) -> 183 | K21: =SUM(K19:K20) -> 213 | L21: =SUM(L19:L20) -> 173 | ... R21: =SUM(R19:R20) -> 139 | S21: =SUM(E21:R21) -> 2585
B22: 2. | C22: Jumlah pengguna hak pilih dalam Daftar Pemilih Tambahan (DPTb) | D22: LK | E22: 1 | F22: 0 | G22: 1 | H22: 0 | I22: 0 | J22: 0 | K22: 2 | L22: 3 | M22: 0 | N22: 0 | O22: 0 | P22: 0 | Q22: 0 | R22: 0 | S22: =SUM(E22:R22) -> 7
D23: PR | E23: 1 | F23: 0 | G23: 0 | H23: 0 | I23: 0 | J23: 0 | K23: 0 | L23: 1 | M23: 1 | N23: 0 | O23: 1 | P23: 1 | Q23: 1 | R23: 0 | S23: =SUM(E23:R23) -> 6
D24: JML | E24: =SUM(E22:E23) -> 2 | F24: =SUM(F22:F23) -> 0 | G24: =SUM(G22:G23) -> 1 | H24: =SUM(H22:H23) -> 0 | I24: =SUM(I22:I23) -> 0 | J24: =SUM(J22:J23) -> 0 | K24: =SUM(K22:K23) -> 2 | L24: =SUM(L22:L23) -> 4 | ... R24: =SUM(R22:R23) -> 0 | S24: =SUM(E24:R24) -> 13
B25: 3. | C25: Jumlah pengguna hak pilih dalam Daftar Pemilih Khusus (DPK) | D25: LK | E25: 0 | F25: 0 | G25: 0 | H25: 0 | I25: 0 | J25: 0 | K25: 0 | L25: 3 | M25: 0 | N25: 0 | O25: 3 | P25: 0 | Q25: 0 | R25: 0 | S25: =SUM(E25:R25) -> 6
D26: PR | E26: 0 | F26: 0 | G26: 0 | H26: 1 | I26: 0 | J26: 0 | K26: 1 | L26: 1 | M26: 3 | N26: 0 | O26: 3 | P26: 3 | Q26: 0 | R26: 0 | S26: =SUM(E26:R26) -> 12
D27: JML | E27: =SUM(E25:E26) -> 0 | F27: =SUM(F25:F26) -> 0 | G27: =SUM(G25:G26) -> 0 | H27: =SUM(H25:H26) -> 1 | I27: =SUM(I25:I26) -> 0 | J27: =SUM(J25:J26) -> 0 | K27: =SUM(K25:K26) -> 1 | L27: =SUM(L25:L26) -> 4 | ... R27: =SUM(R25:R26) -> 0 | S27: =SUM(E27:R27) -> 18
B28: 4. | C28: Jumlah Pengguna Hak Pilih (B.1+B.2+B.3) | D28: LK | E28: =SUM(E19,E22,E25) -> 86 | F28: =SUM(F19,F22,F25) -> 60 | G28: =SUM(G19,G22,G25) -> 74 | H28: =SUM(H19,H22,H25) -> 92 | I28: =SUM(I19,I22,I25) -> 96 | J28: =SUM(J19,J22,J25) -> 94 | K28: =SUM(K19,K22,K25) -> 102 | L28: =SUM(L19,L22,L25) -> 83 | ... R28: =SUM(R19,R22,R25) -> 74 | S28: =SUM(E28:R28) -> 1266
D29: PR | E29: =SUM(E20,E23,E26) -> 89 | F29: =SUM(F20,F23,F26) -> 72 | G29: =SUM(G20,G23,G26) -> 85 | H29: =SUM(H20,H23,H26) -> 101 | I29: =SUM(I20,I23,I26) -> 108 | J29: =SUM(J20,J23,J26) -> 89 | K29: =SUM(K20,K23,K26) -> 114 | L29: =SUM(L20,L23,L26) -> 98 | ... R29: =SUM(R20,R23,R26) -> 65 | S29: =SUM(E29:R29) -> 1350
D30: JML | E30: =SUM(E28:E29) -> 175 | F30: =SUM(F28:F29) -> 132 | G30: =SUM(G28:G29) -> 159 | H30: =SUM(H28:H29) -> 193 | I30: =SUM(I28:I29) -> 204 | J30: =SUM(J28:J29) -> 183 | K30: =SUM(K28:K29) -> 216 | L30: =SUM(L28:L29) -> 181 | ... R30: =SUM(R28:R29) -> 139 | S30: =SUM(E30:R30) -> 2616
A32: II | B32: DATA PENGGUNAAN SURAT SUARA
A33: 1 | B33: Jumlah surat suara yang diterima, termasuk surat suara cadangan 2,5% dari DPT | E33: 339 | F33: 284 | G33: 218 | H33: 264 | I33: 269 | J33: 242 | K33: 261 | L33: 254 | M33: 279 | N33: 269 | O33: 282 | P33: 277 | Q33: 279 | R33: 189 | S33: =SUM(E33:R33) -> 3706
A34: 2 | B34: Jumlah surat suara yang digunakan | E34: 175 | F34: 132 | G34: 159 | H34: 193 | I34: 204 | J34: 183 | K34: 216 | L34: 181 | M34: 201 | N34: 217 | O34: 215 | P34: 202 | Q34: 199 | R34: 109 | S34: =SUM(E34:R34) -> 2586
A35: 3 | B35: Jumlah surat suara dikembalikan oleh pemilih (karena rusak atau keliru coblos) | E35: 0 | F35: 0 | G35: 2 | H35: 0 | I35: 0 | J35: 0 | K35: 1 | L35: 0 | M35: 0 | N35: 0 | O35: 1 | P35: 0 | Q35: 0 | R35: 0 | S35: =SUM(E35:R35) -> 4
A36: 4 | B36: Jumlah surat suara yang tidak digunakan/tidak terpakai, termasuk sisa surat suara cadangan | E36: =E33-(E34+E35) -> 164 | F36: =F33-(F34+F35) -> 152 | G36: =G33-(G34+G35) -> 57 | H36: =H33-(H34+H35) -> 71 | I36: =I33-(I34+I35) -> 65 | J36: =J33-(J34+J35) -> 59 | K36: =K33-(K34+K35) -> 44 | L36: =L33-(L34+L35) -> 73 | ... R36: =R33-(R34+R35) -> 80 | S36: =SUM(E36:R36) -> 1116
A38: III | B38: DATA PEMILIH DISABILITAS
B39: Jumlah seluruh Pemilih disabilitas yang menggunakan hak pilih | D39: LK | E39: 0 | F39: 0 | G39: 0 | H39: 0 | I39: 0 | J39: 0 | K39: 0 | L39: 0 | M39: 0 | N39: 0 | O39: 0 | P39: 0 | Q39: 1 | R39: 0 | S39: =SUM(E39:R39) -> 1
D40: PR | E40: 0 | F40: 0 | G40: 0 | H40: 0 | I40: 0 | J40: 0 | K40: 0 | L40: 0 | M40: 0 | N40: 0 | O40: 0 | P40: 0 | Q40: 0 | R40: 0 | S40: =SUM(E40:R40) -> 0
D41: JML | E41: =SUM(E39:E40) -> 0 | F41: =SUM(F39:F40) -> 0 | G41: =SUM(G39:G40) -> 0 | H41: =SUM(H39:H40) -> 0 | I41: =SUM(I39:I40) -> 0 | J41: =SUM(J39:J40) -> 0 | K41: =SUM(K39:K40) -> 0 | L41: =SUM(L39:L40) -> 0 | ... R41: =SUM(R39:R40) -> 0 | S41: =SUM(E41:R41) -> 1
A43: IV | B43: DATA RINCIAN PEROLEHAN SUARA PASANGAN CALON BUPATI DAN WAKIL BUPATI
A44: NOMOR DAN NAMA CALON
B45: 1 | C45: H. ANIES RASYID BASWEDAN, Ph.D. - Dr. (H.C.) H. A. MUHAIMIN ISKANDAR | E45: 32 | F45: 18 | G45: 21 | H45: 30 | I45: 10 | J45: 4 | K45: 26 | L45: 26 | M45: 7 | N45: 2 | O45: 7 | P45: 14 | Q45: 8 | R45: 3 | S45: =SUM(E45:R45) -> 208
B46: 2 | C46: H. PRABOWO SUBIANTO - GIBRAN RAKABUMING RAKA | E46: 133 | F46: 108 | G46: 117 | H46: 135 | I46: 160 | J46: 163 | K46: 163 | L46: 135 | M46: 165 | N46: 148 | O46: 163 | P46: 146 | Q46: 146 | R46: 127 | S46: =SUM(E46:R46) -> 2009
B47: 3 | C47: H. GANJAR PRANOWO, S.H., M.I.P. - Prof. Dr. H. M. MAHFUD MD | E47: 6 | F47: 5 | G47: 19 | H47: 25 | I47: 11 | J47: 9 | K47: 25 | L47: 16 | M47: 21 | N47: 59 | O47: 28 | P47: 37 | Q47: 43 | R47: 1 | S47: =SUM(E47:R47) -> 305
A49: V | B49: DATA SUARA SAH DAN TIDAK SAH
B50: A. | C50: JUMLAH SELURUH SUARA SAH | E50: =SUM(E45:E47) -> 171 | F50: =SUM(F45:F47) -> 131 | G50: =SUM(G45:G47) -> 157 | H50: =SUM(H45:H47) -> 190 | I50: =SUM(I45:I47) -> 181 | J50: =SUM(J45:J47) -> 176 | K50: =SUM(K45:K47) -> 214 | L50: =SUM(L45:L47) -> 177 | ... R50: =SUM(R45:R47) -> 131 | S50: =SUM(E50:R50) -> 2522
B51: B. | C51: JUMLAH SUARA TIDAK SAH | E51: 4 | F51: 1 | G51: 2 | H51: 1 | I51: 3 | J51: 7 | K51: 2 | L51: 4 | M51: 8 | N51: 9 | O51: 17 | P51: 5 | Q51: 2 | R51: 3 | S51: =SUM(E51:R51) -> 68
B52: C. | C52: JUMLAH SELURUH SUARA SAH DAN SUARA TIDAK SAH (V.A + V.B) | E52: =SUM(E50:E51) -> 175 | F52: =SUM(F50:F51) -> 132 | G52: =SUM(G50:G51) -> 159 | H52: =SUM(H50:H51) -> 191 | I52: =SUM(I50:I51) -> 184 | J52: =SUM(J50:J51) -> 183 | K52: =SUM(K50:K51) -> 216 | L52: =SUM(L50:L51) -> 181 | ... R52: =SUM(R50:R51) -> 134 | S52: =SUM(E52:R52) -> 2590

Sheet KEMIRI
C2: Kecamatan | D2: SINGOJURUH
C3: Kabupaten | D3: BANYUWANGI
C4: Provinsi | D4: JAWA TIMUR
C9: Kelurahan | D9: KEMIRI
A12: I | B12: DATA PEMILIH DAN PENGGUNAAN HAK PILIH | U12: JUMLAH AKHIR
A13: A | B13: DATA PEMILIH | E13: TPS 001 | F13: TPS 002 | G13: TPS 003 | H13: TPS 004 | I13: TPS 005 | J13: TPS 006 | K13: TPS 007 | L13: TPS 008 | M13: TPS 009 | N13: TPS 010 | O13: TPS 011 | P13: TPS 012 | Q13: TPS 013 | R13: TPS 014 | S13: TPS 015 | T13: TPS 016
B14: Jumlah Pemilih dalam Daftar Pemilih Tetap (DPT) | D14: LK | E14: 118 | F14: 114 | G14: 110 | H14: 97 | I14: 115 | J14: 147 | K14: 110 | L14: 151 | M14: 134 | N14: 136 | O14: 132 | P14: 118 | Q14: 120 | R14: 125 | S14: 138 | T14: 113 | U14: =SUM(E14:T14) -> 1978
D15: PR | E15: 114 | F15: 126 | G15: 114 | H15: 93 | I15: 112 | J15: 148 | K15: 113 | L15: 130 | M15: 146 | N15: 140 | O15: 139 | P15: 115 | Q15: 119 | R15: 120 | S15: 126 | T15: 128 | U15: =SUM(E15:T15) -> 1983
D16: JML | E16: =SUM(E14:E15) -> 232 | F16: =SUM(F14:F15) -> 240 | G16: =SUM(G14:G15) -> 224 | H16: =SUM(H14:H15) -> 190 | I16: =SUM(I14:I15) -> 227 | J16: =SUM(J14:J15) -> 295 | K16: =SUM(K14:K15) -> 223 | L16: =SUM(L14:L15) -> 281 | ... T16: =SUM(T14:T15) -> 241 | U16: =SUM(E16:T16) -> 3961
A18: B | B18: PENGGUNA HAK PILIH
B19: 1. | C19: Jumlah pengguna hak pilih dalam Daftar Pemilih Tetap (DPT) | D19: LK | E19: 78 | F19: 84 | G19: 80 | H19: 57 | I19: 69 | J19: 94 | K19: 81 | L19: 107 | M19: 86 | N19: 87 | O19: 78 | P19: 84 | Q19: 77 | R19: 87 | S19: 93 | T19: 74 | U19: =SUM(E19:T19) -> 1316
D20: PR | E20: 74 | F20: 95 | G20: 88 | H20: 63 | I20: 88 | J20: 103 | K20: 83 | L20: 106 | M20: 110 | N20: 109 | O20: 92 | P20: 86 | Q20: 90 | R20: 92 | S20: 108 | T20: 95 | U20: =SUM(E20:T20) -> 1482
D21: JML | E21: =SUM(E19:E20) -> 152 | F21: =SUM(F19:F20) -> 179 | G21: =SUM(G19:G20) -> 168 | H21: =SUM(H19:H20) -> 120 | I21: =SUM(I19:I20) -> 157 | J21: =SUM(J19:J20) -> 197 | K21: =SUM(K19:K20) -> 164 | L21: =SUM(L19:L20) -> 213 | ... T21: =SUM(T19:T20) -> 169 | U21: =SUM(E21:T21) -> 2798
B22: 2. | C22: Jumlah pengguna hak pilih dalam Daftar Pemilih Tambahan (DPTb) | D22: LK | E22: 1 | F22: 0 | G22: 0 | H22: 0 | I22: 0 | J22: 0 | K22: 0 | L22: 1 | M22: 0 | N22: 0 | O22: 2 | P22: 0 | Q22: 1 | R22: 0 | S22: 2 | U22: =SUM(E22:T22) -> 7
D23: PR | E23: 2 | F23: 0 | G23: 0 | H23: 1 | I23: 0 | J23: 0 | K23: 0 | L23: 0 | M23: 0 | N23: 0 | O23: 0 | P23: 0 | Q23: 1 | R23: 1 | S23: 1 | U23: =SUM(E23:T23) -> 6
D24: JML | E24: =SUM(E22:E23) -> 3 | F24: =SUM(F22:F23) -> 0 | G24: =SUM(G22:G23) -> 0 | H24: =SUM(H22:H23) -> 1 | I24: =SUM(I22:I23) -> 0 | J24: =SUM(J22:J23) -> 0 | K24: =SUM(K22:K23) -> 0 | L24: =SUM(L22:L23) -> 1 | ... T24: =SUM(T22:T23) -> 0 | U24: =SUM(E24:T24) -> 13
B25: 3. | C25: Jumlah pengguna hak pilih dalam Daftar Pemilih Khusus (DPK) | D25: LK | E25: 0 | F25: 1 | G25: 1 | H25: 0 | I25: 0 | J25: 0 | K25: 4 | L25: 0 | M25: 3 | N25: 2 | O25: 0 | P25: 1 | Q25: 0 | R25: 1 | S25: 1 | U25: =SUM(E25:T25) -> 14
D26: PR | E26: 1 | F26: 0 | G26: 1 | H26: 1 | I26: 1 | J26: 0 | K26: 4 | L26: 0 | M26: 0 | N26: 1 | O26: 0 | P26: 2 | Q26: 0 | R26: 3 | S26: 4 | U26: =SUM(E26:T26) -> 18
D27: JML | E27: =SUM(E25:E26) -> 1 | F27: =SUM(F25:F26) -> 1 | G27: =SUM(G25:G26) -> 2 | H27: =SUM(H25:H26) -> 1 | I27: =SUM(I25:I26) -> 1 | J27: =SUM(J25:J26) -> 0 | K27: =SUM(K25:K26) -> 8 | L27: =SUM(L25:L26) -> 0 | ... T27: =SUM(T25:T26) -> 0 | U27: =SUM(E27:T27) -> 32
B28: 4. | C28: Jumlah Pengguna Hak Pilih (B.1+B.2+B.3) | D28: LK | E28: =SUM(E19,E22,E25) -> 79 | F28: =SUM(F19,F22,F25) -> 85 | G28: =SUM(G19,G22,G25) -> 81 | H28: =SUM(H19,H22,H25) -> 57 | I28: =SUM(I19,I22,I25) -> 69 | J28: =SUM(J19,J22,J25) -> 94 | K28: =SUM(K19,K22,K25) -> 85 | L28: =SUM(L19,L22,L25) -> 108 | ... T28: =SUM(T19,T22,T25) -> 74 | U28: =SUM(E28:T28) -> 1337
D29: PR | E29: =SUM(E20,E23,E26) -> 77 | F29: =SUM(F20,F23,F26) -> 95 | G29: =SUM(G20,G23,G26) -> 89 | H29: =SUM(H20,H23,H26) -> 65 | I29: =SUM(I20,I23,I26) -> 89 | J29: =SUM(J20,J23,J26) -> 103 | K29: =SUM(K20,K23,K26) -> 87 | L29: =SUM(L20,L23,L26) -> 106 | ... T29: =SUM(T20,T23,T26) -> 95 | U29: =SUM(E29:T29) -> 1506
D30: JML | E30: =SUM(E28:E29) -> 156 | F30: =SUM(F28:F29) -> 180 | G30: =SUM(G28:G29) -> 170 | H30: =SUM(H28:H29) -> 122 | I30: =SUM(I28:I29) -> 158 | J30: =SUM(J28:J29) -> 197 | K30: =SUM(K28:K29) -> 172 | L30: =SUM(L28:L29) -> 214 | ... T30: =SUM(T28:T29) -> 169 | U30: =SUM(E30:T30) -> 2843
A32: II | B32: DATA PENGGUNAAN SURAT SUARA
A33: 1 | B33: Jumlah surat suara yang diterima, termasuk surat suara cadangan 2,5% dari DPT | E33: 227 | F33: 235 | G33: 219 | H33: 183 | I33: 212 | J33: 190 | K33: 224 | L33: 278 | M33: 277 | N33: 272 | O33: 265 | P33: 228 | Q33: 233 | R33: 240 | S33: 250 | T33: 237 | U33: =SUM(E33:T33) -> 3770
A34: 2 | B34: Jumlah surat suara yang digunakan | E34: 156 | F34: 180 | G34: 170 | H34: 122 | I34: 158 | J34: 197 | K34: 172 | L34: 214 | M34: 199 | N34: 201 | O34: 172 | P34: 173 | Q34: 169 | R34: 154 | S34: 208 | T34: 189 | U34: =SUM(E34:T34) -> 2834
A35: 3 | B35: Jumlah surat suara dikembalikan oleh pemilih (karena rusak atau keliru coblos) | E35: 0 | F35: 0 | G35: 0 | H35: 0 | I35: 0 | J35: 0 | K35: 1 | L35: 0 | M35: 0 | N35: 0 | O35: 0 | P35: 0 | Q35: 0 | R35: 2 | S35: 0 | U35: =SUM(E35:T35) -> 3
A36: 4 | B36: Jumlah surat suara yang tidak digunakan/tidak terpakai, termasuk sisa surat suara cadangan | E36: =E33-(E34+E35) -> 71 | F36: =F33-(F34+F35) -> 55 | G36: =G33-(G34+G35) -> 49 | H36: =H33-(H34+H35) -> 61 | I36: =I33-(I34+I35) -> 54 | J36: =J33-(J34+J35) -> -7 | K36: =K33-(K34+K35) -> 51 | L36: =L33-(L34+L35) -> 64 | ... T36: =T33-(T34+T35) -> 48 | U36: =SUM(E36:T36) -> 933
A38: III | B38: DATA PEMILIH DISABILITAS
B39: Jumlah seluruh Pemilih disabilitas yang menggunakan hak pilih | D39: LK | E39: 0 | F39: 0 | G39: 3 | H39: 0 | I39: 1 | J39: 0 | K39: 0 | L39: 2 | M39: 0 | N39: 0 | O39: 0 | P39: 0 | Q39: 0 | R39: 0 | S39: 0 | U39: =SUM(E39:T39) -> 6
D40: PR | E40: 1 | F40: 1 | G40: 1 | H40: 0 | I40: 0 | J40: 0 | K40: 0 | L40: 0 | M40: 0 | N40: 0 | O40: 0 | P40: 0 | Q40: 1 | R40: 0 | S40: 0 | U40: =SUM(E40:T40) -> 4
D41: JML | E41: =SUM(E39:E40) -> 1 | F41: =SUM(F39:F40) -> 1 | G41: =SUM(G39:G40) -> 4 | H41: =SUM(H39:H40) -> 0 | I41: =SUM(I39:I40) -> 1 | J41: =SUM(J39:J40) -> 0 | K41: =SUM(K39:K40) -> 0 | L41: =SUM(L39:L40) -> 2 | ... T41: =SUM(T39:T40) -> 0 | U41: =SUM(E41:T41) -> 10
A43: IV | B43: DATA RINCIAN PEROLEHAN SUARA PASANGAN CALON BUPATI DAN WAKIL BUPATI
A44: NOMOR DAN NAMA CALON
B45: 1 | C45: H. ANIES RASYID BASWEDAN, Ph.D. - Dr. (H.C.) H. A. MUHAIMIN ISKANDAR | E45: 22 | F45: 14 | G45: 13 | H45: 16 | I45: 7 | J45: 22 | K45: 15 | L45: 8 | M45: 18 | N45: 12 | O45: 26 | P45: 31 | Q45: 19 | R45: 7 | S45: 20 | T45: 12 | U45: =SUM(E45:T45) -> 262
B46: 2 | C46: H. PRABOWO SUBIANTO - GIBRAN RAKABUMING RAKA | E46: 103 | F46: 123 | G46: 128 | H46: 79 | I46: 117 | J46: 140 | K46: 124 | L46: 131 | M46: 138 | N46: 157 | O46: 119 | P46: 121 | Q46: 137 | R46: 153 | S46: 135 | T46: 127 | U46: =SUM(E46:T46) -> 2032
B47: 3 | C47: H. GANJAR PRANOWO, S.H., M.I.P. - Prof. Dr. H. M. MAHFUD MD | E47: 29 | F47: 39 | G47: 28 | H47: 35 | I47: 32 | J47: 34 | K47: 27 | L47: 44 | M47: 22 | N47: 27 | O47: 23 | P47: 19 | Q47: 12 | R47: 19 | S47: 21 | T47: 36 | U47: =SUM(E47:T47) -> 447
A49: V | B49: DATA SUARA SAH DAN TIDAK SAH
B50: A. | C50: JUMLAH SELURUH SUARA SAH | E50: =SUM(E45:E47) -> 154 | F50: =SUM(F45:F47) -> 176 | G50: =SUM(G45:G47) -> 169 | H50: =SUM(H45:H47) -> 130 | I50: =SUM(I45:I47) -> 156 | J50: =SUM(J45:J47) -> 196 | K50: =SUM(K45:K47) -> 166 | L50: =SUM(L45:L47) -> 183 | ... T50: =SUM(T45:T47) -> 175 | U50: =SUM(E50:T50) -> 2741
B51: B. | C51: JUMLAH SUARA TIDAK SAH | E51: 2 | F51: 4 | G51: 4 | H51: 2 | I51: 3 | J51: 1 | K51: 8 | L51: 11 | M51: 8 | N51: 5 | O51: 4 | P51: 2 | Q51: 1 | R51: 5 | S51: 4 | T51: 4 | U51: =SUM(E51:T51) -> 68
B52: C. | C52: JUMLAH SELURUH SUARA SAH DAN SUARA TIDAK SAH (V.A + V.B) | E52: =SUM(E50:E51) -> 156 | F52: =SUM(F50:F51) -> 180 | G52: =SUM(G50:G51) -> 173 | H52: =SUM(H50:H51) -> 132 | I52: =SUM(I50:I51) -> 159 | J52: =SUM(J50:J51) -> 197 | K52: =SUM(K50:K51) -> 174 | L52: =SUM(L50:L51) -> 194 | ... T52: =SUM(T50:T51) -> 179 | U52: =SUM(E52:T52) -> 2809

Sheet LEMAHBANGKULON
C2: Kecamatan | D2: SINGOJURUH
C3: Kabupaten | D3: BANYUWANGI
C4: Provinsi | D4: JAWA TIMUR
C9: Kelurahan | D9: LEMAHBANGKULON
A12: I | B12: DATA PEMILIH DAN PENGGUNAAN HAK PILIH | Q12: JUMLAH AKHIR
A13: A | B13: DATA PEMILIH | E13: TPS 001 | F13: TPS 002 | G13: TPS 003 | H13: TPS 004 | I13: TPS 005 | J13: TPS 006 | K13: TPS 007 | L13: TPS 008 | M13: TPS 009 | N13: TPS 010 | O13: TPS 011 | P13: TPS 012
B14: Jumlah Pemilih dalam Daftar Pemilih Tetap (DPT) | D14: LK | E14: 124 | F14: 96 | G14: 127 | H14: 128 | I14: 121 | J14: 117 | K14: 127 | L14: 141 | M14: 108 | N14: 125 | O14: 84 | P14: 68 | Q14: =SUM(E14:P14) -> 1366
D15: PR | E15: 125 | F15: 98 | G15: 137 | H15: 122 | I15: 141 | J15: 139 | K15: 142 | L15: 138 | M15: 119 | N15: 141 | O15: 99 | P15: 83 | Q15: =SUM(E15:P15) -> 1484
D16: JML | E16: =SUM(E14:E15) -> 249 | F16: =SUM(F14:F15) -> 194 | G16: =SUM(G14:G15) -> 264 | H16: =SUM(H14:H15) -> 250 | I16: =SUM(I14:I15) -> 262 | J16: =SUM(J14:J15) -> 256 | K16: =SUM(K14:K15) -> 269 | L16: =SUM(L14:L15) -> 279 | ... P16: =SUM(P14:P15) -> 151 | Q16: =SUM(E16:P16) -> 2850
A18: B | B18: PENGGUNA HAK PILIH
B19: 1. | C19: Jumlah pengguna hak pilih dalam Daftar Pemilih Tetap (DPT) | D19: LK | E19: 85 | F19: 79 | G19: 88 | H19: 86 | I19: 93 | J19: 76 | K19: 105 | L19: 108 | M19: 75 | N19: 94 | O19: 62 | P19: 54 | Q19: =SUM(E19:P19) -> 1005
D20: PR | E20: 101 | F20: 79 | G20: 101 | H20: 94 | I20: 110 | J20: 111 | K20: 124 | L20: 105 | M20: 98 | N20: 106 | O20: 80 | P20: 62 | Q20: =SUM(E20:P20) -> 1171
D21: JML | E21: =SUM(E19:E20) -> 186 | F21: =SUM(F19:F20) -> 158 | G21: =SUM(G19:G20) -> 189 | H21: =SUM(H19:H20) -> 180 | I21: =SUM(I19:I20) -> 203 | J21: =SUM(J19:J20) -> 187 | K21: =SUM(K19:K20) -> 229 | L21: =SUM(L19:L20) -> 213 | ... P21: =SUM(P19:P20) -> 116 | Q21: =SUM(E21:P21) -> 2176
B22: 2. | C22: Jumlah pengguna hak pilih dalam Daftar Pemilih Tambahan (DPTb) | D22: LK | E22: 0 | F22: 0 | G22: 0 | H22: 0 | I22: 0 | J22: 1 | K22: 0 | L22: 1 | M22: 2 | N22: 4 | O22: 0 | P22: 1 | Q22: =SUM(E22:P22) -> 9
D23: PR | E23: 0 | F23: 1 | G23: 0 | H23: 0 | I23: 0 | J23: 1 | K23: 0 | L23: 0 | M23: 1 | N23: 3 | O23: 0 | P23: 0 | Q23: =SUM(E23:P23) -> 6
D24: JML | E24: =SUM(E22:E23) -> 0 | F24: =SUM(F22:F23) -> 1 | G24: =SUM(G22:G23) -> 0 | H24: =SUM(H22:H23) -> 0 | I24: =SUM(I22:I23) -> 0 | J24: =SUM(J22:J23) -> 2 | K24: =SUM(K22:K23) -> 0 | L24: =SUM(L22:L23) -> 1 | ... P24: =SUM(P22:P23) -> 1 | Q24: =SUM(E24:P24) -> 15
B25: 3. | C25: Jumlah pengguna hak pilih dalam Daftar Pemilih Khusus (DPK) | D25: LK | E25: 0 | F25: 2 | G25: 2 | H25: 1 | I25: 0 | J25: 1 | K25: 0 | L25: 0 | M25: 0 | N25: 0 | O25: 0 | P25: 1 | Q25: =SUM(E25:P25) -> 7
D26: PR | E26: 0 | F26: 0 | G26: 2 | H26: 0 | I26: 0 | J26: 1 | K26: 1 | L26: 0 | M26: 1 | N26: 0 | O26: 2 | P26: 1 | Q26: =SUM(E26:P26) -> 8
D27: JML | E27: =SUM(E25:E26) -> 0 | F27: =SUM(F25:F26) -> 2 | G27: =SUM(G25:G26) -> 4 | H27: =SUM(H25:H26) -> 1 | I27: =SUM(I25:I26) -> 0 | J27: =SUM(J25:J26) -> 2 | K27: =SUM(K25:K26) -> 1 | L27: =SUM(L25:L26) -> 0 | ... P27: =SUM(P25:P26) -> 2 | Q27: =SUM(E27:P27) -> 15
B28: 4. | C28: Jumlah Pengguna Hak Pilih (B.1+B.2+B.3) | D28: LK | E28: =SUM(E19,E22,E25) -> 85 | F28: =SUM(F19,F22,F25) -> 81 | G28: =SUM(G19,G22,G25) -> 90 | H28: =SUM(H19,H22,H25) -> 87 | I28: =SUM(I19,I22,I25) -> 93 | J28: =SUM(J19,J22,J25) -> 78 | K28: =SUM(K19,K22,K25) -> 105 | L28: =SUM(L19,L22,L25) -> 109 | ... P28: =SUM(P19,P22,P25) -> 56 | Q28: =SUM(E28:P28) -> 1021
D29: PR | E29: =SUM(E20,E23,E26) -> 101 | F29: =SUM(F20,F23,F26) -> 80 | G29: =SUM(G20,G23,G26) -> 103 | H29: =SUM(H20,H23,H26) -> 94 | I29: =SUM(I20,I23,I26) -> 110 | J29: =SUM(J20,J23,J26) -> 113 | K29: =SUM(K20,K23,K26) -> 125 | L29: =SUM(L20,L23,L26) -> 105 | ... P29: =SUM(P20,P23,P26) -> 63 | Q29: =SUM(E29:P29) -> 1185
D30: JML | E30: =SUM(E28:E29) -> 186 | F30: =SUM(F28:F29) -> 161 | G30: =SUM(G28:G29) -> 193 | H30: =SUM(H28:H29) -> 181 | I30: =SUM(I28:I29) -> 203 | J30: =SUM(J28:J29) -> 191 | K30: =SUM(K28:K29) -> 230 | L30: =SUM(L28:L29) -> 214 | ... P30: =SUM(P28:P29) -> 119 | Q30: =SUM(E30:P30) -> 2206
A32: II | B32: DATA PENGGUNAAN SURAT SUARA
A33: 1 | B33: Jumlah surat suara yang diterima, termasuk surat suara cadangan 2,5% dari DPT | E33: 252 | F33: 198 | G33: 266 | H33: 252 | I33: 266 | J33: 283 | K33: 269 | L33: 283 | M33: 220 | N33: 269 | O33: 184 | P33: 154 | Q33: =SUM(E33:P33) -> 2896
A34: 2 | B34: Jumlah surat suara yang digunakan | E34: 186 | F34: 161 | G34: 193 | H34: 181 | I34: 203 | J34: 191 | K34: 230 | L34: 214 | M34: 177 | N34: 207 | O34: 144 | P34: 119 | Q34: =SUM(E34:P34) -> 2206
A35: 3 | B35: Jumlah surat suara dikembalikan oleh pemilih (karena rusak atau keliru coblos) | E35: 0 | F35: 0 | G35: 0 | H35: 0 | I35: 0 | J35: 3 | K35: 4 | L35: 0 | M35: 0 | N35: 0 | O35: 0 | P35: 0 | Q35: =SUM(E35:P35) -> 7
A36: 4 | B36: Jumlah surat suara yang tidak digunakan/tidak terpakai, termasuk sisa surat suara cadangan | E36: =E33-(E34+E35) -> 66 | F36: =F33-(F34+F35) -> 37 | G36: =G33-(G34+G35) -> 73 | H36: =H33-(H34+H35) -> 71 | I36: =I33-(I34+I35) -> 63 | J36: =J33-(J34+J35) -> 89 | K36: =K33-(K34+K35) -> 35 | L36: =L33-(L34+L35) -> 69 | ... P36: =P33-(P34+P35) -> 35 | Q36: =SUM(E36:P36) -> 683
A38: III | B38: DATA PEMILIH DISABILITAS
B39: Jumlah seluruh Pemilih disabilitas yang menggunakan hak pilih | D39: LK | E39: 0 | F39: 2 | G39: 0 | H39: 0 | I39: 0 | J39: 0 | K39: 0 | L39: 0 | M39: 0 | N39: 1 | O39: 0 | P39: 0 | Q39: =SUM(E39:P39) -> 3
D40: PR | E40: 0 | F40: 0 | G40: 0 | H40: 0 | I40: 0 | J40: 4 | K40: 0 | L40: 0 | M40: 0 | N40: 4 | O40: 0 | P40: 0 | Q40: =SUM(E40:P40) -> 8
D41: JML | E41: =SUM(E39:E40) -> 0 | F41: =SUM(F39:F40) -> 2 | G41: =SUM(G39:G40) -> 0 | H41: =SUM(H39:H40) -> 0 | I41: =SUM(I39:I40) -> 0 | J41: =SUM(J39:J40) -> 4 | K41: =SUM(K39:K40) -> 0 | L41: =SUM(L39:L40) -> 0 | ... P41: =SUM(P39:P40) -> 0 | Q41: =SUM(E41:P41) -> 11
A43: IV | B43: DATA RINCIAN PEROLEHAN SUARA PASANGAN CALON BUPATI DAN WAKIL BUPATI
A44: NOMOR DAN NAMA CALON
B45: 1 | C45: H. ANIES RASYID BASWEDAN, Ph.D. - Dr. (H.C.) H. A. MUHAIMIN ISKANDAR | E45: 11 | F45: 14 | G45: 15 | H45: 19 | I45: 20 | J45: 14 | K45: 21 | L45: 13 | M45: 27 | N45: 19 | O45: 8 | P45: 15 | Q45: =SUM(E45:P45) -> 196
B46: 2 | C46: H. PRABOWO SUBIANTO - GIBRAN RAKABUMING RAKA | E46: 133 | F46: 110 | G46: 135 | H46: 113 | I46: 114 | J46: 135 | K46: 144 | L46: 113 | M46: 106 | N46: 134 | O46: 91 | P46: 72 | Q46: =SUM(E46:P46) -> 1400
B47: 3 | C47: H. GANJAR PRANOWO, S.H., M.I.P. - Prof. Dr. H. M. MAHFUD MD | E47: 31 | F47: 34 | G47: 35 | H47: 46 | I47: 33 | J47: 39 | K47: 60 | L47: 26 | M47: 39 | N47: 50 | O47: 42 | P47: 28 | Q47: =SUM(E47:P47) -> 463
A49: V | B49: DATA SUARA SAH DAN TIDAK SAH
B50: A. | C50: JUMLAH SELURUH SUARA SAH | E50: =SUM(E45:E47) -> 175 | F50: =SUM(F45:F47) -> 158 | G50: =SUM(G45:G47) -> 185 | H50: =SUM(H45:H47) -> 178 | I50: =SUM(I45:I47) -> 167 | J50: =SUM(J45:J47) -> 188 | K50: =SUM(K45:K47) -> 225 | L50: =SUM(L45:L47) -> 152 | ... P50: =SUM(P45:P47) -> 115 | Q50: =SUM(E50:P50) -> 2059
B51: B. | C51: JUMLAH SUARA TIDAK SAH | E51: 10 | F51: 3 | G51: 4 | H51: 3 | I51: 1 | J51: 3 | K51: 1 | L51: 2 | M51: 5 | N51: 4 | O51: 2 | P51: 4 | Q51: =SUM(E51:P51) -> 42
B52: C. | C52: JUMLAH SELURUH SUARA SAH DAN SUARA TIDAK SAH (V.A + V.B) | E52: =SUM(E50:E51) -> 185 | F52: =SUM(F50:F51) -> 161 | G52: =SUM(G50:G51) -> 189 | H52: =SUM(H50:H51) -> 181 | I52: =SUM(I50:I51) -> 168 | J52: =SUM(J50:J51) -> 191 | K52: =SUM(K50:K51) -> 226 | L52: =SUM(L50:L51) -> 154 | ... P52: =SUM(P50:P51) -> 119 | Q52: =SUM(E52:P52) -> 2101

Sheet PADANG
C2: Kecamatan | D2: SINGOJURUH
C3: Kabupaten | D3: BANYUWANGI
C4: Provinsi | D4: JAWA TIMUR
C9: Kelurahan | D9: PADANG
A12: I | B12: DATA PEMILIH DAN PENGGUNAAN HAK PILIH | Q12: JUMLAH AKHIR
A13: A | B13: DATA PEMILIH | E13: TPS 001 | F13: TPS 002 | G13: TPS 003 | H13: TPS 004 | I13: TPS 005 | J13: TPS 006 | K13: TPS 007 | L13: TPS 008 | M13: TPS 009 | N13: TPS 010 | O13: TPS 011 | P13: TPS 012
