Workbook

Sheet PPWP
C8: Kecamatan | D8: PESANGGARAN
C9: Kabupaten | D9: BANYUWANGI
C10: Provinsi | D10: JAWA TIMUR
A12: I | B12: DATA PEMILIH DAN PENGGUNAAN HAK PILIH | E12: JUMLAH AKHIR
A13: A | B13: DATA PEMILIH
B14: Jumlah Pemilih dalam Daftar Pemilih Tetap (DPT) | D14: LK | E14: =KANDANGAN!AG14+PESANGGARAN!AZ14+SARONGAN!X14+SUMBERAGUNG!AX14+SUMBERMULYO!AB14 -> 21449
D15: PR | E15: =KANDANGAN!AG15+PESANGGARAN!AZ15+SARONGAN!X15+SUMBERAGUNG!AX15+SUMBERMULYO!AB15 -> 21441
D16: JML | E16: =SUM(E14:E15) -> 42890
A18: B | B18: PENGGUNA HAK PILIH
B19: 1. | C19: Jumlah pengguna hak pilih dalam Daftar Pemilih Tetap (DPT) | D19: LK | E19: =KANDANGAN!AG19+PESANGGARAN!AZ19+SARONGAN!X19+SUMBERAGUNG!AX19+SUMBERMULYO!AB19 -> 16133
D20: PR | E20: =KANDANGAN!AG20+PESANGGARAN!AZ20+SARONGAN!X20+SUMBERAGUNG!AX20+SUMBERMULYO!AB20 -> 16445
D21: JML | E21: =SUM(E19:E20) -> 32578
B22: 2. | C22: Jumlah pengguna hak pilih dalam Daftar Pemilih Tambahan (DPTb) | D22: LK | E22: =KANDANGAN!AG22+PESANGGARAN!AZ22+SARONGAN!X22+SUMBERAGUNG!AX22+SUMBERMULYO!AB22 -> 245
D23: PR | E23: =KANDANGAN!AG23+PESANGGARAN!AZ23+SARONGAN!X23+SUMBERAGUNG!AX23+SUMBERMULYO!AB23 -> 52
D24: JML | E24: =SUM(E22:E23) -> 297
B25: 3. | C25: Jumlah pengguna hak pilih dalam Daftar Pemilih Khusus (DPK) | D25: LK | E25: =KANDANGAN!AG25+PESANGGARAN!AZ25+SARONGAN!X25+SUMBERAGUNG!AX25+SUMBERMULYO!AB25 -> 291
D26: PR | E26: =KANDANGAN!AG26+PESANGGARAN!AZ26+SARONGAN!X26+SUMBERAGUNG!AX26+SUMBERMULYO!AB26 -> 307
D27: JML | E27: =SUM(E25:E26) -> 598
B28: 4. | C28: Jumlah Pengguna Hak Pilih (B.1+B.2+B.3) | D28: LK | E28: =E19+E22+E25 -> 16669
D29: PR | E29: =E20+E23+E26 -> 16804
D30: JML | E30: =SUM(E28:E29) -> 33473
A32: II | B32: DATA PENGGUNAAN SURAT SUARA
A33: 1 | B33: Jumlah surat suara yang diterima, termasuk surat suara cadangan 2,5% dari DPT | E33: =KANDANGAN!AG33+PESANGGARAN!AZ33+SARONGAN!X33+SUMBERAGUNG!AX33+SUMBERMULYO!AB33 -> 43866
A34: 2 | B34: Jumlah surat suara yang digunakan | E34: =KANDANGAN!AG34+PESANGGARAN!AZ34+SARONGAN!X34+SUMBERAGUNG!AX34+SUMBERMULYO!AB34 -> 33477
A35: 3 | B35: Jumlah surat suara dikembalikan oleh pemilih (karena rusak atau keliru coblos) | E35: =KANDANGAN!AG35+PESANGGARAN!AZ35+SARONGAN!X35+SUMBERAGUNG!AX35+SUMBERMULYO!AB35 -> 47
A36: 4 | B36: Jumlah surat suara yang tidak digunakan/tidak terpakai, termasuk sisa surat suara cadangan | E36: =E33-(E34+E35) -> 10342
A38: III | B38: DATA PEMILIH DISABILITAS
B39: Jumlah seluruh Pemilih disabilitas yang menggunakan hak pilih | D39: LK | E39: =KANDANGAN!AG39+PESANGGARAN!AZ39+SARONGAN!X39+SUMBERAGUNG!AX39+SUMBERMULYO!AB39 -> 30
D40: PR | E40: =KANDANGAN!AG40+PESANGGARAN!AZ40+SARONGAN!X40+SUMBERAGUNG!AX40+SUMBERMULYO!AB40 -> 23
D41: JML | E41: =SUM(E39:E40) -> 53
A43: IV | B43: DATA RINCIAN PEROLEHAN SUARA PASANGAN CALON BUPATI DAN WAKIL BUPATI
A44: NOMOR DAN NAMA CALON
B45: 1 | C45: H. ANIES RASYID BASWEDAN, Ph.D. - Dr. (H.C.) H. A. MUHAIMIN ISKANDAR | E45: =KANDANGAN!AG45+PESANGGARAN!AZ45+SARONGAN!X45+SUMBERAGUNG!AX45+SUMBERMULYO!AB45 -> 2227
B46: 2 | C46: H. PRABOWO SUBIANTO - GIBRAN RAKABUMING RAKA | E46: =KANDANGAN!AG46+PESANGGARAN!AZ46+SARONGAN!X46+SUMBERAGUNG!AX46+SUMBERMULYO!AB46 -> 23095
B47: 3 | C47: H. GANJAR PRANOWO, S.H., M.I.P. - Prof. Dr. H. M. MAHFUD MD | E47: =KANDANGAN!AG47+PESANGGARAN!AZ47+SARONGAN!X47+SUMBERAGUNG!AX47+SUMBERMULYO!AB47 -> 7637
A49: V | B49: DATA SUARA SAH DAN TIDAK SAH
B50: A. | C50: JUMLAH SELURUH SUARA SAH | E50: =KANDANGAN!AG50+PESANGGARAN!AZ50+SARONGAN!X50+SUMBERAGUNG!AX50+SUMBERMULYO!AB50 -> 32959
B51: B. | C51: JUMLAH SUARA TIDAK SAH | E51: =KANDANGAN!AG51+PESANGGARAN!AZ51+SARONGAN!X51+SUMBERAGUNG!AX51+SUMBERMULYO!AB51 -> 515
B52: C. | C52: JUMLAH SELURUH SUARA SAH DAN SUARA TIDAK SAH (V.A + V.B) | E52: =SUM(E50:E51) -> 33474

Sheet KANDANGAN
C2: Kecamatan | D2: PESANGGARAN
C3: Kabupaten | D3: BANYUWANGI
C4: Provinsi | D4: JAWA TIMUR
C9: Kelurahan | D9: KANDANGAN
A12: I | B12: DATA PEMILIH DAN PENGGUNAAN HAK PILIH | AG12: JUMLAH AKHIR
A13: A | B13: DATA PEMILIH | E13: TPS 001 | F13: TPS 002 | G13: TPS 003 | H13: TPS 004 | I13: TPS 005 | J13: TPS 006 | K13: TPS 007 | L13: TPS 008 | M13: TPS 009 | N13: TPS 010 | O13: TPS 011 | P13: TPS 012 | Q13: TPS 013 | R13: TPS 014 | S13: TPS 015 | T13: TPS 016 | U13: TPS 017 | V13: TPS 018 | W13: TPS 019 | X13: TPS 020 | Y13: TPS 021 | Z13: TPS 022 | AA13: TPS 023 | AB13: TPS 024 | AC13: TPS 025 | AD13: TPS 026 | AE13: TPS 027 | AF13: TPS 028
B14: Jumlah Pemilih dalam Daftar Pemilih Tetap (DPT) | D14: LK | E14: 118 | F14: 98 | G14: 113 | H14: 103 | I14: 144 | J14: 150 | K14: 117 | L14: 103 | M14: 112 | N14: 125 | O14: 107 | P14: 141 | Q14: 145 | R14: 131 | S14: 94 | T14: 136 | U14: 115 | V14: 138 | W14: 154 | X14: 136 | Y14: 147 | Z14: 137 | AA14: 84 | AB14: 140 | AC14: 126 | AD14: 113 | AE14: 114 | AF14: 127 | AG14: =SUM(E14:AF14) -> 3468
D15: PR | E15: 138 | F15: 89 | G15: 118 | H15: 121 | I15: 129 | J15: 141 | K15: 102 | L15: 90 | M15: 124 | N15: 123 | O15: 115 | P15: 142 | Q15: 142 | R15: 131 | S15: 115 | T15: 147 | U15: 128 | V15: 136 | W15: 129 | X15: 140 | Y15: 148 | Z15: 130 | AA15: 105 | AB15: 139 | AC15: 119 | AD15: 119 | AE15: 108 | AF15: 119 | AG15: =SUM(E15:AF15) -> 3487
D16: JML | E16: =SUM(E14:E15) -> 256 | F16: =SUM(F14:F15) -> 187 | G16: =SUM(G14:G15) -> 231 | H16: =SUM(H14:H15) -> 224 | I16: =SUM(I14:I15) -> 273 | J16: =SUM(J14:J15) -> 291 | K16: =SUM(K14:K15) -> 219 | L16: =SUM(L14:L15) -> 193 | ... AF16: =SUM(AF14:AF15) -> 246 | AG16: =SUM(E16:AF16) -> 6955
A18: B | B18: PENGGUNA HAK PILIH
B19: 1. | C19: Jumlah pengguna hak pilih dalam Daftar Pemilih Tetap (DPT) | D19: LK | E19: 95 | F19: 82 | G19: 83 | H19: 84 | I19: 118 | J19: 121 | K19: 81 | L19: 76 | M19: 89 | N19: 88 | O19: 71 | P19: 89 | Q19: 93 | R19: 81 | S19: 60 | T19: 95 | U19: 81 | V19: 93 | W19: 110 | X19: 88 | Y19: 101 | Z19: 89 | AA19: 65 | AB19: 106 | AC19: 87 | AD19: 83 | AE19: 94 | AF19: 93 | AG19: =SUM(E19:AF19) -> 2496
D20: PR | E20: 109 | F20: 82 | G20: 91 | H20: 92 | I20: 103 | J20: 109 | K20: 80 | L20: 70 | M20: 97 | N20: 87 | O20: 80 | P20: 101 | Q20: 91 | R20: 90 | S20: 83 | T20: 92 | U20: 97 | V20: 97 | W20: 94 | X20: 95 | Y20: 104 | Z20: 85 | AA20: 79 | AB20: 104 | AC20: 84 | AD20: 91 | AE20: 91 | AF20: 93 | AG20: =SUM(E20:AF20) -> 2571
D21: JML | E21: =SUM(E19:E20) -> 204 | F21: =SUM(F19:F20) -> 164 | G21: =SUM(G19:G20) -> 174 | H21: =SUM(H19:H20) -> 176 | I21: =SUM(I19:I20) -> 221 | J21: =SUM(J19:J20) -> 230 | K21: =SUM(K19:K20) -> 161 | L21: =SUM(L19:L20) -> 146 | ... AF21: =SUM(AF19:AF20) -> 186 | AG21: =SUM(E21:AF21) -> 5067
B22: 2. | C22: Jumlah pengguna hak pilih dalam Daftar Pemilih Tambahan (DPTb) | D22: LK | E22: 0 | F22: 0 | G22: 0 | H22: 0 | I22: 0 | J22: 0 | K22: 0 | L22: 0 | M22: 0 | N22: 0 | O22: 0 | P22: 0 | Q22: 0 | R22: 0 | S22: 0 | T22: 0 | U22: 0 | V22: 0 | W22: 0 | X22: 0 | Y22: 0 | Z22: 0 | AA22: 0 | AB22: 8 | AC22: 0 | AD22: 0 | AE22: 0 | AF22: 0 | AG22: =SUM(E22:AF22) -> 8
D23: PR | E23: 0 | F23: 0 | G23: 0 | H23: 0 | I23: 0 | J23: 0 | K23: 0 | L23: 0 | M23: 0 | N23: 0 | O23: 0 | P23: 0 | Q23: 0 | R23: 0 | S23: 0 | T23: 0 | U23: 0 | V23: 0 | W23: 0 | X23: 0 | Y23: 0 | Z23: 0 | AA23: 0 | AB23: 3 | AC23: 0 | AD23: 0 | AE23: 0 | AF23: 0 | AG23: =SUM(E23:AF23) -> 3
D24: JML | E24: =SUM(E22:E23) -> 0 | F24: =SUM(F22:F23) -> 0 | G24: =SUM(G22:G23) -> 0 | H24: =SUM(H22:H23) -> 0 | I24: =SUM(I22:I23) -> 0 | J24: =SUM(J22:J23) -> 0 | K24: =SUM(K22:K23) -> 0 | L24: =SUM(L22:L23) -> 0 | ... AF24: =SUM(AF22:AF23) -> 0 | AG24: =SUM(E24:AF24) -> 11
B25: 3. | C25: Jumlah pengguna hak pilih dalam Daftar Pemilih Khusus (DPK) | D25: LK | E25: 0 | F25: 0 | G25: 0 | H25: 1 | I25: 2 | J25: 2 | K25: 0 | L25: 0 | M25: 1 | N25: 0 | O25: 0 | P25: 2 | Q25: 1 | R25: 0 | S25: 4 | T25: 12 | U25: 7 | V25: 2 | W25: 3 | X25: 1 | Y25: 0 | Z25: 9 | AA25: 8 | AB25: 3 | AC25: 8 | AD25: 0 | AE25: 0 | AF25: 2 | AG25: =SUM(E25:AF25) -> 68
D26: PR | E26: 0 | F26: 0 | G26: 0 | H26: 2 | I26: 0 | J26: 4 | K26: 4 | L26: 1 | M26: 2 | N26: 0 | O26: 0 | P26: 2 | Q26: 2 | R26: 2 | S26: 3 | T26: 9 | U26: 9 | V26: 2 | W26: 3 | X26: 3 | Y26: 2 | Z26: 8 | AA26: 8 | AB26: 2 | AC26: 10 | AD26: 0 | AE26: 0 | AF26: 5 | AG26: =SUM(E26:AF26) -> 83
D27: JML | E27: =SUM(E25:E26) -> 0 | F27: =SUM(F25:F26) -> 0 | G27: =SUM(G25:G26) -> 0 | H27: =SUM(H25:H26) -> 3 | I27: =SUM(I25:I26) -> 2 | J27: =SUM(J25:J26) -> 6 | K27: =SUM(K25:K26) -> 4 | L27: =SUM(L25:L26) -> 1 | ... AF27: =SUM(AF25:AF26) -> 7 | AG27: =SUM(E27:AF27) -> 151
B28: 4. | C28: Jumlah Pengguna Hak Pilih (B.1+B.2+B.3) | D28: LK | E28: =SUM(E19,E22,E25) -> 95 | F28: =SUM(F19,F22,F25) -> 82 | G28: =SUM(G19,G22,G25) -> 83 | H28: =SUM(H19,H22,H25) -> 85 | I28: =SUM(I19,I22,I25) -> 120 | J28: =SUM(J19,J22,J25) -> 123 | K28: =SUM(K19,K22,K25) -> 81 | L28: =SUM(L19,L22,L25) -> 76 | ... AF28: =SUM(AF19,AF22,AF25) -> 95 | AG28: =SUM(E28:AF28) -> 2572
D29: PR | E29: =SUM(E20,E23,E26) -> 109 | F29: =SUM(F20,F23,F26) -> 82 | G29: =SUM(G20,G23,G26) -> 91 | H29: =SUM(H20,H23,H26) -> 94 | I29: =SUM(I20,I23,I26) -> 103 | J29: =SUM(J20,J23,J26) -> 113 | K29: =SUM(K20,K23,K26) -> 84 | L29: =SUM(L20,L23,L26) -> 71 | ... AF29: =SUM(AF20,AF23,AF26) -> 98 | AG29: =SUM(E29:AF29) -> 2657
D30: JML | E30: =SUM(E28:E29) -> 204 | F30: =SUM(F28:F29) -> 164 | G30: =SUM(G28:G29) -> 174 | H30: =SUM(H28:H29) -> 179 | I30: =SUM(I28:I29) -> 223 | J30: =SUM(J28:J29) -> 236 | K30: =SUM(K28:K29) -> 165 | L30: =SUM(L28:L29) -> 147 | ... AF30: =SUM(AF28:AF29) -> 193 | AG30: =SUM(E30:AF30) -> 5229
A32: II | B32: DATA PENGGUNAAN SURAT SUARA
A33: 1 | B33: Jumlah surat suara yang diterima, termasuk surat suara cadangan 2,5% dari DPT | E33: 262 | F33: 191 | G33: 236 | H33: 230 | I33: 278 | J33: 297 | K33: 226 | L33: 197 | M33: 241 | N33: 254 | O33: 228 | P33: 289 | Q33: 293 | R33: 269 | S33: 214 | T33: 289 | U33: 247 | V33: 280 | W33: 289 | X33: 282 | Y33: 301 | Z33: 273 | AA33: 193 | AB33: 285 | AC33: 250 | AD33: 237 | AE33: 227 | AF33: 251 | AG33: =SUM(E33:AF33) -> 7109
A34: 2 | B34: Jumlah surat suara yang digunakan | E34: 204 | F34: 164 | G34: 174 | H34: 179 | I34: 223 | J34: 236 | K34: 165 | L34: 147 | M34: 189 | N34: 175 | O34: 151 | P34: 194 | Q34: 187 | R34: 173 | S34: 150 | T34: 208 | U34: 194 | V34: 194 | W34: 210 | X34: 187 | Y34: 207 | Z34: 191 | AA34: 160 | AB34: 226 | AC34: 189 | AD34: 174 | AE34: 185 | AF34: 193 | AG34: =SUM(E34:AF34) -> 5229
A35: 3 | B35: Jumlah surat suara dikembalikan oleh pemilih (karena rusak atau keliru coblos) | E35: 0 | F35: 0 | G35: 0 | H35: 0 | I35: 0 | J35: 0 | K35: 0 | L35: 0 | M35: 0 | N35: 0 | O35: 0 | P35: 1 | Q35: 1 | R35: 0 | S35: 0 | T35: 0 | U35: 8 | V35: 0 | W35: 0 | X35: 0 | Y35: 1 | Z35: 0 | AA35: 2 | AB35: 0 | AC35: 0 | AD35: 0 | AE35: 0 | AF35: 0 | AG35: =SUM(E35:AF35) -> 13
A36: 4 | B36: Jumlah surat suara yang tidak digunakan/tidak terpakai, termasuk sisa surat suara cadangan | E36: =E33-(E34+E35) -> 58 | F36: =F33-(F34+F35) -> 27 | G36: =G33-(G34+G35) -> 62 | H36: =H33-(H34+H35) -> 51 | I36: =I33-(I34+I35) -> 55 | J36: =J33-(J34+J35) -> 61 | K36: =K33-(K34+K35) -> 61 | L36: =L33-(L34+L35) -> 50 | ... AF36: =AF33-(AF34+AF35) -> 58 | AG36: =SUM(E36:AF36) -> 1867
A38: III | B38: DATA PEMILIH DISABILITAS
B39: Jumlah seluruh Pemilih disabilitas yang menggunakan hak pilih | D39: LK | E39: 0 | F39: 0 | G39: 0 | H39: 0 | I39: 0 | J39: 0 | K39: 0 | L39: 0 | M39: 0 | N39: 0 | O39: 0 | P39: 0 | Q39: 0 | R39: 0 | S39: 0 | T39: 0 | U39: 0 | V39: 0 | W39: 0 | X39: 0 | Y39: 0 | Z39: 0 | AA39: 0 | AB39: 0 | AC39: 0 | AD39: 0 | AE39: 0 | AF39: 3 | AG39: =SUM(E39:AF39) -> 3
D40: PR | E40: 0 | F40: 0 | G40: 0 | H40: 0 | I40: 0 | J40: 0 | K40: 0 | L40: 0 | M40: 0 | N40: 0 | O40: 0 | P40: 0 | Q40: 0 | R40: 0 | S40: 0 | T40: 0 | U40: 0 | V40: 0 | W40: 0 | X40: 0 | Y40: 0 | Z40: 0 | AA40: 0 | AB40: 0 | AC40: 0 | AD40: 0 | AE40: 0 | AF40: 4 | AG40: =SUM(E40:AF40) -> 4
D41: JML | E41: =SUM(E39:E40) -> 0 | F41: =SUM(F39:F40) -> 0 | G41: =SUM(G39:G40) -> 0 | H41: =SUM(H39:H40) -> 0 | I41: =SUM(I39:I40) -> 0 | J41: =SUM(J39:J40) -> 0 | K41: =SUM(K39:K40) -> 0 | L41: =SUM(L39:L40) -> 0 | ... AF41: =SUM(AF39:AF40) -> 7 | AG41: =SUM(E41:AF41) -> 7
A43: IV | B43: DATA RINCIAN PEROLEHAN SUARA PASANGAN CALON BUPATI DAN WAKIL BUPATI
A44: NOMOR DAN NAMA CALON
B45: 1 | C45: H. ANIES RASYID BASWEDAN, Ph.D. - Dr. (H.C.) H. A. MUHAIMIN ISKANDAR | E45: 29 | F45: 9 | G45: 14 | H45: 21 | I45: 7 | J45: 23 | K45: 9 | L45: 1 | M45: 11 | N45: 9 | O45: 15 | P45: 3 | Q45: 17 | R45: 14 | S45: 11 | T45: 7 | U45: 14 | V45: 13 | W45: 23 | X45: 7 | Y45: 4 | Z45: 1 | AA45: 15 | AB45: 4 | AC45: 14 | AD45: 5 | AE45: 4 | AF45: 7 | AG45: =SUM(E45:AF45) -> 311
B46: 2 | C46: H. PRABOWO SUBIANTO - GIBRAN RAKABUMING RAKA | E46: 122 | F46: 119 | G46: 115 | H46: 121 | I46: 151 | J46: 148 | K46: 103 | L46: 103 | M46: 135 | N46: 112 | O46: 89 | P46: 127 | Q46: 134 | R46: 121 | S46: 100 | T46: 150 | U46: 135 | V46: 134 | W46: 146 | X46: 151 | Y46: 174 | Z46: 161 | AA46: 130 | AB46: 189 | AC46: 167 | AD46: 157 | AE46: 174 | AF46: 170 | AG46: =SUM(E46:AF46) -> 3838
B47: 3 | C47: H. GANJAR PRANOWO, S.H., M.I.P. - Prof. Dr. H. M. MAHFUD MD | E47: 52 | F47: 35 | G47: 44 | H47: 33 | I47: 62 | J47: 62 | K47: 48 | L47: 40 | M47: 39 | N47: 52 | O47: 46 | P47: 56 | Q47: 30 | R47: 36 | S47: 36 | T47: 44 | U47: 39 | V47: 45 | W47: 40 | X47: 26 | Y47: 28 | Z47: 28 | AA47: 11 | AB47: 31 | AC47: 5 | AD47: 9 | AE47: 6 | AF47: 11 | AG47: =SUM(E47:AF47) -> 994
A49: V | B49: DATA SUARA SAH DAN TIDAK SAH
B50: A. | C50: JUMLAH SELURUH SUARA SAH | E50: =SUM(E45:E47) -> 203 | F50: =SUM(F45:F47) -> 163 | G50: =SUM(G45:G47) -> 173 | H50: =SUM(H45:H47) -> 175 | I50: =SUM(I45:I47) -> 220 | J50: =SUM(J45:J47) -> 233 | K50: =SUM(K45:K47) -> 160 | L50: =SUM(L45:L47) -> 144 | ... AF50: =SUM(AF45:AF47) -> 188 | AG50: =SUM(E50:AF50) -> 5143
B51: B. | C51: JUMLAH SUARA TIDAK SAH | E51: 1 | F51: 1 | G51: 1 | H51: 4 | I51: 3 | J51: 3 | K51: 5 | L51: 3 | M51: 4 | N51: 2 | O51: 1 | P51: 8 | Q51: 6 | R51: 2 | S51: 3 | T51: 7 | U51: 6 | V51: 2 | W51: 1 | X51: 3 | Y51: 1 | Z51: 1 | AA51: 4 | AB51: 2 | AC51: 3 | AD51: 3 | AE51: 1 | AF51: 5 | AG51: =SUM(E51:AF51) -> 86
B52: C. | C52: JUMLAH SELURUH SUARA SAH DAN SUARA TIDAK SAH (V.A + V.B) | E52: =SUM(E50:E51) -> 204 | F52: =SUM(F50:F51) -> 164 | G52: =SUM(G50:G51) -> 174 | H52: =SUM(H50:H51) -> 179 | I52: =SUM(I50:I51) -> 223 | J52: =SUM(J50:J51) -> 236 | K52: =SUM(K50:K51) -> 165 | L52: =SUM(L50:L51) -> 147 | ... AF52: =SUM(AF50:AF51) -> 193 | AG52: =SUM(E52:AF52) -> 5229

Sheet PESANGGARAN
C2: Kecamatan | D2: PESANGGARAN
C3: Kabupaten | D3: BANYUWANGI
C4: Provinsi | D4: JAWA TIMUR
C9: Kelurahan | D9: PESANGGARAN
A12: I | B12: DATA PEMILIH DAN PENGGUNAAN HAK PILIH | AZ12: JUMLAH AKHIR
A13: A | B13: DATA PEMILIH | E13: TPS 001 | F13: TPS 002 | G13: TPS 003 | H13: TPS 004 | I13: TPS 005 | J13: TPS 006 | K13: TPS 007 | L13: TPS 008 | M13: TPS 009 | N13: TPS 010 | O13: TPS 011 | P13: TPS 012 | Q13: TPS 013 | R13: TPS 014 | S13: TPS 015 | T13: TPS 016 | U13: TPS 017 | V13: TPS 018 | W13: TPS 019 | X13: TPS 020 | Y13: TPS 021 | Z13: TPS 022 | AA13: TPS 023 | AB13: TPS 024 | AC13: TPS 025 | AD13: TPS 026 | AE13: TPS 027 | AF13: TPS 028 | AG13: TPS 029 | AH13: TPS 030 | AI13: TPS 031 | AJ13: TPS 032 | AK13: TPS 033 | AL13: TPS 034 | AM13: TPS 035 | AN13: TPS 036 | AO13: TPS 037 | AP13: TPS 038 | AQ13: TPS 039 | AR13: TPS 040 | AS13: TPS 041 | AT13: TPS 042 | AU13: TPS 043 | AV13: TPS 044 | AW13: TPS 045 | AX13: TPS 046 | AY13: TPS 047
B14: Jumlah Pemilih dalam Daftar Pemilih Tetap (DPT) | D14: LK | E14: 138 | F14: 150 | G14: 141 | H14: 129 | I14: 146 | J14: 133 | K14: 83 | L14: 145 | M14: 142 | N14: 150 | O14: 147 | P14: 129 | Q14: 149 | R14: 134 | S14: 132 | T14: 136 | U14: 145 | V14: 131 | W14: 152 | X14: 155 | Y14: 115 | Z14: 109 | AA14: 105 | AB14: 127 | AC14: 144 | AD14: 128 | AE14: 118 | AF14: 139 | AG14: 118 | AH14: 144 | AI14: 112 | AJ14: 141 | AK14: 144 | AL14: 148 | AM14: 144 | AN14: 135 | AO14: 120 | AP14: 144 | AQ14: 142 | AR14: 146 | AS14: 130 | AT14: 132 | AU14: 128 | AV14: 134 | AW14: 146 | AX14: 146 | AY14: 123 | AZ14: =SUM(E14:AY14) -> 6329
D15: PR | E15: 141 | F15: 138 | G15: 130 | H15: 152 | I15: 151 | J15: 161 | K15: 83 | L15: 136 | M15: 135 | N15: 144 | O15: 142 | P15: 152 | Q15: 141 | R15: 132 | S15: 128 | T15: 157 | U15: 134 | V15: 126 | W15: 145 | X15: 140 | Y15: 107 | Z15: 113 | AA15: 94 | AB15: 130 | AC15: 149 | AD15: 144 | AE15: 126 | AF15: 101 | AG15: 126 | AH15: 136 | AI15: 109 | AJ15: 148 | AK15: 148 | AL15: 138 | AM15: 134 | AN15: 115 | AO15: 119 | AP15: 147 | AQ15: 153 | AR15: 142 | AS15: 148 | AT15: 160 | AU15: 157 | AV15: 160 | AW15: 146 | AX15: 144 | AY15: 145 | AZ15: =SUM(E15:AY15) -> 6407
D16: JML | E16: =SUM(E14:E15) -> 279 | F16: =SUM(F14:F15) -> 288 | G16: =SUM(G14:G15) -> 271 | H16: =SUM(H14:H15) -> 281 | I16: =SUM(I14:I15) -> 297 | J16: =SUM(J14:J15) -> 294 | K16: =SUM(K14:K15) -> 166 | L16: =SUM(L14:L15) -> 281 | ... AY16: =SUM(AY14:AY15) -> 268 | AZ16: =SUM(E16:AY16) -> 12736
A18: B | B18: PENGGUNA HAK PILIH
B19: 1. | C19: Jumlah pengguna hak pilih dalam Daftar Pemilih Tetap (DPT) | D19: LK | E19: 104 | F19: 115 | G19: 100 | H19: 90 | I19: 103 | J19: 97 | K19: 59 | L19: 108 | M19: 97 | N19: 106 | O19: 117 | P19: 90 | Q19: 113 | R19: 100 | S19: 109 | T19: 102 | U19: 105 | V19: 99 | W19: 119 | X19: 119 | Y19: 86 | Z19: 92 | AA19: 87 | AB19: 90 | AC19: 108 | AD19: 98 | AE19: 93 | AF19: 118 | AG19: 90 | AH19: 110 | AI19: 90 | AJ19: 106 | AK19: 107 | AL19: 114 | AM19: 114 | AN19: 103 | AO19: 96 | AP19: 108 | AQ19: 106 | AR19: 110 | AS19: 85 | AT19: 97 | AU19: 100 | AV19: 90 | AW19: 94 | AX19: 90 | AY19: 100 | AZ19: =SUM(E19:AY19) -> 4734
D20: PR | E20: 112 | F20: 119 | G20: 102 | H20: 111 | I20: 115 | J20: 122 | K20: 63 | L20: 110 | M20: 95 | N20: 116 | O20: 124 | P20: 107 | Q20: 111 | R20: 100 | S20: 103 | T20: 111 | U20: 97 | V20: 101 | W20: 113 | X20: 112 | Y20: 78 | Z20: 98 | AA20: 70 | AB20: 107 | AC20: 102 | AD20: 108 | AE20: 105 | AF20: 81 | AG20: 87 | AH20: 109 | AI20: 89 | AJ20: 107 | AK20: 110 | AL20: 100 | AM20: 103 | AN20: 92 | AO20: 92 | AP20: 118 | AQ20: 119 | AR20: 112 | AS20: 106 | AT20: 120 | AU20: 114 | AV20: 110 | AW20: 100 | AX20: 101 | AY20: 108 | AZ20: =SUM(E20:AY20) -> 4890
D21: JML | E21: =SUM(E19:E20) -> 216 | F21: =SUM(F19:F20) -> 234 | G21: =SUM(G19:G20) -> 202 | H21: =SUM(H19:H20) -> 201 | I21: =SUM(I19:I20) -> 218 | J21: =SUM(J19:J20) -> 219 | K21: =SUM(K19:K20) -> 122 | L21: =SUM(L19:L20) -> 218 | ... AY21: =SUM(AY19:AY20) -> 208 | AZ21: =SUM(E21:AY21) -> 9624
B22: 2. | C22: Jumlah pengguna hak pilih dalam Daftar Pemilih Tambahan (DPTb) | D22: LK | E22: 0 | F22: 0 | G22: 0 | H22: 0 | I22: 0 | J22: 0 | K22: 0 | L22: 0 | M22: 0 | N22: 0 | O22: 0 | P22: 1 | Q22: 0 | R22: 0 | S22: 0 | T22: 0 | U22: 0 | V22: 0 | W22: 0 | X22: 0 | Y22: 0 | Z22: 0 | AA22: 0 | AB22: 0 | AC22: 0 | AD22: 0 | AE22: 0 | AF22: 0 | AG22: 0 | AH22: 0 | AI22: 0 | AJ22: 2 | AK22: 0 | AL22: 0 | AM22: 0 | AN22: 0 | AO22: 0 | AP22: 13 | AQ22: 10 | AR22: 13 | AS22: 11 | AT22: 0 | AU22: 0 | AV22: 7 | AW22: 0 | AX22: 0 | AY22: 0 | AZ22: =SUM(E22:AY22) -> 57
D23: PR | E23: 0 | F23: 0 | G23: 1 | H23: 0 | I23: 0 | J23: 0 | K23: 0 | L23: 0 | M23: 0 | N23: 0 | O23: 0 | P23: 0 | Q23: 1 | R23: 0 | S23: 0 | T23: 0 | U23: 0 | V23: 0 | W23: 0 | X23: 0 | Y23: 0 | Z23: 0 | AA23: 0 | AB23: 0 | AC23: 0 | AD23: 1 | AE23: 0 | AF23: 0 | AG23: 0 | AH23: 0 | AI23: 0 | AJ23: 0 | AK23: 0 | AL23: 0 | AM23: 0 | AN23: 0 | AO23: 0 | AP23: 3 | AQ23: 1 | AR23: 1 | AS23: 0 | AT23: 0 | AU23: 0 | AV23: 0 | AW23: 0 | AX23: 0 | AY23: 1 | AZ23: =SUM(E23:AY23) -> 9
D24: JML | E24: =SUM(E22:E23) -> 0 | F24: =SUM(F22:F23) -> 0 | G24: =SUM(G22:G23) -> 1 | H24: =SUM(H22:H23) -> 0 | I24: =SUM(I22:I23) -> 0 | J24: =SUM(J22:J23) -> 0 | K24: =SUM(K22:K23) -> 0 | L24: =SUM(L22:L23) -> 0 | ... AY24: =SUM(AY22:AY23) -> 1 | AZ24: =SUM(E24:AY24) -> 66
B25: 3. | C25: Jumlah pengguna hak pilih dalam Daftar Pemilih Khusus (DPK) | D25: LK | E25: 3 | F25: 0 | G25: 1 | H25: 0 | I25: 1 | J25: 1 | K25: 0 | L25: 5 | M25: 2 | N25: 2 | O25: 0 | P25: 1 | Q25: 3 | R25: 0 | S25: 1 | T25: 2 | U25: 2 | V25: 2 | W25: 0 | X25: 3 | Y25: 0 | Z25: 1 | AA25: 0 | AB25: 1 | AC25: 1 | AD25: 0 | AE25: 0 | AF25: 0 | AG25: 0 | AH25: 4 | AI25: 0 | AJ25: 2 | AK25: 0 | AL25: 1 | AM25: 1 | AN25: 0 | AO25: 0 | AP25: 3 | AQ25: 2 | AR25: 1 | AS25: 5 | AT25: 4 | AU25: 3 | AV25: 3 | AW25: 1 | AX25: 1 | AY25: 3 | AZ25: =SUM(E25:AY25) -> 66
D26: PR | E26: 1 | F26: 0 | G26: 1 | H26: 4 | I26: 1 | J26: 1 | K26: 0 | L26: 2 | M26: 4 | N26: 1 | O26: 0 | P26: 1 | Q26: 3 | R26: 1 | S26: 0 | T26: 1 | U26: 3 | V26: 1 | W26: 0 | X26: 2 | Y26: 0 | Z26: 0 | AA26: 1 | AB26: 1 | AC26: 1 | AD26: 2 | AE26: 0 | AF26: 1 | AG26: 0 | AH26: 2 | AI26: 1 | AJ26: 0 | AK26: 0 | AL26: 2 | AM26: 0 | AN26: 0 | AO26: 0 | AP26: 2 | AQ26: 1 | AR26: 1 | AS26: 6 | AT26: 5 | AU26: 5 | AV26: 5 | AW26: 5 | AX26: 1 | AY26: 1 | AZ26: =SUM(E26:AY26) -> 70
D27: JML | E27: =SUM(E25:E26) -> 4 | F27: =SUM(F25:F26) -> 0 | G27: =SUM(G25:G26) -> 2 | H27: =SUM(H25:H26) -> 4 | I27: =SUM(I25:I26) -> 2 | J27: =SUM(J25:J26) -> 2 | K27: =SUM(K25:K26) -> 0 | L27: =SUM(L25:L26) -> 7 | ... AY27: =SUM(AY25:AY26) -> 4 | AZ27: =SUM(E27:AY27) -> 136
B28: 4. | C28: Jumlah Pengguna Hak Pilih (B.1+B.2+B.3) | D28: LK | E28: =SUM(E19,E22,E25) -> 107 | F28: =SUM(F19,F22,F25) -> 115 | G28: =SUM(G19,G22,G25) -> 101 | H28: =SUM(H19,H22,H25) -> 90 | I28: =SUM(I19,I22,I25) -> 104 | J28: =SUM(J19,J22,J25) -> 98 | K28: =SUM(K19,K22,K25) -> 59 | L28: =SUM(L19,L22,L25) -> 113 | ... AY28: =SUM(AY19,AY22,AY25) -> 103 | AZ28: =SUM(E28:AY28) -> 4857
D29: PR | E29: =SUM(E20,E23,E26) -> 113 | F29: =SUM(F20,F23,F26) -> 119 | G29: =SUM(G20,G23,G26) -> 104 | H29: =SUM(H20,H23,H26) -> 115 | I29: =SUM(I20,I23,I26) -> 116 | J29: =SUM(J20,J23,J26) -> 123 | K29: =SUM(K20,K23,K26) -> 63 | L29: =SUM(L20,L23,L26) -> 112 | ... AY29: =SUM(AY20,AY23,AY26) -> 110 | AZ29: =SUM(E29:AY29) -> 4969
D30: JML | E30: =SUM(E28:E29) -> 220 | F30: =SUM(F28:F29) -> 234 | G30: =SUM(G28:G29) -> 205 | H30: =SUM(H28:H29) -> 205 | I30: =SUM(I28:I29) -> 220 | J30: =SUM(J28:J29) -> 221 | K30: =SUM(K28:K29) -> 122 | L30: =SUM(L28:L29) -> 225 | ... AY30: =SUM(AY28:AY29) -> 213 | AZ30: =SUM(E30:AY30) -> 9826
A32: II | B32: DATA PENGGUNAAN SURAT SUARA
A33: 1 | B33: Jumlah surat suara yang diterima, termasuk surat suara cadangan 2,5% dari DPT | E33: 285 | F33: 294 | G33: 277 | H33: 285 | I33: 305 | J33: 300 | K33: 170 | L33: 287 | M33: 285 | N33: 300 | O33: 295 | P33: 287 | Q33: 296 | R33: 272 | S33: 276 | T33: 300 | U33: 285 | V33: 264 | W33: 304 | X33: 301 | Y33: 229 | Z33: 227 | AA33: 203 | AB33: 263 | AC33: 299 | AD33: 282 | AE33: 249 | AF33: 245 | AG33: 250 | AH33: 285 | AI33: 228 | AJ33: 296 | AK33: 299 | AL33: 294 | AM33: 285 | AN33: 255 | AO33: 249 | AP33: 297 | AQ33: 302 | AR33: 294 | AS33: 284 | AT33: 298 | AU33: 291 | AV33: 300 | AW33: 298 | AX33: 296 | AY33: 276 | AZ33: =SUM(E33:AY33) -> 13042
A34: 2 | B34: Jumlah surat suara yang digunakan | E34: 220 | F34: 234 | G34: 205 | H34: 206 | I34: 220 | J34: 221 | K34: 122 | L34: 225 | M34: 198 | N34: 225 | O34: 241 | P34: 200 | Q34: 231 | R34: 201 | S34: 213 | T34: 216 | U34: 207 | V34: 203 | W34: 232 | X34: 236 | Y34: 164 | Z34: 191 | AA34: 158 | AB34: 199 | AC34: 212 | AD34: 209 | AE34: 198 | AF34: 200 | AG34: 177 | AH34: 225 | AI34: 180 | AJ34: 217 | AK34: 217 | AL34: 217 | AM34: 218 | AN34: 195 | AO34: 188 | AP34: 247 | AQ34: 239 | AR34: 238 | AS34: 213 | AT34: 226 | AU34: 222 | AV34: 215 | AW34: 200 | AX34: 193 | AY34: 213 | AZ34: =SUM(E34:AY34) -> 9827
A35: 3 | B35: Jumlah surat suara dikembalikan oleh pemilih (karena rusak atau keliru coblos) | E35: 0 | F35: 0 | G35: 0 | H35: 0 | I35: 0 | J35: 0 | K35: 0 | L35: 0 | M35: 0 | N35: 0 | O35: 0 | P35: 0 | Q35: 0 | R35: 0 | S35: 0 | T35: 0 | U35: 0 | V35: 2 | W35: 0 | X35: 3 | Y35: 3 | Z35: 0 | AA35: 0 | AB35: 0 | AC35: 0 | AD35: 0 | AE35: 0 | AF35: 0 | AG35: 0 | AH35: 0 | AI35: 3 | AJ35: 0 | AK35: 0 | AL35: 0 | AM35: 0 | AN35: 0 | AO35: 2 | AP35: 0 | AQ35: 0 | AR35: 0 | AS35: 0 | AT35: 0 | AU35: 0 | AV35: 0 | AW35: 0 | AX35: 0 | AY35: 0 | AZ35: =SUM(E35:AY35) -> 13
A36: 4 | B36: Jumlah surat suara yang tidak digunakan/tidak terpakai, termasuk sisa surat suara cadangan | E36: =E33-(E34+E35) -> 65 | F36: =F33-(F34+F35) -> 60 | G36: =G33-(G34+G35) -> 72 | H36: =H33-(H34+H35) -> 79 | I36: =I33-(I34+I35) -> 85 | J36: =J33-(J34+J35) -> 79 | K36: =K33-(K34+K35) -> 48 | L36: =L33-(L34+L35) -> 62 | ... AY36: =AY33-(AY34+AY35) -> 63 | AZ36: =SUM(E36:AY36) -> 3202
A38: III | B38: DATA PEMILIH DISABILITAS
B39: Jumlah seluruh Pemilih disabilitas yang menggunakan hak pilih | D39: LK | E39: 0 | F39: 0 | G39: 0 | H39: 1 | I39: 0 | J39: 0 | K39: 0 | L39: 0 | M39: 0 | N39: 0 | O39: 0 | P39: 0 | Q39: 0 | R39: 0 | S39: 0 | T39: 0 | U39: 1 | V39: 1 | W39: 0 | X39: 0 | Y39: 0 | Z39: 2 | AA39: 0 | AB39: 1 | AC39: 0 | AD39: 0 | AE39: 0 | AF39: 0 | AG39: 0 | AH39: 0 | AI39: 0 | AJ39: 0 | AK39: 0 | AL39: 0 | AM39: 0 | AN39: 0 | AO39: 0 | AP39: 0 | AQ39: 1 | AR39: 0 | AS39: 1 | AT39: 0 | AU39: 0 | AV39: 0 | AW39: 0 | AX39: 0 | AY39: 0 | AZ39: =SUM(E39:AY39) -> 8
D40: PR | E40: 0 | F40: 0 | G40: 0 | H40: 0 | I40: 0 | J40: 0 | K40: 0 | L40: 0 | M40: 0 | N40: 0 | O40: 0 | P40: 0 | Q40: 0 | R40: 0 | S40: 1 | T40: 0 | U40: 0 | V40: 0 | W40: 0 | X40: 0 | Y40: 0 | Z40: 1 | AA40: 0 | AB40: 1 | AC40: 0 | AD40: 0 | AE40: 0 | AF40: 0 | AG40: 0 | AH40: 0 | AI40: 0 | AJ40: 0 | AK40: 0 | AL40: 0 | AM40: 0 | AN40: 0 | AO40: 0 | AP40: 0 | AQ40: 0 | AR40: 0 | AS40: 0 | AT40: 0 | AU40: 0 | AV40: 0 | AW40: 0 | AX40: 0 | AY40: 0 | AZ40: =SUM(E40:AY40) -> 3
D41: JML | E41: =SUM(E39:E40) -> 0 | F41: =SUM(F39:F40) -> 0 | G41: =SUM(G39:G40) -> 0 | H41: =SUM(H39:H40) -> 1 | I41: =SUM(I39:I40) -> 0 | J41: =SUM(J39:J40) -> 0 | K41: =SUM(K39:K40) -> 0 | L41: =SUM(L39:L40) -> 0 | ... AY41: =SUM(AY39:AY40) -> 0 | AZ41: =SUM(E41:AY41) -> 11
A43: IV | B43: DATA RINCIAN PEROLEHAN SUARA PASANGAN CALON BUPATI DAN WAKIL BUPATI
A44: NOMOR DAN NAMA CALON
B45: 1 | C45: H. ANIES RASYID BASWEDAN, Ph.D. - Dr. (H.C.) H. A. MUHAIMIN ISKANDAR | E45: 14 | F45: 24 | G45: 29 | H45: 29 | I45: 13 | J45: 35 | K45: 19 | L45: 20 | M45: 14 | N45: 16 | O45: 22 | P45: 17 | Q45: 5 | R45: 18 | S45: 20 | T45: 17 | U45: 30 | V45: 9 | W45: 10 | X45: 12 | Y45: 4 | Z45: 8 | AA45: 2 | AB45: 3 | AC45: 11 | AD45: 14 | AE45: 8 | AF45: 2 | AG45: 6 | AH45: 3 | AI45: 4 | AJ45: 16 | AK45: 13 | AL45: 14 | AM45: 6 | AN45: 1 | AO45: 5 | AP45: 26 | AQ45: 22 | AR45: 23 | AS45: 15 | AT45: 16 | AU45: 12 | AV45: 18 | AW45: 6 | AX45: 18 | AY45: 25 | AZ45: =SUM(E45:AY45) -> 674
B46: 2 | C46: H. PRABOWO SUBIANTO - GIBRAN RAKABUMING RAKA | E46: 166 | F46: 172 | G46: 132 | H46: 138 | I46: 132 | J46: 132 | K46: 67 | L46: 147 | M46: 120 | N46: 149 | O46: 137 | P46: 131 | Q46: 167 | R46: 134 | S46: 134 | T46: 122 | U46: 122 | V46: 138 | W46: 152 | X46: 133 | Y46: 109 | Z46: 125 | AA46: 89 | AB46: 119 | AC46: 136 | AD46: 152 | AE46: 134 | AF46: 153 | AG46: 124 | AH46: 167 | AI46: 138 | AJ46: 135 | AK46: 166 | AL46: 159 | AM46: 133 | AN46: 120 | AO46: 138 | AP46: 189 | AQ46: 158 | AR46: 130 | AS46: 135 | AT46: 152 | AU46: 161 | AV46: 129 | AW46: 144 | AX46: 110 | AY46: 120 | AZ46: =SUM(E46:AY46) -> 6450
B47: 3 | C47: H. GANJAR PRANOWO, S.H., M.I.P. - Prof. Dr. H. M. MAHFUD MD | E47: 38 | F47: 33 | G47: 43 | H47: 38 | I47: 74 | J47: 49 | K47: 34 | L47: 55 | M47: 63 | N47: 57 | O47: 77 | P47: 48 | Q47: 53 | R47: 46 | S47: 58 | T47: 74 | U47: 51 | V47: 56 | W47: 63 | X47: 90 | Y47: 47 | Z47: 53 | AA47: 61 | AB47: 74 | AC47: 65 | AD47: 36 | AE47: 54 | AF47: 45 | AG47: 44 | AH47: 53 | AI47: 36 | AJ47: 60 | AK47: 33 | AL47: 41 | AM47: 77 | AN47: 74 | AO47: 40 | AP47: 29 | AQ47: 56 | AR47: 79 | AS47: 58 | AT47: 56 | AU47: 44 | AV47: 64 | AW47: 48 | AX47: 59 | AY47: 65 | AZ47: =SUM(E47:AY47) -> 2551
A49: V | B49: DATA SUARA SAH DAN TIDAK SAH
B50: A. | C50: JUMLAH SELURUH SUARA SAH | E50: =sum(E45:E47) -> 218 | F50: =sum(F45:F47) -> 229 | G50: =SUM(G45:G47) -> 204 | H50: =SUM(H45:H47) -> 205 | I50: =SUM(I45:I47) -> 219 | J50: =SUM(J45:J47) -> 216 | K50: =SUM(K45:K47) -> 120 | L50: =SUM(L45:L47) -> 222 | M50: =SUM(M45:M47) -> 197 | N50: =SUM(N45:N47) -> 222 | ... AY50: =SUM(AY45:AY47) -> 210 | AZ50: =SUM(E50:AY50) -> 9675
B51: B. | C51: JUMLAH SUARA TIDAK SAH | E51: 2 | F51: 5 | G51: 1 | H51: 1 | I51: 1 | J51: 5 | K51: 2 | L51: 3 | M51: 1 | N51: 3 | O51: 5 | P51: 4 | Q51: 6 | R51: 3 | S51: 1 | T51: 3 | U51: 4 | V51: 0 | W51: 7 | X51: 1 | Y51: 4 | Z51: 5 | AA51: 6 | AB51: 3 | AC51: 0 | AD51: 7 | AE51: 2 | AF51: 0 | AG51: 3 | AH51: 2 | AI51: 2 | AJ51: 6 | AK51: 5 | AL51: 3 | AM51: 2 | AN51: 0 | AO51: 5 | AP51: 3 | AQ51: 3 | AR51: 6 | AS51: 5 | AT51: 2 | AU51: 5 | AV51: 4 | AW51: 2 | AX51: 6 | AY51: 3 | AZ51: =SUM(E51:AY51) -> 152
B52: C. | C52: JUMLAH SELURUH SUARA SAH DAN SUARA TIDAK SAH (V.A + V.B) | E52: =SUM(E50:E51) -> 220 | F52: =SUM(F50:F51) -> 234 | G52: =SUM(G50:G51) -> 205 | H52: =SUM(H50:H51) -> 206 | I52: =SUM(I50:I51) -> 220 | J52: =SUM(J50:J51) -> 221 | K52: =SUM(K50:K51) -> 122 | L52: =SUM(L50:L51) -> 225 | ... AY52: =SUM(AY50:AY51) -> 213 | AZ52: =SUM(E52:AY52) -> 9827

Sheet SARONGAN
C2: Kecamatan | D2: PESANGGARAN
C3: Kabupaten | D3: BANYUWANGI
C4: Provinsi | D4: JAWA TIMUR
C9: Kelurahan | D9: SARONGAN
A12: I | B12: DATA PEMILIH DAN PENGGUNAAN HAK PILIH | X12: JUMLAH AKHIR
A13: A | B13: DATA PEMILIH | E13: TPS 001 | F13: TPS 002 | G13: TPS 003 | H13: TPS 004 | I13: TPS 005 | J13: TPS 006 | K13: TPS 007 | L13: TPS 008 | M13: TPS 009 | N13: TPS 010 | O13: TPS 011 | P13: TPS 012 | Q13: TPS 013 | R13: TPS 014 | S13: TPS 015 | T13: TPS 016 | U13: TPS 017 | V13: TPS 018 | W13: TPS 019
B14: Jumlah Pemilih dalam Daftar Pemilih Tetap (DPT) | D14: LK | E14: 105 | F14: 100 | G14: 119 | H14: 147 | I14: 139 | J14: 145 | K14: 140 | L14: 144 | M14: 152 | N14: 145 | O14: 140 | P14: 139 | Q14: 144 | R14: 119 | S14: 121 | T14: 142 | U14: 98 | V14: 103 | W14: 107 | X14: =SUM(E14:W14) -> 2449
D15: PR | E15: 98 | F15: 99 | G15: 114 | H15: 147 | I15: 133 | J15: 147 | K15: 147 | L15: 148 | M15: 141 | N15: 144 | O15: 146 | P15: 140 | Q15: 150 | R15: 132 | S15: 127 | T15: 140 | U15: 89 | V15: 107 | W15: 107 | X15: =SUM(E15:W15) -> 2456
D16: JML | E16: =SUM(E14:E15) -> 203 | F16: =SUM(F14:F15) -> 199 | G16: =SUM(G14:G15) -> 233 | H16: =SUM(H14:H15) -> 294 | I16: =SUM(I14:I15) -> 272 | J16: =SUM(J14:J15) -> 292 | K16: =SUM(K14:K15) -> 287 | L16: =SUM(L14:L15) -> 292 | ... W16: =SUM(W14:W15) -> 214 | X16: =SUM(E16:W16) -> 4905
A18: B | B18: PENGGUNA HAK PILIH
B19: 1. | C19: Jumlah pengguna hak pilih dalam Daftar Pemilih Tetap (DPT) | D19: LK | E19: 89 | F19: 74 | G19: 100 | H19: 110 | I19: 112 | J19: 105 | K19: 119 | L19: 102 | M19: 115 | N19: 108 | O19: 105 | P19: 95 | Q19: 117 | R19: 92 | S19: 90 | T19: 88 | U19: 72 | V19: 81 | W19: 80 | X19: =SUM(E19:W19) -> 1854
D20: PR | E20: 75 | F20: 76 | G20: 101 | H20: 117 | I20: 102 | J20: 105 | K20: 115 | L20: 115 | M20: 104 | N20: 112 | O20: 121 | P20: 106 | Q20: 122 | R20: 99 | S20: 99 | T20: 104 | U20: 73 | V20: 87 | W20: 72 | X20: =SUM(E20:W20) -> 1905
D21: JML | E21: =SUM(E19:E20) -> 164 | F21: =SUM(F19:F20) -> 150 | G21: =SUM(G19:G20) -> 201 | H21: =SUM(H19:H20) -> 227 | I21: =SUM(I19:I20) -> 214 | J21: =SUM(J19:J20) -> 210 | K21: =SUM(K19:K20) -> 234 | L21: =SUM(L19:L20) -> 217 | ... W21: =SUM(W19:W20) -> 152 | X21: =SUM(E21:W21) -> 3759
B22: 2. | C22: Jumlah pengguna hak pilih dalam Daftar Pemilih Tambahan (DPTb) | D22: LK | E22: 0 | F22: 0 | G22: 0 | H22: 0 | I22: 0 | J22: 0 | K22: 0 | L22: 0 | M22: 0 | N22: 0 | O22: 0 | P22: 0 | Q22: 0 | R22: 0 | S22: 0 | T22: 0 | U22: 0 | V22: 0 | W22: 3 | X22: =SUM(E22:W22) -> 3
D23: PR | E23: 0 | F23: 0 | G23: 0 | H23: 0 | I23: 0 | J23: 0 | K23: 0 | L23: 0 | M23: 0 | N23: 0 | O23: 0 | P23: 2 | Q23: 0 | R23: 0 | S23: 0 | T23: 0 | U23: 0 | V23: 0 | W23: 4 | X23: =SUM(E23:W23) -> 6
D24: JML | E24: =SUM(E22:E23) -> 0 | F24: =SUM(F22:F23) -> 0 | G24: =SUM(G22:G23) -> 0 | H24: =SUM(H22:H23) -> 0 | I24: =SUM(I22:I23) -> 0 | J24: =SUM(J22:J23) -> 0 | K24: =SUM(K22:K23) -> 0 | L24: =SUM(L22:L23) -> 0 | ... W24: =SUM(W22:W23) -> 7 | X24: =SUM(E24:W24) -> 9
B25: 3. | C25: Jumlah pengguna hak pilih dalam Daftar Pemilih Khusus (DPK) | D25: LK | E25: 1 | F25: 1 | G25: 0 | H25: 12 | I25: 0 | J25: 1 | K25: 1 | L25: 4 | M25: 3 | N25: 0 | O25: 2 | P25: 1 | Q25: 1 | R25: 5 | S25: 0 | T25: 0 | U25: 2 | V25: 3 | W25: 0 | X25: =SUM(E25:W25) -> 37
D26: PR | E26: 1 | F26: 1 | G26: 0 | H26: 4 | I26: 5 | J26: 0 | K26: 3 | L26: 2 | M26: 2 | N26: 2 | O26: 0 | P26: 4 | Q26: 2 | R26: 4 | S26: 1 | T26: 0 | U26: 3 | V26: 5 | W26: 0 | X26: =SUM(E26:W26) -> 39
D27: JML | E27: =SUM(E25:E26) -> 2 | F27: =SUM(F25:F26) -> 2 | G27: =SUM(G25:G26) -> 0 | H27: =SUM(H25:H26) -> 16 | I27: =SUM(I25:I26) -> 5 | J27: =SUM(J25:J26) -> 1 | K27: =SUM(K25:K26) -> 4 | L27: =SUM(L25:L26) -> 6 | ... W27: =SUM(W25:W26) -> 0 | X27: =SUM(E27:W27) -> 76
B28: 4. | C28: Jumlah Pengguna Hak Pilih (B.1+B.2+B.3) | D28: LK | E28: =SUM(E19,E22,E25) -> 90 | F28: =SUM(F19,F22,F25) -> 75 | G28: =SUM(G19,G22,G25) -> 100 | H28: =SUM(H19,H22,H25) -> 122 | I28: =SUM(I19,I22,I25) -> 112 | J28: =SUM(J19,J22,J25) -> 106 | K28: =SUM(K19,K22,K25) -> 120 | L28: =SUM(L19,L22,L25) -> 106 | ... W28: =SUM(W19,W22,W25) -> 83 | X28: =SUM(E28:W28) -> 1894
D29: PR | E29: =SUM(E20,E23,E26) -> 76 | F29: =SUM(F20,F23,F26) -> 77 | G29: =SUM(G20,G23,G26) -> 101 | H29: =SUM(H20,H23,H26) -> 121 | I29: =SUM(I20,I23,I26) -> 107 | J29: =SUM(J20,J23,J26) -> 105 | K29: =SUM(K20,K23,K26) -> 118 | L29: =SUM(L20,L23,L26) -> 117 | ... W29: =SUM(W20,W23,W26) -> 76 | X29: =SUM(E29:W29) -> 1950
D30: JML | E30: =SUM(E28:E29) -> 166 | F30: =SUM(F28:F29) -> 152 | G30: =SUM(G28:G29) -> 201 | H30: =SUM(H28:H29) -> 243 | I30: =SUM(I28:I29) -> 219 | J30: =SUM(J28:J29) -> 211 | K30: =SUM(K28:K29) -> 238 | L30: =SUM(L28:L29) -> 223 | ... W30: =SUM(W28:W29) -> 159 | X30: =SUM(E30:W30) -> 3844
A32: II | B32: DATA PENGGUNAAN SURAT SUARA
A33: 1 | B33: Jumlah surat suara yang diterima, termasuk surat suara cadangan 2,5% dari DPT | E33: 208 | F33: 204 | G33: 240 | H33: 300 | I33: 278 | J33: 299 | K33: 292 | L33: 298 | M33: 299 | N33: 297 | O33: 294 | P33: 285 | Q33: 300 | R33: 257 | S33: 257 | T33: 289 | U33: 191 | V33: 217 | W33: 221 | X33: =SUM(E33:W33) -> 5026
A34: 2 | B34: Jumlah surat suara yang digunakan | E34: 166 | F34: 152 | G34: 201 | H34: 243 | I34: 219 | J34: 211 | K34: 238 | L34: 223 | M34: 224 | N34: 222 | O34: 228 | P34: 208 | Q34: 242 | R34: 200 | S34: 190 | T34: 192 | U34: 150 | V34: 176 | W34: 159 | X34: =SUM(E34:W34) -> 3844
A35: 3 | B35: Jumlah surat suara dikembalikan oleh pemilih (karena rusak atau keliru coblos) | E35: 0 | F35: 0 | G35: 0 | H35: 0 | I35: 0 | J35: 0 | K35: 0 | L35: 0 | M35: 0 | N35: 0 | O35: 0 | P35: 0 | Q35: 0 | R35: 0 | S35: 0 | T35: 0 | U35: 0 | V35: 0 | W35: 0 | X35: =SUM(E35:W35) -> 0
A36: 4 | B36: Jumlah surat suara yang tidak digunakan/tidak terpakai, termasuk sisa surat suara cadangan | E36: =E33-(E34+E35) -> 42 | F36: =F33-(F34+F35) -> 52 | G36: =G33-(G34+G35) -> 39 | H36: =H33-(H34+H35) -> 57 | I36: =I33-(I34+I35) -> 59 | J36: =J33-(J34+J35) -> 88 | K36: =K33-(K34+K35) -> 54 | L36: =L33-(L34+L35) -> 75 | ... W36: =W33-(W34+W35) -> 62 | X36: =SUM(E36:W36) -> 1182
A38: III | B38: DATA PEMILIH DISABILITAS
B39: Jumlah seluruh Pemilih disabilitas yang menggunakan hak pilih | D39: LK | E39: 0 | F39: 0 | G39: 1 | H39: 2 | I39: 0 | J39: 4 | K39: 0 | L39: 0 | M39: 0 | N39: 0 | O39: 0 | P39: 0 | Q39: 0 | R39: 0 | S39: 0 | T39: 0 | U39: 0 | V39: 0 | W39: 0 | X39: =SUM(E39:W39) -> 7
D40: PR | E40: 0 | F40: 0 | G40: 1 | H40: 0 | I40: 1 | J40: 3 | K40: 0 | L40: 0 | M40: 0 | N40: 1 | O40: 0 | P40: 0 | Q40: 0 | R40: 1 | S40: 1 | T40: 0 | U40: 0 | V40: 0 | W40: 0 | X40: =SUM(E40:W40) -> 8
D41: JML | E41: =SUM(E39:E40) -> 0 | F41: =SUM(F39:F40) -> 0 | G41: =SUM(G39:G40) -> 2 | H41: =SUM(H39:H40) -> 2 | I41: =SUM(I39:I40) -> 1 | J41: =SUM(J39:J40) -> 7 | K41: =SUM(K39:K40) -> 0 | L41: =SUM(L39:L40) -> 0 | ... W41: =SUM(W39:W40) -> 0 | X41: =SUM(E41:W41) -> 15
A43: IV | B43: DATA RINCIAN PEROLEHAN SUARA PASANGAN CALON BUPATI DAN WAKIL BUPATI
A44: NOMOR DAN NAMA CALON
B45: 1 | C45: H. ANIES RASYID BASWEDAN, Ph.D. - Dr. (H.C.) H. A. MUHAIMIN ISKANDAR | E45: 6 | F45: 7 | G45: 5 | H45: 8 | I45: 7 | J45: 5 | K45: 20 | L45: 11 | M45: 27 | N45: 16 | O45: 22 | P45: 22 | Q45: 8 | R45: 12 | S45: 14 | T45: 12 | U45: 2 | V45: 12 | W45: 7 | X45: =SUM(E45:W45) -> 223
B46: 2 | C46: H. PRABOWO SUBIANTO - GIBRAN RAKABUMING RAKA | E46: 109 | F46: 111 | G46: 154 | H46: 152 | I46: 128 | J46: 165 | K46: 152 | L46: 149 | M46: 146 | N46: 129 | O46: 163 | P46: 147 | Q46: 178 | R46: 140 | S46: 137 | T46: 141 | U46: 134 | V46: 141 | W46: 131 | X46: =SUM(E46:W46) -> 2707
B47: 3 | C47: H. GANJAR PRANOWO, S.H., M.I.P. - Prof. Dr. H. M. MAHFUD MD | E47: 45 | F47: 30 | G47: 40 | H47: 80 | I47: 79 | J47: 40 | K47: 61 | L47: 60 | M47: 48 | N47: 72 | O47: 41 | P47: 34 | Q47: 50 | R47: 41 | S47: 32 | T47: 34 | U47: 12 | V47: 21 | W47: 20 | X47: =SUM(E47:W47) -> 840
A49: V | B49: DATA SUARA SAH DAN TIDAK SAH
B50: A. | C50: JUMLAH SELURUH SUARA SAH | E50: =SUM(E45:E47) -> 160 | F50: =SUM(F45:F47) -> 148 | G50: =SUM(G45:G47) -> 199 | H50: =SUM(H45:H47) -> 240 | I50: =SUM(I45:I47) -> 214 | J50: =SUM(J45:J47) -> 210 | K50: =SUM(K45:K47) -> 233 | L50: =SUM(L45:L47) -> 220 | ... W50: =SUM(W45:W47) -> 158 | X50: =SUM(E50:W50) -> 3770
B51: B. | C51: JUMLAH SUARA TIDAK SAH | E51: 6 | F51: 4 | G51: 2 | H51: 3 | I51: 5 | J51: 1 | K51: 5 | L51: 3 | M51: 3 | N51: 5 | O51: 2 | P51: 5 | Q51: 6 | R51: 7 | S51: 7 | T51: 5 | U51: 2 | V51: 2 | W51: 1 | X51: =SUM(E51:W51) -> 74
B52: C. | C52: JUMLAH SELURUH SUARA SAH DAN SUARA TIDAK SAH (V.A + V.B) | E52: =SUM(E50:E51) -> 166 | F52: =SUM(F50:F51) -> 152 | G52: =SUM(G50:G51) -> 201 | H52: =SUM(H50:H51) -> 243 | I52: =SUM(I50:I51) -> 219 | J52: =SUM(J50:J51) -> 211 | K52: =SUM(K50:K51) -> 238 | L52: =SUM(L50:L51) -> 223 | ... W52: =SUM(W50:W51) -> 159 | X52: =SUM(E52:W52) -> 3844

Sheet SUMBERAGUNG
C2: Kecamatan | D2: PESANGGARAN
C3: Kabupaten | D3: BANYUWANGI
C4: Provinsi | D4: JAWA TIMUR
C9: Kelurahan | D9: SUMBERAGUNG
A12: I | B12: DATA PEMILIH DAN PENGGUNAAN HAK PILIH | AX12: JUMLAH AKHIR
A13: A | B13: DATA PEMILIH | E13: TPS 001 | F13: TPS 002 | G13: TPS 003 | H13: TPS 004 | I13: TPS 005 | J13: TPS 006 | K13: TPS 007 | L13: TPS 008 | M13: TPS 009 | N13: TPS 010 | O13: TPS 011 | P13: TPS 012 | Q13: TPS 013 | R13: TPS 014 | S13: TPS 015 | T13: TPS 016 | U13: TPS 017 | V13: TPS 018 | W13: TPS 019 | X13: TPS 020 | Y13: TPS 021 | Z13: TPS 022 | AA13: TPS 023 | AB13: TPS 024 | AC13: TPS 025 | AD13: TPS 026 | AE13: TPS 027 | AF13: TPS 028 | AG13: TPS 029 | AH13: TPS 030 | AI13: TPS 031 | AJ13: TPS 032 | AK13: TPS 033 | AL13: TPS 034 | AM13: TPS 035 | AN13: TPS 036 | AO13: TPS 037 | AP13: TPS 038 | AQ13: TPS 039 | AR13: TPS 040 | AS13: TPS 041 | AT13: TPS 042 | AU13: TPS 043 | AV13: TPS 044 | AW13: TPS 045
B14: Jumlah Pemilih dalam Daftar Pemilih Tetap (DPT) | D14: LK | E14: 137 | F14: 149 | G14: 147 | H14: 151 | I14: 145 | J14: 148 | K14: 145 | L14: 133 | M14: 129 | N14: 139 | O14: 143 | P14: 143 | Q14: 142 | R14: 131 | S14: 108 | T14: 97 | U14: 120 | V14: 123 | W14: 133 | X14: 134 | Y14: 129 | Z14: 149 | AA14: 134 | AB14: 141 | AC14: 132 | AD14: 150 | AE14: 129 | AF14: 96 | AG14: 138 | AH14: 125 | AI14: 142 | AJ14: 149 | AK14: 153 | AL14: 140 | AM14: 153 | AN14: 140 | AO14: 135 | AP14: 128 | AQ14: 149 | AR14: 114 | AS14: 114 | AT14: 120 | AU14: 127 | AV14: 140 | AW14: 144 | AX14: =SUM(E14:AW14) -> 6068
D15: PR | E15: 153 | F15: 143 | G15: 149 | H15: 144 | I15: 150 | J15: 147 | K15: 142 | L15: 146 | M15: 123 | N15: 157 | O15: 144 | P15: 142 | Q15: 146 | R15: 137 | S15: 109 | T15: 90 | U15: 102 | V15: 117 | W15: 126 | X15: 118 | Y15: 131 | Z15: 137 | AA15: 127 | AB15: 121 | AC15: 149 | AD15: 138 | AE15: 125 | AF15: 91 | AG15: 142 | AH15: 123 | AI15: 145 | AJ15: 144 | AK15: 144 | AL15: 145 | AM15: 134 | AN15: 143 | AO15: 149 | AP15: 111 | AQ15: 141 | AR15: 117 | AS15: 110 | AT15: 102 | AU15: 127 | AV15: 139 | AW15: 133 | AX15: =SUM(E15:AW15) -> 5953
D16: JML | E16: =SUM(E14:E15) -> 290 | F16: =SUM(F14:F15) -> 292 | G16: =SUM(G14:G15) -> 296 | H16: =SUM(H14:H15) -> 295 | I16: =SUM(I14:I15) -> 295 | J16: =SUM(J14:J15) -> 295 | K16: =SUM(K14:K15) -> 287 | L16: =SUM(L14:L15) -> 279 | ... AW16: =SUM(AW14:AW15) -> 277 | AX16: =SUM(E16:AW16) -> 12021
A18: B | B18: PENGGUNA HAK PILIH
B19: 1. | C19: Jumlah pengguna hak pilih dalam Daftar Pemilih Tetap (DPT) | D19: LK | E19: 111 | F19: 119 | G19: 117 | H19: 120 | I19: 107 | J19: 112 | K19: 111 | L19: 93 | M19: 91 | N19: 106 | O19: 108 | P19: 93 | Q19: 105 | R19: 108 | S19: 82 | T19: 73 | U19: 96 | V19: 89 | W19: 102 | X19: 112 | Y19: 104 | Z19: 112 | AA19: 106 | AB19: 114 | AC19: 104 | AD19: 120 | AE19: 92 | AF19: 87 | AG19: 109 | AH19: 98 | AI19: 108 | AJ19: 108 | AK19: 119 | AL19: 101 | AM19: 99 | AN19: 109 | AO19: 114 | AP19: 91 | AQ19: 105 | AR19: 77 | AS19: 75 | AT19: 87 | AU19: 84 | AV19: 110 | AW19: 106 | AX19: =SUM(E19:AW19) -> 4594
D20: PR | E20: 112 | F20: 113 | G20: 116 | H20: 116 | I20: 115 | J20: 114 | K20: 108 | L20: 109 | M20: 92 | N20: 142 | O20: 114 | P20: 101 | Q20: 109 | R20: 114 | S20: 81 | T20: 73 | U20: 89 | V20: 72 | W20: 101 | X20: 96 | Y20: 106 | Z20: 109 | AA20: 88 | AB20: 96 | AC20: 120 | AD20: 108 | AE20: 102 | AF20: 76 | AG20: 108 | AH20: 100 | AI20: 111 | AJ20: 113 | AK20: 115 | AL20: 114 | AM20: 95 | AN20: 114 | AO20: 117 | AP20: 84 | AQ20: 117 | AR20: 88 | AS20: 81 | AT20: 80 | AU20: 92 | AV20: 110 | AW20: 91 | AX20: =SUM(E20:AW20) -> 4622
D21: JML | E21: =SUM(E19:E20) -> 223 | F21: =SUM(F19:F20) -> 232 | G21: =SUM(G19:G20) -> 233 | H21: =SUM(H19:H20) -> 236 | I21: =SUM(I19:I20) -> 222 | J21: =SUM(J19:J20) -> 226 | K21: =SUM(K19:K20) -> 219 | L21: =SUM(L19:L20) -> 202 | ... AW21: =SUM(AW19:AW20) -> 197 | AX21: =SUM(E21:AW21) -> 9216
B22: 2. | C22: Jumlah pengguna hak pilih dalam Daftar Pemilih Tambahan (DPTb) | D22: LK | E22: 0 | F22: 1 | G22: 0 | H22: 0 | I22: 0 | J22: 0 | K22: 0 | L22: 0 | M22: 0 | N22: 3 | O22: 2 | P22: 11 | Q22: 8 | R22: 10 | S22: 9 | T22: 6 | U22: 4 | V22: 0 | W22: 5 | X22: 4 | Y22: 7 | Z22: 0 | AA22: 1 | AB22: 1 | AC22: 0 | AD22: 3 | AE22: 9 | AF22: 10 | AG22: 14 | AH22: 9 | AI22: 3 | AJ22: 10 | AK22: 5 | AL22: 0 | AM22: 0 | AN22: 0 | AO22: 0 | AP22: 0 | AQ22: 0 | AR22: 0 | AS22: 0 | AT22: 0 | AU22: 0 | AV22: 0 | AW22: 0 | AX22: =SUM(E22:AW22) -> 135
D23: PR | E23: 0 | F23: 0 | G23: 0 | H23: 0 | I23: 0 | J23: 0 | K23: 0 | L23: 0 | M23: 0 | N23: 0 | O23: 2 | P23: 0 | Q23: 3 | R23: 2 | S23: 1 | T23: 2 | U23: 2 | V23: 0 | W23: 0 | X23: 0 | Y23: 0 | Z23: 0 | AA23: 0 | AB23: 1 | AC23: 0 | AD23: 0 | AE23: 3 | AF23: 0 | AG23: 0 | AH23: 0 | AI23: 3 | AJ23: 0 | AK23: 0 | AL23: 0 | AM23: 0 | AN23: 0 | AO23: 0 | AP23: 0 | AQ23: 0 | AR23: 0 | AS23: 0 | AT23: 0 | AU23: 0 | AV23: 0 | AW23: 0 | AX23: =SUM(E23:AW23) -> 19
D24: JML | E24: =SUM(E22:E23) -> 0 | F24: =SUM(F22:F23) -> 1 | G24: =SUM(G22:G23) -> 0 | H24: =SUM(H22:H23) -> 0 | I24: =SUM(I22:I23) -> 0 | J24: =SUM(J22:J23) -> 0 | K24: =SUM(K22:K23) -> 0 | L24: =SUM(L22:L23) -> 0 | ... AW24: =SUM(AW22:AW23) -> 0 | AX24: =SUM(E24:AW24) -> 154
B25: 3. | C25: Jumlah pengguna hak pilih dalam Daftar Pemilih Khusus (DPK) | D25: LK | E25: 1 | F25: 3 | G25: 3 | H25: 2 | I25: 5 | J25: 1 | K25: 0 | L25: 1 | M25: 0 | N25: 3 | O25: 0 | P25: 1 | Q25: 4 | R25: 0 | S25: 0 | T25: 2 | U25: 1 | V25: 0 | W25: 4 | X25: 1 | Y25: 1 | Z25: 1 | AA25: 0 | AB25: 3 | AC25: 0 | AD25: 0 | AE25: 1 | AF25: 0 | AG25: 6 | AH25: 0 | AI25: 3 | AJ25: 3 | AK25: 1 | AL25: 3 | AM25: 4 | AN25: 5 | AO25: 3 | AP25: 3 | AQ25: 1 | AR25: 11 | AS25: 0 | AT25: 9 | AU25: 0 | AV25: 0 | AW25: 2 | AX25: =SUM(E25:AW25) -> 92
D26: PR | E26: 2 | F26: 0 | G26: 0 | H26: 4 | I26: 3 | J26: 1 | K26: 0 | L26: 1 | M26: 0 | N26: 0 | O26: 2 | P26: 3 | Q26: 2 | R26: 3 | S26: 0 | T26: 2 | U26: 1 | V26: 0 | W26: 5 | X26: 3 | Y26: 1 | Z26: 4 | AA26: 0 | AB26: 3 | AC26: 1 | AD26: 0 | AE26: 0 | AF26: 0 | AG26: 2 | AH26: 0 | AI26: 0 | AJ26: 1 | AK26: 0 | AL26: 0 | AM26: 6 | AN26: 1 | AO26: 2 | AP26: 4 | AQ26: 0 | AR26: 8 | AS26: 1 | AT26: 9 | AU26: 0 | AV26: 1 | AW26: 2 | AX26: =SUM(E26:AW26) -> 78
D27: JML | E27: =SUM(E25:E26) -> 3 | F27: =SUM(F25:F26) -> 3 | G27: =SUM(G25:G26) -> 3 | H27: =SUM(H25:H26) -> 6 | I27: =SUM(I25:I26) -> 8 | J27: =SUM(J25:J26) -> 2 | K27: =SUM(K25:K26) -> 0 | L27: =SUM(L25:L26) -> 2 | ... AW27: =SUM(AW25:AW26) -> 4 | AX27: =SUM(E27:AW27) -> 170
B28: 4. | C28: Jumlah Pengguna Hak Pilih (B.1+B.2+B.3) | D28: LK | E28: =SUM(E19,E22,E25) -> 112 | F28: =SUM(F19,F22,F25) -> 123 | G28: =SUM(G19,G22,G25) -> 120 | H28: =SUM(H19,H22,H25) -> 122 | I28: =SUM(I19,I22,I25) -> 112 | J28: =SUM(J19,J22,J25) -> 113 | K28: =SUM(K19,K22,K25) -> 111 | L28: =SUM(L19,L22,L25) -> 94 | ... AW28: =SUM(AW19,AW22,AW25) -> 108 | AX28: =SUM(E28:AW28) -> 4821
D29: PR | E29: =SUM(E20,E23,E26) -> 114 | F29: =SUM(F20,F23,F26) -> 113 | G29: =SUM(G20,G23,G26) -> 116 | H29: =SUM(H20,H23,H26) -> 120 | I29: =SUM(I20,I23,I26) -> 118 | J29: =SUM(J20,J23,J26) -> 115 | K29: =SUM(K20,K23,K26) -> 108 | L29: =SUM(L20,L23,L26) -> 110 | ... AW29: =SUM(AW20,AW23,AW26) -> 93 | AX29: =SUM(E29:AW29) -> 4719
D30: JML | E30: =SUM(E28:E29) -> 226 | F30: =SUM(F28:F29) -> 236 | G30: =SUM(G28:G29) -> 236 | H30: =SUM(H28:H29) -> 242 | I30: =SUM(I28:I29) -> 230 | J30: =SUM(J28:J29) -> 228 | K30: =SUM(K28:K29) -> 219 | L30: =SUM(L28:L29) -> 204 | ... AW30: =SUM(AW28:AW29) -> 201 | AX30: =SUM(E30:AW30) -> 9540
A32: II | B32: DATA PENGGUNAAN SURAT SUARA
A33: 1 | B33: Jumlah surat suara yang diterima, termasuk surat suara cadangan 2,5% dari DPT | E33: 296 | F33: 304 | G33: 302 | H33: 301 | I33: 301 | J33: 302 | K33: 303 | L33: 286 | M33: 257 | N33: 302 | O33: 293 | P33: 291 | Q33: 294 | R33: 274 | S33: 222 | T33: 191 | U33: 226 | V33: 245 | W33: 265 | X33: 258 | Y33: 266 | Z33: 292 | AA33: 267 | AB33: 271 | AC33: 289 | AD33: 297 | AE33: 260 | AF33: 191 | AG33: 287 | AH33: 253 | AI33: 290 | AJ33: 299 | AK33: 303 | AL33: 291 | AM33: 293 | AN33: 238 | AO33: 290 | AP33: 244 | AQ33: 298 | AR33: 237 | AS33: 231 | AT33: 228 | AU33: 260 | AV33: 285 | AW33: 283 | AX33: =SUM(E33:AW33) -> 12256
A34: 2 | B34: Jumlah surat suara yang digunakan | E34: 226 | F34: 236 | G34: 236 | H34: 242 | I34: 233 | J34: 228 | K34: 219 | L34: 204 | M34: 183 | N34: 254 | O34: 228 | P34: 209 | Q34: 231 | R34: 237 | S34: 173 | T34: 158 | U34: 193 | V34: 161 | W34: 217 | X34: 216 | Y34: 219 | Z34: 226 | AA34: 195 | AB34: 218 | AC34: 225 | AD34: 231 | AE34: 207 | AF34: 173 | AG34: 239 | AH34: 207 | AI34: 228 | AJ34: 235 | AK34: 240 | AL34: 218 | AM34: 204 | AN34: 229 | AO34: 236 | AP34: 182 | AQ34: 223 | AR34: 184 | AS34: 157 | AT34: 185 | AU34: 176 | AV34: 221 | AW34: 201 | AX34: =SUM(E34:AW34) -> 9543
A35: 3 | B35: Jumlah surat suara dikembalikan oleh pemilih (karena rusak atau keliru coblos) | E35: 0 | F35: 0 | G35: 0 | H35: 0 | I35: 0 | J35: 0 | K35: 0 | L35: 0 | M35: 0 | N35: 0 | O35: 0 | P35: 0 | Q35: 0 | R35: 4 | S35: 0 | T35: 0 | U35: 0 | V35: 0 | W35: 0 | X35: 0 | Y35: 0 | Z35: 0 | AA35: 0 | AB35: 1 | AC35: 2 | AD35: 11 | AE35: 1 | AF35: 0 | AG35: 0 | AH35: 0 | AI35: 0 | AJ35: 0 | AK35: 0 | AL35: 0 | AM35: 0 | AN35: 0 | AO35: 0 | AP35: 0 | AQ35: 0 | AR35: 0 | AS35: 0 | AT35: 0 | AU35: 0 | AV35: 0 | AW35: 0 | AX35: =SUM(E35:AW35) -> 19
A36: 4 | B36: Jumlah surat suara yang tidak digunakan/tidak terpakai, termasuk sisa surat suara cadangan | E36: =E33-(E34+E35) -> 70 | F36: =F33-(F34+F35) -> 68 | G36: =G33-(G34+G35) -> 66 | H36: =H33-(H34+H35) -> 59 | I36: =I33-(I34+I35) -> 68 | J36: =J33-(J34+J35) -> 74 | K36: =K33-(K34+K35) -> 84 | L36: =L33-(L34+L35) -> 82 | ... AW36: =AW33-(AW34+AW35) -> 82 | AX36: =SUM(E36:AW36) -> 2694
A38: III | B38: DATA PEMILIH DISABILITAS
B39: Jumlah seluruh Pemilih disabilitas yang menggunakan hak pilih | D39: LK | E39: 0 | F39: 0 | G39: 0 | H39: 0 | I39: 0 | J39: 0 | K39: 0 | L39: 0 | M39: 0 | N39: 0 | O39: 1 | P39: 0 | Q39: 0 | R39: 0 | S39: 0 | T39: 0 | U39: 0 | V39: 0 | W39: 0 | X39: 0 | Y39: 0 | Z39: 0 | AA39: 0 | AB39: 0 | AC39: 0 | AD39: 0 | AE39: 0 | AF39: 2 | AG39: 0 | AH39: 1 | AI39: 1 | AJ39: 0 | AK39: 0 | AL39: 0 | AM39: 0 | AN39: 0 | AO39: 0 | AP39: 0 | AQ39: 0 | AR39: 1 | AS39: 0 | AT39: 0 | AU39: 0 | AV39: 0 | AW39: 0 | AX39: =SUM(E39:AW39) -> 6
D40: PR | E40: 0 | F40: 0 | G40: 0 | H40: 0 | I40: 0 | J40: 2 | K40: 0 | L40: 0 | M40: 0 | N40: 0 | O40: 0 | P40: 1 | Q40: 0 | R40: 0 | S40: 0 | T40: 0 | U40: 0 | V40: 0 | W40: 0 | X40: 0 | Y40: 0 | Z40: 0 | AA40: 0 | AB40: 0 | AC40: 0 | AD40: 0 | AE40: 0 | AF40: 0 | AG40: 0 | AH40: 0 | AI40: 0 | AJ40: 0 | AK40: 0 | AL40: 0 | AM40: 0 | AN40: 0 | AO40: 0 | AP40: 0 | AQ40: 0 | AR40: 1 | AS40: 0 | AT40: 0 | AU40: 0 | AV40: 0 | AW40: 0 | AX40: =SUM(E40:AW40) -> 4
D41: JML | E41: =SUM(E39:E40) -> 0 | F41: =SUM(F39:F40) -> 0 | G41: =SUM(G39:G40) -> 0 | H41: =SUM(H39:H40) -> 0 | I41: =SUM(I39:I40) -> 0 | J41: =SUM(J39:J40) -> 2 | K41: =SUM(K39:K40) -> 0 | L41: =SUM(L39:L40) -> 0 | ... AW41: =SUM(AW39:AW40) -> 0 | AX41: =SUM(E41:AW41) -> 10
A43: IV | B43: DATA RINCIAN PEROLEHAN SUARA PASANGAN CALON BUPATI DAN WAKIL BUPATI
A44: NOMOR DAN NAMA CALON
B45: 1 | C45: H. ANIES RASYID BASWEDAN, Ph.D. - Dr. (H.C.) H. A. MUHAIMIN ISKANDAR | E45: 14 | F45: 14 | G45: 11 | H45: 10 | I45: 6 | J45: 14 | K45: 13 | L45: 17 | M45: 13 | N45: 32 | O45: 15 | P45: 18 | Q45: 29 | R45: 23 | S45: 11 | T45: 18 | U45: 10 | V45: 11 | W45: 15 | X45: 13 | Y45: 8 | Z45: 14 | AA45: 3 | AB45: 15 | AC45: 27 | AD45: 7 | AE45: 11 | AF45: 3 | AG45: 19 | AH45: 16 | AI45: 17 | AJ45: 14 | AK45: 11 | AL45: 12 | AM45: 4 | AN45: 2 | AO45: 14 | AP45: 9 | AQ45: 9 | AR45: 19 | AS45: 4 | AT45: 8 | AU45: 23 | AV45: 18 | AW45: 11 | AX45: =SUM(E45:AW45) -> 605
B46: 2 | C46: H. PRABOWO SUBIANTO - GIBRAN RAKABUMING RAKA | E46: 136 | F46: 187 | G46: 159 | H46: 155 | I46: 155 | J46: 156 | K46: 146 | L46: 126 | M46: 132 | N46: 165 | O46: 163 | P46: 136 | Q46: 132 | R46: 169 | S46: 112 | T46: 105 | U46: 140 | V46: 127 | W46: 155 | X46: 143 | Y46: 149 | Z46: 143 | AA46: 141 | AB46: 153 | AC46: 150 | AD46: 141 | AE46: 162 | AF46: 129 | AG46: 160 | AH46: 145 | AI46: 165 | AJ46: 171 | AK46: 157 | AL46: 167 | AM46: 162 | AN46: 193 | AO46: 195 | AP46: 158 | AQ46: 186 | AR46: 147 | AS46: 132 | AT46: 123 | AU46: 132 | AV46: 173 | AW46: 166 | AX46: =SUM(E46:AW46) -> 6799
B47: 3 | C47: H. GANJAR PRANOWO, S.H., M.I.P. - Prof. Dr. H. M. MAHFUD MD | E47: 69 | F47: 33 | G47: 62 | H47: 73 | I47: 72 | J47: 56 | K47: 56 | L47: 56 | M47: 37 | N47: 57 | O47: 48 | P47: 50 | Q47: 66 | R47: 44 | S47: 48 | T47: 33 | U47: 41 | V47: 22 | W47: 43 | X47: 54 | Y47: 58 | Z47: 67 | AA47: 44 | AB47: 42 | AC47: 47 | AD47: 74 | AE47: 32 | AF47: 36 | AG47: 57 | AH47: 43 | AI47: 46 | AJ47: 45 | AK47: 65 | AL47: 36 | AM47: 38 | AN47: 32 | AO47: 26 | AP47: 9 | AQ47: 25 | AR47: 17 | AS47: 17 | AT47: 52 | AU47: 19 | AV47: 28 | AW47: 23 | AX47: =SUM(E47:AW47) -> 1998
A49: V | B49: DATA SUARA SAH DAN TIDAK SAH
B50: A. | C50: JUMLAH SELURUH SUARA SAH | E50: =SUM(E45:E47) -> 219 | F50: =SUM(F45:F47) -> 234 | G50: =SUM(G45:G47) -> 232 | H50: =SUM(H45:H47) -> 238 | I50: =SUM(I45:I47) -> 233 | J50: =SUM(J45:J47) -> 226 | K50: =SUM(K45:K47) -> 215 | L50: =SUM(L45:L47) -> 199 | ... AW50: =SUM(AW45:AW47) -> 200 | AX50: =SUM(E50:AW50) -> 9402
B51: B. | C51: JUMLAH SUARA TIDAK SAH | E51: 7 | F51: 2 | G51: 4 | H51: 4 | I51: 0 | J51: 2 | K51: 4 | L51: 5 | M51: 1 | N51: 0 | O51: 2 | P51: 5 | Q51: 4 | R51: 1 | S51: 2 | T51: 2 | U51: 2 | V51: 1 | W51: 4 | X51: 6 | Y51: 4 | Z51: 2 | AA51: 7 | AB51: 8 | AC51: 1 | AD51: 9 | AE51: 2 | AF51: 5 | AG51: 3 | AH51: 3 | AI51: 0 | AJ51: 5 | AK51: 7 | AL51: 3 | AM51: 0 | AN51: 2 | AO51: 1 | AP51: 6 | AQ51: 3 | AR51: 1 | AS51: 4 | AT51: 2 | AU51: 2 | AV51: 2 | AW51: 1 | AX51: =SUM(E51:AW51) -> 141
B52: C. | C52: JUMLAH SELURUH SUARA SAH DAN SUARA TIDAK SAH (V.A + V.B) | E52: =SUM(E50:E51) -> 226 | F52: =SUM(F50:F51) -> 236 | G52: =SUM(G50:G51) -> 236 | H52: =SUM(H50:H51) -> 242 | I52: =SUM(I50:I51) -> 233 | J52: =SUM(J50:J51) -> 228 | K52: =SUM(K50:K51) -> 219 | L52: =SUM(L50:L51) -> 204 | ... AW52: =SUM(AW50:AW51) -> 201 | AX52: =SUM(E52:AW52) -> 9543

Sheet SUMBERMULYO
C2: Kecamatan | D2: PESANGGARAN
C3: Kabupaten | D3: BANYUWANGI
C4: Provinsi | D4: JAWA TIMUR
C9: Kelurahan | D9: SUMBERMULYO
A12: I | B12: DATA PEMILIH DAN PENGGUNAAN HAK PILIH | AB12: JUMLAH AKHIR
A13: A | B13: DATA PEMILIH | E13: TPS 001 | F13: TPS 002 | G13: TPS 003 | H13: TPS 004 | I13: TPS 005 | J13: TPS 006 | K13: TPS 007 | L13: TPS 008 | M13: TPS 009 | N13: TPS 010 | O13: TPS 011 | P13: TPS 012 | Q13: TPS 013 | R13: TPS 014 | S13: TPS 015 | T13: TPS 016 | U13: TPS 017 | V13: TPS 018 | W13: TPS 019 | X13: TPS 020 | Y13: TPS 021 | Z13: TPS 022 | AA13: TPS 023
B14: Jumlah Pemilih dalam Daftar Pemilih Tetap (DPT) | D14: LK | E14: 156 | F14: 144 | G14: 150 | H14: 150 | I14: 137 | J14: 140 | K14: 138 | L14: 129 | M14: 106 | N14: 154 | O14: 124 | P14: 126 | Q14: 96 | R14: 146 | S14: 148 | T14: 144 | U14: 151 | V14: 120 | W14: 133 | X14: 123 | Y14: 143 | Z14: 132 | AA14: 145 | AB14: =SUM(E14:AA14) -> 3135
D15: PR | E15: 141 | F15: 148 | G15: 146 | H15: 148 | I15: 142 | J15: 149 | K15: 137 | L15: 127 | M15: 113 | N15: 136 | O15: 143 | P15: 120 | Q15: 94 | R15: 143 | S15: 144 | T15: 152 | U15: 144 | V15: 127 | W15: 131 | X15: 137 | Y15: 135 | Z15: 131 | AA15: 150 | AB15: =SUM(E15:AA15) -> 3138
D16: JML | E16: =SUM(E14:E15) -> 297 | F16: =SUM(F14:F15) -> 292 | G16: =SUM(G14:G15) -> 296 | H16: =SUM(H14:H15) -> 298 | I16: =SUM(I14:I15) -> 279 | J16: =SUM(J14:J15) -> 289 | K16: =SUM(K14:K15) -> 275 | L16: =SUM(L14:L15) -> 256 | ... AA16: =SUM(AA14:AA15) -> 295 | AB16: =SUM(E16:AA16) -> 6273
A18: B | B18: PENGGUNA HAK PILIH
B19: 1. | C19: Jumlah pengguna hak pilih dalam Daftar Pemilih Tetap (DPT) | D19: LK | E19: 125 | F19: 118 | G19: 119 | H19: 104 | I19: 100 | J19: 104 | K19: 92 | L19: 94 | M19: 81 | N19: 120 | O19: 96 | P19: 103 | Q19: 70 | R19: 118 | S19: 119 | T19: 110 | U19: 122 | V19: 88 | W19: 111 | X19: 104 | Y19: 122 | Z19: 113 | AA19: 122 | AB19: =SUM(E19:AA19) -> 2455
D20: PR | E20: 115 | F20: 116 | G20: 110 | H20: 107 | I20: 110 | J20: 109 | K20: 103 | L20: 100 | M20: 92 | N20: 102 | O20: 109 | P20: 100 | Q20: 70 | R20: 112 | S20: 112 | T20: 105 | U20: 123 | V20: 99 | W20: 106 | X20: 118 | Y20: 117 | Z20: 108 | AA20: 114 | AB20: =SUM(E20:AA20) -> 2457
D21: JML | E21: =SUM(E19:E20) -> 240 | F21: =SUM(F19:F20) -> 234 | G21: =SUM(G19:G20) -> 229 | H21: =SUM(H19:H20) -> 211 | I21: =SUM(I19:I20) -> 210 | J21: =SUM(J19:J20) -> 213 | K21: =SUM(K19:K20) -> 195 | L21: =SUM(L19:L20) -> 194 | ... AA21: =SUM(AA19:AA20) -> 236 | AB21: =SUM(E21:AA21) -> 4912
B22: 2. | C22: Jumlah pengguna hak pilih dalam Daftar Pemilih Tambahan (DPTb) | D22: LK | E22: 0 | F22: 0 | G22: 0 | H22: 0 | I22: 0 | J22: 0 | K22: 3 | L22: 0 | M22: 6 | N22: 1 | O22: 0 | P22: 0 | Q22: 8 | R22: 0 | S22: 0 | T22: 1 | U22: 0 | V22: 10 | W22: 8 | X22: 0 | Y22: 0 | Z22: 5 | AA22: 0 | AB22: =SUM(E22:AA22) -> 42
D23: PR | E23: 0 | F23: 0 | G23: 0 | H23: 0 | I23: 0 | J23: 0 | K23: 2 | L23: 1 | M23: 2 | N23: 0 | O23: 0 | P23: 0 | Q23: 1 | R23: 0 | S23: 0 | T23: 0 | U23: 0 | V23: 1 | W23: 0 | X23: 0 | Y23: 8 | Z23: 0 | AA23: 0 | AB23: =SUM(E23:AA23) -> 15
D24: JML | E24: =SUM(E22:E23) -> 0 | F24: =SUM(F22:F23) -> 0 | G24: =SUM(G22:G23) -> 0 | H24: =SUM(H22:H23) -> 0 | I24: =SUM(I22:I23) -> 0 | J24: =SUM(J22:J23) -> 0 | K24: =SUM(K22:K23) -> 5 | L24: =SUM(L22:L23) -> 1 | ... AA24: =SUM(AA22:AA23) -> 0 | AB24: =SUM(E24:AA24) -> 57
B25: 3. | C25: Jumlah pengguna hak pilih dalam Daftar Pemilih Khusus (DPK) | D25: LK | E25: 2 | F25: 1 | G25: 4 | H25: 11 | I25: 2 | J25: 1 | K25: 0 | L25: 2 | M25: 1 | N25: 2 | O25: 0 | P25: 0 | Q25: 0 | R25: 1 | S25: 0 | T25: 0 | U25: 0 | V25: 0 | W25: 1 | X25: 0 | Y25: 0 | Z25: 0 | AA25: 0 | AB25: =SUM(E25:AA25) -> 28
D26: PR | E26: 2 | F26: 1 | G26: 3 | H26: 8 | I26: 2 | J26: 3 | K26: 1 | L26: 1 | M26: 1 | N26: 3 | O26: 0 | P26: 1 | Q26: 0 | R26: 1 | S26: 1 | T26: 1 | U26: 4 | V26: 1 | W26: 0 | X26: 2 | Y26: 1 | Z26: 0 | AA26: 0 | AB26: =SUM(E26:AA26) -> 37
D27: JML | E27: =SUM(E25:E26) -> 4 | F27: =SUM(F25:F26) -> 2 | G27: =SUM(G25:G26) -> 7 | H27: =SUM(H25:H26) -> 19 | I27: =SUM(I25:I26) -> 4 | J27: =SUM(J25:J26) -> 4 | K27: =SUM(K25:K26) -> 1 | L27: =SUM(L25:L26) -> 3 | ... AA27: =SUM(AA25:AA26) -> 0 | AB27: =SUM(E27:AA27) -> 65
B28: 4. | C28: Jumlah Pengguna Hak Pilih (B.1+B.2+B.3) | D28: LK | E28: =SUM(E19,E22,E25) -> 127 | F28: =SUM(F19,F22,F25) -> 119 | G28: =SUM(G19,G22,G25) -> 123 | H28: =SUM(H19,H22,H25) -> 115 | I28: =SUM(I19,I22,I25) -> 102 | J28: =SUM(J19,J22,J25) -> 105 | K28: =SUM(K19,K22,K25) -> 95 | L28: =SUM(L19,L22,L25) -> 96 | ... AA28: =SUM(AA19,AA22,AA25) -> 122 | AB28: =SUM(E28:AA28) -> 2525
D29: PR | E29: =SUM(E20,E23,E26) -> 117 | F29: =SUM(F20,F23,F26) -> 117 | G29: =SUM(G20,G23,G26) -> 113 | H29: =SUM(H20,H23,H26) -> 115 | I29: =SUM(I20,I23,I26) -> 112 | J29: =SUM(J20,J23,J26) -> 112 | K29: =SUM(K20,K23,K26) -> 106 | L29: =SUM(L20,L23,L26) -> 102 | ... AA29: =SUM(AA20,AA23,AA26) -> 114 | AB29: =SUM(E29:AA29) -> 2509
D30: JML | E30: =SUM(E28:E29) -> 244 | F30: =SUM(F28:F29) -> 236 | G30: =SUM(G28:G29) -> 236 | H30: =SUM(H28:H29) -> 230 | I30: =SUM(I28:I29) -> 214 | J30: =SUM(J28:J29) -> 217 | K30: =SUM(K28:K29) -> 201 | L30: =SUM(L28:L29) -> 198 | ... AA30: =SUM(AA28:AA29) -> 236 | AB30: =SUM(E30:AA30) -> 5034
A32: II | B32: DATA PENGGUNAAN SURAT SUARA
A33: 1 | B33: Jumlah surat suara yang diterima, termasuk surat suara cadangan 2,5% dari DPT | E33: 303 | F33: 299 | G33: 302 | H33: 303 | I33: 285 | J33: 295 | K33: 300 | L33: 262 | M33: 224 | N33: 295 | O33: 275 | P33: 250 | Q33: 194 | R33: 295 | S33: 299 | T33: 302 | U33: 301 | V33: 253 | W33: 274 | X33: 266 | Y33: 284 | Z33: 270 | AA33: 302 | AB33: =SUM(E33:AA33) -> 6433
A34: 2 | B34: Jumlah surat suara yang digunakan | E34: 244 | F34: 236 | G34: 236 | H34: 230 | I34: 214 | J34: 217 | K34: 201 | L34: 198 | M34: 183 | N34: 228 | O34: 205 | P34: 204 | Q34: 149 | R34: 232 | S34: 232 | T34: 217 | U34: 249 | V34: 199 | W34: 226 | X34: 224 | Y34: 248 | Z34: 226 | AA34: 236 | AB34: =SUM(E34:AA34) -> 5034
A35: 3 | B35: Jumlah surat suara dikembalikan oleh pemilih (karena rusak atau keliru coblos) | E35: 0 | F35: 0 | G35: 0 | H35: 0 | I35: 1 | J35: 0 | K35: 0 | L35: 0 | M35: 0 | N35: 0 | O35: 1 | P35: 0 | Q35: 0 | R35: 0 | S35: 0 | T35: 0 | U35: 0 | V35: 0 | W35: 0 | X35: 0 | Y35: 0 | Z35: 0 | AA35: 0 | AB35: =SUM(E35:AA35) -> 2
A36: 4 | B36: Jumlah surat suara yang tidak digunakan/tidak terpakai, termasuk sisa surat suara cadangan | E36: =E33-(E34+E35) -> 59 | F36: =F33-(F34+F35) -> 63 | G36: =G33-(G34+G35) -> 66 | H36: =H33-(H34+H35) -> 73 | I36: =I33-(I34+I35) -> 70 | J36: =J33-(J34+J35) -> 78 | K36: =K33-(K34+K35) -> 99 | L36: =L33-(L34+L35) -> 64 | ... AA36: =AA33-(AA34+AA35) -> 66 | AB36: =SUM(E36:AA36) -> 1397
A38: III | B38: DATA PEMILIH DISABILITAS
B39: Jumlah seluruh Pemilih disabilitas yang menggunakan hak pilih | D39: LK | E39: 0 | F39: 0 | G39: 0 | H39: 0 | I39: 0 | J39: 0 | K39: 0 | L39: 0 | M39: 0 | N39: 2 | O39: 0 | P39: 0 | Q39: 0 | R39: 1 | S39: 0 | T39: 0 | U39: 2 | V39: 0 | W39: 0 | X39: 0 | Y39: 0 | Z39: 1 | AA39: 0 | AB39: =SUM(E39:AA39) -> 6
D40: PR | E40: 0 | F40: 0 | G40: 0 | H40: 0 | I40: 0 | J40: 0 | K40: 0 | L40: 0 | M40: 0 | N40: 3 | O40: 0 | P40: 0 | Q40: 0 | R40: 0 | S40: 0 | T40: 0 | U40: 0 | V40: 0 | W40: 1 | X40: 0 | Y40: 0 | Z40: 0 | AA40: 0 | AB40: =SUM(E40:AA40) -> 4
D41: JML | E41: =SUM(E39:E40) -> 0 | F41: =SUM(F39:F40) -> 0 | G41: =SUM(G39:G40) -> 0 | H41: =SUM(H39:H40) -> 0 | I41: =SUM(I39:I40) -> 0 | J41: =SUM(J39:J40) -> 0 | K41: =SUM(K39:K40) -> 0 | L41: =SUM(L39:L40) -> 0 | ... AA41: =SUM(AA39:AA40) -> 0 | AB41: =SUM(E41:AA41) -> 10
A43: IV | B43: DATA RINCIAN PEROLEHAN SUARA PASANGAN CALON BUPATI DAN WAKIL BUPATI
A44: NOMOR DAN NAMA CALON
