Workbook

Sheet PPWP
C8: Kecamatan | D8: GENTENG
C9: Kabupaten | D9: BANYUWANGI
C10: Provinsi | D10: JAWA TIMUR
A12: I | B12: DATA PEMILIH DAN PENGGUNAAN HAK PILIH | E12: JUMLAH AKHIR
A13: A | B13: DATA PEMILIH
B14: Jumlah Pemilih dalam Daftar Pemilih Tetap (DPT) | D14: LK | E14: ='GENTENG KULON'!BK14+'GENTENG WETAN'!BL14+KALIGONDO!BB14+KEMBIRITAN!BQ14+SETAIL!BC14 -> 36085
D15: PR | E15: ='GENTENG KULON'!BK15+'GENTENG WETAN'!BL15+KALIGONDO!BB15+KEMBIRITAN!BQ15+SETAIL!BC15 -> 36168
D16: JML | E16: =SUM(E14:E15) -> 72253
A18: B | B18: PENGGUNA HAK PILIH
B19: 1. | C19: Jumlah pengguna hak pilih dalam Daftar Pemilih Tetap (DPT) | D19: LK | E19: ='GENTENG KULON'!BK19+'GENTENG WETAN'!BL19+KALIGONDO!BB19+KEMBIRITAN!BQ19+SETAIL!BC19 -> 26161
D20: PR | E20: ='GENTENG KULON'!BK20+'GENTENG WETAN'!BL20+KALIGONDO!BB20+KEMBIRITAN!BQ20+SETAIL!BC20 -> 28216
D21: JML | E21: =SUM(E19:E20) -> 54377
B22: 2. | C22: Jumlah pengguna hak pilih dalam Daftar Pemilih Tambahan (DPTb) | D22: LK | E22: ='GENTENG KULON'!BK22+'GENTENG WETAN'!BL22+KALIGONDO!BB22+KEMBIRITAN!BQ22+SETAIL!BC22 -> 249
D23: PR | E23: ='GENTENG KULON'!BK23+'GENTENG WETAN'!BL23+KALIGONDO!BB23+KEMBIRITAN!BQ23+SETAIL!BC23 -> 199
D24: JML | E24: =SUM(E22:E23) -> 448
B25: 3. | C25: Jumlah pengguna hak pilih dalam Daftar Pemilih Khusus (DPK) | D25: LK | E25: ='GENTENG KULON'!BK25+'GENTENG WETAN'!BL25+KALIGONDO!BB25+KEMBIRITAN!BQ25+SETAIL!BC25 -> 284
D26: PR | E26: ='GENTENG KULON'!BK26+'GENTENG WETAN'!BL26+KALIGONDO!BB26+KEMBIRITAN!BQ26+SETAIL!BC26 -> 398
D27: JML | E27: =SUM(E25:E26) -> 682
B28: 4. | C28: Jumlah Pengguna Hak Pilih (B.1+B.2+B.3) | D28: LK | E28: =E19+E22+E25 -> 26694
D29: PR | E29: =E20+E23+E26 -> 28813
D30: JML | E30: =SUM(E28:E29) -> 55507
A32: II | B32: DATA PENGGUNAAN SURAT SUARA
A33: 1 | B33: Jumlah surat suara yang diterima, termasuk surat suara cadangan 2,5% dari DPT | E33: ='GENTENG KULON'!BK33+'GENTENG WETAN'!BL33+KALIGONDO!BB33+KEMBIRITAN!BQ33+SETAIL!BC33 -> 73909
A34: 2 | B34: Jumlah surat suara yang digunakan | E34: ='GENTENG KULON'!BK34+'GENTENG WETAN'!BL34+KALIGONDO!BB34+KEMBIRITAN!BQ34+SETAIL!BC34 -> 55507
A35: 3 | B35: Jumlah surat suara dikembalikan oleh pemilih (karena rusak atau keliru coblos) | E35: ='GENTENG KULON'!BK35+'GENTENG WETAN'!BL35+KALIGONDO!BB35+KEMBIRITAN!BQ35+SETAIL!BC35 -> 77
A36: 4 | B36: Jumlah surat suara yang tidak digunakan/tidak terpakai, termasuk sisa surat suara cadangan | E36: =E33-(E34+E35) -> 18325
A38: III | B38: DATA PEMILIH DISABILITAS
B39: Jumlah seluruh Pemilih disabilitas yang menggunakan hak pilih | D39: LK | E39: ='GENTENG KULON'!BK39+'GENTENG WETAN'!BL39+KALIGONDO!BB39+KEMBIRITAN!BQ39+SETAIL!BC39 -> 47
D40: PR | E40: ='GENTENG KULON'!BK40+'GENTENG WETAN'!BL40+KALIGONDO!BB40+KEMBIRITAN!BQ40+SETAIL!BC40 -> 49
D41: JML | E41: =SUM(E39:E40) -> 96
A43: IV | B43: DATA RINCIAN PEROLEHAN SUARA PASANGAN CALON BUPATI DAN WAKIL BUPATI
A44: NOMOR DAN NAMA CALON
B45: 1 | C45: H. ANIES RASYID BASWEDAN, Ph.D. - Dr. (H.C.) H. A. MUHAIMIN ISKANDAR | E45: ='GENTENG KULON'!BK45+'GENTENG WETAN'!BL45+KALIGONDO!BB45+KEMBIRITAN!BQ45+SETAIL!BC45 -> 7895
B46: 2 | C46: H. PRABOWO SUBIANTO - GIBRAN RAKABUMING RAKA | E46: ='GENTENG KULON'!BK46+'GENTENG WETAN'!BL46+KALIGONDO!BB46+KEMBIRITAN!BQ46+SETAIL!BC46 -> 36179
B47: 3 | C47: H. GANJAR PRANOWO, S.H., M.I.P. - Prof. Dr. H. M. MAHFUD MD | E47: ='GENTENG KULON'!BK47+'GENTENG WETAN'!BL47+KALIGONDO!BB47+KEMBIRITAN!BQ47+SETAIL!BC47 -> 10586
A49: V | B49: DATA SUARA SAH DAN TIDAK SAH
B50: A. | C50: JUMLAH SELURUH SUARA SAH | E50: ='GENTENG KULON'!BK50+'GENTENG WETAN'!BL50+KALIGONDO!BB50+KEMBIRITAN!BQ50+SETAIL!BC50 -> 54660
B51: B. | C51: JUMLAH SUARA TIDAK SAH | E51: ='GENTENG KULON'!BK51+'GENTENG WETAN'!BL51+KALIGONDO!BB51+KEMBIRITAN!BQ51+SETAIL!BC51 -> 847
B52: C. | C52: JUMLAH SELURUH SUARA SAH DAN SUARA TIDAK SAH (V.A + V.B) | E52: =SUM(E50:E51) -> 55507

Sheet GENTENG KULON
C2: Kecamatan | D2: GENTENG
C3: Kabupaten | D3: BANYUWANGI
C4: Provinsi | D4: JAWA TIMUR
C9: Kelurahan | D9: GENTENG KULON
A12: I | B12: DATA PEMILIH DAN PENGGUNAAN HAK PILIH | BK12: JUMLAH AKHIR
A13: A | B13: DATA PEMILIH | E13: TPS 001 | F13: TPS 002 | G13: TPS 003 | H13: TPS 004 | I13: TPS 005 | J13: TPS 006 | K13: TPS 007 | L13: TPS 008 | M13: TPS 009 | N13: TPS 010 | O13: TPS 011 | P13: TPS 012 | Q13: TPS 013 | R13: TPS 014 | S13: TPS 015 | T13: TPS 016 | U13: TPS 017 | V13: TPS 018 | W13: TPS 019 | X13: TPS 020 | Y13: TPS 021 | Z13: TPS 022 | AA13: TPS 023 | AB13: TPS 024 | AC13: TPS 025 | AD13: TPS 026 | AE13: TPS 027 | AF13: TPS 028 | AG13: TPS 029 | AH13: TPS 030 | AI13: TPS 031 | AJ13: TPS 032 | AK13: TPS 033 | AL13: TPS 034 | AM13: TPS 035 | AN13: TPS 036 | AO13: TPS 037 | AP13: TPS 038 | AQ13: TPS 039 | AR13: TPS 040 | AS13: TPS 041 | AT13: TPS 042 | AU13: TPS 043 | AV13: TPS 044 | AW13: TPS 045 | AX13: TPS 046 | AY13: TPS 047 | AZ13: TPS 048 | BA13: TPS 049 | BB13: TPS 050 | BC13: TPS 051 | BD13: TPS 052 | BE13: TPS 053 | BF13: TPS 054 | BG13: TPS 055 | BH13: TPS 056 | BI13: TPS 057 | BJ13: TPS 058
B14: Jumlah Pemilih dalam Daftar Pemilih Tetap (DPT) | D14: LK | E14: 131 | F14: 130 | G14: 125 | H14: 107 | I14: 129 | J14: 136 | K14: 143 | L14: 137 | M14: 136 | N14: 124 | O14: 130 | P14: 128 | Q14: 134 | R14: 106 | S14: 122 | T14: 126 | U14: 133 | V14: 140 | W14: 137 | X14: 141 | Y14: 134 | Z14: 127 | AA14: 135 | AB14: 127 | AC14: 133 | AD14: 139 | AE14: 134 | AF14: 139 | AG14: 136 | AH14: 137 | AI14: 128 | AJ14: 148 | AK14: 131 | AL14: 142 | AM14: 115 | AN14: 136 | AO14: 105 | AP14: 103 | AQ14: 145 | AR14: 150 | AS14: 125 | AT14: 126 | AU14: 141 | AV14: 141 | AW14: 154 | AX14: 130 | AY14: 145 | AZ14: 138 | BA14: 150 | BB14: 148 | BC14: 132 | BD14: 129 | BE14: 136 | BF14: 127 | BG14: 137 | BH14: 143 | BI14: 124 | BJ14: 135 | BK14: =SUM(E14:BJ14) -> 7700
D15: PR | E15: 121 | F15: 134 | G15: 121 | H15: 141 | I15: 126 | J15: 147 | K15: 133 | L15: 145 | M15: 143 | N15: 139 | O15: 153 | P15: 148 | Q15: 149 | R15: 114 | S15: 159 | T15: 138 | U15: 145 | V15: 136 | W15: 138 | X15: 137 | Y15: 147 | Z15: 149 | AA15: 139 | AB15: 149 | AC15: 142 | AD15: 142 | AE15: 132 | AF15: 132 | AG15: 143 | AH15: 141 | AI15: 149 | AJ15: 137 | AK15: 156 | AL15: 147 | AM15: 137 | AN15: 140 | AO15: 118 | AP15: 116 | AQ15: 143 | AR15: 142 | AS15: 145 | AT15: 151 | AU15: 150 | AV15: 145 | AW15: 138 | AX15: 153 | AY15: 141 | AZ15: 144 | BA15: 137 | BB15: 141 | BC15: 149 | BD15: 135 | BE15: 142 | BF15: 121 | BG15: 130 | BH15: 128 | BI15: 133 | BJ15: 128 | BK15: =SUM(E15:BJ15) -> 8079
D16: JML | E16: =SUM(E14:E15) -> 252 | F16: =SUM(F14:F15) -> 264 | G16: =SUM(G14:G15) -> 246 | H16: =SUM(H14:H15) -> 248 | I16: =SUM(I14:I15) -> 255 | J16: =SUM(J14:J15) -> 283 | K16: =SUM(K14:K15) -> 276 | L16: =SUM(L14:L15) -> 282 | ... BJ16: =SUM(BJ14:BJ15) -> 263 | BK16: =SUM(E16:BJ16) -> 15779
A18: B | B18: PENGGUNA HAK PILIH
B19: 1. | C19: Jumlah pengguna hak pilih dalam Daftar Pemilih Tetap (DPT) | D19: LK | E19: 92 | F19: 92 | G19: 90 | H19: 70 | I19: 93 | J19: 91 | K19: 106 | L19: 94 | M19: 90 | N19: 78 | O19: 90 | P19: 95 | Q19: 103 | R19: 82 | S19: 84 | T19: 80 | U19: 93 | V19: 101 | W19: 98 | X19: 98 | Y19: 91 | Z19: 84 | AA19: 106 | AB19: 93 | AC19: 96 | AD19: 89 | AE19: 99 | AF19: 107 | AG19: 99 | AH19: 91 | AI19: 107 | AJ19: 104 | AK19: 97 | AL19: 101 | AM19: 78 | AN19: 95 | AO19: 77 | AP19: 85 | AQ19: 102 | AR19: 108 | AS19: 89 | AT19: 91 | AU19: 105 | AV19: 98 | AW19: 119 | AX19: 102 | AY19: 105 | AZ19: 105 | BA19: 118 | BB19: 119 | BC19: 94 | BD19: 96 | BE19: 105 | BF19: 93 | BG19: 105 | BH19: 104 | BI19: 101 | BJ19: 102 | BK19: =SUM(E19:BJ19) -> 5580
D20: PR | E20: 96 | F20: 101 | G20: 93 | H20: 102 | I20: 92 | J20: 108 | K20: 105 | L20: 106 | M20: 96 | N20: 97 | O20: 115 | P20: 99 | Q20: 107 | R20: 86 | S20: 125 | T20: 102 | U20: 99 | V20: 108 | W20: 95 | X20: 105 | Y20: 108 | Z20: 110 | AA20: 110 | AB20: 111 | AC20: 114 | AD20: 105 | AE20: 104 | AF20: 104 | AG20: 121 | AH20: 98 | AI20: 98 | AJ20: 100 | AK20: 117 | AL20: 112 | AM20: 96 | AN20: 106 | AO20: 93 | AP20: 94 | AQ20: 106 | AR20: 111 | AS20: 100 | AT20: 110 | AU20: 137 | AV20: 104 | AW20: 105 | AX20: 112 | AY20: 113 | AZ20: 116 | BA20: 115 | BB20: 119 | BC20: 114 | BD20: 106 | BE20: 124 | BF20: 95 | BG20: 107 | BH20: 104 | BI20: 111 | BJ20: 106 | BK20: =SUM(E20:BJ20) -> 6153
D21: JML | E21: =SUM(E19:E20) -> 188 | F21: =SUM(F19:F20) -> 193 | G21: =SUM(G19:G20) -> 183 | H21: =SUM(H19:H20) -> 172 | I21: =SUM(I19:I20) -> 185 | J21: =SUM(J19:J20) -> 199 | K21: =SUM(K19:K20) -> 211 | L21: =SUM(L19:L20) -> 200 | ... BJ21: =SUM(BJ19:BJ20) -> 208 | BK21: =SUM(E21:BJ21) -> 11733
B22: 2. | C22: Jumlah pengguna hak pilih dalam Daftar Pemilih Tambahan (DPTb) | D22: LK | E22: 1 | F22: 0 | G22: 0 | H22: 0 | I22: 1 | J22: 1 | K22: 0 | L22: 1 | M22: 0 | N22: 0 | O22: 0 | P22: 0 | Q22: 0 | R22: 0 | S22: 1 | T22: 2 | U22: 0 | V22: 1 | W22: 1 | X22: 1 | Y22: 0 | Z22: 0 | AA22: 0 | AB22: 0 | AC22: 1 | AD22: 0 | AE22: 0 | AF22: 1 | AG22: 0 | AH22: 0 | AJ22: 2 | AL22: 3 | AO22: 1 | AP22: 1 | AS22: 1 | BB22: 2 | BC22: 1 | BI22: 3 | BK22: =SUM(E22:BJ22) -> 26
D23: PR | E23: 0 | F23: 2 | G23: 0 | H23: 0 | I23: 3 | J23: 0 | K23: 0 | L23: 2 | M23: 0 | N23: 0 | O23: 0 | P23: 0 | Q23: 0 | R23: 1 | S23: 1 | T23: 2 | U23: 0 | V23: 1 | W23: 0 | X23: 0 | Y23: 0 | Z23: 0 | AB23: 1 | AF23: 1 | AJ23: 1 | AL23: 1 | AN23: 1 | AO23: 2 | AR23: 1 | AS23: 0 | BB23: 2 | BI23: 3 | BJ23: 1 | BK23: =SUM(E23:BJ23) -> 26
D24: JML | E24: =SUM(E22:E23) -> 1 | F24: =SUM(F22:F23) -> 2 | G24: =SUM(G22:G23) -> 0 | H24: =SUM(H22:H23) -> 0 | I24: =SUM(I22:I23) -> 4 | J24: =SUM(J22:J23) -> 1 | K24: =SUM(K22:K23) -> 0 | L24: =SUM(L22:L23) -> 3 | ... BJ24: =SUM(BJ22:BJ23) -> 1 | BK24: =SUM(E24:BJ24) -> 52
B25: 3. | C25: Jumlah pengguna hak pilih dalam Daftar Pemilih Khusus (DPK) | D25: LK | E25: 1 | F25: 3 | G25: 1 | H25: 1 | I25: 1 | J25: 3 | K25: 4 | L25: 0 | M25: 0 | N25: 1 | O25: 1 | P25: 2 | Q25: 0 | R25: 1 | S25: 0 | T25: 0 | U25: 1 | V25: 1 | X25: 1 | AA25: 1 | AD25: 1 | AE25: 2 | AF25: 4 | AI25: 0 | AJ25: 0 | AL25: 4 | AM25: 2 | AN25: 3 | AO25: 3 | AU25: 2 | AX25: 6 | AY25: 1 | BA25: 3 | BB25: 6 | BD25: 4 | BK25: =SUM(E25:BJ25) -> 64
D26: PR | E26: 0 | F26: 3 | G26: 1 | H26: 0 | I26: 4 | J26: 6 | K26: 2 | L26: 0 | M26: 0 | N26: 0 | O26: 1 | P26: 5 | Q26: 1 | R26: 0 | S26: 1 | T26: 2 | U26: 1 | V26: 0 | W26: 0 | X26: 2 | Y26: 1 | AA26: 3 | AC26: 2 | AD26: 1 | AF26: 1 | AI26: 0 | AJ26: 2 | AK26: 1 | AL26: 2 | AM26: 1 | AN26: 2 | AO26: 1 | AR26: 1 | AU26: 1 | AW26: 1 | AX26: 4 | AY26: 2 | BA26: 4 | BB26: 3 | BC26: 1 | BD26: 3 | BH26: 1 | BK26: =SUM(E26:BJ26) -> 67
D27: JML | E27: =SUM(E25:E26) -> 1 | F27: =SUM(F25:F26) -> 6 | G27: =SUM(G25:G26) -> 2 | H27: =SUM(H25:H26) -> 1 | I27: =SUM(I25:I26) -> 5 | J27: =SUM(J25:J26) -> 9 | K27: =SUM(K25:K26) -> 6 | L27: =SUM(L25:L26) -> 0 | ... BJ27: =SUM(BJ25:BJ26) -> 0 | BK27: =SUM(E27:BJ27) -> 131
B28: 4. | C28: Jumlah Pengguna Hak Pilih (B.1+B.2+B.3) | D28: LK | E28: =SUM(E19,E22,E25) -> 94 | F28: =SUM(F19,F22,F25) -> 95 | G28: =SUM(G19,G22,G25) -> 91 | H28: =SUM(H19,H22,H25) -> 71 | I28: =SUM(I19,I22,I25) -> 95 | J28: =SUM(J19,J22,J25) -> 95 | K28: =SUM(K19,K22,K25) -> 110 | L28: =SUM(L19,L22,L25) -> 95 | ... BJ28: =SUM(BJ19,BJ22,BJ25) -> 102 | BK28: =SUM(E28:BJ28) -> 5670
D29: PR | E29: =SUM(E20,E23,E26) -> 96 | F29: =SUM(F20,F23,F26) -> 106 | G29: =SUM(G20,G23,G26) -> 94 | H29: =SUM(H20,H23,H26) -> 102 | I29: =SUM(I20,I23,I26) -> 99 | J29: =SUM(J20,J23,J26) -> 114 | K29: =SUM(K20,K23,K26) -> 107 | L29: =SUM(L20,L23,L26) -> 108 | ... BJ29: =SUM(BJ20,BJ23,BJ26) -> 107 | BK29: =SUM(E29:BJ29) -> 6246
D30: JML | E30: =SUM(E28:E29) -> 190 | F30: =SUM(F28:F29) -> 201 | G30: =SUM(G28:G29) -> 185 | H30: =SUM(H28:H29) -> 173 | I30: =SUM(I28:I29) -> 194 | J30: =SUM(J28:J29) -> 209 | K30: =SUM(K28:K29) -> 217 | L30: =SUM(L28:L29) -> 203 | ... BJ30: =SUM(BJ28:BJ29) -> 209 | BK30: =SUM(E30:BJ30) -> 11916
A32: II | B32: DATA PENGGUNAAN SURAT SUARA
A33: 1 | B33: Jumlah surat suara yang diterima, termasuk surat suara cadangan 2,5% dari DPT | E33: 258 | F33: 271 | G33: 251 | H33: 253 | I33: 261 | J33: 286 | K33: 278 | L33: 288 | M33: 279 | N33: 269 | O33: 288 | P33: 283 | Q33: 290 | R33: 231 | S33: 287 | T33: 270 | U33: 289 | V33: 284 | W33: 281 | X33: 284 | Y33: 287 | Z33: 282 | AA33: 280 | AB33: 282 | AC33: 281 | AD33: 287 | AE33: 271 | AF33: 277 | AG33: 285 | AH33: 285 | AI33: 283 | AJ33: 291 | AK33: 293 | AL33: 297 | AM33: 238 | AN33: 282 | AO33: 228 | AP33: 230 | AQ33: 294 | AR33: 298 | AS33: 252 | AT33: 283 | AU33: 297 | AV33: 290 | AW33: 289 | AX33: 290 | AY33: 297 | AZ33: 288 | BA33: 295 | BB33: 290 | BC33: 288 | BD33: 270 | BE33: 284 | BF33: 253 | BG33: 273 | BH33: 277 | BI33: 273 | BJ33: 269 | BK33: =SUM(E33:BJ33) -> 16090
A34: 2 | B34: Jumlah surat suara yang digunakan | E34: 190 | F34: 201 | G34: 185 | H34: 173 | I34: 194 | J34: 209 | K34: 217 | L34: 203 | M34: 186 | N34: 176 | O34: 207 | P34: 201 | Q34: 211 | R34: 170 | S34: 212 | T34: 188 | U34: 194 | V34: 212 | W34: 194 | X34: 207 | Y34: 200 | Z34: 194 | AA34: 220 | AB34: 205 | AC34: 213 | AD34: 196 | AE34: 205 | AF34: 218 | AG34: 220 | AH34: 189 | AI34: 205 | AJ34: 209 | AK34: 215 | AL34: 223 | AM34: 177 | AN34: 207 | AO34: 177 | AP34: 180 | AQ34: 208 | AR34: 221 | AS34: 190 | AT34: 201 | AU34: 245 | AV34: 202 | AW34: 225 | AX34: 224 | AY34: 221 | AZ34: 221 | BA34: 240 | BB34: 251 | BC34: 210 | BD34: 209 | BE34: 229 | BF34: 188 | BG34: 212 | BH34: 209 | BI34: 218 | BJ34: 209 | BK34: =SUM(E34:BJ34) -> 11916
A35: 3 | B35: Jumlah surat suara dikembalikan oleh pemilih (karena rusak atau keliru coblos) | E35: 0 | F35: 0 | G35: 3 | H35: 0 | I35: 0 | J35: 1 | K35: 0 | L35: 0 | M35: 1 | N35: 0 | O35: 0 | P35: 0 | Q35: 4 | R35: 1 | S35: 0 | W35: 11 | AC35: 1 | AF35: 2 | AH35: 2 | AL35: 2 | AQ35: 1 | AR35: 1 | AX35: 1 | AY35: 1 | BK35: =SUM(E35:BJ35) -> 32
A36: 4 | B36: Jumlah surat suara yang tidak digunakan/tidak terpakai, termasuk sisa surat suara cadangan | E36: =E33-(E34+E35) -> 68 | F36: =F33-(F34+F35) -> 70 | G36: =G33-(G34+G35) -> 63 | H36: =H33-(H34+H35) -> 80 | I36: =I33-(I34+I35) -> 67 | J36: =J33-(J34+J35) -> 76 | K36: =K33-(K34+K35) -> 61 | L36: =L33-(L34+L35) -> 85 | ... BJ36: =BJ33-(BJ34+BJ35) -> 60 | BK36: =SUM(E36:BJ36) -> 4142
A38: III | B38: DATA PEMILIH DISABILITAS
B39: Jumlah seluruh Pemilih disabilitas yang menggunakan hak pilih | D39: LK | E39: 0 | F39: 0 | G39: 0 | H39: 0 | I39: 0 | J39: 0 | K39: 0 | L39: 0 | M39: 0 | N39: 0 | O39: 0 | P39: 0 | Q39: 2 | R39: 1 | S39: 0 | T39: 0 | U39: 0 | V39: 0 | W39: 0 | X39: 0 | Y39: 0 | Z39: 0 | AA39: 2 | AB39: 1 | AX39: 1 | BB39: 2 | BE39: 2 | BH39: 1 | BK39: =SUM(E39:BJ39) -> 12
D40: PR | E40: 0 | F40: 0 | G40: 0 | H40: 0 | I40: 0 | J40: 0 | K40: 0 | L40: 0 | M40: 0 | N40: 1 | AA40: 2 | AB40: 1 | AP40: 1 | AX40: 1 | BE40: 2 | BH40: 1 | BK40: =SUM(E40:BJ40) -> 9
D41: JML | E41: =SUM(E39:E40) -> 0 | F41: =SUM(F39:F40) -> 0 | G41: =SUM(G39:G40) -> 0 | H41: =SUM(H39:H40) -> 0 | I41: =SUM(I39:I40) -> 0 | J41: =SUM(J39:J40) -> 0 | K41: =SUM(K39:K40) -> 0 | L41: =SUM(L39:L40) -> 0 | ... BJ41: =SUM(BJ39:BJ40) -> 0 | BK41: =SUM(E41:BJ41) -> 21
A43: IV | B43: DATA RINCIAN PEROLEHAN SUARA PASANGAN CALON BUPATI DAN WAKIL BUPATI
A44: NOMOR DAN NAMA CALON
B45: 1 | C45: H. ANIES RASYID BASWEDAN, Ph.D. - Dr. (H.C.) H. A. MUHAIMIN ISKANDAR | E45: 44 | F45: 49 | G45: 38 | H45: 35 | I45: 32 | J45: 44 | K45: 47 | L45: 27 | M45: 14 | N45: 14 | O45: 10 | P45: 14 | Q45: 24 | R45: 44 | S45: 64 | T45: 44 | U45: 40 | V45: 28 | W45: 35 | X45: 30 | Y45: 20 | Z45: 24 | AA45: 55 | AB45: 11 | AC45: 28 | AD45: 14 | AE45: 18 | AF45: 27 | AG45: 28 | AH45: 37 | AI45: 15 | AJ45: 19 | AK45: 24 | AL45: 23 | AM45: 17 | AN45: 10 | AO45: 17 | AP45: 19 | AQ45: 36 | AR45: 31 | AS45: 13 | AT45: 24 | AU45: 55 | AV45: 33 | AW45: 35 | AX45: 10 | AY45: 49 | AZ45: 38 | BA45: 58 | BB45: 53 | BC45: 41 | BD45: 20 | BE45: 55 | BF45: 33 | BG45: 20 | BH45: 37 | BI45: 18 | BJ45: 60 | BK45: =SUM(E45:BJ45) -> 1802
B46: 2 | C46: H. PRABOWO SUBIANTO - GIBRAN RAKABUMING RAKA | E46: 96 | F46: 119 | G46: 107 | H46: 75 | I46: 115 | J46: 124 | K46: 131 | L46: 130 | M46: 115 | N46: 123 | O46: 142 | P46: 132 | Q46: 139 | R46: 86 | S46: 107 | T46: 103 | U46: 119 | V46: 138 | W46: 118 | X46: 130 | Y46: 133 | Z46: 129 | AA46: 129 | AB46: 136 | AC46: 133 | AD46: 129 | AE46: 135 | AF46: 130 | AG46: 124 | AH46: 113 | AI46: 122 | AJ46: 125 | AK46: 126 | AL46: 130 | AM46: 109 | AN46: 125 | AO46: 80 | AP46: 119 | AQ46: 131 | AR46: 130 | AS46: 133 | AT46: 115 | AU46: 148 | AV46: 130 | AW46: 149 | AX46: 166 | AY46: 114 | AZ46: 132 | BA46: 140 | BB46: 141 | BC46: 136 | BD46: 129 | BE46: 138 | BF46: 121 | BG46: 163 | BH46: 124 | BI46: 166 | BJ46: 117 | BK46: =SUM(E46:BJ46) -> 7299
B47: 3 | C47: H. GANJAR PRANOWO, S.H., M.I.P. - Prof. Dr. H. M. MAHFUD MD | E47: 49 | F47: 31 | G47: 38 | H47: 62 | I47: 47 | J47: 38 | K47: 35 | L47: 43 | M47: 51 | N47: 36 | O47: 52 | P47: 53 | Q47: 44 | R47: 36 | S47: 41 | T47: 38 | U47: 34 | V47: 39 | W47: 38 | X47: 44 | Y47: 42 | Z47: 41 | AA47: 36 | AB47: 54 | AC47: 49 | AD47: 52 | AE47: 45 | AF47: 58 | AG47: 67 | AH47: 39 | AI47: 67 | AJ47: 60 | AK47: 61 | AL47: 68 | AM47: 48 | AN47: 69 | AO47: 79 | AP47: 39 | AQ47: 37 | AR47: 60 | AS47: 44 | AT47: 57 | AU47: 42 | AV47: 37 | AW47: 39 | AX47: 47 | AY47: 57 | AZ47: 48 | BA47: 34 | BB47: 53 | BC47: 31 | BD47: 58 | BE47: 35 | BF47: 31 | BG47: 27 | BH47: 42 | BI47: 31 | BJ47: 26 | BK47: =SUM(E47:BJ47) -> 2659
A49: V | B49: DATA SUARA SAH DAN TIDAK SAH
B50: A. | C50: JUMLAH SELURUH SUARA SAH | E50: =SUM(E45:E47) -> 189 | F50: =SUM(F45:F47) -> 199 | G50: =SUM(G45:G47) -> 183 | H50: =SUM(H45:H47) -> 172 | I50: =SUM(I45:I47) -> 194 | J50: =SUM(J45:J47) -> 206 | K50: =SUM(K45:K47) -> 213 | L50: =SUM(L45:L47) -> 200 | ... BJ50: =SUM(BJ45:BJ47) -> 203 | BK50: =SUM(E50:BJ50) -> 11760
B51: B. | C51: JUMLAH SUARA TIDAK SAH | E51: 1 | F51: 2 | G51: 2 | H51: 1 | J51: 3 | K51: 4 | L51: 3 | M51: 6 | N51: 3 | O51: 3 | P51: 2 | Q51: 4 | R51: 4 | S51: 0 | T51: 3 | U51: 1 | V51: 7 | W51: 3 | X51: 3 | Y51: 5 | AB51: 4 | AC51: 3 | AD51: 1 | AE51: 7 | AF51: 3 | AG51: 1 | AH51: 0 | AI51: 1 | AJ51: 5 | AK51: 4 | AL51: 2 | AM51: 3 | AN51: 3 | AO51: 1 | AP51: 3 | AQ51: 4 | AR51: 0 | AS51: 0 | AT51: 5 | AU51: 0 | AV51: 2 | AW51: 2 | AX51: 1 | AY51: 1 | AZ51: 3 | BA51: 8 | BB51: 4 | BC51: 2 | BD51: 2 | BE51: 1 | BF51: 3 | BG51: 2 | BH51: 6 | BI51: 3 | BJ51: 6 | BK51: =SUM(E51:BJ51) -> 156
B52: C. | C52: JUMLAH SELURUH SUARA SAH DAN SUARA TIDAK SAH (V.A + V.B) | E52: =SUM(E50:E51) -> 190 | F52: =SUM(F50:F51) -> 201 | G52: =SUM(G50:G51) -> 185 | H52: =SUM(H50:H51) -> 173 | I52: =SUM(I50:I51) -> 194 | J52: =SUM(J50:J51) -> 209 | K52: =SUM(K50:K51) -> 217 | L52: =SUM(L50:L51) -> 203 | ... BJ52: =SUM(BJ50:BJ51) -> 209 | BK52: =SUM(E52:BJ52) -> 11916

Sheet GENTENG WETAN
C2: Kecamatan | D2: GENTENG
C3: Kabupaten | D3: BANYUWANGI
C4: Provinsi | D4: JAWA TIMUR
C9: Kelurahan | D9: GENTENG WETAN
A12: I | B12: DATA PEMILIH DAN PENGGUNAAN HAK PILIH | BL12: JUMLAH AKHIR
A13: A | B13: DATA PEMILIH | E13: TPS 001 | F13: TPS 002 | G13: TPS 003 | H13: TPS 004 | I13: TPS 005 | J13: TPS 006 | K13: TPS 007 | L13: TPS 008 | M13: TPS 009 | N13: TPS 010 | O13: TPS 011 | P13: TPS 012 | Q13: TPS 013 | R13: TPS 014 | S13: TPS 015 | T13: TPS 016 | U13: TPS 017 | V13: TPS 018 | W13: TPS 019 | X13: TPS 020 | Y13: TPS 021 | Z13: TPS 022 | AA13: TPS 023 | AB13: TPS 024 | AC13: TPS 025 | AD13: TPS 026 | AE13: TPS 027 | AF13: TPS 028 | AG13: TPS 029 | AH13: TPS 030 | AI13: TPS 031 | AJ13: TPS 032 | AK13: TPS 033 | AL13: TPS 034 | AM13: TPS 035 | AN13: TPS 036 | AO13: TPS 037 | AP13: TPS 038 | AQ13: TPS 039 | AR13: TPS 040 | AS13: TPS 041 | AT13: TPS 042 | AU13: TPS 043 | AV13: TPS 044 | AW13: TPS 045 | AX13: TPS 046 | AY13: TPS 047 | AZ13: TPS 048 | BA13: TPS 049 | BB13: TPS 050 | BC13: TPS 051 | BD13: TPS 052 | BE13: TPS 053 | BF13: TPS 054 | BG13: TPS 055 | BH13: TPS 056 | BI13: TPS 057 | BJ13: TPS 058 | BK13: TPS 059
B14: Jumlah Pemilih dalam Daftar Pemilih Tetap (DPT) | D14: LK | E14: 135 | F14: 138 | G14: 127 | H14: 144 | I14: 151 | J14: 137 | K14: 134 | L14: 144 | M14: 137 | N14: 140 | O14: 137 | P14: 141 | Q14: 142 | R14: 129 | S14: 138 | T14: 149 | U14: 151 | V14: 148 | W14: 151 | X14: 143 | Y14: 141 | Z14: 154 | AA14: 147 | AB14: 148 | AC14: 153 | AD14: 139 | AE14: 134 | AF14: 130 | AG14: 126 | AH14: 135 | AI14: 107 | AJ14: 120 | AK14: 109 | AL14: 145 | AM14: 117 | AN14: 116 | AO14: 121 | AP14: 118 | AQ14: 125 | AR14: 132 | AS14: 110 | AT14: 119 | AU14: 119 | AV14: 139 | AW14: 124 | AX14: 140 | AY14: 134 | AZ14: 141 | BA14: 148 | BB14: 138 | BC14: 140 | BD14: 131 | BE14: 143 | BF14: 135 | BG14: 121 | BH14: 152 | BI14: 141 | BJ14: 140 | BK14: 126 | BL14: =SUM(E14:BK14) -> 7974
D15: PR | E15: 137 | F15: 150 | G15: 144 | H15: 133 | I15: 142 | J15: 127 | K15: 141 | L15: 126 | M15: 150 | N15: 112 | O15: 145 | P15: 124 | Q15: 122 | R15: 114 | S15: 151 | T15: 145 | U15: 130 | V15: 139 | W15: 128 | X15: 151 | Y15: 132 | Z15: 134 | AA15: 140 | AB15: 146 | AC15: 141 | AD15: 139 | AE15: 129 | AF15: 123 | AG15: 148 | AH15: 138 | AI15: 101 | AJ15: 112 | AK15: 117 | AL15: 146 | AM15: 128 | AN15: 126 | AO15: 122 | AP15: 129 | AQ15: 152 | AR15: 133 | AS15: 114 | AT15: 98 | AU15: 115 | AV15: 147 | AW15: 126 | AX15: 139 | AY15: 138 | AZ15: 139 | BA15: 144 | BB15: 136 | BC15: 132 | BD15: 144 | BE15: 132 | BF15: 144 | BG15: 134 | BH15: 141 | BI15: 140 | BJ15: 143 | BK15: 156 | BL15: =SUM(E15:BK15) -> 7909
D16: JML | E16: =SUM(E14:E15) -> 272 | F16: =SUM(F14:F15) -> 288 | G16: =SUM(G14:G15) -> 271 | H16: =SUM(H14:H15) -> 277 | I16: =SUM(I14:I15) -> 293 | J16: =SUM(J14:J15) -> 264 | K16: =SUM(K14:K15) -> 275 | L16: =SUM(L14:L15) -> 270 | ... BK16: =SUM(BK14:BK15) -> 282 | BL16: =SUM(E16:BK16) -> 15883
A18: B | B18: PENGGUNA HAK PILIH
B19: 1. | C19: Jumlah pengguna hak pilih dalam Daftar Pemilih Tetap (DPT) | D19: LK | E19: 85 | F19: 99 | G19: 93 | H19: 108 | I19: 112 | J19: 104 | K19: 91 | L19: 115 | M19: 112 | N19: 98 | O19: 97 | P19: 96 | Q19: 118 | R19: 99 | S19: 93 | T19: 106 | U19: 107 | V19: 106 | W19: 116 | X19: 109 | Y19: 87 | Z19: 99 | AA19: 101 | AB19: 105 | AC19: 104 | AD19: 109 | AE19: 109 | AF19: 102 | AG19: 102 | AH19: 96 | AI19: 70 | AJ19: 92 | AK19: 78 | AL19: 105 | AM19: 86 | AN19: 86 | AO19: 90 | AP19: 79 | AQ19: 90 | AR19: 97 | AS19: 80 | AT19: 80 | AU19: 77 | AV19: 86 | AW19: 97 | AX19: 109 | AY19: 84 | AZ19: 101 | BA19: 106 | BB19: 91 | BC19: 92 | BD19: 91 | BE19: 81 | BF19: 81 | BG19: 83 | BH19: 123 | BI19: 101 | BJ19: 90 | BK19: 88 | BL19: =SUM(E19:BK19) -> 5692
D20: PR | E20: 93 | F20: 127 | G20: 117 | H20: 112 | I20: 113 | J20: 104 | K20: 107 | L20: 103 | M20: 108 | N20: 93 | O20: 119 | P20: 100 | Q20: 105 | R20: 92 | S20: 109 | T20: 111 | U20: 100 | V20: 118 | W20: 100 | X20: 122 | Y20: 101 | Z20: 112 | AA20: 108 | AB20: 109 | AC20: 110 | AD20: 103 | AE20: 102 | AF20: 102 | AG20: 115 | AH20: 105 | AI20: 76 | AJ20: 85 | AK20: 89 | AL20: 112 | AM20: 98 | AN20: 106 | AO20: 91 | AP20: 96 | AQ20: 120 | AR20: 101 | AS20: 82 | AT20: 70 | AU20: 91 | AV20: 102 | AW20: 95 | AX20: 115 | AY20: 103 | AZ20: 110 | BA20: 109 | BB20: 113 | BC20: 88 | BD20: 107 | BE20: 82 | BF20: 103 | BG20: 99 | BH20: 117 | BI20: 110 | BJ20: 103 | BK20: 112 | BL20: =SUM(E20:BK20) -> 6105
D21: JML | E21: =SUM(E19:E20) -> 178 | F21: =SUM(F19:F20) -> 226 | G21: =SUM(G19:G20) -> 210 | H21: =SUM(H19:H20) -> 220 | I21: =SUM(I19:I20) -> 225 | J21: =SUM(J19:J20) -> 208 | K21: =SUM(K19:K20) -> 198 | L21: =SUM(L19:L20) -> 218 | ... BK21: =SUM(BK19:BK20) -> 200 | BL21: =SUM(E21:BK21) -> 11797
B22: 2. | C22: Jumlah pengguna hak pilih dalam Daftar Pemilih Tambahan (DPTb) | D22: LK | F22: 1 | G22: 1 | I22: 1 | J22: 3 | M22: 1 | O22: 1 | T22: 2 | W22: 2 | AC22: 1 | AD22: 1 | AL22: 5 | AU22: 1 | BF22: 1 | BG22: 1 | BJ22: 1 | BL22: =SUM(E22:BK22) -> 23
D23: PR | J23: 1 | M23: 3 | T23: 6 | W23: 1 | AD23: 3 | AE23: 1 | AI23: 1 | AJ23: 1 | AL23: 3 | AM23: 1 | AN23: 1 | AO23: 1 | AT23: 1 | AV23: 2 | AY23: 1 | BB23: 1 | BL23: =SUM(E23:BK23) -> 28
D24: JML | E24: =SUM(E22:E23) -> 0 | F24: =SUM(F22:F23) -> 1 | G24: =SUM(G22:G23) -> 1 | H24: =SUM(H22:H23) -> 0 | I24: =SUM(I22:I23) -> 1 | J24: =SUM(J22:J23) -> 4 | K24: =SUM(K22:K23) -> 0 | L24: =SUM(L22:L23) -> 0 | ... BK24: =SUM(BK22:BK23) -> 0 | BL24: =SUM(E24:BK24) -> 51
B25: 3. | C25: Jumlah pengguna hak pilih dalam Daftar Pemilih Khusus (DPK) | D25: LK | E25: 2 | I25: 2 | K25: 1 | N25: 1 | O25: 1 | P25: 4 | Q25: 3 | R25: 1 | S25: 2 | T25: 2 | U25: 3 | V25: 2 | W25: 5 | Y25: 5 | AB25: 4 | AC25: 1 | AD25: 2 | AF25: 2 | AG25: 1 | AI25: 2 | AJ25: 0 | AK25: 1 | AO25: 1 | AR25: 3 | AS25: 1 | AT25: 4 | AU25: 1 | AV25: 4 | BC25: 2 | BD25: 3 | BE25: 1 | BF25: 4 | BG25: 1 | BJ25: 1 | BK25: 2 | BL25: =SUM(E25:BK25) -> 75
D26: PR | E26: 1 | H26: 1 | I26: 1 | J26: 1 | L26: 3 | N26: 2 | O26: 2 | P26: 3 | Q26: 4 | R26: 5 | S26: 5 | T26: 3 | U26: 4 | V26: 2 | W26: 4 | X26: 1 | Z26: 3 | AA26: 4 | AB26: 4 | AC26: 4 | AD26: 3 | AE26: 3 | AF26: 2 | AG26: 4 | AI26: 1 | AJ26: 1 | AK26: 3 | AL26: 2 | AM26: 2 | AO26: 5 | AQ26: 1 | AR26: 2 | AS26: 1 | AT26: 2 | AU26: 2 | AV26: 5 | AW26: 2 | BC26: 3 | BD26: 2 | BF26: 5 | BJ26: 1 | BK26: 6 | BL26: =SUM(E26:BK26) -> 115
D27: JML | E27: =SUM(E25:E26) -> 3 | F27: =SUM(F25:F26) -> 0 | G27: =SUM(G25:G26) -> 0 | H27: =SUM(H25:H26) -> 1 | I27: =SUM(I25:I26) -> 3 | J27: =SUM(J25:J26) -> 1 | K27: =SUM(K25:K26) -> 1 | L27: =SUM(L25:L26) -> 3 | ... BK27: =SUM(BK25:BK26) -> 8 | BL27: =SUM(E27:BK27) -> 190
B28: 4. | C28: Jumlah Pengguna Hak Pilih (B.1+B.2+B.3) | D28: LK | E28: =SUM(E19,E22,E25) -> 87 | F28: =SUM(F19,F22,F25) -> 100 | G28: =SUM(G19,G22,G25) -> 94 | H28: =SUM(H19,H22,H25) -> 108 | I28: =SUM(I19,I22,I25) -> 115 | J28: =SUM(J19,J22,J25) -> 107 | K28: =SUM(K19,K22,K25) -> 92 | L28: =SUM(L19,L22,L25) -> 115 | ... BK28: =SUM(BK19,BK22,BK25) -> 90 | BL28: =SUM(E28:BK28) -> 5790
D29: PR | E29: =SUM(E20,E23,E26) -> 94 | F29: =SUM(F20,F23,F26) -> 127 | G29: =SUM(G20,G23,G26) -> 117 | H29: =SUM(H20,H23,H26) -> 113 | I29: =SUM(I20,I23,I26) -> 114 | J29: =SUM(J20,J23,J26) -> 106 | K29: =SUM(K20,K23,K26) -> 107 | L29: =SUM(L20,L23,L26) -> 106 | ... BK29: =SUM(BK20,BK23,BK26) -> 118 | BL29: =SUM(E29:BK29) -> 6248
D30: JML | E30: =SUM(E28:E29) -> 181 | F30: =SUM(F28:F29) -> 227 | G30: =SUM(G28:G29) -> 211 | H30: =SUM(H28:H29) -> 221 | I30: =SUM(I28:I29) -> 229 | J30: =SUM(J28:J29) -> 213 | K30: =SUM(K28:K29) -> 199 | L30: =SUM(L28:L29) -> 221 | ... BK30: =SUM(BK28:BK29) -> 208 | BL30: =SUM(E30:BK30) -> 12038
A32: II | B32: DATA PENGGUNAAN SURAT SUARA
A33: 1 | B33: Jumlah surat suara yang diterima, termasuk surat suara cadangan 2,5% dari DPT | E33: 277 | F33: 294 | G33: 297 | H33: 284 | I33: 299 | J33: 271 | K33: 282 | L33: 277 | M33: 292 | N33: 257 | O33: 284 | P33: 269 | Q33: 269 | R33: 279 | S33: 296 | T33: 301 | U33: 295 | V33: 297 | W33: 290 | X33: 299 | Y33: 284 | Z33: 294 | AA33: 293 | AB33: 300 | AC33: 300 | AD33: 284 | AE33: 269 | AF33: 259 | AG33: 279 | AH33: 279 | AI33: 210 | AJ33: 238 | AK33: 231 | AL33: 297 | AM33: 250 | AN33: 246 | AO33: 247 | AP33: 254 | AQ33: 284 | AR33: 273 | AS33: 229 | AT33: 219 | AU33: 237 | AV33: 290 | AW33: 255 | AX33: 285 | AY33: 279 | AZ33: 286 | BA33: 298 | BB33: 280 | BC33: 278 | BD33: 281 | BE33: 284 | BF33: 287 | BG33: 263 | BH33: 295 | BI33: 287 | BJ33: 289 | BK33: 290 | BL33: =SUM(E33:BK33) -> 16292
A34: 2 | B34: Jumlah surat suara yang digunakan | E34: 181 | F34: 227 | G34: 211 | H34: 221 | I34: 229 | J34: 213 | K34: 199 | L34: 221 | M34: 224 | N34: 194 | O34: 220 | P34: 203 | Q34: 230 | R34: 197 | S34: 209 | T34: 230 | U34: 214 | V34: 228 | W34: 228 | X34: 232 | Y34: 193 | Z34: 214 | AA34: 213 | AB34: 222 | AC34: 220 | AD34: 221 | AE34: 215 | AF34: 208 | AG34: 222 | AH34: 201 | AI34: 150 | AJ34: 179 | AK34: 171 | AL34: 227 | AM34: 187 | AN34: 193 | AO34: 188 | AP34: 175 | AQ34: 211 | AR34: 203 | AS34: 164 | AT34: 157 | AU34: 172 | AV34: 199 | AW34: 194 | AX34: 224 | AY34: 188 | AZ34: 211 | BA34: 215 | BB34: 205 | BC34: 185 | BD34: 203 | BE34: 164 | BF34: 194 | BG34: 184 | BH34: 240 | BI34: 211 | BJ34: 196 | BK34: 208 | BL34: =SUM(E34:BK34) -> 12038
A35: 3 | B35: Jumlah surat suara dikembalikan oleh pemilih (karena rusak atau keliru coblos) | K35: 1 | N35: 3 | P35: 3 | T35: 1 | AA35: 2 | AF35: 1 | AN35: 1 | AR35: 3 | BB35: 1 | BD35: 1 | BG35: 1 | BK35: 1 | BL35: =SUM(E35:BK35) -> 19
A36: 4 | B36: Jumlah surat suara yang tidak digunakan/tidak terpakai, termasuk sisa surat suara cadangan | E36: =E33-(E34+E35) -> 96 | F36: =F33-(F34+F35) -> 67 | G36: =G33-(G34+G35) -> 86 | H36: =H33-(H34+H35) -> 63 | I36: =I33-(I34+I35) -> 70 | J36: =J33-(J34+J35) -> 58 | K36: =K33-(K34+K35) -> 82 | L36: =L33-(L34+L35) -> 56 | ... BK36: =BK33-(BK34+BK35) -> 81 | BL36: =SUM(E36:BK36) -> 4235
A38: III | B38: DATA PEMILIH DISABILITAS
B39: Jumlah seluruh Pemilih disabilitas yang menggunakan hak pilih | D39: LK | W39: 1 | AH39: 2 | AK39: 2 | AM39: 2 | AN39: 2 | AO39: 4 | AW39: 1 | BF39: 1 | BI39: 1 | BL39: =SUM(E39:BK39) -> 16
D40: PR | W40: 2 | X40: 1 | AH40: 3 | AK40: 4 | AN40: 1 | AQ40: 1 | AW40: 2 | AZ40: 1 | BF40: 1 | BG40: 1 | BH40: 1 | BL40: =SUM(E40:BK40) -> 18
D41: JML | E41: =SUM(E39:E40) -> 0 | F41: =SUM(F39:F40) -> 0 | G41: =SUM(G39:G40) -> 0 | H41: =SUM(H39:H40) -> 0 | I41: =SUM(I39:I40) -> 0 | J41: =SUM(J39:J40) -> 0 | K41: =SUM(K39:K40) -> 0 | L41: =SUM(L39:L40) -> 0 | ... BK41: =SUM(BK39:BK40) -> 0 | BL41: =SUM(E41:BK41) -> 34
A43: IV | B43: DATA RINCIAN PEROLEHAN SUARA PASANGAN CALON BUPATI DAN WAKIL BUPATI
A44: NOMOR DAN NAMA CALON
B45: 1 | C45: H. ANIES RASYID BASWEDAN, Ph.D. - Dr. (H.C.) H. A. MUHAIMIN ISKANDAR | E45: 17 | F45: 40 | G45: 44 | H45: 20 | I45: 48 | J45: 37 | K45: 33 | L45: 43 | M45: 47 | N45: 43 | O45: 55 | P45: 60 | Q45: 43 | R45: 41 | S45: 30 | T45: 48 | U45: 54 | V45: 73 | W45: 46 | X45: 78 | Y45: 70 | Z45: 56 | AA45: 72 | AB45: 76 | AC45: 57 | AD45: 51 | AE45: 27 | AF45: 26 | AG45: 30 | AH45: 13 | AI45: 25 | AJ45: 23 | AK45: 21 | AL45: 32 | AM45: 34 | AN45: 34 | AO45: 41 | AP45: 27 | AQ45: 46 | AR45: 22 | AS45: 23 | AT45: 15 | AU45: 43 | AV45: 51 | AW45: 30 | AX45: 40 | AY45: 24 | AZ45: 19 | BA45: 11 | BB45: 6 | BC45: 17 | BD45: 30 | BE45: 13 | BF45: 11 | BG45: 16 | BH45: 52 | BI45: 17 | BJ45: 19 | BK45: 46 | BL45: =SUM(E45:BK45) -> 2166
B46: 2 | C46: H. PRABOWO SUBIANTO - GIBRAN RAKABUMING RAKA | E46: 133 | F46: 152 | G46: 135 | H46: 181 | I46: 150 | J46: 147 | K46: 147 | L46: 150 | M46: 139 | N46: 115 | O46: 127 | P46: 114 | Q46: 155 | R46: 129 | S46: 147 | T46: 141 | U46: 123 | V46: 125 | W46: 139 | X46: 121 | Y46: 106 | Z46: 133 | AA46: 106 | AB46: 109 | AC46: 130 | AD46: 125 | AE46: 135 | AF46: 135 | AG46: 146 | AH46: 127 | AI46: 78 | AJ46: 111 | AK46: 102 | AL46: 157 | AM46: 108 | AN46: 112 | AO46: 112 | AP46: 120 | AQ46: 135 | AR46: 139 | AS46: 118 | AT46: 110 | AU46: 100 | AV46: 113 | AW46: 108 | AX46: 145 | AY46: 126 | AZ46: 158 | BA46: 171 | BB46: 143 | BC46: 119 | BD46: 147 | BE46: 119 | BF46: 156 | BG46: 126 | BH46: 152 | BI46: 140 | BJ46: 128 | BK46: 123 | BL46: =SUM(E46:BK46) -> 7698
B47: 3 | C47: H. GANJAR PRANOWO, S.H., M.I.P. - Prof. Dr. H. M. MAHFUD MD | E47: 29 | F47: 30 | G47: 29 | H47: 19 | I47: 29 | J47: 21 | K47: 18 | L47: 24 | M47: 30 | N47: 35 | O47: 37 | P47: 25 | Q47: 30 | R47: 23 | S47: 30 | T47: 40 | U47: 37 | V47: 29 | W47: 41 | X47: 31 | Y47: 15 | Z47: 23 | AA47: 34 | AB47: 34 | AC47: 28 | AD47: 44 | AE47: 49 | AF47: 46 | AG47: 44 | AH47: 55 | AI47: 45 | AJ47: 41 | AK47: 47 | AL47: 37 | AM47: 40 | AN47: 44 | AO47: 34 | AP47: 26 | AQ47: 28 | AR47: 38 | AS47: 22 | AT47: 30 | AU47: 28 | AV47: 33 | AW47: 52 | AX47: 38 | AY47: 38 | AZ47: 28 | BA47: 30 | BB47: 50 | BC47: 43 | BD47: 25 | BE47: 27 | BF47: 27 | BG47: 38 | BH47: 31 | BI47: 53 | BJ47: 42 | BK47: 36 | BL47: =SUM(E47:BK47) -> 2010
A49: V | B49: DATA SUARA SAH DAN TIDAK SAH
B50: A. | C50: JUMLAH SELURUH SUARA SAH | E50: =SUM(E45:E47) -> 179 | F50: =SUM(F45:F47) -> 222 | G50: =SUM(G45:G47) -> 208 | H50: =SUM(H45:H47) -> 220 | I50: =SUM(I45:I47) -> 227 | J50: =SUM(J45:J47) -> 205 | K50: =SUM(K45:K47) -> 198 | L50: =SUM(L45:L47) -> 217 | ... BK50: =SUM(BK45:BK47) -> 205 | BL50: =SUM(E50:BK50) -> 11874
B51: B. | C51: JUMLAH SUARA TIDAK SAH | E51: 2 | F51: 5 | G51: 3 | H51: 1 | I51: 2 | J51: 8 | K51: 1 | L51: 4 | M51: 8 | N51: 1 | O51: 1 | P51: 4 | Q51: 2 | R51: 4 | S51: 2 | T51: 1 | V51: 1 | W51: 2 | X51: 2 | Y51: 2 | Z51: 2 | AA51: 1 | AB51: 3 | AC51: 5 | AD51: 1 | AE51: 4 | AF51: 1 | AG51: 2 | AH51: 6 | AI51: 2 | AJ51: 4 | AK51: 1 | AL51: 1 | AM51: 5 | AN51: 3 | AO51: 1 | AP51: 2 | AQ51: 2 | AR51: 4 | AS51: 1 | AT51: 2 | AU51: 1 | AV51: 2 | AW51: 4 | AX51: 1 | AZ51: 6 | BA51: 3 | BB51: 6 | BC51: 6 | BD51: 1 | BE51: 5 | BG51: 4 | BH51: 5 | BI51: 1 | BJ51: 7 | BK51: 3 | BL51: =SUM(E51:BK51) -> 164
B52: C. | C52: JUMLAH SELURUH SUARA SAH DAN SUARA TIDAK SAH (V.A + V.B) | E52: =SUM(E50:E51) -> 181 | F52: =SUM(F50:F51) -> 227 | G52: =SUM(G50:G51) -> 211 | H52: =SUM(H50:H51) -> 221 | I52: =SUM(I50:I51) -> 229 | J52: =SUM(J50:J51) -> 213 | K52: =SUM(K50:K51) -> 199 | L52: =SUM(L50:L51) -> 221 | ... BK52: =SUM(BK50:BK51) -> 208 | BL52: =SUM(E52:BK52) -> 12038

Sheet KALIGONDO
C2: Kecamatan | D2: GENTENG
C3: Kabupaten | D3: BANYUWANGI
C4: Provinsi | D4: JAWA TIMUR
C9: Kelurahan | D9: KALIGONDO
A12: I | B12: DATA PEMILIH DAN PENGGUNAAN HAK PILIH | BB12: JUMLAH AKHIR
A13: A | B13: DATA PEMILIH | E13: TPS 001 | F13: TPS 002 | G13: TPS 003 | H13: TPS 004 | I13: TPS 005 | J13: TPS 006 | K13: TPS 007 | L13: TPS 008 | M13: TPS 009 | N13: TPS 010 | O13: TPS 011 | P13: TPS 012 | Q13: TPS 013 | R13: TPS 014 | S13: TPS 015 | T13: TPS 016 | U13: TPS 017 | V13: TPS 018 | W13: TPS 019 | X13: TPS 020 | Y13: TPS 021 | Z13: TPS 022 | AA13: TPS 023 | AB13: TPS 024 | AC13: TPS 025 | AD13: TPS 026 | AE13: TPS 027 | AF13: TPS 028 | AG13: TPS 029 | AH13: TPS 030 | AI13: TPS 031 | AJ13: TPS 032 | AK13: TPS 033 | AL13: TPS 034 | AM13: TPS 035 | AN13: TPS 036 | AO13: TPS 037 | AP13: TPS 038 | AQ13: TPS 039 | AR13: TPS 040 | AS13: TPS 041 | AT13: TPS 042 | AU13: TPS 043 | AV13: TPS 044 | AW13: TPS 045 | AX13: TPS 046 | AY13: TPS 047 | AZ13: TPS 048 | BA13: TPS 049
B14: Jumlah Pemilih dalam Daftar Pemilih Tetap (DPT) | D14: LK | E14: 96 | F14: 109 | G14: 105 | H14: 130 | I14: 123 | J14: 96 | K14: 115 | L14: 95 | M14: 114 | N14: 104 | O14: 110 | P14: 113 | Q14: 120 | R14: 86 | S14: 114 | T14: 114 | U14: 102 | V14: 125 | W14: 117 | X14: 90 | Y14: 112 | Z14: 88 | AA14: 87 | AB14: 130 | AC14: 106 | AD14: 116 | AE14: 119 | AF14: 120 | AG14: 105 | AH14: 102 | AI14: 101 | AJ14: 96 | AK14: 110 | AL14: 111 | AM14: 113 | AN14: 122 | AO14: 102 | AP14: 114 | AQ14: 105 | AR14: 94 | AS14: 109 | AT14: 109 | AU14: 107 | AV14: 121 | AW14: 132 | AX14: 119 | AY14: 132 | AZ14: 133 | BA14: 118 | BB14: =SUM(E14:BA14) -> 5411
D15: PR | E15: 117 | F15: 107 | G15: 98 | H15: 124 | I15: 124 | J15: 117 | K15: 108 | L15: 96 | M15: 121 | N15: 115 | O15: 105 | P15: 107 | Q15: 123 | R15: 79 | S15: 106 | T15: 114 | U15: 105 | V15: 114 | W15: 125 | X15: 108 | Y15: 120 | Z15: 90 | AA15: 87 | AB15: 107 | AC15: 117 | AD15: 111 | AE15: 120 | AF15: 120 | AG15: 98 | AH15: 101 | AI15: 101 | AJ15: 110 | AK15: 111 | AL15: 110 | AM15: 92 | AN15: 110 | AO15: 109 | AP15: 120 | AQ15: 97 | AR15: 103 | AS15: 101 | AT15: 143 | AU15: 106 | AV15: 124 | AW15: 133 | AX15: 118 | AY15: 139 | AZ15: 135 | BA15: 126 | BB15: =SUM(E15:BA15) -> 5472
D16: JML | E16: =SUM(E14:E15) -> 213 | F16: =SUM(F14:F15) -> 216 | G16: =SUM(G14:G15) -> 203 | H16: =SUM(H14:H15) -> 254 | I16: =SUM(I14:I15) -> 247 | J16: =SUM(J14:J15) -> 213 | K16: =SUM(K14:K15) -> 223 | L16: =SUM(L14:L15) -> 191 | ... BA16: =SUM(BA14:BA15) -> 244 | BB16: =SUM(E16:BA16) -> 10883
A18: B | B18: PENGGUNA HAK PILIH
B19: 1. | C19: Jumlah pengguna hak pilih dalam Daftar Pemilih Tetap (DPT) | D19: LK | E19: 64 | F19: 70 | G19: 64 | H19: 93 | I19: 94 | J19: 53 | K19: 76 | L19: 64 | M19: 87 | N19: 73 | O19: 70 | P19: 79 | Q19: 91 | R19: 60 | S19: 88 | T19: 87 | U19: 72 | V19: 81 | W19: 79 | X19: 70 | Y19: 92 | Z19: 60 | AA19: 52 | AB19: 100 | AC19: 86 | AD19: 88 | AE19: 92 | AF19: 87 | AG19: 76 | AH19: 76 | AI19: 77 | AJ19: 74 | AK19: 83 | AL19: 63 | AM19: 72 | AN19: 92 | AO19: 65 | AP19: 90 | AQ19: 76 | AR19: 65 | AS19: 81 | AT19: 79 | AU19: 78 | AV19: 93 | AW19: 97 | AX19: 87 | AY19: 102 | AZ19: 97 | BA19: 81 | BB19: =SUM(E19:BA19) -> 3876
D20: PR | E20: 96 | F20: 74 | G20: 72 | H20: 103 | I20: 93 | J20: 74 | K20: 79 | L20: 65 | M20: 89 | N20: 88 | O20: 78 | P20: 83 | Q20: 94 | R20: 62 | S20: 89 | T20: 94 | U20: 76 | V20: 86 | W20: 94 | X20: 76 | Y20: 91 | Z20: 72 | AA20: 68 | AB20: 89 | AC20: 89 | AD20: 85 | AE20: 103 | AF20: 92 | AG20: 76 | AH20: 76 | AI20: 78 | AJ20: 94 | AK20: 74 | AL20: 70 | AM20: 70 | AN20: 90 | AO20: 75 | AP20: 94 | AQ20: 76 | AR20: 84 | AS20: 81 | AT20: 105 | AU20: 84 | AV20: 103 | AW20: 96 | AX20: 90 | AY20: 109 | AZ20: 105 | BA20: 93 | BB20: =SUM(E20:BA20) -> 4177
D21: JML | E21: =SUM(E19:E20) -> 160 | F21: =SUM(F19:F20) -> 144 | G21: =SUM(G19:G20) -> 136 | H21: =SUM(H19:H20) -> 196 | I21: =SUM(I19:I20) -> 187 | J21: =SUM(J19:J20) -> 127 | K21: =SUM(K19:K20) -> 155 | L21: =SUM(L19:L20) -> 129 | ... BA21: =SUM(BA19:BA20) -> 174 | BB21: =SUM(E21:BA21) -> 8053
B22: 2. | C22: Jumlah pengguna hak pilih dalam Daftar Pemilih Tambahan (DPTb) | D22: LK | G22: 1 | AG22: 1 | AI22: 7 | AU22: 1 | BB22: =SUM(E22:BA22) -> 10
D23: PR | N23: 1 | P23: 1 | W23: 1 | X23: 1 | Z23: 1 | AG23: 1 | AH23: 2 | AI23: 3 | AM23: 1 | AN23: 1 | AR23: 1 | AU23: 1 | BB23: =SUM(E23:BA23) -> 15
D24: JML | E24: =SUM(E22:E23) -> 0 | F24: =SUM(F22:F23) -> 0 | G24: =SUM(G22:G23) -> 1 | H24: =SUM(H22:H23) -> 0 | I24: =SUM(I22:I23) -> 0 | J24: =SUM(J22:J23) -> 0 | K24: =SUM(K22:K23) -> 0 | L24: =SUM(L22:L23) -> 0 | ... BA24: =SUM(BA22:BA23) -> 0 | BB24: =SUM(E24:BA24) -> 25
B25: 3. | C25: Jumlah pengguna hak pilih dalam Daftar Pemilih Khusus (DPK) | D25: LK | E25: 0 | F25: 0 | G25: 0 | H25: 0 | I25: 0 | J25: 1 | K25: 1 | L25: 7 | M25: 1 | N25: 0 | O25: 0 | P25: 0 | Q25: 0 | R25: 1 | S25: 3 | T25: 0 | U25: 1 | V25: 2 | W25: 0 | X25: 0 | Y25: 0 | Z25: 3 | AA25: 0 | AB25: 1 | AC25: 0 | AD25: 0 | AE25: 1 | AF25: 0 | AG25: 2 | AH25: 3 | AI25: 1 | AJ25: 2 | AK25: 1 | AN25: 1 | AQ25: 1 | AR25: 2 | AS25: 2 | AT25: 1 | BA25: 1 | BB25: =SUM(E25:BA25) -> 39
D26: PR | E26: 0 | F26: 0 | G26: 0 | H26: 0 | I26: 0 | J26: 1 | K26: 1 | L26: 5 | M26: 1 | N26: 0 | O26: 1 | P26: 0 | Q26: 0 | R26: 3 | S26: 2 | T26: 2 | U26: 0 | V26: 2 | W26: 1 | X26: 0 | Y26: 0 | Z26: 5 | AA26: 1 | AB26: 1 | AC26: 0 | AD26: 0 | AE26: 2 | AF26: 0 | AG26: 2 | AH26: 1 | AI26: 2 | AJ26: 2 | AK26: 2 | AM26: 5 | AN26: 1 | AQ26: 4 | AR26: 1 | AS26: 2 | AT26: 4 | AU26: 1 | BA26: 2 | BB26: =SUM(E26:BA26) -> 57
D27: JML | E27: =SUM(E25:E26) -> 0 | F27: =SUM(F25:F26) -> 0 | G27: =SUM(G25:G26) -> 0 | H27: =SUM(H25:H26) -> 0 | I27: =SUM(I25:I26) -> 0 | J27: =SUM(J25:J26) -> 2 | K27: =SUM(K25:K26) -> 2 | L27: =SUM(L25:L26) -> 12 | ... BA27: =SUM(BA25:BA26) -> 3 | BB27: =SUM(E27:BA27) -> 96
B28: 4. | C28: Jumlah Pengguna Hak Pilih (B.1+B.2+B.3) | D28: LK | E28: =SUM(E19,E22,E25) -> 64 | F28: =SUM(F19,F22,F25) -> 70 | G28: =SUM(G19,G22,G25) -> 65 | H28: =SUM(H19,H22,H25) -> 93 | I28: =SUM(I19,I22,I25) -> 94 | J28: =SUM(J19,J22,J25) -> 54 | K28: =SUM(K19,K22,K25) -> 77 | L28: =SUM(L19,L22,L25) -> 71 | ... BA28: =SUM(BA19,BA22,BA25) -> 82 | BB28: =SUM(E28:BA28) -> 3925
D29: PR | E29: =SUM(E20,E23,E26) -> 96 | F29: =SUM(F20,F23,F26) -> 74 | G29: =SUM(G20,G23,G26) -> 72 | H29: =SUM(H20,H23,H26) -> 103 | I29: =SUM(I20,I23,I26) -> 93 | J29: =SUM(J20,J23,J26) -> 75 | K29: =SUM(K20,K23,K26) -> 80 | L29: =SUM(L20,L23,L26) -> 70 | ... BA29: =SUM(BA20,BA23,BA26) -> 95 | BB29: =SUM(E29:BA29) -> 4249
D30: JML | E30: =SUM(E28:E29) -> 160 | F30: =SUM(F28:F29) -> 144 | G30: =SUM(G28:G29) -> 137 | H30: =SUM(H28:H29) -> 196 | I30: =SUM(I28:I29) -> 187 | J30: =SUM(J28:J29) -> 129 | K30: =SUM(K28:K29) -> 157 | L30: =SUM(L28:L29) -> 141 | ... BA30: =SUM(BA28:BA29) -> 177 | BB30: =SUM(E30:BA30) -> 8174
A32: II | B32: DATA PENGGUNAAN SURAT SUARA
A33: 1 | B33: Jumlah surat suara yang diterima, termasuk surat suara cadangan 2,5% dari DPT | E33: 220 | F33: 222 | G33: 208 | H33: 261 | I33: 252 | J33: 219 | K33: 228 | L33: 195 | M33: 241 | N33: 221 | O33: 220 | P33: 225 | Q33: 246 | R33: 169 | S33: 225 | T33: 234 | U33: 212 | V33: 244 | W33: 246 | X33: 201 | Y33: 238 | Z33: 182 | AA33: 178 | AB33: 241 | AC33: 227 | AD33: 232 | AE33: 243 | AF33: 246 | AG33: 209 | AH33: 208 | AI33: 209 | AJ33: 211 | AK33: 225 | AL33: 222 | AM33: 211 | AN33: 212 | AO33: 216 | AP33: 240 | AQ33: 207 | AR33: 201 | AS33: 216 | AT33: 257 | AU33: 218 | AV33: 252 | AW33: 271 | AX33: 242 | AY33: 277 | AZ33: 275 | BA33: 251 | BB33: =SUM(E33:BA33) -> 11106
A34: 2 | B34: Jumlah surat suara yang digunakan | E34: 160 | F34: 144 | G34: 137 | H34: 196 | I34: 187 | J34: 129 | K34: 157 | L34: 141 | M34: 178 | N34: 162 | O34: 149 | P34: 163 | Q34: 185 | R34: 126 | S34: 182 | T34: 183 | U34: 149 | V34: 171 | W34: 175 | X34: 147 | Y34: 183 | Z34: 141 | AA34: 121 | AB34: 191 | AC34: 175 | AD34: 173 | AE34: 198 | AF34: 179 | AG34: 158 | AH34: 158 | AI34: 168 | AJ34: 172 | AK34: 160 | AL34: 133 | AM34: 148 | AN34: 185 | AO34: 140 | AP34: 184 | AQ34: 157 | AR34: 153 | AS34: 166 | AT34: 189 | AU34: 165 | AV34: 196 | AW34: 193 | AX34: 177 | AY34: 211 | AZ34: 202 | BA34: 177 | BB34: =SUM(E34:BA34) -> 8174
A35: 3 | B35: Jumlah surat suara dikembalikan oleh pemilih (karena rusak atau keliru coblos) | L35: 1 | M35: 1 | Z35: 1 | AM35: 1 | AO35: 2 | AS35: 1 | BB35: =SUM(E35:BA35) -> 7
A36: 4 | B36: Jumlah surat suara yang tidak digunakan/tidak terpakai, termasuk sisa surat suara cadangan | E36: =E33-(E34+E35) -> 60 | F36: =F33-(F34+F35) -> 78 | G36: =G33-(G34+G35) -> 71 | H36: =H33-(H34+H35) -> 65 | I36: =I33-(I34+I35) -> 65 | J36: =J33-(J34+J35) -> 90 | K36: =K33-(K34+K35) -> 71 | L36: =L33-(L34+L35) -> 53 | ... BA36: =BA33-(BA34+BA35) -> 74 | BB36: =SUM(E36:BA36) -> 2925
A38: III | B38: DATA PEMILIH DISABILITAS
B39: Jumlah seluruh Pemilih disabilitas yang menggunakan hak pilih | D39: LK | AN39: 1 | BB39: =SUM(E39:BA39) -> 1
D40: PR | L40: 1 | P40: 1 | BB40: =SUM(E40:BA40) -> 2
D41: JML | E41: =SUM(E39:E40) -> 0 | F41: =SUM(F39:F40) -> 0 | G41: =SUM(G39:G40) -> 0 | H41: =SUM(H39:H40) -> 0 | I41: =SUM(I39:I40) -> 0 | J41: =SUM(J39:J40) -> 0 | K41: =SUM(K39:K40) -> 0 | L41: =SUM(L39:L40) -> 1 | ... BA41: =SUM(BA39:BA40) -> 0 | BB41: =SUM(E41:BA41) -> 3
A43: IV | B43: DATA RINCIAN PEROLEHAN SUARA PASANGAN CALON BUPATI DAN WAKIL BUPATI
A44: NOMOR DAN NAMA CALON
B45: 1 | C45: H. ANIES RASYID BASWEDAN, Ph.D. - Dr. (H.C.) H. A. MUHAIMIN ISKANDAR | E45: 9 | F45: 16 | G45: 10 | H45: 11 | I45: 11 | J45: 19 | K45: 27 | L45: 14 | M45: 22 | N45: 23 | O45: 19 | P45: 7 | Q45: 23 | R45: 11 | S45: 26 | T45: 8 | U45: 16 | V45: 11 | W45: 10 | X45: 11 | Y45: 30 | Z45: 11 | AA45: 10 | AB45: 13 | AC45: 18 | AD45: 21 | AE45: 18 | AF45: 23 | AG45: 8 | AH45: 21 | AI45: 31 | AJ45: 6 | AK45: 14 | AL45: 8 | AM45: 17 | AN45: 19 | AO45: 12 | AP45: 19 | AQ45: 8 | AR45: 18 | AS45: 23 | AT45: 14 | AU45: 18 | AV45: 13 | AW45: 9 | AX45: 9 | AY45: 12 | AZ45: 13 | BA45: 11 | BB45: =SUM(E45:BA45) -> 751
B46: 2 | C46: H. PRABOWO SUBIANTO - GIBRAN RAKABUMING RAKA | E46: 122 | F46: 95 | G46: 100 | H46: 147 | I46: 136 | J46: 79 | K46: 109 | L46: 95 | M46: 112 | N46: 96 | O46: 89 | P46: 116 | Q46: 116 | R46: 90 | S46: 122 | T46: 130 | U46: 96 | V46: 125 | W46: 125 | X46: 108 | Y46: 111 | Z46: 105 | AA46: 87 | AB46: 123 | AC46: 113 | AD46: 102 | AE46: 135 | AF46: 123 | AG46: 110 | AH46: 98 | AI46: 106 | AJ46: 130 | AK46: 96 | AL46: 99 | AM46: 99 | AN46: 139 | AO46: 84 | AP46: 128 | AQ46: 110 | AR46: 92 | AS46: 96 | AT46: 130 | AU46: 98 | AV46: 113 | AW46: 113 | AX46: 120 | AY46: 137 | AZ46: 127 | BA46: 119 | BB46: =SUM(E46:BA46) -> 5451
B47: 3 | C47: H. GANJAR PRANOWO, S.H., M.I.P. - Prof. Dr. H. M. MAHFUD MD | E47: 14 | F47: 29 | G47: 22 | H47: 34 | I47: 35 | J47: 29 | K47: 20 | L47: 30 | M47: 42 | N47: 34 | O47: 40 | P47: 33 | Q47: 42 | R47: 16 | S47: 33 | T47: 36 | U47: 36 | V47: 34 | W47: 37 | X47: 27 | Y47: 33 | Z47: 23 | AA47: 20 | AB47: 49 | AC47: 41 | AD47: 45 | AE47: 44 | AF47: 31 | AG47: 40 | AH47: 37 | AI47: 28 | AJ47: 33 | AK47: 43 | AL47: 24 | AM47: 31 | AN47: 22 | AO47: 41 | AP47: 31 | AQ47: 37 | AR47: 42 | AS47: 43 | AT47: 42 | AU47: 48 | AV47: 69 | AW47: 65 | AX47: 42 | AY47: 58 | AZ47: 54 | BA47: 44 | BB47: =SUM(E47:BA47) -> 1783
A49: V | B49: DATA SUARA SAH DAN TIDAK SAH
B50: A. | C50: JUMLAH SELURUH SUARA SAH | E50: =SUM(E45:E47) -> 145 | F50: =SUM(F45:F47) -> 140 | G50: =SUM(G45:G47) -> 132 | H50: =SUM(H45:H47) -> 192 | I50: =SUM(I45:I47) -> 182 | J50: =SUM(J45:J47) -> 127 | K50: =SUM(K45:K47) -> 156 | L50: =SUM(L45:L47) -> 139 | ... BA50: =SUM(BA45:BA47) -> 174 | BB50: =SUM(E50:BA50) -> 7985
B51: B. | C51: JUMLAH SUARA TIDAK SAH | E51: 15 | F51: 4 | G51: 5 | H51: 4 | I51: 5 | J51: 2 | K51: 1 | L51: 2 | M51: 2 | N51: 9 | O51: 1 | P51: 7 | Q51: 4 | R51: 9 | S51: 1 | T51: 9 | U51: 1 | V51: 1 | W51: 3 | X51: 1 | Y51: 9 | Z51: 2 | AA51: 4 | AB51: 6 | AC51: 3 | AD51: 5 | AE51: 1 | AF51: 2 | AH51: 2 | AI51: 3 | AJ51: 3 | AK51: 7 | AL51: 2 | AM51: 1 | AN51: 5 | AO51: 3 | AP51: 6 | AQ51: 2 | AR51: 1 | AS51: 4 | AT51: 3 | AV51: 1 | AW51: 6 | AX51: 7 | AY51: 4 | AZ51: 8 | BA51: 3 | BB51: =SUM(E51:BA51) -> 189
B52: C. | C52: JUMLAH SELURUH SUARA SAH DAN SUARA TIDAK SAH (V.A + V.B) | E52: =SUM(E50:E51) -> 160 | F52: =SUM(F50:F51) -> 144 | G52: =SUM(G50:G51) -> 137 | H52: =SUM(H50:H51) -> 196 | I52: =SUM(I50:I51) -> 187 | J52: =SUM(J50:J51) -> 129 | K52: =SUM(K50:K51) -> 157 | L52: =SUM(L50:L51) -> 141 | ... BA52: =SUM(BA50:BA51) -> 177 | BB52: =SUM(E52:BA52) -> 8174

Sheet KEMBIRITAN
C2: Kecamatan | D2: GENTENG
C3: Kabupaten | D3: BANYUWANGI
C4: Provinsi | D4: JAWA TIMUR
C9: Kelurahan | D9: KEMBIRITAN
A12: I | B12: DATA PEMILIH DAN PENGGUNAAN HAK PILIH | BQ12: JUMLAH AKHIR
A13: A | B13: DATA PEMILIH | E13: TPS 001 | F13: TPS 002 | G13: TPS 003 | H13: TPS 004 | I13: TPS 005 | J13: TPS 006 | K13: TPS 007 | L13: TPS 008 | M13: TPS 009 | N13: TPS 010 | O13: TPS 011 | P13: TPS 012 | Q13: TPS 013 | R13: TPS 014 | S13: TPS 015 | T13: TPS 016 | U13: TPS 017 | V13: TPS 018 | W13: TPS 019 | X13: TPS 020 | Y13: TPS 021 | Z13: TPS 022 | AA13: TPS 023 | AB13: TPS 024 | AC13: TPS 025 | AD13: TPS 026 | AE13: TPS 027 | AF13: TPS 028 | AG13: TPS 029 | AH13: TPS 030 | AI13: TPS 031 | AJ13: TPS 032 | AK13: TPS 033 | AL13: TPS 034 | AM13: TPS 035 | AN13: TPS 036 | AO13: TPS 037 | AP13: TPS 038 | AQ13: TPS 039 | AR13: TPS 040 | AS13: TPS 041 | AT13: TPS 042 | AU13: TPS 043 | AV13: TPS 044 | AW13: TPS 045 | AX13: TPS 046 | AY13: TPS 047 | AZ13: TPS 048 | BA13: TPS 049 | BB13: TPS 050 | BC13: TPS 051 | BD13: TPS 052 | BE13: TPS 053 | BF13: TPS 054 | BG13: TPS 055 | BH13: TPS 056 | BI13: TPS 057 | BJ13: TPS 058 | BK13: TPS 059 | BL13: TPS 060 | BM13: TPS 061 | BN13: TPS 062 | BO13: TPS 063 | BP13: TPS 064
B14: Jumlah Pemilih dalam Daftar Pemilih Tetap (DPT) | D14: LK | E14: 129 | F14: 130 | G14: 147 | H14: 138 | I14: 120 | J14: 116 | K14: 110 | L14: 116 | M14: 115 | N14: 118 | O14: 135 | P14: 139 | Q14: 147 | R14: 119 | S14: 151 | T14: 127 | U14: 128 | V14: 135 | W14: 132 | X14: 126 | Y14: 137 | Z14: 123 | AA14: 137 | AB14: 115 | AC14: 125 | AD14: 116 | AE14: 130 | AF14: 135 | AG14: 141 | AH14: 141 | AI14: 141 | AJ14: 143 | AK14: 136 | AL14: 132 | AM14: 139 | AN14: 135 | AO14: 141 | AP14: 131 | AQ14: 136 | AR14: 138 | AS14: 154 | AT14: 138 | AU14: 114 | AV14: 148 | AW14: 147 | AX14: 151 | AY14: 147 | AZ14: 134 | BA14: 146 | BB14: 139 | BC14: 141 | BD14: 133 | BE14: 129 | BF14: 145 | BG14: 143 | BH14: 157 | BI14: 126 | BJ14: 138 | BK14: 118 | BL14: 139 | BM14: 126 | BN14: 123 | BO14: 122 | BP14: 126 | BQ14: =SUM(E14:BP14) -> 8534
D15: PR | E15: 137 | F15: 134 | G15: 134 | H15: 117 | I15: 115 | J15: 119 | K15: 115 | L15: 117 | M15: 108 | N15: 119 | O15: 125 | P15: 132 | Q15: 124 | R15: 123 | S15: 138 | T15: 136 | U15: 133 | V15: 132 | W15: 138 | X15: 129 | Y15: 118 | Z15: 135 | AA15: 122 | AB15: 113 | AC15: 117 | AD15: 122 | AE15: 131 | AF15: 127 | AG15: 135 | AH15: 133 | AI15: 134 | AJ15: 133 | AK15: 133 | AL15: 137 | AM15: 142 | AN15: 127 | AO15: 128 | AP15: 142 | AQ15: 127 | AR15: 120 | AS15: 124 | AT15: 121 | AU15: 116 | AV15: 149 | AW15: 144 | AX15: 142 | AY15: 144 | AZ15: 147 | BA15: 140 | BB15: 151 | BC15: 146 | BD15: 155 | BE15: 145 | BF15: 151 | BG15: 152 | BH15: 137 | BI15: 129 | BJ15: 126 | BK15: 127 | BL15: 136 | BM15: 137 | BN15: 125 | BO15: 122 | BP15: 119 | BQ15: =SUM(E15:BP15) -> 8386
D16: JML | E16: =SUM(E14:E15) -> 266 | F16: =SUM(F14:F15) -> 264 | G16: =SUM(G14:G15) -> 281 | H16: =SUM(H14:H15) -> 255 | I16: =SUM(I14:I15) -> 235 | J16: =SUM(J14:J15) -> 235 | K16: =SUM(K14:K15) -> 225 | L16: =SUM(L14:L15) -> 233 | ... BP16: =SUM(BP14:BP15) -> 245 | BQ16: =SUM(E16:BP16) -> 16920
A18: B | B18: PENGGUNA HAK PILIH
B19: 1. | C19: Jumlah pengguna hak pilih dalam Daftar Pemilih Tetap (DPT) | D19: LK | E19: 92 | F19: 90 | G19: 93 | H19: 94 | I19: 78 | J19: 91 | K19: 74 | L19: 99 | M19: 98 | N19: 92 | O19: 108 | P19: 105 | Q19: 101 | R19: 88 | S19: 115 | T19: 90 | U19: 83 | V19: 91 | W19: 94 | X19: 80 | Y19: 95 | Z19: 98 | AA19: 99 | AB19: 90 | AC19: 96 | AD19: 90 | AE19: 94 | AF19: 110 | AG19: 104 | AH19: 93 | AI19: 89 | AJ19: 97 | AK19: 91 | AL19: 96 | AM19: 95 | AN19: 89 | AO19: 93 | AP19: 90 | AQ19: 89 | AR19: 95 | AS19: 107 | AT19: 91 | AU19: 73 | AV19: 103 | AW19: 98 | AX19: 114 | AY19: 111 | AZ19: 99 | BA19: 114 | BB19: 106 | BC19: 111 | BD19: 104 | BE19: 98 | BF19: 98 | BG19: 92 | BH19: 108 | BI19: 75 | BJ19: 99 | BK19: 89 | BL19: 108 | BM19: 86 | BN19: 95 | BO19: 103 | BP19: 100 | BQ19: =SUM(E19:BP19) -> 6131
D20: PR | E20: 105 | F20: 99 | G20: 109 | H20: 94 | I20: 82 | J20: 93 | K20: 93 | L20: 92 | M20: 84 | N20: 104 | O20: 97 | P20: 118 | Q20: 95 | R20: 103 | S20: 113 | T20: 109 | U20: 99 | V20: 104 | W20: 109 | X20: 105 | Y20: 88 | Z20: 116 | AA20: 104 | AB20: 96 | AC20: 83 | AD20: 87 | AE20: 99 | AF20: 100 | AG20: 114 | AH20: 108 | AI20: 120 | AJ20: 104 | AK20: 106 | AL20: 99 | AM20: 106 | AN20: 94 | AO20: 104 | AP20: 114 | AQ20: 94 | AR20: 95 | AS20: 99 | AT20: 92 | AU20: 78 | AV20: 110 | AW20: 103 | AX20: 98 | AY20: 117 | AZ20: 102 | BA20: 119 | BB20: 117 | BC20: 121 | BD20: 123 | BE20: 122 | BF20: 110 | BG20: 108 | BH20: 117 | BI20: 102 | BJ20: 99 | BK20: 110 | BL20: 108 | BM20: 109 | BN20: 102 | BO20: 103 | BP20: 102 | BQ20: =SUM(E20:BP20) -> 6609
D21: JML | E21: =SUM(E19:E20) -> 197 | F21: =SUM(F19:F20) -> 189 | G21: =SUM(G19:G20) -> 202 | H21: =SUM(H19:H20) -> 188 | I21: =SUM(I19:I20) -> 160 | J21: =SUM(J19:J20) -> 184 | K21: =SUM(K19:K20) -> 167 | L21: =SUM(L19:L20) -> 191 | ... BP21: =SUM(BP19:BP20) -> 202 | BQ21: =SUM(E21:BP21) -> 12740
B22: 2. | C22: Jumlah pengguna hak pilih dalam Daftar Pemilih Tambahan (DPTb) | D22: LK | I22: 4 | S22: 1 | T22: 2 | V22: 1 | Z22: 1 | AF22: 2 | AK22: 1 | AQ22: 2 | AS22: 1 | AV22: 12 | AX22: 12 | AY22: 12 | AZ22: 0 | BA22: 9 | BB22: 10 | BC22: 4 | BD22: 1 | BE22: 2 | BF22: 15 | BG22: 7 | BJ22: 1 | BK22: 10 | BL22: 6 | BM22: 6 | BN22: 1 | BO22: 2 | BP22: 10 | BQ22: =SUM(E22:BP22) -> 135
D23: PR | I23: 1 | N23: 1 | S23: 1 | T23: 7 | V23: 1 | Z23: 1 | AK23: 1 | AM23: 1 | AR23: 1 | AV23: 1 | AX23: 1 | AY23: 2 | BA23: 3 | BC23: 4 | BD23: 1 | BE23: 1 | BG23: 3 | BH23: 1 | BI23: 14 | BJ23: 11 | BK23: 5 | BL23: 1 | BM23: 12 | BN23: 11 | BO23: 12 | BP23: 1 | BQ23: =SUM(E23:BP23) -> 99
D24: JML | E24: =SUM(E22:E23) -> 0 | F24: =SUM(F22:F23) -> 0 | G24: =SUM(G22:G23) -> 0 | H24: =SUM(H22:H23) -> 0 | I24: =SUM(I22:I23) -> 5 | J24: =SUM(J22:J23) -> 0 | K24: =SUM(K22:K23) -> 0 | L24: =SUM(L22:L23) -> 0 | ... BP24: =SUM(BP22:BP23) -> 11 | BQ24: =SUM(E24:BP24) -> 234
B25: 3. | C25: Jumlah pengguna hak pilih dalam Daftar Pemilih Khusus (DPK) | D25: LK | H25: 1 | M25: 1 | R25: 2 | U25: 1 | W25: 2 | AA25: 4 | AC25: 2 | AE25: 1 | AF25: 1 | AH25: 1 | AI25: 2 | AJ25: 2 | AK25: 7 | AL25: 1 | AO25: 2 | AU25: 2 | AW25: 1 | AY25: 1 | AZ25: 2 | BA25: 4 | BB25: 2 | BE25: 2 | BF25: 3 | BH25: 1 | BJ25: 3 | BL25: 2 | BQ25: =SUM(E25:BP25) -> 53
D26: PR | H26: 2 | I26: 2 | L26: 1 | M26: 2 | N26: 5 | O26: 1 | R26: 4 | W26: 2 | AA26: 3 | AC26: 3 | AD26: 1 | AE26: 3 | AF26: 3 | AH26: 2 | AI26: 1 | AJ26: 7 | AK26: 6 | AL26: 6 | AO26: 3 | AR26: 1 | AS26: 2 | AU26: 4 | AV26: 2 | AW26: 5 | AY26: 1 | AZ26: 1 | BA26: 3 | BB26: 1 | BF26: 3 | BH26: 3 | BJ26: 3 | BL26: 2 | BM26: 1 | BO26: 1 | BQ26: =SUM(E26:BP26) -> 90
D27: JML | E27: =SUM(E25:E26) -> 0 | F27: =SUM(F25:F26) -> 0 | G27: =SUM(G25:G26) -> 0 | H27: =SUM(H25:H26) -> 3 | I27: =SUM(I25:I26) -> 2 | J27: =SUM(J25:J26) -> 0 | K27: =SUM(K25:K26) -> 0 | L27: =SUM(L25:L26) -> 1 | ... BP27: =SUM(BP25:BP26) -> 0 | BQ27: =SUM(E27:BP27) -> 143
B28: 4. | C28: Jumlah Pengguna Hak Pilih (B.1+B.2+B.3) | D28: LK | E28: =SUM(E19,E22,E25) -> 92 | F28: =SUM(F19,F22,F25) -> 90 | G28: =SUM(G19,G22,G25) -> 93 | H28: =SUM(H19,H22,H25) -> 95 | I28: =SUM(I19,I22,I25) -> 82 | J28: =SUM(J19,J22,J25) -> 91 | K28: =SUM(K19,K22,K25) -> 74 | L28: =SUM(L19,L22,L25) -> 99 | ... AT28: =SUM(AT19,AT22,AT25) -> 91 | AU28: 75 | AV28: =SUM(AV19,AV22,AV25) -> 115 | AW28: 99 | AX28: =SUM(AX19,AX22,AX25) -> 126 | AY28: =SUM(AY19,AY22,AY25) -> 124 | AZ28: =SUM(AZ19,AZ22,AZ25) -> 101 | BA28: =SUM(BA19,BA22,BA25) -> 127 | BB28: =SUM(BB19,BB22,BB25) -> 118 | BC28: =SUM(BC19,BC22,BC25) -> 115 | BD28: =SUM(BD19,BD22,BD25) -> 105 | BE28: =SUM(BE19,BE22,BE25) -> 102 | ... BP28: =SUM(BP19,BP22,BP25) -> 110 | BQ28: =SUM(E28:BP28) -> 6319
D29: PR | E29: =SUM(E20,E23,E26) -> 105 | F29: =SUM(F20,F23,F26) -> 99 | G29: =SUM(G20,G23,G26) -> 109 | H29: =SUM(H20,H23,H26) -> 96 | I29: =SUM(I20,I23,I26) -> 85 | J29: =SUM(J20,J23,J26) -> 93 | K29: =SUM(K20,K23,K26) -> 93 | L29: =SUM(L20,L23,L26) -> 93 | ... BP29: =SUM(BP20,BP23,BP26) -> 103 | BQ29: =SUM(E29:BP29) -> 6798
D30: JML | E30: =SUM(E28:E29) -> 197 | F30: =SUM(F28:F29) -> 189 | G30: =SUM(G28:G29) -> 202 | H30: =SUM(H28:H29) -> 191 | I30: =SUM(I28:I29) -> 167 | J30: =SUM(J28:J29) -> 184 | K30: =SUM(K28:K29) -> 167 | L30: =SUM(L28:L29) -> 192 | ... BP30: =SUM(BP28:BP29) -> 213 | BQ30: =SUM(E30:BP30) -> 13117
A32: II | B32: DATA PENGGUNAAN SURAT SUARA
A33: 1 | B33: Jumlah surat suara yang diterima, termasuk surat suara cadangan 2,5% dari DPT | E33: 272 | F33: 271 | G33: 287 | H33: 281 | I33: 240 | J33: 240 | K33: 230 | L33: 238 | M33: 227 | N33: 243 | O33: 266 | P33: 277 | Q33: 277 | R33: 246 | S33: 295 | T33: 269 | U33: 268 | V33: 273 | W33: 277 | X33: 261 | Y33: 261 | Z33: 264 | AA33: 265 | AB33: 235 | AC33: 247 | AD33: 245 | AE33: 267 | AF33: 268 | AG33: 262 | AH33: 275 | AI33: 285 | AJ33: 278 | AK33: 275 | AL33: 275 | AM33: 289 | AN33: 268 | AO33: 275 | AP33: 279 | AQ33: 258 | AR33: 264 | AS33: 284 | AT33: 264 | AU33: 235 | AV33: 303 | AW33: 297 | AX33: 300 | AY33: 293 | AZ33: 289 | BA33: 294 | BB33: 296 | BC33: 293 | BD33: 294 | BE33: 280 | BF33: 304 | BG33: 301 | BH33: 300 | BI33: 261 | BJ33: 269 | BK33: 250 | BL33: 281 | BM33: 269 | BN33: 253 | BO33: 249 | BP33: 250 | BQ33: =SUM(E33:BP33) -> 17282
A34: 2 | B34: Jumlah surat suara yang digunakan | E34: 197 | F34: 189 | G34: 202 | H34: 191 | I34: 167 | J34: 184 | K34: 167 | L34: 192 | M34: 185 | N34: 202 | O34: 206 | P34: 223 | Q34: 196 | R34: 197 | S34: 230 | T34: 208 | U34: 183 | V34: 197 | W34: 207 | X34: 185 | Y34: 183 | Z34: 216 | AA34: 210 | AB34: 186 | AC34: 184 | AD34: 178 | AE34: 197 | AF34: 216 | AG34: 218 | AH34: 204 | AI34: 212 | AJ34: 210 | AK34: 212 | AL34: 202 | AM34: 202 | AN34: 183 | AO34: 202 | AP34: 204 | AQ34: 185 | AR34: 192 | AS34: 209 | AT34: 183 | AU34: 157 | AV34: 228 | AW34: 207 | AX34: 225 | AY34: 244 | AZ34: 204 | BA34: 252 | BB34: 236 | BC34: 240 | BD34: 229 | BE34: 225 | BF34: 229 | BG34: 210 | BH34: 230 | BI34: 191 | BJ34: 216 | BK34: 214 | BL34: 227 | BM34: 214 | BN34: 209 | BO34: 221 | BP34: 213 | BQ34: =SUM(E34:BP34) -> 13117
A35: 3 | B35: Jumlah surat suara dikembalikan oleh pemilih (karena rusak atau keliru coblos) | L35: 2 | M35: 1 | AM35: 1 | AT35: 4 | BF35: 1 | BM35: 1 | BQ35: =SUM(E35:BP35) -> 10
A36: 4 | B36: Jumlah surat suara yang tidak digunakan/tidak terpakai, termasuk sisa surat suara cadangan | E36: =E33-(E34+E35) -> 75 | F36: =F33-(F34+F35) -> 82 | G36: =G33-(G34+G35) -> 85 | H36: =H33-(H34+H35) -> 90 | I36: =I33-(I34+I35) -> 73 | J36: =J33-(J34+J35) -> 56 | K36: =K33-(K34+K35) -> 63 | L36: =L33-(L34+L35) -> 44 | ... BP36: =BP33-(BP34+BP35) -> 37 | BQ36: =SUM(E36:BP36) -> 4155
A38: III | B38: DATA PEMILIH DISABILITAS
B39: Jumlah seluruh Pemilih disabilitas yang menggunakan hak pilih | D39: LK | M39: 1 | U39: 1 | X39: 1 | AJ39: 1 | BE39: 2 | BQ39: =SUM(E39:BP39) -> 6
D40: PR | U40: 1 | W40: 1 | X40: 2 | AJ40: 2 | AW40: 1 | BE40: 1 | BJ40: 2 | BP40: 1 | BQ40: =SUM(E40:BP40) -> 11
D41: JML | E41: =SUM(E39:E40) -> 0 | F41: =SUM(F39:F40) -> 0 | G41: =SUM(G39:G40) -> 0 | H41: =SUM(H39:H40) -> 0 | I41: =SUM(I39:I40) -> 0 | J41: =SUM(J39:J40) -> 0 | K41: =SUM(K39:K40) -> 0 | L41: =SUM(L39:L40) -> 0 | ... BP41: =SUM(BP39:BP40) -> 1 | BQ41: =SUM(E41:BP41) -> 17
A43: IV | B43: DATA RINCIAN PEROLEHAN SUARA PASANGAN CALON BUPATI DAN WAKIL BUPATI
A44: NOMOR DAN NAMA CALON
B45: 1 | C45: H. ANIES RASYID BASWEDAN, Ph.D. - Dr. (H.C.) H. A. MUHAIMIN ISKANDAR | E45: 11 | F45: 12 | G45: 7 | H45: 10 | I45: 11 | J45: 21 | K45: 23 | L45: 16 | M45: 19 | N45: 20 | O45: 23 | P45: 30 | Q45: 48 | R45: 43 | S45: 53 | T45: 31 | U45: 13 | V45: 52 | W45: 19 | X45: 18 | Y45: 17 | Z45: 22 | AA45: 25 | AB45: 18 | AC45: 22 | AD45: 18 | AE45: 19 | AF45: 16 | AG45: 16 | AH45: 28 | AI45: 37 | AJ45: 54 | AK45: 7 | AL45: 14 | AM45: 19 | AN45: 6 | AO45: 15 | AP45: 17 | AQ45: 8 | AR45: 18 | AS45: 15 | AT45: 20 | AU45: 31 | AV45: 19 | AW45: 15 | AX45: 7 | AY45: 48 | AZ45: 22 | BA45: 15 | BB45: 11 | BC45: 19 | BD45: 36 | BE45: 24 | BF45: 52 | BG45: 24 | BH45: 68 | BI45: 27 | BJ45: 36 | BK45: 27 | BL45: 24 | BM45: 37 | BN45: 19 | BO45: 36 | BP45: 31 | BQ45: =SUM(E45:BP45) -> 1539
B46: 2 | C46: H. PRABOWO SUBIANTO - GIBRAN RAKABUMING RAKA | E46: 150 | F46: 152 | G46: 162 | H46: 148 | I46: 123 | J46: 130 | K46: 111 | L46: 142 | M46: 146 | N46: 157 | O46: 153 | P46: 154 | Q46: 116 | R46: 115 | S46: 141 | T46: 126 | U46: 131 | V46: 125 | W46: 159 | X46: 142 | Y46: 140 | Z46: 168 | AA46: 156 | AB46: 134 | AC46: 148 | AD46: 135 | AE46: 153 | AF46: 173 | AG46: 182 | AH46: 134 | AI46: 146 | AJ46: 122 | AK46: 145 | AL46: 142 | AM46: 135 | AN46: 127 | AO46: 153 | AP46: 130 | AQ46: 113 | AR46: 98 | AS46: 134 | AT46: 119 | AU46: 92 | AV46: 146 | AW46: 137 | AX46: 155 | AY46: 164 | AZ46: 156 | BA46: 184 | BB46: 157 | BC46: 153 | BD46: 151 | BE46: 157 | BF46: 158 | BG46: 159 | BH46: 130 | BI46: 148 | BJ46: 143 | BK46: 142 | BL46: 160 | BM46: 140 | BN46: 166 | BO46: 159 | BP46: 162 | BQ46: =SUM(E46:BP46) -> 9189
B47: 3 | C47: H. GANJAR PRANOWO, S.H., M.I.P. - Prof. Dr. H. M. MAHFUD MD | E47: 35 | F47: 22 | G47: 32 | H47: 32 | I47: 32 | J47: 30 | K47: 32 | L47: 29 | M47: 20 | N47: 21 | O47: 27 | P47: 35 | Q47: 27 | R47: 32 | S47: 31 | T47: 47 | U47: 39 | V47: 20 | W47: 27 | X47: 21 | Y47: 24 | Z47: 21 | AA47: 27 | AB47: 33 | AC47: 14 | AD47: 21 | AE47: 23 | AF47: 23 | AG47: 13 | AH47: 29 | AI47: 25 | AJ47: 33 | AK47: 56 | AL47: 45 | AM47: 45 | AN47: 47 | AO47: 31 | AP47: 50 | AQ47: 62 | AR47: 76 | AS47: 57 | AT47: 40 | AU47: 30 | AV47: 60 | AW47: 53 | AX47: 62 | AY47: 30 | AZ47: 23 | BA47: 50 | BB47: 61 | BC47: 66 | BD47: 41 | BE47: 42 | BF47: 16 | BG47: 20 | BH47: 28 | BI47: 16 | BJ47: 31 | BK47: 39 | BL47: 36 | BM47: 36 | BN47: 22 | BO47: 25 | BP47: 16 | BQ47: =SUM(E47:BP47) -> 2189
A49: V | B49: DATA SUARA SAH DAN TIDAK SAH
B50: A. | C50: JUMLAH SELURUH SUARA SAH | E50: =SUM(E45:E47) -> 196 | F50: =SUM(F45:F47) -> 186 | G50: =SUM(G45:G47) -> 201 | H50: =SUM(H45:H47) -> 190 | I50: =SUM(I45:I47) -> 166 | J50: =SUM(J45:J47) -> 181 | K50: =SUM(K45:K47) -> 166 | L50: =SUM(L45:L47) -> 187 | ... BP50: =SUM(BP45:BP47) -> 209 | BQ50: =SUM(E50:BP50) -> 12917
