Workbook

Sheet PPWP
C8: Kecamatan | D8: CLURING
C9: Kabupaten | D9: BANYUWANGI
C10: Provinsi | D10: JAWA TIMUR
A12: I | B12: DATA PEMILIH DAN PENGGUNAAN HAK PILIH | E12: JUMLAH AKHIR
A13: A | B13: DATA PEMILIH
B14: Jumlah Pemilih dalam Daftar Pemilih Tetap (DPT) | D14: LK | E14: =BENCULUK!AS14+CLURING!AL14+KALIPLOSO!Q14+PLAMPANGREJO!AE14+SARIMULYO!AA14+SEMBULUNG!AC14+SRATEN!AB14+TAMANAGUNG!AH14+TAMPO!AB14 -> 30610
D15: PR | E15: =BENCULUK!AS15+CLURING!AL15+KALIPLOSO!Q15+PLAMPANGREJO!AE15+SARIMULYO!AA15+SEMBULUNG!AC15+SRATEN!AB15+TAMANAGUNG!AH15+TAMPO!AB15 -> 30796
D16: JML | E16: =SUM(E14:E15) -> 61406
A18: B | B18: PENGGUNA HAK PILIH
B19: 1. | C19: Jumlah pengguna hak pilih dalam Daftar Pemilih Tetap (DPT) | D19: LK | E19: =BENCULUK!AS19+CLURING!AL19+KALIPLOSO!Q19+PLAMPANGREJO!AE19+SARIMULYO!AA19+SEMBULUNG!AC19+SRATEN!AB19+TAMANAGUNG!AH19+TAMPO!AB19 -> 22875
D20: PR | E20: =BENCULUK!AS20+CLURING!AL20+KALIPLOSO!Q20+PLAMPANGREJO!AE20+SARIMULYO!AA20+SEMBULUNG!AC20+SRATEN!AB20+TAMANAGUNG!AH20+TAMPO!AB20 -> 24376
D21: JML | E21: =SUM(E19:E20) -> 47251
B22: 2. | C22: Jumlah pengguna hak pilih dalam Daftar Pemilih Tambahan (DPTb) | D22: LK | E22: =BENCULUK!AS22+CLURING!AL22+KALIPLOSO!Q22+PLAMPANGREJO!AE22+SARIMULYO!AA22+SEMBULUNG!AC22+SRATEN!AB22+TAMANAGUNG!AH22+TAMPO!AB22 -> 43
D23: PR | E23: =BENCULUK!AS23+CLURING!AL23+KALIPLOSO!Q23+PLAMPANGREJO!AE23+SARIMULYO!AA23+SEMBULUNG!AC23+SRATEN!AB23+TAMANAGUNG!AH23+TAMPO!AB23 -> 45
D24: JML | E24: =SUM(E22:E23) -> 88
B25: 3. | C25: Jumlah pengguna hak pilih dalam Daftar Pemilih Khusus (DPK) | D25: LK | E25: =BENCULUK!AS25+CLURING!AL25+KALIPLOSO!Q25+PLAMPANGREJO!AE25+SARIMULYO!AA25+SEMBULUNG!AC25+SRATEN!AB25+TAMANAGUNG!AH25+TAMPO!AB25 -> 230
D26: PR | E26: =BENCULUK!AS26+CLURING!AL26+KALIPLOSO!Q26+PLAMPANGREJO!AE26+SARIMULYO!AA26+SEMBULUNG!AC26+SRATEN!AB26+TAMANAGUNG!AH26+TAMPO!AB26 -> 295
D27: JML | E27: =SUM(E25:E26) -> 525
B28: 4. | C28: Jumlah Pengguna Hak Pilih (B.1+B.2+B.3) | D28: LK | E28: =E19+E22+E25 -> 23148
D29: PR | E29: =E20+E23+E26 -> 24716
D30: JML | E30: =SUM(E28:E29) -> 47864
A32: II | B32: DATA PENGGUNAAN SURAT SUARA
A33: 1 | B33: Jumlah surat suara yang diterima, termasuk surat suara cadangan 2,5% dari DPT | E33: =BENCULUK!AS33+CLURING!AL33+KALIPLOSO!Q33+PLAMPANGREJO!AE33+SARIMULYO!AA33+SEMBULUNG!AC33+SRATEN!AB33+TAMANAGUNG!AH33+TAMPO!AB33 -> 62836
A34: 2 | B34: Jumlah surat suara yang digunakan | E34: =BENCULUK!AS34+CLURING!AL34+KALIPLOSO!Q34+PLAMPANGREJO!AE34+SARIMULYO!AA34+SEMBULUNG!AC34+SRATEN!AB34+TAMANAGUNG!AH34+TAMPO!AB34 -> 47864
A35: 3 | B35: Jumlah surat suara dikembalikan oleh pemilih (karena rusak atau keliru coblos) | E35: =BENCULUK!AS35+CLURING!AL35+KALIPLOSO!Q35+PLAMPANGREJO!AE35+SARIMULYO!AA35+SEMBULUNG!AC35+SRATEN!AB35+TAMANAGUNG!AH35+TAMPO!AB35 -> 68
A36: 4 | B36: Jumlah surat suara yang tidak digunakan/tidak terpakai, termasuk sisa surat suara cadangan | E36: =E33-(E34+E35) -> 14904
A38: III | B38: DATA PEMILIH DISABILITAS
B39: Jumlah seluruh Pemilih disabilitas yang menggunakan hak pilih | D39: LK | E39: =BENCULUK!AS39+CLURING!AL39+KALIPLOSO!Q39+PLAMPANGREJO!AE39+SARIMULYO!AA39+SEMBULUNG!AC39+SRATEN!AB39+TAMANAGUNG!AH39+TAMPO!AB39 -> 29
D40: PR | E40: =BENCULUK!AS40+CLURING!AL40+KALIPLOSO!Q40+PLAMPANGREJO!AE40+SARIMULYO!AA40+SEMBULUNG!AC40+SRATEN!AB40+TAMANAGUNG!AH40+TAMPO!AB40 -> 41
D41: JML | E41: =SUM(E39:E40) -> 70
A43: IV | B43: DATA RINCIAN PEROLEHAN SUARA PASANGAN CALON BUPATI DAN WAKIL BUPATI
A44: NOMOR DAN NAMA CALON
B45: 1 | C45: H. ANIES RASYID BASWEDAN, Ph.D. - Dr. (H.C.) H. A. MUHAIMIN ISKANDAR | E45: =BENCULUK!AS45+CLURING!AL45+KALIPLOSO!Q45+PLAMPANGREJO!AE45+SARIMULYO!AA45+SEMBULUNG!AC45+SRATEN!AB45+TAMANAGUNG!AH45+TAMPO!AB45 -> 4605
B46: 2 | C46: H. PRABOWO SUBIANTO - GIBRAN RAKABUMING RAKA | E46: =BENCULUK!AS46+CLURING!AL46+KALIPLOSO!Q46+PLAMPANGREJO!AE46+SARIMULYO!AA46+SEMBULUNG!AC46+SRATEN!AB46+TAMANAGUNG!AH46+TAMPO!AB46 -> 31040
B47: 3 | C47: H. GANJAR PRANOWO, S.H., M.I.P. - Prof. Dr. H. M. MAHFUD MD | E47: =BENCULUK!AS47+CLURING!AL47+KALIPLOSO!Q47+PLAMPANGREJO!AE47+SARIMULYO!AA47+SEMBULUNG!AC47+SRATEN!AB47+TAMANAGUNG!AH47+TAMPO!AB47 -> 9078
A49: V | B49: DATA SUARA SAH DAN TIDAK SAH
B50: A. | C50: JUMLAH SELURUH SUARA SAH | E50: =BENCULUK!AS50+CLURING!AL50+KALIPLOSO!Q50+PLAMPANGREJO!AE50+SARIMULYO!AA50+SEMBULUNG!AC50+SRATEN!AB50+TAMANAGUNG!AH50+TAMPO!AB50 -> 47147
B51: B. | C51: JUMLAH SUARA TIDAK SAH | E51: =BENCULUK!AS51+CLURING!AL51+KALIPLOSO!Q51+PLAMPANGREJO!AE51+SARIMULYO!AA51+SEMBULUNG!AC51+SRATEN!AB51+TAMANAGUNG!AH51+TAMPO!AB51 -> 717
B52: C. | C52: JUMLAH SELURUH SUARA SAH DAN SUARA TIDAK SAH (V.A + V.B) | E52: =SUM(E50:E51) -> 47864

Sheet BENCULUK
C2: Kecamatan | D2: CLURING
C3: Kabupaten | D3: BANYUWANGI
C4: Provinsi | D4: JAWA TIMUR
C9: Kelurahan | D9: BENCULUK
A12: I | B12: DATA PEMILIH DAN PENGGUNAAN HAK PILIH | AS12: JUMLAH AKHIR
A13: A | B13: DATA PEMILIH | E13: TPS 001 | F13: TPS 002 | G13: TPS 003 | H13: TPS 004 | I13: TPS 005 | J13: TPS 006 | K13: TPS 007 | L13: TPS 008 | M13: TPS 009 | N13: TPS 010 | O13: TPS 011 | P13: TPS 012 | Q13: TPS 013 | R13: TPS 014 | S13: TPS 015 | T13: TPS 016 | U13: TPS 017 | V13: TPS 018 | W13: TPS 019 | X13: TPS 020 | Y13: TPS 021 | Z13: TPS 022 | AA13: TPS 023 | AB13: TPS 024 | AC13: TPS 025 | AD13: TPS 026 | AE13: TPS 027 | AF13: TPS 028 | AG13: TPS 029 | AH13: TPS 030 | AI13: TPS 031 | AJ13: TPS 032 | AK13: TPS 033 | AL13: TPS 034 | AM13: TPS 035 | AN13: TPS 036 | AO13: TPS 037 | AP13: TPS 038 | AQ13: TPS 039 | AR13: TPS 040
B14: Jumlah Pemilih dalam Daftar Pemilih Tetap (DPT) | D14: LK | E14: 136 | F14: 122 | G14: 131 | H14: 114 | I14: 125 | J14: 123 | K14: 119 | L14: 115 | M14: 138 | N14: 121 | O14: 126 | P14: 124 | Q14: 141 | R14: 144 | S14: 139 | T14: 124 | U14: 123 | V14: 119 | W14: 123 | X14: 134 | Y14: 129 | Z14: 139 | AA14: 138 | AB14: 118 | AC14: 140 | AD14: 136 | AE14: 153 | AF14: 141 | AG14: 133 | AH14: 131 | AI14: 135 | AJ14: 127 | AK14: 141 | AL14: 127 | AM14: 130 | AN14: 132 | AO14: 125 | AP14: 143 | AQ14: 146 | AR14: 130 | AS14: =SUM(E14:AR14) -> 5235
D15: PR | E15: 123 | F15: 131 | G15: 122 | H15: 141 | I15: 121 | J15: 120 | K15: 126 | L15: 120 | M15: 134 | N15: 138 | O15: 125 | P15: 144 | Q15: 142 | R15: 133 | S15: 141 | T15: 137 | U15: 129 | V15: 113 | W15: 146 | X15: 131 | Y15: 146 | Z15: 145 | AA15: 142 | AB15: 132 | AC15: 123 | AD15: 136 | AE15: 136 | AF15: 143 | AG15: 137 | AH15: 122 | AI15: 131 | AJ15: 123 | AK15: 125 | AL15: 130 | AM15: 135 | AN15: 133 | AO15: 132 | AP15: 147 | AQ15: 126 | AR15: 140 | AS15: =SUM(E15:AR15) -> 5301
D16: JML | E16: =SUM(E14:E15) -> 259 | F16: =SUM(F14:F15) -> 253 | G16: =SUM(G14:G15) -> 253 | H16: =SUM(H14:H15) -> 255 | I16: =SUM(I14:I15) -> 246 | J16: =SUM(J14:J15) -> 243 | K16: =SUM(K14:K15) -> 245 | L16: =SUM(L14:L15) -> 235 | ... AR16: =SUM(AR14:AR15) -> 270 | AS16: =SUM(E16:AR16) -> 10536
A18: B | B18: PENGGUNA HAK PILIH
B19: 1. | C19: Jumlah pengguna hak pilih dalam Daftar Pemilih Tetap (DPT) | D19: LK | E19: 106 | F19: 98 | G19: 88 | H19: 84 | I19: 89 | J19: 83 | K19: 79 | L19: 92 | M19: 94 | N19: 87 | O19: 92 | P19: 81 | Q19: 98 | R19: 92 | S19: 102 | T19: 99 | U19: 85 | V19: 77 | W19: 97 | X19: 100 | Y19: 86 | Z19: 106 | AA19: 104 | AB19: 89 | AC19: 103 | AD19: 120 | AE19: 118 | AF19: 112 | AG19: 110 | AH19: 92 | AI19: 109 | AJ19: 92 | AK19: 108 | AL19: 99 | AM19: 93 | AN19: 113 | AO19: 96 | AP19: 111 | AQ19: 92 | AR19: 90 | AS19: =SUM(E19:AR19) -> 3866
D20: PR | E20: 92 | F20: 93 | G20: 89 | H20: 114 | I20: 98 | J20: 82 | K20: 86 | L20: 87 | M20: 104 | N20: 103 | O20: 97 | P20: 92 | Q20: 99 | R20: 85 | S20: 119 | T20: 108 | U20: 103 | V20: 79 | W20: 118 | X20: 108 | Y20: 115 | Z20: 116 | AA20: 124 | AB20: 101 | AC20: 94 | AD20: 118 | AE20: 113 | AF20: 117 | AG20: 112 | AH20: 91 | AI20: 111 | AJ20: 105 | AK20: 109 | AL20: 105 | AM20: 105 | AN20: 120 | AO20: 104 | AP20: 120 | AQ20: 101 | AR20: 106 | AS20: =SUM(E20:AR20) -> 4143
D21: JML | E21: =SUM(E19:E20) -> 198 | F21: =SUM(F19:F20) -> 191 | G21: =SUM(G19:G20) -> 177 | H21: =SUM(H19:H20) -> 198 | I21: =SUM(I19:I20) -> 187 | J21: =SUM(J19:J20) -> 165 | K21: =SUM(K19:K20) -> 165 | L21: =SUM(L19:L20) -> 179 | ... AR21: =SUM(AR19:AR20) -> 196 | AS21: =SUM(E21:AR21) -> 8009
B22: 2. | C22: Jumlah pengguna hak pilih dalam Daftar Pemilih Tambahan (DPTb) | D22: LK | E22: 1 | F22: 0 | G22: 1 | H22: 0 | I22: 0 | J22: 0 | K22: 0 | L22: 0 | M22: 0 | N22: 0 | O22: 0 | P22: 0 | Q22: 0 | R22: 0 | S22: 0 | T22: 0 | U22: 0 | V22: 0 | W22: 0 | X22: 1 | Y22: 0 | Z22: 3 | AA22: 0 | AB22: 0 | AC22: 0 | AD22: 0 | AE22: 0 | AF22: 0 | AG22: 0 | AH22: 0 | AI22: 0 | AJ22: 0 | AK22: 0 | AL22: 0 | AM22: 0 | AN22: 0 | AO22: 0 | AP22: 0 | AQ22: 0 | AR22: 0 | AS22: =SUM(E22:AR22) -> 6
D23: PR | E23: 1 | F23: 0 | G23: 0 | H23: 0 | I23: 0 | J23: 0 | K23: 0 | L23: 0 | M23: 0 | N23: 0 | O23: 0 | P23: 0 | Q23: 0 | R23: 0 | S23: 0 | T23: 0 | U23: 0 | V23: 0 | W23: 0 | X23: 0 | Y23: 0 | Z23: 0 | AA23: 0 | AB23: 0 | AC23: 0 | AD23: 0 | AE23: 0 | AF23: 0 | AG23: 0 | AH23: 0 | AI23: 0 | AJ23: 0 | AK23: 0 | AL23: 0 | AM23: 0 | AN23: 0 | AO23: 0 | AP23: 0 | AQ23: 0 | AR23: 0 | AS23: =SUM(E23:AR23) -> 1
D24: JML | E24: =SUM(E22:E23) -> 2 | F24: =SUM(F22:F23) -> 0 | G24: =SUM(G22:G23) -> 1 | H24: =SUM(H22:H23) -> 0 | I24: =SUM(I22:I23) -> 0 | J24: =SUM(J22:J23) -> 0 | K24: =SUM(K22:K23) -> 0 | L24: =SUM(L22:L23) -> 0 | ... AR24: =SUM(AR22:AR23) -> 0 | AS24: =SUM(E24:AR24) -> 7
B25: 3. | C25: Jumlah pengguna hak pilih dalam Daftar Pemilih Khusus (DPK) | D25: LK | E25: 3 | F25: 0 | G25: 0 | H25: 1 | I25: 0 | J25: 1 | K25: 0 | L25: 0 | M25: 0 | N25: 0 | O25: 2 | P25: 0 | Q25: 2 | R25: 0 | S25: 0 | T25: 5 | U25: 0 | V25: 0 | W25: 0 | X25: 0 | Y25: 2 | Z25: 1 | AA25: 4 | AB25: 1 | AC25: 0 | AD25: 0 | AE25: 0 | AF25: 0 | AG25: 0 | AH25: 3 | AI25: 0 | AJ25: 0 | AK25: 0 | AL25: 1 | AM25: 1 | AN25: 1 | AO25: 0 | AP25: 1 | AQ25: 1 | AR25: 0 | AS25: =SUM(E25:AR25) -> 30
D26: PR | E26: 3 | F26: 0 | G26: 0 | H26: 1 | I26: 0 | J26: 0 | K26: 1 | L26: 0 | M26: 0 | N26: 0 | O26: 4 | P26: 1 | Q26: 3 | R26: 0 | S26: 0 | T26: 0 | U26: 0 | V26: 0 | W26: 0 | X26: 0 | Y26: 3 | Z26: 0 | AA26: 1 | AB26: 2 | AC26: 2 | AD26: 0 | AE26: 0 | AF26: 0 | AG26: 0 | AH26: 1 | AI26: 1 | AJ26: 0 | AK26: 0 | AL26: 0 | AM26: 1 | AN26: 2 | AO26: 0 | AP26: 1 | AQ26: 3 | AR26: 0 | AS26: =SUM(E26:AR26) -> 30
D27: JML | E27: =SUM(E25:E26) -> 6 | F27: =SUM(F25:F26) -> 0 | G27: =SUM(G25:G26) -> 0 | H27: =SUM(H25:H26) -> 2 | I27: =SUM(I25:I26) -> 0 | J27: =SUM(J25:J26) -> 1 | K27: =SUM(K25:K26) -> 1 | L27: =SUM(L25:L26) -> 0 | ... AR27: =SUM(AR25:AR26) -> 0 | AS27: =SUM(E27:AR27) -> 60
B28: 4. | C28: Jumlah Pengguna Hak Pilih (B.1+B.2+B.3) | D28: LK | E28: =SUM(E19,E22,E25) -> 110 | F28: =SUM(F19,F22,F25) -> 98 | G28: =SUM(G19,G22,G25) -> 89 | H28: =SUM(H19,H22,H25) -> 85 | I28: =SUM(I19,I22,I25) -> 89 | J28: =SUM(J19,J22,J25) -> 84 | K28: =SUM(K19,K22,K25) -> 79 | L28: =SUM(L19,L22,L25) -> 92 | ... AR28: =SUM(AR19,AR22,AR25) -> 90 | AS28: =SUM(E28:AR28) -> 3902
D29: PR | E29: =SUM(E20,E23,E26) -> 96 | F29: =SUM(F20,F23,F26) -> 93 | G29: =SUM(G20,G23,G26) -> 89 | H29: =SUM(H20,H23,H26) -> 115 | I29: =SUM(I20,I23,I26) -> 98 | J29: =SUM(J20,J23,J26) -> 82 | K29: =SUM(K20,K23,K26) -> 87 | L29: =SUM(L20,L23,L26) -> 87 | ... AR29: =SUM(AR20,AR23,AR26) -> 106 | AS29: =SUM(E29:AR29) -> 4174
D30: JML | E30: =SUM(E28:E29) -> 206 | F30: =SUM(F28:F29) -> 191 | G30: =SUM(G28:G29) -> 178 | H30: =SUM(H28:H29) -> 200 | I30: =SUM(I28:I29) -> 187 | J30: =SUM(J28:J29) -> 166 | K30: =SUM(K28:K29) -> 166 | L30: =SUM(L28:L29) -> 179 | ... AR30: =SUM(AR28:AR29) -> 196 | AS30: =SUM(E30:AR30) -> 8076
A32: II | B32: DATA PENGGUNAAN SURAT SUARA
A33: 1 | B33: Jumlah surat suara yang diterima, termasuk surat suara cadangan 2,5% dari DPT | E33: 265 | F33: 258 | G33: 259 | H33: 261 | I33: 251 | J33: 247 | K33: 249 | L33: 240 | M33: 278 | N33: 265 | O33: 257 | P33: 274 | Q33: 289 | R33: 283 | S33: 286 | T33: 267 | U33: 258 | V33: 237 | W33: 274 | X33: 272 | Y33: 281 | Z33: 290 | AA33: 286 | AB33: 255 | AC33: 271 | AD33: 278 | AE33: 295 | AF33: 289 | AG33: 277 | AH33: 261 | AI33: 277 | AJ33: 258 | AK33: 272 | AL33: 265 | AM33: 271 | AN33: 274 | AO33: 263 | AP33: 296 | AQ33: 278 | AR33: 284 | AS33: =SUM(E33:AR33) -> 10791
A34: 2 | B34: Jumlah surat suara yang digunakan | E34: 206 | F34: 191 | G34: 178 | H34: 200 | I34: 187 | J34: 166 | K34: 166 | L34: 179 | M34: 198 | N34: 190 | O34: 195 | P34: 174 | Q34: 202 | R34: 177 | S34: 221 | T34: 212 | U34: 188 | V34: 156 | W34: 215 | X34: 209 | Y34: 206 | Z34: 226 | AA34: 233 | AB34: 193 | AC34: 199 | AD34: 238 | AE34: 231 | AF34: 229 | AG34: 222 | AH34: 187 | AI34: 221 | AJ34: 197 | AK34: 217 | AL34: 205 | AM34: 200 | AN34: 236 | AO34: 200 | AP34: 233 | AQ34: 197 | AR34: 196 | AS34: =SUM(E34:AR34) -> 8076
A35: 3 | B35: Jumlah surat suara dikembalikan oleh pemilih (karena rusak atau keliru coblos) | E35: 0 | F35: 0 | G35: 0 | H35: 0 | I35: 0 | J35: 0 | K35: 0 | L35: 0 | M35: 0 | N35: 0 | O35: 0 | P35: 0 | Q35: 0 | R35: 0 | S35: 0 | T35: 0 | U35: 2 | V35: 0 | W35: 0 | X35: 0 | Y35: 0 | Z35: 1 | AA35: 0 | AB35: 0 | AC35: 1 | AD35: 0 | AE35: 0 | AF35: 0 | AG35: 0 | AH35: 1 | AI35: 0 | AJ35: 0 | AK35: 0 | AL35: 0 | AM35: 0 | AN35: 0 | AO35: 0 | AP35: 0 | AQ35: 0 | AR35: 1 | AS35: =SUM(E35:AR35) -> 6
A36: 4 | B36: Jumlah surat suara yang tidak digunakan/tidak terpakai, termasuk sisa surat suara cadangan | E36: =E33-(E34+E35) -> 59 | F36: =F33-(F34+F35) -> 67 | G36: =G33-(G34+G35) -> 81 | H36: =H33-(H34+H35) -> 61 | I36: =I33-(I34+I35) -> 64 | J36: =J33-(J34+J35) -> 81 | K36: =K33-(K34+K35) -> 83 | L36: =L33-(L34+L35) -> 61 | ... AR36: =AR33-(AR34+AR35) -> 87 | AS36: =SUM(E36:AR36) -> 2709
A38: III | B38: DATA PEMILIH DISABILITAS
B39: Jumlah seluruh Pemilih disabilitas yang menggunakan hak pilih | D39: LK | E39: 0 | F39: 1 | G39: 0 | H39: 0 | I39: 0 | J39: 0 | K39: 0 | L39: 0 | M39: 0 | N39: 0 | O39: 0 | P39: 0 | Q39: 0 | R39: 0 | S39: 0 | T39: 0 | U39: 0 | V39: 0 | W39: 0 | X39: 1 | Y39: 0 | Z39: 1 | AA39: 0 | AB39: 1 | AC39: 1 | AD39: 0 | AE39: 0 | AF39: 0 | AG39: 1 | AH39: 0 | AI39: 0 | AJ39: 0 | AK39: 0 | AL39: 1 | AM39: 0 | AN39: 3 | AO39: 0 | AP39: 0 | AQ39: 0 | AR39: 0 | AS39: =SUM(E39:AR39) -> 10
D40: PR | E40: 0 | F40: 0 | G40: 0 | H40: 0 | I40: 0 | J40: 0 | K40: 0 | L40: 0 | M40: 0 | N40: 0 | O40: 0 | P40: 1 | Q40: 0 | R40: 0 | S40: 0 | T40: 0 | U40: 0 | V40: 0 | W40: 0 | X40: 1 | Y40: 0 | Z40: 4 | AA40: 0 | AB40: 1 | AC40: 0 | AD40: 0 | AE40: 0 | AF40: 0 | AG40: 0 | AH40: 0 | AI40: 0 | AJ40: 0 | AK40: 0 | AL40: 1 | AM40: 0 | AN40: 9 | AO40: 0 | AP40: 0 | AQ40: 0 | AR40: 0 | AS40: =SUM(E40:AR40) -> 17
D41: JML | E41: =SUM(E39:E40) -> 0 | F41: =SUM(F39:F40) -> 1 | G41: =SUM(G39:G40) -> 0 | H41: =SUM(H39:H40) -> 0 | I41: =SUM(I39:I40) -> 0 | J41: =SUM(J39:J40) -> 0 | K41: =SUM(K39:K40) -> 0 | L41: =SUM(L39:L40) -> 0 | ... AR41: =SUM(AR39:AR40) -> 0 | AS41: =SUM(E41:AR41) -> 27
A43: IV | B43: DATA RINCIAN PEROLEHAN SUARA PASANGAN CALON BUPATI DAN WAKIL BUPATI
A44: NOMOR DAN NAMA CALON
B45: 1 | C45: H. ANIES RASYID BASWEDAN, Ph.D. - Dr. (H.C.) H. A. MUHAIMIN ISKANDAR | E45: 33 | F45: 14 | G45: 16 | H45: 29 | I45: 22 | J45: 12 | K45: 30 | L45: 14 | M45: 12 | N45: 23 | O45: 20 | P45: 18 | Q45: 21 | R45: 9 | S45: 16 | T45: 14 | U45: 21 | V45: 12 | W45: 24 | X45: 38 | Y45: 41 | Z45: 43 | AA45: 26 | AB45: 37 | AC45: 32 | AD45: 17 | AE45: 21 | AF45: 44 | AG45: 35 | AH45: 24 | AI45: 7 | AJ45: 9 | AK45: 20 | AL45: 24 | AM45: 20 | AN45: 23 | AO45: 18 | AP45: 26 | AQ45: 17 | AR45: 25 | AS45: =SUM(E45:AR45) -> 907
B46: 2 | C46: H. PRABOWO SUBIANTO - GIBRAN RAKABUMING RAKA | E46: 130 | F46: 143 | G46: 145 | H46: 117 | I46: 127 | J46: 130 | K46: 104 | L46: 147 | M46: 147 | N46: 122 | O46: 122 | P46: 103 | Q46: 100 | R46: 125 | S46: 164 | T46: 161 | U46: 122 | V46: 118 | W46: 137 | X46: 144 | Y46: 131 | Z46: 132 | AA46: 165 | AB46: 116 | AC46: 134 | AD46: 171 | AE46: 158 | AF46: 139 | AG46: 140 | AH46: 134 | AI46: 174 | AJ46: 164 | AK46: 144 | AL46: 132 | AM46: 143 | AN46: 158 | AO46: 145 | AP46: 173 | AQ46: 142 | AR46: 134 | AS46: =SUM(E46:AR46) -> 5537
B47: 3 | C47: H. GANJAR PRANOWO, S.H., M.I.P. - Prof. Dr. H. M. MAHFUD MD | E47: 36 | F47: 33 | G47: 17 | H47: 53 | I47: 35 | J47: 22 | K47: 29 | L47: 17 | M47: 36 | N47: 41 | O47: 50 | P47: 52 | Q47: 75 | R47: 38 | S47: 35 | T47: 33 | U47: 43 | V47: 23 | W47: 48 | X47: 24 | Y47: 31 | Z47: 41 | AA47: 37 | AB47: 35 | AC47: 33 | AD47: 45 | AE47: 51 | AF47: 44 | AG47: 44 | AH47: 27 | AI47: 37 | AJ47: 23 | AK47: 48 | AL47: 45 | AM47: 37 | AN47: 55 | AO47: 33 | AP47: 30 | AQ47: 38 | AR47: 36 | AS47: =SUM(E47:AR47) -> 1510
A49: V | B49: DATA SUARA SAH DAN TIDAK SAH
B50: A. | C50: JUMLAH SELURUH SUARA SAH | E50: =SUM(E45:E47) -> 199 | F50: =SUM(F45:F47) -> 190 | G50: =SUM(G45:G47) -> 178 | H50: =SUM(H45:H47) -> 199 | I50: =SUM(I45:I47) -> 184 | J50: =SUM(J45:J47) -> 164 | K50: =SUM(K45:K47) -> 163 | L50: =SUM(L45:L47) -> 178 | ... AR50: =SUM(AR45:AR47) -> 195 | AS50: =SUM(E50:AR50) -> 7954
B51: B. | C51: JUMLAH SUARA TIDAK SAH | E51: 7 | F51: 1 | G51: 0 | H51: 1 | I51: 3 | J51: 2 | K51: 3 | L51: 1 | M51: 3 | N51: 4 | O51: 3 | P51: 1 | Q51: 6 | R51: 5 | S51: 6 | T51: 4 | U51: 2 | V51: 3 | W51: 6 | X51: 3 | Y51: 3 | Z51: 10 | AA51: 5 | AB51: 5 | AC51: 0 | AD51: 5 | AE51: 1 | AF51: 2 | AG51: 3 | AH51: 2 | AI51: 3 | AJ51: 1 | AK51: 5 | AL51: 4 | AM51: 0 | AN51: 0 | AO51: 4 | AP51: 4 | AQ51: 0 | AR51: 1 | AS51: =SUM(E51:AR51) -> 122
B52: C. | C52: JUMLAH SELURUH SUARA SAH DAN SUARA TIDAK SAH (V.A + V.B) | E52: =SUM(E50:E51) -> 206 | F52: =SUM(F50:F51) -> 191 | G52: =SUM(G50:G51) -> 178 | H52: =SUM(H50:H51) -> 200 | I52: =SUM(I50:I51) -> 187 | J52: =SUM(J50:J51) -> 166 | K52: =SUM(K50:K51) -> 166 | L52: =SUM(L50:L51) -> 179 | ... AR52: =SUM(AR50:AR51) -> 196 | AS52: =SUM(E52:AR52) -> 8076

Sheet CLURING
C2: Kecamatan | D2: CLURING
C3: Kabupaten | D3: BANYUWANGI
C4: Provinsi | D4: JAWA TIMUR
C9: Kelurahan | D9: CLURING
A12: I | B12: DATA PEMILIH DAN PENGGUNAAN HAK PILIH | AL12: JUMLAH AKHIR
A13: A | B13: DATA PEMILIH | E13: TPS 001 | F13: TPS 002 | G13: TPS 003 | H13: TPS 004 | I13: TPS 005 | J13: TPS 006 | K13: TPS 007 | L13: TPS 008 | M13: TPS 009 | N13: TPS 010 | O13: TPS 011 | P13: TPS 012 | Q13: TPS 013 | R13: TPS 014 | S13: TPS 015 | T13: TPS 016 | U13: TPS 017 | V13: TPS 018 | W13: TPS 019 | X13: TPS 020 | Y13: TPS 021 | Z13: TPS 022 | AA13: TPS 023 | AB13: TPS 024 | AC13: TPS 025 | AD13: TPS 026 | AE13: TPS 027 | AF13: TPS 028 | AG13: TPS 029 | AH13: TPS 030 | AI13: TPS 031 | AJ13: TPS 032 | AK13: TPS 033
B14: Jumlah Pemilih dalam Daftar Pemilih Tetap (DPT) | D14: LK | E14: 136 | F14: 136 | G14: 145 | H14: 148 | I14: 114 | J14: 134 | K14: 130 | L14: 136 | M14: 132 | N14: 123 | O14: 117 | P14: 133 | Q14: 130 | R14: 132 | S14: 145 | T14: 128 | U14: 136 | V14: 122 | W14: 135 | X14: 135 | Y14: 141 | Z14: 133 | AA14: 142 | AB14: 158 | AC14: 141 | AD14: 146 | AE14: 131 | AF14: 140 | AG14: 134 | AH14: 133 | AI14: 121 | AJ14: 131 | AK14: 134 | AL14: =SUM(E14:AK14) -> 4432
D15: PR | E15: 138 | F15: 128 | G15: 154 | H15: 150 | I15: 139 | J15: 132 | K15: 136 | L15: 129 | M15: 126 | N15: 136 | O15: 124 | P15: 141 | Q15: 129 | R15: 122 | S15: 141 | T15: 122 | U15: 132 | V15: 129 | W15: 134 | X15: 137 | Y15: 131 | Z15: 129 | AA15: 150 | AB15: 132 | AC15: 146 | AD15: 146 | AE15: 146 | AF15: 131 | AG15: 136 | AH15: 138 | AI15: 146 | AJ15: 140 | AK15: 132 | AL15: =SUM(E15:AK15) -> 4482
D16: JML | E16: =SUM(E14:E15) -> 274 | F16: =SUM(F14:F15) -> 264 | G16: =SUM(G14:G15) -> 299 | H16: =SUM(H14:H15) -> 298 | I16: =SUM(I14:I15) -> 253 | J16: =SUM(J14:J15) -> 266 | K16: =SUM(K14:K15) -> 266 | L16: =SUM(L14:L15) -> 265 | ... AK16: =SUM(AK14:AK15) -> 266 | AL16: =SUM(E16:AK16) -> 8914
A18: B | B18: PENGGUNA HAK PILIH
B19: 1. | C19: Jumlah pengguna hak pilih dalam Daftar Pemilih Tetap (DPT) | D19: LK | E19: 98 | F19: 91 | G19: 115 | H19: 156 | I19: 75 | J19: 99 | K19: 86 | L19: 95 | M19: 93 | N19: 101 | O19: 68 | P19: 101 | Q19: 76 | R19: 101 | S19: 96 | T19: 92 | U19: 106 | V19: 95 | W19: 98 | X19: 102 | Y19: 104 | Z19: 102 | AA19: 107 | AB19: 109 | AC19: 107 | AD19: 104 | AE19: 112 | AF19: 111 | AG19: 108 | AH19: 104 | AI19: 100 | AJ19: 97 | AK19: 105 | AL19: =SUM(E19:AK19) -> 3314
D20: PR | E20: 102 | F20: 103 | G20: 123 | H20: 90 | I20: 92 | J20: 103 | K20: 98 | L20: 101 | M20: 98 | N20: 118 | O20: 86 | P20: 115 | Q20: 92 | R20: 98 | S20: 103 | T20: 95 | U20: 108 | V20: 108 | W20: 101 | X20: 108 | Y20: 102 | Z20: 103 | AA20: 112 | AB20: 104 | AC20: 109 | AD20: 117 | AE20: 120 | AF20: 107 | AG20: 106 | AH20: 108 | AI20: 119 | AJ20: 118 | AK20: 106 | AL20: =SUM(E20:AK20) -> 3473
D21: JML | E21: =SUM(E19:E20) -> 200 | F21: =SUM(F19:F20) -> 194 | G21: =SUM(G19:G20) -> 238 | H21: =SUM(H19:H20) -> 246 | I21: =SUM(I19:I20) -> 167 | J21: =SUM(J19:J20) -> 202 | K21: =SUM(K19:K20) -> 184 | L21: =SUM(L19:L20) -> 196 | ... AK21: =SUM(AK19:AK20) -> 211 | AL21: =SUM(E21:AK21) -> 6787
B22: 2. | C22: Jumlah pengguna hak pilih dalam Daftar Pemilih Tambahan (DPTb) | D22: LK | E22: 0 | F22: 1 | G22: 3 | H22: 1 | I22: 0 | J22: 0 | K22: 0 | L22: 0 | M22: 0 | N22: 1 | O22: 2 | P22: 0 | Q22: 0 | R22: 1 | S22: 0 | T22: 1 | U22: 0 | V22: 0 | W22: 0 | X22: 0 | Y22: 0 | Z22: 0 | AA22: 0 | AB22: 0 | AC22: 0 | AD22: 0 | AE22: 0 | AF22: 0 | AG22: 0 | AH22: 0 | AI22: 0 | AJ22: 0 | AK22: 0 | AL22: =SUM(E22:AK22) -> 10
D23: PR | E23: 0 | F23: 2 | G23: 3 | H23: 2 | I23: 0 | J23: 0 | K23: 0 | L23: 0 | M23: 0 | N23: 1 | O23: 2 | P23: 0 | Q23: 0 | R23: 0 | S23: 0 | T23: 1 | U23: 0 | V23: 0 | W23: 0 | X23: 0 | Y23: 0 | Z23: 0 | AA23: 0 | AB23: 0 | AC23: 0 | AD23: 1 | AE23: 0 | AF23: 0 | AG23: 0 | AH23: 0 | AI23: 0 | AJ23: 0 | AK23: 0 | AL23: =SUM(E23:AK23) -> 12
D24: JML | E24: =SUM(E22:E23) -> 0 | F24: =SUM(F22:F23) -> 3 | G24: =SUM(G22:G23) -> 6 | H24: =SUM(H22:H23) -> 3 | I24: =SUM(I22:I23) -> 0 | J24: =SUM(J22:J23) -> 0 | K24: =SUM(K22:K23) -> 0 | L24: =SUM(L22:L23) -> 0 | ... AK24: =SUM(AK22:AK23) -> 0 | AL24: =SUM(E24:AK24) -> 22
B25: 3. | C25: Jumlah pengguna hak pilih dalam Daftar Pemilih Khusus (DPK) | D25: LK | E25: 0 | F25: 0 | G25: 0 | H25: 3 | I25: 0 | J25: 4 | K25: 1 | L25: 1 | M25: 1 | N25: 3 | O25: 1 | P25: 2 | Q25: 1 | R25: 4 | S25: 2 | T25: 1 | U25: 0 | V25: 1 | W25: 0 | X25: 0 | Y25: 1 | Z25: 1 | AA25: 0 | AB25: 1 | AC25: 2 | AD25: 1 | AE25: 2 | AF25: 5 | AG25: 3 | AH25: 0 | AI25: 3 | AJ25: 2 | AK25: 3 | AL25: =SUM(E25:AK25) -> 49
D26: PR | E26: 2 | F26: 1 | G26: 2 | H26: 3 | I26: 1 | J26: 2 | K26: 2 | L26: 4 | M26: 1 | N26: 3 | O26: 2 | P26: 3 | Q26: 4 | R26: 1 | S26: 0 | T26: 0 | U26: 2 | V26: 1 | W26: 0 | X26: 0 | Y26: 1 | Z26: 5 | AA26: 1 | AB26: 3 | AC26: 1 | AD26: 4 | AE26: 3 | AF26: 3 | AG26: 2 | AH26: 0 | AI26: 3 | AJ26: 4 | AK26: 5 | AL26: =SUM(E26:AK26) -> 69
D27: JML | E27: =SUM(E25:E26) -> 2 | F27: =SUM(F25:F26) -> 1 | G27: =SUM(G25:G26) -> 2 | H27: =SUM(H25:H26) -> 6 | I27: =SUM(I25:I26) -> 1 | J27: =SUM(J25:J26) -> 6 | K27: =SUM(K25:K26) -> 3 | L27: =SUM(L25:L26) -> 5 | ... AK27: =SUM(AK25:AK26) -> 8 | AL27: =SUM(E27:AK27) -> 118
B28: 4. | C28: Jumlah Pengguna Hak Pilih (B.1+B.2+B.3) | D28: LK | E28: =SUM(E19,E22,E25) -> 98 | F28: =SUM(F19,F22,F25) -> 92 | G28: =SUM(G19,G22,G25) -> 118 | H28: =SUM(H19,H22,H25) -> 160 | I28: =SUM(I19,I22,I25) -> 75 | J28: =SUM(J19,J22,J25) -> 103 | K28: =SUM(K19,K22,K25) -> 87 | L28: =SUM(L19,L22,L25) -> 96 | ... AK28: =SUM(AK19,AK22,AK25) -> 108 | AL28: =SUM(E28:AK28) -> 3373
D29: PR | E29: =SUM(E20,E23,E26) -> 104 | F29: =SUM(F20,F23,F26) -> 106 | G29: =SUM(G20,G23,G26) -> 128 | H29: =SUM(H20,H23,H26) -> 95 | I29: =SUM(I20,I23,I26) -> 93 | J29: =SUM(J20,J23,J26) -> 105 | K29: =SUM(K20,K23,K26) -> 100 | L29: =SUM(L20,L23,L26) -> 105 | ... AK29: =SUM(AK20,AK23,AK26) -> 111 | AL29: =SUM(E29:AK29) -> 3554
D30: JML | E30: =SUM(E28:E29) -> 202 | F30: =SUM(F28:F29) -> 198 | G30: =SUM(G28:G29) -> 246 | H30: =SUM(H28:H29) -> 255 | I30: =SUM(I28:I29) -> 168 | J30: =SUM(J28:J29) -> 208 | K30: =SUM(K28:K29) -> 187 | L30: =SUM(L28:L29) -> 201 | ... AK30: =SUM(AK28:AK29) -> 219 | AL30: =SUM(E30:AK30) -> 6927
A32: II | B32: DATA PENGGUNAAN SURAT SUARA
A33: 1 | B33: Jumlah surat suara yang diterima, termasuk surat suara cadangan 2,5% dari DPT | E33: 280 | F33: 273 | G33: 305 | H33: 296 | I33: 258 | J33: 271 | K33: 272 | L33: 273 | M33: 264 | N33: 289 | O33: 246 | P33: 280 | Q33: 265 | R33: 259 | S33: 294 | T33: 255 | U33: 274 | V33: 258 | W33: 275 | X33: 277 | Y33: 278 | Z33: 269 | AA33: 299 | AB33: 299 | AC33: 293 | AD33: 298 | AE33: 283 | AF33: 288 | AG33: 277 | AH33: 277 | AI33: 273 | AJ33: 287 | AK33: 272 | AL33: =SUM(E33:AK33) -> 9157
A34: 2 | B34: Jumlah surat suara yang digunakan | E34: 202 | F34: 198 | G34: 246 | H34: 255 | I34: 168 | J34: 208 | K34: 187 | L34: 201 | M34: 193 | N34: 227 | O34: 161 | P34: 221 | Q34: 173 | R34: 205 | S34: 201 | T34: 190 | U34: 216 | V34: 205 | W34: 199 | X34: 210 | Y34: 208 | Z34: 211 | AA34: 220 | AB34: 217 | AC34: 219 | AD34: 227 | AE34: 237 | AF34: 226 | AG34: 219 | AH34: 212 | AI34: 225 | AJ34: 221 | AK34: 219 | AL34: =SUM(E34:AK34) -> 6927
A35: 3 | B35: Jumlah surat suara dikembalikan oleh pemilih (karena rusak atau keliru coblos) | E35: 1 | F35: 0 | G35: 0 | H35: 0 | I35: 0 | J35: 1 | K35: 0 | L35: 0 | M35: 0 | N35: 0 | O35: 0 | P35: 0 | Q35: 0 | R35: 0 | S35: 4 | T35: 2 | U35: 0 | V35: 2 | W35: 0 | X35: 0 | Y35: 0 | Z35: 1 | AA35: 0 | AB35: 1 | AC35: 3 | AD35: 0 | AE35: 1 | AF35: 3 | AG35: 0 | AH35: 0 | AI35: 2 | AJ35: 0 | AK35: 0 | AL35: =SUM(E35:AK35) -> 21
A36: 4 | B36: Jumlah surat suara yang tidak digunakan/tidak terpakai, termasuk sisa surat suara cadangan | E36: =E33-(E34+E35) -> 77 | F36: =F33-(F34+F35) -> 75 | G36: =G33-(G34+G35) -> 59 | H36: =H33-(H34+H35) -> 41 | I36: =I33-(I34+I35) -> 90 | J36: =J33-(J34+J35) -> 62 | K36: =K33-(K34+K35) -> 85 | L36: =L33-(L34+L35) -> 72 | ... AK36: =AK33-(AK34+AK35) -> 53 | AL36: =SUM(E36:AK36) -> 2209
A38: III | B38: DATA PEMILIH DISABILITAS
B39: Jumlah seluruh Pemilih disabilitas yang menggunakan hak pilih | D39: LK | E39: 0 | F39: 0 | G39: 1 | H39: 0 | I39: 0 | J39: 2 | K39: 0 | L39: 0 | M39: 0 | N39: 0 | O39: 0 | P39: 0 | Q39: 0 | R39: 0 | S39: 0 | T39: 0 | U39: 0 | V39: 0 | W39: 0 | X39: 0 | Y39: 0 | Z39: 2 | AA39: 0 | AB39: 0 | AC39: 0 | AD39: 0 | AE39: 0 | AF39: 0 | AG39: 0 | AH39: 0 | AI39: 0 | AJ39: 0 | AK39: 0 | AL39: =SUM(E39:AK39) -> 5
D40: PR | E40: 0 | F40: 0 | G40: 1 | H40: 0 | I40: 0 | J40: 1 | K40: 0 | L40: 0 | M40: 1 | N40: 0 | O40: 0 | P40: 0 | Q40: 0 | R40: 0 | S40: 0 | T40: 0 | U40: 0 | V40: 0 | W40: 1 | X40: 0 | Y40: 0 | Z40: 1 | AA40: 0 | AB40: 0 | AC40: 0 | AD40: 0 | AE40: 0 | AF40: 1 | AG40: 0 | AH40: 0 | AI40: 0 | AJ40: 0 | AK40: 0 | AL40: =SUM(E40:AK40) -> 6
D41: JML | E41: =SUM(E39:E40) -> 0 | F41: =SUM(F39:F40) -> 0 | G41: =SUM(G39:G40) -> 2 | H41: =SUM(H39:H40) -> 0 | I41: =SUM(I39:I40) -> 0 | J41: =SUM(J39:J40) -> 3 | K41: =SUM(K39:K40) -> 0 | L41: =SUM(L39:L40) -> 0 | ... AK41: =SUM(AK39:AK40) -> 0 | AL41: =SUM(E41:AK41) -> 11
A43: IV | B43: DATA RINCIAN PEROLEHAN SUARA PASANGAN CALON BUPATI DAN WAKIL BUPATI
A44: NOMOR DAN NAMA CALON
B45: 1 | C45: H. ANIES RASYID BASWEDAN, Ph.D. - Dr. (H.C.) H. A. MUHAIMIN ISKANDAR | E45: 26 | F45: 27 | G45: 17 | H45: 22 | I45: 11 | J45: 16 | K45: 19 | L45: 17 | M45: 13 | N45: 11 | O45: 18 | P45: 12 | Q45: 12 | R45: 12 | S45: 30 | T45: 28 | U45: 16 | V45: 16 | W45: 17 | X45: 8 | Y45: 18 | Z45: 8 | AA45: 12 | AB45: 20 | AC45: 12 | AD45: 16 | AE45: 22 | AF45: 5 | AG45: 18 | AH45: 9 | AI45: 10 | AJ45: 11 | AK45: 21 | AL45: =SUM(E45:AK45) -> 530
B46: 2 | C46: H. PRABOWO SUBIANTO - GIBRAN RAKABUMING RAKA | E46: 126 | F46: 139 | G46: 185 | H46: 168 | I46: 113 | J46: 133 | K46: 122 | L46: 140 | M46: 155 | N46: 190 | O46: 110 | P46: 148 | Q46: 125 | R46: 124 | S46: 142 | T46: 119 | U46: 143 | V46: 114 | W46: 113 | X46: 91 | Y46: 107 | Z46: 104 | AA46: 138 | AB46: 145 | AC46: 154 | AD46: 139 | AE46: 176 | AF46: 172 | AG46: 142 | AH46: 155 | AI46: 163 | AJ46: 159 | AK46: 140 | AL46: =SUM(E46:AK46) -> 4594
B47: 3 | C47: H. GANJAR PRANOWO, S.H., M.I.P. - Prof. Dr. H. M. MAHFUD MD | E47: 47 | F47: 32 | G47: 43 | H47: 59 | I47: 40 | J47: 57 | K47: 45 | L47: 39 | M47: 22 | N47: 21 | O47: 31 | P47: 56 | Q47: 34 | R47: 65 | S47: 25 | T47: 38 | U47: 51 | V47: 75 | W47: 64 | X47: 100 | Y47: 81 | Z47: 97 | AA47: 63 | AB47: 43 | AC47: 48 | AD47: 70 | AE47: 34 | AF47: 44 | AG47: 54 | AH47: 47 | AI47: 50 | AJ47: 49 | AK47: 56 | AL47: =SUM(E47:AK47) -> 1680
A49: V | B49: DATA SUARA SAH DAN TIDAK SAH
B50: A. | C50: JUMLAH SELURUH SUARA SAH | E50: =SUM(E45:E47) -> 199 | F50: =SUM(F45:F47) -> 198 | G50: =SUM(G45:G47) -> 245 | H50: =SUM(H45:H47) -> 249 | I50: =SUM(I45:I47) -> 164 | J50: =SUM(J45:J47) -> 206 | K50: =SUM(K45:K47) -> 186 | L50: =SUM(L45:L47) -> 196 | ... AK50: =SUM(AK45:AK47) -> 217 | AL50: =SUM(E50:AK50) -> 6804
B51: B. | C51: JUMLAH SUARA TIDAK SAH | E51: 3 | F51: 0 | G51: 1 | H51: 6 | I51: 4 | J51: 2 | K51: 1 | L51: 5 | M51: 3 | N51: 5 | O51: 2 | P51: 5 | Q51: 2 | R51: 4 | S51: 4 | T51: 5 | U51: 6 | V51: 0 | W51: 5 | X51: 11 | Y51: 2 | Z51: 2 | AA51: 7 | AB51: 9 | AC51: 5 | AD51: 2 | AE51: 5 | AF51: 5 | AG51: 5 | AH51: 1 | AI51: 2 | AJ51: 2 | AK51: 2 | AL51: =SUM(E51:AK51) -> 123
B52: C. | C52: JUMLAH SELURUH SUARA SAH DAN SUARA TIDAK SAH (V.A + V.B) | E52: =SUM(E50:E51) -> 202 | F52: =SUM(F50:F51) -> 198 | G52: =SUM(G50:G51) -> 246 | H52: =SUM(H50:H51) -> 255 | I52: =SUM(I50:I51) -> 168 | J52: =SUM(J50:J51) -> 208 | K52: =SUM(K50:K51) -> 187 | L52: =SUM(L50:L51) -> 201 | ... AK52: =SUM(AK50:AK51) -> 219 | AL52: =SUM(E52:AK52) -> 6927

Sheet KALIPLOSO
C2: Kecamatan | D2: CLURING
C3: Kabupaten | D3: BANYUWANGI
C4: Provinsi | D4: JAWA TIMUR
C9: Kelurahan | D9: KALIPLOSO
A12: I | B12: DATA PEMILIH DAN PENGGUNAAN HAK PILIH | Q12: JUMLAH AKHIR
A13: A | B13: DATA PEMILIH | E13: TPS 001 | F13: TPS 002 | G13: TPS 003 | H13: TPS 004 | I13: TPS 005 | J13: TPS 006 | K13: TPS 007 | L13: TPS 008 | M13: TPS 009 | N13: TPS 010 | O13: TPS 011 | P13: TPS 012
B14: Jumlah Pemilih dalam Daftar Pemilih Tetap (DPT) | D14: LK | E14: 137 | F14: 152 | G14: 135 | H14: 160 | I14: 142 | J14: 143 | K14: 128 | L14: 122 | M14: 107 | N14: 132 | O14: 142 | P14: 144 | Q14: =SUM(E14:P14) -> 1644
D15: PR | E15: 149 | F15: 144 | G15: 156 | H15: 137 | I15: 149 | J15: 143 | K15: 117 | L15: 122 | M15: 98 | N15: 124 | O15: 147 | P15: 150 | Q15: =SUM(E15:P15) -> 1636
D16: JML | E16: 286 | F16: 296 | G16: 291 | H16: 297 | I16: 291 | J16: 286 | K16: 245 | L16: 244 | M16: 205 | N16: 256 | O16: 289 | P16: 294 | Q16: =SUM(E16:P16) -> 3280
A18: B | B18: PENGGUNA HAK PILIH
B19: 1. | C19: Jumlah pengguna hak pilih dalam Daftar Pemilih Tetap (DPT) | D19: LK | E19: 81 | F19: 107 | G19: 100 | H19: 113 | I19: 121 | J19: 113 | K19: 103 | L19: 97 | M19: 75 | N19: 114 | O19: 116 | P19: 112 | Q19: =SUM(E19:P19) -> 1252
D20: PR | E20: 112 | F20: 117 | G20: 124 | H20: 127 | I20: 121 | J20: 117 | K20: 94 | L20: 95 | M20: 71 | N20: 87 | O20: 127 | P20: 123 | Q20: =SUM(E20:P20) -> 1315
D21: JML | E21: 193 | F21: 224 | G21: 224 | H21: 240 | I21: 242 | J21: 230 | K21: 197 | L21: 192 | M21: 146 | N21: 201 | O21: 243 | P21: 235 | Q21: =SUM(E21:P21) -> 2567
B22: 2. | C22: Jumlah pengguna hak pilih dalam Daftar Pemilih Tambahan (DPTb) | D22: LK | E22: 0 | F22: 1 | G22: 0 | H22: 0 | I22: 0 | J22: 0 | K22: 0 | L22: 0 | M22: 0 | N22: 0 | O22: 0 | P22: 0 | Q22: =SUM(E22:P22) -> 1
D23: PR | E23: 0 | F23: 2 | G23: 0 | H23: 0 | I23: 1 | J23: 0 | K23: 0 | L23: 0 | M23: 0 | N23: 0 | O23: 0 | P23: 1 | Q23: =SUM(E23:P23) -> 4
D24: JML | E24: 0 | F24: 3 | G24: 0 | H24: 0 | I24: 1 | J24: 0 | K24: 0 | L24: 0 | M24: 0 | N24: 0 | O24: 0 | P24: 1 | Q24: =SUM(E24:P24) -> 5
B25: 3. | C25: Jumlah pengguna hak pilih dalam Daftar Pemilih Khusus (DPK) | D25: LK | E25: 1 | F25: 1 | G25: 0 | H25: 0 | I25: 1 | J25: 1 | K25: 1 | L25: 0 | M25: 1 | N25: 0 | O25: 0 | P25: 0 | Q25: =SUM(E25:P25) -> 6
D26: PR | E26: 2 | F26: 1 | G26: 2 | H26: 0 | I26: 2 | J26: 3 | K26: 2 | L26: 0 | M26: 2 | N26: 0 | O26: 0 | P26: 0 | Q26: =SUM(E26:P26) -> 14
D27: JML | E27: 3 | F27: 2 | G27: 2 | H27: 0 | I27: 3 | J27: 4 | K27: 3 | L27: 0 | M27: 3 | N27: 0 | O27: 0 | P27: 0 | Q27: =SUM(E27:P27) -> 20
B28: 4. | C28: Jumlah Pengguna Hak Pilih (B.1+B.2+B.3) | D28: LK | E28: 82 | F28: 109 | G28: 100 | H28: 113 | I28: 122 | J28: 114 | K28: 104 | L28: 97 | M28: 76 | N28: 114 | O28: 116 | P28: 112 | Q28: =SUM(E28:P28) -> 1259
D29: PR | E29: 114 | F29: 120 | G29: 126 | H29: 127 | I29: 124 | J29: 120 | K29: 96 | L29: 95 | M29: 73 | N29: 87 | O29: 127 | P29: 124 | Q29: =SUM(E29:P29) -> 1333
D30: JML | E30: 196 | F30: 229 | G30: 226 | H30: 240 | I30: 246 | J30: 234 | K30: 200 | L30: 192 | M30: 149 | N30: 201 | O30: 243 | P30: 236 | Q30: =SUM(E30:P30) -> 2592
A32: II | B32: DATA PENGGUNAAN SURAT SUARA
A33: 1 | B33: Jumlah surat suara yang diterima, termasuk surat suara cadangan 2,5% dari DPT | E33: 292 | F33: 302 | G33: 297 | H33: 303 | I33: 297 | J33: 292 | K33: 251 | L33: 249 | M33: 211 | N33: 264 | O33: 293 | P33: 300 | Q33: =SUM(E33:P33) -> 3351
A34: 2 | B34: Jumlah surat suara yang digunakan | E34: 196 | F34: 229 | G34: 226 | H34: 240 | I34: 246 | J34: 234 | K34: 200 | L34: 192 | M34: 149 | N34: 201 | O34: 243 | P34: 236 | Q34: =SUM(E34:P34) -> 2592
A35: 3 | B35: Jumlah surat suara dikembalikan oleh pemilih (karena rusak atau keliru coblos) | E35: 2 | F35: 0 | G35: 2 | H35: 1 | I35: 0 | J35: 0 | K35: 2 | L35: 0 | M35: 0 | N35: 0 | O35: 0 | P35: 0 | Q35: =SUM(E35:P35) -> 7
A36: 4 | B36: Jumlah surat suara yang tidak digunakan/tidak terpakai, termasuk sisa surat suara cadangan | E36: 94 | F36: 73 | G36: 69 | H36: 62 | I36: 51 | J36: 58 | K36: 49 | L36: 57 | M36: 62 | N36: 63 | O36: 50 | P36: 64 | Q36: =SUM(E36:P36) -> 752
A38: III | B38: DATA PEMILIH DISABILITAS
B39: Jumlah seluruh Pemilih disabilitas yang menggunakan hak pilih | D39: LK | E39: 0 | F39: 0 | G39: 0 | H39: 0 | I39: 0 | J39: 0 | K39: 0 | L39: 0 | M39: 0 | N39: 0 | O39: 0 | P39: 0 | Q39: =SUM(E39:P39) -> 0
D40: PR | E40: 0 | F40: 0 | G40: 0 | H40: 0 | I40: 0 | J40: 0 | K40: 0 | L40: 0 | M40: 0 | N40: 0 | O40: 0 | P40: 0 | Q40: =SUM(E40:P40) -> 0
D41: JML | E41: =SUM(E39:E40) -> 0 | F41: =SUM(F39:F40) -> 0 | G41: =SUM(G39:G40) -> 0 | H41: =SUM(H39:H40) -> 0 | I41: =SUM(I39:I40) -> 0 | J41: =SUM(J39:J40) -> 0 | K41: =SUM(K39:K40) -> 0 | L41: =SUM(L39:L40) -> 0 | ... P41: =SUM(P39:P40) -> 0 | Q41: =SUM(E41:P41) -> 0
A43: IV | B43: DATA RINCIAN PEROLEHAN SUARA PASANGAN CALON BUPATI DAN WAKIL BUPATI
A44: NOMOR DAN NAMA CALON
B45: 1 | C45: H. ANIES RASYID BASWEDAN, Ph.D. - Dr. (H.C.) H. A. MUHAIMIN ISKANDAR | E45: 14 | F45: 20 | G45: 18 | H45: 7 | I45: 21 | J45: 18 | K45: 12 | L45: 8 | M45: 4 | N45: 12 | O45: 13 | P45: 47 | Q45: 11
B46: 2 | C46: H. PRABOWO SUBIANTO - GIBRAN RAKABUMING RAKA | E46: 159 | F46: 175 | G46: 167 | H46: 184 | I46: 184 | J46: 177 | K46: 171 | L46: 158 | M46: 121 | N46: 141 | O46: 186 | P46: 138 | Q46: 105
B47: 3 | C47: H. GANJAR PRANOWO, S.H., M.I.P. - Prof. Dr. H. M. MAHFUD MD | E47: 21 | F47: 32 | G47: 39 | H47: 48 | I47: 39 | J47: 37 | K47: 17 | L47: 24 | M47: 24 | N47: 47 | O47: 40 | P47: 49 | Q47: 32
A49: V | B49: DATA SUARA SAH DAN TIDAK SAH
B50: A. | C50: JUMLAH SELURUH SUARA SAH | E50: =SUM(E45:E47) -> 194 | F50: =SUM(F45:F47) -> 227 | G50: =SUM(G45:G47) -> 224 | H50: =SUM(H45:H47) -> 239 | I50: =SUM(I45:I47) -> 244 | J50: =SUM(J45:J47) -> 232 | K50: =SUM(K45:K47) -> 200 | L50: =SUM(L45:L47) -> 190 | ... P50: =SUM(P45:P47) -> 234 | Q50: =SUM(E50:P50) -> 2572
B51: B. | C51: JUMLAH SUARA TIDAK SAH | E51: 2 | F51: 2 | G51: 2 | H51: 1 | I51: 2 | J51: 2 | K51: 0 | L51: 2 | M51: 0 | N51: 1 | O51: 4 | P51: 2 | Q51: =SUM(E51:P51) -> 20
B52: C. | C52: JUMLAH SELURUH SUARA SAH DAN SUARA TIDAK SAH (V.A + V.B) | E52: =SUM(E50:E51) -> 196 | F52: =SUM(F50:F51) -> 229 | G52: =SUM(G50:G51) -> 226 | H52: =SUM(H50:H51) -> 240 | I52: =SUM(I50:I51) -> 246 | J52: =SUM(J50:J51) -> 234 | K52: =SUM(K50:K51) -> 200 | L52: =SUM(L50:L51) -> 192 | ... P52: =SUM(P50:P51) -> 236 | Q52: =SUM(E52:P52) -> 2592

Sheet PLAMPANGREJO
C2: Kecamatan | D2: CLURING
C3: Kabupaten | D3: BANYUWANGI
C4: Provinsi | D4: JAWA TIMUR
C9: Kelurahan | D9: PLAMPANGREJO
A12: I | B12: DATA PEMILIH DAN PENGGUNAAN HAK PILIH | AE12: JUMLAH AKHIR
A13: A | B13: DATA PEMILIH | E13: TPS 001 | F13: TPS 002 | G13: TPS 003 | H13: TPS 004 | I13: TPS 005 | J13: TPS 006 | K13: TPS 007 | L13: TPS 008 | M13: TPS 009 | N13: TPS 010 | O13: TPS 011 | P13: TPS 012 | Q13: TPS 013 | R13: TPS 014 | S13: TPS 015 | T13: TPS 016 | U13: TPS 017 | V13: TPS 018 | W13: TPS 019 | X13: TPS 020 | Y13: TPS 021 | Z13: TPS 022 | AA13: TPS 023 | AB13: TPS 024 | AC13: TPS 025 | AD13: TPS 026
B14: Jumlah Pemilih dalam Daftar Pemilih Tetap (DPT) | D14: LK | E14: 128 | F14: 141 | G14: 138 | H14: 130 | I14: 137 | J14: 101 | K14: 144 | L14: 119 | M14: 133 | N14: 116 | O14: 121 | P14: 145 | Q14: 148 | R14: 147 | S14: 130 | T14: 136 | U14: 150 | V14: 157 | W14: 148 | X14: 143 | Y14: 152 | Z14: 138 | AA14: 120 | AB14: 109 | AC14: 130 | AD14: 107 | AE14: =SUM(E14:AD14) -> 3468
D15: PR | E15: 130 | F15: 137 | G15: 148 | H15: 121 | I15: 128 | J15: 105 | K15: 140 | L15: 128 | M15: 134 | N15: 125 | O15: 122 | P15: 133 | Q15: 150 | R15: 145 | S15: 134 | T15: 141 | U15: 134 | V15: 141 | W15: 143 | X15: 151 | Y15: 143 | Z15: 150 | AA15: 128 | AB15: 109 | AC15: 139 | AD15: 119 | AE15: =SUM(E15:AD15) -> 3478
D16: JML | E16: =SUM(E14:E15) -> 258 | F16: =SUM(F14:F15) -> 278 | G16: =SUM(G14:G15) -> 286 | H16: =SUM(H14:H15) -> 251 | I16: =SUM(I14:I15) -> 265 | J16: =SUM(J14:J15) -> 206 | K16: =SUM(K14:K15) -> 284 | L16: =SUM(L14:L15) -> 247 | ... AD16: =SUM(AD14:AD15) -> 226 | AE16: =SUM(E16:AD16) -> 6946
A18: B | B18: PENGGUNA HAK PILIH
B19: 1. | C19: Jumlah pengguna hak pilih dalam Daftar Pemilih Tetap (DPT) | D19: LK | E19: 100 | F19: 106 | G19: 117 | H19: 94 | I19: 103 | J19: 80 | K19: 116 | L19: 89 | M19: 90 | N19: 93 | O19: 93 | P19: 109 | Q19: 114 | R19: 118 | S19: 96 | T19: 102 | U19: 106 | V19: 125 | W19: 119 | X19: 113 | Y19: 112 | Z19: 96 | AA19: 91 | AB19: 88 | AC19: 107 | AD19: 84 | AE19: =SUM(E19:AD19) -> 2661
D20: PR | E20: 108 | F20: 106 | G20: 117 | H20: 98 | I20: 105 | J20: 85 | K20: 119 | L20: 107 | M20: 110 | N20: 98 | O20: 100 | P20: 102 | Q20: 126 | R20: 114 | S20: 106 | T20: 106 | U20: 116 | V20: 110 | W20: 113 | X20: 107 | Y20: 101 | Z20: 113 | AA20: 97 | AB20: 87 | AC20: 112 | AD20: 96 | AE20: =SUM(E20:AD20) -> 2759
D21: JML | E21: =SUM(E19:E20) -> 208 | F21: =SUM(F19:F20) -> 212 | G21: =SUM(G19:G20) -> 234 | H21: =SUM(H19:H20) -> 192 | I21: =SUM(I19:I20) -> 208 | J21: =SUM(J19:J20) -> 165 | K21: =SUM(K19:K20) -> 235 | L21: =SUM(L19:L20) -> 196 | ... AD21: =SUM(AD19:AD20) -> 180 | AE21: =SUM(E21:AD21) -> 5420
B22: 2. | C22: Jumlah pengguna hak pilih dalam Daftar Pemilih Tambahan (DPTb) | D22: LK | E22: 0 | F22: 0 | G22: 0 | H22: 0 | I22: 0 | J22: 1 | K22: 1 | L22: 0 | M22: 0 | N22: 0 | O22: 0 | P22: 0 | Q22: 0 | R22: 1 | S22: 1 | T22: 0 | U22: 2 | V22: 0 | W22: 0 | X22: 0 | Y22: 0 | Z22: 0 | AA22: 0 | AB22: 0 | AC22: 0 | AD22: 0 | AE22: =SUM(E22:AD22) -> 6
D23: PR | E23: 0 | F23: 0 | G23: 0 | H23: 0 | I23: 0 | J23: 0 | K23: 1 | L23: 0 | M23: 0 | N23: 1 | O23: 1 | P23: 0 | Q23: 0 | R23: 1 | S23: 0 | T23: 0 | U23: 0 | V23: 1 | W23: 1 | X23: 0 | Y23: 0 | Z23: 0 | AA23: 0 | AB23: 0 | AC23: 0 | AD23: 0 | AE23: =SUM(E23:AD23) -> 6
D24: JML | E24: =SUM(E22:E23) -> 0 | F24: =SUM(F22:F23) -> 0 | G24: =SUM(G22:G23) -> 0 | H24: =SUM(H22:H23) -> 0 | I24: =SUM(I22:I23) -> 0 | J24: =SUM(J22:J23) -> 1 | K24: =SUM(K22:K23) -> 2 | L24: =SUM(L22:L23) -> 0 | ... AD24: =SUM(AD22:AD23) -> 0 | AE24: =SUM(E24:AD24) -> 12
B25: 3. | C25: Jumlah pengguna hak pilih dalam Daftar Pemilih Khusus (DPK) | D25: LK | E25: 1 | F25: 1 | G25: 1 | H25: 0 | I25: 1 | J25: 0 | K25: 0 | L25: 0 | M25: 4 | N25: 1 | O25: 0 | P25: 1 | Q25: 0 | R25: 2 | S25: 2 | T25: 0 | U25: 0 | V25: 0 | W25: 1 | X25: 0 | Y25: 0 | Z25: 2 | AA25: 0 | AB25: 0 | AC25: 1 | AD25: 0 | AE25: =SUM(E25:AD25) -> 18
D26: PR | E26: 1 | F26: 1 | G26: 1 | H26: 0 | I26: 2 | J26: 0 | K26: 0 | L26: 0 | M26: 1 | N26: 0 | O26: 1 | P26: 0 | Q26: 0 | R26: 0 | S26: 4 | T26: 1 | U26: 0 | V26: 1 | W26: 0 | X26: 0 | Y26: 1 | Z26: 2 | AA26: 0 | AB26: 0 | AC26: 0 | AD26: 1 | AE26: 17
D27: JML | E27: =SUM(E25:E26) -> 2 | F27: =SUM(F25:F26) -> 2 | G27: =SUM(G25:G26) -> 2 | H27: =SUM(H25:H26) -> 0 | I27: =SUM(I25:I26) -> 3 | J27: =SUM(J25:J26) -> 0 | K27: =SUM(K25:K26) -> 0 | L27: =SUM(L25:L26) -> 0 | ... AD27: =SUM(AD25:AD26) -> 1 | AE27: =SUM(E27:AD27) -> 35
B28: 4. | C28: Jumlah Pengguna Hak Pilih (B.1+B.2+B.3) | D28: LK | E28: =SUM(E19,E22,E25) -> 101 | F28: =SUM(F19,F22,F25) -> 107 | G28: =SUM(G19,G22,G25) -> 118 | H28: =SUM(H19,H22,H25) -> 94 | I28: =SUM(I19,I22,I25) -> 104 | J28: =SUM(J19,J22,J25) -> 81 | K28: =SUM(K19,K22,K25) -> 117 | L28: =SUM(L19,L22,L25) -> 89 | ... AD28: =SUM(AD19,AD22,AD25) -> 84 | AE28: =SUM(E28:AD28) -> 2685
D29: PR | E29: =SUM(E20,E23,E26) -> 109 | F29: =SUM(F20,F23,F26) -> 107 | G29: =SUM(G20,G23,G26) -> 118 | H29: =SUM(H20,H23,H26) -> 98 | I29: =SUM(I20,I23,I26) -> 107 | J29: =SUM(J20,J23,J26) -> 85 | K29: =SUM(K20,K23,K26) -> 120 | L29: =SUM(L20,L23,L26) -> 107 | ... AD29: =SUM(AD20,AD23,AD26) -> 97 | AE29: =SUM(E29:AD29) -> 2782
D30: JML | E30: =SUM(E28:E29) -> 210 | F30: =SUM(F28:F29) -> 214 | G30: =SUM(G28:G29) -> 236 | H30: =SUM(H28:H29) -> 192 | I30: =SUM(I28:I29) -> 211 | J30: =SUM(J28:J29) -> 166 | K30: =SUM(K28:K29) -> 237 | L30: =SUM(L28:L29) -> 196 | ... AD30: =SUM(AD28:AD29) -> 181 | AE30: =SUM(E30:AD30) -> 5467
A32: II | B32: DATA PENGGUNAAN SURAT SUARA
A33: 1 | B33: Jumlah surat suara yang diterima, termasuk surat suara cadangan 2,5% dari DPT | E33: 265 | F33: 284 | G33: 292 | H33: 259 | I33: 274 | J33: 211 | K33: 290 | L33: 252 | M33: 273 | N33: 246 | O33: 248 | P33: 285 | Q33: 308 | R33: 301 | S33: 272 | T33: 283 | U33: 290 | V33: 304 | W33: 297 | X33: 300 | Y33: 301 | Z33: 294 | AA33: 253 | AB33: 223 | AC33: 275 | AD33: 258 | AE33: =SUM(E33:AD33) -> 7138
A34: 2 | B34: Jumlah surat suara yang digunakan | E34: 210 | F34: 214 | G34: 236 | H34: 192 | I34: 211 | J34: 166 | K34: 237 | L34: 196 | M34: 205 | N34: 193 | O34: 195 | P34: 212 | Q34: 240 | R34: 236 | S34: 209 | T34: 209 | U34: 224 | V34: 237 | W34: 234 | X34: 220 | Y34: 214 | Z34: 213 | AA34: 188 | AB34: 175 | AC34: 220 | AD34: 181 | AE34: =SUM(E34:AD34) -> 5467
A35: 3 | B35: Jumlah surat suara dikembalikan oleh pemilih (karena rusak atau keliru coblos) | E35: 0 | F35: 0 | G35: 0 | H35: 0 | I35: 0 | J35: 0 | K35: 1 | L35: 0 | M35: 1 | N35: 0 | O35: 0 | P35: 0 | Q35: 1 | R35: 0 | S35: 0 | T35: 0 | U35: 0 | V35: 0 | W35: 0 | X35: 0 | Y35: 0 | Z35: 0 | AA35: 0 | AB35: 0 | AC35: 0 | AD35: 0 | AE35: =SUM(E35:AD35) -> 3
A36: 4 | B36: Jumlah surat suara yang tidak digunakan/tidak terpakai, termasuk sisa surat suara cadangan | E36: =E33-(E34+E35) -> 55 | F36: =F33-(F34+F35) -> 70 | G36: =G33-(G34+G35) -> 56 | H36: =H33-(H34+H35) -> 67 | I36: =I33-(I34+I35) -> 63 | J36: =J33-(J34+J35) -> 45 | K36: =K33-(K34+K35) -> 52 | L36: =L33-(L34+L35) -> 56 | ... AD36: =AD33-(AD34+AD35) -> 77 | AE36: =SUM(E36:AD36) -> 1668
A38: III | B38: DATA PEMILIH DISABILITAS
B39: Jumlah seluruh Pemilih disabilitas yang menggunakan hak pilih | D39: LK | E39: 1 | F39: 0 | G39: 0 | H39: 0 | I39: 0 | J39: 0 | K39: 0 | L39: 0 | M39: 0 | N39: 0 | O39: 0 | P39: 0 | Q39: 0 | R39: 0 | S39: 0 | T39: 0 | U39: 0 | V39: 0 | W39: 0 | X39: 0 | Y39: 0 | Z39: 0 | AA39: 0 | AB39: 1 | AC39: 0 | AD39: 0 | AE39: =SUM(E39:AD39) -> 2
D40: PR | E40: 0 | F40: 0 | G40: 0 | H40: 0 | I40: 0 | J40: 0 | K40: 0 | L40: 0 | M40: 0 | N40: 0 | O40: 0 | P40: 0 | Q40: 0 | R40: 0 | S40: 0 | T40: 0 | U40: 0 | V40: 0 | W40: 0 | X40: 0 | Y40: 0 | Z40: 0 | AA40: 0 | AB40: 3 | AC40: 0 | AD40: 0 | AE40: =SUM(E40:AD40) -> 3
D41: JML | E41: =SUM(E39:E40) -> 1 | F41: =SUM(F39:F40) -> 0 | G41: =SUM(G39:G40) -> 0 | H41: =SUM(H39:H40) -> 0 | I41: =SUM(I39:I40) -> 0 | J41: =SUM(J39:J40) -> 0 | K41: =SUM(K39:K40) -> 0 | L41: =SUM(L39:L40) -> 0 | ... AD41: =SUM(AD39:AD40) -> 0 | AE41: =SUM(E41:AD41) -> 5
A43: IV | B43: DATA RINCIAN PEROLEHAN SUARA PASANGAN CALON BUPATI DAN WAKIL BUPATI
A44: NOMOR DAN NAMA CALON
B45: 1 | C45: H. ANIES RASYID BASWEDAN, Ph.D. - Dr. (H.C.) H. A. MUHAIMIN ISKANDAR | E45: 11 | F45: 7 | G45: 18 | H45: 6 | I45: 13 | J45: 6 | K45: 24 | L45: 33 | M45: 49 | N45: 46 | O45: 24 | P45: 9 | Q45: 2 | R45: 21 | S45: 37 | T45: 41 | U45: 46 | V45: 15 | W45: 9 | X45: 6 | Y45: 14 | Z45: 28 | AA45: 47 | AB45: 17 | AC45: 36 | AD45: 31 | AE45: =SUM(E45:AD45) -> 596
B46: 2 | C46: H. PRABOWO SUBIANTO - GIBRAN RAKABUMING RAKA | E46: 121 | F46: 129 | G46: 134 | H46: 132 | I46: 158 | J46: 106 | K46: 161 | L46: 132 | M46: 110 | N46: 109 | O46: 120 | P46: 140 | Q46: 141 | R46: 162 | S46: 115 | T46: 138 | U46: 161 | V46: 187 | W46: 197 | X46: 177 | Y46: 127 | Z46: 150 | AA46: 114 | AB46: 87 | AC46: 143 | AD46: 115 | AE46: =SUM(E46:AD46) -> 3566
B47: 3 | C47: H. GANJAR PRANOWO, S.H., M.I.P. - Prof. Dr. H. M. MAHFUD MD | E47: 78 | F47: 77 | G47: 80 | H47: 54 | I47: 40 | J47: 52 | K47: 52 | L47: 31 | M47: 45 | N47: 37 | O47: 45 | P47: 58 | Q47: 93 | R47: 41 | S47: 52 | T47: 26 | U47: 15 | V47: 31 | W47: 24 | X47: 36 | Y47: 66 | Z47: 34 | AA47: 22 | AB47: 68 | AC47: 40 | AD47: 32 | AE47: =SUM(E47:AD47) -> 1229
A49: V | B49: DATA SUARA SAH DAN TIDAK SAH
B50: A. | C50: JUMLAH SELURUH SUARA SAH | E50: =SUM(E45:E47) -> 210 | F50: =SUM(F45:F47) -> 213 | G50: =SUM(G45:G47) -> 232 | H50: =SUM(H45:H47) -> 192 | I50: =SUM(I45:I47) -> 211 | J50: =SUM(J45:J47) -> 164 | K50: =SUM(K45:K47) -> 237 | L50: =SUM(L45:L47) -> 196 | ... AD50: =SUM(AD45:AD47) -> 178 | AE50: =SUM(E50:AD50) -> 5391
B51: B. | C51: JUMLAH SUARA TIDAK SAH | E51: 0 | F51: 1 | G51: 4 | H51: 0 | I51: 0 | J51: 2 | K51: 0 | L51: 0 | M51: 1 | N51: 1 | O51: 6 | P51: 5 | Q51: 4 | R51: 12 | S51: 5 | T51: 4 | U51: 2 | V51: 4 | W51: 4 | X51: 1 | Y51: 7 | Z51: 1 | AA51: 5 | AB51: 3 | AC51: 1 | AD51: 3 | AE51: =SUM(E51:AD51) -> 76
B52: C. | C52: JUMLAH SELURUH SUARA SAH DAN SUARA TIDAK SAH (V.A + V.B) | E52: =SUM(E50:E51) -> 210 | F52: =SUM(F50:F51) -> 214 | G52: =SUM(G50:G51) -> 236 | H52: =SUM(H50:H51) -> 192 | I52: =SUM(I50:I51) -> 211 | J52: =SUM(J50:J51) -> 166 | K52: =SUM(K50:K51) -> 237 | L52: =SUM(L50:L51) -> 196 | ... AD52: =SUM(AD50:AD51) -> 181 | AE52: =SUM(E52:AD52) -> 5467

Sheet SARIMULYO
C2: Kecamatan | D2: CLURING
C3: Kabupaten | D3: BANYUWANGI
C4: Provinsi | D4: JAWA TIMUR
C9: Kelurahan | D9: SARIMULYO
A12: I | B12: DATA PEMILIH DAN PENGGUNAAN HAK PILIH | AA12: JUMLAH AKHIR
A13: A | B13: DATA PEMILIH | E13: TPS 001 | F13: TPS 002 | G13: TPS 003 | H13: TPS 004 | I13: TPS 005 | J13: TPS 006 | K13: TPS 007 | L13: TPS 008 | M13: TPS 009 | N13: TPS 010 | O13: TPS 011 | P13: TPS 012 | Q13: TPS 013 | R13: TPS 014 | S13: TPS 015 | T13: TPS 016 | U13: TPS 017 | V13: TPS 018 | W13: TPS 019 | X13: TPS 020 | Y13: TPS 021 | Z13: TPS 022
B14: Jumlah Pemilih dalam Daftar Pemilih Tetap (DPT) | D14: LK | E14: 143 | F14: 119 | G14: 113 | H14: 127 | I14: 135 | J14: 129 | K14: 128 | L14: 102 | M14: 122 | N14: 114 | O14: 136 | P14: 113 | Q14: 124 | R14: 135 | S14: 125 | T14: 110 | U14: 115 | V14: 126 | W14: 143 | X14: 155 | Y14: 143 | Z14: 137 | AA14: =SUM(E14:Z14) -> 2794
D15: PR | E15: 125 | F15: 134 | G15: 114 | H15: 133 | I15: 137 | J15: 152 | K15: 136 | L15: 110 | M15: 120 | N15: 117 | O15: 129 | P15: 135 | Q15: 118 | R15: 137 | S15: 122 | T15: 115 | U15: 114 | V15: 139 | W15: 137 | X15: 142 | Y15: 149 | Z15: 132 | AA15: =SUM(E15:Z15) -> 2847
D16: JML | E16: 268 | F16: 253 | G16: 227 | H16: 260 | I16: 272 | J16: 281 | K16: 264 | L16: 212 | M16: 242 | N16: 231 | O16: 265 | P16: 248 | Q16: 242 | R16: 272 | S16: 247 | T16: 225 | U16: 229 | V16: 265 | W16: 280 | X16: 297 | Y16: 292 | Z16: 269 | AA16: =SUM(E16:Z16) -> 5641
A18: B | B18: PENGGUNA HAK PILIH
B19: 1. | C19: Jumlah pengguna hak pilih dalam Daftar Pemilih Tetap (DPT) | D19: LK | E19: 103 | F19: 93 | G19: 79 | H19: 82 | I19: 98 | J19: 95 | K19: 91 | L19: 71 | M19: 92 | N19: 78 | O19: 103 | P19: 94 | Q19: 96 | R19: 96 | S19: 88 | T19: 78 | U19: 94 | V19: 85 | W19: 85 | X19: 119 | Y19: 103 | Z19: 115 | AA19: =SUM(E19:Z19) -> 2038
D20: PR | E20: 104 | F20: 113 | G20: 88 | H20: 106 | I20: 104 | J20: 124 | K20: 107 | L20: 74 | M20: 101 | N20: 84 | O20: 103 | P20: 113 | Q20: 97 | R20: 111 | S20: 94 | T20: 87 | U20: 87 | V20: 118 | W20: 118 | X20: 122 | Y20: 122 | Z20: 113 | AA20: =SUM(E20:Z20) -> 2290
D21: JML | E21: 207 | F21: 206 | G21: 167 | H21: 188 | I21: 202 | J21: 219 | K21: 198 | L21: 145 | M21: 193 | N21: 162 | O21: 206 | P21: 207 | Q21: 193 | R21: 207 | S21: 182 | T21: 165 | U21: 181 | V21: 203 | W21: 203 | X21: 241 | Y21: 225 | Z21: 228 | AA21: =SUM(E21:Z21) -> 4328
B22: 2. | C22: Jumlah pengguna hak pilih dalam Daftar Pemilih Tambahan (DPTb) | D22: LK | E22: 0 | F22: 0 | G22: 0 | H22: 0 | I22: 0 | J22: 0 | K22: 1 | L22: 0 | M22: 1 | N22: 5 | O22: 0 | P22: 0 | Q22: 0 | R22: 0 | S22: 0 | T22: 0 | U22: 0 | V22: 0 | W22: 0 | X22: 1 | Y22: 0 | Z22: 0 | AA22: =SUM(E22:Z22) -> 8
D23: PR | E23: 0 | F23: 0 | G23: 0 | H23: 0 | I23: 0 | J23: 0 | K23: 0 | L23: 0 | M23: 4 | N23: 7 | O23: 0 | P23: 0 | Q23: 0 | R23: 0 | S23: 0 | T23: 0 | U23: 0 | V23: 0 | W23: 0 | X23: 1 | Y23: 0 | Z23: 0 | AA23: =SUM(E23:Z23) -> 12
D24: JML | E24: 0 | F24: 0 | G24: 0 | H24: 0 | I24: 0 | J24: 0 | K24: 1 | L24: 0 | M24: 5 | N24: 12 | O24: 0 | P24: 0 | Q24: 0 | R24: 0 | S24: 0 | T24: 0 | U24: 0 | V24: 0 | W24: 0 | X24: 2 | Y24: 0 | Z24: 0 | AA24: =SUM(E24:Z24) -> 20
B25: 3. | C25: Jumlah pengguna hak pilih dalam Daftar Pemilih Khusus (DPK) | D25: LK | E25: 3 | F25: 1 | G25: 2 | H25: 0 | I25: 2 | J25: 3 | K25: 1 | L25: 1 | M25: 1 | N25: 2 | O25: 0 | P25: 0 | Q25: 2 | R25: 3 | S25: 2 | T25: 0 | U25: 1 | V25: 2 | W25: 2 | X25: 0 | Y25: 0 | Z25: 0 | AA25: =SUM(E25:Z25) -> 28
D26: PR | E26: 2 | F26: 3 | G26: 2 | H26: 1 | I26: 2 | J26: 2 | K26: 0 | L26: 3 | M26: 4 | N26: 3 | O26: 3 | P26: 3 | Q26: 2 | R26: 3 | S26: 4 | T26: 0 | U26: 4 | V26: 2 | W26: 2 | X26: 0 | Y26: 0 | Z26: 0 | AA26: =SUM(E26:Z26) -> 45
D27: JML | E27: 5 | F27: 4 | G27: 4 | H27: 1 | I27: 4 | J27: 5 | K27: 1 | L27: 4 | M27: 5 | N27: 5 | O27: 3 | P27: 3 | Q27: 4 | R27: 6 | S27: 6 | T27: 0 | U27: 5 | V27: 4 | W27: 4 | X27: 0 | Y27: 0 | Z27: 0 | AA27: =SUM(E27:Z27) -> 73
B28: 4. | C28: Jumlah Pengguna Hak Pilih (B.1+B.2+B.3) | D28: LK | E28: 106 | F28: 94 | G28: 81 | H28: 82 | I28: 100 | J28: 98 | K28: 93 | L28: 72 | M28: 94 | N28: 85 | O28: 103 | P28: 94 | Q28: 98 | R28: 99 | S28: 90 | T28: 78 | U28: 95 | V28: 87 | W28: 87 | X28: 120 | Y28: 103 | Z28: 115 | AA28: =SUM(E28:Z28) -> 2074
D29: PR | E29: 106 | F29: 116 | G29: 90 | H29: 107 | I29: 106 | J29: 126 | K29: 107 | L29: 77 | M29: 109 | N29: 94 | O29: 106 | P29: 116 | Q29: 99 | R29: 114 | S29: 98 | T29: 87 | U29: 91 | V29: 120 | W29: 120 | X29: 123 | Y29: 122 | Z29: 113 | AA29: =SUM(E29:Z29) -> 2347
D30: JML | E30: 212 | F30: 210 | G30: 171 | H30: 189 | I30: 206 | J30: 224 | K30: 200 | L30: 149 | M30: 203 | N30: 179 | O30: 209 | P30: 210 | Q30: 197 | R30: 213 | S30: 188 | T30: 165 | U30: 186 | V30: 207 | W30: 207 | X30: 243 | Y30: 225 | Z30: 228 | AA30: =SUM(E30:Z30) -> 4421
A32: II | B32: DATA PENGGUNAAN SURAT SUARA
A33: 1 | B33: Jumlah surat suara yang diterima, termasuk surat suara cadangan 2,5% dari DPT | E33: 274 | F33: 264 | G33: 232 | H33: 267 | I33: 278 | J33: 312 | K33: 270 | L33: 217 | M33: 249 | N33: 238 | O33: 257 | P33: 253 | Q33: 247 | R33: 280 | S33: 252 | T33: 231 | U33: 234 | V33: 270 | W33: 270 | X33: 303 | Y33: 298 | Z33: 275 | AA33: =SUM(E33:Z33) -> 5771
A34: 2 | B34: Jumlah surat suara yang digunakan | E34: 212 | F34: 210 | G34: 171 | H34: 189 | I34: 206 | J34: 224 | K34: 200 | L34: 149 | M34: 203 | N34: 179 | O34: 209 | P34: 210 | Q34: 197 | R34: 213 | S34: 188 | T34: 165 | U34: 186 | V34: 207 | W34: 207 | X34: 243 | Y34: 225 | Z34: 228 | AA34: =SUM(E34:Z34) -> 4421
A35: 3 | B35: Jumlah surat suara dikembalikan oleh pemilih (karena rusak atau keliru coblos) | E35: 0 | F35: 0 | G35: 0 | H35: 0 | I35: 1 | J35: 0 | K35: 0 | L35: 0 | M35: 0 | N35: 0 | O35: 0 | P35: 0 | Q35: 0 | R35: 2 | S35: 0 | T35: 0 | U35: 0 | V35: 2 | W35: 2 | X35: 0 | Y35: 0 | Z35: 0 | AA35: =SUM(E35:Z35) -> 7
A36: 4 | B36: Jumlah surat suara yang tidak digunakan/tidak terpakai, termasuk sisa surat suara cadangan | E36: 62 | F36: 54 | G36: 61 | H36: 78 | I36: 71 | J36: 88 | K36: 70 | L36: 68 | M36: 46 | N36: 59 | O36: 48 | P36: 43 | Q36: 50 | R36: 65 | S36: 64 | T36: 66 | U36: 48 | V36: 61 | W36: 61 | X36: 60 | Y36: 73 | Z36: 47 | AA36: =SUM(E36:Z36) -> 1343
A38: III | B38: DATA PEMILIH DISABILITAS
B39: Jumlah seluruh Pemilih disabilitas yang menggunakan hak pilih | D39: LK | E39: 0 | F39: 0 | G39: 0 | H39: 0 | I39: 0 | J39: 0 | K39: 0 | L39: 0 | M39: 0 | N39: 0 | O39: 0 | P39: 0 | Q39: 0 | R39: 0 | S39: 0 | T39: 0 | U39: 0 | V39: 0 | W39: 0 | X39: 0 | Y39: 0 | Z39: 0 | AA39: =SUM(E39:Z39) -> 0
D40: PR | E40: 0 | F40: 0 | G40: 0 | H40: 0 | I40: 0 | J40: 0 | K40: 0 | L40: 0 | M40: 0 | N40: 0 | O40: 0 | P40: 0 | Q40: 0 | R40: 0 | S40: 0 | T40: 0 | U40: 0 | V40: 0 | W40: 0 | X40: 0 | Y40: 0 | Z40: 0 | AA40: =SUM(E40:Z40) -> 0
D41: JML | E41: =SUM(E39:E40) -> 0 | F41: =SUM(F39:F40) -> 0 | G41: =SUM(G39:G40) -> 0 | H41: =SUM(H39:H40) -> 0 | I41: =SUM(I39:I40) -> 0 | J41: =SUM(J39:J40) -> 0 | K41: =SUM(K39:K40) -> 0 | L41: =SUM(L39:L40) -> 0 | ... Z41: =SUM(Z39:Z40) -> 0 | AA41: =SUM(E41:Z41) -> 0
A43: IV | B43: DATA RINCIAN PEROLEHAN SUARA PASANGAN CALON BUPATI DAN WAKIL BUPATI
A44: NOMOR DAN NAMA CALON
B45: 1 | C45: H. ANIES RASYID BASWEDAN, Ph.D. - Dr. (H.C.) H. A. MUHAIMIN ISKANDAR | E45: 34 | F45: 29 | G45: 25 | H45: 22 | I45: 17 | J45: 24 | K45: 33 | L45: 4 | M45: 14 | N45: 15 | O45: 26 | P45: 19 | Q45: 11 | R45: 12 | S45: 13 | T45: 8 | U45: 28 | V45: 32 | W45: 32 | X45: 24 | Y45: 10 | Z45: 7 | AA45: =SUM(E45:Z45) -> 439
B46: 2 | C46: H. PRABOWO SUBIANTO - GIBRAN RAKABUMING RAKA | E46: 138 | F46: 143 | G46: 122 | H46: 135 | I46: 153 | J46: 162 | K46: 128 | L46: 125 | M46: 164 | N46: 143 | O46: 149 | P46: 150 | Q46: 114 | R46: 144 | S46: 136 | T46: 123 | U46: 109 | V46: 143 | W46: 143 | X46: 162 | Y46: 175 | Z46: 171 | AA46: =SUM(E46:Z46) -> 3132
B47: 3 | C47: H. GANJAR PRANOWO, S.H., M.I.P. - Prof. Dr. H. M. MAHFUD MD | E47: 29 | F47: 34 | G47: 21 | H47: 32 | I47: 31 | J47: 36 | K47: 36 | L47: 17 | M47: 18 | N47: 19 | O47: 25 | P47: 38 | Q47: 68 | R47: 52 | S47: 32 | T47: 33 | U47: 46 | V47: 30 | W47: 30 | X47: 54 | Y47: 35 | Z47: 45 | AA47: =SUM(E47:Z47) -> 761
A49: V | B49: DATA SUARA SAH DAN TIDAK SAH
B50: A. | C50: JUMLAH SELURUH SUARA SAH | E50: =SUM(E45:E47) -> 201 | F50: =SUM(F45:F47) -> 206 | G50: =SUM(G45:G47) -> 168 | H50: =SUM(H45:H47) -> 189 | I50: =SUM(I45:I47) -> 201 | J50: =SUM(J45:J47) -> 222 | K50: =SUM(K45:K47) -> 197 | L50: =SUM(L45:L47) -> 146 | ... Z50: =SUM(Z45:Z47) -> 223 | AA50: =SUM(E50:Z50) -> 4332
B51: B. | C51: JUMLAH SUARA TIDAK SAH | E51: 11 | F51: 4 | G51: 3 | H51: 0 | I51: 5 | J51: 2 | K51: 3 | L51: 3 | M51: 7 | N51: 2 | O51: 9 | P51: 3 | Q51: 4 | R51: 5 | S51: 7 | T51: 1 | U51: 3 | V51: 2 | W51: 2 | X51: 3 | Y51: 5 | Z51: 5 | AA51: =SUM(E51:Z51) -> 89
B52: C. | C52: JUMLAH SELURUH SUARA SAH DAN SUARA TIDAK SAH (V.A + V.B) | E52: =SUM(E50:E51) -> 212 | F52: =SUM(F50:F51) -> 210 | G52: =SUM(G50:G51) -> 171 | H52: =SUM(H50:H51) -> 189 | I52: =SUM(I50:I51) -> 206 | J52: =SUM(J50:J51) -> 224 | K52: =SUM(K50:K51) -> 200 | L52: =SUM(L50:L51) -> 149 | ... Z52: =SUM(Z50:Z51) -> 228 | AA52: =SUM(E52:Z52) -> 4421

Sheet SEMBULUNG
C2: Kecamatan | D2: CLURING
C3: Kabupaten | D3: BANYUWANGI
C4: Provinsi | D4: JAWA TIMUR
C9: Kelurahan | D9: SEMBULUNG
A12: I | B12: DATA PEMILIH DAN PENGGUNAAN HAK PILIH | AC12: JUMLAH AKHIR
A13: A | B13: DATA PEMILIH | E13: TPS 001 | F13: TPS 002 | G13: TPS 003 | H13: TPS 004 | I13: TPS 005 | J13: TPS 006 | K13: TPS 007 | L13: TPS 008 | M13: TPS 009 | N13: TPS 010 | O13: TPS 011 | P13: TPS 012 | Q13: TPS 013 | R13: TPS 014 | S13: TPS 015 | T13: TPS 016 | U13: TPS 017 | V13: TPS 018 | W13: TPS 019 | X13: TPS 020 | Y13: TPS 021 | Z13: TPS 022 | AA13: TPS 023 | AB13: TPS 024
B14: Jumlah Pemilih dalam Daftar Pemilih Tetap (DPT) | D14: LK | E14: 123 | F14: 126 | G14: 140 | H14: 149 | I14: 141 | J14: 133 | K14: 140 | L14: 143 | M14: 128 | N14: 131 | O14: 126 | P14: 120 | Q14: 133 | R14: 139 | S14: 136 | T14: 139 | U14: 134 | V14: 136 | W14: 146 | X14: 127 | Y14: 128 | Z14: 132 | AA14: 133 | AB14: 122 | AC14: =SUM(E14:AB14) -> 3205
D15: PR | E15: 146 | F15: 131 | G15: 129 | H15: 138 | I15: 132 | J15: 144 | K15: 136 | L15: 148 | M15: 127 | N15: 123 | O15: 129 | P15: 117 | Q15: 120 | R15: 153 | S15: 135 | T15: 142 | U15: 130 | V15: 157 | W15: 133 | X15: 162 | Y15: 127 | Z15: 145 | AA15: 124 | AB15: 112 | AC15: =SUM(E15:AB15) -> 3240
D16: JML | E16: =SUM(E14:E15) -> 269 | F16: =SUM(F14:F15) -> 257 | G16: =SUM(G14:G15) -> 269 | H16: =SUM(H14:H15) -> 287 | I16: =SUM(I14:I15) -> 273 | J16: =SUM(J14:J15) -> 277 | K16: =SUM(K14:K15) -> 276 | L16: =SUM(L14:L15) -> 291 | ... AB16: =SUM(AB14:AB15) -> 234 | AC16: =SUM(E16:AB16) -> 6445
A18: B | B18: PENGGUNA HAK PILIH
B19: 1. | C19: Jumlah pengguna hak pilih dalam Daftar Pemilih Tetap (DPT) | D19: LK | E19: 89 | F19: 100 | G19: 104 | H19: 110 | I19: 120 | J19: 101 | K19: 105 | L19: 112 | M19: 104 | N19: 99 | O19: 95 | P19: 92 | Q19: 91 | R19: 106 | S19: 91 | T19: 100 | U19: 102 | V19: 104 | W19: 116 | X19: 106 | Y19: 93 | Z19: 102 | AA19: 101 | AB19: 97 | AC19: =SUM(E19:AB19) -> 2440
D20: PR | E20: 115 | F20: 107 | G20: 103 | H20: 110 | I20: 114 | J20: 116 | K20: 112 | L20: 123 | M20: 110 | N20: 98 | O20: 102 | P20: 93 | Q20: 86 | R20: 121 | S20: 107 | T20: 109 | U20: 106 | V20: 119 | W20: 110 | X20: 133 | Y20: 99 | Z20: 107 | AA20: 110 | AB20: 87 | AC20: =SUM(E20:AB20) -> 2597
D21: JML | E21: =SUM(E19:E20) -> 204 | F21: =SUM(F19:F20) -> 207 | G21: =SUM(G19:G20) -> 207 | H21: =SUM(H19:H20) -> 220 | I21: =SUM(I19:I20) -> 234 | J21: =SUM(J19:J20) -> 217 | K21: =SUM(K19:K20) -> 217 | L21: =SUM(L19:L20) -> 235 | ... AB21: =SUM(AB19:AB20) -> 184 | AC21: =SUM(E21:AB21) -> 5037
B22: 2. | C22: Jumlah pengguna hak pilih dalam Daftar Pemilih Tambahan (DPTb) | D22: LK | E22: 0 | F22: 0 | G22: 0 | H22: 0 | I22: 0 | J22: 0 | K22: 0 | L22: 0 | M22: 0 | N22: 0 | O22: 0 | P22: 0 | Q22: 0 | R22: 0 | S22: 0 | T22: 0 | U22: 0 | V22: 0 | W22: 0 | X22: 0 | Y22: 0 | Z22: 0 | AA22: 0 | AB22: 1 | AC22: =SUM(E22:AB22) -> 1
D23: PR | E23: 0 | F23: 1 | G23: 0 | H23: 0 | I23: 0 | J23: 0 | K23: 0 | L23: 0 | M23: 0 | N23: 0 | O23: 0 | P23: 0 | Q23: 0 | R23: 1 | S23: 0 | T23: 0 | U23: 0 | V23: 0 | W23: 0 | X23: 0 | Y23: 0 | Z23: 0 | AA23: 0 | AB23: 0 | AC23: =SUM(E23:AB23) -> 2
D24: JML | E24: =SUM(E22:E23) -> 0 | F24: =SUM(F22:F23) -> 1 | G24: =SUM(G22:G23) -> 0 | H24: =SUM(H22:H23) -> 0 | I24: =SUM(I22:I23) -> 0 | J24: =SUM(J22:J23) -> 0 | K24: =SUM(K22:K23) -> 0 | L24: =SUM(L22:L23) -> 0 | ... S24: =SUM(S22:S23) -> 0 | T24: 0 | U24: =SUM(U22:U23) -> 0 | V24: =SUM(V22:V23) -> 0 | W24: =SUM(W22:W23) -> 0 | X24: =SUM(X22:X23) -> 0 | Y24: =SUM(Y22:Y23) -> 0 | Z24: =SUM(Z22:Z23) -> 0 | AA24: =SUM(AA22:AA23) -> 0 | AB24: =SUM(AB22:AB23) -> 1 | AC24: =SUM(E24:AB24) -> 3
B25: 3. | C25: Jumlah pengguna hak pilih dalam Daftar Pemilih Khusus (DPK) | D25: LK | E25: 0 | F25: 1 | G25: 1 | H25: 1 | I25: 0 | J25: 0 | K25: 0 | L25: 1 | M25: 0 | N25: 0 | O25: 3 | P25: 1 | Q25: 2 | R25: 3 | S25: 0 | T25: 0 | U25: 0 | V25: 1 | W25: 0 | X25: 0 | Y25: 0 | Z25: 0 | AA25: 1 | AB25: 0 | AC25: =SUM(E25:AB25) -> 15
D26: PR | E26: 0 | F26: 1 | G26: 0 | H26: 1 | I26: 0 | J26: 2 | K26: 0 | L26: 0 | M26: 0 | N26: 0 | O26: 1 | P26: 0 | Q26: 1 | R26: 0 | S26: 0 | T26: 1 | U26: 0 | V26: 0 | W26: 1 | X26: 0 | Y26: 0 | Z26: 1 | AA26: 1 | AB26: 2 | AC26: =SUM(E26:AB26) -> 12
D27: JML | E27: =SUM(E25:E26) -> 0 | F27: =SUM(F25:F26) -> 2 | G27: =SUM(G25:G26) -> 1 | H27: =SUM(H25:H26) -> 2 | I27: =SUM(I25:I26) -> 0 | J27: =SUM(J25:J26) -> 2 | K27: =SUM(K25:K26) -> 0 | L27: =SUM(L25:L26) -> 1 | ... AB27: =SUM(AB25:AB26) -> 2 | AC27: =SUM(E27:AB27) -> 27
