Workbook

Sheet PPWP
C8: Kecamatan | D8: SEMPU
C9: Kabupaten | D9: BANYUWANGI
C10: Provinsi | D10: JAWA TIMUR
A12: I | B12: DATA PEMILIH DAN PENGGUNAAN HAK PILIH | E12: JUMLAH AKHIR
A13: A | B13: DATA PEMILIH
B14: Jumlah Pemilih dalam Daftar Pemilih Tetap (DPT) | D14: LK | E14: =GENDOH!AG14+JAMBEWANGI!BR14+KARANGSARI!AX14+SEMPU!Y14+TEGALARUM!AA14+TEMUASRI!AJ14+TEMUGURUH!AL14 -> 32583
D15: PR | E15: =GENDOH!AG15+JAMBEWANGI!BR15+KARANGSARI!AX15+SEMPU!Y15+TEGALARUM!AA15+TEMUASRI!AJ15+TEMUGURUH!AL15 -> 32633
D16: JML | E16: =SUM(E14:E15) -> 65216
A18: B | B18: PENGGUNA HAK PILIH
B19: 1. | C19: Jumlah pengguna hak pilih dalam Daftar Pemilih Tetap (DPT) | D19: LK | E19: =GENDOH!AG19+JAMBEWANGI!BR19+KARANGSARI!AX19+SEMPU!Y19+TEGALARUM!AA19+TEMUASRI!AJ19+TEMUGURUH!AL19 -> 23335
D20: PR | E20: =GENDOH!AG20+JAMBEWANGI!BR20+KARANGSARI!AX20+SEMPU!Y20+TEGALARUM!AA20+TEMUASRI!AJ20+TEMUGURUH!AL20 -> 25100
D21: JML | E21: =SUM(E19:E20) -> 48435
B22: 2. | C22: Jumlah pengguna hak pilih dalam Daftar Pemilih Tambahan (DPTb) | D22: LK | E22: =GENDOH!AG22+JAMBEWANGI!BR22+KARANGSARI!AX22+SEMPU!Y22+TEGALARUM!AA22+TEMUASRI!AJ22+TEMUGURUH!AL22 -> 66
D23: PR | E23: =GENDOH!AG23+JAMBEWANGI!BR23+KARANGSARI!AX23+SEMPU!Y23+TEGALARUM!AA23+TEMUASRI!AJ23+TEMUGURUH!AL23 -> 68
D24: JML | E24: =SUM(E22:E23) -> 134
B25: 3. | C25: Jumlah pengguna hak pilih dalam Daftar Pemilih Khusus (DPK) | D25: LK | E25: =GENDOH!AG25+JAMBEWANGI!BR25+KARANGSARI!AX25+SEMPU!Y25+TEGALARUM!AA25+TEMUASRI!AJ25+TEMUGURUH!AL25 -> 208
D26: PR | E26: =GENDOH!AG26+JAMBEWANGI!BR26+KARANGSARI!AX26+SEMPU!Y26+TEGALARUM!AA26+TEMUASRI!AJ26+TEMUGURUH!AL26 -> 282
D27: JML | E27: =SUM(E25:E26) -> 490
B28: 4. | C28: Jumlah Pengguna Hak Pilih (B.1+B.2+B.3) | D28: LK | E28: =E19+E22+E25 -> 23609
D29: PR | E29: =E20+E23+E26 -> 25450
D30: JML | E30: =SUM(E28:E29) -> 49059
A32: II | B32: DATA PENGGUNAAN SURAT SUARA
A33: 1 | B33: Jumlah surat suara yang diterima, termasuk surat suara cadangan 2,5% dari DPT | E33: =GENDOH!AG33+JAMBEWANGI!BR33+KARANGSARI!AX33+SEMPU!Y33+TEGALARUM!AA33+TEMUASRI!AJ33+TEMUGURUH!AL33 -> 66395
A34: 2 | B34: Jumlah surat suara yang digunakan | E34: =GENDOH!AG34+JAMBEWANGI!BR34+KARANGSARI!AX34+SEMPU!Y34+TEGALARUM!AA34+TEMUASRI!AJ34+TEMUGURUH!AL34 -> 49059
A35: 3 | B35: Jumlah surat suara dikembalikan oleh pemilih (karena rusak atau keliru coblos) | E35: =GENDOH!AG35+JAMBEWANGI!BR35+KARANGSARI!AX35+SEMPU!Y35+TEGALARUM!AA35+TEMUASRI!AJ35+TEMUGURUH!AL35 -> 186
A36: 4 | B36: Jumlah surat suara yang tidak digunakan/tidak terpakai, termasuk sisa surat suara cadangan | E36: =E33-(E34+E35) -> 17150
A38: III | B38: DATA PEMILIH DISABILITAS
B39: Jumlah seluruh Pemilih disabilitas yang menggunakan hak pilih | D39: LK | E39: =GENDOH!AG39+JAMBEWANGI!BR39+KARANGSARI!AX39+SEMPU!Y39+TEGALARUM!AA39+TEMUASRI!AJ39+TEMUGURUH!AL39 -> 50
D40: PR | E40: =GENDOH!AG40+JAMBEWANGI!BR40+KARANGSARI!AX40+SEMPU!Y40+TEGALARUM!AA40+TEMUASRI!AJ40+TEMUGURUH!AL40 -> 75
D41: JML | E41: =SUM(E39:E40) -> 125
A43: IV | B43: DATA RINCIAN PEROLEHAN SUARA PASANGAN CALON BUPATI DAN WAKIL BUPATI
A44: NOMOR DAN NAMA CALON
B45: 1 | C45: H. ANIES RASYID BASWEDAN, Ph.D. - Dr. (H.C.) H. A. MUHAIMIN ISKANDAR | E45: =GENDOH!AG45+JAMBEWANGI!BR45+KARANGSARI!AX45+SEMPU!Y45+TEGALARUM!AA45+TEMUASRI!AJ45+TEMUGURUH!AL45 -> 5073
B46: 2 | C46: H. PRABOWO SUBIANTO - GIBRAN RAKABUMING RAKA | E46: =GENDOH!AG46+JAMBEWANGI!BR46+KARANGSARI!AX46+SEMPU!Y46+TEGALARUM!AA46+TEMUASRI!AJ46+TEMUGURUH!AL46 -> 33416
B47: 3 | C47: H. GANJAR PRANOWO, S.H., M.I.P. - Prof. Dr. H. M. MAHFUD MD | E47: =GENDOH!AG47+JAMBEWANGI!BR47+KARANGSARI!AX47+SEMPU!Y47+TEGALARUM!AA47+TEMUASRI!AJ47+TEMUGURUH!AL47 -> 9515
A49: V | B49: DATA SUARA SAH DAN TIDAK SAH
B50: A. | C50: JUMLAH SELURUH SUARA SAH | E50: =GENDOH!AG50+JAMBEWANGI!BR50+KARANGSARI!AX50+SEMPU!Y50+TEGALARUM!AA50+TEMUASRI!AJ50+TEMUGURUH!AL50 -> 48004
B51: B. | C51: JUMLAH SUARA TIDAK SAH | E51: =GENDOH!AG51+JAMBEWANGI!BR51+KARANGSARI!AX51+SEMPU!Y51+TEGALARUM!AA51+TEMUASRI!AJ51+TEMUGURUH!AL51 -> 1055
B52: C. | C52: JUMLAH SELURUH SUARA SAH DAN SUARA TIDAK SAH (V.A + V.B) | E52: =SUM(E50:E51) -> 49059

Sheet SEMPU
C2: Kecamatan | D2: SEMPU
C3: Kabupaten | D3: BANYUWANGI
C4: Provinsi | D4: JAWA TIMUR
C9: Kelurahan | D9: SEMPU
A12: I | B12: DATA PEMILIH DAN PENGGUNAAN HAK PILIH | Y12: JUMLAH AKHIR
A13: A | B13: DATA PEMILIH | E13: TPS 001 | F13: TPS 002 | G13: TPS 003 | H13: TPS 004 | I13: TPS 005 | J13: TPS 006 | K13: TPS 007 | L13: TPS 008 | M13: TPS 009 | N13: TPS 010 | O13: TPS 011 | P13: TPS 012 | Q13: TPS 013 | R13: TPS 014 | S13: TPS 015 | T13: TPS 016 | U13: TPS 017 | V13: TPS 018 | W13: TPS 019 | X13: TPS 020
B14: Jumlah Pemilih dalam Daftar Pemilih Tetap (DPT) | D14: LK | E14: 131 | F14: 133 | G14: 87 | H14: 116 | I14: 126 | J14: 145 | K14: 80 | L14: 103 | M14: 142 | N14: 129 | O14: 151 | P14: 129 | Q14: 136 | R14: 109 | S14: 132 | T14: 141 | U14: 134 | V14: 99 | W14: 108 | X14: 79 | Y14: =SUM(E14:X14) -> 2410
D15: PR | E15: 140 | F15: 146 | G15: 106 | H15: 107 | I15: 133 | J15: 145 | K15: 104 | L15: 99 | M15: 135 | N15: 146 | O15: 135 | P15: 148 | Q15: 149 | R15: 120 | S15: 143 | T15: 142 | U15: 129 | V15: 112 | W15: 133 | X15: 71 | Y15: =SUM(E15:X15) -> 2543
D16: JML | E16: =SUM(E14:E15) -> 271 | F16: =SUM(F14:F15) -> 279 | G16: =SUM(G14:G15) -> 193 | H16: =SUM(H14:H15) -> 223 | I16: =SUM(I14:I15) -> 259 | J16: =SUM(J14:J15) -> 290 | K16: =SUM(K14:K15) -> 184 | L16: =SUM(L14:L15) -> 202 | ... X16: =SUM(X14:X15) -> 150 | Y16: =SUM(E16:X16) -> 4953
A18: B | B18: PENGGUNA HAK PILIH
B19: 1. | C19: Jumlah pengguna hak pilih dalam Daftar Pemilih Tetap (DPT) | D19: LK | E19: 108 | F19: 92 | G19: 68 | H19: 84 | I19: 96 | J19: 100 | K19: 55 | L19: 86 | M19: 112 | N19: 96 | O19: 113 | P19: 97 | Q19: 99 | R19: 85 | S19: 95 | T19: 99 | U19: 103 | V19: 76 | W19: 77 | X19: 62 | Y19: =SUM(E19:X19) -> 1803
D20: PR | E20: 106 | F20: 114 | G20: 86 | H20: 86 | I20: 101 | J20: 114 | K20: 77 | L20: 82 | M20: 112 | N20: 112 | O20: 109 | P20: 127 | Q20: 116 | R20: 91 | S20: 117 | T20: 108 | U20: 109 | V20: 92 | W20: 107 | X20: 62 | Y20: =SUM(E20:X20) -> 2028
D21: JML | E21: =SUM(E19:E20) -> 214 | F21: =SUM(F19:F20) -> 206 | G21: =SUM(G19:G20) -> 154 | H21: =SUM(H19:H20) -> 170 | I21: =SUM(I19:I20) -> 197 | J21: =SUM(J19:J20) -> 214 | K21: =SUM(K19:K20) -> 132 | L21: =SUM(L19:L20) -> 168 | ... X21: =SUM(X19:X20) -> 124 | Y21: =SUM(E21:X21) -> 3831
B22: 2. | C22: Jumlah pengguna hak pilih dalam Daftar Pemilih Tambahan (DPTb) | D22: LK | E22: 0 | F22: 0 | G22: 0 | H22: 0 | I22: 0 | J22: 0 | K22: 1 | L22: 0 | M22: 0 | N22: 0 | O22: 0 | P22: 0 | Q22: 0 | R22: 2 | S22: 0 | T22: 0 | U22: 0 | V22: 0 | W22: 0 | X22: 0 | Y22: =SUM(E22:X22) -> 3
D23: PR | E23: 0 | F23: 0 | G23: 0 | H23: 0 | I23: 0 | J23: 0 | K23: 4 | L23: 0 | M23: 0 | N23: 0 | O23: 0 | P23: 0 | Q23: 0 | R23: 1 | S23: 0 | T23: 0 | U23: 0 | V23: 0 | W23: 0 | X23: 0 | Y23: =SUM(E23:X23) -> 5
D24: JML | E24: =SUM(E22:E23) -> 0 | F24: =SUM(F22:F23) -> 0 | G24: =SUM(G22:G23) -> 0 | H24: =SUM(H22:H23) -> 0 | I24: =SUM(I22:I23) -> 0 | J24: =SUM(J22:J23) -> 0 | K24: =SUM(K22:K23) -> 5 | L24: =SUM(L22:L23) -> 0 | ... X24: =SUM(X22:X23) -> 0 | Y24: =SUM(E24:X24) -> 8
B25: 3. | C25: Jumlah pengguna hak pilih dalam Daftar Pemilih Khusus (DPK) | D25: LK | E25: 2 | F25: 1 | G25: 0 | H25: 3 | I25: 1 | J25: 1 | K25: 1 | L25: 1 | M25: 2 | N25: 0 | O25: 0 | P25: 1 | Q25: 1 | R25: 3 | S25: 2 | T25: 0 | U25: 10 | V25: 1 | W25: 0 | X25: 1 | Y25: =SUM(E25:X25) -> 31
D26: PR | E26: 1 | F26: 5 | G26: 0 | H26: 4 | I26: 1 | J26: 3 | K26: 0 | L26: 1 | M26: 4 | N26: 0 | O26: 0 | P26: 1 | Q26: 1 | R26: 1 | S26: 4 | T26: 1 | U26: 6 | V26: 5 | W26: 1 | X26: 1 | Y26: =SUM(E26:X26) -> 40
D27: JML | E27: =SUM(E25:E26) -> 3 | F27: =SUM(F25:F26) -> 6 | G27: =SUM(G25:G26) -> 0 | H27: =SUM(H25:H26) -> 7 | I27: =SUM(I25:I26) -> 2 | J27: =SUM(J25:J26) -> 4 | K27: =SUM(K25:K26) -> 1 | L27: =SUM(L25:L26) -> 2 | ... X27: =SUM(X25:X26) -> 2 | Y27: =SUM(E27:X27) -> 71
B28: 4. | C28: Jumlah Pengguna Hak Pilih (B.1+B.2+B.3) | D28: LK | E28: =SUM(E19,E22,E25) -> 110 | F28: =SUM(F19,F22,F25) -> 93 | G28: =SUM(G19,G22,G25) -> 68 | H28: =SUM(H19,H22,H25) -> 87 | I28: =SUM(I19,I22,I25) -> 97 | J28: =SUM(J19,J22,J25) -> 101 | K28: =SUM(K19,K22,K25) -> 57 | L28: =SUM(L19,L22,L25) -> 87 | ... X28: =SUM(X19,X22,X25) -> 63 | Y28: =SUM(E28:X28) -> 1837
D29: PR | E29: =SUM(E20,E23,E26) -> 107 | F29: =SUM(F20,F23,F26) -> 119 | G29: =SUM(G20,G23,G26) -> 86 | H29: =SUM(H20,H23,H26) -> 90 | I29: =SUM(I20,I23,I26) -> 102 | J29: =SUM(J20,J23,J26) -> 117 | K29: =SUM(K20,K23,K26) -> 81 | L29: =SUM(L20,L23,L26) -> 83 | ... X29: =SUM(X20,X23,X26) -> 63 | Y29: =SUM(E29:X29) -> 2073
D30: JML | E30: =SUM(E28:E29) -> 217 | F30: =SUM(F28:F29) -> 212 | G30: =SUM(G28:G29) -> 154 | H30: =SUM(H28:H29) -> 177 | I30: =SUM(I28:I29) -> 199 | J30: =SUM(J28:J29) -> 218 | K30: =SUM(K28:K29) -> 138 | L30: =SUM(L28:L29) -> 170 | ... X30: =SUM(X28:X29) -> 126 | Y30: =SUM(E30:X30) -> 3910
A32: II | B32: DATA PENGGUNAAN SURAT SUARA
A33: 1 | B33: Jumlah surat suara yang diterima, termasuk surat suara cadangan 2,5% dari DPT | E33: 278 | F33: 287 | G33: 203 | H33: 227 | I33: 265 | J33: 299 | K33: 192 | L33: 207 | M33: 283 | N33: 287 | O33: 295 | P33: 281 | Q33: 291 | R33: 234 | S33: 281 | T33: 289 | U33: 269 | V33: 218 | W33: 246 | X33: 153 | Y33: =SUM(E33:X33) -> 5085
A34: 2 | B34: Jumlah surat suara yang digunakan | E34: 217 | F34: 212 | G34: 154 | H34: 177 | I34: 199 | J34: 218 | K34: 138 | L34: 170 | M34: 230 | N34: 208 | O34: 222 | P34: 226 | Q34: 217 | R34: 183 | S34: 218 | T34: 208 | U34: 228 | V34: 174 | W34: 185 | X34: 126 | Y34: =SUM(E34:X34) -> 3910
A35: 3 | B35: Jumlah surat suara dikembalikan oleh pemilih (karena rusak atau keliru coblos) | E35: 0 | F35: 0 | G35: 0 | H35: 0 | I35: 0 | J35: 0 | K35: 0 | L35: 0 | M35: 0 | N35: 0 | O35: 0 | P35: 0 | Q35: 0 | R35: 0 | S35: 0 | T35: 4 | U35: 0 | V35: 0 | W35: 0 | X35: 0 | Y35: =SUM(E35:X35) -> 4
A36: 4 | B36: Jumlah surat suara yang tidak digunakan/tidak terpakai, termasuk sisa surat suara cadangan | E36: =E33-(E34+E35) -> 61 | F36: =F33-(F34+F35) -> 75 | G36: =G33-(G34+G35) -> 49 | H36: =H33-(H34+H35) -> 50 | I36: =I33-(I34+I35) -> 66 | J36: =J33-(J34+J35) -> 81 | K36: =K33-(K34+K35) -> 54 | L36: =L33-(L34+L35) -> 37 | ... X36: =X33-(X34+X35) -> 27 | Y36: =SUM(E36:X36) -> 1171
A38: III | B38: DATA PEMILIH DISABILITAS
B39: Jumlah seluruh Pemilih disabilitas yang menggunakan hak pilih | D39: LK | E39: 0 | F39: 1 | G39: 0 | H39: 1 | I39: 0 | J39: 0 | K39: 0 | L39: 0 | M39: 0 | N39: 0 | O39: 0 | P39: 1 | Q39: 0 | R39: 0 | S39: 0 | T39: 0 | U39: 0 | V39: 0 | W39: 0 | X39: 2 | Y39: =SUM(E39:X39) -> 5
D40: PR | E40: 0 | F40: 0 | G40: 0 | H40: 1 | I40: 0 | J40: 0 | K40: 0 | L40: 2 | M40: 0 | N40: 0 | O40: 0 | P40: 0 | Q40: 0 | R40: 0 | S40: 0 | T40: 0 | U40: 0 | V40: 0 | W40: 2 | X40: 0 | Y40: =SUM(E40:X40) -> 5
D41: JML | E41: =SUM(E39:E40) -> 0 | F41: =SUM(F39:F40) -> 1 | G41: =SUM(G39:G40) -> 0 | H41: =SUM(H39:H40) -> 2 | I41: =SUM(I39:I40) -> 0 | J41: =SUM(J39:J40) -> 0 | K41: =SUM(K39:K40) -> 0 | L41: =SUM(L39:L40) -> 2 | ... X41: =SUM(X39:X40) -> 2 | Y41: =SUM(E41:X41) -> 10
A43: IV | B43: DATA RINCIAN PEROLEHAN SUARA PASANGAN CALON BUPATI DAN WAKIL BUPATI
A44: NOMOR DAN NAMA CALON
B45: 1 | C45: H. ANIES RASYID BASWEDAN, Ph.D. - Dr. (H.C.) H. A. MUHAIMIN ISKANDAR | E45: 29 | F45: 34 | G45: 21 | H45: 34 | I45: 21 | J45: 45 | K45: 13 | L45: 29 | M45: 36 | N45: 12 | O45: 5 | P45: 79 | Q45: 39 | R45: 25 | S45: 27 | T45: 11 | U45: 28 | V45: 21 | W45: 16 | X45: 9 | Y45: =SUM(E45:X45) -> 534
B46: 2 | C46: H. PRABOWO SUBIANTO - GIBRAN RAKABUMING RAKA | E46: 159 | F46: 140 | G46: 105 | H46: 98 | I46: 135 | J46: 108 | K46: 82 | L46: 93 | M46: 139 | N46: 151 | O46: 172 | P46: 120 | Q46: 132 | R46: 119 | S46: 157 | T46: 147 | U46: 164 | V46: 136 | W46: 135 | X46: 93 | Y46: =SUM(E46:X46) -> 2585
B47: 3 | C47: H. GANJAR PRANOWO, S.H., M.I.P. - Prof. Dr. H. M. MAHFUD MD | E47: 26 | F47: 34 | G47: 28 | H47: 41 | I47: 41 | J47: 63 | K47: 39 | L47: 45 | M47: 50 | N47: 42 | O47: 38 | P47: 26 | Q47: 45 | R47: 33 | S47: 30 | T47: 43 | U47: 30 | V47: 15 | W47: 27 | X47: 22 | Y47: =SUM(E47:X47) -> 718
A49: V | B49: DATA SUARA SAH DAN TIDAK SAH
B50: A. | C50: JUMLAH SELURUH SUARA SAH | E50: =SUM(E45:E47) -> 214 | F50: =SUM(F45:F47) -> 208 | G50: =SUM(G45:G47) -> 154 | H50: =SUM(H45:H47) -> 173 | I50: =SUM(I45:I47) -> 197 | J50: =SUM(J45:J47) -> 216 | K50: =SUM(K45:K47) -> 134 | L50: =SUM(L45:L47) -> 167 | ... X50: =SUM(X45:X47) -> 124 | Y50: =SUM(E50:X50) -> 3837
B51: B. | C51: JUMLAH SUARA TIDAK SAH | E51: 3 | F51: 4 | G51: 0 | H51: 4 | I51: 2 | J51: 2 | K51: 4 | L51: 3 | M51: 5 | N51: 3 | O51: 7 | P51: 1 | Q51: 1 | R51: 6 | S51: 4 | T51: 7 | U51: 6 | V51: 2 | W51: 7 | X51: 2 | Y51: =SUM(E51:X51) -> 73
B52: C. | C52: JUMLAH SELURUH SUARA SAH DAN SUARA TIDAK SAH (V.A + V.B) | E52: =SUM(E50:E51) -> 217 | F52: =SUM(F50:F51) -> 212 | G52: =SUM(G50:G51) -> 154 | H52: =SUM(H50:H51) -> 177 | I52: =SUM(I50:I51) -> 199 | J52: =SUM(J50:J51) -> 218 | K52: =SUM(K50:K51) -> 138 | L52: =SUM(L50:L51) -> 170 | ... X52: =SUM(X50:X51) -> 126 | Y52: =SUM(E52:X52) -> 3910

Sheet JAMBEWANGI
C2: Kecamatan | D2: SEMPU
C3: Kabupaten | D3: BANYUWANGI
C4: Provinsi | D4: JAWA TIMUR
C9: Kelurahan | D9: JAMBEWANGI
A12: I | B12: DATA PEMILIH DAN PENGGUNAAN HAK PILIH | BR12: JUMLAH AKHIR
A13: A | B13: DATA PEMILIH | E13: TPS 001 | F13: TPS 002 | G13: TPS 003 | H13: TPS 004 | I13: TPS 005 | J13: TPS 006 | K13: TPS 007 | L13: TPS 008 | M13: TPS 009 | N13: TPS 010 | O13: TPS 011 | P13: TPS 012 | Q13: TPS 013 | R13: TPS 014 | S13: TPS 015 | T13: TPS 016 | U13: TPS 017 | V13: TPS 018 | W13: TPS 019 | X13: TPS 020 | Y13: TPS 021 | Z13: TPS 022 | AA13: TPS 023 | AB13: TPS 024 | AC13: TPS 025 | AD13: TPS 026 | AE13: TPS 027 | AF13: TPS 028 | AG13: TPS 029 | AH13: TPS 030 | AI13: TPS 031 | AJ13: TPS 032 | AK13: TPS 033 | AL13: TPS 034 | AM13: TPS 035 | AN13: TPS 036 | AO13: TPS 037 | AP13: TPS 038 | AQ13: TPS 039 | AR13: TPS 040 | AS13: TPS 041 | AT13: TPS 042 | AU13: TPS 043 | AV13: TPS 044 | AW13: TPS 045 | AX13: TPS 046 | AY13: TPS 047 | AZ13: TPS 048 | BA13: TPS 049 | BB13: TPS 050 | BC13: TPS 051 | BD13: TPS 052 | BE13: TPS 053 | BF13: TPS 054 | BG13: TPS 055 | BH13: TPS 056 | BI13: TPS 057 | BJ13: TPS 058 | BK13: TPS 059 | BL13: TPS 060 | BM13: TPS 061 | BN13: TPS 062 | BO13: TPS 063 | BP13: TPS 064 | BQ13: TPS 065
B14: Jumlah Pemilih dalam Daftar Pemilih Tetap (DPT) | D14: LK | E14: 121 | F14: 122 | G14: 102 | H14: 136 | I14: 143 | J14: 138 | K14: 140 | L14: 114 | M14: 153 | N14: 150 | O14: 146 | P14: 146 | Q14: 136 | R14: 131 | S14: 140 | T14: 142 | U14: 139 | V14: 147 | W14: 140 | X14: 143 | Y14: 143 | Z14: 162 | AA14: 144 | AB14: 145 | AC14: 155 | AD14: 149 | AE14: 157 | AF14: 146 | AG14: 138 | AH14: 145 | AI14: 145 | AJ14: 144 | AK14: 143 | AL14: 133 | AM14: 122 | AN14: 160 | AO14: 153 | AP14: 139 | AQ14: 136 | AR14: 105 | AS14: 115 | AT14: 112 | AU14: 147 | AV14: 126 | AW14: 120 | AX14: 142 | AY14: 144 | AZ14: 140 | BA14: 137 | BB14: 94 | BC14: 108 | BD14: 146 | BE14: 110 | BF14: 132 | BG14: 146 | BH14: 122 | BI14: 126 | BJ14: 140 | BK14: 124 | BL14: 153 | BM14: 132 | BN14: 149 | BO14: 142 | BP14: 146 | BQ14: 133 | BR14: =SUM(E14:BQ14) -> 8879
D15: PR | E15: 118 | F15: 102 | G15: 97 | H15: 144 | I15: 136 | J15: 129 | K15: 142 | L15: 135 | M15: 137 | N15: 144 | O15: 147 | P15: 147 | Q15: 154 | R15: 143 | S15: 141 | T15: 151 | U15: 141 | V15: 132 | W15: 137 | X15: 128 | Y15: 146 | Z15: 136 | AA15: 145 | AB15: 143 | AC15: 136 | AD15: 147 | AE15: 139 | AF15: 149 | AG15: 138 | AH15: 143 | AI15: 139 | AJ15: 147 | AK15: 143 | AL15: 107 | AM15: 121 | AN15: 136 | AO15: 141 | AP15: 143 | AQ15: 142 | AR15: 122 | AS15: 133 | AT15: 103 | AU15: 126 | AV15: 120 | AW15: 132 | AX15: 149 | AY15: 143 | AZ15: 129 | BA15: 145 | BB15: 96 | BC15: 96 | BD15: 143 | BE15: 119 | BF15: 150 | BG15: 131 | BH15: 123 | BI15: 115 | BJ15: 137 | BK15: 132 | BL15: 144 | BM15: 125 | BN15: 141 | BO15: 143 | BP15: 139 | BQ15: 133 | BR15: =SUM(E15:BQ15) -> 8715
D16: JML | E16: =SUM(E14:E15) -> 239 | F16: =SUM(F14:F15) -> 224 | G16: =SUM(G14:G15) -> 199 | H16: =SUM(H14:H15) -> 280 | I16: =SUM(I14:I15) -> 279 | J16: =SUM(J14:J15) -> 267 | K16: =SUM(K14:K15) -> 282 | L16: =SUM(L14:L15) -> 249 | ... BQ16: =SUM(BQ14:BQ15) -> 266 | BR16: =SUM(E16:BQ16) -> 17594
A18: B | B18: PENGGUNA HAK PILIH
B19: 1. | C19: Jumlah pengguna hak pilih dalam Daftar Pemilih Tetap (DPT) | D19: LK | E19: 78 | F19: 85 | G19: 77 | H19: 90 | I19: 103 | J19: 117 | K19: 100 | L19: 82 | M19: 95 | N19: 106 | O19: 94 | P19: 103 | Q19: 88 | R19: 81 | S19: 97 | T19: 86 | U19: 100 | V19: 94 | W19: 84 | X19: 94 | Y19: 109 | Z19: 113 | AA19: 98 | AB19: 104 | AC19: 120 | AD19: 109 | AE19: 113 | AF19: 99 | AG19: 93 | AH19: 95 | AI19: 98 | AJ19: 111 | AK19: 107 | AL19: 104 | AM19: 95 | AN19: 120 | AO19: 118 | AP19: 98 | AQ19: 101 | AR19: 87 | AS19: 87 | AT19: 84 | AU19: 122 | AV19: 80 | AW19: 86 | AX19: 101 | AY19: 94 | AZ19: 98 | BA19: 105 | BB19: 62 | BC19: 81 | BD19: 104 | BE19: 82 | BF19: 101 | BG19: 122 | BH19: 95 | BI19: 101 | BJ19: 112 | BK19: 101 | BL19: 113 | BM19: 96 | BN19: 107 | BO19: 105 | BP19: 115 | BQ19: 109 | BR19: =SUM(E19:BQ19) -> 6409
D20: PR | E20: 93 | F20: 72 | G20: 76 | H20: 107 | I20: 104 | J20: 112 | K20: 112 | L20: 109 | M20: 110 | N20: 122 | O20: 108 | P20: 115 | Q20: 120 | R20: 118 | S20: 108 | T20: 104 | U20: 108 | V20: 96 | W20: 103 | X20: 92 | Y20: 111 | Z20: 107 | AA20: 110 | AB20: 100 | AC20: 115 | AD20: 115 | AE20: 102 | AF20: 122 | AG20: 98 | AH20: 105 | AI20: 102 | AJ20: 116 | AK20: 111 | AL20: 93 | AM20: 98 | AN20: 101 | AO20: 118 | AP20: 121 | AQ20: 110 | AR20: 105 | AS20: 110 | AT20: 83 | AU20: 111 | AV20: 98 | AW20: 102 | AX20: 115 | AY20: 106 | AZ20: 99 | BA20: 109 | BB20: 66 | BC20: 86 | BD20: 119 | BE20: 101 | BF20: 122 | BG20: 108 | BH20: 103 | BI20: 98 | BJ20: 108 | BK20: 103 | BL20: 110 | BM20: 89 | BN20: 121 | BO20: 107 | BP20: 113 | BQ20: 115 | BR20: =SUM(E20:BQ20) -> 6851
D21: JML | E21: =SUM(E19:E20) -> 171 | F21: =SUM(F19:F20) -> 157 | G21: =SUM(G19:G20) -> 153 | H21: =SUM(H19:H20) -> 197 | I21: =SUM(I19:I20) -> 207 | J21: =SUM(J19:J20) -> 229 | K21: =SUM(K19:K20) -> 212 | L21: =SUM(L19:L20) -> 191 | ... BQ21: =SUM(BQ19:BQ20) -> 224 | BR21: =SUM(E21:BQ21) -> 13260
B22: 2. | C22: Jumlah pengguna hak pilih dalam Daftar Pemilih Tambahan (DPTb) | D22: LK | E22: 0 | F22: 0 | G22: 0 | H22: 0 | I22: 0 | J22: 0 | K22: 0 | L22: 0 | M22: 1 | N22: 1 | O22: 1 | P22: 1 | Q22: 0 | R22: 0 | S22: 0 | T22: 2 | U22: 0 | V22: 0 | W22: 0 | X22: 0 | Y22: 0 | Z22: 0 | AA22: 0 | AB22: 1 | AC22: 0 | AD22: 0 | AE22: 0 | AF22: 0 | AG22: 0 | AH22: 0 | AI22: 0 | AJ22: 0 | AK22: 0 | AL22: 0 | AM22: 0 | AN22: 0 | AO22: 0 | AP22: 0 | AQ22: 0 | AR22: 0 | AS22: 0 | AT22: 0 | AU22: 0 | AV22: 0 | AW22: 0 | AX22: 0 | AY22: 0 | AZ22: 0 | BA22: 0 | BB22: 1 | BC22: 0 | BD22: 0 | BE22: 0 | BF22: 0 | BG22: 0 | BH22: 0 | BI22: 0 | BJ22: 0 | BK22: 0 | BL22: 0 | BM22: 2 | BN22: 0 | BO22: 1 | BP22: 0 | BQ22: 0 | BR22: =SUM(E22:BQ22) -> 11
D23: PR | E23: 0 | F23: 0 | G23: 0 | H23: 0 | I23: 0 | J23: 0 | K23: 0 | L23: 0 | M23: 0 | N23: 1 | O23: 0 | P23: 0 | Q23: 0 | R23: 0 | S23: 0 | T23: 1 | U23: 0 | V23: 0 | W23: 0 | X23: 0 | Y23: 0 | Z23: 0 | AA23: 1 | AB23: 0 | AC23: 0 | AD23: 0 | AE23: 0 | AF23: 0 | AG23: 0 | AH23: 0 | AI23: 0 | AJ23: 0 | AK23: 0 | AL23: 0 | AM23: 0 | AN23: 0 | AO23: 1 | AP23: 0 | AQ23: 0 | AR23: 0 | AS23: 0 | AT23: 0 | AU23: 0 | AV23: 0 | AW23: 0 | AX23: 0 | AY23: 0 | AZ23: 0 | BA23: 0 | BB23: 0 | BC23: 0 | BD23: 0 | BE23: 0 | BF23: 0 | BG23: 0 | BH23: 0 | BI23: 0 | BJ23: 0 | BK23: 0 | BL23: 0 | BM23: 1 | BN23: 0 | BO23: 0 | BP23: 0 | BQ23: 0 | BR23: =SUM(E23:BQ23) -> 5
D24: JML | E24: =SUM(E22:E23) -> 0 | F24: =SUM(F22:F23) -> 0 | G24: =SUM(G22:G23) -> 0 | H24: =SUM(H22:H23) -> 0 | I24: =SUM(I22:I23) -> 0 | J24: =SUM(J22:J23) -> 0 | K24: =SUM(K22:K23) -> 0 | L24: =SUM(L22:L23) -> 0 | ... BQ24: =SUM(BQ22:BQ23) -> 0 | BR24: =SUM(E24:BQ24) -> 16
B25: 3. | C25: Jumlah pengguna hak pilih dalam Daftar Pemilih Khusus (DPK) | D25: LK | E25: 0 | F25: 2 | G25: 0 | H25: 1 | I25: 0 | J25: 0 | K25: 5 | L25: 2 | M25: 1 | N25: 3 | O25: 0 | P25: 0 | Q25: 0 | R25: 3 | S25: 1 | T25: 0 | U25: 0 | V25: 0 | W25: 0 | X25: 3 | Y25: 0 | Z25: 0 | AA25: 0 | AB25: 0 | AC25: 0 | AD25: 0 | AE25: 0 | AF25: 0 | AG25: 0 | AH25: 0 | AI25: 0 | AJ25: 0 | AK25: 0 | AL25: 0 | AM25: 1 | AN25: 2 | AO25: 3 | AP25: 0 | AQ25: 1 | AR25: 0 | AS25: 1 | AT25: 0 | AU25: 0 | AV25: 16 | AW25: 0 | AX25: 0 | AY25: 1 | AZ25: 0 | BA25: 0 | BB25: 0 | BC25: 2 | BD25: 0 | BE25: 0 | BF25: 4 | BG25: 1 | BH25: 2 | BI25: 0 | BJ25: 0 | BK25: 0 | BL25: 0 | BM25: 0 | BN25: 0 | BO25: 0 | BP25: 0 | BQ25: 0 | BR25: =SUM(E25:BQ25) -> 55
D26: PR | E26: 0 | F26: 4 | G26: 0 | H26: 2 | I26: 0 | J26: 0 | K26: 4 | L26: 2 | M26: 2 | N26: 0 | O26: 0 | P26: 0 | Q26: 0 | R26: 1 | S26: 0 | T26: 0 | U26: 0 | V26: 0 | W26: 0 | X26: 5 | Y26: 0 | Z26: 0 | AA26: 0 | AB26: 0 | AC26: 0 | AD26: 0 | AE26: 0 | AF26: 0 | AG26: 1 | AH26: 2 | AI26: 0 | AJ26: 0 | AK26: 3 | AL26: 0 | AM26: 1 | AN26: 0 | AO26: 0 | AP26: 0 | AQ26: 1 | AR26: 0 | AS26: 2 | AT26: 0 | AU26: 0 | AV26: 17 | AW26: 0 | AX26: 0 | AY26: 1 | AZ26: 0 | BA26: 0 | BB26: 0 | BC26: 3 | BD26: 0 | BE26: 0 | BF26: 4 | BG26: 2 | BH26: 3 | BI26: 1 | BJ26: 0 | BK26: 0 | BL26: 0 | BM26: 0 | BN26: 0 | BO26: 2 | BP26: 0 | BQ26: 0 | BR26: =SUM(E26:BQ26) -> 63
D27: JML | E27: =SUM(E25:E26) -> 0 | F27: =SUM(F25:F26) -> 6 | G27: =SUM(G25:G26) -> 0 | H27: =SUM(H25:H26) -> 3 | I27: =SUM(I25:I26) -> 0 | J27: =SUM(J25:J26) -> 0 | K27: =SUM(K25:K26) -> 9 | L27: =SUM(L25:L26) -> 4 | ... BQ27: =SUM(BQ25:BQ26) -> 0 | BR27: =SUM(E27:BQ27) -> 118
B28: 4. | C28: Jumlah Pengguna Hak Pilih (B.1+B.2+B.3) | D28: LK | E28: =SUM(E19,E22,E25) -> 78 | F28: =SUM(F19,F22,F25) -> 87 | G28: =SUM(G19,G22,G25) -> 77 | H28: =SUM(H19,H22,H25) -> 91 | I28: =SUM(I19,I22,I25) -> 103 | J28: =SUM(J19,J22,J25) -> 117 | K28: =SUM(K19,K22,K25) -> 105 | L28: =SUM(L19,L22,L25) -> 84 | ... BQ28: =SUM(BQ19,BQ22,BQ25) -> 109 | BR28: =SUM(E28:BQ28) -> 6475
D29: PR | E29: =SUM(E20,E23,E26) -> 93 | F29: =SUM(F20,F23,F26) -> 76 | G29: =SUM(G20,G23,G26) -> 76 | H29: =SUM(H20,H23,H26) -> 109 | I29: =SUM(I20,I23,I26) -> 104 | J29: =SUM(J20,J23,J26) -> 112 | K29: =SUM(K20,K23,K26) -> 116 | L29: =SUM(L20,L23,L26) -> 111 | ... BQ29: =SUM(BQ20,BQ23,BQ26) -> 115 | BR29: =SUM(E29:BQ29) -> 6919
D30: JML | E30: =SUM(E28:E29) -> 171 | F30: =SUM(F28:F29) -> 163 | G30: =SUM(G28:G29) -> 153 | H30: =SUM(H28:H29) -> 200 | I30: =SUM(I28:I29) -> 207 | J30: =SUM(J28:J29) -> 229 | K30: =SUM(K28:K29) -> 221 | L30: =SUM(L28:L29) -> 195 | ... BQ30: =SUM(BQ28:BQ29) -> 224 | BR30: =SUM(E30:BQ30) -> 13394
A32: II | B32: DATA PENGGUNAAN SURAT SUARA
A33: 1 | B33: Jumlah surat suara yang diterima, termasuk surat suara cadangan 2,5% dari DPT | E33: 245 | F33: 228 | G33: 204 | H33: 286 | I33: 285 | J33: 275 | K33: 288 | L33: 254 | M33: 294 | N33: 301 | O33: 300 | P33: 299 | Q33: 296 | R33: 280 | S33: 286 | T33: 299 | U33: 285 | V33: 285 | W33: 283 | X33: 289 | Y33: 296 | Z33: 290 | AA33: 295 | AB33: 294 | AC33: 295 | AD33: 306 | AE33: 301 | AF33: 302 | AG33: 282 | AH33: 287 | AI33: 291 | AJ33: 297 | AK33: 292 | AL33: 245 | AM33: 249 | AN33: 302 | AO33: 300 | AP33: 288 | AQ33: 284 | AR33: 232 | AS33: 254 | AT33: 220 | AU33: 278 | AV33: 251 | AW33: 254 | AX33: 297 | AY33: 293 | AZ33: 277 | BA33: 288 | BB33: 194 | BC33: 210 | BD33: 298 | BE33: 234 | BF33: 289 | BG33: 285 | BH33: 251 | BI33: 246 | BJ33: 284 | BK33: 262 | BL33: 300 | BM33: 263 | BN33: 296 | BO33: 294 | BP33: 291 | BQ33: 272 | BR33: =SUM(E33:BQ33) -> 17971
A34: 2 | B34: Jumlah surat suara yang digunakan | E34: 171 | F34: 163 | G34: 153 | H34: 200 | I34: 207 | J34: 229 | K34: 221 | L34: 195 | M34: 209 | N34: 233 | O34: 203 | P34: 219 | Q34: 208 | R34: 203 | S34: 206 | T34: 193 | U34: 208 | V34: 190 | W34: 187 | X34: 194 | Y34: 220 | Z34: 220 | AA34: 209 | AB34: 205 | AC34: 235 | AD34: 224 | AE34: 215 | AF34: 221 | AG34: 192 | AH34: 202 | AI34: 200 | AJ34: 227 | AK34: 221 | AL34: 197 | AM34: 195 | AN34: 223 | AO34: 240 | AP34: 219 | AQ34: 213 | AR34: 192 | AS34: 200 | AT34: 167 | AU34: 233 | AV34: 211 | AW34: 188 | AX34: 216 | AY34: 202 | AZ34: 197 | BA34: 214 | BB34: 129 | BC34: 172 | BD34: 223 | BE34: 183 | BF34: 231 | BG34: 233 | BH34: 203 | BI34: 200 | BJ34: 220 | BK34: 204 | BL34: 223 | BM34: 188 | BN34: 228 | BO34: 215 | BP34: 228 | BQ34: 224 | BR34: =SUM(E34:BQ34) -> 13394
A35: 3 | B35: Jumlah surat suara dikembalikan oleh pemilih (karena rusak atau keliru coblos) | E35: 3 | F35: 0 | G35: 0 | H35: 0 | I35: 0 | J35: 0 | K35: 0 | L35: 0 | M35: 1 | N35: 0 | O35: 0 | P35: 0 | Q35: 0 | R35: 0 | S35: 0 | T35: 0 | U35: 0 | V35: 0 | W35: 3 | X35: 3 | Y35: 0 | Z35: 0 | AA35: 0 | AB35: 0 | AC35: 10 | AD35: 0 | AE35: 0 | AF35: 0 | AG35: 0 | AH35: 0 | AI35: 0 | AJ35: 0 | AK35: 0 | AL35: 0 | AM35: 1 | AN35: 2 | AO35: 0 | AP35: 0 | AQ35: 0 | AR35: 1 | AS35: 0 | AT35: 0 | AU35: 0 | AV35: 0 | AW35: 3 | AX35: 0 | AY35: 0 | AZ35: 0 | BA35: 0 | BB35: 0 | BC35: 2 | BD35: 0 | BE35: 0 | BF35: 0 | BG35: 0 | BH35: 0 | BI35: 0 | BJ35: 0 | BK35: 0 | BL35: 0 | BM35: 0 | BN35: 0 | BO35: 0 | BP35: 0 | BQ35: 0 | BR35: =SUM(E35:BQ35) -> 29
A36: 4 | B36: Jumlah surat suara yang tidak digunakan/tidak terpakai, termasuk sisa surat suara cadangan | E36: =E33-(E34+E35) -> 71 | F36: =F33-(F34+F35) -> 65 | G36: =G33-(G34+G35) -> 51 | H36: =H33-(H34+H35) -> 86 | I36: =I33-(I34+I35) -> 78 | J36: =J33-(J34+J35) -> 46 | K36: =K33-(K34+K35) -> 67 | L36: =L33-(L34+L35) -> 59 | ... BQ36: =BQ33-(BQ34+BQ35) -> 48 | BR36: =SUM(E36:BQ36) -> 4548
A38: III | B38: DATA PEMILIH DISABILITAS
B39: Jumlah seluruh Pemilih disabilitas yang menggunakan hak pilih | D39: LK | E39: 0 | F39: 1 | G39: 1 | H39: 0 | I39: 0 | J39: 0 | K39: 0 | L39: 0 | M39: 0 | N39: 0 | O39: 0 | P39: 0 | Q39: 0 | R39: 1 | S39: 0 | T39: 0 | U39: 2 | V39: 0 | W39: 0 | X39: 1 | Y39: 0 | Z39: 0 | AA39: 0 | AB39: 0 | AC39: 0 | AD39: 0 | AE39: 0 | AF39: 0 | AG39: 1 | AH39: 0 | AI39: 0 | AJ39: 0 | AK39: 1 | AL39: 0 | AM39: 0 | AN39: 0 | AO39: 2 | AP39: 0 | AQ39: 1 | AR39: 0 | AS39: 0 | AT39: 0 | AU39: 0 | AV39: 0 | AW39: 0 | AX39: 0 | AY39: 1 | AZ39: 0 | BA39: 0 | BB39: 0 | BC39: 0 | BD39: 1 | BE39: 0 | BF39: 0 | BG39: 0 | BH39: 1 | BI39: 1 | BJ39: 0 | BK39: 0 | BL39: 1 | BM39: 0 | BN39: 0 | BO39: 0 | BP39: 0 | BQ39: 0 | BR39: =SUM(E39:BQ39) -> 16
D40: PR | E40: 0 | F40: 1 | G40: 0 | H40: 0 | I40: 0 | J40: 2 | K40: 0 | L40: 0 | M40: 0 | N40: 0 | O40: 0 | P40: 0 | Q40: 0 | R40: 0 | S40: 1 | T40: 0 | U40: 2 | V40: 0 | W40: 0 | X40: 1 | Y40: 0 | Z40: 1 | AA40: 0 | AB40: 0 | AC40: 0 | AD40: 0 | AE40: 0 | AF40: 0 | AG40: 0 | AH40: 0 | AI40: 0 | AJ40: 0 | AK40: 0 | AL40: 0 | AM40: 0 | AN40: 0 | AO40: 0 | AP40: 0 | AQ40: 0 | AR40: 0 | AS40: 0 | AT40: 0 | AU40: 0 | AV40: 0 | AW40: 0 | AX40: 0 | AY40: 0 | AZ40: 1 | BA40: 0 | BB40: 0 | BC40: 0 | BD40: 1 | BE40: 0 | BF40: 0 | BG40: 0 | BH40: 0 | BI40: 1 | BJ40: 0 | BK40: 0 | BL40: 2 | BM40: 0 | BN40: 1 | BO40: 0 | BP40: 0 | BQ40: 0 | BR40: =SUM(E40:BQ40) -> 14
D41: JML | E41: =SUM(E39:E40) -> 0 | F41: =SUM(F39:F40) -> 2 | G41: =SUM(G39:G40) -> 1 | H41: =SUM(H39:H40) -> 0 | I41: =SUM(I39:I40) -> 0 | J41: =SUM(J39:J40) -> 2 | K41: =SUM(K39:K40) -> 0 | L41: =SUM(L39:L40) -> 0 | ... BQ41: =SUM(BQ39:BQ40) -> 0 | BR41: =SUM(E41:BQ41) -> 30
A43: IV | B43: DATA RINCIAN PEROLEHAN SUARA PASANGAN CALON BUPATI DAN WAKIL BUPATI
A44: NOMOR DAN NAMA CALON
B45: 1 | C45: H. ANIES RASYID BASWEDAN, Ph.D. - Dr. (H.C.) H. A. MUHAIMIN ISKANDAR | E45: 22 | F45: 31 | G45: 18 | H45: 19 | I45: 36 | J45: 32 | K45: 18 | L45: 12 | M45: 18 | N45: 34 | O45: 15 | P45: 51 | Q45: 35 | R45: 18 | S45: 27 | T45: 46 | U45: 34 | V45: 21 | W45: 32 | X45: 28 | Y45: 28 | Z45: 16 | AA45: 18 | AB45: 9 | AC45: 12 | AD45: 8 | AE45: 22 | AF45: 38 | AG45: 28 | AH45: 23 | AI45: 20 | AJ45: 20 | AK45: 16 | AL45: 11 | AM45: 5 | AN45: 11 | AO45: 5 | AP45: 30 | AQ45: 14 | AR45: 37 | AS45: 27 | AT45: 19 | AU45: 19 | AV45: 37 | AW45: 42 | AX45: 37 | AY45: 55 | AZ45: 18 | BA45: 39 | BB45: 16 | BC45: 28 | BD45: 38 | BE45: 24 | BF45: 34 | BG45: 54 | BH45: 22 | BI45: 11 | BJ45: 23 | BK45: 12 | BL45: 7 | BM45: 4 | BN45: 6 | BO45: 7 | BP45: 10 | BQ45: 10 | BR45: =SUM(E45:BQ45) -> 1517
B46: 2 | C46: H. PRABOWO SUBIANTO - GIBRAN RAKABUMING RAKA | E46: 123 | F46: 93 | G46: 96 | H46: 126 | I46: 136 | J46: 138 | K46: 134 | L46: 138 | M46: 108 | N46: 162 | O46: 106 | P46: 120 | Q46: 134 | R46: 149 | S46: 136 | T46: 100 | U46: 117 | V46: 131 | W46: 120 | X46: 114 | Y46: 146 | Z46: 159 | AA46: 138 | AB46: 159 | AC46: 177 | AD46: 184 | AE46: 152 | AF46: 136 | AG46: 135 | AH46: 151 | AI46: 127 | AJ46: 137 | AK46: 140 | AL46: 151 | AM46: 149 | AN46: 164 | AO46: 184 | AP46: 130 | AQ46: 136 | AR46: 121 | AS46: 150 | AT46: 114 | AU46: 161 | AV46: 147 | AW46: 107 | AX46: 125 | AY46: 115 | AZ46: 147 | BA46: 151 | BB46: 96 | BC46: 121 | BD46: 163 | BE46: 110 | BF46: 152 | BG46: 133 | BH46: 131 | BI46: 123 | BJ46: 140 | BK46: 157 | BL46: 183 | BM46: 118 | BN46: 170 | BO46: 160 | BP46: 169 | BQ46: 173 | BR46: =SUM(E46:BQ46) -> 8973
B47: 3 | C47: H. GANJAR PRANOWO, S.H., M.I.P. - Prof. Dr. H. M. MAHFUD MD | E47: 23 | F47: 35 | G47: 35 | H47: 54 | I47: 25 | J47: 55 | K47: 55 | L47: 39 | M47: 71 | N47: 32 | O47: 81 | P47: 46 | Q47: 37 | R47: 34 | S47: 39 | T47: 45 | U47: 55 | V47: 38 | W47: 32 | X47: 49 | Y47: 45 | Z47: 45 | AA47: 47 | AB47: 31 | AC47: 44 | AD47: 29 | AE47: 33 | AF47: 42 | AG47: 26 | AH47: 23 | AI47: 46 | AJ47: 63 | AK47: 60 | AL47: 32 | AM47: 37 | AN47: 37 | AO47: 49 | AP47: 51 | AQ47: 60 | AR47: 31 | AS47: 22 | AT47: 33 | AU47: 50 | AV47: 25 | AW47: 38 | AX47: 47 | AY47: 31 | AZ47: 28 | BA47: 22 | BB47: 14 | BC47: 21 | BD47: 19 | BE47: 36 | BF47: 34 | BG47: 43 | BH47: 49 | BI47: 63 | BJ47: 52 | BK47: 31 | BL47: 31 | BM47: 62 | BN47: 47 | BO47: 43 | BP47: 48 | BQ47: 38 | BR47: =SUM(E47:BQ47) -> 2638
A49: V | B49: DATA SUARA SAH DAN TIDAK SAH
B50: A. | C50: JUMLAH SELURUH SUARA SAH | E50: =SUM(E45:E47) -> 168 | F50: =SUM(F45:F47) -> 159 | G50: =SUM(G45:G47) -> 149 | H50: =SUM(H45:H47) -> 199 | I50: =SUM(I45:I47) -> 197 | J50: =SUM(J45:J47) -> 225 | K50: =SUM(K45:K47) -> 207 | L50: =SUM(L45:L47) -> 189 | ... BQ50: =SUM(BQ45:BQ47) -> 221 | BR50: =SUM(E50:BQ50) -> 13128
B51: B. | C51: JUMLAH SUARA TIDAK SAH | E51: 3 | F51: 4 | G51: 4 | H51: 1 | I51: 10 | J51: 4 | K51: 14 | L51: 6 | M51: 12 | N51: 5 | O51: 1 | P51: 2 | Q51: 2 | R51: 2 | S51: 4 | T51: 2 | U51: 2 | V51: 0 | W51: 3 | X51: 3 | Y51: 1 | Z51: 0 | AA51: 6 | AB51: 6 | AC51: 2 | AD51: 3 | AE51: 8 | AF51: 5 | AG51: 3 | AH51: 5 | AI51: 7 | AJ51: 7 | AK51: 5 | AL51: 3 | AM51: 4 | AN51: 11 | AO51: 2 | AP51: 8 | AQ51: 3 | AR51: 3 | AS51: 1 | AT51: 1 | AU51: 3 | AV51: 2 | AW51: 1 | AX51: 7 | AY51: 1 | AZ51: 4 | BA51: 2 | BB51: 3 | BC51: 2 | BD51: 3 | BE51: 13 | BF51: 11 | BG51: 3 | BH51: 1 | BI51: 3 | BJ51: 5 | BK51: 4 | BL51: 2 | BM51: 4 | BN51: 5 | BO51: 5 | BP51: 1 | BQ51: 3 | BR51: =SUM(E51:BQ51) -> 266
B52: C. | C52: JUMLAH SELURUH SUARA SAH DAN SUARA TIDAK SAH (V.A + V.B) | E52: =SUM(E50:E51) -> 171 | F52: =SUM(F50:F51) -> 163 | G52: =SUM(G50:G51) -> 153 | H52: =SUM(H50:H51) -> 200 | I52: =SUM(I50:I51) -> 207 | J52: =SUM(J50:J51) -> 229 | K52: =SUM(K50:K51) -> 221 | L52: =SUM(L50:L51) -> 195 | ... BQ52: =SUM(BQ50:BQ51) -> 224 | BR52: =SUM(E52:BQ52) -> 13394

Sheet KARANGSARI
C2: Kecamatan | D2: SEMPU
C3: Kabupaten | D3: BANYUWANGI
C4: Provinsi | D4: JAWA TIMUR
C9: Kelurahan | D9: KARANGSARI
A12: I | B12: DATA PEMILIH DAN PENGGUNAAN HAK PILIH | AX12: JUMLAH AKHIR
A13: A | B13: DATA PEMILIH | E13: TPS 001 | F13: TPS 002 | G13: TPS 003 | H13: TPS 004 | I13: TPS 005 | J13: TPS 006 | K13: TPS 007 | L13: TPS 008 | M13: TPS 009 | N13: TPS 010 | O13: TPS 011 | P13: TPS 012 | Q13: TPS 013 | R13: TPS 014 | S13: TPS 015 | T13: TPS 016 | U13: TPS 017 | V13: TPS 018 | W13: TPS 019 | X13: TPS 020 | Y13: TPS 021 | Z13: TPS 022 | AA13: TPS 023 | AB13: TPS 024 | AC13: TPS 025 | AD13: TPS 026 | AE13: TPS 027 | AF13: TPS 028 | AG13: TPS 029 | AH13: TPS 030 | AI13: TPS 031 | AJ13: TPS 032 | AK13: TPS 033 | AL13: TPS 034 | AM13: TPS 035 | AN13: TPS 036 | AO13: TPS 037 | AP13: TPS 038 | AQ13: TPS 039 | AR13: TPS 040 | AS13: TPS 041 | AT13: TPS 042 | AU13: TPS 043 | AV13: TPS 044 | AW13: TPS 045
B14: Jumlah Pemilih dalam Daftar Pemilih Tetap (DPT) | D14: LK | E14: 149 | F14: 145 | G14: 119 | H14: 137 | I14: 143 | J14: 101 | K14: 146 | L14: 146 | M14: 150 | N14: 133 | O14: 124 | P14: 95 | Q14: 142 | R14: 147 | S14: 130 | T14: 108 | U14: 149 | V14: 135 | W14: 148 | X14: 149 | Y14: 157 | Z14: 143 | AA14: 163 | AB14: 143 | AC14: 111 | AD14: 116 | AE14: 138 | AF14: 121 | AG14: 136 | AH14: 148 | AI14: 98 | AJ14: 140 | AK14: 107 | AL14: 149 | AM14: 144 | AN14: 121 | AO14: 90 | AP14: 145 | AQ14: 153 | AR14: 135 | AS14: 148 | AT14: 142 | AU14: 140 | AV14: 136 | AW14: 141 | AX14: =SUM(E14:AW14) -> 6061
D15: PR | E15: 128 | F15: 151 | G15: 121 | H15: 140 | I15: 145 | J15: 101 | K15: 146 | L15: 143 | M15: 144 | N15: 128 | O15: 116 | P15: 95 | Q15: 149 | R15: 148 | S15: 138 | T15: 104 | U15: 129 | V15: 132 | W15: 144 | X15: 141 | Y15: 140 | Z15: 134 | AA15: 135 | AB15: 145 | AC15: 122 | AD15: 118 | AE15: 159 | AF15: 128 | AG15: 137 | AH15: 130 | AI15: 93 | AJ15: 136 | AK15: 114 | AL15: 144 | AM15: 148 | AN15: 126 | AO15: 98 | AP15: 143 | AQ15: 145 | AR15: 137 | AS15: 140 | AT15: 152 | AU15: 134 | AV15: 150 | AW15: 154 | AX15: =SUM(E15:AW15) -> 6005
D16: JML | E16: =SUM(E14:E15) -> 277 | F16: =SUM(F14:F15) -> 296 | G16: =SUM(G14:G15) -> 240 | H16: =SUM(H14:H15) -> 277 | I16: =SUM(I14:I15) -> 288 | J16: =SUM(J14:J15) -> 202 | K16: =SUM(K14:K15) -> 292 | L16: =SUM(L14:L15) -> 289 | ... AW16: =SUM(AW14:AW15) -> 295 | AX16: =SUM(E16:AW16) -> 12066
A18: B | B18: PENGGUNA HAK PILIH
B19: 1. | C19: Jumlah pengguna hak pilih dalam Daftar Pemilih Tetap (DPT) | D19: LK | E19: 103 | F19: 106 | G19: 89 | H19: 106 | I19: 101 | J19: 63 | K19: 78 | L19: 102 | M19: 107 | N19: 71 | O19: 85 | P19: 71 | Q19: 111 | R19: 102 | S19: 95 | T19: 77 | U19: 114 | V19: 106 | W19: 100 | X19: 108 | Y19: 105 | Z19: 92 | AA19: 107 | AB19: 94 | AC19: 80 | AD19: 96 | AE19: 93 | AF19: 93 | AG19: 105 | AH19: 115 | AI19: 82 | AJ19: 114 | AK19: 75 | AL19: 104 | AM19: 102 | AN19: 93 | AO19: 71 | AP19: 110 | AQ19: 113 | AR19: 91 | AS19: 123 | AT19: 95 | AU19: 97 | AV19: 96 | AW19: 107 | AX19: =SUM(E19:AW19) -> 4348
D20: PR | E20: 106 | F20: 123 | G20: 88 | H20: 112 | I20: 113 | J20: 73 | K20: 96 | L20: 111 | M20: 95 | N20: 93 | O20: 91 | P20: 72 | Q20: 117 | R20: 111 | S20: 97 | T20: 80 | U20: 104 | V20: 107 | W20: 109 | X20: 111 | Y20: 106 | Z20: 103 | AA20: 103 | AB20: 110 | AC20: 104 | AD20: 90 | AE20: 120 | AF20: 98 | AG20: 116 | AH20: 105 | AI20: 80 | AJ20: 109 | AK20: 94 | AL20: 90 | AM20: 106 | AN20: 101 | AO20: 81 | AP20: 118 | AQ20: 116 | AR20: 106 | AS20: 121 | AT20: 124 | AU20: 102 | AV20: 114 | AW20: 107 | AX20: =SUM(E20:AW20) -> 4633
D21: JML | E21: =SUM(E19:E20) -> 209 | F21: =SUM(F19:F20) -> 229 | G21: =SUM(G19:G20) -> 177 | H21: =SUM(H19:H20) -> 218 | I21: =SUM(I19:I20) -> 214 | J21: =SUM(J19:J20) -> 136 | K21: =SUM(K19:K20) -> 174 | L21: =SUM(L19:L20) -> 213 | ... AW21: =SUM(AW19:AW20) -> 214 | AX21: =SUM(E21:AW21) -> 8981
B22: 2. | C22: Jumlah pengguna hak pilih dalam Daftar Pemilih Tambahan (DPTb) | D22: LK | E22: 0 | F22: 0 | G22: 1 | H22: 0 | I22: 2 | J22: 1 | K22: 0 | L22: 0 | M22: 0 | N22: 0 | O22: 0 | P22: 1 | Q22: 0 | R22: 0 | S22: 0 | T22: 1 | U22: 0 | V22: 0 | W22: 0 | X22: 0 | Y22: 0 | Z22: 0 | AA22: 0 | AB22: 0 | AC22: 0 | AD22: 0 | AE22: 0 | AF22: 0 | AG22: 0 | AH22: 1 | AI22: 1 | AJ22: 0 | AK22: 0 | AL22: 0 | AM22: 1 | AN22: 1 | AO22: 0 | AP22: 1 | AQ22: 0 | AR22: 1 | AS22: 0 | AT22: 1 | AU22: 0 | AV22: 0 | AW22: 0 | AX22: =SUM(E22:AW22) -> 13
D23: PR | E23: 0 | F23: 1 | G23: 2 | H23: 1 | I23: 0 | J23: 0 | K23: 0 | L23: 1 | M23: 1 | N23: 0 | O23: 0 | P23: 0 | Q23: 0 | R23: 1 | S23: 0 | T23: 0 | U23: 0 | V23: 1 | W23: 0 | X23: 0 | Y23: 0 | Z23: 0 | AA23: 0 | AB23: 0 | AC23: 1 | AD23: 0 | AE23: 0 | AF23: 0 | AG23: 2 | AH23: 0 | AI23: 0 | AJ23: 0 | AK23: 0 | AL23: 1 | AM23: 0 | AN23: 0 | AO23: 0 | AP23: 4 | AQ23: 0 | AR23: 1 | AS23: 0 | AT23: 0 | AU23: 0 | AV23: 0 | AW23: 2 | AX23: =SUM(E23:AW23) -> 19
D24: JML | E24: =SUM(E22:E23) -> 0 | F24: =SUM(F22:F23) -> 1 | G24: =SUM(G22:G23) -> 3 | H24: =SUM(H22:H23) -> 1 | I24: =SUM(I22:I23) -> 2 | J24: =SUM(J22:J23) -> 1 | K24: =SUM(K22:K23) -> 0 | L24: =SUM(L22:L23) -> 1 | ... AW24: =SUM(AW22:AW23) -> 2 | AX24: =SUM(E24:AW24) -> 32
B25: 3. | C25: Jumlah pengguna hak pilih dalam Daftar Pemilih Khusus (DPK) | D25: LK | E25: 0 | F25: 0 | G25: 0 | H25: 0 | I25: 0 | J25: 0 | K25: 2 | L25: 4 | M25: 0 | N25: 0 | O25: 0 | P25: 2 | Q25: 0 | R25: 1 | S25: 1 | T25: 0 | U25: 6 | V25: 1 | W25: 3 | X25: 1 | Y25: 2 | Z25: 0 | AA25: 0 | AB25: 2 | AC25: 0 | AD25: 0 | AE25: 0 | AF25: 0 | AG25: 0 | AH25: 0 | AI25: 0 | AJ25: 2 | AK25: 4 | AL25: 0 | AM25: 4 | AN25: 0 | AO25: 0 | AP25: 0 | AQ25: 1 | AR25: 3 | AS25: 0 | AT25: 0 | AU25: 0 | AV25: 0 | AW25: 0 | AX25: =SUM(E25:AW25) -> 39
D26: PR | E26: 0 | F26: 0 | G26: 0 | H26: 0 | I26: 0 | J26: 0 | K26: 2 | L26: 4 | M26: 0 | N26: 0 | O26: 0 | P26: 4 | Q26: 0 | R26: 3 | S26: 3 | T26: 0 | U26: 7 | V26: 0 | W26: 2 | X26: 1 | Y26: 0 | Z26: 0 | AA26: 0 | AB26: 0 | AC26: 0 | AD26: 0 | AE26: 0 | AF26: 0 | AG26: 0 | AH26: 0 | AI26: 1 | AJ26: 3 | AK26: 0 | AL26: 2 | AM26: 3 | AN26: 2 | AO26: 0 | AP26: 0 | AQ26: 0 | AR26: 3 | AS26: 0 | AT26: 0 | AU26: 0 | AV26: 1 | AW26: 2 | AX26: =SUM(E26:AW26) -> 43
D27: JML | E27: =SUM(E25:E26) -> 0 | F27: =SUM(F25:F26) -> 0 | G27: =SUM(G25:G26) -> 0 | H27: =SUM(H25:H26) -> 0 | I27: =SUM(I25:I26) -> 0 | J27: =SUM(J25:J26) -> 0 | K27: =SUM(K25:K26) -> 4 | L27: =SUM(L25:L26) -> 8 | ... AW27: =SUM(AW25:AW26) -> 2 | AX27: =SUM(E27:AW27) -> 82
B28: 4. | C28: Jumlah Pengguna Hak Pilih (B.1+B.2+B.3) | D28: LK | E28: =SUM(E19,E22,E25) -> 103 | F28: =SUM(F19,F22,F25) -> 106 | G28: =SUM(G19,G22,G25) -> 90 | H28: =SUM(H19,H22,H25) -> 106 | I28: =SUM(I19,I22,I25) -> 103 | J28: =SUM(J19,J22,J25) -> 64 | K28: =SUM(K19,K22,K25) -> 80 | L28: =SUM(L19,L22,L25) -> 106 | ... AW28: =SUM(AW19,AW22,AW25) -> 107 | AX28: =SUM(E28:AW28) -> 4400
D29: PR | E29: =SUM(E20,E23,E26) -> 106 | F29: =SUM(F20,F23,F26) -> 124 | G29: =SUM(G20,G23,G26) -> 90 | H29: =SUM(H20,H23,H26) -> 113 | I29: =SUM(I20,I23,I26) -> 113 | J29: =SUM(J20,J23,J26) -> 73 | K29: =SUM(K20,K23,K26) -> 98 | L29: =SUM(L20,L23,L26) -> 116 | ... AW29: =SUM(AW20,AW23,AW26) -> 111 | AX29: =SUM(E29:AW29) -> 4695
D30: JML | E30: =SUM(E28:E29) -> 209 | F30: =SUM(F28:F29) -> 230 | G30: =SUM(G28:G29) -> 180 | H30: =SUM(H28:H29) -> 219 | I30: =SUM(I28:I29) -> 216 | J30: =SUM(J28:J29) -> 137 | K30: =SUM(K28:K29) -> 178 | L30: =SUM(L28:L29) -> 222 | ... AW30: =SUM(AW28:AW29) -> 218 | AX30: =SUM(E30:AW30) -> 9095
A32: II | B32: DATA PENGGUNAAN SURAT SUARA
A33: 1 | B33: Jumlah surat suara yang diterima, termasuk surat suara cadangan 2,5% dari DPT | E33: 283 | F33: 302 | G33: 245 | H33: 283 | I33: 294 | J33: 207 | K33: 294 | L33: 294 | M33: 300 | N33: 267 | O33: 246 | P33: 194 | Q33: 297 | R33: 301 | S33: 276 | T33: 217 | U33: 284 | V33: 273 | W33: 299 | X33: 298 | Y33: 293 | Z33: 283 | AA33: 304 | AB33: 293 | AC33: 238 | AD33: 240 | AE33: 303 | AF33: 253 | AG33: 271 | AH33: 284 | AI33: 300 | AJ33: 281 | AK33: 229 | AL33: 299 | AM33: 297 | AN33: 252 | AO33: 192 | AP33: 294 | AQ33: 304 | AR33: 278 | AS33: 295 | AT33: 305 | AU33: 280 | AV33: 292 | AW33: 300 | AX33: =SUM(E33:AW33) -> 12414
A34: 2 | B34: Jumlah surat suara yang digunakan | E34: 209 | F34: 230 | G34: 180 | H34: 219 | I34: 216 | J34: 137 | K34: 178 | L34: 222 | M34: 203 | N34: 164 | O34: 176 | P34: 150 | Q34: 228 | R34: 218 | S34: 196 | T34: 158 | U34: 231 | V34: 215 | W34: 214 | X34: 221 | Y34: 213 | Z34: 195 | AA34: 210 | AB34: 206 | AC34: 185 | AD34: 186 | AE34: 213 | AF34: 191 | AG34: 223 | AH34: 221 | AI34: 164 | AJ34: 228 | AK34: 173 | AL34: 197 | AM34: 216 | AN34: 197 | AO34: 152 | AP34: 233 | AQ34: 230 | AR34: 205 | AS34: 244 | AT34: 220 | AU34: 199 | AV34: 211 | AW34: 218 | AX34: =SUM(E34:AW34) -> 9095
A35: 3 | B35: Jumlah surat suara dikembalikan oleh pemilih (karena rusak atau keliru coblos) | E35: 0 | F35: 0 | G35: 0 | H35: 0 | I35: 0 | J35: 0 | K35: 1 | L35: 2 | M35: 0 | N35: 0 | O35: 0 | P35: 0 | Q35: 0 | R35: 0 | S35: 1 | T35: 0 | U35: 0 | V35: 0 | W35: 0 | X35: 2 | Y35: 0 | Z35: 0 | AA35: 0 | AB35: 0 | AC35: 1 | AD35: 0 | AE35: 1 | AF35: 0 | AG35: 0 | AH35: 0 | AI35: 6 | AJ35: 0 | AK35: 0 | AL35: 0 | AM35: 0 | AN35: 0 | AO35: 0 | AP35: 0 | AQ35: 0 | AR35: 0 | AS35: 0 | AT35: 1 | AU35: 0 | AV35: 10 | AW35: 0 | AX35: =SUM(E35:AW35) -> 25
A36: 4 | B36: Jumlah surat suara yang tidak digunakan/tidak terpakai, termasuk sisa surat suara cadangan | E36: =E33-(E34+E35) -> 74 | F36: =F33-(F34+F35) -> 72 | G36: =G33-(G34+G35) -> 65 | H36: =H33-(H34+H35) -> 64 | I36: =I33-(I34+I35) -> 78 | J36: =J33-(J34+J35) -> 70 | K36: =K33-(K34+K35) -> 115 | L36: =L33-(L34+L35) -> 70 | ... AW36: =AW33-(AW34+AW35) -> 82 | AX36: =SUM(E36:AW36) -> 3294
A38: III | B38: DATA PEMILIH DISABILITAS
B39: Jumlah seluruh Pemilih disabilitas yang menggunakan hak pilih | D39: LK | E39: 0 | F39: 0 | G39: 0 | H39: 0 | I39: 1 | J39: 0 | K39: 0 | L39: 0 | M39: 0 | N39: 0 | O39: 0 | P39: 0 | Q39: 0 | R39: 0 | S39: 0 | T39: 0 | U39: 0 | V39: 0 | W39: 0 | X39: 0 | Y39: 0 | Z39: 0 | AA39: 0 | AB39: 0 | AC39: 0 | AD39: 0 | AE39: 0 | AF39: 0 | AG39: 0 | AH39: 1 | AI39: 1 | AJ39: 0 | AK39: 0 | AL39: 0 | AM39: 0 | AN39: 0 | AO39: 0 | AP39: 0 | AQ39: 0 | AR39: 0 | AS39: 0 | AT39: 0 | AU39: 0 | AV39: 0 | AW39: 1 | AX39: =SUM(E39:AW39) -> 4
D40: PR | E40: 0 | F40: 0 | G40: 0 | H40: 0 | I40: 0 | J40: 0 | K40: 0 | L40: 0 | M40: 0 | N40: 0 | O40: 0 | P40: 0 | Q40: 0 | R40: 1 | S40: 0 | T40: 0 | U40: 0 | V40: 0 | W40: 0 | X40: 0 | Y40: 0 | Z40: 0 | AA40: 0 | AB40: 0 | AC40: 1 | AD40: 0 | AE40: 0 | AF40: 0 | AG40: 0 | AH40: 0 | AI40: 0 | AJ40: 0 | AK40: 0 | AL40: 0 | AM40: 0 | AN40: 0 | AO40: 0 | AP40: 0 | AQ40: 0 | AR40: 0 | AS40: 0 | AT40: 1 | AU40: 0 | AV40: 0 | AW40: 0 | AX40: =SUM(E40:AW40) -> 3
D41: JML | E41: =SUM(E39:E40) -> 0 | F41: =SUM(F39:F40) -> 0 | G41: =SUM(G39:G40) -> 0 | H41: =SUM(H39:H40) -> 0 | I41: =SUM(I39:I40) -> 1 | J41: =SUM(J39:J40) -> 0 | K41: =SUM(K39:K40) -> 0 | L41: =SUM(L39:L40) -> 0 | ... AW41: =SUM(AW39:AW40) -> 1 | AX41: =SUM(E41:AW41) -> 7
A43: IV | B43: DATA RINCIAN PEROLEHAN SUARA PASANGAN CALON BUPATI DAN WAKIL BUPATI
A44: NOMOR DAN NAMA CALON
B45: 1 | C45: H. ANIES RASYID BASWEDAN, Ph.D. - Dr. (H.C.) H. A. MUHAIMIN ISKANDAR | E45: 19 | F45: 11 | G45: 25 | H45: 10 | I45: 16 | J45: 13 | K45: 28 | L45: 63 | M45: 23 | N45: 18 | O45: 14 | P45: 12 | Q45: 14 | R45: 29 | S45: 7 | T45: 3 | U45: 31 | V45: 14 | W45: 19 | X45: 14 | Y45: 18 | Z45: 8 | AA45: 17 | AB45: 10 | AC45: 5 | AD45: 24 | AE45: 38 | AF45: 18 | AG45: 25 | AH45: 9 | AI45: 13 | AJ45: 35 | AK45: 22 | AL45: 8 | AM45: 38 | AN45: 24 | AO45: 16 | AP45: 18 | AQ45: 19 | AR45: 29 | AS45: 38 | AT45: 13 | AU45: 14 | AV45: 17 | AW45: 13 | AX45: =SUM(E45:AW45) -> 872
B46: 2 | C46: H. PRABOWO SUBIANTO - GIBRAN RAKABUMING RAKA | E46: 127 | F46: 155 | G46: 130 | H46: 157 | I46: 154 | J46: 88 | K46: 132 | L46: 134 | M46: 135 | N46: 122 | O46: 139 | P46: 109 | Q46: 185 | R46: 157 | S46: 147 | T46: 120 | U46: 140 | V46: 168 | W46: 117 | X46: 142 | Y46: 126 | Z46: 149 | AA46: 134 | AB46: 132 | AC46: 131 | AD46: 114 | AE46: 137 | AF46: 105 | AG46: 133 | AH46: 136 | AI46: 104 | AJ46: 150 | AK46: 101 | AL46: 127 | AM46: 130 | AN46: 134 | AO46: 103 | AP46: 152 | AQ46: 156 | AR46: 136 | AS46: 168 | AT46: 165 | AU46: 130 | AV46: 144 | AW46: 146 | AX46: =SUM(E46:AW46) -> 6101
B47: 3 | C47: H. GANJAR PRANOWO, S.H., M.I.P. - Prof. Dr. H. M. MAHFUD MD | E47: 60 | F47: 62 | G47: 23 | H47: 39 | I47: 42 | J47: 33 | K47: 14 | L47: 24 | M47: 42 | N47: 22 | O47: 19 | P47: 26 | Q47: 26 | R47: 24 | S47: 37 | T47: 29 | U47: 55 | V47: 30 | W47: 73 | X47: 58 | Y47: 65 | Z47: 35 | AA47: 54 | AB47: 62 | AC47: 46 | AD47: 45 | AE47: 31 | AF47: 64 | AG47: 57 | AH47: 70 | AI47: 41 | AJ47: 43 | AK47: 43 | AL47: 58 | AM47: 45 | AN47: 34 | AO47: 32 | AP47: 59 | AQ47: 52 | AR47: 35 | AS47: 36 | AT47: 41 | AU47: 53 | AV47: 48 | AW47: 54 | AX47: =SUM(E47:AW47) -> 1941
A49: V | B49: DATA SUARA SAH DAN TIDAK SAH
B50: A. | C50: JUMLAH SELURUH SUARA SAH | E50: =SUM(E45:E47) -> 206 | F50: =SUM(F45:F47) -> 228 | G50: =SUM(G45:G47) -> 178 | H50: =SUM(H45:H47) -> 206 | I50: =SUM(I45:I47) -> 212 | J50: =SUM(J45:J47) -> 134 | K50: =SUM(K45:K47) -> 174 | L50: =SUM(L45:L47) -> 221 | ... AW50: =SUM(AW45:AW47) -> 213 | AX50: =SUM(E50:AW50) -> 8914
B51: B. | C51: JUMLAH SUARA TIDAK SAH | E51: 3 | F51: 2 | G51: 2 | H51: 13 | I51: 4 | J51: 3 | K51: 4 | L51: 1 | M51: 3 | N51: 2 | O51: 4 | P51: 3 | Q51: 3 | R51: 8 | S51: 5 | T51: 6 | U51: 5 | V51: 3 | W51: 5 | X51: 7 | Y51: 4 | Z51: 3 | AA51: 5 | AB51: 2 | AC51: 3 | AD51: 3 | AE51: 7 | AF51: 4 | AG51: 8 | AH51: 6 | AI51: 6 | AJ51: 0 | AK51: 7 | AL51: 4 | AM51: 3 | AN51: 5 | AO51: 1 | AP51: 4 | AQ51: 3 | AR51: 5 | AS51: 2 | AT51: 1 | AU51: 2 | AV51: 2 | AW51: 5 | AX51: =SUM(E51:AW51) -> 181
B52: C. | C52: JUMLAH SELURUH SUARA SAH DAN SUARA TIDAK SAH (V.A + V.B) | E52: =SUM(E50:E51) -> 209 | F52: =SUM(F50:F51) -> 230 | G52: =SUM(G50:G51) -> 180 | H52: =SUM(H50:H51) -> 219 | I52: =SUM(I50:I51) -> 216 | J52: =SUM(J50:J51) -> 137 | K52: =SUM(K50:K51) -> 178 | L52: =SUM(L50:L51) -> 222 | ... AW52: =SUM(AW50:AW51) -> 218 | AX52: =SUM(E52:AW52) -> 9095

Sheet TEMUGURUH
C2: Kecamatan | D2: SEMPU
C3: Kabupaten | D3: BANYUWANGI
C4: Provinsi | D4: JAWA TIMUR
C9: Kelurahan | D9: TEMUGURUH
A12: I | B12: DATA PEMILIH DAN PENGGUNAAN HAK PILIH | AL12: JUMLAH AKHIR
A13: A | B13: DATA PEMILIH | E13: TPS 001 | F13: TPS 002 | G13: TPS 003 | H13: TPS 004 | I13: TPS 005 | J13: TPS 006 | K13: TPS 007 | L13: TPS 008 | M13: TPS 009 | N13: TPS 010 | O13: TPS 011 | P13: TPS 012 | Q13: TPS 013 | R13: TPS 014 | S13: TPS 015 | T13: TPS 016 | U13: TPS 017 | V13: TPS 018 | W13: TPS 019 | X13: TPS 020 | Y13: TPS 021 | Z13: TPS 022 | AA13: TPS 023 | AB13: TPS 024 | AC13: TPS 025 | AD13: TPS 026 | AE13: TPS 027 | AF13: TPS 028 | AG13: TPS 029 | AH13: TPS 030 | AI13: TPS 031 | AJ13: TPS 032 | AK13: TPS 033
B14: Jumlah Pemilih dalam Daftar Pemilih Tetap (DPT) | D14: LK | E14: 149 | F14: 118 | G14: 119 | H14: 126 | I14: 112 | J14: 139 | K14: 141 | L14: 143 | M14: 110 | N14: 142 | O14: 114 | P14: 115 | Q14: 119 | R14: 146 | S14: 131 | T14: 105 | U14: 140 | V14: 152 | W14: 136 | X14: 121 | Y14: 108 | Z14: 112 | AA14: 148 | AB14: 143 | AC14: 149 | AD14: 144 | AE14: 146 | AF14: 150 | AG14: 154 | AH14: 146 | AI14: 158 | AJ14: 144 | AK14: 149 | AL14: =SUM(E14:AK14) -> 4429
D15: PR | E15: 136 | F15: 113 | G15: 123 | H15: 137 | I15: 113 | J15: 131 | K15: 142 | L15: 134 | M15: 141 | N15: 150 | O15: 121 | P15: 131 | Q15: 122 | R15: 144 | S15: 117 | T15: 95 | U15: 126 | V15: 138 | W15: 149 | X15: 115 | Y15: 94 | Z15: 117 | AA15: 135 | AB15: 152 | AC15: 150 | AD15: 146 | AE15: 151 | AF15: 145 | AG15: 143 | AH15: 130 | AI15: 137 | AJ15: 147 | AK15: 146 | AL15: =SUM(E15:AK15) -> 4371
D16: JML | E16: =SUM(E14:E15) -> 285 | F16: =SUM(F14:F15) -> 231 | G16: =SUM(G14:G15) -> 242 | H16: =SUM(H14:H15) -> 263 | I16: =SUM(I14:I15) -> 225 | J16: =SUM(J14:J15) -> 270 | K16: =SUM(K14:K15) -> 283 | L16: =SUM(L14:L15) -> 277 | ... AK16: =SUM(AK14:AK15) -> 295 | AL16: =SUM(E16:AK16) -> 8800
A18: B | B18: PENGGUNA HAK PILIH
B19: 1. | C19: Jumlah pengguna hak pilih dalam Daftar Pemilih Tetap (DPT) | D19: LK | E19: 112 | F19: 80 | G19: 88 | H19: 87 | I19: 80 | J19: 96 | K19: 104 | L19: 105 | M19: 81 | N19: 98 | O19: 77 | P19: 80 | Q19: 83 | R19: 86 | S19: 103 | T19: 71 | U19: 93 | V19: 100 | W19: 97 | X19: 68 | Y19: 67 | Z19: 79 | AA19: 105 | AB19: 90 | AC19: 99 | AD19: 146 | AE19: 112 | AF19: 90 | AG19: 118 | AH19: 100 | AI19: 106 | AJ19: 107 | AK19: 117 | AL19: =SUM(E19:AK19) -> 3125
D20: PR | E20: 98 | F20: 87 | G20: 90 | H20: 97 | I20: 81 | J20: 92 | K20: 110 | L20: 98 | M20: 104 | N20: 110 | O20: 99 | P20: 91 | Q20: 92 | R20: 96 | S20: 98 | T20: 76 | U20: 86 | V20: 94 | W20: 110 | X20: 77 | Y20: 75 | Z20: 86 | AA20: 108 | AB20: 106 | AC20: 119 | AD20: 66 | AE20: 128 | AF20: 95 | AG20: 119 | AH20: 95 | AI20: 104 | AJ20: 123 | AK20: 122 | AL20: =SUM(E20:AK20) -> 3232
D21: JML | E21: =SUM(E19:E20) -> 210 | F21: =SUM(F19:F20) -> 167 | G21: =SUM(G19:G20) -> 178 | H21: =SUM(H19:H20) -> 184 | I21: =SUM(I19:I20) -> 161 | J21: =SUM(J19:J20) -> 188 | K21: =SUM(K19:K20) -> 214 | L21: =SUM(L19:L20) -> 203 | ... AK21: =SUM(AK19:AK20) -> 239 | AL21: =SUM(E21:AK21) -> 6357
B22: 2. | C22: Jumlah pengguna hak pilih dalam Daftar Pemilih Tambahan (DPTb) | D22: LK | E22: 0 | F22: 0 | G22: 1 | H22: 0 | I22: 1 | J22: 1 | K22: 1 | L22: 0 | M22: 0 | N22: 0 | O22: 1 | P22: 0 | Q22: 0 | R22: 0 | S22: 0 | T22: 0 | U22: 0 | V22: 0 | W22: 0 | X22: 0 | Y22: 0 | Z22: 0 | AA22: 0 | AB22: 0 | AC22: 1 | AD22: 0 | AE22: 0 | AF22: 0 | AG22: 0 | AH22: 0 | AI22: 1 | AJ22: 0 | AK22: 0 | AL22: =SUM(E22:AK22) -> 7
D23: PR | E23: 0 | F23: 0 | G23: 1 | H23: 2 | I23: 0 | J23: 0 | K23: 0 | L23: 0 | M23: 0 | N23: 1 | O23: 0 | P23: 0 | Q23: 0 | R23: 0 | S23: 0 | T23: 0 | U23: 0 | V23: 0 | W23: 1 | X23: 0 | Y23: 0 | Z23: 1 | AA23: 0 | AB23: 0 | AC23: 0 | AD23: 0 | AE23: 0 | AF23: 0 | AG23: 1 | AH23: 1 | AI23: 0 | AJ23: 0 | AK23: 1 | AL23: =SUM(E23:AK23) -> 9
D24: JML | E24: =SUM(E22:E23) -> 0 | F24: =SUM(F22:F23) -> 0 | G24: =SUM(G22:G23) -> 2 | H24: =SUM(H22:H23) -> 2 | I24: =SUM(I22:I23) -> 1 | J24: =SUM(J22:J23) -> 1 | K24: =SUM(K22:K23) -> 1 | L24: =SUM(L22:L23) -> 0 | ... AK24: =SUM(AK22:AK23) -> 1 | AL24: =SUM(E24:AK24) -> 16
B25: 3. | C25: Jumlah pengguna hak pilih dalam Daftar Pemilih Khusus (DPK) | D25: LK | E25: 0 | F25: 0 | G25: 0 | H25: 1 | I25: 1 | J25: 2 | K25: 1 | L25: 2 | M25: 1 | N25: 1 | O25: 0 | P25: 1 | Q25: 1 | R25: 0 | S25: 1 | T25: 0 | U25: 0 | V25: 0 | W25: 0 | X25: 0 | Y25: 0 | Z25: 2 | AA25: 0 | AB25: 0 | AC25: 0 | AD25: 0 | AE25: 0 | AF25: 0 | AG25: 0 | AH25: 0 | AI25: 0 | AJ25: 2 | AK25: 2 | AL25: =SUM(E25:AK25) -> 18
D26: PR | E26: 0 | F26: 0 | G26: 2 | H26: 0 | I26: 2 | J26: 2 | K26: 1 | L26: 2 | M26: 3 | N26: 4 | O26: 0 | P26: 2 | Q26: 1 | R26: 0 | S26: 1 | T26: 1 | U26: 0 | V26: 0 | W26: 0 | X26: 0 | Y26: 0 | Z26: 2 | AA26: 0 | AB26: 0 | AC26: 0 | AD26: 0 | AE26: 0 | AF26: 0 | AG26: 0 | AH26: 1 | AI26: 0 | AJ26: 2 | AK26: 3 | AL26: =SUM(E26:AK26) -> 29
D27: JML | E27: =SUM(E25:E26) -> 0 | F27: =SUM(F25:F26) -> 0 | G27: =SUM(G25:G26) -> 2 | H27: =SUM(H25:H26) -> 1 | I27: =SUM(I25:I26) -> 3 | J27: =SUM(J25:J26) -> 4 | K27: =SUM(K25:K26) -> 2 | L27: =SUM(L25:L26) -> 4 | ... AK27: =SUM(AK25:AK26) -> 5 | AL27: =SUM(E27:AK27) -> 47
B28: 4. | C28: Jumlah Pengguna Hak Pilih (B.1+B.2+B.3) | D28: LK | E28: =SUM(E19,E22,E25) -> 112 | F28: =SUM(F19,F22,F25) -> 80 | G28: =SUM(G19,G22,G25) -> 89 | H28: =SUM(H19,H22,H25) -> 88 | I28: =SUM(I19,I22,I25) -> 82 | J28: =SUM(J19,J22,J25) -> 99 | K28: =SUM(K19,K22,K25) -> 106 | L28: =SUM(L19,L22,L25) -> 107 | ... AK28: =SUM(AK19,AK22,AK25) -> 119 | AL28: =SUM(E28:AK28) -> 3150
D29: PR | E29: =SUM(E20,E23,E26) -> 98 | F29: =SUM(F20,F23,F26) -> 87 | G29: =SUM(G20,G23,G26) -> 93 | H29: =SUM(H20,H23,H26) -> 99 | I29: =SUM(I20,I23,I26) -> 83 | J29: =SUM(J20,J23,J26) -> 94 | K29: =SUM(K20,K23,K26) -> 111 | L29: =SUM(L20,L23,L26) -> 100 | ... AK29: =SUM(AK20,AK23,AK26) -> 126 | AL29: =SUM(E29:AK29) -> 3270
D30: JML | E30: =SUM(E28:E29) -> 210 | F30: =SUM(F28:F29) -> 167 | G30: =SUM(G28:G29) -> 182 | H30: =SUM(H28:H29) -> 187 | I30: =SUM(I28:I29) -> 165 | J30: =SUM(J28:J29) -> 193 | K30: =SUM(K28:K29) -> 217 | L30: =SUM(L28:L29) -> 207 | ... AK30: =SUM(AK28:AK29) -> 245 | AL30: =SUM(E30:AK30) -> 6420
A32: II | B32: DATA PENGGUNAAN SURAT SUARA
A33: 1 | B33: Jumlah surat suara yang diterima, termasuk surat suara cadangan 2,5% dari DPT | E33: 282 | F33: 228 | G33: 232 | H33: 256 | I33: 222 | J33: 265 | K33: 279 | L33: 272 | M33: 247 | N33: 285 | O33: 227 | P33: 242 | Q33: 235 | R33: 286 | S33: 243 | T33: 202 | U33: 262 | V33: 286 | W33: 280 | X33: 232 | Y33: 200 | Z33: 227 | AA33: 280 | AB33: 281 | AC33: 297 | AD33: 288 | AE33: 293 | AF33: 290 | AG33: 294 | AH33: 272 | AI33: 290 | AJ33: 287 | AK33: 291 | AL33: =SUM(E33:AK33) -> 8653
A34: 2 | B34: Jumlah surat suara yang digunakan | E34: 210 | F34: 167 | G34: 182 | H34: 187 | I34: 165 | J34: 193 | K34: 217 | L34: 207 | M34: 189 | N34: 214 | O34: 177 | P34: 174 | Q34: 177 | R34: 182 | S34: 203 | T34: 148 | U34: 179 | V34: 194 | W34: 208 | X34: 145 | Y34: 142 | Z34: 170 | AA34: 213 | AB34: 196 | AC34: 219 | AD34: 212 | AE34: 240 | AF34: 185 | AG34: 238 | AH34: 197 | AI34: 211 | AJ34: 234 | AK34: 245 | AL34: =SUM(E34:AK34) -> 6420
A35: 3 | B35: Jumlah surat suara dikembalikan oleh pemilih (karena rusak atau keliru coblos) | E35: 0 | F35: 0 | G35: 1 | H35: 0 | I35: 0 | J35: 0 | K35: 1 | L35: 0 | M35: 0 | N35: 0 | O35: 0 | P35: 0 | Q35: 0 | R35: 2 | S35: 0 | T35: 0 | U35: 0 | V35: 2 | W35: 0 | X35: 0 | Y35: 0 | Z35: 0 | AA35: 0 | AB35: 0 | AC35: 0 | AD35: 0 | AE35: 0 | AF35: 1 | AG35: 0 | AH35: 1 | AI35: 5 | AJ35: 0 | AK35: 5 | AL35: =SUM(E35:AK35) -> 18
A36: 4 | B36: Jumlah surat suara yang tidak digunakan/tidak terpakai, termasuk sisa surat suara cadangan | E36: =E33-(E34+E35) -> 72 | F36: =F33-(F34+F35) -> 61 | G36: =G33-(G34+G35) -> 49 | H36: =H33-(H34+H35) -> 69 | I36: =I33-(I34+I35) -> 57 | J36: =J33-(J34+J35) -> 72 | K36: =K33-(K34+K35) -> 61 | L36: =L33-(L34+L35) -> 65 | ... AK36: =AK33-(AK34+AK35) -> 41 | AL36: =SUM(E36:AK36) -> 2215
A38: III | B38: DATA PEMILIH DISABILITAS
B39: Jumlah seluruh Pemilih disabilitas yang menggunakan hak pilih | D39: LK | E39: 0 | F39: 0 | G39: 0 | H39: 0 | I39: 0 | J39: 0 | K39: 1 | L39: 0 | M39: 1 | N39: 0 | O39: 0 | P39: 0 | Q39: 0 | R39: 0 | S39: 0 | T39: 0 | U39: 0 | V39: 0 | W39: 0 | X39: 0 | Y39: 0 | Z39: 1 | AA39: 0 | AB39: 0 | AC39: 0 | AD39: 0 | AE39: 0 | AF39: 2 | AG39: 0 | AH39: 0 | AI39: 0 | AJ39: 0 | AK39: 0 | AL39: =SUM(E39:AK39) -> 5
D40: PR | E40: 0 | F40: 0 | G40: 0 | H40: 0 | I40: 0 | J40: 0 | K40: 0 | L40: 0 | M40: 0 | N40: 0 | O40: 0 | P40: 0 | Q40: 0 | R40: 0 | S40: 0 | T40: 0 | U40: 0 | V40: 0 | W40: 0 | X40: 0 | Y40: 0 | Z40: 0 | AA40: 0 | AB40: 0 | AC40: 0 | AD40: 0 | AE40: 1 | AF40: 1 | AG40: 0 | AH40: 0 | AI40: 0 | AJ40: 0 | AK40: 0 | AL40: =SUM(E40:AK40) -> 2
D41: JML | E41: =SUM(E39:E40) -> 0 | F41: =SUM(F39:F40) -> 0 | G41: =SUM(G39:G40) -> 0 | H41: =SUM(H39:H40) -> 0 | I41: =SUM(I39:I40) -> 0 | J41: =SUM(J39:J40) -> 0 | K41: =SUM(K39:K40) -> 1 | L41: =SUM(L39:L40) -> 0 | ... AK41: =SUM(AK39:AK40) -> 0 | AL41: =SUM(E41:AK41) -> 7
A43: IV | B43: DATA RINCIAN PEROLEHAN SUARA PASANGAN CALON BUPATI DAN WAKIL BUPATI
A44: NOMOR DAN NAMA CALON
B45: 1 | C45: H. ANIES RASYID BASWEDAN, Ph.D. - Dr. (H.C.) H. A. MUHAIMIN ISKANDAR | E45: 7 | F45: 7 | G45: 44 | H45: 49 | I45: 22 | J45: 26 | K45: 29 | L45: 31 | M45: 28 | N45: 47 | O45: 55 | P45: 26 | Q45: 28 | R45: 23 | S45: 9 | T45: 14 | U45: 23 | V45: 16 | W45: 16 | X45: 12 | Y45: 13 | Z45: 25 | AA45: 12 | AB45: 17 | AC45: 14 | AD45: 13 | AE45: 18 | AF45: 8 | AG45: 8 | AH45: 11 | AI45: 8 | AJ45: 6 | AK45: 10 | AL45: =SUM(E45:AK45) -> 675
B46: 2 | C46: H. PRABOWO SUBIANTO - GIBRAN RAKABUMING RAKA | E46: 162 | F46: 124 | G46: 111 | H46: 105 | I46: 121 | J46: 144 | K46: 145 | L46: 160 | M46: 136 | N46: 137 | O46: 100 | P46: 126 | Q46: 105 | R46: 135 | S46: 158 | T46: 112 | U46: 145 | V46: 154 | W46: 151 | X46: 108 | Y46: 105 | Z46: 118 | AA46: 180 | AB46: 146 | AC46: 159 | AD46: 162 | AE46: 169 | AF46: 128 | AG46: 195 | AH46: 143 | AI46: 159 | AJ46: 198 | AK46: 196 | AL46: =SUM(E46:AK46) -> 4697
B47: 3 | C47: H. GANJAR PRANOWO, S.H., M.I.P. - Prof. Dr. H. M. MAHFUD MD | E47: 33 | F47: 33 | G47: 25 | H47: 31 | I47: 20 | J47: 19 | K47: 36 | L47: 16 | M47: 21 | N47: 23 | O47: 17 | P47: 21 | Q47: 35 | R47: 22 | S47: 33 | T47: 14 | U47: 11 | V47: 17 | W47: 38 | X47: 24 | Y47: 17 | Z47: 23 | AA47: 16 | AB47: 30 | AC47: 42 | AD47: 35 | AE47: 50 | AF47: 49 | AG47: 29 | AH47: 38 | AI47: 37 | AJ47: 19 | AK47: 24 | AL47: =SUM(E47:AK47) -> 898
A49: V | B49: DATA SUARA SAH DAN TIDAK SAH
B50: A. | C50: JUMLAH SELURUH SUARA SAH | E50: =SUM(E45:E47) -> 202 | F50: =SUM(F45:F47) -> 164 | G50: =SUM(G45:G47) -> 180 | H50: =SUM(H45:H47) -> 185 | I50: =SUM(I45:I47) -> 163 | J50: =SUM(J45:J47) -> 189 | K50: =SUM(K45:K47) -> 210 | L50: =SUM(L45:L47) -> 207 | ... AK50: =SUM(AK45:AK47) -> 230 | AL50: =SUM(E50:AK50) -> 6270
B51: B. | C51: JUMLAH SUARA TIDAK SAH | E51: 8 | F51: 3 | G51: 2 | H51: 2 | I51: 2 | J51: 4 | K51: 7 | L51: 0 | M51: 4 | N51: 7 | O51: 5 | P51: 1 | Q51: 9 | R51: 2 | S51: 3 | T51: 8 | U51: 0 | V51: 7 | W51: 3 | X51: 1 | Y51: 7 | Z51: 4 | AA51: 5 | AB51: 3 | AC51: 4 | AD51: 2 | AE51: 3 | AF51: 0 | AG51: 6 | AH51: 5 | AI51: 7 | AJ51: 11 | AK51: 15 | AL51: =SUM(E51:AK51) -> 150
B52: C. | C52: JUMLAH SELURUH SUARA SAH DAN SUARA TIDAK SAH (V.A + V.B) | E52: =SUM(E50:E51) -> 210 | F52: =SUM(F50:F51) -> 167 | G52: =SUM(G50:G51) -> 182 | H52: =SUM(H50:H51) -> 187 | I52: =SUM(I50:I51) -> 165 | J52: =SUM(J50:J51) -> 193 | K52: =SUM(K50:K51) -> 217 | L52: =SUM(L50:L51) -> 207 | ... AK52: =SUM(AK50:AK51) -> 245 | AL52: =SUM(E52:AK52) -> 6420

Sheet GENDOH
C2: Kecamatan | D2: SEMPU
C3: Kabupaten | D3: BANYUWANGI
C4: Provinsi | D4: JAWA TIMUR
C9: Kelurahan | D9: GENDOH
A12: I | B12: DATA PEMILIH DAN PENGGUNAAN HAK PILIH | AG12: JUMLAH AKHIR
A13: A | B13: DATA PEMILIH | E13: TPS 001 | F13: TPS 002 | G13: TPS 003 | H13: TPS 004 | I13: TPS 005 | J13: TPS 006 | K13: TPS 007 | L13: TPS 008 | M13: TPS 009 | N13: TPS 010 | O13: TPS 011 | P13: TPS 012 | Q13: TPS 013 | R13: TPS 014 | S13: TPS 015 | T13: TPS 016 | U13: TPS 017 | V13: TPS 018 | W13: TPS 019 | X13: TPS 020 | Y13: TPS 021 | Z13: TPS 022 | AA13: TPS 023 | AB13: TPS 024 | AC13: TPS 025 | AD13: TPS 026 | AE13: TPS 027 | AF13: TPS 028
B14: Jumlah Pemilih dalam Daftar Pemilih Tetap (DPT) | D14: LK | E14: 142 | F14: 136 | G14: 137 | H14: 141 | I14: 144 | J14: 147 | K14: 140 | L14: 128 | M14: 150 | N14: 138 | O14: 139 | P14: 136 | Q14: 140 | R14: 118 | S14: 129 | T14: 151 | U14: 105 | V14: 135 | W14: 147 | X14: 146 | Y14: 112 | Z14: 111 | AA14: 96 | AB14: 129 | AC14: 139 | AD14: 126 | AE14: 107 | AF14: 133 | AG14: =SUM(E14:AF14) -> 3702
D15: PR | E15: 153 | F15: 155 | G15: 148 | H15: 139 | I15: 144 | J15: 137 | K15: 137 | L15: 148 | M15: 143 | N15: 146 | O15: 133 | P15: 153 | Q15: 148 | R15: 121 | S15: 150 | T15: 142 | U15: 132 | V15: 137 | W15: 141 | X15: 130 | Y15: 132 | Z15: 113 | AA15: 96 | AB15: 149 | AC15: 144 | AD15: 135 | AE15: 96 | AF15: 121 | AG15: =SUM(E15:AF15) -> 3823
D16: JML | E16: =SUM(E14:E15) -> 295 | F16: =SUM(F14:F15) -> 291 | G16: =SUM(G14:G15) -> 285 | H16: =SUM(H14:H15) -> 280 | I16: =SUM(I14:I15) -> 288 | J16: =SUM(J14:J15) -> 284 | K16: =SUM(K14:K15) -> 277 | L16: =SUM(L14:L15) -> 276 | ... AF16: =SUM(AF14:AF15) -> 254 | AG16: =SUM(E16:AF16) -> 7525
A18: B | B18: PENGGUNA HAK PILIH
B19: 1. | C19: Jumlah pengguna hak pilih dalam Daftar Pemilih Tetap (DPT) | D19: LK | E19: 100 | F19: 104 | G19: 96 | H19: 81 | I19: 88 | J19: 102 | K19: 87 | L19: 84 | M19: 102 | N19: 106 | O19: 98 | P19: 79 | Q19: 99 | R19: 80 | S19: 87 | T19: 101 | U19: 72 | V19: 83 | W19: 104 | X19: 105 | Y19: 82 | Z19: 68 | AA19: 69 | AB19: 78 | AC19: 93 | AD19: 94 | AE19: 73 | AF19: 101 | AG19: =SUM(E19:AF19) -> 2516
D20: PR | E20: 107 | F20: 126 | G20: 117 | H20: 109 | I20: 101 | J20: 98 | K20: 100 | L20: 97 | M20: 113 | N20: 120 | O20: 96 | P20: 102 | Q20: 106 | R20: 95 | S20: 116 | T20: 101 | U20: 90 | V20: 102 | W20: 104 | X20: 103 | Y20: 99 | Z20: 78 | AA20: 74 | AB20: 94 | AC20: 105 | AD20: 104 | AE20: 77 | AF20: 95 | AG20: =SUM(E20:AF20) -> 2829
D21: JML | E21: =SUM(E19:E20) -> 207 | F21: =SUM(F19:F20) -> 230 | G21: =SUM(G19:G20) -> 213 | H21: =SUM(H19:H20) -> 190 | I21: =SUM(I19:I20) -> 189 | J21: =SUM(J19:J20) -> 200 | K21: =SUM(K19:K20) -> 187 | L21: =SUM(L19:L20) -> 181 | ... AF21: =SUM(AF19:AF20) -> 196 | AG21: =SUM(E21:AF21) -> 5345
