Workbook

Sheet PPWP
C8: Kecamatan | D8: KALIBARU
C9: Kabupaten | D9: BANYUWANGI
C10: Provinsi | D10: JAWA TIMUR
A12: I | B12: DATA PEMILIH DAN PENGGUNAAN HAK PILIH | E12: JUMLAH AKHIR
A13: A | B13: DATA PEMILIH
B14: Jumlah Pemilih dalam Daftar Pemilih Tetap (DPT) | D14: LK | E14: =BANYUANYAR!AF14+KAJARHARJO!AY14+'KALIBARU KULON'!AF14+'KALIBARU MANIS'!AK14+'KALIBARU WETAN'!AU14+KEBONREJO!AJ14 -> 22324
D15: PR | E15: =BANYUANYAR!AF15+KAJARHARJO!AY15+'KALIBARU KULON'!AF15+'KALIBARU MANIS'!AK15+'KALIBARU WETAN'!AU15+KEBONREJO!AJ15 -> 22867
D16: JML | E16: =SUM(E14:E15) -> 45191
A18: B | B18: PENGGUNA HAK PILIH
B19: 1. | C19: Jumlah pengguna hak pilih dalam Daftar Pemilih Tetap (DPT) | D19: LK | E19: =BANYUANYAR!AF19+KAJARHARJO!AY19+'KALIBARU KULON'!AF19+'KALIBARU MANIS'!AK19+'KALIBARU WETAN'!AU19+KEBONREJO!AJ19 -> 16053
D20: PR | E20: =BANYUANYAR!AF20+KAJARHARJO!AY20+'KALIBARU KULON'!AF20+'KALIBARU MANIS'!AK20+'KALIBARU WETAN'!AU20+KEBONREJO!AJ20 -> 17970
D21: JML | E21: =SUM(E19:E20) -> 34023
B22: 2. | C22: Jumlah pengguna hak pilih dalam Daftar Pemilih Tambahan (DPTb) | D22: LK | E22: =BANYUANYAR!AF22+KAJARHARJO!AY22+'KALIBARU KULON'!AF22+'KALIBARU MANIS'!AK22+'KALIBARU WETAN'!AU22+KEBONREJO!AJ22 -> 109
D23: PR | E23: =BANYUANYAR!AF23+KAJARHARJO!AY23+'KALIBARU KULON'!AF23+'KALIBARU MANIS'!AK23+'KALIBARU WETAN'!AU23+KEBONREJO!AJ23 -> 90
D24: JML | E24: =SUM(E22:E23) -> 199
B25: 3. | C25: Jumlah pengguna hak pilih dalam Daftar Pemilih Khusus (DPK) | D25: LK | E25: =BANYUANYAR!AF25+KAJARHARJO!AY25+'KALIBARU KULON'!AF25+'KALIBARU MANIS'!AK25+'KALIBARU WETAN'!AU25+KEBONREJO!AJ25 -> 178
D26: PR | E26: =BANYUANYAR!AF26+KAJARHARJO!AY26+'KALIBARU KULON'!AF26+'KALIBARU MANIS'!AK26+'KALIBARU WETAN'!AU26+KEBONREJO!AJ26 -> 204
D27: JML | E27: =SUM(E25:E26) -> 382
B28: 4. | C28: Jumlah Pengguna Hak Pilih (B.1+B.2+B.3) | D28: LK | E28: =E19+E22+E25 -> 16340
D29: PR | E29: =E20+E23+E26 -> 18264
D30: JML | E30: =SUM(E28:E29) -> 34604
A32: II | B32: DATA PENGGUNAAN SURAT SUARA
A33: 1 | B33: Jumlah surat suara yang diterima, termasuk surat suara cadangan 2,5% dari DPT | E33: =BANYUANYAR!AF33+KAJARHARJO!AY33+'KALIBARU KULON'!AF33+'KALIBARU MANIS'!AK33+'KALIBARU WETAN'!AU33+KEBONREJO!AJ33 -> 46091
A34: 2 | B34: Jumlah surat suara yang digunakan | E34: =BANYUANYAR!AF34+KAJARHARJO!AY34+'KALIBARU KULON'!AF34+'KALIBARU MANIS'!AK34+'KALIBARU WETAN'!AU34+KEBONREJO!AJ34 -> 34605
A35: 3 | B35: Jumlah surat suara dikembalikan oleh pemilih (karena rusak atau keliru coblos) | E35: =BANYUANYAR!AF35+KAJARHARJO!AY35+'KALIBARU KULON'!AF35+'KALIBARU MANIS'!AK35+'KALIBARU WETAN'!AU35+KEBONREJO!AJ35 -> 50
A36: 4 | B36: Jumlah surat suara yang tidak digunakan/tidak terpakai, termasuk sisa surat suara cadangan | E36: =E33-(E34+E35) -> 11436
A38: III | B38: DATA PEMILIH DISABILITAS
B39: Jumlah seluruh Pemilih disabilitas yang menggunakan hak pilih | D39: LK | E39: =BANYUANYAR!AF39+KAJARHARJO!AY39+'KALIBARU KULON'!AF39+'KALIBARU MANIS'!AK39+'KALIBARU WETAN'!AU39+KEBONREJO!AJ39 -> 47
D40: PR | E40: =BANYUANYAR!AF40+KAJARHARJO!AY40+'KALIBARU KULON'!AF40+'KALIBARU MANIS'!AK40+'KALIBARU WETAN'!AU40+KEBONREJO!AJ40 -> 48
D41: JML | E41: =SUM(E39:E40) -> 95
A43: IV | B43: DATA RINCIAN PEROLEHAN SUARA PASANGAN CALON BUPATI DAN WAKIL BUPATI
A44: NOMOR DAN NAMA CALON
B45: 1 | C45: H. ANIES RASYID BASWEDAN, Ph.D. - Dr. (H.C.) H. A. MUHAIMIN ISKANDAR | E45: =BANYUANYAR!AF45+KAJARHARJO!AY45+'KALIBARU KULON'!AF45+'KALIBARU MANIS'!AK45+'KALIBARU WETAN'!AU45+KEBONREJO!AJ45 -> 5673
B46: 2 | C46: H. PRABOWO SUBIANTO - GIBRAN RAKABUMING RAKA | E46: =BANYUANYAR!AF46+KAJARHARJO!AY46+'KALIBARU KULON'!AF46+'KALIBARU MANIS'!AK46+'KALIBARU WETAN'!AU46+KEBONREJO!AJ46 -> 22219
B47: 3 | C47: H. GANJAR PRANOWO, S.H., M.I.P. - Prof. Dr. H. M. MAHFUD MD | E47: =BANYUANYAR!AF47+KAJARHARJO!AY47+'KALIBARU KULON'!AF47+'KALIBARU MANIS'!AK47+'KALIBARU WETAN'!AU47+KEBONREJO!AJ47 -> 4495
A49: V | B49: DATA SUARA SAH DAN TIDAK SAH
B50: A. | C50: JUMLAH SELURUH SUARA SAH | E50: =BANYUANYAR!AF50+KAJARHARJO!AY50+'KALIBARU KULON'!AF50+'KALIBARU MANIS'!AK50+'KALIBARU WETAN'!AU50+KEBONREJO!AJ50 -> 32385
B51: B. | C51: JUMLAH SUARA TIDAK SAH | E51: =BANYUANYAR!AF51+KAJARHARJO!AY51+'KALIBARU KULON'!AF51+'KALIBARU MANIS'!AK51+'KALIBARU WETAN'!AU51+KEBONREJO!AJ51 -> 990
B52: C. | C52: JUMLAH SELURUH SUARA SAH DAN SUARA TIDAK SAH (V.A + V.B) | E52: =SUM(E50:E51) -> 33375

Sheet BANYUANYAR
C2: Kecamatan | D2: KAKLIBARU
C3: Kabupaten | D3: BANYUWANGI
C4: Provinsi | D4: JAWA TIMUR
C9: Kelurahan | D9: BANYUANYAR
A12: I | B12: DATA PEMILIH DAN PENGGUNAAN HAK PILIH | AF12: JUMLAH AKHIR
A13: A | B13: DATA PEMILIH | E13: TPS 001 | F13: TPS 002 | G13: TPS 003 | H13: TPS 004 | I13: TPS 005 | J13: TPS 006 | K13: TPS 007 | L13: TPS 008 | M13: TPS 009 | N13: TPS 010 | O13: TPS 011 | P13: TPS 012 | Q13: TPS 013 | R13: TPS 014 | S13: TPS 015 | T13: TPS 016 | U13: TPS 017 | V13: TPS 018 | W13: TPS 019 | X13: TPS 020 | Y13: TPS 021 | Z13: TPS 022 | AA13: TPS 023 | AB13: TPS 024 | AC13: TPS 025 | AD13: TPS 026 | AE13: TPS 027
B14: Jumlah Pemilih dalam Daftar Pemilih Tetap (DPT) | D14: LK | E14: 132 | F14: 144 | G14: 127 | H14: 133 | I14: 128 | J14: 153 | K14: 138 | L14: 139 | M14: 144 | N14: 151 | O14: 120 | P14: 109 | Q14: 156 | R14: 137 | S14: 148 | AF14: =SUM(E14:AE14) -> 2059
D15: PR | E15: 159 | F15: 140 | G15: 142 | H15: 148 | I15: 125 | J15: 145 | K15: 136 | L15: 130 | M15: 133 | N15: 139 | O15: 137 | P15: 114 | Q15: 122 | R15: 154 | S15: 134 | AF15: =SUM(E15:AE15) -> 2058
D16: JML | E16: =SUM(E14:E15) -> 291 | F16: =SUM(F14:F15) -> 284 | G16: =SUM(G14:G15) -> 269 | H16: =SUM(H14:H15) -> 281 | I16: =SUM(I14:I15) -> 253 | J16: =SUM(J14:J15) -> 298 | K16: =SUM(K14:K15) -> 274 | L16: =SUM(L14:L15) -> 269 | ... AE16: =SUM(AE14:AE15) -> 0 | AF16: =SUM(E16:AE16) -> 4117
A18: B | B18: PENGGUNA HAK PILIH
B19: 1. | C19: Jumlah pengguna hak pilih dalam Daftar Pemilih Tetap (DPT) | D19: LK | E19: 114 | F19: 116 | G19: 106 | H19: 104 | I19: 85 | J19: 113 | K19: 107 | L19: 110 | M19: 106 | N19: 118 | O19: 91 | P19: 95 | Q19: 124 | R19: 116 | S19: 115 | AF19: =SUM(E19:AE19) -> 1620
D20: PR | E20: 125 | F20: 117 | G20: 118 | H20: 116 | I20: 97 | J20: 117 | K20: 116 | L20: 112 | M20: 106 | N20: 115 | O20: 111 | P20: 107 | Q20: 108 | R20: 129 | S20: 112 | AF20: =SUM(E20:AE20) -> 1706
D21: JML | E21: =SUM(E19:E20) -> 239 | F21: =SUM(F19:F20) -> 233 | G21: =SUM(G19:G20) -> 224 | H21: =SUM(H19:H20) -> 220 | I21: =SUM(I19:I20) -> 182 | J21: =SUM(J19:J20) -> 230 | K21: =SUM(K19:K20) -> 223 | L21: =SUM(L19:L20) -> 222 | ... AE21: =SUM(AE19:AE20) -> 0 | AF21: =SUM(E21:AE21) -> 3326
B22: 2. | C22: Jumlah pengguna hak pilih dalam Daftar Pemilih Tambahan (DPTb) | D22: LK | E22: 0 | F22: 0 | G22: 0 | H22: 1 | I22: 0 | J22: 0 | K22: 0 | L22: 0 | M22: 0 | N22: 1 | O22: 0 | P22: 0 | Q22: 0 | R22: 1 | S22: 0 | AF22: =SUM(E22:AE22) -> 3
D23: PR | E23: 1 | F23: 2 | G23: 1 | H23: 2 | I23: 1 | J23: 1 | K23: 1 | L23: 1 | M23: 1 | N23: 0 | O23: 1 | P23: 1 | Q23: 1 | R23: 0 | S23: 1 | AF23: =SUM(E23:AE23) -> 15
D24: JML | E24: =SUM(E22:E23) -> 1 | F24: =SUM(F22:F23) -> 2 | G24: =SUM(G22:G23) -> 1 | H24: =SUM(H22:H23) -> 3 | I24: =SUM(I22:I23) -> 1 | J24: =SUM(J22:J23) -> 1 | K24: =SUM(K22:K23) -> 1 | L24: =SUM(L22:L23) -> 1 | ... AE24: =SUM(AE22:AE23) -> 0 | AF24: =SUM(E24:AE24) -> 18
B25: 3. | C25: Jumlah pengguna hak pilih dalam Daftar Pemilih Khusus (DPK) | D25: LK | E25: 3 | F25: 0 | G25: 1 | H25: 0 | I25: 0 | J25: 0 | K25: 0 | L25: 0 | M25: 0 | N25: 1 | O25: 0 | P25: 0 | Q25: 0 | R25: 0 | S25: 0 | AF25: =SUM(E25:AE25) -> 5
D26: PR | E26: 0 | F26: 0 | G26: 2 | H26: 0 | I26: 0 | J26: 2 | K26: 1 | L26: 0 | M26: 0 | N26: 1 | O26: 0 | P26: 0 | Q26: 0 | R26: 1 | S26: 1 | AF26: =SUM(E26:AE26) -> 8
D27: JML | E27: =SUM(E25:E26) -> 3 | F27: =SUM(F25:F26) -> 0 | G27: =SUM(G25:G26) -> 3 | H27: =SUM(H25:H26) -> 0 | I27: =SUM(I25:I26) -> 0 | J27: =SUM(J25:J26) -> 2 | K27: =SUM(K25:K26) -> 1 | L27: =SUM(L25:L26) -> 0 | ... AE27: =SUM(AE25:AE26) -> 0 | AF27: =SUM(E27:AE27) -> 13
B28: 4. | C28: Jumlah Pengguna Hak Pilih (B.1+B.2+B.3) | D28: LK | E28: =SUM(E19,E22,E25) -> 117 | F28: =SUM(F19,F22,F25) -> 116 | G28: =SUM(G19,G22,G25) -> 107 | H28: =SUM(H19,H22,H25) -> 105 | I28: =SUM(I19,I22,I25) -> 85 | J28: =SUM(J19,J22,J25) -> 113 | K28: =SUM(K19,K22,K25) -> 107 | L28: =SUM(L19,L22,L25) -> 110 | ... AE28: =SUM(AE19,AE22,AE25) -> 0 | AF28: =SUM(E28:AE28) -> 1628
D29: PR | E29: =SUM(E20,E23,E26) -> 126 | F29: =SUM(F20,F23,F26) -> 119 | G29: =SUM(G20,G23,G26) -> 121 | H29: =SUM(H20,H23,H26) -> 118 | I29: =SUM(I20,I23,I26) -> 98 | J29: =SUM(J20,J23,J26) -> 120 | K29: =SUM(K20,K23,K26) -> 118 | L29: =SUM(L20,L23,L26) -> 113 | ... AE29: =SUM(AE20,AE23,AE26) -> 0 | AF29: =SUM(E29:AE29) -> 1729
D30: JML | E30: =SUM(E28:E29) -> 243 | F30: =SUM(F28:F29) -> 235 | G30: =SUM(G28:G29) -> 228 | H30: =SUM(H28:H29) -> 223 | I30: =SUM(I28:I29) -> 183 | J30: =SUM(J28:J29) -> 233 | K30: =SUM(K28:K29) -> 225 | L30: =SUM(L28:L29) -> 223 | ... AE30: =SUM(AE28:AE29) -> 0 | AF30: =SUM(E30:AE30) -> 3357
A32: II | B32: DATA PENGGUNAAN SURAT SUARA
A33: 1 | B33: Jumlah surat suara yang diterima, termasuk surat suara cadangan 2,5% dari DPT | E33: 297 | F33: 290 | G33: 275 | H33: 287 | I33: 261 | J33: 303 | K33: 279 | L33: 275 | M33: 277 | N33: 295 | O33: 265 | P33: 228 | Q33: 287 | R33: 296 | S33: 287 | AF33: =SUM(E33:AE33) -> 4202
A34: 2 | B34: Jumlah surat suara yang digunakan | E34: 243 | F34: 235 | G34: 228 | H34: 223 | I34: 183 | J34: 233 | K34: 225 | L34: 223 | M34: 213 | N34: 236 | O34: 203 | P34: 203 | Q34: 233 | R34: 247 | S34: 229 | AF34: =SUM(E34:AE34) -> 3357
A35: 3 | B35: Jumlah surat suara dikembalikan oleh pemilih (karena rusak atau keliru coblos) | E35: 1 | F35: 0 | G35: 1 | H35: 0 | I35: 0 | J35: 0 | K35: 1 | L35: 0 | M35: 0 | N35: 0 | O35: 0 | P35: 0 | Q35: 0 | R35: 0 | S35: 1 | AF35: =SUM(E35:AE35) -> 4
A36: 4 | B36: Jumlah surat suara yang tidak digunakan/tidak terpakai, termasuk sisa surat suara cadangan | E36: =E33-(E34+E35) -> 53 | F36: =F33-(F34+F35) -> 55 | G36: =G33-(G34+G35) -> 46 | H36: =H33-(H34+H35) -> 64 | I36: =I33-(I34+I35) -> 78 | J36: =J33-(J34+J35) -> 70 | K36: =K33-(K34+K35) -> 53 | L36: =L33-(L34+L35) -> 52 | ... AE36: =AE33-(AE34+AE35) -> 0 | AF36: =SUM(E36:AE36) -> 841
A38: III | B38: DATA PEMILIH DISABILITAS
B39: Jumlah seluruh Pemilih disabilitas yang menggunakan hak pilih | D39: LK | E39: 0 | F39: 0 | G39: 1 | H39: 0 | I39: 0 | J39: 0 | K39: 0 | L39: 0 | M39: 0 | N39: 0 | O39: 1 | P39: 0 | Q39: 0 | R39: 0 | S39: 1 | AF39: =SUM(E39:AE39) -> 3
D40: PR | E40: 1 | F40: 0 | G40: 0 | H40: 0 | I40: 0 | J40: 0 | K40: 0 | L40: 0 | M40: 0 | N40: 0 | O40: 0 | P40: 0 | Q40: 0 | R40: 0 | S40: 0 | AF40: =SUM(E40:AE40) -> 1
D41: JML | E41: =SUM(E39:E40) -> 1 | F41: =SUM(F39:F40) -> 0 | G41: =SUM(G39:G40) -> 1 | H41: =SUM(H39:H40) -> 0 | I41: =SUM(I39:I40) -> 0 | J41: =SUM(J39:J40) -> 0 | K41: =SUM(K39:K40) -> 0 | L41: =SUM(L39:L40) -> 0 | ... AE41: =SUM(AE39:AE40) -> 0 | AF41: =SUM(E41:AE41) -> 4
A43: IV | B43: DATA RINCIAN PEROLEHAN SUARA PASANGAN CALON BUPATI DAN WAKIL BUPATI
A44: NOMOR DAN NAMA CALON
B45: 1 | C45: H. ANIES RASYID BASWEDAN, Ph.D. - Dr. (H.C.) H. A. MUHAIMIN ISKANDAR | E45: 32 | F45: 38 | G45: 70 | H45: 64 | I45: 48 | J45: 73 | K45: 38 | L45: 42 | M45: 29 | N45: 19 | O45: 61 | P45: 27 | Q45: 72 | R45: 96 | S45: 107 | T45: 45 | U45: 53 | V45: 24 | W45: 52 | X45: 13 | Y45: 12 | Z45: 44 | AA45: 30 | AB45: 64 | AC45: 59 | AD45: 62 | AE45: 49 | AF45: =SUM(E45:AE45) -> 1323
B46: 2 | C46: H. PRABOWO SUBIANTO - GIBRAN RAKABUMING RAKA | E46: 144 | F46: 109 | G46: 127 | H46: 117 | I46: 92 | J46: 114 | K46: 143 | L46: 141 | M46: 130 | N46: 151 | O46: 103 | P46: 162 | Q46: 126 | R46: 109 | S46: 88 | T46: 144 | U46: 77 | V46: 55 | W46: 110 | X46: 87 | Y46: 74 | Z46: 111 | AA46: 102 | AB46: 103 | AC46: 119 | AD46: 84 | AE46: 80 | AF46: =SUM(E46:AE46) -> 3002
B47: 3 | C47: H. GANJAR PRANOWO, S.H., M.I.P. - Prof. Dr. H. M. MAHFUD MD | E47: 57 | F47: 74 | G47: 27 | H47: 32 | I47: 33 | J47: 40 | K47: 34 | L47: 34 | M47: 49 | N47: 56 | O47: 24 | P47: 13 | Q47: 22 | R47: 27 | S47: 24 | T47: 34 | U47: 31 | V47: 6 | W47: 41 | X47: 30 | Y47: 22 | Z47: 21 | AA47: 9 | AB47: 16 | AC47: 11 | AD47: 20 | AE47: 12 | AF47: =SUM(E47:AE47) -> 799
A49: V | B49: DATA SUARA SAH DAN TIDAK SAH
B50: A. | C50: JUMLAH SELURUH SUARA SAH | E50: =SUM(E45:E47) -> 233 | F50: =SUM(F45:F47) -> 221 | G50: =SUM(G45:G47) -> 224 | H50: =SUM(H45:H47) -> 213 | I50: =SUM(I45:I47) -> 173 | J50: =SUM(J45:J47) -> 227 | K50: =SUM(K45:K47) -> 215 | L50: =SUM(L45:L47) -> 217 | ... AE50: =SUM(AE45:AE47) -> 141 | AF50: =SUM(E50:AE50) -> 5124
B51: B. | C51: JUMLAH SUARA TIDAK SAH | E51: 10 | F51: 14 | G51: 4 | H51: 10 | I51: 10 | J51: 6 | K51: 10 | L51: 6 | M51: 5 | N51: 10 | O51: 15 | P51: 1 | Q51: 13 | R51: 13 | S51: 10 | T51: 8 | U51: 5 | V51: 11 | W51: 8 | X51: 3 | Y51: 2 | Z51: 7 | AA51: 6 | AB51: 3 | AC51: 11 | AD51: 2 | AE51: 2 | AF51: =SUM(E51:AE51) -> 205
B52: C. | C52: JUMLAH SELURUH SUARA SAH DAN SUARA TIDAK SAH (V.A + V.B) | E52: =SUM(E50:E51) -> 243 | F52: =SUM(F50:F51) -> 235 | G52: =SUM(G50:G51) -> 228 | H52: =SUM(H50:H51) -> 223 | I52: =SUM(I50:I51) -> 183 | J52: =SUM(J50:J51) -> 233 | K52: =SUM(K50:K51) -> 225 | L52: =SUM(L50:L51) -> 223 | ... AE52: =SUM(AE50:AE51) -> 143 | AF52: =SUM(E52:AE52) -> 5329

Sheet KAJARHARJO
C2: Kecamatan | D2: KAKLIBARU
C3: Kabupaten | D3: BANYUWANGI
C4: Provinsi | D4: JAWA TIMUR
C9: Kelurahan | D9: KAJARHARJO
A12: I | B12: DATA PEMILIH DAN PENGGUNAAN HAK PILIH | AY12: JUMLAH AKHIR
A13: A | B13: DATA PEMILIH | E13: TPS 001 | F13: TPS 002 | G13: TPS 003 | H13: TPS 004 | I13: TPS 005 | J13: TPS 006 | K13: TPS 007 | L13: TPS 008 | M13: TPS 009 | N13: TPS 010 | O13: TPS 011 | P13: TPS 012 | Q13: TPS 013 | R13: TPS 014 | S13: TPS 015 | T13: TPS 016 | U13: TPS 017 | V13: TPS 018 | W13: TPS 019 | X13: TPS 020 | Y13: TPS 021 | Z13: TPS 022 | AA13: TPS 023 | AB13: TPS 024 | AC13: TPS 025 | AD13: TPS 026 | AE13: TPS 027 | AF13: TPS 028 | AG13: TPS 029 | AH13: TPS 030 | AI13: TPS 031 | AJ13: TPS 032 | AK13: TPS 033 | AL13: TPS 034 | AM13: TPS 035 | AN13: TPS 036 | AO13: TPS 037 | AP13: TPS 038 | AQ13: TPS 039 | AR13: TPS 040 | AS13: TPS 041 | AT13: TPS 042 | AU13: TPS 043 | AV13: TPS 044 | AW13: TPS 045 | AX13: TPS 046
B14: Jumlah Pemilih dalam Daftar Pemilih Tetap (DPT) | D14: LK | E14: 141 | F14: 140 | G14: 111 | H14: 122 | I14: 125 | J14: 111 | K14: 135 | L14: 141 | M14: 153 | N14: 142 | O14: 127 | P14: 144 | Q14: 124 | R14: 126 | S14: 116 | T14: 132 | U14: 89 | V14: 132 | W14: 111 | X14: 142 | Y14: 118 | Z14: 127 | AA14: 149 | AB14: 142 | AC14: 125 | AD14: 92 | AE14: 122 | AF14: 129 | AG14: 91 | AH14: 99 | AI14: 86 | AJ14: 65 | AK14: 81 | AL14: 93 | AM14: 68 | AN14: 92 | AO14: 103 | AP14: 143 | AQ14: 98 | AR14: 105 | AS14: 134 | AT14: 113 | AU14: 128 | AV14: 136 | AW14: 86 | AX14: 53 | AY14: =SUM(E14:AX14) -> 5342
D15: PR | E15: 141 | F15: 142 | G15: 104 | H15: 127 | I15: 114 | J15: 125 | K15: 129 | L15: 156 | M15: 139 | N15: 132 | O15: 141 | P15: 150 | Q15: 127 | R15: 134 | S15: 118 | T15: 145 | U15: 94 | V15: 139 | W15: 127 | X15: 154 | Y15: 109 | Z15: 140 | AA15: 148 | AB15: 150 | AC15: 128 | AD15: 99 | AE15: 144 | AF15: 121 | AG15: 96 | AH15: 104 | AI15: 88 | AJ15: 72 | AK15: 86 | AL15: 90 | AM15: 60 | AN15: 98 | AO15: 96 | AP15: 150 | AQ15: 110 | AR15: 115 | AS15: 109 | AT15: 140 | AU15: 125 | AV15: 128 | AW15: 92 | AX15: 69 | AY15: =SUM(E15:AX15) -> 5505
D16: JML | E16: =SUM(E14:E15) -> 282 | F16: =SUM(F14:F15) -> 282 | G16: =SUM(G14:G15) -> 215 | H16: =SUM(H14:H15) -> 249 | I16: =SUM(I14:I15) -> 239 | J16: =SUM(J14:J15) -> 236 | K16: =SUM(K14:K15) -> 264 | L16: =SUM(L14:L15) -> 297 | ... AX16: =SUM(AX14:AX15) -> 122 | AY16: =SUM(E16:AX16) -> 10847
A18: B | B18: PENGGUNA HAK PILIH
B19: 1. | C19: Jumlah pengguna hak pilih dalam Daftar Pemilih Tetap (DPT) | D19: LK | E19: 92 | F19: 98 | G19: 89 | H19: 90 | I19: 87 | J19: 84 | K19: 104 | L19: 108 | M19: 115 | N19: 106 | O19: 101 | P19: 113 | Q19: 95 | R19: 103 | S19: 92 | T19: 91 | U19: 65 | V19: 92 | W19: 77 | X19: 108 | Y19: 87 | Z19: 92 | AA19: 119 | AB19: 104 | AC19: 73 | AD19: 53 | AE19: 85 | AF19: 74 | AG19: 56 | AH19: 52 | AI19: 53 | AJ19: 42 | AK19: 69 | AL19: 63 | AM19: 50 | AN19: 67 | AO19: 73 | AP19: 112 | AQ19: 74 | AR19: 69 | AS19: 108 | AT19: 69 | AU19: 77 | AV19: 89 | AW19: 63 | AX19: 84 | AY19: =SUM(E19:AX19) -> 3867
D20: PR | E20: 114 | F20: 116 | G20: 84 | H20: 106 | I20: 97 | J20: 100 | K20: 108 | L20: 123 | M20: 110 | N20: 100 | O20: 113 | P20: 118 | Q20: 108 | R20: 109 | S20: 97 | T20: 106 | U20: 75 | V20: 104 | W20: 94 | X20: 125 | Y20: 96 | Z20: 108 | AA20: 121 | AB20: 116 | AC20: 101 | AD20: 79 | AE20: 113 | AF20: 92 | AG20: 82 | AH20: 76 | AI20: 70 | AJ20: 57 | AK20: 56 | AL20: 70 | AM20: 54 | AN20: 78 | AO20: 77 | AP20: 127 | AQ20: 85 | AR20: 102 | AS20: 83 | AT20: 101 | AU20: 91 | AV20: 103 | AW20: 76 | AX20: 70 | AY20: =SUM(E20:AX20) -> 4391
D21: JML | E21: =SUM(E19:E20) -> 206 | F21: =SUM(F19:F20) -> 214 | G21: =SUM(G19:G20) -> 173 | H21: =SUM(H19:H20) -> 196 | I21: =SUM(I19:I20) -> 184 | J21: =SUM(J19:J20) -> 184 | K21: =SUM(K19:K20) -> 212 | L21: =SUM(L19:L20) -> 231 | ... AX21: =SUM(AX19:AX20) -> 154 | AY21: =SUM(E21:AX21) -> 8258
B22: 2. | C22: Jumlah pengguna hak pilih dalam Daftar Pemilih Tambahan (DPTb) | D22: LK | E22: 0 | F22: 0 | G22: 0 | H22: 2 | I22: 0 | J22: 0 | K22: 2 | L22: 1 | M22: 0 | N22: 0 | O22: 1 | P22: 1 | Q22: 2 | R22: 1 | S22: 1 | T22: 0 | U22: 0 | V22: 0 | W22: 3 | X22: 0 | Y22: 0 | Z22: 0 | AA22: 1 | AB22: 1 | AC22: 0 | AD22: 1 | AE22: 0 | AF22: 0 | AG22: 2 | AH22: 1 | AI22: 3 | AJ22: 1 | AK22: 1 | AL22: 2 | AM22: 3 | AN22: 1 | AO22: 2 | AP22: 2 | AQ22: 2 | AR22: 1 | AS22: 0 | AT22: 1 | AU22: 1 | AV22: 1 | AW22: 1 | AX22: 3 | AY22: =SUM(E22:AX22) -> 45
D23: PR | E23: 2 | F23: 1 | G23: 1 | H23: 0 | I23: 1 | J23: 1 | K23: 3 | L23: 0 | M23: 1 | N23: 1 | O23: 0 | P23: 0 | Q23: 0 | R23: 0 | S23: 0 | T23: 1 | U23: 1 | V23: 1 | W23: 1 | X23: 0 | Y23: 1 | Z23: 1 | AA23: 0 | AB23: 0 | AC23: 1 | AD23: 2 | AE23: 1 | AF23: 1 | AG23: 0 | AH23: 0 | AI23: 1 | AJ23: 0 | AK23: 0 | AL23: 0 | AM23: 0 | AN23: 1 | AO23: 0 | AP23: 0 | AQ23: 0 | AR23: 0 | AS23: 1 | AT23: 0 | AU23: 1 | AV23: 0 | AW23: 0 | AX23: 3 | AY23: =SUM(E23:AX23) -> 29
D24: JML | E24: =SUM(E22:E23) -> 2 | F24: =SUM(F22:F23) -> 1 | G24: =SUM(G22:G23) -> 1 | H24: =SUM(H22:H23) -> 2 | I24: =SUM(I22:I23) -> 1 | J24: =SUM(J22:J23) -> 1 | K24: =SUM(K22:K23) -> 5 | L24: =SUM(L22:L23) -> 1 | ... AX24: =SUM(AX22:AX23) -> 6 | AY24: =SUM(E24:AX24) -> 74
B25: 3. | C25: Jumlah pengguna hak pilih dalam Daftar Pemilih Khusus (DPK) | D25: LK | E25: 1 | F25: 0 | G25: 2 | H25: 1 | I25: 2 | J25: 0 | K25: 2 | L25: 2 | M25: 0 | N25: 2 | O25: 0 | P25: 1 | Q25: 1 | R25: 0 | S25: 0 | T25: 1 | U25: 1 | V25: 2 | W25: 1 | X25: 3 | Y25: 2 | Z25: 1 | AA25: 0 | AB25: 0 | AC25: 0 | AD25: 0 | AE25: 1 | AF25: 0 | AG25: 0 | AH25: 0 | AI25: 1 | AJ25: 1 | AK25: 2 | AL25: 0 | AM25: 0 | AN25: 2 | AO25: 0 | AP25: 1 | AQ25: 0 | AR25: 1 | AS25: 2 | AT25: 0 | AU25: 0 | AV25: 0 | AW25: 0 | AX25: 4 | AY25: =SUM(E25:AX25) -> 40
D26: PR | E26: 1 | F26: 0 | G26: 5 | H26: 1 | I26: 4 | J26: 0 | K26: 1 | L26: 2 | M26: 0 | N26: 2 | O26: 1 | P26: 0 | Q26: 1 | R26: 2 | S26: 0 | T26: 1 | U26: 1 | V26: 3 | W26: 2 | X26: 1 | Y26: 0 | Z26: 0 | AA26: 0 | AB26: 0 | AC26: 0 | AD26: 0 | AE26: 0 | AF26: 0 | AG26: 0 | AH26: 0 | AI26: 2 | AJ26: 0 | AK26: 1 | AL26: 0 | AM26: 0 | AN26: 0 | AO26: 0 | AP26: 0 | AQ26: 0 | AR26: 2 | AS26: 6 | AT26: 0 | AU26: 0 | AV26: 0 | AW26: 0 | AX26: 4 | AY26: =SUM(E26:AX26) -> 43
D27: JML | E27: =SUM(E25:E26) -> 2 | F27: =SUM(F25:F26) -> 0 | G27: =SUM(G25:G26) -> 7 | H27: =SUM(H25:H26) -> 2 | I27: =SUM(I25:I26) -> 6 | J27: =SUM(J25:J26) -> 0 | K27: =SUM(K25:K26) -> 3 | L27: =SUM(L25:L26) -> 4 | ... AX27: =SUM(AX25:AX26) -> 8 | AY27: =SUM(E27:AX27) -> 83
B28: 4. | C28: Jumlah Pengguna Hak Pilih (B.1+B.2+B.3) | D28: LK | E28: =SUM(E19,E22,E25) -> 93 | F28: =SUM(F19,F22,F25) -> 98 | G28: =SUM(G19,G22,G25) -> 91 | H28: =SUM(H19,H22,H25) -> 93 | I28: =SUM(I19,I22,I25) -> 89 | J28: =SUM(J19,J22,J25) -> 84 | K28: =SUM(K19,K22,K25) -> 108 | L28: =SUM(L19,L22,L25) -> 111 | ... AX28: =SUM(AX19,AX22,AX25) -> 91 | AY28: =SUM(E28:AX28) -> 3952
D29: PR | E29: =SUM(E20,E23,E26) -> 117 | F29: =SUM(F20,F23,F26) -> 117 | G29: =SUM(G20,G23,G26) -> 90 | H29: =SUM(H20,H23,H26) -> 107 | I29: =SUM(I20,I23,I26) -> 102 | J29: =SUM(J20,J23,J26) -> 101 | K29: =SUM(K20,K23,K26) -> 112 | L29: =SUM(L20,L23,L26) -> 125 | ... AX29: =SUM(AX20,AX23,AX26) -> 77 | AY29: =SUM(E29:AX29) -> 4463
D30: JML | E30: =SUM(E28:E29) -> 210 | F30: =SUM(F28:F29) -> 215 | G30: =SUM(G28:G29) -> 181 | H30: =SUM(H28:H29) -> 200 | I30: =SUM(I28:I29) -> 191 | J30: =SUM(J28:J29) -> 185 | K30: =SUM(K28:K29) -> 220 | L30: =SUM(L28:L29) -> 236 | ... AX30: =SUM(AX28:AX29) -> 168 | AY30: =SUM(E30:AX30) -> 8415
A32: II | B32: DATA PENGGUNAAN SURAT SUARA
A33: 1 | B33: Jumlah surat suara yang diterima, termasuk surat suara cadangan 2,5% dari DPT | E33: 288 | F33: 280 | G33: 220 | H33: 254 | I33: 244 | J33: 240 | K33: 270 | L33: 303 | M33: 298 | N33: 283 | O33: 274 | P33: 300 | Q33: 257 | R33: 266 | S33: 239 | T33: 283 | U33: 189 | V33: 278 | W33: 243 | X33: 302 | Y33: 232 | Z33: 272 | AA33: 303 | AB33: 298 | AC33: 259 | AD33: 196 | AE33: 273 | AF33: 255 | AG33: 191 | AH33: 208 | AI33: 178 | AJ33: 140 | AK33: 171 | AL33: 187 | AM33: 132 | AN33: 196 | AO33: 202 | AP33: 299 | AQ33: 214 | AR33: 223 | AS33: 250 | AT33: 259 | AU33: 258 | AV33: 270 | AW33: 182 | AX33: 180 | AY33: =SUM(E33:AX33) -> 11139
A34: 2 | B34: Jumlah surat suara yang digunakan | E34: 210 | F34: 215 | G34: 181 | H34: 200 | I34: 191 | J34: 185 | K34: 220 | L34: 236 | M34: 226 | N34: 211 | O34: 216 | P34: 233 | Q34: 207 | R34: 215 | S34: 190 | T34: 200 | U34: 143 | V34: 202 | W34: 178 | X34: 237 | Y34: 186 | Z34: 202 | AA34: 241 | AB34: 221 | AC34: 175 | AD34: 135 | AE34: 200 | AF34: 167 | AG34: 140 | AH34: 129 | AI34: 130 | AJ34: 101 | AK34: 129 | AL34: 135 | AM34: 107 | AN34: 149 | AO34: 152 | AP34: 242 | AQ34: 161 | AR34: 175 | AS34: 200 | AT34: 171 | AU34: 170 | AV34: 193 | AW34: 140 | AX34: 168 | AY34: =SUM(E34:AX34) -> 8415
A35: 3 | B35: Jumlah surat suara dikembalikan oleh pemilih (karena rusak atau keliru coblos) | E35: 0 | F35: 0 | G35: 0 | H35: 0 | I35: 2 | J35: 0 | K35: 0 | L35: 0 | M35: 1 | N35: 0 | O35: 0 | P35: 3 | Q35: 0 | R35: 1 | S35: 1 | T35: 0 | U35: 0 | V35: 0 | W35: 0 | X35: 0 | Y35: 0 | Z35: 0 | AA35: 0 | AB35: 0 | AC35: 0 | AD35: 0 | AE35: 0 | AF35: 0 | AG35: 0 | AH35: 0 | AI35: 0 | AJ35: 0 | AK35: 0 | AL35: 1 | AM35: 1 | AN35: 0 | AO35: 0 | AP35: 0 | AQ35: 0 | AR35: 0 | AS35: 2 | AT35: 0 | AU35: 0 | AV35: 0 | AW35: 0 | AX35: 0 | AY35: =SUM(E35:AX35) -> 12
A36: 4 | B36: Jumlah surat suara yang tidak digunakan/tidak terpakai, termasuk sisa surat suara cadangan | E36: =E33-(E34+E35) -> 78 | F36: =F33-(F34+F35) -> 65 | G36: =G33-(G34+G35) -> 39 | H36: =H33-(H34+H35) -> 54 | I36: =I33-(I34+I35) -> 51 | J36: =J33-(J34+J35) -> 55 | K36: =K33-(K34+K35) -> 50 | L36: =L33-(L34+L35) -> 67 | ... AX36: =AX33-(AX34+AX35) -> 12 | AY36: =SUM(E36:AX36) -> 2712
A38: III | B38: DATA PEMILIH DISABILITAS
B39: Jumlah seluruh Pemilih disabilitas yang menggunakan hak pilih | D39: LK | E39: 0 | F39: 0 | G39: 0 | H39: 0 | I39: 0 | J39: 0 | K39: 0 | L39: 1 | M39: 0 | N39: 0 | O39: 0 | P39: 0 | Q39: 2 | R39: 0 | S39: 0 | T39: 0 | U39: 0 | V39: 0 | W39: 0 | X39: 0 | Y39: 0 | Z39: 0 | AA39: 0 | AB39: 0 | AC39: 0 | AD39: 0 | AE39: 0 | AF39: 0 | AG39: 0 | AH39: 0 | AI39: 0 | AJ39: 0 | AK39: 1 | AL39: 0 | AM39: 0 | AN39: 0 | AO39: 0 | AP39: 0 | AQ39: 0 | AR39: 0 | AS39: 0 | AT39: 0 | AU39: 0 | AV39: 0 | AW39: 0 | AX39: 0 | AY39: =SUM(E39:AX39) -> 4
D40: PR | E40: 0 | F40: 0 | G40: 0 | H40: 0 | I40: 0 | J40: 0 | K40: 0 | L40: 0 | M40: 0 | N40: 0 | O40: 0 | P40: 0 | Q40: 3 | R40: 0 | S40: 0 | T40: 0 | U40: 0 | V40: 0 | W40: 0 | X40: 0 | Y40: 0 | Z40: 1 | AA40: 0 | AB40: 0 | AC40: 0 | AD40: 0 | AE40: 0 | AF40: 0 | AG40: 0 | AH40: 0 | AI40: 0 | AJ40: 0 | AK40: 2 | AL40: 0 | AM40: 0 | AN40: 0 | AO40: 0 | AP40: 0 | AQ40: 0 | AR40: 1 | AS40: 0 | AT40: 0 | AU40: 0 | AV40: 0 | AW40: 0 | AX40: 0 | AY40: =SUM(E40:AX40) -> 7
D41: JML | E41: =SUM(E39:E40) -> 0 | F41: =SUM(F39:F40) -> 0 | G41: =SUM(G39:G40) -> 0 | H41: =SUM(H39:H40) -> 0 | I41: =SUM(I39:I40) -> 0 | J41: =SUM(J39:J40) -> 0 | K41: =SUM(K39:K40) -> 0 | L41: =SUM(L39:L40) -> 1 | ... AX41: =SUM(AX39:AX40) -> 0 | AY41: =SUM(E41:AX41) -> 11
A43: IV | B43: DATA RINCIAN PEROLEHAN SUARA PASANGAN CALON BUPATI DAN WAKIL BUPATI
A44: NOMOR DAN NAMA CALON
B45: 1 | C45: H. ANIES RASYID BASWEDAN, Ph.D. - Dr. (H.C.) H. A. MUHAIMIN ISKANDAR | E45: 19 | F45: 24 | G45: 15 | H45: 50 | I45: 32 | J45: 31 | K45: 26 | L45: 46 | M45: 39 | N45: 58 | O45: 32 | P45: 39 | Q45: 62 | R45: 51 | S45: 11 | T45: 42 | U45: 39 | V45: 29 | W45: 26 | X45: 40 | Y45: 25 | Z45: 46 | AA45: 27 | AB45: 43 | AC45: 30 | AD45: 14 | AE45: 38 | AF45: 14 | AG45: 39 | AH45: 16 | AI45: 32 | AJ45: 15 | AK45: 20 | AL45: 32 | AM45: 44 | AN45: 41 | AO45: 12 | AP45: 35 | AQ45: 33 | AR45: 52 | AS45: 34 | AT45: 24 | AU45: 32 | AV45: 20 | AW45: 34 | AX45: 29 | AY45: =SUM(E45:AX45) -> 1492
B46: 2 | C46: H. PRABOWO SUBIANTO - GIBRAN RAKABUMING RAKA | E46: 154 | F46: 153 | G46: 144 | H46: 131 | I46: 125 | J46: 127 | K46: 149 | L46: 147 | M46: 160 | N46: 126 | O46: 159 | P46: 146 | Q46: 121 | R46: 137 | S46: 155 | T46: 130 | U46: 91 | V46: 135 | W46: 114 | X46: 159 | Y46: 134 | Z46: 136 | AA46: 189 | AB46: 119 | AC46: 130 | AD46: 95 | AE46: 145 | AF46: 141 | AG46: 82 | AH46: 96 | AI46: 77 | AJ46: 74 | AK46: 99 | AL46: 85 | AM46: 47 | AN46: 59 | AO46: 110 | AP46: 172 | AQ46: 88 | AR46: 125 | AS46: 133 | AT46: 129 | AU46: 124 | AV46: 154 | AW46: 88 | AX46: 94 | AY46: =SUM(E46:AX46) -> 5688
B47: 3 | C47: H. GANJAR PRANOWO, S.H., M.I.P. - Prof. Dr. H. M. MAHFUD MD | E47: 29 | F47: 30 | G47: 16 | H47: 15 | I47: 30 | J47: 22 | K47: 39 | L47: 35 | M47: 23 | N47: 25 | O47: 17 | P47: 39 | Q47: 16 | R47: 19 | S47: 19 | T47: 26 | U47: 8 | V47: 33 | W47: 28 | X47: 31 | Y47: 20 | Z47: 14 | AA47: 9 | AB47: 46 | AC47: 12 | AD47: 23 | AE47: 11 | AF47: 9 | AG47: 10 | AH47: 16 | AI47: 19 | AJ47: 9 | AK47: 9 | AL47: 12 | AM47: 14 | AN47: 42 | AO47: 30 | AP47: 24 | AQ47: 30 | AR47: 4 | AS47: 30 | AT47: 16 | AU47: 7 | AV47: 17 | AW47: 13 | AX47: 21 | AY47: =SUM(E47:AX47) -> 967
A49: V | B49: DATA SUARA SAH DAN TIDAK SAH
B50: A. | C50: JUMLAH SELURUH SUARA SAH | E50: =SUM(E45:E47) -> 202 | F50: =SUM(F45:F47) -> 207 | G50: =SUM(G45:G47) -> 175 | H50: =SUM(H45:H47) -> 196 | I50: =SUM(I45:I47) -> 187 | J50: =SUM(J45:J47) -> 180 | K50: =SUM(K45:K47) -> 214 | L50: =SUM(L45:L47) -> 228 | ... AF50: =SUM(AF45:AF47) -> 164 | AG50: 139 | AH50: =SUM(AH45:AH47) -> 128 | AI50: =SUM(AI45:AI47) -> 128 | AJ50: =SUM(AJ45:AJ47) -> 98 | AK50: =SUM(AK45:AK47) -> 128 | AL50: =SUM(AL45:AL47) -> 129 | AM50: =SUM(AM45:AM47) -> 105 | AN50: =SUM(AN45:AN47) -> 142 | AO50: =SUM(AO45:AO47) -> 152 | ... AX50: =SUM(AX45:AX47) -> 144 | AY50: =SUM(E50:AX50) -> 8155
B51: B. | C51: JUMLAH SUARA TIDAK SAH | E51: 8 | F51: 8 | G51: 6 | H51: 4 | I51: 4 | J51: 5 | K51: 6 | L51: 8 | M51: 4 | N51: 2 | O51: 8 | P51: 9 | Q51: 8 | R51: 8 | S51: 5 | T51: 2 | U51: 5 | V51: 5 | W51: 10 | X51: 7 | Y51: 7 | Z51: 6 | AA51: 16 | AB51: 13 | AC51: 3 | AD51: 3 | AE51: 6 | AF51: 3 | AG51: 1 | AH51: 1 | AI51: 2 | AJ51: 3 | AK51: 1 | AL51: 6 | AM51: 2 | AN51: 7 | AO51: 0 | AP51: 11 | AQ51: 10 | AR51: 7 | AS51: 3 | AT51: 2 | AU51: 7 | AV51: 4 | AW51: 5 | AX51: 21 | AY51: =SUM(E51:AX51) -> 272
B52: C. | C52: JUMLAH SELURUH SUARA SAH DAN SUARA TIDAK SAH (V.A + V.B) | E52: =SUM(E50:E51) -> 210 | F52: =SUM(F50:F51) -> 215 | G52: =SUM(G50:G51) -> 181 | H52: =SUM(H50:H51) -> 200 | I52: =SUM(I50:I51) -> 191 | J52: =SUM(J50:J51) -> 185 | K52: =SUM(K50:K51) -> 220 | L52: =SUM(L50:L51) -> 236 | ... AX52: =SUM(AX50:AX51) -> 165 | AY52: =SUM(E52:AX52) -> 8427

Sheet KALIBARU KULON
C2: Kecamatan | D2: KAKLIBARU
C3: Kabupaten | D3: BANYUWANGI
C4: Provinsi | D4: JAWA TIMUR
C9: Kelurahan | D9: KALIBARU KULON
A12: I | B12: DATA PEMILIH DAN PENGGUNAAN HAK PILIH | AF12: JUMLAH AKHIR
A13: A | B13: DATA PEMILIH | E13: TPS 001 | F13: TPS 002 | G13: TPS 003 | H13: TPS 004 | I13: TPS 005 | J13: TPS 006 | K13: TPS 007 | L13: TPS 008 | M13: TPS 009 | N13: TPS 010 | O13: TPS 011 | P13: TPS 012 | Q13: TPS 013 | R13: TPS 014 | S13: TPS 015 | T13: TPS 016 | U13: TPS 017 | V13: TPS 018 | W13: TPS 019 | X13: TPS 020 | Y13: TPS 021 | Z13: TPS 022 | AA13: TPS 023 | AB13: TPS 024 | AC13: TPS 025 | AD13: TPS 026 | AE13: TPS 027
B14: Jumlah Pemilih dalam Daftar Pemilih Tetap (DPT) | D14: LK | E14: 121 | F14: 105 | G14: 122 | H14: 112 | I14: 100 | J14: 104 | K14: 131 | L14: 115 | M14: 115 | N14: 128 | O14: 137 | P14: 129 | Q14: 142 | R14: 95 | S14: 65 | T14: 145 | U14: 118 | V14: 104 | W14: 104 | X14: 138 | Y14: 100 | Z14: 153 | AA14: 91 | AB14: 98 | AC14: 74 | AD14: 140 | AE14: 125 | AF14: =SUM(E14:AE14) -> 3111
D15: PR | E15: 124 | F15: 131 | G15: 126 | H15: 114 | I15: 113 | J15: 102 | K15: 136 | L15: 139 | M15: 108 | N15: 141 | O15: 146 | P15: 121 | Q15: 157 | R15: 106 | S15: 58 | T15: 153 | U15: 108 | V15: 119 | W15: 113 | X15: 143 | Y15: 104 | Z15: 143 | AA15: 97 | AB15: 95 | AC15: 77 | AD15: 155 | AE15: 136 | AF15: =SUM(E15:AE15) -> 3265
D16: JML | E16: =SUM(E14:E15) -> 245 | F16: =SUM(F14:F15) -> 236 | G16: =SUM(G14:G15) -> 248 | H16: =SUM(H14:H15) -> 226 | I16: =SUM(I14:I15) -> 213 | J16: =SUM(J14:J15) -> 206 | K16: =SUM(K14:K15) -> 267 | L16: =SUM(L14:L15) -> 254 | ... AE16: =SUM(AE14:AE15) -> 261 | AF16: =SUM(E16:AE16) -> 6376
A18: B | B18: PENGGUNA HAK PILIH
B19: 1. | C19: Jumlah pengguna hak pilih dalam Daftar Pemilih Tetap (DPT) | D19: LK | E19: 90 | F19: 86 | G19: 102 | H19: 88 | I19: 76 | J19: 80 | K19: 96 | L19: 85 | M19: 89 | N19: 80 | O19: 96 | P19: 94 | Q19: 103 | R19: 84 | S19: 49 | T19: 101 | U19: 88 | V19: 77 | W19: 87 | X19: 98 | Y19: 75 | Z19: 116 | AA19: 71 | AB19: 65 | AC19: 48 | AD19: 103 | AE19: 82 | AF19: =SUM(E19:AE19) -> 2309
D20: PR | E20: 99 | F20: 110 | G20: 102 | H20: 95 | I20: 94 | J20: 87 | K20: 105 | L20: 118 | M20: 91 | N20: 105 | O20: 108 | P20: 93 | Q20: 118 | R20: 92 | S20: 46 | T20: 136 | U20: 95 | V20: 86 | W20: 91 | X20: 113 | Y20: 83 | Z20: 111 | AA20: 76 | AB20: 76 | AC20: 59 | AD20: 127 | AE20: 117 | AF20: =SUM(E20:AE20) -> 2633
D21: JML | E21: =SUM(E19:E20) -> 189 | F21: =SUM(F19:F20) -> 196 | G21: =SUM(G19:G20) -> 204 | H21: =SUM(H19:H20) -> 183 | I21: =SUM(I19:I20) -> 170 | J21: =SUM(J19:J20) -> 167 | K21: =SUM(K19:K20) -> 201 | L21: =SUM(L19:L20) -> 203 | ... AE21: =SUM(AE19:AE20) -> 199 | AF21: =SUM(E21:AE21) -> 4942
B22: 2. | C22: Jumlah pengguna hak pilih dalam Daftar Pemilih Tambahan (DPTb) | D22: LK | E22: 2 | F22: 0 | G22: 1 | H22: 0 | I22: 1 | J22: 0 | K22: 1 | L22: 1 | M22: 0 | N22: 0 | O22: 0 | P22: 0 | Q22: 0 | R22: 0 | S22: 0 | T22: 0 | U22: 0 | V22: 1 | W22: 0 | X22: 0 | Y22: 1 | Z22: 0 | AA22: 0 | AB22: 0 | AC22: 0 | AD22: 0 | AE22: 1 | AF22: =SUM(E22:AE22) -> 9
D23: PR | E23: 0 | F23: 1 | G23: 0 | H23: 0 | I23: 1 | J23: 0 | K23: 0 | L23: 0 | M23: 0 | N23: 0 | O23: 1 | P23: 1 | Q23: 0 | R23: 0 | S23: 1 | T23: 1 | U23: 0 | V23: 1 | W23: 0 | X23: 0 | Y23: 0 | Z23: 0 | AA23: 0 | AB23: 1 | AC23: 0 | AD23: 0 | AE23: 0 | AF23: =SUM(E23:AE23) -> 8
D24: JML | E24: =SUM(E22:E23) -> 2 | F24: =SUM(F22:F23) -> 1 | G24: =SUM(G22:G23) -> 1 | H24: =SUM(H22:H23) -> 0 | I24: =SUM(I22:I23) -> 2 | J24: =SUM(J22:J23) -> 0 | K24: =SUM(K22:K23) -> 1 | L24: =SUM(L22:L23) -> 1 | ... AE24: =SUM(AE22:AE23) -> 1 | AF24: =SUM(E24:AE24) -> 17
B25: 3. | C25: Jumlah pengguna hak pilih dalam Daftar Pemilih Khusus (DPK) | D25: LK | E25: 7 | F25: 2 | G25: 1 | H25: 2 | I25: 4 | J25: 2 | K25: 1 | L25: 1 | M25: 1 | N25: 3 | O25: 1 | P25: 1 | Q25: 4 | R25: 1 | S25: 2 | T25: 1 | U25: 1 | V25: 2 | W25: 3 | X25: 0 | Y25: 1 | Z25: 3 | AA25: 5 | AB25: 2 | AC25: 2 | AD25: 2 | AE25: 0 | AF25: =SUM(E25:AE25) -> 55
D26: PR | E26: 7 | F26: 2 | G26: 1 | H26: 2 | I26: 4 | J26: 1 | K26: 5 | L26: 1 | M26: 0 | N26: 1 | O26: 1 | P26: 2 | Q26: 4 | R26: 3 | S26: 5 | T26: 1 | U26: 2 | V26: 5 | W26: 2 | X26: 0 | Y26: 0 | Z26: 4 | AA26: 5 | AB26: 2 | AC26: 2 | AD26: 2 | AE26: 0 | AF26: =SUM(E26:AE26) -> 64
D27: JML | E27: =SUM(E25:E26) -> 14 | F27: =SUM(F25:F26) -> 4 | G27: =SUM(G25:G26) -> 2 | H27: =SUM(H25:H26) -> 4 | I27: =SUM(I25:I26) -> 8 | J27: =SUM(J25:J26) -> 3 | K27: =SUM(K25:K26) -> 6 | L27: =SUM(L25:L26) -> 2 | ... AE27: =SUM(AE25:AE26) -> 0 | AF27: =SUM(E27:AE27) -> 119
B28: 4. | C28: Jumlah Pengguna Hak Pilih (B.1+B.2+B.3) | D28: LK | E28: =SUM(E19,E22,E25) -> 99 | F28: =SUM(F19,F22,F25) -> 88 | G28: =SUM(G19,G22,G25) -> 104 | H28: =SUM(H19,H22,H25) -> 90 | I28: =SUM(I19,I22,I25) -> 81 | J28: =SUM(J19,J22,J25) -> 82 | K28: =SUM(K19,K22,K25) -> 98 | L28: =SUM(L19,L22,L25) -> 87 | ... AE28: =SUM(AE19,AE22,AE25) -> 83 | AF28: =SUM(E28:AE28) -> 2373
D29: PR | E29: =SUM(E20,E23,E26) -> 106 | F29: =SUM(F20,F23,F26) -> 113 | G29: =SUM(G20,G23,G26) -> 103 | H29: =SUM(H20,H23,H26) -> 97 | I29: =SUM(I20,I23,I26) -> 99 | J29: =SUM(J20,J23,J26) -> 88 | K29: =SUM(K20,K23,K26) -> 110 | L29: =SUM(L20,L23,L26) -> 119 | ... AE29: =SUM(AE20,AE23,AE26) -> 117 | AF29: =SUM(E29:AE29) -> 2705
D30: JML | E30: =SUM(E28:E29) -> 205 | F30: =SUM(F28:F29) -> 201 | G30: =SUM(G28:G29) -> 207 | H30: =SUM(H28:H29) -> 187 | I30: =SUM(I28:I29) -> 180 | J30: =SUM(J28:J29) -> 170 | K30: =SUM(K28:K29) -> 208 | L30: =SUM(L28:L29) -> 206 | ... AE30: =SUM(AE28:AE29) -> 200 | AF30: =SUM(E30:AE30) -> 5078
A32: II | B32: DATA PENGGUNAAN SURAT SUARA
A33: 1 | B33: Jumlah surat suara yang diterima, termasuk surat suara cadangan 2,5% dari DPT | E33: 251 | F33: 243 | G33: 249 | H33: 231 | I33: 218 | J33: 212 | K33: 274 | L33: 268 | M33: 228 | N33: 271 | O33: 291 | P33: 255 | Q33: 280 | R33: 207 | S33: 127 | T33: 304 | U33: 232 | V33: 228 | W33: 224 | X33: 287 | Y33: 210 | Z33: 303 | AA33: 193 | AB33: 197 | AC33: 155 | AD33: 301 | AE33: 262 | AF33: =SUM(E33:AE33) -> 6501
A34: 2 | B34: Jumlah surat suara yang digunakan | E34: 205 | F34: 201 | G34: 207 | H34: 187 | I34: 180 | J34: 170 | K34: 208 | L34: 206 | M34: 181 | N34: 189 | O34: 207 | P34: 191 | Q34: 229 | R34: 180 | S34: 103 | T34: 240 | U34: 186 | V34: 172 | W34: 183 | X34: 211 | Y34: 160 | Z34: 234 | AA34: 157 | AB34: 146 | AC34: 111 | AD34: 234 | AE34: 200 | AF34: =SUM(E34:AE34) -> 5078
A35: 3 | B35: Jumlah surat suara dikembalikan oleh pemilih (karena rusak atau keliru coblos) | E35: 0 | F35: 0 | G35: 0 | H35: 0 | I35: 0 | J35: 1 | K35: 0 | L35: 3 | M35: 0 | N35: 0 | O35: 0 | P35: 0 | Q35: 0 | R35: 0 | S35: 0 | T35: 0 | U35: 0 | V35: 0 | W35: 0 | X35: 0 | Y35: 0 | Z35: 2 | AA35: 0 | AB35: 0 | AC35: 0 | AD35: 0 | AE35: 1 | AF35: =SUM(E35:AE35) -> 7
A36: 4 | B36: Jumlah surat suara yang tidak digunakan/tidak terpakai, termasuk sisa surat suara cadangan | E36: =E33-(E34+E35) -> 46 | F36: =F33-(F34+F35) -> 42 | G36: =G33-(G34+G35) -> 42 | H36: =H33-(H34+H35) -> 44 | I36: =I33-(I34+I35) -> 38 | J36: =J33-(J34+J35) -> 41 | K36: =K33-(K34+K35) -> 66 | L36: =L33-(L34+L35) -> 59 | ... AE36: =AE33-(AE34+AE35) -> 61 | AF36: =SUM(E36:AE36) -> 1416
A38: III | B38: DATA PEMILIH DISABILITAS
B39: Jumlah seluruh Pemilih disabilitas yang menggunakan hak pilih | D39: LK | E39: 0 | F39: 1 | G39: 0 | H39: 0 | I39: 0 | J39: 0 | K39: 0 | L39: 2 | M39: 0 | N39: 2 | O39: 1 | P39: 0 | Q39: 0 | R39: 0 | S39: 2 | T39: 0 | U39: 0 | V39: 0 | W39: 0 | X39: 0 | Y39: 0 | Z39: 0 | AA39: 0 | AB39: 1 | AC39: 0 | AD39: 0 | AE39: 0 | AF39: =SUM(E39:AE39) -> 9
D40: PR | E40: 0 | F40: 0 | G40: 0 | H40: 0 | I40: 0 | J40: 0 | K40: 0 | L40: 3 | M40: 0 | N40: 8 | O40: 0 | P40: 0 | Q40: 1 | R40: 0 | S40: 0 | T40: 0 | U40: 0 | V40: 0 | W40: 0 | X40: 0 | Y40: 0 | Z40: 0 | AA40: 0 | AB40: 1 | AC40: 0 | AD40: 0 | AE40: 0 | AF40: =SUM(E40:AE40) -> 13
D41: JML | E41: =SUM(E39:E40) -> 0 | F41: =SUM(F39:F40) -> 1 | G41: =SUM(G39:G40) -> 0 | H41: =SUM(H39:H40) -> 0 | I41: =SUM(I39:I40) -> 0 | J41: =SUM(J39:J40) -> 0 | K41: =SUM(K39:K40) -> 0 | L41: =SUM(L39:L40) -> 5 | ... AE41: =SUM(AE39:AE40) -> 0 | AF41: =SUM(E41:AE41) -> 22
A43: IV | B43: DATA RINCIAN PEROLEHAN SUARA PASANGAN CALON BUPATI DAN WAKIL BUPATI
A44: NOMOR DAN NAMA CALON
B45: 1 | C45: H. ANIES RASYID BASWEDAN, Ph.D. - Dr. (H.C.) H. A. MUHAIMIN ISKANDAR | E45: 23 | F45: 38 | G45: 18 | H45: 27 | I45: 18 | J45: 17 | K45: 33 | L45: 44 | M45: 35 | N45: 24 | O45: 27 | P45: 13 | Q45: 25 | R45: 16 | S45: 16 | T45: 34 | U45: 28 | V45: 25 | W45: 27 | X45: 27 | Y45: 21 | Z45: 37 | AA45: 14 | AB45: 17 | AC45: 25 | AD45: 20 | AE45: 35 | AF45: =SUM(E45:AE45) -> 684
B46: 2 | C46: H. PRABOWO SUBIANTO - GIBRAN RAKABUMING RAKA | E46: 158 | F46: 121 | G46: 134 | H46: 123 | I46: 133 | J46: 122 | K46: 129 | L46: 138 | M46: 113 | N46: 137 | O46: 157 | P46: 132 | Q46: 156 | R46: 121 | S46: 66 | T46: 160 | U46: 124 | V46: 107 | W46: 127 | X46: 146 | Y46: 119 | Z46: 168 | AA46: 113 | AB46: 88 | AC46: 61 | AD46: 164 | AE46: 144 | AF46: =SUM(E46:AE46) -> 3461
B47: 3 | C47: H. GANJAR PRANOWO, S.H., M.I.P. - Prof. Dr. H. M. MAHFUD MD | E47: 22 | F47: 37 | G47: 52 | H47: 36 | I47: 25 | J47: 29 | K47: 44 | L47: 22 | M47: 31 | N47: 28 | O47: 19 | P47: 38 | Q47: 45 | R47: 39 | S47: 20 | T47: 44 | U47: 32 | V47: 38 | W47: 32 | X47: 29 | Y47: 16 | Z47: 22 | AA47: 27 | AB47: 38 | AC47: 24 | AD47: 42 | AE47: 15 | AF47: =SUM(E47:AE47) -> 846
A49: V | B49: DATA SUARA SAH DAN TIDAK SAH
B50: A. | C50: JUMLAH SELURUH SUARA SAH | E50: =SUM(E45:E47) -> 203 | F50: =SUM(F45:F47) -> 196 | G50: =SUM(G45:G47) -> 204 | H50: =SUM(H45:H47) -> 186 | I50: =SUM(I45:I47) -> 176 | J50: =SUM(J45:J47) -> 168 | K50: =SUM(K45:K47) -> 206 | L50: =SUM(L45:L47) -> 204 | ... V50: =SUM(V45:V47) -> 170 | W50: 176 | X50: =SUM(X45:X47) -> 202 | Y50: =SUM(Y45:Y47) -> 156 | Z50: =SUM(Z45:Z47) -> 227 | AA50: =SUM(AA45:AA47) -> 154 | AB50: =SUM(AB45:AB47) -> 143 | AC50: =SUM(AC45:AC47) -> 110 | AD50: =SUM(AD45:AD47) -> 226 | AE50: =SUM(AE45:AE47) -> 194 | AF50: =SUM(E50:AE50) -> 4981
B51: B. | C51: JUMLAH SUARA TIDAK SAH | E51: 2 | F51: 5 | G51: 3 | H51: 1 | I51: 4 | J51: 2 | K51: 2 | L51: 2 | M51: 2 | N51: 0 | O51: 4 | P51: 8 | Q51: 3 | R51: 4 | S51: 1 | T51: 2 | U51: 2 | V51: 2 | W51: 7 | X51: 9 | Y51: 4 | Z51: 7 | AA51: 3 | AB51: 3 | AC51: 1 | AD51: 8 | AE51: 6 | AF51: =SUM(E51:AE51) -> 97
B52: C. | C52: JUMLAH SELURUH SUARA SAH DAN SUARA TIDAK SAH (V.A + V.B) | E52: =SUM(E50:E51) -> 205 | F52: =SUM(F50:F51) -> 201 | G52: =SUM(G50:G51) -> 207 | H52: =SUM(H50:H51) -> 187 | I52: =SUM(I50:I51) -> 180 | J52: =SUM(J50:J51) -> 170 | K52: =SUM(K50:K51) -> 208 | L52: =SUM(L50:L51) -> 206 | ... AE52: =SUM(AE50:AE51) -> 200 | AF52: =SUM(E52:AE52) -> 5078

Sheet KALIBARU MANIS
C2: Kecamatan | D2: KAKLIBARU
C3: Kabupaten | D3: BANYUWANGI
C4: Provinsi | D4: JAWA TIMUR
C9: Kelurahan | D9: KALIBARU MANIS
A12: I | B12: DATA PEMILIH DAN PENGGUNAAN HAK PILIH | AK12: JUMLAH AKHIR
A13: A | B13: DATA PEMILIH | E13: TPS 001 | F13: TPS 002 | G13: TPS 003 | H13: TPS 004 | I13: TPS 005 | J13: TPS 006 | K13: TPS 007 | L13: TPS 008 | M13: TPS 009 | N13: TPS 010 | O13: TPS 011 | P13: TPS 012 | Q13: TPS 013 | R13: TPS 014 | S13: TPS 015 | T13: TPS 016 | U13: TPS 017 | V13: TPS 018 | W13: TPS 019 | X13: TPS 020 | Y13: TPS 021 | Z13: TPS 022 | AA13: TPS 023 | AB13: TPS 024 | AC13: TPS 025 | AD13: TPS 026 | AE13: TPS 027 | AF13: TPS 028 | AG13: TPS 029 | AH13: TPS 030 | AI13: TPS 031 | AJ13: TPS 032
B14: Jumlah Pemilih dalam Daftar Pemilih Tetap (DPT) | D14: LK | E14: 139 | F14: 116 | G14: 147 | H14: 149 | I14: 147 | J14: 128 | K14: 140 | L14: 129 | M14: 148 | N14: 138 | O14: 136 | P14: 124 | Q14: 126 | R14: 143 | S14: 148 | T14: 147 | U14: 117 | V14: 139 | W14: 131 | X14: 139 | Y14: 130 | Z14: 143 | AA14: 115 | AB14: 120 | AC14: 108 | AD14: 124 | AE14: 127 | AF14: 148 | AG14: 138 | AH14: 136 | AI14: 91 | AJ14: 119 | AK14: =SUM(E14:AJ14) -> 4230
D15: PR | E15: 140 | F15: 126 | G15: 140 | H15: 141 | I15: 140 | J15: 136 | K15: 146 | L15: 145 | M15: 139 | N15: 152 | O15: 138 | P15: 141 | Q15: 140 | R15: 152 | S15: 146 | T15: 146 | U15: 126 | V15: 136 | W15: 159 | X15: 150 | Y15: 147 | Z15: 147 | AA15: 112 | AB15: 114 | AC15: 117 | AD15: 117 | AE15: 121 | AF15: 123 | AG15: 134 | AH15: 126 | AI15: 91 | AJ15: 115 | AK15: =SUM(E15:AJ15) -> 4303
D16: JML | E16: =SUM(E14:E15) -> 279 | F16: =SUM(F14:F15) -> 242 | G16: =SUM(G14:G15) -> 287 | H16: =SUM(H14:H15) -> 290 | I16: =SUM(I14:I15) -> 287 | J16: =SUM(J14:J15) -> 264 | K16: =SUM(K14:K15) -> 286 | L16: =SUM(L14:L15) -> 274 | ... AJ16: =SUM(AJ14:AJ15) -> 234 | AK16: =SUM(E16:AJ16) -> 8533
A18: B | B18: PENGGUNA HAK PILIH
B19: 1. | C19: Jumlah pengguna hak pilih dalam Daftar Pemilih Tetap (DPT) | D19: LK | E19: 101 | F19: 98 | G19: 114 | H19: 96 | I19: 104 | J19: 94 | K19: 110 | L19: 104 | M19: 110 | N19: 99 | O19: 99 | P19: 84 | Q19: 87 | R19: 115 | S19: 100 | T19: 104 | U19: 95 | V19: 100 | W19: 99 | X19: 89 | Y19: 72 | Z19: 77 | AA19: 75 | AB19: 87 | AC19: 69 | AD19: 84 | AE19: 81 | AF19: 101 | AG19: 88 | AH19: 89 | AI19: 61 | AJ19: 82 | AK19: =SUM(E19:AJ19) -> 2968
D20: PR | E20: 106 | F20: 109 | G20: 111 | H20: 108 | I20: 112 | J20: 105 | K20: 120 | L20: 123 | M20: 118 | N20: 117 | O20: 112 | P20: 111 | Q20: 112 | R20: 126 | S20: 100 | T20: 110 | U20: 97 | V20: 91 | W20: 120 | X20: 111 | Y20: 104 | Z20: 110 | AA20: 84 | AB20: 90 | AC20: 80 | AD20: 87 | AE20: 92 | AF20: 95 | AG20: 93 | AH20: 105 | AI20: 61 | AJ20: 76 | AK20: =SUM(E20:AJ20) -> 3296
D21: JML | E21: =SUM(E19:E20) -> 207 | F21: =SUM(F19:F20) -> 207 | G21: =SUM(G19:G20) -> 225 | H21: =SUM(H19:H20) -> 204 | I21: =SUM(I19:I20) -> 216 | J21: =SUM(J19:J20) -> 199 | K21: =SUM(K19:K20) -> 230 | L21: =SUM(L19:L20) -> 227 | ... AJ21: =SUM(AJ19:AJ20) -> 158 | AK21: =SUM(E21:AJ21) -> 6264
B22: 2. | C22: Jumlah pengguna hak pilih dalam Daftar Pemilih Tambahan (DPTb) | D22: LK | E22: 4 | F22: 1 | G22: 0 | H22: 0 | I22: 1 | J22: 0 | K22: 0 | L22: 1 | M22: 0 | N22: 0 | O22: 0 | P22: 1 | Q22: 0 | R22: 0 | S22: 1 | T22: 1 | U22: 0 | V22: 1 | W22: 0 | X22: 0 | Y22: 0 | Z22: 0 | AA22: 0 | AB22: 0 | AC22: 0 | AD22: 1 | AE22: 2 | AF22: 2 | AG22: 1 | AH22: 0 | AI22: 1 | AJ22: 1 | AK22: =SUM(E22:AJ22) -> 19
D23: PR | E23: 0 | F23: 0 | G23: 1 | H23: 1 | I23: 0 | J23: 1 | K23: 1 | L23: 0 | M23: 1 | N23: 1 | O23: 0 | P23: 2 | Q23: 1 | R23: 0 | S23: 0 | T23: 0 | U23: 0 | V23: 0 | W23: 0 | X23: 1 | Y23: 0 | Z23: 1 | AA23: 1 | AB23: 1 | AC23: 1 | AD23: 0 | AE23: 0 | AF23: 0 | AG23: 1 | AH23: 0 | AI23: 0 | AJ23: 0 | AK23: =SUM(E23:AJ23) -> 15
D24: JML | E24: =SUM(E22:E23) -> 4 | F24: =SUM(F22:F23) -> 1 | G24: =SUM(G22:G23) -> 1 | H24: =SUM(H22:H23) -> 1 | I24: =SUM(I22:I23) -> 1 | J24: =SUM(J22:J23) -> 1 | K24: =SUM(K22:K23) -> 1 | L24: =SUM(L22:L23) -> 1 | ... AJ24: =SUM(AJ22:AJ23) -> 1 | AK24: =SUM(E24:AJ24) -> 34
B25: 3. | C25: Jumlah pengguna hak pilih dalam Daftar Pemilih Khusus (DPK) | D25: LK | E25: 0 | F25: 0 | G25: 2 | H25: 0 | I25: 0 | J25: 0 | K25: 0 | L25: 0 | M25: 0 | N25: 0 | O25: 0 | P25: 1 | Q25: 0 | R25: 0 | S25: 1 | T25: 0 | U25: 2 | V25: 3 | W25: 2 | X25: 0 | Y25: 0 | Z25: 1 | AA25: 0 | AB25: 0 | AC25: 0 | AD25: 0 | AE25: 0 | AF25: 1 | AG25: 0 | AH25: 0 | AI25: 0 | AJ25: 0 | AK25: =SUM(E25:AJ25) -> 13
D26: PR | E26: 0 | F26: 0 | G26: 2 | H26: 0 | I26: 0 | J26: 0 | K26: 0 | L26: 0 | M26: 0 | N26: 0 | O26: 0 | P26: 2 | Q26: 0 | R26: 0 | S26: 0 | T26: 0 | U26: 1 | V26: 4 | W26: 1 | X26: 0 | Y26: 0 | Z26: 0 | AA26: 0 | AB26: 0 | AC26: 0 | AD26: 0 | AE26: 0 | AF26: 2 | AG26: 0 | AH26: 0 | AI26: 0 | AJ26: 0 | AK26: =SUM(E26:AJ26) -> 12
D27: JML | E27: =SUM(E25:E26) -> 0 | F27: =SUM(F25:F26) -> 0 | G27: =SUM(G25:G26) -> 4 | H27: =SUM(H25:H26) -> 0 | I27: =SUM(I25:I26) -> 0 | J27: =SUM(J25:J26) -> 0 | K27: =SUM(K25:K26) -> 0 | L27: =SUM(L25:L26) -> 0 | ... AJ27: =SUM(AJ25:AJ26) -> 0 | AK27: =SUM(E27:AJ27) -> 25
B28: 4. | C28: Jumlah Pengguna Hak Pilih (B.1+B.2+B.3) | D28: LK | E28: =SUM(E19,E22,E25) -> 105 | F28: =SUM(F19,F22,F25) -> 99 | G28: =SUM(G19,G22,G25) -> 116 | H28: =SUM(H19,H22,H25) -> 96 | I28: =SUM(I19,I22,I25) -> 105 | J28: =SUM(J19,J22,J25) -> 94 | K28: =SUM(K19,K22,K25) -> 110 | L28: =SUM(L19,L22,L25) -> 105 | ... AJ28: =SUM(AJ19,AJ22,AJ25) -> 83 | AK28: =SUM(E28:AJ28) -> 3000
D29: PR | E29: =SUM(E20,E23,E26) -> 106 | F29: =SUM(F20,F23,F26) -> 109 | G29: =SUM(G20,G23,G26) -> 114 | H29: =SUM(H20,H23,H26) -> 109 | I29: =SUM(I20,I23,I26) -> 112 | J29: =SUM(J20,J23,J26) -> 106 | K29: =SUM(K20,K23,K26) -> 121 | L29: =SUM(L20,L23,L26) -> 123 | ... AJ29: =SUM(AJ20,AJ23,AJ26) -> 76 | AK29: =SUM(E29:AJ29) -> 3323
D30: JML | E30: =SUM(E28:E29) -> 211 | F30: =SUM(F28:F29) -> 208 | G30: =SUM(G28:G29) -> 230 | H30: =SUM(H28:H29) -> 205 | I30: =SUM(I28:I29) -> 217 | J30: =SUM(J28:J29) -> 200 | K30: =SUM(K28:K29) -> 231 | L30: =SUM(L28:L29) -> 228 | ... AJ30: =SUM(AJ28:AJ29) -> 159 | AK30: =SUM(E30:AJ30) -> 6323
A32: II | B32: DATA PENGGUNAAN SURAT SUARA
A33: 1 | B33: Jumlah surat suara yang diterima, termasuk surat suara cadangan 2,5% dari DPT | E33: 285 | F33: 247 | G33: 295 | H33: 295 | I33: 292 | J33: 270 | K33: 293 | L33: 279 | M33: 293 | N33: 296 | O33: 280 | P33: 273 | Q33: 272 | R33: 300 | S33: 306 | T33: 300 | U33: 248 | V33: 281 | W33: 295 | X33: 295 | Y33: 285 | Z33: 296 | AA33: 232 | AB33: 239 | AC33: 251 | AD33: 246 | AE33: 253 | AF33: 279 | AG33: 279 | AH33: 264 | AI33: 188 | AJ33: 239 | AK33: =SUM(E33:AJ33) -> 8746
A34: 2 | B34: Jumlah surat suara yang digunakan | E34: 211 | F34: 208 | G34: 230 | H34: 205 | I34: 217 | J34: 200 | K34: 231 | L34: 228 | M34: 229 | N34: 217 | O34: 211 | P34: 201 | Q34: 200 | R34: 241 | S34: 202 | T34: 215 | U34: 195 | V34: 199 | W34: 222 | X34: 201 | Y34: 176 | Z34: 189 | AA34: 160 | AB34: 178 | AC34: 150 | AD34: 172 | AE34: 175 | AF34: 201 | AG34: 183 | AH34: 194 | AI34: 123 | AJ34: 159 | AK34: =SUM(E34:AJ34) -> 6323
A35: 3 | B35: Jumlah surat suara dikembalikan oleh pemilih (karena rusak atau keliru coblos) | E35: 6 | F35: 0 | G35: 2 | H35: 0 | I35: 0 | J35: 0 | K35: 3 | L35: 0 | M35: 0 | N35: 0 | O35: 0 | P35: 0 | Q35: 1 | R35: 0 | S35: 0 | T35: 1 | U35: 1 | V35: 0 | W35: 0 | X35: 0 | Y35: 0 | Z35: 0 | AA35: 0 | AB35: 0 | AC35: 0 | AD35: 0 | AE35: 0 | AF35: 0 | AG35: 0 | AH35: 0 | AI35: 4 | AJ35: 0 | AK35: =SUM(E35:AJ35) -> 18
A36: 4 | B36: Jumlah surat suara yang tidak digunakan/tidak terpakai, termasuk sisa surat suara cadangan | E36: =E33-(E34+E35) -> 68 | F36: =F33-(F34+F35) -> 39 | G36: =G33-(G34+G35) -> 63 | H36: =H33-(H34+H35) -> 90 | I36: =I33-(I34+I35) -> 75 | J36: =J33-(J34+J35) -> 70 | K36: =K33-(K34+K35) -> 59 | L36: =L33-(L34+L35) -> 51 | ... AJ36: =AJ33-(AJ34+AJ35) -> 80 | AK36: =SUM(E36:AJ36) -> 2405
A38: III | B38: DATA PEMILIH DISABILITAS
B39: Jumlah seluruh Pemilih disabilitas yang menggunakan hak pilih | D39: LK | E39: 1 | F39: 0 | G39: 2 | H39: 0 | I39: 0 | J39: 0 | K39: 0 | L39: 0 | M39: 0 | N39: 0 | O39: 0 | P39: 0 | Q39: 0 | R39: 0 | S39: 0 | T39: 0 | U39: 0 | V39: 0 | W39: 0 | X39: 0 | Y39: 0 | Z39: 0 | AA39: 0 | AB39: 0 | AC39: 0 | AD39: 0 | AE39: 0 | AF39: 0 | AG39: 0 | AH39: 0 | AI39: 0 | AJ39: 0 | AK39: =SUM(E39:AJ39) -> 3
D40: PR | E40: 1 | F40: 0 | G40: 1 | H40: 0 | I40: 0 | J40: 0 | K40: 0 | L40: 0 | M40: 0 | N40: 0 | O40: 0 | P40: 0 | Q40: 0 | R40: 0 | S40: 0 | T40: 0 | U40: 0 | V40: 0 | W40: 0 | X40: 0 | Y40: 0 | Z40: 1 | AA40: 0 | AB40: 0 | AC40: 0 | AD40: 0 | AE40: 0 | AF40: 0 | AG40: 0 | AH40: 0 | AI40: 0 | AJ40: 0 | AK40: =SUM(E40:AJ40) -> 3
D41: JML | E41: =SUM(E39:E40) -> 2 | F41: =SUM(F39:F40) -> 0 | G41: =SUM(G39:G40) -> 3 | H41: =SUM(H39:H40) -> 0 | I41: =SUM(I39:I40) -> 0 | J41: =SUM(J39:J40) -> 0 | K41: =SUM(K39:K40) -> 0 | L41: =SUM(L39:L40) -> 0 | ... AJ41: =SUM(AJ39:AJ40) -> 0 | AK41: =SUM(E41:AJ41) -> 6
A43: IV | B43: DATA RINCIAN PEROLEHAN SUARA PASANGAN CALON BUPATI DAN WAKIL BUPATI
A44: NOMOR DAN NAMA CALON
B45: 1 | C45: H. ANIES RASYID BASWEDAN, Ph.D. - Dr. (H.C.) H. A. MUHAIMIN ISKANDAR | E45: 20 | F45: 27 | G45: 29 | H45: 26 | I45: 30 | J45: 25 | K45: 23 | L45: 40 | M45: 41 | N45: 26 | O45: 47 | P45: 47 | Q45: 55 | R45: 74 | S45: 24 | T45: 105 | U45: 75 | V45: 46 | W45: 38 | X45: 42 | Y45: 33 | Z45: 7 | AA45: 34 | AB45: 18 | AC45: 10 | AD45: 21 | AE45: 19 | AF45: 27 | AG45: 27 | AH45: 31 | AI45: 5 | AJ45: 21 | AK45: =SUM(E45:AJ45) -> 1093
B46: 2 | C46: H. PRABOWO SUBIANTO - GIBRAN RAKABUMING RAKA | E46: 161 | F46: 133 | G46: 149 | H46: 142 | I46: 145 | J46: 140 | K46: 159 | L46: 156 | M46: 154 | N46: 160 | O46: 141 | P46: 134 | Q46: 115 | R46: 149 | S46: 148 | T46: 91 | U46: 107 | V46: 130 | W46: 151 | X46: 130 | Y46: 124 | Z46: 153 | AA46: 96 | AB46: 125 | AC46: 125 | AD46: 123 | AE46: 90 | AF46: 124 | AG46: 119 | AH46: 138 | AI46: 110 | AJ46: 112 | AK46: =SUM(E46:AJ46) -> 4234
B47: 3 | C47: H. GANJAR PRANOWO, S.H., M.I.P. - Prof. Dr. H. M. MAHFUD MD | E47: 24 | F47: 36 | G47: 47 | H47: 36 | I47: 34 | J47: 30 | K47: 47 | L47: 24 | M47: 31 | N47: 19 | O47: 19 | P47: 11 | Q47: 23 | R47: 9 | S47: 23 | T47: 15 | U47: 6 | V47: 16 | W47: 21 | X47: 20 | Y47: 18 | Z47: 21 | AA47: 19 | AB47: 29 | AC47: 10 | AD47: 22 | AE47: 56 | AF47: 41 | AG47: 24 | AH47: 15 | AI47: 8 | AJ47: 24 | AK47: =SUM(E47:AJ47) -> 778
A49: V | B49: DATA SUARA SAH DAN TIDAK SAH
B50: A. | C50: JUMLAH SELURUH SUARA SAH | E50: =SUM(E45:E47) -> 205 | F50: =SUM(F45:F47) -> 196 | G50: =SUM(G45:G47) -> 225 | H50: =SUM(H45:H47) -> 204 | I50: =SUM(I45:I47) -> 209 | J50: =SUM(J45:J47) -> 195 | K50: =SUM(K45:K47) -> 229 | L50: =SUM(L45:L47) -> 220 | ... AJ50: =SUM(AJ45:AJ47) -> 157 | AK50: =SUM(E50:AJ50) -> 6105
B51: B. | C51: JUMLAH SUARA TIDAK SAH | E51: 6 | F51: 12 | G51: 5 | H51: 1 | I51: 8 | J51: 5 | K51: 2 | L51: 8 | M51: 3 | N51: 12 | O51: 4 | P51: 9 | Q51: 7 | R51: 9 | S51: 7 | T51: 4 | U51: 7 | V51: 7 | W51: 12 | X51: 9 | Y51: 1 | Z51: 8 | AA51: 11 | AB51: 6 | AC51: 5 | AD51: 6 | AE51: 10 | AF51: 9 | AG51: 13 | AH51: 10 | AI51: 0 | AJ51: 2 | AK51: =SUM(E51:AJ51) -> 218
B52: C. | C52: JUMLAH SELURUH SUARA SAH DAN SUARA TIDAK SAH (V.A + V.B) | E52: =SUM(E50:E51) -> 211 | F52: =SUM(F50:F51) -> 208 | G52: =SUM(G50:G51) -> 230 | H52: =SUM(H50:H51) -> 205 | I52: =SUM(I50:I51) -> 217 | J52: =SUM(J50:J51) -> 200 | K52: =SUM(K50:K51) -> 231 | L52: =SUM(L50:L51) -> 228 | ... AJ52: =SUM(AJ50:AJ51) -> 159 | AK52: =SUM(E52:AJ52) -> 6323

Sheet KALIBARU WETAN
C2: Kecamatan | D2: KAKLIBARU
C3: Kabupaten | D3: BANYUWANGI
C4: Provinsi | D4: JAWA TIMUR
C9: Kelurahan | D9: KALIBARU WETAN
A12: I | B12: DATA PEMILIH DAN PENGGUNAAN HAK PILIH | AU12: JUMLAH AKHIR
A13: A | B13: DATA PEMILIH | E13: TPS 001 | F13: TPS 002 | G13: TPS 003 | H13: TPS 004 | I13: TPS 005 | J13: TPS 006 | K13: TPS 007 | L13: TPS 008 | M13: TPS 009 | N13: TPS 010 | O13: TPS 011 | P13: TPS 012 | Q13: TPS 013 | R13: TPS 014 | S13: TPS 015 | T13: TPS 016 | U13: TPS 017 | V13: TPS 018 | W13: TPS 019 | X13: TPS 020 | Y13: TPS 021 | Z13: TPS 022 | AA13: TPS 023 | AB13: TPS 024 | AC13: TPS 025 | AD13: TPS 026 | AE13: TPS 027 | AF13: TPS 028 | AG13: TPS 029 | AH13: TPS 030 | AI13: TPS 031 | AJ13: TPS 032 | AK13: TPS 033 | AL13: TPS 034 | AM13: TPS 035 | AN13: TPS 036 | AO13: TPS 037 | AP13: TPS 038 | AQ13: TPS 039 | AR13: TPS 040 | AS13: TPS 041 | AT13: TPS 042
B14: Jumlah Pemilih dalam Daftar Pemilih Tetap (DPT) | D14: LK | E14: 119 | F14: 148 | G14: 140 | H14: 99 | I14: 127 | J14: 131 | K14: 86 | L14: 129 | M14: 124 | N14: 132 | O14: 127 | P14: 133 | Q14: 144 | R14: 142 | S14: 141 | T14: 139 | U14: 136 | V14: 135 | W14: 142 | X14: 148 | Y14: 127 | Z14: 140 | AA14: 133 | AB14: 116 | AC14: 112 | AD14: 143 | AE14: 123 | AF14: 114 | AG14: 122 | AH14: 130 | AI14: 120 | AJ14: 151 | AK14: 123 | AL14: 106 | AM14: 103 | AN14: 147 | AO14: 142 | AP14: 141 | AQ14: 152 | AR14: 158 | AS14: 150 | AT14: 137 | AU14: =SUM(E14:AT14) -> 5512
D15: PR | E15: 127 | F15: 144 | G15: 142 | H15: 83 | I15: 121 | J15: 128 | K15: 86 | L15: 142 | M15: 127 | N15: 127 | O15: 113 | P15: 140 | Q15: 145 | R15: 143 | S15: 150 | T15: 138 | U15: 156 | V15: 155 | W15: 141 | X15: 147 | Y15: 159 | Z15: 138 | AA15: 158 | AB15: 121 | AC15: 139 | AD15: 152 | AE15: 110 | AF15: 118 | AG15: 136 | AH15: 127 | AI15: 128 | AJ15: 137 | AK15: 131 | AL15: 119 | AM15: 115 | AN15: 147 | AO15: 147 | AP15: 153 | AQ15: 143 | AR15: 141 | AS15: 144 | AT15: 120 | AU15: =SUM(E15:AT15) -> 5638
D16: JML | E16: =SUM(E14:E15) -> 246 | F16: =SUM(F14:F15) -> 292 | G16: =SUM(G14:G15) -> 282 | H16: =SUM(H14:H15) -> 182 | I16: =SUM(I14:I15) -> 248 | J16: =SUM(J14:J15) -> 259 | K16: =SUM(K14:K15) -> 172 | L16: =SUM(L14:L15) -> 271 | ... AT16: =SUM(AT14:AT15) -> 257 | AU16: =SUM(E16:AT16) -> 11150
A18: B | B18: PENGGUNA HAK PILIH
B19: 1. | C19: Jumlah pengguna hak pilih dalam Daftar Pemilih Tetap (DPT) | D19: LK | E19: 89 | F19: 93 | G19: 98 | H19: 74 | I19: 82 | J19: 91 | K19: 64 | L19: 84 | M19: 83 | N19: 93 | O19: 97 | P19: 84 | Q19: 92 | R19: 91 | S19: 91 | T19: 87 | U19: 96 | V19: 86 | W19: 92 | X19: 101 | Y19: 83 | Z19: 101 | AA19: 99 | AB19: 90 | AC19: 70 | AD19: 93 | AE19: 86 | AF19: 85 | AG19: 80 | AH19: 78 | AI19: 83 | AJ19: 98 | AK19: 101 | AL19: 78 | AM19: 64 | AN19: 88 | AO19: 101 | AP19: 103 | AQ19: 93 | AR19: 110 | AS19: 115 | AT19: 88 | AU19: =SUM(E19:AT19) -> 3755
D20: PR | E20: 95 | F20: 110 | G20: 104 | H20: 71 | I20: 90 | J20: 95 | K20: 69 | L20: 109 | M20: 99 | N20: 93 | O20: 87 | P20: 101 | Q20: 116 | R20: 107 | S20: 113 | T20: 105 | U20: 118 | V20: 118 | W20: 104 | X20: 108 | Y20: 108 | Z20: 114 | AA20: 128 | AB20: 98 | AC20: 101 | AD20: 101 | AE20: 84 | AF20: 93 | AG20: 90 | AH20: 96 | AI20: 109 | AJ20: 101 | AK20: 101 | AL20: 84 | AM20: 86 | AN20: 107 | AO20: 116 | AP20: 118 | AQ20: 109 | AR20: 118 | AS20: 127 | AT20: 100 | AU20: =SUM(E20:AT20) -> 4301
D21: JML | E21: =SUM(E19:E20) -> 184 | F21: =SUM(F19:F20) -> 203 | G21: =SUM(G19:G20) -> 202 | H21: =SUM(H19:H20) -> 145 | I21: =SUM(I19:I20) -> 172 | J21: =SUM(J19:J20) -> 186 | K21: =SUM(K19:K20) -> 133 | L21: =SUM(L19:L20) -> 193 | ... AT21: =SUM(AT19:AT20) -> 188 | AU21: =SUM(E21:AT21) -> 8056
B22: 2. | C22: Jumlah pengguna hak pilih dalam Daftar Pemilih Tambahan (DPTb) | D22: LK | E22: 1 | F22: 0 | G22: 1 | H22: 0 | I22: 0 | J22: 1 | K22: 1 | L22: 2 | M22: 0 | N22: 3 | O22: 1 | P22: 1 | Q22: 0 | R22: 1 | S22: 1 | T22: 1 | U22: 1 | V22: 1 | W22: 0 | X22: 1 | Y22: 1 | Z22: 0 | AA22: 0 | AB22: 1 | AC22: 0 | AD22: 1 | AE22: 1 | AF22: 1 | AG22: 1 | AH22: 0 | AI22: 0 | AJ22: 0 | AK22: 2 | AL22: 1 | AM22: 1 | AN22: 0 | AO22: 0 | AP22: 0 | AQ22: 0 | AR22: 1 | AS22: 1 | AT22: 0 | AU22: =SUM(E22:AT22) -> 29
D23: PR | E23: 0 | F23: 0 | G23: 0 | H23: 0 | I23: 1 | J23: 0 | K23: 0 | L23: 0 | M23: 1 | N23: 1 | O23: 0 | P23: 0 | Q23: 1 | R23: 0 | S23: 0 | T23: 0 | U23: 0 | V23: 0 | W23: 0 | X23: 1 | Y23: 0 | Z23: 0 | AA23: 1 | AB23: 2 | AC23: 0 | AD23: 1 | AE23: 1 | AF23: 0 | AG23: 1 | AH23: 1 | AI23: 1 | AJ23: 1 | AK23: 0 | AL23: 0 | AM23: 0 | AN23: 1 | AO23: 1 | AP23: 1 | AQ23: 1 | AR23: 0 | AS23: 0 | AT23: 0 | AU23: =SUM(E23:AT23) -> 18
D24: JML | E24: =SUM(E22:E23) -> 1 | F24: =SUM(F22:F23) -> 0 | G24: =SUM(G22:G23) -> 1 | H24: =SUM(H22:H23) -> 0 | I24: =SUM(I22:I23) -> 1 | J24: =SUM(J22:J23) -> 1 | K24: =SUM(K22:K23) -> 1 | L24: =SUM(L22:L23) -> 2 | ... AT24: =SUM(AT22:AT23) -> 0 | AU24: =SUM(E24:AT24) -> 47
B25: 3. | C25: Jumlah pengguna hak pilih dalam Daftar Pemilih Khusus (DPK) | D25: LK | E25: 1 | F25: 0 | G25: 3 | H25: 0 | I25: 0 | J25: 1 | K25: 0 | L25: 1 | M25: 3 | N25: 0 | O25: 1 | P25: 4 | Q25: 1 | R25: 1 | S25: 1 | T25: 1 | U25: 1 | V25: 3 | W25: 3 | X25: 1 | Y25: 2 | Z25: 1 | AA25: 1 | AB25: 3 | AC25: 2 | AD25: 1 | AE25: 0 | AF25: 1 | AG25: 0 | AH25: 0 | AI25: 0 | AJ25: 6 | AK25: 0 | AL25: 0 | AM25: 1 | AN25: 2 | AO25: 6 | AP25: 2 | AQ25: 0 | AR25: 2 | AS25: 2 | AT25: 0 | AU25: =SUM(E25:AT25) -> 58
D26: PR | E26: 3 | F26: 0 | G26: 3 | H26: 0 | I26: 0 | J26: 0 | K26: 0 | L26: 2 | M26: 3 | N26: 1 | O26: 1 | P26: 4 | Q26: 2 | R26: 0 | S26: 2 | T26: 1 | U26: 5 | V26: 1 | W26: 2 | X26: 0 | Y26: 0 | Z26: 1 | AA26: 3 | AB26: 2 | AC26: 1 | AD26: 0 | AE26: 1 | AF26: 0 | AG26: 2 | AH26: 0 | AI26: 0 | AJ26: 5 | AK26: 1 | AL26: 3 | AM26: 0 | AN26: 3 | AO26: 2 | AP26: 2 | AQ26: 0 | AR26: 0 | AS26: 1 | AT26: 0 | AU26: =SUM(E26:AT26) -> 57
D27: JML | E27: =SUM(E25:E26) -> 4 | F27: =SUM(F25:F26) -> 0 | G27: =SUM(G25:G26) -> 6 | H27: =SUM(H25:H26) -> 0 | I27: =SUM(I25:I26) -> 0 | J27: =SUM(J25:J26) -> 1 | K27: =SUM(K25:K26) -> 0 | L27: =SUM(L25:L26) -> 3 | ... AT27: =SUM(AT25:AT26) -> 0 | AU27: =SUM(E27:AT27) -> 115
B28: 4. | C28: Jumlah Pengguna Hak Pilih (B.1+B.2+B.3) | D28: LK | E28: =SUM(E19,E22,E25) -> 91 | F28: =SUM(F19,F22,F25) -> 93 | G28: =SUM(G19,G22,G25) -> 102 | H28: =SUM(H19,H22,H25) -> 74 | I28: =SUM(I19,I22,I25) -> 82 | J28: =SUM(J19,J22,J25) -> 93 | K28: =SUM(K19,K22,K25) -> 65 | L28: =SUM(L19,L22,L25) -> 87 | ... AT28: =SUM(AT19,AT22,AT25) -> 88 | AU28: =SUM(E28:AT28) -> 3842
D29: PR | E29: =SUM(E20,E23,E26) -> 98 | F29: =SUM(F20,F23,F26) -> 110 | G29: =SUM(G20,G23,G26) -> 107 | H29: =SUM(H20,H23,H26) -> 71 | I29: =SUM(I20,I23,I26) -> 91 | J29: =SUM(J20,J23,J26) -> 95 | K29: =SUM(K20,K23,K26) -> 69 | L29: =SUM(L20,L23,L26) -> 111 | ... AT29: =SUM(AT20,AT23,AT26) -> 100 | AU29: =SUM(E29:AT29) -> 4376
D30: JML | E30: =SUM(E28:E29) -> 189 | F30: =SUM(F28:F29) -> 203 | G30: =SUM(G28:G29) -> 209 | H30: =SUM(H28:H29) -> 145 | I30: =SUM(I28:I29) -> 173 | J30: =SUM(J28:J29) -> 188 | K30: =SUM(K28:K29) -> 134 | L30: =SUM(L28:L29) -> 198 | ... AT30: =SUM(AT28:AT29) -> 188 | AU30: =SUM(E30:AT30) -> 8218
A32: II | B32: DATA PENGGUNAAN SURAT SUARA
A33: 1 | B33: Jumlah surat suara yang diterima, termasuk surat suara cadangan 2,5% dari DPT | E33: 252 | F33: 298 | G33: 288 | H33: 186 | I33: 256 | J33: 265 | K33: 177 | L33: 278 | M33: 258 | N33: 265 | O33: 246 | P33: 251 | Q33: 298 | R33: 243 | S33: 298 | T33: 288 | U33: 298 | V33: 307 | W33: 289 | X33: 301 | Y33: 292 | Z33: 284 | AA33: 298 | AB33: 241 | AC33: 259 | AD33: 301 | AE33: 238 | AF33: 237 | AG33: 264 | AH33: 265 | AI33: 255 | AJ33: 297 | AK33: 260 | AL33: 230 | AM33: 223 | AN33: 300 | AO33: 295 | AP33: 302 | AQ33: 301 | AR33: 309 | AS33: 300 | AT33: 212 | AU33: =SUM(E33:AT33) -> 11305
A34: 2 | B34: Jumlah surat suara yang digunakan | E34: 189 | F34: 203 | G34: 209 | H34: 145 | I34: 173 | J34: 188 | K34: 134 | L34: 198 | M34: 189 | N34: 191 | O34: 187 | P34: 194 | Q34: 212 | R34: 200 | S34: 208 | T34: 195 | U34: 221 | V34: 209 | W34: 201 | X34: 212 | Y34: 194 | Z34: 217 | AA34: 232 | AB34: 196 | AC34: 174 | AD34: 197 | AE34: 173 | AF34: 180 | AG34: 174 | AH34: 175 | AI34: 193 | AJ34: 211 | AK34: 205 | AL34: 166 | AM34: 152 | AN34: 201 | AO34: 226 | AP34: 226 | AQ34: 203 | AR34: 231 | AS34: 246 | AT34: 188 | AU34: =SUM(E34:AT34) -> 8218
A35: 3 | B35: Jumlah surat suara dikembalikan oleh pemilih (karena rusak atau keliru coblos) | E35: 0 | F35: 0 | G35: 0 | H35: 0 | I35: 0 | J35: 0 | K35: 0 | L35: 0 | M35: 0 | N35: 0 | O35: 0 | P35: 0 | Q35: 0 | R35: 0 | S35: 0 | T35: 0 | U35: 0 | V35: 0 | W35: 0 | X35: 0 | Y35: 1 | Z35: 0 | AA35: 0 | AB35: 0 | AC35: 0 | AD35: 0 | AE35: 0 | AF35: 3 | AG35: 0 | AH35: 0 | AI35: 0 | AJ35: 0 | AK35: 0 | AL35: 0 | AM35: 0 | AN35: 0 | AO35: 0 | AP35: 0 | AQ35: 0 | AR35: 1 | AS35: 0 | AT35: 0 | AU35: =SUM(E35:AT35) -> 5
A36: 4 | B36: Jumlah surat suara yang tidak digunakan/tidak terpakai, termasuk sisa surat suara cadangan | E36: =E33-(E34+E35) -> 63 | F36: =F33-(F34+F35) -> 95 | G36: =G33-(G34+G35) -> 79 | H36: =H33-(H34+H35) -> 41 | I36: =I33-(I34+I35) -> 83 | J36: =J33-(J34+J35) -> 77 | K36: =K33-(K34+K35) -> 43 | L36: =L33-(L34+L35) -> 80 | ... AT36: =AT33-(AT34+AT35) -> 24 | AU36: =SUM(E36:AT36) -> 3082
A38: III | B38: DATA PEMILIH DISABILITAS
B39: Jumlah seluruh Pemilih disabilitas yang menggunakan hak pilih | D39: LK | E39: 0 | F39: 0 | G39: 0 | H39: 0 | I39: 0 | J39: 1 | K39: 0 | L39: 1 | M39: 3 | N39: 0 | O39: 1 | P39: 3 | Q39: 0 | R39: 0 | S39: 0 | T39: 1 | U39: 2 | V39: 0 | W39: 0 | X39: 0 | Y39: 1 | Z39: 0 | AA39: 1 | AB39: 0 | AC39: 1 | AD39: 0 | AE39: 0 | AF39: 1 | AG39: 0 | AH39: 1 | AI39: 0 | AJ39: 0 | AK39: 1 | AL39: 0 | AM39: 0 | AN39: 0 | AO39: 0 | AP39: 0 | AQ39: 0 | AR39: 0 | AS39: 2 | AT39: 1 | AU39: =SUM(E39:AT39) -> 21
