Workbook

Sheet PPWP
C8: Kecamatan
C9: Kabupaten | D9: BANYUWANGI
C10: Provinsi | D10: JAWA TIMUR
A12: I | B12: DATA PEMILIH DAN PENGGUNAAN HAK PILIH | E12: JUMLAH AKHIR
A13: A | B13: DATA PEMILIH
B14: Jumlah Pemilih dalam Daftar Pemilih Tetap (DPT) | D14: LK | E14: 31987
D15: PR | E15: 33057
D16: JML | E16: =SUM(E14:E15) -> 65044
A18: B | B18: PENGGUNA HAK PILIH
B19: 1. | C19: Jumlah pengguna hak pilih dalam Daftar Pemilih Tetap (DPT) | D19: LK | E19: =Kalipuro!AR19+KLATAK!AV19+GOMBENGSARI!AC19+BULUSAN!AC19+Ketapang!BE19+Pesucen!R19+Kelir!W19+Telemung!T19+Bulusari!R19 -> 24074
D20: PR | E20: =Kalipuro!AR20+KLATAK!AV20+GOMBENGSARI!AC20+BULUSAN!AC20+Ketapang!BE20+Pesucen!R20+Kelir!W20+Telemung!T20+Bulusari!R20 -> 26769
D21: JML | E21: =SUM(E19:E20) -> 50843
B22: 2. | C22: Jumlah pengguna hak pilih dalam Daftar Pemilih Tambahan (DPTb) | D22: LK | E22: =Kalipuro!AR22+KLATAK!AV22+GOMBENGSARI!AC22+BULUSAN!AC22+Ketapang!BE22+Pesucen!R22+Kelir!W22+Telemung!T22+Bulusari!R22 -> 169
D23: PR | E23: =Kalipuro!AR23+KLATAK!AV23+GOMBENGSARI!AC23+BULUSAN!AC23+Ketapang!BE23+Pesucen!R23+Kelir!W23+Telemung!T23+Bulusari!R23 -> 135
D24: JML | E24: =SUM(E22:E23) -> 304
B25: 3. | C25: Jumlah pengguna hak pilih dalam Daftar Pemilih Khusus (DPK) | D25: LK | E25: =Kalipuro!AR25+KLATAK!AV25+GOMBENGSARI!AC25+BULUSAN!AC25+Ketapang!BE25+Pesucen!R25+Kelir!W25+Telemung!T25+Bulusari!R25 -> 365
D26: PR | E26: =Kalipuro!AR26+KLATAK!AV26+GOMBENGSARI!AC26+BULUSAN!AC26+Ketapang!BE26+Pesucen!R26+Kelir!W26+Telemung!T26+Bulusari!R26 -> 432
D27: JML | E27: =SUM(E25:E26) -> 797
B28: 4. | C28: Jumlah Pengguna Hak Pilih (B.1+B.2+B.3) | D28: LK | E28: =E19+E22+E25 -> 24608
D29: PR | E29: =E20+E23+E26 -> 27336
D30: JML | E30: =SUM(E28:E29) -> 51944
A32: II | B32: DATA PENGGUNAAN SURAT SUARA
A33: 1 | B33: Jumlah surat suara yang diterima, termasuk surat suara cadangan 2,5% dari DPT | E33: =Kalipuro!AR33+KLATAK!AV33+GOMBENGSARI!AC33+BULUSAN!AC33+Ketapang!BE33+Pesucen!R33+Kelir!W33+Telemung!T33+Bulusari!R33 -> 65562
A34: 2 | B34: Jumlah surat suara yang digunakan | E34: =Kalipuro!AR34+KLATAK!AV34+GOMBENGSARI!AC34+BULUSAN!AC34+Ketapang!BE34+Pesucen!R34+Kelir!W34+Telemung!T34+Bulusari!R34 -> 51944
A35: 3 | B35: Jumlah surat suara dikembalikan oleh pemilih (karena rusak atau keliru coblos) | E35: =Kalipuro!AR35+KLATAK!AV35+GOMBENGSARI!AC35+BULUSAN!AC35+Ketapang!BE35+Pesucen!R35+Kelir!W35+Telemung!T35+Bulusari!R35 -> 107
A36: 4 | B36: Jumlah surat suara yang tidak digunakan/tidak terpakai, termasuk sisa surat suara cadangan | E36: =E33-(E34+E35) -> 13511
A38: III | B38: DATA PEMILIH DISABILITAS
B39: Jumlah seluruh Pemilih disabilitas yang menggunakan hak pilih | D39: LK | E39: =Kalipuro!AR39+KLATAK!AV39+GOMBENGSARI!AC39+BULUSAN!AC39+Ketapang!BE39+Pesucen!R39+Kelir!W39+Telemung!T39+Bulusari!R39 -> 63
D40: PR | E40: =Kalipuro!AR40+KLATAK!AV40+GOMBENGSARI!AC40+BULUSAN!AC40+Ketapang!BE40+Pesucen!R40+Kelir!W40+Telemung!T40+Bulusari!R40 -> 85
D41: JML | E41: =SUM(E39:E40) -> 148
A43: IV | B43: DATA RINCIAN PEROLEHAN SUARA PASANGAN CALON BUPATI DAN WAKIL BUPATI
A44: NOMOR DAN NAMA CALON
B45: 1 | C45: H. ANIES RASYID BASWEDAN, Ph.D. - Dr. (H.C.) H. A. MUHAIMIN ISKANDAR | E45: =Kalipuro!AR45+KLATAK!AV45+GOMBENGSARI!AC45+BULUSAN!AC45+Ketapang!BE45+Pesucen!R45+Kelir!W45+Telemung!T45+Bulusari!R45 -> 11043
B46: 2 | C46: H. PRABOWO SUBIANTO - GIBRAN RAKABUMING RAKA | E46: =Kalipuro!AR46+KLATAK!AV46+GOMBENGSARI!AC46+BULUSAN!AC46+Ketapang!BE46+Pesucen!R46+Kelir!W46+Telemung!T46+Bulusari!R46 -> 32014
B47: 3 | C47: H. GANJAR PRANOWO, S.H., M.I.P. - Prof. Dr. H. M. MAHFUD MD | E47: =Kalipuro!AR47+KLATAK!AV47+GOMBENGSARI!AC47+BULUSAN!AC47+Ketapang!BE47+Pesucen!R47+Kelir!W47+Telemung!T47+Bulusari!R47 -> 7570
A49: V | B49: DATA SUARA SAH DAN TIDAK SAH
B50: A. | C50: JUMLAH SELURUH SUARA SAH | E50: =Kalipuro!AR50+KLATAK!AV50+GOMBENGSARI!AC50+BULUSAN!AC50+Ketapang!BE50+Pesucen!R50+Kelir!W50+Telemung!T50+Bulusari!R50 -> 50627
B51: B. | C51: JUMLAH SUARA TIDAK SAH | E51: =Kalipuro!AR51+KLATAK!AV51+GOMBENGSARI!AC51+BULUSAN!AC51+Ketapang!BE51+Pesucen!R51+Kelir!W51+Telemung!T51+Bulusari!R51 -> 1317
B52: C. | C52: JUMLAH SELURUH SUARA SAH DAN SUARA TIDAK SAH (V.A + V.B) | E52: =SUM(E50:E51) -> 51944

Sheet Kalipuro
C2: Kecamatan
C3: Kabupaten | D3: BANYUWANGI
C4: Provinsi | D4: JAWA TIMUR
C9: Kelurahan
A12: I | B12: DATA PEMILIH DAN PENGGUNAAN HAK PILIH | AR12: JUMLAH AKHIR
A13: A | B13: DATA PEMILIH | E13: TPS 001 | F13: TPS 002 | G13: TPS 003 | H13: TPS 004 | I13: TPS 005 | J13: TPS 006 | K13: TPS 007 | L13: TPS 008 | M13: TPS 009 | N13: TPS 010 | O13: TPS 011 | P13: TPS 012 | Q13: TPS 013 | R13: TPS 014 | S13: TPS 015 | T13: TPS 016 | U13: TPS 017 | V13: TPS 018 | W13: TPS 019 | X13: TPS 020 | Y13: TPS 021 | Z13: TPS 022 | AA13: TPS 023 | AB13: TPS 024 | AC13: TPS 025 | AD13: TPS 026 | AE13: TPS 027 | AF13: TPS 028 | AG13: TPS 029 | AH13: TPS 030 | AI13: TPS 031 | AJ13: TPS 032 | AK13: TPS 033 | AL13: TPS 034 | AM13: TPS 035 | AN13: TPS 036 | AO13: TPS 037 | AP13: TPS 038 | AQ13: TPS 039
B14: Jumlah Pemilih dalam Daftar Pemilih Tetap (DPT) | D14: LK | E14: 137 | F14: 141 | G14: 136 | H14: 135 | I14: 156 | J14: 147 | K14: 145 | L14: 147 | M14: 140 | N14: 141 | O14: 145 | P14: 134 | Q14: 148 | R14: 147 | S14: 139 | T14: 147 | U14: 138 | V14: 143 | W14: 133 | X14: 141 | Y14: 122 | Z14: 145 | AA14: 126 | AB14: 144 | AC14: 145 | AD14: 155 | AE14: 155 | AF14: 149 | AG14: 145 | AH14: 141 | AI14: 143 | AJ14: 135 | AK14: 145 | AL14: 147 | AM14: 132 | AN14: 147 | AO14: 136 | AP14: 150 | AQ14: 134 | AR14: =SUM(E14:AQ14) -> 5536
D15: PR | E15: 157 | F15: 146 | G15: 131 | H15: 154 | I15: 140 | J15: 146 | K15: 148 | L15: 151 | M15: 135 | N15: 158 | O15: 154 | P15: 124 | Q15: 150 | R15: 149 | S15: 156 | T15: 151 | U15: 158 | V15: 153 | W15: 158 | X15: 157 | Y15: 143 | Z15: 142 | AA15: 156 | AB15: 154 | AC15: 149 | AD15: 143 | AE15: 144 | AF15: 143 | AG15: 142 | AH15: 137 | AI15: 150 | AJ15: 157 | AK15: 149 | AL15: 147 | AM15: 123 | AN15: 147 | AO15: 143 | AP15: 147 | AQ15: 149 | AR15: =SUM(E15:AQ15) -> 5741
D16: JML | E16: =SUM(E14:E15) -> 294 | F16: =SUM(F14:F15) -> 287 | G16: =SUM(G14:G15) -> 267 | H16: =SUM(H14:H15) -> 289 | I16: =SUM(I14:I15) -> 296 | J16: =SUM(J14:J15) -> 293 | K16: =SUM(K14:K15) -> 293 | L16: =SUM(L14:L15) -> 298 | ... S16: =SUM(S14:S15) -> 295 | T16: 298 | U16: =SUM(U14:U15) -> 296 | V16: =SUM(V14:V15) -> 296 | W16: =SUM(W14:W15) -> 291 | X16: =SUM(X14:X15) -> 298 | Y16: =SUM(Y14:Y15) -> 265 | Z16: 287 | AA16: =SUM(AA14:AA15) -> 282 | AB16: =SUM(AB14:AB15) -> 298 | AC16: =SUM(AC14:AC15) -> 294 | AD16: =SUM(AD14:AD15) -> 298 | AE16: =SUM(AE14:AE15) -> 299 | AF16: =SUM(AF14:AF15) -> 292 | AG16: =SUM(AG14:AG15) -> 287 | AH16: =SUM(AH14:AH15) -> 278 | AI16: =SUM(AI14:AI15) -> 293 | AJ16: 292 | AK16: =SUM(AK14:AK15) -> 294 | AL16: 294 | AM16: =SUM(AM14:AM15) -> 255 | AN16: =SUM(AN14:AN15) -> 294 | AO16: =SUM(AO14:AO15) -> 279 | AP16: =SUM(AP14:AP15) -> 297 | AQ16: 283 | AR16: =SUM(E16:AQ16) -> 11277
A18: B | B18: PENGGUNA HAK PILIH
B19: 1. | C19: Jumlah pengguna hak pilih dalam Daftar Pemilih Tetap (DPT) | D19: LK | E19: 107 | F19: 105 | G19: 71 | H19: 91 | I19: 100 | J19: 84 | K19: 104 | L19: 108 | M19: 106 | N19: 101 | O19: 104 | P19: 103 | Q19: 113 | R19: 108 | S19: 105 | T19: 122 | U19: 89 | V19: 122 | W19: 95 | X19: 96 | Y19: 98 | Z19: 104 | AA19: 94 | AB19: 132 | AC19: 109 | AD19: 138 | AE19: 116 | AF19: 131 | AG19: 109 | AH19: 107 | AI19: 114 | AJ19: 110 | AK19: 111 | AL19: 127 | AM19: 107 | AN19: 123 | AO19: 101 | AP19: 131 | AQ19: 101 | AR19: =SUM(E19:AQ19) -> 4197
D20: PR | E20: 128 | F20: 117 | G20: 90 | H20: 101 | I20: 104 | J20: 99 | K20: 108 | L20: 126 | M20: 102 | N20: 116 | O20: 132 | P20: 109 | Q20: 122 | R20: 125 | S20: 120 | T20: 130 | U20: 111 | V20: 116 | W20: 125 | X20: 126 | Y20: 102 | Z20: 107 | AA20: 121 | AB20: 124 | AC20: 127 | AD20: 127 | AE20: 117 | AF20: 134 | AG20: 114 | AH20: 103 | AI20: 120 | AJ20: 123 | AK20: 109 | AL20: 126 | AM20: 107 | AN20: 116 | AO20: 96 | AP20: 122 | AQ20: 99 | AR20: =SUM(E20:AQ20) -> 4501
D21: JML | E21: =SUM(E19:E20) -> 235 | F21: =SUM(F19:F20) -> 222 | G21: =SUM(G19:G20) -> 161 | H21: =SUM(H19:H20) -> 192 | I21: =SUM(I19:I20) -> 204 | J21: =SUM(J19:J20) -> 183 | K21: =SUM(K19:K20) -> 212 | L21: =SUM(L19:L20) -> 234 | ... AH21: =SUM(AH19:AH20) -> 210 | AI21: 234 | AJ21: =SUM(AJ19:AJ20) -> 233 | AK21: =SUM(AK19:AK20) -> 220 | AL21: =SUM(AL19:AL20) -> 253 | AM21: =SUM(AM19:AM20) -> 214 | AN21: =SUM(AN19:AN20) -> 239 | AO21: 197 | AP21: 253 | AQ21: =SUM(AQ19:AQ20) -> 200 | AR21: =SUM(E21:AQ21) -> 8698
B22: 2. | C22: Jumlah pengguna hak pilih dalam Daftar Pemilih Tambahan (DPTb) | D22: LK | E22: 0 | F22: 0 | G22: 3 | H22: 0 | I22: 1 | J22: 2 | K22: 0 | L22: 1 | M22: 0 | N22: 0 | O22: 0 | P22: 0 | Q22: 2 | R22: 2 | S22: 0 | T22: 1 | U22: 1 | V22: 0 | W22: 1 | X22: 0 | Y22: 0 | Z22: 1 | AA22: 0 | AB22: 1 | AC22: 0 | AD22: 0 | AE22: 0 | AF22: 0 | AG22: 0 | AH22: 0 | AI22: 0 | AJ22: 0 | AK22: 1 | AL22: 1 | AM22: 0 | AN22: 0 | AO22: 0 | AP22: 0 | AQ22: 1 | AR22: =SUM(E22:AQ22) -> 19
D23: PR | E23: 0 | F23: 1 | G23: 1 | H23: 0 | I23: 0 | J23: 0 | K23: 1 | L23: 1 | M23: 0 | N23: 0 | O23: 0 | P23: 0 | Q23: 0 | R23: 1 | S23: 1 | T23: 1 | U23: 0 | V23: 1 | W23: 0 | X23: 1 | Y23: 0 | Z23: 0 | AA23: 1 | AB23: 1 | AC23: 0 | AD23: 0 | AE23: 0 | AF23: 0 | AG23: 0 | AH23: 0 | AI23: 1 | AJ23: 0 | AK23: 0 | AL23: 0 | AM23: 1 | AN23: 0 | AO23: 0 | AP23: 0 | AQ23: 0 | AR23: =SUM(E23:AQ23) -> 13
D24: JML | E24: =SUM(E22:E23) -> 0 | F24: 1 | G24: =SUM(G22:G23) -> 4 | H24: =SUM(H22:H23) -> 0 | I24: =SUM(I22:I23) -> 1 | J24: =SUM(J22:J23) -> 2 | K24: =SUM(K22:K23) -> 1 | L24: =SUM(L22:L23) -> 2 | M24: =SUM(M22:M23) -> 0 | N24: =SUM(N22:N23) -> 0 | ... Y24: =SUM(Y22:Y23) -> 0 | Z24: 1 | AA24: 1 | AB24: =SUM(AB22:AB23) -> 2 | AC24: =SUM(AC22:AC23) -> 0 | AD24: =SUM(AD22:AD23) -> 0 | AE24: =SUM(AE22:AE23) -> 0 | AF24: =SUM(AF22:AF23) -> 0 | AG24: =SUM(AG22:AG23) -> 0 | AH24: =SUM(AH22:AH23) -> 0 | AI24: =SUM(AI22:AI23) -> 1 | ... AQ24: =SUM(AQ22:AQ23) -> 1 | AR24: =SUM(E24:AQ24) -> 32
B25: 3. | C25: Jumlah pengguna hak pilih dalam Daftar Pemilih Khusus (DPK) | D25: LK | E25: 1 | F25: 7 | G25: 1 | H25: 0 | I25: 2 | J25: 4 | K25: 4 | L25: 3 | M25: 2 | N25: 2 | O25: 2 | P25: 2 | Q25: 1 | R25: 0 | S25: 0 | T25: 3 | U25: 0 | V25: 9 | W25: 1 | X25: 7 | Y25: 1 | Z25: 1 | AA25: 0 | AB25: 2 | AC25: 1 | AD25: 3 | AE25: 3 | AF25: 0 | AG25: 2 | AH25: 6 | AI25: 4 | AJ25: 5 | AK25: 5 | AL25: 1 | AM25: 6 | AN25: 15 | AO25: 4 | AP25: 0 | AQ25: 0 | AR25: =SUM(E25:AQ25) -> 110
D26: PR | E26: 0 | F26: 1 | G26: 1 | H26: 1 | I26: 3 | J26: 8 | K26: 2 | L26: 2 | M26: 3 | N26: 1 | O26: 3 | P26: 2 | Q26: 2 | R26: 1 | S26: 5 | T26: 4 | U26: 0 | V26: 10 | W26: 0 | X26: 6 | Y26: 1 | Z26: 4 | AA26: 0 | AB26: 0 | AC26: 2 | AD26: 6 | AE26: 6 | AF26: 1 | AG26: 3 | AH26: 3 | AI26: 7 | AJ26: 6 | AK26: 8 | AL26: 2 | AM26: 5 | AN26: 15 | AO26: 4 | AP26: 0 | AQ26: 1 | AR26: =SUM(E26:AQ26) -> 129
D27: JML | E27: =SUM(E25:E26) -> 1 | F27: =SUM(F25:F26) -> 8 | G27: =SUM(G25:G26) -> 2 | H27: =SUM(H25:H26) -> 1 | I27: =SUM(I25:I26) -> 5 | J27: =SUM(J25:J26) -> 12 | K27: =SUM(K25:K26) -> 6 | L27: =SUM(L25:L26) -> 5 | ... AQ27: =SUM(AQ25:AQ26) -> 1 | AR27: =SUM(E27:AQ27) -> 239
B28: 4. | C28: Jumlah Pengguna Hak Pilih (B.1+B.2+B.3) | D28: LK | E28: =SUM(E19,E22,E25) -> 108 | F28: =SUM(F19,F22,F25) -> 112 | G28: =SUM(G19,G22,G25) -> 75 | H28: =SUM(H19,H22,H25) -> 91 | I28: =SUM(I19,I22,I25) -> 103 | J28: =SUM(J19,J22,J25) -> 90 | K28: =SUM(K19,K22,K25) -> 108 | L28: =SUM(L19,L22,L25) -> 112 | ... AQ28: =SUM(AQ19,AQ22,AQ25) -> 102 | AR28: =SUM(E28:AQ28) -> 4326
D29: PR | E29: =SUM(E20,E23,E26) -> 128 | F29: =SUM(F20,F23,F26) -> 119 | G29: =SUM(G20,G23,G26) -> 92 | H29: =SUM(H20,H23,H26) -> 102 | I29: =SUM(I20,I23,I26) -> 107 | J29: =SUM(J20,J23,J26) -> 107 | K29: =SUM(K20,K23,K26) -> 111 | L29: =SUM(L20,L23,L26) -> 129 | ... AQ29: =SUM(AQ20,AQ23,AQ26) -> 100 | AR29: =SUM(E29:AQ29) -> 4643
D30: JML | E30: =SUM(E28:E29) -> 236 | F30: =SUM(F28:F29) -> 231 | G30: =SUM(G28:G29) -> 167 | H30: =SUM(H28:H29) -> 193 | I30: =SUM(I28:I29) -> 210 | J30: =SUM(J28:J29) -> 197 | K30: =SUM(K28:K29) -> 219 | L30: =SUM(L28:L29) -> 241 | ... AQ30: =SUM(AQ28:AQ29) -> 202 | AR30: =SUM(E30:AQ30) -> 8969
A32: II | B32: DATA PENGGUNAAN SURAT SUARA
A33: 1 | B33: Jumlah surat suara yang diterima, termasuk surat suara cadangan 2,5% dari DPT | E33: 293 | F33: 286 | G33: 266 | H33: 288 | I33: 295 | J33: 293 | K33: 292 | L33: 297 | M33: 281 | N33: 300 | O33: 298 | P33: 256 | Q33: 297 | R33: 294 | S33: 294 | T33: 297 | U33: 296 | V33: 295 | W33: 280 | X33: 297 | Y33: 263 | Z33: 287 | AA33: 282 | AB33: 299 | AC33: 300 | AD33: 298 | AE33: 299 | AF33: 291 | AG33: 285 | AH33: 278 | AI33: 292 | AJ33: 280 | AK33: 280 | AL33: 293 | AM33: 244 | AN33: 294 | AO33: 278 | AP33: 303 | AQ33: 283 | AR33: =SUM(E33:AQ33) -> 11224
A34: 2 | B34: Jumlah surat suara yang digunakan | E34: 236 | F34: 231 | G34: 167 | H34: 193 | I34: 210 | J34: 197 | K34: 219 | L34: 241 | M34: 213 | N34: 220 | O34: 241 | P34: 216 | Q34: 240 | R34: 237 | S34: 231 | T34: 261 | U34: 201 | V34: 258 | W34: 222 | X34: 236 | Y34: 202 | Z34: 217 | AA34: 216 | AB34: 260 | AC34: 239 | AD34: 274 | AE34: 242 | AF34: 266 | AG34: 228 | AH34: 219 | AI34: 246 | AJ34: 244 | AK34: 234 | AL34: 257 | AM34: 226 | AN34: 269 | AO34: 205 | AP34: 253 | AQ34: 202 | AR34: =SUM(E34:AQ34) -> 8969
A35: 3 | B35: Jumlah surat suara dikembalikan oleh pemilih (karena rusak atau keliru coblos) | E35: 0 | F35: 0 | G35: 0 | H35: 0 | I35: 2 | J35: 0 | K35: 0 | L35: 0 | M35: 0 | N35: 0 | O35: 1 | P35: 0 | Q35: 0 | R35: 0 | S35: 0 | T35: 0 | U35: 1 | V35: 0 | W35: 0 | X35: 0 | Y35: 0 | Z35: 2 | AA35: 0 | AB35: 1 | AC35: 0 | AD35: 1 | AE35: 0 | AF35: 0 | AG35: 0 | AH35: 1 | AI35: 0 | AJ35: 0 | AK35: 0 | AL35: 3 | AM35: 0 | AN35: 0 | AO35: 0 | AP35: 0 | AR35: =SUM(E35:AQ35) -> 12
A36: 4 | B36: Jumlah surat suara yang tidak digunakan/tidak terpakai, termasuk sisa surat suara cadangan | E36: =E33-(E34+E35) -> 57 | F36: =F33-(F34+F35) -> 55 | G36: =G33-(G34+G35) -> 99 | H36: =H33-(H34+H35) -> 95 | I36: =I33-(I34+I35) -> 83 | J36: =J33-(J34+J35) -> 96 | K36: =K33-(K34+K35) -> 73 | L36: =L33-(L34+L35) -> 56 | ... AQ36: =AQ33-(AQ34+AQ35) -> 81 | AR36: =SUM(E36:AQ36) -> 2243
A38: III | B38: DATA PEMILIH DISABILITAS
B39: Jumlah seluruh Pemilih disabilitas yang menggunakan hak pilih | D39: LK | E39: 1 | F39: 1 | G39: 0 | H39: 0 | I39: 0 | J39: 0 | K39: 0 | L39: 0 | M39: 1 | N39: 0 | O39: 0 | P39: 0 | Q39: 0 | R39: 0 | S39: 2 | T39: 1 | U39: 0 | V39: 0 | W39: 2 | X39: 0 | Y39: 0 | Z39: 0 | AA39: 0 | AB39: 0 | AC39: 3 | AD39: 3 | AE39: 0 | AF39: 0 | AG39: 0 | AH39: 1 | AI39: 0 | AJ39: 0 | AK39: 0 | AL39: 0 | AM39: 0 | AN39: 0 | AO39: 0 | AP39: 0 | AQ39: 0 | AR39: =SUM(E39:AQ39) -> 15
D40: PR | E40: 2 | F40: 0 | G40: 0 | H40: 0 | I40: 0 | J40: 0 | K40: 0 | L40: 0 | M40: 0 | N40: 0 | O40: 0 | P40: 0 | Q40: 0 | R40: 0 | S40: 3 | T40: 0 | U40: 2 | V40: 0 | W40: 1 | X40: 0 | Y40: 0 | Z40: 0 | AA40: 0 | AB40: 0 | AC40: 4 | AD40: 1 | AE40: 0 | AF40: 0 | AG40: 1 | AH40: 0 | AI40: 0 | AJ40: 0 | AK40: 0 | AL40: 0 | AM40: 0 | AN40: 0 | AO40: 0 | AP40: 0 | AQ40: 0 | AR40: =SUM(E40:AQ40) -> 14
D41: JML | E41: =SUM(E39:E40) -> 3 | F41: =SUM(F39:F40) -> 1 | G41: =SUM(G39:G40) -> 0 | H41: =SUM(H39:H40) -> 0 | I41: =SUM(I39:I40) -> 0 | J41: =SUM(J39:J40) -> 0 | K41: =SUM(K39:K40) -> 0 | L41: =SUM(L39:L40) -> 0 | ... AQ41: =SUM(AQ39:AQ40) -> 0 | AR41: =SUM(E41:AQ41) -> 29
A43: IV | B43: DATA RINCIAN PEROLEHAN SUARA PASANGAN CALON BUPATI DAN WAKIL BUPATI
A44: NOMOR DAN NAMA CALON
B45: 1 | C45: H. ANIES RASYID BASWEDAN, Ph.D. - Dr. (H.C.) H. A. MUHAIMIN ISKANDAR | E45: 31 | F45: 26 | G45: 23 | H45: 36 | I45: 30 | J45: 30 | K45: 55 | L45: 54 | M45: 22 | N45: 27 | O45: 69 | P45: 60 | Q45: 44 | R45: 41 | S45: 18 | T45: 35 | U45: 19 | V45: 86 | W45: 30 | X45: 30 | Y45: 71 | Z45: 93 | AA45: 60 | AB45: 110 | AC45: 101 | AD45: 75 | AE45: 62 | AF45: 85 | AG45: 106 | AH45: 64 | AI45: 110 | AJ45: 99 | AK45: 38 | AL45: 98 | AM45: 68 | AN45: 123 | AO45: 93 | AP45: 76 | AQ45: 13 | AR45: =SUM(E45:AQ45) -> 2311
B46: 2 | C46: H. PRABOWO SUBIANTO - GIBRAN RAKABUMING RAKA | E46: 160 | F46: 161 | G46: 123 | H46: 115 | I46: 140 | J46: 142 | K46: 140 | L46: 166 | M46: 161 | N46: 156 | O46: 126 | P46: 131 | Q46: 173 | R46: 162 | S46: 188 | T46: 185 | U46: 153 | V46: 140 | W46: 171 | X46: 169 | Y46: 96 | Z46: 85 | AA46: 113 | AB46: 117 | AC46: 110 | AD46: 152 | AE46: 153 | AF46: 133 | AG46: 80 | AH46: 104 | AI46: 108 | AJ46: 93 | AK46: 164 | AL46: 117 | AM46: 115 | AN46: 86 | AO46: 85 | AP46: 133 | AQ46: 173 | AR46: =SUM(E46:AQ46) -> 5279
B47: 3 | C47: H. GANJAR PRANOWO, S.H., M.I.P. - Prof. Dr. H. M. MAHFUD MD | E47: 42 | F47: 41 | G47: 16 | H47: 38 | I47: 39 | J47: 17 | K47: 19 | L47: 21 | M47: 27 | N47: 26 | O47: 42 | P47: 23 | Q47: 21 | R47: 32 | S47: 17 | T47: 35 | U47: 25 | V47: 22 | W47: 16 | X47: 29 | Y47: 31 | Z47: 39 | AA47: 31 | AB47: 30 | AC47: 22 | AD47: 26 | AE47: 25 | AF47: 40 | AG47: 30 | AH47: 38 | AI47: 21 | AJ47: 46 | AK47: 30 | AL47: 32 | AM47: 31 | AN47: 40 | AO47: 23 | AP47: 30 | AQ47: 12 | AR47: =SUM(E47:AQ47) -> 1125
A49: V | B49: DATA SUARA SAH DAN TIDAK SAH
B50: A. | C50: JUMLAH SELURUH SUARA SAH | E50: =SUM(E45:E47) -> 233 | F50: =SUM(F45:F47) -> 228 | G50: =SUM(G45:G47) -> 162 | H50: =SUM(H45:H47) -> 189 | I50: =SUM(I45:I47) -> 209 | J50: =SUM(J45:J47) -> 189 | K50: =SUM(K45:K47) -> 214 | L50: =SUM(L45:L47) -> 241 | ... S50: =SUM(S45:S47) -> 223 | T50: 255 | U50: =SUM(U45:U47) -> 197 | V50: =SUM(V45:V47) -> 248 | W50: =SUM(W45:W47) -> 217 | X50: =SUM(X45:X47) -> 228 | Y50: =SUM(Y45:Y47) -> 198 | Z50: =SUM(Z45:Z47) -> 217 | AA50: =SUM(AA45:AA47) -> 204 | AB50: =SUM(AB45:AB47) -> 257 | ... AQ50: =SUM(AQ45:AQ47) -> 198 | AR50: =SUM(E50:AQ50) -> 8715
B51: B. | C51: JUMLAH SUARA TIDAK SAH | E51: 3 | F51: 3 | G51: 5 | H51: 4 | I51: 1 | J51: 8 | K51: 5 | L51: 0 | M51: 3 | N51: 11 | O51: 4 | P51: 2 | Q51: 2 | R51: 2 | S51: 8 | T51: 6 | U51: 4 | V51: 10 | W51: 5 | X51: 8 | Y51: 4 | Z51: 0 | AA51: 12 | AB51: 3 | AC51: 6 | AD51: 21 | AE51: 2 | AF51: 8 | AG51: 12 | AH51: 13 | AI51: 7 | AJ51: 6 | AK51: 2 | AL51: 10 | AM51: 12 | AN51: 20 | AO51: 4 | AP51: 14 | AQ51: 4 | AR51: =SUM(E51:AQ51) -> 254
B52: C. | C52: JUMLAH SELURUH SUARA SAH DAN SUARA TIDAK SAH (V.A + V.B) | E52: =SUM(E50:E51) -> 236 | F52: =SUM(F50:F51) -> 231 | G52: =SUM(G50:G51) -> 167 | H52: =SUM(H50:H51) -> 193 | I52: =SUM(I50:I51) -> 210 | J52: =SUM(J50:J51) -> 197 | K52: =SUM(K50:K51) -> 219 | L52: =SUM(L50:L51) -> 241 | ... AQ52: =SUM(AQ50:AQ51) -> 202 | AR52: =SUM(E52:AQ52) -> 8969

Sheet KLATAK
C2: Kecamatan
C3: Kabupaten | D3: BANYUWANGI
C4: Provinsi | D4: JAWA TIMUR
C9: Kelurahan
A12: I | B12: DATA PEMILIH DAN PENGGUNAAN HAK PILIH | AV12: JUMLAH AKHIR
A13: A | B13: DATA PEMILIH | E13: TPS 001 | F13: TPS 002 | G13: TPS 003 | H13: TPS 004 | I13: TPS 005 | J13: TPS 006 | K13: TPS 007 | L13: TPS 008 | M13: TPS 009 | N13: TPS 010 | O13: TPS 011 | P13: TPS 012 | Q13: TPS 013 | R13: TPS 014 | S13: TPS 015 | T13: TPS 016 | U13: TPS 017 | V13: TPS 018 | W13: TPS 019 | X13: TPS 020 | Y13: TPS 021 | Z13: TPS 022 | AA13: TPS 023 | AB13: TPS 024 | AC13: TPS 025 | AD13: TPS 026 | AE13: TPS 027 | AF13: TPS 028 | AG13: TPS 029 | AH13: TPS 030 | AI13: TPS 031 | AJ13: TPS 032 | AK13: TPS 033 | AL13: TPS 034 | AM13: TPS 035 | AN13: TPS 036 | AO13: TPS 037 | AP13: TPS 038 | AQ13: TPS 039 | AR13: TPS 040 | AS13: TPS 041 | AT13: TPS 042 | AU13: TPS 043
B14: Jumlah Pemilih dalam Daftar Pemilih Tetap (DPT) | D14: LK | E14: 142 | F14: 137 | G14: 103 | H14: 135 | I14: 134 | J14: 137 | K14: 139 | L14: 142 | M14: 126 | N14: 153 | O14: 140 | P14: 133 | Q14: 133 | R14: 144 | S14: 133 | T14: 140 | U14: 147 | V14: 140 | W14: 152 | X14: 143 | Y14: 141 | Z14: 133 | AA14: 139 | AB14: 134 | AC14: 144 | AD14: 131 | AE14: 150 | AF14: 155 | AG14: 132 | AH14: 148 | AI14: 139 | AJ14: 148 | AK14: 137 | AL14: 106 | AM14: 131 | AN14: 128 | AO14: 123 | AP14: 134 | AQ14: 152 | AR14: 119 | AS14: 145 | AT14: 137 | AU14: 145 | AV14: =SUM(E14:AU14) -> 5904
D15: PR | E15: 141 | F15: 151 | G15: 117 | H15: 138 | I15: 161 | J15: 148 | K15: 154 | L15: 143 | M15: 163 | N15: 142 | O15: 152 | P15: 158 | Q15: 150 | R15: 138 | S15: 148 | T15: 147 | U15: 147 | V15: 148 | W15: 141 | X15: 146 | Y15: 141 | Z15: 148 | AA15: 151 | AB15: 148 | AC15: 146 | AD15: 135 | AE15: 142 | AF15: 140 | AG15: 146 | AH15: 150 | AI15: 151 | AJ15: 145 | AK15: 150 | AL15: 112 | AM15: 136 | AN15: 143 | AO15: 140 | AP15: 155 | AQ15: 143 | AR15: 123 | AS15: 144 | AT15: 158 | AU15: 146 | AV15: =SUM(E15:AU15) -> 6226
D16: JML | E16: =SUM(E14:E15) -> 283 | F16: =SUM(F14:F15) -> 288 | G16: =SUM(G14:G15) -> 220 | H16: =SUM(H14:H15) -> 273 | I16: =SUM(I14:I15) -> 295 | J16: =SUM(J14:J15) -> 285 | K16: =SUM(K14:K15) -> 293 | L16: =SUM(L14:L15) -> 285 | ... AU16: =SUM(AU14:AU15) -> 291 | AV16: =SUM(E16:AU16) -> 12130
A18: B | B18: PENGGUNA HAK PILIH
B19: 1. | C19: Jumlah pengguna hak pilih dalam Daftar Pemilih Tetap (DPT) | D19: LK | E19: 114 | F19: 77 | G19: 75 | H19: 104 | I19: 97 | J19: 101 | K19: 98 | L19: 98 | M19: 85 | N19: 108 | O19: 87 | P19: 92 | Q19: 89 | R19: 106 | S19: 83 | T19: 102 | U19: 97 | V19: 87 | W19: 112 | X19: 98 | Y19: 102 | Z19: 99 | AA19: 106 | AB19: 100 | AC19: 98 | AD19: 92 | AE19: 106 | AF19: 113 | AG19: 95 | AH19: 88 | AI19: 89 | AJ19: 110 | AK19: 105 | AL19: 68 | AM19: 85 | AN19: 93 | AO19: 83 | AP19: 89 | AQ19: 95 | AR19: 77 | AS19: 92 | AT19: 121 | AU19: 79 | AV19: =SUM(E19:AU19) -> 4095
D20: PR | E20: 126 | F20: 107 | G20: 93 | H20: 108 | I20: 124 | J20: 109 | K20: 124 | L20: 116 | M20: 122 | N20: 116 | O20: 117 | P20: 120 | Q20: 118 | R20: 99 | S20: 119 | T20: 112 | U20: 110 | V20: 108 | W20: 109 | X20: 125 | Y20: 113 | Z20: 123 | AA20: 119 | AB20: 127 | AC20: 120 | AD20: 111 | AE20: 113 | AF20: 108 | AG20: 109 | AH20: 109 | AI20: 126 | AJ20: 109 | AK20: 126 | AL20: 74 | AM20: 101 | AN20: 111 | AO20: 105 | AP20: 113 | AQ20: 109 | AR20: 94 | AS20: 110 | AT20: 87 | AU20: 100 | AV20: =SUM(E20:AU20) -> 4799
D21: JML | E21: =SUM(E19:E20) -> 240 | F21: =SUM(F19:F20) -> 184 | G21: =SUM(G19:G20) -> 168 | H21: =SUM(H19:H20) -> 212 | I21: =SUM(I19:I20) -> 221 | J21: =SUM(J19:J20) -> 210 | K21: =SUM(K19:K20) -> 222 | L21: =SUM(L19:L20) -> 214 | ... AU21: =SUM(AU19:AU20) -> 179 | AV21: =SUM(E21:AU21) -> 8894
B22: 2. | C22: Jumlah pengguna hak pilih dalam Daftar Pemilih Tambahan (DPTb) | D22: LK | E22: 1 | F22: 4 | G22: 8 | H22: 1 | I22: 0 | J22: 0 | K22: 0 | L22: 0 | M22: 1 | N22: 1 | O22: 6 | P22: 0 | Q22: 1 | R22: 1 | S22: 1 | T22: 1 | U22: 2 | V22: 1 | W22: 2 | X22: 1 | Y22: 0 | Z22: 0 | AA22: 1 | AB22: 0 | AC22: 0 | AD22: 1 | AE22: 1 | AF22: 2 | AG22: 1 | AH22: 0 | AI22: 0 | AJ22: 0 | AK22: 0 | AL22: 1 | AM22: 1 | AN22: 0 | AO22: 0 | AP22: 2 | AQ22: 2 | AR22: 1 | AS22: 1 | AT22: 1 | AU22: 1 | AV22: =SUM(E22:AU22) -> 48
D23: PR | E23: 1 | F23: 1 | G23: 2 | H23: 1 | I23: 0 | J23: 0 | K23: 0 | L23: 0 | M23: 0 | N23: 2 | O23: 1 | P23: 1 | Q23: 1 | R23: 0 | S23: 0 | T23: 1 | U23: 1 | V23: 2 | W23: 1 | X23: 2 | Y23: 3 | Z23: 1 | AA23: 0 | AB23: 0 | AC23: 1 | AD23: 0 | AE23: 3 | AF23: 6 | AG23: 0 | AH23: 1 | AI23: 0 | AJ23: 0 | AK23: 1 | AL23: 0 | AM23: 0 | AN23: 1 | AO23: 1 | AP23: 3 | AQ23: 0 | AR23: 0 | AS23: 1 | AT23: 0 | AU23: 1 | AV23: =SUM(E23:AU23) -> 40
D24: JML | E24: =SUM(E22:E23) -> 2 | F24: =SUM(F22:F23) -> 5 | G24: =SUM(G22:G23) -> 10 | H24: =SUM(H22:H23) -> 2 | I24: =SUM(I22:I23) -> 0 | J24: =SUM(J22:J23) -> 0 | K24: =SUM(K22:K23) -> 0 | L24: =SUM(L22:L23) -> 0 | ... AD24: =SUM(AD22:AD23) -> 1 | AE24: 4 | AF24: =SUM(AF22:AF23) -> 8 | AG24: =SUM(AG22:AG23) -> 1 | AH24: =SUM(AH22:AH23) -> 1 | AI24: =SUM(AI22:AI23) -> 0 | AJ24: =SUM(AJ22:AJ23) -> 0 | AK24: =SUM(AK22:AK23) -> 1 | AL24: =SUM(AL22:AL23) -> 1 | AM24: =SUM(AM22:AM23) -> 1 | ... AU24: =SUM(AU22:AU23) -> 2 | AV24: =SUM(E24:AU24) -> 88
B25: 3. | C25: Jumlah pengguna hak pilih dalam Daftar Pemilih Khusus (DPK) | D25: LK | E25: 5 | F25: 1 | G25: 2 | H25: 8 | I25: 4 | J25: 2 | K25: 3 | L25: 0 | M25: 1 | N25: 0 | O25: 0 | P25: 2 | Q25: 1 | R25: 2 | S25: 2 | T25: 0 | U25: 1 | V25: 8 | W25: 2 | X25: 2 | Y25: 1 | Z25: 1 | AA25: 0 | AB25: 0 | AC25: 0 | AD25: 5 | AE25: 1 | AF25: 3 | AG25: 0 | AH25: 7 | AI25: 0 | AJ25: 5 | AK25: 2 | AL25: 1 | AM25: 1 | AN25: 2 | AO25: 1 | AP25: 5 | AQ25: 0 | AR25: 0 | AS25: 2 | AT25: 2 | AU25: 2 | AV25: =SUM(E25:AU25) -> 87
D26: PR | E26: 6 | F26: 0 | G26: 3 | H26: 10 | I26: 1 | J26: 1 | K26: 3 | L26: 0 | M26: 2 | N26: 0 | O26: 1 | P26: 0 | Q26: 1 | R26: 1 | S26: 0 | T26: 0 | U26: 0 | V26: 9 | W26: 2 | X26: 0 | Y26: 1 | Z26: 2 | AA26: 0 | AB26: 0 | AC26: 0 | AD26: 5 | AE26: 0 | AF26: 3 | AG26: 1 | AH26: 3 | AI26: 0 | AJ26: 6 | AK26: 0 | AL26: 1 | AM26: 1 | AN26: 1 | AO26: 0 | AP26: 5 | AQ26: 1 | AR26: 0 | AS26: 4 | AT26: 2 | AU26: 2 | AV26: =SUM(E26:AU26) -> 78
D27: JML | E27: =SUM(E25:E26) -> 11 | F27: =SUM(F25:F26) -> 1 | G27: =SUM(G25:G26) -> 5 | H27: =SUM(H25:H26) -> 18 | I27: =SUM(I25:I26) -> 5 | J27: =SUM(J25:J26) -> 3 | K27: =SUM(K25:K26) -> 6 | L27: =SUM(L25:L26) -> 0 | ... AU27: =SUM(AU25:AU26) -> 4 | AV27: =SUM(E27:AU27) -> 165
B28: 4. | C28: Jumlah Pengguna Hak Pilih (B.1+B.2+B.3) | D28: LK | E28: =SUM(E19,E22,E25) -> 120 | F28: =SUM(F19,F22,F25) -> 82 | G28: =SUM(G19,G22,G25) -> 85 | H28: =SUM(H19,H22,H25) -> 113 | I28: =SUM(I19,I22,I25) -> 101 | J28: =SUM(J19,J22,J25) -> 103 | K28: =SUM(K19,K22,K25) -> 101 | L28: =SUM(L19,L22,L25) -> 98 | ... R28: =SUM(R19,R22,R25) -> 109 | S28: 86 | T28: =SUM(T19,T22,T25) -> 103 | U28: =SUM(U19,U22,U25) -> 100 | V28: =SUM(V19,V22,V25) -> 96 | W28: =SUM(W19,W22,W25) -> 116 | X28: =SUM(X19,X22,X25) -> 101 | Y28: =SUM(Y19,Y22,Y25) -> 103 | Z28: =SUM(Z19,Z22,Z25) -> 100 | AA28: =SUM(AA19,AA22,AA25) -> 107 | ... AU28: =SUM(AU19,AU22,AU25) -> 82 | AV28: =SUM(E28:AU28) -> 4230
D29: PR | E29: =SUM(E20,E23,E26) -> 133 | F29: =SUM(F20,F23,F26) -> 108 | G29: =SUM(G20,G23,G26) -> 98 | H29: =SUM(H20,H23,H26) -> 119 | I29: =SUM(I20,I23,I26) -> 125 | J29: =SUM(J20,J23,J26) -> 110 | K29: =SUM(K20,K23,K26) -> 127 | L29: =SUM(L20,L23,L26) -> 116 | ... P29: =SUM(P20,P23,P26) -> 121 | Q29: 120 | R29: =SUM(R20,R23,R26) -> 100 | S29: =SUM(S20,S23,S26) -> 119 | T29: =SUM(T20,T23,T26) -> 113 | U29: =SUM(U20,U23,U26) -> 111 | V29: =SUM(V20,V23,V26) -> 119 | W29: =SUM(W20,W23,W26) -> 112 | X29: =SUM(X20,X23,X26) -> 127 | Y29: =SUM(Y20,Y23,Y26) -> 117 | ... AU29: =SUM(AU20,AU23,AU26) -> 103 | AV29: =SUM(E29:AU29) -> 4917
D30: JML | E30: =SUM(E28:E29) -> 253 | F30: =SUM(F28:F29) -> 190 | G30: =SUM(G28:G29) -> 183 | H30: =SUM(H28:H29) -> 232 | I30: =SUM(I28:I29) -> 226 | J30: =SUM(J28:J29) -> 213 | K30: =SUM(K28:K29) -> 228 | L30: =SUM(L28:L29) -> 214 | ... AU30: =SUM(AU28:AU29) -> 185 | AV30: =SUM(E30:AU30) -> 9147
A32: II | B32: DATA PENGGUNAAN SURAT SUARA
A33: 1 | B33: Jumlah surat suara yang diterima, termasuk surat suara cadangan 2,5% dari DPT | E33: 279 | F33: 285 | G33: 216 | H33: 262 | I33: 291 | J33: 282 | K33: 280 | L33: 281 | M33: 288 | N33: 293 | O33: 288 | P33: 287 | Q33: 280 | R33: 278 | S33: 277 | T33: 283 | U33: 291 | V33: 285 | W33: 289 | X33: 285 | Y33: 278 | Z33: 278 | AA33: 290 | AB33: 278 | AC33: 287 | AD33: 262 | AE33: 290 | AF33: 292 | AG33: 275 | AH33: 294 | AI33: 286 | AJ33: 288 | AK33: 287 | AL33: 213 | AM33: 262 | AN33: 267 | AO33: 258 | AP33: 285 | AQ33: 292 | AR33: 237 | AS33: 284 | AT33: 292 | AU33: 291 | AV33: =SUM(E33:AU33) -> 11966
A34: 2 | B34: Jumlah surat suara yang digunakan | E34: 253 | F34: 190 | G34: 183 | H34: 232 | I34: 226 | J34: 213 | K34: 228 | L34: 214 | M34: 211 | N34: 227 | O34: 212 | P34: 215 | Q34: 211 | R34: 209 | S34: 205 | T34: 216 | U34: 211 | V34: 215 | W34: 228 | X34: 228 | Y34: 220 | Z34: 226 | AA34: 226 | AB34: 227 | AC34: 219 | AD34: 214 | AE34: 224 | AF34: 235 | AG34: 206 | AH34: 208 | AI34: 215 | AJ34: 230 | AK34: 234 | AL34: 145 | AM34: 189 | AN34: 208 | AO34: 190 | AP34: 217 | AQ34: 207 | AR34: 172 | AS34: 210 | AT34: 213 | AU34: 185 | AV34: =SUM(E34:AU34) -> 9147
A35: 3 | B35: Jumlah surat suara dikembalikan oleh pemilih (karena rusak atau keliru coblos) | E35: 0 | F35: 0 | G35: 0 | H35: 0 | I35: 0 | J35: 0 | K35: 0 | L35: 0 | M35: 0 | N35: 0 | O35: 0 | P35: 0 | Q35: 0 | R35: 0 | S35: 0 | T35: 0 | U35: 0 | V35: 0 | W35: 0 | X35: 0 | Y35: 0 | Z35: 1 | AA35: 0 | AB35: 5 | AC35: 1 | AD35: 0 | AE35: 2 | AF35: 1 | AG35: 0 | AH35: 0 | AI35: 0 | AJ35: 0 | AK35: 0 | AL35: 0 | AM35: 0 | AN35: 0 | AO35: 0 | AP35: 1 | AQ35: 0 | AR35: 0 | AS35: 0 | AT35: 0 | AU35: 0 | AV35: =SUM(E35:AU35) -> 11
A36: 4 | B36: Jumlah surat suara yang tidak digunakan/tidak terpakai, termasuk sisa surat suara cadangan | E36: =E33-(E34+E35) -> 26 | F36: =F33-(F34+F35) -> 95 | G36: =G33-(G34+G35) -> 33 | H36: =H33-(H34+H35) -> 30 | I36: =I33-(I34+I35) -> 65 | J36: =J33-(J34+J35) -> 69 | K36: =K33-(K34+K35) -> 52 | L36: =L33-(L34+L35) -> 67 | ... AU36: =AU33-(AU34+AU35) -> 106 | AV36: =SUM(E36:AU36) -> 2808
A38: III | B38: DATA PEMILIH DISABILITAS
B39: Jumlah seluruh Pemilih disabilitas yang menggunakan hak pilih | D39: LK | E39: 1 | F39: 0 | G39: 1 | H39: 0 | I39: 0 | J39: 2 | K39: 0 | L39: 0 | M39: 1 | N39: 0 | O39: 0 | P39: 0 | Q39: 0 | R39: 0 | S39: 0 | T39: 0 | U39: 0 | V39: 0 | W39: 0 | X39: 3 | Y39: 0 | Z39: 0 | AA39: 1 | AB39: 0 | AC39: 0 | AD39: 0 | AE39: 0 | AF39: 1 | AG39: 0 | AH39: 0 | AI39: 1 | AJ39: 0 | AK39: 0 | AL39: 0 | AM39: 0 | AN39: 0 | AO39: 1 | AP39: 0 | AQ39: 0 | AR39: 0 | AS39: 0 | AT39: 0 | AU39: 1 | AV39: =SUM(E39:AU39) -> 13
D40: PR | E40: 1 | F40: 0 | G40: 0 | H40: 0 | I40: 0 | J40: 0 | K40: 0 | L40: 0 | M40: 0 | N40: 0 | O40: 0 | P40: 2 | Q40: 0 | R40: 0 | S40: 0 | T40: 0 | U40: 1 | V40: 0 | W40: 0 | X40: 2 | Y40: 0 | Z40: 0 | AA40: 2 | AB40: 0 | AC40: 0 | AD40: 0 | AE40: 0 | AF40: 1 | AG40: 0 | AH40: 1 | AI40: 1 | AJ40: 0 | AK40: 0 | AL40: 0 | AM40: 1 | AN40: 0 | AO40: 0 | AP40: 0 | AQ40: 0 | AR40: 0 | AS40: 0 | AT40: 0 | AU40: 1 | AV40: =SUM(E40:AU40) -> 13
D41: JML | E41: =SUM(E39:E40) -> 2 | F41: =SUM(F39:F40) -> 0 | G41: =SUM(G39:G40) -> 1 | H41: =SUM(H39:H40) -> 0 | I41: =SUM(I39:I40) -> 0 | J41: =SUM(J39:J40) -> 2 | K41: =SUM(K39:K40) -> 0 | L41: =SUM(L39:L40) -> 0 | ... AU41: =SUM(AU39:AU40) -> 2 | AV41: =SUM(E41:AU41) -> 26
A43: IV | B43: DATA RINCIAN PEROLEHAN SUARA PASANGAN CALON BUPATI DAN WAKIL BUPATI
A44: NOMOR DAN NAMA CALON
B45: 1 | C45: H. ANIES RASYID BASWEDAN, Ph.D. - Dr. (H.C.) H. A. MUHAIMIN ISKANDAR | E45: 16 | F45: 21 | G45: 19 | H45: 22 | I45: 19 | J45: 52 | K45: 37 | L45: 18 | M45: 20 | N45: 32 | O45: 36 | P45: 45 | Q45: 30 | R45: 15 | S45: 30 | T45: 40 | U45: 34 | V45: 26 | W45: 19 | X45: 29 | Y45: 24 | Z45: 43 | AA45: 33 | AB45: 20 | AC45: 32 | AD45: 37 | AE45: 64 | AF45: 52 | AG45: 31 | AH45: 50 | AI45: 40 | AJ45: 42 | AK45: 47 | AL45: 26 | AM45: 32 | AN45: 57 | AO45: 46 | AP45: 55 | AQ45: 27 | AR45: 29 | AS45: 44 | AT45: 29 | AU45: 22 | AV45: =SUM(E45:AU45) -> 1442
B46: 2 | C46: H. PRABOWO SUBIANTO - GIBRAN RAKABUMING RAKA | E46: 131 | F46: 132 | G46: 123 | H46: 119 | I46: 159 | J46: 129 | K46: 136 | L46: 144 | M46: 137 | N46: 154 | O46: 152 | P46: 130 | Q46: 141 | R46: 148 | S46: 153 | T46: 146 | U46: 148 | V46: 130 | W46: 171 | X46: 160 | Y46: 150 | Z46: 147 | AA46: 167 | AB46: 180 | AC46: 171 | AD46: 149 | AE46: 118 | AF46: 131 | AG46: 141 | AH46: 129 | AI46: 131 | AJ46: 133 | AK46: 145 | AL46: 103 | AM46: 133 | AN46: 122 | AO46: 122 | AP46: 123 | AQ46: 144 | AR46: 114 | AS46: 140 | AT46: 143 | AU46: 134 | AV46: =SUM(E46:AU46) -> 6013
B47: 3 | C47: H. GANJAR PRANOWO, S.H., M.I.P. - Prof. Dr. H. M. MAHFUD MD | E47: 103 | F47: 34 | G47: 37 | H47: 90 | I47: 44 | J47: 31 | K47: 50 | L47: 46 | M47: 50 | N47: 39 | O47: 22 | P47: 39 | Q47: 38 | R47: 42 | S47: 18 | T47: 26 | U47: 21 | V47: 57 | W47: 31 | X47: 29 | Y47: 39 | Z47: 31 | AA47: 19 | AB47: 22 | AC47: 16 | AD47: 24 | AE47: 38 | AF47: 46 | AG47: 32 | AH47: 26 | AI47: 40 | AJ47: 49 | AK47: 38 | AL47: 15 | AM47: 24 | AN47: 27 | AO47: 20 | AP47: 36 | AQ47: 30 | AR47: 28 | AS47: 23 | AT47: 38 | AU47: 29 | AV47: =SUM(E47:AU47) -> 1537
A49: V | B49: DATA SUARA SAH DAN TIDAK SAH
B50: A. | C50: JUMLAH SELURUH SUARA SAH | E50: =SUM(E45:E47) -> 250 | F50: =SUM(F45:F47) -> 187 | G50: =SUM(G45:G47) -> 179 | H50: =SUM(H45:H47) -> 231 | I50: =SUM(I45:I47) -> 222 | J50: =SUM(J45:J47) -> 212 | K50: =SUM(K45:K47) -> 223 | L50: =SUM(L45:L47) -> 208 | ... AU50: =SUM(AU45:AU47) -> 185 | AV50: =SUM(E50:AU50) -> 8992
B51: B. | C51: JUMLAH SUARA TIDAK SAH | E51: 3 | F51: 3 | G51: 4 | H51: 1 | I51: 4 | J51: 1 | K51: 5 | L51: 6 | M51: 4 | N51: 2 | O51: 2 | P51: 1 | Q51: 2 | R51: 4 | S51: 4 | T51: 4 | U51: 8 | V51: 2 | W51: 7 | X51: 10 | Y51: 7 | Z51: 5 | AA51: 7 | AB51: 5 | AC51: 0 | AD51: 4 | AE51: 4 | AF51: 6 | AG51: 2 | AH51: 3 | AI51: 4 | AJ51: 6 | AK51: 4 | AL51: 1 | AM51: 0 | AN51: 2 | AO51: 2 | AP51: 3 | AQ51: 6 | AR51: 1 | AS51: 3 | AT51: 3 | AU51: 0 | AV51: =SUM(E51:AU51) -> 155
B52: C. | C52: JUMLAH SELURUH SUARA SAH DAN SUARA TIDAK SAH (V.A + V.B) | E52: =SUM(E50:E51) -> 253 | F52: =SUM(F50:F51) -> 190 | G52: =SUM(G50:G51) -> 183 | H52: =SUM(H50:H51) -> 232 | I52: =SUM(I50:I51) -> 226 | J52: =SUM(J50:J51) -> 213 | K52: =SUM(K50:K51) -> 228 | L52: =SUM(L50:L51) -> 214 | ... AU52: =SUM(AU50:AU51) -> 185 | AV52: =SUM(E52:AU52) -> 9147

Sheet GOMBENGSARI
C2: Kecamatan
C3: Kabupaten | D3: BANYUWANGI
C4: Provinsi | D4: JAWA TIMUR
C9: Kelurahan
A12: I | B12: DATA PEMILIH DAN PENGGUNAAN HAK PILIH | AC12: JUMLAH AKHIR
A13: A | B13: DATA PEMILIH | E13: TPS 001 | F13: TPS 002 | G13: TPS 003 | H13: TPS 004 | I13: TPS 005 | J13: TPS 006 | K13: TPS 007 | L13: TPS 008 | M13: TPS 009 | N13: TPS 010 | O13: TPS 011 | P13: TPS 012 | Q13: TPS 013 | R13: TPS 014 | S13: TPS 015 | T13: TPS 016 | U13: TPS 017 | V13: TPS 018 | W13: TPS 019 | X13: TPS 020 | Y13: TPS 021 | Z13: TPS 022 | AA13: TPS 023 | AB13: TPS 024
B14: Jumlah Pemilih dalam Daftar Pemilih Tetap (DPT) | D14: LK | E14: 88 | F14: 112 | G14: 144 | H14: 112 | I14: 130 | J14: 147 | K14: 145 | L14: 148 | M14: 125 | N14: 122 | O14: 120 | P14: 148 | Q14: 148 | R14: 139 | S14: 100 | T14: 141 | U14: 139 | V14: 139 | W14: 139 | X14: 137 | Y14: 122 | Z14: 109 | AA14: 124 | AB14: 127 | AC14: =SUM(E14:AB14) -> 3105
D15: PR | E15: 84 | F15: 119 | G15: 147 | H15: 118 | I15: 144 | J15: 150 | K15: 150 | L15: 143 | M15: 136 | N15: 125 | O15: 132 | P15: 146 | Q15: 140 | R15: 146 | S15: 100 | T15: 143 | U15: 142 | V15: 139 | W15: 145 | X15: 130 | Y15: 130 | Z15: 108 | AA15: 132 | AB15: 123 | AC15: =SUM(E15:AB15) -> 3172
D16: JML | E16: =SUM(E14:E15) -> 172 | F16: =SUM(F14:F15) -> 231 | G16: =SUM(G14:G15) -> 291 | H16: =SUM(H14:H15) -> 230 | I16: =SUM(I14:I15) -> 274 | J16: =SUM(J14:J15) -> 297 | K16: =SUM(K14:K15) -> 295 | L16: =SUM(L14:L15) -> 291 | ... AB16: =SUM(AB14:AB15) -> 250 | AC16: =SUM(E16:AB16) -> 6277
A18: B | B18: PENGGUNA HAK PILIH
B19: 1. | C19: Jumlah pengguna hak pilih dalam Daftar Pemilih Tetap (DPT) | D19: LK | E19: 63 | F19: 88 | G19: 101 | H19: 80 | I19: 104 | J19: 117 | K19: 117 | L19: 124 | M19: 96 | N19: 98 | O19: 106 | P19: 124 | Q19: 111 | R19: 115 | S19: 94 | T19: 121 | U19: 120 | V19: 123 | W19: 112 | X19: 114 | Y19: 105 | Z19: 87 | AA19: 99 | AB19: 97 | AC19: =SUM(E19:AB19) -> 2516
D20: PR | E20: 73 | F20: 104 | G20: 118 | H20: 97 | I20: 133 | J20: 129 | K20: 128 | L20: 127 | M20: 107 | N20: 106 | O20: 122 | P20: 125 | Q20: 116 | R20: 123 | S20: 94 | T20: 122 | U20: 121 | V20: 120 | W20: 122 | X20: 108 | Y20: 107 | Z20: 89 | AA20: 118 | AB20: 96 | AC20: =SUM(E20:AB20) -> 2705
D21: JML | E21: =SUM(E19:E20) -> 136 | F21: =SUM(F19:F20) -> 192 | G21: =SUM(G19:G20) -> 219 | H21: =SUM(H19:H20) -> 177 | I21: =SUM(I19:I20) -> 237 | J21: =SUM(J19:J20) -> 246 | K21: =SUM(K19:K20) -> 245 | L21: =SUM(L19:L20) -> 251 | ... AB21: =SUM(AB19:AB20) -> 193 | AC21: =SUM(E21:AB21) -> 5221
B22: 2. | C22: Jumlah pengguna hak pilih dalam Daftar Pemilih Tambahan (DPTb) | D22: LK | E22: 0 | F22: 0 | G22: 0 | H22: 0 | I22: 0 | J22: 0 | K22: 0 | L22: 0 | M22: 1 | N22: 0 | O22: 0 | P22: 0 | Q22: 1 | R22: 0 | S22: 0 | T22: 1 | U22: 0 | V22: 0 | W22: 0 | X22: 0 | Y22: 0 | Z22: 0 | AA22: 1 | AB22: 0 | AC22: =SUM(E22:AB22) -> 4
D23: PR | E23: 1 | F23: 0 | G23: 1 | H23: 0 | I23: 1 | J23: 0 | K23: 1 | L23: 0 | M23: 0 | N23: 0 | O23: 0 | P23: 0 | Q23: 2 | R23: 0 | S23: 1 | T23: 0 | U23: 0 | V23: 0 | W23: 1 | X23: 0 | Y23: 0 | Z23: 0 | AA23: 1 | AB23: 1 | AC23: =SUM(E23:AB23) -> 10
D24: JML | E24: =SUM(E22:E23) -> 1 | F24: =SUM(F22:F23) -> 0 | G24: =SUM(G22:G23) -> 1 | H24: =SUM(H22:H23) -> 0 | I24: =SUM(I22:I23) -> 1 | J24: =SUM(J22:J23) -> 0 | K24: =SUM(K22:K23) -> 1 | L24: =SUM(L22:L23) -> 0 | ... AB24: =SUM(AB22:AB23) -> 1 | AC24: =SUM(E24:AB24) -> 14
B25: 3. | C25: Jumlah pengguna hak pilih dalam Daftar Pemilih Khusus (DPK) | D25: LK | E25: 0 | F25: 1 | G25: 0 | H25: 0 | I25: 1 | J25: 0 | K25: 1 | L25: 1 | M25: 0 | N25: 0 | O25: 0 | P25: 0 | Q25: 0 | R25: 0 | S25: 0 | T25: 0 | U25: 0 | V25: 3 | W25: 1 | X25: 3 | Y25: 3 | Z25: 0 | AA25: 0 | AB25: 1 | AC25: =SUM(E25:AB25) -> 15
D26: PR | E26: 1 | F26: 3 | G26: 1 | H26: 1 | I26: 0 | J26: 0 | K26: 2 | L26: 1 | M26: 1 | N26: 0 | O26: 0 | P26: 0 | Q26: 0 | R26: 0 | S26: 0 | T26: 0 | U26: 1 | V26: 0 | W26: 1 | X26: 2 | Y26: 2 | Z26: 0 | AA26: 0 | AB26: 1 | AC26: =SUM(E26:AB26) -> 17
D27: JML | E27: =SUM(E25:E26) -> 1 | F27: =SUM(F25:F26) -> 4 | G27: =SUM(G25:G26) -> 1 | H27: =SUM(H25:H26) -> 1 | I27: =SUM(I25:I26) -> 1 | J27: =SUM(J25:J26) -> 0 | K27: =SUM(K25:K26) -> 3 | L27: =SUM(L25:L26) -> 2 | ... AB27: =SUM(AB25:AB26) -> 2 | AC27: =SUM(E27:AB27) -> 32
B28: 4. | C28: Jumlah Pengguna Hak Pilih (B.1+B.2+B.3) | D28: LK | E28: =SUM(E19,E22,E25) -> 63 | F28: =SUM(F19,F22,F25) -> 89 | G28: =SUM(G19,G22,G25) -> 101 | H28: =SUM(H19,H22,H25) -> 80 | I28: =SUM(I19,I22,I25) -> 105 | J28: =SUM(J19,J22,J25) -> 117 | K28: =SUM(K19,K22,K25) -> 118 | L28: =SUM(L19,L22,L25) -> 125 | ... AB28: =SUM(AB19,AB22,AB25) -> 98 | AC28: =SUM(E28:AB28) -> 2535
D29: PR | E29: =SUM(E20,E23,E26) -> 75 | F29: =SUM(F20,F23,F26) -> 107 | G29: =SUM(G20,G23,G26) -> 120 | H29: =SUM(H20,H23,H26) -> 98 | I29: =SUM(I20,I23,I26) -> 134 | J29: =SUM(J20,J23,J26) -> 129 | K29: =SUM(K20,K23,K26) -> 131 | L29: =SUM(L20,L23,L26) -> 128 | ... AB29: =SUM(AB20,AB23,AB26) -> 98 | AC29: =SUM(E29:AB29) -> 2732
D30: JML | E30: =SUM(E28:E29) -> 138 | F30: =SUM(F28:F29) -> 196 | G30: =SUM(G28:G29) -> 221 | H30: =SUM(H28:H29) -> 178 | I30: =SUM(I28:I29) -> 239 | J30: =SUM(J28:J29) -> 246 | K30: =SUM(K28:K29) -> 249 | L30: =SUM(L28:L29) -> 253 | ... AB30: =SUM(AB28:AB29) -> 196 | AC30: =SUM(E30:AB30) -> 5267
A32: II | B32: DATA PENGGUNAAN SURAT SUARA
A33: 1 | B33: Jumlah surat suara yang diterima, termasuk surat suara cadangan 2,5% dari DPT | E33: 166 | F33: 227 | G33: 285 | H33: 226 | I33: 271 | J33: 294 | K33: 293 | L33: 288 | M33: 255 | N33: 248 | O33: 247 | P33: 291 | Q33: 286 | R33: 276 | S33: 194 | T33: 282 | U33: 279 | V33: 274 | W33: 282 | X33: 263 | Y33: 257 | Z33: 215 | AA33: 242 | AB33: 248 | AC33: =SUM(E33:AB33) -> 6189
A34: 2 | B34: Jumlah surat suara yang digunakan | E34: 138 | F34: 196 | G34: 221 | H34: 178 | I34: 239 | J34: 246 | K34: 249 | L34: 253 | M34: 205 | N34: 204 | O34: 228 | P34: 249 | Q34: 230 | R34: 238 | S34: 189 | T34: 244 | U34: 242 | V34: 246 | W34: 237 | X34: 227 | Y34: 217 | Z34: 176 | AA34: 219 | AB34: 196 | AC34: =SUM(E34:AB34) -> 5267
A35: 3 | B35: Jumlah surat suara dikembalikan oleh pemilih (karena rusak atau keliru coblos) | E35: 0 | F35: 0 | G35: 0 | H35: 0 | I35: 2 | J35: 0 | K35: 0 | L35: 0 | M35: 0 | N35: 34 | O35: 0 | P35: 0 | Q35: 0 | R35: 2 | S35: 0 | T35: 6 | U35: 0 | V35: 0 | W35: 0 | X35: 0 | Y35: 1 | Z35: 0 | AA35: 0 | AB35: 0 | AC35: =SUM(E35:AB35) -> 45
A36: 4 | B36: Jumlah surat suara yang tidak digunakan/tidak terpakai, termasuk sisa surat suara cadangan | E36: =E33-(E34+E35) -> 28 | F36: =F33-(F34+F35) -> 31 | G36: =G33-(G34+G35) -> 64 | H36: =H33-(H34+H35) -> 48 | I36: =I33-(I34+I35) -> 30 | J36: =J33-(J34+J35) -> 48 | K36: =K33-(K34+K35) -> 44 | L36: =L33-(L34+L35) -> 35 | ... AB36: =AB33-(AB34+AB35) -> 52 | AC36: =SUM(E36:AB36) -> 877
A38: III | B38: DATA PEMILIH DISABILITAS
B39: Jumlah seluruh Pemilih disabilitas yang menggunakan hak pilih | D39: LK | E39: 0 | F39: 0 | G39: 0 | H39: 0 | I39: 0 | J39: 1 | K39: 0 | L39: 0 | M39: 0 | N39: 0 | O39: 0 | P39: 0 | Q39: 0 | R39: 0 | S39: 0 | T39: 0 | U39: 0 | V39: 0 | W39: 1 | X39: 0 | Y39: 0 | Z39: 0 | AA39: 2 | AB39: 1 | AC39: =SUM(E39:AB39) -> 5
D40: PR | E40: 1 | F40: 0 | G40: 0 | H40: 0 | I40: 0 | J40: 0 | K40: 0 | L40: 0 | M40: 1 | N40: 0 | O40: 0 | P40: 0 | Q40: 0 | R40: 0 | S40: 0 | T40: 0 | U40: 0 | V40: 0 | W40: 0 | X40: 0 | Y40: 0 | Z40: 0 | AA40: 2 | AB40: 0 | AC40: =SUM(E40:AB40) -> 4
D41: JML | E41: =SUM(E39:E40) -> 1 | F41: =SUM(F39:F40) -> 0 | G41: =SUM(G39:G40) -> 0 | H41: =SUM(H39:H40) -> 0 | I41: =SUM(I39:I40) -> 0 | J41: =SUM(J39:J40) -> 1 | K41: =SUM(K39:K40) -> 0 | L41: =SUM(L39:L40) -> 0 | ... AB41: =SUM(AB39:AB40) -> 1 | AC41: =SUM(E41:AB41) -> 9
A43: IV | B43: DATA RINCIAN PEROLEHAN SUARA PASANGAN CALON BUPATI DAN WAKIL BUPATI
A44: NOMOR DAN NAMA CALON
B45: 1 | C45: H. ANIES RASYID BASWEDAN, Ph.D. - Dr. (H.C.) H. A. MUHAIMIN ISKANDAR | E45: 16 | F45: 17 | G45: 19 | H45: 16 | I45: 32 | J45: 42 | K45: 37 | L45: 71 | M45: 43 | N45: 47 | O45: 47 | P45: 17 | Q45: 28 | R45: 25 | S45: 6 | T45: 41 | U45: 62 | V45: 66 | W45: 82 | X45: 107 | Y45: 68 | Z45: 23 | AA45: 57 | AB45: 19 | AC45: =SUM(E45:AB45) -> 988
B46: 2 | C46: H. PRABOWO SUBIANTO - GIBRAN RAKABUMING RAKA | E46: 99 | F46: 146 | G46: 162 | H46: 119 | I46: 174 | J46: 164 | K46: 191 | L46: 149 | M46: 131 | N46: 134 | O46: 143 | P46: 88 | Q46: 122 | R46: 165 | S46: 169 | T46: 173 | U46: 155 | V46: 151 | W46: 130 | X46: 112 | Y46: 126 | Z46: 119 | AA46: 129 | AB46: 145 | AC46: =SUM(E46:AB46) -> 3396
B47: 3 | C47: H. GANJAR PRANOWO, S.H., M.I.P. - Prof. Dr. H. M. MAHFUD MD | E47: 15 | F47: 28 | G47: 28 | H47: 34 | I47: 27 | J47: 24 | K47: 14 | L47: 25 | M47: 24 | N47: 19 | O47: 36 | P47: 133 | Q47: 68 | R47: 42 | S47: 5 | T47: 19 | U47: 22 | V47: 27 | W47: 21 | X47: 7 | Y47: 16 | Z47: 29 | AA47: 27 | AB47: 28 | AC47: =SUM(E47:AB47) -> 718
A49: V | B49: DATA SUARA SAH DAN TIDAK SAH
B50: A. | C50: JUMLAH SELURUH SUARA SAH | E50: =SUM(E45:E47) -> 130 | F50: =SUM(F45:F47) -> 191 | G50: =SUM(G45:G47) -> 209 | H50: =SUM(H45:H47) -> 169 | I50: =SUM(I45:I47) -> 233 | J50: =SUM(J45:J47) -> 230 | K50: =SUM(K45:K47) -> 242 | L50: =SUM(L45:L47) -> 245 | ... AB50: =SUM(AB45:AB47) -> 192 | AC50: =SUM(E50:AB50) -> 5102
B51: B. | C51: JUMLAH SUARA TIDAK SAH | E51: 8 | F51: 5 | G51: 12 | H51: 9 | I51: 6 | J51: 16 | K51: 7 | L51: 8 | M51: 7 | N51: 4 | O51: 2 | P51: 11 | Q51: 12 | R51: 6 | S51: 9 | T51: 11 | U51: 3 | V51: 2 | W51: 4 | X51: 1 | Y51: 7 | Z51: 5 | AA51: 6 | AB51: 4 | AC51: =SUM(E51:AB51) -> 165
B52: C. | C52: JUMLAH SELURUH SUARA SAH DAN SUARA TIDAK SAH (V.A + V.B) | E52: =SUM(E50:E51) -> 138 | F52: =SUM(F50:F51) -> 196 | G52: =SUM(G50:G51) -> 221 | H52: =SUM(H50:H51) -> 178 | I52: =SUM(I50:I51) -> 239 | J52: =SUM(J50:J51) -> 246 | K52: =SUM(K50:K51) -> 249 | L52: =SUM(L50:L51) -> 253 | ... AB52: =SUM(AB50:AB51) -> 196 | AC52: =SUM(E52:AB52) -> 5267

Sheet BULUSAN
C2: Kecamatan
C3: Kabupaten | D3: BANYUWANGI
C4: Provinsi | D4: JAWA TIMUR
C9: Kelurahan
A12: I | B12: DATA PEMILIH DAN PENGGUNAAN HAK PILIH | AC12: JUMLAH AKHIR
A13: A | B13: DATA PEMILIH | E13: TPS 001 | F13: TPS 002 | G13: TPS 003 | H13: TPS 004 | I13: TPS 005 | J13: TPS 006 | K13: TPS 007 | L13: TPS 008 | M13: TPS 009 | N13: TPS 010 | O13: TPS 011 | P13: TPS 012 | Q13: TPS 013 | R13: TPS 014 | S13: TPS 015 | T13: TPS 016 | U13: TPS 017 | V13: TPS 018 | W13: TPS 019 | X13: TPS 020 | Y13: TPS 021 | Z13: TPS 022 | AA13: TPS 023 | AB13: TPS 024
B14: Jumlah Pemilih dalam Daftar Pemilih Tetap (DPT) | D14: LK | E14: 148 | F14: 140 | G14: 133 | H14: 145 | I14: 130 | J14: 136 | K14: 147 | L14: 130 | M14: 139 | N14: 140 | O14: 129 | P14: 109 | Q14: 148 | R14: 138 | S14: 139 | T14: 143 | U14: 140 | V14: 131 | W14: 132 | X14: 144 | Y14: 104 | Z14: 86 | AA14: 146 | AB14: 116 | AC14: =SUM(E14:AB14) -> 3193
D15: PR | E15: 146 | F15: 139 | G15: 139 | H15: 150 | I15: 136 | J15: 144 | K15: 133 | L15: 153 | M15: 145 | N15: 134 | O15: 144 | P15: 118 | Q15: 140 | R15: 146 | S15: 139 | T15: 142 | U15: 137 | V15: 134 | W15: 149 | X15: 148 | Y15: 122 | Z15: 110 | AA15: 142 | AB15: 124 | AC15: =SUM(E15:AB15) -> 3314
D16: JML | E16: =SUM(E14:E15) -> 294 | F16: =SUM(F14:F15) -> 279 | G16: =SUM(G14:G15) -> 272 | H16: =SUM(H14:H15) -> 295 | I16: =SUM(I14:I15) -> 266 | J16: =SUM(J14:J15) -> 280 | K16: =SUM(K14:K15) -> 280 | L16: =SUM(L14:L15) -> 283 | ... AB16: =SUM(AB14:AB15) -> 240 | AC16: =SUM(E16:AB16) -> 6507
A18: B | B18: PENGGUNA HAK PILIH
B19: 1. | C19: Jumlah pengguna hak pilih dalam Daftar Pemilih Tetap (DPT) | D19: LK | E19: 101 | F19: 102 | G19: 101 | H19: 122 | I19: 82 | J19: 102 | K19: 111 | L19: 98 | M19: 95 | N19: 102 | O19: 88 | P19: 68 | Q19: 92 | R19: 92 | S19: 86 | T19: 117 | U19: 122 | V19: 108 | W19: 106 | X19: 104 | Y19: 89 | Z19: 65 | AA19: 92 | AB19: 94 | AC19: =SUM(E19:AB19) -> 2339
D20: PR | E20: 117 | F20: 115 | G20: 119 | H20: 125 | I20: 107 | J20: 119 | K20: 107 | L20: 121 | M20: 119 | N20: 111 | O20: 116 | P20: 100 | Q20: 97 | R20: 109 | S20: 111 | T20: 121 | U20: 121 | V20: 121 | W20: 118 | X20: 116 | Y20: 101 | Z20: 91 | AA20: 110 | AB20: 108 | AC20: =SUM(E20:AB20) -> 2700
D21: JML | E21: =SUM(E19:E20) -> 218 | F21: =SUM(F19:F20) -> 217 | G21: =SUM(G19:G20) -> 220 | H21: =SUM(H19:H20) -> 247 | I21: =SUM(I19:I20) -> 189 | J21: =SUM(J19:J20) -> 221 | K21: =SUM(K19:K20) -> 218 | L21: =SUM(L19:L20) -> 219 | ... AB21: =SUM(AB19:AB20) -> 202 | AC21: =SUM(E21:AB21) -> 5039
B22: 2. | C22: Jumlah pengguna hak pilih dalam Daftar Pemilih Tambahan (DPTb) | D22: LK | E22: 1 | F22: 0 | G22: 1 | H22: 1 | I22: 0 | J22: 0 | K22: 0 | L22: 0 | M22: 1 | N22: 1 | O22: 0 | P22: 0 | Q22: 1 | R22: 1 | S22: 0 | T22: 0 | U22: 1 | V22: 0 | W22: 2 | X22: 0 | Y22: 0 | Z22: 0 | AA22: 0 | AB22: 0 | AC22: =SUM(E22:AB22) -> 10
D23: PR | E23: 1 | F23: 1 | G23: 0 | H23: 0 | I23: 0 | J23: 1 | K23: 1 | L23: 1 | M23: 0 | N23: 1 | O23: 0 | P23: 1 | Q23: 0 | R23: 0 | S23: 1 | T23: 2 | U23: 1 | V23: 1 | W23: 1 | X23: 1 | Y23: 1 | Z23: 1 | AA23: 1 | AB23: 1 | AC23: =SUM(E23:AB23) -> 18
D24: JML | E24: =SUM(E22:E23) -> 2 | F24: =SUM(F22:F23) -> 1 | G24: =SUM(G22:G23) -> 1 | H24: =SUM(H22:H23) -> 1 | I24: =SUM(I22:I23) -> 0 | J24: =SUM(J22:J23) -> 1 | K24: =SUM(K22:K23) -> 1 | L24: =SUM(L22:L23) -> 1 | ... AB24: =SUM(AB22:AB23) -> 1 | AC24: =SUM(E24:AB24) -> 28
B25: 3. | C25: Jumlah pengguna hak pilih dalam Daftar Pemilih Khusus (DPK) | D25: LK | E25: 2 | F25: 1 | G25: 0 | H25: 0 | I25: 0 | J25: 0 | K25: 2 | L25: 4 | M25: 0 | N25: 0 | O25: 0 | P25: 3 | Q25: 1 | R25: 0 | S25: 1 | T25: 0 | U25: 3 | V25: 1 | W25: 0 | X25: 1 | Y25: 0 | Z25: 5 | AA25: 1 | AB25: 3 | AC25: =SUM(E25:AB25) -> 28
D26: PR | E26: 4 | F26: 3 | G26: 0 | H26: 0 | I26: 1 | J26: 1 | K26: 0 | L26: 4 | M26: 0 | N26: 1 | O26: 1 | P26: 4 | Q26: 1 | R26: 0 | S26: 2 | T26: 0 | U26: 1 | V26: 1 | W26: 0 | X26: 3 | Y26: 0 | Z26: 1 | AA26: 5 | AB26: 4 | AC26: =SUM(E26:AB26) -> 37
D27: JML | E27: =SUM(E25:E26) -> 6 | F27: =SUM(F25:F26) -> 4 | G27: =SUM(G25:G26) -> 0 | H27: =SUM(H25:H26) -> 0 | I27: =SUM(I25:I26) -> 1 | J27: =SUM(J25:J26) -> 1 | K27: =SUM(K25:K26) -> 2 | L27: =SUM(L25:L26) -> 8 | ... AB27: =SUM(AB25:AB26) -> 7 | AC27: =SUM(E27:AB27) -> 65
B28: 4. | C28: Jumlah Pengguna Hak Pilih (B.1+B.2+B.3) | D28: LK | E28: =SUM(E19,E22,E25) -> 104 | F28: =SUM(F19,F22,F25) -> 103 | G28: =SUM(G19,G22,G25) -> 102 | H28: =SUM(H19,H22,H25) -> 123 | I28: =SUM(I19,I22,I25) -> 82 | J28: =SUM(J19,J22,J25) -> 102 | K28: =SUM(K19,K22,K25) -> 113 | L28: =SUM(L19,L22,L25) -> 102 | ... AB28: =SUM(AB19,AB22,AB25) -> 97 | AC28: =SUM(E28:AB28) -> 2377
D29: PR | E29: =SUM(E20,E23,E26) -> 122 | F29: =SUM(F20,F23,F26) -> 119 | G29: =SUM(G20,G23,G26) -> 119 | H29: =SUM(H20,H23,H26) -> 125 | I29: =SUM(I20,I23,I26) -> 108 | J29: =SUM(J20,J23,J26) -> 121 | K29: =SUM(K20,K23,K26) -> 108 | L29: =SUM(L20,L23,L26) -> 126 | ... AB29: =SUM(AB20,AB23,AB26) -> 113 | AC29: =SUM(E29:AB29) -> 2755
D30: JML | E30: =SUM(E28:E29) -> 226 | F30: =SUM(F28:F29) -> 222 | G30: =SUM(G28:G29) -> 221 | H30: =SUM(H28:H29) -> 248 | I30: =SUM(I28:I29) -> 190 | J30: =SUM(J28:J29) -> 223 | K30: =SUM(K28:K29) -> 221 | L30: =SUM(L28:L29) -> 228 | ... AB30: =SUM(AB28:AB29) -> 210 | AC30: =SUM(E30:AB30) -> 5132
A32: II | B32: DATA PENGGUNAAN SURAT SUARA
A33: 1 | B33: Jumlah surat suara yang diterima, termasuk surat suara cadangan 2,5% dari DPT | E33: 302 | F33: 286 | G33: 278 | H33: 301 | I33: 272 | J33: 286 | K33: 286 | L33: 291 | M33: 290 | N33: 280 | O33: 280 | P33: 232 | Q33: 295 | R33: 290 | S33: 284 | T33: 291 | U33: 283 | V33: 270 | W33: 285 | X33: 302 | Y33: 229 | Z33: 201 | AA33: 296 | AB33: 245 | AC33: =SUM(E33:AB33) -> 6655
A34: 2 | B34: Jumlah surat suara yang digunakan | E34: 226 | F34: 222 | G34: 221 | H34: 248 | I34: 190 | J34: 223 | K34: 221 | L34: 228 | M34: 215 | N34: 216 | O34: 205 | P34: 176 | Q34: 192 | R34: 202 | S34: 201 | T34: 240 | U34: 249 | V34: 232 | W34: 227 | X34: 225 | Y34: 191 | Z34: 163 | AA34: 209 | AB34: 210 | AC34: =SUM(E34:AB34) -> 5132
A35: 3 | B35: Jumlah surat suara dikembalikan oleh pemilih (karena rusak atau keliru coblos) | E35: 1 | F35: 0 | G35: 1 | H35: 0 | I35: 0 | J35: 0 | K35: 1 | L35: 1 | M35: 0 | N35: 1 | O35: 0 | P35: 0 | Q35: 0 | R35: 0 | S35: 0 | T35: 0 | U35: 0 | V35: 0 | W35: 0 | X35: 6 | Y35: 0 | Z35: 3 | AA35: 2 | AB35: 0 | AC35: =SUM(E35:AB35) -> 16
A36: 4 | B36: Jumlah surat suara yang tidak digunakan/tidak terpakai, termasuk sisa surat suara cadangan | E36: =E33-(E34+E35) -> 75 | F36: =F33-(F34+F35) -> 64 | G36: =G33-(G34+G35) -> 56 | H36: =H33-(H34+H35) -> 53 | I36: =I33-(I34+I35) -> 82 | J36: =J33-(J34+J35) -> 63 | K36: =K33-(K34+K35) -> 64 | L36: =L33-(L34+L35) -> 62 | ... AB36: =AB33-(AB34+AB35) -> 35 | AC36: =SUM(E36:AB36) -> 1507
A38: III | B38: DATA PEMILIH DISABILITAS
B39: Jumlah seluruh Pemilih disabilitas yang menggunakan hak pilih | D39: LK | E39: 0 | F39: 0 | G39: 0 | H39: 0 | I39: 1 | J39: 0 | K39: 3 | L39: 0 | M39: 0 | N39: 0 | O39: 0 | P39: 0 | Q39: 0 | R39: 0 | S39: 0 | T39: 0 | U39: 0 | V39: 0 | W39: 0 | X39: 0 | Y39: 0 | Z39: 0 | AA39: 0 | AB39: 0 | AC39: =SUM(E39:AB39) -> 4
D40: PR | E40: 0 | F40: 0 | G40: 0 | H40: 0 | I40: 0 | J40: 0 | K40: 6 | L40: 0 | M40: 0 | N40: 0 | O40: 0 | P40: 0 | Q40: 0 | R40: 0 | S40: 0 | T40: 0 | U40: 0 | V40: 0 | W40: 0 | X40: 0 | Y40: 0 | Z40: 0 | AA40: 0 | AB40: 0 | AC40: =SUM(E40:AB40) -> 6
D41: JML | E41: =SUM(E39:E40) -> 0 | F41: =SUM(F39:F40) -> 0 | G41: =SUM(G39:G40) -> 0 | H41: =SUM(H39:H40) -> 0 | I41: =SUM(I39:I40) -> 1 | J41: =SUM(J39:J40) -> 0 | K41: =SUM(K39:K40) -> 9 | L41: =SUM(L39:L40) -> 0 | ... AB41: =SUM(AB39:AB40) -> 0 | AC41: =SUM(E41:AB41) -> 10
A43: IV | B43: DATA RINCIAN PEROLEHAN SUARA PASANGAN CALON BUPATI DAN WAKIL BUPATI
A44: NOMOR DAN NAMA CALON
B45: 1 | C45: H. ANIES RASYID BASWEDAN, Ph.D. - Dr. (H.C.) H. A. MUHAIMIN ISKANDAR | E45: 46 | F45: 47 | G45: 63 | H45: 22 | I45: 25 | J45: 56 | K45: 70 | L45: 75 | M45: 48 | N45: 29 | O45: 39 | P45: 20 | Q45: 55 | R45: 44 | S45: 13 | T45: 130 | U45: 106 | V45: 71 | W45: 82 | X45: 82 | Y45: 51 | Z45: 50 | AA45: 59 | AB45: 89 | AC45: =SUM(E45:AB45) -> 1372
B46: 2 | C46: H. PRABOWO SUBIANTO - GIBRAN RAKABUMING RAKA | E46: 157 | F46: 153 | G46: 126 | H46: 198 | I46: 139 | J46: 132 | K46: 121 | L46: 113 | M46: 108 | N46: 140 | O46: 130 | P46: 111 | Q46: 109 | R46: 111 | S46: 128 | T46: 88 | U46: 97 | V46: 130 | W46: 124 | X46: 108 | Y46: 102 | Z46: 81 | AA46: 115 | AB46: 86 | AC46: =SUM(E46:AB46) -> 2907
B47: 3 | C47: H. GANJAR PRANOWO, S.H., M.I.P. - Prof. Dr. H. M. MAHFUD MD | E47: 23 | F47: 16 | G47: 30 | H47: 21 | I47: 22 | J47: 34 | K47: 28 | L47: 35 | M47: 55 | N47: 45 | O47: 32 | P47: 43 | Q47: 25 | R47: 42 | S47: 52 | T47: 19 | U47: 44 | V47: 29 | W47: 19 | X47: 29 | Y47: 28 | Z47: 29 | AA47: 31 | AB47: 35 | AC47: =SUM(E47:AB47) -> 766
A49: V | B49: DATA SUARA SAH DAN TIDAK SAH
B50: A. | C50: JUMLAH SELURUH SUARA SAH | E50: =SUM(E45:E47) -> 226 | F50: =SUM(F45:F47) -> 216 | G50: =SUM(G45:G47) -> 219 | H50: =SUM(H45:H47) -> 241 | I50: =SUM(I45:I47) -> 186 | J50: =SUM(J45:J47) -> 222 | K50: =SUM(K45:K47) -> 219 | L50: =SUM(L45:L47) -> 223 | ... AB50: =SUM(AB45:AB47) -> 210 | AC50: =SUM(E50:AB50) -> 5045
B51: B. | C51: JUMLAH SUARA TIDAK SAH | E51: 0 | F51: 6 | G51: 2 | H51: 7 | I51: 4 | J51: 1 | K51: 2 | L51: 5 | M51: 4 | N51: 2 | O51: 4 | P51: 2 | Q51: 3 | R51: 5 | S51: 8 | T51: 3 | U51: 2 | V51: 2 | W51: 2 | X51: 6 | Y51: 10 | Z51: 3 | AA51: 4 | AB51: 0 | AC51: =SUM(E51:AB51) -> 87
B52: C. | C52: JUMLAH SELURUH SUARA SAH DAN SUARA TIDAK SAH (V.A + V.B) | E52: =SUM(E50:E51) -> 226 | F52: =SUM(F50:F51) -> 222 | G52: =SUM(G50:G51) -> 221 | H52: =SUM(H50:H51) -> 248 | I52: =SUM(I50:I51) -> 190 | J52: =SUM(J50:J51) -> 223 | K52: =SUM(K50:K51) -> 221 | L52: =SUM(L50:L51) -> 228 | ... AB52: =SUM(AB50:AB51) -> 210 | AC52: =SUM(E52:AB52) -> 5132

Sheet Ketapang
C2: Kecamatan
C3: Kabupaten | D3: BANYUWANGI
C4: Provinsi | D4: JAWA TIMUR
C9: Kelurahan
A12: I | B12: DATA PEMILIH DAN PENGGUNAAN HAK PILIH | BE12: JUMLAH AKHIR
A13: A | B13: DATA PEMILIH | E13: TPS 001 | F13: TPS 002 | G13: TPS 003 | H13: TPS 004 | I13: TPS 005 | J13: TPS 006 | K13: TPS 007 | L13: TPS 008 | M13: TPS 009 | N13: TPS 010 | O13: TPS 011 | P13: TPS 012 | Q13: TPS 013 | R13: TPS 014 | S13: TPS 015 | T13: TPS 016 | U13: TPS 017 | V13: TPS 018 | W13: TPS 019 | X13: TPS 020 | Y13: TPS 021 | Z13: TPS 022 | AA13: TPS 023 | AB13: TPS 024 | AC13: TPS 025 | AD13: TPS 026 | AE13: TPS 027 | AF13: TPS 028 | AG13: TPS 029 | AH13: TPS 030 | AI13: TPS 031 | AJ13: TPS 032 | AK13: TPS 033 | AL13: TPS 034 | AM13: TPS 035 | AN13: TPS 036 | AO13: TPS 037 | AP13: TPS 038 | AQ13: TPS 039 | AR13: TPS 040 | AS13: TPS 041 | AT13: TPS 042 | AU13: TPS 043 | AV13: TPS 044 | AW13: TPS 045 | AX13: TPS 046 | AY13: TPS 047 | AZ13: TPS 048 | BA13: TPS 049 | BB13: TPS 050 | BC13: TPS 051 | BD13: TPS 052
B14: Jumlah Pemilih dalam Daftar Pemilih Tetap (DPT) | D14: LK | E14: 138 | F14: 139 | G14: 141 | H14: 142 | I14: 141 | J14: 101 | K14: 124 | L14: 133 | M14: 108 | N14: 93 | O14: 138 | P14: 122 | Q14: 138 | R14: 144 | S14: 140 | T14: 125 | U14: 124 | V14: 128 | W14: 112 | X14: 95 | Y14: 140 | Z14: 128 | AA14: 139 | AB14: 146 | AC14: 149 | AD14: 140 | AE14: 107 | AF14: 142 | AG14: 142 | AH14: 141 | AI14: 133 | AJ14: 135 | AK14: 132 | AL14: 146 | AM14: 127 | AN14: 148 | AO14: 143 | AP14: 131 | AQ14: 98 | AR14: 143 | AS14: 135 | AT14: 136 | AU14: 137 | AV14: 139 | AW14: 123 | AX14: 125 | AY14: 91 | AZ14: 137 | BA14: 121 | BB14: 125 | BC14: 121 | BD14: 116 | BE14: =SUM(E14:BD14) -> 6742
D15: PR | E15: 128 | F15: 132 | G15: 148 | H15: 139 | I15: 142 | J15: 125 | K15: 155 | L15: 131 | M15: 107 | N15: 94 | O15: 156 | P15: 129 | Q15: 148 | R15: 139 | S15: 136 | T15: 132 | U15: 139 | V15: 141 | W15: 123 | X15: 100 | Y15: 142 | Z15: 146 | AA15: 146 | AB15: 154 | AC15: 150 | AD15: 157 | AE15: 105 | AF15: 153 | AG15: 145 | AH15: 147 | AI15: 140 | AJ15: 155 | AK15: 124 | AL15: 150 | AM15: 142 | AN15: 148 | AO15: 154 | AP15: 135 | AQ15: 120 | AR15: 147 | AS15: 149 | AT15: 134 | AU15: 133 | AV15: 133 | AW15: 129 | AX15: 137 | AY15: 102 | AZ15: 147 | BA15: 126 | BB15: 126 | BC15: 134 | BD15: 104 | BE15: =SUM(E15:BD15) -> 7058
D16: JML | E16: =SUM(E14:E15) -> 266 | F16: =SUM(F14:F15) -> 271 | G16: =SUM(G14:G15) -> 289 | H16: =SUM(H14:H15) -> 281 | I16: =SUM(I14:I15) -> 283 | J16: =SUM(J14:J15) -> 226 | K16: =SUM(K14:K15) -> 279 | L16: =SUM(L14:L15) -> 264 | ... BD16: =SUM(BD14:BD15) -> 220 | BE16: =SUM(E16:BD16) -> 13800
A18: B | B18: PENGGUNA HAK PILIH
B19: 1. | C19: Jumlah pengguna hak pilih dalam Daftar Pemilih Tetap (DPT) | D19: LK | E19: 98 | F19: 98 | G19: 96 | H19: 100 | I19: 100 | J19: 70 | K19: 81 | L19: 85 | M19: 75 | N19: 71 | O19: 77 | P19: 74 | Q19: 94 | R19: 97 | S19: 83 | T19: 91 | U19: 72 | V19: 92 | W19: 68 | X19: 78 | Y19: 104 | Z19: 99 | AA19: 129 | AB19: 116 | AC19: 114 | AD19: 110 | AE19: 90 | AF19: 118 | AG19: 102 | AH19: 120 | AI19: 105 | AJ19: 100 | AK19: 97 | AL19: 96 | AM19: 90 | AN19: 101 | AO19: 97 | AP19: 96 | AQ19: 67 | AR19: 97 | AS19: 95 | AT19: 100 | AU19: 103 | AV19: 110 | AW19: 104 | AX19: 83 | AY19: 65 | AZ19: 103 | BA19: 94 | BB19: 92 | BC19: 94 | BD19: 77 | BE19: =SUM(E19:BD19) -> 4868
D20: PR | E20: 100 | F20: 97 | G20: 117 | H20: 112 | I20: 118 | J20: 97 | K20: 115 | L20: 106 | M20: 84 | N20: 76 | O20: 98 | P20: 92 | Q20: 117 | R20: 108 | S20: 107 | T20: 106 | U20: 100 | V20: 110 | W20: 90 | X20: 88 | Y20: 113 | Z20: 119 | AA20: 137 | AB20: 127 | AC20: 151 | AD20: 152 | AE20: 97 | AF20: 118 | AG20: 121 | AH20: 127 | AI20: 114 | AJ20: 120 | AK20: 104 | AL20: 117 | AM20: 105 | AN20: 118 | AO20: 118 | AP20: 104 | AQ20: 94 | AR20: 114 | AS20: 122 | AT20: 104 | AU20: 101 | AV20: 110 | AW20: 106 | AX20: 116 | AY20: 84 | AZ20: 114 | BA20: 97 | BB20: 83 | BC20: 102 | BD20: 83 | BE20: =SUM(E20:BD20) -> 5630
D21: JML | E21: =SUM(E19:E20) -> 198 | F21: =SUM(F19:F20) -> 195 | G21: =SUM(G19:G20) -> 213 | H21: =SUM(H19:H20) -> 212 | I21: =SUM(I19:I20) -> 218 | J21: =SUM(J19:J20) -> 167 | K21: =SUM(K19:K20) -> 196 | L21: =SUM(L19:L20) -> 191 | ... BD21: =SUM(BD19:BD20) -> 160 | BE21: =SUM(E21:BD21) -> 10498
B22: 2. | C22: Jumlah pengguna hak pilih dalam Daftar Pemilih Tambahan (DPTb) | D22: LK | E22: 4 | F22: 2 | G22: 1 | H22: 0 | I22: 0 | J22: 0 | K22: 1 | L22: 2 | M22: 0 | N22: 2 | O22: 6 | P22: 0 | Q22: 3 | R22: 0 | S22: 1 | T22: 1 | U22: 1 | V22: 0 | W22: 2 | X22: 1 | Y22: 0 | Z22: 0 | AA22: 1 | AB22: 2 | AC22: 1 | AD22: 1 | AE22: 0 | AF22: 0 | AG22: 0 | AH22: 0 | AI22: 1 | AJ22: 0 | AK22: 0 | AL22: 1 | AM22: 1 | AN22: 0 | AO22: 0 | AP22: 1 | AQ22: 0 | AR22: 1 | AS22: 1 | AT22: 1 | AU22: 1 | AV22: 2 | AW22: 1 | AX22: 0 | AY22: 1 | AZ22: 3 | BA22: 3 | BB22: 0 | BC22: 1 | BD22: 5 | BE22: =SUM(E22:BD22) -> 56
D23: PR | E23: 2 | F23: 1 | G23: 0 | H23: 1 | I23: 1 | J23: 1 | K23: 0 | L23: 0 | M23: 1 | N23: 1 | O23: 2 | P23: 0 | Q23: 3 | R23: 1 | S23: 1 | T23: 0 | U23: 0 | V23: 1 | W23: 2 | X23: 0 | Y23: 1 | Z23: 0 | AA23: 0 | AB23: 0 | AC23: 0 | AD23: 0 | AE23: 1 | AF23: 0 | AG23: 0 | AH23: 1 | AI23: 0 | AJ23: 1 | AK23: 2 | AL23: 1 | AM23: 0 | AN23: 0 | AO23: 1 | AP23: 0 | AQ23: 0 | AR23: 2 | AS23: 0 | AT23: 0 | AU23: 0 | AV23: 2 | AW23: 0 | AX23: 0 | AY23: 0 | AZ23: 2 | BA23: 0 | BB23: 0 | BC23: 0 | BD23: 2 | BE23: =SUM(E23:BD23) -> 34
D24: JML | E24: =SUM(E22:E23) -> 6 | F24: =SUM(F22:F23) -> 3 | G24: =SUM(G22:G23) -> 1 | H24: =SUM(H22:H23) -> 1 | I24: =SUM(I22:I23) -> 1 | J24: =SUM(J22:J23) -> 1 | K24: =SUM(K22:K23) -> 1 | L24: =SUM(L22:L23) -> 2 | ... AD24: =SUM(AD22:AD23) -> 1 | AE24: 1 | AF24: =SUM(AF22:AF23) -> 0 | AG24: =SUM(AG22:AG23) -> 0 | AH24: =SUM(AH22:AH23) -> 1 | AI24: =SUM(AI22:AI23) -> 1 | AJ24: =SUM(AJ22:AJ23) -> 1 | AK24: =SUM(AK22:AK23) -> 2 | AL24: =SUM(AL22:AL23) -> 2 | AM24: =SUM(AM22:AM23) -> 1 | ... BD24: =SUM(BD22:BD23) -> 7 | BE24: =SUM(E24:BD24) -> 90
B25: 3. | C25: Jumlah pengguna hak pilih dalam Daftar Pemilih Khusus (DPK) | D25: LK | E25: 1 | F25: 0 | G25: 0 | H25: 0 | I25: 0 | J25: 1 | K25: 1 | L25: 0 | M25: 0 | N25: 0 | O25: 0 | P25: 4 | Q25: 7 | R25: 2 | S25: 1 | T25: 0 | U25: 2 | V25: 1 | W25: 3 | X25: 2 | Y25: 1 | Z25: 2 | AA25: 0 | AB25: 3 | AC25: 1 | AD25: 7 | AE25: 2 | AF25: 0 | AG25: 0 | AH25: 1 | AI25: 1 | AJ25: 3 | AK25: 0 | AL25: 2 | AM25: 0 | AN25: 0 | AO25: 2 | AP25: 1 | AQ25: 1 | AR25: 2 | AS25: 0 | AT25: 0 | AU25: 0 | AV25: 1 | AW25: 0 | AX25: 1 | AY25: 1 | AZ25: 0 | BA25: 1 | BB25: 0 | BC25: 1 | BD25: 1 | BE25: =SUM(E25:BD25) -> 60
