Workbook

Sheet PPWP
C8: Kecamatan | D8: PURWOHARJO
C9: Kabupaten | D9: BANYUWANGI
C10: Provinsi | D10: JAWA TIMUR
A12: I | B12: DATA PEMILIH DAN PENGGUNAAN HAK PILIH | E12: JUMLAH AKHIR
A13: A | B13: DATA PEMILIH
B14: Jumlah Pemilih dalam Daftar Pemilih Tetap (DPT) | D14: LK | E14: =BULUREJO!AF14+GLAGAHAGUNG!AA14+GRAJAGAN!AV14+KARETAN!O14+KRADENAN!AK14+PURWOHARJO!AK14+SIDOREJO!AA14+SUMBERASRI!X14 -> 27886
D15: PR | E15: =BULUREJO!AF15+GLAGAHAGUNG!AA15+GRAJAGAN!AV15+KARETAN!O15+KRADENAN!AK15+PURWOHARJO!AK15+SIDOREJO!AA15+SUMBERASRI!X15 -> 27699
D16: JML | E16: =SUM(E14:E15) -> 55585
A18: B | B18: PENGGUNA HAK PILIH
B19: 1. | C19: Jumlah pengguna hak pilih dalam Daftar Pemilih Tetap (DPT) | D19: LK | E19: =BULUREJO!AF19+GLAGAHAGUNG!AA19+GRAJAGAN!AV19+KARETAN!O19+KRADENAN!AK19+PURWOHARJO!AK19+SIDOREJO!AA19+SUMBERASRI!X19 -> 21193
D20: PR | E20: =BULUREJO!AF20+GLAGAHAGUNG!AA20+GRAJAGAN!AV20+KARETAN!O20+KRADENAN!AK20+PURWOHARJO!AK20+SIDOREJO!AA20+SUMBERASRI!X20 -> 21906
D21: JML | E21: =SUM(E19:E20) -> 43099
B22: 2. | C22: Jumlah pengguna hak pilih dalam Daftar Pemilih Tambahan (DPTb) | D22: LK | E22: =BULUREJO!AF22+GLAGAHAGUNG!AA22+GRAJAGAN!AV22+KARETAN!O22+KRADENAN!AK22+PURWOHARJO!AK22+SIDOREJO!AA22+SUMBERASRI!X22 -> 23
D23: PR | E23: =BULUREJO!AF23+GLAGAHAGUNG!AA23+GRAJAGAN!AV23+KARETAN!O23+KRADENAN!AK23+PURWOHARJO!AK23+SIDOREJO!AA23+SUMBERASRI!X23 -> 18
D24: JML | E24: =SUM(E22:E23) -> 41
B25: 3. | C25: Jumlah pengguna hak pilih dalam Daftar Pemilih Khusus (DPK) | D25: LK | E25: =BULUREJO!AF25+GLAGAHAGUNG!AA25+GRAJAGAN!AV25+KARETAN!O25+KRADENAN!AK25+PURWOHARJO!AK25+SIDOREJO!AA25+SUMBERASRI!X25 -> 228
D26: PR | E26: =BULUREJO!AF26+GLAGAHAGUNG!AA26+GRAJAGAN!AV26+KARETAN!O26+KRADENAN!AK26+PURWOHARJO!AK26+SIDOREJO!AA26+SUMBERASRI!X26 -> 279
D27: JML | E27: =SUM(E25:E26) -> 507
B28: 4. | C28: Jumlah Pengguna Hak Pilih (B.1+B.2+B.3) | D28: LK | E28: =E19+E22+E25 -> 21444
D29: PR | E29: =E20+E23+E26 -> 22203
D30: JML | E30: =SUM(E28:E29) -> 43647
A32: II | B32: DATA PENGGUNAAN SURAT SUARA
A33: 1 | B33: Jumlah surat suara yang diterima, termasuk surat suara cadangan 2,5% dari DPT | E33: =BULUREJO!AF33+GLAGAHAGUNG!AA33+GRAJAGAN!AV33+KARETAN!O33+KRADENAN!AK33+PURWOHARJO!AK33+SIDOREJO!AA33+SUMBERASRI!X33 -> 56860
A34: 2 | B34: Jumlah surat suara yang digunakan | E34: =BULUREJO!AF34+GLAGAHAGUNG!AA34+GRAJAGAN!AV34+KARETAN!O34+KRADENAN!AK34+PURWOHARJO!AK34+SIDOREJO!AA34+SUMBERASRI!X34 -> 43647
A35: 3 | B35: Jumlah surat suara dikembalikan oleh pemilih (karena rusak atau keliru coblos) | E35: =BULUREJO!AF35+GLAGAHAGUNG!AA35+GRAJAGAN!AV35+KARETAN!O35+KRADENAN!AK35+PURWOHARJO!AK35+SIDOREJO!AA35+SUMBERASRI!X35 -> 65
A36: 4 | B36: Jumlah surat suara yang tidak digunakan/tidak terpakai, termasuk sisa surat suara cadangan | E36: =E33-(E34+E35) -> 13148
A38: III | B38: DATA PEMILIH DISABILITAS
B39: Jumlah seluruh Pemilih disabilitas yang menggunakan hak pilih | D39: LK | E39: =BULUREJO!AF39+GLAGAHAGUNG!AA39+GRAJAGAN!AV39+KARETAN!O39+KRADENAN!AK39+PURWOHARJO!AK39+SIDOREJO!AA39+SUMBERASRI!X39 -> 19
D40: PR | E40: =BULUREJO!AF40+GLAGAHAGUNG!AA40+GRAJAGAN!AV40+KARETAN!O40+KRADENAN!AK40+PURWOHARJO!AK40+SIDOREJO!AA40+SUMBERASRI!X40 -> 20
D41: JML | E41: =SUM(E39:E40) -> 39
A43: IV | B43: DATA RINCIAN PEROLEHAN SUARA PASANGAN CALON BUPATI DAN WAKIL BUPATI
A44: NOMOR DAN NAMA CALON
B45: 1 | C45: H. ANIES RASYID BASWEDAN, Ph.D. - Dr. (H.C.) H. A. MUHAIMIN ISKANDAR | E45: =BULUREJO!AF45+GLAGAHAGUNG!AA45+GRAJAGAN!AV45+KARETAN!O45+KRADENAN!AK45+PURWOHARJO!AK45+SIDOREJO!AA45+SUMBERASRI!X45 -> 4388
B46: 2 | C46: H. PRABOWO SUBIANTO - GIBRAN RAKABUMING RAKA | E46: =BULUREJO!AF46+GLAGAHAGUNG!AA46+GRAJAGAN!AV46+KARETAN!O46+KRADENAN!AK46+PURWOHARJO!AK46+SIDOREJO!AA46+SUMBERASRI!X46 -> 30382
B47: 3 | C47: H. GANJAR PRANOWO, S.H., M.I.P. - Prof. Dr. H. M. MAHFUD MD | E47: =BULUREJO!AF47+GLAGAHAGUNG!AA47+GRAJAGAN!AV47+KARETAN!O47+KRADENAN!AK47+PURWOHARJO!AK47+SIDOREJO!AA47+SUMBERASRI!X47 -> 8340
A49: V | B49: DATA SUARA SAH DAN TIDAK SAH
B50: A. | C50: JUMLAH SELURUH SUARA SAH | E50: =BULUREJO!AF50+GLAGAHAGUNG!AA50+GRAJAGAN!AV50+KARETAN!O50+KRADENAN!AK50+PURWOHARJO!AK50+SIDOREJO!AA50+SUMBERASRI!X50 -> 43110
B51: B. | C51: JUMLAH SUARA TIDAK SAH | E51: =BULUREJO!AF51+GLAGAHAGUNG!AA51+GRAJAGAN!AV51+KARETAN!O51+KRADENAN!AK51+PURWOHARJO!AK51+SIDOREJO!AA51+SUMBERASRI!X51 -> 537
B52: C. | C52: JUMLAH SELURUH SUARA SAH DAN SUARA TIDAK SAH (V.A + V.B) | E52: =SUM(E50:E51) -> 43647

Sheet GRAJAGAN
C2: Kecamatan | D2: PURWOHARJO
C3: Kabupaten | D3: BANYUWANGI
C4: Provinsi | D4: JAWA TIMUR
C9: Kelurahan | D9: GRAJAGAN
A12: I | B12: DATA PEMILIH DAN PENGGUNAAN HAK PILIH | AV12: JUMLAH AKHIR
A13: A | B13: DATA PEMILIH | E13: TPS 001 | F13: TPS 002 | G13: TPS 003 | H13: TPS 004 | I13: TPS 005 | J13: TPS 006 | K13: TPS 007 | L13: TPS 008 | M13: TPS 009 | N13: TPS 010 | O13: TPS 011 | P13: TPS 012 | Q13: TPS 013 | R13: TPS 014 | S13: TPS 015 | T13: TPS 016 | U13: TPS 017 | V13: TPS 018 | W13: TPS 019 | X13: TPS 020 | Y13: TPS 021 | Z13: TPS 022 | AA13: TPS 023 | AB13: TPS 024 | AC13: TPS 025 | AD13: TPS 026 | AE13: TPS 027 | AF13: TPS 028 | AG13: TPS 029 | AH13: TPS 030 | AI13: TPS 031 | AJ13: TPS 032 | AK13: TPS 033 | AL13: TPS 034 | AM13: TPS 035 | AN13: TPS 036 | AO13: TPS 037 | AP13: TPS 038 | AQ13: TPS 039 | AR13: TPS 040 | AS13: TPS 041 | AT13: TPS 042 | AU13: TPS 043
B14: Jumlah Pemilih dalam Daftar Pemilih Tetap (DPT) | D14: LK | E14: 133 | F14: 134 | G14: 131 | H14: 125 | I14: 129 | J14: 128 | K14: 127 | L14: 128 | M14: 131 | N14: 133 | O14: 130 | P14: 142 | Q14: 127 | R14: 133 | S14: 135 | T14: 131 | U14: 136 | V14: 131 | W14: 143 | X14: 129 | Y14: 127 | Z14: 131 | AA14: 137 | AB14: 134 | AC14: 141 | AD14: 130 | AE14: 131 | AF14: 138 | AG14: 138 | AH14: 142 | AI14: 133 | AJ14: 139 | AK14: 129 | AL14: 125 | AM14: 132 | AN14: 133 | AO14: 128 | AP14: 149 | AQ14: 130 | AR14: 143 | AS14: 130 | AT14: 136 | AU14: 141 | AV14: =SUM(E14:AU14) -> 5733
D15: PR | E15: 131 | F15: 127 | G15: 135 | H15: 127 | I15: 141 | J15: 136 | K15: 136 | L15: 139 | M15: 138 | N15: 132 | O15: 137 | P15: 121 | Q15: 130 | R15: 130 | S15: 134 | T15: 127 | U15: 129 | V15: 125 | W15: 124 | X15: 124 | Y15: 134 | Z15: 138 | AA15: 140 | AB15: 138 | AC15: 138 | AD15: 128 | AE15: 140 | AF15: 139 | AG15: 134 | AH15: 128 | AI15: 115 | AJ15: 122 | AK15: 138 | AL15: 124 | AM15: 133 | AN15: 124 | AO15: 141 | AP15: 117 | AQ15: 126 | AR15: 121 | AS15: 130 | AT15: 135 | AU15: 133 | AV15: =SUM(E15:AU15) -> 5639
D16: JML | E16: =SUM(E14:E15) -> 264 | F16: =SUM(F14:F15) -> 261 | G16: =SUM(G14:G15) -> 266 | H16: =SUM(H14:H15) -> 252 | I16: =SUM(I14:I15) -> 270 | J16: =SUM(J14:J15) -> 264 | K16: =SUM(K14:K15) -> 263 | L16: =SUM(L14:L15) -> 267 | ... AU16: =SUM(AU14:AU15) -> 274 | AV16: =SUM(E16:AU16) -> 11372
A18: B | B18: PENGGUNA HAK PILIH
B19: 1. | C19: Jumlah pengguna hak pilih dalam Daftar Pemilih Tetap (DPT) | D19: LK | E19: 90 | F19: 97 | G19: 95 | H19: 92 | I19: 89 | J19: 92 | K19: 88 | L19: 95 | M19: 95 | N19: 96 | O19: 93 | P19: 99 | Q19: 93 | R19: 90 | S19: 97 | T19: 88 | U19: 102 | V19: 110 | W19: 106 | X19: 95 | Y19: 108 | Z19: 104 | AA19: 97 | AB19: 106 | AC19: 108 | AD19: 89 | AE19: 101 | AF19: 99 | AG19: 101 | AH19: 105 | AI19: 84 | AJ19: 113 | AK19: 96 | AL19: 86 | AM19: 97 | AN19: 85 | AO19: 98 | AP19: 117 | AQ19: 91 | AR19: 109 | AS19: 100 | AT19: 102 | AU19: 114 | AV19: =SUM(E19:AU19) -> 4212
D20: PR | E20: 104 | F20: 99 | G20: 110 | H20: 94 | I20: 98 | J20: 98 | K20: 106 | L20: 110 | M20: 99 | N20: 96 | O20: 108 | P20: 95 | Q20: 91 | R20: 84 | S20: 100 | T20: 94 | U20: 94 | V20: 108 | W20: 101 | X20: 98 | Y20: 113 | Z20: 117 | AA20: 109 | AB20: 107 | AC20: 112 | AD20: 98 | AE20: 104 | AF20: 113 | AG20: 96 | AH20: 105 | AI20: 81 | AJ20: 88 | AK20: 93 | AL20: 89 | AM20: 94 | AN20: 76 | AO20: 103 | AP20: 93 | AQ20: 96 | AR20: 89 | AS20: 103 | AT20: 105 | AU20: 104 | AV20: =SUM(E20:AU20) -> 4275
D21: JML | E21: =SUM(E19:E20) -> 194 | F21: =SUM(F19:F20) -> 196 | G21: =SUM(G19:G20) -> 205 | H21: =SUM(H19:H20) -> 186 | I21: =SUM(I19:I20) -> 187 | J21: =SUM(J19:J20) -> 190 | K21: =SUM(K19:K20) -> 194 | L21: =SUM(L19:L20) -> 205 | ... AU21: =SUM(AU19:AU20) -> 218 | AV21: =SUM(E21:AU21) -> 8487
B22: 2. | C22: Jumlah pengguna hak pilih dalam Daftar Pemilih Tambahan (DPTb) | D22: LK | E22: 0 | F22: 0 | G22: 0 | H22: 0 | I22: 0 | J22: 0 | K22: 0 | L22: 0 | M22: 0 | N22: 0 | O22: 0 | P22: 0 | Q22: 0 | R22: 0 | S22: 0 | T22: 0 | U22: 0 | V22: 0 | W22: 0 | X22: 0 | Y22: 0 | Z22: 0 | AA22: 0 | AB22: 0 | AC22: 0 | AD22: 0 | AE22: 0 | AF22: 0 | AG22: 0 | AH22: 0 | AI22: 0 | AJ22: 0 | AK22: 0 | AL22: 0 | AM22: 1 | AN22: 0 | AO22: 0 | AP22: 0 | AQ22: 0 | AR22: 0 | AS22: 0 | AT22: 0 | AU22: 0 | AV22: =SUM(E22:AU22) -> 1
D23: PR | E23: 0 | F23: 0 | G23: 0 | H23: 0 | I23: 0 | J23: 0 | K23: 0 | L23: 0 | M23: 0 | N23: 0 | O23: 0 | P23: 0 | Q23: 0 | R23: 0 | S23: 0 | T23: 0 | U23: 0 | V23: 0 | W23: 0 | X23: 0 | Y23: 0 | Z23: 0 | AA23: 0 | AB23: 0 | AC23: 0 | AD23: 4 | AE23: 0 | AF23: 0 | AG23: 0 | AH23: 0 | AI23: 0 | AJ23: 0 | AK23: 0 | AL23: 0 | AM23: 0 | AN23: 0 | AO23: 0 | AP23: 0 | AQ23: 0 | AR23: 0 | AS23: 0 | AT23: 0 | AU23: 0 | AV23: =SUM(E23:AU23) -> 4
D24: JML | E24: =SUM(E22:E23) -> 0 | F24: =SUM(F22:F23) -> 0 | G24: =SUM(G22:G23) -> 0 | H24: =SUM(H22:H23) -> 0 | I24: =SUM(I22:I23) -> 0 | J24: =SUM(J22:J23) -> 0 | K24: =SUM(K22:K23) -> 0 | L24: =SUM(L22:L23) -> 0 | ... AU24: =SUM(AU22:AU23) -> 0 | AV24: =SUM(E24:AU24) -> 5
B25: 3. | C25: Jumlah pengguna hak pilih dalam Daftar Pemilih Khusus (DPK) | D25: LK | E25: 2 | F25: 3 | G25: 2 | H25: 3 | I25: 1 | J25: 5 | K25: 0 | L25: 1 | M25: 2 | N25: 3 | O25: 0 | P25: 0 | Q25: 0 | R25: 1 | S25: 0 | T25: 1 | U25: 1 | V25: 0 | W25: 3 | X25: 4 | Y25: 0 | Z25: 1 | AA25: 0 | AB25: 3 | AC25: 0 | AD25: 0 | AE25: 1 | AF25: 2 | AG25: 2 | AH25: 0 | AI25: 2 | AJ25: 1 | AK25: 0 | AL25: 7 | AM25: 0 | AN25: 6 | AO25: 1 | AP25: 2 | AQ25: 2 | AR25: 3 | AS25: 2 | AT25: 0 | AU25: 0 | AV25: =SUM(E25:AU25) -> 67
D26: PR | E26: 4 | F26: 4 | G26: 1 | H26: 5 | I26: 1 | J26: 9 | K26: 0 | L26: 1 | M26: 1 | N26: 1 | O26: 1 | P26: 0 | Q26: 1 | R26: 1 | S26: 0 | T26: 4 | U26: 1 | V26: 0 | W26: 4 | X26: 4 | Y26: 0 | Z26: 2 | AA26: 0 | AB26: 2 | AC26: 0 | AD26: 1 | AE26: 1 | AF26: 1 | AG26: 2 | AH26: 2 | AI26: 2 | AJ26: 2 | AK26: 0 | AL26: 12 | AM26: 0 | AN26: 7 | AO26: 2 | AP26: 1 | AQ26: 2 | AR26: 1 | AS26: 0 | AT26: 1 | AU26: 0 | AV26: =SUM(E26:AU26) -> 84
D27: JML | E27: =SUM(E25:E26) -> 6 | F27: =SUM(F25:F26) -> 7 | G27: =SUM(G25:G26) -> 3 | H27: =SUM(H25:H26) -> 8 | I27: =SUM(I25:I26) -> 2 | J27: =SUM(J25:J26) -> 14 | K27: =SUM(K25:K26) -> 0 | L27: =SUM(L25:L26) -> 2 | ... AU27: =SUM(AU25:AU26) -> 0 | AV27: =SUM(E27:AU27) -> 151
B28: 4. | C28: Jumlah Pengguna Hak Pilih (B.1+B.2+B.3) | D28: LK | E28: =SUM(E19,E22,E25) -> 92 | F28: =SUM(F19,F22,F25) -> 100 | G28: =SUM(G19,G22,G25) -> 97 | H28: =SUM(H19,H22,H25) -> 95 | I28: =SUM(I19,I22,I25) -> 90 | J28: =SUM(J19,J22,J25) -> 97 | K28: =SUM(K19,K22,K25) -> 88 | L28: =SUM(L19,L22,L25) -> 96 | ... AU28: =SUM(AU19,AU22,AU25) -> 114 | AV28: =SUM(E28:AU28) -> 4280
D29: PR | E29: =SUM(E20,E23,E26) -> 108 | F29: =SUM(F20,F23,F26) -> 103 | G29: =SUM(G20,G23,G26) -> 111 | H29: =SUM(H20,H23,H26) -> 99 | I29: =SUM(I20,I23,I26) -> 99 | J29: =SUM(J20,J23,J26) -> 107 | K29: =SUM(K20,K23,K26) -> 106 | L29: =SUM(L20,L23,L26) -> 111 | ... AU29: =SUM(AU20,AU23,AU26) -> 104 | AV29: =SUM(E29:AU29) -> 4363
D30: JML | E30: =SUM(E28:E29) -> 200 | F30: =SUM(F28:F29) -> 203 | G30: =SUM(G28:G29) -> 208 | H30: =SUM(H28:H29) -> 194 | I30: =SUM(I28:I29) -> 189 | J30: =SUM(J28:J29) -> 204 | K30: =SUM(K28:K29) -> 194 | L30: =SUM(L28:L29) -> 207 | ... AU30: =SUM(AU28:AU29) -> 218 | AV30: =SUM(E30:AU30) -> 8643
A32: II | B32: DATA PENGGUNAAN SURAT SUARA
A33: 1 | B33: Jumlah surat suara yang diterima, termasuk surat suara cadangan 2,5% dari DPT | E33: 272 | F33: 271 | G33: 272 | H33: 258 | I33: 275 | J33: 270 | K33: 264 | L33: 275 | M33: 275 | N33: 271 | O33: 273 | P33: 269 | Q33: 263 | R33: 269 | S33: 275 | T33: 264 | U33: 271 | V33: 264 | W33: 272 | X33: 259 | Y33: 267 | Z33: 276 | AA33: 283 | AB33: 275 | AC33: 287 | AD33: 264 | AE33: 279 | AF33: 284 | AG33: 276 | AH33: 276 | AI33: 254 | AJ33: 267 | AK33: 273 | AL33: 256 | AM33: 278 | AN33: 263 | AO33: 275 | AP33: 272 | AQ33: 262 | AR33: 271 | AS33: 266 | AT33: 277 | AU33: 281 | AV33: =SUM(E33:AU33) -> 11644
A34: 2 | B34: Jumlah surat suara yang digunakan | E34: 200 | F34: 203 | G34: 208 | H34: 194 | I34: 189 | J34: 204 | K34: 194 | L34: 207 | M34: 197 | N34: 196 | O34: 202 | P34: 194 | Q34: 185 | R34: 176 | S34: 197 | T34: 187 | U34: 198 | V34: 218 | W34: 214 | X34: 201 | Y34: 221 | Z34: 224 | AA34: 206 | AB34: 218 | AC34: 220 | AD34: 192 | AE34: 207 | AF34: 215 | AG34: 201 | AH34: 212 | AI34: 169 | AJ34: 204 | AK34: 189 | AL34: 194 | AM34: 192 | AN34: 174 | AO34: 204 | AP34: 213 | AQ34: 191 | AR34: 202 | AS34: 205 | AT34: 208 | AU34: 218 | AV34: =SUM(E34:AU34) -> 8643
A35: 3 | B35: Jumlah surat suara dikembalikan oleh pemilih (karena rusak atau keliru coblos) | E35: 0 | F35: 0 | G35: 0 | H35: 2 | I35: 0 | J35: 0 | K35: 0 | L35: 0 | M35: 0 | N35: 0 | O35: 0 | P35: 0 | Q35: 0 | R35: 1 | S35: 0 | T35: 0 | U35: 0 | V35: 0 | W35: 0 | X35: 0 | Y35: 0 | Z35: 0 | AA35: 0 | AB35: 0 | AC35: 1 | AD35: 0 | AE35: 0 | AF35: 0 | AG35: 0 | AH35: 0 | AI35: 0 | AJ35: 0 | AK35: 0 | AL35: 0 | AM35: 1 | AN35: 1 | AO35: 0 | AP35: 0 | AQ35: 0 | AR35: 0 | AS35: 0 | AT35: 0 | AU35: 0 | AV35: =SUM(E35:AU35) -> 6
A36: 4 | B36: Jumlah surat suara yang tidak digunakan/tidak terpakai, termasuk sisa surat suara cadangan | E36: =E33-(E34+E35) -> 72 | F36: =F33-(F34+F35) -> 68 | G36: =G33-(G34+G35) -> 64 | H36: =H33-(H34+H35) -> 62 | I36: =I33-(I34+I35) -> 86 | J36: =J33-(J34+J35) -> 66 | K36: =K33-(K34+K35) -> 70 | L36: =L33-(L34+L35) -> 68 | ... AU36: =AU33-(AU34+AU35) -> 63 | AV36: =SUM(E36:AU36) -> 2995
A38: III | B38: DATA PEMILIH DISABILITAS
B39: Jumlah seluruh Pemilih disabilitas yang menggunakan hak pilih | D39: LK | E39: 0 | F39: 0 | G39: 0 | H39: 0 | I39: 0 | J39: 0 | K39: 0 | L39: 0 | M39: 0 | N39: 0 | O39: 0 | P39: 0 | Q39: 0 | R39: 0 | S39: 0 | T39: 0 | U39: 0 | V39: 0 | W39: 0 | X39: 0 | Y39: 0 | Z39: 0 | AA39: 0 | AB39: 0 | AC39: 0 | AD39: 0 | AE39: 0 | AF39: 0 | AG39: 0 | AH39: 0 | AI39: 0 | AJ39: 0 | AK39: 0 | AL39: 0 | AM39: 0 | AN39: 0 | AO39: 0 | AP39: 0 | AQ39: 0 | AR39: 1 | AS39: 0 | AT39: 0 | AU39: 0 | AV39: =SUM(E39:AU39) -> 1
D40: PR | E40: 0 | F40: 0 | G40: 0 | H40: 0 | I40: 0 | J40: 0 | K40: 0 | L40: 0 | M40: 0 | N40: 0 | O40: 0 | P40: 0 | Q40: 0 | R40: 0 | S40: 0 | T40: 0 | U40: 0 | V40: 0 | W40: 0 | X40: 0 | Y40: 0 | Z40: 0 | AA40: 0 | AB40: 0 | AC40: 0 | AD40: 0 | AE40: 0 | AF40: 0 | AG40: 0 | AH40: 0 | AI40: 0 | AJ40: 0 | AK40: 0 | AL40: 0 | AM40: 0 | AN40: 0 | AO40: 0 | AP40: 0 | AQ40: 0 | AR40: 0 | AS40: 0 | AT40: 0 | AU40: 0 | AV40: =SUM(E40:AU40) -> 0
D41: JML | E41: =SUM(E39:E40) -> 0 | F41: =SUM(F39:F40) -> 0 | G41: =SUM(G39:G40) -> 0 | H41: =SUM(H39:H40) -> 0 | I41: =SUM(I39:I40) -> 0 | J41: =SUM(J39:J40) -> 0 | K41: =SUM(K39:K40) -> 0 | L41: =SUM(L39:L40) -> 0 | ... AU41: =SUM(AU39:AU40) -> 0 | AV41: =SUM(E41:AU41) -> 1
A43: IV | B43: DATA RINCIAN PEROLEHAN SUARA PASANGAN CALON BUPATI DAN WAKIL BUPATI
A44: NOMOR DAN NAMA CALON
B45: 1 | C45: H. ANIES RASYID BASWEDAN, Ph.D. - Dr. (H.C.) H. A. MUHAIMIN ISKANDAR | E45: 12 | F45: 13 | G45: 14 | H45: 23 | I45: 17 | J45: 14 | K45: 9 | L45: 10 | M45: 22 | N45: 8 | O45: 12 | P45: 9 | Q45: 7 | R45: 12 | S45: 6 | T45: 9 | U45: 6 | V45: 8 | W45: 4 | X45: 5 | Y45: 7 | Z45: 16 | AA45: 8 | AB45: 12 | AC45: 7 | AD45: 11 | AE45: 11 | AF45: 3 | AG45: 4 | AH45: 4 | AI45: 4 | AJ45: 8 | AK45: 13 | AL45: 4 | AM45: 5 | AN45: 2 | AO45: 9 | AP45: 4 | AQ45: 12 | AR45: 7 | AS45: 7 | AT45: 7 | AU45: 9 | AV45: =SUM(E45:AU45) -> 394
B46: 2 | C46: H. PRABOWO SUBIANTO - GIBRAN RAKABUMING RAKA | E46: 171 | F46: 157 | G46: 147 | H46: 134 | I46: 146 | J46: 155 | K46: 137 | L46: 159 | M46: 136 | N46: 142 | O46: 159 | P46: 155 | Q46: 140 | R46: 139 | S46: 149 | T46: 151 | U46: 171 | V46: 154 | W46: 162 | X46: 184 | Y46: 205 | Z46: 169 | AA46: 161 | AB46: 159 | AC46: 179 | AD46: 109 | AE46: 138 | AF46: 141 | AG46: 135 | AH46: 155 | AI46: 125 | AJ46: 172 | AK46: 131 | AL46: 139 | AM46: 143 | AN46: 128 | AO46: 156 | AP46: 178 | AQ46: 138 | AR46: 154 | AS46: 172 | AT46: 167 | AU46: 192 | AV46: =SUM(E46:AU46) -> 6594
B47: 3 | C47: H. GANJAR PRANOWO, S.H., M.I.P. - Prof. Dr. H. M. MAHFUD MD | E47: 17 | F47: 32 | G47: 43 | H47: 37 | I47: 25 | J47: 34 | K47: 46 | L47: 38 | M47: 38 | N47: 43 | O47: 29 | P47: 30 | Q47: 34 | R47: 24 | S47: 41 | T47: 27 | U47: 20 | V47: 54 | W47: 47 | X47: 12 | Y47: 9 | Z47: 38 | AA47: 33 | AB47: 46 | AC47: 34 | AD47: 71 | AE47: 57 | AF47: 68 | AG47: 61 | AH47: 51 | AI47: 38 | AJ47: 22 | AK47: 45 | AL47: 48 | AM47: 38 | AN47: 35 | AO47: 38 | AP47: 28 | AQ47: 39 | AR47: 39 | AS47: 25 | AT47: 28 | AU47: 14 | AV47: =SUM(E47:AU47) -> 1576
A49: V | B49: DATA SUARA SAH DAN TIDAK SAH
B50: A. | C50: JUMLAH SELURUH SUARA SAH | E50: =SUM(E45:E47) -> 200 | F50: =SUM(F45:F47) -> 202 | G50: =SUM(G45:G47) -> 204 | H50: =SUM(H45:H47) -> 194 | I50: =SUM(I45:I47) -> 188 | J50: =SUM(J45:J47) -> 203 | K50: =SUM(K45:K47) -> 192 | L50: =SUM(L45:L47) -> 207 | ... AU50: =SUM(AU45:AU47) -> 215 | AV50: =SUM(E50:AU50) -> 8564
B51: B. | C51: JUMLAH SUARA TIDAK SAH | E51: 0 | F51: 1 | G51: 4 | H51: 0 | I51: 1 | J51: 1 | K51: 2 | L51: 0 | M51: 1 | N51: 3 | O51: 2 | P51: 0 | Q51: 4 | R51: 1 | S51: 1 | T51: 0 | U51: 1 | V51: 2 | W51: 1 | X51: 0 | Y51: 0 | Z51: 1 | AA51: 4 | AB51: 1 | AC51: 0 | AD51: 1 | AE51: 1 | AF51: 3 | AG51: 1 | AH51: 2 | AI51: 2 | AJ51: 2 | AK51: 0 | AL51: 3 | AM51: 6 | AN51: 9 | AO51: 1 | AP51: 3 | AQ51: 2 | AR51: 2 | AS51: 1 | AT51: 6 | AU51: 3 | AV51: =SUM(E51:AU51) -> 79
B52: C. | C52: JUMLAH SELURUH SUARA SAH DAN SUARA TIDAK SAH (V.A + V.B) | E52: =SUM(E50:E51) -> 200 | F52: =SUM(F50:F51) -> 203 | G52: =SUM(G50:G51) -> 208 | H52: =SUM(H50:H51) -> 194 | I52: =SUM(I50:I51) -> 189 | J52: =SUM(J50:J51) -> 204 | K52: =SUM(K50:K51) -> 194 | L52: =SUM(L50:L51) -> 207 | ... AU52: =SUM(AU50:AU51) -> 218 | AV52: =SUM(E52:AU52) -> 8643

Sheet SUMBERASRI
C2: Kecamatan | D2: PURWOHARJO
C3: Kabupaten | D3: BANYUWANGI
C4: Provinsi | D4: JAWA TIMUR
C9: Kelurahan | D9: SUMBERSARI
A12: I | B12: DATA PEMILIH DAN PENGGUNAAN HAK PILIH | X12: JUMLAH AKHIR
A13: A | B13: DATA PEMILIH | E13: TPS 001 | F13: TPS 002 | G13: TPS 003 | H13: TPS 004 | I13: TPS 005 | J13: TPS 006 | K13: TPS 007 | L13: TPS 008 | M13: TPS 009 | N13: TPS 010 | O13: TPS 011 | P13: TPS 012 | Q13: TPS 013 | R13: TPS 014 | S13: TPS 015 | T13: TPS 016 | U13: TPS 017 | V13: TPS 018 | W13: TPS 019
B14: Jumlah Pemilih dalam Daftar Pemilih Tetap (DPT) | D14: LK | E14: 143 | F14: 127 | G14: 140 | H14: 144 | I14: 152 | J14: 149 | K14: 125 | L14: 146 | M14: 146 | N14: 148 | O14: 147 | P14: 143 | Q14: 143 | R14: 118 | S14: 111 | T14: 153 | U14: 151 | V14: 150 | W14: 143 | X14: =SUM(E14:W14) -> 2679
D15: PR | E15: 140 | F15: 131 | G15: 134 | H15: 142 | I15: 137 | J15: 143 | K15: 119 | L15: 132 | M15: 137 | N15: 145 | O15: 135 | P15: 140 | Q15: 143 | R15: 125 | S15: 115 | T15: 140 | U15: 141 | V15: 145 | W15: 148 | X15: =SUM(E15:W15) -> 2592
D16: JML | E16: =SUM(E14:E15) -> 283 | F16: =SUM(F14:F15) -> 258 | G16: =SUM(G14:G15) -> 274 | H16: =SUM(H14:H15) -> 286 | I16: =SUM(I14:I15) -> 289 | J16: =SUM(J14:J15) -> 292 | K16: =SUM(K14:K15) -> 244 | L16: =SUM(L14:L15) -> 278 | ... W16: =SUM(W14:W15) -> 291 | X16: =SUM(E16:W16) -> 5271
A18: B | B18: PENGGUNA HAK PILIH
B19: 1. | C19: Jumlah pengguna hak pilih dalam Daftar Pemilih Tetap (DPT) | D19: LK | E19: 109 | F19: 97 | G19: 106 | H19: 113 | I19: 115 | J19: 111 | K19: 91 | L19: 113 | M19: 124 | N19: 112 | O19: 113 | P19: 112 | Q19: 114 | R19: 78 | S19: 88 | T19: 120 | U19: 113 | V19: 124 | W19: 133 | X19: =SUM(E19:W19) -> 2086
D20: PR | E20: 118 | F20: 109 | G20: 102 | H20: 113 | I20: 112 | J20: 113 | K20: 96 | L20: 102 | M20: 119 | N20: 117 | O20: 117 | P20: 120 | Q20: 118 | R20: 90 | S20: 93 | T20: 112 | U20: 111 | V20: 116 | W20: 140 | X20: =SUM(E20:W20) -> 2118
D21: JML | E21: =SUM(E19:E20) -> 227 | F21: =SUM(F19:F20) -> 206 | G21: =SUM(G19:G20) -> 208 | H21: =SUM(H19:H20) -> 226 | I21: =SUM(I19:I20) -> 227 | J21: =SUM(J19:J20) -> 224 | K21: =SUM(K19:K20) -> 187 | L21: =SUM(L19:L20) -> 215 | ... W21: =SUM(W19:W20) -> 273 | X21: =SUM(E21:W21) -> 4204
B22: 2. | C22: Jumlah pengguna hak pilih dalam Daftar Pemilih Tambahan (DPTb) | D22: LK | E22: 0 | F22: 1 | G22: 1 | H22: 0 | I22: 0 | J22: 0 | K22: 0 | L22: 0 | M22: 0 | N22: 0 | O22: 0 | P22: 0 | Q22: 1 | R22: 0 | S22: 1 | T22: 0 | U22: 0 | V22: 3 | W22: 1 | X22: =SUM(E22:W22) -> 8
D23: PR | E23: 0 | F23: 0 | G23: 1 | H23: 0 | I23: 0 | J23: 0 | K23: 0 | L23: 0 | M23: 0 | N23: 0 | O23: 0 | P23: 0 | Q23: 2 | R23: 0 | S23: 0 | T23: 0 | U23: 1 | V23: 1 | W23: 1 | X23: =SUM(E23:W23) -> 6
D24: JML | E24: =SUM(E22:E23) -> 0 | F24: =SUM(F22:F23) -> 1 | G24: =SUM(G22:G23) -> 2 | H24: =SUM(H22:H23) -> 0 | I24: =SUM(I22:I23) -> 0 | J24: =SUM(J22:J23) -> 0 | K24: =SUM(K22:K23) -> 0 | L24: =SUM(L22:L23) -> 0 | ... W24: =SUM(W22:W23) -> 2 | X24: =SUM(E24:W24) -> 14
B25: 3. | C25: Jumlah pengguna hak pilih dalam Daftar Pemilih Khusus (DPK) | D25: LK | E25: 0 | F25: 0 | G25: 1 | H25: 1 | I25: 1 | J25: 0 | K25: 0 | L25: 0 | M25: 0 | N25: 0 | O25: 3 | P25: 1 | Q25: 0 | R25: 2 | S25: 1 | T25: 1 | U25: 1 | V25: 1 | W25: 1 | X25: =SUM(E25:W25) -> 14
D26: PR | E26: 2 | F26: 0 | G26: 0 | H26: 0 | I26: 1 | J26: 4 | K26: 0 | L26: 0 | M26: 1 | N26: 2 | O26: 2 | P26: 4 | Q26: 0 | R26: 0 | S26: 1 | T26: 2 | U26: 0 | V26: 1 | W26: 0 | X26: =SUM(E26:W26) -> 20
D27: JML | E27: =SUM(E25:E26) -> 2 | F27: =SUM(F25:F26) -> 0 | G27: =SUM(G25:G26) -> 1 | H27: =SUM(H25:H26) -> 1 | I27: =SUM(I25:I26) -> 2 | J27: =SUM(J25:J26) -> 4 | K27: =SUM(K25:K26) -> 0 | L27: =SUM(L25:L26) -> 0 | ... W27: =SUM(W25:W26) -> 1 | X27: =SUM(E27:W27) -> 34
B28: 4. | C28: Jumlah Pengguna Hak Pilih (B.1+B.2+B.3) | D28: LK | E28: =SUM(E19,E22,E25) -> 109 | F28: =SUM(F19,F22,F25) -> 98 | G28: =SUM(G19,G22,G25) -> 108 | H28: =SUM(H19,H22,H25) -> 114 | I28: =SUM(I19,I22,I25) -> 116 | J28: =SUM(J19,J22,J25) -> 111 | K28: =SUM(K19,K22,K25) -> 91 | L28: =SUM(L19,L22,L25) -> 113 | ... W28: =SUM(W19,W22,W25) -> 135 | X28: =SUM(E28:W28) -> 2108
D29: PR | E29: =SUM(E20,E23,E26) -> 120 | F29: =SUM(F20,F23,F26) -> 109 | G29: =SUM(G20,G23,G26) -> 103 | H29: =SUM(H20,H23,H26) -> 113 | I29: =SUM(I20,I23,I26) -> 113 | J29: =SUM(J20,J23,J26) -> 117 | K29: =SUM(K20,K23,K26) -> 96 | L29: =SUM(L20,L23,L26) -> 102 | ... W29: =SUM(W20,W23,W26) -> 141 | X29: =SUM(E29:W29) -> 2144
D30: JML | E30: =SUM(E28:E29) -> 229 | F30: =SUM(F28:F29) -> 207 | G30: =SUM(G28:G29) -> 211 | H30: =SUM(H28:H29) -> 227 | I30: =SUM(I28:I29) -> 229 | J30: =SUM(J28:J29) -> 228 | K30: =SUM(K28:K29) -> 187 | L30: =SUM(L28:L29) -> 215 | ... W30: =SUM(W28:W29) -> 276 | X30: =SUM(E30:W30) -> 4252
A32: II | B32: DATA PENGGUNAAN SURAT SUARA
A33: 1 | B33: Jumlah surat suara yang diterima, termasuk surat suara cadangan 2,5% dari DPT | E33: 293 | F33: 263 | G33: 283 | H33: 292 | I33: 298 | J33: 298 | K33: 247 | L33: 284 | M33: 289 | N33: 299 | O33: 288 | P33: 289 | Q33: 292 | R33: 248 | S33: 231 | T33: 299 | U33: 298 | V33: 301 | W33: 300 | X33: =SUM(E33:W33) -> 5392
A34: 2 | B34: Jumlah surat suara yang digunakan | E34: 229 | F34: 207 | G34: 211 | H34: 227 | I34: 229 | J34: 228 | K34: 187 | L34: 215 | M34: 244 | N34: 231 | O34: 235 | P34: 237 | Q34: 235 | R34: 170 | S34: 184 | T34: 235 | U34: 226 | V34: 246 | W34: 276 | X34: =SUM(E34:W34) -> 4252
A35: 3 | B35: Jumlah surat suara dikembalikan oleh pemilih (karena rusak atau keliru coblos) | E35: 2 | F35: 3 | G35: 0 | H35: 0 | I35: 2 | J35: 0 | K35: 0 | L35: 0 | M35: 0 | N35: 0 | O35: 0 | P35: 0 | Q35: 0 | R35: 0 | S35: 0 | T35: 0 | U35: 0 | V35: 0 | W35: 1 | X35: =SUM(E35:W35) -> 8
A36: 4 | B36: Jumlah surat suara yang tidak digunakan/tidak terpakai, termasuk sisa surat suara cadangan | E36: =E33-(E34+E35) -> 62 | F36: =F33-(F34+F35) -> 53 | G36: =G33-(G34+G35) -> 72 | H36: =H33-(H34+H35) -> 65 | I36: =I33-(I34+I35) -> 67 | J36: =J33-(J34+J35) -> 70 | K36: =K33-(K34+K35) -> 60 | L36: =L33-(L34+L35) -> 69 | ... W36: =W33-(W34+W35) -> 23 | X36: =SUM(E36:W36) -> 1132
A38: III | B38: DATA PEMILIH DISABILITAS
B39: Jumlah seluruh Pemilih disabilitas yang menggunakan hak pilih | D39: LK | E39: 0 | F39: 0 | G39: 1 | H39: 0 | I39: 0 | J39: 0 | K39: 0 | L39: 0 | M39: 0 | N39: 0 | O39: 0 | P39: 0 | Q39: 0 | R39: 0 | S39: 0 | T39: 0 | U39: 0 | V39: 0 | W39: 0 | X39: =SUM(E39:W39) -> 1
D40: PR | E40: 0 | F40: 0 | G40: 2 | H40: 0 | I40: 0 | J40: 0 | K40: 0 | L40: 0 | M40: 0 | N40: 0 | O40: 0 | P40: 1 | Q40: 1 | R40: 0 | S40: 0 | T40: 0 | U40: 0 | V40: 0 | W40: 0 | X40: =SUM(E40:W40) -> 4
D41: JML | E41: =SUM(E39:E40) -> 0 | F41: =SUM(F39:F40) -> 0 | G41: =SUM(G39:G40) -> 3 | H41: =SUM(H39:H40) -> 0 | I41: =SUM(I39:I40) -> 0 | J41: =SUM(J39:J40) -> 0 | K41: =SUM(K39:K40) -> 0 | L41: =SUM(L39:L40) -> 0 | ... W41: =SUM(W39:W40) -> 0 | X41: =SUM(E41:W41) -> 5
A43: IV | B43: DATA RINCIAN PEROLEHAN SUARA PASANGAN CALON BUPATI DAN WAKIL BUPATI
A44: NOMOR DAN NAMA CALON
B45: 1 | C45: H. ANIES RASYID BASWEDAN, Ph.D. - Dr. (H.C.) H. A. MUHAIMIN ISKANDAR | E45: 92 | F45: 43 | G45: 59 | H45: 83 | I45: 45 | J45: 39 | K45: 51 | L45: 40 | M45: 47 | N45: 10 | O45: 25 | P45: 28 | Q45: 58 | R45: 32 | S45: 6 | T45: 8 | U45: 11 | V45: 32 | W45: 17 | X45: =SUM(E45:W45) -> 726
B46: 2 | C46: H. PRABOWO SUBIANTO - GIBRAN RAKABUMING RAKA | E46: 111 | F46: 145 | G46: 133 | H46: 132 | I46: 165 | J46: 155 | K46: 117 | L46: 144 | M46: 158 | N46: 198 | O46: 186 | P46: 181 | Q46: 154 | R46: 120 | S46: 151 | T46: 196 | U46: 192 | V46: 199 | W46: 231 | X46: =SUM(E46:W46) -> 3068
B47: 3 | C47: H. GANJAR PRANOWO, S.H., M.I.P. - Prof. Dr. H. M. MAHFUD MD | E47: 23 | F47: 17 | G47: 18 | H47: 8 | I47: 17 | J47: 30 | K47: 15 | L47: 30 | M47: 33 | N47: 22 | O47: 23 | P47: 25 | Q47: 17 | R47: 18 | S47: 25 | T47: 28 | U47: 21 | V47: 13 | W47: 28 | X47: =SUM(E47:W47) -> 411
A49: V | B49: DATA SUARA SAH DAN TIDAK SAH
B50: A. | C50: JUMLAH SELURUH SUARA SAH | E50: =SUM(E45:E47) -> 226 | F50: =SUM(F45:F47) -> 205 | G50: =SUM(G45:G47) -> 210 | H50: =SUM(H45:H47) -> 223 | I50: =SUM(I45:I47) -> 227 | J50: =SUM(J45:J47) -> 224 | K50: =SUM(K45:K47) -> 183 | L50: =SUM(L45:L47) -> 214 | ... W50: =SUM(W45:W47) -> 276 | X50: =SUM(E50:W50) -> 4205
B51: B. | C51: JUMLAH SUARA TIDAK SAH | E51: 3 | F51: 2 | G51: 1 | H51: 4 | I51: 2 | J51: 4 | K51: 4 | L51: 1 | M51: 6 | N51: 1 | O51: 1 | P51: 3 | Q51: 6 | R51: 0 | S51: 2 | T51: 3 | U51: 2 | V51: 2 | W51: 0 | X51: =SUM(E51:W51) -> 47
B52: C. | C52: JUMLAH SELURUH SUARA SAH DAN SUARA TIDAK SAH (V.A + V.B) | E52: =SUM(E50:E51) -> 229 | F52: =SUM(F50:F51) -> 207 | G52: =SUM(G50:G51) -> 211 | H52: =SUM(H50:H51) -> 227 | I52: =SUM(I50:I51) -> 229 | J52: =SUM(J50:J51) -> 228 | K52: =SUM(K50:K51) -> 187 | L52: =SUM(L50:L51) -> 215 | ... W52: =SUM(W50:W51) -> 276 | X52: =SUM(E52:W52) -> 4252

Sheet GLAGAHAGUNG
C2: Kecamatan | D2: PURWOHARJO
C3: Kabupaten | D3: BANYUWANGI
C4: Provinsi | D4: JAWA TIMUR
C9: Kelurahan | D9: GLAGAHAGUNG
A12: I | B12: DATA PEMILIH DAN PENGGUNAAN HAK PILIH | AA12: JUMLAH AKHIR
A13: A | B13: DATA PEMILIH | E13: TPS 001 | F13: TPS 002 | G13: TPS 003 | H13: TPS 004 | I13: TPS 005 | J13: TPS 006 | K13: TPS 007 | L13: TPS 008 | M13: TPS 009 | N13: TPS 010 | O13: TPS 011 | P13: TPS 012 | Q13: TPS 013 | R13: TPS 014 | S13: TPS 015 | T13: TPS 016 | U13: TPS 017 | V13: TPS 018 | W13: TPS 019 | X13: TPS 020 | Y13: TPS 021 | Z13: TPS 022
B14: Jumlah Pemilih dalam Daftar Pemilih Tetap (DPT) | D14: LK | E14: 142 | F14: 147 | G14: 140 | H14: 141 | I14: 141 | J14: 142 | K14: 122 | L14: 153 | M14: 154 | N14: 113 | O14: 131 | P14: 136 | Q14: 146 | R14: 138 | S14: 147 | T14: 127 | U14: 136 | V14: 142 | W14: 132 | X14: 133 | Y14: 134 | Z14: 148 | AA14: =SUM(E14:Z14) -> 3045
D15: PR | E15: 153 | F15: 130 | G15: 144 | H15: 149 | I15: 141 | J15: 129 | K15: 122 | L15: 125 | M15: 139 | N15: 115 | O15: 144 | P15: 150 | Q15: 135 | R15: 135 | S15: 148 | T15: 117 | U15: 142 | V15: 138 | W15: 141 | X15: 130 | Y15: 148 | Z15: 147 | AA15: =SUM(E15:Z15) -> 3022
D16: JML | E16: =SUM(E14:E15) -> 295 | F16: =SUM(F14:F15) -> 277 | G16: =SUM(G14:G15) -> 284 | H16: =SUM(H14:H15) -> 290 | I16: =SUM(I14:I15) -> 282 | J16: =SUM(J14:J15) -> 271 | K16: =SUM(K14:K15) -> 244 | L16: =SUM(L14:L15) -> 278 | ... Z16: =SUM(Z14:Z15) -> 295 | AA16: =SUM(E16:Z16) -> 6067
A18: B | B18: PENGGUNA HAK PILIH
B19: 1. | C19: Jumlah pengguna hak pilih dalam Daftar Pemilih Tetap (DPT) | D19: LK | E19: 102 | F19: 119 | G19: 113 | H19: 114 | I19: 112 | J19: 109 | K19: 100 | L19: 100 | M19: 118 | N19: 93 | O19: 111 | P19: 104 | Q19: 111 | R19: 111 | S19: 110 | T19: 102 | U19: 107 | V19: 118 | W19: 99 | X19: 100 | Y19: 106 | Z19: 129 | AA19: =SUM(E19:Z19) -> 2388
D20: PR | E20: 116 | F20: 106 | G20: 117 | H20: 115 | I20: 125 | J20: 99 | K20: 101 | L20: 96 | M20: 109 | N20: 101 | O20: 132 | P20: 134 | Q20: 120 | R20: 104 | S20: 107 | T20: 107 | U20: 121 | V20: 125 | W20: 111 | X20: 103 | Y20: 129 | Z20: 129 | AA20: =SUM(E20:Z20) -> 2507
D21: JML | E21: =SUM(E19:E20) -> 218 | F21: =SUM(F19:F20) -> 225 | G21: =SUM(G19:G20) -> 230 | H21: =SUM(H19:H20) -> 229 | I21: =SUM(I19:I20) -> 237 | J21: =SUM(J19:J20) -> 208 | K21: =SUM(K19:K20) -> 201 | L21: =SUM(L19:L20) -> 196 | ... Z21: =SUM(Z19:Z20) -> 258 | AA21: =SUM(E21:Z21) -> 4895
B22: 2. | C22: Jumlah pengguna hak pilih dalam Daftar Pemilih Tambahan (DPTb) | D22: LK | E22: 0 | F22: 0 | G22: 0 | H22: 0 | I22: 0 | J22: 1 | K22: 0 | L22: 1 | M22: 1 | N22: 0 | O22: 0 | P22: 0 | Q22: 0 | R22: 0 | S22: 0 | T22: 1 | U22: 0 | V22: 0 | W22: 1 | X22: 0 | Y22: 0 | Z22: 0 | AA22: =SUM(E22:Z22) -> 5
D23: PR | E23: 0 | F23: 0 | G23: 0 | H23: 0 | I23: 0 | J23: 1 | K23: 0 | L23: 0 | M23: 0 | N23: 0 | O23: 0 | P23: 0 | Q23: 1 | R23: 0 | S23: 0 | T23: 0 | U23: 0 | V23: 0 | W23: 0 | X23: 0 | Y23: 0 | Z23: 0 | AA23: =SUM(E23:Z23) -> 2
D24: JML | E24: =SUM(E22:E23) -> 0 | F24: =SUM(F22:F23) -> 0 | G24: =SUM(G22:G23) -> 0 | H24: =SUM(H22:H23) -> 0 | I24: =SUM(I22:I23) -> 0 | J24: =SUM(J22:J23) -> 2 | K24: =SUM(K22:K23) -> 0 | L24: =SUM(L22:L23) -> 1 | ... Z24: =SUM(Z22:Z23) -> 0 | AA24: =SUM(E24:Z24) -> 7
B25: 3. | C25: Jumlah pengguna hak pilih dalam Daftar Pemilih Khusus (DPK) | D25: LK | E25: 0 | F25: 1 | G25: 0 | H25: 0 | I25: 1 | J25: 1 | K25: 1 | L25: 1 | M25: 2 | N25: 1 | O25: 0 | P25: 0 | Q25: 0 | R25: 3 | S25: 1 | T25: 1 | U25: 2 | V25: 0 | W25: 0 | X25: 2 | Y25: 1 | Z25: 0 | AA25: =SUM(E25:Z25) -> 18
D26: PR | E26: 1 | F26: 1 | G26: 3 | H26: 1 | I26: 2 | J26: 1 | K26: 1 | L26: 2 | M26: 2 | N26: 4 | O26: 0 | P26: 0 | Q26: 0 | R26: 1 | S26: 3 | T26: 1 | U26: 0 | V26: 0 | W26: 0 | X26: 1 | Y26: 1 | Z26: 0 | AA26: =SUM(E26:Z26) -> 25
D27: JML | E27: =SUM(E25:E26) -> 1 | F27: =SUM(F25:F26) -> 2 | G27: =SUM(G25:G26) -> 3 | H27: =SUM(H25:H26) -> 1 | I27: =SUM(I25:I26) -> 3 | J27: =SUM(J25:J26) -> 2 | K27: =SUM(K25:K26) -> 2 | L27: =SUM(L25:L26) -> 3 | ... Z27: =SUM(Z25:Z26) -> 0 | AA27: =SUM(E27:Z27) -> 43
B28: 4. | C28: Jumlah Pengguna Hak Pilih (B.1+B.2+B.3) | D28: LK | E28: =SUM(E19,E22,E25) -> 102 | F28: =SUM(F19,F22,F25) -> 120 | G28: =SUM(G19,G22,G25) -> 113 | H28: =SUM(H19,H22,H25) -> 114 | I28: =SUM(I19,I22,I25) -> 113 | J28: =SUM(J19,J22,J25) -> 111 | K28: =SUM(K19,K22,K25) -> 101 | L28: =SUM(L19,L22,L25) -> 102 | ... Z28: =SUM(Z19,Z22,Z25) -> 129 | AA28: =SUM(E28:Z28) -> 2411
D29: PR | E29: =SUM(E20,E23,E26) -> 117 | F29: =SUM(F20,F23,F26) -> 107 | G29: =SUM(G20,G23,G26) -> 120 | H29: =SUM(H20,H23,H26) -> 116 | I29: =SUM(I20,I23,I26) -> 127 | J29: =SUM(J20,J23,J26) -> 101 | K29: =SUM(K20,K23,K26) -> 102 | L29: =SUM(L20,L23,L26) -> 98 | ... Z29: =SUM(Z20,Z23,Z26) -> 129 | AA29: =SUM(E29:Z29) -> 2534
D30: JML | E30: =SUM(E28:E29) -> 219 | F30: =SUM(F28:F29) -> 227 | G30: =SUM(G28:G29) -> 233 | H30: =SUM(H28:H29) -> 230 | I30: =SUM(I28:I29) -> 240 | J30: =SUM(J28:J29) -> 212 | K30: =SUM(K28:K29) -> 203 | L30: =SUM(L28:L29) -> 200 | ... Z30: =SUM(Z28:Z29) -> 258 | AA30: =SUM(E30:Z30) -> 4945
A32: II | B32: DATA PENGGUNAAN SURAT SUARA
A33: 1 | B33: Jumlah surat suara yang diterima, termasuk surat suara cadangan 2,5% dari DPT | E33: 301 | F33: 284 | G33: 290 | H33: 299 | I33: 284 | J33: 277 | K33: 249 | L33: 278 | M33: 303 | N33: 231 | O33: 282 | P33: 298 | Q33: 288 | R33: 285 | S33: 302 | T33: 251 | U33: 284 | V33: 286 | W33: 278 | X33: 270 | Y33: 287 | Z33: 301 | AA33: =SUM(E33:Z33) -> 6208
A34: 2 | B34: Jumlah surat suara yang digunakan | E34: 219 | F34: 227 | G34: 233 | H34: 230 | I34: 240 | J34: 212 | K34: 203 | L34: 200 | M34: 232 | N34: 199 | O34: 243 | P34: 238 | Q34: 232 | R34: 219 | S34: 221 | T34: 212 | U34: 230 | V34: 243 | W34: 211 | X34: 206 | Y34: 237 | Z34: 258 | AA34: =SUM(E34:Z34) -> 4945
A35: 3 | B35: Jumlah surat suara dikembalikan oleh pemilih (karena rusak atau keliru coblos) | E35: 0 | F35: 0 | G35: 0 | H35: 0 | I35: 0 | J35: 1 | K35: 1 | L35: 0 | M35: 1 | N35: 0 | O35: 0 | P35: 0 | Q35: 2 | R35: 0 | S35: 0 | T35: 0 | U35: 2 | V35: 0 | W35: 0 | X35: 0 | Y35: 1 | Z35: 0 | AA35: =SUM(E35:Z35) -> 8
A36: 4 | B36: Jumlah surat suara yang tidak digunakan/tidak terpakai, termasuk sisa surat suara cadangan | E36: =E33-(E34+E35) -> 82 | F36: =F33-(F34+F35) -> 57 | G36: =G33-(G34+G35) -> 57 | H36: =H33-(H34+H35) -> 69 | I36: =I33-(I34+I35) -> 44 | J36: =J33-(J34+J35) -> 64 | K36: =K33-(K34+K35) -> 45 | L36: =L33-(L34+L35) -> 78 | ... Z36: =Z33-(Z34+Z35) -> 43 | AA36: =SUM(E36:Z36) -> 1255
A38: III | B38: DATA PEMILIH DISABILITAS
B39: Jumlah seluruh Pemilih disabilitas yang menggunakan hak pilih | D39: LK | E39: 1 | F39: 0 | G39: 0 | H39: 0 | I39: 0 | J39: 0 | K39: 0 | L39: 0 | M39: 0 | N39: 0 | O39: 0 | P39: 0 | Q39: 0 | R39: 0 | S39: 2 | T39: 0 | U39: 0 | V39: 0 | W39: 0 | X39: 0 | Y39: 0 | Z39: 0 | AA39: =SUM(E39:Z39) -> 3
D40: PR | E40: 0 | F40: 0 | G40: 0 | H40: 0 | I40: 0 | J40: 0 | K40: 0 | L40: 0 | M40: 0 | N40: 0 | O40: 0 | P40: 0 | Q40: 0 | R40: 0 | S40: 1 | T40: 0 | U40: 1 | V40: 0 | W40: 0 | X40: 0 | Y40: 0 | Z40: 0 | AA40: =SUM(E40:Z40) -> 2
D41: JML | E41: =SUM(E39:E40) -> 1 | F41: =SUM(F39:F40) -> 0 | G41: =SUM(G39:G40) -> 0 | H41: =SUM(H39:H40) -> 0 | I41: =SUM(I39:I40) -> 0 | J41: =SUM(J39:J40) -> 0 | K41: =SUM(K39:K40) -> 0 | L41: =SUM(L39:L40) -> 0 | ... Z41: =SUM(Z39:Z40) -> 0 | AA41: =SUM(E41:Z41) -> 5
A43: IV | B43: DATA RINCIAN PEROLEHAN SUARA PASANGAN CALON BUPATI DAN WAKIL BUPATI
A44: NOMOR DAN NAMA CALON
B45: 1 | C45: H. ANIES RASYID BASWEDAN, Ph.D. - Dr. (H.C.) H. A. MUHAIMIN ISKANDAR | E45: 6 | F45: 24 | G45: 32 | H45: 28 | I45: 28 | J45: 39 | K45: 38 | L45: 21 | M45: 21 | N45: 32 | O45: 112 | P45: 124 | Q45: 78 | R45: 44 | S45: 19 | T45: 47 | U45: 47 | V45: 88 | W45: 50 | X45: 60 | Y45: 38 | Z45: 48 | AA45: =SUM(E45:Z45) -> 1024
B46: 2 | C46: H. PRABOWO SUBIANTO - GIBRAN RAKABUMING RAKA | E46: 142 | F46: 156 | G46: 173 | H46: 154 | I46: 183 | J46: 153 | K46: 140 | L46: 144 | M46: 174 | N46: 144 | O46: 111 | P46: 105 | Q46: 138 | R46: 130 | S46: 151 | T46: 135 | U46: 148 | V46: 139 | W46: 142 | X46: 118 | Y46: 160 | Z46: 184 | AA46: =SUM(E46:Z46) -> 3224
B47: 3 | C47: H. GANJAR PRANOWO, S.H., M.I.P. - Prof. Dr. H. M. MAHFUD MD | E47: 68 | F47: 46 | G47: 23 | H47: 39 | I47: 24 | J47: 17 | K47: 22 | L47: 34 | M47: 32 | N47: 17 | O47: 17 | P47: 9 | Q47: 16 | R47: 43 | S47: 49 | T47: 30 | U47: 33 | V47: 14 | W47: 19 | X47: 26 | Y47: 36 | Z47: 21 | AA47: =SUM(E47:Z47) -> 635
A49: V | B49: DATA SUARA SAH DAN TIDAK SAH
B50: A. | C50: JUMLAH SELURUH SUARA SAH | E50: =SUM(E45:E47) -> 216 | F50: =SUM(F45:F47) -> 226 | G50: =SUM(G45:G47) -> 228 | H50: =SUM(H45:H47) -> 221 | I50: =SUM(I45:I47) -> 235 | J50: =SUM(J45:J47) -> 209 | K50: =SUM(K45:K47) -> 200 | L50: =SUM(L45:L47) -> 199 | ... Z50: =SUM(Z45:Z47) -> 253 | AA50: =SUM(E50:Z50) -> 4883
B51: B. | C51: JUMLAH SUARA TIDAK SAH | E51: 3 | F51: 1 | G51: 5 | H51: 9 | I51: 5 | J51: 3 | K51: 3 | L51: 1 | M51: 5 | N51: 6 | O51: 3 | P51: 0 | Q51: 0 | R51: 2 | S51: 2 | T51: 0 | U51: 2 | V51: 2 | W51: 0 | X51: 2 | Y51: 3 | Z51: 5 | AA51: =SUM(E51:Z51) -> 62
B52: C. | C52: JUMLAH SELURUH SUARA SAH DAN SUARA TIDAK SAH (V.A + V.B) | E52: =SUM(E50:E51) -> 219 | F52: =SUM(F50:F51) -> 227 | G52: =SUM(G50:G51) -> 233 | H52: =SUM(H50:H51) -> 230 | I52: =SUM(I50:I51) -> 240 | J52: =SUM(J50:J51) -> 212 | K52: =SUM(K50:K51) -> 203 | L52: =SUM(L50:L51) -> 200 | ... Z52: =SUM(Z50:Z51) -> 258 | AA52: =SUM(E52:Z52) -> 4945

Sheet SIDOREJO
C2: Kecamatan | D2: PURWOHARJO
C3: Kabupaten | D3: BANYUWANGI
C4: Provinsi | D4: JAWA TIMUR
C9: Kelurahan | D9: SIDOREJO
A12: I | B12: DATA PEMILIH DAN PENGGUNAAN HAK PILIH | AA12: JUMLAH AKHIR
A13: A | B13: DATA PEMILIH | E13: TPS 001 | F13: TPS 002 | G13: TPS 003 | H13: TPS 004 | I13: TPS 005 | J13: TPS 006 | K13: TPS 007 | L13: TPS 008 | M13: TPS 009 | N13: TPS 010 | O13: TPS 011 | P13: TPS 012 | Q13: TPS 013 | R13: TPS 014 | S13: TPS 015 | T13: TPS 016 | U13: TPS 017 | V13: TPS 018 | W13: TPS 019 | X13: TPS 020 | Y13: TPS 021 | Z13: TPS 022
B14: Jumlah Pemilih dalam Daftar Pemilih Tetap (DPT) | D14: LK | E14: 131 | F14: 134 | G14: 136 | H14: 143 | I14: 134 | J14: 129 | K14: 142 | L14: 141 | M14: 138 | N14: 150 | O14: 141 | P14: 147 | Q14: 156 | R14: 137 | S14: 123 | T14: 139 | U14: 132 | V14: 132 | W14: 133 | X14: 137 | Y14: 125 | Z14: 139 | AA14: =SUM(E14:Z14) -> 3019
D15: PR | E15: 144 | F15: 132 | G15: 137 | H15: 144 | I15: 136 | J15: 145 | K15: 134 | L15: 136 | M15: 148 | N15: 145 | O15: 140 | P15: 146 | Q15: 141 | R15: 124 | S15: 129 | T15: 125 | U15: 133 | V15: 137 | W15: 133 | X15: 137 | Y15: 133 | Z15: 133 | AA15: =SUM(E15:Z15) -> 3012
D16: JML | E16: =SUM(E14:E15) -> 275 | F16: =SUM(F14:F15) -> 266 | G16: =SUM(G14:G15) -> 273 | H16: =SUM(H14:H15) -> 287 | I16: =SUM(I14:I15) -> 270 | J16: =SUM(J14:J15) -> 274 | K16: =SUM(K14:K15) -> 276 | L16: =SUM(L14:L15) -> 277 | ... Z16: =SUM(Z14:Z15) -> 272 | AA16: =SUM(E16:Z16) -> 6031
A18: B | B18: PENGGUNA HAK PILIH
B19: 1. | C19: Jumlah pengguna hak pilih dalam Daftar Pemilih Tetap (DPT) | D19: LK | E19: 102 | F19: 99 | G19: 104 | H19: 112 | I19: 106 | J19: 100 | K19: 106 | L19: 113 | M19: 101 | N19: 111 | O19: 108 | P19: 122 | Q19: 121 | R19: 111 | S19: 102 | T19: 110 | U19: 103 | V19: 94 | W19: 110 | X19: 100 | Y19: 99 | Z19: 108 | AA19: =SUM(E19:Z19) -> 2342
D20: PR | E20: 123 | F20: 109 | G20: 107 | H20: 111 | I20: 113 | J20: 117 | K20: 113 | L20: 108 | M20: 125 | N20: 113 | O20: 113 | P20: 118 | Q20: 110 | R20: 105 | S20: 115 | T20: 104 | U20: 95 | V20: 105 | W20: 105 | X20: 107 | Y20: 102 | Z20: 109 | AA20: =SUM(E20:Z20) -> 2427
D21: JML | E21: =SUM(E19:E20) -> 225 | F21: =SUM(F19:F20) -> 208 | G21: =SUM(G19:G20) -> 211 | H21: =SUM(H19:H20) -> 223 | I21: =SUM(I19:I20) -> 219 | J21: =SUM(J19:J20) -> 217 | K21: =SUM(K19:K20) -> 219 | L21: =SUM(L19:L20) -> 221 | ... Z21: =SUM(Z19:Z20) -> 217 | AA21: =SUM(E21:Z21) -> 4769
B22: 2. | C22: Jumlah pengguna hak pilih dalam Daftar Pemilih Tambahan (DPTb) | D22: LK | E22: 1 | F22: 0 | G22: 0 | H22: 0 | I22: 0 | J22: 0 | K22: 0 | L22: 0 | M22: 0 | N22: 0 | O22: 0 | P22: 0 | Q22: 0 | R22: 0 | S22: 0 | T22: 0 | U22: 0 | V22: 0 | W22: 0 | X22: 0 | Y22: 0 | Z22: 0 | AA22: =SUM(E22:Z22) -> 1
D23: PR | E23: 0 | F23: 0 | G23: 0 | H23: 0 | I23: 0 | J23: 0 | K23: 0 | L23: 0 | M23: 0 | N23: 0 | O23: 0 | P23: 0 | Q23: 0 | R23: 0 | S23: 0 | T23: 0 | U23: 1 | V23: 0 | W23: 0 | X23: 0 | Y23: 0 | Z23: 0 | AA23: =SUM(E23:Z23) -> 1
D24: JML | E24: =SUM(E22:E23) -> 1 | F24: =SUM(F22:F23) -> 0 | G24: =SUM(G22:G23) -> 0 | H24: =SUM(H22:H23) -> 0 | I24: =SUM(I22:I23) -> 0 | J24: =SUM(J22:J23) -> 0 | K24: =SUM(K22:K23) -> 0 | L24: =SUM(L22:L23) -> 0 | ... Z24: =SUM(Z22:Z23) -> 0 | AA24: =SUM(E24:Z24) -> 2
B25: 3. | C25: Jumlah pengguna hak pilih dalam Daftar Pemilih Khusus (DPK) | D25: LK | E25: 2 | F25: 0 | G25: 3 | H25: 0 | I25: 1 | J25: 0 | K25: 1 | L25: 1 | M25: 0 | N25: 0 | O25: 0 | P25: 0 | Q25: 0 | R25: 0 | S25: 2 | T25: 0 | U25: 1 | V25: 1 | W25: 0 | X25: 2 | Y25: 1 | Z25: 1 | AA25: =SUM(E25:Z25) -> 16
D26: PR | E26: 2 | F26: 0 | G26: 1 | H26: 0 | I26: 3 | J26: 2 | K26: 2 | L26: 1 | M26: 0 | N26: 0 | O26: 6 | P26: 2 | Q26: 0 | R26: 1 | S26: 0 | T26: 0 | U26: 2 | V26: 0 | W26: 0 | X26: 2 | Y26: 1 | Z26: 2 | AA26: =SUM(E26:Z26) -> 27
D27: JML | E27: =SUM(E25:E26) -> 4 | F27: =SUM(F25:F26) -> 0 | G27: =SUM(G25:G26) -> 4 | H27: =SUM(H25:H26) -> 0 | I27: =SUM(I25:I26) -> 4 | J27: =SUM(J25:J26) -> 2 | K27: =SUM(K25:K26) -> 3 | L27: =SUM(L25:L26) -> 2 | ... Z27: =SUM(Z25:Z26) -> 3 | AA27: =SUM(E27:Z27) -> 43
B28: 4. | C28: Jumlah Pengguna Hak Pilih (B.1+B.2+B.3) | D28: LK | E28: =SUM(E19,E22,E25) -> 105 | F28: =SUM(F19,F22,F25) -> 99 | G28: =SUM(G19,G22,G25) -> 107 | H28: =SUM(H19,H22,H25) -> 112 | I28: =SUM(I19,I22,I25) -> 107 | J28: =SUM(J19,J22,J25) -> 100 | K28: =SUM(K19,K22,K25) -> 107 | L28: =SUM(L19,L22,L25) -> 114 | ... Z28: =SUM(Z19,Z22,Z25) -> 109 | AA28: =SUM(E28:Z28) -> 2359
D29: PR | E29: =SUM(E20,E23,E26) -> 125 | F29: =SUM(F20,F23,F26) -> 109 | G29: =SUM(G20,G23,G26) -> 108 | H29: =SUM(H20,H23,H26) -> 111 | I29: =SUM(I20,I23,I26) -> 116 | J29: =SUM(J20,J23,J26) -> 119 | K29: =SUM(K20,K23,K26) -> 115 | L29: =SUM(L20,L23,L26) -> 109 | ... Z29: =SUM(Z20,Z23,Z26) -> 111 | AA29: =SUM(E29:Z29) -> 2455
D30: JML | E30: =SUM(E28:E29) -> 230 | F30: =SUM(F28:F29) -> 208 | G30: =SUM(G28:G29) -> 215 | H30: =SUM(H28:H29) -> 223 | I30: =SUM(I28:I29) -> 223 | J30: =SUM(J28:J29) -> 219 | K30: =SUM(K28:K29) -> 222 | L30: =SUM(L28:L29) -> 223 | ... Z30: =SUM(Z28:Z29) -> 220 | AA30: =SUM(E30:Z30) -> 4814
A32: II | B32: DATA PENGGUNAAN SURAT SUARA
A33: 1 | B33: Jumlah surat suara yang diterima, termasuk surat suara cadangan 2,5% dari DPT | E33: 281 | F33: 272 | G33: 279 | H33: 295 | I33: 276 | J33: 281 | K33: 277 | L33: 286 | M33: 293 | N33: 301 | O33: 287 | P33: 301 | Q33: 303 | R33: 267 | S33: 258 | T33: 270 | U33: 271 | V33: 275 | W33: 272 | X33: 281 | Y33: 263 | Z33: 278 | AA33: =SUM(E33:Z33) -> 6167
A34: 2 | B34: Jumlah surat suara yang digunakan | E34: 230 | F34: 208 | G34: 215 | H34: 223 | I34: 223 | J34: 219 | K34: 222 | L34: 223 | M34: 226 | N34: 224 | O34: 227 | P34: 242 | Q34: 231 | R34: 217 | S34: 219 | T34: 214 | U34: 202 | V34: 200 | W34: 215 | X34: 211 | Y34: 203 | Z34: 220 | AA34: =SUM(E34:Z34) -> 4814
A35: 3 | B35: Jumlah surat suara dikembalikan oleh pemilih (karena rusak atau keliru coblos) | E35: 0 | F35: 0 | G35: 0 | H35: 2 | I35: 0 | J35: 0 | K35: 0 | L35: 2 | M35: 0 | N35: 0 | O35: 0 | P35: 0 | Q35: 2 | R35: 0 | S35: 0 | T35: 0 | U35: 0 | V35: 1 | W35: 1 | X35: 0 | Y35: 0 | Z35: 0 | AA35: =SUM(E35:Z35) -> 8
A36: 4 | B36: Jumlah surat suara yang tidak digunakan/tidak terpakai, termasuk sisa surat suara cadangan | E36: =E33-(E34+E35) -> 51 | F36: =F33-(F34+F35) -> 64 | G36: =G33-(G34+G35) -> 64 | H36: =H33-(H34+H35) -> 70 | I36: =I33-(I34+I35) -> 53 | J36: =J33-(J34+J35) -> 62 | K36: =K33-(K34+K35) -> 55 | L36: =L33-(L34+L35) -> 61 | ... Z36: =Z33-(Z34+Z35) -> 58 | AA36: =SUM(E36:Z36) -> 1345
A38: III | B38: DATA PEMILIH DISABILITAS
B39: Jumlah seluruh Pemilih disabilitas yang menggunakan hak pilih | D39: LK | E39: 0 | F39: 0 | G39: 0 | H39: 1 | I39: 0 | J39: 0 | K39: 0 | L39: 0 | M39: 0 | N39: 0 | O39: 0 | P39: 0 | Q39: 0 | R39: 0 | S39: 0 | T39: 0 | U39: 0 | V39: 0 | W39: 0 | X39: 0 | Y39: 0 | Z39: 0 | AA39: =SUM(E39:Z39) -> 1
D40: PR | E40: 0 | F40: 0 | G40: 0 | H40: 0 | I40: 0 | J40: 0 | K40: 0 | L40: 0 | M40: 0 | N40: 0 | O40: 0 | P40: 0 | Q40: 0 | R40: 0 | S40: 0 | T40: 0 | U40: 0 | V40: 0 | W40: 0 | X40: 0 | Y40: 0 | Z40: 0 | AA40: =SUM(E40:Z40) -> 0
D41: JML | E41: =SUM(E39:E40) -> 0 | F41: =SUM(F39:F40) -> 0 | G41: =SUM(G39:G40) -> 0 | H41: =SUM(H39:H40) -> 1 | I41: =SUM(I39:I40) -> 0 | J41: =SUM(J39:J40) -> 0 | K41: =SUM(K39:K40) -> 0 | L41: =SUM(L39:L40) -> 0 | ... Z41: =SUM(Z39:Z40) -> 0 | AA41: =SUM(E41:Z41) -> 1
A43: IV | B43: DATA RINCIAN PEROLEHAN SUARA PASANGAN CALON BUPATI DAN WAKIL BUPATI
A44: NOMOR DAN NAMA CALON
B45: 1 | C45: H. ANIES RASYID BASWEDAN, Ph.D. - Dr. (H.C.) H. A. MUHAIMIN ISKANDAR | E45: 53 | F45: 33 | G45: 11 | H45: 21 | I45: 25 | J45: 19 | K45: 15 | L45: 6 | M45: 23 | N45: 31 | O45: 8 | P45: 26 | Q45: 23 | R45: 23 | S45: 22 | T45: 23 | U45: 10 | V45: 9 | W45: 13 | X45: 5 | Y45: 9 | Z45: 13 | AA45: =SUM(E45:Z45) -> 421
B46: 2 | C46: H. PRABOWO SUBIANTO - GIBRAN RAKABUMING RAKA | E46: 129 | F46: 131 | G46: 146 | H46: 156 | I46: 145 | J46: 163 | K46: 162 | L46: 161 | M46: 141 | N46: 154 | O46: 170 | P46: 142 | Q46: 129 | R46: 158 | S46: 143 | T46: 150 | U46: 160 | V46: 151 | W46: 157 | X46: 147 | Y46: 83 | Z46: 173 | AA46: =SUM(E46:Z46) -> 3251
B47: 3 | C47: H. GANJAR PRANOWO, S.H., M.I.P. - Prof. Dr. H. M. MAHFUD MD | E47: 44 | F47: 44 | G47: 52 | H47: 43 | I47: 49 | J47: 35 | K47: 41 | L47: 54 | M47: 59 | N47: 37 | O47: 48 | P47: 73 | Q47: 77 | R47: 28 | S47: 53 | T47: 40 | U47: 30 | V47: 38 | W47: 41 | X47: 59 | Y47: 108 | Z47: 33 | AA47: =SUM(E47:Z47) -> 1086
A49: V | B49: DATA SUARA SAH DAN TIDAK SAH
B50: A. | C50: JUMLAH SELURUH SUARA SAH | E50: =SUM(E45:E47) -> 226 | F50: =SUM(F45:F47) -> 208 | G50: =SUM(G45:G47) -> 209 | H50: =SUM(H45:H47) -> 220 | I50: =SUM(I45:I47) -> 219 | J50: =SUM(J45:J47) -> 217 | K50: =SUM(K45:K47) -> 218 | L50: =SUM(L45:L47) -> 221 | ... Z50: =SUM(Z45:Z47) -> 219 | AA50: =SUM(E50:Z50) -> 4758
B51: B. | C51: JUMLAH SUARA TIDAK SAH | E51: 4 | F51: 0 | G51: 6 | H51: 3 | I51: 4 | J51: 2 | K51: 4 | L51: 2 | M51: 3 | N51: 2 | O51: 1 | P51: 1 | Q51: 2 | R51: 8 | S51: 1 | T51: 1 | U51: 2 | V51: 2 | W51: 4 | X51: 0 | Y51: 3 | Z51: 1 | AA51: =SUM(E51:Z51) -> 56
B52: C. | C52: JUMLAH SELURUH SUARA SAH DAN SUARA TIDAK SAH (V.A + V.B) | E52: =SUM(E50:E51) -> 230 | F52: =SUM(F50:F51) -> 208 | G52: =SUM(G50:G51) -> 215 | H52: =SUM(H50:H51) -> 223 | I52: =SUM(I50:I51) -> 223 | J52: =SUM(J50:J51) -> 219 | K52: =SUM(K50:K51) -> 222 | L52: =SUM(L50:L51) -> 223 | ... Z52: =SUM(Z50:Z51) -> 220 | AA52: =SUM(E52:Z52) -> 4814

Sheet PURWOHARJO
C2: Kecamatan | D2: PURWOHARJO
C3: Kabupaten | D3: BANYUWANGI
C4: Provinsi | D4: JAWA TIMUR
C9: Kelurahan | D9: PURWOHARJO
A12: I | B12: DATA PEMILIH DAN PENGGUNAAN HAK PILIH | AK12: JUMLAH AKHIR
A13: A | B13: DATA PEMILIH | E13: TPS 001 | F13: TPS 002 | G13: TPS 003 | H13: TPS 004 | I13: TPS 005 | J13: TPS 006 | K13: TPS 007 | L13: TPS 008 | M13: TPS 009 | N13: TPS 010 | O13: TPS 011 | P13: TPS 012 | Q13: TPS 013 | R13: TPS 014 | S13: TPS 015 | T13: TPS 016 | U13: TPS 017 | V13: TPS 018 | W13: TPS 019 | X13: TPS 020 | Y13: TPS 021 | Z13: TPS 022 | AA13: TPS 023 | AB13: TPS 024 | AC13: TPS 025 | AD13: TPS 026 | AE13: TPS 027 | AF13: TPS 028 | AG13: TPS 029 | AH13: TPS 030 | AI13: TPS 031 | AJ13: TPS 032
B14: Jumlah Pemilih dalam Daftar Pemilih Tetap (DPT) | D14: LK | E14: 128 | F14: 130 | G14: 145 | H14: 137 | I14: 140 | J14: 140 | K14: 126 | L14: 133 | M14: 131 | N14: 137 | O14: 140 | P14: 134 | Q14: 129 | R14: 129 | S14: 128 | T14: 130 | U14: 130 | V14: 134 | W14: 128 | X14: 134 | Y14: 133 | Z14: 127 | AA14: 137 | AB14: 130 | AC14: 142 | AD14: 133 | AE14: 138 | AF14: 135 | AG14: 125 | AH14: 140 | AI14: 135 | AJ14: 135 | AK14: =SUM(E14:AJ14) -> 4273
D15: PR | E15: 123 | F15: 135 | G15: 138 | H15: 133 | I15: 125 | J15: 139 | K15: 135 | L15: 135 | M15: 140 | N15: 136 | O15: 131 | P15: 138 | Q15: 135 | R15: 137 | S15: 140 | T15: 132 | U15: 138 | V15: 125 | W15: 140 | X15: 134 | Y15: 130 | Z15: 135 | AA15: 133 | AB15: 130 | AC15: 135 | AD15: 133 | AE15: 135 | AF15: 122 | AG15: 121 | AH15: 126 | AI15: 133 | AJ15: 133 | AK15: =SUM(E15:AJ15) -> 4255
D16: JML | E16: =SUM(E14:E15) -> 251 | F16: =SUM(F14:F15) -> 265 | G16: =SUM(G14:G15) -> 283 | H16: =SUM(H14:H15) -> 270 | I16: =SUM(I14:I15) -> 265 | J16: =SUM(J14:J15) -> 279 | K16: =SUM(K14:K15) -> 261 | L16: =SUM(L14:L15) -> 268 | ... AJ16: =SUM(AJ14:AJ15) -> 268 | AK16: =SUM(E16:AJ16) -> 8528
A18: B | B18: PENGGUNA HAK PILIH
B19: 1. | C19: Jumlah pengguna hak pilih dalam Daftar Pemilih Tetap (DPT) | D19: LK | E19: 96 | F19: 92 | G19: 111 | H19: 107 | I19: 106 | J19: 108 | K19: 97 | L19: 102 | M19: 97 | N19: 114 | O19: 101 | P19: 90 | Q19: 99 | R19: 84 | S19: 83 | T19: 102 | U19: 97 | V19: 98 | W19: 102 | X19: 99 | Y19: 100 | Z19: 105 | AA19: 103 | AB19: 101 | AC19: 114 | AD19: 107 | AE19: 106 | AF19: 106 | AG19: 98 | AH19: 108 | AI19: 87 | AJ19: 108 | AK19: =SUM(E19:AJ19) -> 3228
D20: PR | E20: 100 | F20: 103 | G20: 109 | H20: 110 | I20: 112 | J20: 110 | K20: 105 | L20: 112 | M20: 106 | N20: 112 | O20: 103 | P20: 107 | Q20: 113 | R20: 106 | S20: 94 | T20: 109 | U20: 101 | V20: 100 | W20: 115 | X20: 90 | Y20: 101 | Z20: 108 | AA20: 106 | AB20: 105 | AC20: 112 | AD20: 104 | AE20: 100 | AF20: 101 | AG20: 85 | AH20: 95 | AI20: 105 | AJ20: 104 | AK20: =SUM(E20:AJ20) -> 3343
D21: JML | E21: =SUM(E19:E20) -> 196 | F21: =SUM(F19:F20) -> 195 | G21: =SUM(G19:G20) -> 220 | H21: =SUM(H19:H20) -> 217 | I21: =SUM(I19:I20) -> 218 | J21: =SUM(J19:J20) -> 218 | K21: =SUM(K19:K20) -> 202 | L21: =SUM(L19:L20) -> 214 | ... AJ21: =SUM(AJ19:AJ20) -> 212 | AK21: =SUM(E21:AJ21) -> 6571
B22: 2. | C22: Jumlah pengguna hak pilih dalam Daftar Pemilih Tambahan (DPTb) | D22: LK | E22: 0 | F22: 0 | G22: 0 | H22: 0 | I22: 1 | J22: 0 | K22: 0 | L22: 0 | M22: 0 | N22: 0 | O22: 1 | P22: 0 | Q22: 1 | R22: 0 | S22: 0 | T22: 0 | U22: 0 | V22: 0 | W22: 0 | X22: 0 | Y22: 0 | Z22: 1 | AA22: 0 | AB22: 0 | AC22: 0 | AD22: 0 | AE22: 0 | AF22: 1 | AG22: 0 | AH22: 0 | AI22: 0 | AJ22: 0 | AK22: =SUM(E22:AJ22) -> 5
D23: PR | E23: 1 | F23: 0 | G23: 0 | H23: 0 | I23: 1 | J23: 0 | K23: 0 | L23: 0 | M23: 0 | N23: 0 | O23: 1 | P23: 0 | Q23: 0 | R23: 0 | S23: 0 | T23: 0 | U23: 1 | V23: 0 | W23: 0 | X23: 0 | Y23: 0 | Z23: 0 | AA23: 0 | AB23: 0 | AC23: 0 | AD23: 0 | AE23: 0 | AF23: 0 | AG23: 0 | AH23: 0 | AI23: 0 | AJ23: 0 | AK23: =SUM(E23:AJ23) -> 4
D24: JML | E24: =SUM(E22:E23) -> 1 | F24: =SUM(F22:F23) -> 0 | G24: =SUM(G22:G23) -> 0 | H24: =SUM(H22:H23) -> 0 | I24: =SUM(I22:I23) -> 2 | J24: =SUM(J22:J23) -> 0 | K24: =SUM(K22:K23) -> 0 | L24: =SUM(L22:L23) -> 0 | ... AJ24: =SUM(AJ22:AJ23) -> 0 | AK24: =SUM(E24:AJ24) -> 9
B25: 3. | C25: Jumlah pengguna hak pilih dalam Daftar Pemilih Khusus (DPK) | D25: LK | E25: 2 | F25: 2 | G25: 2 | H25: 0 | I25: 0 | J25: 1 | K25: 1 | L25: 0 | M25: 1 | N25: 0 | O25: 1 | P25: 2 | Q25: 2 | R25: 0 | S25: 0 | T25: 1 | U25: 0 | V25: 1 | W25: 0 | X25: 3 | Y25: 0 | Z25: 1 | AA25: 0 | AB25: 1 | AC25: 1 | AD25: 3 | AE25: 2 | AF25: 0 | AG25: 3 | AH25: 1 | AI25: 2 | AJ25: 2 | AK25: =SUM(E25:AJ25) -> 35
D26: PR | E26: 1 | F26: 2 | G26: 3 | H26: 0 | I26: 1 | J26: 1 | K26: 2 | L26: 0 | M26: 2 | N26: 4 | O26: 1 | P26: 2 | Q26: 2 | R26: 1 | S26: 0 | T26: 0 | U26: 2 | V26: 0 | W26: 0 | X26: 5 | Y26: 0 | Z26: 0 | AA26: 4 | AB26: 2 | AC26: 3 | AD26: 0 | AE26: 3 | AF26: 0 | AG26: 2 | AH26: 3 | AI26: 1 | AJ26: 1 | AK26: =SUM(E26:AJ26) -> 48
D27: JML | E27: =SUM(E25:E26) -> 3 | F27: =SUM(F25:F26) -> 4 | G27: =SUM(G25:G26) -> 5 | H27: =SUM(H25:H26) -> 0 | I27: =SUM(I25:I26) -> 1 | J27: =SUM(J25:J26) -> 2 | K27: =SUM(K25:K26) -> 3 | L27: =SUM(L25:L26) -> 0 | ... AJ27: =SUM(AJ25:AJ26) -> 3 | AK27: =SUM(E27:AJ27) -> 83
B28: 4. | C28: Jumlah Pengguna Hak Pilih (B.1+B.2+B.3) | D28: LK | E28: =SUM(E19,E22,E25) -> 98 | F28: =SUM(F19,F22,F25) -> 94 | G28: =SUM(G19,G22,G25) -> 113 | H28: =SUM(H19,H22,H25) -> 107 | I28: =SUM(I19,I22,I25) -> 107 | J28: =SUM(J19,J22,J25) -> 109 | K28: =SUM(K19,K22,K25) -> 98 | L28: =SUM(L19,L22,L25) -> 102 | ... AJ28: =SUM(AJ19,AJ22,AJ25) -> 110 | AK28: =SUM(E28:AJ28) -> 3268
D29: PR | E29: =SUM(E20,E23,E26) -> 102 | F29: =SUM(F20,F23,F26) -> 105 | G29: =SUM(G20,G23,G26) -> 112 | H29: =SUM(H20,H23,H26) -> 110 | I29: =SUM(I20,I23,I26) -> 114 | J29: =SUM(J20,J23,J26) -> 111 | K29: =SUM(K20,K23,K26) -> 107 | L29: =SUM(L20,L23,L26) -> 112 | ... AJ29: =SUM(AJ20,AJ23,AJ26) -> 105 | AK29: =SUM(E29:AJ29) -> 3395
D30: JML | E30: =SUM(E28:E29) -> 200 | F30: =SUM(F28:F29) -> 199 | G30: =SUM(G28:G29) -> 225 | H30: =SUM(H28:H29) -> 217 | I30: =SUM(I28:I29) -> 221 | J30: =SUM(J28:J29) -> 220 | K30: =SUM(K28:K29) -> 205 | L30: =SUM(L28:L29) -> 214 | ... AJ30: =SUM(AJ28:AJ29) -> 215 | AK30: =SUM(E30:AJ30) -> 6663
A32: II | B32: DATA PENGGUNAAN SURAT SUARA
A33: 1 | B33: Jumlah surat suara yang diterima, termasuk surat suara cadangan 2,5% dari DPT | E33: 257 | F33: 271 | G33: 291 | H33: 276 | I33: 271 | J33: 285 | K33: 267 | L33: 275 | M33: 277 | N33: 279 | O33: 278 | P33: 278 | Q33: 270 | R33: 272 | S33: 272 | T33: 270 | U33: 274 | V33: 265 | W33: 274 | X33: 275 | Y33: 269 | Z33: 270 | AA33: 276 | AB33: 266 | AC33: 283 | AD33: 272 | AE33: 284 | AF33: 263 | AG33: 251 | AH33: 248 | AI33: 274 | AJ33: 279 | AK33: =SUM(E33:AJ33) -> 8712
A34: 2 | B34: Jumlah surat suara yang digunakan | E34: 200 | F34: 199 | G34: 225 | H34: 217 | I34: 221 | J34: 220 | K34: 205 | L34: 214 | M34: 206 | N34: 230 | O34: 208 | P34: 201 | Q34: 217 | R34: 191 | S34: 177 | T34: 212 | U34: 201 | V34: 199 | W34: 217 | X34: 197 | Y34: 201 | Z34: 215 | AA34: 213 | AB34: 209 | AC34: 230 | AD34: 214 | AE34: 211 | AF34: 208 | AG34: 188 | AH34: 207 | AI34: 195 | AJ34: 215 | AK34: =SUM(E34:AJ34) -> 6663
A35: 3 | B35: Jumlah surat suara dikembalikan oleh pemilih (karena rusak atau keliru coblos) | E35: 0 | F35: 0 | G35: 0 | H35: 0 | I35: 0 | J35: 0 | K35: 0 | L35: 0 | M35: 0 | N35: 0 | O35: 1 | P35: 0 | Q35: 2 | R35: 0 | S35: 0 | T35: 0 | U35: 0 | V35: 0 | W35: 1 | X35: 1 | Y35: 0 | Z35: 0 | AA35: 0 | AB35: 1 | AC35: 0 | AD35: 0 | AE35: 0 | AF35: 0 | AG35: 0 | AH35: 0 | AI35: 3 | AJ35: 1 | AK35: =SUM(E35:AJ35) -> 10
A36: 4 | B36: Jumlah surat suara yang tidak digunakan/tidak terpakai, termasuk sisa surat suara cadangan | E36: =E33-(E34+E35) -> 57 | F36: =F33-(F34+F35) -> 72 | G36: =G33-(G34+G35) -> 66 | H36: =H33-(H34+H35) -> 59 | I36: =I33-(I34+I35) -> 50 | J36: =J33-(J34+J35) -> 65 | K36: =K33-(K34+K35) -> 62 | L36: =L33-(L34+L35) -> 61 | ... AJ36: =AJ33-(AJ34+AJ35) -> 63 | AK36: =SUM(E36:AJ36) -> 2039
A38: III | B38: DATA PEMILIH DISABILITAS
B39: Jumlah seluruh Pemilih disabilitas yang menggunakan hak pilih | D39: LK | E39: 0 | F39: 0 | G39: 0 | H39: 0 | I39: 0 | J39: 0 | K39: 0 | L39: 0 | M39: 0 | N39: 0 | O39: 1 | P39: 0 | Q39: 0 | R39: 0 | S39: 0 | T39: 0 | U39: 1 | V39: 0 | W39: 0 | X39: 0 | Y39: 0 | Z39: 0 | AA39: 0 | AB39: 0 | AC39: 0 | AD39: 0 | AE39: 0 | AF39: 0 | AG39: 0 | AH39: 0 | AI39: 0 | AJ39: 0 | AK39: =SUM(E39:AJ39) -> 2
D40: PR | E40: 0 | F40: 0 | G40: 0 | H40: 0 | I40: 0 | J40: 0 | K40: 0 | L40: 0 | M40: 0 | N40: 0 | O40: 0 | P40: 0 | Q40: 0 | R40: 0 | S40: 0 | T40: 0 | U40: 2 | V40: 0 | W40: 0 | X40: 0 | Y40: 0 | Z40: 0 | AA40: 0 | AB40: 0 | AC40: 0 | AD40: 0 | AE40: 0 | AF40: 0 | AG40: 0 | AH40: 1 | AI40: 0 | AJ40: 0 | AK40: =SUM(E40:AJ40) -> 3
D41: JML | E41: =SUM(E39:E40) -> 0 | F41: =SUM(F39:F40) -> 0 | G41: =SUM(G39:G40) -> 0 | H41: =SUM(H39:H40) -> 0 | I41: =SUM(I39:I40) -> 0 | J41: =SUM(J39:J40) -> 0 | K41: =SUM(K39:K40) -> 0 | L41: =SUM(L39:L40) -> 0 | ... AJ41: =SUM(AJ39:AJ40) -> 0 | AK41: =SUM(E41:AJ41) -> 5
A43: IV | B43: DATA RINCIAN PEROLEHAN SUARA PASANGAN CALON BUPATI DAN WAKIL BUPATI
A44: NOMOR DAN NAMA CALON
B45: 1 | C45: H. ANIES RASYID BASWEDAN, Ph.D. - Dr. (H.C.) H. A. MUHAIMIN ISKANDAR | E45: 16 | F45: 19 | G45: 25 | H45: 32 | I45: 19 | J45: 16 | K45: 35 | L45: 21 | M45: 22 | N45: 13 | O45: 24 | P45: 18 | Q45: 24 | R45: 16 | S45: 13 | T45: 23 | U45: 11 | V45: 17 | W45: 14 | X45: 27 | Y45: 10 | Z45: 12 | AA45: 14 | AB45: 24 | AC45: 18 | AD45: 30 | AE45: 16 | AF45: 16 | AG45: 6 | AH45: 10 | AI45: 14 | AJ45: 15 | AK45: =SUM(E45:AJ45) -> 590
B46: 2 | C46: H. PRABOWO SUBIANTO - GIBRAN RAKABUMING RAKA | E46: 151 | F46: 156 | G46: 150 | H46: 136 | I46: 147 | J46: 147 | K46: 119 | L46: 145 | M46: 140 | N46: 170 | O46: 149 | P46: 132 | Q46: 127 | R46: 122 | S46: 127 | T46: 143 | U46: 120 | V46: 140 | W46: 169 | X46: 131 | Y46: 144 | Z46: 156 | AA46: 129 | AB46: 158 | AC46: 166 | AD46: 143 | AE46: 160 | AF46: 150 | AG46: 148 | AH46: 138 | AI46: 138 | AJ46: 129 | AK46: =SUM(E46:AJ46) -> 4580
B47: 3 | C47: H. GANJAR PRANOWO, S.H., M.I.P. - Prof. Dr. H. M. MAHFUD MD | E47: 32 | F47: 21 | G47: 48 | H47: 45 | I47: 52 | J47: 55 | K47: 50 | L47: 42 | M47: 42 | N47: 41 | O47: 31 | P47: 46 | Q47: 65 | R47: 51 | S47: 35 | T47: 40 | U47: 66 | V47: 37 | W47: 29 | X47: 38 | Y47: 46 | Z47: 41 | AA47: 66 | AB47: 27 | AC47: 42 | AD47: 37 | AE47: 31 | AF47: 38 | AG47: 33 | AH47: 54 | AI47: 41 | AJ47: 71 | AK47: =SUM(E47:AJ47) -> 1393
A49: V | B49: DATA SUARA SAH DAN TIDAK SAH
B50: A. | C50: JUMLAH SELURUH SUARA SAH | E50: =SUM(E45:E47) -> 199 | F50: =SUM(F45:F47) -> 196 | G50: =SUM(G45:G47) -> 223 | H50: =SUM(H45:H47) -> 213 | I50: =SUM(I45:I47) -> 218 | J50: =SUM(J45:J47) -> 218 | K50: =SUM(K45:K47) -> 204 | L50: =SUM(L45:L47) -> 208 | ... AJ50: =SUM(AJ45:AJ47) -> 215 | AK50: =SUM(E50:AJ50) -> 6563
B51: B. | C51: JUMLAH SUARA TIDAK SAH | E51: 1 | F51: 3 | G51: 2 | H51: 4 | I51: 3 | J51: 2 | K51: 1 | L51: 6 | M51: 2 | N51: 6 | O51: 4 | P51: 5 | Q51: 1 | R51: 2 | S51: 2 | T51: 6 | U51: 4 | V51: 5 | W51: 5 | X51: 1 | Y51: 1 | Z51: 6 | AA51: 4 | AB51: 0 | AC51: 4 | AD51: 4 | AE51: 4 | AF51: 4 | AG51: 1 | AH51: 5 | AI51: 2 | AJ51: 0 | AK51: =SUM(E51:AJ51) -> 100
B52: C. | C52: JUMLAH SELURUH SUARA SAH DAN SUARA TIDAK SAH (V.A + V.B) | E52: =SUM(E50:E51) -> 200 | F52: =SUM(F50:F51) -> 199 | G52: =SUM(G50:G51) -> 225 | H52: =SUM(H50:H51) -> 217 | I52: =SUM(I50:I51) -> 221 | J52: =SUM(J50:J51) -> 220 | K52: =SUM(K50:K51) -> 205 | L52: =SUM(L50:L51) -> 214 | ... AJ52: =SUM(AJ50:AJ51) -> 215 | AK52: =SUM(E52:AJ52) -> 6663

Sheet BULUREJO
C2: Kecamatan | D2: PURWOHARJO
C3: Kabupaten | D3: BANYUWANGI
C4: Provinsi | D4: JAWA TIMUR
C9: Kelurahan | D9: BULUREJO
A12: I | B12: DATA PEMILIH DAN PENGGUNAAN HAK PILIH | AF12: JUMLAH AKHIR
A13: A | B13: DATA PEMILIH | E13: TPS 001 | F13: TPS 002 | G13: TPS 003 | H13: TPS 004 | I13: TPS 005 | J13: TPS 006 | K13: TPS 007 | L13: TPS 008 | M13: TPS 009 | N13: TPS 010 | O13: TPS 011 | P13: TPS 012 | Q13: TPS 013 | R13: TPS 014 | S13: TPS 015 | T13: TPS 016 | U13: TPS 017 | V13: TPS 018 | W13: TPS 019 | X13: TPS 020 | Y13: TPS 021 | Z13: TPS 022 | AA13: TPS 023 | AB13: TPS 024 | AC13: TPS 025 | AD13: TPS 026 | AE13: TPS 027
B14: Jumlah Pemilih dalam Daftar Pemilih Tetap (DPT) | D14: LK | E14: 135 | F14: 123 | G14: 136 | H14: 133 | I14: 128 | J14: 133 | K14: 136 | L14: 143 | M14: 129 | N14: 138 | O14: 134 | P14: 128 | Q14: 143 | R14: 137 | S14: 135 | T14: 129 | U14: 110 | V14: 120 | W14: 117 | X14: 112 | Y14: 116 | Z14: 117 | AA14: 127 | AB14: 133 | AC14: 147 | AD14: 143 | AE14: 147 | AF14: =SUM(E14:AE14) -> 3529
D15: PR | E15: 136 | F15: 136 | G15: 135 | H15: 122 | I15: 135 | J15: 133 | K15: 128 | L15: 118 | M15: 140 | N15: 122 | O15: 126 | P15: 148 | Q15: 125 | R15: 131 | S15: 135 | T15: 138 | U15: 118 | V15: 121 | W15: 130 | X15: 131 | Y15: 128 | Z15: 119 | AA15: 141 | AB15: 146 | AC15: 142 | AD15: 153 | AE15: 147 | AF15: =SUM(E15:AE15) -> 3584
D16: JML | E16: =SUM(E14:E15) -> 271 | F16: =SUM(F14:F15) -> 259 | G16: =SUM(G14:G15) -> 271 | H16: =SUM(H14:H15) -> 255 | I16: =SUM(I14:I15) -> 263 | J16: =SUM(J14:J15) -> 266 | K16: =SUM(K14:K15) -> 264 | L16: =SUM(L14:L15) -> 261 | ... AE16: =SUM(AE14:AE15) -> 294 | AF16: =SUM(E16:AE16) -> 7113
A18: B | B18: PENGGUNA HAK PILIH
B19: 1. | C19: Jumlah pengguna hak pilih dalam Daftar Pemilih Tetap (DPT) | D19: LK | E19: 104 | F19: 105 | G19: 100 | H19: 102 | I19: 90 | J19: 99 | K19: 108 | L19: 103 | M19: 86 | N19: 102 | O19: 98 | P19: 96 | Q19: 99 | R19: 93 | S19: 103 | T19: 99 | U19: 89 | V19: 109 | W19: 88 | X19: 85 | Y19: 94 | Z19: 98 | AA19: 105 | AB19: 104 | AC19: 123 | AD19: 119 | AE19: 110 | AF19: =SUM(E19:AE19) -> 2711
D20: PR | E20: 105 | F20: 117 | G20: 106 | H20: 88 | I20: 95 | J20: 107 | K20: 108 | L20: 96 | M20: 103 | N20: 102 | O20: 102 | P20: 112 | Q20: 105 | R20: 99 | S20: 104 | T20: 101 | U20: 93 | V20: 95 | W20: 105 | X20: 105 | Y20: 98 | Z20: 105 | AA20: 112 | AB20: 123 | AC20: 123 | AD20: 127 | AE20: 113 | AF20: =SUM(E20:AE20) -> 2849
