Workbook

Sheet PPWP
C8: Kecamatan | D8: TEGALDLIMO
C9: Kabupaten | D9: BANYUWANGI
C10: Provinsi | D10: JAWA TIMUR
A12: I | B12: DATA PEMILIH DAN PENGGUNAAN HAK PILIH | E12: JUMLAH AKHIR
A13: A | B13: DATA PEMILIH
B14: Jumlah Pemilih dalam Daftar Pemilih Tetap (DPT) | D14: LK | E14: =KALIPAIT!X14+KEDUNGASRI!AD14+KEDUNGGEBANG!AM14+KEDUNGWUNGU!AF14+KENDALREJO!V14+PURWOAGUNG!S14+PURWOASRI!S14+TEGALDLIMO!AF14+WRINGINPITU!AF14 -> 26653
D15: PR | E15: =KALIPAIT!X15+KEDUNGASRI!AD15+KEDUNGGEBANG!AM15+KEDUNGWUNGU!AF15+KENDALREJO!V15+PURWOAGUNG!S15+PURWOASRI!S15+TEGALDLIMO!AF15+WRINGINPITU!AF15 -> 26210
D16: JML | E16: =SUM(E14:E15) -> 52863
A18: B | B18: PENGGUNA HAK PILIH
B19: 1. | C19: Jumlah pengguna hak pilih dalam Daftar Pemilih Tetap (DPT) | D19: LK | E19: =KALIPAIT!X19+KEDUNGASRI!AD19+KEDUNGGEBANG!AM19+KEDUNGWUNGU!AF19+KENDALREJO!V19+PURWOAGUNG!S19+PURWOASRI!S19+TEGALDLIMO!AF19+WRINGINPITU!AF19 -> 20780
D20: PR | E20: =KALIPAIT!X20+KEDUNGASRI!AD20+KEDUNGGEBANG!AM20+KEDUNGWUNGU!AF20+KENDALREJO!V20+PURWOAGUNG!S20+PURWOASRI!S20+TEGALDLIMO!AF20+WRINGINPITU!AF20 -> 21181
D21: JML | E21: =SUM(E19:E20) -> 41961
B22: 2. | C22: Jumlah pengguna hak pilih dalam Daftar Pemilih Tambahan (DPTb) | D22: LK | E22: =KALIPAIT!X22+KEDUNGASRI!AD22+KEDUNGGEBANG!AM22+KEDUNGWUNGU!AF22+KENDALREJO!V22+PURWOAGUNG!S22+PURWOASRI!S22+TEGALDLIMO!AF22+WRINGINPITU!AF22 -> 59
D23: PR | E23: =KALIPAIT!X23+KEDUNGASRI!AD23+KEDUNGGEBANG!AM23+KEDUNGWUNGU!AF23+KENDALREJO!V23+PURWOAGUNG!S23+PURWOASRI!S23+TEGALDLIMO!AF23+WRINGINPITU!AF23 -> 35
D24: JML | E24: =SUM(E22:E23) -> 94
B25: 3. | C25: Jumlah pengguna hak pilih dalam Daftar Pemilih Khusus (DPK) | D25: LK | E25: =KALIPAIT!X25+KEDUNGASRI!AD25+KEDUNGGEBANG!AM25+KEDUNGWUNGU!AF25+KENDALREJO!V25+PURWOAGUNG!S25+PURWOASRI!S25+TEGALDLIMO!AF25+WRINGINPITU!AF25 -> 56
D26: PR | E26: =KALIPAIT!X26+KEDUNGASRI!AD26+KEDUNGGEBANG!AM26+KEDUNGWUNGU!AF26+KENDALREJO!V26+PURWOAGUNG!S26+PURWOASRI!S26+TEGALDLIMO!AF26+WRINGINPITU!AF26 -> 87
D27: JML | E27: =SUM(E25:E26) -> 143
B28: 4. | C28: Jumlah Pengguna Hak Pilih (B.1+B.2+B.3) | D28: LK | E28: =E19+E22+E25 -> 20895
D29: PR | E29: =E20+E23+E26 -> 21303
D30: JML | E30: =SUM(E28:E29) -> 42198
A32: II | B32: DATA PENGGUNAAN SURAT SUARA
A33: 1 | B33: Jumlah surat suara yang diterima, termasuk surat suara cadangan 2,5% dari DPT | E33: =KALIPAIT!X33+KEDUNGASRI!AD33+KEDUNGGEBANG!AM33+KEDUNGWUNGU!AF33+KENDALREJO!V33+PURWOAGUNG!S33+PURWOASRI!S33+TEGALDLIMO!AF33+WRINGINPITU!AF33 -> 54103
A34: 2 | B34: Jumlah surat suara yang digunakan | E34: =KALIPAIT!X34+KEDUNGASRI!AD34+KEDUNGGEBANG!AM34+KEDUNGWUNGU!AF34+KENDALREJO!V34+PURWOAGUNG!S34+PURWOASRI!S34+TEGALDLIMO!AF34+WRINGINPITU!AF34 -> 42198
A35: 3 | B35: Jumlah surat suara dikembalikan oleh pemilih (karena rusak atau keliru coblos) | E35: =KALIPAIT!X35+KEDUNGASRI!AD35+KEDUNGGEBANG!AM35+KEDUNGWUNGU!AF35+KENDALREJO!V35+PURWOAGUNG!S35+PURWOASRI!S35+TEGALDLIMO!AF35+WRINGINPITU!AF35 -> 45
A36: 4 | B36: Jumlah surat suara yang tidak digunakan/tidak terpakai, termasuk sisa surat suara cadangan | E36: =E33-(E34+E35) -> 11860
A38: III | B38: DATA PEMILIH DISABILITAS
B39: Jumlah seluruh Pemilih disabilitas yang menggunakan hak pilih | D39: LK | E39: =KALIPAIT!X39+KEDUNGASRI!AD39+KEDUNGGEBANG!AM39+KEDUNGWUNGU!AF39+KENDALREJO!V39+PURWOAGUNG!S39+PURWOASRI!S39+TEGALDLIMO!AF39+WRINGINPITU!AF39 -> 17
D40: PR | E40: =KALIPAIT!X40+KEDUNGASRI!AD40+KEDUNGGEBANG!AM40+KEDUNGWUNGU!AF40+KENDALREJO!V40+PURWOAGUNG!S40+PURWOASRI!S40+TEGALDLIMO!AF40+WRINGINPITU!AF40 -> 22
D41: JML | E41: =SUM(E39:E40) -> 39
A43: IV | B43: DATA RINCIAN PEROLEHAN SUARA PASANGAN CALON BUPATI DAN WAKIL BUPATI
A44: NOMOR DAN NAMA CALON
B45: 1 | C45: H. ANIES RASYID BASWEDAN, Ph.D. - Dr. (H.C.) H. A. MUHAIMIN ISKANDAR | E45: =KALIPAIT!X45+KEDUNGASRI!AD45+KEDUNGGEBANG!AM45+KEDUNGWUNGU!AF45+KENDALREJO!V45+PURWOAGUNG!S45+PURWOASRI!S45+TEGALDLIMO!AF45+WRINGINPITU!AF45 -> 3245
B46: 2 | C46: H. PRABOWO SUBIANTO - GIBRAN RAKABUMING RAKA | E46: =KALIPAIT!X46+KEDUNGASRI!AD46+KEDUNGGEBANG!AM46+KEDUNGWUNGU!AF46+KENDALREJO!V46+PURWOAGUNG!S46+PURWOASRI!S46+TEGALDLIMO!AF46+WRINGINPITU!AF46 -> 30832
B47: 3 | C47: H. GANJAR PRANOWO, S.H., M.I.P. - Prof. Dr. H. M. MAHFUD MD | E47: =KALIPAIT!X47+KEDUNGASRI!AD47+KEDUNGGEBANG!AM47+KEDUNGWUNGU!AF47+KENDALREJO!V47+PURWOAGUNG!S47+PURWOASRI!S47+TEGALDLIMO!AF47+WRINGINPITU!AF47 -> 7603
A49: V | B49: DATA SUARA SAH DAN TIDAK SAH
B50: A. | C50: JUMLAH SELURUH SUARA SAH | E50: =KALIPAIT!X50+KEDUNGASRI!AD50+KEDUNGGEBANG!AM50+KEDUNGWUNGU!AF50+KENDALREJO!V50+PURWOAGUNG!S50+PURWOASRI!S50+TEGALDLIMO!AF50+WRINGINPITU!AF50 -> 41680
B51: B. | C51: JUMLAH SUARA TIDAK SAH | E51: =KALIPAIT!X51+KEDUNGASRI!AD51+KEDUNGGEBANG!AM51+KEDUNGWUNGU!AF51+KENDALREJO!V51+PURWOAGUNG!S51+PURWOASRI!S51+TEGALDLIMO!AF51+WRINGINPITU!AF51 -> 518
B52: C. | C52: JUMLAH SELURUH SUARA SAH DAN SUARA TIDAK SAH (V.A + V.B) | E52: =SUM(E50:E51) -> 42198

Sheet KALIPAIT
C2: Kecamatan | D2: TEGALDLIMO
C3: Kabupaten | D3: BANYUWANGI
C4: Provinsi | D4: JAWA TIMUR
C9: Kelurahan | D9: KALIPAIT
A12: I | B12: DATA PEMILIH DAN PENGGUNAAN HAK PILIH | X12: JUMLAH AKHIR
A13: A | B13: DATA PEMILIH | E13: TPS 001 | F13: TPS 002 | G13: TPS 003 | H13: TPS 004 | I13: TPS 005 | J13: TPS 006 | K13: TPS 007 | L13: TPS 008 | M13: TPS 009 | N13: TPS 010 | O13: TPS 011 | P13: TPS 012 | Q13: TPS 013 | R13: TPS 014 | S13: TPS 015 | T13: TPS 016 | U13: TPS 017 | V13: TPS 018 | W13: TPS 019
B14: Jumlah Pemilih dalam Daftar Pemilih Tetap (DPT) | D14: LK | E14: 120 | F14: 126 | G14: 116 | H14: 132 | I14: 127 | J14: 120 | K14: 130 | L14: 135 | M14: 143 | N14: 139 | O14: 138 | P14: 127 | Q14: 144 | R14: 134 | S14: 128 | T14: 125 | U14: 107 | V14: 136 | W14: 128 | X14: =SUM(E14:W14) -> 2455
D15: PR | E15: 130 | F15: 121 | G15: 128 | H15: 134 | I15: 133 | J15: 126 | K15: 121 | L15: 127 | M15: 116 | N15: 126 | O15: 135 | P15: 141 | Q15: 130 | R15: 117 | S15: 123 | T15: 119 | U15: 132 | V15: 130 | W15: 123 | X15: =SUM(E15:W15) -> 2412
D16: JML | E16: =SUM(E14:E15) -> 250 | F16: =SUM(F14:F15) -> 247 | G16: =SUM(G14:G15) -> 244 | H16: =SUM(H14:H15) -> 266 | I16: =SUM(I14:I15) -> 260 | J16: =SUM(J14:J15) -> 246 | K16: =SUM(K14:K15) -> 251 | L16: =SUM(L14:L15) -> 262 | ... W16: =SUM(W14:W15) -> 251 | X16: =SUM(E16:W16) -> 4867
A18: B | B18: PENGGUNA HAK PILIH
B19: 1. | C19: Jumlah pengguna hak pilih dalam Daftar Pemilih Tetap (DPT) | D19: LK | E19: 94 | F19: 93 | G19: 93 | H19: 104 | I19: 101 | J19: 103 | K19: 109 | L19: 112 | M19: 107 | N19: 119 | O19: 123 | P19: 105 | Q19: 129 | R19: 109 | S19: 98 | T19: 103 | U19: 87 | V19: 113 | W19: 107 | X19: =SUM(E19:W19) -> 2009
D20: PR | E20: 117 | F20: 100 | G20: 104 | H20: 116 | I20: 118 | J20: 109 | K20: 106 | L20: 110 | M20: 93 | N20: 114 | O20: 110 | P20: 112 | Q20: 113 | R20: 95 | S20: 92 | T20: 100 | U20: 107 | V20: 107 | W20: 103 | X20: =SUM(E20:W20) -> 2026
D21: JML | E21: =SUM(E19:E20) -> 211 | F21: =SUM(F19:F20) -> 193 | G21: =SUM(G19:G20) -> 197 | H21: =SUM(H19:H20) -> 220 | I21: =SUM(I19:I20) -> 219 | J21: =SUM(J19:J20) -> 212 | K21: =SUM(K19:K20) -> 215 | L21: =SUM(L19:L20) -> 222 | ... W21: =SUM(W19:W20) -> 210 | X21: =SUM(E21:W21) -> 4035
B22: 2. | C22: Jumlah pengguna hak pilih dalam Daftar Pemilih Tambahan (DPTb) | D22: LK | E22: 0 | F22: 0 | G22: 0 | H22: 0 | I22: 0 | J22: 0 | K22: 0 | L22: 1 | M22: 0 | N22: 0 | O22: 0 | P22: 0 | Q22: 1 | R22: 0 | S22: 0 | T22: 0 | U22: 0 | V22: 0 | W22: 0 | X22: =SUM(E22:W22) -> 2
D23: PR | E23: 0 | F23: 0 | G23: 0 | H23: 0 | I23: 0 | J23: 0 | K23: 0 | L23: 0 | M23: 1 | N23: 0 | O23: 0 | P23: 0 | Q23: 0 | R23: 0 | S23: 0 | T23: 0 | U23: 0 | V23: 0 | W23: 0 | X23: =SUM(E23:W23) -> 1
D24: JML | E24: =SUM(E22:E23) -> 0 | F24: =SUM(F22:F23) -> 0 | G24: =SUM(G22:G23) -> 0 | H24: =SUM(H22:H23) -> 0 | I24: =SUM(I22:I23) -> 0 | J24: =SUM(J22:J23) -> 0 | K24: =SUM(K22:K23) -> 0 | L24: =SUM(L22:L23) -> 1 | ... W24: =SUM(W22:W23) -> 0 | X24: =SUM(E24:W24) -> 3
B25: 3. | C25: Jumlah pengguna hak pilih dalam Daftar Pemilih Khusus (DPK) | D25: LK | E25: 0 | F25: 1 | G25: 2 | H25: 1 | I25: 2 | J25: 0 | K25: 0 | L25: 0 | M25: 0 | N25: 0 | O25: 0 | P25: 0 | Q25: 0 | R25: 0 | S25: 0 | T25: 0 | U25: 0 | V25: 2 | W25: 0 | X25: =SUM(E25:W25) -> 8
D26: PR | E26: 0 | F26: 0 | G26: 2 | H26: 1 | I26: 0 | J26: 0 | K26: 0 | L26: 1 | M26: 0 | N26: 2 | O26: 0 | P26: 0 | Q26: 0 | R26: 0 | S26: 0 | T26: 1 | U26: 0 | V26: 1 | W26: 0 | X26: =SUM(E26:W26) -> 8
D27: JML | E27: =SUM(E25:E26) -> 0 | F27: =SUM(F25:F26) -> 1 | G27: =SUM(G25:G26) -> 4 | H27: =SUM(H25:H26) -> 2 | I27: =SUM(I25:I26) -> 2 | J27: =SUM(J25:J26) -> 0 | K27: =SUM(K25:K26) -> 0 | L27: =SUM(L25:L26) -> 1 | ... W27: =SUM(W25:W26) -> 0 | X27: =SUM(E27:W27) -> 16
B28: 4. | C28: Jumlah Pengguna Hak Pilih (B.1+B.2+B.3) | D28: LK | E28: =SUM(E19,E22,E25) -> 94 | F28: =SUM(F19,F22,F25) -> 94 | G28: =SUM(G19,G22,G25) -> 95 | H28: =SUM(H19,H22,H25) -> 105 | I28: =SUM(I19,I22,I25) -> 103 | J28: =SUM(J19,J22,J25) -> 103 | K28: =SUM(K19,K22,K25) -> 109 | L28: =SUM(L19,L22,L25) -> 113 | ... W28: =SUM(W19,W22,W25) -> 107 | X28: =SUM(E28:W28) -> 2019
D29: PR | E29: =SUM(E20,E23,E26) -> 117 | F29: =SUM(F20,F23,F26) -> 100 | G29: =SUM(G20,G23,G26) -> 106 | H29: =SUM(H20,H23,H26) -> 117 | I29: =SUM(I20,I23,I26) -> 118 | J29: =SUM(J20,J23,J26) -> 109 | K29: =SUM(K20,K23,K26) -> 106 | L29: =SUM(L20,L23,L26) -> 111 | ... W29: =SUM(W20,W23,W26) -> 103 | X29: =SUM(E29:W29) -> 2035
D30: JML | E30: =SUM(E28:E29) -> 211 | F30: =SUM(F28:F29) -> 194 | G30: =SUM(G28:G29) -> 201 | H30: =SUM(H28:H29) -> 222 | I30: =SUM(I28:I29) -> 221 | J30: =SUM(J28:J29) -> 212 | K30: =SUM(K28:K29) -> 215 | L30: =SUM(L28:L29) -> 224 | ... W30: =SUM(W28:W29) -> 210 | X30: =SUM(E30:W30) -> 4054
A32: II | B32: DATA PENGGUNAAN SURAT SUARA
A33: 1 | B33: Jumlah surat suara yang diterima, termasuk surat suara cadangan 2,5% dari DPT | E33: 255 | F33: 254 | G33: 250 | H33: 274 | I33: 266 | J33: 251 | K33: 259 | L33: 267 | M33: 266 | N33: 271 | O33: 279 | P33: 275 | Q33: 280 | R33: 257 | S33: 257 | T33: 250 | U33: 244 | V33: 273 | W33: 255 | X33: =SUM(E33:W33) -> 4983
A34: 2 | B34: Jumlah surat suara yang digunakan | E34: 211 | F34: 194 | G34: 201 | H34: 222 | I34: 221 | J34: 212 | K34: 215 | L34: 224 | M34: 201 | N34: 235 | O34: 233 | P34: 217 | Q34: 243 | R34: 204 | S34: 190 | T34: 204 | U34: 194 | V34: 223 | W34: 210 | X34: =SUM(E34:W34) -> 4054
A35: 3 | B35: Jumlah surat suara dikembalikan oleh pemilih (karena rusak atau keliru coblos) | E35: 1 | F35: 0 | G35: 0 | H35: 0 | I35: 5 | J35: 0 | K35: 0 | L35: 0 | M35: 0 | N35: 0 | O35: 0 | P35: 0 | Q35: 0 | R35: 0 | S35: 0 | T35: 0 | U35: 0 | V35: 0 | W35: 0 | X35: =SUM(E35:W35) -> 6
A36: 4 | B36: Jumlah surat suara yang tidak digunakan/tidak terpakai, termasuk sisa surat suara cadangan | E36: =E33-(E34+E35) -> 43 | F36: =F33-(F34+F35) -> 60 | G36: =G33-(G34+G35) -> 49 | H36: =H33-(H34+H35) -> 52 | I36: =I33-(I34+I35) -> 40 | J36: =J33-(J34+J35) -> 39 | K36: =K33-(K34+K35) -> 44 | L36: =L33-(L34+L35) -> 43 | ... W36: =W33-(W34+W35) -> 45 | X36: =SUM(E36:W36) -> 923
A38: III | B38: DATA PEMILIH DISABILITAS
B39: Jumlah seluruh Pemilih disabilitas yang menggunakan hak pilih | D39: LK | E39: 0 | F39: 0 | G39: 0 | H39: 0 | I39: 0 | J39: 0 | K39: 0 | L39: 0 | M39: 0 | N39: 0 | O39: 0 | P39: 0 | Q39: 0 | R39: 0 | S39: 0 | T39: 1 | U39: 0 | V39: 0 | W39: 0 | X39: =SUM(E39:W39) -> 1
D40: PR | E40: 0 | F40: 0 | G40: 0 | H40: 0 | I40: 0 | J40: 0 | K40: 0 | L40: 0 | M40: 0 | N40: 0 | O40: 0 | P40: 0 | Q40: 0 | R40: 0 | S40: 0 | T40: 0 | U40: 0 | V40: 0 | W40: 0 | X40: =SUM(E40:W40) -> 0
D41: JML | E41: =SUM(E39:E40) -> 0 | F41: =SUM(F39:F40) -> 0 | G41: =SUM(G39:G40) -> 0 | H41: =SUM(H39:H40) -> 0 | I41: =SUM(I39:I40) -> 0 | J41: =SUM(J39:J40) -> 0 | K41: =SUM(K39:K40) -> 0 | L41: =SUM(L39:L40) -> 0 | ... W41: =SUM(W39:W40) -> 0 | X41: =SUM(E41:W41) -> 1
A43: IV | B43: DATA RINCIAN PEROLEHAN SUARA PASANGAN CALON BUPATI DAN WAKIL BUPATI
A44: NOMOR DAN NAMA CALON
B45: 1 | C45: H. ANIES RASYID BASWEDAN, Ph.D. - Dr. (H.C.) H. A. MUHAIMIN ISKANDAR | E45: 30 | F45: 25 | G45: 20 | H45: 37 | I45: 21 | J45: 10 | K45: 11 | L45: 17 | M45: 8 | N45: 2 | O45: 11 | P45: 9 | Q45: 8 | R45: 6 | S45: 5 | T45: 7 | U45: 15 | V45: 7 | W45: 12 | X45: =SUM(E45:W45) -> 261
B46: 2 | C46: H. PRABOWO SUBIANTO - GIBRAN RAKABUMING RAKA | E46: 148 | F46: 146 | G46: 138 | H46: 143 | I46: 169 | J46: 185 | K46: 174 | L46: 182 | M46: 171 | N46: 215 | O46: 207 | P46: 185 | Q46: 193 | R46: 160 | S46: 148 | T46: 155 | U46: 155 | V46: 186 | W46: 177 | X46: =SUM(E46:W46) -> 3237
B47: 3 | C47: H. GANJAR PRANOWO, S.H., M.I.P. - Prof. Dr. H. M. MAHFUD MD | E47: 31 | F47: 19 | G47: 42 | H47: 37 | I47: 30 | J47: 17 | K47: 29 | L47: 25 | M47: 22 | N47: 18 | O47: 15 | P47: 19 | Q47: 42 | R47: 37 | S47: 36 | T47: 40 | U47: 22 | V47: 30 | W47: 13 | X47: =SUM(E47:W47) -> 524
A49: V | B49: DATA SUARA SAH DAN TIDAK SAH
B50: A. | C50: JUMLAH SELURUH SUARA SAH | E50: =SUM(E45:E47) -> 209 | F50: =SUM(F45:F47) -> 190 | G50: =SUM(G45:G47) -> 200 | H50: =SUM(H45:H47) -> 217 | I50: =SUM(I45:I47) -> 220 | J50: =SUM(J45:J47) -> 212 | K50: =SUM(K45:K47) -> 214 | L50: =SUM(L45:L47) -> 224 | ... W50: =SUM(W45:W47) -> 202 | X50: =SUM(E50:W50) -> 4022
B51: B. | C51: JUMLAH SUARA TIDAK SAH | E51: 2 | F51: 4 | G51: 1 | H51: 5 | I51: 1 | J51: 0 | K51: 1 | L51: 0 | M51: 0 | N51: 0 | O51: 0 | P51: 4 | Q51: 0 | R51: 1 | S51: 1 | T51: 2 | U51: 2 | V51: 0 | W51: 8 | X51: =SUM(E51:W51) -> 32
B52: C. | C52: JUMLAH SELURUH SUARA SAH DAN SUARA TIDAK SAH (V.A + V.B) | E52: =SUM(E50:E51) -> 211 | F52: =SUM(F50:F51) -> 194 | G52: =SUM(G50:G51) -> 201 | H52: =SUM(H50:H51) -> 222 | I52: =SUM(I50:I51) -> 221 | J52: =SUM(J50:J51) -> 212 | K52: =SUM(K50:K51) -> 215 | L52: =SUM(L50:L51) -> 224 | ... W52: =SUM(W50:W51) -> 210 | X52: =SUM(E52:W52) -> 4054

Sheet KEDUNGASRI
C2: Kecamatan | D2: TEGALDLIMO
C3: Kabupaten | D3: BANYUWANGI
C4: Provinsi | D4: JAWA TIMUR
C9: Kelurahan | D9: KEDUNGASRI
A12: I | B12: DATA PEMILIH DAN PENGGUNAAN HAK PILIH | AD12: JUMLAH AKHIR
A13: A | B13: DATA PEMILIH | E13: TPS 001 | F13: TPS 002 | G13: TPS 003 | H13: TPS 004 | I13: TPS 005 | J13: TPS 006 | K13: TPS 007 | L13: TPS 008 | M13: TPS 009 | N13: TPS 010 | O13: TPS 011 | P13: TPS 012 | Q13: TPS 013 | R13: TPS 014 | S13: TPS 015 | T13: TPS 016 | U13: TPS 017 | V13: TPS 018 | W13: TPS 019 | X13: TPS 020 | Y13: TPS 021 | Z13: TPS 022 | AA13: TPS 023 | AB13: TPS 024 | AC13: TPS 025
B14: Jumlah Pemilih dalam Daftar Pemilih Tetap (DPT) | D14: LK | E14: 138 | F14: 129 | G14: 132 | H14: 134 | I14: 116 | J14: 124 | K14: 130 | L14: 140 | M14: 136 | N14: 124 | O14: 126 | P14: 136 | Q14: 135 | R14: 132 | S14: 147 | T14: 130 | U14: 135 | V14: 149 | W14: 110 | X14: 88 | Y14: 127 | Z14: 128 | AA14: 142 | AB14: 134 | AC14: 127 | AD14: =SUM(E14:AC14) -> 3249
D15: PR | E15: 129 | F15: 136 | G15: 138 | H15: 132 | I15: 122 | J15: 126 | K15: 130 | L15: 137 | M15: 139 | N15: 139 | O15: 137 | P15: 130 | Q15: 129 | R15: 134 | S15: 135 | T15: 137 | U15: 136 | V15: 133 | W15: 111 | X15: 66 | Y15: 131 | Z15: 126 | AA15: 115 | AB15: 134 | AC15: 127 | AD15: =SUM(E15:AC15) -> 3209
D16: JML | E16: =SUM(E14:E15) -> 267 | F16: =SUM(F14:F15) -> 265 | G16: =SUM(G14:G15) -> 270 | H16: =SUM(H14:H15) -> 266 | I16: =SUM(I14:I15) -> 238 | J16: =SUM(J14:J15) -> 250 | K16: =SUM(K14:K15) -> 260 | L16: =SUM(L14:L15) -> 277 | ... AC16: =SUM(AC14:AC15) -> 254 | AD16: =SUM(E16:AC16) -> 6458
A18: B | B18: PENGGUNA HAK PILIH
B19: 1. | C19: Jumlah pengguna hak pilih dalam Daftar Pemilih Tetap (DPT) | D19: LK | E19: 121 | F19: 98 | G19: 101 | H19: 107 | I19: 81 | J19: 101 | K19: 97 | L19: 123 | M19: 102 | N19: 90 | O19: 97 | P19: 110 | Q19: 102 | R19: 101 | S19: 103 | T19: 95 | U19: 118 | V19: 123 | W19: 88 | X19: 66 | Y19: 97 | Z19: 106 | AA19: 97 | AB19: 107 | AC19: 108 | AD19: =SUM(E19:AC19) -> 2539
D20: PR | E20: 117 | F20: 100 | G20: 108 | H20: 118 | I20: 97 | J20: 103 | K20: 106 | L20: 119 | M20: 108 | N20: 114 | O20: 112 | P20: 104 | Q20: 105 | R20: 108 | S20: 110 | T20: 108 | U20: 110 | V20: 106 | W20: 93 | X20: 55 | Y20: 106 | Z20: 99 | AA20: 92 | AB20: 115 | AC20: 114 | AD20: =SUM(E20:AC20) -> 2627
D21: JML | E21: =SUM(E19:E20) -> 238 | F21: =SUM(F19:F20) -> 198 | G21: =SUM(G19:G20) -> 209 | H21: =SUM(H19:H20) -> 225 | I21: =SUM(I19:I20) -> 178 | J21: =SUM(J19:J20) -> 204 | K21: =SUM(K19:K20) -> 203 | L21: =SUM(L19:L20) -> 242 | ... AC21: =SUM(AC19:AC20) -> 222 | AD21: =SUM(E21:AC21) -> 5166
B22: 2. | C22: Jumlah pengguna hak pilih dalam Daftar Pemilih Tambahan (DPTb) | D22: LK | E22: 0 | F22: 0 | G22: 0 | H22: 0 | I22: 0 | J22: 0 | K22: 0 | L22: 0 | M22: 0 | N22: 0 | O22: 0 | P22: 0 | Q22: 0 | R22: 0 | S22: 0 | T22: 0 | U22: 0 | V22: 0 | W22: 0 | X22: 0 | Y22: 0 | Z22: 0 | AA22: 0 | AB22: 0 | AC22: 0 | AD22: =SUM(E22:AC22) -> 0
D23: PR | E23: 0 | F23: 0 | G23: 0 | H23: 0 | I23: 0 | J23: 0 | K23: 0 | L23: 0 | M23: 0 | N23: 0 | O23: 0 | P23: 0 | Q23: 0 | R23: 0 | S23: 0 | T23: 0 | U23: 0 | V23: 0 | W23: 0 | X23: 0 | Y23: 0 | Z23: 0 | AA23: 0 | AB23: 0 | AC23: 0 | AD23: =SUM(E23:AC23) -> 0
D24: JML | E24: =SUM(E22:E23) -> 0 | F24: =SUM(F22:F23) -> 0 | G24: =SUM(G22:G23) -> 0 | H24: =SUM(H22:H23) -> 0 | I24: =SUM(I22:I23) -> 0 | J24: =SUM(J22:J23) -> 0 | K24: =SUM(K22:K23) -> 0 | L24: =SUM(L22:L23) -> 0 | ... AC24: =SUM(AC22:AC23) -> 0 | AD24: =SUM(E24:AC24) -> 0
B25: 3. | C25: Jumlah pengguna hak pilih dalam Daftar Pemilih Khusus (DPK) | D25: LK | E25: 0 | F25: 0 | G25: 0 | H25: 0 | I25: 0 | J25: 0 | K25: 0 | L25: 0 | M25: 0 | N25: 0 | O25: 0 | P25: 0 | Q25: 0 | R25: 0 | S25: 0 | T25: 0 | U25: 0 | V25: 0 | W25: 0 | X25: 0 | Y25: 0 | Z25: 0 | AA25: 0 | AB25: 0 | AC25: 1 | AD25: =SUM(E25:AC25) -> 1
D26: PR | E26: 0 | F26: 0 | G26: 0 | H26: 0 | I26: 0 | J26: 0 | K26: 0 | L26: 0 | M26: 0 | N26: 0 | O26: 0 | P26: 0 | Q26: 0 | R26: 0 | S26: 0 | T26: 0 | U26: 0 | V26: 0 | W26: 2 | X26: 0 | Y26: 0 | Z26: 0 | AA26: 0 | AB26: 0 | AC26: 0 | AD26: =SUM(E26:AC26) -> 2
D27: JML | E27: =SUM(E25:E26) -> 0 | F27: =SUM(F25:F26) -> 0 | G27: =SUM(G25:G26) -> 0 | H27: =SUM(H25:H26) -> 0 | I27: =SUM(I25:I26) -> 0 | J27: =SUM(J25:J26) -> 0 | K27: =SUM(K25:K26) -> 0 | L27: =SUM(L25:L26) -> 0 | ... AC27: =SUM(AC25:AC26) -> 1 | AD27: =SUM(E27:AC27) -> 3
B28: 4. | C28: Jumlah Pengguna Hak Pilih (B.1+B.2+B.3) | D28: LK | E28: =SUM(E19,E22,E25) -> 121 | F28: =SUM(F19,F22,F25) -> 98 | G28: =SUM(G19,G22,G25) -> 101 | H28: =SUM(H19,H22,H25) -> 107 | I28: =SUM(I19,I22,I25) -> 81 | J28: =SUM(J19,J22,J25) -> 101 | K28: =SUM(K19,K22,K25) -> 97 | L28: =SUM(L19,L22,L25) -> 123 | ... AC28: =SUM(AC19,AC22,AC25) -> 109 | AD28: =SUM(E28:AC28) -> 2540
D29: PR | E29: =SUM(E20,E23,E26) -> 117 | F29: =SUM(F20,F23,F26) -> 100 | G29: =SUM(G20,G23,G26) -> 108 | H29: =SUM(H20,H23,H26) -> 118 | I29: =SUM(I20,I23,I26) -> 97 | J29: =SUM(J20,J23,J26) -> 103 | K29: =SUM(K20,K23,K26) -> 106 | L29: =SUM(L20,L23,L26) -> 119 | ... AC29: =SUM(AC20,AC23,AC26) -> 114 | AD29: =SUM(E29:AC29) -> 2629
D30: JML | E30: =SUM(E28:E29) -> 238 | F30: =SUM(F28:F29) -> 198 | G30: =SUM(G28:G29) -> 209 | H30: =SUM(H28:H29) -> 225 | I30: =SUM(I28:I29) -> 178 | J30: =SUM(J28:J29) -> 204 | K30: =SUM(K28:K29) -> 203 | L30: =SUM(L28:L29) -> 242 | ... AC30: =SUM(AC28:AC29) -> 223 | AD30: =SUM(E30:AC30) -> 5169
A32: II | B32: DATA PENGGUNAAN SURAT SUARA
A33: 1 | B33: Jumlah surat suara yang diterima, termasuk surat suara cadangan 2,5% dari DPT | E33: 273 | F33: 271 | G33: 276 | H33: 272 | I33: 243 | J33: 255 | K33: 266 | L33: 283 | M33: 281 | N33: 269 | O33: 269 | P33: 271 | Q33: 270 | R33: 272 | S33: 288 | T33: 272 | U33: 277 | V33: 288 | W33: 226 | X33: 158 | Y33: 264 | Z33: 260 | AA33: 265 | AB33: 273 | AC33: 272 | AD33: =SUM(E33:AC33) -> 6614
A34: 2 | B34: Jumlah surat suara yang digunakan | E34: 238 | F34: 198 | G34: 209 | H34: 225 | I34: 178 | J34: 204 | K34: 203 | L34: 242 | M34: 210 | N34: 204 | O34: 209 | P34: 214 | Q34: 207 | R34: 209 | S34: 213 | T34: 203 | U34: 228 | V34: 229 | W34: 183 | X34: 121 | Y34: 203 | Z34: 205 | AA34: 189 | AB34: 222 | AC34: 223 | AD34: =SUM(E34:AC34) -> 5169
A35: 3 | B35: Jumlah surat suara dikembalikan oleh pemilih (karena rusak atau keliru coblos) | E35: 0 | F35: 0 | G35: 1 | H35: 0 | I35: 0 | J35: 0 | K35: 0 | L35: 0 | M35: 0 | N35: 0 | O35: 0 | P35: 0 | Q35: 0 | R35: 0 | S35: 0 | T35: 0 | U35: 0 | V35: 0 | W35: 0 | X35: 1 | Y35: 0 | Z35: 0 | AA35: 0 | AB35: 0 | AC35: 0 | AD35: =SUM(E35:AC35) -> 2
A36: 4 | B36: Jumlah surat suara yang tidak digunakan/tidak terpakai, termasuk sisa surat suara cadangan | E36: =E33-(E34+E35) -> 35 | F36: =F33-(F34+F35) -> 73 | G36: =G33-(G34+G35) -> 66 | H36: =H33-(H34+H35) -> 47 | I36: =I33-(I34+I35) -> 65 | J36: =J33-(J34+J35) -> 51 | K36: =K33-(K34+K35) -> 63 | L36: =L33-(L34+L35) -> 41 | ... AC36: =AC33-(AC34+AC35) -> 49 | AD36: =SUM(E36:AC36) -> 1443
A38: III | B38: DATA PEMILIH DISABILITAS
B39: Jumlah seluruh Pemilih disabilitas yang menggunakan hak pilih | D39: LK | E39: 0 | F39: 0 | G39: 0 | H39: 0 | I39: 0 | J39: 0 | K39: 0 | L39: 0 | M39: 0 | N39: 0 | O39: 0 | P39: 0 | Q39: 0 | R39: 0 | S39: 0 | T39: 0 | U39: 0 | V39: 0 | W39: 0 | X39: 0 | Y39: 0 | Z39: 0 | AA39: 0 | AB39: 0 | AC39: 1 | AD39: =SUM(E39:AC39) -> 1
D40: PR | E40: 0 | F40: 0 | G40: 0 | H40: 0 | I40: 0 | J40: 0 | K40: 0 | L40: 0 | M40: 0 | N40: 0 | O40: 0 | P40: 0 | Q40: 0 | R40: 0 | S40: 0 | T40: 0 | U40: 0 | V40: 0 | W40: 0 | X40: 0 | Y40: 0 | Z40: 0 | AA40: 0 | AB40: 0 | AC40: 2 | AD40: =SUM(E40:AC40) -> 2
D41: JML | E41: =SUM(E39:E40) -> 0 | F41: =SUM(F39:F40) -> 0 | G41: =SUM(G39:G40) -> 0 | H41: =SUM(H39:H40) -> 0 | I41: =SUM(I39:I40) -> 0 | J41: =SUM(J39:J40) -> 0 | K41: =SUM(K39:K40) -> 0 | L41: =SUM(L39:L40) -> 0 | ... AC41: =SUM(AC39:AC40) -> 3 | AD41: =SUM(E41:AC41) -> 3
A43: IV | B43: DATA RINCIAN PEROLEHAN SUARA PASANGAN CALON BUPATI DAN WAKIL BUPATI
A44: NOMOR DAN NAMA CALON
B45: 1 | C45: H. ANIES RASYID BASWEDAN, Ph.D. - Dr. (H.C.) H. A. MUHAIMIN ISKANDAR | E45: 23 | F45: 31 | G45: 39 | H45: 17 | I45: 6 | J45: 7 | K45: 11 | L45: 27 | M45: 13 | N45: 8 | O45: 8 | P45: 10 | Q45: 11 | R45: 9 | S45: 1 | T45: 8 | U45: 6 | V45: 5 | W45: 4 | X45: 2 | Y45: 14 | Z45: 2 | AA45: 7 | AB45: 1 | AC45: 11 | AD45: =SUM(E45:AC45) -> 281
B46: 2 | C46: H. PRABOWO SUBIANTO - GIBRAN RAKABUMING RAKA | E46: 181 | F46: 140 | G46: 147 | H46: 143 | I46: 119 | J46: 140 | K46: 169 | L46: 184 | M46: 153 | N46: 142 | O46: 139 | P46: 183 | Q46: 153 | R46: 164 | S46: 189 | T46: 167 | U46: 186 | V46: 185 | W46: 162 | X46: 91 | Y46: 165 | Z46: 161 | AA46: 165 | AB46: 198 | AC46: 175 | AD46: =SUM(E46:AC46) -> 4001
B47: 3 | C47: H. GANJAR PRANOWO, S.H., M.I.P. - Prof. Dr. H. M. MAHFUD MD | E47: 32 | F47: 25 | G47: 23 | H47: 63 | I47: 49 | J47: 55 | K47: 23 | L47: 27 | M47: 42 | N47: 54 | O47: 61 | P47: 18 | Q47: 43 | R47: 33 | S47: 22 | T47: 27 | U47: 36 | V47: 30 | W47: 16 | X47: 27 | Y47: 24 | Z47: 40 | AA47: 17 | AB47: 19 | AC47: 33 | AD47: =SUM(E47:AC47) -> 839
A49: V | B49: DATA SUARA SAH DAN TIDAK SAH
B50: A. | C50: JUMLAH SELURUH SUARA SAH | E50: =SUM(E45:E47) -> 236 | F50: =SUM(F45:F47) -> 196 | G50: =SUM(G45:G47) -> 209 | H50: =SUM(H45:H47) -> 223 | I50: =SUM(I45:I47) -> 174 | J50: =SUM(J45:J47) -> 202 | K50: =SUM(K45:K47) -> 203 | L50: =SUM(L45:L47) -> 238 | ... AC50: =SUM(AC45:AC47) -> 219 | AD50: =SUM(E50:AC50) -> 5121
B51: B. | C51: JUMLAH SUARA TIDAK SAH | E51: 2 | F51: 2 | G51: 0 | H51: 2 | I51: 4 | J51: 2 | K51: 0 | L51: 4 | M51: 2 | N51: 0 | O51: 1 | P51: 3 | Q51: 0 | R51: 3 | S51: 1 | T51: 1 | U51: 0 | V51: 9 | W51: 1 | X51: 1 | Y51: 0 | Z51: 2 | AA51: 0 | AB51: 4 | AC51: 4 | AD51: =SUM(E51:AC51) -> 48
B52: C. | C52: JUMLAH SELURUH SUARA SAH DAN SUARA TIDAK SAH (V.A + V.B) | E52: =SUM(E50:E51) -> 238 | F52: =SUM(F50:F51) -> 198 | G52: =SUM(G50:G51) -> 209 | H52: =SUM(H50:H51) -> 225 | I52: =SUM(I50:I51) -> 178 | J52: =SUM(J50:J51) -> 204 | K52: =SUM(K50:K51) -> 203 | L52: =SUM(L50:L51) -> 242 | ... AC52: =SUM(AC50:AC51) -> 223 | AD52: =SUM(E52:AC52) -> 5169

Sheet KEDUNGGEBANG
C2: Kecamatan | D2: TEGALDLIMO
C3: Kabupaten | D3: BANYUWANGI
C4: Provinsi | D4: JAWA TIMUR
C9: Kelurahan | D9: KEDUNGGEBANG
A12: I | B12: DATA PEMILIH DAN PENGGUNAAN HAK PILIH | AM12: JUMLAH AKHIR
A13: A | B13: DATA PEMILIH | E13: TPS 001 | F13: TPS 002 | G13: TPS 003 | H13: TPS 004 | I13: TPS 005 | J13: TPS 006 | K13: TPS 007 | L13: TPS 008 | M13: TPS 009 | N13: TPS 010 | O13: TPS 011 | P13: TPS 012 | Q13: TPS 013 | R13: TPS 014 | S13: TPS 015 | T13: TPS 016 | U13: TPS 017 | V13: TPS 018 | W13: TPS 019 | X13: TPS 020 | Y13: TPS 021 | Z13: TPS 022 | AA13: TPS 023 | AB13: TPS 024 | AC13: TPS 025 | AD13: TPS 026 | AE13: TPS 027 | AF13: TPS 028 | AG13: TPS 029 | AH13: TPS 030 | AI13: TPS 031 | AJ13: TPS 032 | AK13: TPS 033 | AL13: TPS 034
B14: Jumlah Pemilih dalam Daftar Pemilih Tetap (DPT) | D14: LK | E14: 147 | F14: 147 | G14: 137 | H14: 153 | I14: 140 | J14: 139 | K14: 120 | L14: 148 | M14: 144 | N14: 94 | O14: 105 | P14: 134 | Q14: 118 | R14: 130 | S14: 131 | T14: 129 | U14: 129 | V14: 124 | W14: 133 | X14: 139 | Y14: 138 | Z14: 131 | AA14: 122 | AB14: 144 | AC14: 132 | AD14: 126 | AE14: 129 | AF14: 127 | AG14: 121 | AH14: 119 | AI14: 131 | AJ14: 131 | AK14: 116 | AL14: 123 | AM14: =SUM(E14:AL14) -> 4431
D15: PR | E15: 140 | F15: 146 | G15: 149 | H15: 141 | I15: 140 | J15: 138 | K15: 115 | L15: 143 | M15: 143 | N15: 91 | O15: 91 | P15: 126 | Q15: 133 | R15: 126 | S15: 124 | T15: 124 | U15: 122 | V15: 132 | W15: 118 | X15: 125 | Y15: 116 | Z15: 118 | AA15: 120 | AB15: 123 | AC15: 128 | AD15: 139 | AE15: 122 | AF15: 133 | AG15: 121 | AH15: 129 | AI15: 128 | AJ15: 128 | AK15: 126 | AL15: 123 | AM15: =SUM(E15:AL15) -> 4321
D16: JML | E16: =SUM(E14:E15) -> 287 | F16: =SUM(F14:F15) -> 293 | G16: =SUM(G14:G15) -> 286 | H16: =SUM(H14:H15) -> 294 | I16: =SUM(I14:I15) -> 280 | J16: =SUM(J14:J15) -> 277 | K16: =SUM(K14:K15) -> 235 | L16: =SUM(L14:L15) -> 291 | ... AL16: =SUM(AL14:AL15) -> 246 | AM16: =SUM(E16:AL16) -> 8752
A18: B | B18: PENGGUNA HAK PILIH
B19: 1. | C19: Jumlah pengguna hak pilih dalam Daftar Pemilih Tetap (DPT) | D19: LK | E19: 106 | F19: 100 | G19: 99 | H19: 118 | I19: 107 | J19: 112 | K19: 112 | L19: 117 | M19: 104 | N19: 72 | O19: 71 | P19: 100 | Q19: 98 | R19: 110 | S19: 100 | T19: 101 | U19: 85 | V19: 112 | W19: 90 | X19: 112 | Y19: 111 | Z19: 96 | AA19: 92 | AB19: 112 | AC19: 102 | AD19: 89 | AE19: 101 | AF19: 96 | AG19: 90 | AH19: 97 | AI19: 93 | AJ19: 104 | AK19: 88 | AL19: 94 | AM19: =SUM(E19:AL19) -> 3391
D20: PR | E20: 118 | F20: 112 | G20: 110 | H20: 109 | I20: 124 | J20: 113 | K20: 108 | L20: 124 | M20: 110 | N20: 70 | O20: 64 | P20: 105 | Q20: 108 | R20: 102 | S20: 92 | T20: 108 | U20: 101 | V20: 103 | W20: 86 | X20: 110 | Y20: 94 | Z20: 95 | AA20: 99 | AB20: 102 | AC20: 109 | AD20: 113 | AE20: 101 | AF20: 115 | AG20: 104 | AH20: 106 | AI20: 102 | AJ20: 104 | AK20: 103 | AL20: 105 | AM20: =SUM(E20:AL20) -> 3529
D21: JML | E21: =SUM(E19:E20) -> 224 | F21: =SUM(F19:F20) -> 212 | G21: =SUM(G19:G20) -> 209 | H21: =SUM(H19:H20) -> 227 | I21: =SUM(I19:I20) -> 231 | J21: =SUM(J19:J20) -> 225 | K21: =SUM(K19:K20) -> 220 | L21: =SUM(L19:L20) -> 241 | ... AL21: =SUM(AL19:AL20) -> 199 | AM21: =SUM(E21:AL21) -> 6920
B22: 2. | C22: Jumlah pengguna hak pilih dalam Daftar Pemilih Tambahan (DPTb) | D22: LK | E22: 1 | F22: 0 | G22: 1 | H22: 1 | I22: 1 | J22: 0 | K22: 0 | L22: 0 | M22: 2 | N22: 0 | O22: 0 | P22: 0 | Q22: 0 | R22: 0 | S22: 0 | T22: 0 | U22: 0 | V22: 0 | W22: 0 | X22: 0 | Y22: 0 | Z22: 0 | AA22: 0 | AB22: 1 | AC22: 0 | AD22: 1 | AE22: 1 | AF22: 0 | AG22: 0 | AH22: 2 | AI22: 0 | AJ22: 0 | AK22: 0 | AL22: 0 | AM22: =SUM(E22:AL22) -> 11
D23: PR | E23: 0 | F23: 0 | G23: 2 | H23: 0 | I23: 0 | J23: 0 | K23: 0 | L23: 0 | M23: 1 | N23: 0 | O23: 1 | P23: 0 | Q23: 0 | R23: 1 | S23: 0 | T23: 1 | U23: 1 | V23: 0 | W23: 0 | X23: 0 | Y23: 0 | Z23: 0 | AA23: 0 | AB23: 1 | AC23: 0 | AD23: 1 | AE23: 0 | AF23: 0 | AG23: 0 | AH23: 1 | AI23: 0 | AJ23: 0 | AK23: 0 | AL23: 0 | AM23: =SUM(E23:AL23) -> 10
D24: JML | E24: =SUM(E22:E23) -> 1 | F24: =SUM(F22:F23) -> 0 | G24: =SUM(G22:G23) -> 3 | H24: =SUM(H22:H23) -> 1 | I24: =SUM(I22:I23) -> 1 | J24: =SUM(J22:J23) -> 0 | K24: =SUM(K22:K23) -> 0 | L24: =SUM(L22:L23) -> 0 | ... AL24: =SUM(AL22:AL23) -> 0 | AM24: =SUM(E24:AL24) -> 21
B25: 3. | C25: Jumlah pengguna hak pilih dalam Daftar Pemilih Khusus (DPK) | D25: LK | E25: 0 | F25: 1 | G25: 0 | H25: 0 | I25: 0 | J25: 0 | K25: 0 | L25: 4 | M25: 3 | N25: 0 | O25: 0 | P25: 0 | Q25: 0 | R25: 0 | S25: 1 | T25: 0 | U25: 1 | V25: 2 | W25: 0 | X25: 0 | Y25: 1 | Z25: 0 | AA25: 0 | AB25: 0 | AC25: 0 | AD25: 0 | AE25: 0 | AF25: 0 | AG25: 1 | AH25: 0 | AI25: 0 | AJ25: 0 | AK25: 0 | AL25: 0 | AM25: =SUM(E25:AL25) -> 14
D26: PR | E26: 0 | F26: 3 | G26: 0 | H26: 0 | I26: 0 | J26: 0 | K26: 0 | L26: 4 | M26: 2 | N26: 0 | O26: 0 | P26: 0 | Q26: 0 | R26: 0 | S26: 4 | T26: 0 | U26: 5 | V26: 4 | W26: 0 | X26: 0 | Y26: 1 | Z26: 0 | AA26: 0 | AB26: 0 | AC26: 0 | AD26: 0 | AE26: 0 | AF26: 0 | AG26: 2 | AH26: 0 | AI26: 0 | AJ26: 0 | AK26: 0 | AL26: 1 | AM26: =SUM(E26:AL26) -> 26
D27: JML | E27: =SUM(E25:E26) -> 0 | F27: =SUM(F25:F26) -> 4 | G27: =SUM(G25:G26) -> 0 | H27: =SUM(H25:H26) -> 0 | I27: =SUM(I25:I26) -> 0 | J27: =SUM(J25:J26) -> 0 | K27: =SUM(K25:K26) -> 0 | L27: =SUM(L25:L26) -> 8 | ... AL27: =SUM(AL25:AL26) -> 1 | AM27: =SUM(E27:AL27) -> 40
B28: 4. | C28: Jumlah Pengguna Hak Pilih (B.1+B.2+B.3) | D28: LK | E28: =SUM(E19,E22,E25) -> 107 | F28: =SUM(F19,F22,F25) -> 101 | G28: =SUM(G19,G22,G25) -> 100 | H28: =SUM(H19,H22,H25) -> 119 | I28: =SUM(I19,I22,I25) -> 108 | J28: =SUM(J19,J22,J25) -> 112 | K28: =SUM(K19,K22,K25) -> 112 | L28: =SUM(L19,L22,L25) -> 121 | ... AL28: =SUM(AL19,AL22,AL25) -> 94 | AM28: =SUM(E28:AL28) -> 3416
D29: PR | E29: =SUM(E20,E23,E26) -> 118 | F29: =SUM(F20,F23,F26) -> 115 | G29: =SUM(G20,G23,G26) -> 112 | H29: =SUM(H20,H23,H26) -> 109 | I29: =SUM(I20,I23,I26) -> 124 | J29: =SUM(J20,J23,J26) -> 113 | K29: =SUM(K20,K23,K26) -> 108 | L29: =SUM(L20,L23,L26) -> 128 | ... AL29: =SUM(AL20,AL23,AL26) -> 106 | AM29: =SUM(E29:AL29) -> 3565
D30: JML | E30: =SUM(E28:E29) -> 225 | F30: =SUM(F28:F29) -> 216 | G30: =SUM(G28:G29) -> 212 | H30: =SUM(H28:H29) -> 228 | I30: =SUM(I28:I29) -> 232 | J30: =SUM(J28:J29) -> 225 | K30: =SUM(K28:K29) -> 220 | L30: =SUM(L28:L29) -> 249 | ... AL30: =SUM(AL28:AL29) -> 200 | AM30: =SUM(E30:AL30) -> 6981
A32: II | B32: DATA PENGGUNAAN SURAT SUARA
A33: 1 | B33: Jumlah surat suara yang diterima, termasuk surat suara cadangan 2,5% dari DPT | E33: 289 | F33: 299 | G33: 293 | H33: 300 | I33: 286 | J33: 283 | K33: 240 | L33: 297 | M33: 298 | N33: 189 | O33: 225 | P33: 266 | Q33: 257 | R33: 262 | S33: 261 | T33: 257 | U33: 257 | V33: 262 | W33: 257 | X33: 270 | Y33: 260 | Z33: 254 | AA33: 247 | AB33: 270 | AC33: 266 | AD33: 271 | AE33: 257 | AF33: 266 | AG33: 247 | AH33: 253 | AI33: 265 | AJ33: 265 | AK33: 247 | AL33: 251 | AM33: =SUM(E33:AL33) -> 8967
A34: 2 | B34: Jumlah surat suara yang digunakan | E34: 225 | F34: 216 | G34: 212 | H34: 228 | I34: 232 | J34: 225 | K34: 220 | L34: 249 | M34: 222 | N34: 142 | O34: 136 | P34: 205 | Q34: 206 | R34: 213 | S34: 197 | T34: 210 | U34: 193 | V34: 221 | W34: 176 | X34: 222 | Y34: 207 | Z34: 191 | AA34: 191 | AB34: 216 | AC34: 211 | AD34: 204 | AE34: 203 | AF34: 211 | AG34: 197 | AH34: 206 | AI34: 195 | AJ34: 208 | AK34: 191 | AL34: 200 | AM34: =SUM(E34:AL34) -> 6981
A35: 3 | B35: Jumlah surat suara dikembalikan oleh pemilih (karena rusak atau keliru coblos) | E35: 0 | F35: 0 | G35: 1 | H35: 0 | I35: 0 | J35: 0 | K35: 0 | L35: 0 | M35: 0 | N35: 0 | O35: 0 | P35: 0 | Q35: 0 | R35: 0 | S35: 0 | T35: 0 | U35: 0 | V35: 0 | W35: 0 | X35: 0 | Y35: 1 | Z35: 0 | AA35: 0 | AB35: 0 | AC35: 0 | AD35: 0 | AE35: 0 | AF35: 0 | AG35: 3 | AH35: 0 | AI35: 0 | AJ35: 0 | AK35: 0 | AL35: 0 | AM35: =SUM(E35:AL35) -> 5
A36: 4 | B36: Jumlah surat suara yang tidak digunakan/tidak terpakai, termasuk sisa surat suara cadangan | E36: =E33-(E34+E35) -> 64 | F36: =F33-(F34+F35) -> 83 | G36: =G33-(G34+G35) -> 80 | H36: =H33-(H34+H35) -> 72 | I36: =I33-(I34+I35) -> 54 | J36: =J33-(J34+J35) -> 58 | K36: =K33-(K34+K35) -> 20 | L36: =L33-(L34+L35) -> 48 | ... AL36: =AL33-(AL34+AL35) -> 51 | AM36: =SUM(E36:AL36) -> 1981
A38: III | B38: DATA PEMILIH DISABILITAS
B39: Jumlah seluruh Pemilih disabilitas yang menggunakan hak pilih | D39: LK | E39: 0 | F39: 0 | G39: 0 | H39: 0 | I39: 0 | J39: 0 | K39: 0 | L39: 0 | M39: 0 | N39: 0 | O39: 0 | P39: 0 | Q39: 0 | R39: 0 | S39: 0 | T39: 0 | U39: 0 | V39: 0 | W39: 0 | X39: 0 | Y39: 0 | Z39: 0 | AA39: 0 | AB39: 0 | AC39: 0 | AD39: 0 | AE39: 0 | AF39: 0 | AG39: 0 | AH39: 0 | AI39: 0 | AJ39: 0 | AK39: 0 | AL39: 0 | AM39: =SUM(E39:AL39) -> 0
D40: PR | E40: 0 | F40: 0 | G40: 0 | H40: 0 | I40: 0 | J40: 0 | K40: 0 | L40: 0 | M40: 0 | N40: 0 | O40: 0 | P40: 0 | Q40: 0 | R40: 0 | S40: 0 | T40: 0 | U40: 0 | V40: 0 | W40: 0 | X40: 0 | Y40: 0 | Z40: 0 | AA40: 0 | AB40: 0 | AC40: 0 | AD40: 0 | AE40: 0 | AF40: 0 | AG40: 0 | AH40: 0 | AI40: 0 | AJ40: 0 | AK40: 0 | AL40: 0 | AM40: =SUM(E40:AL40) -> 0
D41: JML | E41: =SUM(E39:E40) -> 0 | F41: =SUM(F39:F40) -> 0 | G41: =SUM(G39:G40) -> 0 | H41: =SUM(H39:H40) -> 0 | I41: =SUM(I39:I40) -> 0 | J41: =SUM(J39:J40) -> 0 | K41: =SUM(K39:K40) -> 0 | L41: =SUM(L39:L40) -> 0 | ... AL41: =SUM(AL39:AL40) -> 0 | AM41: =SUM(E41:AL41) -> 0
A43: IV | B43: DATA RINCIAN PEROLEHAN SUARA PASANGAN CALON BUPATI DAN WAKIL BUPATI
A44: NOMOR DAN NAMA CALON
B45: 1 | C45: H. ANIES RASYID BASWEDAN, Ph.D. - Dr. (H.C.) H. A. MUHAIMIN ISKANDAR | E45: 8 | F45: 18 | G45: 6 | H45: 9 | I45: 22 | J45: 14 | K45: 16 | L45: 19 | M45: 6 | N45: 5 | O45: 4 | P45: 8 | Q45: 10 | R45: 18 | S45: 2 | T45: 4 | U45: 4 | V45: 11 | W45: 15 | X45: 22 | Y45: 19 | Z45: 34 | AA45: 15 | AB45: 25 | AC45: 14 | AD45: 28 | AE45: 14 | AF45: 22 | AG45: 23 | AH45: 22 | AI45: 16 | AJ45: 23 | AK45: 23 | AL45: 17 | AM45: =SUM(E45:AL45) -> 516
B46: 2 | C46: H. PRABOWO SUBIANTO - GIBRAN RAKABUMING RAKA | E46: 170 | F46: 160 | G46: 167 | H46: 169 | I46: 165 | J46: 165 | K46: 177 | L46: 177 | M46: 172 | N46: 104 | O46: 98 | P46: 149 | Q46: 153 | R46: 161 | S46: 149 | T46: 131 | U46: 144 | V46: 158 | W46: 124 | X46: 162 | Y46: 158 | Z46: 118 | AA46: 136 | AB46: 139 | AC46: 156 | AD46: 153 | AE46: 146 | AF46: 154 | AG46: 133 | AH46: 165 | AI46: 117 | AJ46: 145 | AK46: 126 | AL46: 142 | AM46: =SUM(E46:AL46) -> 5043
B47: 3 | C47: H. GANJAR PRANOWO, S.H., M.I.P. - Prof. Dr. H. M. MAHFUD MD | E47: 47 | F47: 33 | G47: 36 | H47: 49 | I47: 43 | J47: 41 | K47: 25 | L47: 48 | M47: 42 | N47: 32 | O47: 34 | P47: 45 | Q47: 42 | R47: 32 | S47: 44 | T47: 74 | U47: 45 | V47: 46 | W47: 34 | X47: 37 | Y47: 24 | Z47: 35 | AA47: 37 | AB47: 51 | AC47: 40 | AD47: 21 | AE47: 42 | AF47: 34 | AG47: 38 | AH47: 18 | AI47: 59 | AJ47: 37 | AK47: 39 | AL47: 38 | AM47: =SUM(E47:AL47) -> 1342
A49: V | B49: DATA SUARA SAH DAN TIDAK SAH
B50: A. | C50: JUMLAH SELURUH SUARA SAH | E50: =SUM(E45:E47) -> 225 | F50: =SUM(F45:F47) -> 211 | G50: =SUM(G45:G47) -> 209 | H50: =SUM(H45:H47) -> 227 | I50: =SUM(I45:I47) -> 230 | J50: =SUM(J45:J47) -> 220 | K50: =SUM(K45:K47) -> 218 | L50: =SUM(L45:L47) -> 244 | ... AL50: =SUM(AL45:AL47) -> 197 | AM50: =SUM(E50:AL50) -> 6901
B51: B. | C51: JUMLAH SUARA TIDAK SAH | E51: 0 | F51: 5 | G51: 3 | H51: 1 | I51: 2 | J51: 5 | K51: 2 | L51: 5 | M51: 2 | N51: 1 | O51: 0 | P51: 3 | Q51: 1 | R51: 2 | S51: 2 | T51: 1 | U51: 0 | V51: 6 | W51: 3 | X51: 1 | Y51: 6 | Z51: 4 | AA51: 3 | AB51: 1 | AC51: 1 | AD51: 2 | AE51: 1 | AF51: 1 | AG51: 3 | AH51: 1 | AI51: 3 | AJ51: 3 | AK51: 3 | AL51: 3 | AM51: =SUM(E51:AL51) -> 80
B52: C. | C52: JUMLAH SELURUH SUARA SAH DAN SUARA TIDAK SAH (V.A + V.B) | E52: =SUM(E50:E51) -> 225 | F52: =SUM(F50:F51) -> 216 | G52: =SUM(G50:G51) -> 212 | H52: =SUM(H50:H51) -> 228 | I52: =SUM(I50:I51) -> 232 | J52: =SUM(J50:J51) -> 225 | K52: =SUM(K50:K51) -> 220 | L52: =SUM(L50:L51) -> 249 | ... AL52: =SUM(AL50:AL51) -> 200 | AM52: =SUM(E52:AL52) -> 6981

Sheet KEDUNGWUNGU
C2: Kecamatan | D2: TEGALDLIMO
C3: Kabupaten | D3: BANYUWANGI
C4: Provinsi | D4: JAWA TIMUR
C9: Kelurahan | D9: KEDUNGWUNGU
A12: I | B12: DATA PEMILIH DAN PENGGUNAAN HAK PILIH | AF12: JUMLAH AKHIR
A13: A | B13: DATA PEMILIH | E13: TPS 001 | F13: TPS 002 | G13: TPS 003 | H13: TPS 004 | I13: TPS 005 | J13: TPS 006 | K13: TPS 007 | L13: TPS 008 | M13: TPS 009 | N13: TPS 010 | O13: TPS 011 | P13: TPS 012 | Q13: TPS 013 | R13: TPS 014 | S13: TPS 015 | T13: TPS 016 | U13: TPS 017 | V13: TPS 018 | W13: TPS 019 | X13: TPS 020 | Y13: TPS 021 | Z13: TPS 022 | AA13: TPS 023 | AB13: TPS 024 | AC13: TPS 025 | AD13: TPS 026 | AE13: TPS 027
B14: Jumlah Pemilih dalam Daftar Pemilih Tetap (DPT) | D14: LK | E14: 121 | F14: 121 | G14: 146 | H14: 129 | I14: 120 | J14: 134 | K14: 117 | L14: 139 | M14: 91 | N14: 126 | O14: 144 | P14: 132 | Q14: 104 | R14: 147 | S14: 143 | T14: 146 | U14: 136 | V14: 141 | W14: 118 | X14: 145 | Y14: 139 | Z14: 141 | AA14: 140 | AB14: 154 | AC14: 149 | AD14: 104 | AE14: 104 | AF14: =SUM(E14:AE14) -> 3531
D15: PR | E15: 121 | F15: 125 | G15: 131 | H15: 131 | I15: 128 | J15: 123 | K15: 130 | L15: 139 | M15: 97 | N15: 125 | O15: 137 | P15: 135 | Q15: 113 | R15: 119 | S15: 138 | T15: 141 | U15: 145 | V15: 144 | W15: 104 | X15: 133 | Y15: 143 | Z15: 145 | AA15: 140 | AB15: 139 | AC15: 144 | AD15: 104 | AE15: 119 | AF15: =SUM(E15:AE15) -> 3493
D16: JML | E16: =SUM(E14:E15) -> 242 | F16: =SUM(F14:F15) -> 246 | G16: =SUM(G14:G15) -> 277 | H16: =SUM(H14:H15) -> 260 | I16: =SUM(I14:I15) -> 248 | J16: =SUM(J14:J15) -> 257 | K16: =SUM(K14:K15) -> 247 | L16: =SUM(L14:L15) -> 278 | ... AE16: =SUM(AE14:AE15) -> 223 | AF16: =SUM(E16:AE16) -> 7024
A18: B | B18: PENGGUNA HAK PILIH
B19: 1. | C19: Jumlah pengguna hak pilih dalam Daftar Pemilih Tetap (DPT) | D19: LK | E19: 83 | F19: 95 | G19: 107 | H19: 104 | I19: 95 | J19: 106 | K19: 100 | L19: 98 | M19: 78 | N19: 103 | O19: 102 | P19: 102 | Q19: 92 | R19: 128 | S19: 113 | T19: 108 | U19: 119 | V19: 104 | W19: 77 | X19: 106 | Y19: 102 | Z19: 107 | AA19: 106 | AB19: 123 | AC19: 115 | AD19: 69 | AE19: 79 | AF19: =SUM(E19:AE19) -> 2721
D20: PR | E20: 93 | F20: 97 | G20: 108 | H20: 113 | I20: 96 | J20: 99 | K20: 113 | L20: 108 | M20: 80 | N20: 97 | O20: 122 | P20: 111 | Q20: 99 | R20: 104 | S20: 112 | T20: 105 | U20: 124 | V20: 114 | W20: 73 | X20: 99 | Y20: 110 | Z20: 118 | AA20: 110 | AB20: 106 | AC20: 103 | AD20: 68 | AE20: 94 | AF20: =SUM(E20:AE20) -> 2776
D21: JML | E21: =SUM(E19:E20) -> 176 | F21: =SUM(F19:F20) -> 192 | G21: =SUM(G19:G20) -> 215 | H21: =SUM(H19:H20) -> 217 | I21: =SUM(I19:I20) -> 191 | J21: =SUM(J19:J20) -> 205 | K21: =SUM(K19:K20) -> 213 | L21: =SUM(L19:L20) -> 206 | ... AE21: =SUM(AE19:AE20) -> 173 | AF21: =SUM(E21:AE21) -> 5497
B22: 2. | C22: Jumlah pengguna hak pilih dalam Daftar Pemilih Tambahan (DPTb) | D22: LK | E22: 0 | F22: 1 | G22: 0 | H22: 0 | I22: 0 | J22: 0 | K22: 0 | L22: 0 | M22: 0 | N22: 0 | O22: 0 | P22: 0 | Q22: 0 | R22: 0 | S22: 0 | T22: 0 | U22: 0 | V22: 0 | W22: 0 | X22: 0 | Y22: 0 | Z22: 9 | AA22: 10 | AB22: 4 | AC22: 0 | AD22: 0 | AE22: 0 | AF22: =SUM(E22:AE22) -> 24
D23: PR | E23: 0 | F23: 0 | G23: 0 | H23: 0 | I23: 0 | J23: 0 | K23: 0 | L23: 0 | M23: 0 | N23: 0 | O23: 0 | P23: 0 | Q23: 0 | R23: 0 | S23: 0 | T23: 0 | U23: 0 | V23: 0 | W23: 0 | X23: 0 | Y23: 0 | Z23: 1 | AA23: 0 | AB23: 2 | AC23: 0 | AD23: 0 | AE23: 0 | AF23: =SUM(E23:AE23) -> 3
D24: JML | E24: =SUM(E22:E23) -> 0 | F24: =SUM(F22:F23) -> 1 | G24: =SUM(G22:G23) -> 0 | H24: =SUM(H22:H23) -> 0 | I24: =SUM(I22:I23) -> 0 | J24: =SUM(J22:J23) -> 0 | K24: =SUM(K22:K23) -> 0 | L24: =SUM(L22:L23) -> 0 | ... AE24: =SUM(AE22:AE23) -> 0 | AF24: =SUM(E24:AE24) -> 27
B25: 3. | C25: Jumlah pengguna hak pilih dalam Daftar Pemilih Khusus (DPK) | D25: LK | E25: 0 | F25: 0 | G25: 0 | H25: 0 | I25: 0 | J25: 0 | K25: 0 | L25: 0 | M25: 0 | N25: 0 | O25: 0 | P25: 0 | Q25: 0 | R25: 0 | S25: 0 | T25: 0 | U25: 0 | V25: 0 | W25: 0 | X25: 0 | Y25: 0 | Z25: 0 | AA25: 0 | AB25: 0 | AC25: 0 | AD25: 0 | AE25: 0 | AF25: =SUM(E25:AE25) -> 0
D26: PR | E26: 0 | F26: 0 | G26: 0 | H26: 0 | I26: 0 | J26: 0 | K26: 0 | L26: 0 | M26: 0 | N26: 0 | O26: 0 | P26: 3 | Q26: 0 | R26: 0 | S26: 0 | T26: 0 | U26: 0 | V26: 0 | W26: 0 | X26: 0 | Y26: 0 | Z26: 0 | AA26: 0 | AB26: 0 | AC26: 0 | AD26: 0 | AE26: 0 | AF26: =SUM(E26:AE26) -> 3
D27: JML | E27: =SUM(E25:E26) -> 0 | F27: =SUM(F25:F26) -> 0 | G27: =SUM(G25:G26) -> 0 | H27: =SUM(H25:H26) -> 0 | I27: =SUM(I25:I26) -> 0 | J27: =SUM(J25:J26) -> 0 | K27: =SUM(K25:K26) -> 0 | L27: =SUM(L25:L26) -> 0 | ... AE27: =SUM(AE25:AE26) -> 0 | AF27: =SUM(E27:AE27) -> 3
B28: 4. | C28: Jumlah Pengguna Hak Pilih (B.1+B.2+B.3) | D28: LK | E28: =SUM(E19,E22,E25) -> 83 | F28: =SUM(F19,F22,F25) -> 96 | G28: =SUM(G19,G22,G25) -> 107 | H28: =SUM(H19,H22,H25) -> 104 | I28: =SUM(I19,I22,I25) -> 95 | J28: =SUM(J19,J22,J25) -> 106 | K28: =SUM(K19,K22,K25) -> 100 | L28: =SUM(L19,L22,L25) -> 98 | ... AE28: =SUM(AE19,AE22,AE25) -> 79 | AF28: =SUM(E28:AE28) -> 2745
D29: PR | E29: =SUM(E20,E23,E26) -> 93 | F29: =SUM(F20,F23,F26) -> 97 | G29: =SUM(G20,G23,G26) -> 108 | H29: =SUM(H20,H23,H26) -> 113 | I29: =SUM(I20,I23,I26) -> 96 | J29: =SUM(J20,J23,J26) -> 99 | K29: =SUM(K20,K23,K26) -> 113 | L29: =SUM(L20,L23,L26) -> 108 | ... AE29: =SUM(AE20,AE23,AE26) -> 94 | AF29: =SUM(E29:AE29) -> 2782
D30: JML | E30: =SUM(E28:E29) -> 176 | F30: =SUM(F28:F29) -> 193 | G30: =SUM(G28:G29) -> 215 | H30: =SUM(H28:H29) -> 217 | I30: =SUM(I28:I29) -> 191 | J30: =SUM(J28:J29) -> 205 | K30: =SUM(K28:K29) -> 213 | L30: =SUM(L28:L29) -> 206 | ... AE30: =SUM(AE28:AE29) -> 173 | AF30: =SUM(E30:AE30) -> 5527
A32: II | B32: DATA PENGGUNAAN SURAT SUARA
A33: 1 | B33: Jumlah surat suara yang diterima, termasuk surat suara cadangan 2,5% dari DPT | E33: 247 | F33: 251 | G33: 283 | H33: 266 | I33: 256 | J33: 263 | K33: 253 | L33: 284 | M33: 192 | N33: 256 | O33: 287 | P33: 277 | Q33: 222 | R33: 272 | S33: 287 | T33: 293 | U33: 287 | V33: 295 | W33: 227 | X33: 284 | Y33: 288 | Z33: 292 | AA33: 286 | AB33: 299 | AC33: 299 | AD33: 213 | AE33: 228 | AF33: =SUM(E33:AE33) -> 7187
A34: 2 | B34: Jumlah surat suara yang digunakan | E34: 176 | F34: 193 | G34: 215 | H34: 217 | I34: 191 | J34: 205 | K34: 213 | L34: 206 | M34: 158 | N34: 200 | O34: 224 | P34: 216 | Q34: 191 | R34: 232 | S34: 225 | T34: 213 | U34: 243 | V34: 218 | W34: 150 | X34: 205 | Y34: 212 | Z34: 235 | AA34: 226 | AB34: 235 | AC34: 218 | AD34: 137 | AE34: 173 | AF34: =SUM(E34:AE34) -> 5527
A35: 3 | B35: Jumlah surat suara dikembalikan oleh pemilih (karena rusak atau keliru coblos) | E35: 0 | F35: 0 | G35: 0 | H35: 0 | I35: 0 | J35: 1 | K35: 3 | L35: 0 | M35: 0 | N35: 5 | O35: 0 | P35: 0 | Q35: 0 | R35: 1 | S35: 0 | T35: 2 | U35: 0 | V35: 0 | W35: 0 | X35: 0 | Y35: 0 | Z35: 0 | AA35: 0 | AB35: 1 | AC35: 0 | AD35: 0 | AE35: 0 | AF35: =SUM(E35:AE35) -> 13
A36: 4 | B36: Jumlah surat suara yang tidak digunakan/tidak terpakai, termasuk sisa surat suara cadangan | E36: =E33-(E34+E35) -> 71 | F36: =F33-(F34+F35) -> 58 | G36: =G33-(G34+G35) -> 68 | H36: =H33-(H34+H35) -> 49 | I36: =I33-(I34+I35) -> 65 | J36: =J33-(J34+J35) -> 57 | K36: =K33-(K34+K35) -> 37 | L36: =L33-(L34+L35) -> 78 | ... AE36: =AE33-(AE34+AE35) -> 55 | AF36: =SUM(E36:AE36) -> 1647
A38: III | B38: DATA PEMILIH DISABILITAS
B39: Jumlah seluruh Pemilih disabilitas yang menggunakan hak pilih | D39: LK | E39: 0 | F39: 0 | G39: 0 | H39: 0 | I39: 0 | J39: 0 | K39: 0 | L39: 0 | M39: 0 | N39: 0 | O39: 2 | P39: 0 | Q39: 0 | R39: 0 | S39: 0 | T39: 0 | U39: 0 | V39: 0 | W39: 0 | X39: 0 | Y39: 0 | Z39: 0 | AA39: 0 | AB39: 0 | AC39: 0 | AD39: 0 | AE39: 0 | AF39: =SUM(E39:AE39) -> 2
D40: PR | E40: 0 | F40: 0 | G40: 0 | H40: 0 | I40: 0 | J40: 0 | K40: 0 | L40: 0 | M40: 0 | N40: 0 | O40: 0 | P40: 0 | Q40: 0 | R40: 0 | S40: 0 | T40: 0 | U40: 0 | V40: 0 | W40: 2 | X40: 0 | Y40: 0 | Z40: 0 | AA40: 0 | AB40: 0 | AC40: 0 | AD40: 0 | AE40: 0 | AF40: =SUM(E40:AE40) -> 2
D41: JML | E41: =SUM(E39:E40) -> 0 | F41: =SUM(F39:F40) -> 0 | G41: =SUM(G39:G40) -> 0 | H41: =SUM(H39:H40) -> 0 | I41: =SUM(I39:I40) -> 0 | J41: =SUM(J39:J40) -> 0 | K41: =SUM(K39:K40) -> 0 | L41: =SUM(L39:L40) -> 0 | ... AE41: =SUM(AE39:AE40) -> 0 | AF41: =SUM(E41:AE41) -> 4
A43: IV | B43: DATA RINCIAN PEROLEHAN SUARA PASANGAN CALON BUPATI DAN WAKIL BUPATI
A44: NOMOR DAN NAMA CALON
B45: 1 | C45: H. ANIES RASYID BASWEDAN, Ph.D. - Dr. (H.C.) H. A. MUHAIMIN ISKANDAR | E45: 7 | F45: 10 | G45: 15 | H45: 11 | I45: 9 | J45: 11 | K45: 27 | L45: 18 | M45: 22 | N45: 12 | O45: 20 | P45: 17 | Q45: 11 | R45: 18 | S45: 10 | T45: 17 | U45: 6 | V45: 28 | W45: 9 | X45: 22 | Y45: 7 | Z45: 21 | AA45: 26 | AB45: 19 | AC45: 33 | AD45: 6 | AE45: 11 | AF45: =SUM(E45:AE45) -> 423
B46: 2 | C46: H. PRABOWO SUBIANTO - GIBRAN RAKABUMING RAKA | E46: 114 | F46: 147 | G46: 167 | H46: 163 | I46: 156 | J46: 164 | K46: 147 | L46: 162 | M46: 119 | N46: 155 | O46: 162 | P46: 169 | Q46: 166 | R46: 183 | S46: 184 | T46: 164 | U46: 192 | V46: 149 | W46: 108 | X46: 147 | Y46: 162 | Z46: 174 | AA46: 183 | AB46: 187 | AC46: 140 | AD46: 111 | AE46: 132 | AF46: =SUM(E46:AE46) -> 4207
B47: 3 | C47: H. GANJAR PRANOWO, S.H., M.I.P. - Prof. Dr. H. M. MAHFUD MD | E47: 55 | F47: 36 | G47: 28 | H47: 40 | I47: 23 | J47: 29 | K47: 36 | L47: 20 | M47: 17 | N47: 28 | O47: 37 | P47: 28 | Q47: 13 | R47: 27 | S47: 29 | T47: 26 | U47: 38 | V47: 41 | W47: 32 | X47: 32 | Y47: 40 | Z47: 37 | AA47: 16 | AB47: 29 | AC47: 43 | AD47: 18 | AE47: 26 | AF47: =SUM(E47:AE47) -> 824
A49: V | B49: DATA SUARA SAH DAN TIDAK SAH
B50: A. | C50: JUMLAH SELURUH SUARA SAH | E50: =SUM(E45:E47) -> 176 | F50: =SUM(F45:F47) -> 193 | G50: =SUM(G45:G47) -> 210 | H50: =SUM(H45:H47) -> 214 | I50: =SUM(I45:I47) -> 188 | J50: =SUM(J45:J47) -> 204 | K50: =SUM(K45:K47) -> 210 | L50: =SUM(L45:L47) -> 200 | ... AE50: =SUM(AE45:AE47) -> 169 | AF50: =SUM(E50:AE50) -> 5454
B51: B. | C51: JUMLAH SUARA TIDAK SAH | E51: 0 | F51: 0 | G51: 5 | H51: 3 | I51: 3 | J51: 1 | K51: 3 | L51: 6 | M51: 0 | N51: 5 | O51: 5 | P51: 2 | Q51: 1 | R51: 4 | S51: 2 | T51: 6 | U51: 7 | V51: 0 | W51: 1 | X51: 4 | Y51: 3 | Z51: 3 | AA51: 1 | AB51: 0 | AC51: 2 | AD51: 2 | AE51: 4 | AF51: =SUM(E51:AE51) -> 73
B52: C. | C52: JUMLAH SELURUH SUARA SAH DAN SUARA TIDAK SAH (V.A + V.B) | E52: =SUM(E50:E51) -> 176 | F52: =SUM(F50:F51) -> 193 | G52: =SUM(G50:G51) -> 215 | H52: =SUM(H50:H51) -> 217 | I52: =SUM(I50:I51) -> 191 | J52: =SUM(J50:J51) -> 205 | K52: =SUM(K50:K51) -> 213 | L52: =SUM(L50:L51) -> 206 | ... AE52: =SUM(AE50:AE51) -> 173 | AF52: =SUM(E52:AE52) -> 5527

Sheet KENDALREJO
C2: Kecamatan | D2: TEGALDLIMO
C3: Kabupaten | D3: BANYUWANGI
C4: Provinsi | D4: JAWA TIMUR
C9: Kelurahan | D9: KENDALREJO
A12: I | B12: DATA PEMILIH DAN PENGGUNAAN HAK PILIH | V12: JUMLAH AKHIR
A13: A | B13: DATA PEMILIH | E13: TPS 001 | F13: TPS 002 | G13: TPS 003 | H13: TPS 004 | I13: TPS 005 | J13: TPS 006 | K13: TPS 007 | L13: TPS 008 | M13: TPS 009 | N13: TPS 010 | O13: TPS 011 | P13: TPS 012 | Q13: TPS 013 | R13: TPS 014 | S13: TPS 015 | T13: TPS 016 | U13: TPS 017
B14: Jumlah Pemilih dalam Daftar Pemilih Tetap (DPT) | D14: LK | E14: 108 | F14: 112 | G14: 113 | H14: 115 | I14: 136 | J14: 130 | K14: 128 | L14: 134 | M14: 130 | N14: 131 | O14: 136 | P14: 79 | Q14: 123 | R14: 111 | S14: 100 | T14: 114 | U14: 98 | V14: =SUM(E14:U14) -> 1998
D15: PR | E15: 113 | F15: 106 | G15: 112 | H15: 115 | I15: 120 | J15: 133 | K15: 127 | L15: 130 | M15: 127 | N15: 126 | O15: 122 | P15: 92 | Q15: 121 | R15: 107 | S15: 96 | T15: 105 | U15: 92 | V15: =SUM(E15:U15) -> 1944
D16: JML | E16: =SUM(E14:E15) -> 221 | F16: =SUM(F14:F15) -> 218 | G16: =SUM(G14:G15) -> 225 | H16: =SUM(H14:H15) -> 230 | I16: =SUM(I14:I15) -> 256 | J16: =SUM(J14:J15) -> 263 | K16: =SUM(K14:K15) -> 255 | L16: =SUM(L14:L15) -> 264 | ... U16: =SUM(U14:U15) -> 190 | V16: =SUM(E16:U16) -> 3942
A18: B | B18: PENGGUNA HAK PILIH
B19: 1. | C19: Jumlah pengguna hak pilih dalam Daftar Pemilih Tetap (DPT) | D19: LK | E19: 92 | F19: 95 | G19: 88 | H19: 91 | I19: 111 | J19: 115 | K19: 109 | L19: 118 | M19: 99 | N19: 92 | O19: 93 | P19: 67 | Q19: 102 | R19: 85 | S19: 76 | T19: 94 | U19: 82 | V19: =SUM(E19:U19) -> 1609
D20: PR | E20: 83 | F20: 86 | G20: 94 | H20: 97 | I20: 104 | J20: 107 | K20: 107 | L20: 117 | M20: 98 | N20: 94 | O20: 97 | P20: 77 | Q20: 103 | R20: 87 | S20: 76 | T20: 86 | U20: 77 | V20: =SUM(E20:U20) -> 1590
D21: JML | E21: =SUM(E19:E20) -> 175 | F21: =SUM(F19:F20) -> 181 | G21: =SUM(G19:G20) -> 182 | H21: =SUM(H19:H20) -> 188 | I21: =SUM(I19:I20) -> 215 | J21: =SUM(J19:J20) -> 222 | K21: =SUM(K19:K20) -> 216 | L21: =SUM(L19:L20) -> 235 | ... U21: =SUM(U19:U20) -> 159 | V21: =SUM(E21:U21) -> 3199
B22: 2. | C22: Jumlah pengguna hak pilih dalam Daftar Pemilih Tambahan (DPTb) | D22: LK | E22: 0 | F22: 0 | G22: 0 | H22: 1 | I22: 0 | J22: 0 | K22: 0 | L22: 0 | M22: 2 | N22: 0 | O22: 1 | P22: 0 | Q22: 1 | R22: 0 | S22: 0 | T22: 0 | U22: 0 | V22: =SUM(E22:U22) -> 5
D23: PR | E23: 0 | F23: 0 | G23: 0 | H23: 0 | I23: 0 | J23: 1 | K23: 1 | L23: 0 | M23: 2 | N23: 1 | O23: 0 | P23: 0 | Q23: 0 | R23: 0 | S23: 0 | T23: 0 | U23: 0 | V23: =SUM(E23:U23) -> 5
D24: JML | E24: =SUM(E22:E23) -> 0 | F24: =SUM(F22:F23) -> 0 | G24: =SUM(G22:G23) -> 0 | H24: =SUM(H22:H23) -> 1 | I24: =SUM(I22:I23) -> 0 | J24: =SUM(J22:J23) -> 1 | K24: =SUM(K22:K23) -> 1 | L24: =SUM(L22:L23) -> 0 | ... U24: =SUM(U22:U23) -> 0 | V24: =SUM(E24:U24) -> 10
B25: 3. | C25: Jumlah pengguna hak pilih dalam Daftar Pemilih Khusus (DPK) | D25: LK | E25: 0 | F25: 0 | G25: 0 | H25: 0 | I25: 0 | J25: 0 | K25: 0 | L25: 0 | M25: 0 | N25: 0 | O25: 0 | P25: 0 | Q25: 1 | R25: 0 | S25: 0 | T25: 0 | U25: 0 | V25: =SUM(E25:U25) -> 1
D26: PR | E26: 0 | F26: 0 | G26: 0 | H26: 0 | I26: 0 | J26: 0 | K26: 0 | L26: 0 | M26: 0 | N26: 0 | O26: 0 | P26: 0 | Q26: 0 | R26: 0 | S26: 0 | T26: 0 | U26: 0 | V26: =SUM(E26:U26) -> 0
D27: JML | E27: =SUM(E25:E26) -> 0 | F27: =SUM(F25:F26) -> 0 | G27: =SUM(G25:G26) -> 0 | H27: =SUM(H25:H26) -> 0 | I27: =SUM(I25:I26) -> 0 | J27: =SUM(J25:J26) -> 0 | K27: =SUM(K25:K26) -> 0 | L27: =SUM(L25:L26) -> 0 | ... U27: =SUM(U25:U26) -> 0 | V27: =SUM(E27:U27) -> 1
B28: 4. | C28: Jumlah Pengguna Hak Pilih (B.1+B.2+B.3) | D28: LK | E28: =SUM(E19,E22,E25) -> 92 | F28: =SUM(F19,F22,F25) -> 95 | G28: =SUM(G19,G22,G25) -> 88 | H28: =SUM(H19,H22,H25) -> 92 | I28: =SUM(I19,I22,I25) -> 111 | J28: =SUM(J19,J22,J25) -> 115 | K28: =SUM(K19,K22,K25) -> 109 | L28: =SUM(L19,L22,L25) -> 118 | ... U28: =SUM(U19,U22,U25) -> 82 | V28: =SUM(E28:U28) -> 1615
D29: PR | E29: =SUM(E20,E23,E26) -> 83 | F29: =SUM(F20,F23,F26) -> 86 | G29: =SUM(G20,G23,G26) -> 94 | H29: =SUM(H20,H23,H26) -> 97 | I29: =SUM(I20,I23,I26) -> 104 | J29: =SUM(J20,J23,J26) -> 108 | K29: =SUM(K20,K23,K26) -> 108 | L29: =SUM(L20,L23,L26) -> 117 | ... U29: =SUM(U20,U23,U26) -> 77 | V29: =SUM(E29:U29) -> 1595
D30: JML | E30: =SUM(E28:E29) -> 175 | F30: =SUM(F28:F29) -> 181 | G30: =SUM(G28:G29) -> 182 | H30: =SUM(H28:H29) -> 189 | I30: =SUM(I28:I29) -> 215 | J30: =SUM(J28:J29) -> 223 | K30: =SUM(K28:K29) -> 217 | L30: =SUM(L28:L29) -> 235 | ... U30: =SUM(U28:U29) -> 159 | V30: =SUM(E30:U30) -> 3210
A32: II | B32: DATA PENGGUNAAN SURAT SUARA
A33: 1 | B33: Jumlah surat suara yang diterima, termasuk surat suara cadangan 2,5% dari DPT | E33: 222 | F33: 223 | G33: 230 | H33: 235 | I33: 262 | J33: 269 | K33: 261 | L33: 270 | M33: 263 | N33: 263 | O33: 264 | P33: 174 | Q33: 248 | R33: 223 | S33: 200 | T33: 222 | U33: 194 | V33: =SUM(E33:U33) -> 4023
A34: 2 | B34: Jumlah surat suara yang digunakan | E34: 175 | F34: 181 | G34: 182 | H34: 189 | I34: 215 | J34: 223 | K34: 217 | L34: 235 | M34: 201 | N34: 187 | O34: 191 | P34: 144 | Q34: 207 | R34: 172 | S34: 152 | T34: 180 | U34: 159 | V34: =SUM(E34:U34) -> 3210
A35: 3 | B35: Jumlah surat suara dikembalikan oleh pemilih (karena rusak atau keliru coblos) | E35: 0 | F35: 1 | G35: 0 | H35: 0 | I35: 0 | J35: 0 | K35: 0 | L35: 0 | M35: 0 | N35: 0 | O35: 0 | P35: 0 | Q35: 0 | R35: 0 | S35: 0 | T35: 0 | U35: 0 | V35: =SUM(E35:U35) -> 1
A36: 4 | B36: Jumlah surat suara yang tidak digunakan/tidak terpakai, termasuk sisa surat suara cadangan | E36: =E33-(E34+E35) -> 47 | F36: =F33-(F34+F35) -> 41 | G36: =G33-(G34+G35) -> 48 | H36: =H33-(H34+H35) -> 46 | I36: =I33-(I34+I35) -> 47 | J36: =J33-(J34+J35) -> 46 | K36: =K33-(K34+K35) -> 44 | L36: =L33-(L34+L35) -> 35 | ... U36: =U33-(U34+U35) -> 35 | V36: =SUM(E36:U36) -> 812
A38: III | B38: DATA PEMILIH DISABILITAS
B39: Jumlah seluruh Pemilih disabilitas yang menggunakan hak pilih | D39: LK | E39: 0 | F39: 0 | G39: 0 | H39: 0 | I39: 0 | J39: 0 | K39: 0 | L39: 0 | M39: 0 | N39: 0 | O39: 0 | P39: 0 | Q39: 0 | R39: 0 | S39: 0 | T39: 0 | U39: 2 | V39: =SUM(E39:U39) -> 2
D40: PR | E40: 0 | F40: 0 | G40: 0 | H40: 0 | I40: 0 | J40: 0 | K40: 0 | L40: 0 | M40: 0 | N40: 0 | O40: 0 | P40: 0 | Q40: 0 | R40: 0 | S40: 0 | T40: 0 | U40: 0 | V40: =SUM(E40:U40) -> 0
D41: JML | E41: =SUM(E39:E40) -> 0 | F41: =SUM(F39:F40) -> 0 | G41: =SUM(G39:G40) -> 0 | H41: =SUM(H39:H40) -> 0 | I41: =SUM(I39:I40) -> 0 | J41: =SUM(J39:J40) -> 0 | K41: =SUM(K39:K40) -> 0 | L41: =SUM(L39:L40) -> 0 | ... U41: =SUM(U39:U40) -> 2 | V41: =SUM(E41:U41) -> 2
A43: IV | B43: DATA RINCIAN PEROLEHAN SUARA PASANGAN CALON BUPATI DAN WAKIL BUPATI
A44: NOMOR DAN NAMA CALON
B45: 1 | C45: H. ANIES RASYID BASWEDAN, Ph.D. - Dr. (H.C.) H. A. MUHAIMIN ISKANDAR | E45: 36 | F45: 27 | G45: 33 | H45: 30 | I45: 29 | J45: 3 | K45: 17 | L45: 16 | M45: 10 | N45: 12 | O45: 10 | P45: 1 | Q45: 43 | R45: 15 | S45: 4 | T45: 8 | U45: 2 | V45: =SUM(E45:U45) -> 296
B46: 2 | C46: H. PRABOWO SUBIANTO - GIBRAN RAKABUMING RAKA | E46: 115 | F46: 127 | G46: 123 | H46: 143 | I46: 156 | J46: 175 | K46: 158 | L46: 177 | M46: 148 | N46: 138 | O46: 153 | P46: 108 | Q46: 113 | R46: 115 | S46: 124 | T46: 106 | U46: 139 | V46: =SUM(E46:U46) -> 2318
B47: 3 | C47: H. GANJAR PRANOWO, S.H., M.I.P. - Prof. Dr. H. M. MAHFUD MD | E47: 23 | F47: 24 | G47: 23 | H47: 16 | I47: 29 | J47: 43 | K47: 40 | L47: 39 | M47: 42 | N47: 35 | O47: 25 | P47: 31 | Q47: 47 | R47: 36 | S47: 22 | T47: 65 | U47: 18 | V47: =SUM(E47:U47) -> 558
A49: V | B49: DATA SUARA SAH DAN TIDAK SAH
B50: A. | C50: JUMLAH SELURUH SUARA SAH | E50: =SUM(E45:E47) -> 174 | F50: =SUM(F45:F47) -> 178 | G50: =SUM(G45:G47) -> 179 | H50: =SUM(H45:H47) -> 189 | I50: =SUM(I45:I47) -> 214 | J50: =SUM(J45:J47) -> 221 | K50: =SUM(K45:K47) -> 215 | L50: =SUM(L45:L47) -> 232 | ... U50: =SUM(U45:U47) -> 159 | V50: =SUM(E50:U50) -> 3172
B51: B. | C51: JUMLAH SUARA TIDAK SAH | E51: 1 | F51: 3 | G51: 3 | H51: 0 | I51: 1 | J51: 2 | K51: 2 | L51: 3 | M51: 1 | N51: 2 | O51: 3 | P51: 4 | Q51: 4 | R51: 6 | S51: 2 | T51: 1 | U51: 0 | V51: =SUM(E51:U51) -> 38
B52: C. | C52: JUMLAH SELURUH SUARA SAH DAN SUARA TIDAK SAH (V.A + V.B) | E52: =SUM(E50:E51) -> 175 | F52: =SUM(F50:F51) -> 181 | G52: =SUM(G50:G51) -> 182 | H52: =SUM(H50:H51) -> 189 | I52: =SUM(I50:I51) -> 215 | J52: =SUM(J50:J51) -> 223 | K52: =SUM(K50:K51) -> 217 | L52: =SUM(L50:L51) -> 235 | ... U52: =SUM(U50:U51) -> 159 | V52: =SUM(E52:U52) -> 3210

Sheet PURWOAGUNG
C2: Kecamatan | D2: TEGALDLIMO
C3: Kabupaten | D3: BANYUWANGI
C4: Provinsi | D4: JAWA TIMUR
C9: Kelurahan | D9: PURWOAGUNG
A12: I | B12: DATA PEMILIH DAN PENGGUNAAN HAK PILIH | S12: JUMLAH AKHIR
A13: A | B13: DATA PEMILIH | E13: TPS 001 | F13: TPS 002 | G13: TPS 003 | H13: TPS 004 | I13: TPS 005 | J13: TPS 006 | K13: TPS 007 | L13: TPS 008 | M13: TPS 009 | N13: TPS 010 | O13: TPS 011 | P13: TPS 012 | Q13: TPS 013 | R13: TPS 014
B14: Jumlah Pemilih dalam Daftar Pemilih Tetap (DPT) | D14: LK | E14: 140 | F14: 97 | G14: 117 | H14: 127 | I14: 131 | J14: 133 | K14: 116 | L14: 108 | M14: 131 | N14: 123 | O14: 118 | P14: 116 | Q14: 128 | R14: 129 | S14: =SUM(E14:R14) -> 1714
D15: PR | E15: 115 | F15: 100 | G15: 116 | H15: 135 | I15: 128 | J15: 135 | K15: 124 | L15: 94 | M15: 140 | N15: 128 | O15: 108 | P15: 111 | Q15: 121 | R15: 111 | S15: =SUM(E15:R15) -> 1666
D16: JML | E16: =SUM(E14:E15) -> 255 | F16: =SUM(F14:F15) -> 197 | G16: =SUM(G14:G15) -> 233 | H16: =SUM(H14:H15) -> 262 | I16: =SUM(I14:I15) -> 259 | J16: =SUM(J14:J15) -> 268 | K16: =SUM(K14:K15) -> 240 | L16: =SUM(L14:L15) -> 202 | ... R16: =SUM(R14:R15) -> 240 | S16: =SUM(E16:R16) -> 3380
A18: B | B18: PENGGUNA HAK PILIH
B19: 1. | C19: Jumlah pengguna hak pilih dalam Daftar Pemilih Tetap (DPT) | D19: LK | E19: 111 | F19: 71 | G19: 89 | H19: 98 | I19: 99 | J19: 110 | K19: 87 | L19: 87 | M19: 100 | N19: 93 | O19: 95 | P19: 101 | Q19: 107 | R19: 112 | S19: =SUM(E19:R19) -> 1360
D20: PR | E20: 89 | F20: 70 | G20: 91 | H20: 112 | I20: 101 | J20: 109 | K20: 99 | L20: 83 | M20: 109 | N20: 101 | O20: 91 | P20: 88 | Q20: 98 | R20: 98 | S20: =SUM(E20:R20) -> 1339
D21: JML | E21: =SUM(E19:E20) -> 200 | F21: =SUM(F19:F20) -> 141 | G21: =SUM(G19:G20) -> 180 | H21: =SUM(H19:H20) -> 210 | I21: =SUM(I19:I20) -> 200 | J21: =SUM(J19:J20) -> 219 | K21: =SUM(K19:K20) -> 186 | L21: =SUM(L19:L20) -> 170 | ... R21: =SUM(R19:R20) -> 210 | S21: =SUM(E21:R21) -> 2699
B22: 2. | C22: Jumlah pengguna hak pilih dalam Daftar Pemilih Tambahan (DPTb) | D22: LK | E22: 0 | F22: 0 | G22: 0 | H22: 0 | I22: 0 | J22: 0 | K22: 0 | L22: 0 | M22: 0 | N22: 0 | O22: 0 | P22: 0 | Q22: 0 | R22: 0 | S22: =SUM(E22:R22) -> 0
D23: PR | E23: 0 | F23: 0 | G23: 0 | H23: 0 | I23: 0 | J23: 0 | K23: 0 | L23: 0 | M23: 0 | N23: 0 | O23: 0 | P23: 0 | Q23: 0 | R23: 0 | S23: =SUM(E23:R23) -> 0
D24: JML | E24: =SUM(E22:E23) -> 0 | F24: =SUM(F22:F23) -> 0 | G24: =SUM(G22:G23) -> 0 | H24: =SUM(H22:H23) -> 0 | I24: =SUM(I22:I23) -> 0 | J24: =SUM(J22:J23) -> 0 | K24: =SUM(K22:K23) -> 0 | L24: =SUM(L22:L23) -> 0 | ... R24: =SUM(R22:R23) -> 0 | S24: =SUM(E24:R24) -> 0
B25: 3. | C25: Jumlah pengguna hak pilih dalam Daftar Pemilih Khusus (DPK) | D25: LK | E25: 0 | F25: 0 | G25: 0 | H25: 0 | I25: 0 | J25: 0 | K25: 0 | L25: 0 | M25: 0 | N25: 0 | O25: 0 | P25: 0 | Q25: 0 | R25: 0 | S25: =SUM(E25:R25) -> 0
D26: PR | E26: 0 | F26: 0 | G26: 0 | H26: 0 | I26: 0 | J26: 0 | K26: 0 | L26: 0 | M26: 0 | N26: 0 | O26: 0 | P26: 0 | Q26: 0 | R26: 0 | S26: =SUM(E26:R26) -> 0
D27: JML | E27: =SUM(E25:E26) -> 0 | F27: =SUM(F25:F26) -> 0 | G27: =SUM(G25:G26) -> 0 | H27: =SUM(H25:H26) -> 0 | I27: =SUM(I25:I26) -> 0 | J27: =SUM(J25:J26) -> 0 | K27: =SUM(K25:K26) -> 0 | L27: =SUM(L25:L26) -> 0 | ... R27: =SUM(R25:R26) -> 0 | S27: =SUM(E27:R27) -> 0
B28: 4. | C28: Jumlah Pengguna Hak Pilih (B.1+B.2+B.3) | D28: LK | E28: =SUM(E19,E22,E25) -> 111 | F28: =SUM(F19,F22,F25) -> 71 | G28: =SUM(G19,G22,G25) -> 89 | H28: =SUM(H19,H22,H25) -> 98 | I28: =SUM(I19,I22,I25) -> 99 | J28: =SUM(J19,J22,J25) -> 110 | K28: =SUM(K19,K22,K25) -> 87 | L28: =SUM(L19,L22,L25) -> 87 | ... R28: =SUM(R19,R22,R25) -> 112 | S28: =SUM(E28:R28) -> 1360
D29: PR | E29: =SUM(E20,E23,E26) -> 89 | F29: =SUM(F20,F23,F26) -> 70 | G29: =SUM(G20,G23,G26) -> 91 | H29: =SUM(H20,H23,H26) -> 112 | I29: =SUM(I20,I23,I26) -> 101 | J29: =SUM(J20,J23,J26) -> 109 | K29: =SUM(K20,K23,K26) -> 99 | L29: =SUM(L20,L23,L26) -> 83 | ... R29: =SUM(R20,R23,R26) -> 98 | S29: =SUM(E29:R29) -> 1339
D30: JML | E30: =SUM(E28:E29) -> 200 | F30: =SUM(F28:F29) -> 141 | G30: =SUM(G28:G29) -> 180 | H30: =SUM(H28:H29) -> 210 | I30: =SUM(I28:I29) -> 200 | J30: =SUM(J28:J29) -> 219 | K30: =SUM(K28:K29) -> 186 | L30: =SUM(L28:L29) -> 170 | ... R30: =SUM(R28:R29) -> 210 | S30: =SUM(E30:R30) -> 2699
A32: II | B32: DATA PENGGUNAAN SURAT SUARA
A33: 1 | B33: Jumlah surat suara yang diterima, termasuk surat suara cadangan 2,5% dari DPT | E33: 261 | F33: 201 | G33: 238 | H33: 268 | I33: 267 | J33: 285 | K33: 247 | L33: 207 | M33: 287 | N33: 256 | O33: 232 | P33: 233 | Q33: 254 | R33: 246 | S33: =SUM(E33:R33) -> 3482
A34: 2 | B34: Jumlah surat suara yang digunakan | E34: 200 | F34: 141 | G34: 180 | H34: 210 | I34: 200 | J34: 219 | K34: 186 | L34: 170 | M34: 209 | N34: 194 | O34: 186 | P34: 189 | Q34: 205 | R34: 210 | S34: =SUM(E34:R34) -> 2699
A35: 3 | B35: Jumlah surat suara dikembalikan oleh pemilih (karena rusak atau keliru coblos) | E35: 0 | F35: 0 | G35: 0 | H35: 0 | I35: 0 | J35: 0 | K35: 0 | L35: 0 | M35: 0 | N35: 1 | O35: 0 | P35: 0 | Q35: 0 | R35: 0 | S35: =SUM(E35:R35) -> 1
