Workbook

Sheet PPWP
C8: Kecamatan
C9: Kabupaten | D9: BANYUWANGI
C10: Provinsi | D10: JAWA TIMUR
A12: I | B12: DATA PEMILIH DAN PENGGUNAAN HAK PILIH | E12: JUMLAH AKHIR
A13: A | B13: DATA PEMILIH
B14: Jumlah Pemilih dalam Daftar Pemilih Tetap (DPT) | D14: LK | E14: =SONGGON!AF14+BALAK!X14+SRAGI!AG14+PARANGHARJO!S14+BEDEWANG!W14+BAYU!AB14+SUMBERARUM!X14+SUMBERBULU!Q14+BANGUNSARI!O14 -> 22660
D15: PR | E15: =SONGGON!AF15+BALAK!X15+SRAGI!AG15+PARANGHARJO!S15+BEDEWANG!W15+BAYU!AB15+SUMBERARUM!X15+SUMBERBULU!Q15+BANGUNSARI!O15 -> 22859
D16: JML | E16: =SUM(E14:E15) -> 45519
A18: B | B18: PENGGUNA HAK PILIH
B19: 1. | C19: Jumlah pengguna hak pilih dalam Daftar Pemilih Tetap (DPT) | D19: LK | E19: =SONGGON!AF19+BALAK!X19+SRAGI!AG19+PARANGHARJO!S19+BEDEWANG!W19+BAYU!AB19+SUMBERARUM!X19+SUMBERBULU!Q19+BANGUNSARI!O19 -> 16766
D20: PR | E20: =SONGGON!AF20+BALAK!X20+SRAGI!AG20+PARANGHARJO!S20+BEDEWANG!W20+BAYU!AB20+SUMBERARUM!X20+SUMBERBULU!Q20+BANGUNSARI!O20 -> 18135
D21: JML | E21: =SUM(E19:E20) -> 34901
B22: 2. | C22: Jumlah pengguna hak pilih dalam Daftar Pemilih Tambahan (DPTb) | D22: LK | E22: =SONGGON!AF22+BALAK!X22+SRAGI!AG22+PARANGHARJO!S22+BEDEWANG!W22+BAYU!AB22+SUMBERARUM!X22+SUMBERBULU!Q22+BANGUNSARI!O22 -> 10
D23: PR | E23: =SONGGON!AF23+BALAK!X23+SRAGI!AG23+PARANGHARJO!S23+BEDEWANG!W23+BAYU!AB23+SUMBERARUM!X23+SUMBERBULU!Q23+BANGUNSARI!O23 -> 45
D24: JML | E24: =SUM(E22:E23) -> 55
B25: 3. | C25: Jumlah pengguna hak pilih dalam Daftar Pemilih Khusus (DPK) | D25: LK | E25: =SONGGON!AF25+BALAK!X25+SRAGI!AG25+PARANGHARJO!S25+BEDEWANG!W25+BAYU!AB25+SUMBERARUM!X25+SUMBERBULU!Q25+BANGUNSARI!O25 -> 110
D26: PR | E26: =SONGGON!AF26+BALAK!X26+SRAGI!AG26+PARANGHARJO!S26+BEDEWANG!W26+BAYU!AB26+SUMBERARUM!X26+SUMBERBULU!Q26+BANGUNSARI!O26 -> 111
D27: JML | E27: =SUM(E25:E26) -> 221
B28: 4. | C28: Jumlah Pengguna Hak Pilih (B.1+B.2+B.3) | D28: LK | E28: =E19+E22+E25 -> 16886
D29: PR | E29: =E20+E23+E26 -> 18291
D30: JML | E30: =SUM(E28:E29) -> 35177
A32: II | B32: DATA PENGGUNAAN SURAT SUARA
A33: 1 | B33: Jumlah surat suara yang diterima, termasuk surat suara cadangan 2,5% dari DPT | E33: =SONGGON!AF33+BALAK!X33+SRAGI!AG33+PARANGHARJO!S33+BEDEWANG!W33+BAYU!AB33+SUMBERARUM!X33+SUMBERBULU!Q33+BANGUNSARI!O33 -> 45591
A34: 2 | B34: Jumlah surat suara yang digunakan | E34: =SONGGON!AF34+BALAK!X34+SRAGI!AG34+PARANGHARJO!S34+BEDEWANG!W34+BAYU!AB34+SUMBERARUM!X34+SUMBERBULU!Q34+BANGUNSARI!O34 -> 35177
A35: 3 | B35: Jumlah surat suara dikembalikan oleh pemilih (karena rusak atau keliru coblos) | E35: =SONGGON!AF35+BALAK!X35+SRAGI!AG35+PARANGHARJO!S35+BEDEWANG!W35+BAYU!AB35+SUMBERARUM!X35+SUMBERBULU!Q35+BANGUNSARI!O35 -> 40
A36: 4 | B36: Jumlah surat suara yang tidak digunakan/tidak terpakai, termasuk sisa surat suara cadangan | E36: =E33-(E34+E35) -> 10374
A38: III | B38: DATA PEMILIH DISABILITAS
B39: Jumlah seluruh Pemilih disabilitas yang menggunakan hak pilih | D39: LK | E39: =SONGGON!AF39+BALAK!X39+SRAGI!AG39+PARANGHARJO!S39+BEDEWANG!W39+BAYU!AB39+SUMBERARUM!X39+SUMBERBULU!Q39+BANGUNSARI!O39 -> 22
D40: PR | E40: =SONGGON!AF40+BALAK!X40+SRAGI!AG40+PARANGHARJO!S40+BEDEWANG!W40+BAYU!AB40+SUMBERARUM!X40+SUMBERBULU!Q40+BANGUNSARI!O40 -> 30
D41: JML | E41: =SUM(E39:E40) -> 52
A43: IV | B43: DATA RINCIAN PEROLEHAN SUARA PASANGAN CALON BUPATI DAN WAKIL BUPATI
A44: NOMOR DAN NAMA CALON
B45: 1 | C45: H. ANIES RASYID BASWEDAN, Ph.D. - Dr. (H.C.) H. A. MUHAIMIN ISKANDAR | E45: =SONGGON!AF45+BALAK!X45+SRAGI!AG45+PARANGHARJO!S45+BEDEWANG!W45+BAYU!AB45+SUMBERARUM!X45+SUMBERBULU!Q45+BANGUNSARI!O45 -> 3207
B46: 2 | C46: H. PRABOWO SUBIANTO - GIBRAN RAKABUMING RAKA | E46: =SONGGON!AF46+BALAK!X46+SRAGI!AG46+PARANGHARJO!S46+BEDEWANG!W46+BAYU!AB46+SUMBERARUM!X46+SUMBERBULU!Q46+BANGUNSARI!O46 -> 24397
B47: 3 | C47: H. GANJAR PRANOWO, S.H., M.I.P. - Prof. Dr. H. M. MAHFUD MD | E47: =SONGGON!AF47+BALAK!X47+SRAGI!AG47+PARANGHARJO!S47+BEDEWANG!W47+BAYU!AB47+SUMBERARUM!X47+SUMBERBULU!Q47+BANGUNSARI!O47 -> 6735
A49: V | B49: DATA SUARA SAH DAN TIDAK SAH
B50: A. | C50: JUMLAH SELURUH SUARA SAH | E50: =SONGGON!AF50+BALAK!X50+SRAGI!AG50+PARANGHARJO!S50+BEDEWANG!W50+BAYU!AB50+SUMBERARUM!X50+SUMBERBULU!Q50+BANGUNSARI!O50 -> 34349
B51: B. | C51: JUMLAH SUARA TIDAK SAH | E51: =SONGGON!AF51+BALAK!X51+SRAGI!AG51+PARANGHARJO!S51+BEDEWANG!W51+BAYU!AB51+SUMBERARUM!X51+SUMBERBULU!Q51+BANGUNSARI!O51 -> 828
B52: C. | C52: JUMLAH SELURUH SUARA SAH DAN SUARA TIDAK SAH (V.A + V.B) | E52: =SUM(E50:E51) -> 35177

Sheet SONGGON
C2: Kecamatan
C3: Kabupaten | D3: BANYUWANGI
C4: Provinsi | D4: JAWA TIMUR
C9: Kelurahan
A12: I | B12: DATA PEMILIH DAN PENGGUNAAN HAK PILIH | AF12: JUMLAH AKHIR
A13: A | B13: DATA PEMILIH | E13: TPS 001 | F13: TPS 002 | G13: TPS 003 | H13: TPS 004 | I13: TPS 005 | J13: TPS 006 | K13: TPS 007 | L13: TPS 008 | M13: TPS 009 | N13: TPS 010 | O13: TPS 011 | P13: TPS 012 | Q13: TPS 013 | R13: TPS 014 | S13: TPS 015 | T13: TPS 016 | U13: TPS 017 | V13: TPS 018 | W13: TPS 019 | X13: TPS 020 | Y13: TPS 021 | Z13: TPS 022 | AA13: TPS 023 | AB13: TPS 024 | AC13: TPS 025 | AD13: TPS 026 | AE13: TPS 027
B14: Jumlah Pemilih dalam Daftar Pemilih Tetap (DPT) | D14: LK | E14: 105 | F14: 135 | G14: 112 | H14: 110 | I14: 120 | J14: 136 | K14: 146 | L14: 92 | M14: 81 | N14: 119 | O14: 140 | P14: 140 | Q14: 140 | R14: 145 | S14: 139 | T14: 94 | U14: 127 | V14: 157 | W14: 149 | X14: 127 | Y14: 140 | Z14: 127 | AA14: 122 | AB14: 147 | AC14: 150 | AD14: 148 | AE14: 136 | AF14: =SUM(E14:AE14) -> 3484
D15: PR | E15: 127 | F15: 134 | G15: 128 | H15: 110 | I15: 127 | J15: 130 | K15: 142 | L15: 98 | M15: 97 | N15: 129 | O15: 140 | P15: 136 | Q15: 134 | R15: 139 | S15: 141 | T15: 103 | U15: 127 | V15: 142 | W15: 148 | X15: 131 | Y15: 150 | Z15: 137 | AA15: 110 | AB15: 132 | AC15: 148 | AD15: 151 | AE15: 144 | AF15: =SUM(E15:AE15) -> 3535
D16: JML | E16: =SUM(E14:E15) -> 232 | F16: =SUM(F14:F15) -> 269 | G16: =SUM(G14:G15) -> 240 | H16: =SUM(H14:H15) -> 220 | I16: =SUM(I14:I15) -> 247 | J16: =SUM(J14:J15) -> 266 | K16: =SUM(K14:K15) -> 288 | L16: =SUM(L14:L15) -> 190 | ... AE16: =SUM(AE14:AE15) -> 280 | AF16: =SUM(E16:AE16) -> 7019
A18: B | B18: PENGGUNA HAK PILIH
B19: 1. | C19: Jumlah pengguna hak pilih dalam Daftar Pemilih Tetap (DPT) | D19: LK | E19: 77 | F19: 95 | G19: 67 | H19: 84 | I19: 101 | J19: 95 | K19: 104 | L19: 65 | M19: 59 | N19: 80 | O19: 108 | P19: 103 | Q19: 109 | R19: 105 | S19: 101 | T19: 76 | U19: 95 | V19: 119 | W19: 110 | X19: 95 | Y19: 99 | Z19: 98 | AA19: 95 | AB19: 110 | AC19: 115 | AD19: 127 | AE19: 112 | AF19: =SUM(E19:AE19) -> 2604
D20: PR | E20: 107 | F20: 106 | G20: 88 | H20: 90 | I20: 104 | J20: 104 | K20: 108 | L20: 69 | M20: 68 | N20: 100 | O20: 108 | P20: 115 | Q20: 103 | R20: 115 | S20: 115 | T20: 81 | U20: 105 | V20: 120 | W20: 128 | X20: 110 | Y20: 116 | Z20: 116 | AA20: 93 | AB20: 109 | AC20: 114 | AD20: 132 | AE20: 127 | AF20: =SUM(E20:AE20) -> 2851
D21: JML | E21: =SUM(E19:E20) -> 184 | F21: =SUM(F19:F20) -> 201 | G21: =SUM(G19:G20) -> 155 | H21: =SUM(H19:H20) -> 174 | I21: =SUM(I19:I20) -> 205 | J21: =SUM(J19:J20) -> 199 | K21: =SUM(K19:K20) -> 212 | L21: =SUM(L19:L20) -> 134 | ... AE21: =SUM(AE19:AE20) -> 239 | AF21: =SUM(E21:AE21) -> 5455
B22: 2. | C22: Jumlah pengguna hak pilih dalam Daftar Pemilih Tambahan (DPTb) | D22: LK | E22: 0 | F22: 0 | G22: 0 | H22: 0 | I22: 0 | J22: 0 | K22: 0 | L22: 0 | M22: 0 | N22: 0 | O22: 0 | P22: 0 | Q22: 0 | R22: 0 | S22: 0 | T22: 0 | U22: 0 | V22: 0 | W22: 1 | X22: 0 | Y22: 1 | Z22: 0 | AA22: 0 | AB22: 0 | AC22: 0 | AD22: 0 | AE22: 0 | AF22: =SUM(E22:AE22) -> 2
D23: PR | E23: 0 | F23: 0 | G23: 0 | H23: 0 | I23: 0 | J23: 0 | K23: 0 | L23: 0 | M23: 1 | N23: 0 | O23: 0 | P23: 1 | Q23: 0 | R23: 0 | S23: 0 | T23: 0 | U23: 0 | V23: 1 | W23: 1 | X23: 0 | Y23: 1 | Z23: 0 | AA23: 0 | AB23: 0 | AC23: 0 | AD23: 0 | AE23: 0 | AF23: =SUM(E23:AE23) -> 5
D24: JML | E24: =SUM(E22:E23) -> 0 | F24: =SUM(F22:F23) -> 0 | G24: =SUM(G22:G23) -> 0 | H24: =SUM(H22:H23) -> 0 | I24: =SUM(I22:I23) -> 0 | J24: =SUM(J22:J23) -> 0 | K24: =SUM(K22:K23) -> 0 | L24: =SUM(L22:L23) -> 0 | ... AE24: =SUM(AE22:AE23) -> 0 | AF24: =SUM(E24:AE24) -> 7
B25: 3. | C25: Jumlah pengguna hak pilih dalam Daftar Pemilih Khusus (DPK) | D25: LK | E25: 0 | F25: 2 | G25: 1 | H25: 1 | I25: 3 | J25: 0 | K25: 0 | L25: 0 | M25: 0 | N25: 1 | O25: 1 | P25: 2 | Q25: 1 | R25: 1 | S25: 0 | T25: 1 | U25: 0 | V25: 0 | W25: 5 | X25: 0 | Y25: 0 | Z25: 1 | AA25: 1 | AB25: 0 | AC25: 0 | AD25: 0 | AE25: 0 | AF25: =SUM(E25:AE25) -> 21
D26: PR | E26: 1 | F26: 0 | G26: 0 | H26: 0 | I26: 1 | J26: 0 | K26: 0 | L26: 0 | M26: 0 | N26: 0 | O26: 0 | P26: 0 | Q26: 1 | R26: 1 | S26: 0 | T26: 0 | U26: 0 | V26: 0 | W26: 4 | X26: 1 | Y26: 1 | Z26: 0 | AA26: 2 | AB26: 0 | AC26: 0 | AD26: 0 | AE26: 0 | AF26: =SUM(E26:AE26) -> 12
D27: JML | E27: =SUM(E25:E26) -> 1 | F27: =SUM(F25:F26) -> 2 | G27: =SUM(G25:G26) -> 1 | H27: =SUM(H25:H26) -> 1 | I27: =SUM(I25:I26) -> 4 | J27: =SUM(J25:J26) -> 0 | K27: =SUM(K25:K26) -> 0 | L27: =SUM(L25:L26) -> 0 | ... AE27: =SUM(AE25:AE26) -> 0 | AF27: =SUM(E27:AE27) -> 33
B28: 4. | C28: Jumlah Pengguna Hak Pilih (B.1+B.2+B.3) | D28: LK | E28: =SUM(E19,E22,E25) -> 77 | F28: =SUM(F19,F22,F25) -> 97 | G28: =SUM(G19,G22,G25) -> 68 | H28: =SUM(H19,H22,H25) -> 85 | I28: =SUM(I19,I22,I25) -> 104 | J28: =SUM(J19,J22,J25) -> 95 | K28: =SUM(K19,K22,K25) -> 104 | L28: =SUM(L19,L22,L25) -> 65 | ... AE28: =SUM(AE19,AE22,AE25) -> 112 | AF28: =SUM(E28:AE28) -> 2627
D29: PR | E29: =SUM(E20,E23,E26) -> 108 | F29: =SUM(F20,F23,F26) -> 106 | G29: =SUM(G20,G23,G26) -> 88 | H29: =SUM(H20,H23,H26) -> 90 | I29: =SUM(I20,I23,I26) -> 105 | J29: =SUM(J20,J23,J26) -> 104 | K29: =SUM(K20,K23,K26) -> 108 | L29: =SUM(L20,L23,L26) -> 69 | ... AE29: =SUM(AE20,AE23,AE26) -> 127 | AF29: =SUM(E29:AE29) -> 2868
D30: JML | E30: =SUM(E28:E29) -> 185 | F30: =SUM(F28:F29) -> 203 | G30: =SUM(G28:G29) -> 156 | H30: =SUM(H28:H29) -> 175 | I30: =SUM(I28:I29) -> 209 | J30: =SUM(J28:J29) -> 199 | K30: =SUM(K28:K29) -> 212 | L30: =SUM(L28:L29) -> 134 | ... AE30: =SUM(AE28:AE29) -> 239 | AF30: =SUM(E30:AE30) -> 5495
A32: II | B32: DATA PENGGUNAAN SURAT SUARA
A33: 1 | B33: Jumlah surat suara yang diterima, termasuk surat suara cadangan 2,5% dari DPT | E33: 227 | F33: 261 | G33: 235 | H33: 214 | I33: 242 | J33: 263 | K33: 284 | L33: 184 | M33: 172 | N33: 244 | O33: 286 | P33: 272 | Q33: 272 | R33: 280 | S33: 286 | T33: 192 | U33: 259 | V33: 295 | W33: 289 | X33: 255 | Y33: 285 | Z33: 270 | AA33: 227 | AB33: 279 | AC33: 295 | AD33: 295 | AE33: 278 | AF33: =SUM(E33:AE33) -> 6941
A34: 2 | B34: Jumlah surat suara yang digunakan | E34: 185 | F34: 203 | G34: 156 | H34: 175 | I34: 209 | J34: 199 | K34: 212 | L34: 134 | M34: 128 | N34: 181 | O34: 217 | P34: 221 | Q34: 214 | R34: 222 | S34: 216 | T34: 158 | U34: 200 | V34: 240 | W34: 249 | X34: 206 | Y34: 218 | Z34: 215 | AA34: 191 | AB34: 219 | AC34: 229 | AD34: 259 | AE34: 239 | AF34: =SUM(E34:AE34) -> 5495
A35: 3 | B35: Jumlah surat suara dikembalikan oleh pemilih (karena rusak atau keliru coblos) | E35: 0 | F35: 2 | G35: 0 | H35: 0 | I35: 1 | J35: 0 | K35: 0 | L35: 0 | M35: 0 | N35: 0 | O35: 1 | P35: 0 | Q35: 0 | R35: 0 | S35: 0 | T35: 0 | U35: 0 | V35: 0 | W35: 0 | X35: 0 | Y35: 0 | Z35: 0 | AA35: 0 | AB35: 0 | AC35: 0 | AD35: 0 | AE35: 0 | AF35: =SUM(E35:AE35) -> 4
A36: 4 | B36: Jumlah surat suara yang tidak digunakan/tidak terpakai, termasuk sisa surat suara cadangan | E36: =E33-(E34+E35) -> 42 | F36: =F33-(F34+F35) -> 56 | G36: =G33-(G34+G35) -> 79 | H36: =H33-(H34+H35) -> 39 | I36: =I33-(I34+I35) -> 32 | J36: =J33-(J34+J35) -> 64 | K36: =K33-(K34+K35) -> 72 | L36: =L33-(L34+L35) -> 50 | ... AE36: =AE33-(AE34+AE35) -> 39 | AF36: =SUM(E36:AE36) -> 1442
A38: III | B38: DATA PEMILIH DISABILITAS
B39: Jumlah seluruh Pemilih disabilitas yang menggunakan hak pilih | D39: LK | E39: 0 | F39: 0 | G39: 0 | H39: 0 | I39: 0 | J39: 0 | K39: 1 | L39: 0 | M39: 1 | N39: 0 | O39: 0 | P39: 0 | Q39: 0 | R39: 2 | S39: 0 | T39: 0 | U39: 0 | V39: 2 | W39: 0 | X39: 0 | Y39: 0 | Z39: 0 | AA39: 0 | AB39: 0 | AC39: 0 | AD39: 0 | AE39: 0 | AF39: =SUM(E39:AE39) -> 6
D40: PR | E40: 0 | F40: 0 | G40: 0 | H40: 0 | I40: 1 | J40: 0 | K40: 0 | L40: 0 | M40: 2 | N40: 2 | O40: 0 | P40: 0 | Q40: 0 | R40: 4 | S40: 0 | T40: 0 | U40: 0 | V40: 2 | W40: 0 | X40: 0 | Y40: 2 | Z40: 0 | AA40: 0 | AB40: 0 | AC40: 0 | AD40: 0 | AE40: 0 | AF40: =SUM(E40:AE40) -> 13
D41: JML | E41: =SUM(E39:E40) -> 0 | F41: =SUM(F39:F40) -> 0 | G41: =SUM(G39:G40) -> 0 | H41: =SUM(H39:H40) -> 0 | I41: =SUM(I39:I40) -> 1 | J41: =SUM(J39:J40) -> 0 | K41: =SUM(K39:K40) -> 1 | L41: =SUM(L39:L40) -> 0 | ... AE41: =SUM(AE39:AE40) -> 0 | AF41: =SUM(E41:AE41) -> 19
A43: IV | B43: DATA RINCIAN PEROLEHAN SUARA PASANGAN CALON BUPATI DAN WAKIL BUPATI
A44: NOMOR DAN NAMA CALON
B45: 1 | C45: H. ANIES RASYID BASWEDAN, Ph.D. - Dr. (H.C.) H. A. MUHAIMIN ISKANDAR | E45: 23 | F45: 44 | G45: 17 | H45: 14 | I45: 9 | J45: 33 | K45: 8 | L45: 6 | M45: 6 | N45: 18 | O45: 28 | P45: 13 | Q45: 4 | R45: 23 | S45: 20 | T45: 8 | U45: 9 | V45: 35 | W45: 39 | X45: 17 | Y45: 16 | Z45: 25 | AA45: 7 | AB45: 15 | AC45: 27 | AD45: 33 | AE45: 7 | AF45: =SUM(E45:AE45) -> 504
B46: 2 | C46: H. PRABOWO SUBIANTO - GIBRAN RAKABUMING RAKA | E46: 129 | F46: 131 | G46: 93 | H46: 117 | I46: 147 | J46: 135 | K46: 170 | L46: 87 | M46: 88 | N46: 129 | O46: 129 | P46: 161 | Q46: 153 | R46: 158 | S46: 130 | T46: 100 | U46: 133 | V46: 159 | W46: 174 | X46: 136 | Y46: 128 | Z46: 134 | AA46: 144 | AB46: 148 | AC46: 125 | AD46: 157 | AE46: 170 | AF46: =SUM(E46:AE46) -> 3665
B47: 3 | C47: H. GANJAR PRANOWO, S.H., M.I.P. - Prof. Dr. H. M. MAHFUD MD | E47: 26 | F47: 25 | G47: 39 | H47: 41 | I47: 51 | J47: 29 | K47: 32 | L47: 40 | M47: 28 | N47: 33 | O47: 55 | P47: 45 | Q47: 55 | R47: 39 | S47: 52 | T47: 43 | U47: 55 | V47: 43 | W47: 33 | X47: 47 | Y47: 72 | Z47: 52 | AA47: 37 | AB47: 51 | AC47: 76 | AD47: 65 | AE47: 50 | AF47: =SUM(E47:AE47) -> 1214
A49: V | B49: DATA SUARA SAH DAN TIDAK SAH
B50: A. | C50: JUMLAH SELURUH SUARA SAH | E50: =SUM(E45:E47) -> 178 | F50: =SUM(F45:F47) -> 200 | G50: =SUM(G45:G47) -> 149 | H50: =SUM(H45:H47) -> 172 | I50: =SUM(I45:I47) -> 207 | J50: =SUM(J45:J47) -> 197 | K50: =SUM(K45:K47) -> 210 | L50: =SUM(L45:L47) -> 133 | ... AE50: =SUM(AE45:AE47) -> 227 | AF50: =SUM(E50:AE50) -> 5383
B51: B. | C51: JUMLAH SUARA TIDAK SAH | E51: 7 | F51: 3 | G51: 7 | H51: 3 | I51: 2 | J51: 2 | K51: 2 | L51: 1 | M51: 6 | N51: 1 | O51: 5 | P51: 2 | Q51: 2 | R51: 2 | S51: 14 | T51: 7 | U51: 3 | V51: 3 | W51: 3 | X51: 6 | Y51: 2 | Z51: 4 | AA51: 3 | AB51: 5 | AC51: 1 | AD51: 4 | AE51: 12 | AF51: =SUM(E51:AE51) -> 112
B52: C. | C52: JUMLAH SELURUH SUARA SAH DAN SUARA TIDAK SAH (V.A + V.B) | E52: =SUM(E50:E51) -> 185 | F52: =SUM(F50:F51) -> 203 | G52: =SUM(G50:G51) -> 156 | H52: =SUM(H50:H51) -> 175 | I52: =SUM(I50:I51) -> 209 | J52: =SUM(J50:J51) -> 199 | K52: =SUM(K50:K51) -> 212 | L52: =SUM(L50:L51) -> 134 | ... AE52: =SUM(AE50:AE51) -> 239 | AF52: =SUM(E52:AE52) -> 5495

Sheet BALAK
C2: Kecamatan
C3: Kabupaten | D3: BANYUWANGI
C4: Provinsi | D4: JAWA TIMUR
C9: Kelurahan
A12: I | B12: DATA PEMILIH DAN PENGGUNAAN HAK PILIH | X12: JUMLAH AKHIR
A13: A | B13: DATA PEMILIH | E13: TPS 001 | F13: TPS 002 | G13: TPS 003 | H13: TPS 004 | I13: TPS 005 | J13: TPS 006 | K13: TPS 007 | L13: TPS 008 | M13: TPS 009 | N13: TPS 010 | O13: TPS 011 | P13: TPS 012 | Q13: TPS 013 | R13: TPS 014 | S13: TPS 015 | T13: TPS 016 | U13: TPS 017 | V13: TPS 018 | W13: TPS 019
B14: Jumlah Pemilih dalam Daftar Pemilih Tetap (DPT) | D14: LK | E14: 138 | F14: 141 | G14: 136 | H14: 140 | I14: 129 | J14: 138 | K14: 139 | L14: 139 | M14: 137 | N14: 138 | O14: 132 | P14: 140 | Q14: 134 | R14: 141 | S14: 131 | T14: 125 | U14: 136 | V14: 136 | W14: 141 | X14: =SUM(E14:W14) -> 2591
D15: PR | E15: 128 | F15: 135 | G15: 145 | H15: 126 | I15: 124 | J15: 136 | K15: 142 | L15: 143 | M15: 147 | N15: 137 | O15: 143 | P15: 150 | Q15: 149 | R15: 145 | S15: 150 | T15: 137 | U15: 141 | V15: 144 | W15: 140 | X15: =SUM(E15:W15) -> 2662
D16: JML | E16: =SUM(E14:E15) -> 266 | F16: =SUM(F14:F15) -> 276 | G16: =SUM(G14:G15) -> 281 | H16: =SUM(H14:H15) -> 266 | I16: =SUM(I14:I15) -> 253 | J16: =SUM(J14:J15) -> 274 | K16: =SUM(K14:K15) -> 281 | L16: =SUM(L14:L15) -> 282 | ... W16: =SUM(W14:W15) -> 281 | X16: =SUM(E16:W16) -> 5253
A18: B | B18: PENGGUNA HAK PILIH
B19: 1. | C19: Jumlah pengguna hak pilih dalam Daftar Pemilih Tetap (DPT) | D19: LK | E19: 73 | F19: 109 | G19: 112 | H19: 93 | I19: 95 | J19: 104 | K19: 96 | L19: 110 | M19: 98 | N19: 104 | O19: 102 | P19: 107 | Q19: 109 | R19: 97 | S19: 93 | T19: 98 | U19: 113 | V19: 104 | W19: 123 | X19: =SUM(E19:W19) -> 1940
D20: PR | E20: 90 | F20: 112 | G20: 118 | H20: 97 | I20: 88 | J20: 110 | K20: 115 | L20: 117 | M20: 127 | N20: 106 | O20: 119 | P20: 122 | Q20: 113 | R20: 122 | S20: 120 | T20: 108 | U20: 116 | V20: 119 | W20: 123 | X20: =SUM(E20:W20) -> 2142
D21: JML | E21: =SUM(E19:E20) -> 163 | F21: =SUM(F19:F20) -> 221 | G21: =SUM(G19:G20) -> 230 | H21: =SUM(H19:H20) -> 190 | I21: =SUM(I19:I20) -> 183 | J21: =SUM(J19:J20) -> 214 | K21: =SUM(K19:K20) -> 211 | L21: =SUM(L19:L20) -> 227 | ... W21: =SUM(W19:W20) -> 246 | X21: =SUM(E21:W21) -> 4082
B22: 2. | C22: Jumlah pengguna hak pilih dalam Daftar Pemilih Tambahan (DPTb) | D22: LK | E22: 0 | F22: 0 | G22: 0 | H22: 0 | I22: 0 | J22: 0 | K22: 0 | L22: 0 | M22: 0 | N22: 0 | O22: 0 | P22: 0 | Q22: 0 | R22: 0 | S22: 0 | T22: 0 | U22: 0 | V22: 0 | W22: 0 | X22: =SUM(E22:W22) -> 0
D23: PR | E23: 0 | F23: 0 | G23: 0 | H23: 0 | I23: 0 | J23: 0 | K23: 0 | L23: 0 | M23: 0 | N23: 0 | O23: 0 | P23: 0 | Q23: 0 | R23: 0 | S23: 0 | T23: 0 | U23: 0 | V23: 0 | W23: 0 | X23: =SUM(E23:W23) -> 0
D24: JML | E24: =SUM(E22:E23) -> 0 | F24: =SUM(F22:F23) -> 0 | G24: =SUM(G22:G23) -> 0 | H24: =SUM(H22:H23) -> 0 | I24: =SUM(I22:I23) -> 0 | J24: =SUM(J22:J23) -> 0 | K24: =SUM(K22:K23) -> 0 | L24: =SUM(L22:L23) -> 0 | ... W24: =SUM(W22:W23) -> 0 | X24: =SUM(E24:W24) -> 0
B25: 3. | C25: Jumlah pengguna hak pilih dalam Daftar Pemilih Khusus (DPK) | D25: LK | E25: 0 | F25: 0 | G25: 2 | H25: 3 | I25: 1 | J25: 0 | K25: 0 | L25: 3 | M25: 0 | N25: 0 | O25: 0 | P25: 0 | Q25: 0 | R25: 3 | S25: 2 | T25: 0 | U25: 0 | V25: 1 | W25: 0 | X25: =SUM(E25:W25) -> 15
D26: PR | E26: 1 | F26: 0 | G26: 1 | H26: 3 | I26: 3 | J26: 1 | K26: 0 | L26: 1 | M26: 0 | N26: 0 | O26: 1 | P26: 0 | Q26: 0 | R26: 3 | S26: 2 | T26: 0 | U26: 2 | V26: 0 | W26: 1 | X26: =SUM(E26:W26) -> 19
D27: JML | E27: =SUM(E25:E26) -> 1 | F27: =SUM(F25:F26) -> 0 | G27: =SUM(G25:G26) -> 3 | H27: =SUM(H25:H26) -> 6 | I27: =SUM(I25:I26) -> 4 | J27: =SUM(J25:J26) -> 1 | K27: =SUM(K25:K26) -> 0 | L27: =SUM(L25:L26) -> 4 | ... W27: =SUM(W25:W26) -> 1 | X27: =SUM(E27:W27) -> 34
B28: 4. | C28: Jumlah Pengguna Hak Pilih (B.1+B.2+B.3) | D28: LK | E28: =SUM(E19,E22,E25) -> 73 | F28: =SUM(F19,F22,F25) -> 109 | G28: =SUM(G19,G22,G25) -> 114 | H28: =SUM(H19,H22,H25) -> 96 | I28: =SUM(I19,I22,I25) -> 96 | J28: =SUM(J19,J22,J25) -> 104 | K28: =SUM(K19,K22,K25) -> 96 | L28: =SUM(L19,L22,L25) -> 113 | ... W28: =SUM(W19,W22,W25) -> 123 | X28: =SUM(E28:W28) -> 1955
D29: PR | E29: =SUM(E20,E23,E26) -> 91 | F29: =SUM(F20,F23,F26) -> 112 | G29: =SUM(G20,G23,G26) -> 119 | H29: =SUM(H20,H23,H26) -> 100 | I29: =SUM(I20,I23,I26) -> 91 | J29: =SUM(J20,J23,J26) -> 111 | K29: =SUM(K20,K23,K26) -> 115 | L29: =SUM(L20,L23,L26) -> 118 | ... W29: =SUM(W20,W23,W26) -> 124 | X29: =SUM(E29:W29) -> 2161
D30: JML | E30: =SUM(E28:E29) -> 164 | F30: =SUM(F28:F29) -> 221 | G30: =SUM(G28:G29) -> 233 | H30: =SUM(H28:H29) -> 196 | I30: =SUM(I28:I29) -> 187 | J30: =SUM(J28:J29) -> 215 | K30: =SUM(K28:K29) -> 211 | L30: =SUM(L28:L29) -> 231 | ... W30: =SUM(W28:W29) -> 247 | X30: =SUM(E30:W30) -> 4116
A32: II | B32: DATA PENGGUNAAN SURAT SUARA
A33: 1 | B33: Jumlah surat suara yang diterima, termasuk surat suara cadangan 2,5% dari DPT | E33: 262 | F33: 283 | G33: 277 | H33: 265 | I33: 250 | J33: 269 | K33: 273 | L33: 288 | M33: 291 | N33: 281 | O33: 285 | P33: 288 | Q33: 282 | R33: 281 | S33: 275 | T33: 258 | U33: 272 | V33: 276 | W33: 273 | X33: =SUM(E33:W33) -> 5229
A34: 2 | B34: Jumlah surat suara yang digunakan | E34: 164 | F34: 221 | G34: 233 | H34: 196 | I34: 187 | J34: 215 | K34: 211 | L34: 231 | M34: 225 | N34: 210 | O34: 222 | P34: 229 | Q34: 222 | R34: 225 | S34: 217 | T34: 206 | U34: 231 | V34: 224 | W34: 247 | X34: =SUM(E34:W34) -> 4116
A35: 3 | B35: Jumlah surat suara dikembalikan oleh pemilih (karena rusak atau keliru coblos) | E35: 0 | F35: 0 | G35: 1 | H35: 0 | I35: 0 | J35: 0 | K35: 0 | L35: 0 | M35: 0 | N35: 0 | O35: 0 | P35: 0 | Q35: 2 | R35: 0 | S35: 0 | T35: 0 | U35: 1 | V35: 1 | W35: 0 | X35: =SUM(E35:W35) -> 5
A36: 4 | B36: Jumlah surat suara yang tidak digunakan/tidak terpakai, termasuk sisa surat suara cadangan | E36: =E33-(E34+E35) -> 98 | F36: =F33-(F34+F35) -> 62 | G36: =G33-(G34+G35) -> 43 | H36: =H33-(H34+H35) -> 69 | I36: =I33-(I34+I35) -> 63 | J36: =J33-(J34+J35) -> 54 | K36: =K33-(K34+K35) -> 62 | L36: =L33-(L34+L35) -> 57 | ... W36: =W33-(W34+W35) -> 26 | X36: =SUM(E36:W36) -> 1108
A38: III | B38: DATA PEMILIH DISABILITAS
B39: Jumlah seluruh Pemilih disabilitas yang menggunakan hak pilih | D39: LK | E39: 0 | F39: 0 | G39: 2 | H39: 0 | I39: 0 | J39: 0 | K39: 0 | L39: 0 | M39: 0 | N39: 1 | O39: 0 | P39: 0 | Q39: 0 | R39: 0 | S39: 0 | T39: 0 | U39: 0 | V39: 0 | W39: 0 | X39: =SUM(E39:W39) -> 3
D40: PR | E40: 0 | F40: 0 | G40: 1 | H40: 0 | I40: 0 | J40: 0 | K40: 0 | L40: 0 | M40: 0 | N40: 1 | O40: 0 | P40: 0 | Q40: 0 | R40: 0 | S40: 0 | T40: 0 | U40: 0 | V40: 0 | W40: 0 | X40: =SUM(E40:W40) -> 2
D41: JML | E41: =SUM(E39:E40) -> 0 | F41: =SUM(F39:F40) -> 0 | G41: =SUM(G39:G40) -> 3 | H41: =SUM(H39:H40) -> 0 | I41: =SUM(I39:I40) -> 0 | J41: =SUM(J39:J40) -> 0 | K41: =SUM(K39:K40) -> 0 | L41: =SUM(L39:L40) -> 0 | ... W41: =SUM(W39:W40) -> 0 | X41: =SUM(E41:W41) -> 5
A43: IV | B43: DATA RINCIAN PEROLEHAN SUARA PASANGAN CALON BUPATI DAN WAKIL BUPATI
A44: NOMOR DAN NAMA CALON
B45: 1 | C45: H. ANIES RASYID BASWEDAN, Ph.D. - Dr. (H.C.) H. A. MUHAIMIN ISKANDAR | E45: 15 | F45: 16 | G45: 24 | H45: 17 | I45: 32 | J45: 24 | K45: 16 | L45: 14 | M45: 7 | N45: 13 | O45: 12 | P45: 22 | Q45: 38 | R45: 28 | S45: 22 | T45: 38 | U45: 24 | V45: 40 | W45: 6 | X45: =SUM(E45:W45) -> 408
B46: 2 | C46: H. PRABOWO SUBIANTO - GIBRAN RAKABUMING RAKA | E46: 108 | F46: 148 | G46: 149 | H46: 143 | I46: 131 | J46: 142 | K46: 142 | L46: 157 | M46: 110 | N46: 122 | O46: 145 | P46: 172 | Q46: 111 | R46: 128 | S46: 129 | T46: 134 | U46: 169 | V46: 152 | W46: 161 | X46: =SUM(E46:W46) -> 2653
B47: 3 | C47: H. GANJAR PRANOWO, S.H., M.I.P. - Prof. Dr. H. M. MAHFUD MD | E47: 31 | F47: 41 | G47: 54 | H47: 33 | I47: 20 | J47: 47 | K47: 48 | L47: 55 | M47: 104 | N47: 69 | O47: 59 | P47: 31 | Q47: 68 | R47: 60 | S47: 54 | T47: 27 | U47: 30 | V47: 25 | W47: 76 | X47: =SUM(E47:W47) -> 932
A49: V | B49: DATA SUARA SAH DAN TIDAK SAH
B50: A. | C50: JUMLAH SELURUH SUARA SAH | E50: =SUM(E45:E47) -> 154 | F50: =SUM(F45:F47) -> 205 | G50: =SUM(G45:G47) -> 227 | H50: =SUM(H45:H47) -> 193 | I50: =SUM(I45:I47) -> 183 | J50: =SUM(J45:J47) -> 213 | K50: =SUM(K45:K47) -> 206 | L50: =SUM(L45:L47) -> 226 | ... W50: =SUM(W45:W47) -> 243 | X50: =SUM(E50:W50) -> 3993
B51: B. | C51: JUMLAH SUARA TIDAK SAH | E51: 10 | F51: 16 | G51: 6 | H51: 3 | I51: 4 | J51: 2 | K51: 5 | L51: 5 | M51: 4 | N51: 6 | O51: 6 | P51: 4 | Q51: 5 | R51: 9 | S51: 12 | T51: 7 | U51: 8 | V51: 7 | W51: 4 | X51: =SUM(E51:W51) -> 123
B52: C. | C52: JUMLAH SELURUH SUARA SAH DAN SUARA TIDAK SAH (V.A + V.B) | E52: =SUM(E50:E51) -> 164 | F52: =SUM(F50:F51) -> 221 | G52: =SUM(G50:G51) -> 233 | H52: =SUM(H50:H51) -> 196 | I52: =SUM(I50:I51) -> 187 | J52: =SUM(J50:J51) -> 215 | K52: =SUM(K50:K51) -> 211 | L52: =SUM(L50:L51) -> 231 | ... W52: =SUM(W50:W51) -> 247 | X52: =SUM(E52:W52) -> 4116

Sheet SRAGI
C2: Kecamatan
C3: Kabupaten | D3: BANYUWANGI
C4: Provinsi | D4: JAWA TIMUR
C9: Kelurahan
A12: I | B12: DATA PEMILIH DAN PENGGUNAAN HAK PILIH | AG12: JUMLAH AKHIR
A13: A | B13: DATA PEMILIH | E13: TPS 001 | F13: TPS 002 | G13: TPS 003 | H13: TPS 004 | I13: TPS 005 | J13: TPS 006 | K13: TPS 007 | L13: TPS 008 | M13: TPS 009 | N13: TPS 010 | O13: TPS 011 | P13: TPS 012 | Q13: TPS 013 | R13: TPS 014 | S13: TPS 015 | T13: TPS 016 | U13: TPS 017 | V13: TPS 018 | W13: TPS 019 | X13: TPS 020 | Y13: TPS 021 | Z13: TPS 022 | AA13: TPS 023 | AB13: TPS 024 | AC13: TPS 025 | AD13: TPS 026 | AE13: TPS 027 | AF13: TPS 028
B14: Jumlah Pemilih dalam Daftar Pemilih Tetap (DPT) | D14: LK | E14: 133 | F14: 130 | G14: 141 | H14: 116 | I14: 135 | J14: 111 | K14: 134 | L14: 150 | M14: 151 | N14: 146 | O14: 125 | P14: 115 | Q14: 115 | R14: 143 | S14: 150 | T14: 151 | U14: 157 | V14: 140 | W14: 142 | X14: 149 | Y14: 148 | Z14: 151 | AA14: 149 | AB14: 131 | AC14: 127 | AD14: 148 | AE14: 151 | AF14: 135 | AG14: =SUM(E14:AF14) -> 3874
D15: PR | E15: 137 | F15: 129 | G15: 133 | H15: 122 | I15: 125 | J15: 103 | K15: 142 | L15: 148 | M15: 148 | N15: 149 | O15: 132 | P15: 106 | Q15: 115 | R15: 148 | S15: 139 | T15: 142 | U15: 136 | V15: 156 | W15: 152 | X15: 145 | Y15: 148 | Z15: 140 | AA15: 143 | AB15: 117 | AC15: 135 | AD15: 150 | AE15: 140 | AF15: 142 | AG15: =SUM(E15:AF15) -> 3822
D16: JML | E16: =SUM(E14:E15) -> 270 | F16: =SUM(F14:F15) -> 259 | G16: =SUM(G14:G15) -> 274 | H16: =SUM(H14:H15) -> 238 | I16: =SUM(I14:I15) -> 260 | J16: =SUM(J14:J15) -> 214 | K16: =SUM(K14:K15) -> 276 | L16: =SUM(L14:L15) -> 298 | ... AF16: =SUM(AF14:AF15) -> 277 | AG16: =SUM(E16:AF16) -> 7696
A18: B | B18: PENGGUNA HAK PILIH
B19: 1. | C19: Jumlah pengguna hak pilih dalam Daftar Pemilih Tetap (DPT) | D19: LK | E19: 100 | F19: 88 | G19: 101 | H19: 67 | I19: 99 | J19: 81 | K19: 101 | L19: 101 | M19: 113 | N19: 118 | O19: 90 | P19: 90 | Q19: 86 | R19: 111 | S19: 108 | T19: 113 | U19: 101 | V19: 113 | W19: 101 | X19: 116 | Y19: 119 | Z19: 115 | AA19: 112 | AB19: 99 | AC19: 94 | AD19: 102 | AE19: 112 | AF19: 104 | AG19: =SUM(E19:AF19) -> 2855
D20: PR | E20: 104 | F20: 108 | G20: 96 | H20: 86 | I20: 102 | J20: 83 | K20: 109 | L20: 118 | M20: 129 | N20: 124 | O20: 108 | P20: 87 | Q20: 93 | R20: 119 | S20: 108 | T20: 111 | U20: 101 | V20: 126 | W20: 115 | X20: 116 | Y20: 127 | Z20: 108 | AA20: 111 | AB20: 99 | AC20: 107 | AD20: 115 | AE20: 118 | AF20: 111 | AG20: =SUM(E20:AF20) -> 3039
D21: JML | E21: =SUM(E19:E20) -> 204 | F21: =SUM(F19:F20) -> 196 | G21: =SUM(G19:G20) -> 197 | H21: =SUM(H19:H20) -> 153 | I21: =SUM(I19:I20) -> 201 | J21: =SUM(J19:J20) -> 164 | K21: =SUM(K19:K20) -> 210 | L21: =SUM(L19:L20) -> 219 | ... AF21: =SUM(AF19:AF20) -> 215 | AG21: =SUM(E21:AF21) -> 5894
B22: 2. | C22: Jumlah pengguna hak pilih dalam Daftar Pemilih Tambahan (DPTb) | D22: LK | E22: 0 | F22: 0 | G22: 0 | H22: 0 | I22: 0 | J22: 0 | K22: 1 | L22: 0 | M22: 0 | N22: 0 | O22: 0 | P22: 0 | Q22: 0 | R22: 0 | S22: 0 | T22: 0 | U22: 0 | V22: 0 | W22: 0 | X22: 0 | Y22: 0 | Z22: 0 | AA22: 0 | AB22: 0 | AC22: 0 | AD22: 0 | AE22: 0 | AF22: 0 | AG22: =SUM(E22:AF22) -> 1
D23: PR | E23: 0 | F23: 0 | G23: 0 | H23: 0 | I23: 0 | J23: 0 | K23: 1 | L23: 0 | M23: 0 | N23: 0 | O23: 0 | P23: 0 | Q23: 0 | R23: 0 | S23: 0 | T23: 0 | U23: 0 | V23: 0 | W23: 0 | X23: 0 | Y23: 0 | Z23: 0 | AA23: 0 | AB23: 0 | AC23: 0 | AD23: 0 | AE23: 0 | AF23: 0 | AG23: =SUM(E23:AF23) -> 1
D24: JML | E24: =SUM(E22:E23) -> 0 | F24: =SUM(F22:F23) -> 0 | G24: =SUM(G22:G23) -> 0 | H24: =SUM(H22:H23) -> 0 | I24: =SUM(I22:I23) -> 0 | J24: =SUM(J22:J23) -> 0 | K24: =SUM(K22:K23) -> 2 | L24: =SUM(L22:L23) -> 0 | ... AF24: =SUM(AF22:AF23) -> 0 | AG24: =SUM(E24:AF24) -> 2
B25: 3. | C25: Jumlah pengguna hak pilih dalam Daftar Pemilih Khusus (DPK) | D25: LK | E25: 1 | F25: 1 | G25: 0 | H25: 2 | I25: 0 | J25: 0 | K25: 2 | L25: 0 | M25: 1 | N25: 2 | O25: 0 | P25: 0 | Q25: 0 | R25: 1 | S25: 0 | T25: 0 | U25: 1 | V25: 1 | W25: 0 | X25: 0 | Y25: 0 | Z25: 0 | AA25: 0 | AB25: 0 | AC25: 4 | AD25: 1 | AE25: 2 | AF25: 3 | AG25: =SUM(E25:AF25) -> 22
D26: PR | E26: 0 | F26: 0 | G26: 0 | H26: 0 | I26: 1 | J26: 1 | K26: 2 | L26: 2 | M26: 1 | N26: 0 | O26: 0 | P26: 0 | Q26: 1 | R26: 0 | S26: 0 | T26: 0 | U26: 1 | V26: 1 | W26: 0 | X26: 0 | Y26: 1 | Z26: 0 | AA26: 0 | AB26: 0 | AC26: 2 | AD26: 1 | AE26: 1 | AF26: 8 | AG26: =SUM(E26:AF26) -> 23
D27: JML | E27: =SUM(E25:E26) -> 1 | F27: =SUM(F25:F26) -> 1 | G27: =SUM(G25:G26) -> 0 | H27: =SUM(H25:H26) -> 2 | I27: =SUM(I25:I26) -> 1 | J27: =SUM(J25:J26) -> 1 | K27: =SUM(K25:K26) -> 4 | L27: =SUM(L25:L26) -> 2 | ... AF27: =SUM(AF25:AF26) -> 11 | AG27: =SUM(E27:AF27) -> 45
B28: 4. | C28: Jumlah Pengguna Hak Pilih (B.1+B.2+B.3) | D28: LK | E28: =SUM(E19,E22,E25) -> 101 | F28: =SUM(F19,F22,F25) -> 89 | G28: =SUM(G19,G22,G25) -> 101 | H28: =SUM(H19,H22,H25) -> 69 | I28: =SUM(I19,I22,I25) -> 99 | J28: =SUM(J19,J22,J25) -> 81 | K28: =SUM(K19,K22,K25) -> 104 | L28: =SUM(L19,L22,L25) -> 101 | ... AF28: =SUM(AF19,AF22,AF25) -> 107 | AG28: =SUM(E28:AF28) -> 2878
D29: PR | E29: =SUM(E20,E23,E26) -> 104 | F29: =SUM(F20,F23,F26) -> 108 | G29: =SUM(G20,G23,G26) -> 96 | H29: =SUM(H20,H23,H26) -> 86 | I29: =SUM(I20,I23,I26) -> 103 | J29: =SUM(J20,J23,J26) -> 84 | K29: =SUM(K20,K23,K26) -> 112 | L29: =SUM(L20,L23,L26) -> 120 | ... AF29: =SUM(AF20,AF23,AF26) -> 119 | AG29: =SUM(E29:AF29) -> 3063
D30: JML | E30: =SUM(E28:E29) -> 205 | F30: =SUM(F28:F29) -> 197 | G30: =SUM(G28:G29) -> 197 | H30: =SUM(H28:H29) -> 155 | I30: =SUM(I28:I29) -> 202 | J30: =SUM(J28:J29) -> 165 | K30: =SUM(K28:K29) -> 216 | L30: =SUM(L28:L29) -> 221 | ... AF30: =SUM(AF28:AF29) -> 226 | AG30: =SUM(E30:AF30) -> 5941
A32: II | B32: DATA PENGGUNAAN SURAT SUARA
A33: 1 | B33: Jumlah surat suara yang diterima, termasuk surat suara cadangan 2,5% dari DPT | E33: 265 | F33: 255 | G33: 270 | H33: 233 | I33: 257 | J33: 219 | K33: 275 | L33: 293 | M33: 296 | N33: 293 | O33: 255 | P33: 219 | Q33: 227 | R33: 286 | S33: 295 | T33: 294 | U33: 290 | V33: 292 | W33: 298 | X33: 294 | Y33: 296 | Z33: 264 | AA33: 289 | AB33: 248 | AC33: 253 | AD33: 304 | AE33: 285 | AF33: 273 | AG33: =SUM(E33:AF33) -> 7618
A34: 2 | B34: Jumlah surat suara yang digunakan | E34: 205 | F34: 197 | G34: 197 | H34: 155 | I34: 202 | J34: 165 | K34: 216 | L34: 221 | M34: 244 | N34: 244 | O34: 198 | P34: 177 | Q34: 180 | R34: 231 | S34: 216 | T34: 224 | U34: 204 | V34: 241 | W34: 216 | X34: 232 | Y34: 247 | Z34: 223 | AA34: 223 | AB34: 198 | AC34: 207 | AD34: 219 | AE34: 233 | AF34: 226 | AG34: =SUM(E34:AF34) -> 5941
A35: 3 | B35: Jumlah surat suara dikembalikan oleh pemilih (karena rusak atau keliru coblos) | E35: 0 | F35: 0 | G35: 0 | H35: 0 | I35: 0 | J35: 0 | K35: 0 | L35: 0 | M35: 0 | N35: 0 | O35: 1 | P35: 0 | Q35: 0 | R35: 0 | S35: 0 | T35: 0 | U35: 1 | V35: 0 | W35: 0 | X35: 0 | Y35: 0 | Z35: 0 | AA35: 0 | AB35: 0 | AC35: 1 | AD35: 0 | AE35: 0 | AF35: 0 | AG35: =SUM(E35:AF35) -> 3
A36: 4 | B36: Jumlah surat suara yang tidak digunakan/tidak terpakai, termasuk sisa surat suara cadangan | E36: =E33-(E34+E35) -> 60 | F36: =F33-(F34+F35) -> 58 | G36: =G33-(G34+G35) -> 73 | H36: =H33-(H34+H35) -> 78 | I36: =I33-(I34+I35) -> 55 | J36: =J33-(J34+J35) -> 54 | K36: =K33-(K34+K35) -> 59 | L36: =L33-(L34+L35) -> 72 | ... AF36: =AF33-(AF34+AF35) -> 47 | AG36: =SUM(E36:AF36) -> 1674
A38: III | B38: DATA PEMILIH DISABILITAS
B39: Jumlah seluruh Pemilih disabilitas yang menggunakan hak pilih | D39: LK | E39: 0 | F39: 0 | G39: 0 | H39: 0 | I39: 0 | J39: 0 | K39: 1 | L39: 0 | M39: 0 | N39: 0 | O39: 0 | P39: 0 | Q39: 0 | R39: 0 | S39: 0 | T39: 0 | U39: 0 | V39: 0 | W39: 0 | X39: 0 | Y39: 0 | Z39: 0 | AA39: 0 | AB39: 0 | AC39: 0 | AD39: 0 | AE39: 1 | AF39: 1 | AG39: =SUM(E39:AF39) -> 3
D40: PR | E40: 0 | F40: 0 | G40: 0 | H40: 0 | I40: 0 | J40: 0 | K40: 0 | L40: 0 | M40: 0 | N40: 0 | O40: 0 | P40: 0 | Q40: 0 | R40: 0 | S40: 0 | T40: 0 | U40: 0 | V40: 0 | W40: 0 | X40: 0 | Y40: 0 | Z40: 0 | AA40: 0 | AB40: 0 | AC40: 0 | AD40: 1 | AE40: 0 | AF40: 0 | AG40: =SUM(E40:AF40) -> 1
D41: JML | E41: =SUM(E39:E40) -> 0 | F41: =SUM(F39:F40) -> 0 | G41: =SUM(G39:G40) -> 0 | H41: =SUM(H39:H40) -> 0 | I41: =SUM(I39:I40) -> 0 | J41: =SUM(J39:J40) -> 0 | K41: =SUM(K39:K40) -> 1 | L41: =SUM(L39:L40) -> 0 | ... AF41: =SUM(AF39:AF40) -> 1 | AG41: =SUM(E41:AF41) -> 4
A43: IV | B43: DATA RINCIAN PEROLEHAN SUARA PASANGAN CALON BUPATI DAN WAKIL BUPATI
A44: NOMOR DAN NAMA CALON
B45: 1 | C45: H. ANIES RASYID BASWEDAN, Ph.D. - Dr. (H.C.) H. A. MUHAIMIN ISKANDAR | E45: 19 | F45: 23 | G45: 24 | H45: 21 | I45: 13 | J45: 28 | K45: 19 | L45: 15 | M45: 32 | N45: 20 | O45: 19 | P45: 39 | Q45: 31 | R45: 48 | S45: 15 | T45: 27 | U45: 16 | V45: 28 | W45: 17 | X45: 20 | Y45: 30 | Z45: 14 | AA45: 25 | AB45: 20 | AC45: 30 | AD45: 15 | AE45: 35 | AF45: 27 | AG45: =SUM(E45:AF45) -> 670
B46: 2 | C46: H. PRABOWO SUBIANTO - GIBRAN RAKABUMING RAKA | E46: 142 | F46: 135 | G46: 130 | H46: 112 | I46: 172 | J46: 87 | K46: 166 | L46: 164 | M46: 157 | N46: 198 | O46: 146 | P46: 81 | Q46: 90 | R46: 137 | S46: 146 | T46: 158 | U46: 133 | V46: 166 | W46: 118 | X46: 107 | Y46: 116 | Z46: 141 | AA46: 160 | AB46: 87 | AC46: 127 | AD46: 151 | AE46: 137 | AF46: 137 | AG46: =SUM(E46:AF46) -> 3801
B47: 3 | C47: H. GANJAR PRANOWO, S.H., M.I.P. - Prof. Dr. H. M. MAHFUD MD | E47: 40 | F47: 35 | G47: 42 | H47: 21 | I47: 13 | J47: 48 | K47: 27 | L47: 36 | M47: 50 | N47: 17 | O47: 31 | P47: 54 | Q47: 54 | R47: 40 | S47: 47 | T47: 31 | U47: 47 | V47: 43 | W47: 77 | X47: 101 | Y47: 95 | Z47: 66 | AA47: 36 | AB47: 85 | AC47: 46 | AD47: 52 | AE47: 53 | AF47: 48 | AG47: =SUM(E47:AF47) -> 1335
A49: V | B49: DATA SUARA SAH DAN TIDAK SAH
B50: A. | C50: JUMLAH SELURUH SUARA SAH | E50: =SUM(E45:E47) -> 201 | F50: =SUM(F45:F47) -> 193 | G50: =SUM(G45:G47) -> 196 | H50: =SUM(H45:H47) -> 154 | I50: =SUM(I45:I47) -> 198 | J50: =SUM(J45:J47) -> 163 | K50: =SUM(K45:K47) -> 212 | L50: =SUM(L45:L47) -> 215 | ... AF50: =SUM(AF45:AF47) -> 212 | AG50: =SUM(E50:AF50) -> 5806
B51: B. | C51: JUMLAH SUARA TIDAK SAH | E51: 4 | F51: 4 | G51: 1 | H51: 1 | I51: 4 | J51: 2 | K51: 4 | L51: 6 | M51: 5 | N51: 9 | O51: 2 | P51: 3 | Q51: 5 | R51: 6 | S51: 8 | T51: 8 | U51: 8 | V51: 4 | W51: 4 | X51: 4 | Y51: 6 | Z51: 2 | AA51: 2 | AB51: 6 | AC51: 4 | AD51: 1 | AE51: 8 | AF51: 14 | AG51: =SUM(E51:AF51) -> 135
B52: C. | C52: JUMLAH SELURUH SUARA SAH DAN SUARA TIDAK SAH (V.A + V.B) | E52: =SUM(E50:E51) -> 205 | F52: =SUM(F50:F51) -> 197 | G52: =SUM(G50:G51) -> 197 | H52: =SUM(H50:H51) -> 155 | I52: =SUM(I50:I51) -> 202 | J52: =SUM(J50:J51) -> 165 | K52: =SUM(K50:K51) -> 216 | L52: =SUM(L50:L51) -> 221 | ... AF52: =SUM(AF50:AF51) -> 226 | AG52: =SUM(E52:AF52) -> 5941

Sheet PARANGHARJO
C2: Kecamatan
C3: Kabupaten | D3: BANYUWANGI
C4: Provinsi | D4: JAWA TIMUR
C9: Kelurahan
A12: I | B12: DATA PEMILIH DAN PENGGUNAAN HAK PILIH | S12: JUMLAH AKHIR
A13: A | B13: DATA PEMILIH | E13: TPS 001 | F13: TPS 002 | G13: TPS 003 | H13: TPS 004 | I13: TPS 005 | J13: TPS 006 | K13: TPS 007 | L13: TPS 008 | M13: TPS 009 | N13: TPS 010 | O13: TPS 011 | P13: TPS 012 | Q13: TPS 013 | R13: TPS 014
B14: Jumlah Pemilih dalam Daftar Pemilih Tetap (DPT) | D14: LK | E14: 142 | F14: 126 | G14: 141 | H14: 137 | I14: 124 | J14: 138 | K14: 148 | L14: 124 | M14: 140 | N14: 140 | O14: 112 | P14: 97 | Q14: 113 | R14: 122 | S14: =SUM(E14:R14) -> 1804
D15: PR | E15: 147 | F15: 137 | G15: 137 | H15: 156 | I15: 130 | J15: 126 | K15: 134 | L15: 107 | M15: 129 | N15: 129 | O15: 121 | P15: 103 | Q15: 107 | R15: 113 | S15: =SUM(E15:R15) -> 1776
D16: JML | E16: =SUM(E14:E15) -> 289 | F16: =SUM(F14:F15) -> 263 | G16: =SUM(G14:G15) -> 278 | H16: =SUM(H14:H15) -> 293 | I16: =SUM(I14:I15) -> 254 | J16: =SUM(J14:J15) -> 264 | K16: =SUM(K14:K15) -> 282 | L16: =SUM(L14:L15) -> 231 | ... R16: =SUM(R14:R15) -> 235 | S16: =SUM(E16:R16) -> 3580
A18: B | B18: PENGGUNA HAK PILIH
B19: 1. | C19: Jumlah pengguna hak pilih dalam Daftar Pemilih Tetap (DPT) | D19: LK | E19: 114 | F19: 88 | G19: 96 | H19: 92 | I19: 83 | J19: 95 | K19: 107 | L19: 86 | M19: 110 | N19: 95 | O19: 82 | P19: 60 | Q19: 77 | R19: 91 | S19: =SUM(E19:R19) -> 1276
D20: PR | E20: 121 | F20: 104 | G20: 115 | H20: 115 | I20: 96 | J20: 105 | K20: 104 | L20: 83 | M20: 109 | N20: 113 | O20: 89 | P20: 73 | Q20: 74 | R20: 104 | S20: =SUM(E20:R20) -> 1405
D21: JML | E21: =SUM(E19:E20) -> 235 | F21: =SUM(F19:F20) -> 192 | G21: =SUM(G19:G20) -> 211 | H21: =SUM(H19:H20) -> 207 | I21: =SUM(I19:I20) -> 179 | J21: =SUM(J19:J20) -> 200 | K21: =SUM(K19:K20) -> 211 | L21: =SUM(L19:L20) -> 169 | ... R21: =SUM(R19:R20) -> 195 | S21: =SUM(E21:R21) -> 2681
B22: 2. | C22: Jumlah pengguna hak pilih dalam Daftar Pemilih Tambahan (DPTb) | D22: LK | E22: 0 | F22: 0 | G22: 0 | H22: 0 | I22: 0 | J22: 0 | K22: 0 | L22: 0 | M22: 0 | N22: 0 | O22: 0 | P22: 1 | Q22: 0 | R22: 0 | S22: =SUM(E22:R22) -> 1
D23: PR | E23: 15 | F23: 18 | G23: 4 | H23: 0 | I23: 0 | J23: 0 | K23: 0 | L23: 0 | M23: 0 | N23: 0 | O23: 0 | P23: 1 | Q23: 0 | R23: 0 | S23: =SUM(E23:R23) -> 38
D24: JML | E24: =SUM(E22:E23) -> 15 | F24: =SUM(F22:F23) -> 18 | G24: =SUM(G22:G23) -> 4 | H24: =SUM(H22:H23) -> 0 | I24: =SUM(I22:I23) -> 0 | J24: =SUM(J22:J23) -> 0 | K24: =SUM(K22:K23) -> 0 | L24: =SUM(L22:L23) -> 0 | ... R24: =SUM(R22:R23) -> 0 | S24: =SUM(E24:R24) -> 39
B25: 3. | C25: Jumlah pengguna hak pilih dalam Daftar Pemilih Khusus (DPK) | D25: LK | E25: 3 | F25: 0 | G25: 0 | H25: 0 | I25: 2 | J25: 2 | K25: 0 | L25: 1 | M25: 1 | N25: 0 | O25: 0 | P25: 1 | Q25: 1 | R25: 2 | S25: =SUM(E25:R25) -> 13
D26: PR | E26: 0 | F26: 0 | G26: 1 | H26: 0 | I26: 3 | J26: 2 | K26: 0 | L26: 1 | M26: 2 | N26: 0 | O26: 0 | P26: 6 | Q26: 1 | R26: 2 | S26: =SUM(E26:R26) -> 18
D27: JML | E27: =SUM(E25:E26) -> 3 | F27: =SUM(F25:F26) -> 0 | G27: =SUM(G25:G26) -> 1 | H27: =SUM(H25:H26) -> 0 | I27: =SUM(I25:I26) -> 5 | J27: =SUM(J25:J26) -> 4 | K27: =SUM(K25:K26) -> 0 | L27: =SUM(L25:L26) -> 2 | ... R27: =SUM(R25:R26) -> 4 | S27: =SUM(E27:R27) -> 31
B28: 4. | C28: Jumlah Pengguna Hak Pilih (B.1+B.2+B.3) | D28: LK | E28: =SUM(E19,E22,E25) -> 117 | F28: =SUM(F19,F22,F25) -> 88 | G28: =SUM(G19,G22,G25) -> 96 | H28: =SUM(H19,H22,H25) -> 92 | I28: =SUM(I19,I22,I25) -> 85 | J28: =SUM(J19,J22,J25) -> 97 | K28: =SUM(K19,K22,K25) -> 107 | L28: =SUM(L19,L22,L25) -> 87 | ... R28: =SUM(R19,R22,R25) -> 93 | S28: =SUM(E28:R28) -> 1290
D29: PR | E29: =SUM(E20,E23,E26) -> 136 | F29: =SUM(F20,F23,F26) -> 122 | G29: =SUM(G20,G23,G26) -> 120 | H29: =SUM(H20,H23,H26) -> 115 | I29: =SUM(I20,I23,I26) -> 99 | J29: =SUM(J20,J23,J26) -> 107 | K29: =SUM(K20,K23,K26) -> 104 | L29: =SUM(L20,L23,L26) -> 84 | ... R29: =SUM(R20,R23,R26) -> 106 | S29: =SUM(E29:R29) -> 1461
D30: JML | E30: =SUM(E28:E29) -> 253 | F30: =SUM(F28:F29) -> 210 | G30: =SUM(G28:G29) -> 216 | H30: =SUM(H28:H29) -> 207 | I30: =SUM(I28:I29) -> 184 | J30: =SUM(J28:J29) -> 204 | K30: =SUM(K28:K29) -> 211 | L30: =SUM(L28:L29) -> 171 | ... R30: =SUM(R28:R29) -> 199 | S30: =SUM(E30:R30) -> 2751
A32: II | B32: DATA PENGGUNAAN SURAT SUARA
A33: 1 | B33: Jumlah surat suara yang diterima, termasuk surat suara cadangan 2,5% dari DPT | E33: 285 | F33: 259 | G33: 276 | H33: 286 | I33: 251 | J33: 265 | K33: 280 | L33: 225 | M33: 266 | N33: 265 | O33: 228 | P33: 196 | Q33: 225 | R33: 230 | S33: =SUM(E33:R33) -> 3537
A34: 2 | B34: Jumlah surat suara yang digunakan | E34: 253 | F34: 210 | G34: 216 | H34: 207 | I34: 184 | J34: 204 | K34: 211 | L34: 171 | M34: 222 | N34: 208 | O34: 171 | P34: 142 | Q34: 153 | R34: 199 | S34: =SUM(E34:R34) -> 2751
A35: 3 | B35: Jumlah surat suara dikembalikan oleh pemilih (karena rusak atau keliru coblos) | E35: 0 | F35: 0 | G35: 1 | H35: 0 | I35: 0 | J35: 0 | K35: 0 | L35: 0 | M35: 0 | N35: 0 | O35: 0 | P35: 0 | Q35: 0 | R35: 0 | S35: =SUM(E35:R35) -> 1
A36: 4 | B36: Jumlah surat suara yang tidak digunakan/tidak terpakai, termasuk sisa surat suara cadangan | E36: =E33-(E34+E35) -> 32 | F36: =F33-(F34+F35) -> 49 | G36: =G33-(G34+G35) -> 59 | H36: =H33-(H34+H35) -> 79 | I36: =I33-(I34+I35) -> 67 | J36: =J33-(J34+J35) -> 61 | K36: =K33-(K34+K35) -> 69 | L36: =L33-(L34+L35) -> 54 | ... R36: =R33-(R34+R35) -> 31 | S36: =SUM(E36:R36) -> 785
A38: III | B38: DATA PEMILIH DISABILITAS
B39: Jumlah seluruh Pemilih disabilitas yang menggunakan hak pilih | D39: LK | E39: 0 | F39: 0 | G39: 0 | H39: 0 | I39: 0 | J39: 0 | K39: 0 | L39: 0 | M39: 0 | N39: 0 | O39: 0 | P39: 0 | Q39: 0 | R39: 0 | S39: =SUM(E39:R39) -> 0
D40: PR | E40: 0 | F40: 0 | G40: 0 | H40: 0 | I40: 0 | J40: 0 | K40: 0 | L40: 0 | M40: 0 | N40: 0 | O40: 0 | P40: 0 | Q40: 0 | R40: 2 | S40: =SUM(E40:R40) -> 2
D41: JML | E41: =SUM(E39:E40) -> 0 | F41: =SUM(F39:F40) -> 0 | G41: =SUM(G39:G40) -> 0 | H41: =SUM(H39:H40) -> 0 | I41: =SUM(I39:I40) -> 0 | J41: =SUM(J39:J40) -> 0 | K41: =SUM(K39:K40) -> 0 | L41: =SUM(L39:L40) -> 0 | ... R41: =SUM(R39:R40) -> 2 | S41: =SUM(E41:R41) -> 2
A43: IV | B43: DATA RINCIAN PEROLEHAN SUARA PASANGAN CALON BUPATI DAN WAKIL BUPATI
A44: NOMOR DAN NAMA CALON
B45: 1 | C45: H. ANIES RASYID BASWEDAN, Ph.D. - Dr. (H.C.) H. A. MUHAIMIN ISKANDAR | E45: 55 | F45: 34 | G45: 24 | H45: 25 | I45: 8 | J45: 6 | K45: 9 | L45: 14 | M45: 20 | N45: 6 | O45: 16 | P45: 9 | Q45: 17 | R45: 11 | S45: =SUM(E45:R45) -> 254
B46: 2 | C46: H. PRABOWO SUBIANTO - GIBRAN RAKABUMING RAKA | E46: 179 | F46: 153 | G46: 167 | H46: 149 | I46: 147 | J46: 153 | K46: 170 | L46: 120 | M46: 150 | N46: 172 | O46: 130 | P46: 96 | Q46: 97 | R46: 140 | S46: =SUM(E46:R46) -> 2023
B47: 3 | C47: H. GANJAR PRANOWO, S.H., M.I.P. - Prof. Dr. H. M. MAHFUD MD | E47: 15 | F47: 19 | G47: 20 | H47: 29 | I47: 22 | J47: 39 | K47: 28 | L47: 33 | M47: 48 | N47: 18 | O47: 20 | P47: 37 | Q47: 35 | R47: 44 | S47: =SUM(E47:R47) -> 407
A49: V | B49: DATA SUARA SAH DAN TIDAK SAH
B50: A. | C50: JUMLAH SELURUH SUARA SAH | E50: =SUM(E45:E47) -> 249 | F50: =SUM(F45:F47) -> 206 | G50: =SUM(G45:G47) -> 211 | H50: =SUM(H45:H47) -> 203 | I50: =SUM(I45:I47) -> 177 | J50: =SUM(J45:J47) -> 198 | K50: =SUM(K45:K47) -> 207 | L50: =SUM(L45:L47) -> 167 | ... R50: =SUM(R45:R47) -> 195 | S50: =SUM(E50:R50) -> 2684
B51: B. | C51: JUMLAH SUARA TIDAK SAH | E51: 4 | F51: 4 | G51: 5 | H51: 4 | I51: 7 | J51: 6 | K51: 4 | L51: 4 | M51: 4 | N51: 12 | O51: 5 | P51: 0 | Q51: 4 | R51: 4 | S51: =SUM(E51:R51) -> 67
B52: C. | C52: JUMLAH SELURUH SUARA SAH DAN SUARA TIDAK SAH (V.A + V.B) | E52: =SUM(E50:E51) -> 253 | F52: =SUM(F50:F51) -> 210 | G52: =SUM(G50:G51) -> 216 | H52: =SUM(H50:H51) -> 207 | I52: =SUM(I50:I51) -> 184 | J52: =SUM(J50:J51) -> 204 | K52: =SUM(K50:K51) -> 211 | L52: =SUM(L50:L51) -> 171 | ... R52: =SUM(R50:R51) -> 199 | S52: =SUM(E52:R52) -> 2751

Sheet BEDEWANG
C2: Kecamatan
C3: Kabupaten | D3: BANYUWANGI
C4: Provinsi | D4: JAWA TIMUR
C9: Kelurahan
A12: I | B12: DATA PEMILIH DAN PENGGUNAAN HAK PILIH | W12: JUMLAH AKHIR
A13: A | B13: DATA PEMILIH | E13: TPS 001 | F13: TPS 002 | G13: TPS 003 | H13: TPS 004 | I13: TPS 005 | J13: TPS 006 | K13: TPS 007 | L13: TPS 008 | M13: TPS 009 | N13: TPS 010 | O13: TPS 011 | P13: TPS 012 | Q13: TPS 013 | R13: TPS 014 | S13: TPS 015 | T13: TPS 016 | U13: TPS 017 | V13: TPS 018
B14: Jumlah Pemilih dalam Daftar Pemilih Tetap (DPT) | D14: LK | E14: 143 | F14: 141 | G14: 147 | H14: 147 | I14: 123 | J14: 113 | K14: 136 | L14: 122 | M14: 123 | N14: 129 | O14: 137 | P14: 145 | Q14: 131 | R14: 148 | S14: 133 | T14: 153 | U14: 111 | V14: 87 | W14: =SUM(E14:V14) -> 2369
D15: PR | E15: 149 | F15: 157 | G15: 145 | H15: 141 | I15: 133 | J15: 118 | K15: 126 | L15: 132 | M15: 128 | N15: 131 | O15: 148 | P15: 148 | Q15: 149 | R15: 134 | S15: 143 | T15: 128 | U15: 107 | V15: 79 | W15: =SUM(E15:V15) -> 2396
D16: JML | E16: =SUM(E14:E15) -> 292 | F16: =SUM(F14:F15) -> 298 | G16: =SUM(G14:G15) -> 292 | H16: =SUM(H14:H15) -> 288 | I16: =SUM(I14:I15) -> 256 | J16: =SUM(J14:J15) -> 231 | K16: =SUM(K14:K15) -> 262 | L16: =SUM(L14:L15) -> 254 | ... V16: =SUM(V14:V15) -> 166 | W16: =SUM(E16:V16) -> 4765
A18: B | B18: PENGGUNA HAK PILIH
B19: 1. | C19: Jumlah pengguna hak pilih dalam Daftar Pemilih Tetap (DPT) | D19: LK | E19: 118 | F19: 102 | G19: 113 | H19: 114 | I19: 85 | J19: 88 | K19: 106 | L19: 86 | M19: 82 | N19: 95 | O19: 95 | P19: 107 | Q19: 100 | R19: 108 | S19: 96 | T19: 108 | U19: 76 | V19: 68 | W19: =SUM(E19:V19) -> 1747
D20: PR | E20: 121 | F20: 123 | G20: 110 | H20: 113 | I20: 101 | J20: 91 | K20: 102 | L20: 97 | M20: 100 | N20: 101 | O20: 115 | P20: 114 | Q20: 122 | R20: 102 | S20: 114 | T20: 118 | U20: 83 | V20: 66 | W20: =SUM(E20:V20) -> 1893
D21: JML | E21: =SUM(E19:E20) -> 239 | F21: =SUM(F19:F20) -> 225 | G21: =SUM(G19:G20) -> 223 | H21: =SUM(H19:H20) -> 227 | I21: =SUM(I19:I20) -> 186 | J21: =SUM(J19:J20) -> 179 | K21: =SUM(K19:K20) -> 208 | L21: =SUM(L19:L20) -> 183 | ... V21: =SUM(V19:V20) -> 134 | W21: =SUM(E21:V21) -> 3640
B22: 2. | C22: Jumlah pengguna hak pilih dalam Daftar Pemilih Tambahan (DPTb) | D22: LK | E22: 0 | F22: 0 | G22: 0 | H22: 0 | I22: 0 | J22: 0 | K22: 0 | L22: 0 | M22: 0 | N22: 0 | O22: 0 | P22: 0 | Q22: 0 | R22: 0 | S22: 0 | T22: 0 | U22: 0 | V22: 0 | W22: =SUM(E22:V22) -> 0
D23: PR | E23: 0 | F23: 0 | G23: 0 | H23: 0 | I23: 0 | J23: 0 | K23: 0 | L23: 0 | M23: 0 | N23: 0 | O23: 0 | P23: 0 | Q23: 0 | R23: 0 | S23: 0 | T23: 0 | U23: 0 | V23: 0 | W23: =SUM(E23:V23) -> 0
D24: JML | E24: =SUM(E22:E23) -> 0 | F24: =SUM(F22:F23) -> 0 | G24: =SUM(G22:G23) -> 0 | H24: =SUM(H22:H23) -> 0 | I24: =SUM(I22:I23) -> 0 | J24: =SUM(J22:J23) -> 0 | K24: =SUM(K22:K23) -> 0 | L24: =SUM(L22:L23) -> 0 | ... V24: =SUM(V22:V23) -> 0 | W24: =SUM(E24:V24) -> 0
B25: 3. | C25: Jumlah pengguna hak pilih dalam Daftar Pemilih Khusus (DPK) | D25: LK | E25: 0 | F25: 0 | G25: 0 | H25: 1 | I25: 0 | J25: 0 | K25: 0 | L25: 0 | M25: 0 | N25: 0 | O25: 0 | P25: 0 | Q25: 0 | R25: 0 | S25: 0 | T25: 1 | U25: 0 | V25: 1 | W25: =SUM(E25:V25) -> 3
D26: PR | E26: 0 | F26: 0 | G26: 0 | H26: 0 | I26: 0 | J26: 0 | K26: 0 | L26: 0 | M26: 0 | N26: 0 | O26: 0 | P26: 0 | Q26: 0 | R26: 0 | S26: 0 | T26: 0 | U26: 0 | V26: 1 | W26: =SUM(E26:V26) -> 1
D27: JML | E27: =SUM(E25:E26) -> 0 | F27: =SUM(F25:F26) -> 0 | G27: =SUM(G25:G26) -> 0 | H27: =SUM(H25:H26) -> 1 | I27: =SUM(I25:I26) -> 0 | J27: =SUM(J25:J26) -> 0 | K27: =SUM(K25:K26) -> 0 | L27: =SUM(L25:L26) -> 0 | ... V27: =SUM(V25:V26) -> 2 | W27: =SUM(E27:V27) -> 4
B28: 4. | C28: Jumlah Pengguna Hak Pilih (B.1+B.2+B.3) | D28: LK | E28: =SUM(E19,E22,E25) -> 118 | F28: =SUM(F19,F22,F25) -> 102 | G28: =SUM(G19,G22,G25) -> 113 | H28: =SUM(H19,H22,H25) -> 115 | I28: =SUM(I19,I22,I25) -> 85 | J28: =SUM(J19,J22,J25) -> 88 | K28: =SUM(K19,K22,K25) -> 106 | L28: =SUM(L19,L22,L25) -> 86 | ... V28: =SUM(V19,V22,V25) -> 69 | W28: =SUM(E28:V28) -> 1750
D29: PR | E29: =SUM(E20,E23,E26) -> 121 | F29: =SUM(F20,F23,F26) -> 123 | G29: =SUM(G20,G23,G26) -> 110 | H29: =SUM(H20,H23,H26) -> 113 | I29: =SUM(I20,I23,I26) -> 101 | J29: =SUM(J20,J23,J26) -> 91 | K29: =SUM(K20,K23,K26) -> 102 | L29: =SUM(L20,L23,L26) -> 97 | ... V29: =SUM(V20,V23,V26) -> 67 | W29: =SUM(E29:V29) -> 1894
D30: JML | E30: =SUM(E28:E29) -> 239 | F30: =SUM(F28:F29) -> 225 | G30: =SUM(G28:G29) -> 223 | H30: =SUM(H28:H29) -> 228 | I30: =SUM(I28:I29) -> 186 | J30: =SUM(J28:J29) -> 179 | K30: =SUM(K28:K29) -> 208 | L30: =SUM(L28:L29) -> 183 | ... V30: =SUM(V28:V29) -> 136 | W30: =SUM(E30:V30) -> 3644
A32: II | B32: DATA PENGGUNAAN SURAT SUARA
A33: 1 | B33: Jumlah surat suara yang diterima, termasuk surat suara cadangan 2,5% dari DPT | E33: 298 | F33: 304 | G33: 298 | H33: 299 | I33: 259 | J33: 226 | K33: 257 | L33: 250 | M33: 257 | N33: 256 | O33: 291 | P33: 293 | Q33: 286 | R33: 288 | S33: 282 | T33: 286 | U33: 213 | V33: 170 | W33: =SUM(E33:V33) -> 4813
A34: 2 | B34: Jumlah surat suara yang digunakan | E34: 239 | F34: 225 | G34: 223 | H34: 228 | I34: 186 | J34: 179 | K34: 208 | L34: 183 | M34: 182 | N34: 196 | O34: 210 | P34: 221 | Q34: 222 | R34: 210 | S34: 210 | T34: 227 | U34: 159 | V34: 136 | W34: =SUM(E34:V34) -> 3644
A35: 3 | B35: Jumlah surat suara dikembalikan oleh pemilih (karena rusak atau keliru coblos) | E35: 1 | F35: 0 | G35: 0 | H35: 0 | I35: 0 | J35: 0 | K35: 0 | L35: 0 | M35: 0 | N35: 0 | O35: 0 | P35: 0 | Q35: 0 | R35: 0 | S35: 0 | T35: 0 | U35: 0 | V35: 0 | W35: =SUM(E35:V35) -> 1
A36: 4 | B36: Jumlah surat suara yang tidak digunakan/tidak terpakai, termasuk sisa surat suara cadangan | E36: =E33-(E34+E35) -> 58 | F36: =F33-(F34+F35) -> 79 | G36: =G33-(G34+G35) -> 75 | H36: =H33-(H34+H35) -> 71 | I36: =I33-(I34+I35) -> 73 | J36: =J33-(J34+J35) -> 47 | K36: =K33-(K34+K35) -> 49 | L36: =L33-(L34+L35) -> 67 | ... V36: =V33-(V34+V35) -> 34 | W36: =SUM(E36:V36) -> 1168
A38: III | B38: DATA PEMILIH DISABILITAS
B39: Jumlah seluruh Pemilih disabilitas yang menggunakan hak pilih | D39: LK | E39: 0 | F39: 0 | G39: 0 | H39: 2 | I39: 0 | J39: 0 | K39: 0 | L39: 0 | M39: 0 | N39: 0 | O39: 0 | P39: 1 | Q39: 0 | R39: 0 | S39: 0 | T39: 1 | U39: 0 | V39: 0 | W39: =SUM(E39:V39) -> 4
D40: PR | E40: 0 | F40: 0 | G40: 0 | H40: 1 | I40: 1 | J40: 0 | K40: 0 | L40: 0 | M40: 0 | N40: 0 | O40: 0 | P40: 1 | Q40: 0 | R40: 0 | S40: 0 | T40: 1 | U40: 0 | V40: 0 | W40: =SUM(E40:V40) -> 4
D41: JML | E41: =SUM(E39:E40) -> 0 | F41: =SUM(F39:F40) -> 0 | G41: =SUM(G39:G40) -> 0 | H41: =SUM(H39:H40) -> 3 | I41: =SUM(I39:I40) -> 1 | J41: =SUM(J39:J40) -> 0 | K41: =SUM(K39:K40) -> 0 | L41: =SUM(L39:L40) -> 0 | ... V41: =SUM(V39:V40) -> 0 | W41: =SUM(E41:V41) -> 8
A43: IV | B43: DATA RINCIAN PEROLEHAN SUARA PASANGAN CALON BUPATI DAN WAKIL BUPATI
A44: NOMOR DAN NAMA CALON
B45: 1 | C45: H. ANIES RASYID BASWEDAN, Ph.D. - Dr. (H.C.) H. A. MUHAIMIN ISKANDAR | E45: 12 | F45: 16 | G45: 6 | H45: 21 | I45: 31 | J45: 22 | K45: 34 | L45: 27 | M45: 16 | N45: 11 | O45: 24 | P45: 24 | Q45: 26 | R45: 4 | S45: 20 | T45: 11 | U45: 20 | V45: 4 | W45: =SUM(E45:V45) -> 329
B46: 2 | C46: H. PRABOWO SUBIANTO - GIBRAN RAKABUMING RAKA | E46: 185 | F46: 151 | G46: 183 | H46: 190 | I46: 129 | J46: 130 | K46: 122 | L46: 118 | M46: 125 | N46: 166 | O46: 150 | P46: 142 | Q46: 166 | R46: 181 | S46: 141 | T46: 180 | U46: 108 | V46: 117 | W46: =SUM(E46:V46) -> 2684
B47: 3 | C47: H. GANJAR PRANOWO, S.H., M.I.P. - Prof. Dr. H. M. MAHFUD MD | E47: 37 | F47: 56 | G47: 27 | H47: 12 | I47: 24 | J47: 22 | K47: 43 | L47: 35 | M47: 38 | N47: 16 | O47: 30 | P47: 49 | Q47: 22 | R47: 23 | S47: 43 | T47: 26 | U47: 26 | V47: 14 | W47: =SUM(E47:V47) -> 543
A49: V | B49: DATA SUARA SAH DAN TIDAK SAH
B50: A. | C50: JUMLAH SELURUH SUARA SAH | E50: =SUM(E45:E47) -> 234 | F50: =SUM(F45:F47) -> 223 | G50: =SUM(G45:G47) -> 216 | H50: =SUM(H45:H47) -> 223 | I50: =SUM(I45:I47) -> 184 | J50: =SUM(J45:J47) -> 174 | K50: =SUM(K45:K47) -> 199 | L50: =SUM(L45:L47) -> 180 | ... S50: =SUM(S45:S47) -> 204 | T50: 227 | U50: 154 | V50: =SUM(V45:V47) -> 135 | W50: =SUM(E50:V50) -> 3566
B51: B. | C51: JUMLAH SUARA TIDAK SAH | E51: 5 | F51: 2 | G51: 7 | H51: 5 | I51: 2 | J51: 5 | K51: 9 | L51: 3 | M51: 3 | N51: 3 | O51: 6 | P51: 6 | Q51: 8 | R51: 2 | S51: 6 | T51: 0 | U51: 5 | V51: 1 | W51: =SUM(E51:V51) -> 78
B52: C. | C52: JUMLAH SELURUH SUARA SAH DAN SUARA TIDAK SAH (V.A + V.B) | E52: =SUM(E50:E51) -> 239 | F52: =SUM(F50:F51) -> 225 | G52: =SUM(G50:G51) -> 223 | H52: =SUM(H50:H51) -> 228 | I52: =SUM(I50:I51) -> 186 | J52: =SUM(J50:J51) -> 179 | K52: =SUM(K50:K51) -> 208 | L52: =SUM(L50:L51) -> 183 | ... V52: =SUM(V50:V51) -> 136 | W52: =SUM(E52:V52) -> 3644

Sheet BAYU
C2: Kecamatan
C3: Kabupaten | D3: BANYUWANGI
C4: Provinsi | D4: JAWA TIMUR
C9: Kelurahan
A12: I | B12: DATA PEMILIH DAN PENGGUNAAN HAK PILIH | AB12: JUMLAH AKHIR
A13: A | B13: DATA PEMILIH | E13: TPS 001 | F13: TPS 002 | G13: TPS 003 | H13: TPS 004 | I13: TPS 005 | J13: TPS 006 | K13: TPS 007 | L13: TPS 008 | M13: TPS 009 | N13: TPS 010 | O13: TPS 011 | P13: TPS 012 | Q13: TPS 013 | R13: TPS 014 | S13: TPS 015 | T13: TPS 016 | U13: TPS 017 | V13: TPS 018 | W13: TPS 019 | X13: TPS 020 | Y13: TPS 021 | Z13: TPS 022 | AA13: TPS 023
B14: Jumlah Pemilih dalam Daftar Pemilih Tetap (DPT) | D14: LK | E14: 109 | F14: 118 | G14: 129 | H14: 125 | I14: 117 | J14: 132 | K14: 139 | L14: 132 | M14: 137 | N14: 140 | O14: 139 | P14: 128 | Q14: 127 | R14: 131 | S14: 83 | T14: 133 | U14: 139 | V14: 149 | W14: 140 | X14: 152 | Y14: 150 | Z14: 150 | AA14: 147 | AB14: =SUM(E14:AA14) -> 3046
D15: PR | E15: 118 | F15: 140 | G15: 133 | H15: 136 | I15: 140 | J15: 123 | K15: 131 | L15: 146 | M15: 141 | N15: 148 | O15: 135 | P15: 134 | Q15: 123 | R15: 117 | S15: 94 | T15: 151 | U15: 147 | V15: 139 | W15: 151 | X15: 144 | Y15: 144 | Z15: 148 | AA15: 146 | AB15: =SUM(E15:AA15) -> 3129
D16: JML | E16: =SUM(E14:E15) -> 227 | F16: =SUM(F14:F15) -> 258 | G16: =SUM(G14:G15) -> 262 | H16: =SUM(H14:H15) -> 261 | I16: =SUM(I14:I15) -> 257 | J16: =SUM(J14:J15) -> 255 | K16: =SUM(K14:K15) -> 270 | L16: =SUM(L14:L15) -> 278 | ... AA16: =SUM(AA14:AA15) -> 293 | AB16: =SUM(E16:AA16) -> 6175
A18: B | B18: PENGGUNA HAK PILIH
B19: 1. | C19: Jumlah pengguna hak pilih dalam Daftar Pemilih Tetap (DPT) | D19: LK | E19: 95 | F19: 107 | G19: 92 | H19: 103 | I19: 96 | J19: 93 | K19: 100 | L19: 98 | M19: 94 | N19: 108 | O19: 97 | P19: 74 | Q19: 92 | R19: 100 | S19: 66 | T19: 83 | U19: 94 | V19: 103 | W19: 103 | X19: 122 | Y19: 117 | Z19: 121 | AA19: 108 | AB19: =SUM(E19:AA19) -> 2266
D20: PR | E20: 96 | F20: 87 | G20: 105 | H20: 107 | I20: 119 | J20: 106 | K20: 105 | L20: 117 | M20: 107 | N20: 120 | O20: 101 | P20: 88 | Q20: 93 | R20: 100 | S20: 81 | T20: 117 | U20: 116 | V20: 115 | W20: 120 | X20: 106 | Y20: 119 | Z20: 106 | AA20: 109 | AB20: =SUM(E20:AA20) -> 2440
D21: JML | E21: =SUM(E19:E20) -> 191 | F21: =SUM(F19:F20) -> 194 | G21: =SUM(G19:G20) -> 197 | H21: =SUM(H19:H20) -> 210 | I21: =SUM(I19:I20) -> 215 | J21: =SUM(J19:J20) -> 199 | K21: =SUM(K19:K20) -> 205 | L21: =SUM(L19:L20) -> 215 | ... AA21: =SUM(AA19:AA20) -> 217 | AB21: =SUM(E21:AA21) -> 4706
B22: 2. | C22: Jumlah pengguna hak pilih dalam Daftar Pemilih Tambahan (DPTb) | D22: LK | E22: 0 | F22: 0 | G22: 0 | H22: 0 | I22: 0 | J22: 0 | K22: 0 | L22: 0 | M22: 0 | N22: 1 | O22: 1 | P22: 0 | Q22: 0 | R22: 0 | S22: 0 | T22: 0 | U22: 0 | V22: 0 | W22: 0 | X22: 0 | Y22: 0 | Z22: 0 | AA22: 0 | AB22: =SUM(E22:AA22) -> 2
D23: PR | E23: 0 | F23: 0 | G23: 0 | H23: 0 | I23: 0 | J23: 0 | K23: 0 | L23: 0 | M23: 0 | N23: 0 | O23: 0 | P23: 0 | Q23: 0 | R23: 0 | S23: 0 | T23: 0 | U23: 0 | V23: 0 | W23: 0 | X23: 0 | Y23: 0 | Z23: 0 | AA23: 0 | AB23: =SUM(E23:AA23) -> 0
D24: JML | E24: =SUM(E22:E23) -> 0 | F24: =SUM(F22:F23) -> 0 | G24: =SUM(G22:G23) -> 0 | H24: =SUM(H22:H23) -> 0 | I24: =SUM(I22:I23) -> 0 | J24: =SUM(J22:J23) -> 0 | K24: =SUM(K22:K23) -> 0 | L24: =SUM(L22:L23) -> 0 | ... AA24: =SUM(AA22:AA23) -> 0 | AB24: =SUM(E24:AA24) -> 2
B25: 3. | C25: Jumlah pengguna hak pilih dalam Daftar Pemilih Khusus (DPK) | D25: LK | E25: 0 | F25: 0 | G25: 1 | H25: 3 | I25: 0 | J25: 0 | K25: 0 | L25: 0 | M25: 0 | N25: 0 | O25: 0 | P25: 0 | Q25: 0 | R25: 0 | S25: 1 | T25: 2 | U25: 1 | V25: 1 | W25: 0 | X25: 0 | Y25: 2 | Z25: 1 | AA25: 0 | AB25: =SUM(E25:AA25) -> 12
D26: PR | E26: 0 | F26: 0 | G26: 0 | H26: 1 | I26: 0 | J26: 0 | K26: 0 | L26: 1 | M26: 1 | N26: 1 | O26: 0 | P26: 0 | Q26: 0 | R26: 0 | S26: 1 | T26: 1 | U26: 0 | V26: 1 | W26: 1 | X26: 0 | Y26: 0 | Z26: 1 | AA26: 0 | AB26: =SUM(E26:AA26) -> 9
D27: JML | E27: =SUM(E25:E26) -> 0 | F27: =SUM(F25:F26) -> 0 | G27: =SUM(G25:G26) -> 1 | H27: =SUM(H25:H26) -> 4 | I27: =SUM(I25:I26) -> 0 | J27: =SUM(J25:J26) -> 0 | K27: =SUM(K25:K26) -> 0 | L27: =SUM(L25:L26) -> 1 | ... AA27: =SUM(AA25:AA26) -> 0 | AB27: =SUM(E27:AA27) -> 21
B28: 4. | C28: Jumlah Pengguna Hak Pilih (B.1+B.2+B.3) | D28: LK | E28: =SUM(E19,E22,E25) -> 95 | F28: =SUM(F19,F22,F25) -> 107 | G28: =SUM(G19,G22,G25) -> 93 | H28: =SUM(H19,H22,H25) -> 106 | I28: =SUM(I19,I22,I25) -> 96 | J28: =SUM(J19,J22,J25) -> 93 | K28: =SUM(K19,K22,K25) -> 100 | L28: =SUM(L19,L22,L25) -> 98 | ... AA28: =SUM(AA19,AA22,AA25) -> 108 | AB28: =SUM(E28:AA28) -> 2280
D29: PR | E29: =SUM(E20,E23,E26) -> 96 | F29: =SUM(F20,F23,F26) -> 87 | G29: =SUM(G20,G23,G26) -> 105 | H29: =SUM(H20,H23,H26) -> 108 | I29: =SUM(I20,I23,I26) -> 119 | J29: =SUM(J20,J23,J26) -> 106 | K29: =SUM(K20,K23,K26) -> 105 | L29: =SUM(L20,L23,L26) -> 118 | ... AA29: =SUM(AA20,AA23,AA26) -> 109 | AB29: =SUM(E29:AA29) -> 2449
D30: JML | E30: =SUM(E28:E29) -> 191 | F30: =SUM(F28:F29) -> 194 | G30: =SUM(G28:G29) -> 198 | H30: =SUM(H28:H29) -> 214 | I30: =SUM(I28:I29) -> 215 | J30: =SUM(J28:J29) -> 199 | K30: =SUM(K28:K29) -> 205 | L30: =SUM(L28:L29) -> 216 | ... AA30: =SUM(AA28:AA29) -> 217 | AB30: =SUM(E30:AA30) -> 4729
A32: II | B32: DATA PENGGUNAAN SURAT SUARA
A33: 1 | B33: Jumlah surat suara yang diterima, termasuk surat suara cadangan 2,5% dari DPT | E33: 233 | F33: 259 | G33: 258 | H33: 259 | I33: 251 | J33: 250 | K33: 252 | L33: 284 | M33: 284 | N33: 295 | O33: 274 | P33: 267 | Q33: 256 | R33: 253 | S33: 181 | T33: 290 | U33: 315 | V33: 282 | W33: 298 | X33: 302 | Y33: 300 | Z33: 308 | AA33: 290 | AB33: =SUM(E33:AA33) -> 6241
A34: 2 | B34: Jumlah surat suara yang digunakan | E34: 191 | F34: 194 | G34: 198 | H34: 214 | I34: 215 | J34: 199 | K34: 205 | L34: 216 | M34: 202 | N34: 230 | O34: 199 | P34: 162 | Q34: 185 | R34: 200 | S34: 149 | T34: 203 | U34: 211 | V34: 220 | W34: 224 | X34: 228 | Y34: 238 | Z34: 229 | AA34: 217 | AB34: =SUM(E34:AA34) -> 4729
A35: 3 | B35: Jumlah surat suara dikembalikan oleh pemilih (karena rusak atau keliru coblos) | E35: 0 | F35: 0 | G35: 5 | H35: 0 | I35: 2 | J35: 2 | K35: 0 | L35: 0 | M35: 0 | N35: 0 | O35: 0 | P35: 0 | Q35: 0 | R35: 9 | S35: 0 | T35: 0 | U35: 0 | V35: 0 | W35: 0 | X35: 0 | Y35: 0 | Z35: 0 | AA35: 0 | AB35: =SUM(E35:AA35) -> 18
A36: 4 | B36: Jumlah surat suara yang tidak digunakan/tidak terpakai, termasuk sisa surat suara cadangan | E36: =E33-(E34+E35) -> 42 | F36: =F33-(F34+F35) -> 65 | G36: =G33-(G34+G35) -> 55 | H36: =H33-(H34+H35) -> 45 | I36: =I33-(I34+I35) -> 34 | J36: =J33-(J34+J35) -> 49 | K36: =K33-(K34+K35) -> 47 | L36: =L33-(L34+L35) -> 68 | ... AA36: =AA33-(AA34+AA35) -> 73 | AB36: =SUM(E36:AA36) -> 1494
A38: III | B38: DATA PEMILIH DISABILITAS
B39: Jumlah seluruh Pemilih disabilitas yang menggunakan hak pilih | D39: LK | E39: 0 | F39: 0 | G39: 1 | H39: 0 | I39: 0 | J39: 0 | K39: 0 | L39: 0 | M39: 0 | N39: 0 | O39: 0 | P39: 0 | Q39: 0 | R39: 0 | S39: 0 | T39: 0 | U39: 0 | V39: 0 | W39: 0 | X39: 0 | Y39: 0 | Z39: 0 | AA39: 0 | AB39: =SUM(E39:AA39) -> 1
D40: PR | E40: 0 | F40: 0 | G40: 0 | H40: 0 | I40: 0 | J40: 0 | K40: 0 | L40: 0 | M40: 0 | N40: 0 | O40: 0 | P40: 0 | Q40: 0 | R40: 0 | S40: 0 | T40: 0 | U40: 0 | V40: 0 | W40: 0 | X40: 0 | Y40: 0 | Z40: 0 | AA40: 1 | AB40: =SUM(E40:AA40) -> 1
D41: JML | E41: =SUM(E39:E40) -> 0 | F41: =SUM(F39:F40) -> 0 | G41: =SUM(G39:G40) -> 1 | H41: =SUM(H39:H40) -> 0 | I41: =SUM(I39:I40) -> 0 | J41: =SUM(J39:J40) -> 0 | K41: =SUM(K39:K40) -> 0 | L41: =SUM(L39:L40) -> 0 | ... AA41: =SUM(AA39:AA40) -> 1 | AB41: =SUM(E41:AA41) -> 2
A43: IV | B43: DATA RINCIAN PEROLEHAN SUARA PASANGAN CALON BUPATI DAN WAKIL BUPATI
A44: NOMOR DAN NAMA CALON
B45: 1 | C45: H. ANIES RASYID BASWEDAN, Ph.D. - Dr. (H.C.) H. A. MUHAIMIN ISKANDAR | E45: 8 | F45: 7 | G45: 6 | H45: 30 | I45: 19 | J45: 13 | K45: 8 | L45: 9 | M45: 15 | N45: 18 | O45: 11 | P45: 23 | Q45: 23 | R45: 11 | S45: 6 | T45: 23 | U45: 25 | V45: 31 | W45: 24 | X45: 3 | Y45: 4 | Z45: 10 | AA45: 12 | AB45: =SUM(E45:AA45) -> 339
B46: 2 | C46: H. PRABOWO SUBIANTO - GIBRAN RAKABUMING RAKA | E46: 141 | F46: 154 | G46: 147 | H46: 133 | I46: 165 | J46: 145 | K46: 146 | L46: 147 | M46: 136 | N46: 184 | O46: 145 | P46: 114 | Q46: 142 | R46: 164 | S46: 137 | T46: 128 | U46: 134 | V46: 124 | W46: 147 | X46: 160 | Y46: 167 | Z46: 184 | AA46: 158 | AB46: =SUM(E46:AA46) -> 3402
B47: 3 | C47: H. GANJAR PRANOWO, S.H., M.I.P. - Prof. Dr. H. M. MAHFUD MD | E47: 29 | F47: 29 | G47: 41 | H47: 43 | I47: 26 | J47: 33 | K47: 50 | L47: 53 | M47: 46 | N47: 23 | O47: 32 | P47: 20 | Q47: 14 | R47: 24 | S47: 3 | T47: 47 | U47: 44 | V47: 61 | W47: 47 | X47: 63 | Y47: 56 | Z47: 27 | AA47: 42 | AB47: =SUM(E47:AA47) -> 853
A49: V | B49: DATA SUARA SAH DAN TIDAK SAH
