Workbook

Sheet PPWP
C8: Kecamatan | D8: GLENMORE
C9: Kabupaten | D9: BANYUWANGI
C10: Provinsi | D10: JAWA TIMUR
A12: I | B12: DATA PEMILIH DAN PENGGUNAAN HAK PILIH | E12: JUMLAH AKHIR
A13: A | B13: DATA PEMILIH
B14: Jumlah Pemilih dalam Daftar Pemilih Tetap (DPT) | D14: LK | E14: =BUMIHARJO!AE14+KARANGHARJO!BK14+MARGOMULYO!S14+SEPANJANG!AJ14+SUMBERGONDO!AB14+TEGALHARJO!AP14+TULUNGREJO!BL14 -> 29418
D15: PR | E15: =BUMIHARJO!AE15+KARANGHARJO!BK15+MARGOMULYO!S15+SEPANJANG!AJ15+SUMBERGONDO!AB15+TEGALHARJO!AP15+TULUNGREJO!BL15 -> 30287
D16: JML | E16: =SUM(E14:E15) -> 59705
A18: B | B18: PENGGUNA HAK PILIH
B19: 1. | C19: Jumlah pengguna hak pilih dalam Daftar Pemilih Tetap (DPT) | D19: LK | E19: =BUMIHARJO!AE19+KARANGHARJO!BK19+MARGOMULYO!S19+SEPANJANG!AJ19+SUMBERGONDO!AB19+TEGALHARJO!AP19+TULUNGREJO!BL19 -> 21580
D20: PR | E20: =BUMIHARJO!AE20+KARANGHARJO!BK20+MARGOMULYO!S20+SEPANJANG!AJ20+SUMBERGONDO!AB20+TEGALHARJO!AP20+TULUNGREJO!BL20 -> 23932
D21: JML | E21: =SUM(E19:E20) -> 45512
B22: 2. | C22: Jumlah pengguna hak pilih dalam Daftar Pemilih Tambahan (DPTb) | D22: LK | E22: =BUMIHARJO!AE22+KARANGHARJO!BK22+MARGOMULYO!S22+SEPANJANG!AJ22+SUMBERGONDO!AB22+TEGALHARJO!AP22+TULUNGREJO!BL22 -> 102
D23: PR | E23: =BUMIHARJO!AE23+KARANGHARJO!BK23+MARGOMULYO!S23+SEPANJANG!AJ23+SUMBERGONDO!AB23+TEGALHARJO!AP23+TULUNGREJO!BL23 -> 75
D24: JML | E24: =SUM(E22:E23) -> 177
B25: 3. | C25: Jumlah pengguna hak pilih dalam Daftar Pemilih Khusus (DPK) | D25: LK | E25: =BUMIHARJO!AE25+KARANGHARJO!BK25+MARGOMULYO!S25+SEPANJANG!AJ25+SUMBERGONDO!AB25+TEGALHARJO!AP25+TULUNGREJO!BL25 -> 146
D26: PR | E26: =BUMIHARJO!AE26+KARANGHARJO!BK26+MARGOMULYO!S26+SEPANJANG!AJ26+SUMBERGONDO!AB26+TEGALHARJO!AP26+TULUNGREJO!BL26 -> 199
D27: JML | E27: =SUM(E25:E26) -> 345
B28: 4. | C28: Jumlah Pengguna Hak Pilih (B.1+B.2+B.3) | D28: LK | E28: =E19+E22+E25 -> 21828
D29: PR | E29: =E20+E23+E26 -> 24206
D30: JML | E30: =SUM(E28:E29) -> 46034
A32: II | B32: DATA PENGGUNAAN SURAT SUARA
A33: 1 | B33: Jumlah surat suara yang diterima, termasuk surat suara cadangan 2,5% dari DPT | E33: =BUMIHARJO!AE33+KARANGHARJO!BK33+MARGOMULYO!S33+SEPANJANG!AJ33+SUMBERGONDO!AB33+TEGALHARJO!AP33+TULUNGREJO!BL33 -> 61182
A34: 2 | B34: Jumlah surat suara yang digunakan | E34: =BUMIHARJO!AE34+KARANGHARJO!BK34+MARGOMULYO!S34+SEPANJANG!AJ34+SUMBERGONDO!AB34+TEGALHARJO!AP34+TULUNGREJO!BL34 -> 46034
A35: 3 | B35: Jumlah surat suara dikembalikan oleh pemilih (karena rusak atau keliru coblos) | E35: =BUMIHARJO!AE35+KARANGHARJO!BK35+MARGOMULYO!S35+SEPANJANG!AJ35+SUMBERGONDO!AB35+TEGALHARJO!AP35+TULUNGREJO!BL35 -> 51
A36: 4 | B36: Jumlah surat suara yang tidak digunakan/tidak terpakai, termasuk sisa surat suara cadangan | E36: =E33-(E34+E35) -> 15097
A38: III | B38: DATA PEMILIH DISABILITAS
B39: Jumlah seluruh Pemilih disabilitas yang menggunakan hak pilih | D39: LK | E39: =BUMIHARJO!AE39+KARANGHARJO!BK39+MARGOMULYO!S39+SEPANJANG!AJ39+SUMBERGONDO!AB39+TEGALHARJO!AP39+TULUNGREJO!BL39 -> 38
D40: PR | E40: =BUMIHARJO!AE40+KARANGHARJO!BK40+MARGOMULYO!S40+SEPANJANG!AJ40+SUMBERGONDO!AB40+TEGALHARJO!AP40+TULUNGREJO!BL40 -> 66
D41: JML | E41: =SUM(E39:E40) -> 104
A43: IV | B43: DATA RINCIAN PEROLEHAN SUARA PASANGAN CALON BUPATI DAN WAKIL BUPATI
A44: NOMOR DAN NAMA CALON
B45: 1 | C45: H. ANIES RASYID BASWEDAN, Ph.D. - Dr. (H.C.) H. A. MUHAIMIN ISKANDAR | E45: =BUMIHARJO!AE45+KARANGHARJO!BK45+MARGOMULYO!S45+SEPANJANG!AJ45+SUMBERGONDO!AB45+TEGALHARJO!AP45+TULUNGREJO!BL45 -> 5805
B46: 2 | C46: H. PRABOWO SUBIANTO - GIBRAN RAKABUMING RAKA | E46: =BUMIHARJO!AE46+KARANGHARJO!BK46+MARGOMULYO!S46+SEPANJANG!AJ46+SUMBERGONDO!AB46+TEGALHARJO!AP46+TULUNGREJO!BL46 -> 33714
B47: 3 | C47: H. GANJAR PRANOWO, S.H., M.I.P. - Prof. Dr. H. M. MAHFUD MD | E47: =BUMIHARJO!AE47+KARANGHARJO!BK47+MARGOMULYO!S47+SEPANJANG!AJ47+SUMBERGONDO!AB47+TEGALHARJO!AP47+TULUNGREJO!BL47 -> 5747
A49: V | B49: DATA SUARA SAH DAN TIDAK SAH
B50: A. | C50: JUMLAH SELURUH SUARA SAH | E50: =BUMIHARJO!AE50+KARANGHARJO!BK50+MARGOMULYO!S50+SEPANJANG!AJ50+SUMBERGONDO!AB50+TEGALHARJO!AP50+TULUNGREJO!BL50 -> 45266
B51: B. | C51: JUMLAH SUARA TIDAK SAH | E51: =BUMIHARJO!AE51+KARANGHARJO!BK51+MARGOMULYO!S51+SEPANJANG!AJ51+SUMBERGONDO!AB51+TEGALHARJO!AP51+TULUNGREJO!BL51 -> 768
B52: C. | C52: JUMLAH SELURUH SUARA SAH DAN SUARA TIDAK SAH (V.A + V.B) | E52: =SUM(E50:E51) -> 46034

Sheet BUMIHARJO
C2: Kecamatan | D2: GLENMORE
C3: Kabupaten | D3: BANYUWANGI
C4: Provinsi | D4: JAWA TIMUR
C9: Kelurahan | D9: BUMIHARJO
A12: I | B12: DATA PEMILIH DAN PENGGUNAAN HAK PILIH | AE12: JUMLAH AKHIR
A13: A | B13: DATA PEMILIH | E13: TPS 001 | F13: TPS 002 | G13: TPS 003 | H13: TPS 004 | I13: TPS 005 | J13: TPS 006 | K13: TPS 007 | L13: TPS 008 | M13: TPS 009 | N13: TPS 010 | O13: TPS 011 | P13: TPS 012 | Q13: TPS 013 | R13: TPS 014 | S13: TPS 015 | T13: TPS 016 | U13: TPS 017 | V13: TPS 018 | W13: TPS 019 | X13: TPS 020 | Y13: TPS 021 | Z13: TPS 022 | AA13: TPS 023 | AB13: TPS 024 | AC13: TPS 025 | AD13: TPS 026
B14: Jumlah Pemilih dalam Daftar Pemilih Tetap (DPT) | D14: LK | E14: 132 | F14: 118 | G14: 130 | H14: 112 | I14: 147 | J14: 159 | K14: 144 | L14: 151 | M14: 141 | N14: 144 | O14: 122 | P14: 124 | Q14: 123 | R14: 92 | S14: 142 | T14: 126 | U14: 127 | V14: 116 | W14: 145 | X14: 142 | Y14: 119 | Z14: 140 | AA14: 108 | AB14: 103 | AC14: 123 | AD14: 138 | AE14: =SUM(E14:AD14) -> 3368
D15: PR | E15: 127 | F15: 126 | G15: 123 | H15: 114 | I15: 142 | J15: 141 | K15: 149 | L15: 145 | M15: 147 | N15: 153 | O15: 116 | P15: 128 | Q15: 116 | R15: 106 | S15: 126 | T15: 124 | U15: 145 | V15: 97 | W15: 134 | X15: 137 | Y15: 126 | Z15: 151 | AA15: 115 | AB15: 118 | AC15: 132 | AD15: 149 | AE15: =SUM(E15:AD15) -> 3387
D16: JML | E16: =SUM(E14:E15) -> 259 | F16: =SUM(F14:F15) -> 244 | G16: =SUM(G14:G15) -> 253 | H16: =SUM(H14:H15) -> 226 | I16: =SUM(I14:I15) -> 289 | J16: =SUM(J14:J15) -> 300 | K16: =SUM(K14:K15) -> 293 | L16: =SUM(L14:L15) -> 296 | ... AD16: =SUM(AD14:AD15) -> 287 | AE16: =SUM(E16:AD16) -> 6755
A18: B | B18: PENGGUNA HAK PILIH
B19: 1. | C19: Jumlah pengguna hak pilih dalam Daftar Pemilih Tetap (DPT) | D19: LK | E19: 105 | F19: 100 | G19: 94 | H19: 91 | I19: 104 | J19: 118 | K19: 109 | L19: 115 | M19: 105 | N19: 107 | O19: 87 | P19: 97 | Q19: 90 | R19: 68 | S19: 113 | T19: 89 | U19: 87 | V19: 95 | W19: 113 | X19: 101 | Y19: 87 | Z19: 96 | AA19: 77 | AB19: 76 | AC19: 80 | AD19: 95 | AE19: =SUM(E19:AD19) -> 2499
D20: PR | E20: 101 | F20: 100 | G20: 107 | H20: 93 | I20: 104 | J20: 112 | K20: 115 | L20: 114 | M20: 118 | N20: 119 | O20: 89 | P20: 116 | Q20: 93 | R20: 86 | S20: 107 | T20: 105 | U20: 112 | V20: 86 | W20: 110 | X20: 105 | Y20: 104 | Z20: 126 | AA20: 100 | AB20: 78 | AC20: 92 | AD20: 112 | AE20: =SUM(E20:AD20) -> 2704
D21: JML | E21: =SUM(E19:E20) -> 206 | F21: =SUM(F19:F20) -> 200 | G21: =SUM(G19:G20) -> 201 | H21: =SUM(H19:H20) -> 184 | I21: =SUM(I19:I20) -> 208 | J21: =SUM(J19:J20) -> 230 | K21: =SUM(K19:K20) -> 224 | L21: =SUM(L19:L20) -> 229 | ... AD21: =SUM(AD19:AD20) -> 207 | AE21: =SUM(E21:AD21) -> 5203
B22: 2. | C22: Jumlah pengguna hak pilih dalam Daftar Pemilih Tambahan (DPTb) | D22: LK | N22: 2 | P22: 1 | Z22: 1 | AE22: =SUM(E22:AD22) -> 4
D23: PR | N23: 1 | O23: 1 | S23: 1 | V23: 1 | AE23: =SUM(E23:AD23) -> 4
D24: JML | E24: =SUM(E22:E23) -> 0 | F24: =SUM(F22:F23) -> 0 | G24: =SUM(G22:G23) -> 0 | H24: =SUM(H22:H23) -> 0 | I24: =SUM(I22:I23) -> 0 | J24: =SUM(J22:J23) -> 0 | K24: =SUM(K22:K23) -> 0 | L24: =SUM(L22:L23) -> 0 | ... AD24: =SUM(AD22:AD23) -> 0 | AE24: =SUM(E24:AD24) -> 8
B25: 3. | C25: Jumlah pengguna hak pilih dalam Daftar Pemilih Khusus (DPK) | D25: LK | E25: 1 | I25: 2 | R25: 1 | V25: 2 | W25: 1 | AE25: =SUM(E25:AD25) -> 7
D26: PR | P26: 1 | V26: 1 | W26: 1 | X26: 4 | AE26: =SUM(E26:AD26) -> 7
D27: JML | E27: =SUM(E25:E26) -> 1 | F27: =SUM(F25:F26) -> 0 | G27: =SUM(G25:G26) -> 0 | H27: =SUM(H25:H26) -> 0 | I27: =SUM(I25:I26) -> 2 | J27: =SUM(J25:J26) -> 0 | K27: =SUM(K25:K26) -> 0 | L27: =SUM(L25:L26) -> 0 | ... AD27: =SUM(AD25:AD26) -> 0 | AE27: =SUM(E27:AD27) -> 14
B28: 4. | C28: Jumlah Pengguna Hak Pilih (B.1+B.2+B.3) | D28: LK | E28: =SUM(E19,E22,E25) -> 106 | F28: =SUM(F19,F22,F25) -> 100 | G28: =SUM(G19,G22,G25) -> 94 | H28: =SUM(H19,H22,H25) -> 91 | I28: =SUM(I19,I22,I25) -> 106 | J28: =SUM(J19,J22,J25) -> 118 | K28: =SUM(K19,K22,K25) -> 109 | L28: =SUM(L19,L22,L25) -> 115 | ... AD28: =SUM(AD19,AD22,AD25) -> 95 | AE28: =SUM(E28:AD28) -> 2510
D29: PR | E29: =SUM(E20,E23,E26) -> 101 | F29: =SUM(F20,F23,F26) -> 100 | G29: =SUM(G20,G23,G26) -> 107 | H29: =SUM(H20,H23,H26) -> 93 | I29: =SUM(I20,I23,I26) -> 104 | J29: =SUM(J20,J23,J26) -> 112 | K29: =SUM(K20,K23,K26) -> 115 | L29: =SUM(L20,L23,L26) -> 114 | ... AD29: =SUM(AD20,AD23,AD26) -> 112 | AE29: =SUM(E29:AD29) -> 2715
D30: JML | E30: =SUM(E28:E29) -> 207 | F30: =SUM(F28:F29) -> 200 | G30: =SUM(G28:G29) -> 201 | H30: =SUM(H28:H29) -> 184 | I30: =SUM(I28:I29) -> 210 | J30: =SUM(J28:J29) -> 230 | K30: =SUM(K28:K29) -> 224 | L30: =SUM(L28:L29) -> 229 | ... AD30: =SUM(AD28:AD29) -> 207 | AE30: =SUM(E30:AD30) -> 5225
A32: II | B32: DATA PENGGUNAAN SURAT SUARA
A33: 1 | B33: Jumlah surat suara yang diterima, termasuk surat suara cadangan 2,5% dari DPT | E33: 265 | F33: 249 | G33: 259 | H33: 231 | I33: 295 | J33: 307 | K33: 299 | L33: 302 | M33: 294 | N33: 303 | O33: 243 | P33: 259 | Q33: 244 | R33: 202 | S33: 280 | T33: 256 | U33: 279 | V33: 218 | W33: 290 | X33: 285 | Y33: 250 | Z33: 297 | AA33: 228 | AB33: 226 | AC33: 261 | AD33: 293 | AE33: =SUM(E33:AD33) -> 6915
A34: 2 | B34: Jumlah surat suara yang digunakan | E34: 207 | F34: 200 | G34: 201 | H34: 184 | I34: 210 | J34: 230 | K34: 224 | L34: 229 | M34: 223 | N34: 229 | O34: 177 | P34: 215 | Q34: 183 | R34: 155 | S34: 221 | T34: 194 | U34: 199 | V34: 185 | W34: 225 | X34: 210 | Y34: 191 | Z34: 223 | AA34: 177 | AB34: 154 | AC34: 172 | AD34: 207 | AE34: =SUM(E34:AD34) -> 5225
A35: 3 | B35: Jumlah surat suara dikembalikan oleh pemilih (karena rusak atau keliru coblos) | E35: 1 | L35: 1 | O35: 2 | P35: 1 | AE35: =SUM(E35:AD35) -> 5
A36: 4 | B36: Jumlah surat suara yang tidak digunakan/tidak terpakai, termasuk sisa surat suara cadangan | E36: =E33-(E34+E35) -> 57 | F36: =F33-(F34+F35) -> 49 | G36: =G33-(G34+G35) -> 58 | H36: =H33-(H34+H35) -> 47 | I36: =I33-(I34+I35) -> 85 | J36: =J33-(J34+J35) -> 77 | K36: =K33-(K34+K35) -> 75 | L36: =L33-(L34+L35) -> 72 | ... AD36: =AD33-(AD34+AD35) -> 86 | AE36: =SUM(E36:AD36) -> 1685
A38: III | B38: DATA PEMILIH DISABILITAS
B39: Jumlah seluruh Pemilih disabilitas yang menggunakan hak pilih | D39: LK | E39: 2 | J39: 1 | U39: 1 | V39: 1 | Y39: 1 | AA39: 3 | AB39: 1 | AE39: =SUM(E39:AD39) -> 10
D40: PR | E40: 2 | I40: 1 | R40: 2 | W40: 2 | Y40: 1 | Z40: 1 | AA40: 2 | AB40: 3 | AE40: =SUM(E40:AD40) -> 14
D41: JML | E41: =SUM(E39:E40) -> 4 | F41: =SUM(F39:F40) -> 0 | G41: =SUM(G39:G40) -> 0 | H41: =SUM(H39:H40) -> 0 | I41: =SUM(I39:I40) -> 1 | J41: =SUM(J39:J40) -> 1 | K41: =SUM(K39:K40) -> 0 | L41: =SUM(L39:L40) -> 0 | ... AD41: =SUM(AD39:AD40) -> 0 | AE41: =SUM(E41:AD41) -> 24
A43: IV | B43: DATA RINCIAN PEROLEHAN SUARA PASANGAN CALON BUPATI DAN WAKIL BUPATI
A44: NOMOR DAN NAMA CALON
B45: 1 | C45: H. ANIES RASYID BASWEDAN, Ph.D. - Dr. (H.C.) H. A. MUHAIMIN ISKANDAR | E45: 12 | F45: 25 | G45: 29 | H45: 5 | I45: 13 | J45: 16 | K45: 9 | L45: 11 | M45: 13 | N45: 13 | O45: 10 | P45: 19 | Q45: 18 | R45: 10 | S45: 29 | T45: 25 | U45: 15 | V45: 9 | W45: 25 | X45: 14 | Y45: 24 | Z45: 26 | AA45: 19 | AB45: 6 | AC45: 16 | AD45: 37 | AE45: =SUM(E45:AD45) -> 448
B46: 2 | C46: H. PRABOWO SUBIANTO - GIBRAN RAKABUMING RAKA | E46: 143 | F46: 139 | G46: 145 | H46: 147 | I46: 160 | J46: 175 | K46: 155 | L46: 162 | M46: 175 | N46: 169 | O46: 143 | P46: 160 | Q46: 141 | R46: 119 | S46: 162 | T46: 144 | U46: 136 | V46: 82 | W46: 143 | X46: 135 | Y46: 142 | Z46: 171 | AA46: 113 | AB46: 94 | AC46: 141 | AD46: 145 | AE46: =SUM(E46:AD46) -> 3741
B47: 3 | C47: H. GANJAR PRANOWO, S.H., M.I.P. - Prof. Dr. H. M. MAHFUD MD | E47: 47 | F47: 32 | G47: 24 | H47: 29 | I47: 32 | J47: 33 | K47: 48 | L47: 49 | M47: 32 | N47: 45 | O47: 23 | P47: 31 | Q47: 22 | R47: 25 | S47: 25 | T47: 23 | U47: 44 | V47: 89 | W47: 53 | X47: 58 | Y47: 22 | Z47: 26 | AA47: 43 | AB47: 54 | AC47: 12 | AD47: 21 | AE47: =SUM(E47:AD47) -> 942
A49: V | B49: DATA SUARA SAH DAN TIDAK SAH
B50: A. | C50: JUMLAH SELURUH SUARA SAH | E50: =SUM(E45:E47) -> 202 | F50: =SUM(F45:F47) -> 196 | G50: =SUM(G45:G47) -> 198 | H50: =SUM(H45:H47) -> 181 | I50: =SUM(I45:I47) -> 205 | J50: =SUM(J45:J47) -> 224 | K50: =SUM(K45:K47) -> 212 | L50: =SUM(L45:L47) -> 222 | ... AD50: =SUM(AD45:AD47) -> 203 | AE50: =SUM(E50:AD50) -> 5131
B51: B. | C51: JUMLAH SUARA TIDAK SAH | E51: 5 | F51: 4 | G51: 3 | H51: 3 | I51: 5 | J51: 6 | K51: 12 | L51: 7 | M51: 3 | N51: 2 | O51: 1 | P51: 5 | Q51: 2 | R51: 1 | S51: 5 | T51: 2 | U51: 4 | V51: 5 | W51: 4 | X51: 3 | Y51: 3 | AA51: 2 | AC51: 3 | AD51: 4 | AE51: =SUM(E51:AD51) -> 94
B52: C. | C52: JUMLAH SELURUH SUARA SAH DAN SUARA TIDAK SAH (V.A + V.B) | E52: =SUM(E50:E51) -> 207 | F52: =SUM(F50:F51) -> 200 | G52: =SUM(G50:G51) -> 201 | H52: =SUM(H50:H51) -> 184 | I52: =SUM(I50:I51) -> 210 | J52: =SUM(J50:J51) -> 230 | K52: =SUM(K50:K51) -> 224 | L52: =SUM(L50:L51) -> 229 | ... AD52: =SUM(AD50:AD51) -> 207 | AE52: =SUM(E52:AD52) -> 5225

Sheet KARANGHARJO
C2: Kecamatan | D2: GLENMORE
C3: Kabupaten | D3: BANYUWANGI
C4: Provinsi | D4: JAWA TIMUR
C9: Kelurahan | D9: KARANGHARJO
A12: I | B12: DATA PEMILIH DAN PENGGUNAAN HAK PILIH | BK12: JUMLAH AKHIR
A13: A | B13: DATA PEMILIH | E13: TPS 001 | F13: TPS 002 | G13: TPS 003 | H13: TPS 004 | I13: TPS 005 | J13: TPS 006 | K13: TPS 007 | L13: TPS 008 | M13: TPS 009 | N13: TPS 010 | O13: TPS 011 | P13: TPS 012 | Q13: TPS 013 | R13: TPS 014 | S13: TPS 015 | T13: TPS 016 | U13: TPS 017 | V13: TPS 018 | W13: TPS 019 | X13: TPS 020 | Y13: TPS 021 | Z13: TPS 022 | AA13: TPS 023 | AB13: TPS 024 | AC13: TPS 025 | AD13: TPS 026 | AE13: TPS 027 | AF13: TPS 028 | AG13: TPS 029 | AH13: TPS 030 | AI13: TPS 031 | AJ13: TPS 032 | AK13: TPS 033 | AL13: TPS 034 | AM13: TPS 035 | AN13: TPS 036 | AO13: TPS 037 | AP13: TPS 038 | AQ13: TPS 039 | AR13: TPS 040 | AS13: TPS 041 | AT13: TPS 042 | AU13: TPS 043 | AV13: TPS 044 | AW13: TPS 045 | AX13: TPS 046 | AY13: TPS 047 | AZ13: TPS 048 | BA13: TPS 049 | BB13: TPS 050 | BC13: TPS 051 | BD13: TPS 052 | BE13: TPS 053 | BF13: TPS 054 | BG13: TPS 055 | BH13: TPS 056 | BI13: TPS 057 | BJ13: TPS 058
B14: Jumlah Pemilih dalam Daftar Pemilih Tetap (DPT) | D14: LK | E14: 48 | F14: 60 | G14: 57 | H14: 49 | I14: 111 | J14: 137 | K14: 142 | L14: 129 | M14: 134 | N14: 50 | O14: 120 | P14: 109 | Q14: 109 | R14: 73 | S14: 120 | T14: 78 | U14: 127 | V14: 147 | W14: 111 | X14: 150 | Y14: 128 | Z14: 100 | AA14: 119 | AB14: 97 | AC14: 150 | AD14: 108 | AE14: 87 | AF14: 66 | AG14: 128 | AH14: 143 | AI14: 113 | AJ14: 92 | AK14: 99 | AL14: 130 | AM14: 107 | AN14: 94 | AO14: 81 | AP14: 102 | AQ14: 90 | AR14: 99 | AS14: 81 | AT14: 145 | AU14: 141 | AV14: 131 | AW14: 138 | AX14: 105 | AY14: 132 | AZ14: 81 | BA14: 103 | BB14: 87 | BC14: 128 | BD14: 117 | BE14: 132 | BF14: 84 | BG14: 135 | BH14: 139 | BI14: 117 | BJ14: 134 | BK14: =SUM(E14:BJ14) -> 6324
D15: PR | E15: 53 | F15: 48 | G15: 58 | H15: 39 | I15: 110 | J15: 137 | K15: 146 | L15: 145 | M15: 132 | N15: 43 | O15: 152 | P15: 115 | Q15: 101 | R15: 68 | S15: 123 | T15: 84 | U15: 118 | V15: 147 | W15: 122 | X15: 138 | Y15: 125 | Z15: 109 | AA15: 136 | AB15: 82 | AC15: 144 | AD15: 97 | AE15: 95 | AF15: 74 | AG15: 139 | AH15: 154 | AI15: 125 | AJ15: 101 | AK15: 99 | AL15: 139 | AM15: 121 | AN15: 91 | AO15: 77 | AP15: 109 | AQ15: 91 | AR15: 89 | AS15: 77 | AT15: 151 | AU15: 133 | AV15: 156 | AW15: 159 | AX15: 121 | AY15: 162 | AZ15: 93 | BA15: 108 | BB15: 89 | BC15: 130 | BD15: 129 | BE15: 148 | BF15: 99 | BG15: 147 | BH15: 152 | BI15: 121 | BJ15: 138 | BK15: =SUM(E15:BJ15) -> 6589
D16: JML | E16: =SUM(E14:E15) -> 101 | F16: =SUM(F14:F15) -> 108 | G16: =SUM(G14:G15) -> 115 | H16: =SUM(H14:H15) -> 88 | I16: =SUM(I14:I15) -> 221 | J16: =SUM(J14:J15) -> 274 | K16: =SUM(K14:K15) -> 288 | L16: =SUM(L14:L15) -> 274 | ... BJ16: =SUM(BJ14:BJ15) -> 272 | BK16: =SUM(E16:BJ16) -> 12913
A18: B | B18: PENGGUNA HAK PILIH
B19: 1. | C19: Jumlah pengguna hak pilih dalam Daftar Pemilih Tetap (DPT) | D19: LK | E19: 39 | F19: 49 | G19: 45 | H19: 30 | I19: 77 | J19: 91 | K19: 77 | L19: 83 | M19: 88 | N19: 50 | O19: 85 | P19: 70 | Q19: 75 | R19: 44 | S19: 92 | T19: 54 | U19: 94 | V19: 99 | W19: 95 | X19: 120 | Y19: 76 | Z19: 72 | AA19: 82 | AB19: 56 | AC19: 109 | AD19: 59 | AE19: 67 | AF19: 55 | AG19: 75 | AH19: 109 | AI19: 78 | AJ19: 64 | AK19: 73 | AL19: 112 | AM19: 74 | AN19: 64 | AO19: 69 | AP19: 86 | AQ19: 75 | AR19: 79 | AS19: 64 | AT19: 98 | AU19: 101 | AV19: 92 | AW19: 86 | AX19: 68 | AY19: 96 | AZ19: 59 | BA19: 72 | BB19: 67 | BC19: 99 | BD19: 83 | BE19: 80 | BF19: 72 | BG19: 86 | BH19: 95 | BI19: 99 | BJ19: 87 | BK19: =SUM(E19:BJ19) -> 4495
D20: PR | E20: 35 | F20: 37 | G20: 50 | H20: 21 | I20: 82 | J20: 102 | K20: 103 | L20: 110 | M20: 90 | N20: 42 | O20: 120 | P20: 78 | Q20: 76 | R20: 46 | S20: 88 | T20: 65 | U20: 102 | V20: 121 | W20: 107 | X20: 126 | Y20: 89 | Z20: 85 | AA20: 112 | AB20: 68 | AC20: 112 | AD20: 72 | AE20: 78 | AF20: 59 | AG20: 103 | AH20: 116 | AI20: 104 | AJ20: 71 | AK20: 69 | AL20: 123 | AM20: 86 | AN20: 66 | AO20: 71 | AP20: 86 | AQ20: 74 | AR20: 79 | AS20: 62 | AT20: 116 | AU20: 100 | AV20: 106 | AW20: 108 | AX20: 92 | AY20: 124 | AZ20: 83 | BA20: 80 | BB20: 71 | BC20: 102 | BD20: 99 | BE20: 100 | BF20: 86 | BG20: 110 | BH20: 128 | BI20: 99 | BJ20: 103 | BK20: =SUM(E20:BJ20) -> 5093
D21: JML | E21: =SUM(E19:E20) -> 74 | F21: =SUM(F19:F20) -> 86 | G21: =SUM(G19:G20) -> 95 | H21: =SUM(H19:H20) -> 51 | I21: =SUM(I19:I20) -> 159 | J21: =SUM(J19:J20) -> 193 | K21: =SUM(K19:K20) -> 180 | L21: =SUM(L19:L20) -> 193 | ... BJ21: =SUM(BJ19:BJ20) -> 190 | BK21: =SUM(E21:BJ21) -> 9588
B22: 2. | C22: Jumlah pengguna hak pilih dalam Daftar Pemilih Tambahan (DPTb) | D22: LK | E22: 1 | F22: 1 | G22: 1 | H22: 1 | I22: 1 | J22: 1 | K22: 1 | L22: 1 | M22: 1 | N22: 1 | O22: 1 | R22: 1 | S22: 1 | U22: 1 | V22: 1 | W22: 1 | Z22: 1 | AA22: 1 | AB22: 1 | AC22: 1 | AD22: 1 | AF22: 2 | AI22: 1 | AJ22: 1 | AL22: 1 | AO22: 6 | AP22: 5 | AQ22: 2 | AS22: 1 | AU22: 1 | AX22: 1 | BA22: 2 | BB22: 1 | BH22: 1 | BK22: =SUM(E22:BJ22) -> 46
D23: PR | Q23: 1 | X23: 1 | AF23: 1 | AK23: 1 | AM23: 1 | AN23: 1 | AO23: 1 | AP23: 3 | AQ23: 2 | AT23: 1 | AV23: 1 | AX23: 1 | AY23: 3 | AZ23: 1 | BA23: 2 | BE23: 1 | BF23: 1 | BG23: 1 | BI23: 1 | BJ23: 1 | BK23: =SUM(E23:BJ23) -> 26
D24: JML | E24: =SUM(E22:E23) -> 1 | F24: =SUM(F22:F23) -> 1 | G24: =SUM(G22:G23) -> 1 | H24: =SUM(H22:H23) -> 1 | I24: =SUM(I22:I23) -> 1 | J24: =SUM(J22:J23) -> 1 | K24: =SUM(K22:K23) -> 1 | L24: =SUM(L22:L23) -> 1 | ... BJ24: =SUM(BJ22:BJ23) -> 1 | BK24: =SUM(E24:BJ24) -> 72
B25: 3. | C25: Jumlah pengguna hak pilih dalam Daftar Pemilih Khusus (DPK) | D25: LK | AA25: 3 | AB25: 1 | AV25: 6 | AX25: 1 | BD25: 3 | BE25: 1 | BH25: 1 | BI25: 1 | BK25: =SUM(E25:BJ25) -> 17
D26: PR | M26: 3 | AA26: 5 | AB26: 2 | AF26: 1 | AQ26: 1 | AV26: 3 | AY26: 2 | BA26: 2 | BD26: 1 | BG26: 4 | BI26: 4 | BJ26: 2 | BK26: =SUM(E26:BJ26) -> 30
D27: JML | E27: =SUM(E25:E26) -> 0 | F27: =SUM(F25:F26) -> 0 | G27: =SUM(G25:G26) -> 0 | H27: =SUM(H25:H26) -> 0 | I27: =SUM(I25:I26) -> 0 | J27: =SUM(J25:J26) -> 0 | K27: =SUM(K25:K26) -> 0 | L27: =SUM(L25:L26) -> 0 | ... BJ27: =SUM(BJ25:BJ26) -> 2 | BK27: =SUM(E27:BJ27) -> 47
B28: 4. | C28: Jumlah Pengguna Hak Pilih (B.1+B.2+B.3) | D28: LK | E28: =SUM(E19,E22,E25) -> 40 | F28: =SUM(F19,F22,F25) -> 50 | G28: =SUM(G19,G22,G25) -> 46 | H28: =SUM(H19,H22,H25) -> 31 | I28: =SUM(I19,I22,I25) -> 78 | J28: =SUM(J19,J22,J25) -> 92 | K28: =SUM(K19,K22,K25) -> 78 | L28: =SUM(L19,L22,L25) -> 84 | ... BJ28: =SUM(BJ19,BJ22,BJ25) -> 87 | BK28: =SUM(E28:BJ28) -> 4558
D29: PR | E29: =SUM(E20,E23,E26) -> 35 | F29: =SUM(F20,F23,F26) -> 37 | G29: =SUM(G20,G23,G26) -> 50 | H29: =SUM(H20,H23,H26) -> 21 | I29: =SUM(I20,I23,I26) -> 82 | J29: =SUM(J20,J23,J26) -> 102 | K29: =SUM(K20,K23,K26) -> 103 | L29: =SUM(L20,L23,L26) -> 110 | ... BJ29: =SUM(BJ20,BJ23,BJ26) -> 106 | BK29: =SUM(E29:BJ29) -> 5149
D30: JML | E30: =SUM(E28:E29) -> 75 | F30: =SUM(F28:F29) -> 87 | G30: =SUM(G28:G29) -> 96 | H30: =SUM(H28:H29) -> 52 | I30: =SUM(I28:I29) -> 160 | J30: =SUM(J28:J29) -> 194 | K30: =SUM(K28:K29) -> 181 | L30: =SUM(L28:L29) -> 194 | ... BJ30: =SUM(BJ28:BJ29) -> 193 | BK30: =SUM(E30:BJ30) -> 9707
A32: II | B32: DATA PENGGUNAAN SURAT SUARA
A33: 1 | B33: Jumlah surat suara yang diterima, termasuk surat suara cadangan 2,5% dari DPT | E33: 104 | F33: 111 | G33: 118 | H33: 90 | I33: 226 | J33: 281 | K33: 295 | L33: 295 | M33: 272 | N33: 95 | O33: 278 | P33: 259 | Q33: 215 | R33: 144 | S33: 248 | T33: 167 | U33: 250 | V33: 300 | W33: 240 | X33: 299 | Y33: 259 | Z33: 215 | AA33: 261 | AB33: 183 | AC33: 300 | AD33: 210 | AE33: 186 | AF33: 143 | AG33: 273 | AH33: 303 | AI33: 243 | AJ33: 201 | AK33: 200 | AL33: 275 | AM33: 233 | AN33: 189 | AO33: 160 | AP33: 216 | AQ33: 187 | AR33: 192 | AS33: 162 | AT33: 303 | AU33: 280 | AV33: 301 | AW33: 303 | AX33: 231 | AY33: 300 | AZ33: 178 | BA33: 216 | BB33: 180 | BC33: 264 | BD33: 253 | BE33: 287 | BF33: 187 | BG33: 288 | BH33: 291 | BI33: 244 | BJ33: 273 | BK33: =SUM(E33:BJ33) -> 13257
A34: 2 | B34: Jumlah surat suara yang digunakan | E34: 75 | F34: 87 | G34: 96 | H34: 52 | I34: 160 | J34: 194 | K34: 181 | L34: 194 | M34: 182 | N34: 93 | O34: 206 | P34: 148 | Q34: 152 | R34: 91 | S34: 181 | T34: 119 | U34: 197 | V34: 221 | W34: 203 | X34: 247 | Y34: 165 | Z34: 158 | AA34: 203 | AB34: 128 | AC34: 222 | AD34: 132 | AE34: 145 | AF34: 118 | AG34: 178 | AH34: 225 | AI34: 183 | AJ34: 136 | AK34: 143 | AL34: 236 | AM34: 161 | AN34: 131 | AO34: 147 | AP34: 180 | AQ34: 154 | AR34: 158 | AS34: 127 | AT34: 215 | AU34: 202 | AV34: 208 | AW34: 194 | AX34: 163 | AY34: 225 | AZ34: 143 | BA34: 158 | BB34: 139 | BC34: 201 | BD34: 186 | BE34: 182 | BF34: 159 | BG34: 201 | BH34: 225 | BI34: 204 | BJ34: 193 | BK34: =SUM(E34:BJ34) -> 9707
A35: 3 | B35: Jumlah surat suara dikembalikan oleh pemilih (karena rusak atau keliru coblos) | L35: 1 | Q35: 1 | R35: 1 | AD35: 3 | AG35: 2 | AH35: 1 | AM35: 1 | AQ35: 1 | AV35: 8 | BK35: =SUM(E35:BJ35) -> 19
A36: 4 | B36: Jumlah surat suara yang tidak digunakan/tidak terpakai, termasuk sisa surat suara cadangan | E36: =E33-(E34+E35) -> 29 | F36: =F33-(F34+F35) -> 24 | G36: =G33-(G34+G35) -> 22 | H36: =H33-(H34+H35) -> 38 | I36: =I33-(I34+I35) -> 66 | J36: =J33-(J34+J35) -> 87 | K36: =K33-(K34+K35) -> 114 | L36: =L33-(L34+L35) -> 100 | ... BJ36: =BJ33-(BJ34+BJ35) -> 80 | BK36: =SUM(E36:BJ36) -> 3531
A38: III | B38: DATA PEMILIH DISABILITAS
B39: Jumlah seluruh Pemilih disabilitas yang menggunakan hak pilih | D39: LK | S39: 1 | X39: 1 | Y39: 1 | Z39: 1 | AG39: 1 | AI39: 2 | AR39: 1 | AX39: 1 | BK39: =SUM(E39:BJ39) -> 9
D40: PR | F40: 1 | O40: 1 | S40: 2 | T40: 1 | X40: 3 | Z40: 1 | AI40: 3 | AT40: 1 | AX40: 3 | BK40: =SUM(E40:BJ40) -> 16
D41: JML | E41: =SUM(E39:E40) -> 0 | F41: =SUM(F39:F40) -> 1 | G41: =SUM(G39:G40) -> 0 | H41: =SUM(H39:H40) -> 0 | I41: =SUM(I39:I40) -> 0 | J41: =SUM(J39:J40) -> 0 | K41: =SUM(K39:K40) -> 0 | L41: =SUM(L39:L40) -> 0 | ... BJ41: =SUM(BJ39:BJ40) -> 0 | BK41: =SUM(E41:BJ41) -> 25
A43: IV | B43: DATA RINCIAN PEROLEHAN SUARA PASANGAN CALON BUPATI DAN WAKIL BUPATI
A44: NOMOR DAN NAMA CALON
B45: 1 | C45: H. ANIES RASYID BASWEDAN, Ph.D. - Dr. (H.C.) H. A. MUHAIMIN ISKANDAR | E45: 2 | F45: 3 | G45: 30 | H45: 4 | I45: 17 | J45: 40 | K45: 50 | L45: 46 | M45: 55 | N45: 60 | O45: 11 | P45: 12 | Q45: 19 | R45: 22 | S45: 8 | T45: 12 | U45: 26 | V45: 36 | W45: 23 | X45: 8 | Y45: 13 | Z45: 9 | AA45: 11 | AB45: 15 | AC45: 38 | AD45: 8 | AE45: 15 | AF45: 5 | AG45: 15 | AH45: 22 | AI45: 18 | AJ45: 16 | AK45: 13 | AL45: 18 | AM45: 30 | AN45: 13 | AO45: 4 | AP45: 16 | AQ45: 18 | AR45: 9 | AS45: 13 | AT45: 24 | AU45: 29 | AV45: 27 | AW45: 29 | AX45: 27 | AY45: 35 | AZ45: 11 | BA45: 16 | BB45: 9 | BC45: 22 | BD45: 23 | BE45: 32 | BF45: 31 | BG45: 28 | BH45: 20 | BI45: 21 | BJ45: 26 | BK45: =SUM(E45:BJ45) -> 1213
B46: 2 | C46: H. PRABOWO SUBIANTO - GIBRAN RAKABUMING RAKA | E46: 72 | F46: 77 | G46: 60 | H46: 45 | I46: 127 | J46: 143 | K46: 112 | L46: 134 | M46: 115 | N46: 28 | O46: 187 | P46: 117 | Q46: 111 | R46: 62 | S46: 158 | T46: 100 | U46: 162 | V46: 170 | W46: 157 | X46: 230 | Y46: 136 | Z46: 130 | AA46: 142 | AB46: 89 | AC46: 148 | AD46: 97 | AE46: 118 | AF46: 90 | AG46: 125 | AH46: 174 | AI46: 94 | AJ46: 113 | AK46: 117 | AL46: 205 | AM46: 123 | AN46: 112 | AO46: 102 | AP46: 159 | AQ46: 128 | AR46: 132 | AS46: 98 | AT46: 170 | AU46: 149 | AV46: 152 | AW46: 156 | AX46: 105 | AY46: 154 | AZ46: 99 | BA46: 118 | BB46: 120 | BC46: 141 | BD46: 119 | BE46: 115 | BF46: 104 | BG46: 157 | BH46: 181 | BI46: 166 | BJ46: 139 | BK46: =SUM(E46:BJ46) -> 7344
B47: 3 | C47: H. GANJAR PRANOWO, S.H., M.I.P. - Prof. Dr. H. M. MAHFUD MD | E47: 1 | F47: 7 | G47: 6 | H47: 3 | I47: 15 | J47: 8 | K47: 13 | L47: 9 | M47: 9 | N47: 0 | O47: 8 | P47: 15 | Q47: 18 | R47: 6 | S47: 14 | T47: 7 | U47: 3 | V47: 9 | W47: 10 | X47: 8 | Y47: 8 | Z47: 15 | AA47: 47 | AB47: 19 | AC47: 36 | AD47: 25 | AE47: 11 | AF47: 21 | AG47: 33 | AH47: 27 | AI47: 69 | AJ47: 5 | AK47: 8 | AL47: 12 | AM47: 6 | AN47: 3 | AO47: 37 | AP47: 5 | AQ47: 6 | AR47: 14 | AS47: 15 | AT47: 20 | AU47: 23 | AV47: 21 | AW47: 8 | AX47: 31 | AY47: 34 | AZ47: 22 | BA47: 20 | BB47: 8 | BC47: 37 | BD47: 44 | BE47: 31 | BF47: 21 | BG47: 12 | BH47: 22 | BI47: 15 | BJ47: 22 | BK47: =SUM(E47:BJ47) -> 982
A49: V | B49: DATA SUARA SAH DAN TIDAK SAH
B50: A. | C50: JUMLAH SELURUH SUARA SAH | E50: =SUM(E45:E47) -> 75 | F50: =SUM(F45:F47) -> 87 | G50: =SUM(G45:G47) -> 96 | H50: =SUM(H45:H47) -> 52 | I50: =SUM(I45:I47) -> 159 | J50: =SUM(J45:J47) -> 191 | K50: =SUM(K45:K47) -> 175 | L50: =SUM(L45:L47) -> 189 | ... BJ50: =SUM(BJ45:BJ47) -> 187 | BK50: =SUM(E50:BJ50) -> 9539
B51: B. | C51: JUMLAH SUARA TIDAK SAH | I51: 1 | J51: 3 | K51: 6 | L51: 5 | M51: 3 | N51: 5 | P51: 4 | Q51: 4 | R51: 1 | S51: 1 | U51: 6 | V51: 6 | W51: 13 | X51: 1 | Y51: 8 | Z51: 4 | AA51: 3 | AB51: 5 | AD51: 2 | AE51: 1 | AF51: 2 | AG51: 5 | AH51: 2 | AI51: 2 | AJ51: 2 | AK51: 5 | AL51: 1 | AM51: 2 | AN51: 3 | AO51: 4 | AQ51: 2 | AR51: 3 | AS51: 1 | AT51: 1 | AU51: 1 | AV51: 8 | AW51: 1 | AY51: 2 | AZ51: 11 | BA51: 4 | BB51: 2 | BC51: 1 | BE51: 4 | BF51: 3 | BG51: 4 | BH51: 2 | BI51: 2 | BJ51: 6 | BK51: =SUM(E51:BJ51) -> 168
B52: C. | C52: JUMLAH SELURUH SUARA SAH DAN SUARA TIDAK SAH (V.A + V.B) | E52: =SUM(E50:E51) -> 75 | F52: =SUM(F50:F51) -> 87 | G52: =SUM(G50:G51) -> 96 | H52: =SUM(H50:H51) -> 52 | I52: =SUM(I50:I51) -> 160 | J52: =SUM(J50:J51) -> 194 | K52: =SUM(K50:K51) -> 181 | L52: =SUM(L50:L51) -> 194 | ... BJ52: =SUM(BJ50:BJ51) -> 193 | BK52: =SUM(E52:BJ52) -> 9707

Sheet MARGOMULYO
C2: Kecamatan | D2: GLENMORE
C3: Kabupaten | D3: BANYUWANGI
C4: Provinsi | D4: JAWA TIMUR
C9: Kelurahan | D9: MARGOMULYO
A12: I | B12: DATA PEMILIH DAN PENGGUNAAN HAK PILIH | S12: JUMLAH AKHIR
A13: A | B13: DATA PEMILIH | E13: TPS 001 | F13: TPS 002 | G13: TPS 003 | H13: TPS 004 | I13: TPS 005 | J13: TPS 006 | K13: TPS 007 | L13: TPS 008 | M13: TPS 009 | N13: TPS 010 | O13: TPS 011 | P13: TPS 012 | Q13: TPS 013 | R13: TPS 014
B14: Jumlah Pemilih dalam Daftar Pemilih Tetap (DPT) | D14: LK | E14: 100 | F14: 130 | G14: 131 | H14: 141 | I14: 115 | J14: 138 | K14: 136 | L14: 115 | M14: 146 | N14: 142 | O14: 79 | P14: 101 | Q14: 123 | R14: 146 | S14: =SUM(E14:R14) -> 1743
D15: PR | E15: 86 | F15: 114 | G15: 125 | H15: 145 | I15: 108 | J15: 127 | K15: 145 | L15: 124 | M15: 138 | N15: 126 | O15: 89 | P15: 106 | Q15: 143 | R15: 146 | S15: =SUM(E15:R15) -> 1722
D16: JML | E16: =SUM(E14:E15) -> 186 | F16: =SUM(F14:F15) -> 244 | G16: =SUM(G14:G15) -> 256 | H16: =SUM(H14:H15) -> 286 | I16: =SUM(I14:I15) -> 223 | J16: =SUM(J14:J15) -> 265 | K16: =SUM(K14:K15) -> 281 | L16: =SUM(L14:L15) -> 239 | ... R16: =SUM(R14:R15) -> 292 | S16: =SUM(E16:R16) -> 3465
A18: B | B18: PENGGUNA HAK PILIH
B19: 1. | C19: Jumlah pengguna hak pilih dalam Daftar Pemilih Tetap (DPT) | D19: LK | E19: 77 | F19: 90 | G19: 89 | H19: 93 | I19: 98 | J19: 105 | K19: 110 | L19: 70 | M19: 91 | N19: 105 | O19: 59 | P19: 84 | Q19: 96 | R19: 103 | S19: =SUM(E19:R19) -> 1270
D20: PR | E20: 69 | F20: 88 | G20: 102 | H20: 112 | I20: 95 | J20: 104 | K20: 121 | L20: 85 | M20: 106 | N20: 108 | O20: 67 | P20: 85 | Q20: 116 | R20: 118 | S20: =SUM(E20:R20) -> 1376
D21: JML | E21: =SUM(E19:E20) -> 146 | F21: =SUM(F19:F20) -> 178 | G21: =SUM(G19:G20) -> 191 | H21: =SUM(H19:H20) -> 205 | I21: =SUM(I19:I20) -> 193 | J21: =SUM(J19:J20) -> 209 | K21: =SUM(K19:K20) -> 231 | L21: =SUM(L19:L20) -> 155 | ... R21: =SUM(R19:R20) -> 221 | S21: =SUM(E21:R21) -> 2646
B22: 2. | C22: Jumlah pengguna hak pilih dalam Daftar Pemilih Tambahan (DPTb) | D22: LK | Q22: 3 | S22: =SUM(E22:R22) -> 3
D23: PR | Q23: 1 | S23: =SUM(E23:R23) -> 1
D24: JML | E24: =SUM(E22:E23) -> 0 | F24: =SUM(F22:F23) -> 0 | G24: =SUM(G22:G23) -> 0 | H24: =SUM(H22:H23) -> 0 | I24: =SUM(I22:I23) -> 0 | J24: =SUM(J22:J23) -> 0 | K24: =SUM(K22:K23) -> 0 | L24: =SUM(L22:L23) -> 0 | ... R24: =SUM(R22:R23) -> 0 | S24: =SUM(E24:R24) -> 4
B25: 3. | C25: Jumlah pengguna hak pilih dalam Daftar Pemilih Khusus (DPK) | D25: LK | F25: 1 | I25: 1 | M25: 2 | N25: 3 | P25: 4 | Q25: 3 | R25: 1 | S25: =SUM(E25:R25) -> 15
D26: PR | E26: 1 | F26: 1 | H26: 1 | M26: 1 | P26: 3 | Q26: 2 | R26: 2 | S26: =SUM(E26:R26) -> 11
D27: JML | E27: =SUM(E25:E26) -> 1 | F27: =SUM(F25:F26) -> 2 | G27: =SUM(G25:G26) -> 0 | H27: =SUM(H25:H26) -> 1 | I27: =SUM(I25:I26) -> 1 | J27: =SUM(J25:J26) -> 0 | K27: =SUM(K25:K26) -> 0 | L27: =SUM(L25:L26) -> 0 | ... R27: =SUM(R25:R26) -> 3 | S27: =SUM(E27:R27) -> 26
B28: 4. | C28: Jumlah Pengguna Hak Pilih (B.1+B.2+B.3) | D28: LK | E28: =SUM(E19,E22,E25) -> 77 | F28: =SUM(F19,F22,F25) -> 91 | G28: =SUM(G19,G22,G25) -> 89 | H28: =SUM(H19,H22,H25) -> 93 | I28: =SUM(I19,I22,I25) -> 99 | J28: =SUM(J19,J22,J25) -> 105 | K28: =SUM(K19,K22,K25) -> 110 | L28: =SUM(L19,L22,L25) -> 70 | ... R28: =SUM(R19,R22,R25) -> 104 | S28: =SUM(E28:R28) -> 1288
D29: PR | E29: =SUM(E20,E23,E26) -> 70 | F29: =SUM(F20,F23,F26) -> 89 | G29: =SUM(G20,G23,G26) -> 102 | H29: =SUM(H20,H23,H26) -> 113 | I29: =SUM(I20,I23,I26) -> 95 | J29: =SUM(J20,J23,J26) -> 104 | K29: =SUM(K20,K23,K26) -> 121 | L29: =SUM(L20,L23,L26) -> 85 | ... R29: =SUM(R20,R23,R26) -> 120 | S29: =SUM(E29:R29) -> 1388
D30: JML | E30: =SUM(E28:E29) -> 147 | F30: =SUM(F28:F29) -> 180 | G30: =SUM(G28:G29) -> 191 | H30: =SUM(H28:H29) -> 206 | I30: =SUM(I28:I29) -> 194 | J30: =SUM(J28:J29) -> 209 | K30: =SUM(K28:K29) -> 231 | L30: =SUM(L28:L29) -> 155 | ... R30: =SUM(R28:R29) -> 224 | S30: =SUM(E30:R30) -> 2676
A32: II | B32: DATA PENGGUNAAN SURAT SUARA
A33: 1 | B33: Jumlah surat suara yang diterima, termasuk surat suara cadangan 2,5% dari DPT | E33: 190 | F33: 249 | G33: 264 | H33: 292 | I33: 226 | J33: 271 | K33: 288 | L33: 244 | M33: 290 | N33: 274 | O33: 172 | P33: 212 | Q33: 274 | R33: 298 | S33: =SUM(E33:R33) -> 3544
A34: 2 | B34: Jumlah surat suara yang digunakan | E34: 147 | F34: 180 | G34: 191 | H34: 206 | I34: 194 | J34: 209 | K34: 231 | L34: 155 | M34: 200 | N34: 216 | O34: 126 | P34: 176 | Q34: 221 | R34: 224 | S34: =SUM(E34:R34) -> 2676
A35: 3 | B35: Jumlah surat suara dikembalikan oleh pemilih (karena rusak atau keliru coblos) | G35: 1 | I35: 1 | S35: =SUM(E35:R35) -> 2
A36: 4 | B36: Jumlah surat suara yang tidak digunakan/tidak terpakai, termasuk sisa surat suara cadangan | E36: =E33-(E34+E35) -> 43 | F36: =F33-(F34+F35) -> 69 | G36: =G33-(G34+G35) -> 72 | H36: =H33-(H34+H35) -> 86 | I36: =I33-(I34+I35) -> 31 | J36: =J33-(J34+J35) -> 62 | K36: =K33-(K34+K35) -> 57 | L36: =L33-(L34+L35) -> 89 | ... R36: =R33-(R34+R35) -> 74 | S36: =SUM(E36:R36) -> 866
A38: III | B38: DATA PEMILIH DISABILITAS
B39: Jumlah seluruh Pemilih disabilitas yang menggunakan hak pilih | D39: LK | E39: 2 | M39: 2 | P39: 1 | R39: 1 | S39: =SUM(E39:R39) -> 6
D40: PR | L40: 1 | R40: 2 | S40: =SUM(E40:R40) -> 3
D41: JML | E41: =SUM(E39:E40) -> 2 | F41: =SUM(F39:F40) -> 0 | G41: =SUM(G39:G40) -> 0 | H41: =SUM(H39:H40) -> 0 | I41: =SUM(I39:I40) -> 0 | J41: =SUM(J39:J40) -> 0 | K41: =SUM(K39:K40) -> 0 | L41: =SUM(L39:L40) -> 1 | ... R41: =SUM(R39:R40) -> 3 | S41: =SUM(E41:R41) -> 9
A43: IV | B43: DATA RINCIAN PEROLEHAN SUARA PASANGAN CALON BUPATI DAN WAKIL BUPATI
A44: NOMOR DAN NAMA CALON
B45: 1 | C45: H. ANIES RASYID BASWEDAN, Ph.D. - Dr. (H.C.) H. A. MUHAIMIN ISKANDAR | E45: 4 | F45: 3 | G45: 11 | H45: 16 | I45: 10 | J45: 27 | K45: 15 | L45: 5 | M45: 28 | N45: 67 | O45: 9 | P45: 11 | Q45: 20 | R45: 21 | S45: =SUM(E45:R45) -> 247
B46: 2 | C46: H. PRABOWO SUBIANTO - GIBRAN RAKABUMING RAKA | E46: 105 | F46: 139 | G46: 150 | H46: 157 | I46: 150 | J46: 151 | K46: 179 | L46: 105 | M46: 136 | N46: 121 | O46: 112 | P46: 147 | Q46: 182 | R46: 149 | S46: =SUM(E46:R46) -> 1983
B47: 3 | C47: H. GANJAR PRANOWO, S.H., M.I.P. - Prof. Dr. H. M. MAHFUD MD | E47: 35 | F47: 33 | G47: 26 | H47: 30 | I47: 30 | J47: 24 | K47: 31 | L47: 42 | M47: 27 | N47: 24 | O47: 5 | P47: 14 | Q47: 16 | R47: 51 | S47: =SUM(E47:R47) -> 388
A49: V | B49: DATA SUARA SAH DAN TIDAK SAH
B50: A. | C50: JUMLAH SELURUH SUARA SAH | E50: =SUM(E45:E47) -> 144 | F50: =SUM(F45:F47) -> 175 | G50: =SUM(G45:G47) -> 187 | H50: =SUM(H45:H47) -> 203 | I50: =SUM(I45:I47) -> 190 | J50: =SUM(J45:J47) -> 202 | K50: =SUM(K45:K47) -> 225 | L50: =SUM(L45:L47) -> 152 | ... R50: =SUM(R45:R47) -> 221 | S50: =SUM(E50:R50) -> 2618
B51: B. | C51: JUMLAH SUARA TIDAK SAH | E51: 3 | F51: 5 | G51: 4 | H51: 3 | I51: 4 | J51: 7 | K51: 6 | L51: 3 | M51: 9 | N51: 4 | P51: 4 | Q51: 3 | R51: 3 | S51: =SUM(E51:R51) -> 58
B52: C. | C52: JUMLAH SELURUH SUARA SAH DAN SUARA TIDAK SAH (V.A + V.B) | E52: =SUM(E50:E51) -> 147 | F52: =SUM(F50:F51) -> 180 | G52: =SUM(G50:G51) -> 191 | H52: =SUM(H50:H51) -> 206 | I52: =SUM(I50:I51) -> 194 | J52: =SUM(J50:J51) -> 209 | K52: =SUM(K50:K51) -> 231 | L52: =SUM(L50:L51) -> 155 | ... R52: =SUM(R50:R51) -> 224 | S52: =SUM(E52:R52) -> 2676

Sheet SEPANJANG
C2: Kecamatan | D2: GLENMORE
C3: Kabupaten | D3: BANYUWANGI
C4: Provinsi | D4: JAWA TIMUR
C9: Kelurahan | D9: SEPANJANG
A12: I | B12: DATA PEMILIH DAN PENGGUNAAN HAK PILIH | AJ12: JUMLAH AKHIR
A13: A | B13: DATA PEMILIH | E13: TPS 001 | F13: TPS 002 | G13: TPS 003 | H13: TPS 004 | I13: TPS 005 | J13: TPS 006 | K13: TPS 007 | L13: TPS 008 | M13: TPS 009 | N13: TPS 010 | O13: TPS 011 | P13: TPS 012 | Q13: TPS 013 | R13: TPS 014 | S13: TPS 015 | T13: TPS 016 | U13: TPS 017 | V13: TPS 018 | W13: TPS 019 | X13: TPS 020 | Y13: TPS 021 | Z13: TPS 022 | AA13: TPS 023 | AB13: TPS 024 | AC13: TPS 025 | AD13: TPS 026 | AE13: TPS 027 | AF13: TPS 028 | AG13: TPS 029 | AH13: TPS 030 | AI13: TPS 031
B14: Jumlah Pemilih dalam Daftar Pemilih Tetap (DPT) | D14: LK | E14: 148 | F14: 122 | G14: 150 | H14: 138 | I14: 116 | J14: 149 | K14: 118 | L14: 112 | M14: 137 | N14: 138 | O14: 106 | P14: 129 | Q14: 135 | R14: 147 | S14: 122 | T14: 136 | U14: 125 | V14: 138 | W14: 128 | X14: 146 | Y14: 110 | Z14: 102 | AA14: 121 | AB14: 122 | AC14: 116 | AD14: 128 | AE14: 125 | AF14: 134 | AG14: 117 | AH14: 139 | AI14: 152 | AJ14: =SUM(E14:AI14) -> 4006
D15: PR | E15: 143 | F15: 129 | G15: 144 | H15: 147 | I15: 116 | J15: 146 | K15: 131 | L15: 126 | M15: 158 | N15: 154 | O15: 126 | P15: 136 | Q15: 143 | R15: 144 | S15: 130 | T15: 135 | U15: 140 | V15: 122 | W15: 127 | X15: 148 | Y15: 108 | Z15: 100 | AA15: 121 | AB15: 114 | AC15: 131 | AD15: 147 | AE15: 133 | AF15: 156 | AG15: 113 | AH15: 146 | AI15: 140 | AJ15: =SUM(E15:AI15) -> 4154
D16: JML | E16: =SUM(E14:E15) -> 291 | F16: =SUM(F14:F15) -> 251 | G16: =SUM(G14:G15) -> 294 | H16: =SUM(H14:H15) -> 285 | I16: =SUM(I14:I15) -> 232 | J16: =SUM(J14:J15) -> 295 | K16: =SUM(K14:K15) -> 249 | L16: =SUM(L14:L15) -> 238 | ... AI16: =SUM(AI14:AI15) -> 292 | AJ16: =SUM(E16:AI16) -> 8160
A18: B | B18: PENGGUNA HAK PILIH
B19: 1. | C19: Jumlah pengguna hak pilih dalam Daftar Pemilih Tetap (DPT) | D19: LK | E19: 110 | F19: 89 | G19: 114 | H19: 97 | I19: 90 | J19: 113 | K19: 84 | L19: 68 | M19: 105 | N19: 100 | O19: 84 | P19: 103 | Q19: 103 | R19: 112 | S19: 91 | T19: 105 | U19: 84 | V19: 99 | W19: 94 | X19: 98 | Y19: 87 | Z19: 82 | AA19: 86 | AB19: 84 | AC19: 80 | AD19: 84 | AE19: 94 | AF19: 95 | AG19: 95 | AH19: 107 | AI19: 116 | AJ19: =SUM(E19:AI19) -> 2953
D20: PR | E20: 111 | F20: 107 | G20: 117 | H20: 118 | I20: 95 | J20: 117 | K20: 93 | L20: 97 | M20: 124 | N20: 113 | O20: 101 | P20: 110 | Q20: 111 | R20: 121 | S20: 108 | T20: 99 | U20: 99 | V20: 98 | W20: 97 | X20: 117 | Y20: 92 | Z20: 83 | AA20: 101 | AB20: 86 | AC20: 99 | AD20: 105 | AE20: 104 | AF20: 118 | AG20: 89 | AH20: 119 | AI20: 127 | AJ20: =SUM(E20:AI20) -> 3276
D21: JML | E21: =SUM(E19:E20) -> 221 | F21: =SUM(F19:F20) -> 196 | G21: =SUM(G19:G20) -> 231 | H21: =SUM(H19:H20) -> 215 | I21: =SUM(I19:I20) -> 185 | J21: =SUM(J19:J20) -> 230 | K21: =SUM(K19:K20) -> 177 | L21: =SUM(L19:L20) -> 165 | ... AI21: =SUM(AI19:AI20) -> 243 | AJ21: =SUM(E21:AI21) -> 6229
B22: 2. | C22: Jumlah pengguna hak pilih dalam Daftar Pemilih Tambahan (DPTb) | D22: LK | I22: 1 | K22: 1 | L22: 1 | O22: 1 | S22: 1 | T22: 1 | U22: 1 | X22: 1 | AA22: 1 | AB22: 1 | AC22: 1 | AD22: 3 | AE22: 1 | AH22: 1 | AI22: 1 | AJ22: =SUM(E22:AI22) -> 17
D23: PR | E23: 1 | L23: 1 | N23: 1 | T23: 2 | V23: 1 | W23: 1 | Y23: 1 | Z23: 1 | AD23: 2 | AF23: 1 | AG23: 2 | AJ23: =SUM(E23:AI23) -> 14
D24: JML | E24: =SUM(E22:E23) -> 1 | F24: =SUM(F22:F23) -> 0 | G24: =SUM(G22:G23) -> 0 | H24: =SUM(H22:H23) -> 0 | I24: =SUM(I22:I23) -> 1 | J24: =SUM(J22:J23) -> 0 | K24: =SUM(K22:K23) -> 1 | L24: =SUM(L22:L23) -> 2 | ... AI24: =SUM(AI22:AI23) -> 1 | AJ24: =SUM(E24:AI24) -> 31
B25: 3. | C25: Jumlah pengguna hak pilih dalam Daftar Pemilih Khusus (DPK) | D25: LK | F25: 2 | H25: 1 | J25: 7 | K25: 1 | O25: 1 | Q25: 2 | S25: 2 | T25: 1 | U25: 1 | W25: 1 | AD25: 1 | AF25: 2 | AJ25: =SUM(E25:AI25) -> 22
D26: PR | H26: 1 | J26: 5 | K26: 2 | O26: 1 | Q26: 4 | S26: 5 | T26: 2 | U26: 1 | W26: 2 | AA26: 1 | AE26: 1 | AF26: 1 | AJ26: =SUM(E26:AI26) -> 26
D27: JML | E27: =SUM(E25:E26) -> 0 | F27: =SUM(F25:F26) -> 2 | G27: =SUM(G25:G26) -> 0 | H27: =SUM(H25:H26) -> 2 | I27: =SUM(I25:I26) -> 0 | J27: =SUM(J25:J26) -> 12 | K27: =SUM(K25:K26) -> 3 | L27: =SUM(L25:L26) -> 0 | ... AI27: =SUM(AI25:AI26) -> 0 | AJ27: =SUM(E27:AI27) -> 48
B28: 4. | C28: Jumlah Pengguna Hak Pilih (B.1+B.2+B.3) | D28: LK | E28: =SUM(E19,E22,E25) -> 110 | F28: =SUM(F19,F22,F25) -> 91 | G28: =SUM(G19,G22,G25) -> 114 | H28: =SUM(H19,H22,H25) -> 98 | I28: =SUM(I19,I22,I25) -> 91 | J28: =SUM(J19,J22,J25) -> 120 | K28: =SUM(K19,K22,K25) -> 86 | L28: =SUM(L19,L22,L25) -> 69 | ... AI28: =SUM(AI19,AI22,AI25) -> 117 | AJ28: =SUM(E28:AI28) -> 2992
D29: PR | E29: =SUM(E20,E23,E26) -> 112 | F29: =SUM(F20,F23,F26) -> 107 | G29: =SUM(G20,G23,G26) -> 117 | H29: =SUM(H20,H23,H26) -> 119 | I29: =SUM(I20,I23,I26) -> 95 | J29: =SUM(J20,J23,J26) -> 122 | K29: =SUM(K20,K23,K26) -> 95 | L29: =SUM(L20,L23,L26) -> 98 | ... AI29: =SUM(AI20,AI23,AI26) -> 127 | AJ29: =SUM(E29:AI29) -> 3316
D30: JML | E30: =SUM(E28:E29) -> 222 | F30: =SUM(F28:F29) -> 198 | G30: =SUM(G28:G29) -> 231 | H30: =SUM(H28:H29) -> 217 | I30: =SUM(I28:I29) -> 186 | J30: =SUM(J28:J29) -> 242 | K30: =SUM(K28:K29) -> 181 | L30: =SUM(L28:L29) -> 167 | ... AI30: =SUM(AI28:AI29) -> 244 | AJ30: =SUM(E30:AI30) -> 6308
A32: II | B32: DATA PENGGUNAAN SURAT SUARA
A33: 1 | B33: Jumlah surat suara yang diterima, termasuk surat suara cadangan 2,5% dari DPT | E33: 298 | F33: 260 | G33: 300 | H33: 291 | I33: 235 | J33: 303 | K33: 254 | L33: 238 | M33: 301 | N33: 298 | O33: 236 | P33: 271 | Q33: 284 | R33: 297 | S33: 258 | T33: 278 | U33: 270 | V33: 265 | W33: 261 | X33: 303 | Y33: 223 | Z33: 207 | AA33: 247 | AB33: 244 | AC33: 252 | AD33: 282 | AE33: 271 | AF33: 296 | AG33: 235 | AH33: 289 | AI33: 300 | AJ33: =SUM(E33:AI33) -> 8347
A34: 2 | B34: Jumlah surat suara yang digunakan | E34: 222 | F34: 198 | G34: 231 | H34: 217 | I34: 186 | J34: 242 | K34: 181 | L34: 167 | M34: 229 | N34: 214 | O34: 188 | P34: 213 | Q34: 220 | R34: 233 | S34: 207 | T34: 210 | U34: 186 | V34: 198 | W34: 195 | X34: 216 | Y34: 180 | Z34: 166 | AA34: 189 | AB34: 171 | AC34: 180 | AD34: 195 | AE34: 200 | AF34: 217 | AG34: 186 | AH34: 227 | AI34: 244 | AJ34: =SUM(E34:AI34) -> 6308
A35: 3 | B35: Jumlah surat suara dikembalikan oleh pemilih (karena rusak atau keliru coblos) | J35: 2 | U35: 1 | AJ35: =SUM(E35:AI35) -> 3
A36: 4 | B36: Jumlah surat suara yang tidak digunakan/tidak terpakai, termasuk sisa surat suara cadangan | E36: =E33-(E34+E35) -> 76 | F36: =F33-(F34+F35) -> 62 | G36: =G33-(G34+G35) -> 69 | H36: =H33-(H34+H35) -> 74 | I36: =I33-(I34+I35) -> 49 | J36: =J33-(J34+J35) -> 59 | K36: =K33-(K34+K35) -> 73 | L36: =L33-(L34+L35) -> 71 | ... AI36: =AI33-(AI34+AI35) -> 56 | AJ36: =SUM(E36:AI36) -> 2036
A38: III | B38: DATA PEMILIH DISABILITAS
B39: Jumlah seluruh Pemilih disabilitas yang menggunakan hak pilih | D39: LK | N39: 2 | AJ39: =SUM(E39:AI39) -> 2
D40: PR | K40: 1 | L40: 1 | N40: 6 | AJ40: =SUM(E40:AI40) -> 8
D41: JML | E41: =SUM(E39:E40) -> 0 | F41: =SUM(F39:F40) -> 0 | G41: =SUM(G39:G40) -> 0 | H41: =SUM(H39:H40) -> 0 | I41: =SUM(I39:I40) -> 0 | J41: =SUM(J39:J40) -> 0 | K41: =SUM(K39:K40) -> 1 | L41: =SUM(L39:L40) -> 1 | ... AI41: =SUM(AI39:AI40) -> 0 | AJ41: =SUM(E41:AI41) -> 10
A43: IV | B43: DATA RINCIAN PEROLEHAN SUARA PASANGAN CALON BUPATI DAN WAKIL BUPATI
A44: NOMOR DAN NAMA CALON
B45: 1 | C45: H. ANIES RASYID BASWEDAN, Ph.D. - Dr. (H.C.) H. A. MUHAIMIN ISKANDAR | E45: 24 | F45: 21 | G45: 15 | H45: 23 | I45: 30 | J45: 40 | K45: 28 | L45: 28 | M45: 46 | N45: 45 | O45: 24 | P45: 26 | Q45: 43 | R45: 51 | S45: 51 | T45: 33 | U45: 24 | V45: 14 | W45: 28 | X45: 32 | Y45: 28 | Z45: 16 | AA45: 26 | AB45: 26 | AC45: 27 | AD45: 37 | AE45: 25 | AF45: 52 | AG45: 42 | AH45: 24 | AI45: 29 | AJ45: =SUM(E45:AI45) -> 958
B46: 2 | C46: H. PRABOWO SUBIANTO - GIBRAN RAKABUMING RAKA | E46: 170 | F46: 154 | G46: 198 | H46: 153 | I46: 141 | J46: 185 | K46: 137 | L46: 108 | M46: 155 | N46: 145 | O46: 129 | P46: 167 | Q46: 159 | R46: 161 | S46: 122 | T46: 150 | U46: 139 | V46: 161 | W46: 140 | X46: 156 | Y46: 139 | Z46: 130 | AA46: 147 | AB46: 119 | AC46: 128 | AD46: 141 | AE46: 163 | AF46: 141 | AG46: 128 | AH46: 168 | AI46: 178 | AJ46: =SUM(E46:AI46) -> 4612
B47: 3 | C47: H. GANJAR PRANOWO, S.H., M.I.P. - Prof. Dr. H. M. MAHFUD MD | E47: 21 | F47: 20 | G47: 16 | H47: 36 | I47: 13 | J47: 15 | K47: 12 | L47: 24 | M47: 26 | N47: 24 | O47: 33 | P47: 20 | Q47: 17 | R47: 20 | S47: 33 | T47: 21 | U47: 21 | V47: 23 | W47: 25 | X47: 23 | Y47: 12 | Z47: 14 | AA47: 13 | AB47: 22 | AC47: 23 | AD47: 15 | AE47: 10 | AF47: 21 | AG47: 16 | AH47: 30 | AI47: 34 | AJ47: =SUM(E47:AI47) -> 653
A49: V | B49: DATA SUARA SAH DAN TIDAK SAH
B50: A. | C50: JUMLAH SELURUH SUARA SAH | E50: =SUM(E45:E47) -> 215 | F50: =SUM(F45:F47) -> 195 | G50: =SUM(G45:G47) -> 229 | H50: =SUM(H45:H47) -> 212 | I50: =SUM(I45:I47) -> 184 | J50: =SUM(J45:J47) -> 240 | K50: =SUM(K45:K47) -> 177 | L50: =SUM(L45:L47) -> 160 | ... AI50: =SUM(AI45:AI47) -> 241 | AJ50: =SUM(E50:AI50) -> 6223
B51: B. | C51: JUMLAH SUARA TIDAK SAH | E51: 7 | F51: 3 | G51: 2 | H51: 5 | I51: 2 | J51: 2 | K51: 4 | L51: 7 | M51: 2 | O51: 2 | Q51: 1 | R51: 1 | S51: 1 | T51: 6 | U51: 2 | W51: 2 | X51: 5 | Y51: 1 | Z51: 6 | AA51: 3 | AB51: 4 | AC51: 2 | AD51: 2 | AE51: 2 | AF51: 3 | AH51: 5 | AI51: 3 | AJ51: =SUM(E51:AI51) -> 85
B52: C. | C52: JUMLAH SELURUH SUARA SAH DAN SUARA TIDAK SAH (V.A + V.B) | E52: =SUM(E50:E51) -> 222 | F52: =SUM(F50:F51) -> 198 | G52: =SUM(G50:G51) -> 231 | H52: =SUM(H50:H51) -> 217 | I52: =SUM(I50:I51) -> 186 | J52: =SUM(J50:J51) -> 242 | K52: =SUM(K50:K51) -> 181 | L52: =SUM(L50:L51) -> 167 | ... AI52: =SUM(AI50:AI51) -> 244 | AJ52: =SUM(E52:AI52) -> 6308

Sheet SUMBERGONDO
C2: Kecamatan | D2: GLENMORE
C3: Kabupaten | D3: BANYUWANGI
C4: Provinsi | D4: JAWA TIMUR
C9: Kelurahan | D9: SUMBERGONDO
A12: I | B12: DATA PEMILIH DAN PENGGUNAAN HAK PILIH | AB12: JUMLAH AKHIR
A13: A | B13: DATA PEMILIH | E13: TPS 001 | F13: TPS 002 | G13: TPS 003 | H13: TPS 004 | I13: TPS 005 | J13: TPS 006 | K13: TPS 007 | L13: TPS 008 | M13: TPS 009 | N13: TPS 010 | O13: TPS 011 | P13: TPS 012 | Q13: TPS 013 | R13: TPS 014 | S13: TPS 015 | T13: TPS 016 | U13: TPS 017 | V13: TPS 018 | W13: TPS 019 | X13: TPS 020 | Y13: TPS 021 | Z13: TPS 022 | AA13: TPS 023
B14: Jumlah Pemilih dalam Daftar Pemilih Tetap (DPT) | D14: LK | E14: 126 | F14: 129 | G14: 134 | H14: 125 | I14: 79 | J14: 90 | K14: 102 | L14: 83 | M14: 154 | N14: 128 | O14: 152 | P14: 134 | Q14: 146 | R14: 144 | S14: 137 | T14: 130 | U14: 143 | V14: 131 | W14: 124 | X14: 143 | Y14: 134 | Z14: 117 | AA14: 86 | AB14: =SUM(E14:AA14) -> 2871
D15: PR | E15: 123 | F15: 119 | G15: 158 | H15: 130 | I15: 81 | J15: 80 | K15: 96 | L15: 86 | M15: 146 | N15: 122 | O15: 141 | P15: 144 | Q15: 133 | R15: 148 | S15: 137 | T15: 143 | U15: 155 | V15: 130 | W15: 144 | X15: 146 | Y15: 124 | Z15: 113 | AA15: 80 | AB15: =SUM(E15:AA15) -> 2879
D16: JML | E16: =SUM(E14:E15) -> 249 | F16: =SUM(F14:F15) -> 248 | G16: =SUM(G14:G15) -> 292 | H16: =SUM(H14:H15) -> 255 | I16: =SUM(I14:I15) -> 160 | J16: =SUM(J14:J15) -> 170 | K16: =SUM(K14:K15) -> 198 | L16: =SUM(L14:L15) -> 169 | ... AA16: =SUM(AA14:AA15) -> 166 | AB16: =SUM(E16:AA16) -> 5750
A18: B | B18: PENGGUNA HAK PILIH
B19: 1. | C19: Jumlah pengguna hak pilih dalam Daftar Pemilih Tetap (DPT) | D19: LK | E19: 81 | F19: 83 | G19: 103 | H19: 97 | I19: 59 | J19: 71 | K19: 74 | L19: 61 | M19: 112 | N19: 98 | O19: 109 | P19: 105 | Q19: 95 | R19: 105 | S19: 88 | T19: 96 | U19: 116 | V19: 90 | W19: 93 | X19: 93 | Y19: 103 | Z19: 63 | AA19: 59 | AB19: =SUM(E19:AA19) -> 2054
D20: PR | E20: 91 | F20: 105 | G20: 131 | H20: 98 | I20: 62 | J20: 63 | K20: 67 | L20: 64 | M20: 117 | N20: 89 | O20: 119 | P20: 109 | Q20: 106 | R20: 117 | S20: 99 | T20: 114 | U20: 124 | V20: 100 | W20: 108 | X20: 126 | Y20: 91 | Z20: 79 | AA20: 61 | AB20: =SUM(E20:AA20) -> 2240
D21: JML | E21: =SUM(E19:E20) -> 172 | F21: =SUM(F19:F20) -> 188 | G21: =SUM(G19:G20) -> 234 | H21: =SUM(H19:H20) -> 195 | I21: =SUM(I19:I20) -> 121 | J21: =SUM(J19:J20) -> 134 | K21: =SUM(K19:K20) -> 141 | L21: =SUM(L19:L20) -> 125 | ... AA21: =SUM(AA19:AA20) -> 120 | AB21: =SUM(E21:AA21) -> 4294
B22: 2. | C22: Jumlah pengguna hak pilih dalam Daftar Pemilih Tambahan (DPTb) | D22: LK | F22: 1 | I22: 2 | AB22: =SUM(E22:AA22) -> 3
D23: PR | I23: 1 | P23: 1 | Q23: 1 | AB23: =SUM(E23:AA23) -> 3
D24: JML | E24: =SUM(E22:E23) -> 0 | F24: =SUM(F22:F23) -> 1 | G24: =SUM(G22:G23) -> 0 | H24: =SUM(H22:H23) -> 0 | I24: =SUM(I22:I23) -> 3 | J24: =SUM(J22:J23) -> 0 | K24: =SUM(K22:K23) -> 0 | L24: =SUM(L22:L23) -> 0 | ... AA24: =SUM(AA22:AA23) -> 0 | AB24: =SUM(E24:AA24) -> 6
B25: 3. | C25: Jumlah pengguna hak pilih dalam Daftar Pemilih Khusus (DPK) | D25: LK | H25: 1 | J25: 1 | P25: 2 | Q25: 2 | V25: 2 | X25: 4 | Y25: 1 | AB25: =SUM(E25:AA25) -> 13
D26: PR | E26: 3 | F26: 1 | G26: 1 | H26: 1 | J26: 3 | K26: 3 | L26: 1 | N26: 1 | P26: 2 | T26: 1 | U26: 1 | V26: 2 | W26: 1 | X26: 3 | Y26: 4 | AA26: 1 | AB26: =SUM(E26:AA26) -> 29
D27: JML | E27: =SUM(E25:E26) -> 3 | F27: =SUM(F25:F26) -> 1 | G27: =SUM(G25:G26) -> 1 | H27: =SUM(H25:H26) -> 2 | I27: =SUM(I25:I26) -> 0 | J27: =SUM(J25:J26) -> 4 | K27: =SUM(K25:K26) -> 3 | L27: =SUM(L25:L26) -> 1 | ... AA27: =SUM(AA25:AA26) -> 1 | AB27: =SUM(E27:AA27) -> 42
B28: 4. | C28: Jumlah Pengguna Hak Pilih (B.1+B.2+B.3) | D28: LK | E28: =SUM(E19,E22,E25) -> 81 | F28: =SUM(F19,F22,F25) -> 84 | G28: =SUM(G19,G22,G25) -> 103 | H28: =SUM(H19,H22,H25) -> 98 | I28: =SUM(I19,I22,I25) -> 61 | J28: =SUM(J19,J22,J25) -> 72 | K28: =SUM(K19,K22,K25) -> 74 | L28: =SUM(L19,L22,L25) -> 61 | ... AA28: =SUM(AA19,AA22,AA25) -> 59 | AB28: =SUM(E28:AA28) -> 2070
D29: PR | E29: =SUM(E20,E23,E26) -> 94 | F29: =SUM(F20,F23,F26) -> 106 | G29: =SUM(G20,G23,G26) -> 132 | H29: =SUM(H20,H23,H26) -> 99 | I29: =SUM(I20,I23,I26) -> 63 | J29: =SUM(J20,J23,J26) -> 66 | K29: =SUM(K20,K23,K26) -> 70 | L29: =SUM(L20,L23,L26) -> 65 | ... AA29: =SUM(AA20,AA23,AA26) -> 62 | AB29: =SUM(E29:AA29) -> 2272
D30: JML | E30: =SUM(E28:E29) -> 175 | F30: =SUM(F28:F29) -> 190 | G30: =SUM(G28:G29) -> 235 | H30: =SUM(H28:H29) -> 197 | I30: =SUM(I28:I29) -> 124 | J30: =SUM(J28:J29) -> 138 | K30: =SUM(K28:K29) -> 144 | L30: =SUM(L28:L29) -> 126 | ... AA30: =SUM(AA28:AA29) -> 121 | AB30: =SUM(E30:AA30) -> 4342
A32: II | B32: DATA PENGGUNAAN SURAT SUARA
A33: 1 | B33: Jumlah surat suara yang diterima, termasuk surat suara cadangan 2,5% dari DPT | E33: 255 | F33: 253 | G33: 298 | H33: 257 | I33: 164 | J33: 176 | K33: 203 | L33: 173 | M33: 302 | N33: 251 | O33: 299 | P33: 284 | Q33: 286 | R33: 298 | S33: 280 | T33: 275 | U33: 305 | V33: 268 | W33: 274 | X33: 293 | Y33: 268 | Z33: 235 | AA33: 172 | AB33: =SUM(E33:AA33) -> 5869
A34: 2 | B34: Jumlah surat suara yang digunakan | E34: 175 | F34: 190 | G34: 235 | H34: 197 | I34: 124 | J34: 138 | K34: 144 | L34: 126 | M34: 229 | N34: 188 | O34: 228 | P34: 219 | Q34: 204 | R34: 222 | S34: 187 | T34: 211 | U34: 241 | V34: 194 | W34: 202 | X34: 226 | Y34: 199 | Z34: 142 | AA34: 121 | AB34: =SUM(E34:AA34) -> 4342
A35: 3 | B35: Jumlah surat suara dikembalikan oleh pemilih (karena rusak atau keliru coblos) | N35: 1 | Y35: 2 | AB35: =SUM(E35:AA35) -> 3
A36: 4 | B36: Jumlah surat suara yang tidak digunakan/tidak terpakai, termasuk sisa surat suara cadangan | E36: =E33-(E34+E35) -> 80 | F36: =F33-(F34+F35) -> 63 | G36: =G33-(G34+G35) -> 63 | H36: =H33-(H34+H35) -> 60 | I36: =I33-(I34+I35) -> 40 | J36: =J33-(J34+J35) -> 38 | K36: =K33-(K34+K35) -> 59 | L36: =L33-(L34+L35) -> 47 | ... AA36: =AA33-(AA34+AA35) -> 51 | AB36: =SUM(E36:AA36) -> 1524
A38: III | B38: DATA PEMILIH DISABILITAS
B39: Jumlah seluruh Pemilih disabilitas yang menggunakan hak pilih | D39: LK | J39: 1 | V39: 1 | AB39: =SUM(E39:AA39) -> 2
D40: PR | AB40: =SUM(E40:AA40) -> 0
D41: JML | E41: =SUM(E39:E40) -> 0 | F41: =SUM(F39:F40) -> 0 | G41: =SUM(G39:G40) -> 0 | H41: =SUM(H39:H40) -> 0 | I41: =SUM(I39:I40) -> 0 | J41: =SUM(J39:J40) -> 1 | K41: =SUM(K39:K40) -> 0 | L41: =SUM(L39:L40) -> 0 | ... AA41: =SUM(AA39:AA40) -> 0 | AB41: =SUM(E41:AA41) -> 2
A43: IV | B43: DATA RINCIAN PEROLEHAN SUARA PASANGAN CALON BUPATI DAN WAKIL BUPATI
A44: NOMOR DAN NAMA CALON
B45: 1 | C45: H. ANIES RASYID BASWEDAN, Ph.D. - Dr. (H.C.) H. A. MUHAIMIN ISKANDAR | E45: 20 | F45: 36 | G45: 79 | H45: 24 | I45: 15 | J45: 6 | K45: 20 | L45: 9 | M45: 6 | N45: 2 | O45: 15 | P45: 20 | Q45: 16 | R45: 8 | S45: 9 | T45: 38 | U45: 13 | V45: 26 | W45: 24 | X45: 39 | Y45: 19 | Z45: 8 | AA45: 8 | AB45: =SUM(E45:AA45) -> 460
B46: 2 | C46: H. PRABOWO SUBIANTO - GIBRAN RAKABUMING RAKA | E46: 125 | F46: 114 | G46: 122 | H46: 127 | I46: 83 | J46: 85 | K46: 105 | L46: 95 | M46: 169 | N46: 130 | O46: 168 | P46: 131 | Q46: 167 | R46: 197 | S46: 120 | T46: 144 | U46: 188 | V46: 143 | W46: 132 | X46: 162 | Y46: 149 | Z46: 120 | AA46: 95 | AB46: =SUM(E46:AA46) -> 3071
B47: 3 | C47: H. GANJAR PRANOWO, S.H., M.I.P. - Prof. Dr. H. M. MAHFUD MD | E47: 26 | F47: 37 | G47: 32 | H47: 40 | I47: 25 | J47: 45 | K47: 18 | L47: 20 | M47: 49 | N47: 51 | O47: 40 | P47: 60 | Q47: 13 | R47: 14 | S47: 53 | T47: 24 | U47: 37 | V47: 21 | W47: 41 | X47: 22 | Y47: 29 | Z47: 12 | AA47: 14 | AB47: =SUM(E47:AA47) -> 723
A49: V | B49: DATA SUARA SAH DAN TIDAK SAH
B50: A. | C50: JUMLAH SELURUH SUARA SAH | E50: =SUM(E45:E47) -> 171 | F50: =SUM(F45:F47) -> 187 | G50: =SUM(G45:G47) -> 233 | H50: =SUM(H45:H47) -> 191 | I50: =SUM(I45:I47) -> 123 | J50: =SUM(J45:J47) -> 136 | K50: =SUM(K45:K47) -> 143 | L50: =SUM(L45:L47) -> 124 | ... AA50: =SUM(AA45:AA47) -> 117 | AB50: =SUM(E50:AA50) -> 4254
B51: B. | C51: JUMLAH SUARA TIDAK SAH | E51: 4 | F51: 3 | G51: 2 | H51: 6 | I51: 1 | J51: 2 | K51: 1 | L51: 2 | M51: 5 | N51: 5 | O51: 5 | P51: 8 | Q51: 8 | R51: 3 | S51: 5 | T51: 5 | U51: 3 | V51: 4 | W51: 5 | X51: 3 | Y51: 2 | Z51: 2 | AA51: 4 | AB51: =SUM(E51:AA51) -> 88
B52: C. | C52: JUMLAH SELURUH SUARA SAH DAN SUARA TIDAK SAH (V.A + V.B) | E52: =SUM(E50:E51) -> 175 | F52: =SUM(F50:F51) -> 190 | G52: =SUM(G50:G51) -> 235 | H52: =SUM(H50:H51) -> 197 | I52: =SUM(I50:I51) -> 124 | J52: =SUM(J50:J51) -> 138 | K52: =SUM(K50:K51) -> 144 | L52: =SUM(L50:L51) -> 126 | ... AA52: =SUM(AA50:AA51) -> 121 | AB52: =SUM(E52:AA52) -> 4342

Sheet TEGALHARJO
C2: Kecamatan | D2: GLENMORE
C3: Kabupaten | D3: BANYUWANGI
C4: Provinsi | D4: JAWA TIMUR
C9: Kelurahan | D9: TEGALHARJO
A12: I | B12: DATA PEMILIH DAN PENGGUNAAN HAK PILIH | AP12: JUMLAH AKHIR
A13: A | B13: DATA PEMILIH | E13: TPS 001 | F13: TPS 002 | G13: TPS 003 | H13: TPS 004 | I13: TPS 005 | J13: TPS 006 | K13: TPS 007 | L13: TPS 008 | M13: TPS 009 | N13: TPS 010 | O13: TPS 011 | P13: TPS 012 | Q13: TPS 013 | R13: TPS 014 | S13: TPS 015 | T13: TPS 016 | U13: TPS 017 | V13: TPS 018 | W13: TPS 019 | X13: TPS 020 | Y13: TPS 021 | Z13: TPS 022 | AA13: TPS 023 | AB13: TPS 024 | AC13: TPS 025 | AD13: TPS 026 | AE13: TPS 027 | AF13: TPS 028 | AG13: TPS 029 | AH13: TPS 030 | AI13: TPS 031 | AJ13: TPS 032 | AK13: TPS 033 | AL13: TPS 034 | AM13: TPS 035 | AN13: TPS 036 | AO13: TPS 037
B14: Jumlah Pemilih dalam Daftar Pemilih Tetap (DPT) | D14: LK | E14: 146 | F14: 90 | G14: 124 | H14: 88 | I14: 100 | J14: 130 | K14: 149 | L14: 149 | M14: 146 | N14: 129 | O14: 102 | P14: 117 | Q14: 117 | R14: 142 | S14: 147 | T14: 127 | U14: 81 | V14: 139 | W14: 98 | X14: 137 | Y14: 141 | Z14: 134 | AA14: 102 | AB14: 132 | AC14: 88 | AD14: 88 | AE14: 97 | AF14: 105 | AG14: 112 | AH14: 117 | AI14: 107 | AJ14: 104 | AK14: 109 | AL14: 143 | AM14: 126 | AN14: 109 | AO14: 99 | AP14: =SUM(E14:AO14) -> 4371
D15: PR | E15: 148 | F15: 85 | G15: 124 | H15: 94 | I15: 110 | J15: 116 | K15: 144 | L15: 145 | M15: 145 | N15: 116 | O15: 108 | P15: 114 | Q15: 135 | R15: 153 | S15: 143 | T15: 141 | U15: 80 | V15: 145 | W15: 96 | X15: 131 | Y15: 149 | Z15: 142 | AA15: 109 | AB15: 132 | AC15: 107 | AD15: 96 | AE15: 102 | AF15: 103 | AG15: 141 | AH15: 103 | AI15: 105 | AJ15: 116 | AK15: 111 | AL15: 137 | AM15: 122 | AN15: 115 | AO15: 103 | AP15: =SUM(E15:AO15) -> 4466
D16: JML | E16: =SUM(E14:E15) -> 294 | F16: =SUM(F14:F15) -> 175 | G16: =SUM(G14:G15) -> 248 | H16: =SUM(H14:H15) -> 182 | I16: =SUM(I14:I15) -> 210 | J16: =SUM(J14:J15) -> 246 | K16: =SUM(K14:K15) -> 293 | L16: =SUM(L14:L15) -> 294 | ... AO16: =SUM(AO14:AO15) -> 202 | AP16: =SUM(E16:AO16) -> 8837
A18: B | B18: PENGGUNA HAK PILIH
B19: 1. | C19: Jumlah pengguna hak pilih dalam Daftar Pemilih Tetap (DPT) | D19: LK | E19: 99 | F19: 69 | G19: 95 | H19: 53 | I19: 84 | J19: 98 | K19: 111 | L19: 112 | M19: 109 | N19: 90 | O19: 77 | P19: 80 | Q19: 95 | R19: 101 | S19: 107 | T19: 88 | U19: 64 | V19: 114 | W19: 74 | X19: 104 | Y19: 115 | Z19: 85 | AA19: 75 | AB19: 89 | AC19: 73 | AD19: 69 | AE19: 82 | AF19: 83 | AG19: 89 | AH19: 92 | AI19: 74 | AJ19: 86 | AK19: 93 | AL19: 95 | AM19: 104 | AN19: 82 | AO19: 90 | AP19: =SUM(E19:AO19) -> 3300
D20: PR | E20: 122 | F20: 69 | G20: 98 | H20: 73 | I20: 75 | J20: 97 | K20: 121 | L20: 123 | M20: 119 | N20: 94 | O20: 84 | P20: 91 | Q20: 108 | R20: 116 | S20: 106 | T20: 103 | U20: 66 | V20: 122 | W20: 79 | X20: 107 | Y20: 125 | Z20: 106 | AA20: 94 | AB20: 89 | AC20: 87 | AD20: 77 | AE20: 86 | AF20: 93 | AG20: 107 | AH20: 89 | AI20: 87 | AJ20: 98 | AK20: 92 | AL20: 115 | AM20: 99 | AN20: 98 | AO20: 98 | AP20: =SUM(E20:AO20) -> 3613
D21: JML | E21: =SUM(E19:E20) -> 221 | F21: =SUM(F19:F20) -> 138 | G21: =SUM(G19:G20) -> 193 | H21: =SUM(H19:H20) -> 126 | I21: =SUM(I19:I20) -> 159 | J21: =SUM(J19:J20) -> 195 | K21: =SUM(K19:K20) -> 232 | L21: =SUM(L19:L20) -> 235 | ... AO21: =SUM(AO19:AO20) -> 188 | AP21: =SUM(E21:AO21) -> 6913
B22: 2. | C22: Jumlah pengguna hak pilih dalam Daftar Pemilih Tambahan (DPTb) | D22: LK | I22: 1 | P22: 1 | Q22: 2 | U22: 1 | V22: 2 | W22: 1 | AG22: 1 | AH22: 1 | AI22: 1 | AJ22: 2 | AK22: 1 | AM22: 1 | AN22: 1 | AO22: 1 | AP22: =SUM(E22:AO22) -> 17
D23: PR | M23: 1 | N23: 1 | O23: 1 | Q23: 2 | R23: 3 | S23: 1 | U23: 1 | V23: 2 | W23: 1 | Y23: 1 | AF23: 2 | AJ23: 2 | AP23: =SUM(E23:AO23) -> 18
D24: JML | E24: =SUM(E22:E23) -> 0 | F24: =SUM(F22:F23) -> 0 | G24: =SUM(G22:G23) -> 0 | H24: =SUM(H22:H23) -> 0 | I24: =SUM(I22:I23) -> 1 | J24: =SUM(J22:J23) -> 0 | K24: =SUM(K22:K23) -> 0 | L24: =SUM(L22:L23) -> 0 | ... AO24: =SUM(AO22:AO23) -> 1 | AP24: =SUM(E24:AO24) -> 35
B25: 3. | C25: Jumlah pengguna hak pilih dalam Daftar Pemilih Khusus (DPK) | D25: LK | F25: 1 | H25: 1 | J25: 1 | L25: 1 | P25: 1 | R25: 4 | T25: 3 | V25: 1 | W25: 1 | X25: 2 | Z25: 2 | AA25: 4 | AB25: 4 | AE25: 3 | AH25: 5 | AI25: 2 | AK25: 1 | AP25: =SUM(E25:AO25) -> 37
D26: PR | F26: 1 | G26: 2 | H26: 1 | I26: 3 | J26: 3 | L26: 2 | M26: 1 | O26: 3 | P26: 1 | R26: 9 | T26: 5 | V26: 1 | X26: 1 | Z26: 3 | AA26: 3 | AB26: 3 | AC26: 2 | AE26: 2 | AH26: 4 | AI26: 3 | AK26: 2 | AM26: 4 | AP26: =SUM(E26:AO26) -> 59
D27: JML | E27: =SUM(E25:E26) -> 0 | F27: =SUM(F25:F26) -> 2 | G27: =SUM(G25:G26) -> 2 | H27: =SUM(H25:H26) -> 2 | I27: =SUM(I25:I26) -> 3 | J27: =SUM(J25:J26) -> 4 | K27: =SUM(K25:K26) -> 0 | L27: =SUM(L25:L26) -> 3 | ... AO27: =SUM(AO25:AO26) -> 0 | AP27: =SUM(E27:AO27) -> 96
B28: 4. | C28: Jumlah Pengguna Hak Pilih (B.1+B.2+B.3) | D28: LK | E28: =SUM(E19,E22,E25) -> 99 | F28: =SUM(F19,F22,F25) -> 70 | G28: =SUM(G19,G22,G25) -> 95 | H28: =SUM(H19,H22,H25) -> 54 | I28: =SUM(I19,I22,I25) -> 85 | J28: =SUM(J19,J22,J25) -> 99 | K28: =SUM(K19,K22,K25) -> 111 | L28: =SUM(L19,L22,L25) -> 113 | ... AO28: =SUM(AO19,AO22,AO25) -> 91 | AP28: =SUM(E28:AO28) -> 3354
D29: PR | E29: =SUM(E20,E23,E26) -> 122 | F29: =SUM(F20,F23,F26) -> 70 | G29: =SUM(G20,G23,G26) -> 100 | H29: =SUM(H20,H23,H26) -> 74 | I29: =SUM(I20,I23,I26) -> 78 | J29: =SUM(J20,J23,J26) -> 100 | K29: =SUM(K20,K23,K26) -> 121 | L29: =SUM(L20,L23,L26) -> 125 | ... AO29: =SUM(AO20,AO23,AO26) -> 98 | AP29: =SUM(E29:AO29) -> 3690
D30: JML | E30: =SUM(E28:E29) -> 221 | F30: =SUM(F28:F29) -> 140 | G30: =SUM(G28:G29) -> 195 | H30: =SUM(H28:H29) -> 128 | I30: =SUM(I28:I29) -> 163 | J30: =SUM(J28:J29) -> 199 | K30: =SUM(K28:K29) -> 232 | L30: =SUM(L28:L29) -> 238 | ... AO30: =SUM(AO28:AO29) -> 189 | AP30: =SUM(E30:AO30) -> 7044
A32: II | B32: DATA PENGGUNAAN SURAT SUARA
A33: 1 | B33: Jumlah surat suara yang diterima, termasuk surat suara cadangan 2,5% dari DPT | E33: 305 | F33: 179 | G33: 254 | H33: 186 | I33: 215 | J33: 250 | K33: 299 | L33: 300 | M33: 297 | N33: 250 | O33: 215 | P33: 236 | Q33: 258 | R33: 302 | S33: 286 | T33: 272 | U33: 165 | V33: 291 | W33: 198 | X33: 274 | Y33: 296 | Z33: 282 | AA33: 216 | AB33: 271 | AC33: 194 | AD33: 188 | AE33: 205 | AF33: 213 | AG33: 259 | AH33: 225 | AI33: 217 | AJ33: 225 | AK33: 225 | AL33: 286 | AM33: 255 | AN33: 229 | AO33: 207 | AP33: =SUM(E33:AO33) -> 9025
A34: 2 | B34: Jumlah surat suara yang digunakan | E34: 221 | F34: 140 | G34: 195 | H34: 128 | I34: 163 | J34: 199 | K34: 232 | L34: 238 | M34: 230 | N34: 185 | O34: 165 | P34: 174 | Q34: 207 | R34: 233 | S34: 214 | T34: 199 | U34: 132 | V34: 242 | W34: 156 | X34: 214 | Y34: 241 | Z34: 196 | AA34: 176 | AB34: 185 | AC34: 162 | AD34: 146 | AE34: 173 | AF34: 178 | AG34: 197 | AH34: 191 | AI34: 167 | AJ34: 188 | AK34: 189 | AL34: 210 | AM34: 208 | AN34: 181 | AO34: 189 | AP34: =SUM(E34:AO34) -> 7044
A35: 3 | B35: Jumlah surat suara dikembalikan oleh pemilih (karena rusak atau keliru coblos) | K35: 1 | Q35: 1 | V35: 2 | W35: 2 | AB35: 1 | AF35: 2 | AP35: =SUM(E35:AO35) -> 9
A36: 4 | B36: Jumlah surat suara yang tidak digunakan/tidak terpakai, termasuk sisa surat suara cadangan | E36: =E33-(E34+E35) -> 84 | F36: =F33-(F34+F35) -> 39 | G36: =G33-(G34+G35) -> 59 | H36: =H33-(H34+H35) -> 58 | I36: =I33-(I34+I35) -> 52 | J36: =J33-(J34+J35) -> 51 | K36: =K33-(K34+K35) -> 66 | L36: =L33-(L34+L35) -> 62 | ... AO36: =AO33-(AO34+AO35) -> 18 | AP36: =SUM(E36:AO36) -> 1972
A38: III | B38: DATA PEMILIH DISABILITAS
