Workbook

Sheet PPWP
C8: Kecamatan | D8: BLIMBINGSARI
C9: Kabupaten | D9: BANYUWANGI
C10: Provinsi | D10: JAWA TIMUR
A12: I | B12: DATA PEMILIH DAN PENGGUNAAN HAK PILIH | E12: JUMLAH AKHIR
A13: A | B13: DATA PEMILIH
B14: Jumlah Pemilih dalam Daftar Pemilih Tetap (DPT) | D14: LK | E14: =BADEAN!AB14+BLIMBINGSARI!U14+BOMO!W14+GINTANGAN!Z14+KALIGUNG!R14+KAOTAN!M14+KARANGREJO!P14+PATOMAN!T14+SUKOJATI!P14+WATUKEBO!AK14 -> 21865
D15: PR | E15: =BADEAN!AB15+BLIMBINGSARI!U15+BOMO!W15+GINTANGAN!Z15+KALIGUNG!R15+KAOTAN!M15+KARANGREJO!P15+PATOMAN!T15+SUKOJATI!P15+WATUKEBO!AK15 -> 21891
D16: JML | E16: =SUM(E14:E15) -> 43756
A18: B | B18: PENGGUNA HAK PILIH
B19: 1. | C19: Jumlah pengguna hak pilih dalam Daftar Pemilih Tetap (DPT) | D19: LK | E19: =BADEAN!AB19+BLIMBINGSARI!U19+BOMO!W19+GINTANGAN!Z19+KALIGUNG!R19+KAOTAN!M19+KARANGREJO!P19+PATOMAN!T19+SUKOJATI!P19+WATUKEBO!AK19 -> 16413
D20: PR | E20: =BADEAN!AB20+BLIMBINGSARI!U20+BOMO!W20+GINTANGAN!Z20+KALIGUNG!R20+KAOTAN!M20+KARANGREJO!P20+PATOMAN!T20+SUKOJATI!P20+WATUKEBO!AK20 -> 17835
D21: JML | E21: =SUM(E19:E20) -> 34248
B22: 2. | C22: Jumlah pengguna hak pilih dalam Daftar Pemilih Tambahan (DPTb) | D22: LK | E22: =BADEAN!AB22+BLIMBINGSARI!U22+BOMO!W22+GINTANGAN!Z22+KALIGUNG!R22+KAOTAN!M22+KARANGREJO!P22+PATOMAN!T22+SUKOJATI!P22+WATUKEBO!AK22 -> 516
D23: PR | E23: =BADEAN!AB23+BLIMBINGSARI!U23+BOMO!W23+GINTANGAN!Z23+KALIGUNG!R23+KAOTAN!M23+KARANGREJO!P23+PATOMAN!T23+SUKOJATI!P23+WATUKEBO!AK23 -> 65
D24: JML | E24: =SUM(E22:E23) -> 581
B25: 3. | C25: Jumlah pengguna hak pilih dalam Daftar Pemilih Khusus (DPK) | D25: LK | E25: =BADEAN!AB25+BLIMBINGSARI!U25+BOMO!W25+GINTANGAN!Z25+KALIGUNG!R25+KAOTAN!M25+KARANGREJO!P25+PATOMAN!T25+SUKOJATI!P25+WATUKEBO!AK25 -> 100
D26: PR | E26: =BADEAN!AB26+BLIMBINGSARI!U26+BOMO!W26+GINTANGAN!Z26+KALIGUNG!R26+KAOTAN!M26+KARANGREJO!P26+PATOMAN!T26+SUKOJATI!P26+WATUKEBO!AK26 -> 140
D27: JML | E27: =SUM(E25:E26) -> 240
B28: 4. | C28: Jumlah Pengguna Hak Pilih (B.1+B.2+B.3) | D28: LK | E28: =E19+E22+E25 -> 17029
D29: PR | E29: =E20+E23+E26 -> 18040
D30: JML | E30: =SUM(E28:E29) -> 35069
A32: II | B32: DATA PENGGUNAAN SURAT SUARA
A33: 1 | B33: Jumlah surat suara yang diterima, termasuk surat suara cadangan 2,5% dari DPT | E33: =BADEAN!AB33+BLIMBINGSARI!U33+BOMO!W33+GINTANGAN!Z33+KALIGUNG!R33+KAOTAN!M33+KARANGREJO!P33+PATOMAN!T33+SUKOJATI!P33+WATUKEBO!AK33 -> 44731
A34: 2 | B34: Jumlah surat suara yang digunakan | E34: =BADEAN!AB34+BLIMBINGSARI!U34+BOMO!W34+GINTANGAN!Z34+KALIGUNG!R34+KAOTAN!M34+KARANGREJO!P34+PATOMAN!T34+SUKOJATI!P34+WATUKEBO!AK34 -> 35069
A35: 3 | B35: Jumlah surat suara dikembalikan oleh pemilih (karena rusak atau keliru coblos) | E35: =BADEAN!AB35+BLIMBINGSARI!U35+BOMO!W35+GINTANGAN!Z35+KALIGUNG!R35+KAOTAN!M35+KARANGREJO!P35+PATOMAN!T35+SUKOJATI!P35+WATUKEBO!AK35 -> 103
A36: 4 | B36: Jumlah surat suara yang tidak digunakan/tidak terpakai, termasuk sisa surat suara cadangan | E36: =E33-(E34+E35) -> 9559
A38: III | B38: DATA PEMILIH DISABILITAS
B39: Jumlah seluruh Pemilih disabilitas yang menggunakan hak pilih | D39: LK | E39: =BADEAN!AB39+BLIMBINGSARI!U39+BOMO!W39+GINTANGAN!Z39+KALIGUNG!R39+KAOTAN!M39+KARANGREJO!P39+PATOMAN!T39+SUKOJATI!P39+WATUKEBO!AK39 -> 48
D40: PR | E40: =BADEAN!AB40+BLIMBINGSARI!U40+BOMO!W40+GINTANGAN!Z40+KALIGUNG!R40+KAOTAN!M40+KARANGREJO!P40+PATOMAN!T40+SUKOJATI!P40+WATUKEBO!AK40 -> 51
D41: JML | E41: =SUM(E39:E40) -> 99
A43: IV | B43: DATA RINCIAN PEROLEHAN SUARA PASANGAN CALON BUPATI DAN WAKIL BUPATI
A44: NOMOR DAN NAMA CALON
B45: 1 | C45: H. ANIES RASYID BASWEDAN, Ph.D. - Dr. (H.C.) H. A. MUHAIMIN ISKANDAR | E45: =BADEAN!AB45+BLIMBINGSARI!U45+BOMO!W45+GINTANGAN!Z45+KALIGUNG!R45+KAOTAN!M45+KARANGREJO!P45+PATOMAN!T45+SUKOJATI!P45+WATUKEBO!AK45 -> 3710
B46: 2 | C46: H. PRABOWO SUBIANTO - GIBRAN RAKABUMING RAKA | E46: =BADEAN!AB46+BLIMBINGSARI!U46+BOMO!W46+GINTANGAN!Z46+KALIGUNG!R46+KAOTAN!M46+KARANGREJO!P46+PATOMAN!T46+SUKOJATI!P46+WATUKEBO!AK46 -> 25646
B47: 3 | C47: H. GANJAR PRANOWO, S.H., M.I.P. - Prof. Dr. H. M. MAHFUD MD | E47: =BADEAN!AB47+BLIMBINGSARI!U47+BOMO!W47+GINTANGAN!Z47+KALIGUNG!R47+KAOTAN!M47+KARANGREJO!P47+PATOMAN!T47+SUKOJATI!P47+WATUKEBO!AK47 -> 4996
A49: V | B49: DATA SUARA SAH DAN TIDAK SAH
B50: A. | C50: JUMLAH SELURUH SUARA SAH | E50: =BADEAN!AB50+BLIMBINGSARI!U50+BOMO!W50+GINTANGAN!Z50+KALIGUNG!R50+KAOTAN!M50+KARANGREJO!P50+PATOMAN!T50+SUKOJATI!P50+WATUKEBO!AK50 -> 34352
B51: B. | C51: JUMLAH SUARA TIDAK SAH | E51: =BADEAN!AB51+BLIMBINGSARI!U51+BOMO!W51+GINTANGAN!Z51+KALIGUNG!R51+KAOTAN!M51+KARANGREJO!P51+PATOMAN!T51+SUKOJATI!P51+WATUKEBO!AK51 -> 717
B52: C. | C52: JUMLAH SELURUH SUARA SAH DAN SUARA TIDAK SAH (V.A + V.B) | E52: =SUM(E50:E51) -> 35069

Sheet BADEAN
C2: Kecamatan | D2: BLIMBINGSARI
C3: Kabupaten | D3: BANYUWANGI
C4: Provinsi | D4: JAWA TIMUR
C9: Kelurahan | D9: BADEAN
A12: I | B12: DATA PEMILIH DAN PENGGUNAAN HAK PILIH | AB12: JUMLAH AKHIR
A13: A | B13: DATA PEMILIH | E13: TPS 001 | F13: TPS 002 | G13: TPS 003 | H13: TPS 004 | I13: TPS 005 | J13: TPS 006 | K13: TPS 007 | L13: TPS 008 | M13: TPS 009 | N13: TPS 010 | O13: TPS 011 | P13: TPS 012 | Q13: TPS 013 | R13: TPS 014 | S13: TPS 015 | T13: TPS 016 | U13: TPS 017 | V13: TPS 018 | W13: TPS 019 | X13: TPS 020 | Y13: TPS 021 | Z13: TPS 022 | AA13: TPS 023
B14: Jumlah Pemilih dalam Daftar Pemilih Tetap (DPT) | D14: LK | E14: 135 | F14: 117 | G14: 109 | H14: 108 | I14: 137 | J14: 145 | K14: 122 | L14: 119 | M14: 144 | N14: 134 | O14: 146 | P14: 128 | Q14: 141 | R14: 115 | S14: 85 | T14: 89 | U14: 124 | V14: 120 | W14: 134 | X14: 136 | Y14: 131 | Z14: 125 | AA14: 125 | AB14: =SUM(E14:AA14) -> 2869
D15: PR | E15: 130 | F15: 129 | G15: 141 | H15: 122 | I15: 129 | J15: 134 | K15: 132 | L15: 151 | M15: 131 | N15: 143 | O15: 129 | P15: 126 | Q15: 125 | R15: 114 | S15: 102 | T15: 101 | U15: 129 | V15: 131 | W15: 126 | X15: 122 | Y15: 124 | Z15: 116 | AA15: 114 | AB15: =SUM(E15:AA15) -> 2901
D16: JML | E16: =SUM(E14:E15) -> 265 | F16: =SUM(F14:F15) -> 246 | G16: =SUM(G14:G15) -> 250 | H16: =SUM(H14:H15) -> 230 | I16: =SUM(I14:I15) -> 266 | J16: =SUM(J14:J15) -> 279 | K16: =SUM(K14:K15) -> 254 | L16: =SUM(L14:L15) -> 270 | ... AA16: =SUM(AA14:AA15) -> 239 | AB16: =SUM(E16:AA16) -> 5770
A18: B | B18: PENGGUNA HAK PILIH
B19: 1. | C19: Jumlah pengguna hak pilih dalam Daftar Pemilih Tetap (DPT) | D19: LK | E19: 111 | F19: 99 | G19: 84 | H19: 86 | I19: 104 | J19: 102 | K19: 85 | L19: 72 | M19: 104 | N19: 93 | O19: 106 | P19: 104 | Q19: 93 | R19: 67 | S19: 64 | T19: 55 | U19: 92 | V19: 91 | W19: 100 | X19: 98 | Y19: 100 | Z19: 104 | AA19: 95 | AB19: =SUM(E19:AA19) -> 2109
D20: PR | E20: 114 | F20: 104 | G20: 115 | H20: 98 | I20: 108 | J20: 102 | K20: 120 | L20: 108 | M20: 111 | N20: 110 | O20: 102 | P20: 107 | Q20: 97 | R20: 81 | S20: 81 | T20: 71 | U20: 107 | V20: 112 | W20: 98 | X20: 104 | Y20: 92 | Z20: 101 | AA20: 94 | AB20: =SUM(E20:AA20) -> 2337
D21: JML | E21: =SUM(E19:E20) -> 225 | F21: =SUM(F19:F20) -> 203 | G21: =SUM(G19:G20) -> 199 | H21: =SUM(H19:H20) -> 184 | I21: =SUM(I19:I20) -> 212 | J21: =SUM(J19:J20) -> 204 | K21: =SUM(K19:K20) -> 205 | L21: =SUM(L19:L20) -> 180 | ... AA21: =SUM(AA19:AA20) -> 189 | AB21: =SUM(E21:AA21) -> 4446
B22: 2. | C22: Jumlah pengguna hak pilih dalam Daftar Pemilih Tambahan (DPTb) | D22: LK | E22: 0 | F22: 0 | G22: 0 | H22: 0 | I22: 0 | J22: 0 | K22: 0 | L22: 0 | M22: 0 | N22: 0 | O22: 2 | P22: 0 | Q22: 0 | R22: 0 | S22: 0 | T22: 0 | U22: 0 | V22: 0 | W22: 0 | X22: 0 | Y22: 0 | Z22: 1 | AA22: 0 | AB22: =SUM(E22:AA22) -> 3
D23: PR | E23: 0 | F23: 0 | G23: 0 | H23: 0 | I23: 0 | J23: 0 | K23: 0 | L23: 0 | M23: 0 | N23: 0 | O23: 1 | P23: 0 | Q23: 0 | R23: 0 | S23: 0 | T23: 0 | U23: 0 | V23: 0 | W23: 0 | X23: 0 | Y23: 0 | Z23: 0 | AA23: 0 | AB23: =SUM(E23:AA23) -> 1
D24: JML | E24: =SUM(E22:E23) -> 0 | F24: =SUM(F22:F23) -> 0 | G24: =SUM(G22:G23) -> 0 | H24: =SUM(H22:H23) -> 0 | I24: =SUM(I22:I23) -> 0 | J24: =SUM(J22:J23) -> 0 | K24: =SUM(K22:K23) -> 0 | L24: =SUM(L22:L23) -> 0 | ... AA24: =SUM(AA22:AA23) -> 0 | AB24: =SUM(E24:AA24) -> 4
B25: 3. | C25: Jumlah pengguna hak pilih dalam Daftar Pemilih Khusus (DPK) | D25: LK | E25: 0 | F25: 0 | G25: 4 | H25: 0 | I25: 1 | J25: 3 | K25: 1 | L25: 1 | M25: 0 | N25: 3 | O25: 1 | P25: 2 | Q25: 4 | R25: 3 | S25: 0 | T25: 6 | U25: 0 | V25: 4 | W25: 1 | X25: 0 | Y25: 3 | Z25: 3 | AA25: 1 | AB25: =SUM(E25:AA25) -> 41
D26: PR | E26: 0 | F26: 0 | G26: 2 | H26: 0 | I26: 3 | J26: 6 | K26: 0 | L26: 2 | M26: 2 | N26: 1 | O26: 3 | P26: 4 | Q26: 3 | R26: 3 | S26: 0 | T26: 6 | U26: 0 | V26: 2 | W26: 2 | X26: 0 | Y26: 1 | Z26: 0 | AA26: 0 | AB26: =SUM(E26:AA26) -> 40
D27: JML | E27: =SUM(E25:E26) -> 0 | F27: =SUM(F25:F26) -> 0 | G27: =SUM(G25:G26) -> 6 | H27: =SUM(H25:H26) -> 0 | I27: =SUM(I25:I26) -> 4 | J27: =SUM(J25:J26) -> 9 | K27: =SUM(K25:K26) -> 1 | L27: =SUM(L25:L26) -> 3 | ... AA27: =SUM(AA25:AA26) -> 1 | AB27: =SUM(E27:AA27) -> 81
B28: 4. | C28: Jumlah Pengguna Hak Pilih (B.1+B.2+B.3) | D28: LK | E28: =SUM(E19,E22,E25) -> 111 | F28: =SUM(F19,F22,F25) -> 99 | G28: =SUM(G19,G22,G25) -> 88 | H28: =SUM(H19,H22,H25) -> 86 | I28: =SUM(I19,I22,I25) -> 105 | J28: =SUM(J19,J22,J25) -> 105 | K28: =SUM(K19,K22,K25) -> 86 | L28: =SUM(L19,L22,L25) -> 73 | ... AA28: =SUM(AA19,AA22,AA25) -> 96 | AB28: =SUM(E28:AA28) -> 2153
D29: PR | E29: =SUM(E20,E23,E26) -> 114 | F29: =SUM(F20,F23,F26) -> 104 | G29: =SUM(G20,G23,G26) -> 117 | H29: =SUM(H20,H23,H26) -> 98 | I29: =SUM(I20,I23,I26) -> 111 | J29: =SUM(J20,J23,J26) -> 108 | K29: =SUM(K20,K23,K26) -> 120 | L29: =SUM(L20,L23,L26) -> 110 | ... AA29: =SUM(AA20,AA23,AA26) -> 94 | AB29: =SUM(E29:AA29) -> 2378
D30: JML | E30: =SUM(E28:E29) -> 225 | F30: =SUM(F28:F29) -> 203 | G30: =SUM(G28:G29) -> 205 | H30: =SUM(H28:H29) -> 184 | I30: =SUM(I28:I29) -> 216 | J30: =SUM(J28:J29) -> 213 | K30: =SUM(K28:K29) -> 206 | L30: =SUM(L28:L29) -> 183 | ... AA30: =SUM(AA28:AA29) -> 190 | AB30: =SUM(E30:AA30) -> 4531
A32: II | B32: DATA PENGGUNAAN SURAT SUARA
A33: 1 | B33: Jumlah surat suara yang diterima, termasuk surat suara cadangan 2,5% dari DPT | E33: 270 | F33: 251 | G33: 255 | H33: 235 | I33: 272 | J33: 285 | K33: 260 | L33: 276 | M33: 281 | N33: 283 | O33: 291 | P33: 260 | Q33: 272 | R33: 234 | S33: 191 | T33: 194 | U33: 260 | V33: 257 | W33: 266 | X33: 264 | Y33: 261 | Z33: 246 | AA33: 244 | AB33: =SUM(E33:AA33) -> 5908
A34: 2 | B34: Jumlah surat suara yang digunakan | E34: 225 | F34: 203 | G34: 205 | H34: 184 | I34: 216 | J34: 213 | K34: 206 | L34: 183 | M34: 217 | N34: 207 | O34: 215 | P34: 217 | Q34: 197 | R34: 154 | S34: 145 | T34: 138 | U34: 199 | V34: 209 | W34: 201 | X34: 202 | Y34: 196 | Z34: 209 | AA34: 190 | AB34: =SUM(E34:AA34) -> 4531
A35: 3 | B35: Jumlah surat suara dikembalikan oleh pemilih (karena rusak atau keliru coblos) | E35: 0 | F35: 0 | G35: 0 | H35: 0 | I35: 0 | J35: 1 | K35: 0 | L35: 0 | M35: 0 | N35: 0 | O35: 0 | P35: 0 | Q35: 0 | R35: 0 | S35: 0 | T35: 0 | U35: 0 | V35: 0 | W35: 0 | X35: 0 | Y35: 1 | Z35: 0 | AA35: 0 | AB35: =SUM(E35:AA35) -> 2
A36: 4 | B36: Jumlah surat suara yang tidak digunakan/tidak terpakai, termasuk sisa surat suara cadangan | E36: =E33-(E34+E35) -> 45 | F36: =F33-(F34+F35) -> 48 | G36: =G33-(G34+G35) -> 50 | H36: =H33-(H34+H35) -> 51 | I36: =I33-(I34+I35) -> 56 | J36: =J33-(J34+J35) -> 71 | K36: =K33-(K34+K35) -> 54 | L36: =L33-(L34+L35) -> 93 | ... AA36: =AA33-(AA34+AA35) -> 54 | AB36: =SUM(E36:AA36) -> 1375
A38: III | B38: DATA PEMILIH DISABILITAS
B39: Jumlah seluruh Pemilih disabilitas yang menggunakan hak pilih | D39: LK | E39: 0 | F39: 0 | G39: 0 | H39: 0 | I39: 1 | J39: 0 | K39: 0 | L39: 0 | M39: 0 | N39: 0 | O39: 0 | P39: 0 | Q39: 0 | R39: 1 | S39: 0 | T39: 0 | U39: 0 | V39: 0 | W39: 0 | X39: 0 | Y39: 0 | Z39: 0 | AA39: 1 | AB39: =SUM(E39:AA39) -> 3
D40: PR | E40: 0 | F40: 0 | G40: 0 | H40: 0 | I40: 1 | J40: 0 | K40: 0 | L40: 0 | M40: 0 | N40: 0 | O40: 0 | P40: 0 | Q40: 0 | R40: 3 | S40: 0 | T40: 0 | U40: 0 | V40: 0 | W40: 0 | X40: 0 | Y40: 0 | Z40: 0 | AA40: 2 | AB40: =SUM(E40:AA40) -> 6
D41: JML | E41: =SUM(E39:E40) -> 0 | F41: =SUM(F39:F40) -> 0 | G41: =SUM(G39:G40) -> 0 | H41: =SUM(H39:H40) -> 0 | I41: =SUM(I39:I40) -> 2 | J41: =SUM(J39:J40) -> 0 | K41: =SUM(K39:K40) -> 0 | L41: =SUM(L39:L40) -> 0 | ... AA41: =SUM(AA39:AA40) -> 3 | AB41: =SUM(E41:AA41) -> 9
A43: IV | B43: DATA RINCIAN PEROLEHAN SUARA PASANGAN CALON BUPATI DAN WAKIL BUPATI
A44: NOMOR DAN NAMA CALON
B45: 1 | C45: H. ANIES RASYID BASWEDAN, Ph.D. - Dr. (H.C.) H. A. MUHAIMIN ISKANDAR | E45: 24 | F45: 18 | G45: 23 | H45: 12 | I45: 26 | J45: 18 | K45: 7 | L45: 6 | M45: 17 | N45: 22 | O45: 11 | P45: 30 | Q45: 24 | R45: 15 | S45: 17 | T45: 13 | U45: 20 | V45: 28 | W45: 13 | X45: 9 | Y45: 15 | Z45: 22 | AA45: 19 | AB45: =SUM(E45:AA45) -> 409
B46: 2 | C46: H. PRABOWO SUBIANTO - GIBRAN RAKABUMING RAKA | E46: 184 | F46: 160 | G46: 174 | H46: 159 | I46: 181 | J46: 173 | K46: 187 | L46: 168 | M46: 186 | N46: 164 | O46: 199 | P46: 169 | Q46: 150 | R46: 122 | S46: 111 | T46: 110 | U46: 158 | V46: 152 | W46: 167 | X46: 165 | Y46: 146 | Z46: 150 | AA46: 146 | AB46: =SUM(E46:AA46) -> 3681
B47: 3 | C47: H. GANJAR PRANOWO, S.H., M.I.P. - Prof. Dr. H. M. MAHFUD MD | E47: 14 | F47: 23 | G47: 3 | H47: 13 | I47: 6 | J47: 20 | K47: 10 | L47: 5 | M47: 13 | N47: 18 | O47: 3 | P47: 14 | Q47: 21 | R47: 14 | S47: 12 | T47: 10 | U47: 16 | V47: 22 | W47: 16 | X47: 25 | Y47: 33 | Z47: 31 | AA47: 23 | AB47: =SUM(E47:AA47) -> 365
A49: V | B49: DATA SUARA SAH DAN TIDAK SAH
B50: A. | C50: JUMLAH SELURUH SUARA SAH | E50: =SUM(E45:E47) -> 222 | F50: =SUM(F45:F47) -> 201 | G50: =SUM(G45:G47) -> 200 | H50: =SUM(H45:H47) -> 184 | I50: =SUM(I45:I47) -> 213 | J50: =SUM(J45:J47) -> 211 | K50: =SUM(K45:K47) -> 204 | L50: =SUM(L45:L47) -> 179 | ... AA50: =SUM(AA45:AA47) -> 188 | AB50: =SUM(E50:AA50) -> 4455
B51: B. | C51: JUMLAH SUARA TIDAK SAH | E51: 3 | F51: 2 | G51: 5 | H51: 0 | I51: 3 | J51: 2 | K51: 2 | L51: 4 | M51: 1 | N51: 3 | O51: 2 | P51: 4 | Q51: 2 | R51: 3 | S51: 5 | T51: 5 | U51: 5 | V51: 7 | W51: 5 | X51: 3 | Y51: 2 | Z51: 6 | AA51: 2 | AB51: =SUM(E51:AA51) -> 76
B52: C. | C52: JUMLAH SELURUH SUARA SAH DAN SUARA TIDAK SAH (V.A + V.B) | E52: =SUM(E50:E51) -> 225 | F52: =SUM(F50:F51) -> 203 | G52: =SUM(G50:G51) -> 205 | H52: =SUM(H50:H51) -> 184 | I52: =SUM(I50:I51) -> 216 | J52: =SUM(J50:J51) -> 213 | K52: =SUM(K50:K51) -> 206 | L52: =SUM(L50:L51) -> 183 | ... AA52: =SUM(AA50:AA51) -> 190 | AB52: =SUM(E52:AA52) -> 4531

Sheet BLIMBINGSARI
C2: Kecamatan | D2: BLIMBINGSARI
C3: Kabupaten | D3: BANYUWANGI
C4: Provinsi | D4: JAWA TIMUR
C9: Kelurahan | D9: BLIMBINGSARI
A12: I | B12: DATA PEMILIH DAN PENGGUNAAN HAK PILIH | U12: JUMLAH AKHIR
A13: A | B13: DATA PEMILIH | E13: TPS 001 | F13: TPS 002 | G13: TPS 003 | H13: TPS 004 | I13: TPS 005 | J13: TPS 006 | K13: TPS 007 | L13: TPS 008 | M13: TPS 009 | N13: TPS 010 | O13: TPS 011 | P13: TPS 012 | Q13: TPS 013 | R13: TPS 014 | S13: TPS 015 | T13: TPS 016
B14: Jumlah Pemilih dalam Daftar Pemilih Tetap (DPT) | D14: LK | E14: 131 | F14: 147 | G14: 117 | H14: 106 | I14: 134 | J14: 135 | K14: 123 | L14: 110 | M14: 101 | N14: 126 | O14: 86 | P14: 122 | Q14: 144 | R14: 131 | S14: 112 | T14: 143 | U14: =SUM(E14:T14) -> 1968
D15: PR | E15: 131 | F15: 139 | G15: 132 | H15: 111 | I15: 139 | J15: 140 | K15: 143 | L15: 118 | M15: 116 | N15: 139 | O15: 95 | P15: 114 | Q15: 144 | R15: 141 | S15: 107 | T15: 145 | U15: =SUM(E15:T15) -> 2054
D16: JML | E16: =SUM(E14:E15) -> 262 | F16: =SUM(F14:F15) -> 286 | G16: =SUM(G14:G15) -> 249 | H16: =SUM(H14:H15) -> 217 | I16: =SUM(I14:I15) -> 273 | J16: =SUM(J14:J15) -> 275 | K16: =SUM(K14:K15) -> 266 | L16: =SUM(L14:L15) -> 228 | ... T16: =SUM(T14:T15) -> 288 | U16: =SUM(E16:T16) -> 4022
A18: B | B18: PENGGUNA HAK PILIH
B19: 1. | C19: Jumlah pengguna hak pilih dalam Daftar Pemilih Tetap (DPT) | D19: LK | E19: 101 | F19: 117 | G19: 86 | H19: 84 | I19: 107 | J19: 108 | K19: 94 | L19: 77 | M19: 87 | N19: 98 | O19: 62 | P19: 92 | Q19: 106 | R19: 93 | S19: 84 | T19: 114 | U19: =SUM(E19:T19) -> 1510
D20: PR | E20: 116 | F20: 122 | G20: 109 | H20: 91 | I20: 112 | J20: 110 | K20: 118 | L20: 89 | M20: 99 | N20: 115 | O20: 79 | P20: 102 | Q20: 108 | R20: 97 | S20: 90 | T20: 125 | U20: =SUM(E20:T20) -> 1682
D21: JML | E21: =SUM(E19:E20) -> 217 | F21: =SUM(F19:F20) -> 239 | G21: =SUM(G19:G20) -> 195 | H21: =SUM(H19:H20) -> 175 | I21: =SUM(I19:I20) -> 219 | J21: =SUM(J19:J20) -> 218 | K21: =SUM(K19:K20) -> 212 | L21: =SUM(L19:L20) -> 166 | ... T21: =SUM(T19:T20) -> 239 | U21: =SUM(E21:T21) -> 3192
B22: 2. | C22: Jumlah pengguna hak pilih dalam Daftar Pemilih Tambahan (DPTb) | D22: LK | E22: 11 | F22: 2 | G22: 2 | H22: 3 | I22: 2 | J22: 3 | K22: 6 | L22: 7 | M22: 4 | N22: 5 | O22: 0 | P22: 0 | Q22: 0 | R22: 0 | S22: 0 | T22: 0 | U22: =SUM(E22:T22) -> 45
D23: PR | E23: 5 | F23: 3 | G23: 0 | H23: 0 | I23: 2 | J23: 1 | K23: 4 | L23: 5 | M23: 7 | N23: 2 | O23: 0 | P23: 0 | Q23: 0 | R23: 0 | S23: 0 | T23: 0 | U23: =SUM(E23:T23) -> 29
D24: JML | E24: =SUM(E22:E23) -> 16 | F24: =SUM(F22:F23) -> 5 | G24: =SUM(G22:G23) -> 2 | H24: =SUM(H22:H23) -> 3 | I24: =SUM(I22:I23) -> 4 | J24: =SUM(J22:J23) -> 4 | K24: =SUM(K22:K23) -> 10 | L24: =SUM(L22:L23) -> 12 | ... T24: =SUM(T22:T23) -> 0 | U24: =SUM(E24:T24) -> 74
B25: 3. | C25: Jumlah pengguna hak pilih dalam Daftar Pemilih Khusus (DPK) | D25: LK | E25: 1 | F25: 1 | G25: 1 | H25: 3 | I25: 0 | J25: 0 | K25: 1 | L25: 0 | M25: 0 | N25: 2 | O25: 0 | P25: 1 | Q25: 1 | R25: 1 | S25: 4 | T25: 0 | U25: =SUM(E25:T25) -> 16
D26: PR | E26: 2 | F26: 1 | G26: 0 | H26: 1 | I26: 2 | J26: 1 | K26: 1 | L26: 1 | M26: 1 | N26: 2 | O26: 1 | P26: 1 | Q26: 0 | R26: 1 | S26: 3 | T26: 1 | U26: =SUM(E26:T26) -> 19
D27: JML | E27: =SUM(E25:E26) -> 3 | F27: =SUM(F25:F26) -> 2 | G27: =SUM(G25:G26) -> 1 | H27: =SUM(H25:H26) -> 4 | I27: =SUM(I25:I26) -> 2 | J27: =SUM(J25:J26) -> 1 | K27: =SUM(K25:K26) -> 2 | L27: =SUM(L25:L26) -> 1 | ... T27: =SUM(T25:T26) -> 1 | U27: =SUM(E27:T27) -> 35
B28: 4. | C28: Jumlah Pengguna Hak Pilih (B.1+B.2+B.3) | D28: LK | E28: =SUM(E19,E22,E25) -> 113 | F28: =SUM(F19,F22,F25) -> 120 | G28: =SUM(G19,G22,G25) -> 89 | H28: =SUM(H19,H22,H25) -> 90 | I28: =SUM(I19,I22,I25) -> 109 | J28: =SUM(J19,J22,J25) -> 111 | K28: =SUM(K19,K22,K25) -> 101 | L28: =SUM(L19,L22,L25) -> 84 | ... T28: =SUM(T19,T22,T25) -> 114 | U28: =SUM(E28:T28) -> 1571
D29: PR | E29: =SUM(E20,E23,E26) -> 123 | F29: =SUM(F20,F23,F26) -> 126 | G29: =SUM(G20,G23,G26) -> 109 | H29: =SUM(H20,H23,H26) -> 92 | I29: =SUM(I20,I23,I26) -> 116 | J29: =SUM(J20,J23,J26) -> 112 | K29: =SUM(K20,K23,K26) -> 123 | L29: =SUM(L20,L23,L26) -> 95 | ... T29: =SUM(T20,T23,T26) -> 126 | U29: =SUM(E29:T29) -> 1730
D30: JML | E30: =SUM(E28:E29) -> 236 | F30: =SUM(F28:F29) -> 246 | G30: =SUM(G28:G29) -> 198 | H30: =SUM(H28:H29) -> 182 | I30: =SUM(I28:I29) -> 225 | J30: =SUM(J28:J29) -> 223 | K30: =SUM(K28:K29) -> 224 | L30: =SUM(L28:L29) -> 179 | ... T30: =SUM(T28:T29) -> 240 | U30: =SUM(E30:T30) -> 3301
A32: II | B32: DATA PENGGUNAAN SURAT SUARA
A33: 1 | B33: Jumlah surat suara yang diterima, termasuk surat suara cadangan 2,5% dari DPT | E33: 268 | F33: 292 | G33: 254 | H33: 222 | I33: 278 | J33: 281 | K33: 272 | L33: 233 | M33: 222 | N33: 271 | O33: 185 | P33: 241 | Q33: 296 | R33: 278 | S33: 224 | T33: 294 | U33: =SUM(E33:T33) -> 4111
A34: 2 | B34: Jumlah surat suara yang digunakan | E34: 236 | F34: 246 | G34: 198 | H34: 182 | I34: 225 | J34: 223 | K34: 224 | L34: 179 | M34: 198 | N34: 224 | O34: 142 | P34: 196 | Q34: 215 | R34: 192 | S34: 181 | T34: 240 | U34: =SUM(E34:T34) -> 3301
A35: 3 | B35: Jumlah surat suara dikembalikan oleh pemilih (karena rusak atau keliru coblos) | E35: 1 | F35: 0 | G35: 0 | H35: 0 | I35: 1 | J35: 3 | K35: 0 | L35: 0 | M35: 0 | N35: 4 | O35: 0 | P35: 0 | Q35: 0 | R35: 0 | S35: 4 | T35: 0 | U35: =SUM(E35:T35) -> 13
A36: 4 | B36: Jumlah surat suara yang tidak digunakan/tidak terpakai, termasuk sisa surat suara cadangan | E36: =E33-(E34+E35) -> 31 | F36: =F33-(F34+F35) -> 46 | G36: =G33-(G34+G35) -> 56 | H36: =H33-(H34+H35) -> 40 | I36: =I33-(I34+I35) -> 52 | J36: =J33-(J34+J35) -> 55 | K36: =K33-(K34+K35) -> 48 | L36: =L33-(L34+L35) -> 54 | ... T36: =T33-(T34+T35) -> 54 | U36: =SUM(E36:T36) -> 797
A38: III | B38: DATA PEMILIH DISABILITAS
B39: Jumlah seluruh Pemilih disabilitas yang menggunakan hak pilih | D39: LK | E39: 0 | F39: 0 | G39: 0 | H39: 1 | I39: 0 | J39: 0 | K39: 0 | L39: 1 | M39: 0 | N39: 0 | O39: 2 | P39: 0 | Q39: 1 | R39: 0 | S39: 0 | T39: 0 | U39: =SUM(E39:T39) -> 5
D40: PR | E40: 0 | F40: 0 | G40: 0 | H40: 1 | I40: 0 | J40: 0 | K40: 0 | L40: 0 | M40: 1 | N40: 0 | O40: 1 | P40: 0 | Q40: 1 | R40: 0 | S40: 0 | T40: 0 | U40: =SUM(E40:T40) -> 4
D41: JML | E41: =SUM(E39:E40) -> 0 | F41: =SUM(F39:F40) -> 0 | G41: =SUM(G39:G40) -> 0 | H41: =SUM(H39:H40) -> 2 | I41: =SUM(I39:I40) -> 0 | J41: =SUM(J39:J40) -> 0 | K41: =SUM(K39:K40) -> 0 | L41: =SUM(L39:L40) -> 1 | ... T41: =SUM(T39:T40) -> 0 | U41: =SUM(E41:T41) -> 9
A43: IV | B43: DATA RINCIAN PEROLEHAN SUARA PASANGAN CALON BUPATI DAN WAKIL BUPATI
A44: NOMOR DAN NAMA CALON
B45: 1 | C45: H. ANIES RASYID BASWEDAN, Ph.D. - Dr. (H.C.) H. A. MUHAIMIN ISKANDAR | E45: 27 | F45: 23 | G45: 18 | H45: 10 | I45: 40 | J45: 10 | K45: 14 | L45: 37 | M45: 26 | N45: 51 | O45: 15 | P45: 15 | Q45: 15 | R45: 8 | S45: 11 | T45: 21 | U45: =SUM(E45:T45) -> 341
B46: 2 | C46: H. PRABOWO SUBIANTO - GIBRAN RAKABUMING RAKA | E46: 188 | F46: 187 | G46: 141 | H46: 154 | I46: 160 | J46: 181 | K46: 186 | L46: 113 | M46: 149 | N46: 157 | O46: 111 | P46: 160 | Q46: 164 | R46: 151 | S46: 153 | T46: 176 | U46: =SUM(E46:T46) -> 2531
B47: 3 | C47: H. GANJAR PRANOWO, S.H., M.I.P. - Prof. Dr. H. M. MAHFUD MD | E47: 20 | F47: 30 | G47: 33 | H47: 17 | I47: 22 | J47: 29 | K47: 22 | L47: 25 | M47: 21 | N47: 13 | O47: 16 | P47: 19 | Q47: 30 | R47: 18 | S47: 17 | T47: 41 | U47: =SUM(E47:T47) -> 373
A49: V | B49: DATA SUARA SAH DAN TIDAK SAH
B50: A. | C50: JUMLAH SELURUH SUARA SAH | E50: =SUM(E45:E47) -> 235 | F50: =SUM(F45:F47) -> 240 | G50: =SUM(G45:G47) -> 192 | H50: =SUM(H45:H47) -> 181 | I50: =SUM(I45:I47) -> 222 | J50: =SUM(J45:J47) -> 220 | K50: =SUM(K45:K47) -> 222 | L50: =SUM(L45:L47) -> 175 | ... T50: =SUM(T45:T47) -> 238 | U50: =SUM(E50:T50) -> 3245
B51: B. | C51: JUMLAH SUARA TIDAK SAH | E51: 1 | F51: 6 | G51: 6 | H51: 1 | I51: 3 | J51: 3 | K51: 2 | L51: 4 | M51: 2 | N51: 3 | O51: 0 | P51: 2 | Q51: 6 | R51: 15 | S51: 0 | T51: 2 | U51: =SUM(E51:T51) -> 56
B52: C. | C52: JUMLAH SELURUH SUARA SAH DAN SUARA TIDAK SAH (V.A + V.B) | E52: =SUM(E50:E51) -> 236 | F52: =SUM(F50:F51) -> 246 | G52: =SUM(G50:G51) -> 198 | H52: =SUM(H50:H51) -> 182 | I52: =SUM(I50:I51) -> 225 | J52: =SUM(J50:J51) -> 223 | K52: =SUM(K50:K51) -> 224 | L52: =SUM(L50:L51) -> 179 | ... T52: =SUM(T50:T51) -> 240 | U52: =SUM(E52:T52) -> 3301

Sheet BOMO
C2: Kecamatan | D2: BLIMBINGSARI
C3: Kabupaten | D3: BANYUWANGI
C4: Provinsi | D4: JAWA TIMUR
C9: Kelurahan | D9: BOMO
A12: I | B12: DATA PEMILIH DAN PENGGUNAAN HAK PILIH | W12: JUMLAH AKHIR
A13: A | B13: DATA PEMILIH | E13: TPS 001 | F13: TPS 002 | G13: TPS 003 | H13: TPS 004 | I13: TPS 005 | J13: TPS 006 | K13: TPS 007 | L13: TPS 008 | M13: TPS 009 | N13: TPS 010 | O13: TPS 011 | P13: TPS 012 | Q13: TPS 013 | R13: TPS 014 | S13: TPS 015 | T13: TPS 016 | U13: TPS 017 | V13: TPS 018
B14: Jumlah Pemilih dalam Daftar Pemilih Tetap (DPT) | D14: LK | E14: 142 | F14: 123 | G14: 144 | H14: 139 | I14: 133 | J14: 151 | K14: 136 | L14: 141 | M14: 150 | N14: 113 | O14: 133 | P14: 121 | Q14: 121 | R14: 133 | S14: 130 | T14: 121 | U14: 127 | V14: 123 | W14: =SUM(E14:V14) -> 2381
D15: PR | E15: 143 | F15: 143 | G15: 150 | H15: 146 | I15: 133 | J15: 145 | K15: 138 | L15: 156 | M15: 141 | N15: 121 | O15: 140 | P15: 132 | Q15: 131 | R15: 129 | S15: 136 | T15: 122 | U15: 128 | V15: 119 | W15: =SUM(E15:V15) -> 2453
D16: JML | E16: =SUM(E14:E15) -> 285 | F16: =SUM(F14:F15) -> 266 | G16: =SUM(G14:G15) -> 294 | H16: =SUM(H14:H15) -> 285 | I16: =SUM(I14:I15) -> 266 | J16: =SUM(J14:J15) -> 296 | K16: =SUM(K14:K15) -> 274 | L16: =SUM(L14:L15) -> 297 | ... V16: =SUM(V14:V15) -> 242 | W16: =SUM(E16:V16) -> 4834
A18: B | B18: PENGGUNA HAK PILIH
B19: 1. | C19: Jumlah pengguna hak pilih dalam Daftar Pemilih Tetap (DPT) | D19: LK | E19: 117 | F19: 88 | G19: 96 | H19: 104 | I19: 96 | J19: 109 | K19: 105 | L19: 105 | M19: 113 | N19: 96 | O19: 102 | P19: 96 | Q19: 67 | R19: 89 | S19: 95 | T19: 99 | U19: 93 | V19: 83 | W19: =SUM(E19:V19) -> 1753
D20: PR | E20: 122 | F20: 111 | G20: 116 | H20: 118 | I20: 100 | J20: 109 | K20: 112 | L20: 127 | M20: 117 | N20: 99 | O20: 122 | P20: 102 | Q20: 87 | R20: 92 | S20: 106 | T20: 99 | U20: 109 | V20: 88 | W20: =SUM(E20:V20) -> 1936
D21: JML | E21: =SUM(E19:E20) -> 239 | F21: =SUM(F19:F20) -> 199 | G21: =SUM(G19:G20) -> 212 | H21: =SUM(H19:H20) -> 222 | I21: =SUM(I19:I20) -> 196 | J21: =SUM(J19:J20) -> 218 | K21: =SUM(K19:K20) -> 217 | L21: =SUM(L19:L20) -> 232 | ... V21: =SUM(V19:V20) -> 171 | W21: =SUM(E21:V21) -> 3689
B22: 2. | C22: Jumlah pengguna hak pilih dalam Daftar Pemilih Tambahan (DPTb) | D22: LK | E22: 0 | F22: 0 | G22: 0 | H22: 0 | I22: 0 | J22: 2 | K22: 0 | L22: 0 | M22: 0 | N22: 0 | O22: 0 | P22: 0 | Q22: 0 | R22: 0 | S22: 0 | T22: 6 | U22: 4 | V22: 0 | W22: =SUM(E22:V22) -> 12
D23: PR | E23: 0 | F23: 0 | G23: 0 | H23: 0 | I23: 0 | J23: 0 | K23: 0 | L23: 0 | M23: 0 | N23: 0 | O23: 0 | P23: 0 | Q23: 0 | R23: 0 | S23: 0 | T23: 4 | U23: 1 | V23: 0 | W23: =SUM(E23:V23) -> 5
D24: JML | E24: =SUM(E22:E23) -> 0 | F24: =SUM(F22:F23) -> 0 | G24: =SUM(G22:G23) -> 0 | H24: =SUM(H22:H23) -> 0 | I24: =SUM(I22:I23) -> 0 | J24: =SUM(J22:J23) -> 2 | K24: =SUM(K22:K23) -> 0 | L24: =SUM(L22:L23) -> 0 | ... V24: =SUM(V22:V23) -> 0 | W24: =SUM(E24:V24) -> 17
B25: 3. | C25: Jumlah pengguna hak pilih dalam Daftar Pemilih Khusus (DPK) | D25: LK | E25: 1 | F25: 0 | G25: 2 | H25: 0 | I25: 0 | J25: 0 | K25: 0 | L25: 1 | M25: 1 | N25: 0 | O25: 0 | P25: 1 | Q25: 1 | R25: 0 | S25: 0 | T25: 0 | U25: 1 | V25: 1 | W25: =SUM(E25:V25) -> 9
D26: PR | E26: 2 | F26: 0 | G26: 1 | H26: 0 | I26: 0 | J26: 0 | K26: 0 | L26: 0 | M26: 3 | N26: 0 | O26: 0 | P26: 1 | Q26: 0 | R26: 0 | S26: 1 | T26: 0 | U26: 0 | V26: 1 | W26: =SUM(E26:V26) -> 9
D27: JML | E27: =SUM(E25:E26) -> 3 | F27: =SUM(F25:F26) -> 0 | G27: =SUM(G25:G26) -> 3 | H27: =SUM(H25:H26) -> 0 | I27: =SUM(I25:I26) -> 0 | J27: =SUM(J25:J26) -> 0 | K27: =SUM(K25:K26) -> 0 | L27: =SUM(L25:L26) -> 1 | ... V27: =SUM(V25:V26) -> 2 | W27: =SUM(E27:V27) -> 18
B28: 4. | C28: Jumlah Pengguna Hak Pilih (B.1+B.2+B.3) | D28: LK | E28: =SUM(E19,E22,E25) -> 118 | F28: =SUM(F19,F22,F25) -> 88 | G28: =SUM(G19,G22,G25) -> 98 | H28: =SUM(H19,H22,H25) -> 104 | I28: =SUM(I19,I22,I25) -> 96 | J28: =SUM(J19,J22,J25) -> 111 | K28: =SUM(K19,K22,K25) -> 105 | L28: =SUM(L19,L22,L25) -> 106 | ... V28: =SUM(V19,V22,V25) -> 84 | W28: =SUM(E28:V28) -> 1774
D29: PR | E29: =SUM(E20,E23,E26) -> 124 | F29: =SUM(F20,F23,F26) -> 111 | G29: =SUM(G20,G23,G26) -> 117 | H29: =SUM(H20,H23,H26) -> 118 | I29: =SUM(I20,I23,I26) -> 100 | J29: =SUM(J20,J23,J26) -> 109 | K29: =SUM(K20,K23,K26) -> 112 | L29: =SUM(L20,L23,L26) -> 127 | ... V29: =SUM(V20,V23,V26) -> 89 | W29: =SUM(E29:V29) -> 1950
D30: JML | E30: =SUM(E28:E29) -> 242 | F30: =SUM(F28:F29) -> 199 | G30: =SUM(G28:G29) -> 215 | H30: =SUM(H28:H29) -> 222 | I30: =SUM(I28:I29) -> 196 | J30: =SUM(J28:J29) -> 220 | K30: =SUM(K28:K29) -> 217 | L30: =SUM(L28:L29) -> 233 | ... V30: =SUM(V28:V29) -> 173 | W30: =SUM(E30:V30) -> 3724
A32: II | B32: DATA PENGGUNAAN SURAT SUARA
A33: 1 | B33: Jumlah surat suara yang diterima, termasuk surat suara cadangan 2,5% dari DPT | E33: 291 | F33: 272 | G33: 300 | H33: 291 | I33: 272 | J33: 302 | K33: 280 | L33: 303 | M33: 297 | N33: 239 | O33: 280 | P33: 260 | Q33: 258 | R33: 268 | S33: 272 | T33: 249 | U33: 261 | V33: 246 | W33: =SUM(E33:V33) -> 4941
A34: 2 | B34: Jumlah surat suara yang digunakan | E34: 242 | F34: 199 | G34: 215 | H34: 222 | I34: 196 | J34: 220 | K34: 217 | L34: 233 | M34: 234 | N34: 195 | O34: 224 | P34: 200 | Q34: 155 | R34: 181 | S34: 202 | T34: 208 | U34: 208 | V34: 173 | W34: =SUM(E34:V34) -> 3724
A35: 3 | B35: Jumlah surat suara dikembalikan oleh pemilih (karena rusak atau keliru coblos) | E35: 0 | F35: 0 | G35: 0 | H35: 2 | I35: 0 | J35: 0 | K35: 2 | L35: 0 | M35: 0 | N35: 0 | O35: 0 | P35: 0 | Q35: 0 | R35: 0 | S35: 0 | T35: 0 | U35: 0 | V35: 0 | W35: =SUM(E35:V35) -> 4
A36: 4 | B36: Jumlah surat suara yang tidak digunakan/tidak terpakai, termasuk sisa surat suara cadangan | E36: =E33-(E34+E35) -> 49 | F36: =F33-(F34+F35) -> 73 | G36: =G33-(G34+G35) -> 85 | H36: =H33-(H34+H35) -> 67 | I36: =I33-(I34+I35) -> 76 | J36: =J33-(J34+J35) -> 82 | K36: =K33-(K34+K35) -> 61 | L36: =L33-(L34+L35) -> 70 | ... V36: =V33-(V34+V35) -> 73 | W36: =SUM(E36:V36) -> 1213
A38: III | B38: DATA PEMILIH DISABILITAS
B39: Jumlah seluruh Pemilih disabilitas yang menggunakan hak pilih | D39: LK | E39: 0 | F39: 0 | G39: 0 | H39: 0 | I39: 0 | J39: 0 | K39: 0 | L39: 0 | M39: 0 | N39: 0 | O39: 1 | P39: 1 | Q39: 0 | R39: 0 | S39: 0 | T39: 1 | U39: 0 | V39: 1 | W39: =SUM(E39:V39) -> 4
D40: PR | E40: 0 | F40: 0 | G40: 0 | H40: 0 | I40: 0 | J40: 0 | K40: 0 | L40: 0 | M40: 0 | N40: 0 | O40: 0 | P40: 0 | Q40: 0 | R40: 0 | S40: 0 | T40: 0 | U40: 0 | V40: 0 | W40: =SUM(E40:V40) -> 0
D41: JML | E41: =SUM(E39:E40) -> 0 | F41: =SUM(F39:F40) -> 0 | G41: =SUM(G39:G40) -> 0 | H41: =SUM(H39:H40) -> 0 | I41: =SUM(I39:I40) -> 0 | J41: =SUM(J39:J40) -> 0 | K41: =SUM(K39:K40) -> 0 | L41: =SUM(L39:L40) -> 0 | ... V41: =SUM(V39:V40) -> 1 | W41: =SUM(E41:V41) -> 4
A43: IV | B43: DATA RINCIAN PEROLEHAN SUARA PASANGAN CALON BUPATI DAN WAKIL BUPATI
A44: NOMOR DAN NAMA CALON
B45: 1 | C45: H. ANIES RASYID BASWEDAN, Ph.D. - Dr. (H.C.) H. A. MUHAIMIN ISKANDAR | E45: 1 | F45: 9 | G45: 9 | H45: 10 | I45: 10 | J45: 20 | K45: 13 | L45: 17 | M45: 6 | N45: 6 | O45: 11 | P45: 9 | Q45: 17 | R45: 6 | S45: 8 | T45: 3 | U45: 7 | V45: 5 | W45: =SUM(E45:V45) -> 167
B46: 2 | C46: H. PRABOWO SUBIANTO - GIBRAN RAKABUMING RAKA | E46: 209 | F46: 173 | G46: 158 | H46: 157 | I46: 144 | J46: 162 | K46: 132 | L46: 181 | M46: 203 | N46: 164 | O46: 167 | P46: 124 | Q46: 99 | R46: 118 | S46: 138 | T46: 169 | U46: 165 | V46: 104 | W46: =SUM(E46:V46) -> 2767
B47: 3 | C47: H. GANJAR PRANOWO, S.H., M.I.P. - Prof. Dr. H. M. MAHFUD MD | E47: 25 | F47: 13 | G47: 37 | H47: 45 | I47: 39 | J47: 31 | K47: 64 | L47: 28 | M47: 23 | N47: 23 | O47: 44 | P47: 63 | Q47: 36 | R47: 54 | S47: 52 | T47: 34 | U47: 32 | V47: 62 | W47: =SUM(E47:V47) -> 705
A49: V | B49: DATA SUARA SAH DAN TIDAK SAH
B50: A. | C50: JUMLAH SELURUH SUARA SAH | E50: =SUM(E45:E47) -> 235 | F50: =SUM(F45:F47) -> 195 | G50: =SUM(G45:G47) -> 204 | H50: =SUM(H45:H47) -> 212 | I50: =SUM(I45:I47) -> 193 | J50: =SUM(J45:J47) -> 213 | K50: =SUM(K45:K47) -> 209 | L50: =SUM(L45:L47) -> 226 | ... V50: =SUM(V45:V47) -> 171 | W50: =SUM(E50:V50) -> 3639
B51: B. | C51: JUMLAH SUARA TIDAK SAH | E51: 7 | F51: 4 | G51: 11 | H51: 10 | I51: 3 | J51: 7 | K51: 8 | L51: 7 | M51: 2 | N51: 2 | O51: 2 | P51: 4 | Q51: 3 | R51: 3 | S51: 4 | T51: 2 | U51: 4 | V51: 2 | W51: =SUM(E51:V51) -> 85
B52: C. | C52: JUMLAH SELURUH SUARA SAH DAN SUARA TIDAK SAH (V.A + V.B) | E52: =SUM(E50:E51) -> 242 | F52: =SUM(F50:F51) -> 199 | G52: =SUM(G50:G51) -> 215 | H52: =SUM(H50:H51) -> 222 | I52: =SUM(I50:I51) -> 196 | J52: =SUM(J50:J51) -> 220 | K52: =SUM(K50:K51) -> 217 | L52: =SUM(L50:L51) -> 233 | ... V52: =SUM(V50:V51) -> 173 | W52: =SUM(E52:V52) -> 3724

Sheet GINTANGAN
C2: Kecamatan | D2: BLIMBINGSARI
C3: Kabupaten | D3: BANYUWANGI
C4: Provinsi | D4: JAWA TIMUR
C9: Kelurahan | D9: GINTANGAN
A12: I | B12: DATA PEMILIH DAN PENGGUNAAN HAK PILIH | Z12: JUMLAH AKHIR
A13: A | B13: DATA PEMILIH | E13: TPS 001 | F13: TPS 002 | G13: TPS 003 | H13: TPS 004 | I13: TPS 005 | J13: TPS 006 | K13: TPS 007 | L13: TPS 008 | M13: TPS 009 | N13: TPS 010 | O13: TPS 011 | P13: TPS 012 | Q13: TPS 013 | R13: TPS 014 | S13: TPS 015 | T13: TPS 016 | U13: TPS 017 | V13: TPS 018 | W13: TPS 019 | X13: TPS 020 | Y13: TPS 021
B14: Jumlah Pemilih dalam Daftar Pemilih Tetap (DPT) | D14: LK | E14: 131 | F14: 144 | G14: 132 | H14: 135 | I14: 130 | J14: 127 | K14: 139 | L14: 150 | M14: 143 | N14: 116 | O14: 128 | P14: 110 | Q14: 120 | R14: 112 | S14: 110 | T14: 139 | U14: 131 | V14: 125 | W14: 127 | X14: 126 | Y14: 133 | Z14: =SUM(E14:Y14) -> 2708
D15: PR | E15: 133 | F15: 142 | G15: 152 | H15: 150 | I15: 140 | J15: 133 | K15: 145 | L15: 139 | M15: 141 | N15: 125 | O15: 107 | P15: 133 | Q15: 124 | R15: 117 | S15: 115 | T15: 138 | U15: 144 | V15: 137 | W15: 140 | X15: 148 | Y15: 136 | Z15: =SUM(E15:Y15) -> 2839
D16: JML | E16: =SUM(E14:E15) -> 264 | F16: =SUM(F14:F15) -> 286 | G16: =SUM(G14:G15) -> 284 | H16: =SUM(H14:H15) -> 285 | I16: =SUM(I14:I15) -> 270 | J16: =SUM(J14:J15) -> 260 | K16: =SUM(K14:K15) -> 284 | L16: =SUM(L14:L15) -> 289 | ... Y16: =SUM(Y14:Y15) -> 269 | Z16: =SUM(E16:Y16) -> 5547
A18: B | B18: PENGGUNA HAK PILIH
B19: 1. | C19: Jumlah pengguna hak pilih dalam Daftar Pemilih Tetap (DPT) | D19: LK | E19: 95 | F19: 101 | G19: 106 | H19: 92 | I19: 99 | J19: 97 | K19: 96 | L19: 125 | M19: 112 | N19: 81 | O19: 88 | P19: 88 | Q19: 104 | R19: 95 | S19: 86 | T19: 98 | U19: 102 | V19: 100 | W19: 91 | X19: 105 | Y19: 90 | Z19: =SUM(E19:Y19) -> 2051
D20: PR | E20: 105 | F20: 108 | G20: 128 | H20: 117 | I20: 119 | J20: 110 | K20: 128 | L20: 116 | M20: 122 | N20: 102 | O20: 88 | P20: 111 | Q20: 106 | R20: 93 | S20: 91 | T20: 113 | U20: 113 | V20: 112 | W20: 105 | X20: 127 | Y20: 107 | Z20: =SUM(E20:Y20) -> 2321
D21: JML | E21: =SUM(E19:E20) -> 200 | F21: =SUM(F19:F20) -> 209 | G21: =SUM(G19:G20) -> 234 | H21: =SUM(H19:H20) -> 209 | I21: =SUM(I19:I20) -> 218 | J21: =SUM(J19:J20) -> 207 | K21: =SUM(K19:K20) -> 224 | L21: =SUM(L19:L20) -> 241 | ... Y21: =SUM(Y19:Y20) -> 197 | Z21: =SUM(E21:Y21) -> 4372
B22: 2. | C22: Jumlah pengguna hak pilih dalam Daftar Pemilih Tambahan (DPTb) | D22: LK | E22: 0 | F22: 0 | G22: 0 | H22: 0 | I22: 1 | J22: 0 | K22: 0 | L22: 0 | M22: 0 | N22: 0 | O22: 0 | P22: 0 | Q22: 1 | R22: 0 | S22: 0 | T22: 0 | U22: 0 | V22: 0 | W22: 0 | X22: 0 | Y22: 0 | Z22: =SUM(E22:Y22) -> 2
D23: PR | E23: 0 | F23: 0 | G23: 0 | H23: 0 | I23: 0 | J23: 1 | K23: 0 | L23: 0 | M23: 0 | N23: 0 | O23: 0 | P23: 1 | Q23: 1 | R23: 0 | S23: 0 | T23: 0 | U23: 0 | V23: 0 | W23: 0 | X23: 0 | Y23: 1 | Z23: =SUM(E23:Y23) -> 4
D24: JML | E24: =SUM(E22:E23) -> 0 | F24: =SUM(F22:F23) -> 0 | G24: =SUM(G22:G23) -> 0 | H24: =SUM(H22:H23) -> 0 | I24: =SUM(I22:I23) -> 1 | J24: =SUM(J22:J23) -> 1 | K24: =SUM(K22:K23) -> 0 | L24: =SUM(L22:L23) -> 0 | ... Y24: =SUM(Y22:Y23) -> 1 | Z24: =SUM(E24:Y24) -> 6
B25: 3. | C25: Jumlah pengguna hak pilih dalam Daftar Pemilih Khusus (DPK) | D25: LK | E25: 0 | F25: 1 | G25: 0 | H25: 0 | I25: 0 | J25: 0 | K25: 1 | L25: 0 | M25: 1 | N25: 0 | O25: 0 | P25: 0 | Q25: 1 | R25: 0 | S25: 0 | T25: 0 | U25: 0 | V25: 0 | W25: 0 | X25: 1 | Y25: 0 | Z25: =SUM(E25:Y25) -> 5
D26: PR | E26: 0 | F26: 0 | G26: 0 | H26: 1 | I26: 1 | J26: 3 | K26: 2 | L26: 2 | M26: 0 | N26: 0 | O26: 0 | P26: 0 | Q26: 1 | R26: 0 | S26: 0 | T26: 0 | U26: 0 | V26: 0 | W26: 0 | X26: 0 | Y26: 0 | Z26: =SUM(E26:Y26) -> 10
D27: JML | E27: =SUM(E25:E26) -> 0 | F27: =SUM(F25:F26) -> 1 | G27: =SUM(G25:G26) -> 0 | H27: =SUM(H25:H26) -> 1 | I27: =SUM(I25:I26) -> 1 | J27: =SUM(J25:J26) -> 3 | K27: =SUM(K25:K26) -> 3 | L27: =SUM(L25:L26) -> 2 | ... Y27: =SUM(Y25:Y26) -> 0 | Z27: =SUM(E27:Y27) -> 15
B28: 4. | C28: Jumlah Pengguna Hak Pilih (B.1+B.2+B.3) | D28: LK | E28: =SUM(E19,E22,E25) -> 95 | F28: =SUM(F19,F22,F25) -> 102 | G28: =SUM(G19,G22,G25) -> 106 | H28: =SUM(H19,H22,H25) -> 92 | I28: =SUM(I19,I22,I25) -> 100 | J28: =SUM(J19,J22,J25) -> 97 | K28: =SUM(K19,K22,K25) -> 97 | L28: =SUM(L19,L22,L25) -> 125 | ... Y28: =SUM(Y19,Y22,Y25) -> 90 | Z28: =SUM(E28:Y28) -> 2058
D29: PR | E29: =SUM(E20,E23,E26) -> 105 | F29: =SUM(F20,F23,F26) -> 108 | G29: =SUM(G20,G23,G26) -> 128 | H29: =SUM(H20,H23,H26) -> 118 | I29: =SUM(I20,I23,I26) -> 120 | J29: =SUM(J20,J23,J26) -> 114 | K29: =SUM(K20,K23,K26) -> 130 | L29: =SUM(L20,L23,L26) -> 118 | ... Y29: =SUM(Y20,Y23,Y26) -> 108 | Z29: =SUM(E29:Y29) -> 2335
D30: JML | E30: =SUM(E28:E29) -> 200 | F30: =SUM(F28:F29) -> 210 | G30: =SUM(G28:G29) -> 234 | H30: =SUM(H28:H29) -> 210 | I30: =SUM(I28:I29) -> 220 | J30: =SUM(J28:J29) -> 211 | K30: =SUM(K28:K29) -> 227 | L30: =SUM(L28:L29) -> 243 | ... Y30: =SUM(Y28:Y29) -> 198 | Z30: =SUM(E30:Y30) -> 4393
A32: II | B32: DATA PENGGUNAAN SURAT SUARA
A33: 1 | B33: Jumlah surat suara yang diterima, termasuk surat suara cadangan 2,5% dari DPT | E33: 270 | F33: 292 | G33: 290 | H33: 292 | I33: 276 | J33: 266 | K33: 290 | L33: 294 | M33: 290 | N33: 246 | O33: 240 | P33: 248 | Q33: 248 | R33: 233 | S33: 230 | T33: 283 | U33: 281 | V33: 268 | W33: 273 | X33: 280 | Y33: 275 | Z33: =SUM(E33:Y33) -> 5665
A34: 2 | B34: Jumlah surat suara yang digunakan | E34: 200 | F34: 210 | G34: 234 | H34: 210 | I34: 220 | J34: 211 | K34: 227 | L34: 243 | M34: 235 | N34: 183 | O34: 176 | P34: 200 | Q34: 214 | R34: 188 | S34: 177 | T34: 211 | U34: 215 | V34: 212 | W34: 196 | X34: 233 | Y34: 198 | Z34: =SUM(E34:Y34) -> 4393
A35: 3 | B35: Jumlah surat suara dikembalikan oleh pemilih (karena rusak atau keliru coblos) | E35: 0 | F35: 2 | G35: 0 | H35: 0 | I35: 1 | J35: 0 | K35: 0 | L35: 0 | M35: 0 | N35: 0 | O35: 0 | P35: 0 | Q35: 0 | R35: 1 | S35: 0 | T35: 0 | U35: 0 | V35: 0 | W35: 0 | X35: 0 | Y35: 0 | Z35: =SUM(E35:Y35) -> 4
A36: 4 | B36: Jumlah surat suara yang tidak digunakan/tidak terpakai, termasuk sisa surat suara cadangan | E36: =E33-(E34+E35) -> 70 | F36: =F33-(F34+F35) -> 80 | G36: =G33-(G34+G35) -> 56 | H36: =H33-(H34+H35) -> 82 | I36: =I33-(I34+I35) -> 55 | J36: =J33-(J34+J35) -> 55 | K36: =K33-(K34+K35) -> 63 | L36: =L33-(L34+L35) -> 51 | ... Y36: =Y33-(Y34+Y35) -> 77 | Z36: =SUM(E36:Y36) -> 1268
A38: III | B38: DATA PEMILIH DISABILITAS
B39: Jumlah seluruh Pemilih disabilitas yang menggunakan hak pilih | D39: LK | E39: 0 | F39: 0 | G39: 1 | H39: 0 | I39: 0 | J39: 0 | K39: 0 | L39: 2 | M39: 0 | N39: 0 | O39: 0 | P39: 0 | Q39: 0 | R39: 0 | S39: 1 | T39: 0 | U39: 0 | V39: 0 | W39: 0 | X39: 0 | Y39: 0 | Z39: =SUM(E39:Y39) -> 4
D40: PR | E40: 0 | F40: 1 | G40: 0 | H40: 0 | I40: 0 | J40: 0 | K40: 2 | L40: 1 | M40: 0 | N40: 1 | O40: 0 | P40: 0 | Q40: 0 | R40: 0 | S40: 0 | T40: 0 | U40: 0 | V40: 0 | W40: 0 | X40: 1 | Y40: 0 | Z40: =SUM(E40:Y40) -> 6
D41: JML | E41: =SUM(E39:E40) -> 0 | F41: =SUM(F39:F40) -> 1 | G41: =SUM(G39:G40) -> 1 | H41: =SUM(H39:H40) -> 0 | I41: =SUM(I39:I40) -> 0 | J41: =SUM(J39:J40) -> 0 | K41: =SUM(K39:K40) -> 2 | L41: =SUM(L39:L40) -> 3 | ... Y41: =SUM(Y39:Y40) -> 0 | Z41: =SUM(E41:Y41) -> 10
A43: IV | B43: DATA RINCIAN PEROLEHAN SUARA PASANGAN CALON BUPATI DAN WAKIL BUPATI
A44: NOMOR DAN NAMA CALON
B45: 1 | C45: H. ANIES RASYID BASWEDAN, Ph.D. - Dr. (H.C.) H. A. MUHAIMIN ISKANDAR | E45: 10 | F45: 15 | G45: 30 | H45: 12 | I45: 6 | J45: 10 | K45: 20 | L45: 28 | M45: 54 | N45: 30 | O45: 23 | P45: 24 | Q45: 18 | R45: 27 | S45: 18 | T45: 17 | U45: 30 | V45: 17 | W45: 32 | X45: 41 | Y45: 27 | Z45: =SUM(E45:Y45) -> 489
B46: 2 | C46: H. PRABOWO SUBIANTO - GIBRAN RAKABUMING RAKA | E46: 133 | F46: 132 | G46: 149 | H46: 153 | I46: 166 | J46: 138 | K46: 156 | L46: 161 | M46: 149 | N46: 105 | O46: 127 | P46: 151 | Q46: 155 | R46: 127 | S46: 116 | T46: 157 | U46: 177 | V46: 179 | W46: 135 | X46: 164 | Y46: 143 | Z46: =SUM(E46:Y46) -> 3073
B47: 3 | C47: H. GANJAR PRANOWO, S.H., M.I.P. - Prof. Dr. H. M. MAHFUD MD | E47: 52 | F47: 58 | G47: 52 | H47: 44 | I47: 42 | J47: 54 | K47: 44 | L47: 48 | M47: 26 | N47: 45 | O47: 21 | P47: 23 | Q47: 38 | R47: 32 | S47: 39 | T47: 34 | U47: 8 | V47: 13 | W47: 27 | X47: 23 | Y47: 27 | Z47: =SUM(E47:Y47) -> 750
A49: V | B49: DATA SUARA SAH DAN TIDAK SAH
B50: A. | C50: JUMLAH SELURUH SUARA SAH | E50: =SUM(E45:E47) -> 195 | F50: =SUM(F45:F47) -> 205 | G50: =SUM(G45:G47) -> 231 | H50: =SUM(H45:H47) -> 209 | I50: =SUM(I45:I47) -> 214 | J50: =SUM(J45:J47) -> 202 | K50: =SUM(K45:K47) -> 220 | L50: =SUM(L45:L47) -> 237 | ... Y50: =SUM(Y45:Y47) -> 197 | Z50: =SUM(E50:Y50) -> 4312
B51: B. | C51: JUMLAH SUARA TIDAK SAH | E51: 5 | F51: 5 | G51: 3 | H51: 1 | I51: 6 | J51: 9 | K51: 7 | L51: 6 | M51: 6 | N51: 3 | O51: 5 | P51: 2 | Q51: 3 | R51: 2 | S51: 4 | T51: 3 | U51: 0 | V51: 3 | W51: 2 | X51: 5 | Y51: 1 | Z51: =SUM(E51:Y51) -> 81
B52: C. | C52: JUMLAH SELURUH SUARA SAH DAN SUARA TIDAK SAH (V.A + V.B) | E52: =SUM(E50:E51) -> 200 | F52: =SUM(F50:F51) -> 210 | G52: =SUM(G50:G51) -> 234 | H52: =SUM(H50:H51) -> 210 | I52: =SUM(I50:I51) -> 220 | J52: =SUM(J50:J51) -> 211 | K52: =SUM(K50:K51) -> 227 | L52: =SUM(L50:L51) -> 243 | ... Y52: =SUM(Y50:Y51) -> 198 | Z52: =SUM(E52:Y52) -> 4393

Sheet KALIGUNG
C2: Kecamatan | D2: BLIMBINGSARI
C3: Kabupaten | D3: BANYUWANGI
C4: Provinsi | D4: JAWA TIMUR
C9: Kelurahan | D9: KALIGUNG
A12: I | B12: DATA PEMILIH DAN PENGGUNAAN HAK PILIH | R12: JUMLAH AKHIR
A13: A | B13: DATA PEMILIH | E13: TPS 001 | F13: TPS 002 | G13: TPS 003 | H13: TPS 004 | I13: TPS 005 | J13: TPS 006 | K13: TPS 007 | L13: TPS 008 | M13: TPS 009 | N13: TPS 010 | O13: TPS 011 | P13: TPS 901 | Q13: TPS 902
B14: Jumlah Pemilih dalam Daftar Pemilih Tetap (DPT) | D14: LK | E14: 116 | F14: 123 | G14: 135 | H14: 136 | I14: 146 | J14: 140 | K14: 127 | L14: 122 | M14: 134 | N14: 143 | O14: 140 | P14: 267 | Q14: 223 | R14: =SUM(E14:Q14) -> 1952
D15: PR | E15: 119 | F15: 131 | G15: 117 | H15: 138 | I15: 149 | J15: 135 | K15: 123 | L15: 140 | M15: 148 | N15: 139 | O15: 137 | P15: 0 | Q15: 0 | R15: =SUM(E15:Q15) -> 1476
D16: JML | E16: =SUM(E14:E15) -> 235 | F16: =SUM(F14:F15) -> 254 | G16: =SUM(G14:G15) -> 252 | H16: =SUM(H14:H15) -> 274 | I16: =SUM(I14:I15) -> 295 | J16: =SUM(J14:J15) -> 275 | K16: =SUM(K14:K15) -> 250 | L16: =SUM(L14:L15) -> 262 | ... Q16: =SUM(Q14:Q15) -> 223 | R16: =SUM(E16:Q16) -> 3428
A18: B | B18: PENGGUNA HAK PILIH
B19: 1. | C19: Jumlah pengguna hak pilih dalam Daftar Pemilih Tetap (DPT) | D19: LK | E19: 83 | F19: 81 | G19: 95 | H19: 103 | I19: 116 | J19: 101 | K19: 85 | L19: 89 | M19: 97 | N19: 113 | O19: 104 | P19: 125 | Q19: 97 | R19: =SUM(E19:Q19) -> 1289
D20: PR | E20: 91 | F20: 108 | G20: 95 | H20: 115 | I20: 128 | J20: 114 | K20: 100 | L20: 115 | M20: 128 | N20: 104 | O20: 105 | P20: 0 | Q20: 0 | R20: =SUM(E20:Q20) -> 1203
D21: JML | E21: =SUM(E19:E20) -> 174 | F21: =SUM(F19:F20) -> 189 | G21: =SUM(G19:G20) -> 190 | H21: =SUM(H19:H20) -> 218 | I21: =SUM(I19:I20) -> 244 | J21: =SUM(J19:J20) -> 215 | K21: =SUM(K19:K20) -> 185 | L21: =SUM(L19:L20) -> 204 | ... Q21: =SUM(Q19:Q20) -> 97 | R21: =SUM(E21:Q21) -> 2492
B22: 2. | C22: Jumlah pengguna hak pilih dalam Daftar Pemilih Tambahan (DPTb) | D22: LK | E22: 13 | F22: 12 | G22: 12 | H22: 13 | I22: 6 | J22: 9 | K22: 13 | L22: 9 | M22: 12 | N22: 13 | O22: 10 | P22: 137 | Q22: 116 | R22: =SUM(E22:Q22) -> 375
D23: PR | E23: 0 | F23: 2 | G23: 0 | H23: 0 | I23: 0 | J23: 0 | K23: 0 | L23: 1 | M23: 0 | N23: 0 | O23: 0 | P23: 0 | Q23: 0 | R23: =SUM(E23:Q23) -> 3
D24: JML | E24: 13 | F24: =SUM(F22:F23) -> 14 | G24: =SUM(G22:G23) -> 12 | H24: =SUM(H22:H23) -> 13 | I24: =SUM(I22:I23) -> 6 | J24: =SUM(J22:J23) -> 9 | K24: =SUM(K22:K23) -> 13 | L24: =SUM(L22:L23) -> 10 | M24: =SUM(M22:M23) -> 12 | ... Q24: =SUM(Q22:Q23) -> 116 | R24: =SUM(E24:Q24) -> 378
B25: 3. | C25: Jumlah pengguna hak pilih dalam Daftar Pemilih Khusus (DPK) | D25: LK | E25: 0 | F25: 0 | G25: 1 | H25: 0 | I25: 0 | J25: 0 | K25: 0 | L25: 0 | M25: 0 | N25: 0 | O25: 1 | P25: 0 | Q25: 0 | R25: =SUM(E25:Q25) -> 2
D26: PR | E26: 1 | F26: 0 | G26: 3 | H26: 0 | I26: 0 | J26: 0 | K26: 0 | L26: 2 | M26: 0 | N26: 0 | O26: 2 | P26: 0 | Q26: 0 | R26: =SUM(E26:Q26) -> 8
D27: JML | E27: =SUM(E25:E26) -> 1 | F27: =SUM(F25:F26) -> 0 | G27: =SUM(G25:G26) -> 4 | H27: =SUM(H25:H26) -> 0 | I27: =SUM(I25:I26) -> 0 | J27: =SUM(J25:J26) -> 0 | K27: =SUM(K25:K26) -> 0 | L27: =SUM(L25:L26) -> 2 | ... Q27: =SUM(Q25:Q26) -> 0 | R27: =SUM(E27:Q27) -> 10
B28: 4. | C28: Jumlah Pengguna Hak Pilih (B.1+B.2+B.3) | D28: LK | E28: =SUM(E19,E22,E25) -> 96 | F28: =SUM(F19,F22,F25) -> 93 | G28: =SUM(G19,G22,G25) -> 108 | H28: =SUM(H19,H22,H25) -> 116 | I28: =SUM(I19,I22,I25) -> 122 | J28: =SUM(J19,J22,J25) -> 110 | K28: =SUM(K19,K22,K25) -> 98 | L28: =SUM(L19,L22,L25) -> 98 | ... Q28: =SUM(Q19,Q22,Q25) -> 213 | R28: =SUM(E28:Q28) -> 1666
D29: PR | E29: =SUM(E20,E23,E26) -> 92 | F29: =SUM(F20,F23,F26) -> 110 | G29: =SUM(G20,G23,G26) -> 98 | H29: =SUM(H20,H23,H26) -> 115 | I29: =SUM(I20,I23,I26) -> 128 | J29: =SUM(J20,J23,J26) -> 114 | K29: =SUM(K20,K23,K26) -> 100 | L29: =SUM(L20,L23,L26) -> 118 | ... Q29: =SUM(Q20,Q23,Q26) -> 0 | R29: =SUM(E29:Q29) -> 1214
D30: JML | E30: =SUM(E28:E29) -> 188 | F30: =SUM(F28:F29) -> 203 | G30: =SUM(G28:G29) -> 206 | H30: =SUM(H28:H29) -> 231 | I30: =SUM(I28:I29) -> 250 | J30: =SUM(J28:J29) -> 224 | K30: =SUM(K28:K29) -> 198 | L30: =SUM(L28:L29) -> 216 | ... Q30: =SUM(Q28:Q29) -> 213 | R30: =SUM(E30:Q30) -> 2880
A32: II | B32: DATA PENGGUNAAN SURAT SUARA
A33: 1 | B33: Jumlah surat suara yang diterima, termasuk surat suara cadangan 2,5% dari DPT | E33: 240 | F33: 260 | G33: 258 | H33: 279 | I33: 301 | J33: 281 | K33: 255 | L33: 268 | M33: 288 | N33: 290 | O33: 283 | P33: 273 | Q33: 229 | R33: =SUM(E33:Q33) -> 3505
A34: 2 | B34: Jumlah surat suara yang digunakan | E34: 188 | F34: 203 | G34: 206 | H34: 231 | I34: 250 | J34: 224 | K34: 198 | L34: 216 | M34: 237 | N34: 230 | O34: 222 | P34: 262 | Q34: 213 | R34: =SUM(E34:Q34) -> 2880
A35: 3 | B35: Jumlah surat suara dikembalikan oleh pemilih (karena rusak atau keliru coblos) | E35: 0 | F35: 0 | G35: 0 | H35: 0 | I35: 2 | J35: 0 | K35: 0 | L35: 1 | M35: 0 | N35: 3 | O35: 1 | P35: 0 | Q35: 0 | R35: =SUM(E35:Q35) -> 7
A36: 4 | B36: Jumlah surat suara yang tidak digunakan/tidak terpakai, termasuk sisa surat suara cadangan | E36: =E33-(E34+E35) -> 52 | F36: =F33-(F34+F35) -> 57 | G36: =G33-(G34+G35) -> 52 | H36: =H33-(H34+H35) -> 48 | I36: =I33-(I34+I35) -> 49 | J36: =J33-(J34+J35) -> 57 | K36: =K33-(K34+K35) -> 57 | L36: =L33-(L34+L35) -> 51 | ... Q36: =Q33-(Q34+Q35) -> 16 | R36: =SUM(E36:Q36) -> 618
A38: III | B38: DATA PEMILIH DISABILITAS
B39: Jumlah seluruh Pemilih disabilitas yang menggunakan hak pilih | D39: LK | E39: 0 | F39: 0 | G39: 0 | H39: 0 | I39: 3 | J39: 0 | K39: 0 | L39: 0 | M39: 0 | N39: 0 | O39: 0 | P39: 0 | Q39: 0 | R39: =SUM(E39:Q39) -> 3
D40: PR | E40: 0 | F40: 0 | G40: 0 | H40: 0 | I40: 1 | J40: 0 | K40: 0 | L40: 0 | M40: 0 | N40: 1 | O40: 0 | P40: 0 | Q40: 0 | R40: =SUM(E40:Q40) -> 2
D41: JML | E41: =SUM(E39:E40) -> 0 | F41: =SUM(F39:F40) -> 0 | G41: =SUM(G39:G40) -> 0 | H41: =SUM(H39:H40) -> 0 | I41: =SUM(I39:I40) -> 4 | J41: =SUM(J39:J40) -> 0 | K41: =SUM(K39:K40) -> 0 | L41: =SUM(L39:L40) -> 0 | ... Q41: =SUM(Q39:Q40) -> 0 | R41: =SUM(E41:Q41) -> 5
A43: IV | B43: DATA RINCIAN PEROLEHAN SUARA PASANGAN CALON BUPATI DAN WAKIL BUPATI
A44: NOMOR DAN NAMA CALON
B45: 1 | C45: H. ANIES RASYID BASWEDAN, Ph.D. - Dr. (H.C.) H. A. MUHAIMIN ISKANDAR | E45: 35 | F45: 29 | G45: 33 | H45: 22 | I45: 52 | J45: 42 | K45: 51 | L45: 31 | M45: 44 | N45: 31 | O45: 30 | P45: 244 | Q45: 191 | R45: =SUM(E45:Q45) -> 835
B46: 2 | C46: H. PRABOWO SUBIANTO - GIBRAN RAKABUMING RAKA | E46: 123 | F46: 134 | G46: 141 | H46: 137 | I46: 173 | J46: 155 | K46: 121 | L46: 165 | M46: 162 | N46: 170 | O46: 153 | P46: 10 | Q46: 20 | R46: =SUM(E46:Q46) -> 1664
B47: 3 | C47: H. GANJAR PRANOWO, S.H., M.I.P. - Prof. Dr. H. M. MAHFUD MD | E47: 28 | F47: 39 | G47: 27 | H47: 68 | I47: 24 | J47: 23 | K47: 21 | L47: 17 | M47: 23 | N47: 27 | O47: 36 | P47: 1 | Q47: 1 | R47: =SUM(E47:Q47) -> 335
A49: V | B49: DATA SUARA SAH DAN TIDAK SAH
B50: A. | C50: JUMLAH SELURUH SUARA SAH | E50: =SUM(E45:E47) -> 186 | F50: =SUM(F45:F47) -> 202 | G50: =SUM(G45:G47) -> 201 | H50: =SUM(H45:H47) -> 227 | I50: =SUM(I45:I47) -> 249 | J50: =SUM(J45:J47) -> 220 | K50: =SUM(K45:K47) -> 193 | L50: =SUM(L45:L47) -> 213 | ... Q50: =SUM(Q45:Q47) -> 212 | R50: =SUM(E50:Q50) -> 2834
B51: B. | C51: JUMLAH SUARA TIDAK SAH | E51: 2 | F51: 1 | G51: 5 | H51: 4 | I51: 1 | J51: 4 | K51: 5 | L51: 3 | M51: 8 | N51: 2 | O51: 3 | P51: 7 | Q51: 1 | R51: =SUM(E51:Q51) -> 46
B52: C. | C52: JUMLAH SELURUH SUARA SAH DAN SUARA TIDAK SAH (V.A + V.B) | E52: =SUM(E50:E51) -> 188 | F52: =SUM(F50:F51) -> 203 | G52: =SUM(G50:G51) -> 206 | H52: =SUM(H50:H51) -> 231 | I52: =SUM(I50:I51) -> 250 | J52: =SUM(J50:J51) -> 224 | K52: =SUM(K50:K51) -> 198 | L52: =SUM(L50:L51) -> 216 | ... Q52: =SUM(Q50:Q51) -> 213 | R52: =SUM(E52:Q52) -> 2880

Sheet KAOTAN
C2: Kecamatan | D2: BLIMBINGSARI
C3: Kabupaten | D3: BANYUWANGI
C4: Provinsi | D4: JAWA TIMUR
C9: Kelurahan | D9: KAOTAN
A12: I | B12: DATA PEMILIH DAN PENGGUNAAN HAK PILIH | M12: JUMLAH AKHIR
A13: A | B13: DATA PEMILIH | E13: TPS 001 | F13: TPS 002 | G13: TPS 003 | H13: TPS 004 | I13: TPS 005 | J13: TPS 006 | K13: TPS 007 | L13: TPS 008
B14: Jumlah Pemilih dalam Daftar Pemilih Tetap (DPT) | D14: LK | E14: 143 | F14: 142 | G14: 147 | H14: 115 | I14: 127 | J14: 132 | K14: 135 | L14: 139 | M14: =SUM(E14:L14) -> 1080
D15: PR | E15: 147 | F15: 139 | G15: 121 | H15: 123 | I15: 130 | J15: 136 | K15: 141 | L15: 148 | M15: =SUM(E15:L15) -> 1085
D16: JML | E16: =SUM(E14:E15) -> 290 | F16: =SUM(F14:F15) -> 281 | G16: =SUM(G14:G15) -> 268 | H16: =SUM(H14:H15) -> 238 | I16: =SUM(I14:I15) -> 257 | J16: =SUM(J14:J15) -> 268 | K16: =SUM(K14:K15) -> 276 | L16: =SUM(L14:L15) -> 287 | M16: =SUM(E16:L16) -> 2165
A18: B | B18: PENGGUNA HAK PILIH
B19: 1. | C19: Jumlah pengguna hak pilih dalam Daftar Pemilih Tetap (DPT) | D19: LK | E19: 117 | F19: 103 | G19: 125 | H19: 102 | I19: 110 | J19: 119 | K19: 109 | L19: 115 | M19: =SUM(E19:L19) -> 900
D20: PR | E20: 123 | F20: 111 | G20: 108 | H20: 102 | I20: 117 | J20: 99 | K20: 119 | L20: 127 | M20: =SUM(E20:L20) -> 906
D21: JML | E21: =SUM(E19:E20) -> 240 | F21: =SUM(F19:F20) -> 214 | G21: =SUM(G19:G20) -> 233 | H21: =SUM(H19:H20) -> 204 | I21: =SUM(I19:I20) -> 227 | J21: =SUM(J19:J20) -> 218 | K21: =SUM(K19:K20) -> 228 | L21: =SUM(L19:L20) -> 242 | M21: =SUM(E21:L21) -> 1806
B22: 2. | C22: Jumlah pengguna hak pilih dalam Daftar Pemilih Tambahan (DPTb) | D22: LK | E22: 0 | F22: 1 | G22: 0 | H22: 0 | I22: 0 | J22: 1 | K22: 1 | L22: 2 | M22: =SUM(E22:L22) -> 5
D23: PR | E23: 0 | F23: 1 | G23: 1 | H23: 0 | I23: 0 | J23: 0 | K23: 1 | L23: 1 | M23: =SUM(E23:L23) -> 4
D24: JML | E24: =SUM(E22:E23) -> 0 | F24: =SUM(F22:F23) -> 2 | G24: =SUM(G22:G23) -> 1 | H24: =SUM(H22:H23) -> 0 | I24: =SUM(I22:I23) -> 0 | J24: =SUM(J22:J23) -> 1 | K24: =SUM(K22:K23) -> 2 | L24: =SUM(L22:L23) -> 3 | M24: =SUM(E24:L24) -> 9
B25: 3. | C25: Jumlah pengguna hak pilih dalam Daftar Pemilih Khusus (DPK) | D25: LK | E25: 0 | F25: 1 | G25: 0 | H25: 0 | I25: 0 | J25: 0 | K25: 0 | L25: 0 | M25: =SUM(E25:L25) -> 1
D26: PR | E26: 0 | F26: 2 | G26: 0 | H26: 0 | I26: 0 | J26: 2 | K26: 0 | L26: 0 | M26: =SUM(E26:L26) -> 4
D27: JML | E27: =SUM(E25:E26) -> 0 | F27: =SUM(F25:F26) -> 3 | G27: =SUM(G25:G26) -> 0 | H27: =SUM(H25:H26) -> 0 | I27: =SUM(I25:I26) -> 0 | J27: =SUM(J25:J26) -> 2 | K27: =SUM(K25:K26) -> 0 | L27: =SUM(L25:L26) -> 0 | M27: =SUM(E27:L27) -> 5
B28: 4. | C28: Jumlah Pengguna Hak Pilih (B.1+B.2+B.3) | D28: LK | E28: =SUM(E19,E22,E25) -> 117 | F28: =SUM(F19,F22,F25) -> 105 | G28: =SUM(G19,G22,G25) -> 125 | H28: =SUM(H19,H22,H25) -> 102 | I28: =SUM(I19,I22,I25) -> 110 | J28: =SUM(J19,J22,J25) -> 120 | K28: =SUM(K19,K22,K25) -> 110 | L28: =SUM(L19,L22,L25) -> 117 | M28: =SUM(E28:L28) -> 906
D29: PR | E29: =SUM(E20,E23,E26) -> 123 | F29: =SUM(F20,F23,F26) -> 114 | G29: =SUM(G20,G23,G26) -> 109 | H29: =SUM(H20,H23,H26) -> 102 | I29: =SUM(I20,I23,I26) -> 117 | J29: =SUM(J20,J23,J26) -> 101 | K29: =SUM(K20,K23,K26) -> 120 | L29: =SUM(L20,L23,L26) -> 128 | M29: =SUM(E29:L29) -> 914
D30: JML | E30: =SUM(E28:E29) -> 240 | F30: =SUM(F28:F29) -> 219 | G30: =SUM(G28:G29) -> 234 | H30: =SUM(H28:H29) -> 204 | I30: =SUM(I28:I29) -> 227 | J30: =SUM(J28:J29) -> 221 | K30: =SUM(K28:K29) -> 230 | L30: =SUM(L28:L29) -> 245 | M30: =SUM(E30:L30) -> 1820
A32: II | B32: DATA PENGGUNAAN SURAT SUARA
A33: 1 | B33: Jumlah surat suara yang diterima, termasuk surat suara cadangan 2,5% dari DPT | E33: 296 | F33: 287 | G33: 278 | H33: 243 | I33: 263 | J33: 274 | K33: 282 | L33: 293 | M33: =SUM(E33:L33) -> 2216
A34: 2 | B34: Jumlah surat suara yang digunakan | E34: 240 | F34: 219 | G34: 234 | H34: 204 | I34: 227 | J34: 221 | K34: 230 | L34: 245 | M34: =SUM(E34:L34) -> 1820
A35: 3 | B35: Jumlah surat suara dikembalikan oleh pemilih (karena rusak atau keliru coblos) | E35: 1 | F35: 1 | G35: 2 | H35: 0 | I35: 0 | J35: 1 | K35: 0 | L35: 0 | M35: =SUM(E35:L35) -> 5
A36: 4 | B36: Jumlah surat suara yang tidak digunakan/tidak terpakai, termasuk sisa surat suara cadangan | E36: =E33-(E34+E35) -> 55 | F36: =F33-(F34+F35) -> 67 | G36: =G33-(G34+G35) -> 42 | H36: =H33-(H34+H35) -> 39 | I36: =I33-(I34+I35) -> 36 | J36: =J33-(J34+J35) -> 52 | K36: =K33-(K34+K35) -> 52 | L36: =L33-(L34+L35) -> 48 | M36: =SUM(E36:L36) -> 391
A38: III | B38: DATA PEMILIH DISABILITAS
B39: Jumlah seluruh Pemilih disabilitas yang menggunakan hak pilih | D39: LK | E39: 1 | F39: 0 | G39: 0 | H39: 1 | I39: 0 | J39: 0 | K39: 0 | L39: 1 | M39: =SUM(E39:L39) -> 3
D40: PR | E40: 0 | F40: 0 | G40: 0 | H40: 3 | I40: 0 | J40: 2 | K40: 1 | L40: 4 | M40: =SUM(E40:L40) -> 10
D41: JML | E41: =SUM(E39:E40) -> 1 | F41: =SUM(F39:F40) -> 0 | G41: =SUM(G39:G40) -> 0 | H41: =SUM(H39:H40) -> 4 | I41: =SUM(I39:I40) -> 0 | J41: =SUM(J39:J40) -> 2 | K41: =SUM(K39:K40) -> 1 | L41: =SUM(L39:L40) -> 5 | M41: =SUM(E41:L41) -> 13
A43: IV | B43: DATA RINCIAN PEROLEHAN SUARA PASANGAN CALON BUPATI DAN WAKIL BUPATI
A44: NOMOR DAN NAMA CALON
B45: 1 | C45: H. ANIES RASYID BASWEDAN, Ph.D. - Dr. (H.C.) H. A. MUHAIMIN ISKANDAR | E45: 24 | F45: 27 | G45: 23 | H45: 13 | I45: 10 | J45: 38 | K45: 15 | L45: 29 | M45: =SUM(E45:L45) -> 179
B46: 2 | C46: H. PRABOWO SUBIANTO - GIBRAN RAKABUMING RAKA | E46: 187 | F46: 169 | G46: 189 | H46: 178 | I46: 182 | J46: 157 | K46: 171 | L46: 147 | M46: =SUM(E46:L46) -> 1380
B47: 3 | C47: H. GANJAR PRANOWO, S.H., M.I.P. - Prof. Dr. H. M. MAHFUD MD | E47: 23 | F47: 17 | G47: 16 | H47: 13 | I47: 24 | J47: 22 | K47: 35 | L47: 57 | M47: =SUM(E47:L47) -> 207
A49: V | B49: DATA SUARA SAH DAN TIDAK SAH
B50: A. | C50: JUMLAH SELURUH SUARA SAH | E50: =SUM(E45:E47) -> 234 | F50: =SUM(F45:F47) -> 213 | G50: =SUM(G45:G47) -> 228 | H50: =SUM(H45:H47) -> 204 | I50: =SUM(I45:I47) -> 216 | J50: =SUM(J45:J47) -> 217 | K50: =SUM(K45:K47) -> 221 | L50: =SUM(L45:L47) -> 233 | M50: =SUM(E50:L50) -> 1766
B51: B. | C51: JUMLAH SUARA TIDAK SAH | E51: 6 | F51: 6 | G51: 6 | H51: 0 | I51: 11 | J51: 4 | K51: 9 | L51: 12 | M51: =SUM(E51:L51) -> 54
B52: C. | C52: JUMLAH SELURUH SUARA SAH DAN SUARA TIDAK SAH (V.A + V.B) | E52: =SUM(E50:E51) -> 240 | F52: =SUM(F50:F51) -> 219 | G52: =SUM(G50:G51) -> 234 | H52: =SUM(H50:H51) -> 204 | I52: =SUM(I50:I51) -> 227 | J52: =SUM(J50:J51) -> 221 | K52: =SUM(K50:K51) -> 230 | L52: =SUM(L50:L51) -> 245 | M52: =SUM(E52:L52) -> 1820

Sheet KARANGREJO
C2: Kecamatan | D2: BLIMBINGSARI
C3: Kabupaten | D3: BANYUWANGI
C4: Provinsi | D4: JAWA TIMUR
C9: Kelurahan | D9: KARANGREJO
A12: I | B12: DATA PEMILIH DAN PENGGUNAAN HAK PILIH | P12: JUMLAH AKHIR
A13: A | B13: DATA PEMILIH | E13: TPS 001 | F13: TPS 002 | G13: TPS 003 | H13: TPS 004 | I13: TPS 005 | J13: TPS 006 | K13: TPS 007 | L13: TPS 008 | M13: TPS 009 | N13: TPS 010 | O13: TPS 011
B14: Jumlah Pemilih dalam Daftar Pemilih Tetap (DPT) | D14: LK | E14: 116 | F14: 118 | G14: 141 | H14: 136 | I14: 143 | J14: 130 | K14: 131 | L14: 127 | M14: 127 | N14: 121 | O14: 116 | P14: =SUM(E14:O14) -> 1406
D15: PR | E15: 112 | F15: 113 | G15: 122 | H15: 150 | I15: 134 | J15: 139 | K15: 128 | L15: 133 | M15: 124 | N15: 131 | O15: 126 | P15: =SUM(E15:O15) -> 1412
D16: JML | E16: =SUM(E14:E15) -> 228 | F16: =SUM(F14:F15) -> 231 | G16: =SUM(G14:G15) -> 263 | H16: =SUM(H14:H15) -> 286 | I16: =SUM(I14:I15) -> 277 | J16: =SUM(J14:J15) -> 269 | K16: =SUM(K14:K15) -> 259 | L16: =SUM(L14:L15) -> 260 | ... O16: =SUM(O14:O15) -> 242 | P16: =SUM(E16:O16) -> 2818
A18: B | B18: PENGGUNA HAK PILIH
B19: 1. | C19: Jumlah pengguna hak pilih dalam Daftar Pemilih Tetap (DPT) | D19: LK | E19: 79 | F19: 73 | G19: 108 | H19: 104 | I19: 113 | J19: 99 | K19: 100 | L19: 103 | M19: 85 | N19: 79 | O19: 81 | P19: =SUM(E19:O19) -> 1024
D20: PR | E20: 85 | F20: 88 | G20: 105 | H20: 120 | I20: 114 | J20: 112 | K20: 101 | L20: 116 | M20: 101 | N20: 94 | O20: 97 | P20: =SUM(E20:O20) -> 1133
D21: JML | E21: =SUM(E19:E20) -> 164 | F21: =SUM(F19:F20) -> 161 | G21: =SUM(G19:G20) -> 213 | H21: =SUM(H19:H20) -> 224 | I21: =SUM(I19:I20) -> 227 | J21: =SUM(J19:J20) -> 211 | K21: =SUM(K19:K20) -> 201 | L21: =SUM(L19:L20) -> 219 | ... O21: =SUM(O19:O20) -> 178 | P21: =SUM(E21:O21) -> 2157
B22: 2. | C22: Jumlah pengguna hak pilih dalam Daftar Pemilih Tambahan (DPTb) | D22: LK | E22: 6 | F22: 9 | G22: 2 | H22: 2 | I22: 0 | J22: 0 | K22: 0 | L22: 0 | M22: 1 | N22: 0 | O22: 0 | P22: =SUM(E22:O22) -> 20
D23: PR | E23: 0 | F23: 0 | G23: 1 | H23: 1 | I23: 0 | J23: 0 | K23: 0 | L23: 0 | M23: 0 | N23: 0 | O23: 1 | P23: =SUM(E23:O23) -> 3
D24: JML | E24: =SUM(E22:E23) -> 6 | F24: =SUM(F22:F23) -> 9 | G24: =SUM(G22:G23) -> 3 | H24: =SUM(H22:H23) -> 3 | I24: =SUM(I22:I23) -> 0 | J24: =SUM(J22:J23) -> 0 | K24: =SUM(K22:K23) -> 0 | L24: =SUM(L22:L23) -> 0 | ... O24: =SUM(O22:O23) -> 1 | P24: =SUM(E24:O24) -> 23
B25: 3. | C25: Jumlah pengguna hak pilih dalam Daftar Pemilih Khusus (DPK) | D25: LK | E25: 0 | F25: 0 | G25: 0 | H25: 1 | I25: 0 | J25: 0 | K25: 1 | L25: 1 | M25: 0 | N25: 0 | O25: 0 | P25: =SUM(E25:O25) -> 3
D26: PR | E26: 0 | F26: 0 | G26: 1 | H26: 1 | I26: 0 | J26: 0 | K26: 1 | L26: 2 | M26: 0 | N26: 1 | O26: 1 | P26: =SUM(E26:O26) -> 7
D27: JML | E27: =SUM(E25:E26) -> 0 | F27: =SUM(F25:F26) -> 0 | G27: =SUM(G25:G26) -> 1 | H27: =SUM(H25:H26) -> 2 | I27: =SUM(I25:I26) -> 0 | J27: =SUM(J25:J26) -> 0 | K27: =SUM(K25:K26) -> 2 | L27: =SUM(L25:L26) -> 3 | ... O27: =SUM(O25:O26) -> 1 | P27: =SUM(E27:O27) -> 10
B28: 4. | C28: Jumlah Pengguna Hak Pilih (B.1+B.2+B.3) | D28: LK | E28: =SUM(E19,E22,E25) -> 85 | F28: =SUM(F19,F22,F25) -> 82 | G28: =SUM(G19,G22,G25) -> 110 | H28: =SUM(H19,H22,H25) -> 107 | I28: =SUM(I19,I22,I25) -> 113 | J28: =SUM(J19,J22,J25) -> 99 | K28: =SUM(K19,K22,K25) -> 101 | L28: =SUM(L19,L22,L25) -> 104 | ... O28: =SUM(O19,O22,O25) -> 81 | P28: =SUM(E28:O28) -> 1047
D29: PR | E29: =SUM(E20,E23,E26) -> 85 | F29: =SUM(F20,F23,F26) -> 88 | G29: =SUM(G20,G23,G26) -> 107 | H29: =SUM(H20,H23,H26) -> 122 | I29: =SUM(I20,I23,I26) -> 114 | J29: =SUM(J20,J23,J26) -> 112 | K29: =SUM(K20,K23,K26) -> 102 | L29: =SUM(L20,L23,L26) -> 118 | ... O29: =SUM(O20,O23,O26) -> 99 | P29: =SUM(E29:O29) -> 1143
D30: JML | E30: =SUM(E28:E29) -> 170 | F30: =SUM(F28:F29) -> 170 | G30: =SUM(G28:G29) -> 217 | H30: =SUM(H28:H29) -> 229 | I30: =SUM(I28:I29) -> 227 | J30: =SUM(J28:J29) -> 211 | K30: =SUM(K28:K29) -> 203 | L30: =SUM(L28:L29) -> 222 | ... O30: =SUM(O28:O29) -> 180 | P30: =SUM(E30:O30) -> 2190
A32: II | B32: DATA PENGGUNAAN SURAT SUARA
A33: 1 | B33: Jumlah surat suara yang diterima, termasuk surat suara cadangan 2,5% dari DPT | E33: 233 | F33: 236 | G33: 269 | H33: 293 | I33: 283 | J33: 275 | K33: 265 | L33: 266 | M33: 257 | N33: 258 | O33: 247 | P33: =SUM(E33:O33) -> 2882
A34: 2 | B34: Jumlah surat suara yang digunakan | E34: 170 | F34: 170 | G34: 217 | H34: 229 | I34: 227 | J34: 211 | K34: 203 | L34: 222 | M34: 187 | N34: 174 | O34: 180 | P34: =SUM(E34:O34) -> 2190
A35: 3 | B35: Jumlah surat suara dikembalikan oleh pemilih (karena rusak atau keliru coblos) | E35: 13 | F35: 0 | G35: 6 | H35: 5 | I35: 2 | J35: 19 | K35: 0 | L35: 4 | M35: 0 | N35: 0 | O35: 2 | P35: =SUM(E35:O35) -> 51
A36: 4 | B36: Jumlah surat suara yang tidak digunakan/tidak terpakai, termasuk sisa surat suara cadangan | E36: =E33-(E34+E35) -> 50 | F36: =F33-(F34+F35) -> 66 | G36: =G33-(G34+G35) -> 46 | H36: =H33-(H34+H35) -> 59 | I36: =I33-(I34+I35) -> 54 | J36: =J33-(J34+J35) -> 45 | K36: =K33-(K34+K35) -> 62 | L36: =L33-(L34+L35) -> 40 | ... O36: =O33-(O34+O35) -> 65 | P36: =SUM(E36:O36) -> 641
